{
  size: [13, 24, 29], 
  entities: [
    {
      nbt: {
        Motion: [0.0d, 0.0d, 0.0d], 
        Health: 5s, 
        UUIDLeast: -7695661062048667361L, 
        Invulnerable: 0b, 
        Air: 300s, 
        Dimension: 0, 
        OnGround: 1b, 
        PortalCooldown: 0, 
        Rotation: [122.66803741455078f, 0.0f], 
        Item: {
          id: "minecraft:dragon_head", 
          Count: 1b
        }, 
        FallDistance: 0.0f, 
        UUIDMost: 2239083118994146168L, 
        Pos: [-1024.6012964727665d, 7.0d, -994.875d], 
        PickupDelay: 0s, 
        Fire: -1s, 
        id: "minecraft:item", 
        Age: 322s
      }, 
      blockPos: [5, 0, 0], 
      pos: [5.398703527233465d, 0.0d, 0.125d]
    }, 
    {
      nbt: {
        Motion: [0.0d, 0.0d, 0.0d], 
        Health: 5s, 
        UUIDLeast: -6883295886898162315L, 
        Invulnerable: 0b, 
        Air: 300s, 
        Dimension: 0, 
        OnGround: 1b, 
        PortalCooldown: 0, 
        Rotation: [226.66976928710938f, 0.0f], 
        Item: {
          id: "minecraft:potion", 
          tag: {
            Potion: "minecraft:strong_healing"
          }, 
          Count: 1b
        }, 
        FallDistance: 0.0f, 
        UUIDMost: 6945015366122491450L, 
        Pos: [-1023.6875d, 14.125d, -969.4243165492055d], 
        PickupDelay: 0s, 
        Fire: -1s, 
        id: "minecraft:item", 
        Age: 322s
      }, 
      blockPos: [6, 7, 25], 
      pos: [6.3125d, 7.125d, 25.575683450794486d]
    }, 
    {
      nbt: {
        Motion: [0.0d, 0.0d, 0.0d], 
        Health: 5s, 
        UUIDLeast: -6006735563912788582L, 
        Invulnerable: 0b, 
        Air: 300s, 
        Dimension: 0, 
        OnGround: 1b, 
        PortalCooldown: 0, 
        Rotation: [256.96685791015625f, 0.0f], 
        Item: {
          id: "minecraft:potion", 
          tag: {
            Potion: "minecraft:strong_healing"
          }, 
          Count: 1b
        }, 
        FallDistance: 0.0f, 
        UUIDMost: -4708082166652058195L, 
        Pos: [-1023.2750662100219d, 14.125d, -969.9505169248425d], 
        PickupDelay: 0s, 
        Fire: -1s, 
        id: "minecraft:item", 
        Age: 322s
      }, 
      blockPos: [6, 7, 25], 
      pos: [6.724933789978081d, 7.125d, 25.049483075157468d]
    }
  ], 
  blocks: [
    {
      pos: [6, 0, 11], 
      state: 0
    }, 
    {
      pos: [6, 0, 12], 
      state: 0
    }, 
    {
      pos: [6, 0, 13], 
      state: 0
    }, 
    {
      pos: [6, 0, 14], 
      state: 0
    }, 
    {
      pos: [6, 0, 15], 
      state: 0
    }, 
    {
      pos: [6, 0, 16], 
      state: 0
    }, 
    {
      pos: [6, 0, 17], 
      state: 0
    }, 
    {
      pos: [6, 0, 18], 
      state: 0
    }, 
    {
      pos: [6, 0, 19], 
      state: 0
    }, 
    {
      pos: [6, 0, 20], 
      state: 0
    }, 
    {
      pos: [6, 0, 21], 
      state: 0
    }, 
    {
      pos: [6, 0, 22], 
      state: 0
    }, 
    {
      pos: [6, 0, 23], 
      state: 0
    }, 
    {
      pos: [0, 0, 0], 
      state: 1
    }, 
    {
      pos: [1, 0, 0], 
      state: 1
    }, 
    {
      pos: [2, 0, 0], 
      state: 1
    }, 
    {
      pos: [3, 0, 0], 
      state: 1
    }, 
    {
      pos: [4, 0, 0], 
      state: 1
    }, 
    {
      pos: [5, 0, 0], 
      state: 1
    }, 
    {
      pos: [6, 0, 0], 
      state: 1
    }, 
    {
      pos: [7, 0, 0], 
      state: 1
    }, 
    {
      pos: [8, 0, 0], 
      state: 1
    }, 
    {
      pos: [9, 0, 0], 
      state: 1
    }, 
    {
      pos: [10, 0, 0], 
      state: 1
    }, 
    {
      pos: [11, 0, 0], 
      state: 1
    }, 
    {
      pos: [12, 0, 0], 
      state: 1
    }, 
    {
      pos: [0, 0, 1], 
      state: 1
    }, 
    {
      pos: [1, 0, 1], 
      state: 1
    }, 
    {
      pos: [2, 0, 1], 
      state: 1
    }, 
    {
      pos: [3, 0, 1], 
      state: 1
    }, 
    {
      pos: [4, 0, 1], 
      state: 1
    }, 
    {
      pos: [5, 0, 1], 
      state: 1
    }, 
    {
      pos: [6, 0, 1], 
      state: 1
    }, 
    {
      pos: [7, 0, 1], 
      state: 1
    }, 
    {
      pos: [8, 0, 1], 
      state: 1
    }, 
    {
      pos: [9, 0, 1], 
      state: 1
    }, 
    {
      pos: [10, 0, 1], 
      state: 1
    }, 
    {
      pos: [11, 0, 1], 
      state: 1
    }, 
    {
      pos: [12, 0, 1], 
      state: 1
    }, 
    {
      pos: [0, 0, 2], 
      state: 1
    }, 
    {
      pos: [1, 0, 2], 
      state: 1
    }, 
    {
      pos: [2, 0, 2], 
      state: 1
    }, 
    {
      pos: [3, 0, 2], 
      state: 1
    }, 
    {
      pos: [4, 0, 2], 
      state: 1
    }, 
    {
      pos: [5, 0, 2], 
      state: 1
    }, 
    {
      pos: [6, 0, 2], 
      state: 1
    }, 
    {
      pos: [7, 0, 2], 
      state: 1
    }, 
    {
      pos: [8, 0, 2], 
      state: 1
    }, 
    {
      pos: [9, 0, 2], 
      state: 1
    }, 
    {
      pos: [10, 0, 2], 
      state: 1
    }, 
    {
      pos: [11, 0, 2], 
      state: 1
    }, 
    {
      pos: [12, 0, 2], 
      state: 1
    }, 
    {
      pos: [0, 0, 3], 
      state: 1
    }, 
    {
      pos: [1, 0, 3], 
      state: 1
    }, 
    {
      pos: [2, 0, 3], 
      state: 1
    }, 
    {
      pos: [3, 0, 3], 
      state: 1
    }, 
    {
      pos: [4, 0, 3], 
      state: 1
    }, 
    {
      pos: [5, 0, 3], 
      state: 1
    }, 
    {
      pos: [6, 0, 3], 
      state: 1
    }, 
    {
      pos: [7, 0, 3], 
      state: 1
    }, 
    {
      pos: [8, 0, 3], 
      state: 1
    }, 
    {
      pos: [9, 0, 3], 
      state: 1
    }, 
    {
      pos: [10, 0, 3], 
      state: 1
    }, 
    {
      pos: [11, 0, 3], 
      state: 1
    }, 
    {
      pos: [12, 0, 3], 
      state: 1
    }, 
    {
      pos: [0, 0, 4], 
      state: 1
    }, 
    {
      pos: [1, 0, 4], 
      state: 1
    }, 
    {
      pos: [2, 0, 4], 
      state: 1
    }, 
    {
      pos: [3, 0, 4], 
      state: 1
    }, 
    {
      pos: [4, 0, 4], 
      state: 1
    }, 
    {
      pos: [5, 0, 4], 
      state: 1
    }, 
    {
      pos: [6, 0, 4], 
      state: 1
    }, 
    {
      pos: [7, 0, 4], 
      state: 1
    }, 
    {
      pos: [8, 0, 4], 
      state: 1
    }, 
    {
      pos: [9, 0, 4], 
      state: 1
    }, 
    {
      pos: [10, 0, 4], 
      state: 1
    }, 
    {
      pos: [11, 0, 4], 
      state: 1
    }, 
    {
      pos: [12, 0, 4], 
      state: 1
    }, 
    {
      pos: [0, 0, 5], 
      state: 1
    }, 
    {
      pos: [1, 0, 5], 
      state: 1
    }, 
    {
      pos: [2, 0, 5], 
      state: 1
    }, 
    {
      pos: [3, 0, 5], 
      state: 1
    }, 
    {
      pos: [4, 0, 5], 
      state: 1
    }, 
    {
      pos: [5, 0, 5], 
      state: 1
    }, 
    {
      pos: [6, 0, 5], 
      state: 1
    }, 
    {
      pos: [7, 0, 5], 
      state: 1
    }, 
    {
      pos: [8, 0, 5], 
      state: 1
    }, 
    {
      pos: [9, 0, 5], 
      state: 1
    }, 
    {
      pos: [10, 0, 5], 
      state: 1
    }, 
    {
      pos: [11, 0, 5], 
      state: 1
    }, 
    {
      pos: [12, 0, 5], 
      state: 1
    }, 
    {
      pos: [0, 0, 6], 
      state: 1
    }, 
    {
      pos: [1, 0, 6], 
      state: 1
    }, 
    {
      pos: [2, 0, 6], 
      state: 1
    }, 
    {
      pos: [3, 0, 6], 
      state: 1
    }, 
    {
      pos: [4, 0, 6], 
      state: 1
    }, 
    {
      pos: [5, 0, 6], 
      state: 1
    }, 
    {
      pos: [6, 0, 6], 
      state: 1
    }, 
    {
      pos: [7, 0, 6], 
      state: 1
    }, 
    {
      pos: [8, 0, 6], 
      state: 1
    }, 
    {
      pos: [9, 0, 6], 
      state: 1
    }, 
    {
      pos: [10, 0, 6], 
      state: 1
    }, 
    {
      pos: [11, 0, 6], 
      state: 1
    }, 
    {
      pos: [12, 0, 6], 
      state: 1
    }, 
    {
      pos: [0, 0, 7], 
      state: 1
    }, 
    {
      pos: [1, 0, 7], 
      state: 1
    }, 
    {
      pos: [2, 0, 7], 
      state: 1
    }, 
    {
      pos: [3, 0, 7], 
      state: 1
    }, 
    {
      pos: [4, 0, 7], 
      state: 1
    }, 
    {
      pos: [5, 0, 7], 
      state: 1
    }, 
    {
      pos: [6, 0, 7], 
      state: 1
    }, 
    {
      pos: [7, 0, 7], 
      state: 1
    }, 
    {
      pos: [8, 0, 7], 
      state: 1
    }, 
    {
      pos: [9, 0, 7], 
      state: 1
    }, 
    {
      pos: [10, 0, 7], 
      state: 1
    }, 
    {
      pos: [11, 0, 7], 
      state: 1
    }, 
    {
      pos: [12, 0, 7], 
      state: 1
    }, 
    {
      pos: [0, 0, 8], 
      state: 1
    }, 
    {
      pos: [1, 0, 8], 
      state: 1
    }, 
    {
      pos: [2, 0, 8], 
      state: 1
    }, 
    {
      pos: [3, 0, 8], 
      state: 1
    }, 
    {
      pos: [4, 0, 8], 
      state: 1
    }, 
    {
      pos: [5, 0, 8], 
      state: 1
    }, 
    {
      pos: [6, 0, 8], 
      state: 1
    }, 
    {
      pos: [7, 0, 8], 
      state: 1
    }, 
    {
      pos: [8, 0, 8], 
      state: 1
    }, 
    {
      pos: [9, 0, 8], 
      state: 1
    }, 
    {
      pos: [10, 0, 8], 
      state: 1
    }, 
    {
      pos: [11, 0, 8], 
      state: 1
    }, 
    {
      pos: [12, 0, 8], 
      state: 1
    }, 
    {
      pos: [0, 0, 9], 
      state: 1
    }, 
    {
      pos: [1, 0, 9], 
      state: 1
    }, 
    {
      pos: [2, 0, 9], 
      state: 1
    }, 
    {
      pos: [3, 0, 9], 
      state: 1
    }, 
    {
      pos: [4, 0, 9], 
      state: 1
    }, 
    {
      pos: [5, 0, 9], 
      state: 1
    }, 
    {
      pos: [6, 0, 9], 
      state: 1
    }, 
    {
      pos: [7, 0, 9], 
      state: 1
    }, 
    {
      pos: [8, 0, 9], 
      state: 1
    }, 
    {
      pos: [9, 0, 9], 
      state: 1
    }, 
    {
      pos: [10, 0, 9], 
      state: 1
    }, 
    {
      pos: [11, 0, 9], 
      state: 1
    }, 
    {
      pos: [12, 0, 9], 
      state: 1
    }, 
    {
      pos: [0, 0, 10], 
      state: 1
    }, 
    {
      pos: [1, 0, 10], 
      state: 1
    }, 
    {
      pos: [2, 0, 10], 
      state: 1
    }, 
    {
      pos: [3, 0, 10], 
      state: 1
    }, 
    {
      pos: [4, 0, 10], 
      state: 1
    }, 
    {
      pos: [5, 0, 10], 
      state: 1
    }, 
    {
      pos: [6, 0, 10], 
      state: 1
    }, 
    {
      pos: [7, 0, 10], 
      state: 1
    }, 
    {
      pos: [8, 0, 10], 
      state: 1
    }, 
    {
      pos: [9, 0, 10], 
      state: 1
    }, 
    {
      pos: [10, 0, 10], 
      state: 1
    }, 
    {
      pos: [11, 0, 10], 
      state: 1
    }, 
    {
      pos: [12, 0, 10], 
      state: 1
    }, 
    {
      pos: [0, 0, 11], 
      state: 1
    }, 
    {
      pos: [1, 0, 11], 
      state: 1
    }, 
    {
      pos: [2, 0, 11], 
      state: 1
    }, 
    {
      pos: [3, 0, 11], 
      state: 1
    }, 
    {
      pos: [4, 0, 11], 
      state: 1
    }, 
    {
      pos: [5, 0, 11], 
      state: 1
    }, 
    {
      pos: [7, 0, 11], 
      state: 1
    }, 
    {
      pos: [8, 0, 11], 
      state: 1
    }, 
    {
      pos: [9, 0, 11], 
      state: 1
    }, 
    {
      pos: [10, 0, 11], 
      state: 1
    }, 
    {
      pos: [11, 0, 11], 
      state: 1
    }, 
    {
      pos: [12, 0, 11], 
      state: 1
    }, 
    {
      pos: [0, 0, 12], 
      state: 1
    }, 
    {
      pos: [1, 0, 12], 
      state: 1
    }, 
    {
      pos: [2, 0, 12], 
      state: 1
    }, 
    {
      pos: [3, 0, 12], 
      state: 1
    }, 
    {
      pos: [4, 0, 12], 
      state: 1
    }, 
    {
      pos: [5, 0, 12], 
      state: 1
    }, 
    {
      pos: [7, 0, 12], 
      state: 1
    }, 
    {
      pos: [8, 0, 12], 
      state: 1
    }, 
    {
      pos: [9, 0, 12], 
      state: 1
    }, 
    {
      pos: [10, 0, 12], 
      state: 1
    }, 
    {
      pos: [11, 0, 12], 
      state: 1
    }, 
    {
      pos: [12, 0, 12], 
      state: 1
    }, 
    {
      pos: [0, 0, 13], 
      state: 1
    }, 
    {
      pos: [1, 0, 13], 
      state: 1
    }, 
    {
      pos: [2, 0, 13], 
      state: 1
    }, 
    {
      pos: [3, 0, 13], 
      state: 1
    }, 
    {
      pos: [4, 0, 13], 
      state: 1
    }, 
    {
      pos: [5, 0, 13], 
      state: 1
    }, 
    {
      pos: [7, 0, 13], 
      state: 1
    }, 
    {
      pos: [8, 0, 13], 
      state: 1
    }, 
    {
      pos: [9, 0, 13], 
      state: 1
    }, 
    {
      pos: [10, 0, 13], 
      state: 1
    }, 
    {
      pos: [11, 0, 13], 
      state: 1
    }, 
    {
      pos: [12, 0, 13], 
      state: 1
    }, 
    {
      pos: [0, 0, 14], 
      state: 1
    }, 
    {
      pos: [1, 0, 14], 
      state: 1
    }, 
    {
      pos: [2, 0, 14], 
      state: 1
    }, 
    {
      pos: [3, 0, 14], 
      state: 1
    }, 
    {
      pos: [4, 0, 14], 
      state: 1
    }, 
    {
      pos: [5, 0, 14], 
      state: 1
    }, 
    {
      pos: [7, 0, 14], 
      state: 1
    }, 
    {
      pos: [8, 0, 14], 
      state: 1
    }, 
    {
      pos: [9, 0, 14], 
      state: 1
    }, 
    {
      pos: [10, 0, 14], 
      state: 1
    }, 
    {
      pos: [11, 0, 14], 
      state: 1
    }, 
    {
      pos: [12, 0, 14], 
      state: 1
    }, 
    {
      pos: [0, 0, 15], 
      state: 1
    }, 
    {
      pos: [1, 0, 15], 
      state: 1
    }, 
    {
      pos: [2, 0, 15], 
      state: 1
    }, 
    {
      pos: [3, 0, 15], 
      state: 1
    }, 
    {
      pos: [4, 0, 15], 
      state: 1
    }, 
    {
      pos: [5, 0, 15], 
      state: 1
    }, 
    {
      pos: [7, 0, 15], 
      state: 1
    }, 
    {
      pos: [8, 0, 15], 
      state: 1
    }, 
    {
      pos: [9, 0, 15], 
      state: 1
    }, 
    {
      pos: [10, 0, 15], 
      state: 1
    }, 
    {
      pos: [11, 0, 15], 
      state: 1
    }, 
    {
      pos: [12, 0, 15], 
      state: 1
    }, 
    {
      pos: [0, 0, 16], 
      state: 1
    }, 
    {
      pos: [1, 0, 16], 
      state: 1
    }, 
    {
      pos: [2, 0, 16], 
      state: 1
    }, 
    {
      pos: [3, 0, 16], 
      state: 1
    }, 
    {
      pos: [4, 0, 16], 
      state: 1
    }, 
    {
      pos: [5, 0, 16], 
      state: 1
    }, 
    {
      pos: [7, 0, 16], 
      state: 1
    }, 
    {
      pos: [8, 0, 16], 
      state: 1
    }, 
    {
      pos: [9, 0, 16], 
      state: 1
    }, 
    {
      pos: [10, 0, 16], 
      state: 1
    }, 
    {
      pos: [11, 0, 16], 
      state: 1
    }, 
    {
      pos: [12, 0, 16], 
      state: 1
    }, 
    {
      pos: [0, 0, 17], 
      state: 1
    }, 
    {
      pos: [1, 0, 17], 
      state: 1
    }, 
    {
      pos: [2, 0, 17], 
      state: 1
    }, 
    {
      pos: [3, 0, 17], 
      state: 1
    }, 
    {
      pos: [4, 0, 17], 
      state: 1
    }, 
    {
      pos: [5, 0, 17], 
      state: 1
    }, 
    {
      pos: [7, 0, 17], 
      state: 1
    }, 
    {
      pos: [8, 0, 17], 
      state: 1
    }, 
    {
      pos: [9, 0, 17], 
      state: 1
    }, 
    {
      pos: [10, 0, 17], 
      state: 1
    }, 
    {
      pos: [11, 0, 17], 
      state: 1
    }, 
    {
      pos: [12, 0, 17], 
      state: 1
    }, 
    {
      pos: [0, 0, 18], 
      state: 1
    }, 
    {
      pos: [1, 0, 18], 
      state: 1
    }, 
    {
      pos: [2, 0, 18], 
      state: 1
    }, 
    {
      pos: [3, 0, 18], 
      state: 1
    }, 
    {
      pos: [4, 0, 18], 
      state: 1
    }, 
    {
      pos: [5, 0, 18], 
      state: 1
    }, 
    {
      pos: [7, 0, 18], 
      state: 1
    }, 
    {
      pos: [8, 0, 18], 
      state: 1
    }, 
    {
      pos: [9, 0, 18], 
      state: 1
    }, 
    {
      pos: [10, 0, 18], 
      state: 1
    }, 
    {
      pos: [11, 0, 18], 
      state: 1
    }, 
    {
      pos: [12, 0, 18], 
      state: 1
    }, 
    {
      pos: [0, 0, 19], 
      state: 1
    }, 
    {
      pos: [1, 0, 19], 
      state: 1
    }, 
    {
      pos: [2, 0, 19], 
      state: 1
    }, 
    {
      pos: [3, 0, 19], 
      state: 1
    }, 
    {
      pos: [4, 0, 19], 
      state: 1
    }, 
    {
      pos: [5, 0, 19], 
      state: 1
    }, 
    {
      pos: [7, 0, 19], 
      state: 1
    }, 
    {
      pos: [8, 0, 19], 
      state: 1
    }, 
    {
      pos: [9, 0, 19], 
      state: 1
    }, 
    {
      pos: [10, 0, 19], 
      state: 1
    }, 
    {
      pos: [11, 0, 19], 
      state: 1
    }, 
    {
      pos: [12, 0, 19], 
      state: 1
    }, 
    {
      pos: [0, 0, 20], 
      state: 1
    }, 
    {
      pos: [1, 0, 20], 
      state: 1
    }, 
    {
      pos: [2, 0, 20], 
      state: 1
    }, 
    {
      pos: [3, 0, 20], 
      state: 1
    }, 
    {
      pos: [4, 0, 20], 
      state: 1
    }, 
    {
      pos: [5, 0, 20], 
      state: 1
    }, 
    {
      pos: [7, 0, 20], 
      state: 1
    }, 
    {
      pos: [8, 0, 20], 
      state: 1
    }, 
    {
      pos: [9, 0, 20], 
      state: 1
    }, 
    {
      pos: [10, 0, 20], 
      state: 1
    }, 
    {
      pos: [11, 0, 20], 
      state: 1
    }, 
    {
      pos: [12, 0, 20], 
      state: 1
    }, 
    {
      pos: [0, 0, 21], 
      state: 1
    }, 
    {
      pos: [1, 0, 21], 
      state: 1
    }, 
    {
      pos: [2, 0, 21], 
      state: 1
    }, 
    {
      pos: [3, 0, 21], 
      state: 1
    }, 
    {
      pos: [4, 0, 21], 
      state: 1
    }, 
    {
      pos: [5, 0, 21], 
      state: 1
    }, 
    {
      pos: [7, 0, 21], 
      state: 1
    }, 
    {
      pos: [8, 0, 21], 
      state: 1
    }, 
    {
      pos: [9, 0, 21], 
      state: 1
    }, 
    {
      pos: [10, 0, 21], 
      state: 1
    }, 
    {
      pos: [11, 0, 21], 
      state: 1
    }, 
    {
      pos: [12, 0, 21], 
      state: 1
    }, 
    {
      pos: [0, 0, 22], 
      state: 1
    }, 
    {
      pos: [1, 0, 22], 
      state: 1
    }, 
    {
      pos: [2, 0, 22], 
      state: 1
    }, 
    {
      pos: [3, 0, 22], 
      state: 1
    }, 
    {
      pos: [4, 0, 22], 
      state: 1
    }, 
    {
      pos: [5, 0, 22], 
      state: 1
    }, 
    {
      pos: [7, 0, 22], 
      state: 1
    }, 
    {
      pos: [8, 0, 22], 
      state: 1
    }, 
    {
      pos: [9, 0, 22], 
      state: 1
    }, 
    {
      pos: [10, 0, 22], 
      state: 1
    }, 
    {
      pos: [11, 0, 22], 
      state: 1
    }, 
    {
      pos: [12, 0, 22], 
      state: 1
    }, 
    {
      pos: [0, 0, 23], 
      state: 1
    }, 
    {
      pos: [1, 0, 23], 
      state: 1
    }, 
    {
      pos: [2, 0, 23], 
      state: 1
    }, 
    {
      pos: [3, 0, 23], 
      state: 1
    }, 
    {
      pos: [4, 0, 23], 
      state: 1
    }, 
    {
      pos: [5, 0, 23], 
      state: 1
    }, 
    {
      pos: [7, 0, 23], 
      state: 1
    }, 
    {
      pos: [8, 0, 23], 
      state: 1
    }, 
    {
      pos: [9, 0, 23], 
      state: 1
    }, 
    {
      pos: [10, 0, 23], 
      state: 1
    }, 
    {
      pos: [11, 0, 23], 
      state: 1
    }, 
    {
      pos: [12, 0, 23], 
      state: 1
    }, 
    {
      pos: [0, 0, 24], 
      state: 1
    }, 
    {
      pos: [1, 0, 24], 
      state: 1
    }, 
    {
      pos: [2, 0, 24], 
      state: 1
    }, 
    {
      pos: [3, 0, 24], 
      state: 1
    }, 
    {
      pos: [4, 0, 24], 
      state: 1
    }, 
    {
      pos: [5, 0, 24], 
      state: 1
    }, 
    {
      pos: [6, 0, 24], 
      state: 1
    }, 
    {
      pos: [7, 0, 24], 
      state: 1
    }, 
    {
      pos: [8, 0, 24], 
      state: 1
    }, 
    {
      pos: [9, 0, 24], 
      state: 1
    }, 
    {
      pos: [10, 0, 24], 
      state: 1
    }, 
    {
      pos: [11, 0, 24], 
      state: 1
    }, 
    {
      pos: [12, 0, 24], 
      state: 1
    }, 
    {
      pos: [0, 0, 25], 
      state: 1
    }, 
    {
      pos: [1, 0, 25], 
      state: 1
    }, 
    {
      pos: [2, 0, 25], 
      state: 1
    }, 
    {
      pos: [3, 0, 25], 
      state: 1
    }, 
    {
      pos: [4, 0, 25], 
      state: 1
    }, 
    {
      pos: [5, 0, 25], 
      state: 1
    }, 
    {
      pos: [6, 0, 25], 
      state: 1
    }, 
    {
      pos: [7, 0, 25], 
      state: 1
    }, 
    {
      pos: [8, 0, 25], 
      state: 1
    }, 
    {
      pos: [9, 0, 25], 
      state: 1
    }, 
    {
      pos: [10, 0, 25], 
      state: 1
    }, 
    {
      pos: [11, 0, 25], 
      state: 1
    }, 
    {
      pos: [12, 0, 25], 
      state: 1
    }, 
    {
      pos: [0, 0, 26], 
      state: 1
    }, 
    {
      pos: [1, 0, 26], 
      state: 1
    }, 
    {
      pos: [2, 0, 26], 
      state: 1
    }, 
    {
      pos: [3, 0, 26], 
      state: 1
    }, 
    {
      pos: [4, 0, 26], 
      state: 1
    }, 
    {
      pos: [5, 0, 26], 
      state: 1
    }, 
    {
      pos: [6, 0, 26], 
      state: 1
    }, 
    {
      pos: [7, 0, 26], 
      state: 1
    }, 
    {
      pos: [8, 0, 26], 
      state: 1
    }, 
    {
      pos: [9, 0, 26], 
      state: 1
    }, 
    {
      pos: [10, 0, 26], 
      state: 1
    }, 
    {
      pos: [11, 0, 26], 
      state: 1
    }, 
    {
      pos: [12, 0, 26], 
      state: 1
    }, 
    {
      pos: [0, 0, 27], 
      state: 1
    }, 
    {
      pos: [1, 0, 27], 
      state: 1
    }, 
    {
      pos: [2, 0, 27], 
      state: 1
    }, 
    {
      pos: [3, 0, 27], 
      state: 1
    }, 
    {
      pos: [4, 0, 27], 
      state: 1
    }, 
    {
      pos: [5, 0, 27], 
      state: 1
    }, 
    {
      pos: [6, 0, 27], 
      state: 1
    }, 
    {
      pos: [7, 0, 27], 
      state: 1
    }, 
    {
      pos: [8, 0, 27], 
      state: 1
    }, 
    {
      pos: [9, 0, 27], 
      state: 1
    }, 
    {
      pos: [10, 0, 27], 
      state: 1
    }, 
    {
      pos: [11, 0, 27], 
      state: 1
    }, 
    {
      pos: [12, 0, 27], 
      state: 1
    }, 
    {
      pos: [0, 0, 28], 
      state: 1
    }, 
    {
      pos: [1, 0, 28], 
      state: 1
    }, 
    {
      pos: [2, 0, 28], 
      state: 1
    }, 
    {
      pos: [3, 0, 28], 
      state: 1
    }, 
    {
      pos: [4, 0, 28], 
      state: 1
    }, 
    {
      pos: [5, 0, 28], 
      state: 1
    }, 
    {
      pos: [6, 0, 28], 
      state: 1
    }, 
    {
      pos: [7, 0, 28], 
      state: 1
    }, 
    {
      pos: [8, 0, 28], 
      state: 1
    }, 
    {
      pos: [9, 0, 28], 
      state: 1
    }, 
    {
      pos: [10, 0, 28], 
      state: 1
    }, 
    {
      pos: [11, 0, 28], 
      state: 1
    }, 
    {
      pos: [12, 0, 28], 
      state: 1
    }, 
    {
      pos: [6, 1, 8], 
      state: 0
    }, 
    {
      pos: [6, 1, 9], 
      state: 0
    }, 
    {
      pos: [6, 1, 10], 
      state: 0
    }, 
    {
      pos: [6, 1, 11], 
      state: 0
    }, 
    {
      pos: [5, 1, 12], 
      state: 2
    }, 
    {
      pos: [6, 1, 12], 
      state: 2
    }, 
    {
      pos: [7, 1, 12], 
      state: 2
    }, 
    {
      pos: [5, 1, 13], 
      state: 2
    }, 
    {
      pos: [6, 1, 13], 
      state: 2
    }, 
    {
      pos: [7, 1, 13], 
      state: 2
    }, 
    {
      pos: [5, 1, 14], 
      state: 2
    }, 
    {
      pos: [6, 1, 14], 
      state: 2
    }, 
    {
      pos: [7, 1, 14], 
      state: 2
    }, 
    {
      pos: [5, 1, 15], 
      state: 2
    }, 
    {
      pos: [6, 1, 15], 
      state: 2
    }, 
    {
      pos: [7, 1, 15], 
      state: 2
    }, 
    {
      pos: [5, 1, 16], 
      state: 2
    }, 
    {
      pos: [6, 1, 16], 
      state: 2
    }, 
    {
      pos: [7, 1, 16], 
      state: 2
    }, 
    {
      pos: [5, 1, 17], 
      state: 2
    }, 
    {
      pos: [6, 1, 17], 
      state: 2
    }, 
    {
      pos: [7, 1, 17], 
      state: 2
    }, 
    {
      pos: [5, 1, 18], 
      state: 2
    }, 
    {
      pos: [6, 1, 18], 
      state: 2
    }, 
    {
      pos: [7, 1, 18], 
      state: 2
    }, 
    {
      pos: [5, 1, 19], 
      state: 2
    }, 
    {
      pos: [6, 1, 19], 
      state: 2
    }, 
    {
      pos: [7, 1, 19], 
      state: 2
    }, 
    {
      pos: [5, 1, 20], 
      state: 2
    }, 
    {
      pos: [6, 1, 20], 
      state: 2
    }, 
    {
      pos: [7, 1, 20], 
      state: 2
    }, 
    {
      pos: [5, 1, 21], 
      state: 2
    }, 
    {
      pos: [6, 1, 21], 
      state: 2
    }, 
    {
      pos: [7, 1, 21], 
      state: 2
    }, 
    {
      pos: [5, 1, 22], 
      state: 2
    }, 
    {
      pos: [6, 1, 22], 
      state: 2
    }, 
    {
      pos: [7, 1, 22], 
      state: 2
    }, 
    {
      pos: [5, 1, 23], 
      state: 2
    }, 
    {
      pos: [6, 1, 23], 
      state: 0
    }, 
    {
      pos: [7, 1, 23], 
      state: 2
    }, 
    {
      pos: [5, 1, 24], 
      state: 2
    }, 
    {
      pos: [6, 1, 24], 
      state: 0
    }, 
    {
      pos: [7, 1, 24], 
      state: 2
    }, 
    {
      pos: [0, 1, 0], 
      state: 1
    }, 
    {
      pos: [1, 1, 0], 
      state: 1
    }, 
    {
      pos: [2, 1, 0], 
      state: 1
    }, 
    {
      pos: [3, 1, 0], 
      state: 1
    }, 
    {
      pos: [4, 1, 0], 
      state: 1
    }, 
    {
      pos: [5, 1, 0], 
      state: 1
    }, 
    {
      pos: [6, 1, 0], 
      state: 1
    }, 
    {
      pos: [7, 1, 0], 
      state: 1
    }, 
    {
      pos: [8, 1, 0], 
      state: 1
    }, 
    {
      pos: [9, 1, 0], 
      state: 1
    }, 
    {
      pos: [10, 1, 0], 
      state: 1
    }, 
    {
      pos: [11, 1, 0], 
      state: 1
    }, 
    {
      pos: [12, 1, 0], 
      state: 1
    }, 
    {
      pos: [0, 1, 1], 
      state: 1
    }, 
    {
      pos: [1, 1, 1], 
      state: 1
    }, 
    {
      pos: [2, 1, 1], 
      state: 1
    }, 
    {
      pos: [3, 1, 1], 
      state: 1
    }, 
    {
      pos: [4, 1, 1], 
      state: 1
    }, 
    {
      pos: [5, 1, 1], 
      state: 1
    }, 
    {
      pos: [6, 1, 1], 
      state: 1
    }, 
    {
      pos: [7, 1, 1], 
      state: 1
    }, 
    {
      pos: [8, 1, 1], 
      state: 1
    }, 
    {
      pos: [9, 1, 1], 
      state: 1
    }, 
    {
      pos: [10, 1, 1], 
      state: 1
    }, 
    {
      pos: [11, 1, 1], 
      state: 1
    }, 
    {
      pos: [12, 1, 1], 
      state: 1
    }, 
    {
      pos: [0, 1, 2], 
      state: 1
    }, 
    {
      pos: [1, 1, 2], 
      state: 1
    }, 
    {
      pos: [2, 1, 2], 
      state: 1
    }, 
    {
      pos: [3, 1, 2], 
      state: 1
    }, 
    {
      pos: [4, 1, 2], 
      state: 1
    }, 
    {
      pos: [5, 1, 2], 
      state: 1
    }, 
    {
      pos: [6, 1, 2], 
      state: 1
    }, 
    {
      pos: [7, 1, 2], 
      state: 1
    }, 
    {
      pos: [8, 1, 2], 
      state: 1
    }, 
    {
      pos: [9, 1, 2], 
      state: 1
    }, 
    {
      pos: [10, 1, 2], 
      state: 1
    }, 
    {
      pos: [11, 1, 2], 
      state: 1
    }, 
    {
      pos: [12, 1, 2], 
      state: 1
    }, 
    {
      pos: [0, 1, 3], 
      state: 1
    }, 
    {
      pos: [1, 1, 3], 
      state: 1
    }, 
    {
      pos: [2, 1, 3], 
      state: 1
    }, 
    {
      pos: [3, 1, 3], 
      state: 1
    }, 
    {
      pos: [4, 1, 3], 
      state: 1
    }, 
    {
      pos: [5, 1, 3], 
      state: 1
    }, 
    {
      pos: [6, 1, 3], 
      state: 1
    }, 
    {
      pos: [7, 1, 3], 
      state: 1
    }, 
    {
      pos: [8, 1, 3], 
      state: 1
    }, 
    {
      pos: [9, 1, 3], 
      state: 1
    }, 
    {
      pos: [10, 1, 3], 
      state: 1
    }, 
    {
      pos: [11, 1, 3], 
      state: 1
    }, 
    {
      pos: [12, 1, 3], 
      state: 1
    }, 
    {
      pos: [0, 1, 4], 
      state: 1
    }, 
    {
      pos: [1, 1, 4], 
      state: 1
    }, 
    {
      pos: [2, 1, 4], 
      state: 1
    }, 
    {
      pos: [3, 1, 4], 
      state: 1
    }, 
    {
      pos: [4, 1, 4], 
      state: 1
    }, 
    {
      pos: [5, 1, 4], 
      state: 1
    }, 
    {
      pos: [6, 1, 4], 
      state: 1
    }, 
    {
      pos: [7, 1, 4], 
      state: 1
    }, 
    {
      pos: [8, 1, 4], 
      state: 1
    }, 
    {
      pos: [9, 1, 4], 
      state: 1
    }, 
    {
      pos: [10, 1, 4], 
      state: 1
    }, 
    {
      pos: [11, 1, 4], 
      state: 1
    }, 
    {
      pos: [12, 1, 4], 
      state: 1
    }, 
    {
      pos: [0, 1, 5], 
      state: 1
    }, 
    {
      pos: [1, 1, 5], 
      state: 1
    }, 
    {
      pos: [2, 1, 5], 
      state: 1
    }, 
    {
      pos: [3, 1, 5], 
      state: 1
    }, 
    {
      pos: [4, 1, 5], 
      state: 1
    }, 
    {
      pos: [5, 1, 5], 
      state: 1
    }, 
    {
      pos: [6, 1, 5], 
      state: 1
    }, 
    {
      pos: [7, 1, 5], 
      state: 1
    }, 
    {
      pos: [8, 1, 5], 
      state: 1
    }, 
    {
      pos: [9, 1, 5], 
      state: 1
    }, 
    {
      pos: [10, 1, 5], 
      state: 1
    }, 
    {
      pos: [11, 1, 5], 
      state: 1
    }, 
    {
      pos: [12, 1, 5], 
      state: 1
    }, 
    {
      pos: [0, 1, 6], 
      state: 1
    }, 
    {
      pos: [1, 1, 6], 
      state: 1
    }, 
    {
      pos: [2, 1, 6], 
      state: 1
    }, 
    {
      pos: [3, 1, 6], 
      state: 1
    }, 
    {
      pos: [4, 1, 6], 
      state: 1
    }, 
    {
      pos: [5, 1, 6], 
      state: 1
    }, 
    {
      pos: [6, 1, 6], 
      state: 1
    }, 
    {
      pos: [7, 1, 6], 
      state: 1
    }, 
    {
      pos: [8, 1, 6], 
      state: 1
    }, 
    {
      pos: [9, 1, 6], 
      state: 1
    }, 
    {
      pos: [10, 1, 6], 
      state: 1
    }, 
    {
      pos: [11, 1, 6], 
      state: 1
    }, 
    {
      pos: [12, 1, 6], 
      state: 1
    }, 
    {
      pos: [0, 1, 7], 
      state: 1
    }, 
    {
      pos: [1, 1, 7], 
      state: 1
    }, 
    {
      pos: [2, 1, 7], 
      state: 1
    }, 
    {
      pos: [3, 1, 7], 
      state: 1
    }, 
    {
      pos: [4, 1, 7], 
      state: 1
    }, 
    {
      pos: [5, 1, 7], 
      state: 1
    }, 
    {
      pos: [6, 1, 7], 
      state: 1
    }, 
    {
      pos: [7, 1, 7], 
      state: 1
    }, 
    {
      pos: [8, 1, 7], 
      state: 1
    }, 
    {
      pos: [9, 1, 7], 
      state: 1
    }, 
    {
      pos: [10, 1, 7], 
      state: 1
    }, 
    {
      pos: [11, 1, 7], 
      state: 1
    }, 
    {
      pos: [12, 1, 7], 
      state: 1
    }, 
    {
      pos: [0, 1, 8], 
      state: 1
    }, 
    {
      pos: [1, 1, 8], 
      state: 1
    }, 
    {
      pos: [2, 1, 8], 
      state: 1
    }, 
    {
      pos: [3, 1, 8], 
      state: 1
    }, 
    {
      pos: [4, 1, 8], 
      state: 1
    }, 
    {
      pos: [5, 1, 8], 
      state: 1
    }, 
    {
      pos: [7, 1, 8], 
      state: 1
    }, 
    {
      pos: [8, 1, 8], 
      state: 1
    }, 
    {
      pos: [9, 1, 8], 
      state: 1
    }, 
    {
      pos: [10, 1, 8], 
      state: 1
    }, 
    {
      pos: [11, 1, 8], 
      state: 1
    }, 
    {
      pos: [12, 1, 8], 
      state: 1
    }, 
    {
      pos: [0, 1, 9], 
      state: 1
    }, 
    {
      pos: [1, 1, 9], 
      state: 1
    }, 
    {
      pos: [2, 1, 9], 
      state: 1
    }, 
    {
      pos: [3, 1, 9], 
      state: 1
    }, 
    {
      pos: [4, 1, 9], 
      state: 1
    }, 
    {
      pos: [5, 1, 9], 
      state: 1
    }, 
    {
      pos: [7, 1, 9], 
      state: 1
    }, 
    {
      pos: [8, 1, 9], 
      state: 1
    }, 
    {
      pos: [9, 1, 9], 
      state: 1
    }, 
    {
      pos: [10, 1, 9], 
      state: 1
    }, 
    {
      pos: [11, 1, 9], 
      state: 1
    }, 
    {
      pos: [12, 1, 9], 
      state: 1
    }, 
    {
      pos: [0, 1, 10], 
      state: 1
    }, 
    {
      pos: [1, 1, 10], 
      state: 1
    }, 
    {
      pos: [2, 1, 10], 
      state: 1
    }, 
    {
      pos: [3, 1, 10], 
      state: 1
    }, 
    {
      pos: [4, 1, 10], 
      state: 1
    }, 
    {
      pos: [5, 1, 10], 
      state: 1
    }, 
    {
      pos: [7, 1, 10], 
      state: 1
    }, 
    {
      pos: [8, 1, 10], 
      state: 1
    }, 
    {
      pos: [9, 1, 10], 
      state: 1
    }, 
    {
      pos: [10, 1, 10], 
      state: 1
    }, 
    {
      pos: [11, 1, 10], 
      state: 1
    }, 
    {
      pos: [12, 1, 10], 
      state: 1
    }, 
    {
      pos: [0, 1, 11], 
      state: 1
    }, 
    {
      pos: [1, 1, 11], 
      state: 1
    }, 
    {
      pos: [2, 1, 11], 
      state: 1
    }, 
    {
      pos: [3, 1, 11], 
      state: 1
    }, 
    {
      pos: [4, 1, 11], 
      state: 1
    }, 
    {
      pos: [5, 1, 11], 
      state: 1
    }, 
    {
      pos: [7, 1, 11], 
      state: 1
    }, 
    {
      pos: [8, 1, 11], 
      state: 1
    }, 
    {
      pos: [9, 1, 11], 
      state: 1
    }, 
    {
      pos: [10, 1, 11], 
      state: 1
    }, 
    {
      pos: [11, 1, 11], 
      state: 1
    }, 
    {
      pos: [12, 1, 11], 
      state: 1
    }, 
    {
      pos: [0, 1, 12], 
      state: 1
    }, 
    {
      pos: [1, 1, 12], 
      state: 1
    }, 
    {
      pos: [2, 1, 12], 
      state: 1
    }, 
    {
      pos: [3, 1, 12], 
      state: 1
    }, 
    {
      pos: [4, 1, 12], 
      state: 1
    }, 
    {
      pos: [8, 1, 12], 
      state: 1
    }, 
    {
      pos: [9, 1, 12], 
      state: 1
    }, 
    {
      pos: [10, 1, 12], 
      state: 1
    }, 
    {
      pos: [11, 1, 12], 
      state: 1
    }, 
    {
      pos: [12, 1, 12], 
      state: 1
    }, 
    {
      pos: [0, 1, 13], 
      state: 1
    }, 
    {
      pos: [1, 1, 13], 
      state: 1
    }, 
    {
      pos: [2, 1, 13], 
      state: 1
    }, 
    {
      pos: [3, 1, 13], 
      state: 1
    }, 
    {
      pos: [4, 1, 13], 
      state: 3
    }, 
    {
      pos: [8, 1, 13], 
      state: 4
    }, 
    {
      pos: [9, 1, 13], 
      state: 1
    }, 
    {
      pos: [10, 1, 13], 
      state: 1
    }, 
    {
      pos: [11, 1, 13], 
      state: 1
    }, 
    {
      pos: [12, 1, 13], 
      state: 1
    }, 
    {
      pos: [0, 1, 14], 
      state: 1
    }, 
    {
      pos: [1, 1, 14], 
      state: 1
    }, 
    {
      pos: [2, 1, 14], 
      state: 1
    }, 
    {
      pos: [3, 1, 14], 
      state: 1
    }, 
    {
      pos: [4, 1, 14], 
      state: 1
    }, 
    {
      pos: [8, 1, 14], 
      state: 1
    }, 
    {
      pos: [9, 1, 14], 
      state: 1
    }, 
    {
      pos: [10, 1, 14], 
      state: 1
    }, 
    {
      pos: [11, 1, 14], 
      state: 1
    }, 
    {
      pos: [12, 1, 14], 
      state: 1
    }, 
    {
      pos: [0, 1, 15], 
      state: 1
    }, 
    {
      pos: [1, 1, 15], 
      state: 1
    }, 
    {
      pos: [2, 1, 15], 
      state: 1
    }, 
    {
      pos: [3, 1, 15], 
      state: 1
    }, 
    {
      pos: [4, 1, 15], 
      state: 1
    }, 
    {
      pos: [8, 1, 15], 
      state: 1
    }, 
    {
      pos: [9, 1, 15], 
      state: 1
    }, 
    {
      pos: [10, 1, 15], 
      state: 1
    }, 
    {
      pos: [11, 1, 15], 
      state: 1
    }, 
    {
      pos: [12, 1, 15], 
      state: 1
    }, 
    {
      pos: [0, 1, 16], 
      state: 1
    }, 
    {
      pos: [1, 1, 16], 
      state: 1
    }, 
    {
      pos: [2, 1, 16], 
      state: 1
    }, 
    {
      pos: [3, 1, 16], 
      state: 1
    }, 
    {
      pos: [4, 1, 16], 
      state: 1
    }, 
    {
      pos: [8, 1, 16], 
      state: 1
    }, 
    {
      pos: [9, 1, 16], 
      state: 1
    }, 
    {
      pos: [10, 1, 16], 
      state: 1
    }, 
    {
      pos: [11, 1, 16], 
      state: 1
    }, 
    {
      pos: [12, 1, 16], 
      state: 1
    }, 
    {
      pos: [0, 1, 17], 
      state: 1
    }, 
    {
      pos: [1, 1, 17], 
      state: 1
    }, 
    {
      pos: [2, 1, 17], 
      state: 1
    }, 
    {
      pos: [3, 1, 17], 
      state: 1
    }, 
    {
      pos: [4, 1, 17], 
      state: 3
    }, 
    {
      pos: [8, 1, 17], 
      state: 4
    }, 
    {
      pos: [9, 1, 17], 
      state: 1
    }, 
    {
      pos: [10, 1, 17], 
      state: 1
    }, 
    {
      pos: [11, 1, 17], 
      state: 1
    }, 
    {
      pos: [12, 1, 17], 
      state: 1
    }, 
    {
      pos: [0, 1, 18], 
      state: 1
    }, 
    {
      pos: [1, 1, 18], 
      state: 1
    }, 
    {
      pos: [2, 1, 18], 
      state: 1
    }, 
    {
      pos: [3, 1, 18], 
      state: 1
    }, 
    {
      pos: [4, 1, 18], 
      state: 1
    }, 
    {
      pos: [8, 1, 18], 
      state: 1
    }, 
    {
      pos: [9, 1, 18], 
      state: 1
    }, 
    {
      pos: [10, 1, 18], 
      state: 1
    }, 
    {
      pos: [11, 1, 18], 
      state: 1
    }, 
    {
      pos: [12, 1, 18], 
      state: 1
    }, 
    {
      pos: [0, 1, 19], 
      state: 1
    }, 
    {
      pos: [1, 1, 19], 
      state: 1
    }, 
    {
      pos: [2, 1, 19], 
      state: 1
    }, 
    {
      pos: [3, 1, 19], 
      state: 1
    }, 
    {
      pos: [4, 1, 19], 
      state: 1
    }, 
    {
      pos: [8, 1, 19], 
      state: 1
    }, 
    {
      pos: [9, 1, 19], 
      state: 1
    }, 
    {
      pos: [10, 1, 19], 
      state: 1
    }, 
    {
      pos: [11, 1, 19], 
      state: 1
    }, 
    {
      pos: [12, 1, 19], 
      state: 1
    }, 
    {
      pos: [0, 1, 20], 
      state: 1
    }, 
    {
      pos: [1, 1, 20], 
      state: 1
    }, 
    {
      pos: [2, 1, 20], 
      state: 1
    }, 
    {
      pos: [3, 1, 20], 
      state: 1
    }, 
    {
      pos: [4, 1, 20], 
      state: 1
    }, 
    {
      pos: [8, 1, 20], 
      state: 1
    }, 
    {
      pos: [9, 1, 20], 
      state: 1
    }, 
    {
      pos: [10, 1, 20], 
      state: 1
    }, 
    {
      pos: [11, 1, 20], 
      state: 1
    }, 
    {
      pos: [12, 1, 20], 
      state: 1
    }, 
    {
      pos: [0, 1, 21], 
      state: 1
    }, 
    {
      pos: [1, 1, 21], 
      state: 1
    }, 
    {
      pos: [2, 1, 21], 
      state: 1
    }, 
    {
      pos: [3, 1, 21], 
      state: 1
    }, 
    {
      pos: [4, 1, 21], 
      state: 3
    }, 
    {
      pos: [8, 1, 21], 
      state: 4
    }, 
    {
      pos: [9, 1, 21], 
      state: 1
    }, 
    {
      pos: [10, 1, 21], 
      state: 1
    }, 
    {
      pos: [11, 1, 21], 
      state: 1
    }, 
    {
      pos: [12, 1, 21], 
      state: 1
    }, 
    {
      pos: [0, 1, 22], 
      state: 1
    }, 
    {
      pos: [1, 1, 22], 
      state: 1
    }, 
    {
      pos: [2, 1, 22], 
      state: 1
    }, 
    {
      pos: [3, 1, 22], 
      state: 1
    }, 
    {
      pos: [4, 1, 22], 
      state: 1
    }, 
    {
      pos: [8, 1, 22], 
      state: 1
    }, 
    {
      pos: [9, 1, 22], 
      state: 1
    }, 
    {
      pos: [10, 1, 22], 
      state: 1
    }, 
    {
      pos: [11, 1, 22], 
      state: 1
    }, 
    {
      pos: [12, 1, 22], 
      state: 1
    }, 
    {
      pos: [0, 1, 23], 
      state: 1
    }, 
    {
      pos: [1, 1, 23], 
      state: 1
    }, 
    {
      pos: [2, 1, 23], 
      state: 1
    }, 
    {
      pos: [3, 1, 23], 
      state: 1
    }, 
    {
      pos: [4, 1, 23], 
      state: 1
    }, 
    {
      pos: [8, 1, 23], 
      state: 1
    }, 
    {
      pos: [9, 1, 23], 
      state: 1
    }, 
    {
      pos: [10, 1, 23], 
      state: 1
    }, 
    {
      pos: [11, 1, 23], 
      state: 1
    }, 
    {
      pos: [12, 1, 23], 
      state: 1
    }, 
    {
      pos: [0, 1, 24], 
      state: 1
    }, 
    {
      pos: [1, 1, 24], 
      state: 1
    }, 
    {
      pos: [2, 1, 24], 
      state: 1
    }, 
    {
      pos: [3, 1, 24], 
      state: 1
    }, 
    {
      pos: [4, 1, 24], 
      state: 1
    }, 
    {
      pos: [8, 1, 24], 
      state: 1
    }, 
    {
      pos: [9, 1, 24], 
      state: 1
    }, 
    {
      pos: [10, 1, 24], 
      state: 1
    }, 
    {
      pos: [11, 1, 24], 
      state: 1
    }, 
    {
      pos: [12, 1, 24], 
      state: 1
    }, 
    {
      pos: [0, 1, 25], 
      state: 1
    }, 
    {
      pos: [1, 1, 25], 
      state: 1
    }, 
    {
      pos: [2, 1, 25], 
      state: 1
    }, 
    {
      pos: [3, 1, 25], 
      state: 1
    }, 
    {
      pos: [4, 1, 25], 
      state: 1
    }, 
    {
      pos: [5, 1, 25], 
      state: 1
    }, 
    {
      pos: [6, 1, 25], 
      state: 1
    }, 
    {
      pos: [7, 1, 25], 
      state: 1
    }, 
    {
      pos: [8, 1, 25], 
      state: 1
    }, 
    {
      pos: [9, 1, 25], 
      state: 1
    }, 
    {
      pos: [10, 1, 25], 
      state: 1
    }, 
    {
      pos: [11, 1, 25], 
      state: 1
    }, 
    {
      pos: [12, 1, 25], 
      state: 1
    }, 
    {
      pos: [0, 1, 26], 
      state: 1
    }, 
    {
      pos: [1, 1, 26], 
      state: 1
    }, 
    {
      pos: [2, 1, 26], 
      state: 1
    }, 
    {
      pos: [3, 1, 26], 
      state: 1
    }, 
    {
      pos: [4, 1, 26], 
      state: 1
    }, 
    {
      pos: [5, 1, 26], 
      state: 1
    }, 
    {
      pos: [6, 1, 26], 
      state: 1
    }, 
    {
      pos: [7, 1, 26], 
      state: 1
    }, 
    {
      pos: [8, 1, 26], 
      state: 1
    }, 
    {
      pos: [9, 1, 26], 
      state: 1
    }, 
    {
      pos: [10, 1, 26], 
      state: 1
    }, 
    {
      pos: [11, 1, 26], 
      state: 1
    }, 
    {
      pos: [12, 1, 26], 
      state: 1
    }, 
    {
      pos: [0, 1, 27], 
      state: 1
    }, 
    {
      pos: [1, 1, 27], 
      state: 1
    }, 
    {
      pos: [2, 1, 27], 
      state: 1
    }, 
    {
      pos: [3, 1, 27], 
      state: 1
    }, 
    {
      pos: [4, 1, 27], 
      state: 1
    }, 
    {
      pos: [5, 1, 27], 
      state: 1
    }, 
    {
      pos: [6, 1, 27], 
      state: 1
    }, 
    {
      pos: [7, 1, 27], 
      state: 1
    }, 
    {
      pos: [8, 1, 27], 
      state: 1
    }, 
    {
      pos: [9, 1, 27], 
      state: 1
    }, 
    {
      pos: [10, 1, 27], 
      state: 1
    }, 
    {
      pos: [11, 1, 27], 
      state: 1
    }, 
    {
      pos: [12, 1, 27], 
      state: 1
    }, 
    {
      pos: [0, 1, 28], 
      state: 1
    }, 
    {
      pos: [1, 1, 28], 
      state: 1
    }, 
    {
      pos: [2, 1, 28], 
      state: 1
    }, 
    {
      pos: [3, 1, 28], 
      state: 1
    }, 
    {
      pos: [4, 1, 28], 
      state: 1
    }, 
    {
      pos: [5, 1, 28], 
      state: 1
    }, 
    {
      pos: [6, 1, 28], 
      state: 1
    }, 
    {
      pos: [7, 1, 28], 
      state: 1
    }, 
    {
      pos: [8, 1, 28], 
      state: 1
    }, 
    {
      pos: [9, 1, 28], 
      state: 1
    }, 
    {
      pos: [10, 1, 28], 
      state: 1
    }, 
    {
      pos: [11, 1, 28], 
      state: 1
    }, 
    {
      pos: [12, 1, 28], 
      state: 1
    }, 
    {
      pos: [6, 2, 6], 
      state: 0
    }, 
    {
      pos: [6, 2, 7], 
      state: 0
    }, 
    {
      pos: [5, 2, 8], 
      state: 2
    }, 
    {
      pos: [6, 2, 8], 
      state: 0
    }, 
    {
      pos: [7, 2, 8], 
      state: 2
    }, 
    {
      pos: [5, 2, 9], 
      state: 2
    }, 
    {
      pos: [6, 2, 9], 
      state: 0
    }, 
    {
      pos: [7, 2, 9], 
      state: 2
    }, 
    {
      pos: [4, 2, 10], 
      state: 2
    }, 
    {
      pos: [5, 2, 10], 
      state: 2
    }, 
    {
      pos: [6, 2, 10], 
      state: 0
    }, 
    {
      pos: [7, 2, 10], 
      state: 2
    }, 
    {
      pos: [8, 2, 10], 
      state: 2
    }, 
    {
      pos: [4, 2, 11], 
      state: 2
    }, 
    {
      pos: [5, 2, 11], 
      state: 2
    }, 
    {
      pos: [6, 2, 11], 
      state: 0
    }, 
    {
      pos: [7, 2, 11], 
      state: 2
    }, 
    {
      pos: [8, 2, 11], 
      state: 2
    }, 
    {
      pos: [4, 2, 12], 
      state: 2
    }, 
    {
      pos: [5, 2, 12], 
      state: 5
    }, 
    {
      pos: [6, 2, 12], 
      state: 0
    }, 
    {
      pos: [7, 2, 12], 
      state: 5
    }, 
    {
      pos: [8, 2, 12], 
      state: 2
    }, 
    {
      pos: [4, 2, 13], 
      state: 2
    }, 
    {
      pos: [5, 2, 13], 
      state: 5
    }, 
    {
      pos: [6, 2, 13], 
      state: 0
    }, 
    {
      pos: [7, 2, 13], 
      state: 5
    }, 
    {
      pos: [8, 2, 13], 
      state: 2
    }, 
    {
      pos: [4, 2, 14], 
      state: 2
    }, 
    {
      pos: [5, 2, 14], 
      state: 5
    }, 
    {
      pos: [6, 2, 14], 
      state: 6
    }, 
    {
      pos: [7, 2, 14], 
      state: 5
    }, 
    {
      pos: [8, 2, 14], 
      state: 2
    }, 
    {
      pos: [4, 2, 15], 
      state: 2
    }, 
    {
      pos: [5, 2, 15], 
      state: 5
    }, 
    {
      pos: [6, 2, 15], 
      state: 0
    }, 
    {
      pos: [7, 2, 15], 
      state: 5
    }, 
    {
      pos: [8, 2, 15], 
      state: 2
    }, 
    {
      pos: [4, 2, 16], 
      state: 2
    }, 
    {
      pos: [5, 2, 16], 
      state: 5
    }, 
    {
      pos: [6, 2, 16], 
      state: 0
    }, 
    {
      pos: [7, 2, 16], 
      state: 5
    }, 
    {
      pos: [8, 2, 16], 
      state: 2
    }, 
    {
      pos: [4, 2, 17], 
      state: 2
    }, 
    {
      pos: [5, 2, 17], 
      state: 5
    }, 
    {
      pos: [6, 2, 17], 
      state: 0
    }, 
    {
      pos: [7, 2, 17], 
      state: 5
    }, 
    {
      pos: [8, 2, 17], 
      state: 2
    }, 
    {
      pos: [4, 2, 18], 
      state: 2
    }, 
    {
      pos: [5, 2, 18], 
      state: 5
    }, 
    {
      pos: [6, 2, 18], 
      state: 0
    }, 
    {
      pos: [7, 2, 18], 
      state: 5
    }, 
    {
      pos: [8, 2, 18], 
      state: 2
    }, 
    {
      pos: [4, 2, 19], 
      state: 2
    }, 
    {
      pos: [5, 2, 19], 
      state: 5
    }, 
    {
      pos: [6, 2, 19], 
      state: 0
    }, 
    {
      pos: [7, 2, 19], 
      state: 5
    }, 
    {
      pos: [8, 2, 19], 
      state: 2
    }, 
    {
      pos: [4, 2, 20], 
      state: 2
    }, 
    {
      pos: [5, 2, 20], 
      state: 5
    }, 
    {
      pos: [6, 2, 20], 
      state: 0
    }, 
    {
      pos: [7, 2, 20], 
      state: 5
    }, 
    {
      pos: [8, 2, 20], 
      state: 2
    }, 
    {
      pos: [4, 2, 21], 
      state: 2
    }, 
    {
      pos: [5, 2, 21], 
      state: 5
    }, 
    {
      pos: [6, 2, 21], 
      state: 0
    }, 
    {
      pos: [7, 2, 21], 
      state: 5
    }, 
    {
      pos: [8, 2, 21], 
      state: 2
    }, 
    {
      pos: [4, 2, 22], 
      state: 2
    }, 
    {
      pos: [5, 2, 22], 
      state: 5
    }, 
    {
      pos: [6, 2, 22], 
      state: 0
    }, 
    {
      pos: [7, 2, 22], 
      state: 5
    }, 
    {
      pos: [8, 2, 22], 
      state: 2
    }, 
    {
      pos: [4, 2, 23], 
      state: 2
    }, 
    {
      pos: [5, 2, 23], 
      state: 5
    }, 
    {
      pos: [6, 2, 23], 
      state: 0
    }, 
    {
      pos: [7, 2, 23], 
      state: 5
    }, 
    {
      pos: [8, 2, 23], 
      state: 2
    }, 
    {
      pos: [4, 2, 24], 
      state: 2
    }, 
    {
      pos: [5, 2, 24], 
      state: 5
    }, 
    {
      pos: [6, 2, 24], 
      state: 0
    }, 
    {
      pos: [7, 2, 24], 
      state: 5
    }, 
    {
      pos: [8, 2, 24], 
      state: 2
    }, 
    {
      pos: [4, 2, 25], 
      state: 2
    }, 
    {
      pos: [5, 2, 25], 
      state: 2
    }, 
    {
      pos: [6, 2, 25], 
      state: 0
    }, 
    {
      pos: [7, 2, 25], 
      state: 2
    }, 
    {
      pos: [8, 2, 25], 
      state: 2
    }, 
    {
      pos: [0, 2, 0], 
      state: 1
    }, 
    {
      pos: [1, 2, 0], 
      state: 1
    }, 
    {
      pos: [2, 2, 0], 
      state: 1
    }, 
    {
      pos: [3, 2, 0], 
      state: 1
    }, 
    {
      pos: [4, 2, 0], 
      state: 1
    }, 
    {
      pos: [5, 2, 0], 
      state: 1
    }, 
    {
      pos: [6, 2, 0], 
      state: 1
    }, 
    {
      pos: [7, 2, 0], 
      state: 1
    }, 
    {
      pos: [8, 2, 0], 
      state: 1
    }, 
    {
      pos: [9, 2, 0], 
      state: 1
    }, 
    {
      pos: [10, 2, 0], 
      state: 1
    }, 
    {
      pos: [11, 2, 0], 
      state: 1
    }, 
    {
      pos: [12, 2, 0], 
      state: 1
    }, 
    {
      pos: [0, 2, 1], 
      state: 1
    }, 
    {
      pos: [1, 2, 1], 
      state: 1
    }, 
    {
      pos: [2, 2, 1], 
      state: 1
    }, 
    {
      pos: [3, 2, 1], 
      state: 1
    }, 
    {
      pos: [4, 2, 1], 
      state: 1
    }, 
    {
      pos: [5, 2, 1], 
      state: 1
    }, 
    {
      pos: [6, 2, 1], 
      state: 1
    }, 
    {
      pos: [7, 2, 1], 
      state: 1
    }, 
    {
      pos: [8, 2, 1], 
      state: 1
    }, 
    {
      pos: [9, 2, 1], 
      state: 1
    }, 
    {
      pos: [10, 2, 1], 
      state: 1
    }, 
    {
      pos: [11, 2, 1], 
      state: 1
    }, 
    {
      pos: [12, 2, 1], 
      state: 1
    }, 
    {
      pos: [0, 2, 2], 
      state: 1
    }, 
    {
      pos: [1, 2, 2], 
      state: 1
    }, 
    {
      pos: [2, 2, 2], 
      state: 1
    }, 
    {
      pos: [3, 2, 2], 
      state: 1
    }, 
    {
      pos: [4, 2, 2], 
      state: 1
    }, 
    {
      pos: [5, 2, 2], 
      state: 1
    }, 
    {
      pos: [6, 2, 2], 
      state: 1
    }, 
    {
      pos: [7, 2, 2], 
      state: 1
    }, 
    {
      pos: [8, 2, 2], 
      state: 1
    }, 
    {
      pos: [9, 2, 2], 
      state: 1
    }, 
    {
      pos: [10, 2, 2], 
      state: 1
    }, 
    {
      pos: [11, 2, 2], 
      state: 1
    }, 
    {
      pos: [12, 2, 2], 
      state: 1
    }, 
    {
      pos: [0, 2, 3], 
      state: 1
    }, 
    {
      pos: [1, 2, 3], 
      state: 1
    }, 
    {
      pos: [2, 2, 3], 
      state: 1
    }, 
    {
      pos: [3, 2, 3], 
      state: 1
    }, 
    {
      pos: [4, 2, 3], 
      state: 1
    }, 
    {
      pos: [5, 2, 3], 
      state: 1
    }, 
    {
      pos: [6, 2, 3], 
      state: 1
    }, 
    {
      pos: [7, 2, 3], 
      state: 1
    }, 
    {
      pos: [8, 2, 3], 
      state: 1
    }, 
    {
      pos: [9, 2, 3], 
      state: 1
    }, 
    {
      pos: [10, 2, 3], 
      state: 1
    }, 
    {
      pos: [11, 2, 3], 
      state: 1
    }, 
    {
      pos: [12, 2, 3], 
      state: 1
    }, 
    {
      pos: [0, 2, 4], 
      state: 1
    }, 
    {
      pos: [1, 2, 4], 
      state: 1
    }, 
    {
      pos: [2, 2, 4], 
      state: 1
    }, 
    {
      pos: [3, 2, 4], 
      state: 1
    }, 
    {
      pos: [4, 2, 4], 
      state: 1
    }, 
    {
      pos: [5, 2, 4], 
      state: 1
    }, 
    {
      pos: [6, 2, 4], 
      state: 1
    }, 
    {
      pos: [7, 2, 4], 
      state: 1
    }, 
    {
      pos: [8, 2, 4], 
      state: 1
    }, 
    {
      pos: [9, 2, 4], 
      state: 1
    }, 
    {
      pos: [10, 2, 4], 
      state: 1
    }, 
    {
      pos: [11, 2, 4], 
      state: 1
    }, 
    {
      pos: [12, 2, 4], 
      state: 1
    }, 
    {
      pos: [0, 2, 5], 
      state: 1
    }, 
    {
      pos: [1, 2, 5], 
      state: 1
    }, 
    {
      pos: [2, 2, 5], 
      state: 1
    }, 
    {
      pos: [3, 2, 5], 
      state: 1
    }, 
    {
      pos: [4, 2, 5], 
      state: 1
    }, 
    {
      pos: [5, 2, 5], 
      state: 1
    }, 
    {
      pos: [6, 2, 5], 
      state: 1
    }, 
    {
      pos: [7, 2, 5], 
      state: 1
    }, 
    {
      pos: [8, 2, 5], 
      state: 1
    }, 
    {
      pos: [9, 2, 5], 
      state: 1
    }, 
    {
      pos: [10, 2, 5], 
      state: 1
    }, 
    {
      pos: [11, 2, 5], 
      state: 1
    }, 
    {
      pos: [12, 2, 5], 
      state: 1
    }, 
    {
      pos: [0, 2, 6], 
      state: 1
    }, 
    {
      pos: [1, 2, 6], 
      state: 1
    }, 
    {
      pos: [2, 2, 6], 
      state: 1
    }, 
    {
      pos: [3, 2, 6], 
      state: 1
    }, 
    {
      pos: [4, 2, 6], 
      state: 1
    }, 
    {
      pos: [5, 2, 6], 
      state: 1
    }, 
    {
      pos: [7, 2, 6], 
      state: 1
    }, 
    {
      pos: [8, 2, 6], 
      state: 1
    }, 
    {
      pos: [9, 2, 6], 
      state: 1
    }, 
    {
      pos: [10, 2, 6], 
      state: 1
    }, 
    {
      pos: [11, 2, 6], 
      state: 1
    }, 
    {
      pos: [12, 2, 6], 
      state: 1
    }, 
    {
      pos: [0, 2, 7], 
      state: 1
    }, 
    {
      pos: [1, 2, 7], 
      state: 1
    }, 
    {
      pos: [2, 2, 7], 
      state: 1
    }, 
    {
      pos: [3, 2, 7], 
      state: 1
    }, 
    {
      pos: [4, 2, 7], 
      state: 1
    }, 
    {
      pos: [5, 2, 7], 
      state: 1
    }, 
    {
      pos: [7, 2, 7], 
      state: 1
    }, 
    {
      pos: [8, 2, 7], 
      state: 1
    }, 
    {
      pos: [9, 2, 7], 
      state: 1
    }, 
    {
      pos: [10, 2, 7], 
      state: 1
    }, 
    {
      pos: [11, 2, 7], 
      state: 1
    }, 
    {
      pos: [12, 2, 7], 
      state: 1
    }, 
    {
      pos: [0, 2, 8], 
      state: 1
    }, 
    {
      pos: [1, 2, 8], 
      state: 1
    }, 
    {
      pos: [2, 2, 8], 
      state: 1
    }, 
    {
      pos: [3, 2, 8], 
      state: 1
    }, 
    {
      pos: [4, 2, 8], 
      state: 1
    }, 
    {
      pos: [8, 2, 8], 
      state: 1
    }, 
    {
      pos: [9, 2, 8], 
      state: 1
    }, 
    {
      pos: [10, 2, 8], 
      state: 1
    }, 
    {
      pos: [11, 2, 8], 
      state: 1
    }, 
    {
      pos: [12, 2, 8], 
      state: 1
    }, 
    {
      pos: [0, 2, 9], 
      state: 1
    }, 
    {
      pos: [1, 2, 9], 
      state: 1
    }, 
    {
      pos: [2, 2, 9], 
      state: 1
    }, 
    {
      pos: [3, 2, 9], 
      state: 1
    }, 
    {
      pos: [4, 2, 9], 
      state: 1
    }, 
    {
      pos: [8, 2, 9], 
      state: 1
    }, 
    {
      pos: [9, 2, 9], 
      state: 1
    }, 
    {
      pos: [10, 2, 9], 
      state: 1
    }, 
    {
      pos: [11, 2, 9], 
      state: 1
    }, 
    {
      pos: [12, 2, 9], 
      state: 1
    }, 
    {
      pos: [0, 2, 10], 
      state: 1
    }, 
    {
      pos: [1, 2, 10], 
      state: 1
    }, 
    {
      pos: [2, 2, 10], 
      state: 1
    }, 
    {
      pos: [3, 2, 10], 
      state: 1
    }, 
    {
      pos: [9, 2, 10], 
      state: 1
    }, 
    {
      pos: [10, 2, 10], 
      state: 1
    }, 
    {
      pos: [11, 2, 10], 
      state: 1
    }, 
    {
      pos: [12, 2, 10], 
      state: 1
    }, 
    {
      pos: [0, 2, 11], 
      state: 1
    }, 
    {
      pos: [1, 2, 11], 
      state: 1
    }, 
    {
      pos: [2, 2, 11], 
      state: 1
    }, 
    {
      pos: [3, 2, 11], 
      state: 1
    }, 
    {
      pos: [9, 2, 11], 
      state: 1
    }, 
    {
      pos: [10, 2, 11], 
      state: 1
    }, 
    {
      pos: [11, 2, 11], 
      state: 1
    }, 
    {
      pos: [12, 2, 11], 
      state: 1
    }, 
    {
      pos: [0, 2, 12], 
      state: 1
    }, 
    {
      pos: [1, 2, 12], 
      state: 1
    }, 
    {
      pos: [2, 2, 12], 
      state: 1
    }, 
    {
      pos: [3, 2, 12], 
      state: 1
    }, 
    {
      pos: [9, 2, 12], 
      state: 1
    }, 
    {
      pos: [10, 2, 12], 
      state: 1
    }, 
    {
      pos: [11, 2, 12], 
      state: 1
    }, 
    {
      pos: [12, 2, 12], 
      state: 1
    }, 
    {
      pos: [0, 2, 13], 
      state: 1
    }, 
    {
      pos: [1, 2, 13], 
      state: 1
    }, 
    {
      pos: [2, 2, 13], 
      state: 1
    }, 
    {
      pos: [3, 2, 13], 
      state: 3
    }, 
    {
      pos: [9, 2, 13], 
      state: 4
    }, 
    {
      pos: [10, 2, 13], 
      state: 1
    }, 
    {
      pos: [11, 2, 13], 
      state: 1
    }, 
    {
      pos: [12, 2, 13], 
      state: 1
    }, 
    {
      pos: [0, 2, 14], 
      state: 1
    }, 
    {
      pos: [1, 2, 14], 
      state: 1
    }, 
    {
      pos: [2, 2, 14], 
      state: 1
    }, 
    {
      pos: [3, 2, 14], 
      state: 1
    }, 
    {
      pos: [9, 2, 14], 
      state: 1
    }, 
    {
      pos: [10, 2, 14], 
      state: 1
    }, 
    {
      pos: [11, 2, 14], 
      state: 1
    }, 
    {
      pos: [12, 2, 14], 
      state: 1
    }, 
    {
      pos: [0, 2, 15], 
      state: 1
    }, 
    {
      pos: [1, 2, 15], 
      state: 1
    }, 
    {
      pos: [2, 2, 15], 
      state: 1
    }, 
    {
      pos: [3, 2, 15], 
      state: 1
    }, 
    {
      pos: [9, 2, 15], 
      state: 1
    }, 
    {
      pos: [10, 2, 15], 
      state: 1
    }, 
    {
      pos: [11, 2, 15], 
      state: 1
    }, 
    {
      pos: [12, 2, 15], 
      state: 1
    }, 
    {
      pos: [0, 2, 16], 
      state: 1
    }, 
    {
      pos: [1, 2, 16], 
      state: 1
    }, 
    {
      pos: [2, 2, 16], 
      state: 1
    }, 
    {
      pos: [3, 2, 16], 
      state: 1
    }, 
    {
      pos: [9, 2, 16], 
      state: 1
    }, 
    {
      pos: [10, 2, 16], 
      state: 1
    }, 
    {
      pos: [11, 2, 16], 
      state: 1
    }, 
    {
      pos: [12, 2, 16], 
      state: 1
    }, 
    {
      pos: [0, 2, 17], 
      state: 1
    }, 
    {
      pos: [1, 2, 17], 
      state: 1
    }, 
    {
      pos: [2, 2, 17], 
      state: 1
    }, 
    {
      pos: [3, 2, 17], 
      state: 3
    }, 
    {
      pos: [9, 2, 17], 
      state: 4
    }, 
    {
      pos: [10, 2, 17], 
      state: 1
    }, 
    {
      pos: [11, 2, 17], 
      state: 1
    }, 
    {
      pos: [12, 2, 17], 
      state: 1
    }, 
    {
      pos: [0, 2, 18], 
      state: 1
    }, 
    {
      pos: [1, 2, 18], 
      state: 1
    }, 
    {
      pos: [2, 2, 18], 
      state: 1
    }, 
    {
      pos: [3, 2, 18], 
      state: 1
    }, 
    {
      pos: [9, 2, 18], 
      state: 1
    }, 
    {
      pos: [10, 2, 18], 
      state: 1
    }, 
    {
      pos: [11, 2, 18], 
      state: 1
    }, 
    {
      pos: [12, 2, 18], 
      state: 1
    }, 
    {
      pos: [0, 2, 19], 
      state: 1
    }, 
    {
      pos: [1, 2, 19], 
      state: 1
    }, 
    {
      pos: [2, 2, 19], 
      state: 1
    }, 
    {
      pos: [3, 2, 19], 
      state: 1
    }, 
    {
      pos: [9, 2, 19], 
      state: 1
    }, 
    {
      pos: [10, 2, 19], 
      state: 1
    }, 
    {
      pos: [11, 2, 19], 
      state: 1
    }, 
    {
      pos: [12, 2, 19], 
      state: 1
    }, 
    {
      pos: [0, 2, 20], 
      state: 1
    }, 
    {
      pos: [1, 2, 20], 
      state: 1
    }, 
    {
      pos: [2, 2, 20], 
      state: 1
    }, 
    {
      pos: [3, 2, 20], 
      state: 1
    }, 
    {
      pos: [9, 2, 20], 
      state: 1
    }, 
    {
      pos: [10, 2, 20], 
      state: 1
    }, 
    {
      pos: [11, 2, 20], 
      state: 1
    }, 
    {
      pos: [12, 2, 20], 
      state: 1
    }, 
    {
      pos: [0, 2, 21], 
      state: 1
    }, 
    {
      pos: [1, 2, 21], 
      state: 1
    }, 
    {
      pos: [2, 2, 21], 
      state: 1
    }, 
    {
      pos: [3, 2, 21], 
      state: 3
    }, 
    {
      pos: [9, 2, 21], 
      state: 4
    }, 
    {
      pos: [10, 2, 21], 
      state: 1
    }, 
    {
      pos: [11, 2, 21], 
      state: 1
    }, 
    {
      pos: [12, 2, 21], 
      state: 1
    }, 
    {
      pos: [0, 2, 22], 
      state: 1
    }, 
    {
      pos: [1, 2, 22], 
      state: 1
    }, 
    {
      pos: [2, 2, 22], 
      state: 1
    }, 
    {
      pos: [3, 2, 22], 
      state: 1
    }, 
    {
      pos: [9, 2, 22], 
      state: 1
    }, 
    {
      pos: [10, 2, 22], 
      state: 1
    }, 
    {
      pos: [11, 2, 22], 
      state: 1
    }, 
    {
      pos: [12, 2, 22], 
      state: 1
    }, 
    {
      pos: [0, 2, 23], 
      state: 1
    }, 
    {
      pos: [1, 2, 23], 
      state: 1
    }, 
    {
      pos: [2, 2, 23], 
      state: 1
    }, 
    {
      pos: [3, 2, 23], 
      state: 1
    }, 
    {
      pos: [9, 2, 23], 
      state: 1
    }, 
    {
      pos: [10, 2, 23], 
      state: 1
    }, 
    {
      pos: [11, 2, 23], 
      state: 1
    }, 
    {
      pos: [12, 2, 23], 
      state: 1
    }, 
    {
      pos: [0, 2, 24], 
      state: 1
    }, 
    {
      pos: [1, 2, 24], 
      state: 1
    }, 
    {
      pos: [2, 2, 24], 
      state: 1
    }, 
    {
      pos: [3, 2, 24], 
      state: 1
    }, 
    {
      pos: [9, 2, 24], 
      state: 1
    }, 
    {
      pos: [10, 2, 24], 
      state: 1
    }, 
    {
      pos: [11, 2, 24], 
      state: 1
    }, 
    {
      pos: [12, 2, 24], 
      state: 1
    }, 
    {
      pos: [0, 2, 25], 
      state: 1
    }, 
    {
      pos: [1, 2, 25], 
      state: 1
    }, 
    {
      pos: [2, 2, 25], 
      state: 1
    }, 
    {
      pos: [3, 2, 25], 
      state: 3
    }, 
    {
      pos: [9, 2, 25], 
      state: 4
    }, 
    {
      pos: [10, 2, 25], 
      state: 1
    }, 
    {
      pos: [11, 2, 25], 
      state: 1
    }, 
    {
      pos: [12, 2, 25], 
      state: 1
    }, 
    {
      pos: [0, 2, 26], 
      state: 1
    }, 
    {
      pos: [1, 2, 26], 
      state: 1
    }, 
    {
      pos: [2, 2, 26], 
      state: 1
    }, 
    {
      pos: [3, 2, 26], 
      state: 1
    }, 
    {
      pos: [4, 2, 26], 
      state: 1
    }, 
    {
      pos: [5, 2, 26], 
      state: 1
    }, 
    {
      pos: [6, 2, 26], 
      state: 1
    }, 
    {
      pos: [7, 2, 26], 
      state: 1
    }, 
    {
      pos: [8, 2, 26], 
      state: 1
    }, 
    {
      pos: [9, 2, 26], 
      state: 1
    }, 
    {
      pos: [10, 2, 26], 
      state: 1
    }, 
    {
      pos: [11, 2, 26], 
      state: 1
    }, 
    {
      pos: [12, 2, 26], 
      state: 1
    }, 
    {
      pos: [0, 2, 27], 
      state: 1
    }, 
    {
      pos: [1, 2, 27], 
      state: 1
    }, 
    {
      pos: [2, 2, 27], 
      state: 1
    }, 
    {
      pos: [3, 2, 27], 
      state: 1
    }, 
    {
      pos: [4, 2, 27], 
      state: 1
    }, 
    {
      pos: [5, 2, 27], 
      state: 1
    }, 
    {
      pos: [6, 2, 27], 
      state: 1
    }, 
    {
      pos: [7, 2, 27], 
      state: 1
    }, 
    {
      pos: [8, 2, 27], 
      state: 1
    }, 
    {
      pos: [9, 2, 27], 
      state: 1
    }, 
    {
      pos: [10, 2, 27], 
      state: 1
    }, 
    {
      pos: [11, 2, 27], 
      state: 1
    }, 
    {
      pos: [12, 2, 27], 
      state: 1
    }, 
    {
      pos: [0, 2, 28], 
      state: 1
    }, 
    {
      pos: [1, 2, 28], 
      state: 1
    }, 
    {
      pos: [2, 2, 28], 
      state: 1
    }, 
    {
      pos: [3, 2, 28], 
      state: 1
    }, 
    {
      pos: [4, 2, 28], 
      state: 1
    }, 
    {
      pos: [5, 2, 28], 
      state: 1
    }, 
    {
      pos: [6, 2, 28], 
      state: 1
    }, 
    {
      pos: [7, 2, 28], 
      state: 1
    }, 
    {
      pos: [8, 2, 28], 
      state: 1
    }, 
    {
      pos: [9, 2, 28], 
      state: 1
    }, 
    {
      pos: [10, 2, 28], 
      state: 1
    }, 
    {
      pos: [11, 2, 28], 
      state: 1
    }, 
    {
      pos: [12, 2, 28], 
      state: 1
    }, 
    {
      pos: [6, 3, 5], 
      state: 0
    }, 
    {
      pos: [6, 3, 6], 
      state: 0
    }, 
    {
      pos: [5, 3, 7], 
      state: 2
    }, 
    {
      pos: [6, 3, 7], 
      state: 2
    }, 
    {
      pos: [7, 3, 7], 
      state: 2
    }, 
    {
      pos: [4, 3, 8], 
      state: 2
    }, 
    {
      pos: [5, 3, 8], 
      state: 2
    }, 
    {
      pos: [6, 3, 8], 
      state: 2
    }, 
    {
      pos: [7, 3, 8], 
      state: 2
    }, 
    {
      pos: [8, 3, 8], 
      state: 2
    }, 
    {
      pos: [4, 3, 9], 
      state: 2
    }, 
    {
      pos: [8, 3, 9], 
      state: 2
    }, 
    {
      pos: [3, 3, 10], 
      state: 2
    }, 
    {
      pos: [9, 3, 10], 
      state: 2
    }, 
    {
      pos: [3, 3, 11], 
      state: 2
    }, 
    {
      pos: [9, 3, 11], 
      state: 2
    }, 
    {
      pos: [3, 3, 12], 
      state: 2
    }, 
    {
      pos: [9, 3, 12], 
      state: 2
    }, 
    {
      pos: [3, 3, 13], 
      state: 2
    }, 
    {
      pos: [9, 3, 13], 
      state: 2
    }, 
    {
      pos: [3, 3, 14], 
      state: 2
    }, 
    {
      pos: [6, 3, 14], 
      state: 6
    }, 
    {
      pos: [9, 3, 14], 
      state: 2
    }, 
    {
      pos: [3, 3, 15], 
      state: 2
    }, 
    {
      pos: [9, 3, 15], 
      state: 2
    }, 
    {
      pos: [3, 3, 16], 
      state: 2
    }, 
    {
      pos: [8, 3, 16], 
      state: 2
    }, 
    {
      pos: [9, 3, 16], 
      state: 2
    }, 
    {
      pos: [3, 3, 17], 
      state: 2
    }, 
    {
      pos: [8, 3, 17], 
      state: 2
    }, 
    {
      pos: [9, 3, 17], 
      state: 2
    }, 
    {
      pos: [3, 3, 18], 
      state: 2
    }, 
    {
      pos: [8, 3, 18], 
      state: 2
    }, 
    {
      pos: [9, 3, 18], 
      state: 2
    }, 
    {
      pos: [3, 3, 19], 
      state: 2
    }, 
    {
      pos: [8, 3, 19], 
      state: 2
    }, 
    {
      pos: [9, 3, 19], 
      state: 2
    }, 
    {
      pos: [3, 3, 20], 
      state: 2
    }, 
    {
      pos: [8, 3, 20], 
      state: 2
    }, 
    {
      pos: [9, 3, 20], 
      state: 2
    }, 
    {
      pos: [3, 3, 21], 
      state: 2
    }, 
    {
      pos: [8, 3, 21], 
      state: 2
    }, 
    {
      pos: [9, 3, 21], 
      state: 2
    }, 
    {
      pos: [3, 3, 22], 
      state: 2
    }, 
    {
      pos: [8, 3, 22], 
      state: 2
    }, 
    {
      pos: [9, 3, 22], 
      state: 2
    }, 
    {
      pos: [3, 3, 23], 
      state: 2
    }, 
    {
      pos: [8, 3, 23], 
      state: 2
    }, 
    {
      pos: [9, 3, 23], 
      state: 2
    }, 
    {
      pos: [3, 3, 24], 
      state: 2
    }, 
    {
      pos: [8, 3, 24], 
      state: 2
    }, 
    {
      pos: [9, 3, 24], 
      state: 2
    }, 
    {
      pos: [3, 3, 25], 
      state: 2
    }, 
    {
      pos: [4, 3, 25], 
      state: 2
    }, 
    {
      pos: [5, 3, 25], 
      state: 2
    }, 
    {
      pos: [6, 3, 25], 
      state: 2
    }, 
    {
      pos: [7, 3, 25], 
      state: 2
    }, 
    {
      pos: [8, 3, 25], 
      state: 2
    }, 
    {
      pos: [9, 3, 25], 
      state: 2
    }, 
    {
      pos: [0, 3, 0], 
      state: 1
    }, 
    {
      pos: [1, 3, 0], 
      state: 1
    }, 
    {
      pos: [2, 3, 0], 
      state: 1
    }, 
    {
      pos: [3, 3, 0], 
      state: 1
    }, 
    {
      pos: [4, 3, 0], 
      state: 1
    }, 
    {
      pos: [5, 3, 0], 
      state: 1
    }, 
    {
      pos: [6, 3, 0], 
      state: 1
    }, 
    {
      pos: [7, 3, 0], 
      state: 1
    }, 
    {
      pos: [8, 3, 0], 
      state: 1
    }, 
    {
      pos: [9, 3, 0], 
      state: 1
    }, 
    {
      pos: [10, 3, 0], 
      state: 1
    }, 
    {
      pos: [11, 3, 0], 
      state: 1
    }, 
    {
      pos: [12, 3, 0], 
      state: 1
    }, 
    {
      pos: [0, 3, 1], 
      state: 1
    }, 
    {
      pos: [1, 3, 1], 
      state: 1
    }, 
    {
      pos: [2, 3, 1], 
      state: 1
    }, 
    {
      pos: [3, 3, 1], 
      state: 1
    }, 
    {
      pos: [4, 3, 1], 
      state: 1
    }, 
    {
      pos: [5, 3, 1], 
      state: 1
    }, 
    {
      pos: [6, 3, 1], 
      state: 1
    }, 
    {
      pos: [7, 3, 1], 
      state: 1
    }, 
    {
      pos: [8, 3, 1], 
      state: 1
    }, 
    {
      pos: [9, 3, 1], 
      state: 1
    }, 
    {
      pos: [10, 3, 1], 
      state: 1
    }, 
    {
      pos: [11, 3, 1], 
      state: 1
    }, 
    {
      pos: [12, 3, 1], 
      state: 1
    }, 
    {
      pos: [0, 3, 2], 
      state: 1
    }, 
    {
      pos: [1, 3, 2], 
      state: 1
    }, 
    {
      pos: [2, 3, 2], 
      state: 1
    }, 
    {
      pos: [3, 3, 2], 
      state: 1
    }, 
    {
      pos: [4, 3, 2], 
      state: 1
    }, 
    {
      pos: [5, 3, 2], 
      state: 1
    }, 
    {
      pos: [6, 3, 2], 
      state: 1
    }, 
    {
      pos: [7, 3, 2], 
      state: 1
    }, 
    {
      pos: [8, 3, 2], 
      state: 1
    }, 
    {
      pos: [9, 3, 2], 
      state: 1
    }, 
    {
      pos: [10, 3, 2], 
      state: 1
    }, 
    {
      pos: [11, 3, 2], 
      state: 1
    }, 
    {
      pos: [12, 3, 2], 
      state: 1
    }, 
    {
      pos: [0, 3, 3], 
      state: 1
    }, 
    {
      pos: [1, 3, 3], 
      state: 1
    }, 
    {
      pos: [2, 3, 3], 
      state: 1
    }, 
    {
      pos: [3, 3, 3], 
      state: 1
    }, 
    {
      pos: [4, 3, 3], 
      state: 1
    }, 
    {
      pos: [5, 3, 3], 
      state: 1
    }, 
    {
      pos: [6, 3, 3], 
      state: 1
    }, 
    {
      pos: [7, 3, 3], 
      state: 1
    }, 
    {
      pos: [8, 3, 3], 
      state: 1
    }, 
    {
      pos: [9, 3, 3], 
      state: 1
    }, 
    {
      pos: [10, 3, 3], 
      state: 1
    }, 
    {
      pos: [11, 3, 3], 
      state: 1
    }, 
    {
      pos: [12, 3, 3], 
      state: 1
    }, 
    {
      pos: [0, 3, 4], 
      state: 1
    }, 
    {
      pos: [1, 3, 4], 
      state: 1
    }, 
    {
      pos: [2, 3, 4], 
      state: 1
    }, 
    {
      pos: [3, 3, 4], 
      state: 1
    }, 
    {
      pos: [4, 3, 4], 
      state: 1
    }, 
    {
      pos: [5, 3, 4], 
      state: 1
    }, 
    {
      pos: [6, 3, 4], 
      state: 1
    }, 
    {
      pos: [7, 3, 4], 
      state: 1
    }, 
    {
      pos: [8, 3, 4], 
      state: 1
    }, 
    {
      pos: [9, 3, 4], 
      state: 1
    }, 
    {
      pos: [10, 3, 4], 
      state: 1
    }, 
    {
      pos: [11, 3, 4], 
      state: 1
    }, 
    {
      pos: [12, 3, 4], 
      state: 1
    }, 
    {
      pos: [0, 3, 5], 
      state: 1
    }, 
    {
      pos: [1, 3, 5], 
      state: 1
    }, 
    {
      pos: [2, 3, 5], 
      state: 1
    }, 
    {
      pos: [3, 3, 5], 
      state: 1
    }, 
    {
      pos: [4, 3, 5], 
      state: 1
    }, 
    {
      pos: [5, 3, 5], 
      state: 1
    }, 
    {
      pos: [7, 3, 5], 
      state: 1
    }, 
    {
      pos: [8, 3, 5], 
      state: 1
    }, 
    {
      pos: [9, 3, 5], 
      state: 1
    }, 
    {
      pos: [10, 3, 5], 
      state: 1
    }, 
    {
      pos: [11, 3, 5], 
      state: 1
    }, 
    {
      pos: [12, 3, 5], 
      state: 1
    }, 
    {
      pos: [0, 3, 6], 
      state: 1
    }, 
    {
      pos: [1, 3, 6], 
      state: 1
    }, 
    {
      pos: [2, 3, 6], 
      state: 1
    }, 
    {
      pos: [3, 3, 6], 
      state: 1
    }, 
    {
      pos: [4, 3, 6], 
      state: 1
    }, 
    {
      pos: [5, 3, 6], 
      state: 1
    }, 
    {
      pos: [7, 3, 6], 
      state: 1
    }, 
    {
      pos: [8, 3, 6], 
      state: 1
    }, 
    {
      pos: [9, 3, 6], 
      state: 1
    }, 
    {
      pos: [10, 3, 6], 
      state: 1
    }, 
    {
      pos: [11, 3, 6], 
      state: 1
    }, 
    {
      pos: [12, 3, 6], 
      state: 1
    }, 
    {
      pos: [0, 3, 7], 
      state: 1
    }, 
    {
      pos: [1, 3, 7], 
      state: 1
    }, 
    {
      pos: [2, 3, 7], 
      state: 1
    }, 
    {
      pos: [3, 3, 7], 
      state: 1
    }, 
    {
      pos: [4, 3, 7], 
      state: 1
    }, 
    {
      pos: [8, 3, 7], 
      state: 1
    }, 
    {
      pos: [9, 3, 7], 
      state: 1
    }, 
    {
      pos: [10, 3, 7], 
      state: 1
    }, 
    {
      pos: [11, 3, 7], 
      state: 1
    }, 
    {
      pos: [12, 3, 7], 
      state: 1
    }, 
    {
      pos: [0, 3, 8], 
      state: 1
    }, 
    {
      pos: [1, 3, 8], 
      state: 1
    }, 
    {
      pos: [2, 3, 8], 
      state: 1
    }, 
    {
      pos: [3, 3, 8], 
      state: 1
    }, 
    {
      pos: [9, 3, 8], 
      state: 1
    }, 
    {
      pos: [10, 3, 8], 
      state: 1
    }, 
    {
      pos: [11, 3, 8], 
      state: 1
    }, 
    {
      pos: [12, 3, 8], 
      state: 1
    }, 
    {
      pos: [0, 3, 9], 
      state: 1
    }, 
    {
      pos: [1, 3, 9], 
      state: 1
    }, 
    {
      pos: [2, 3, 9], 
      state: 1
    }, 
    {
      pos: [3, 3, 9], 
      state: 1
    }, 
    {
      pos: [5, 3, 9], 
      state: 1
    }, 
    {
      pos: [6, 3, 9], 
      state: 1
    }, 
    {
      pos: [7, 3, 9], 
      state: 1
    }, 
    {
      pos: [9, 3, 9], 
      state: 1
    }, 
    {
      pos: [10, 3, 9], 
      state: 1
    }, 
    {
      pos: [11, 3, 9], 
      state: 1
    }, 
    {
      pos: [12, 3, 9], 
      state: 1
    }, 
    {
      pos: [0, 3, 10], 
      state: 1
    }, 
    {
      pos: [1, 3, 10], 
      state: 1
    }, 
    {
      pos: [2, 3, 10], 
      state: 1
    }, 
    {
      pos: [4, 3, 10], 
      state: 1
    }, 
    {
      pos: [5, 3, 10], 
      state: 1
    }, 
    {
      pos: [6, 3, 10], 
      state: 1
    }, 
    {
      pos: [7, 3, 10], 
      state: 1
    }, 
    {
      pos: [8, 3, 10], 
      state: 1
    }, 
    {
      pos: [10, 3, 10], 
      state: 1
    }, 
    {
      pos: [11, 3, 10], 
      state: 1
    }, 
    {
      pos: [12, 3, 10], 
      state: 1
    }, 
    {
      pos: [0, 3, 11], 
      state: 1
    }, 
    {
      pos: [1, 3, 11], 
      state: 1
    }, 
    {
      pos: [2, 3, 11], 
      state: 1
    }, 
    {
      pos: [4, 3, 11], 
      state: 1
    }, 
    {
      pos: [5, 3, 11], 
      state: 1
    }, 
    {
      pos: [6, 3, 11], 
      state: 1
    }, 
    {
      pos: [7, 3, 11], 
      state: 1
    }, 
    {
      pos: [8, 3, 11], 
      state: 1
    }, 
    {
      pos: [10, 3, 11], 
      state: 1
    }, 
    {
      pos: [11, 3, 11], 
      state: 1
    }, 
    {
      pos: [12, 3, 11], 
      state: 1
    }, 
    {
      pos: [0, 3, 12], 
      state: 1
    }, 
    {
      pos: [1, 3, 12], 
      state: 1
    }, 
    {
      pos: [2, 3, 12], 
      state: 1
    }, 
    {
      pos: [4, 3, 12], 
      state: 1
    }, 
    {
      pos: [5, 3, 12], 
      state: 1
    }, 
    {
      pos: [6, 3, 12], 
      state: 1
    }, 
    {
      pos: [7, 3, 12], 
      state: 1
    }, 
    {
      pos: [8, 3, 12], 
      state: 1
    }, 
    {
      pos: [10, 3, 12], 
      state: 1
    }, 
    {
      pos: [11, 3, 12], 
      state: 1
    }, 
    {
      pos: [12, 3, 12], 
      state: 1
    }, 
    {
      pos: [0, 3, 13], 
      state: 1
    }, 
    {
      pos: [1, 3, 13], 
      state: 1
    }, 
    {
      pos: [2, 3, 13], 
      state: 3
    }, 
    {
      pos: [4, 3, 13], 
      state: 1
    }, 
    {
      pos: [5, 3, 13], 
      state: 1
    }, 
    {
      pos: [6, 3, 13], 
      state: 1
    }, 
    {
      pos: [7, 3, 13], 
      state: 1
    }, 
    {
      pos: [8, 3, 13], 
      state: 1
    }, 
    {
      pos: [10, 3, 13], 
      state: 4
    }, 
    {
      pos: [11, 3, 13], 
      state: 1
    }, 
    {
      pos: [12, 3, 13], 
      state: 1
    }, 
    {
      pos: [0, 3, 14], 
      state: 1
    }, 
    {
      pos: [1, 3, 14], 
      state: 1
    }, 
    {
      pos: [2, 3, 14], 
      state: 1
    }, 
    {
      pos: [4, 3, 14], 
      state: 1
    }, 
    {
      pos: [5, 3, 14], 
      state: 1
    }, 
    {
      pos: [7, 3, 14], 
      state: 1
    }, 
    {
      pos: [8, 3, 14], 
      state: 1
    }, 
    {
      pos: [10, 3, 14], 
      state: 1
    }, 
    {
      pos: [11, 3, 14], 
      state: 1
    }, 
    {
      pos: [12, 3, 14], 
      state: 1
    }, 
    {
      pos: [0, 3, 15], 
      state: 1
    }, 
    {
      pos: [1, 3, 15], 
      state: 1
    }, 
    {
      pos: [2, 3, 15], 
      state: 1
    }, 
    {
      pos: [4, 3, 15], 
      state: 1
    }, 
    {
      pos: [5, 3, 15], 
      state: 1
    }, 
    {
      pos: [6, 3, 15], 
      state: 1
    }, 
    {
      pos: [7, 3, 15], 
      state: 1
    }, 
    {
      pos: [8, 3, 15], 
      state: 7
    }, 
    {
      pos: [10, 3, 15], 
      state: 1
    }, 
    {
      pos: [11, 3, 15], 
      state: 1
    }, 
    {
      pos: [12, 3, 15], 
      state: 1
    }, 
    {
      pos: [0, 3, 16], 
      state: 1
    }, 
    {
      pos: [1, 3, 16], 
      state: 1
    }, 
    {
      pos: [2, 3, 16], 
      state: 1
    }, 
    {
      pos: [4, 3, 16], 
      state: 1
    }, 
    {
      pos: [5, 3, 16], 
      state: 1
    }, 
    {
      pos: [6, 3, 16], 
      state: 1
    }, 
    {
      pos: [7, 3, 16], 
      state: 1
    }, 
    {
      pos: [10, 3, 16], 
      state: 1
    }, 
    {
      pos: [11, 3, 16], 
      state: 1
    }, 
    {
      pos: [12, 3, 16], 
      state: 1
    }, 
    {
      pos: [0, 3, 17], 
      state: 1
    }, 
    {
      pos: [1, 3, 17], 
      state: 1
    }, 
    {
      pos: [2, 3, 17], 
      state: 3
    }, 
    {
      pos: [4, 3, 17], 
      state: 1
    }, 
    {
      pos: [5, 3, 17], 
      state: 1
    }, 
    {
      pos: [6, 3, 17], 
      state: 1
    }, 
    {
      pos: [7, 3, 17], 
      state: 1
    }, 
    {
      pos: [10, 3, 17], 
      state: 4
    }, 
    {
      pos: [11, 3, 17], 
      state: 1
    }, 
    {
      pos: [12, 3, 17], 
      state: 1
    }, 
    {
      pos: [0, 3, 18], 
      state: 1
    }, 
    {
      pos: [1, 3, 18], 
      state: 1
    }, 
    {
      pos: [2, 3, 18], 
      state: 1
    }, 
    {
      pos: [4, 3, 18], 
      state: 1
    }, 
    {
      pos: [5, 3, 18], 
      state: 1
    }, 
    {
      pos: [6, 3, 18], 
      state: 1
    }, 
    {
      pos: [7, 3, 18], 
      state: 1
    }, 
    {
      pos: [10, 3, 18], 
      state: 1
    }, 
    {
      pos: [11, 3, 18], 
      state: 1
    }, 
    {
      pos: [12, 3, 18], 
      state: 1
    }, 
    {
      pos: [0, 3, 19], 
      state: 1
    }, 
    {
      pos: [1, 3, 19], 
      state: 1
    }, 
    {
      pos: [2, 3, 19], 
      state: 1
    }, 
    {
      pos: [4, 3, 19], 
      state: 1
    }, 
    {
      pos: [5, 3, 19], 
      state: 1
    }, 
    {
      pos: [6, 3, 19], 
      state: 1
    }, 
    {
      pos: [7, 3, 19], 
      state: 1
    }, 
    {
      pos: [10, 3, 19], 
      state: 1
    }, 
    {
      pos: [11, 3, 19], 
      state: 1
    }, 
    {
      pos: [12, 3, 19], 
      state: 1
    }, 
    {
      pos: [0, 3, 20], 
      state: 1
    }, 
    {
      pos: [1, 3, 20], 
      state: 1
    }, 
    {
      pos: [2, 3, 20], 
      state: 1
    }, 
    {
      pos: [4, 3, 20], 
      state: 1
    }, 
    {
      pos: [5, 3, 20], 
      state: 1
    }, 
    {
      pos: [6, 3, 20], 
      state: 1
    }, 
    {
      pos: [7, 3, 20], 
      state: 1
    }, 
    {
      pos: [10, 3, 20], 
      state: 1
    }, 
    {
      pos: [11, 3, 20], 
      state: 1
    }, 
    {
      pos: [12, 3, 20], 
      state: 1
    }, 
    {
      pos: [0, 3, 21], 
      state: 1
    }, 
    {
      pos: [1, 3, 21], 
      state: 1
    }, 
    {
      pos: [2, 3, 21], 
      state: 3
    }, 
    {
      pos: [4, 3, 21], 
      state: 1
    }, 
    {
      pos: [5, 3, 21], 
      state: 1
    }, 
    {
      pos: [6, 3, 21], 
      state: 1
    }, 
    {
      pos: [7, 3, 21], 
      state: 1
    }, 
    {
      pos: [10, 3, 21], 
      state: 4
    }, 
    {
      pos: [11, 3, 21], 
      state: 1
    }, 
    {
      pos: [12, 3, 21], 
      state: 1
    }, 
    {
      pos: [0, 3, 22], 
      state: 1
    }, 
    {
      pos: [1, 3, 22], 
      state: 1
    }, 
    {
      pos: [2, 3, 22], 
      state: 1
    }, 
    {
      pos: [4, 3, 22], 
      state: 1
    }, 
    {
      pos: [5, 3, 22], 
      state: 1
    }, 
    {
      pos: [6, 3, 22], 
      state: 1
    }, 
    {
      pos: [7, 3, 22], 
      state: 1
    }, 
    {
      pos: [10, 3, 22], 
      state: 1
    }, 
    {
      pos: [11, 3, 22], 
      state: 1
    }, 
    {
      pos: [12, 3, 22], 
      state: 1
    }, 
    {
      pos: [0, 3, 23], 
      state: 1
    }, 
    {
      pos: [1, 3, 23], 
      state: 1
    }, 
    {
      pos: [2, 3, 23], 
      state: 1
    }, 
    {
      pos: [4, 3, 23], 
      state: 1
    }, 
    {
      pos: [5, 3, 23], 
      state: 1
    }, 
    {
      pos: [6, 3, 23], 
      state: 1
    }, 
    {
      pos: [7, 3, 23], 
      state: 1
    }, 
    {
      pos: [10, 3, 23], 
      state: 1
    }, 
    {
      pos: [11, 3, 23], 
      state: 1
    }, 
    {
      pos: [12, 3, 23], 
      state: 1
    }, 
    {
      pos: [0, 3, 24], 
      state: 1
    }, 
    {
      pos: [1, 3, 24], 
      state: 1
    }, 
    {
      pos: [2, 3, 24], 
      state: 1
    }, 
    {
      pos: [4, 3, 24], 
      state: 1
    }, 
    {
      pos: [5, 3, 24], 
      state: 1
    }, 
    {
      pos: [6, 3, 24], 
      state: 1
    }, 
    {
      pos: [7, 3, 24], 
      state: 1
    }, 
    {
      pos: [10, 3, 24], 
      state: 1
    }, 
    {
      pos: [11, 3, 24], 
      state: 1
    }, 
    {
      pos: [12, 3, 24], 
      state: 1
    }, 
    {
      pos: [0, 3, 25], 
      state: 1
    }, 
    {
      pos: [1, 3, 25], 
      state: 1
    }, 
    {
      pos: [2, 3, 25], 
      state: 3
    }, 
    {
      pos: [10, 3, 25], 
      state: 4
    }, 
    {
      pos: [11, 3, 25], 
      state: 1
    }, 
    {
      pos: [12, 3, 25], 
      state: 1
    }, 
    {
      pos: [0, 3, 26], 
      state: 1
    }, 
    {
      pos: [1, 3, 26], 
      state: 1
    }, 
    {
      pos: [2, 3, 26], 
      state: 1
    }, 
    {
      pos: [3, 3, 26], 
      state: 1
    }, 
    {
      pos: [4, 3, 26], 
      state: 1
    }, 
    {
      pos: [5, 3, 26], 
      state: 1
    }, 
    {
      pos: [6, 3, 26], 
      state: 1
    }, 
    {
      pos: [7, 3, 26], 
      state: 1
    }, 
    {
      pos: [8, 3, 26], 
      state: 1
    }, 
    {
      pos: [9, 3, 26], 
      state: 1
    }, 
    {
      pos: [10, 3, 26], 
      state: 1
    }, 
    {
      pos: [11, 3, 26], 
      state: 1
    }, 
    {
      pos: [12, 3, 26], 
      state: 1
    }, 
    {
      pos: [0, 3, 27], 
      state: 1
    }, 
    {
      pos: [1, 3, 27], 
      state: 1
    }, 
    {
      pos: [2, 3, 27], 
      state: 1
    }, 
    {
      pos: [3, 3, 27], 
      state: 1
    }, 
    {
      pos: [4, 3, 27], 
      state: 1
    }, 
    {
      pos: [5, 3, 27], 
      state: 1
    }, 
    {
      pos: [6, 3, 27], 
      state: 1
    }, 
    {
      pos: [7, 3, 27], 
      state: 1
    }, 
    {
      pos: [8, 3, 27], 
      state: 1
    }, 
    {
      pos: [9, 3, 27], 
      state: 1
    }, 
    {
      pos: [10, 3, 27], 
      state: 1
    }, 
    {
      pos: [11, 3, 27], 
      state: 1
    }, 
    {
      pos: [12, 3, 27], 
      state: 1
    }, 
    {
      pos: [0, 3, 28], 
      state: 1
    }, 
    {
      pos: [1, 3, 28], 
      state: 1
    }, 
    {
      pos: [2, 3, 28], 
      state: 1
    }, 
    {
      pos: [3, 3, 28], 
      state: 1
    }, 
    {
      pos: [4, 3, 28], 
      state: 1
    }, 
    {
      pos: [5, 3, 28], 
      state: 1
    }, 
    {
      pos: [6, 3, 28], 
      state: 1
    }, 
    {
      pos: [7, 3, 28], 
      state: 1
    }, 
    {
      pos: [8, 3, 28], 
      state: 1
    }, 
    {
      pos: [9, 3, 28], 
      state: 1
    }, 
    {
      pos: [10, 3, 28], 
      state: 1
    }, 
    {
      pos: [11, 3, 28], 
      state: 1
    }, 
    {
      pos: [12, 3, 28], 
      state: 1
    }, 
    {
      pos: [6, 4, 5], 
      state: 2
    }, 
    {
      pos: [5, 4, 6], 
      state: 2
    }, 
    {
      pos: [6, 4, 6], 
      state: 2
    }, 
    {
      pos: [7, 4, 6], 
      state: 2
    }, 
    {
      pos: [4, 4, 7], 
      state: 2
    }, 
    {
      pos: [8, 4, 7], 
      state: 2
    }, 
    {
      pos: [4, 4, 8], 
      state: 2
    }, 
    {
      pos: [8, 4, 8], 
      state: 2
    }, 
    {
      pos: [3, 4, 9], 
      state: 2
    }, 
    {
      pos: [9, 4, 9], 
      state: 2
    }, 
    {
      pos: [3, 4, 10], 
      state: 2
    }, 
    {
      pos: [9, 4, 10], 
      state: 2
    }, 
    {
      pos: [2, 4, 11], 
      state: 2
    }, 
    {
      pos: [10, 4, 11], 
      state: 2
    }, 
    {
      pos: [2, 4, 12], 
      state: 2
    }, 
    {
      pos: [10, 4, 12], 
      state: 2
    }, 
    {
      pos: [2, 4, 13], 
      state: 2
    }, 
    {
      pos: [10, 4, 13], 
      state: 2
    }, 
    {
      pos: [2, 4, 14], 
      state: 2
    }, 
    {
      pos: [6, 4, 14], 
      state: 6
    }, 
    {
      pos: [10, 4, 14], 
      state: 2
    }, 
    {
      pos: [2, 4, 15], 
      state: 2
    }, 
    {
      pos: [10, 4, 15], 
      state: 2
    }, 
    {
      pos: [2, 4, 16], 
      state: 2
    }, 
    {
      pos: [10, 4, 16], 
      state: 2
    }, 
    {
      pos: [2, 4, 17], 
      state: 2
    }, 
    {
      pos: [10, 4, 17], 
      state: 2
    }, 
    {
      pos: [2, 4, 18], 
      state: 2
    }, 
    {
      pos: [10, 4, 18], 
      state: 2
    }, 
    {
      pos: [2, 4, 19], 
      state: 2
    }, 
    {
      pos: [10, 4, 19], 
      state: 2
    }, 
    {
      pos: [2, 4, 20], 
      state: 2
    }, 
    {
      pos: [8, 4, 20], 
      state: 2
    }, 
    {
      pos: [9, 4, 20], 
      state: 2
    }, 
    {
      pos: [10, 4, 20], 
      state: 2
    }, 
    {
      pos: [2, 4, 21], 
      state: 2
    }, 
    {
      pos: [8, 4, 21], 
      state: 2
    }, 
    {
      pos: [9, 4, 21], 
      state: 2
    }, 
    {
      pos: [10, 4, 21], 
      state: 2
    }, 
    {
      pos: [2, 4, 22], 
      state: 2
    }, 
    {
      pos: [8, 4, 22], 
      state: 2
    }, 
    {
      pos: [9, 4, 22], 
      state: 2
    }, 
    {
      pos: [10, 4, 22], 
      state: 2
    }, 
    {
      pos: [2, 4, 23], 
      state: 2
    }, 
    {
      pos: [8, 4, 23], 
      state: 2
    }, 
    {
      pos: [9, 4, 23], 
      state: 2
    }, 
    {
      pos: [10, 4, 23], 
      state: 2
    }, 
    {
      pos: [2, 4, 24], 
      state: 2
    }, 
    {
      pos: [8, 4, 24], 
      state: 2
    }, 
    {
      pos: [9, 4, 24], 
      state: 2
    }, 
    {
      pos: [10, 4, 24], 
      state: 2
    }, 
    {
      pos: [2, 4, 25], 
      state: 2
    }, 
    {
      pos: [3, 4, 25], 
      state: 2
    }, 
    {
      pos: [4, 4, 25], 
      state: 2
    }, 
    {
      pos: [5, 4, 25], 
      state: 2
    }, 
    {
      pos: [6, 4, 25], 
      state: 2
    }, 
    {
      pos: [7, 4, 25], 
      state: 2
    }, 
    {
      pos: [8, 4, 25], 
      state: 2
    }, 
    {
      pos: [9, 4, 25], 
      state: 2
    }, 
    {
      pos: [10, 4, 25], 
      state: 2
    }, 
    {
      nbt: {
        Items: [], 
        id: "minecraft:chest", 
        Lock: ""
      }, 
      pos: [5, 4, 7], 
      state: 8
    }, 
    {
      nbt: {
        Items: [], 
        id: "minecraft:chest", 
        Lock: ""
      }, 
      pos: [7, 4, 7], 
      state: 8
    }, 
    {
      nbt: {
        metadata: "Sentry", 
        mirror: "NONE", 
        ignoreEntities: 0b, 
        powered: 0b, 
        seed: 0L, 
        author: "jeb_", 
        rotation: "NONE", 
        mode: "DATA", 
        posX: 1, 
        posY: 1, 
        sizeX: 0, 
        integrity: 1.0f, 
        posZ: 1, 
        showair: 0b, 
        name: "", 
        id: "minecraft:structure_block", 
        sizeY: 0, 
        showboundingbox: 0b, 
        sizeZ: 0
      }, 
      pos: [6, 4, 8], 
      state: 9
    }, 
    {
      pos: [0, 4, 0], 
      state: 1
    }, 
    {
      pos: [1, 4, 0], 
      state: 1
    }, 
    {
      pos: [2, 4, 0], 
      state: 1
    }, 
    {
      pos: [3, 4, 0], 
      state: 1
    }, 
    {
      pos: [4, 4, 0], 
      state: 1
    }, 
    {
      pos: [5, 4, 0], 
      state: 1
    }, 
    {
      pos: [6, 4, 0], 
      state: 1
    }, 
    {
      pos: [7, 4, 0], 
      state: 1
    }, 
    {
      pos: [8, 4, 0], 
      state: 1
    }, 
    {
      pos: [9, 4, 0], 
      state: 1
    }, 
    {
      pos: [10, 4, 0], 
      state: 1
    }, 
    {
      pos: [11, 4, 0], 
      state: 1
    }, 
    {
      pos: [12, 4, 0], 
      state: 1
    }, 
    {
      pos: [0, 4, 1], 
      state: 1
    }, 
    {
      pos: [1, 4, 1], 
      state: 1
    }, 
    {
      pos: [2, 4, 1], 
      state: 1
    }, 
    {
      pos: [3, 4, 1], 
      state: 1
    }, 
    {
      pos: [4, 4, 1], 
      state: 1
    }, 
    {
      pos: [5, 4, 1], 
      state: 1
    }, 
    {
      pos: [6, 4, 1], 
      state: 1
    }, 
    {
      pos: [7, 4, 1], 
      state: 1
    }, 
    {
      pos: [8, 4, 1], 
      state: 1
    }, 
    {
      pos: [9, 4, 1], 
      state: 1
    }, 
    {
      pos: [10, 4, 1], 
      state: 1
    }, 
    {
      pos: [11, 4, 1], 
      state: 1
    }, 
    {
      pos: [12, 4, 1], 
      state: 1
    }, 
    {
      pos: [0, 4, 2], 
      state: 1
    }, 
    {
      pos: [1, 4, 2], 
      state: 1
    }, 
    {
      pos: [2, 4, 2], 
      state: 1
    }, 
    {
      pos: [3, 4, 2], 
      state: 1
    }, 
    {
      pos: [4, 4, 2], 
      state: 1
    }, 
    {
      pos: [5, 4, 2], 
      state: 1
    }, 
    {
      pos: [6, 4, 2], 
      state: 1
    }, 
    {
      pos: [7, 4, 2], 
      state: 1
    }, 
    {
      pos: [8, 4, 2], 
      state: 1
    }, 
    {
      pos: [9, 4, 2], 
      state: 1
    }, 
    {
      pos: [10, 4, 2], 
      state: 1
    }, 
    {
      pos: [11, 4, 2], 
      state: 1
    }, 
    {
      pos: [12, 4, 2], 
      state: 1
    }, 
    {
      pos: [0, 4, 3], 
      state: 1
    }, 
    {
      pos: [1, 4, 3], 
      state: 1
    }, 
    {
      pos: [2, 4, 3], 
      state: 1
    }, 
    {
      pos: [3, 4, 3], 
      state: 1
    }, 
    {
      pos: [4, 4, 3], 
      state: 1
    }, 
    {
      pos: [5, 4, 3], 
      state: 1
    }, 
    {
      pos: [6, 4, 3], 
      state: 1
    }, 
    {
      pos: [7, 4, 3], 
      state: 1
    }, 
    {
      pos: [8, 4, 3], 
      state: 1
    }, 
    {
      pos: [9, 4, 3], 
      state: 1
    }, 
    {
      pos: [10, 4, 3], 
      state: 1
    }, 
    {
      pos: [11, 4, 3], 
      state: 1
    }, 
    {
      pos: [12, 4, 3], 
      state: 1
    }, 
    {
      pos: [0, 4, 4], 
      state: 1
    }, 
    {
      pos: [1, 4, 4], 
      state: 1
    }, 
    {
      pos: [2, 4, 4], 
      state: 1
    }, 
    {
      pos: [3, 4, 4], 
      state: 1
    }, 
    {
      pos: [4, 4, 4], 
      state: 1
    }, 
    {
      pos: [5, 4, 4], 
      state: 1
    }, 
    {
      pos: [6, 4, 4], 
      state: 1
    }, 
    {
      pos: [7, 4, 4], 
      state: 1
    }, 
    {
      pos: [8, 4, 4], 
      state: 1
    }, 
    {
      pos: [9, 4, 4], 
      state: 1
    }, 
    {
      pos: [10, 4, 4], 
      state: 1
    }, 
    {
      pos: [11, 4, 4], 
      state: 1
    }, 
    {
      pos: [12, 4, 4], 
      state: 1
    }, 
    {
      pos: [0, 4, 5], 
      state: 1
    }, 
    {
      pos: [1, 4, 5], 
      state: 1
    }, 
    {
      pos: [2, 4, 5], 
      state: 1
    }, 
    {
      pos: [3, 4, 5], 
      state: 1
    }, 
    {
      pos: [4, 4, 5], 
      state: 1
    }, 
    {
      pos: [5, 4, 5], 
      state: 1
    }, 
    {
      pos: [7, 4, 5], 
      state: 1
    }, 
    {
      pos: [8, 4, 5], 
      state: 1
    }, 
    {
      pos: [9, 4, 5], 
      state: 1
    }, 
    {
      pos: [10, 4, 5], 
      state: 1
    }, 
    {
      pos: [11, 4, 5], 
      state: 1
    }, 
    {
      pos: [12, 4, 5], 
      state: 1
    }, 
    {
      pos: [0, 4, 6], 
      state: 1
    }, 
    {
      pos: [1, 4, 6], 
      state: 1
    }, 
    {
      pos: [2, 4, 6], 
      state: 1
    }, 
    {
      pos: [3, 4, 6], 
      state: 1
    }, 
    {
      pos: [4, 4, 6], 
      state: 1
    }, 
    {
      pos: [8, 4, 6], 
      state: 1
    }, 
    {
      pos: [9, 4, 6], 
      state: 1
    }, 
    {
      pos: [10, 4, 6], 
      state: 1
    }, 
    {
      pos: [11, 4, 6], 
      state: 1
    }, 
    {
      pos: [12, 4, 6], 
      state: 1
    }, 
    {
      pos: [0, 4, 7], 
      state: 1
    }, 
    {
      pos: [1, 4, 7], 
      state: 1
    }, 
    {
      pos: [2, 4, 7], 
      state: 1
    }, 
    {
      pos: [3, 4, 7], 
      state: 1
    }, 
    {
      pos: [6, 4, 7], 
      state: 1
    }, 
    {
      pos: [9, 4, 7], 
      state: 1
    }, 
    {
      pos: [10, 4, 7], 
      state: 1
    }, 
    {
      pos: [11, 4, 7], 
      state: 1
    }, 
    {
      pos: [12, 4, 7], 
      state: 1
    }, 
    {
      pos: [0, 4, 8], 
      state: 1
    }, 
    {
      pos: [1, 4, 8], 
      state: 1
    }, 
    {
      pos: [2, 4, 8], 
      state: 1
    }, 
    {
      pos: [3, 4, 8], 
      state: 1
    }, 
    {
      pos: [5, 4, 8], 
      state: 1
    }, 
    {
      pos: [7, 4, 8], 
      state: 1
    }, 
    {
      pos: [9, 4, 8], 
      state: 1
    }, 
    {
      pos: [10, 4, 8], 
      state: 1
    }, 
    {
      pos: [11, 4, 8], 
      state: 1
    }, 
    {
      pos: [12, 4, 8], 
      state: 1
    }, 
    {
      pos: [0, 4, 9], 
      state: 1
    }, 
    {
      pos: [1, 4, 9], 
      state: 1
    }, 
    {
      pos: [2, 4, 9], 
      state: 1
    }, 
    {
      pos: [4, 4, 9], 
      state: 1
    }, 
    {
      pos: [5, 4, 9], 
      state: 1
    }, 
    {
      pos: [6, 4, 9], 
      state: 1
    }, 
    {
      pos: [7, 4, 9], 
      state: 1
    }, 
    {
      pos: [8, 4, 9], 
      state: 1
    }, 
    {
      pos: [10, 4, 9], 
      state: 1
    }, 
    {
      pos: [11, 4, 9], 
      state: 1
    }, 
    {
      pos: [12, 4, 9], 
      state: 1
    }, 
    {
      pos: [0, 4, 10], 
      state: 1
    }, 
    {
      pos: [1, 4, 10], 
      state: 1
    }, 
    {
      pos: [2, 4, 10], 
      state: 1
    }, 
    {
      pos: [4, 4, 10], 
      state: 1
    }, 
    {
      pos: [5, 4, 10], 
      state: 1
    }, 
    {
      pos: [6, 4, 10], 
      state: 1
    }, 
    {
      pos: [7, 4, 10], 
      state: 1
    }, 
    {
      pos: [8, 4, 10], 
      state: 1
    }, 
    {
      pos: [10, 4, 10], 
      state: 1
    }, 
    {
      pos: [11, 4, 10], 
      state: 1
    }, 
    {
      pos: [12, 4, 10], 
      state: 1
    }, 
    {
      pos: [0, 4, 11], 
      state: 1
    }, 
    {
      pos: [1, 4, 11], 
      state: 1
    }, 
    {
      pos: [3, 4, 11], 
      state: 1
    }, 
    {
      pos: [4, 4, 11], 
      state: 1
    }, 
    {
      pos: [5, 4, 11], 
      state: 1
    }, 
    {
      pos: [6, 4, 11], 
      state: 1
    }, 
    {
      pos: [7, 4, 11], 
      state: 1
    }, 
    {
      pos: [8, 4, 11], 
      state: 1
    }, 
    {
      pos: [9, 4, 11], 
      state: 1
    }, 
    {
      pos: [11, 4, 11], 
      state: 1
    }, 
    {
      pos: [12, 4, 11], 
      state: 1
    }, 
    {
      pos: [0, 4, 12], 
      state: 1
    }, 
    {
      pos: [1, 4, 12], 
      state: 1
    }, 
    {
      pos: [3, 4, 12], 
      state: 1
    }, 
    {
      pos: [4, 4, 12], 
      state: 1
    }, 
    {
      pos: [5, 4, 12], 
      state: 1
    }, 
    {
      pos: [6, 4, 12], 
      state: 1
    }, 
    {
      pos: [7, 4, 12], 
      state: 1
    }, 
    {
      pos: [8, 4, 12], 
      state: 1
    }, 
    {
      pos: [9, 4, 12], 
      state: 1
    }, 
    {
      pos: [11, 4, 12], 
      state: 1
    }, 
    {
      pos: [12, 4, 12], 
      state: 1
    }, 
    {
      pos: [0, 4, 13], 
      state: 1
    }, 
    {
      pos: [1, 4, 13], 
      state: 1
    }, 
    {
      pos: [3, 4, 13], 
      state: 1
    }, 
    {
      pos: [4, 4, 13], 
      state: 1
    }, 
    {
      pos: [5, 4, 13], 
      state: 1
    }, 
    {
      pos: [6, 4, 13], 
      state: 1
    }, 
    {
      pos: [7, 4, 13], 
      state: 1
    }, 
    {
      pos: [8, 4, 13], 
      state: 1
    }, 
    {
      pos: [9, 4, 13], 
      state: 1
    }, 
    {
      pos: [11, 4, 13], 
      state: 1
    }, 
    {
      pos: [12, 4, 13], 
      state: 1
    }, 
    {
      pos: [0, 4, 14], 
      state: 1
    }, 
    {
      pos: [1, 4, 14], 
      state: 1
    }, 
    {
      pos: [3, 4, 14], 
      state: 1
    }, 
    {
      pos: [4, 4, 14], 
      state: 1
    }, 
    {
      pos: [5, 4, 14], 
      state: 1
    }, 
    {
      pos: [7, 4, 14], 
      state: 1
    }, 
    {
      pos: [8, 4, 14], 
      state: 1
    }, 
    {
      pos: [9, 4, 14], 
      state: 1
    }, 
    {
      pos: [11, 4, 14], 
      state: 1
    }, 
    {
      pos: [12, 4, 14], 
      state: 1
    }, 
    {
      pos: [0, 4, 15], 
      state: 1
    }, 
    {
      pos: [1, 4, 15], 
      state: 1
    }, 
    {
      pos: [3, 4, 15], 
      state: 1
    }, 
    {
      pos: [4, 4, 15], 
      state: 1
    }, 
    {
      pos: [5, 4, 15], 
      state: 1
    }, 
    {
      pos: [6, 4, 15], 
      state: 1
    }, 
    {
      pos: [7, 4, 15], 
      state: 1
    }, 
    {
      pos: [8, 4, 15], 
      state: 1
    }, 
    {
      pos: [9, 4, 15], 
      state: 1
    }, 
    {
      pos: [11, 4, 15], 
      state: 1
    }, 
    {
      pos: [12, 4, 15], 
      state: 1
    }, 
    {
      pos: [0, 4, 16], 
      state: 1
    }, 
    {
      pos: [1, 4, 16], 
      state: 1
    }, 
    {
      pos: [3, 4, 16], 
      state: 1
    }, 
    {
      pos: [4, 4, 16], 
      state: 1
    }, 
    {
      pos: [5, 4, 16], 
      state: 1
    }, 
    {
      pos: [6, 4, 16], 
      state: 1
    }, 
    {
      pos: [7, 4, 16], 
      state: 1
    }, 
    {
      pos: [8, 4, 16], 
      state: 1
    }, 
    {
      pos: [9, 4, 16], 
      state: 1
    }, 
    {
      pos: [11, 4, 16], 
      state: 1
    }, 
    {
      pos: [12, 4, 16], 
      state: 1
    }, 
    {
      pos: [0, 4, 17], 
      state: 1
    }, 
    {
      pos: [1, 4, 17], 
      state: 1
    }, 
    {
      pos: [3, 4, 17], 
      state: 1
    }, 
    {
      pos: [4, 4, 17], 
      state: 1
    }, 
    {
      pos: [5, 4, 17], 
      state: 1
    }, 
    {
      pos: [6, 4, 17], 
      state: 1
    }, 
    {
      pos: [7, 4, 17], 
      state: 1
    }, 
    {
      pos: [8, 4, 17], 
      state: 1
    }, 
    {
      pos: [9, 4, 17], 
      state: 1
    }, 
    {
      pos: [11, 4, 17], 
      state: 1
    }, 
    {
      pos: [12, 4, 17], 
      state: 1
    }, 
    {
      pos: [0, 4, 18], 
      state: 1
    }, 
    {
      pos: [1, 4, 18], 
      state: 1
    }, 
    {
      pos: [3, 4, 18], 
      state: 1
    }, 
    {
      pos: [4, 4, 18], 
      state: 1
    }, 
    {
      pos: [5, 4, 18], 
      state: 1
    }, 
    {
      pos: [6, 4, 18], 
      state: 1
    }, 
    {
      pos: [7, 4, 18], 
      state: 1
    }, 
    {
      pos: [8, 4, 18], 
      state: 1
    }, 
    {
      pos: [9, 4, 18], 
      state: 1
    }, 
    {
      pos: [11, 4, 18], 
      state: 1
    }, 
    {
      pos: [12, 4, 18], 
      state: 1
    }, 
    {
      pos: [0, 4, 19], 
      state: 1
    }, 
    {
      pos: [1, 4, 19], 
      state: 1
    }, 
    {
      pos: [3, 4, 19], 
      state: 1
    }, 
    {
      pos: [4, 4, 19], 
      state: 1
    }, 
    {
      pos: [5, 4, 19], 
      state: 1
    }, 
    {
      pos: [6, 4, 19], 
      state: 1
    }, 
    {
      pos: [7, 4, 19], 
      state: 1
    }, 
    {
      pos: [8, 4, 19], 
      state: 7
    }, 
    {
      pos: [9, 4, 19], 
      state: 7
    }, 
    {
      pos: [11, 4, 19], 
      state: 1
    }, 
    {
      pos: [12, 4, 19], 
      state: 1
    }, 
    {
      pos: [0, 4, 20], 
      state: 1
    }, 
    {
      pos: [1, 4, 20], 
      state: 1
    }, 
    {
      pos: [3, 4, 20], 
      state: 1
    }, 
    {
      pos: [4, 4, 20], 
      state: 1
    }, 
    {
      pos: [5, 4, 20], 
      state: 1
    }, 
    {
      pos: [6, 4, 20], 
      state: 1
    }, 
    {
      pos: [7, 4, 20], 
      state: 1
    }, 
    {
      pos: [11, 4, 20], 
      state: 1
    }, 
    {
      pos: [12, 4, 20], 
      state: 1
    }, 
    {
      pos: [0, 4, 21], 
      state: 1
    }, 
    {
      pos: [1, 4, 21], 
      state: 1
    }, 
    {
      pos: [3, 4, 21], 
      state: 1
    }, 
    {
      pos: [4, 4, 21], 
      state: 1
    }, 
    {
      pos: [5, 4, 21], 
      state: 1
    }, 
    {
      pos: [6, 4, 21], 
      state: 1
    }, 
    {
      pos: [7, 4, 21], 
      state: 1
    }, 
    {
      pos: [11, 4, 21], 
      state: 1
    }, 
    {
      pos: [12, 4, 21], 
      state: 1
    }, 
    {
      pos: [0, 4, 22], 
      state: 1
    }, 
    {
      pos: [1, 4, 22], 
      state: 1
    }, 
    {
      pos: [3, 4, 22], 
      state: 1
    }, 
    {
      pos: [4, 4, 22], 
      state: 1
    }, 
    {
      pos: [5, 4, 22], 
      state: 1
    }, 
    {
      pos: [6, 4, 22], 
      state: 1
    }, 
    {
      pos: [7, 4, 22], 
      state: 1
    }, 
    {
      pos: [11, 4, 22], 
      state: 1
    }, 
    {
      pos: [12, 4, 22], 
      state: 1
    }, 
    {
      pos: [0, 4, 23], 
      state: 1
    }, 
    {
      pos: [1, 4, 23], 
      state: 1
    }, 
    {
      pos: [3, 4, 23], 
      state: 1
    }, 
    {
      pos: [4, 4, 23], 
      state: 1
    }, 
    {
      pos: [5, 4, 23], 
      state: 1
    }, 
    {
      pos: [6, 4, 23], 
      state: 1
    }, 
    {
      pos: [7, 4, 23], 
      state: 1
    }, 
    {
      pos: [11, 4, 23], 
      state: 1
    }, 
    {
      pos: [12, 4, 23], 
      state: 1
    }, 
    {
      pos: [0, 4, 24], 
      state: 1
    }, 
    {
      pos: [1, 4, 24], 
      state: 1
    }, 
    {
