{
  size: [13, 24, 29], 
  entities: [
    {
      nbt: {
        Motion: [0.0d, -0.0d, 0.0d], 
        Health: 5s, 
        UUIDLeast: -7695661062048667361L, 
        Invulnerable: 0b, 
        Air: 300s, 
        Dimension: 0, 
        OnGround: 1b, 
        PortalCooldown: 0, 
        Rotation: [122.66803741455078f, 0.0f], 
        FallDistance: 0.0f, 
        Item: {
          Count: 1b, 
          id: "minecraft:dragon_head"
        }, 
        UUIDMost: 2239083118994146168L, 
        Pos: [-1024.6012964727665d, 7.0d, -994.875d], 
        PickupDelay: 0s, 
        Fire: -1s, 
        id: "minecraft:item", 
        Age: 322s
      }, 
      blockPos: [5, 0, 0], 
      pos: [5.398703527233465d, 0.0d, 0.125d]
    }, 
    {
      nbt: {
        Motion: [0.0d, -0.0d, 0.0d], 
        Health: 5s, 
        UUIDLeast: -6883295886898162315L, 
        Invulnerable: 0b, 
        Air: 300s, 
        Dimension: 0, 
        OnGround: 1b, 
        PortalCooldown: 0, 
        Rotation: [226.66976928710938f, 0.0f], 
        FallDistance: 0.0f, 
        Item: {
          Count: 1b, 
          id: "minecraft:potion", 
          tag: {
            Potion: "minecraft:strong_healing"
          }
        }, 
        UUIDMost: 6945015366122491450L, 
        Pos: [-1023.6875d, 14.125d, -969.4243165492055d], 
        PickupDelay: 0s, 
        Fire: -1s, 
        id: "minecraft:item", 
        Age: 322s
      }, 
      blockPos: [6, 7, 25], 
      pos: [6.3125d, 7.125d, 25.575683450794486d]
    }, 
    {
      nbt: {
        Motion: [0.0d, -0.0d, 0.0d], 
        Health: 5s, 
        UUIDLeast: -6006735563912788582L, 
        Invulnerable: 0b, 
        Air: 300s, 
        Dimension: 0, 
        OnGround: 1b, 
        PortalCooldown: 0, 
        Rotation: [256.96685791015625f, 0.0f], 
        FallDistance: 0.0f, 
        Item: {
          Count: 1b, 
          id: "minecraft:potion", 
          tag: {
            Potion: "minecraft:strong_healing"
          }
        }, 
        UUIDMost: -4708082166652058195L, 
        Pos: [-1023.2750662100219d, 14.125d, -969.9505169248425d], 
        PickupDelay: 0s, 
        Fire: -1s, 
        id: "minecraft:item", 
        Age: 322s
      }, 
      blockPos: [6, 7, 25], 
      pos: [6.724933789978081d, 7.125d, 25.049483075157468d]
    }
  ], 
  author: "jeb_", 
  blocks: [
    {
      pos: [6, 7, 1], 
      state: 0
    }, 
    {
      pos: [6, 7, 2], 
      state: 0
    }, 
    {
      pos: [6, 12, 2], 
      state: 0
    }, 
    {
      pos: [6, 6, 3], 
      state: 0
    }, 
    {
      pos: [6, 7, 3], 
      state: 0
    }, 
    {
      pos: [6, 12, 3], 
      state: 0
    }, 
    {
      pos: [6, 5, 4], 
      state: 0
    }, 
    {
      pos: [6, 6, 4], 
      state: 0
    }, 
    {
      pos: [6, 7, 4], 
      state: 0
    }, 
    {
      pos: [6, 8, 4], 
      state: 1
    }, 
    {
      pos: [6, 11, 4], 
      state: 0
    }, 
    {
      pos: [6, 3, 5], 
      state: 0
    }, 
    {
      pos: [6, 4, 5], 
      state: 1
    }, 
    {
      pos: [6, 5, 5], 
      state: 0
    }, 
    {
      pos: [6, 6, 5], 
      state: 1
    }, 
    {
      pos: [5, 7, 5], 
      state: 1
    }, 
    {
      pos: [6, 7, 5], 
      state: 1
    }, 
    {
      pos: [7, 7, 5], 
      state: 1
    }, 
    {
      pos: [5, 8, 5], 
      state: 1
    }, 
    {
      pos: [7, 8, 5], 
      state: 1
    }, 
    {
      pos: [6, 11, 5], 
      state: 0
    }, 
    {
      pos: [6, 2, 6], 
      state: 0
    }, 
    {
      pos: [6, 3, 6], 
      state: 0
    }, 
    {
      pos: [5, 4, 6], 
      state: 1
    }, 
    {
      pos: [6, 4, 6], 
      state: 1
    }, 
    {
      pos: [7, 4, 6], 
      state: 1
    }, 
    {
      pos: [5, 5, 6], 
      state: 1
    }, 
    {
      pos: [6, 5, 6], 
      state: 1
    }, 
    {
      pos: [7, 5, 6], 
      state: 1
    }, 
    {
      pos: [5, 6, 6], 
      state: 1
    }, 
    {
      pos: [7, 6, 6], 
      state: 1
    }, 
    {
      pos: [4, 7, 6], 
      state: 1
    }, 
    {
      pos: [5, 7, 6], 
      state: 1
    }, 
    {
      pos: [6, 7, 6], 
      state: 1
    }, 
    {
      pos: [7, 7, 6], 
      state: 1
    }, 
    {
      pos: [8, 7, 6], 
      state: 1
    }, 
    {
      pos: [4, 8, 6], 
      state: 1
    }, 
    {
      pos: [8, 8, 6], 
      state: 1
    }, 
    {
      pos: [6, 10, 6], 
      state: 0
    }, 
    {
      pos: [6, 2, 7], 
      state: 0
    }, 
    {
      pos: [5, 3, 7], 
      state: 1
    }, 
    {
      pos: [6, 3, 7], 
      state: 1
    }, 
    {
      pos: [7, 3, 7], 
      state: 1
    }, 
    {
      pos: [4, 4, 7], 
      state: 1
    }, 
    {
      pos: [8, 4, 7], 
      state: 1
    }, 
    {
      pos: [4, 5, 7], 
      state: 1
    }, 
    {
      pos: [8, 5, 7], 
      state: 1
    }, 
    {
      pos: [4, 6, 7], 
      state: 1
    }, 
    {
      pos: [8, 6, 7], 
      state: 1
    }, 
    {
      pos: [4, 7, 7], 
      state: 1
    }, 
    {
      pos: [5, 7, 7], 
      state: 1
    }, 
    {
      pos: [6, 7, 7], 
      state: 1
    }, 
    {
      pos: [7, 7, 7], 
      state: 1
    }, 
    {
      pos: [8, 7, 7], 
      state: 1
    }, 
    {
      pos: [6, 10, 7], 
      state: 0
    }, 
    {
      pos: [6, 1, 8], 
      state: 0
    }, 
    {
      pos: [5, 2, 8], 
      state: 1
    }, 
    {
      pos: [6, 2, 8], 
      state: 0
    }, 
    {
      pos: [7, 2, 8], 
      state: 1
    }, 
    {
      pos: [4, 3, 8], 
      state: 1
    }, 
    {
      pos: [5, 3, 8], 
      state: 1
    }, 
    {
      pos: [6, 3, 8], 
      state: 1
    }, 
    {
      pos: [7, 3, 8], 
      state: 1
    }, 
    {
      pos: [8, 3, 8], 
      state: 1
    }, 
    {
      pos: [4, 4, 8], 
      state: 1
    }, 
    {
      pos: [8, 4, 8], 
      state: 1
    }, 
    {
      pos: [4, 5, 8], 
      state: 1
    }, 
    {
      pos: [8, 5, 8], 
      state: 1
    }, 
    {
      pos: [4, 6, 8], 
      state: 1
    }, 
    {
      pos: [8, 6, 8], 
      state: 1
    }, 
    {
      pos: [3, 7, 8], 
      state: 1
    }, 
    {
      pos: [4, 7, 8], 
      state: 1
    }, 
    {
      pos: [5, 7, 8], 
      state: 1
    }, 
    {
      pos: [6, 7, 8], 
      state: 1
    }, 
    {
      pos: [7, 7, 8], 
      state: 1
    }, 
    {
      pos: [8, 7, 8], 
      state: 1
    }, 
    {
      pos: [9, 7, 8], 
      state: 1
    }, 
    {
      pos: [3, 8, 8], 
      state: 1
    }, 
    {
      pos: [9, 8, 8], 
      state: 1
    }, 
    {
      pos: [6, 9, 8], 
      state: 0
    }, 
    {
      pos: [6, 1, 9], 
      state: 0
    }, 
    {
      pos: [5, 2, 9], 
      state: 1
    }, 
    {
      pos: [6, 2, 9], 
      state: 0
    }, 
    {
      pos: [7, 2, 9], 
      state: 1
    }, 
    {
      pos: [4, 3, 9], 
      state: 1
    }, 
    {
      pos: [8, 3, 9], 
      state: 1
    }, 
    {
      pos: [3, 4, 9], 
      state: 1
    }, 
    {
      pos: [9, 4, 9], 
      state: 1
    }, 
    {
      pos: [3, 5, 9], 
      state: 1
    }, 
    {
      pos: [9, 5, 9], 
      state: 1
    }, 
    {
      pos: [3, 6, 9], 
      state: 1
    }, 
    {
      pos: [9, 6, 9], 
      state: 1
    }, 
    {
      pos: [3, 7, 9], 
      state: 1
    }, 
    {
      pos: [4, 7, 9], 
      state: 1
    }, 
    {
      pos: [5, 7, 9], 
      state: 1
    }, 
    {
      pos: [6, 7, 9], 
      state: 1
    }, 
    {
      pos: [7, 7, 9], 
      state: 1
    }, 
    {
      pos: [8, 7, 9], 
      state: 1
    }, 
    {
      pos: [9, 7, 9], 
      state: 1
    }, 
    {
      pos: [6, 9, 9], 
      state: 0
    }, 
    {
      pos: [6, 1, 10], 
      state: 0
    }, 
    {
      pos: [4, 2, 10], 
      state: 1
    }, 
    {
      pos: [5, 2, 10], 
      state: 1
    }, 
    {
      pos: [6, 2, 10], 
      state: 0
    }, 
    {
      pos: [7, 2, 10], 
      state: 1
    }, 
    {
      pos: [8, 2, 10], 
      state: 1
    }, 
    {
      pos: [3, 3, 10], 
      state: 1
    }, 
    {
      pos: [9, 3, 10], 
      state: 1
    }, 
    {
      pos: [3, 4, 10], 
      state: 1
    }, 
    {
      pos: [9, 4, 10], 
      state: 1
    }, 
    {
      pos: [3, 5, 10], 
      state: 1
    }, 
    {
      pos: [9, 5, 10], 
      state: 1
    }, 
    {
      pos: [3, 6, 10], 
      state: 1
    }, 
    {
      pos: [9, 6, 10], 
      state: 1
    }, 
    {
      pos: [2, 7, 10], 
      state: 1
    }, 
    {
      pos: [3, 7, 10], 
      state: 1
    }, 
    {
      pos: [4, 7, 10], 
      state: 1
    }, 
    {
      pos: [5, 7, 10], 
      state: 1
    }, 
    {
      pos: [6, 7, 10], 
      state: 1
    }, 
    {
      pos: [7, 7, 10], 
      state: 1
    }, 
    {
      pos: [8, 7, 10], 
      state: 1
    }, 
    {
      pos: [9, 7, 10], 
      state: 1
    }, 
    {
      pos: [10, 7, 10], 
      state: 1
    }, 
    {
      pos: [2, 8, 10], 
      state: 1
    }, 
    {
      pos: [6, 8, 10], 
      state: 0
    }, 
    {
      pos: [10, 8, 10], 
      state: 1
    }, 
    {
      pos: [6, 0, 11], 
      state: 0
    }, 
    {
      pos: [6, 1, 11], 
      state: 0
    }, 
    {
      pos: [4, 2, 11], 
      state: 1
    }, 
    {
      pos: [5, 2, 11], 
      state: 1
    }, 
    {
      pos: [6, 2, 11], 
      state: 0
    }, 
    {
      pos: [7, 2, 11], 
      state: 1
    }, 
    {
      pos: [8, 2, 11], 
      state: 1
    }, 
    {
      pos: [3, 3, 11], 
      state: 1
    }, 
    {
      pos: [9, 3, 11], 
      state: 1
    }, 
    {
      pos: [2, 4, 11], 
      state: 1
    }, 
    {
      pos: [10, 4, 11], 
      state: 1
    }, 
    {
      pos: [2, 5, 11], 
      state: 1
    }, 
    {
      pos: [10, 5, 11], 
      state: 1
    }, 
    {
      pos: [2, 6, 11], 
      state: 1
    }, 
    {
      pos: [10, 6, 11], 
      state: 1
    }, 
    {
      pos: [2, 7, 11], 
      state: 1
    }, 
    {
      pos: [3, 7, 11], 
      state: 1
    }, 
    {
      pos: [4, 7, 11], 
      state: 1
    }, 
    {
      pos: [5, 7, 11], 
      state: 1
    }, 
    {
      pos: [6, 7, 11], 
      state: 1
    }, 
    {
      pos: [7, 7, 11], 
      state: 1
    }, 
    {
      pos: [8, 7, 11], 
      state: 1
    }, 
    {
      pos: [9, 7, 11], 
      state: 1
    }, 
    {
      pos: [10, 7, 11], 
      state: 1
    }, 
    {
      pos: [6, 8, 11], 
      state: 0
    }, 
    {
      pos: [6, 0, 12], 
      state: 0
    }, 
    {
      pos: [5, 1, 12], 
      state: 1
    }, 
    {
      pos: [6, 1, 12], 
      state: 1
    }, 
    {
      pos: [7, 1, 12], 
      state: 1
    }, 
    {
      pos: [4, 2, 12], 
      state: 1
    }, 
    {
      pos: [5, 2, 12], 
      state: 2
    }, 
    {
      pos: [6, 2, 12], 
      state: 0
    }, 
    {
      pos: [7, 2, 12], 
      state: 2
    }, 
    {
      pos: [8, 2, 12], 
      state: 1
    }, 
    {
      pos: [3, 3, 12], 
      state: 1
    }, 
    {
      pos: [9, 3, 12], 
      state: 1
    }, 
    {
      pos: [2, 4, 12], 
      state: 1
    }, 
    {
      pos: [10, 4, 12], 
      state: 1
    }, 
    {
      pos: [2, 5, 12], 
      state: 1
    }, 
    {
      pos: [10, 5, 12], 
      state: 1
    }, 
    {
      pos: [2, 6, 12], 
      state: 1
    }, 
    {
      pos: [10, 6, 12], 
      state: 1
    }, 
    {
      pos: [2, 7, 12], 
      state: 1
    }, 
    {
      pos: [3, 7, 12], 
      state: 1
    }, 
    {
      pos: [4, 7, 12], 
      state: 1
    }, 
    {
      pos: [5, 7, 12], 
      state: 1
    }, 
    {
      pos: [6, 7, 12], 
      state: 0
    }, 
    {
      pos: [7, 7, 12], 
      state: 1
    }, 
    {
      pos: [8, 7, 12], 
      state: 1
    }, 
    {
      pos: [9, 7, 12], 
      state: 1
    }, 
    {
      pos: [10, 7, 12], 
      state: 1
    }, 
    {
      pos: [6, 0, 13], 
      state: 0
    }, 
    {
      pos: [5, 1, 13], 
      state: 1
    }, 
    {
      pos: [6, 1, 13], 
      state: 1
    }, 
    {
      pos: [7, 1, 13], 
      state: 1
    }, 
    {
      pos: [4, 2, 13], 
      state: 1
    }, 
    {
      pos: [5, 2, 13], 
      state: 2
    }, 
    {
      pos: [6, 2, 13], 
      state: 0
    }, 
    {
      pos: [7, 2, 13], 
      state: 2
    }, 
    {
      pos: [8, 2, 13], 
      state: 1
    }, 
    {
      pos: [3, 3, 13], 
      state: 1
    }, 
    {
      pos: [9, 3, 13], 
      state: 1
    }, 
    {
      pos: [2, 4, 13], 
      state: 1
    }, 
    {
      pos: [10, 4, 13], 
      state: 1
    }, 
    {
      pos: [2, 5, 13], 
      state: 1
    }, 
    {
      pos: [10, 5, 13], 
      state: 1
    }, 
    {
      pos: [2, 7, 13], 
      state: 1
    }, 
    {
      pos: [3, 7, 13], 
      state: 1
    }, 
    {
      pos: [4, 7, 13], 
      state: 1
    }, 
    {
      pos: [5, 7, 13], 
      state: 1
    }, 
    {
      pos: [7, 7, 13], 
      state: 1
    }, 
    {
      pos: [8, 7, 13], 
      state: 1
    }, 
    {
      pos: [9, 7, 13], 
      state: 1
    }, 
    {
      pos: [10, 7, 13], 
      state: 1
    }, 
    {
      pos: [2, 8, 13], 
      state: 1
    }, 
    {
      pos: [10, 8, 13], 
      state: 1
    }, 
    {
      pos: [6, 0, 14], 
      state: 0
    }, 
    {
      pos: [5, 1, 14], 
      state: 1
    }, 
    {
      pos: [6, 1, 14], 
      state: 1
    }, 
    {
      pos: [7, 1, 14], 
      state: 1
    }, 
    {
      pos: [4, 2, 14], 
      state: 1
    }, 
    {
      pos: [5, 2, 14], 
      state: 2
    }, 
    {
      pos: [6, 2, 14], 
      state: 3
    }, 
    {
      pos: [7, 2, 14], 
      state: 2
    }, 
    {
      pos: [8, 2, 14], 
      state: 1
    }, 
    {
      pos: [3, 3, 14], 
      state: 1
    }, 
    {
      pos: [6, 3, 14], 
      state: 3
    }, 
    {
      pos: [9, 3, 14], 
      state: 1
    }, 
    {
      pos: [2, 4, 14], 
      state: 1
    }, 
    {
      pos: [6, 4, 14], 
      state: 3
    }, 
    {
      pos: [10, 4, 14], 
      state: 1
    }, 
    {
      pos: [2, 5, 14], 
      state: 1
    }, 
    {
      pos: [6, 5, 14], 
      state: 3
    }, 
    {
      pos: [10, 5, 14], 
      state: 1
    }, 
    {
      pos: [2, 6, 14], 
      state: 1
    }, 
    {
      pos: [6, 6, 14], 
      state: 3
    }, 
    {
      pos: [10, 6, 14], 
      state: 1
    }, 
    {
      pos: [2, 7, 14], 
      state: 1
    }, 
    {
      pos: [3, 7, 14], 
      state: 1
    }, 
    {
      pos: [4, 7, 14], 
      state: 1
    }, 
    {
      pos: [5, 7, 14], 
      state: 1
    }, 
    {
      pos: [6, 7, 14], 
      state: 3
    }, 
    {
      pos: [7, 7, 14], 
      state: 1
    }, 
    {
      pos: [8, 7, 14], 
      state: 1
    }, 
    {
      pos: [9, 7, 14], 
      state: 1
    }, 
    {
      pos: [10, 7, 14], 
      state: 1
    }, 
    {
      pos: [6, 8, 14], 
      state: 3
    }, 
    {
      pos: [6, 9, 14], 
      state: 3
    }, 
    {
      pos: [6, 10, 14], 
      state: 3
    }, 
    {
      pos: [6, 11, 14], 
      state: 3
    }, 
    {
      pos: [6, 12, 14], 
      state: 3
    }, 
    {
      pos: [6, 13, 14], 
      state: 3
    }, 
    {
      pos: [6, 14, 14], 
      state: 3
    }, 
    {
      pos: [6, 15, 14], 
      state: 3
    }, 
    {
      pos: [6, 16, 14], 
      state: 3
    }, 
    {
      pos: [6, 17, 14], 
      state: 3
    }, 
    {
      pos: [6, 18, 14], 
      state: 3
    }, 
    {
      pos: [6, 19, 14], 
      state: 3
    }, 
    {
      pos: [6, 20, 14], 
      state: 3
    }, 
    {
      pos: [6, 21, 14], 
      state: 3
    }, 
    {
      pos: [6, 22, 14], 
      state: 3
    }, 
    {
      pos: [6, 23, 14], 
      state: 1
    }, 
    {
      pos: [6, 0, 15], 
      state: 0
    }, 
    {
      pos: [5, 1, 15], 
      state: 1
    }, 
    {
      pos: [6, 1, 15], 
      state: 1
    }, 
    {
      pos: [7, 1, 15], 
      state: 1
    }, 
    {
      pos: [4, 2, 15], 
      state: 1
    }, 
    {
      pos: [5, 2, 15], 
      state: 2
    }, 
    {
      pos: [6, 2, 15], 
      state: 0
    }, 
    {
      pos: [7, 2, 15], 
      state: 2
    }, 
    {
      pos: [8, 2, 15], 
      state: 1
    }, 
    {
      pos: [3, 3, 15], 
      state: 1
    }, 
    {
      pos: [9, 3, 15], 
      state: 1
    }, 
    {
      pos: [2, 4, 15], 
      state: 1
    }, 
    {
      pos: [10, 4, 15], 
      state: 1
    }, 
    {
      pos: [2, 5, 15], 
      state: 1
    }, 
    {
      pos: [10, 5, 15], 
      state: 1
    }, 
    {
      pos: [2, 6, 15], 
      state: 1
    }, 
    {
      pos: [10, 6, 15], 
      state: 1
    }, 
    {
      pos: [2, 7, 15], 
      state: 1
    }, 
    {
      pos: [3, 7, 15], 
      state: 1
    }, 
    {
      pos: [4, 7, 15], 
      state: 1
    }, 
    {
      pos: [5, 7, 15], 
      state: 1
    }, 
    {
      pos: [6, 7, 15], 
      state: 1
    }, 
    {
      pos: [7, 7, 15], 
      state: 1
    }, 
    {
      pos: [8, 7, 15], 
      state: 1
    }, 
    {
      pos: [9, 7, 15], 
      state: 1
    }, 
    {
      pos: [10, 7, 15], 
      state: 1
    }, 
    {
      pos: [6, 0, 16], 
      state: 0
    }, 
    {
      pos: [5, 1, 16], 
      state: 1
    }, 
    {
      pos: [6, 1, 16], 
      state: 1
    }, 
    {
      pos: [7, 1, 16], 
      state: 1
    }, 
    {
      pos: [4, 2, 16], 
      state: 1
    }, 
    {
      pos: [5, 2, 16], 
      state: 2
    }, 
    {
      pos: [6, 2, 16], 
      state: 0
    }, 
    {
      pos: [7, 2, 16], 
      state: 2
    }, 
    {
      pos: [8, 2, 16], 
      state: 1
    }, 
    {
      pos: [3, 3, 16], 
      state: 1
    }, 
    {
      pos: [8, 3, 16], 
      state: 1
    }, 
    {
      pos: [9, 3, 16], 
      state: 1
    }, 
    {
      pos: [2, 4, 16], 
      state: 1
    }, 
    {
      pos: [10, 4, 16], 
      state: 1
    }, 
    {
      pos: [2, 5, 16], 
      state: 1
    }, 
    {
      pos: [10, 5, 16], 
      state: 1
    }, 
    {
      pos: [2, 7, 16], 
      state: 1
    }, 
    {
      pos: [3, 7, 16], 
      state: 1
    }, 
    {
      pos: [4, 7, 16], 
      state: 1
    }, 
    {
      pos: [5, 7, 16], 
      state: 1
    }, 
    {
      pos: [6, 7, 16], 
      state: 1
    }, 
    {
      pos: [7, 7, 16], 
      state: 1
    }, 
    {
      pos: [8, 7, 16], 
      state: 1
    }, 
    {
      pos: [9, 7, 16], 
      state: 1
    }, 
    {
      pos: [10, 7, 16], 
      state: 1
    }, 
    {
      pos: [2, 8, 16], 
      state: 1
    }, 
    {
      pos: [10, 8, 16], 
      state: 1
    }, 
    {
      pos: [6, 0, 17], 
      state: 0
    }, 
    {
      pos: [5, 1, 17], 
      state: 1
    }, 
    {
      pos: [6, 1, 17], 
      state: 1
    }, 
    {
      pos: [7, 1, 17], 
      state: 1
    }, 
    {
      pos: [4, 2, 17], 
      state: 1
    }, 
    {
      pos: [5, 2, 17], 
      state: 2
    }, 
    {
      pos: [6, 2, 17], 
      state: 0
    }, 
    {
      pos: [7, 2, 17], 
      state: 2
    }, 
    {
      pos: [8, 2, 17], 
      state: 1
    }, 
    {
      pos: [3, 3, 17], 
      state: 1
    }, 
    {
      pos: [8, 3, 17], 
      state: 1
    }, 
    {
      pos: [9, 3, 17], 
      state: 1
    }, 
    {
      pos: [2, 4, 17], 
      state: 1
    }, 
    {
      pos: [10, 4, 17], 
      state: 1
    }, 
    {
      pos: [2, 5, 17], 
      state: 1
    }, 
    {
      pos: [10, 5, 17], 
      state: 1
    }, 
    {
      pos: [2, 6, 17], 
      state: 1
    }, 
    {
      pos: [10, 6, 17], 
      state: 1
    }, 
    {
      pos: [2, 7, 17], 
      state: 1
    }, 
    {
      pos: [3, 7, 17], 
      state: 1
    }, 
    {
      pos: [4, 7, 17], 
      state: 1
    }, 
    {
      pos: [5, 7, 17], 
      state: 1
    }, 
    {
      pos: [6, 7, 17], 
      state: 1
    }, 
    {
      pos: [7, 7, 17], 
      state: 1
    }, 
    {
      pos: [8, 7, 17], 
      state: 1
    }, 
    {
      pos: [9, 7, 17], 
      state: 1
    }, 
    {
      pos: [10, 7, 17], 
      state: 1
    }, 
    {
      pos: [6, 0, 18], 
      state: 0
    }, 
    {
      pos: [5, 1, 18], 
      state: 1
    }, 
    {
      pos: [6, 1, 18], 
      state: 1
    }, 
    {
      pos: [7, 1, 18], 
      state: 1
    }, 
    {
      pos: [4, 2, 18], 
      state: 1
    }, 
    {
      pos: [5, 2, 18], 
      state: 2
    }, 
    {
      pos: [6, 2, 18], 
      state: 0
    }, 
    {
      pos: [7, 2, 18], 
      state: 2
    }, 
    {
      pos: [8, 2, 18], 
      state: 1
    }, 
    {
      pos: [3, 3, 18], 
      state: 1
    }, 
    {
      pos: [8, 3, 18], 
      state: 1
    }, 
    {
      pos: [9, 3, 18], 
      state: 1
    }, 
    {
      pos: [2, 4, 18], 
      state: 1
    }, 
    {
      pos: [10, 4, 18], 
      state: 1
    }, 
    {
      pos: [2, 5, 18], 
      state: 1
    }, 
    {
      pos: [10, 5, 18], 
      state: 1
    }, 
    {
      pos: [2, 6, 18], 
      state: 1
    }, 
    {
      pos: [10, 6, 18], 
      state: 1
    }, 
    {
      pos: [2, 7, 18], 
      state: 1
    }, 
    {
      pos: [3, 7, 18], 
      state: 1
    }, 
    {
      pos: [4, 7, 18], 
      state: 1
    }, 
    {
      pos: [5, 7, 18], 
      state: 1
    }, 
    {
      pos: [6, 7, 18], 
      state: 1
    }, 
    {
      pos: [7, 7, 18], 
      state: 1
    }, 
    {
      pos: [8, 7, 18], 
      state: 1
    }, 
    {
      pos: [9, 7, 18], 
      state: 1
    }, 
    {
      pos: [10, 7, 18], 
      state: 1
    }, 
    {
      pos: [6, 0, 19], 
      state: 0
    }, 
    {
      pos: [5, 1, 19], 
      state: 1
    }, 
    {
      pos: [6, 1, 19], 
      state: 1
    }, 
    {
      pos: [7, 1, 19], 
      state: 1
    }, 
    {
      pos: [4, 2, 19], 
      state: 1
    }, 
    {
      pos: [5, 2, 19], 
      state: 2
    }, 
    {
      pos: [6, 2, 19], 
      state: 0
    }, 
    {
      pos: [7, 2, 19], 
      state: 2
    }, 
    {
      pos: [8, 2, 19], 
      state: 1
    }, 
    {
      pos: [3, 3, 19], 
      state: 1
    }, 
    {
      pos: [8, 3, 19], 
      state: 1
    }, 
    {
      pos: [9, 3, 19], 
      state: 1
    }, 
    {
      pos: [2, 4, 19], 
      state: 1
    }, 
    {
      pos: [10, 4, 19], 
      state: 1
    }, 
    {
      pos: [2, 5, 19], 
      state: 1
    }, 
    {
      pos: [10, 5, 19], 
      state: 1
    }, 
    {
      pos: [2, 6, 19], 
      state: 1
    }, 
    {
      pos: [3, 6, 19], 
      state: 1
    }, 
    {
      pos: [4, 6, 19], 
      state: 1
    }, 
    {
      pos: [5, 6, 19], 
      state: 1
    }, 
    {
      pos: [6, 6, 19], 
      state: 1
    }, 
    {
      pos: [7, 6, 19], 
      state: 1
    }, 
    {
      pos: [10, 6, 19], 
      state: 1
    }, 
    {
      pos: [2, 7, 19], 
      state: 1
    }, 
    {
      pos: [3, 7, 19], 
      state: 1
    }, 
    {
      pos: [6, 7, 19], 
      state: 1
    }, 
    {
      pos: [7, 7, 19], 
      state: 1
    }, 
    {
      pos: [10, 7, 19], 
      state: 1
    }, 
    {
      pos: [2, 8, 19], 
      state: 1
    }, 
    {
      pos: [10, 8, 19], 
      state: 1
    }, 
    {
      pos: [6, 0, 20], 
      state: 0
    }, 
    {
      pos: [5, 1, 20], 
      state: 1
    }, 
    {
      pos: [6, 1, 20], 
      state: 1
    }, 
    {
      pos: [7, 1, 20], 
      state: 1
    }, 
    {
      pos: [4, 2, 20], 
      state: 1
    }, 
    {
      pos: [5, 2, 20], 
      state: 2
    }, 
    {
      pos: [6, 2, 20], 
      state: 0
    }, 
    {
      pos: [7, 2, 20], 
      state: 2
    }, 
    {
      pos: [8, 2, 20], 
      state: 1
    }, 
    {
      pos: [3, 3, 20], 
      state: 1
    }, 
    {
      pos: [8, 3, 20], 
      state: 1
    }, 
    {
      pos: [9, 3, 20], 
      state: 1
    }, 
    {
      pos: [2, 4, 20], 
      state: 1
    }, 
    {
      pos: [8, 4, 20], 
      state: 1
    }, 
    {
      pos: [9, 4, 20], 
      state: 1
    }, 
    {
      pos: [10, 4, 20], 
      state: 1
    }, 
    {
      pos: [2, 5, 20], 
      state: 1
    }, 
    {
      pos: [3, 5, 20], 
      state: 1
    }, 
    {
      pos: [4, 5, 20], 
      state: 1
    }, 
    {
      pos: [5, 5, 20], 
      state: 1
    }, 
    {
      pos: [6, 5, 20], 
      state: 1
    }, 
    {
      pos: [7, 5, 20], 
      state: 1
    }, 
    {
      pos: [10, 5, 20], 
      state: 1
    }, 
    {
      pos: [2, 6, 20], 
      state: 1
    }, 
    {
      pos: [3, 6, 20], 
      state: 1
    }, 
    {
      pos: [6, 6, 20], 
      state: 1
    }, 
    {
      pos: [7, 6, 20], 
      state: 1
    }, 
    {
      pos: [10, 6, 20], 
      state: 1
    }, 
    {
      pos: [2, 7, 20], 
      state: 1
    }, 
    {
      pos: [3, 7, 20], 
      state: 1
    }, 
    {
      pos: [6, 7, 20], 
      state: 1
    }, 
    {
      pos: [7, 7, 20], 
      state: 1
    }, 
    {
      pos: [10, 7, 20], 
      state: 1
    }, 
    {
      pos: [2, 8, 20], 
      state: 1
    }, 
    {
      pos: [8, 8, 20], 
      state: 1
    }, 
    {
      pos: [9, 8, 20], 
      state: 1
    }, 
    {
      pos: [10, 8, 20], 
      state: 1
    }, 
    {
      pos: [1, 9, 20], 
      state: 1
    }, 
    {
      pos: [2, 9, 20], 
      state: 1
    }, 
    {
      pos: [3, 9, 20], 
      state: 1
    }, 
    {
      pos: [6, 9, 20], 
      state: 1
    }, 
    {
      pos: [7, 9, 20], 
      state: 1
    }, 
    {
      pos: [10, 9, 20], 
      state: 1
    }, 
    {
      pos: [11, 9, 20], 
      state: 1
    }, 
    {
      pos: [1, 10, 20], 
      state: 1
    }, 
    {
      pos: [3, 10, 20], 
      state: 1
    }, 
    {
      pos: [6, 10, 20], 
      state: 1
    }, 
    {
      pos: [7, 10, 20], 
      state: 1
    }, 
    {
      pos: [10, 10, 20], 
      state: 1
    }, 
    {
      pos: [11, 10, 20], 
      state: 1
    }, 
    {
      pos: [6, 0, 21], 
      state: 0
    }, 
    {
      pos: [5, 1, 21], 
      state: 1
    }, 
    {
      pos: [6, 1, 21], 
      state: 1
    }, 
    {
      pos: [7, 1, 21], 
      state: 1
    }, 
    {
      pos: [4, 2, 21], 
      state: 1
    }, 
    {
      pos: [5, 2, 21], 
      state: 2
    }, 
    {
      pos: [6, 2, 21], 
      state: 0
    }, 
    {
      pos: [7, 2, 21], 
      state: 2
    }, 
    {
      pos: [8, 2, 21], 
      state: 1
    }, 
    {
      pos: [3, 3, 21], 
      state: 1
    }, 
    {
      pos: [8, 3, 21], 
      state: 1
    }, 
    {
      pos: [9, 3, 21], 
      state: 1
    }, 
    {
      pos: [2, 4, 21], 
      state: 1
    }, 
    {
      pos: [8, 4, 21], 
      state: 1
    }, 
    {
      pos: [9, 4, 21], 
      state: 1
    }, 
    {
      pos: [10, 4, 21], 
      state: 1
    }, 
    {
      pos: [2, 5, 21], 
      state: 1
    }, 
    {
      pos: [3, 5, 21], 
      state: 1
    }, 
    {
      pos: [4, 5, 21], 
      state: 1
    }, 
    {
      pos: [5, 5, 21], 
      state: 1
    }, 
    {
      pos: [6, 5, 21], 
      state: 1
    }, 
    {
      pos: [7, 5, 21], 
      state: 1
    }, 
    {
      pos: [8, 5, 21], 
      state: 1
    }, 
    {
      pos: [9, 5, 21], 
      state: 1
    }, 
    {
      pos: [10, 5, 21], 
      state: 1
    }, 
    {
      pos: [2, 6, 21], 
      state: 3
    }, 
    {
      pos: [3, 6, 21], 
      state: 1
    }, 
    {
      pos: [6, 6, 21], 
      state: 1
    }, 
    {
      pos: [7, 6, 21], 
      state: 1
    }, 
    {
      pos: [10, 6, 21], 
      state: 3
    }, 
    {
      pos: [2, 7, 21], 
      state: 3
    }, 
    {
      pos: [3, 7, 21], 
      state: 1
    }, 
    {
      pos: [6, 7, 21], 
      state: 1
    }, 
    {
      pos: [7, 7, 21], 
      state: 1
    }, 
    {
      pos: [10, 7, 21], 
      state: 3
    }, 
    {
      pos: [2, 8, 21], 
      state: 3
    }, 
    {
      pos: [3, 8, 21], 
      state: 1
    }, 
    {
      pos: [6, 8, 21], 
      state: 1
    }, 
    {
      pos: [7, 8, 21], 
      state: 1
    }, 
    {
      pos: [10, 8, 21], 
      state: 3
    }, 
    {
      pos: [1, 9, 21], 
      state: 1
    }, 
    {
      pos: [2, 9, 21], 
      state: 1
    }, 
    {
      pos: [3, 9, 21], 
      state: 1
    }, 
    {
      pos: [4, 9, 21], 
      state: 1
    }, 
    {
      pos: [5, 9, 21], 
      state: 1
    }, 
    {
      pos: [6, 9, 21], 
      state: 1
    }, 
    {
      pos: [7, 9, 21], 
      state: 1
    }, 
    {
      pos: [8, 9, 21], 
      state: 1
    }, 
    {
      pos: [9, 9, 21], 
      state: 1
    }, 
    {
      pos: [10, 9, 21], 
      state: 1
    }, 
    {
      pos: [11, 9, 21], 
      state: 1
    }, 
    {
      pos: [6, 0, 22], 
      state: 0
    }, 
    {
      pos: [5, 1, 22], 
      state: 1
    }, 
    {
      pos: [6, 1, 22], 
      state: 1
    }, 
    {
      pos: [7, 1, 22], 
      state: 1
    }, 
    {
      pos: [4, 2, 22], 
      state: 1
    }, 
    {
      pos: [5, 2, 22], 
      state: 2
    }, 
    {
      pos: [6, 2, 22], 
      state: 0
    }, 
    {
      pos: [7, 2, 22], 
      state: 2
    }, 
    {
      pos: [8, 2, 22], 
      state: 1
    }, 
    {
      pos: [3, 3, 22], 
      state: 1
    }, 
    {
      pos: [8, 3, 22], 
      state: 1
    }, 
    {
      pos: [9, 3, 22], 
      state: 1
    }, 
    {
      pos: [2, 4, 22], 
      state: 1
    }, 
    {
      pos: [8, 4, 22], 
      state: 1
    }, 
    {
      pos: [9, 4, 22], 
      state: 1
    }, 
    {
      pos: [10, 4, 22], 
      state: 1
    }, 
    {
      pos: [2, 5, 22], 
      state: 1
    }, 
    {
      pos: [3, 5, 22], 
      state: 1
    }, 
    {
      pos: [4, 5, 22], 
      state: 1
    }, 
    {
      pos: [5, 5, 22], 
      state: 1
    }, 
    {
      pos: [6, 5, 22], 
      state: 1
    }, 
    {
      pos: [7, 5, 22], 
      state: 1
    }, 
    {
      pos: [8, 5, 22], 
      state: 1
    }, 
    {
      pos: [9, 5, 22], 
      state: 1
    }, 
    {
      pos: [10, 5, 22], 
      state: 1
    }, 
    {
      pos: [2, 6, 22], 
      state: 4
    }, 
    {
      pos: [10, 6, 22], 
      state: 4
    }, 
    {
      pos: [2, 7, 22], 
      state: 4
    }, 
    {
      pos: [10, 7, 22], 
      state: 4
    }, 
    {
      pos: [2, 8, 22], 
      state: 4
    }, 
    {
      pos: [10, 8, 22], 
      state: 4
    }, 
    {
      pos: [1, 9, 22], 
      state: 1
    }, 
    {
      pos: [2, 9, 22], 
      state: 1
    }, 
    {
      pos: [3, 9, 22], 
      state: 1
    }, 
    {
      pos: [4, 9, 22], 
      state: 1
    }, 
    {
      pos: [5, 9, 22], 
      state: 1
    }, 
    {
      pos: [6, 9, 22], 
      state: 1
    }, 
    {
      pos: [7, 9, 22], 
      state: 1
    }, 
    {
      pos: [8, 9, 22], 
      state: 1
    }, 
    {
      pos: [9, 9, 22], 
      state: 1
    }, 
    {
      pos: [10, 9, 22], 
      state: 1
    }, 
    {
      pos: [11, 9, 22], 
      state: 1
    }, 
    {
      pos: [4, 10, 22], 
      state: 3
    }, 
    {
      pos: [6, 0, 23], 
      state: 0
    }, 
    {
      pos: [5, 1, 23], 
      state: 1
    }, 
    {
      pos: [6, 1, 23], 
      state: 0
    }, 
    {
      pos: [7, 1, 23], 
      state: 1
    }, 
    {
      pos: [4, 2, 23], 
      state: 1
    }, 
    {
      pos: [5, 2, 23], 
      state: 2
    }, 
    {
      pos: [6, 2, 23], 
      state: 0
    }, 
    {
      pos: [7, 2, 23], 
      state: 2
    }, 
    {
      pos: [8, 2, 23], 
      state: 1
    }, 
    {
      pos: [3, 3, 23], 
      state: 1
    }, 
    {
      pos: [8, 3, 23], 
      state: 1
    }, 
    {
      pos: [9, 3, 23], 
      state: 1
    }, 
    {
      pos: [2, 4, 23], 
      state: 1
    }, 
    {
      pos: [8, 4, 23], 
      state: 1
    }, 
    {
      pos: [9, 4, 23], 
      state: 1
    }, 
    {
      pos: [10, 4, 23], 
      state: 1
    }, 
    {
      pos: [2, 5, 23], 
      state: 1
    }, 
    {
      pos: [3, 5, 23], 
      state: 1
    }, 
    {
      pos: [4, 5, 23], 
      state: 1
    }, 
    {
      pos: [5, 5, 23], 
      state: 1
    }, 
    {
      pos: [6, 5, 23], 
      state: 1
    }, 
    {
      pos: [7, 5, 23], 
      state: 1
    }, 
    {
      pos: [8, 5, 23], 
      state: 1
    }, 
    {
      pos: [9, 5, 23], 
      state: 1
    }, 
    {
      pos: [10, 5, 23], 
      state: 1
    }, 
    {
      pos: [2, 6, 23], 
      state: 4
    }, 
    {
      pos: [10, 6, 23], 
      state: 4
    }, 
    {
      pos: [2, 8, 23], 
      state: 4
    }, 
    {
      pos: [10, 8, 23], 
      state: 4
    }, 
    {
      pos: [1, 9, 23], 
      state: 1
    }, 
    {
      pos: [2, 9, 23], 
      state: 1
    }, 
    {
      pos: [3, 9, 23], 
      state: 1
    }, 
    {
      pos: [4, 9, 23], 
      state: 1
    }, 
    {
      pos: [5, 9, 23], 
      state: 1
    }, 
    {
      pos: [6, 9, 23], 
      state: 1
    }, 
    {
      pos: [7, 9, 23], 
      state: 1
    }, 
    {
      pos: [8, 9, 23], 
      state: 1
    }, 
    {
      pos: [9, 9, 23], 
      state: 1
    }, 
    {
      pos: [10, 9, 23], 
      state: 1
    }, 
    {
      pos: [11, 9, 23], 
      state: 1
    }, 
    {
      pos: [5, 1, 24], 
      state: 1
    }, 
    {
      pos: [6, 1, 24], 
      state: 0
    }, 
    {
      pos: [7, 1, 24], 
      state: 1
    }, 
    {
      pos: [4, 2, 24], 
      state: 1
    }, 
    {
      pos: [5, 2, 24], 
      state: 2
    }, 
    {
      pos: [6, 2, 24], 
      state: 0
    }, 
    {
      pos: [7, 2, 24], 
      state: 2
    }, 
    {
      pos: [8, 2, 24], 
      state: 1
    }, 
    {
      pos: [3, 3, 24], 
      state: 1
    }, 
    {
      pos: [8, 3, 24], 
      state: 1
    }, 
    {
      pos: [9, 3, 24], 
      state: 1
    }, 
    {
      pos: [2, 4, 24], 
      state: 1
    }, 
    {
      pos: [8, 4, 24], 
      state: 1
    }, 
    {
      pos: [9, 4, 24], 
      state: 1
    }, 
    {
      pos: [10, 4, 24], 
      state: 1
    }, 
    {
      pos: [2, 5, 24], 
      state: 1
    }, 
    {
      pos: [3, 5, 24], 
      state: 1
    }, 
    {
      pos: [4, 5, 24], 
      state: 1
    }, 
    {
      pos: [5, 5, 24], 
      state: 1
    }, 
    {
      pos: [6, 5, 24], 
      state: 1
    }, 
    {
      pos: [7, 5, 24], 
      state: 1
    }, 
    {
      pos: [8, 5, 24], 
      state: 1
    }, 
    {
      pos: [9, 5, 24], 
      state: 1
    }, 
    {
      pos: [10, 5, 24], 
      state: 1
    }, 
    {
      pos: [2, 6, 24], 
      state: 4
    }, 
    {
      pos: [10, 6, 24], 
      state: 4
    }, 
    {
      pos: [2, 8, 24], 
      state: 4
    }, 
    {
      pos: [10, 8, 24], 
      state: 4
    }, 
    {
      pos: [1, 9, 24], 
      state: 1
    }, 
    {
      pos: [2, 9, 24], 
      state: 1
    }, 
    {
      pos: [3, 9, 24], 
      state: 1
    }, 
    {
      pos: [4, 9, 24], 
      state: 1
    }, 
    {
      pos: [5, 9, 24], 
      state: 1
    }, 
    {
      pos: [6, 9, 24], 
      state: 1
    }, 
    {
      pos: [7, 9, 24], 
      state: 1
    }, 
    {
      pos: [8, 9, 24], 
      state: 1
    }, 
    {
      pos: [9, 9, 24], 
      state: 1
    }, 
    {
      pos: [10, 9, 24], 
      state: 1
    }, 
    {
      pos: [11, 9, 24], 
      state: 1
    }, 
    {
      pos: [4, 2, 25], 
      state: 1
    }, 
    {
      pos: [5, 2, 25], 
      state: 1
    }, 
    {
      pos: [6, 2, 25], 
      state: 0
    }, 
    {
      pos: [7, 2, 25], 
      state: 1
    }, 
    {
      pos: [8, 2, 25], 
      state: 1
    }, 
    {
      pos: [3, 3, 25], 
      state: 1
    }, 
    {
      pos: [4, 3, 25], 
      state: 1
    }, 
    {
      pos: [5, 3, 25], 
      state: 1
    }, 
    {
      pos: [6, 3, 25], 
      state: 1
    }, 
    {
      pos: [7, 3, 25], 
      state: 1
    }, 
    {
      pos: [8, 3, 25], 
      state: 1
    }, 
    {
      pos: [9, 3, 25], 
      state: 1
    }, 
    {
      pos: [2, 4, 25], 
      state: 1
    }, 
    {
      pos: [3, 4, 25], 
      state: 1
    }, 
    {
      pos: [4, 4, 25], 
      state: 1
    }, 
    {
      pos: [5, 4, 25], 
      state: 1
    }, 
    {
      pos: [6, 4, 25], 
      state: 1
    }, 
    {
      pos: [7, 4, 25], 
      state: 1
    }, 
    {
      pos: [8, 4, 25], 
      state: 1
    }, 
    {
      pos: [9, 4, 25], 
      state: 1
    }, 
    {
      pos: [10, 4, 25], 
      state: 1
    }, 
    {
      pos: [2, 5, 25], 
      state: 1
    }, 
    {
      pos: [3, 5, 25], 
      state: 1
    }, 
    {
      pos: [4, 5, 25], 
      state: 1
    }, 
    {
      pos: [5, 5, 25], 
      state: 1
    }, 
    {
      pos: [6, 5, 25], 
      state: 1
    }, 
    {
      pos: [7, 5, 25], 
      state: 1
    }, 
    {
      pos: [8, 5, 25], 
      state: 1
    }, 
    {
      pos: [9, 5, 25], 
      state: 1
    }, 
    {
      pos: [10, 5, 25], 
      state: 1
    }, 
    {
      pos: [2, 6, 25], 
      state: 4
    }, 
    {
      pos: [6, 6, 25], 
      state: 3
    }, 
    {
      pos: [10, 6, 25], 
      state: 4
    }, 
    {
      pos: [2, 7, 25], 
      state: 4
    }, 
    {
      pos: [10, 7, 25], 
      state: 4
    }, 
    {
      pos: [2, 8, 25], 
      state: 4
    }, 
    {
      pos: [10, 8, 25], 
      state: 4
    }, 
    {
      pos: [1, 9, 25], 
      state: 1
    }, 
    {
      pos: [2, 9, 25], 
      state: 1
    }, 
    {
      pos: [3, 9, 25], 
      state: 1
    }, 
    {
      pos: [4, 9, 25], 
      state: 1
    }, 
    {
      pos: [5, 9, 25], 
      state: 1
    }, 
    {
      pos: [6, 9, 25], 
      state: 1
    }, 
    {
      pos: [7, 9, 25], 
      state: 1
    }, 
    {
      pos: [8, 9, 25], 
      state: 1
    }, 
    {
      pos: [9, 9, 25], 
      state: 1
    }, 
    {
      pos: [10, 9, 25], 
      state: 1
    }, 
    {
      pos: [11, 9, 25], 
      state: 1
    }, 
    {
      pos: [2, 5, 26], 
      state: 1
    }, 
    {
      pos: [3, 5, 26], 
      state: 1
    }, 
    {
      pos: [4, 5, 26], 
      state: 1
    }, 
    {
      pos: [5, 5, 26], 
      state: 1
    }, 
    {
      pos: [6, 5, 26], 
      state: 1
    }, 
    {
      pos: [7, 5, 26], 
      state: 1
    }, 
    {
      pos: [8, 5, 26], 
      state: 1
    }, 
    {
      pos: [9, 5, 26], 
      state: 1
    }, 
    {
      pos: [10, 5, 26], 
      state: 1
    }, 
    {
      pos: [2, 6, 26], 
      state: 3
    }, 
    {
      pos: [3, 6, 26], 
      state: 4
    }, 
    {
      pos: [4, 6, 26], 
      state: 4
    }, 
    {
      pos: [5, 6, 26], 
      state: 4
    }, 
    {
      pos: [6, 6, 26], 
      state: 3
    }, 
    {
      pos: [7, 6, 26], 
      state: 4
    }, 
    {
      pos: [8, 6, 26], 
      state: 4
    }, 
    {
      pos: [9, 6, 26], 
      state: 4
    }, 
    {
      pos: [10, 6, 26], 
      state: 3
    }, 
    {
      pos: [2, 7, 26], 
      state: 3
    }, 
    {
      pos: [3, 7, 26], 
      state: 4
    }, 
    {
      pos: [5, 7, 26], 
      state: 4
    }, 
    {
      pos: [6, 7, 26], 
      state: 3
    }, 
    {
      pos: [7, 7, 26], 
      state: 4
    }, 
    {
      pos: [9, 7, 26], 
      state: 4
    }, 
    {
      pos: [10, 7, 26], 
      state: 3
    }, 
    {
      pos: [2, 8, 26], 
      state: 3
    }, 
    {
      pos: [3, 8, 26], 
      state: 4
    }, 
    {
      pos: [4, 8, 26], 
      state: 4
    }, 
    {
      pos: [5, 8, 26], 
      state: 4
    }, 
    {
      pos: [6, 8, 26], 
      state: 3
    }, 
    {
      pos: [7, 8, 26], 
      state: 4
    }, 
    {
      pos: [8, 8, 26], 
      state: 4
    }, 
    {
      pos: [9, 8, 26], 
      state: 4
    }, 
    {
      pos: [10, 8, 26], 
      state: 3
    }, 
    {
      pos: [1, 9, 26], 
      state: 1
    }, 
    {
      pos: [2, 9, 26], 
      state: 1
    }, 
    {
      pos: [3, 9, 26], 
      state: 1
    }, 
    {
      pos: [4, 9, 26], 
      state: 1
    }, 
    {
      pos: [5, 9, 26], 
      state: 1
    }, 
    {
      pos: [6, 9, 26], 
      state: 1
    }, 
    {
      pos: [7, 9, 26], 
      state: 1
    }, 
    {
      pos: [8, 9, 26], 
      state: 1
    }, 
    {
      pos: [9, 9, 26], 
      state: 1
    }, 
    {
      pos: [10, 9, 26], 
      state: 1
    }, 
    {
      pos: [11, 9, 26], 
      state: 1
    }, 
    {
      pos: [1, 9, 27], 
      state: 1
    }, 
    {
      pos: [2, 9, 27], 
      state: 1
    }, 
    {
      pos: [3, 9, 27], 
      state: 1
    }, 
    {
      pos: [4, 9, 27], 
      state: 1
    }, 
    {
      pos: [5, 9, 27], 
      state: 1
    }, 
    {
      pos: [6, 9, 27], 
      state: 1
    }, 
    {
      pos: [7, 9, 27], 
      state: 1
    }, 
    {
      pos: [8, 9, 27], 
      state: 1
    }, 
    {
      pos: [9, 9, 27], 
      state: 1
    }, 
    {
      pos: [10, 9, 27], 
      state: 1
    }, 
    {
      pos: [11, 9, 27], 
      state: 1
    }, 
    {
      pos: [1, 10, 27], 
      state: 1
    }, 
    {
      pos: [4, 10, 27], 
      state: 1
    }, 
    {
      pos: [8, 10, 27], 
      state: 1
    }, 
    {
      pos: [11, 10, 27], 
      state: 1
    }, 
    {
      nbt: {
        id: "minecraft:skull"
      }, 
      pos: [6, 8, 0], 
      state: 5
    }, 
    {
      nbt: {
        Items: [], 
        id: "minecraft:chest", 
        Lock: ""
      }, 
      pos: [5, 4, 7], 
      state: 6
    }, 
    {
      nbt: {
        Items: [], 
        id: "minecraft:chest", 
        Lock: ""
      }, 
      pos: [7, 4, 7], 
      state: 6
    }, 
    {
      nbt: {
        metadata: "Chest", 
        mirror: "NONE", 
        ignoreEntities: 0b, 
        powered: 0b, 
        seed: 0L, 
        author: "jeb_", 
        rotation: "NONE", 
        mode: "DATA", 
        posX: 1, 
        posY: 1, 
        sizeX: 0, 
        integrity: 1.0f, 
        posZ: 1, 
        showair: 0b, 
        name: "", 
        id: "minecraft:structure_block", 
        sizeY: 0, 
        showboundingbox: 0b, 
        sizeZ: 0
      }, 
      pos: [5, 5, 7], 
      state: 7
    }, 
    {
      nbt: {
        metadata: "Elytra", 
        mirror: "NONE", 
        ignoreEntities: 0b, 
        powered: 0b, 
        seed: 0L, 
        author: "jeb_", 
        rotation: "NONE", 
        mode: "DATA", 
        posX: 1, 
        posY: 1, 
        sizeX: 0, 
        integrity: 1.0f, 
        posZ: 1, 
        showair: 0b, 
        name: "", 
        id: "minecraft:structure_block", 
        sizeY: 0, 
        showboundingbox: 0b, 
        sizeZ: 0
      }, 
      pos: [6, 5, 7], 
      state: 7
    }, 
    {
      nbt: {
        metadata: "Chest", 
        mirror: "NONE", 
        ignoreEntities: 0b, 
        powered: 0b, 
        seed: 0L, 
        author: "jeb_", 
        rotation: "NONE", 
        mode: "DATA", 
        posX: 1, 
        posY: 1, 
        sizeX: 0, 
        integrity: 1.0f, 
        posZ: 1, 
        showair: 0b, 
        name: "", 
        id: "minecraft:structure_block", 
        sizeY: 0, 
        showboundingbox: 0b, 
        sizeZ: 0
      }, 
      pos: [7, 5, 7], 
      state: 7
    }, 
    {
      nbt: {
        metadata: "Sentry", 
        mirror: "NONE", 
        ignoreEntities: 0b, 
        powered: 0b, 
        seed: 0L, 
        author: "jeb_", 
        rotation: "NONE", 
        mode: "DATA", 
        posX: 1, 
        posY: 1, 
        sizeX: 0, 
        integrity: 1.0f, 
        posZ: 1, 
        showair: 0b, 
        name: "", 
        id: "minecraft:structure_block", 
        sizeY: 0, 
        showboundingbox: 0b, 
        sizeZ: 0
      }, 
      pos: [6, 4, 8], 
      state: 7
    }, 
    {
      nbt: {
        Fuel: 0b, 
        Items: [
          {
            Slot: 0b, 
            Count: 1b, 
            id: "minecraft:potion", 
            tag: {
              Potion: "minecraft:strong_healing"
            }
          }, 
          {
            Slot: 2b, 
            Count: 1b, 
            id: "minecraft:potion", 
            tag: {
              Potion: "minecraft:strong_healing"
            }
          }
        ], 
        id: "minecraft:brewing_stand", 
        BrewTime: 0s, 
        Lock: ""
      }, 
      pos: [6, 7, 25], 
      state: 8
    }, 
    {
      nbt: {
        metadata: "Sentry", 
        mirror: "NONE", 
        ignoreEntities: 0b, 
        powered: 0b, 
        seed: 0L, 
        author: "jeb_", 
        rotation: "NONE", 
        mode: "DATA", 
        posX: 1, 
        posY: 1, 
        sizeX: 0, 
        integrity: 1.0f, 
        posZ: 1, 
        showair: 0b, 
        name: "", 
        id: "minecraft:structure_block", 
        sizeY: 0, 
        showboundingbox: 0b, 
        sizeZ: 0
      }, 
      pos: [8, 6, 27], 
      state: 7
    }, 
    {
      nbt: {
        metadata: "Sentry", 
        mirror: "NONE", 
        ignoreEntities: 0b, 
        powered: 0b, 
        seed: 0L, 
        author: "jeb_", 
        rotation: "NONE", 
        mode: "DATA", 
        posX: 1, 
        posY: 1, 
        sizeX: 0, 
        integrity: 1.0f, 
        posZ: 1, 
        showair: 0b, 
        name: "", 
        id: "minecraft:structure_block", 
        sizeY: 0, 
        showboundingbox: 0b, 
        sizeZ: 0
      }, 
      pos: [4, 11, 27], 
      state: 7
    }, 
    {
      pos: [0, 0, 0], 
      state: 9
    }, 
    {
      pos: [1, 0, 0], 
      state: 9
    }, 
    {
      pos: [2, 0, 0], 
      state: 9
    }, 
    {
      pos: [3, 0, 0], 
      state: 9
    }, 
    {
      pos: [4, 0, 0], 
      state: 9
    }, 
    {
      pos: [5, 0, 0], 
      state: 9
    }, 
    {
      pos: [6, 0, 0], 
      state: 9
    }, 
    {
      pos: [7, 0, 0], 
      state: 9
    }, 
    {
      pos: [8, 0, 0], 
      state: 9
    }, 
    {
      pos: [9, 0, 0], 
      state: 9
    }, 
    {
      pos: [10, 0, 0], 
      state: 9
    }, 
    {
      pos: [11, 0, 0], 
      state: 9
    }, 
    {
      pos: [12, 0, 0], 
      state: 9
    }, 
    {
      pos: [0, 1, 0], 
      state: 9
    }, 
    {
      pos: [1, 1, 0], 
      state: 9
    }, 
    {
      pos: [2, 1, 0], 
      state: 9
    }, 
    {
      pos: [3, 1, 0], 
      state: 9
    }, 
    {
      pos: [4, 1, 0], 
      state: 9
    }, 
    {
      pos: [5, 1, 0], 
      state: 9
    }, 
    {
      pos: [6, 1, 0], 
      state: 9
    }, 
    {
      pos: [7, 1, 0], 
      state: 9
    }, 
    {
      pos: [8, 1, 0], 
      state: 9
    }, 
    {
      pos: [9, 1, 0], 
      state: 9
    }, 
    {
      pos: [10, 1, 0], 
      state: 9
    }, 
    {
      pos: [11, 1, 0], 
      state: 9
    }, 
    {
      pos: [12, 1, 0], 
      state: 9
    }, 
    {
      pos: [0, 2, 0], 
      state: 9
    }, 
    {
      pos: [1, 2, 0], 
      state: 9
    }, 
    {
      pos: [2, 2, 0], 
      state: 9
    }, 
    {
      pos: [3, 2, 0], 
      state: 9
    }, 
    {
      pos: [4, 2, 0], 
      state: 9
    }, 
    {
      pos: [5, 2, 0], 
      state: 9
    }, 
    {
      pos: [6, 2, 0], 
      state: 9
    }, 
    {
      pos: [7, 2, 0], 
      state: 9
    }, 
    {
      pos: [8, 2, 0], 
      state: 9
    }, 
    {
      pos: [9, 2, 0], 
      state: 9
    }, 
    {
      pos: [10, 2, 0], 
      state: 9
    }, 
    {
      pos: [11, 2, 0], 
      state: 9
    }, 
    {
      pos: [12, 2, 0], 
      state: 9
    }, 
    {
      pos: [0, 3, 0], 
      state: 9
    }, 
    {
      pos: [1, 3, 0], 
      state: 9
    }, 
    {
      pos: [2, 3, 0], 
      state: 9
    }, 
    {
      pos: [3, 3, 0], 
      state: 9
    }, 
    {
      pos: [4, 3, 0], 
      state: 9
    }, 
    {
      pos: [5, 3, 0], 
      state: 9
    }, 
    {
      pos: [6, 3, 0], 
      state: 9
    }, 
    {
      pos: [7, 3, 0], 
      state: 9
    }, 
    {
      pos: [8, 3, 0], 
      state: 9
    }, 
    {
      pos: [9, 3, 0], 
      state: 9
    }, 
    {
      pos: [10, 3, 0], 
      state: 9
    }, 
    {
      pos: [11, 3, 0], 
      state: 9
    }, 
    {
      pos: [12, 3, 0], 
      state: 9
    }, 
    {
      pos: [0, 4, 0], 
      state: 9
    }, 
    {
      pos: [1, 4, 0], 
      state: 9
    }, 
    {
      pos: [2, 4, 0], 
      state: 9
    }, 
    {
      pos: [3, 4, 0], 
      state: 9
    }, 
    {
      pos: [4, 4, 0], 
      state: 9
    }, 
    {
      pos: [5, 4, 0], 
      state: 9
    }, 
    {
      pos: [6, 4, 0], 
      state: 9
    }, 
    {
      pos: [7, 4, 0], 
      state: 9
    }, 
    {
      pos: [8, 4, 0], 
      state: 9
    }, 
    {
      pos: [9, 4, 0], 
      state: 9
    }, 
    {
      pos: [10, 4, 0], 
      state: 9
    }, 
    {
      pos: [11, 4, 0], 
      state: 9
    }, 
    {
      pos: [12, 4, 0], 
      state: 9
    }, 
    {
      pos: [0, 5, 0], 
      state: 9
    }, 
    {
      pos: [1, 5, 0], 
      state: 9
    }, 
    {
      pos: [2, 5, 0], 
      state: 9
    }, 
    {
      pos: [3, 5, 0], 
      state: 9
    }, 
    {
      pos: [4, 5, 0], 
      state: 9
    }, 
    {
      pos: [5, 5, 0], 
      state: 9
    }, 
    {
      pos: [6, 5, 0], 
      state: 9
    }, 
    {
      pos: [7, 5, 0], 
      state: 9
    }, 
    {
      pos: [8, 5, 0], 
      state: 9
    }, 
    {
      pos: [9, 5, 0], 
      state: 9
    }, 
    {
      pos: [10, 5, 0], 
      state: 9
    }, 
    {
      pos: [11, 5, 0], 
      state: 9
    }, 
    {
      pos: [12, 5, 0], 
      state: 9
    }, 
    {
      pos: [0, 6, 0], 
      state: 9
    }, 
    {
      pos: [1, 6, 0], 
      state: 9
    }, 
    {
      pos: [2, 6, 0], 
      state: 9
    }, 
    {
      pos: [3, 6, 0], 
      state: 9
    }, 
    {
      pos: [4, 6, 0], 
      state: 9
    }, 
    {
      pos: [5, 6, 0], 
      state: 9
    }, 
    {
      pos: [6, 6, 0], 
      state: 9
    }, 
    {
      pos: [7, 6, 0], 
      state: 9
    }, 
    {
      pos: [8, 6, 0], 
      state: 9
    }, 
    {
      pos: [9, 6, 0], 
      state: 9
    }, 
    {
      pos: [10, 6, 0], 
      state: 9
    }, 
    {
      pos: [11, 6, 0], 
      state: 9
    }, 
    {
      pos: [12, 6, 0], 
      state: 9
    }, 
    {
      pos: [0, 7, 0], 
      state: 9
    }, 
    {
      pos: [1, 7, 0], 
      state: 9
    }, 
    {
      pos: [2, 7, 0], 
      state: 9
    }, 
    {
      pos: [3, 7, 0], 
      state: 9
    }, 
    {
      pos: [4, 7, 0], 
      state: 9
    }, 
    {
      pos: [5, 7, 0], 
      state: 9
    }, 
    {
      pos: [6, 7, 0], 
      state: 9
    }, 
    {
      pos: [7, 7, 0], 
      state: 9
    }, 
    {
      pos: [8, 7, 0], 
      state: 9
    }, 
    {
      pos: [9, 7, 0], 
      state: 9
    }, 
    {
      pos: [10, 7, 0], 
      state: 9
    }, 
    {
      pos: [11, 7, 0], 
      state: 9
    }, 
    {
      pos: [12, 7, 0], 
      state: 9
    }, 
    {
      pos: [0, 8, 0], 
      state: 9
    }, 
    {
      pos: [1, 8, 0], 
      state: 9
    }, 
    {
      pos: [2, 8, 0], 
      state: 9
    }, 
    {
      pos: [3, 8, 0], 
      state: 9
    }, 
    {
      pos: [4, 8, 0], 
      state: 9
    }, 
    {
      pos: [5, 8, 0], 
      state: 9
    }, 
    {
      pos: [7, 8, 0], 
      state: 9
    }, 
    {
      pos: [8, 8, 0], 
      state: 9
    }, 
    {
      pos: [9, 8, 0], 
      state: 9
    }, 
    {
      pos: [10, 8, 0], 
      state: 9
    }, 
    {
      pos: [11, 8, 0], 
      state: 9
    }, 
    {
      pos: [12, 8, 0], 
      state: 9
    }, 
    {
      pos: [0, 9, 0], 
      state: 9
    }, 
    {
      pos: [1, 9, 0], 
      state: 9
    }, 
    {
      pos: [2, 9, 0], 
      state: 9
    }, 
    {
      pos: [3, 9, 0], 
      state: 9
    }, 
    {
      pos: [4, 9, 0], 
      state: 9
    }, 
    {
      pos: [5, 9, 0], 
      state: 9
    }, 
    {
      pos: [6, 9, 0], 
      state: 9
    }, 
    {
      pos: [7, 9, 0], 
      state: 9
    }, 
    {
      pos: [8, 9, 0], 
      state: 9
    }, 
    {
      pos: [9, 9, 0], 
      state: 9
    }, 
    {
      pos: [10, 9, 0], 
      state: 9
    }, 
    {
      pos: [11, 9, 0], 
      state: 9
    }, 
    {
      pos: [12, 9, 0], 
      state: 9
    }, 
    {
      pos: [0, 10, 0], 
      state: 9
    }, 
    {
      pos: [1, 10, 0], 
      state: 9
    }, 
    {
      pos: [2, 10, 0], 
      state: 9
    }, 
    {
      pos: [3, 10, 0], 
      state: 9
    }, 
    {
      pos: [4, 10, 0], 
      state: 9
    }, 
    {
      pos: [5, 10, 0], 
      state: 9
    }, 
    {
      pos: [6, 10, 0], 
      state: 9
    }, 
    {
      pos: [7, 10, 0], 
      state: 9
    }, 
    {
      pos: [8, 10, 0], 
      state: 9
    }, 
    {
      pos: [9, 10, 0], 
      state: 9
    }, 
    {
      pos: [10, 10, 0], 
      state: 9
    }, 
    {
      pos: [11, 10, 0], 
      state: 9
    }, 
    {
      pos: [12, 10, 0], 
      state: 9
    }, 
    {
      pos: [0, 11, 0], 
      state: 9
    }, 
    {
      pos: [1, 11, 0], 
      state: 9
    }, 
    {
      pos: [2, 11, 0], 
      state: 9
    }, 
    {
      pos: [3, 11, 0], 
      state: 9
    }, 
    {
      pos: [4, 11, 0], 
      state: 9
    }, 
    {
      pos: [5, 11, 0], 
      state: 9
    }, 
    {
      pos: [6, 11, 0], 
      state: 9
    }, 
    {
      pos: [7, 11, 0], 
      state: 9
    }, 
    {
      pos: [8, 11, 0], 
      state: 9
    }, 
    {
      pos: [9, 11, 0], 
      state: 9
    }, 
    {
      pos: [10, 11, 0], 
      state: 9
    }, 
    {
      pos: [11, 11, 0], 
      state: 9
    }, 
    {
      pos: [12, 11, 0], 
      state: 9
    }, 
    {
      pos: [0, 12, 0], 
      state: 9
    }, 
    {
      pos: [1, 12, 0], 
      state: 9
    }, 
    {
      pos: [2, 12, 0], 
      state: 9
    }, 
    {
      pos: [3, 12, 0], 
      state: 9
    }, 
    {
      pos: [4, 12, 0], 
      state: 9
    }, 
    {
      pos: [5, 12, 0], 
      state: 9
    }, 
    {
      pos: [6, 12, 0], 
      state: 9
    }, 
    {
      pos: [7, 12, 0], 
      state: 9
    }, 
    {
      pos: [8, 12, 0], 
      state: 9
    }, 
    {
      pos: [9, 12, 0], 
      state: 9
    }, 
    {
      pos: [10, 12, 0], 
      state: 9
    }, 
    {
      pos: [11, 12, 0], 
      state: 9
    }, 
    {
      pos: [12, 12, 0], 
      state: 9
    }, 
    {
      pos: [0, 13, 0], 
      state: 9
    }, 
    {
      pos: [1, 13, 0], 
      state: 9
    }, 
    {
      pos: [2, 13, 0], 
      state: 9
    }, 
    {
      pos: [3, 13, 0], 
      state: 9
    }, 
    {
      pos: [4, 13, 0], 
      state: 9
    }, 
    {
      pos: [5, 13, 0], 
      state: 9
    }, 
    {
      pos: [6, 13, 0], 
      state: 9
    }, 
    {
      pos: [7, 13, 0], 
      state: 9
    }, 
    {
      pos: [8, 13, 0], 
      state: 9
    }, 
    {
      pos: [9, 13, 0], 
      state: 9
    }, 
    {
      pos: [10, 13, 0], 
      state: 9
    }, 
    {
      pos: [11, 13, 0], 
      state: 9
    }, 
    {
      pos: [12, 13, 0], 
      state: 9
    }, 
    {
      pos: [0, 14, 0], 
      state: 9
    }, 
    {
      pos: [1, 14, 0], 
      state: 9
    }, 
    {
      pos: [2, 14, 0], 
      state: 9
    }, 
    {
      pos: [3, 14, 0], 
      state: 9
    }, 
    {
      pos: [4, 14, 0], 
      state: 9
    }, 
    {
      pos: [5, 14, 0], 
      state: 9
    }, 
    {
      pos: [6, 14, 0], 
      state: 9
    }, 
    {
      pos: [7, 14, 0], 
      state: 9
    }, 
    {
      pos: [8, 14, 0], 
      state: 9
    }, 
    {
      pos: [9, 14, 0], 
      state: 9
    }, 
    {
      pos: [10, 14, 0], 
      state: 9
    }, 
    {
      pos: [11, 14, 0], 
      state: 9
    }, 
    {
      pos: [12, 14, 0], 
      state: 9
    }, 
    {
      pos: [0, 15, 0], 
      state: 9
    }, 
    {
      pos: [1, 15, 0], 
      state: 9
    }, 
    {
      pos: [2, 15, 0], 
      state: 9
    }, 
    {
      pos: [3, 15, 0], 
      state: 9
    }, 
    {
      pos: [4, 15, 0], 
      state: 9
    }, 
    {
      pos: [5, 15, 0], 
      state: 9
    }, 
    {
      pos: [6, 15, 0], 
      state: 9
    }, 
    {
      pos: [7, 15, 0], 
      state: 9
    }, 
    {
      pos: [8, 15, 0], 
      state: 9
    }, 
    {
      pos: [9, 15, 0], 
      state: 9
    }, 
    {
      pos: [10, 15, 0], 
      state: 9
    }, 
    {
      pos: [11, 15, 0], 
      state: 9
    }, 
    {
      pos: [12, 15, 0], 
      state: 9
    }, 
    {
      pos: [0, 16, 0], 
      state: 9
    }, 
    {
      pos: [1, 16, 0], 
      state: 9
    }, 
    {
      pos: [2, 16, 0], 
      state: 9
    }, 
    {
      pos: [3, 16, 0], 
      state: 9
    }, 
    {
      pos: [4, 16, 0], 
      state: 9
    }, 
    {
      pos: [5, 16, 0], 
      state: 9
    }, 
    {
      pos: [6, 16, 0], 
      state: 9
    }, 
    {
      pos: [7, 16, 0], 
      state: 9
    }, 
    {
      pos: [8, 16, 0], 
      state: 9
    }, 
    {
      pos: [9, 16, 0], 
      state: 9
    }, 
    {
      pos: [10, 16, 0], 
      state: 9
    }, 
    {
      pos: [11, 16, 0], 
      state: 9
    }, 
    {
      pos: [12, 16, 0], 
      state: 9
    }, 
    {
      pos: [0, 17, 0], 
      state: 9
    }, 
    {
      pos: [1, 17, 0], 
      state: 9
    }, 
    {
      pos: [2, 17, 0], 
      state: 9
    }, 
    {
      pos: [3, 17, 0], 
      state: 9
    }, 
    {
      pos: [4, 17, 0], 
      state: 9
    }, 
    {
      pos: [5, 17, 0], 
      state: 9
    }, 
    {
      pos: [6, 17, 0], 
      state: 9
    }, 
    {
      pos: [7, 17, 0], 
      state: 9
    }, 
    {
      pos: [8, 17, 0], 
      state: 9
    }, 
    {
      pos: [9, 17, 0], 
      state: 9
    }, 
    {
      pos: [10, 17, 0], 
      state: 9
    }, 
    {
      pos: [11, 17, 0], 
      state: 9
    }, 
    {
      pos: [12, 17, 0], 
      state: 9
    }, 
    {
      pos: [0, 18, 0], 
      state: 9
    }, 
    {
      pos: [1, 18, 0], 
      state: 9
    }, 
    {
      pos: [2, 18, 0], 
      state: 9
    }, 
    {
      pos: [3, 18, 0], 
      state: 9
    }, 
    {
      pos: [4, 18, 0], 
      state: 9
    }, 
    {
      pos: [5, 18, 0], 
      state: 9
    }, 
    {
      pos: [6, 18, 0], 
      state: 9
    }, 
    {
      pos: [7, 18, 0], 
      state: 9
    }, 
    {
      pos: [8, 18, 0], 
      state: 9
    }, 
    {
      pos: [9, 18, 0], 
      state: 9
    }, 
    {
      pos: [10, 18, 0], 
      state: 9
    }, 
    {
      pos: [11, 18, 0], 
      state: 9
    }, 
    {
      pos: [12, 18, 0], 
      state: 9
    }, 
    {
      pos: [0, 19, 0], 
      state: 9
    }, 
    {
      pos: [1, 19, 0], 
      state: 9
    }, 
    {
      pos: [2, 19, 0], 
      state: 9
    }, 
    {
      pos: [3, 19, 0], 
      state: 9
    }, 
    {
      pos: [4, 19, 0], 
      state: 9
    }, 
    {
      pos: [5, 19, 0], 
      state: 9
    }, 
    {
      pos: [6, 19, 0], 
      state: 9
    }, 
    {
      pos: [7, 19, 0], 
      state: 9
    }, 
    {
      pos: [8, 19, 0], 
      state: 9
    }, 
    {
      pos: [9, 19, 0], 
      state: 9
    }, 
    {
      pos: [10, 19, 0], 
      state: 9
    }, 
    {
      pos: [11, 19, 0], 
      state: 9
    }, 
    {
      pos: [12, 19, 0], 
      state: 9
    }, 
    {
      pos: [0, 20, 0], 
      state: 9
    }, 
    {
      pos: [1, 20, 0], 
      state: 9
    }, 
    {
      pos: [2, 20, 0], 
      state: 9
    }, 
    {
      pos: [3, 20, 0], 
      state: 9
    }, 
    {
      pos: [4, 20, 0], 
      state: 9
    }, 
    {
      pos: [5, 20, 0], 
      state: 9
    }, 
    {
      pos: [6, 20, 0], 
      state: 9
    }, 
    {
      pos: [7, 20, 0], 
      state: 9
    }, 
    {
      pos: [8, 20, 0], 
      state: 9
    }, 
    {
      pos: [9, 20, 0], 
      state: 9
    }, 
    {
      pos: [10, 20, 0], 
      state: 9
    }, 
    {
      pos: [11, 20, 0], 
      state: 9
    }, 
    {
      pos: [12, 20, 0], 
      state: 9
    }, 
    {
      pos: [0, 21, 0], 
      state: 9
    }, 
    {
      pos: [1, 21, 0], 
      state: 9
    }, 
    {
      pos: [2, 21, 0], 
      state: 9
    }, 
    {
      pos: [3, 21, 0], 
      state: 9
    }, 
    {
      pos: [4, 21, 0], 
      state: 9
    }, 
    {
      pos: [5, 21, 0], 
      state: 9
    }, 
    {
      pos: [6, 21, 0], 
      state: 9
    }, 
    {
      pos: [7, 21, 0], 
      state: 9
    }, 
    {
      pos: [8, 21, 0], 
      state: 9
    }, 
    {
      pos: [9, 21, 0], 
      state: 9
    }, 
    {
      pos: [10, 21, 0], 
      state: 9
    }, 
    {
      pos: [11, 21, 0], 
      state: 9
    }, 
    {
      pos: [12, 21, 0], 
      state: 9
    }, 
    {
      pos: [0, 22, 0], 
      state: 9
    }, 
    {
      pos: [1, 22, 0], 
      state: 9
    }, 
    {
      pos: [2, 22, 0], 
      state: 9
    }, 
    {
      pos: [3, 22, 0], 
      state: 9
    }, 
    {
      pos: [4, 22, 0], 
      state: 9
    }, 
    {
      pos: [5, 22, 0], 
      state: 9
    }, 
    {
      pos: [6, 22, 0], 
      state: 9
    }, 
    {
      pos: [7, 22, 0], 
      state: 9
    }, 
    {
      pos: [8, 22, 0], 
      state: 9
    }, 
    {
      pos: [9, 22, 0], 
      state: 9
    }, 
    {
      pos: [10, 22, 0], 
      state: 9
    }, 
    {
      pos: [11, 22, 0], 
      state: 9
    }, 
    {
      pos: [12, 22, 0], 
      state: 9
    }, 
    {
      pos: [0, 23, 0], 
      state: 9
    }, 
    {
      pos: [1, 23, 0], 
      state: 9
    }, 
    {
      pos: [2, 23, 0], 
      state: 9
    }, 
    {
      pos: [3, 23, 0], 
      state: 9
    }, 
    {
      pos: [4, 23, 0], 
      state: 9
    }, 
    {
      pos: [5, 23, 0], 
      state: 9
    }, 
    {
      pos: [6, 23, 0], 
      state: 9
    }, 
    {
      pos: [7, 23, 0], 
      state: 9
    }, 
    {
      pos: [8, 23, 0], 
      state: 9
    }, 
    {
      pos: [9, 23, 0], 
      state: 9
    }, 
    {
      pos: [10, 23, 0], 
      state: 9
    }, 
    {
      pos: [11, 23, 0], 
      state: 9
    }, 
    {
      pos: [12, 23, 0], 
      state: 9
    }, 
    {
      pos: [0, 0, 1], 
      state: 9
    }, 
    {
      pos: [1, 0, 1], 
      state: 9
    }, 
    {
      pos: [2, 0, 1], 
      state: 9
    }, 
    {
      pos: [3, 0, 1], 
      state: 9
    }, 
    {
      pos: [4, 0, 1], 
      state: 9
    }, 
    {
      pos: [5, 0, 1], 
      state: 9
    }, 
    {
      pos: [6, 0, 1], 
      state: 9
    }, 
    {
      pos: [7, 0, 1], 
      state: 9
    }, 
    {
      pos: [8, 0, 1], 
      state: 9
    }, 
    {
      pos: [9, 0, 1], 
      state: 9
    }, 
    {
      pos: [10, 0, 1], 
      state: 9
    }, 
    {
      pos: [11, 0, 1], 
      state: 9
    }, 
    {
      pos: [12, 0, 1], 
      state: 9
    }, 
    {
      pos: [0, 1, 1], 
      state: 9
    }, 
    {
      pos: [1, 1, 1], 
      state: 9
    }, 
    {
      pos: [2, 1, 1], 
      state: 9
    }, 
    {
      pos: [3, 1, 1], 
      state: 9
    }, 
    {
      pos: [4, 1, 1], 
      state: 9
    }, 
    {
      pos: [5, 1, 1], 
      state: 9
    }, 
    {
      pos: [6, 1, 1], 
      state: 9
    }, 
    {
      pos: [7, 1, 1], 
      state: 9
    }, 
    {
      pos: [8, 1, 1], 
      state: 9
    }, 
    {
      pos: [9, 1, 1], 
      state: 9
    }, 
    {
      pos: [10, 1, 1], 
      state: 9
    }, 
    {
      pos: [11, 1, 1], 
      state: 9
    }, 
    {
      pos: [12, 1, 1], 
      state: 9
    }, 
    {
      pos: [0, 2, 1], 
      state: 9
    }, 
    {
      pos: [1, 2, 1], 
      state: 9
    }, 
    {
      pos: [2, 2, 1], 
      state: 9
    }, 
    {
      pos: [3, 2, 1], 
      state: 9
    }, 
    {
      pos: [4, 2, 1], 
      state: 9
    }, 
    {
      pos: [5, 2, 1], 
      state: 9
    }, 
    {
      pos: [6, 2, 1], 
      state: 9
    }, 
    {
      pos: [7, 2, 1], 
      state: 9
    }, 
    {
      pos: [8, 2, 1], 
      state: 9
    }, 
    {
      pos: [9, 2, 1], 
      state: 9
    }, 
    {
      pos: [10, 2, 1], 
      state: 9
    }, 
    {
      pos: [11, 2, 1], 
      state: 9
    }, 
    {
      pos: [12, 2, 1], 
      state: 9
    }, 
    {
      pos: [0, 3, 1], 
      state: 9
    }, 
    {
      pos: [1, 3, 1], 
      state: 9
    }, 
    {
      pos: [2, 3, 1], 
      state: 9
    }, 
    {
      pos: [3, 3, 1], 
      state: 9
    }, 
    {
      pos: [4, 3, 1], 
      state: 9
    }, 
    {
      pos: [5, 3, 1], 
      state: 9
    }, 
    {
      pos: [6, 3, 1], 
      state: 9
    }, 
    {
      pos: [7, 3, 1], 
      state: 9
    }, 
    {
      pos: [8, 3, 1], 
      state: 9
    }, 
    {
      pos: [9, 3, 1], 
      state: 9
    }, 
    {
      pos: [10, 3, 1], 
      state: 9
    }, 
    {
      pos: [11, 3, 1], 
      state: 9
    }, 
    {
      pos: [12, 3, 1], 
      state: 9
    }, 
    {
      pos: [0, 4, 1], 
      state: 9
    }, 
    {
      pos: [1, 4, 1], 
      state: 9
    }, 
    {
      pos: [2, 4, 1], 
      state: 9
    }, 
    {
      pos: [3, 4, 1], 
      state: 9
    }, 
    {
      pos: [4, 4, 1], 
      state: 9
    }, 
    {
      pos: [5, 4, 1], 
      state: 9
    }, 
    {
      pos: [6, 4, 1], 
      state: 9
    }, 
    {
      pos: [7, 4, 1], 
      state: 9
    }, 
    {
      pos: [8, 4, 1], 
      state: 9
    }, 
    {
      pos: [9, 4, 1], 
      state: 9
    }, 
    {
      pos: [10, 4, 1], 
      state: 9
    }, 
    {
      pos: [11, 4, 1], 
      state: 9
    }, 
    {
      pos: [12, 4, 1], 
      state: 9
    }, 
    {
      pos: [0, 5, 1], 
      state: 9
    }, 
    {
      pos: [1, 5, 1], 
      state: 9
    }, 
    {
      pos: [2, 5, 1], 
      state: 9
    }, 
    {
      pos: [3, 5, 1], 
      state: 9
    }, 
    {
      pos: [4, 5, 1], 
      state: 9
    }, 
    {
      pos: [5, 5, 1], 
      state: 9
    }, 
    {
      pos: [6, 5, 1], 
      state: 9
    }, 
    {
      pos: [7, 5, 1], 
      state: 9
    }, 
    {
      pos: [8, 5, 1], 
      state: 9
    }, 
    {
      pos: [9, 5, 1], 
      state: 9
    }, 
    {
      pos: [10, 5, 1], 
      state: 9
    }, 
    {
      pos: [11, 5, 1], 
      state: 9
    }, 
    {
      pos: [12, 5, 1], 
      state: 9
    }, 
    {
      pos: [0, 6, 1], 
      state: 9
    }, 
    {
      pos: [1, 6, 1], 
      state: 9
    }, 
    {
      pos: [2, 6, 1], 
      state: 9
    }, 
    {
      pos: [3, 6, 1], 
      state: 9
    }, 
    {
      pos: [4, 6, 1], 
      state: 9
    }, 
    {
      pos: [5, 6, 1], 
      state: 9
    }, 
    {
      pos: [6, 6, 1], 
      state: 9
    }, 
    {
      pos: [7, 6, 1], 
      state: 9
    }, 
    {
      pos: [8, 6, 1], 
      state: 9
    }, 
    {
      pos: [9, 6, 1], 
      state: 9
    }, 
    {
      pos: [10, 6, 1], 
      state: 9
    }, 
    {
      pos: [11, 6, 1], 
      state: 9
    }, 
    {
      pos: [12, 6, 1], 
      state: 9
    }, 
    {
      pos: [0, 7, 1], 
      state: 9
    }, 
    {
      pos: [1, 7, 1], 
      state: 9
    }, 
    {
      pos: [2, 7, 1], 
      state: 9
    }, 
    {
      pos: [3, 7, 1], 
      state: 9
    }, 
    {
      pos: [4, 7, 1], 
      state: 9
    }, 
    {
      pos: [5, 7, 1], 
      state: 9
    }, 
    {
      pos: [7, 7, 1], 
      state: 9
    }, 
    {
      pos: [8, 7, 1], 
      state: 9
    }, 
    {
      pos: [9, 7, 1], 
      state: 9
    }, 
    {
      pos: [10, 7, 1], 
      state: 9
    }, 
    {
      pos: [11, 7, 1], 
      state: 9
    }, 
    {
      pos: [12, 7, 1], 
      state: 9
    }, 
    {
      pos: [0, 8, 1], 
      state: 9
    }, 
    {
      pos: [1, 8, 1], 
      state: 9
    }, 
    {
      pos: [2, 8, 1], 
      state: 9
    }, 
    {
      pos: [3, 8, 1], 
      state: 9
    }, 
    {
      pos: [4, 8, 1], 
      state: 9
    }, 
    {
      pos: [5, 8, 1], 
      state: 9
    }, 
    {
      pos: [6, 8, 1], 
      state: 10
    }, 
    {
      pos: [7, 8, 1], 
      state: 9
    }, 
    {
      pos: [8, 8, 1], 
      state: 9
    }, 
    {
      pos: [9, 8, 1], 
      state: 9
    }, 
    {
      pos: [10, 8, 1], 
      state: 9
    }, 
    {
      pos: [11, 8, 1], 
      state: 9
    }, 
    {
      pos: [12, 8, 1], 
      state: 9
    }, 
    {
      pos: [0, 9, 1], 
      state: 9
    }, 
    {
      pos: [1, 9, 1], 
      state: 9
    }, 
    {
      pos: [2, 9, 1], 
      state: 9
    }, 
    {
      pos: [3, 9, 1], 
      state: 9
    }, 
    {
      pos: [4, 9, 1], 
      state: 9
    }, 
    {
      pos: [5, 9, 1], 
      state: 9
    }, 
    {
      pos: [6, 9, 1], 
      state: 9
    }, 
    {
      pos: [7, 9, 1], 
      state: 9
    }, 
    {
      pos: [8, 9, 1], 
      state: 9
    }, 
    {
      pos: [9, 9, 1], 
      state: 9
    }, 
    {
      pos: [10, 9, 1], 
      state: 9
    }, 
    {
      pos: [11, 9, 1], 
      state: 9
    }, 
    {
      pos: [12, 9, 1], 
      state: 9
    }, 
    {
      pos: [0, 10, 1], 
      state: 9
    }, 
    {
      pos: [1, 10, 1], 
      state: 9
    }, 
    {
      pos: [2, 10, 1], 
      state: 9
    }, 
    {
      pos: [3, 10, 1], 
      state: 9
    }, 
    {
      pos: [4, 10, 1], 
      state: 9
    }, 
    {
      pos: [5, 10, 1], 
      state: 9
    }, 
    {
      pos: [6, 10, 1], 
      state: 9
    }, 
    {
      pos: [7, 10, 1], 
      state: 9
    }, 
    {
      pos: [8, 10, 1], 
      state: 9
    }, 
    {
      pos: [9, 10, 1], 
      state: 9
    }, 
    {
      pos: [10, 10, 1], 
      state: 9
    }, 
    {
      pos: [11, 10, 1], 
      state: 9
    }, 
    {
      pos: [12, 10, 1], 
      state: 9
    }, 
    {
      pos: [0, 11, 1], 
      state: 9
    }, 
    {
      pos: [1, 11, 1], 
      state: 9
    }, 
    {
      pos: [2, 11, 1], 
      state: 9
    }, 
    {
      pos: [3, 11, 1], 
      state: 9
    }, 
    {
      pos: [4, 11, 1], 
      state: 9
    }, 
    {
      pos: [5, 11, 1], 
      state: 9
    }, 
    {
      pos: [6, 11, 1], 
      state: 9
    }, 
    {
      pos: [7, 11, 1], 
      state: 9
    }, 
    {
      pos: [8, 11, 1], 
      state: 9
    }, 
    {
      pos: [9, 11, 1], 
      state: 9
    }, 
    {
      pos: [10, 11, 1], 
      state: 9
    }, 
    {
      pos: [11, 11, 1], 
      state: 9
    }, 
    {
      pos: [12, 11, 1], 
      state: 9
    }, 
    {
      pos: [0, 12, 1], 
      state: 9
    }, 
    {
      pos: [1, 12, 1], 
      state: 9
    }, 
    {
      pos: [2, 12, 1], 
      state: 9
    }, 
    {
      pos: [3, 12, 1], 
      state: 9
    }, 
    {
      pos: [4, 12, 1], 
      state: 9
    }, 
    {
      pos: [5, 12, 1], 
      state: 9
    }, 
    {
      pos: [6, 12, 1], 
      state: 11
    }, 
    {
      pos: [7, 12, 1], 
      state: 9
    }, 
    {
      pos: [8, 12, 1], 
      state: 9
    }, 
    {
      pos: [9, 12, 1], 
      state: 9
    }, 
    {
      pos: [10, 12, 1], 
      state: 9
    }, 
    {
      pos: [11, 12, 1], 
      state: 9
    }, 
    {
      pos: [12, 12, 1], 
      state: 9
    }, 
    {
      pos: [0, 13, 1], 
      state: 9
    }, 
    {
      pos: [1, 13, 1], 
      state: 9
    }, 
    {
      pos: [2, 13, 1], 
      state: 9
    }, 
    {
      pos: [3, 13, 1], 
      state: 9
    }, 
    {
      pos: [4, 13, 1], 
      state: 9
    }, 
    {
      pos: [5, 13, 1], 
      state: 9
    }, 
    {
      pos: [6, 13, 1], 
      state: 9
    }, 
    {
      pos: [7, 13, 1], 
      state: 9
    }, 
    {
      pos: [8, 13, 1], 
      state: 9
    }, 
    {
      pos: [9, 13, 1], 
      state: 9
    }, 
    {
      pos: [10, 13, 1], 
      state: 9
    }, 
    {
      pos: [11, 13, 1], 
      state: 9
    }, 
    {
      pos: [12, 13, 1], 
      state: 9
    }, 
    {
      pos: [0, 14, 1], 
      state: 9
    }, 
    {
      pos: [1, 14, 1], 
      state: 9
    }, 
    {
      pos: [2, 14, 1], 
      state: 9
    }, 
    {
      pos: [3, 14, 1], 
      state: 9
    }, 
    {
      pos: [4, 14, 1], 
      state: 9
    }, 
    {
      pos: [5, 14, 1], 
      state: 9
    }, 
    {
      pos: [6, 14, 1], 
      state: 9
    }, 
    {
      pos: [7, 14, 1], 
      state: 9
    }, 
    {
      pos: [8, 14, 1], 
      state: 9
    }, 
    {
      pos: [9, 14, 1], 
      state: 9
    }, 
    {
      pos: [10, 14, 1], 
      state: 9
    }, 
    {
      pos: [11, 14, 1], 
      state: 9
    }, 
    {
      pos: [12, 14, 1], 
      state: 9
    }, 
    {
      pos: [0, 15, 1], 
      state: 9
    }, 
    {
      pos: [1, 15, 1], 
      state: 9
    }, 
    {
      pos: [2, 15, 1], 
      state: 9
    }, 
    {
      pos: [3, 15, 1], 
      state: 9
    }, 
    {
      pos: [4, 15, 1], 
      state: 9
    }, 
    {
      pos: [5, 15, 1], 
      state: 9
    }, 
    {
      pos: [6, 15, 1], 
      state: 9
    }, 
    {
      pos: [7, 15, 1], 
      state: 9
    }, 
    {
      pos: [8, 15, 1], 
      state: 9
    }, 
    {
      pos: [9, 15, 1], 
      state: 9
    }, 
    {
      pos: [10, 15, 1], 
      state: 9
    }, 
    {
      pos: [11, 15, 1], 
      state: 9
    }, 
    {
      pos: [12, 15, 1], 
      state: 9
    }, 
    {
      pos: [0, 16, 1], 
      state: 9
    }, 
    {
      pos: [1, 16, 1], 
      state: 9
    }, 
    {
      pos: [2, 16, 1], 
      state: 9
    }, 
    {
      pos: [3, 16, 1], 
      state: 9
    }, 
    {
      pos: [4, 16, 1], 
      state: 9
    }, 
    {
      pos: [5, 16, 1], 
      state: 9
    }, 
    {
      pos: [6, 16, 1], 
      state: 9
    }, 
    {
      pos: [7, 16, 1], 
      state: 9
    }, 
    {
      pos: [8, 16, 1], 
      state: 9
    }, 
    {
      pos: [9, 16, 1], 
      state: 9
    }, 
    {
      pos: [10, 16, 1], 
      state: 9
    }, 
    {
      pos: [11, 16, 1], 
      state: 9
    }, 
    {
      pos: [12, 16, 1], 
      state: 9
    }, 
    {
      pos: [0, 17, 1], 
      state: 9
    }, 
    {
      pos: [1, 17, 1], 
      state: 9
    }, 
    {
      pos: [2, 17, 1], 
      state: 9
    }, 
    {
      pos: [3, 17, 1], 
      state: 9
    }, 
    {
      pos: [4, 17, 1], 
      state: 9
    }, 
    {
      pos: [5, 17, 1], 
      state: 9
    }, 
    {
      pos: [6, 17, 1], 
      state: 9
    }, 
    {
      pos: [7, 17, 1], 
      state: 9
    }, 
    {
      pos: [8, 17, 1], 
      state: 9
    }, 
    {
      pos: [9, 17, 1], 
      state: 9
    }, 
    {
      pos: [10, 17, 1], 
      state: 9
    }, 
    {
      pos: [11, 17, 1], 
      state: 9
    }, 
    {
      pos: [12, 17, 1], 
      state: 9
    }, 
    {
      pos: [0, 18, 1], 
      state: 9
    }, 
    {
      pos: [1, 18, 1], 
      state: 9
    }, 
    {
      pos: [2, 18, 1], 
      state: 9
    }, 
    {
      pos: [3, 18, 1], 
      state: 9
    }, 
    {
      pos: [4, 18, 1], 
      state: 9
    }, 
    {
      pos: [5, 18, 1], 
      state: 9
    }, 
    {
      pos: [6, 18, 1], 
      state: 9
    }, 
    {
      pos: [7, 18, 1], 
      state: 9
    }, 
    {
      pos: [8, 18, 1], 
      state: 9
    }, 
    {
      pos: [9, 18, 1], 
      state: 9
    }, 
    {
      pos: [10, 18, 1], 
      state: 9
    }, 
    {
      pos: [11, 18, 1], 
      state: 9
    }, 
    {
      pos: [12, 18, 1], 
      state: 9
    }, 
    {
      pos: [0, 19, 1], 
      state: 9
    }, 
    {
      pos: [1, 19, 1], 
      state: 9
    }, 
    {
      pos: [2, 19, 1], 
      state: 9
    }, 
    {
      pos: [3, 19, 1], 
      state: 9
    }, 
    {
      pos: [4, 19, 1], 
      state: 9
    }, 
    {
      pos: [5, 19, 1], 
      state: 9
    }, 
    {
      pos: [6, 19, 1], 
      state: 9
    }, 
    {
      pos: [7, 19, 1], 
      state: 9
    }, 
    {
      pos: [8, 19, 1], 
      state: 9
    }, 
    {
      pos: [9, 19, 1], 
      state: 9
    }, 
    {
      pos: [10, 19, 1], 
      state: 9
    }, 
    {
      pos: [11, 19, 1], 
      state: 9
    }, 
    {
      pos: [12, 19, 1], 
      state: 9
    }, 
    {
      pos: [0, 20, 1], 
      state: 9
    }, 
    {
      pos: [1, 20, 1], 
      state: 9
    }, 
    {
      pos: [2, 20, 1], 
      state: 9
    }, 
    {
      pos: [3, 20, 1], 
      state: 9
    }, 
    {
      pos: [4, 20, 1], 
      state: 9
    }, 
    {
      pos: [5, 20, 1], 
      state: 9
    }, 
    {
      pos: [6, 20, 1], 
      state: 9
    }, 
    {
      pos: [7, 20, 1], 
      state: 9
    }, 
    {
      pos: [8, 20, 1], 
      state: 9
    }, 
    {
      pos: [9, 20, 1], 
      state: 9
    }, 
    {
      pos: [10, 20, 1], 
      state: 9
    }, 
    {
      pos: [11, 20, 1], 
      state: 9
    }, 
    {
      pos: [12, 20, 1], 
      state: 9
    }, 
    {
      pos: [0, 21, 1], 
      state: 9
    }, 
    {
      pos: [1, 21, 1], 
      state: 9
    }, 
    {
      pos: [2, 21, 1], 
      state: 9
    }, 
    {
      pos: [3, 21, 1], 
      state: 9
    }, 
    {
      pos: [4, 21, 1], 
      state: 9
    }, 
    {
      pos: [5, 21, 1], 
      state: 9
    }, 
    {
      pos: [6, 21, 1], 
      state: 9
    }, 
    {
      pos: [7, 21, 1], 
      state: 9
    }, 
    {
      pos: [8, 21, 1], 
      state: 9
    }, 
    {
      pos: [9, 21, 1], 
      state: 9
    }, 
    {
      pos: [10, 21, 1], 
      state: 9
    }, 
    {
      pos: [11, 21, 1], 
      state: 9
    }, 
    {
      pos: [12, 21, 1], 
      state: 9
    }, 
    {
      pos: [0, 22, 1], 
      state: 9
    }, 
    {
      pos: [1, 22, 1], 
      state: 9
    }, 
    {
      pos: [2, 22, 1], 
      state: 9
    }, 
    {
      pos: [3, 22, 1], 
      state: 9
    }, 
    {
      pos: [4, 22, 1], 
      state: 9
    }, 
    {
      pos: [5, 22, 1], 
      state: 9
    }, 
    {
      pos: [6, 22, 1], 
      state: 9
    }, 
    {
      pos: [7, 22, 1], 
      state: 9
    }, 
    {
      pos: [8, 22, 1], 
      state: 9
    }, 
    {
      pos: [9, 22, 1], 
      state: 9
    }, 
    {
      pos: [10, 22, 1], 
      state: 9
    }, 
    {
      pos: [11, 22, 1], 
      state: 9
    }, 
    {
      pos: [12, 22, 1], 
      state: 9
    }, 
    {
      pos: [0, 23, 1], 
      state: 9
    }, 
    {
      pos: [1, 23, 1], 
      state: 9
    }, 
    {
      pos: [2, 23, 1], 
      state: 9
    }, 
    {
      pos: [3, 23, 1], 
      state: 9
    }, 
    {
      pos: [4, 23, 1], 
      state: 9
    }, 
    {
      pos: [5, 23, 1], 
      state: 9
    }, 
    {
      pos: [6, 23, 1], 
      state: 9
    }, 
    {
      pos: [7, 23, 1], 
      state: 9
    }, 
    {
      pos: [8, 23, 1], 
      state: 9
    }, 
    {
      pos: [9, 23, 1], 
      state: 9
    }, 
    {
      pos: [10, 23, 1], 
      state: 9
    }, 
    {
      pos: [11, 23, 1], 
      state: 9
    }, 
    {
      pos: [12, 23, 1], 
      state: 9
    }, 
    {
      pos: [0, 0, 2], 
      state: 9
    }, 
    {
      pos: [1, 0, 2], 
      state: 9
    }, 
    {
      pos: [2, 0, 2], 
      state: 9
    }, 
    {
      pos: [3, 0, 2], 
      state: 9
    }, 
    {
      pos: [4, 0, 2], 
      state: 9
    }, 
    {
      pos: [5, 0, 2], 
      state: 9
    }, 
    {
      pos: [6, 0, 2], 
      state: 9
    }, 
    {
      pos: [7, 0, 2], 
      state: 9
    }, 
    {
      pos: [8, 0, 2], 
      state: 9
    }, 
    {
      pos: [9, 0, 2], 
      state: 9
    }, 
    {
      pos: [10, 0, 2], 
      state: 9
    }, 
    {
      pos: [11, 0, 2], 
      state: 9
    }, 
    {
      pos: [12, 0, 2], 
      state: 9
    }, 
    {
      pos: [0, 1, 2], 
      state: 9
    }, 
    {
      pos: [1, 1, 2], 
      state: 9
    }, 
    {
      pos: [2, 1, 2], 
      state: 9
    }, 
    {
      pos: [3, 1, 2], 
      state: 9
    }, 
    {
      pos: [4, 1, 2], 
      state: 9
    }, 
    {
      pos: [5, 1, 2], 
      state: 9
    }, 
    {
      pos: [6, 1, 2], 
      state: 9
    }, 
    {
      pos: [7, 1, 2], 
      state: 9
    }, 
    {
      pos: [8, 1, 2], 
      state: 9
    }, 
    {
      pos: [9, 1, 2], 
      state: 9
    }, 
    {
      pos: [10, 1, 2], 
      state: 9
    }, 
    {
      pos: [11, 1, 2], 
      state: 9
    }, 
    {
      pos: [12, 1, 2], 
      state: 9
    }, 
    {
      pos: [0, 2, 2], 
      state: 9
    }, 
    {
      pos: [1, 2, 2], 
      state: 9
    }, 
    {
      pos: [2, 2, 2], 
      state: 9
    }, 
    {
      pos: [3, 2, 2], 
      state: 9
    }, 
    {
      pos: [4, 2, 2], 
      state: 9
    }, 
    {
      pos: [5, 2, 2], 
      state: 9
    }, 
    {
      pos: [6, 2, 2], 
      state: 9
    }, 
    {
      pos: [7, 2, 2], 
      state: 9
    }, 
    {
      pos: [8, 2, 2], 
      state: 9
    }, 
    {
      pos: [9, 2, 2], 
      state: 9
    }, 
    {
      pos: [10, 2, 2], 
      state: 9
    }, 
    {
      pos: [11, 2, 2], 
      state: 9
    }, 
    {
      pos: [12, 2, 2], 
      state: 9
    }, 
    {
      pos: [0, 3, 2], 
      state: 9
    }, 
    {
      pos: [1, 3, 2], 
      state: 9
    }, 
    {
      pos: [2, 3, 2], 
      state: 9
    }, 
    {
      pos: [3, 3, 2], 
      state: 9
    }, 
    {
      pos: [4, 3, 2], 
      state: 9
    }, 
    {
      pos: [5, 3, 2], 
      state: 9
    }, 
    {
      pos: [6, 3, 2], 
      state: 9
    }, 
    {
      pos: [7, 3, 2], 
      state: 9
    }, 
    {
      pos: [8, 3, 2], 
      state: 9
    }, 
    {
      pos: [9, 3, 2], 
      state: 9
    }, 
    {
      pos: [10, 3, 2], 
      state: 9
    }, 
    {
      pos: [11, 3, 2], 
      state: 9
    }, 
    {
      pos: [12, 3, 2], 
      state: 9
    }, 
    {
      pos: [0, 4, 2], 
      state: 9
    }, 
    {
      pos: [1, 4, 2], 
      state: 9
    }, 
    {
      pos: [2, 4, 2], 
      state: 9
    }, 
    {
      pos: [3, 4, 2], 
      state: 9
    }, 
    {
      pos: [4, 4, 2], 
      state: 9
    }, 
    {
      pos: [5, 4, 2], 
      state: 9
    }, 
    {
      pos: [6, 4, 2], 
      state: 9
    }, 
    {
      pos: [7, 4, 2], 
      state: 9
    }, 
    {
      pos: [8, 4, 2], 
      state: 9
    }, 
    {
      pos: [9, 4, 2], 
      state: 9
    }, 
    {
      pos: [10, 4, 2], 
      state: 9
    }, 
    {
      pos: [11, 4, 2], 
      state: 9
    }, 
    {
      pos: [12, 4, 2], 
      state: 9
    }, 
    {
      pos: [0, 5, 2], 
      state: 9
    }, 
    {
      pos: [1, 5, 2], 
      state: 9
    }, 
    {
      pos: [2, 5, 2], 
      state: 9
    }, 
    {
      pos: [3, 5, 2], 
      state: 9
    }, 
    {
      pos: [4, 5, 2], 
      state: 9
    }, 
    {
      pos: [5, 5, 2], 
      state: 9
    }, 
    {
      pos: [6, 5, 2], 
      state: 9
    }, 
    {
      pos: [7, 5, 2], 
      state: 9
    }, 
    {
      pos: [8, 5, 2], 
      state: 9
    }, 
    {
      pos: [9, 5, 2], 
      state: 9
    }, 
    {
      pos: [10, 5, 2], 
      state: 9
    }, 
    {
      pos: [11, 5, 2], 
      state: 9
    }, 
    {
      pos: [12, 5, 2], 
      state: 9
    }, 
    {
      pos: [0, 6, 2], 
      state: 9
    }, 
    {
      pos: [1, 6, 2], 
      state: 9
    }, 
    {
      pos: [2, 6, 2], 
      state: 9
    }, 
    {
      pos: [3, 6, 2], 
      state: 9
    }, 
    {
      pos: [4, 6, 2], 
      state: 9
    }, 
    {
      pos: [5, 6, 2], 
      state: 9
    }, 
    {
      pos: [6, 6, 2], 
      state: 9
    }, 
    {
      pos: [7, 6, 2], 
      state: 9
    }, 
    {
      pos: [8, 6, 2], 
      state: 9
    }, 
    {
      pos: [9, 6, 2], 
      state: 9
    }, 
    {
      pos: [10, 6, 2], 
      state: 9
    }, 
    {
      pos: [11, 6, 2], 
      state: 9
    }, 
    {
      pos: [12, 6, 2], 
      state: 9
    }, 
    {
      pos: [0, 7, 2], 
      state: 9
    }, 
    {
      pos: [1, 7, 2], 
      state: 9
    }, 
    {
      pos: [2, 7, 2], 
      state: 9
    }, 
    {
      pos: [3, 7, 2], 
      state: 9
    }, 
    {
      pos: [4, 7, 2], 
      state: 9
    }, 
    {
      pos: [5, 7, 2], 
      state: 9
    }, 
    {
      pos: [7, 7, 2], 
      state: 9
    }, 
    {
      pos: [8, 7, 2], 
      state: 9
    }, 
    {
      pos: [9, 7, 2], 
      state: 9
    }, 
    {
      pos: [10, 7, 2], 
      state: 9
    }, 
    {
      pos: [11, 7, 2], 
      state: 9
    }, 
    {
      pos: [12, 7, 2], 
      state: 9
    }, 
    {
      pos: [0, 8, 2], 
      state: 9
    }, 
    {
      pos: [1, 8, 2], 
      state: 9
    }, 
    {
      pos: [2, 8, 2], 
      state: 9
    }, 
    {
      pos: [3, 8, 2], 
      state: 9
    }, 
    {
      pos: [4, 8, 2], 
      state: 9
    }, 
    {
      pos: [5, 8, 2], 
      state: 9
    }, 
    {
      pos: [6, 8, 2], 
      state: 9
    }, 
    {
      pos: [7, 8, 2], 
      state: 9
    }, 
    {
      pos: [8, 8, 2], 
      state: 9
    }, 
    {
      pos: [9, 8, 2], 
      state: 9
    }, 
    {
      pos: [10, 8, 2], 
      state: 9
    }, 
    {
      pos: [11, 8, 2], 
      state: 9
    }, 
    {
      pos: [12, 8, 2], 
      state: 9
    }, 
    {
      pos: [0, 9, 2], 
      state: 9
    }, 
    {
      pos: [1, 9, 2], 
      state: 9
    }, 
    {
      pos: [2, 9, 2], 
      state: 9
    }, 
    {
      pos: [3, 9, 2], 
      state: 9
    }, 
    {
      pos: [4, 9, 2], 
      state: 9
    }, 
    {
      pos: [5, 9, 2], 
      state: 9
    }, 
    {
      pos: [6, 9, 2], 
      state: 9
    }, 
    {
      pos: [7, 9, 2], 
      state: 9
    }, 
    {
      pos: [8, 9, 2], 
      state: 9
    }, 
    {
      pos: [9, 9, 2], 
      state: 9
    }, 
    {
      pos: [10, 9, 2], 
      state: 9
    }, 
    {
      pos: [11, 9, 2], 
      state: 9
    }, 
    {
      pos: [12, 9, 2], 
      state: 9
    }, 
    {
      pos: [0, 10, 2], 
      state: 9
    }, 
    {
      pos: [1, 10, 2], 
      state: 9
    }, 
    {
      pos: [2, 10, 2], 
      state: 9
    }, 
    {
      pos: [3, 10, 2], 
      state: 9
    }, 
    {
      pos: [4, 10, 2], 
      state: 9
    }, 
    {
      pos: [5, 10, 2], 
      state: 9
    }, 
    {
      pos: [6, 10, 2], 
      state: 9
    }, 
    {
      pos: [7, 10, 2], 
      state: 9
    }, 
    {
      pos: [8, 10, 2], 
      state: 9
    }, 
    {
      pos: [9, 10, 2], 
      state: 9
    }, 
    {
      pos: [10, 10, 2], 
      state: 9
    }, 
    {
      pos: [11, 10, 2], 
      state: 9
    }, 
    {
      pos: [12, 10, 2], 
      state: 9
    }, 
    {
      pos: [0, 11, 2], 
      state: 9
    }, 
    {
      pos: [1, 11, 2], 
      state: 9
    }, 
    {
      pos: [2, 11, 2], 
      state: 9
    }, 
    {
      pos: [3, 11, 2], 
      state: 9
    }, 
    {
      pos: [4, 11, 2], 
      state: 9
    }, 
    {
      pos: [5, 11, 2], 
      state: 9
    }, 
    {
      pos: [6, 11, 2], 
      state: 9
    }, 
    {
      pos: [7, 11, 2], 
      state: 9
    }, 
    {
      pos: [8, 11, 2], 
      state: 9
    }, 
    {
      pos: [9, 11, 2], 
      state: 9
    }, 
    {
      pos: [10, 11, 2], 
      state: 9
    }, 
    {
      pos: [11, 11, 2], 
      state: 9
    }, 
    {
      pos: [12, 11, 2], 
      state: 9
    }, 
    {
      pos: [0, 12, 2], 
      state: 9
    }, 
    {
      pos: [1, 12, 2], 
      state: 9
    }, 
    {
      pos: [2, 12, 2], 
      state: 9
    }, 
    {
      pos: [3, 12, 2], 
      state: 9
    }, 
    {
      pos: [4, 12, 2], 
      state: 9
    }, 
    {
      pos: [5, 12, 2], 
      state: 9
    }, 
    {
      pos: [7, 12, 2], 
      state: 9
    }, 
    {
      pos: [8, 12, 2], 
      state: 9
    }, 
    {
      pos: [9, 12, 2], 
      state: 9
    }, 
    {
      pos: [10, 12, 2], 
      state: 9
    }, 
    {
      pos: [11, 12, 2], 
      state: 9
    }, 
    {
      pos: [12, 12, 2], 
      state: 9
    }, 
    {
      pos: [0, 13, 2], 
      state: 9
    }, 
    {
      pos: [1, 13, 2], 
      state: 9
    }, 
    {
      pos: [2, 13, 2], 
      state: 9
    }, 
    {
      pos: [3, 13, 2], 
      state: 9
    }, 
    {
      pos: [4, 13, 2], 
      state: 9
    }, 
    {
      pos: [5, 13, 2], 
      state: 9
    }, 
    {
      pos: [6, 13, 2], 
      state: 9
    }, 
    {
      pos: [7, 13, 2], 
      state: 9
    }, 
    {
      pos: [8, 13, 2], 
      state: 9
    }, 
    {
      pos: [9, 13, 2], 
      state: 9
    }, 
    {
      pos: [10, 13, 2], 
      state: 9
    }, 
    {
      pos: [11, 13, 2], 
      state: 9
    }, 
    {
      pos: [12, 13, 2], 
      state: 9
    }, 
    {
      pos: [0, 14, 2], 
      state: 9
    }, 
    {
      pos: [1, 14, 2], 
      state: 9
    }, 
    {
      pos: [2, 14, 2], 
      state: 9
    }, 
    {
      pos: [3, 14, 2], 
      state: 9
    }, 
    {
      pos: [4, 14, 2], 
      state: 9
    }, 
    {
      pos: [5, 14, 2], 
      state: 9
    }, 
    {
      pos: [6, 14, 2], 
      state: 9
    }, 
    {
      pos: [7, 14, 2], 
      state: 9
    }, 
    {
      pos: [8, 14, 2], 
      state: 9
    }, 
    {
      pos: [9, 14, 2], 
      state: 9
    }, 
    {
      pos: [10, 14, 2], 
      state: 9
    }, 
    {
      pos: [11, 14, 2], 
      state: 9
    }, 
    {
      pos: [12, 14, 2], 
      state: 9
    }, 
    {
      pos: [0, 15, 2], 
      state: 9
    }, 
    {
      pos: [1, 15, 2], 
      state: 9
    }, 
    {
      pos: [2, 15, 2], 
      state: 9
    }, 
    {
      pos: [3, 15, 2], 
      state: 9
    }, 
    {
      pos: [4, 15, 2], 
      state: 9
    }, 
    {
      pos: [5, 15, 2], 
      state: 9
    }, 
    {
      pos: [6, 15, 2], 
      state: 9
    }, 
    {
      pos: [7, 15, 2], 
      state: 9
    }, 
    {
      pos: [8, 15, 2], 
      state: 9
    }, 
    {
      pos: [9, 15, 2], 
      state: 9
    }, 
    {
      pos: [10, 15, 2], 
      state: 9
    }, 
    {
      pos: [11, 15, 2], 
      state: 9
    }, 
    {
      pos: [12, 15, 2], 
      state: 9
    }, 
    {
      pos: [0, 16, 2], 
      state: 9
    }, 
    {
      pos: [1, 16, 2], 
      state: 9
    }, 
    {
      pos: [2, 16, 2], 
      state: 9
    }, 
    {
      pos: [3, 16, 2], 
      state: 9
    }, 
    {
      pos: [4, 16, 2], 
      state: 9
    }, 
    {
      pos: [5, 16, 2], 
      state: 9
    }, 
    {
      pos: [6, 16, 2], 
      state: 9
    }, 
    {
      pos: [7, 16, 2], 
      state: 9
    }, 
    {
      pos: [8, 16, 2], 
      state: 9
    }, 
    {
      pos: [9, 16, 2], 
      state: 9
    }, 
    {
      pos: [10, 16, 2], 
      state: 9
    }, 
    {
      pos: [11, 16, 2], 
      state: 9
    }, 
    {
      pos: [12, 16, 2], 
      state: 9
    }, 
    {
      pos: [0, 17, 2], 
      state: 9
    }, 
    {
      pos: [1, 17, 2], 
      state: 9
    }, 
    {
      pos: [2, 17, 2], 
      state: 9
    }, 
    {
      pos: [3, 17, 2], 
      state: 9
    }, 
    {
      pos: [4, 17, 2], 
      state: 9
    }, 
    {
      pos: [5, 17, 2], 
      state: 9
    }, 
    {
      pos: [6, 17, 2], 
      state: 9
    }, 
    {
      pos: [7, 17, 2], 
      state: 9
    }, 
    {
      pos: [8, 17, 2], 
      state: 9
    }, 
    {
      pos: [9, 17, 2], 
      state: 9
    }, 
    {
      pos: [10, 17, 2], 
      state: 9
    }, 
    {
      pos: [11, 17, 2], 
      state: 9
    }, 
    {
      pos: [12, 17, 2], 
      state: 9
    }, 
    {
      pos: [0, 18, 2], 
      state: 9
    }, 
    {
      pos: [1, 18, 2], 
      state: 9
    }, 
    {
      pos: [2, 18, 2], 
      state: 9
    }, 
    {
      pos: [3, 18, 2], 
      state: 9
    }, 
    {
      pos: [4, 18, 2], 
      state: 9
    }, 
    {
      pos: [5, 18, 2], 
      state: 9
    }, 
    {
      pos: [6, 18, 2], 
      state: 9
    }, 
    {
      pos: [7, 18, 2], 
      state: 9
    }, 
    {
      pos: [8, 18, 2], 
      state: 9
    }, 
    {
      pos: [9, 18, 2], 
      state: 9
    }, 
    {
      pos: [10, 18, 2], 
      state: 9
    }, 
    {
      pos: [11, 18, 2], 
      state: 9
    }, 
    {
      pos: [12, 18, 2], 
      state: 9
    }, 
    {
      pos: [0, 19, 2], 
      state: 9
    }, 
    {
      pos: [1, 19, 2], 
      state: 9
    }, 
    {
      pos: [2, 19, 2], 
      state: 9
    }, 
    {
      pos: [3, 19, 2], 
      state: 9
    }, 
    {
      pos: [4, 19, 2], 
      state: 9
    }, 
    {
      pos: [5, 19, 2], 
      state: 9
    }, 
    {
      pos: [6, 19, 2], 
      state: 9
    }, 
    {
      pos: [7, 19, 2], 
      state: 9
    }, 
    {
      pos: [8, 19, 2], 
      state: 9
    }, 
    {
      pos: [9, 19, 2], 
      state: 9
    }, 
    {
      pos: [10, 19, 2], 
      state: 9
    }, 
    {
      pos: [11, 19, 2], 
      state: 9
    }, 
    {
      pos: [12, 19, 2], 
      state: 9
    }, 
    {
      pos: [0, 20, 2], 
      state: 9
    }, 
    {
      pos: [1, 20, 2], 
      state: 9
    }, 
    {
      pos: [2, 20, 2], 
      state: 9
    }, 
    {
      pos: [3, 20, 2], 
      state: 9
    }, 
    {
      pos: [4, 20, 2], 
      state: 9
    }, 
    {
      pos: [5, 20, 2], 
      state: 9
    }, 
    {
      pos: [6, 20, 2], 
      state: 9
    }, 
    {
      pos: [7, 20, 2], 
      state: 9
    }, 
    {
      pos: [8, 20, 2], 
      state: 9
    }, 
    {
      pos: [9, 20, 2], 
      state: 9
    }, 
    {
      pos: [10, 20, 2], 
      state: 9
    }, 
    {
      pos: [11, 20, 2], 
      state: 9
    }, 
    {
      pos: [12, 20, 2], 
      state: 9
    }, 
    {
      pos: [0, 21, 2], 
      state: 9
    }, 
    {
      pos: [1, 21, 2], 
      state: 9
    }, 
    {
      pos: [2, 21, 2], 
      state: 9
    }, 
    {
      pos: [3, 21, 2], 
      state: 9
    }, 
    {
      pos: [4, 21, 2], 
      state: 9
    }, 
    {
      pos: [5, 21, 2], 
      state: 9
    }, 
    {
      pos: [6, 21, 2], 
      state: 9
    }, 
    {
      pos: [7, 21, 2], 
      state: 9
    }, 
    {
      pos: [8, 21, 2], 
      state: 9
    }, 
    {
      pos: [9, 21, 2], 
      state: 9
    }, 
    {
      pos: [10, 21, 2], 
      state: 9
    }, 
    {
      pos: [11, 21, 2], 
      state: 9
    }, 
    {
      pos: [12, 21, 2], 
      state: 9
    }, 
    {
      pos: [0, 22, 2], 
      state: 9
    }, 
    {
      pos: [1, 22, 2], 
      state: 9
    }, 
    {
      pos: [2, 22, 2], 
      state: 9
    }, 
    {
      pos: [3, 22, 2], 
      state: 9
    }, 
    {
      pos: [4, 22, 2], 
      state: 9
    }, 
    {
      pos: [5, 22, 2], 
      state: 9
    }, 
    {
      pos: [6, 22, 2], 
      state: 9
    }, 
    {
      pos: [7, 22, 2], 
      state: 9
    }, 
    {
      pos: [8, 22, 2], 
      state: 9
    }, 
    {
      pos: [9, 22, 2], 
      state: 9
    }, 
    {
      pos: [10, 22, 2], 
      state: 9
    }, 
    {
      pos: [11, 22, 2], 
      state: 9
    }, 
    {
      pos: [12, 22, 2], 
      state: 9
    }, 
    {
      pos: [0, 23, 2], 
      state: 9
    }, 
    {
      pos: [1, 23, 2], 
      state: 9
    }, 
    {
      pos: [2, 23, 2], 
      state: 9
    }, 
    {
      pos: [3, 23, 2], 
      state: 9
    }, 
    {
      pos: [4, 23, 2], 
      state: 9
    }, 
    {
      pos: [5, 23, 2], 
      state: 9
    }, 
    {
      pos: [6, 23, 2], 
      state: 9
    }, 
    {
      pos: [7, 23, 2], 
      state: 9
    }, 
    {
      pos: [8, 23, 2], 
      state: 9
    }, 
    {
      pos: [9, 23, 2], 
      state: 9
    }, 
    {
      pos: [10, 23, 2], 
      state: 9
    }, 
    {
      pos: [11, 23, 2], 
      state: 9
    }, 
    {
      pos: [12, 23, 2], 
      state: 9
    }, 
    {
      pos: [0, 0, 3], 
      state: 9
    }, 
    {
      pos: [1, 0, 3], 
      state: 9
    }, 
    {
      pos: [2, 0, 3], 
      state: 9
    }, 
    {
      pos: [3, 0, 3], 
      state: 9
    }, 
    {
      pos: [4, 0, 3], 
      state: 9
    }, 
    {
      pos: [5, 0, 3], 
      state: 9
    }, 
    {
      pos: [6, 0, 3], 
      state: 9
    }, 
    {
      pos: [7, 0, 3], 
      state: 9
    }, 
    {
      pos: [8, 0, 3], 
      state: 9
    }, 
    {
      pos: [9, 0, 3], 
      state: 9
    }, 
    {
      pos: [10, 0, 3], 
      state: 9
    }, 
    {
      pos: [11, 0, 3], 
      state: 9
    }, 
    {
      pos: [12, 0, 3], 
      state: 9
    }, 
    {
      pos: [0, 1, 3], 
      state: 9
    }, 
    {
      pos: [1, 1, 3], 
      state: 9
    }, 
    {
      pos: [2, 1, 3], 
      state: 9
    }, 
    {
      pos: [3, 1, 3], 
      state: 9
    }, 
    {
      pos: [4, 1, 3], 
      state: 9
    }, 
    {
      pos: [5, 1, 3], 
      state: 9
    }, 
    {
      pos: [6, 1, 3], 
      state: 9
    }, 
    {
      pos: [7, 1, 3], 
      state: 9
    }, 
    {
      pos: [8, 1, 3], 
      state: 9
    }, 
    {
      pos: [9, 1, 3], 
      state: 9
    }, 
    {
      pos: [10, 1, 3], 
      state: 9
    }, 
    {
      pos: [11, 1, 3], 
      state: 9
    }, 
    {
      pos: [12, 1, 3], 
      state: 9
    }, 
    {
      pos: [0, 2, 3], 
      state: 9
    }, 
    {
      pos: [1, 2, 3], 
      state: 9
    }, 
    {
      pos: [2, 2, 3], 
      state: 9
    }, 
    {
      pos: [3, 2, 3], 
      state: 9
    }, 
    {
      pos: [4, 2, 3], 
      state: 9
    }, 
    {
      pos: [5, 2, 3], 
      state: 9
    }, 
    {
      pos: [6, 2, 3], 
      state: 9
    }, 
    {
      pos: [7, 2, 3], 
      state: 9
    }, 
    {
      pos: [8, 2, 3], 
      state: 9
    }, 
    {
      pos: [9, 2, 3], 
      state: 9
    }, 
    {
      pos: [10, 2, 3], 
      state: 9
    }, 
    {
      pos: [11, 2, 3], 
      state: 9
    }, 
    {
      pos: [12, 2, 3], 
      state: 9
    }, 
    {
      pos: [0, 3, 3], 
      state: 9
    }, 
    {
      pos: [1, 3, 3], 
      state: 9
    }, 
    {
      pos: [2, 3, 3], 
      state: 9
    }, 
    {
      pos: [3, 3, 3], 
      state: 9
    }, 
    {
      pos: [4, 3, 3], 
      state: 9
    }, 
    {
      pos: [5, 3, 3], 
      state: 9
    }, 
    {
      pos: [6, 3, 3], 
      state: 9
    }, 
    {
      pos: [7, 3, 3], 
      state: 9
    }, 
    {
      pos: [8, 3, 3], 
      state: 9
    }, 
    {
      pos: [9, 3, 3], 
      state: 9
    }, 
    {
      pos: [10, 3, 3], 
      state: 9
    }, 
    {
      pos: [11, 3, 3], 
      state: 9
    }, 
    {
      pos: [12, 3, 3], 
      state: 9
    }, 
    {
      pos: [0, 4, 3], 
      state: 9
    }, 
    {
      pos: [1, 4, 3], 
      state: 9
    }, 
    {
      pos: [2, 4, 3], 
      state: 9
    }, 
    {
      pos: [3, 4, 3], 
      state: 9
    }, 
    {
      pos: [4, 4, 3], 
      state: 9
    }, 
    {
      pos: [5, 4, 3], 
      state: 9
    }, 
    {
      pos: [6, 4, 3], 
      state: 9
    }, 
    {
      pos: [7, 4, 3], 
      state: 9
    }, 
    {
      pos: [8, 4, 3], 
      state: 9
    }, 
    {
      pos: [9, 4, 3], 
      state: 9
    }, 
    {
      pos: [10, 4, 3], 
      state: 9
    }, 
    {
      pos: [11, 4, 3], 
      state: 9
    }, 
    {
      pos: [12, 4, 3], 
      state: 9
    }, 
    {
      pos: [0, 5, 3], 
      state: 9
    }, 
    {
      pos: [1, 5, 3], 
      state: 9
    }, 
    {
      pos: [2, 5, 3], 
      state: 9
    }, 
    {
      pos: [3, 5, 3], 
      state: 9
    }, 
    {
      pos: [4, 5, 3], 
      state: 9
    }, 
    {
      pos: [5, 5, 3], 
      state: 9
    }, 
    {
      pos: [6, 5, 3], 
      state: 9
    }, 
    {
      pos: [7, 5, 3], 
      state: 9
    }, 
    {
      pos: [8, 5, 3], 
      state: 9
    }, 
    {
      pos: [9, 5, 3], 
      state: 9
    }, 
    {
      pos: [10, 5, 3], 
      state: 9
    }, 
    {
      pos: [11, 5, 3], 
      state: 9
    }, 
    {
      pos: [12, 5, 3], 
      state: 9
    }, 
    {
      pos: [0, 6, 3], 
      state: 9
    }, 
    {
      pos: [1, 6, 3], 
      state: 9
    }, 
    {
      pos: [2, 6, 3], 
      state: 9
    }, 
    {
      pos: [3, 6, 3], 
      state: 9
    }, 
    {
      pos: [4, 6, 3], 
      state: 9
    }, 
    {
      pos: [5, 6, 3], 
      state: 9
    }, 
    {
      pos: [7, 6, 3], 
      state: 9
    }, 
    {
      pos: [8, 6, 3], 
      state: 9
    }, 
    {
      pos: [9, 6, 3], 
      state: 9
    }, 
    {
      pos: [10, 6, 3], 
      state: 9
    }, 
    {
      pos: [11, 6, 3], 
      state: 9
    }, 
    {
      pos: [12, 6, 3], 
      state: 9
    }, 
    {
      pos: [0, 7, 3], 
      state: 9
    }, 
    {
      pos: [1, 7, 3], 
      state: 9
    }, 
    {
      pos: [2, 7, 3], 
      state: 9
    }, 
    {
      pos: [3, 7, 3], 
      state: 9
    }, 
    {
      pos: [4, 7, 3], 
      state: 9
    }, 
    {
      pos: [5, 7, 3], 
      state: 9
    }, 
    {
      pos: [7, 7, 3], 
      state: 9
    }, 
    {
      pos: [8, 7, 3], 
      state: 9
    }, 
    {
      pos: [9, 7, 3], 
      state: 9
    }, 
    {
      pos: [10, 7, 3], 
      state: 9
    }, 
    {
      pos: [11, 7, 3], 
      state: 9
    }, 
    {
      pos: [12, 7, 3], 
      state: 9
    }, 
    {
      pos: [0, 8, 3], 
      state: 9
    }, 
    {
      pos: [1, 8, 3], 
      state: 9
    }, 
    {
      pos: [2, 8, 3], 
      state: 9
    }, 
    {
      pos: [3, 8, 3], 
      state: 9
    }, 
    {
      pos: [4, 8, 3], 
      state: 9
    }, 
    {
      pos: [5, 8, 3], 
      state: 9
    }, 
    {
      pos: [6, 8, 3], 
      state: 9
    }, 
    {
      pos: [7, 8, 3], 
      state: 9
    }, 
    {
      pos: [8, 8, 3], 
      state: 9
    }, 
    {
      pos: [9, 8, 3], 
      state: 9
    }, 
    {
      pos: [10, 8, 3], 
      state: 9
    }, 
    {
      pos: [11, 8, 3], 
      state: 9
    }, 
    {
      pos: [12, 8, 3], 
      state: 9
    }, 
    {
      pos: [0, 9, 3], 
      state: 9
    }, 
    {
      pos: [1, 9, 3], 
      state: 9
    }, 
    {
      pos: [2, 9, 3], 
      state: 9
    }, 
    {
      pos: [3, 9, 3], 
      state: 9
    }, 
    {
      pos: [4, 9, 3], 
      state: 9
    }, 
    {
      pos: [5, 9, 3], 
      state: 9
    }, 
    {
      pos: [6, 9, 3], 
      state: 9
