{
  size: [9, 5, 9], 
  entities: [], 
  author: "jeb_", 
  blocks: [
    {
      pos: [1, 4, 1], 
      state: 0
    }, 
    {
      pos: [2, 4, 1], 
      state: 0
    }, 
    {
      pos: [3, 4, 1], 
      state: 0
    }, 
    {
      pos: [4, 4, 1], 
      state: 0
    }, 
    {
      pos: [5, 4, 1], 
      state: 0
    }, 
    {
      pos: [6, 4, 1], 
      state: 0
    }, 
    {
      pos: [7, 4, 1], 
      state: 0
    }, 
    {
      pos: [2, 0, 2], 
      state: 0
    }, 
    {
      pos: [3, 0, 2], 
      state: 0
    }, 
    {
      pos: [4, 0, 2], 
      state: 0
    }, 
    {
      pos: [5, 0, 2], 
      state: 0
    }, 
    {
      pos: [6, 0, 2], 
      state: 0
    }, 
    {
      pos: [2, 1, 2], 
      state: 1
    }, 
    {
      pos: [3, 1, 2], 
      state: 2
    }, 
    {
      pos: [4, 1, 2], 
      state: 2
    }, 
    {
      pos: [5, 1, 2], 
      state: 2
    }, 
    {
      pos: [6, 1, 2], 
      state: 1
    }, 
    {
      pos: [2, 2, 2], 
      state: 1
    }, 
    {
      pos: [3, 2, 2], 
      state: 2
    }, 
    {
      pos: [5, 2, 2], 
      state: 2
    }, 
    {
      pos: [6, 2, 2], 
      state: 1
    }, 
    {
      pos: [2, 3, 2], 
      state: 1
    }, 
    {
      pos: [3, 3, 2], 
      state: 2
    }, 
    {
      pos: [5, 3, 2], 
      state: 2
    }, 
    {
      pos: [6, 3, 2], 
      state: 1
    }, 
    {
      pos: [1, 4, 2], 
      state: 0
    }, 
    {
      pos: [2, 4, 2], 
      state: 0
    }, 
    {
      pos: [3, 4, 2], 
      state: 0
    }, 
    {
      pos: [4, 4, 2], 
      state: 0
    }, 
    {
      pos: [5, 4, 2], 
      state: 0
    }, 
    {
      pos: [6, 4, 2], 
      state: 0
    }, 
    {
      pos: [7, 4, 2], 
      state: 0
    }, 
    {
      pos: [2, 0, 3], 
      state: 0
    }, 
    {
      pos: [5, 0, 3], 
      state: 0
    }, 
    {
      pos: [6, 0, 3], 
      state: 0
    }, 
    {
      pos: [2, 1, 3], 
      state: 2
    }, 
    {
      pos: [2, 2, 3], 
      state: 2
    }, 
    {
      pos: [2, 3, 3], 
      state: 2
    }, 
    {
      pos: [6, 3, 3], 
      state: 2
    }, 
    {
      pos: [1, 4, 3], 
      state: 0
    }, 
    {
      pos: [2, 4, 3], 
      state: 0
    }, 
    {
      pos: [3, 4, 3], 
      state: 0
    }, 
    {
      pos: [4, 4, 3], 
      state: 0
    }, 
    {
      pos: [5, 4, 3], 
      state: 0
    }, 
    {
      pos: [6, 4, 3], 
      state: 0
    }, 
    {
      pos: [7, 4, 3], 
      state: 0
    }, 
    {
      pos: [2, 0, 4], 
      state: 0
    }, 
    {
      pos: [6, 0, 4], 
      state: 0
    }, 
    {
      pos: [2, 1, 4], 
      state: 2
    }, 
    {
      pos: [6, 3, 4], 
      state: 2
    }, 
    {
      pos: [1, 4, 4], 
      state: 0
    }, 
    {
      pos: [2, 4, 4], 
      state: 0
    }, 
    {
      pos: [3, 4, 4], 
      state: 0
    }, 
    {
      pos: [4, 4, 4], 
      state: 0
    }, 
    {
      pos: [5, 4, 4], 
      state: 0
    }, 
    {
      pos: [6, 4, 4], 
      state: 0
    }, 
    {
      pos: [7, 4, 4], 
      state: 0
    }, 
    {
      pos: [2, 0, 5], 
      state: 0
    }, 
    {
      pos: [6, 0, 5], 
      state: 0
    }, 
    {
      pos: [2, 1, 5], 
      state: 2
    }, 
    {
      pos: [6, 1, 5], 
      state: 2
    }, 
    {
      pos: [2, 2, 5], 
      state: 2
    }, 
    {
      pos: [6, 2, 5], 
      state: 2
    }, 
    {
      pos: [2, 3, 5], 
      state: 2
    }, 
    {
      pos: [6, 3, 5], 
      state: 2
    }, 
    {
      pos: [1, 4, 5], 
      state: 0
    }, 
    {
      pos: [2, 4, 5], 
      state: 0
    }, 
    {
      pos: [3, 4, 5], 
      state: 0
    }, 
    {
      pos: [4, 4, 5], 
      state: 0
    }, 
    {
      pos: [5, 4, 5], 
      state: 0
    }, 
    {
      pos: [6, 4, 5], 
      state: 0
    }, 
    {
      pos: [7, 4, 5], 
      state: 0
    }, 
    {
      pos: [2, 0, 6], 
      state: 0
    }, 
    {
      pos: [3, 0, 6], 
      state: 0
    }, 
    {
      pos: [4, 0, 6], 
      state: 0
    }, 
    {
      pos: [5, 0, 6], 
      state: 0
    }, 
    {
      pos: [6, 0, 6], 
      state: 0
    }, 
    {
      pos: [2, 1, 6], 
      state: 1
    }, 
    {
      pos: [3, 1, 6], 
      state: 2
    }, 
    {
      pos: [4, 1, 6], 
      state: 2
    }, 
    {
      pos: [5, 1, 6], 
      state: 2
    }, 
    {
      pos: [6, 1, 6], 
      state: 1
    }, 
    {
      pos: [2, 2, 6], 
      state: 1
    }, 
    {
      pos: [3, 2, 6], 
      state: 2
    }, 
    {
      pos: [5, 2, 6], 
      state: 2
    }, 
    {
      pos: [6, 2, 6], 
      state: 1
    }, 
    {
      pos: [2, 3, 6], 
      state: 1
    }, 
    {
      pos: [3, 3, 6], 
      state: 2
    }, 
    {
      pos: [5, 3, 6], 
      state: 2
    }, 
    {
      pos: [6, 3, 6], 
      state: 1
    }, 
    {
      pos: [1, 4, 6], 
      state: 0
    }, 
    {
      pos: [2, 4, 6], 
      state: 0
    }, 
    {
      pos: [3, 4, 6], 
      state: 0
    }, 
    {
      pos: [4, 4, 6], 
      state: 0
    }, 
    {
      pos: [5, 4, 6], 
      state: 0
    }, 
    {
      pos: [6, 4, 6], 
      state: 0
    }, 
    {
      pos: [7, 4, 6], 
      state: 0
    }, 
    {
      pos: [1, 4, 7], 
      state: 0
    }, 
    {
      pos: [2, 4, 7], 
      state: 0
    }, 
    {
      pos: [3, 4, 7], 
      state: 0
    }, 
    {
      pos: [4, 4, 7], 
      state: 0
    }, 
    {
      pos: [5, 4, 7], 
      state: 0
    }, 
    {
      pos: [6, 4, 7], 
      state: 0
    }, 
    {
      pos: [7, 4, 7], 
      state: 0
    }, 
    {
      nbt: {
        id: "minecraft:banner", 
        Patterns: [
          {
            Pattern: "tt", 
            Color: 15
          }, 
          {
            Pattern: "bt", 
            Color: 15
          }
        ]
      }, 
      pos: [2, 0, 0], 
      state: 3
    }, 
    {
      nbt: {
        id: "minecraft:banner", 
        Patterns: [
          {
            Pattern: "tt", 
            Color: 15
          }, 
          {
            Pattern: "bt", 
            Color: 15
          }
        ]
      }, 
      pos: [6, 0, 0], 
      state: 3
    }, 
    {
      nbt: {
        id: "minecraft:banner", 
        Patterns: [
          {
            Pattern: "tt", 
            Color: 15
          }, 
          {
            Pattern: "bt", 
            Color: 15
          }
        ]
      }, 
      pos: [0, 0, 2], 
      state: 4
    }, 
    {
      nbt: {
        id: "minecraft:banner", 
        Patterns: [
          {
            Pattern: "tt", 
            Color: 15
          }, 
          {
            Pattern: "bt", 
            Color: 15
          }
        ]
      }, 
      pos: [8, 0, 2], 
      state: 5
    }, 
    {
      nbt: {
        metadata: "Sentry", 
        mirror: "NONE", 
        ignoreEntities: 0b, 
        powered: 0b, 
        seed: 0L, 
        author: "jeb_", 
        rotation: "NONE", 
        mode: "DATA", 
        posX: 1, 
        posY: 1, 
        sizeX: 0, 
        integrity: 1.0f, 
        posZ: 1, 
        showair: 0b, 
        name: "", 
        id: "minecraft:structure_block", 
        sizeY: 0, 
        showboundingbox: 0b, 
        sizeZ: 0
      }, 
      pos: [4, 3, 4], 
      state: 6
    }, 
    {
      nbt: {
        id: "minecraft:banner", 
        Patterns: [
          {
            Pattern: "tt", 
            Color: 15
          }, 
          {
            Pattern: "bt", 
            Color: 15
          }
        ]
      }, 
      pos: [0, 0, 6], 
      state: 4
    }, 
    {
      nbt: {
        id: "minecraft:banner", 
        Patterns: [
          {
            Pattern: "tt", 
            Color: 15
          }, 
          {
            Pattern: "bt", 
            Color: 15
          }
        ]
      }, 
      pos: [8, 0, 6], 
      state: 5
    }, 
    {
      nbt: {
        id: "minecraft:banner", 
        Patterns: [
          {
            Pattern: "tt", 
            Color: 15
          }, 
          {
            Pattern: "bt", 
            Color: 15
          }
        ]
      }, 
      pos: [2, 0, 8], 
      state: 7
    }, 
    {
      nbt: {
        id: "minecraft:banner", 
        Patterns: [
          {
            Pattern: "tt", 
            Color: 15
          }, 
          {
            Pattern: "bt", 
            Color: 15
          }
        ]
      }, 
      pos: [6, 0, 8], 
      state: 7
    }, 
    {
      pos: [0, 0, 0], 
      state: 8
    }, 
    {
      pos: [1, 0, 0], 
      state: 8
    }, 
    {
      pos: [3, 0, 0], 
      state: 8
    }, 
    {
      pos: [4, 0, 0], 
      state: 8
    }, 
    {
      pos: [5, 0, 0], 
      state: 8
    }, 
    {
      pos: [7, 0, 0], 
      state: 8
    }, 
    {
      pos: [8, 0, 0], 
      state: 8
    }, 
    {
      pos: [0, 1, 0], 
      state: 8
    }, 
    {
      pos: [1, 1, 0], 
      state: 8
    }, 
    {
      pos: [2, 1, 0], 
      state: 8
    }, 
    {
      pos: [3, 1, 0], 
      state: 8
    }, 
    {
      pos: [4, 1, 0], 
      state: 8
    }, 
    {
      pos: [5, 1, 0], 
      state: 8
    }, 
    {
      pos: [6, 1, 0], 
      state: 8
    }, 
    {
      pos: [7, 1, 0], 
      state: 8
    }, 
    {
      pos: [8, 1, 0], 
      state: 8
    }, 
    {
      pos: [0, 2, 0], 
      state: 8
    }, 
    {
      pos: [1, 2, 0], 
      state: 8
    }, 
    {
      pos: [2, 2, 0], 
      state: 8
    }, 
    {
      pos: [3, 2, 0], 
      state: 8
    }, 
    {
      pos: [4, 2, 0], 
      state: 8
    }, 
    {
      pos: [5, 2, 0], 
      state: 8
    }, 
    {
      pos: [6, 2, 0], 
      state: 8
    }, 
    {
      pos: [7, 2, 0], 
      state: 8
    }, 
    {
      pos: [8, 2, 0], 
      state: 8
    }, 
    {
      pos: [0, 3, 0], 
      state: 8
    }, 
    {
      pos: [1, 3, 0], 
      state: 8
    }, 
    {
      pos: [2, 3, 0], 
      state: 8
    }, 
    {
      pos: [3, 3, 0], 
      state: 8
    }, 
    {
      pos: [4, 3, 0], 
      state: 8
    }, 
    {
      pos: [5, 3, 0], 
      state: 8
    }, 
    {
      pos: [6, 3, 0], 
      state: 8
    }, 
    {
      pos: [7, 3, 0], 
      state: 8
    }, 
    {
      pos: [8, 3, 0], 
      state: 8
    }, 
    {
      pos: [0, 4, 0], 
      state: 9
    }, 
    {
      pos: [1, 4, 0], 
      state: 10
    }, 
    {
      pos: [2, 4, 0], 
      state: 11
    }, 
    {
      pos: [3, 4, 0], 
      state: 11
    }, 
    {
      pos: [4, 4, 0], 
      state: 10
    }, 
    {
      pos: [5, 4, 0], 
      state: 11
    }, 
    {
      pos: [6, 4, 0], 
      state: 11
    }, 
    {
      pos: [7, 4, 0], 
      state: 10
    }, 
    {
      pos: [8, 4, 0], 
      state: 12
    }, 
    {
      pos: [0, 0, 1], 
      state: 8
    }, 
    {
      pos: [1, 0, 1], 
      state: 9
    }, 
    {
      pos: [2, 0, 1], 
      state: 10
    }, 
    {
      pos: [3, 0, 1], 
      state: 11
    }, 
    {
      pos: [4, 0, 1], 
      state: 10
    }, 
    {
      pos: [5, 0, 1], 
      state: 11
    }, 
    {
      pos: [6, 0, 1], 
      state: 10
    }, 
    {
      pos: [7, 0, 1], 
      state: 13
    }, 
    {
      pos: [8, 0, 1], 
      state: 8
    }, 
    {
      pos: [0, 1, 1], 
      state: 8
    }, 
    {
      pos: [1, 1, 1], 
      state: 14
    }, 
    {
      pos: [2, 1, 1], 
      state: 8
    }, 
    {
      pos: [3, 1, 1], 
      state: 8
    }, 
    {
      pos: [4, 1, 1], 
      state: 8
    }, 
    {
      pos: [5, 1, 1], 
      state: 8
    }, 
    {
      pos: [6, 1, 1], 
      state: 8
    }, 
    {
      pos: [7, 1, 1], 
      state: 14
    }, 
    {
      pos: [8, 1, 1], 
      state: 8
    }, 
    {
      pos: [0, 2, 1], 
      state: 8
    }, 
    {
      pos: [1, 2, 1], 
      state: 8
    }, 
    {
      pos: [2, 2, 1], 
      state: 8
    }, 
    {
      pos: [3, 2, 1], 
      state: 8
    }, 
    {
      pos: [4, 2, 1], 
      state: 8
    }, 
    {
      pos: [5, 2, 1], 
      state: 8
    }, 
    {
      pos: [6, 2, 1], 
      state: 8
    }, 
    {
      pos: [7, 2, 1], 
      state: 8
    }, 
    {
      pos: [8, 2, 1], 
      state: 8
    }, 
    {
      pos: [0, 3, 1], 
      state: 8
    }, 
    {
      pos: [1, 3, 1], 
      state: 8
    }, 
    {
      pos: [2, 3, 1], 
      state: 8
    }, 
    {
      pos: [3, 3, 1], 
      state: 8
    }, 
    {
      pos: [4, 3, 1], 
      state: 8
    }, 
    {
      pos: [5, 3, 1], 
      state: 8
    }, 
    {
      pos: [6, 3, 1], 
      state: 8
    }, 
    {
      pos: [7, 3, 1], 
      state: 8
    }, 
    {
      pos: [8, 3, 1], 
      state: 8
    }, 
    {
      pos: [0, 4, 1], 
      state: 15
    }, 
    {
      pos: [8, 4, 1], 
      state: 16
    }, 
    {
      pos: [1, 0, 2], 
      state: 15
    }, 
    {
      pos: [7, 0, 2], 
      state: 16
    }, 
    {
      pos: [0, 1, 2], 
      state: 8
    }, 
    {
      pos: [1, 1, 2], 
      state: 8
    }, 
    {
      pos: [7, 1, 2], 
      state: 8
    }, 
    {
      pos: [8, 1, 2], 
      state: 8
    }, 
    {
      pos: [0, 2, 2], 
      state: 8
    }, 
    {
      pos: [1, 2, 2], 
      state: 8
    }, 
    {
      pos: [4, 2, 2], 
      state: 17
    }, 
    {
      pos: [7, 2, 2], 
      state: 8
    }, 
    {
      pos: [8, 2, 2], 
      state: 8
    }, 
    {
      pos: [0, 3, 2], 
      state: 8
    }, 
    {
      pos: [1, 3, 2], 
      state: 8
    }, 
    {
      pos: [4, 3, 2], 
      state: 17
    }, 
    {
      pos: [7, 3, 2], 
      state: 8
    }, 
    {
      pos: [8, 3, 2], 
      state: 8
    }, 
    {
      pos: [0, 4, 2], 
      state: 18
    }, 
    {
      pos: [8, 4, 2], 
      state: 19
    }, 
    {
      pos: [0, 0, 3], 
      state: 8
    }, 
    {
      pos: [1, 0, 3], 
      state: 18
    }, 
    {
      pos: [3, 0, 3], 
      state: 20
    }, 
    {
      pos: [4, 0, 3], 
      state: 20
    }, 
    {
      pos: [7, 0, 3], 
      state: 19
    }, 
    {
      pos: [8, 0, 3], 
      state: 8
    }, 
    {
      pos: [0, 1, 3], 
      state: 8
    }, 
    {
      pos: [1, 1, 3], 
      state: 8
    }, 
    {
      pos: [3, 1, 3], 
      state: 8
    }, 
    {
      pos: [4, 1, 3], 
      state: 8
    }, 
    {
      pos: [5, 1, 3], 
      state: 8
    }, 
    {
      pos: [6, 1, 3], 
      state: 8
    }, 
    {
      pos: [7, 1, 3], 
      state: 8
    }, 
    {
      pos: [8, 1, 3], 
      state: 8
    }, 
    {
      pos: [0, 2, 3], 
      state: 8
    }, 
    {
      pos: [1, 2, 3], 
      state: 8
    }, 
    {
      pos: [3, 2, 3], 
      state: 8
    }, 
    {
      pos: [4, 2, 3], 
      state: 8
    }, 
    {
      pos: [5, 2, 3], 
      state: 8
    }, 
    {
      pos: [6, 2, 3], 
      state: 8
    }, 
    {
      pos: [7, 2, 3], 
      state: 8
    }, 
    {
      pos: [8, 2, 3], 
      state: 8
    }, 
    {
      pos: [0, 3, 3], 
      state: 8
    }, 
    {
      pos: [1, 3, 3], 
      state: 8
    }, 
    {
      pos: [3, 3, 3], 
      state: 8
    }, 
    {
      pos: [4, 3, 3], 
      state: 8
    }, 
    {
      pos: [5, 3, 3], 
      state: 8
    }, 
    {
      pos: [7, 3, 3], 
      state: 8
    }, 
    {
      pos: [8, 3, 3], 
      state: 8
    }, 
    {
      pos: [0, 4, 3], 
      state: 18
    }, 
    {
      pos: [8, 4, 3], 
      state: 19
    }, 
    {
      pos: [0, 0, 4], 
      state: 8
    }, 
    {
      pos: [1, 0, 4], 
      state: 15
    }, 
    {
      pos: [3, 0, 4], 
      state: 8
    }, 
    {
      pos: [4, 0, 4], 
      state: 8
    }, 
    {
      pos: [5, 0, 4], 
      state: 8
    }, 
    {
      pos: [7, 0, 4], 
      state: 16
    }, 
    {
      pos: [8, 0, 4], 
      state: 8
    }, 
    {
      pos: [0, 1, 4], 
      state: 8
    }, 
    {
      pos: [1, 1, 4], 
      state: 8
    }, 
    {
      pos: [3, 1, 4], 
      state: 8
    }, 
    {
      pos: [4, 1, 4], 
      state: 8
    }, 
    {
      pos: [5, 1, 4], 
      state: 8
    }, 
    {
      pos: [6, 1, 4], 
      state: 8
    }, 
    {
      pos: [7, 1, 4], 
      state: 8
    }, 
    {
      pos: [8, 1, 4], 
      state: 8
    }, 
    {
      pos: [0, 2, 4], 
      state: 8
    }, 
    {
      pos: [1, 2, 4], 
      state: 8
    }, 
    {
      pos: [2, 2, 4], 
      state: 17
    }, 
    {
      pos: [3, 2, 4], 
      state: 8
    }, 
    {
      pos: [4, 2, 4], 
      state: 8
    }, 
    {
      pos: [5, 2, 4], 
      state: 8
    }, 
    {
      pos: [6, 2, 4], 
      state: 8
    }, 
    {
      pos: [7, 2, 4], 
      state: 8
    }, 
    {
      pos: [8, 2, 4], 
      state: 8
    }, 
    {
      pos: [0, 3, 4], 
      state: 8
    }, 
    {
      pos: [1, 3, 4], 
      state: 8
    }, 
    {
      pos: [2, 3, 4], 
      state: 17
    }, 
    {
      pos: [3, 3, 4], 
      state: 8
    }, 
    {
      pos: [5, 3, 4], 
      state: 8
    }, 
    {
      pos: [7, 3, 4], 
      state: 8
    }, 
    {
      pos: [8, 3, 4], 
      state: 8
    }, 
    {
      pos: [0, 4, 4], 
      state: 15
    }, 
    {
      pos: [8, 4, 4], 
      state: 16
    }, 
    {
      pos: [0, 0, 5], 
      state: 8
    }, 
    {
      pos: [1, 0, 5], 
      state: 18
    }, 
    {
      pos: [3, 0, 5], 
      state: 8
    }, 
    {
      pos: [4, 0, 5], 
      state: 8
    }, 
    {
      pos: [5, 0, 5], 
      state: 8
    }, 
    {
      pos: [7, 0, 5], 
      state: 19
    }, 
    {
      pos: [8, 0, 5], 
      state: 8
    }, 
    {
      pos: [0, 1, 5], 
      state: 8
    }, 
    {
      pos: [1, 1, 5], 
      state: 8
    }, 
    {
      pos: [3, 1, 5], 
      state: 8
    }, 
    {
      pos: [4, 1, 5], 
      state: 8
    }, 
    {
      pos: [5, 1, 5], 
      state: 8
    }, 
    {
      pos: [7, 1, 5], 
      state: 8
    }, 
    {
      pos: [8, 1, 5], 
      state: 8
    }, 
    {
      pos: [0, 2, 5], 
      state: 8
    }, 
    {
      pos: [1, 2, 5], 
      state: 8
    }, 
    {
      pos: [3, 2, 5], 
      state: 8
    }, 
    {
      pos: [4, 2, 5], 
      state: 8
    }, 
    {
      pos: [5, 2, 5], 
      state: 8
    }, 
    {
      pos: [7, 2, 5], 
      state: 8
    }, 
    {
      pos: [8, 2, 5], 
      state: 8
    }, 
    {
      pos: [0, 3, 5], 
      state: 8
    }, 
    {
      pos: [1, 3, 5], 
      state: 8
    }, 
    {
      pos: [3, 3, 5], 
      state: 8
    }, 
    {
      pos: [4, 3, 5], 
      state: 8
    }, 
    {
      pos: [5, 3, 5], 
      state: 8
    }, 
    {
      pos: [7, 3, 5], 
      state: 8
    }, 
    {
      pos: [8, 3, 5], 
      state: 8
    }, 
    {
      pos: [0, 4, 5], 
      state: 18
    }, 
    {
      pos: [8, 4, 5], 
      state: 19
    }, 
    {
      pos: [1, 0, 6], 
      state: 15
    }, 
    {
      pos: [7, 0, 6], 
      state: 16
    }, 
    {
      pos: [0, 1, 6], 
      state: 8
    }, 
    {
      pos: [1, 1, 6], 
      state: 8
    }, 
    {
      pos: [7, 1, 6], 
      state: 8
    }, 
    {
      pos: [8, 1, 6], 
      state: 8
    }, 
    {
      pos: [0, 2, 6], 
      state: 8
    }, 
    {
      pos: [1, 2, 6], 
      state: 8
    }, 
    {
      pos: [4, 2, 6], 
      state: 17
    }, 
    {
      pos: [7, 2, 6], 
      state: 8
    }, 
    {
      pos: [8, 2, 6], 
      state: 8
    }, 
    {
      pos: [0, 3, 6], 
      state: 8
    }, 
    {
      pos: [1, 3, 6], 
      state: 8
    }, 
    {
      pos: [4, 3, 6], 
      state: 17
    }, 
    {
      pos: [7, 3, 6], 
      state: 8
    }, 
    {
      pos: [8, 3, 6], 
      state: 8
    }, 
    {
      pos: [0, 4, 6], 
      state: 18
    }, 
    {
      pos: [8, 4, 6], 
      state: 19
    }, 
    {
      pos: [0, 0, 7], 
      state: 8
    }, 
    {
      pos: [1, 0, 7], 
      state: 21
    }, 
    {
      pos: [2, 0, 7], 
      state: 22
    }, 
    {
      pos: [3, 0, 7], 
      state: 23
    }, 
    {
      pos: [4, 0, 7], 
      state: 22
    }, 
    {
      pos: [5, 0, 7], 
      state: 23
    }, 
    {
      pos: [6, 0, 7], 
      state: 22
    }, 
    {
      pos: [7, 0, 7], 
      state: 24
    }, 
    {
      pos: [8, 0, 7], 
      state: 8
    }, 
    {
      pos: [0, 1, 7], 
      state: 8
    }, 
    {
      pos: [1, 1, 7], 
      state: 14
    }, 
    {
      pos: [2, 1, 7], 
      state: 8
    }, 
    {
      pos: [3, 1, 7], 
      state: 8
    }, 
    {
      pos: [4, 1, 7], 
      state: 8
    }, 
    {
      pos: [5, 1, 7], 
      state: 8
    }, 
    {
      pos: [6, 1, 7], 
      state: 8
    }, 
    {
      pos: [7, 1, 7], 
      state: 14
    }, 
    {
      pos: [8, 1, 7], 
      state: 8
    }, 
    {
      pos: [0, 2, 7], 
      state: 8
    }, 
    {
      pos: [1, 2, 7], 
      state: 8
    }, 
    {
      pos: [2, 2, 7], 
      state: 8
    }, 
    {
      pos: [3, 2, 7], 
      state: 8
    }, 
    {
      pos: [4, 2, 7], 
      state: 8
    }, 
    {
      pos: [5, 2, 7], 
      state: 8
    }, 
    {
      pos: [6, 2, 7], 
      state: 8
    }, 
    {
      pos: [7, 2, 7], 
      state: 8
    }, 
    {
      pos: [8, 2, 7], 
      state: 8
    }, 
    {
      pos: [0, 3, 7], 
      state: 8
    }, 
    {
      pos: [1, 3, 7], 
      state: 8
    }, 
    {
      pos: [2, 3, 7], 
      state: 8
    }, 
    {
      pos: [3, 3, 7], 
      state: 8
    }, 
    {
      pos: [4, 3, 7], 
      state: 8
    }, 
    {
      pos: [5, 3, 7], 
      state: 8
    }, 
    {
      pos: [6, 3, 7], 
      state: 8
    }, 
    {
      pos: [7, 3, 7], 
      state: 8
    }, 
    {
      pos: [8, 3, 7], 
      state: 8
    }, 
    {
      pos: [0, 4, 7], 
      state: 15
    }, 
    {
      pos: [8, 4, 7], 
      state: 16
    }, 
    {
      pos: [0, 0, 8], 
      state: 8
    }, 
    {
      pos: [1, 0, 8], 
      state: 8
    }, 
    {
      pos: [3, 0, 8], 
      state: 8
    }, 
    {
      pos: [4, 0, 8], 
      state: 8
    }, 
    {
      pos: [5, 0, 8], 
      state: 8
    }, 
    {
      pos: [7, 0, 8], 
      state: 8
    }, 
    {
      pos: [8, 0, 8], 
      state: 8
    }, 
    {
      pos: [0, 1, 8], 
      state: 8
    }, 
    {
      pos: [1, 1, 8], 
      state: 8
    }, 
    {
      pos: [2, 1, 8], 
      state: 8
    }, 
    {
      pos: [3, 1, 8], 
      state: 8
    }, 
    {
      pos: [4, 1, 8], 
      state: 8
    }, 
    {
      pos: [5, 1, 8], 
      state: 8
    }, 
    {
      pos: [6, 1, 8], 
      state: 8
    }, 
    {
      pos: [7, 1, 8], 
      state: 8
    }, 
    {
      pos: [8, 1, 8], 
      state: 8
    }, 
    {
      pos: [0, 2, 8], 
      state: 8
    }, 
    {
      pos: [1, 2, 8], 
      state: 8
    }, 
    {
      pos: [2, 2, 8], 
      state: 8
    }, 
    {
      pos: [3, 2, 8], 
      state: 8
    }, 
    {
      pos: [4, 2, 8], 
      state: 8
    }, 
    {
      pos: [5, 2, 8], 
      state: 8
    }, 
    {
      pos: [6, 2, 8], 
      state: 8
    }, 
    {
      pos: [7, 2, 8], 
      state: 8
    }, 
    {
      pos: [8, 2, 8], 
      state: 8
    }, 
    {
      pos: [0, 3, 8], 
      state: 8
    }, 
    {
      pos: [1, 3, 8], 
      state: 8
    }, 
    {
      pos: [2, 3, 8], 
      state: 8
    }, 
    {
      pos: [3, 3, 8], 
      state: 8
    }, 
    {
      pos: [4, 3, 8], 
      state: 8
    }, 
    {
      pos: [5, 3, 8], 
      state: 8
    }, 
    {
      pos: [6, 3, 8], 
      state: 8
    }, 
    {
      pos: [7, 3, 8], 
      state: 8
    }, 
    {
      pos: [8, 3, 8], 
      state: 8
    }, 
    {
      pos: [0, 4, 8], 
      state: 25
    }, 
    {
      pos: [1, 4, 8], 
      state: 22
    }, 
    {
      pos: [2, 4, 8], 
      state: 23
    }, 
    {
      pos: [3, 4, 8], 
      state: 23
    }, 
    {
      pos: [4, 4, 8], 
      state: 22
    }, 
    {
      pos: [5, 4, 8], 
      state: 23
    }, 
    {
      pos: [6, 4, 8], 
      state: 23
    }, 
    {
      pos: [7, 4, 8], 
      state: 22
    }, 
    {
      pos: [8, 4, 8], 
      state: 26
    }
  ], 
  palette: [
    {
      Name: "minecraft:purpur_block"
    }, 
    {
      Properties: {
        axis: "y"
      }, 
      Name: "minecraft:purpur_pillar"
    }, 
    {
      Name: "minecraft:end_stone_bricks"
    }, 
    {
      Properties: {
        facing: "north"
      }, 
      Name: "minecraft:magenta_wall_banner"
    }, 
    {
      Properties: {
        facing: "west"
      }, 
      Name: "minecraft:magenta_wall_banner"
    }, 
    {
      Properties: {
        facing: "east"
      }, 
      Name: "minecraft:magenta_wall_banner"
    }, 
    {
      Properties: {
        mode: "data"
      }, 
      Name: "minecraft:structure_block"
    }, 
    {
      Properties: {
        facing: "south"
      }, 
      Name: "minecraft:magenta_wall_banner"
    }, 
    {
      Name: "minecraft:air"
    }, 
    {
      Properties: {
        half: "top", 
        shape: "outer_right", 
        facing: "east"
      }, 
      Name: "minecraft:purpur_stairs"
    }, 
    {
      Properties: {
        half: "top", 
        shape: "straight", 
        facing: "south"
      }, 
      Name: "minecraft:purpur_stairs"
    }, 
    {
      Properties: {
        half: "bottom", 
        shape: "straight", 
        facing: "south"
      }, 
      Name: "minecraft:purpur_stairs"
    }, 
    {
      Properties: {
        half: "top", 
        shape: "outer_right", 
        facing: "south"
      }, 
      Name: "minecraft:purpur_stairs"
    }, 
    {
      Properties: {
        half: "top", 
        shape: "outer_left", 
        facing: "west"
      }, 
      Name: "minecraft:purpur_stairs"
    }, 
    {
      Properties: {
        facing: "up"
      }, 
      Name: "minecraft:end_rod"
    }, 
    {
      Properties: {
        half: "top", 
        shape: "straight", 
        facing: "east"
      }, 
      Name: "minecraft:purpur_stairs"
    }, 
    {
      Properties: {
        half: "top", 
        shape: "straight", 
        facing: "west"
      }, 
      Name: "minecraft:purpur_stairs"
    }, 
    {
      Name: "minecraft:magenta_stained_glass"
    }, 
    {
      Properties: {
        half: "bottom", 
        shape: "straight", 
        facing: "east"
      }, 
      Name: "minecraft:purpur_stairs"
    }, 
    {
      Properties: {
        half: "bottom", 
        shape: "straight", 
        facing: "west"
      }, 
      Name: "minecraft:purpur_stairs"
    }, 
    {
      Properties: {
        type: "bottom"
      }, 
      Name: "minecraft:purpur_slab"
    }, 
    {
      Properties: {
        half: "top", 
        shape: "outer_left", 
        facing: "east"
      }, 
      Name: "minecraft:purpur_stairs"
    }, 
    {
      Properties: {
        half: "top", 
        shape: "straight", 
        facing: "north"
      }, 
      Name: "minecraft:purpur_stairs"
    }, 
    {
      Properties: {
        half: "bottom", 
        shape: "straight", 
        facing: "north"
      }, 
      Name: "minecraft:purpur_stairs"
    }, 
    {
      Properties: {
        half: "top", 
        shape: "outer_left", 
        facing: "north"
      }, 
      Name: "minecraft:purpur_stairs"
    }, 
    {
      Properties: {
        half: "top", 
        shape: "outer_right", 
        facing: "north"
      }, 
      Name: "minecraft:purpur_stairs"
    }, 
    {
      Properties: {
        half: "top", 
        shape: "outer_right", 
        facing: "west"
      }, 
      Name: "minecraft:purpur_stairs"
    }
  ]
}
