{
  size: [5, 7, 5], 
  entities: [], 
  blocks: [
    {
      pos: [0, 0, 1], 
      state: 0
    }, 
    {
      pos: [0, 0, 2], 
      state: 0
    }, 
    {
      pos: [0, 0, 3], 
      state: 0
    }, 
    {
      pos: [1, 0, 0], 
      state: 0
    }, 
    {
      pos: [1, 0, 1], 
      state: 0
    }, 
    {
      pos: [1, 0, 2], 
      state: 0
    }, 
    {
      pos: [1, 0, 3], 
      state: 0
    }, 
    {
      pos: [1, 0, 4], 
      state: 0
    }, 
    {
      pos: [2, 0, 0], 
      state: 0
    }, 
    {
      pos: [2, 0, 1], 
      state: 0
    }, 
    {
      pos: [2, 0, 2], 
      state: 0
    }, 
    {
      pos: [2, 0, 3], 
      state: 0
    }, 
    {
      pos: [2, 0, 4], 
      state: 0
    }, 
    {
      pos: [3, 0, 0], 
      state: 0
    }, 
    {
      pos: [3, 0, 1], 
      state: 0
    }, 
    {
      pos: [3, 0, 2], 
      state: 0
    }, 
    {
      pos: [3, 0, 3], 
      state: 0
    }, 
    {
      pos: [3, 0, 4], 
      state: 0
    }, 
    {
      pos: [4, 0, 0], 
      state: 0
    }, 
    {
      pos: [4, 0, 1], 
      state: 0
    }, 
    {
      pos: [4, 0, 2], 
      state: 0
    }, 
    {
      pos: [4, 0, 3], 
      state: 0
    }, 
    {
      pos: [4, 0, 4], 
      state: 0
    }, 
    {
      pos: [0, 1, 1], 
      state: 0
    }, 
    {
      pos: [0, 1, 2], 
      state: 0
    }, 
    {
      pos: [0, 1, 3], 
      state: 0
    }, 
    {
      pos: [1, 1, 0], 
      state: 0
    }, 
    {
      pos: [1, 1, 1], 
      state: 1
    }, 
    {
      pos: [1, 1, 2], 
      state: 1
    }, 
    {
      pos: [1, 1, 3], 
      state: 2
    }, 
    {
      pos: [1, 1, 4], 
      state: 0
    }, 
    {
      pos: [2, 1, 0], 
      state: 0
    }, 
    {
      pos: [2, 1, 1], 
      state: 1
    }, 
    {
      pos: [2, 1, 2], 
      state: 1
    }, 
    {
      pos: [2, 1, 4], 
      state: 1
    }, 
    {
      pos: [3, 1, 0], 
      state: 0
    }, 
    {
      pos: [3, 1, 1], 
      state: 1
    }, 
    {
      pos: [3, 1, 2], 
      state: 1
    }, 
    {
      pos: [3, 1, 3], 
      state: 1
    }, 
    {
      pos: [3, 1, 4], 
      state: 1
    }, 
    {
      pos: [4, 1, 0], 
      state: 0
    }, 
    {
      pos: [4, 1, 1], 
      state: 1
    }, 
    {
      pos: [4, 1, 2], 
      state: 1
    }, 
    {
      pos: [4, 1, 3], 
      state: 2
    }, 
    {
      pos: [4, 1, 4], 
      state: 1
    }, 
    {
      pos: [0, 2, 1], 
      state: 0
    }, 
    {
      pos: [0, 2, 2], 
      state: 0
    }, 
    {
      pos: [0, 2, 3], 
      state: 0
    }, 
    {
      pos: [1, 2, 0], 
      state: 0
    }, 
    {
      pos: [1, 2, 3], 
      state: 2
    }, 
    {
      pos: [1, 2, 4], 
      state: 0
    }, 
    {
      pos: [2, 2, 0], 
      state: 0
    }, 
    {
      pos: [2, 2, 3], 
      state: 1
    }, 
    {
      pos: [2, 2, 4], 
      state: 1
    }, 
    {
      pos: [3, 2, 0], 
      state: 0
    }, 
    {
      pos: [3, 2, 3], 
      state: 1
    }, 
    {
      pos: [3, 2, 4], 
      state: 1
    }, 
    {
      pos: [4, 2, 0], 
      state: 0
    }, 
    {
      pos: [4, 2, 1], 
      state: 1
    }, 
    {
      pos: [4, 2, 3], 
      state: 2
    }, 
    {
      pos: [4, 2, 4], 
      state: 1
    }, 
    {
      pos: [0, 3, 1], 
      state: 0
    }, 
    {
      pos: [0, 3, 2], 
      state: 0
    }, 
    {
      pos: [0, 3, 3], 
      state: 0
    }, 
    {
      pos: [1, 3, 0], 
      state: 0
    }, 
    {
      pos: [1, 3, 1], 
      state: 2
    }, 
    {
      pos: [1, 3, 2], 
      state: 2
    }, 
    {
      pos: [1, 3, 3], 
      state: 2
    }, 
    {
      pos: [1, 3, 4], 
      state: 0
    }, 
    {
      pos: [2, 3, 0], 
      state: 0
    }, 
    {
      pos: [2, 3, 1], 
      state: 2
    }, 
    {
      pos: [2, 3, 2], 
      state: 2
    }, 
    {
      pos: [2, 3, 4], 
      state: 1
    }, 
    {
      pos: [3, 3, 0], 
      state: 0
    }, 
    {
      pos: [3, 3, 1], 
      state: 2
    }, 
    {
      pos: [3, 3, 2], 
      state: 2
    }, 
    {
      pos: [3, 3, 3], 
      state: 2
    }, 
    {
      pos: [4, 3, 0], 
      state: 0
    }, 
    {
      pos: [4, 3, 1], 
      state: 2
    }, 
    {
      pos: [4, 3, 2], 
      state: 2
    }, 
    {
      pos: [4, 3, 3], 
      state: 2
    }, 
    {
      pos: [0, 4, 1], 
      state: 0
    }, 
    {
      pos: [0, 4, 2], 
      state: 0
    }, 
    {
      pos: [0, 4, 3], 
      state: 0
    }, 
    {
      pos: [1, 4, 0], 
      state: 0
    }, 
    {
      pos: [1, 4, 1], 
      state: 1
    }, 
    {
      pos: [1, 4, 3], 
      state: 2
    }, 
    {
      pos: [1, 4, 4], 
      state: 0
    }, 
    {
      pos: [2, 4, 0], 
      state: 0
    }, 
    {
      pos: [2, 4, 1], 
      state: 1
    }, 
    {
      pos: [2, 4, 2], 
      state: 1
    }, 
    {
      pos: [3, 4, 1], 
      state: 1
    }, 
    {
      pos: [3, 4, 2], 
      state: 1
    }, 
    {
      pos: [3, 4, 3], 
      state: 1
    }, 
    {
      pos: [4, 4, 0], 
      state: 0
    }, 
    {
      pos: [4, 4, 1], 
      state: 2
    }, 
    {
      pos: [4, 4, 2], 
      state: 2
    }, 
    {
      pos: [4, 4, 3], 
      state: 2
    }, 
    {
      pos: [0, 5, 1], 
      state: 3
    }, 
    {
      pos: [0, 5, 2], 
      state: 3
    }, 
    {
      pos: [0, 5, 3], 
      state: 3
    }, 
    {
      pos: [1, 5, 0], 
      state: 3
    }, 
    {
      pos: [1, 5, 1], 
      state: 1
    }, 
    {
      pos: [1, 5, 3], 
      state: 2
    }, 
    {
      pos: [1, 5, 4], 
      state: 3
    }, 
    {
      pos: [2, 5, 0], 
      state: 3
    }, 
    {
      pos: [2, 5, 1], 
      state: 1
    }, 
    {
      pos: [2, 5, 2], 
      state: 1
    }, 
    {
      pos: [2, 5, 4], 
      state: 3
    }, 
    {
      pos: [3, 5, 0], 
      state: 3
    }, 
    {
      pos: [3, 5, 4], 
      state: 3
    }, 
    {
      pos: [4, 5, 0], 
      state: 3
    }, 
    {
      pos: [4, 5, 1], 
      state: 2
    }, 
    {
      pos: [4, 5, 2], 
      state: 2
    }, 
    {
      pos: [4, 5, 3], 
      state: 2
    }, 
    {
      pos: [4, 5, 4], 
      state: 3
    }, 
    {
      pos: [1, 6, 2], 
      state: 3
    }, 
    {
      pos: [1, 6, 3], 
      state: 3
    }, 
    {
      pos: [2, 6, 2], 
      state: 1
    }, 
    {
      pos: [2, 6, 3], 
      state: 3
    }, 
    {
      pos: [3, 6, 1], 
      state: 3
    }, 
    {
      pos: [3, 6, 2], 
      state: 3
    }, 
    {
      pos: [3, 6, 3], 
      state: 3
    }, 
    {
      pos: [4, 6, 1], 
      state: 3
    }, 
    {
      pos: [4, 6, 3], 
      state: 3
    }, 
    {
      pos: [2, 1, 3], 
      state: 4
    }, 
    {
      pos: [1, 2, 1], 
      state: 5
    }, 
    {
      pos: [1, 2, 2], 
      state: 5
    }, 
    {
      pos: [2, 2, 1], 
      state: 5
    }, 
    {
      pos: [2, 2, 2], 
      state: 5
    }, 
    {
      pos: [3, 2, 1], 
      state: 5
    }, 
    {
      pos: [3, 2, 2], 
      state: 5
    }, 
    {
      pos: [2, 3, 3], 
      state: 5
    }, 
    {
      pos: [3, 3, 4], 
      state: 5
    }, 
    {
      pos: [4, 3, 4], 
      state: 5
    }, 
    {
      pos: [1, 4, 2], 
      state: 5
    }, 
    {
      pos: [2, 4, 3], 
      state: 5
    }, 
    {
      pos: [2, 4, 4], 
      state: 5
    }, 
    {
      pos: [3, 4, 0], 
      state: 5
    }, 
    {
      pos: [3, 4, 4], 
      state: 5
    }, 
    {
      pos: [4, 4, 4], 
      state: 5
    }, 
    {
      pos: [1, 5, 2], 
      state: 5
    }, 
    {
      pos: [2, 5, 3], 
      state: 5
    }, 
    {
      pos: [3, 5, 1], 
      state: 5
    }, 
    {
      pos: [3, 5, 2], 
      state: 5
    }, 
    {
      pos: [3, 5, 3], 
      state: 5
    }, 
    {
      nbt: {
        joint: "rollable", 
        final_state: "minecraft:sand", 
        name: "minecraft:room_connector", 
        pool: "minecraft:trail_ruins/buildings/grouped", 
        id: "minecraft:jigsaw", 
        target: "minecraft:room_connector"
      }, 
      pos: [4, 2, 2], 
      state: 6
    }
  ], 
  palette: [
    {
      Name: "minecraft:red_terracotta"
    }, 
    {
      Name: "minecraft:sand"
    }, 
    {
      Name: "minecraft:mud_bricks"
    }, 
    {
      Name: "minecraft:yellow_terracotta"
    }, 
    {
      Properties: {
        waterlogged: "false", 
        facing: "east"
      }, 
      Name: "minecraft:ladder"
    }, 
    {
      Name: "minecraft:air"
    }, 
    {
      Properties: {
        orientation: "east_up"
      }, 
      Name: "minecraft:jigsaw"
    }
  ]
}
