{
  size: [14, 7, 11], 
  entities: [], 
  blocks: [
    {
      pos: [5, 0, 5], 
      state: 0
    }, 
    {
      pos: [5, 0, 6], 
      state: 0
    }, 
    {
      pos: [5, 0, 7], 
      state: 0
    }, 
    {
      pos: [5, 0, 8], 
      state: 0
    }, 
    {
      pos: [5, 0, 9], 
      state: 0
    }, 
    {
      pos: [6, 0, 5], 
      state: 0
    }, 
    {
      pos: [6, 0, 6], 
      state: 0
    }, 
    {
      pos: [6, 0, 7], 
      state: 0
    }, 
    {
      pos: [6, 0, 8], 
      state: 0
    }, 
    {
      pos: [6, 0, 9], 
      state: 0
    }, 
    {
      pos: [6, 0, 10], 
      state: 0
    }, 
    {
      pos: [7, 0, 5], 
      state: 0
    }, 
    {
      pos: [7, 0, 6], 
      state: 0
    }, 
    {
      pos: [7, 0, 7], 
      state: 0
    }, 
    {
      pos: [7, 0, 8], 
      state: 0
    }, 
    {
      pos: [7, 0, 9], 
      state: 0
    }, 
    {
      pos: [7, 0, 10], 
      state: 0
    }, 
    {
      pos: [8, 0, 5], 
      state: 0
    }, 
    {
      pos: [8, 0, 6], 
      state: 0
    }, 
    {
      pos: [8, 0, 7], 
      state: 0
    }, 
    {
      pos: [8, 0, 8], 
      state: 0
    }, 
    {
      pos: [8, 0, 9], 
      state: 0
    }, 
    {
      pos: [8, 0, 10], 
      state: 0
    }, 
    {
      pos: [9, 0, 5], 
      state: 0
    }, 
    {
      pos: [9, 0, 6], 
      state: 0
    }, 
    {
      pos: [9, 0, 7], 
      state: 0
    }, 
    {
      pos: [9, 0, 8], 
      state: 0
    }, 
    {
      pos: [9, 0, 9], 
      state: 0
    }, 
    {
      pos: [5, 1, 5], 
      state: 1
    }, 
    {
      pos: [5, 1, 6], 
      state: 1
    }, 
    {
      pos: [5, 1, 7], 
      state: 1
    }, 
    {
      pos: [5, 1, 8], 
      state: 1
    }, 
    {
      pos: [5, 1, 9], 
      state: 1
    }, 
    {
      pos: [6, 1, 5], 
      state: 1
    }, 
    {
      pos: [6, 1, 6], 
      state: 1
    }, 
    {
      pos: [6, 1, 7], 
      state: 1
    }, 
    {
      pos: [6, 1, 8], 
      state: 1
    }, 
    {
      pos: [6, 1, 9], 
      state: 1
    }, 
    {
      pos: [6, 1, 10], 
      state: 0
    }, 
    {
      pos: [7, 1, 5], 
      state: 1
    }, 
    {
      pos: [7, 1, 6], 
      state: 1
    }, 
    {
      pos: [7, 1, 7], 
      state: 1
    }, 
    {
      pos: [7, 1, 8], 
      state: 1
    }, 
    {
      pos: [7, 1, 9], 
      state: 1
    }, 
    {
      pos: [7, 1, 10], 
      state: 1
    }, 
    {
      pos: [8, 1, 5], 
      state: 1
    }, 
    {
      pos: [8, 1, 6], 
      state: 1
    }, 
    {
      pos: [8, 1, 7], 
      state: 1
    }, 
    {
      pos: [8, 1, 8], 
      state: 1
    }, 
    {
      pos: [8, 1, 9], 
      state: 1
    }, 
    {
      pos: [8, 1, 10], 
      state: 0
    }, 
    {
      pos: [9, 1, 5], 
      state: 1
    }, 
    {
      pos: [9, 1, 6], 
      state: 1
    }, 
    {
      pos: [9, 1, 7], 
      state: 1
    }, 
    {
      pos: [9, 1, 8], 
      state: 1
    }, 
    {
      pos: [9, 1, 9], 
      state: 1
    }, 
    {
      pos: [5, 2, 5], 
      state: 2
    }, 
    {
      pos: [5, 2, 6], 
      state: 2
    }, 
    {
      pos: [5, 2, 7], 
      state: 1
    }, 
    {
      pos: [5, 2, 8], 
      state: 1
    }, 
    {
      pos: [5, 2, 9], 
      state: 1
    }, 
    {
      pos: [6, 2, 5], 
      state: 3
    }, 
    {
      pos: [6, 2, 8], 
      state: 2
    }, 
    {
      pos: [6, 2, 9], 
      state: 3
    }, 
    {
      pos: [6, 2, 10], 
      state: 1
    }, 
    {
      pos: [7, 2, 6], 
      state: 3
    }, 
    {
      pos: [7, 2, 7], 
      state: 3
    }, 
    {
      pos: [7, 2, 8], 
      state: 3
    }, 
    {
      pos: [7, 2, 9], 
      state: 3
    }, 
    {
      pos: [8, 2, 5], 
      state: 3
    }, 
    {
      pos: [8, 2, 6], 
      state: 3
    }, 
    {
      pos: [8, 2, 7], 
      state: 3
    }, 
    {
      pos: [8, 2, 8], 
      state: 3
    }, 
    {
      pos: [8, 2, 9], 
      state: 3
    }, 
    {
      pos: [8, 2, 10], 
      state: 1
    }, 
    {
      pos: [9, 2, 5], 
      state: 3
    }, 
    {
      pos: [9, 2, 6], 
      state: 3
    }, 
    {
      pos: [9, 2, 8], 
      state: 3
    }, 
    {
      pos: [9, 2, 9], 
      state: 1
    }, 
    {
      pos: [5, 3, 5], 
      state: 2
    }, 
    {
      pos: [5, 3, 6], 
      state: 2
    }, 
    {
      pos: [5, 3, 8], 
      state: 2
    }, 
    {
      pos: [5, 3, 9], 
      state: 2
    }, 
    {
      pos: [6, 3, 5], 
      state: 3
    }, 
    {
      pos: [6, 3, 6], 
      state: 2
    }, 
    {
      pos: [6, 3, 7], 
      state: 4
    }, 
    {
      pos: [6, 3, 8], 
      state: 0
    }, 
    {
      pos: [6, 3, 9], 
      state: 3
    }, 
    {
      pos: [6, 3, 10], 
      state: 1
    }, 
    {
      pos: [7, 3, 5], 
      state: 3
    }, 
    {
      pos: [7, 3, 6], 
      state: 3
    }, 
    {
      pos: [7, 3, 7], 
      state: 3
    }, 
    {
      pos: [7, 3, 8], 
      state: 3
    }, 
    {
      pos: [7, 3, 9], 
      state: 3
    }, 
    {
      pos: [7, 3, 10], 
      state: 3
    }, 
    {
      pos: [8, 3, 5], 
      state: 0
    }, 
    {
      pos: [8, 3, 6], 
      state: 3
    }, 
    {
      pos: [8, 3, 7], 
      state: 3
    }, 
    {
      pos: [8, 3, 8], 
      state: 3
    }, 
    {
      pos: [8, 3, 9], 
      state: 3
    }, 
    {
      pos: [8, 3, 10], 
      state: 3
    }, 
    {
      pos: [9, 3, 5], 
      state: 3
    }, 
    {
      pos: [9, 3, 6], 
      state: 3
    }, 
    {
      pos: [9, 3, 7], 
      state: 3
    }, 
    {
      pos: [9, 3, 8], 
      state: 3
    }, 
    {
      pos: [9, 3, 9], 
      state: 1
    }, 
    {
      pos: [5, 4, 8], 
      state: 2
    }, 
    {
      pos: [5, 4, 9], 
      state: 2
    }, 
    {
      pos: [6, 4, 9], 
      state: 3
    }, 
    {
      pos: [6, 4, 10], 
      state: 3
    }, 
    {
      pos: [7, 4, 6], 
      state: 0
    }, 
    {
      pos: [7, 4, 7], 
      state: 0
    }, 
    {
      pos: [7, 4, 8], 
      state: 5
    }, 
    {
      pos: [7, 4, 9], 
      state: 3
    }, 
    {
      pos: [8, 4, 7], 
      state: 3
    }, 
    {
      pos: [8, 4, 8], 
      state: 3
    }, 
    {
      pos: [8, 4, 9], 
      state: 3
    }, 
    {
      pos: [9, 4, 5], 
      state: 0
    }, 
    {
      pos: [9, 4, 8], 
      state: 3
    }, 
    {
      pos: [9, 4, 9], 
      state: 2
    }, 
    {
      pos: [5, 5, 7], 
      state: 2
    }, 
    {
      pos: [5, 5, 8], 
      state: 2
    }, 
    {
      pos: [6, 5, 9], 
      state: 2
    }, 
    {
      pos: [7, 5, 9], 
      state: 3
    }, 
    {
      pos: [8, 5, 8], 
      state: 3
    }, 
    {
      pos: [9, 5, 7], 
      state: 2
    }, 
    {
      pos: [9, 5, 8], 
      state: 2
    }, 
    {
      pos: [9, 5, 9], 
      state: 3
    }, 
    {
      nbt: {
        joint: "rollable", 
        final_state: "minecraft:sand", 
        name: "minecraft:entrance_front", 
        pool: "minecraft:trail_ruins/buildings/grouped", 
        id: "minecraft:jigsaw", 
        target: "minecraft:room_front"
      }, 
      pos: [7, 2, 5], 
      state: 6
    }, 
    {
      nbt: {
        joint: "rollable", 
        final_state: "minecraft:sand", 
        name: "minecraft:building_anchor", 
        pool: "minecraft:trail_ruins/roads", 
        id: "minecraft:jigsaw", 
        target: "minecraft:road_anchor"
      }, 
      pos: [7, 2, 10], 
      state: 7
    }, 
    {
      nbt: {
        joint: "rollable", 
        final_state: "minecraft:sand", 
        name: "minecraft:entrance_right", 
        pool: "minecraft:trail_ruins/buildings/grouped", 
        id: "minecraft:jigsaw", 
        target: "minecraft:room_right"
      }, 
      pos: [9, 2, 7], 
      state: 8
    }
  ], 
  palette: [
    {
      Name: "minecraft:red_terracotta"
    }, 
    {
      Name: "minecraft:mud_bricks"
    }, 
    {
      Name: "minecraft:yellow_terracotta"
    }, 
    {
      Name: "minecraft:sand"
    }, 
    {
      Properties: {
        facing: "south"
      }, 
      Name: "minecraft:yellow_glazed_terracotta"
    }, 
    {
      Properties: {
        facing: "west"
      }, 
      Name: "minecraft:yellow_glazed_terracotta"
    }, 
    {
      Properties: {
        orientation: "north_up"
      }, 
      Name: "minecraft:jigsaw"
    }, 
    {
      Properties: {
        orientation: "south_up"
      }, 
      Name: "minecraft:jigsaw"
    }, 
    {
      Properties: {
        orientation: "east_up"
      }, 
      Name: "minecraft:jigsaw"
    }
  ]
}
