{
  size: [5, 12, 5], 
  entities: [], 
  blocks: [
    {
      pos: [0, 0, 1], 
      state: 0
    }, 
    {
      pos: [0, 0, 2], 
      state: 0
    }, 
    {
      pos: [0, 0, 3], 
      state: 0
    }, 
    {
      pos: [1, 0, 0], 
      state: 0
    }, 
    {
      pos: [1, 0, 1], 
      state: 0
    }, 
    {
      pos: [1, 0, 2], 
      state: 0
    }, 
    {
      pos: [1, 0, 3], 
      state: 0
    }, 
    {
      pos: [1, 0, 4], 
      state: 0
    }, 
    {
      pos: [2, 0, 0], 
      state: 0
    }, 
    {
      pos: [2, 0, 1], 
      state: 0
    }, 
    {
      pos: [2, 0, 3], 
      state: 0
    }, 
    {
      pos: [2, 0, 4], 
      state: 0
    }, 
    {
      pos: [3, 0, 0], 
      state: 0
    }, 
    {
      pos: [3, 0, 1], 
      state: 0
    }, 
    {
      pos: [3, 0, 2], 
      state: 0
    }, 
    {
      pos: [3, 0, 3], 
      state: 0
    }, 
    {
      pos: [3, 0, 4], 
      state: 0
    }, 
    {
      pos: [4, 0, 1], 
      state: 0
    }, 
    {
      pos: [4, 0, 2], 
      state: 0
    }, 
    {
      pos: [4, 0, 3], 
      state: 0
    }, 
    {
      pos: [0, 4, 1], 
      state: 1
    }, 
    {
      pos: [0, 4, 2], 
      state: 1
    }, 
    {
      pos: [0, 4, 3], 
      state: 1
    }, 
    {
      pos: [1, 4, 0], 
      state: 1
    }, 
    {
      pos: [1, 4, 1], 
      state: 1
    }, 
    {
      pos: [1, 4, 2], 
      state: 1
    }, 
    {
      pos: [1, 4, 3], 
      state: 1
    }, 
    {
      pos: [1, 4, 4], 
      state: 1
    }, 
    {
      pos: [2, 4, 0], 
      state: 1
    }, 
    {
      pos: [2, 4, 1], 
      state: 1
    }, 
    {
      pos: [2, 4, 2], 
      state: 1
    }, 
    {
      pos: [2, 4, 3], 
      state: 1
    }, 
    {
      pos: [2, 4, 4], 
      state: 1
    }, 
    {
      pos: [3, 4, 0], 
      state: 1
    }, 
    {
      pos: [3, 4, 1], 
      state: 1
    }, 
    {
      pos: [3, 4, 2], 
      state: 1
    }, 
    {
      pos: [3, 4, 3], 
      state: 1
    }, 
    {
      pos: [3, 4, 4], 
      state: 1
    }, 
    {
      pos: [4, 4, 1], 
      state: 1
    }, 
    {
      pos: [4, 4, 2], 
      state: 1
    }, 
    {
      pos: [4, 4, 3], 
      state: 1
    }, 
    {
      pos: [0, 5, 1], 
      state: 0
    }, 
    {
      pos: [0, 5, 2], 
      state: 0
    }, 
    {
      pos: [0, 5, 3], 
      state: 0
    }, 
    {
      pos: [1, 5, 0], 
      state: 0
    }, 
    {
      pos: [1, 5, 1], 
      state: 0
    }, 
    {
      pos: [1, 5, 2], 
      state: 0
    }, 
    {
      pos: [1, 5, 3], 
      state: 0
    }, 
    {
      pos: [1, 5, 4], 
      state: 2
    }, 
    {
      pos: [2, 5, 0], 
      state: 0
    }, 
    {
      pos: [2, 5, 1], 
      state: 0
    }, 
    {
      pos: [2, 5, 2], 
      state: 0
    }, 
    {
      pos: [2, 5, 3], 
      state: 0
    }, 
    {
      pos: [2, 5, 4], 
      state: 2
    }, 
    {
      pos: [3, 5, 0], 
      state: 0
    }, 
    {
      pos: [3, 5, 1], 
      state: 0
    }, 
    {
      pos: [3, 5, 2], 
      state: 0
    }, 
    {
      pos: [3, 5, 3], 
      state: 0
    }, 
    {
      pos: [3, 5, 4], 
      state: 2
    }, 
    {
      pos: [4, 5, 1], 
      state: 0
    }, 
    {
      pos: [4, 5, 2], 
      state: 0
    }, 
    {
      pos: [4, 5, 3], 
      state: 0
    }, 
    {
      pos: [1, 6, 4], 
      state: 3
    }, 
    {
      pos: [2, 6, 4], 
      state: 3
    }, 
    {
      pos: [3, 6, 4], 
      state: 3
    }, 
    {
      pos: [1, 7, 4], 
      state: 2
    }, 
    {
      pos: [3, 7, 4], 
      state: 2
    }, 
    {
      pos: [1, 8, 4], 
      state: 2
    }, 
    {
      pos: [2, 8, 4], 
      state: 2
    }, 
    {
      pos: [3, 8, 4], 
      state: 2
    }, 
    {
      pos: [1, 9, 4], 
      state: 4
    }, 
    {
      pos: [2, 9, 4], 
      state: 5
    }, 
    {
      pos: [3, 9, 4], 
      state: 4
    }, 
    {
      pos: [1, 10, 4], 
      state: 2
    }, 
    {
      pos: [2, 10, 4], 
      state: 2
    }, 
    {
      pos: [3, 10, 4], 
      state: 2
    }, 
    {
      pos: [0, 11, 1], 
      state: 1
    }, 
    {
      pos: [0, 11, 2], 
      state: 1
    }, 
    {
      pos: [0, 11, 3], 
      state: 1
    }, 
    {
      pos: [1, 11, 0], 
      state: 1
    }, 
    {
      pos: [1, 11, 1], 
      state: 1
    }, 
    {
      pos: [1, 11, 2], 
      state: 1
    }, 
    {
      pos: [1, 11, 3], 
      state: 1
    }, 
    {
      pos: [1, 11, 4], 
      state: 1
    }, 
    {
      pos: [2, 11, 0], 
      state: 1
    }, 
    {
      pos: [2, 11, 1], 
      state: 1
    }, 
    {
      pos: [2, 11, 2], 
      state: 1
    }, 
    {
      pos: [2, 11, 3], 
      state: 1
    }, 
    {
      pos: [2, 11, 4], 
      state: 1
    }, 
    {
      pos: [3, 11, 0], 
      state: 1
    }, 
    {
      pos: [3, 11, 1], 
      state: 1
    }, 
    {
      pos: [3, 11, 2], 
      state: 1
    }, 
    {
      pos: [3, 11, 3], 
      state: 1
    }, 
    {
      pos: [3, 11, 4], 
      state: 1
    }, 
    {
      pos: [4, 11, 1], 
      state: 1
    }, 
    {
      pos: [4, 11, 2], 
      state: 1
    }, 
    {
      pos: [4, 11, 3], 
      state: 1
    }, 
    {
      pos: [0, 1, 1], 
      state: 6
    }, 
    {
      pos: [0, 1, 2], 
      state: 6
    }, 
    {
      pos: [0, 1, 3], 
      state: 6
    }, 
    {
      pos: [1, 1, 0], 
      state: 6
    }, 
    {
      pos: [1, 1, 1], 
      state: 6
    }, 
    {
      pos: [1, 1, 2], 
      state: 6
    }, 
    {
      pos: [1, 1, 3], 
      state: 6
    }, 
    {
      pos: [1, 1, 4], 
      state: 6
    }, 
    {
      pos: [2, 1, 0], 
      state: 6
    }, 
    {
      pos: [2, 1, 1], 
      state: 6
    }, 
    {
      pos: [2, 1, 2], 
      state: 6
    }, 
    {
      pos: [2, 1, 3], 
      state: 6
    }, 
    {
      pos: [2, 1, 4], 
      state: 6
    }, 
    {
      pos: [3, 1, 0], 
      state: 6
    }, 
    {
      pos: [3, 1, 1], 
      state: 6
    }, 
    {
      pos: [3, 1, 2], 
      state: 6
    }, 
    {
      pos: [3, 1, 3], 
      state: 6
    }, 
    {
      pos: [3, 1, 4], 
      state: 6
    }, 
    {
      pos: [4, 1, 1], 
      state: 6
    }, 
    {
      pos: [4, 1, 2], 
      state: 6
    }, 
    {
      pos: [4, 1, 3], 
      state: 6
    }, 
    {
      pos: [0, 2, 1], 
      state: 6
    }, 
    {
      pos: [0, 2, 3], 
      state: 6
    }, 
    {
      pos: [1, 2, 0], 
      state: 6
    }, 
    {
      pos: [1, 2, 1], 
      state: 6
    }, 
    {
      pos: [1, 2, 2], 
      state: 6
    }, 
    {
      pos: [1, 2, 3], 
      state: 6
    }, 
    {
      pos: [1, 2, 4], 
      state: 6
    }, 
    {
      pos: [2, 2, 1], 
      state: 6
    }, 
    {
      pos: [2, 2, 2], 
      state: 6
    }, 
    {
      pos: [2, 2, 3], 
      state: 6
    }, 
    {
      pos: [3, 2, 0], 
      state: 6
    }, 
    {
      pos: [3, 2, 1], 
      state: 6
    }, 
    {
      pos: [3, 2, 2], 
      state: 6
    }, 
    {
      pos: [3, 2, 3], 
      state: 6
    }, 
    {
      pos: [3, 2, 4], 
      state: 6
    }, 
    {
      pos: [4, 2, 1], 
      state: 6
    }, 
    {
      pos: [4, 2, 3], 
      state: 6
    }, 
    {
      pos: [0, 3, 1], 
      state: 6
    }, 
    {
      pos: [0, 3, 2], 
      state: 6
    }, 
    {
      pos: [0, 3, 3], 
      state: 6
    }, 
    {
      pos: [1, 3, 0], 
      state: 6
    }, 
    {
      pos: [1, 3, 1], 
      state: 6
    }, 
    {
      pos: [1, 3, 2], 
      state: 6
    }, 
    {
      pos: [1, 3, 3], 
      state: 6
    }, 
    {
      pos: [1, 3, 4], 
      state: 6
    }, 
    {
      pos: [2, 3, 0], 
      state: 6
    }, 
    {
      pos: [2, 3, 1], 
      state: 6
    }, 
    {
      pos: [2, 3, 2], 
      state: 6
    }, 
    {
      pos: [2, 3, 3], 
      state: 6
    }, 
    {
      pos: [2, 3, 4], 
      state: 6
    }, 
    {
      pos: [3, 3, 0], 
      state: 6
    }, 
    {
      pos: [3, 3, 1], 
      state: 6
    }, 
    {
      pos: [3, 3, 2], 
      state: 6
    }, 
    {
      pos: [3, 3, 3], 
      state: 6
    }, 
    {
      pos: [3, 3, 4], 
      state: 6
    }, 
    {
      pos: [4, 3, 1], 
      state: 6
    }, 
    {
      pos: [4, 3, 2], 
      state: 6
    }, 
    {
      pos: [4, 3, 3], 
      state: 6
    }, 
    {
      pos: [0, 6, 1], 
      state: 6
    }, 
    {
      pos: [0, 6, 2], 
      state: 6
    }, 
    {
      pos: [0, 6, 3], 
      state: 6
    }, 
    {
      pos: [1, 6, 0], 
      state: 6
    }, 
    {
      pos: [1, 6, 1], 
      state: 6
    }, 
    {
      pos: [1, 6, 2], 
      state: 6
    }, 
    {
      pos: [1, 6, 3], 
      state: 6
    }, 
    {
      pos: [2, 6, 0], 
      state: 6
    }, 
    {
      pos: [2, 6, 1], 
      state: 6
    }, 
    {
      pos: [2, 6, 2], 
      state: 6
    }, 
    {
      pos: [2, 6, 3], 
      state: 6
    }, 
    {
      pos: [3, 6, 0], 
      state: 6
    }, 
    {
      pos: [3, 6, 1], 
      state: 6
    }, 
    {
      pos: [3, 6, 2], 
      state: 6
    }, 
    {
      pos: [3, 6, 3], 
      state: 6
    }, 
    {
      pos: [4, 6, 1], 
      state: 6
    }, 
    {
      pos: [4, 6, 2], 
      state: 6
    }, 
    {
      pos: [4, 6, 3], 
      state: 6
    }, 
    {
      pos: [0, 7, 1], 
      state: 6
    }, 
    {
      pos: [0, 7, 3], 
      state: 6
    }, 
    {
      pos: [1, 7, 0], 
      state: 6
    }, 
    {
      pos: [1, 7, 1], 
      state: 6
    }, 
    {
      pos: [1, 7, 2], 
      state: 6
    }, 
    {
      pos: [1, 7, 3], 
      state: 6
    }, 
    {
      pos: [2, 7, 1], 
      state: 6
    }, 
    {
      pos: [2, 7, 3], 
      state: 6
    }, 
    {
      pos: [3, 7, 0], 
      state: 6
    }, 
    {
      pos: [3, 7, 1], 
      state: 6
    }, 
    {
      pos: [3, 7, 2], 
      state: 6
    }, 
    {
      pos: [3, 7, 3], 
      state: 6
    }, 
    {
      pos: [4, 7, 1], 
      state: 6
    }, 
    {
      pos: [4, 7, 3], 
      state: 6
    }, 
    {
      pos: [0, 8, 1], 
      state: 6
    }, 
    {
      pos: [0, 8, 2], 
      state: 6
    }, 
    {
      pos: [0, 8, 3], 
      state: 6
    }, 
    {
      pos: [1, 8, 0], 
      state: 6
    }, 
    {
      pos: [1, 8, 1], 
      state: 6
    }, 
    {
      pos: [1, 8, 2], 
      state: 6
    }, 
    {
      pos: [1, 8, 3], 
      state: 6
    }, 
    {
      pos: [2, 8, 0], 
      state: 6
    }, 
    {
      pos: [2, 8, 1], 
      state: 6
    }, 
    {
      pos: [2, 8, 2], 
      state: 6
    }, 
    {
      pos: [2, 8, 3], 
      state: 6
    }, 
    {
      pos: [3, 8, 0], 
      state: 6
    }, 
    {
      pos: [3, 8, 1], 
      state: 6
    }, 
    {
      pos: [3, 8, 2], 
      state: 6
    }, 
    {
      pos: [3, 8, 3], 
      state: 6
    }, 
    {
      pos: [4, 8, 1], 
      state: 6
    }, 
    {
      pos: [4, 8, 2], 
      state: 6
    }, 
    {
      pos: [4, 8, 3], 
      state: 6
    }, 
    {
      pos: [0, 9, 1], 
      state: 6
    }, 
    {
      pos: [0, 9, 2], 
      state: 6
    }, 
    {
      pos: [0, 9, 3], 
      state: 6
    }, 
    {
      pos: [1, 9, 0], 
      state: 6
    }, 
    {
      pos: [1, 9, 1], 
      state: 6
    }, 
    {
      pos: [1, 9, 2], 
      state: 6
    }, 
    {
      pos: [1, 9, 3], 
      state: 6
    }, 
    {
      pos: [2, 9, 0], 
      state: 6
    }, 
    {
      pos: [2, 9, 1], 
      state: 6
    }, 
    {
      pos: [2, 9, 2], 
      state: 6
    }, 
    {
      pos: [2, 9, 3], 
      state: 6
    }, 
    {
      pos: [3, 9, 0], 
      state: 6
    }, 
    {
      pos: [3, 9, 1], 
      state: 6
    }, 
    {
      pos: [3, 9, 2], 
      state: 6
    }, 
    {
      pos: [3, 9, 3], 
      state: 6
    }, 
    {
      pos: [4, 9, 1], 
      state: 6
    }, 
    {
      pos: [4, 9, 2], 
      state: 6
    }, 
    {
      pos: [4, 9, 3], 
      state: 6
    }, 
    {
      pos: [0, 10, 1], 
      state: 6
    }, 
    {
      pos: [0, 10, 2], 
      state: 6
    }, 
    {
      pos: [0, 10, 3], 
      state: 6
    }, 
    {
      pos: [1, 10, 0], 
      state: 6
    }, 
    {
      pos: [1, 10, 1], 
      state: 6
    }, 
    {
      pos: [1, 10, 2], 
      state: 6
    }, 
    {
      pos: [1, 10, 3], 
      state: 6
    }, 
    {
      pos: [2, 10, 0], 
      state: 6
    }, 
    {
      pos: [2, 10, 1], 
      state: 6
    }, 
    {
      pos: [2, 10, 2], 
      state: 6
    }, 
    {
      pos: [2, 10, 3], 
      state: 6
    }, 
    {
      pos: [3, 10, 0], 
      state: 6
    }, 
    {
      pos: [3, 10, 1], 
      state: 6
    }, 
    {
      pos: [3, 10, 2], 
      state: 6
    }, 
    {
      pos: [3, 10, 3], 
      state: 6
    }, 
    {
      pos: [4, 10, 1], 
      state: 6
    }, 
    {
      pos: [4, 10, 2], 
      state: 6
    }, 
    {
      pos: [4, 10, 3], 
      state: 6
    }, 
    {
      nbt: {
        joint: "rollable", 
        final_state: "minecraft:waxed_oxidized_copper", 
        name: "minecraft:center", 
        placement_priority: 0, 
        pool: "minecraft:empty", 
        selection_priority: 0, 
        id: "minecraft:jigsaw", 
        target: "minecraft:empty"
      }, 
      pos: [2, 0, 2], 
      state: 7
    }, 
    {
      nbt: {
        joint: "rollable", 
        final_state: "minecraft:air", 
        name: "minecraft:empty", 
        placement_priority: 0, 
        pool: "minecraft:trial_chambers/chamber/slanted", 
        selection_priority: 0, 
        id: "minecraft:jigsaw", 
        target: "minecraft:lower_arm"
      }, 
      pos: [0, 2, 2], 
      state: 8
    }, 
    {
      nbt: {
        joint: "rollable", 
        final_state: "minecraft:air", 
        name: "minecraft:empty", 
        placement_priority: 0, 
        pool: "minecraft:trial_chambers/chamber/slanted", 
        selection_priority: 0, 
        id: "minecraft:jigsaw", 
        target: "minecraft:lower_arm"
      }, 
      pos: [2, 2, 0], 
      state: 9
    }, 
    {
      nbt: {
        joint: "rollable", 
        final_state: "minecraft:air", 
        name: "minecraft:empty", 
        placement_priority: 0, 
        pool: "minecraft:trial_chambers/chamber/slanted", 
        selection_priority: 0, 
        id: "minecraft:jigsaw", 
        target: "minecraft:lower_arm"
      }, 
      pos: [2, 2, 4], 
      state: 10
    }, 
    {
      nbt: {
        joint: "rollable", 
        final_state: "minecraft:air", 
        name: "minecraft:empty", 
        placement_priority: 0, 
        pool: "minecraft:trial_chambers/chamber/slanted", 
        selection_priority: 0, 
        id: "minecraft:jigsaw", 
        target: "minecraft:lower_arm"
      }, 
      pos: [4, 2, 2], 
      state: 11
    }, 
    {
      nbt: {
        joint: "rollable", 
        final_state: "minecraft:air", 
        name: "minecraft:empty", 
        placement_priority: 0, 
        pool: "minecraft:trial_chambers/chamber/slanted", 
        selection_priority: 0, 
        id: "minecraft:jigsaw", 
        target: "minecraft:upper_arm"
      }, 
      pos: [0, 7, 2], 
      state: 8
    }, 
    {
      nbt: {
        joint: "rollable", 
        final_state: "minecraft:air", 
        name: "minecraft:empty", 
        placement_priority: 0, 
        pool: "minecraft:trial_chambers/chamber/slanted", 
        selection_priority: 0, 
        id: "minecraft:jigsaw", 
        target: "minecraft:upper_arm"
      }, 
      pos: [2, 7, 0], 
      state: 9
    }, 
    {
      nbt: {
        joint: "aligned", 
        final_state: "minecraft:air", 
        name: "minecraft:empty", 
        placement_priority: 1, 
        pool: "minecraft:trial_chambers/spawner/breeze", 
        selection_priority: 1, 
        id: "minecraft:jigsaw", 
        target: "minecraft:spawner_connector"
      }, 
      pos: [2, 7, 2], 
      state: 10
    }, 
    {
      nbt: {
        joint: "rollable", 
        final_state: "minecraft:waxed_copper_bulb[lit=true]", 
        name: "minecraft:empty", 
        placement_priority: 0, 
        pool: "minecraft:trial_chambers/chamber/slanted", 
        selection_priority: 0, 
        id: "minecraft:jigsaw", 
        target: "minecraft:ominous_upper_arm"
      }, 
      pos: [2, 7, 4], 
      state: 10
    }, 
    {
      nbt: {
        joint: "rollable", 
        final_state: "minecraft:air", 
        name: "minecraft:empty", 
        placement_priority: 0, 
        pool: "minecraft:trial_chambers/chamber/slanted", 
        selection_priority: 0, 
        id: "minecraft:jigsaw", 
        target: "minecraft:upper_arm"
      }, 
      pos: [4, 7, 2], 
      state: 11
    }
  ], 
  palette: [
    {
      Name: "minecraft:waxed_oxidized_copper"
    }, 
    {
      Name: "minecraft:polished_tuff"
    }, 
    {
      Name: "minecraft:tuff_bricks"
    }, 
    {
      Name: "minecraft:waxed_copper_block"
    }, 
    {
      Name: "minecraft:chiseled_tuff_bricks"
    }, 
    {
      Name: "minecraft:chiseled_tuff"
    }, 
    {
      Name: "minecraft:air"
    }, 
    {
      Properties: {
        orientation: "down_north"
      }, 
      Name: "minecraft:jigsaw"
    }, 
    {
      Properties: {
        orientation: "west_up"
      }, 
      Name: "minecraft:jigsaw"
    }, 
    {
      Properties: {
        orientation: "north_up"
      }, 
      Name: "minecraft:jigsaw"
    }, 
    {
      Properties: {
        orientation: "south_up"
      }, 
      Name: "minecraft:jigsaw"
    }, 
    {
      Properties: {
        orientation: "east_up"
      }, 
      Name: "minecraft:jigsaw"
    }
  ]
}
