{
  size: [5, 5, 10], 
  entities: [], 
  blocks: [
    {
      pos: [0, 0, 1], 
      state: 0
    }, 
    {
      pos: [0, 0, 2], 
      state: 0
    }, 
    {
      pos: [0, 0, 3], 
      state: 0
    }, 
    {
      pos: [0, 0, 6], 
      state: 0
    }, 
    {
      pos: [0, 0, 7], 
      state: 0
    }, 
    {
      pos: [0, 0, 8], 
      state: 0
    }, 
    {
      pos: [1, 0, 0], 
      state: 0
    }, 
    {
      pos: [1, 0, 1], 
      state: 0
    }, 
    {
      pos: [1, 0, 2], 
      state: 0
    }, 
    {
      pos: [1, 0, 3], 
      state: 0
    }, 
    {
      pos: [1, 0, 4], 
      state: 1
    }, 
    {
      pos: [1, 0, 5], 
      state: 0
    }, 
    {
      pos: [1, 0, 6], 
      state: 0
    }, 
    {
      pos: [1, 0, 7], 
      state: 0
    }, 
    {
      pos: [1, 0, 8], 
      state: 0
    }, 
    {
      pos: [1, 0, 9], 
      state: 0
    }, 
    {
      pos: [2, 0, 0], 
      state: 0
    }, 
    {
      pos: [2, 0, 1], 
      state: 0
    }, 
    {
      pos: [2, 0, 2], 
      state: 0
    }, 
    {
      pos: [2, 0, 3], 
      state: 0
    }, 
    {
      pos: [2, 0, 4], 
      state: 1
    }, 
    {
      pos: [2, 0, 5], 
      state: 0
    }, 
    {
      pos: [2, 0, 6], 
      state: 0
    }, 
    {
      pos: [2, 0, 7], 
      state: 0
    }, 
    {
      pos: [2, 0, 8], 
      state: 0
    }, 
    {
      pos: [2, 0, 9], 
      state: 0
    }, 
    {
      pos: [3, 0, 0], 
      state: 0
    }, 
    {
      pos: [3, 0, 1], 
      state: 0
    }, 
    {
      pos: [3, 0, 2], 
      state: 0
    }, 
    {
      pos: [3, 0, 3], 
      state: 0
    }, 
    {
      pos: [3, 0, 4], 
      state: 1
    }, 
    {
      pos: [3, 0, 5], 
      state: 0
    }, 
    {
      pos: [3, 0, 6], 
      state: 0
    }, 
    {
      pos: [3, 0, 7], 
      state: 0
    }, 
    {
      pos: [3, 0, 8], 
      state: 0
    }, 
    {
      pos: [3, 0, 9], 
      state: 0
    }, 
    {
      pos: [4, 0, 1], 
      state: 0
    }, 
    {
      pos: [4, 0, 2], 
      state: 0
    }, 
    {
      pos: [4, 0, 3], 
      state: 0
    }, 
    {
      pos: [4, 0, 6], 
      state: 0
    }, 
    {
      pos: [4, 0, 7], 
      state: 0
    }, 
    {
      pos: [4, 0, 8], 
      state: 0
    }, 
    {
      pos: [1, 1, 4], 
      state: 2
    }, 
    {
      pos: [2, 1, 4], 
      state: 2
    }, 
    {
      pos: [3, 1, 4], 
      state: 2
    }, 
    {
      pos: [1, 2, 4], 
      state: 1
    }, 
    {
      pos: [2, 2, 4], 
      state: 3
    }, 
    {
      pos: [3, 2, 4], 
      state: 1
    }, 
    {
      pos: [1, 3, 4], 
      state: 1
    }, 
    {
      pos: [2, 3, 4], 
      state: 1
    }, 
    {
      pos: [3, 3, 4], 
      state: 1
    }, 
    {
      pos: [0, 4, 1], 
      state: 4
    }, 
    {
      pos: [0, 4, 2], 
      state: 4
    }, 
    {
      pos: [0, 4, 3], 
      state: 4
    }, 
    {
      pos: [0, 4, 7], 
      state: 4
    }, 
    {
      pos: [0, 4, 8], 
      state: 4
    }, 
    {
      pos: [1, 4, 0], 
      state: 4
    }, 
    {
      pos: [1, 4, 1], 
      state: 4
    }, 
    {
      pos: [1, 4, 2], 
      state: 4
    }, 
    {
      pos: [1, 4, 3], 
      state: 4
    }, 
    {
      pos: [1, 4, 4], 
      state: 1
    }, 
    {
      pos: [1, 4, 5], 
      state: 4
    }, 
    {
      pos: [1, 4, 6], 
      state: 4
    }, 
    {
      pos: [1, 4, 7], 
      state: 4
    }, 
    {
      pos: [1, 4, 8], 
      state: 4
    }, 
    {
      pos: [1, 4, 9], 
      state: 2
    }, 
    {
      pos: [2, 4, 0], 
      state: 4
    }, 
    {
      pos: [2, 4, 1], 
      state: 4
    }, 
    {
      pos: [2, 4, 2], 
      state: 4
    }, 
    {
      pos: [2, 4, 3], 
      state: 4
    }, 
    {
      pos: [2, 4, 4], 
      state: 1
    }, 
    {
      pos: [2, 4, 5], 
      state: 4
    }, 
    {
      pos: [2, 4, 6], 
      state: 4
    }, 
    {
      pos: [2, 4, 7], 
      state: 4
    }, 
    {
      pos: [2, 4, 8], 
      state: 4
    }, 
    {
      pos: [2, 4, 9], 
      state: 2
    }, 
    {
      pos: [3, 4, 0], 
      state: 4
    }, 
    {
      pos: [3, 4, 1], 
      state: 4
    }, 
    {
      pos: [3, 4, 2], 
      state: 4
    }, 
    {
      pos: [3, 4, 3], 
      state: 4
    }, 
    {
      pos: [3, 4, 4], 
      state: 1
    }, 
    {
      pos: [3, 4, 5], 
      state: 4
    }, 
    {
      pos: [3, 4, 6], 
      state: 4
    }, 
    {
      pos: [3, 4, 7], 
      state: 4
    }, 
    {
      pos: [3, 4, 8], 
      state: 4
    }, 
    {
      pos: [3, 4, 9], 
      state: 2
    }, 
    {
      pos: [4, 4, 1], 
      state: 4
    }, 
    {
      pos: [4, 4, 2], 
      state: 4
    }, 
    {
      pos: [4, 4, 6], 
      state: 4
    }, 
    {
      pos: [4, 4, 7], 
      state: 4
    }, 
    {
      pos: [4, 4, 8], 
      state: 4
    }, 
    {
      pos: [0, 1, 1], 
      state: 5
    }, 
    {
      pos: [0, 1, 2], 
      state: 5
    }, 
    {
      pos: [0, 1, 3], 
      state: 5
    }, 
    {
      pos: [0, 1, 6], 
      state: 5
    }, 
    {
      pos: [0, 1, 7], 
      state: 5
    }, 
    {
      pos: [0, 1, 8], 
      state: 5
    }, 
    {
      pos: [1, 1, 0], 
      state: 5
    }, 
    {
      pos: [1, 1, 1], 
      state: 5
    }, 
    {
      pos: [1, 1, 2], 
      state: 5
    }, 
    {
      pos: [1, 1, 3], 
      state: 5
    }, 
    {
      pos: [1, 1, 5], 
      state: 5
    }, 
    {
      pos: [1, 1, 6], 
      state: 5
    }, 
    {
      pos: [1, 1, 7], 
      state: 5
    }, 
    {
      pos: [1, 1, 8], 
      state: 5
    }, 
    {
      pos: [1, 1, 9], 
      state: 5
    }, 
    {
      pos: [2, 1, 0], 
      state: 5
    }, 
    {
      pos: [2, 1, 1], 
      state: 5
    }, 
    {
      pos: [2, 1, 2], 
      state: 5
    }, 
    {
      pos: [2, 1, 3], 
      state: 5
    }, 
    {
      pos: [2, 1, 5], 
      state: 5
    }, 
    {
      pos: [2, 1, 6], 
      state: 5
    }, 
    {
      pos: [2, 1, 7], 
      state: 5
    }, 
    {
      pos: [2, 1, 8], 
      state: 5
    }, 
    {
      pos: [2, 1, 9], 
      state: 5
    }, 
    {
      pos: [3, 1, 0], 
      state: 5
    }, 
    {
      pos: [3, 1, 1], 
      state: 5
    }, 
    {
      pos: [3, 1, 2], 
      state: 5
    }, 
    {
      pos: [3, 1, 3], 
      state: 5
    }, 
    {
      pos: [3, 1, 5], 
      state: 5
    }, 
    {
      pos: [3, 1, 6], 
      state: 5
    }, 
    {
      pos: [3, 1, 7], 
      state: 5
    }, 
    {
      pos: [3, 1, 8], 
      state: 5
    }, 
    {
      pos: [3, 1, 9], 
      state: 5
    }, 
    {
      pos: [4, 1, 1], 
      state: 5
    }, 
    {
      pos: [4, 1, 2], 
      state: 5
    }, 
    {
      pos: [4, 1, 3], 
      state: 5
    }, 
    {
      pos: [4, 1, 6], 
      state: 5
    }, 
    {
      pos: [4, 1, 7], 
      state: 5
    }, 
    {
      pos: [4, 1, 8], 
      state: 5
    }, 
    {
      pos: [0, 2, 1], 
      state: 5
    }, 
    {
      pos: [0, 2, 3], 
      state: 5
    }, 
    {
      pos: [0, 2, 6], 
      state: 5
    }, 
    {
      pos: [0, 2, 8], 
      state: 5
    }, 
    {
      pos: [1, 2, 0], 
      state: 5
    }, 
    {
      pos: [1, 2, 1], 
      state: 5
    }, 
    {
      pos: [1, 2, 2], 
      state: 5
    }, 
    {
      pos: [1, 2, 3], 
      state: 5
    }, 
    {
      pos: [1, 2, 5], 
      state: 5
    }, 
    {
      pos: [1, 2, 6], 
      state: 5
    }, 
    {
      pos: [1, 2, 7], 
      state: 5
    }, 
    {
      pos: [1, 2, 8], 
      state: 5
    }, 
    {
      pos: [1, 2, 9], 
      state: 5
    }, 
    {
      pos: [2, 2, 1], 
      state: 5
    }, 
    {
      pos: [2, 2, 2], 
      state: 5
    }, 
    {
      pos: [2, 2, 3], 
      state: 5
    }, 
    {
      pos: [2, 2, 5], 
      state: 5
    }, 
    {
      pos: [2, 2, 6], 
      state: 5
    }, 
    {
      pos: [2, 2, 8], 
      state: 5
    }, 
    {
      pos: [2, 2, 9], 
      state: 5
    }, 
    {
      pos: [3, 2, 0], 
      state: 5
    }, 
    {
      pos: [3, 2, 1], 
      state: 5
    }, 
    {
      pos: [3, 2, 2], 
      state: 5
    }, 
    {
      pos: [3, 2, 3], 
      state: 5
    }, 
    {
      pos: [3, 2, 5], 
      state: 5
    }, 
    {
      pos: [3, 2, 6], 
      state: 5
    }, 
    {
      pos: [3, 2, 7], 
      state: 5
    }, 
    {
      pos: [3, 2, 8], 
      state: 5
    }, 
    {
      pos: [3, 2, 9], 
      state: 5
    }, 
    {
      pos: [4, 2, 1], 
      state: 5
    }, 
    {
      pos: [4, 2, 3], 
      state: 5
    }, 
    {
      pos: [4, 2, 6], 
      state: 5
    }, 
    {
      pos: [4, 2, 8], 
      state: 5
    }, 
    {
      pos: [0, 3, 1], 
      state: 5
    }, 
    {
      pos: [0, 3, 2], 
      state: 5
    }, 
    {
      pos: [0, 3, 3], 
      state: 5
    }, 
    {
      pos: [0, 3, 6], 
      state: 5
    }, 
    {
      pos: [0, 3, 7], 
      state: 5
    }, 
    {
      pos: [0, 3, 8], 
      state: 5
    }, 
    {
      pos: [1, 3, 0], 
      state: 5
    }, 
    {
      pos: [1, 3, 1], 
      state: 5
    }, 
    {
      pos: [1, 3, 2], 
      state: 5
    }, 
    {
      pos: [1, 3, 3], 
      state: 5
    }, 
    {
      pos: [1, 3, 5], 
      state: 5
    }, 
    {
      pos: [1, 3, 6], 
      state: 5
    }, 
    {
      pos: [1, 3, 7], 
      state: 5
    }, 
    {
      pos: [1, 3, 8], 
      state: 5
    }, 
    {
      pos: [1, 3, 9], 
      state: 5
    }, 
    {
      pos: [2, 3, 0], 
      state: 5
    }, 
    {
      pos: [2, 3, 1], 
      state: 5
    }, 
    {
      pos: [2, 3, 2], 
      state: 5
    }, 
    {
      pos: [2, 3, 3], 
      state: 5
    }, 
    {
      pos: [2, 3, 5], 
      state: 5
    }, 
    {
      pos: [2, 3, 6], 
      state: 5
    }, 
    {
      pos: [2, 3, 7], 
      state: 5
    }, 
    {
      pos: [2, 3, 8], 
      state: 5
    }, 
    {
      pos: [2, 3, 9], 
      state: 5
    }, 
    {
      pos: [3, 3, 0], 
      state: 5
    }, 
    {
      pos: [3, 3, 1], 
      state: 5
    }, 
    {
      pos: [3, 3, 2], 
      state: 5
    }, 
    {
      pos: [3, 3, 3], 
      state: 5
    }, 
    {
      pos: [3, 3, 5], 
      state: 5
    }, 
    {
      pos: [3, 3, 6], 
      state: 5
    }, 
    {
      pos: [3, 3, 7], 
      state: 5
    }, 
    {
      pos: [3, 3, 8], 
      state: 5
    }, 
    {
      pos: [3, 3, 9], 
      state: 5
    }, 
    {
      pos: [4, 3, 1], 
      state: 5
    }, 
    {
      pos: [4, 3, 2], 
      state: 5
    }, 
    {
      pos: [4, 3, 3], 
      state: 5
    }, 
    {
      pos: [4, 3, 6], 
      state: 5
    }, 
    {
      pos: [4, 3, 7], 
      state: 5
    }, 
    {
      pos: [4, 3, 8], 
      state: 5
    }, 
    {
      pos: [0, 4, 6], 
      state: 5
    }, 
    {
      pos: [4, 4, 3], 
      state: 5
    }, 
    {
      nbt: {
        joint: "rollable", 
        final_state: "minecraft:air", 
        name: "minecraft:empty", 
        placement_priority: 0, 
        pool: "minecraft:trial_chambers/chamber/slanted", 
        selection_priority: 0, 
        id: "minecraft:jigsaw", 
        target: "minecraft:quadrant"
      }, 
      pos: [0, 2, 2], 
      state: 6
    }, 
    {
      nbt: {
        joint: "rollable", 
        final_state: "minecraft:air", 
        name: "minecraft:empty", 
        placement_priority: 0, 
        pool: "minecraft:trial_chambers/chamber/slanted", 
        selection_priority: 0, 
        id: "minecraft:jigsaw", 
        target: "minecraft:quadrant"
      }, 
      pos: [0, 2, 7], 
      state: 6
    }, 
    {
      nbt: {
        joint: "rollable", 
        final_state: "minecraft:air", 
        name: "minecraft:lower_arm", 
        placement_priority: 0, 
        pool: "minecraft:empty", 
        selection_priority: 0, 
        id: "minecraft:jigsaw", 
        target: "minecraft:empty"
      }, 
      pos: [2, 2, 0], 
      state: 7
    }, 
    {
      nbt: {
        joint: "aligned", 
        final_state: "minecraft:air", 
        name: "minecraft:empty", 
        placement_priority: 0, 
        pool: "minecraft:trial_chambers/reward/all", 
        selection_priority: 0, 
        id: "minecraft:jigsaw", 
        target: "minecraft:reward_connector"
      }, 
      pos: [2, 2, 7], 
      state: 7
    }, 
    {
      nbt: {
        joint: "rollable", 
        final_state: "minecraft:air", 
        name: "minecraft:empty", 
        placement_priority: 0, 
        pool: "minecraft:trial_chambers/chamber/slanted", 
        selection_priority: 0, 
        id: "minecraft:jigsaw", 
        target: "minecraft:quadrant"
      }, 
      pos: [4, 2, 2], 
      state: 8
    }, 
    {
      nbt: {
        joint: "rollable", 
        final_state: "minecraft:air", 
        name: "minecraft:empty", 
        placement_priority: 0, 
        pool: "minecraft:trial_chambers/chamber/slanted", 
        selection_priority: 0, 
        id: "minecraft:jigsaw", 
        target: "minecraft:quadrant"
      }, 
      pos: [4, 2, 7], 
      state: 8
    }
  ], 
  palette: [
    {
      Name: "minecraft:waxed_oxidized_copper"
    }, 
    {
      Name: "minecraft:tuff_bricks"
    }, 
    {
      Name: "minecraft:waxed_copper_block"
    }, 
    {
      Properties: {
        powered: "false", 
        lit: "true"
      }, 
      Name: "minecraft:waxed_copper_bulb"
    }, 
    {
      Name: "minecraft:polished_tuff"
    }, 
    {
      Name: "minecraft:air"
    }, 
    {
      Properties: {
        orientation: "west_up"
      }, 
      Name: "minecraft:jigsaw"
    }, 
    {
      Properties: {
        orientation: "north_up"
      }, 
      Name: "minecraft:jigsaw"
    }, 
    {
      Properties: {
        orientation: "east_up"
      }, 
      Name: "minecraft:jigsaw"
    }
  ]
}
