{
  size: [7, 11, 8], 
  entities: [], 
  blocks: [
    {
      pos: [1, 0, 2], 
      state: 0
    }, 
    {
      pos: [1, 0, 3], 
      state: 0
    }, 
    {
      pos: [1, 0, 4], 
      state: 0
    }, 
    {
      pos: [1, 0, 5], 
      state: 0
    }, 
    {
      pos: [2, 0, 2], 
      state: 0
    }, 
    {
      pos: [2, 0, 3], 
      state: 0
    }, 
    {
      pos: [2, 0, 4], 
      state: 0
    }, 
    {
      pos: [2, 0, 5], 
      state: 0
    }, 
    {
      pos: [3, 0, 2], 
      state: 0
    }, 
    {
      pos: [3, 0, 3], 
      state: 0
    }, 
    {
      pos: [3, 0, 4], 
      state: 0
    }, 
    {
      pos: [3, 0, 5], 
      state: 0
    }, 
    {
      pos: [4, 0, 2], 
      state: 0
    }, 
    {
      pos: [4, 0, 3], 
      state: 0
    }, 
    {
      pos: [4, 0, 4], 
      state: 0
    }, 
    {
      pos: [4, 0, 5], 
      state: 0
    }, 
    {
      pos: [2, 1, 3], 
      state: 0
    }, 
    {
      pos: [2, 1, 4], 
      state: 0
    }, 
    {
      pos: [3, 1, 3], 
      state: 0
    }, 
    {
      pos: [3, 1, 4], 
      state: 0
    }, 
    {
      pos: [2, 2, 3], 
      state: 0
    }, 
    {
      pos: [2, 2, 4], 
      state: 0
    }, 
    {
      pos: [3, 2, 3], 
      state: 0
    }, 
    {
      pos: [3, 2, 4], 
      state: 0
    }, 
    {
      pos: [2, 3, 3], 
      state: 1
    }, 
    {
      pos: [2, 3, 4], 
      state: 1
    }, 
    {
      pos: [3, 3, 3], 
      state: 1
    }, 
    {
      pos: [3, 3, 4], 
      state: 1
    }, 
    {
      pos: [2, 4, 3], 
      state: 2
    }, 
    {
      pos: [2, 4, 4], 
      state: 2
    }, 
    {
      pos: [3, 4, 3], 
      state: 2
    }, 
    {
      pos: [3, 4, 4], 
      state: 2
    }, 
    {
      pos: [2, 5, 3], 
      state: 3
    }, 
    {
      pos: [2, 5, 4], 
      state: 3
    }, 
    {
      pos: [3, 5, 3], 
      state: 3
    }, 
    {
      pos: [3, 5, 4], 
      state: 3
    }, 
    {
      pos: [2, 6, 3], 
      state: 1
    }, 
    {
      pos: [2, 6, 4], 
      state: 1
    }, 
    {
      pos: [3, 6, 3], 
      state: 1
    }, 
    {
      pos: [3, 6, 4], 
      state: 1
    }, 
    {
      pos: [2, 7, 3], 
      state: 0
    }, 
    {
      pos: [2, 7, 4], 
      state: 0
    }, 
    {
      pos: [3, 7, 3], 
      state: 0
    }, 
    {
      pos: [3, 7, 4], 
      state: 0
    }, 
    {
      pos: [2, 8, 3], 
      state: 0
    }, 
    {
      pos: [2, 8, 4], 
      state: 0
    }, 
    {
      pos: [3, 8, 3], 
      state: 0
    }, 
    {
      pos: [3, 8, 4], 
      state: 0
    }, 
    {
      pos: [0, 9, 3], 
      state: 0
    }, 
    {
      pos: [0, 9, 4], 
      state: 0
    }, 
    {
      pos: [0, 9, 5], 
      state: 0
    }, 
    {
      pos: [0, 9, 6], 
      state: 0
    }, 
    {
      pos: [1, 9, 2], 
      state: 1
    }, 
    {
      pos: [1, 9, 3], 
      state: 0
    }, 
    {
      pos: [1, 9, 4], 
      state: 0
    }, 
    {
      pos: [1, 9, 5], 
      state: 0
    }, 
    {
      pos: [1, 9, 6], 
      state: 0
    }, 
    {
      pos: [2, 9, 1], 
      state: 0
    }, 
    {
      pos: [2, 9, 2], 
      state: 0
    }, 
    {
      pos: [2, 9, 3], 
      state: 0
    }, 
    {
      pos: [2, 9, 4], 
      state: 0
    }, 
    {
      pos: [2, 9, 5], 
      state: 0
    }, 
    {
      pos: [2, 9, 6], 
      state: 0
    }, 
    {
      pos: [3, 9, 0], 
      state: 0
    }, 
    {
      pos: [3, 9, 1], 
      state: 0
    }, 
    {
      pos: [3, 9, 2], 
      state: 0
    }, 
    {
      pos: [3, 9, 3], 
      state: 0
    }, 
    {
      pos: [3, 9, 4], 
      state: 0
    }, 
    {
      pos: [3, 9, 5], 
      state: 0
    }, 
    {
      pos: [3, 9, 6], 
      state: 0
    }, 
    {
      pos: [4, 9, 1], 
      state: 0
    }, 
    {
      pos: [4, 9, 2], 
      state: 1
    }, 
    {
      pos: [4, 9, 3], 
      state: 0
    }, 
    {
      pos: [4, 9, 4], 
      state: 0
    }, 
    {
      pos: [4, 9, 5], 
      state: 0
    }, 
    {
      pos: [5, 9, 3], 
      state: 0
    }, 
    {
      pos: [5, 9, 4], 
      state: 0
    }, 
    {
      pos: [5, 9, 5], 
      state: 0
    }, 
    {
      pos: [6, 9, 3], 
      state: 0
    }, 
    {
      pos: [6, 9, 4], 
      state: 0
    }, 
    {
      pos: [0, 10, 5], 
      state: 0
    }, 
    {
      pos: [0, 10, 6], 
      state: 0
    }, 
    {
      pos: [0, 10, 7], 
      state: 0
    }, 
    {
      pos: [1, 10, 3], 
      state: 0
    }, 
    {
      pos: [1, 10, 4], 
      state: 0
    }, 
    {
      pos: [1, 10, 5], 
      state: 0
    }, 
    {
      pos: [1, 10, 6], 
      state: 0
    }, 
    {
      pos: [1, 10, 7], 
      state: 0
    }, 
    {
      pos: [2, 10, 2], 
      state: 0
    }, 
    {
      pos: [2, 10, 3], 
      state: 0
    }, 
    {
      pos: [2, 10, 4], 
      state: 0
    }, 
    {
      pos: [2, 10, 5], 
      state: 0
    }, 
    {
      pos: [2, 10, 6], 
      state: 0
    }, 
    {
      pos: [2, 10, 7], 
      state: 0
    }, 
    {
      pos: [3, 10, 2], 
      state: 0
    }, 
    {
      pos: [3, 10, 3], 
      state: 0
    }, 
    {
      pos: [3, 10, 4], 
      state: 0
    }, 
    {
      pos: [3, 10, 5], 
      state: 0
    }, 
    {
      pos: [4, 10, 3], 
      state: 0
    }, 
    {
      pos: [4, 10, 4], 
      state: 0
    }, 
    {
      pos: [4, 10, 5], 
      state: 0
    }, 
    {
      pos: [5, 10, 3], 
      state: 0
    }, 
    {
      pos: [5, 10, 4], 
      state: 0
    }, 
    {
      pos: [5, 10, 5], 
      state: 0
    }, 
    {
      pos: [6, 10, 3], 
      state: 0
    }, 
    {
      pos: [1, 1, 2], 
      state: 4
    }, 
    {
      pos: [1, 1, 3], 
      state: 5
    }, 
    {
      pos: [1, 1, 4], 
      state: 5
    }, 
    {
      pos: [1, 1, 5], 
      state: 6
    }, 
    {
      pos: [2, 1, 2], 
      state: 7
    }, 
    {
      pos: [2, 1, 5], 
      state: 8
    }, 
    {
      pos: [3, 1, 2], 
      state: 7
    }, 
    {
      pos: [3, 1, 5], 
      state: 8
    }, 
    {
      pos: [4, 1, 2], 
      state: 9
    }, 
    {
      pos: [4, 1, 5], 
      state: 9
    }, 
    {
      pos: [1, 8, 2], 
      state: 10
    }, 
    {
      pos: [1, 8, 3], 
      state: 11
    }, 
    {
      pos: [1, 8, 4], 
      state: 11
    }, 
    {
      pos: [1, 8, 5], 
      state: 12
    }, 
    {
      pos: [2, 8, 2], 
      state: 13
    }, 
    {
      pos: [2, 8, 5], 
      state: 14
    }, 
    {
      pos: [3, 8, 2], 
      state: 13
    }, 
    {
      pos: [3, 8, 5], 
      state: 14
    }, 
    {
      pos: [4, 8, 2], 
      state: 15
    }, 
    {
      pos: [4, 8, 3], 
      state: 16
    }, 
    {
      pos: [4, 8, 4], 
      state: 16
    }, 
    {
      pos: [4, 8, 5], 
      state: 17
    }, 
    {
      nbt: {
        joint: "rollable", 
        final_state: "minecraft:structure_void", 
        name: "minecraft:connect_structure", 
        pool: "minecraft:empty", 
        id: "minecraft:jigsaw", 
        target: "minecraft:empty"
      }, 
      pos: [6, 0, 3], 
      state: 18
    }, 
    {
      nbt: {
        joint: "rollable", 
        final_state: "minecraft:structure_void", 
        name: "minecraft:connect_structure", 
        pool: "minecraft:empty", 
        id: "minecraft:jigsaw", 
        target: "minecraft:empty"
      }, 
      pos: [6, 0, 4], 
      state: 18
    }, 
    {
      nbt: {
        id: "minecraft:skull"
      }, 
      pos: [4, 1, 4], 
      state: 19
    }
  ], 
  palette: [
    {
      Properties: {
        axis: "y"
      }, 
      Name: "minecraft:deepslate"
    }, 
    {
      Name: "minecraft:polished_deepslate"
    }, 
    {
      Name: "minecraft:chiseled_deepslate"
    }, 
    {
      Name: "minecraft:deepslate_tiles"
    }, 
    {
      Properties: {
        half: "bottom", 
        waterlogged: "false", 
        shape: "outer_left", 
        facing: "south"
      }, 
      Name: "minecraft:deepslate_tile_stairs"
    }, 
    {
      Properties: {
        half: "bottom", 
        waterlogged: "false", 
        shape: "straight", 
        facing: "east"
      }, 
      Name: "minecraft:deepslate_tile_stairs"
    }, 
    {
      Properties: {
        half: "bottom", 
        waterlogged: "false", 
        shape: "outer_left", 
        facing: "east"
      }, 
      Name: "minecraft:deepslate_tile_stairs"
    }, 
    {
      Properties: {
        half: "bottom", 
        waterlogged: "false", 
        shape: "straight", 
        facing: "south"
      }, 
      Name: "minecraft:deepslate_tile_stairs"
    }, 
    {
      Properties: {
        half: "bottom", 
        waterlogged: "false", 
        shape: "straight", 
        facing: "north"
      }, 
      Name: "minecraft:deepslate_tile_stairs"
    }, 
    {
      Properties: {
        waterlogged: "false", 
        type: "bottom"
      }, 
      Name: "minecraft:deepslate_tile_slab"
    }, 
    {
      Properties: {
        half: "top", 
        waterlogged: "false", 
        shape: "outer_left", 
        facing: "south"
      }, 
      Name: "minecraft:deepslate_tile_stairs"
    }, 
    {
      Properties: {
        half: "top", 
        waterlogged: "false", 
        shape: "straight", 
        facing: "east"
      }, 
      Name: "minecraft:deepslate_tile_stairs"
    }, 
    {
      Properties: {
        half: "top", 
        waterlogged: "false", 
        shape: "outer_right", 
        facing: "north"
      }, 
      Name: "minecraft:deepslate_tile_stairs"
    }, 
    {
      Properties: {
        half: "top", 
        waterlogged: "false", 
        shape: "straight", 
        facing: "south"
      }, 
      Name: "minecraft:deepslate_tile_stairs"
    }, 
    {
      Properties: {
        half: "top", 
        waterlogged: "false", 
        shape: "straight", 
        facing: "north"
      }, 
      Name: "minecraft:deepslate_tile_stairs"
    }, 
    {
      Properties: {
        half: "top", 
        waterlogged: "false", 
        shape: "outer_left", 
        facing: "west"
      }, 
      Name: "minecraft:deepslate_tile_stairs"
    }, 
    {
      Properties: {
        half: "top", 
        waterlogged: "false", 
        shape: "straight", 
        facing: "west"
      }, 
      Name: "minecraft:deepslate_tile_stairs"
    }, 
    {
      Properties: {
        half: "top", 
        waterlogged: "false", 
        shape: "outer_right", 
        facing: "west"
      }, 
      Name: "minecraft:deepslate_tile_stairs"
    }, 
    {
      Properties: {
        orientation: "east_up"
      }, 
      Name: "minecraft:jigsaw"
    }, 
    {
      Properties: {
        rotation: "2"
      }, 
      Name: "minecraft:skeleton_skull"
    }
  ]
}
