{
  size: [7, 8, 9], 
  entities: [], 
  blocks: [
    {
      pos: [0, 4, 0], 
      state: 0
    }, 
    {
      pos: [6, 4, 0], 
      state: 0
    }, 
    {
      pos: [1, 5, 0], 
      state: 0
    }, 
    {
      pos: [5, 5, 0], 
      state: 0
    }, 
    {
      pos: [2, 6, 0], 
      state: 0
    }, 
    {
      pos: [4, 6, 0], 
      state: 0
    }, 
    {
      pos: [3, 7, 0], 
      state: 0
    }, 
    {
      pos: [1, 0, 1], 
      state: 1
    }, 
    {
      pos: [2, 0, 1], 
      state: 2
    }, 
    {
      pos: [3, 0, 1], 
      state: 2
    }, 
    {
      pos: [4, 0, 1], 
      state: 2
    }, 
    {
      pos: [5, 0, 1], 
      state: 1
    }, 
    {
      pos: [1, 1, 1], 
      state: 3
    }, 
    {
      pos: [5, 1, 1], 
      state: 3
    }, 
    {
      pos: [1, 2, 1], 
      state: 3
    }, 
    {
      pos: [5, 2, 1], 
      state: 3
    }, 
    {
      pos: [1, 3, 1], 
      state: 3
    }, 
    {
      pos: [5, 3, 1], 
      state: 3
    }, 
    {
      pos: [0, 4, 1], 
      state: 0
    }, 
    {
      pos: [1, 4, 1], 
      state: 3
    }, 
    {
      pos: [5, 4, 1], 
      state: 3
    }, 
    {
      pos: [6, 4, 1], 
      state: 0
    }, 
    {
      pos: [1, 5, 1], 
      state: 0
    }, 
    {
      pos: [2, 5, 1], 
      state: 4
    }, 
    {
      pos: [3, 5, 1], 
      state: 4
    }, 
    {
      pos: [4, 5, 1], 
      state: 4
    }, 
    {
      pos: [5, 5, 1], 
      state: 0
    }, 
    {
      pos: [2, 6, 1], 
      state: 0
    }, 
    {
      pos: [4, 6, 1], 
      state: 0
    }, 
    {
      pos: [3, 7, 1], 
      state: 0
    }, 
    {
      pos: [1, 0, 2], 
      state: 1
    }, 
    {
      pos: [2, 0, 2], 
      state: 1
    }, 
    {
      pos: [3, 0, 2], 
      state: 1
    }, 
    {
      pos: [4, 0, 2], 
      state: 1
    }, 
    {
      pos: [5, 0, 2], 
      state: 1
    }, 
    {
      pos: [1, 1, 2], 
      state: 3
    }, 
    {
      pos: [2, 1, 2], 
      state: 5
    }, 
    {
      pos: [3, 1, 2], 
      state: 5
    }, 
    {
      pos: [4, 1, 2], 
      state: 5
    }, 
    {
      pos: [5, 1, 2], 
      state: 3
    }, 
    {
      pos: [1, 2, 2], 
      state: 3
    }, 
    {
      pos: [2, 2, 2], 
      state: 5
    }, 
    {
      pos: [4, 2, 2], 
      state: 5
    }, 
    {
      pos: [5, 2, 2], 
      state: 3
    }, 
    {
      pos: [1, 3, 2], 
      state: 3
    }, 
    {
      pos: [2, 3, 2], 
      state: 5
    }, 
    {
      pos: [4, 3, 2], 
      state: 5
    }, 
    {
      pos: [5, 3, 2], 
      state: 3
    }, 
    {
      pos: [0, 4, 2], 
      state: 0
    }, 
    {
      pos: [1, 4, 2], 
      state: 3
    }, 
    {
      pos: [2, 4, 2], 
      state: 5
    }, 
    {
      pos: [3, 4, 2], 
      state: 5
    }, 
    {
      pos: [4, 4, 2], 
      state: 5
    }, 
    {
      pos: [5, 4, 2], 
      state: 3
    }, 
    {
      pos: [6, 4, 2], 
      state: 0
    }, 
    {
      pos: [1, 5, 2], 
      state: 0
    }, 
    {
      pos: [2, 5, 2], 
      state: 4
    }, 
    {
      pos: [3, 5, 2], 
      state: 4
    }, 
    {
      pos: [4, 5, 2], 
      state: 4
    }, 
    {
      pos: [5, 5, 2], 
      state: 0
    }, 
    {
      pos: [2, 6, 2], 
      state: 0
    }, 
    {
      pos: [3, 6, 2], 
      state: 5
    }, 
    {
      pos: [4, 6, 2], 
      state: 0
    }, 
    {
      pos: [3, 7, 2], 
      state: 0
    }, 
    {
      pos: [1, 0, 3], 
      state: 1
    }, 
    {
      pos: [2, 0, 3], 
      state: 1
    }, 
    {
      pos: [3, 0, 3], 
      state: 1
    }, 
    {
      pos: [4, 0, 3], 
      state: 1
    }, 
    {
      pos: [5, 0, 3], 
      state: 1
    }, 
    {
      pos: [1, 1, 3], 
      state: 5
    }, 
    {
      pos: [3, 1, 3], 
      state: 6
    }, 
    {
      pos: [4, 1, 3], 
      state: 6
    }, 
    {
      pos: [5, 1, 3], 
      state: 5
    }, 
    {
      pos: [1, 2, 3], 
      state: 5
    }, 
    {
      pos: [5, 2, 3], 
      state: 5
    }, 
    {
      pos: [1, 3, 3], 
      state: 5
    }, 
    {
      pos: [5, 3, 3], 
      state: 5
    }, 
    {
      pos: [0, 4, 3], 
      state: 0
    }, 
    {
      pos: [1, 4, 3], 
      state: 5
    }, 
    {
      pos: [5, 4, 3], 
      state: 5
    }, 
    {
      pos: [6, 4, 3], 
      state: 0
    }, 
    {
      pos: [1, 5, 3], 
      state: 0
    }, 
    {
      pos: [5, 5, 3], 
      state: 0
    }, 
    {
      pos: [2, 6, 3], 
      state: 0
    }, 
    {
      pos: [4, 6, 3], 
      state: 0
    }, 
    {
      pos: [3, 7, 3], 
      state: 0
    }, 
    {
      pos: [1, 0, 4], 
      state: 1
    }, 
    {
      pos: [2, 0, 4], 
      state: 1
    }, 
    {
      pos: [3, 0, 4], 
      state: 1
    }, 
    {
      pos: [4, 0, 4], 
      state: 1
    }, 
    {
      pos: [5, 0, 4], 
      state: 1
    }, 
    {
      pos: [1, 1, 4], 
      state: 5
    }, 
    {
      pos: [2, 1, 4], 
      state: 6
    }, 
    {
      pos: [3, 1, 4], 
      state: 6
    }, 
    {
      pos: [4, 1, 4], 
      state: 6
    }, 
    {
      pos: [5, 1, 4], 
      state: 5
    }, 
    {
      pos: [1, 2, 4], 
      state: 5
    }, 
    {
      pos: [5, 2, 4], 
      state: 5
    }, 
    {
      pos: [0, 4, 4], 
      state: 0
    }, 
    {
      pos: [1, 4, 4], 
      state: 5
    }, 
    {
      pos: [5, 4, 4], 
      state: 5
    }, 
    {
      pos: [6, 4, 4], 
      state: 0
    }, 
    {
      pos: [1, 5, 4], 
      state: 0
    }, 
    {
      pos: [5, 5, 4], 
      state: 0
    }, 
    {
      pos: [2, 6, 4], 
      state: 0
    }, 
    {
      pos: [4, 6, 4], 
      state: 0
    }, 
    {
      pos: [3, 7, 4], 
      state: 0
    }, 
    {
      pos: [1, 0, 5], 
      state: 1
    }, 
    {
      pos: [2, 0, 5], 
      state: 1
    }, 
    {
      pos: [3, 0, 5], 
      state: 1
    }, 
    {
      pos: [4, 0, 5], 
      state: 1
    }, 
    {
      pos: [5, 0, 5], 
      state: 1
    }, 
    {
      pos: [1, 1, 5], 
      state: 5
    }, 
    {
      pos: [2, 1, 5], 
      state: 6
    }, 
    {
      pos: [3, 1, 5], 
      state: 6
    }, 
    {
      pos: [4, 1, 5], 
      state: 6
    }, 
    {
      pos: [5, 1, 5], 
      state: 5
    }, 
    {
      pos: [1, 2, 5], 
      state: 5
    }, 
    {
      pos: [5, 2, 5], 
      state: 5
    }, 
    {
      pos: [1, 3, 5], 
      state: 5
    }, 
    {
      pos: [5, 3, 5], 
      state: 5
    }, 
    {
      pos: [0, 4, 5], 
      state: 0
    }, 
    {
      pos: [1, 4, 5], 
      state: 5
    }, 
    {
      pos: [5, 4, 5], 
      state: 5
    }, 
    {
      pos: [6, 4, 5], 
      state: 0
    }, 
    {
      pos: [1, 5, 5], 
      state: 0
    }, 
    {
      pos: [5, 5, 5], 
      state: 0
    }, 
    {
      pos: [2, 6, 5], 
      state: 0
    }, 
    {
      pos: [4, 6, 5], 
      state: 0
    }, 
    {
      pos: [3, 7, 5], 
      state: 0
    }, 
    {
      pos: [1, 0, 6], 
      state: 1
    }, 
    {
      pos: [2, 0, 6], 
      state: 1
    }, 
    {
      pos: [3, 0, 6], 
      state: 1
    }, 
    {
      pos: [4, 0, 6], 
      state: 1
    }, 
    {
      pos: [5, 0, 6], 
      state: 1
    }, 
    {
      pos: [1, 1, 6], 
      state: 3
    }, 
    {
      pos: [2, 1, 6], 
      state: 5
    }, 
    {
      pos: [3, 1, 6], 
      state: 5
    }, 
    {
      pos: [4, 1, 6], 
      state: 5
    }, 
    {
      pos: [5, 1, 6], 
      state: 3
    }, 
    {
      pos: [1, 2, 6], 
      state: 3
    }, 
    {
      pos: [2, 2, 6], 
      state: 5
    }, 
    {
      pos: [3, 2, 6], 
      state: 5
    }, 
    {
      pos: [4, 2, 6], 
      state: 5
    }, 
    {
      pos: [5, 2, 6], 
      state: 3
    }, 
    {
      pos: [1, 3, 6], 
      state: 3
    }, 
    {
      pos: [2, 3, 6], 
      state: 5
    }, 
    {
      pos: [4, 3, 6], 
      state: 5
    }, 
    {
      pos: [5, 3, 6], 
      state: 3
    }, 
    {
      pos: [0, 4, 6], 
      state: 0
    }, 
    {
      pos: [1, 4, 6], 
      state: 3
    }, 
    {
      pos: [2, 4, 6], 
      state: 5
    }, 
    {
      pos: [3, 4, 6], 
      state: 5
    }, 
    {
      pos: [4, 4, 6], 
      state: 5
    }, 
    {
      pos: [5, 4, 6], 
      state: 3
    }, 
    {
      pos: [6, 4, 6], 
      state: 0
    }, 
    {
      pos: [1, 5, 6], 
      state: 0
    }, 
    {
      pos: [2, 5, 6], 
      state: 4
    }, 
    {
      pos: [3, 5, 6], 
      state: 4
    }, 
    {
      pos: [4, 5, 6], 
      state: 4
    }, 
    {
      pos: [5, 5, 6], 
      state: 0
    }, 
    {
      pos: [2, 6, 6], 
      state: 0
    }, 
    {
      pos: [3, 6, 6], 
      state: 5
    }, 
    {
      pos: [4, 6, 6], 
      state: 0
    }, 
    {
      pos: [3, 7, 6], 
      state: 0
    }, 
    {
      pos: [1, 0, 7], 
      state: 1
    }, 
    {
      pos: [5, 0, 7], 
      state: 1
    }, 
    {
      pos: [1, 1, 7], 
      state: 3
    }, 
    {
      pos: [5, 1, 7], 
      state: 3
    }, 
    {
      pos: [1, 2, 7], 
      state: 3
    }, 
    {
      pos: [5, 2, 7], 
      state: 3
    }, 
    {
      pos: [1, 3, 7], 
      state: 3
    }, 
    {
      pos: [5, 3, 7], 
      state: 3
    }, 
    {
      pos: [0, 4, 7], 
      state: 0
    }, 
    {
      pos: [1, 4, 7], 
      state: 3
    }, 
    {
      pos: [5, 4, 7], 
      state: 3
    }, 
    {
      pos: [6, 4, 7], 
      state: 0
    }, 
    {
      pos: [1, 5, 7], 
      state: 0
    }, 
    {
      pos: [2, 5, 7], 
      state: 4
    }, 
    {
      pos: [3, 5, 7], 
      state: 4
    }, 
    {
      pos: [4, 5, 7], 
      state: 4
    }, 
    {
      pos: [5, 5, 7], 
      state: 0
    }, 
    {
      pos: [2, 6, 7], 
      state: 0
    }, 
    {
      pos: [4, 6, 7], 
      state: 0
    }, 
    {
      pos: [3, 7, 7], 
      state: 0
    }, 
    {
      pos: [0, 4, 8], 
      state: 0
    }, 
    {
      pos: [6, 4, 8], 
      state: 0
    }, 
    {
      pos: [1, 5, 8], 
      state: 0
    }, 
    {
      pos: [5, 5, 8], 
      state: 0
    }, 
    {
      pos: [2, 6, 8], 
      state: 0
    }, 
    {
      pos: [4, 6, 8], 
      state: 0
    }, 
    {
      pos: [3, 7, 8], 
      state: 0
    }, 
    {
      nbt: {
        target_pool: "minecraft:empty", 
        final_state: "minecraft:structure_void", 
        id: "minecraft:jigsaw", 
        attachement_type: "minecraft:building_entrance"
      }, 
      pos: [3, 1, 0], 
      state: 7
    }, 
    {
      nbt: {
        target_pool: "minecraft:village/taiga/villagers", 
        final_state: "minecraft:spruce_planks", 
        id: "minecraft:jigsaw", 
        attachement_type: "minecraft:bottom"
      }, 
      pos: [2, 1, 3], 
      state: 8
    }, 
    {
      nbt: {
        Color: "black", 
        Text4: '{"text":""}', 
        Text3: '{"text":""}', 
        Text2: '{"text":""}', 
        Text1: '{"text":""}', 
        id: "minecraft:sign"
      }, 
      pos: [4, 2, 3], 
      state: 9
    }, 
    {
      nbt: {
        id: "minecraft:bed"
      }, 
      pos: [2, 2, 4], 
      state: 10
    }, 
    {
      nbt: {
        id: "minecraft:bed"
      }, 
      pos: [2, 2, 5], 
      state: 11
    }, 
    {
      nbt: {
        Color: "black", 
        Text4: '{"text":""}', 
        Text3: '{"text":""}', 
        Text2: '{"text":""}', 
        Text1: '{"text":""}', 
        id: "minecraft:sign"
      }, 
      pos: [4, 2, 5], 
      state: 12
    }, 
    {
      pos: [3, 0, 0], 
      state: 13
    }, 
    {
      pos: [0, 1, 0], 
      state: 14
    }, 
    {
      pos: [1, 1, 0], 
      state: 14
    }, 
    {
      pos: [2, 1, 0], 
      state: 14
    }, 
    {
      pos: [4, 1, 0], 
      state: 14
    }, 
    {
      pos: [5, 1, 0], 
      state: 14
    }, 
    {
      pos: [6, 1, 0], 
      state: 14
    }, 
    {
      pos: [0, 2, 0], 
      state: 14
    }, 
    {
      pos: [1, 2, 0], 
      state: 14
    }, 
    {
      pos: [2, 2, 0], 
      state: 14
    }, 
    {
      pos: [3, 2, 0], 
      state: 14
    }, 
    {
      pos: [4, 2, 0], 
      state: 14
    }, 
    {
      pos: [5, 2, 0], 
      state: 14
    }, 
    {
      pos: [6, 2, 0], 
      state: 14
    }, 
    {
      pos: [0, 3, 0], 
      state: 14
    }, 
    {
      pos: [1, 3, 0], 
      state: 14
    }, 
    {
      pos: [2, 3, 0], 
      state: 14
    }, 
    {
      pos: [3, 3, 0], 
      state: 14
    }, 
    {
      pos: [4, 3, 0], 
      state: 14
    }, 
    {
      pos: [5, 3, 0], 
      state: 14
    }, 
    {
      pos: [6, 3, 0], 
      state: 14
    }, 
    {
      pos: [1, 4, 0], 
      state: 14
    }, 
    {
      pos: [2, 4, 0], 
      state: 14
    }, 
    {
      pos: [3, 4, 0], 
      state: 14
    }, 
    {
      pos: [4, 4, 0], 
      state: 14
    }, 
    {
      pos: [5, 4, 0], 
      state: 14
    }, 
    {
      pos: [0, 5, 0], 
      state: 14
    }, 
    {
      pos: [2, 5, 0], 
      state: 14
    }, 
    {
      pos: [3, 5, 0], 
      state: 14
    }, 
    {
      pos: [4, 5, 0], 
      state: 14
    }, 
    {
      pos: [6, 5, 0], 
      state: 14
    }, 
    {
      pos: [0, 6, 0], 
      state: 14
    }, 
    {
      pos: [1, 6, 0], 
      state: 14
    }, 
    {
      pos: [3, 6, 0], 
      state: 14
    }, 
    {
      pos: [5, 6, 0], 
      state: 14
    }, 
    {
      pos: [6, 6, 0], 
      state: 14
    }, 
    {
      pos: [0, 7, 0], 
      state: 14
    }, 
    {
      pos: [1, 7, 0], 
      state: 14
    }, 
    {
      pos: [2, 7, 0], 
      state: 14
    }, 
    {
      pos: [4, 7, 0], 
      state: 14
    }, 
    {
      pos: [5, 7, 0], 
      state: 14
    }, 
    {
      pos: [6, 7, 0], 
      state: 14
    }, 
    {
      pos: [0, 1, 1], 
      state: 14
    }, 
    {
      pos: [2, 1, 1], 
      state: 15
    }, 
    {
      pos: [3, 1, 1], 
      state: 16
    }, 
    {
      pos: [4, 1, 1], 
      state: 17
    }, 
    {
      pos: [6, 1, 1], 
      state: 14
    }, 
    {
      pos: [0, 2, 1], 
      state: 14
    }, 
    {
      pos: [2, 2, 1], 
      state: 18
    }, 
    {
      pos: [3, 2, 1], 
      state: 14
    }, 
    {
      pos: [4, 2, 1], 
      state: 18
    }, 
    {
      pos: [6, 2, 1], 
      state: 14
    }, 
    {
      pos: [0, 3, 1], 
      state: 14
    }, 
    {
      pos: [2, 3, 1], 
      state: 14
    }, 
    {
      pos: [3, 3, 1], 
      state: 14
    }, 
    {
      pos: [4, 3, 1], 
      state: 14
    }, 
    {
      pos: [6, 3, 1], 
      state: 14
    }, 
    {
      pos: [2, 4, 1], 
      state: 14
    }, 
    {
      pos: [3, 4, 1], 
      state: 14
    }, 
    {
      pos: [4, 4, 1], 
      state: 14
    }, 
    {
      pos: [0, 5, 1], 
      state: 14
    }, 
    {
      pos: [6, 5, 1], 
      state: 14
    }, 
    {
      pos: [0, 6, 1], 
      state: 14
    }, 
    {
      pos: [1, 6, 1], 
      state: 14
    }, 
    {
      pos: [3, 6, 1], 
      state: 14
    }, 
    {
      pos: [5, 6, 1], 
      state: 14
    }, 
    {
      pos: [6, 6, 1], 
      state: 14
    }, 
    {
      pos: [0, 7, 1], 
      state: 14
    }, 
    {
      pos: [1, 7, 1], 
      state: 14
    }, 
    {
      pos: [2, 7, 1], 
      state: 14
    }, 
    {
      pos: [4, 7, 1], 
      state: 14
    }, 
    {
      pos: [5, 7, 1], 
      state: 14
    }, 
    {
      pos: [6, 7, 1], 
      state: 14
    }, 
    {
      pos: [0, 1, 2], 
      state: 14
    }, 
    {
      pos: [6, 1, 2], 
      state: 14
    }, 
    {
      pos: [0, 2, 2], 
      state: 14
    }, 
    {
      pos: [3, 2, 2], 
      state: 19
    }, 
    {
      pos: [6, 2, 2], 
      state: 14
    }, 
    {
      pos: [0, 3, 2], 
      state: 14
    }, 
    {
      pos: [3, 3, 2], 
      state: 20
    }, 
    {
      pos: [6, 3, 2], 
      state: 14
    }, 
    {
      pos: [0, 5, 2], 
      state: 14
    }, 
    {
      pos: [6, 5, 2], 
      state: 14
    }, 
    {
      pos: [0, 6, 2], 
      state: 14
    }, 
    {
      pos: [1, 6, 2], 
      state: 14
    }, 
    {
      pos: [5, 6, 2], 
      state: 14
    }, 
    {
      pos: [6, 6, 2], 
      state: 14
    }, 
    {
      pos: [0, 7, 2], 
      state: 14
    }, 
    {
      pos: [1, 7, 2], 
      state: 14
    }, 
    {
      pos: [2, 7, 2], 
      state: 14
    }, 
    {
      pos: [4, 7, 2], 
      state: 14
    }, 
    {
      pos: [5, 7, 2], 
      state: 14
    }, 
    {
      pos: [6, 7, 2], 
      state: 14
    }, 
    {
      pos: [6, 1, 3], 
      state: 14
    }, 
    {
      pos: [0, 2, 3], 
      state: 14
    }, 
    {
      pos: [2, 2, 3], 
      state: 14
    }, 
    {
      pos: [3, 2, 3], 
      state: 14
    }, 
    {
      pos: [6, 2, 3], 
      state: 14
    }, 
    {
      pos: [0, 3, 3], 
      state: 21
    }, 
    {
      pos: [2, 3, 3], 
      state: 14
    }, 
    {
      pos: [3, 3, 3], 
      state: 14
    }, 
    {
      pos: [4, 3, 3], 
      state: 14
    }, 
    {
      pos: [6, 3, 3], 
      state: 22
    }, 
    {
      pos: [2, 4, 3], 
      state: 14
    }, 
    {
      pos: [3, 4, 3], 
      state: 14
    }, 
    {
      pos: [4, 4, 3], 
      state: 14
    }, 
    {
      pos: [0, 5, 3], 
      state: 14
    }, 
    {
      pos: [2, 5, 3], 
      state: 14
    }, 
    {
      pos: [3, 5, 3], 
      state: 23
    }, 
    {
      pos: [4, 5, 3], 
      state: 14
    }, 
    {
      pos: [6, 5, 3], 
      state: 14
    }, 
    {
      pos: [0, 6, 3], 
      state: 14
    }, 
    {
      pos: [1, 6, 3], 
      state: 14
    }, 
    {
      pos: [3, 6, 3], 
      state: 14
    }, 
    {
      pos: [5, 6, 3], 
      state: 14
    }, 
    {
      pos: [6, 6, 3], 
      state: 14
    }, 
    {
      pos: [0, 7, 3], 
      state: 14
    }, 
    {
      pos: [1, 7, 3], 
      state: 14
    }, 
    {
      pos: [2, 7, 3], 
      state: 14
    }, 
    {
      pos: [4, 7, 3], 
      state: 14
    }, 
    {
      pos: [5, 7, 3], 
      state: 14
    }, 
    {
      pos: [6, 7, 3], 
      state: 14
    }, 
    {
      pos: [0, 1, 4], 
      state: 14
    }, 
    {
      pos: [6, 1, 4], 
      state: 14
    }, 
    {
      pos: [0, 2, 4], 
      state: 14
    }, 
    {
      pos: [3, 2, 4], 
      state: 14
    }, 
    {
      pos: [4, 2, 4], 
      state: 24
    }, 
    {
      pos: [6, 2, 4], 
      state: 14
    }, 
    {
      pos: [0, 3, 4], 
      state: 14
    }, 
    {
      pos: [1, 3, 4], 
      state: 25
    }, 
    {
      pos: [2, 3, 4], 
      state: 14
    }, 
    {
      pos: [3, 3, 4], 
      state: 14
    }, 
    {
      pos: [4, 3, 4], 
      state: 14
    }, 
    {
      pos: [5, 3, 4], 
      state: 25
    }, 
    {
      pos: [6, 3, 4], 
      state: 14
    }, 
    {
      pos: [2, 4, 4], 
      state: 14
    }, 
    {
      pos: [3, 4, 4], 
      state: 14
    }, 
    {
      pos: [4, 4, 4], 
      state: 14
    }, 
    {
      pos: [0, 5, 4], 
      state: 14
    }, 
    {
      pos: [2, 5, 4], 
      state: 14
    }, 
    {
      pos: [3, 5, 4], 
      state: 14
    }, 
    {
      pos: [4, 5, 4], 
      state: 14
    }, 
    {
      pos: [6, 5, 4], 
      state: 14
    }, 
    {
      pos: [0, 6, 4], 
      state: 14
    }, 
    {
      pos: [1, 6, 4], 
      state: 14
    }, 
    {
      pos: [3, 6, 4], 
      state: 14
    }, 
    {
      pos: [5, 6, 4], 
      state: 14
    }, 
    {
      pos: [6, 6, 4], 
      state: 14
    }, 
    {
      pos: [0, 7, 4], 
      state: 14
    }, 
    {
      pos: [1, 7, 4], 
      state: 14
    }, 
    {
      pos: [2, 7, 4], 
      state: 14
    }, 
    {
      pos: [4, 7, 4], 
      state: 14
    }, 
    {
      pos: [5, 7, 4], 
      state: 14
    }, 
    {
      pos: [6, 7, 4], 
      state: 14
    }, 
    {
      pos: [0, 1, 5], 
      state: 14
    }, 
    {
      pos: [6, 1, 5], 
      state: 14
    }, 
    {
      pos: [0, 2, 5], 
      state: 14
    }, 
    {
      pos: [3, 2, 5], 
      state: 14
    }, 
    {
      pos: [6, 2, 5], 
      state: 14
    }, 
    {
      pos: [0, 3, 5], 
      state: 21
    }, 
    {
      pos: [2, 3, 5], 
      state: 14
    }, 
    {
      pos: [3, 3, 5], 
      state: 14
    }, 
    {
      pos: [4, 3, 5], 
      state: 14
    }, 
    {
      pos: [6, 3, 5], 
      state: 22
    }, 
    {
      pos: [2, 4, 5], 
      state: 14
    }, 
    {
      pos: [3, 4, 5], 
      state: 14
    }, 
    {
      pos: [4, 4, 5], 
      state: 14
    }, 
    {
      pos: [0, 5, 5], 
      state: 14
    }, 
    {
      pos: [2, 5, 5], 
      state: 14
    }, 
    {
      pos: [3, 5, 5], 
      state: 14
    }, 
    {
      pos: [4, 5, 5], 
      state: 14
    }, 
    {
      pos: [6, 5, 5], 
      state: 14
    }, 
    {
      pos: [0, 6, 5], 
      state: 14
    }, 
    {
      pos: [1, 6, 5], 
      state: 14
    }, 
    {
      pos: [3, 6, 5], 
      state: 14
    }, 
    {
      pos: [5, 6, 5], 
      state: 14
    }, 
    {
      pos: [6, 6, 5], 
      state: 14
    }, 
    {
      pos: [0, 7, 5], 
      state: 14
    }, 
    {
      pos: [1, 7, 5], 
      state: 14
    }, 
    {
      pos: [2, 7, 5], 
      state: 14
    }, 
    {
      pos: [4, 7, 5], 
      state: 14
    }, 
    {
      pos: [5, 7, 5], 
      state: 14
    }, 
    {
      pos: [6, 7, 5], 
      state: 14
    }, 
    {
      pos: [0, 1, 6], 
      state: 14
    }, 
    {
      pos: [6, 1, 6], 
      state: 14
    }, 
    {
      pos: [0, 2, 6], 
      state: 14
    }, 
    {
      pos: [6, 2, 6], 
      state: 14
    }, 
    {
      pos: [0, 3, 6], 
      state: 14
    }, 
    {
      pos: [3, 3, 6], 
      state: 26
    }, 
    {
      pos: [6, 3, 6], 
      state: 14
    }, 
    {
      pos: [0, 5, 6], 
      state: 14
    }, 
    {
      pos: [6, 5, 6], 
      state: 14
    }, 
    {
      pos: [0, 6, 6], 
      state: 14
    }, 
    {
      pos: [1, 6, 6], 
      state: 14
    }, 
    {
      pos: [5, 6, 6], 
      state: 14
    }, 
    {
      pos: [6, 6, 6], 
      state: 14
    }, 
    {
      pos: [0, 7, 6], 
      state: 14
    }, 
    {
      pos: [1, 7, 6], 
      state: 14
    }, 
    {
      pos: [2, 7, 6], 
      state: 14
    }, 
    {
      pos: [4, 7, 6], 
      state: 14
    }, 
    {
      pos: [5, 7, 6], 
      state: 14
    }, 
    {
      pos: [6, 7, 6], 
      state: 14
    }, 
    {
      pos: [0, 1, 7], 
      state: 14
    }, 
    {
      pos: [2, 1, 7], 
      state: 14
    }, 
    {
      pos: [3, 1, 7], 
      state: 14
    }, 
    {
      pos: [4, 1, 7], 
      state: 14
    }, 
    {
      pos: [6, 1, 7], 
      state: 14
    }, 
    {
      pos: [0, 2, 7], 
      state: 14
    }, 
    {
      pos: [2, 2, 7], 
      state: 14
    }, 
    {
      pos: [3, 2, 7], 
      state: 14
    }, 
    {
      pos: [4, 2, 7], 
      state: 14
    }, 
    {
      pos: [6, 2, 7], 
      state: 14
    }, 
    {
      pos: [0, 3, 7], 
      state: 14
    }, 
    {
      pos: [2, 3, 7], 
      state: 27
    }, 
    {
      pos: [3, 3, 7], 
      state: 14
    }, 
    {
      pos: [4, 3, 7], 
      state: 27
    }, 
    {
      pos: [6, 3, 7], 
      state: 14
    }, 
    {
      pos: [2, 4, 7], 
      state: 14
    }, 
    {
      pos: [3, 4, 7], 
      state: 14
    }, 
    {
      pos: [4, 4, 7], 
      state: 14
    }, 
    {
      pos: [0, 5, 7], 
      state: 14
    }, 
    {
      pos: [6, 5, 7], 
      state: 14
    }, 
    {
      pos: [0, 6, 7], 
      state: 14
    }, 
    {
      pos: [1, 6, 7], 
      state: 14
    }, 
    {
      pos: [3, 6, 7], 
      state: 14
    }, 
    {
      pos: [5, 6, 7], 
      state: 14
    }, 
    {
      pos: [6, 6, 7], 
      state: 14
    }, 
    {
      pos: [0, 7, 7], 
      state: 14
    }, 
    {
      pos: [1, 7, 7], 
      state: 14
    }, 
    {
      pos: [2, 7, 7], 
      state: 14
    }, 
    {
      pos: [4, 7, 7], 
      state: 14
    }, 
    {
      pos: [5, 7, 7], 
      state: 14
    }, 
    {
      pos: [6, 7, 7], 
      state: 14
    }, 
    {
      pos: [0, 1, 8], 
      state: 14
    }, 
    {
      pos: [1, 1, 8], 
      state: 14
    }, 
    {
      pos: [2, 1, 8], 
      state: 14
    }, 
    {
      pos: [3, 1, 8], 
      state: 14
    }, 
    {
      pos: [4, 1, 8], 
      state: 14
    }, 
    {
      pos: [5, 1, 8], 
      state: 14
    }, 
    {
      pos: [6, 1, 8], 
      state: 14
    }, 
    {
      pos: [0, 2, 8], 
      state: 14
    }, 
    {
      pos: [1, 2, 8], 
      state: 14
    }, 
    {
      pos: [2, 2, 8], 
      state: 14
    }, 
    {
      pos: [3, 2, 8], 
      state: 14
    }, 
    {
      pos: [4, 2, 8], 
      state: 14
    }, 
    {
      pos: [5, 2, 8], 
      state: 14
    }, 
    {
      pos: [6, 2, 8], 
      state: 14
    }, 
    {
      pos: [0, 3, 8], 
      state: 14
    }, 
    {
      pos: [1, 3, 8], 
      state: 14
    }, 
    {
      pos: [2, 3, 8], 
      state: 14
    }, 
    {
      pos: [3, 3, 8], 
      state: 14
    }, 
    {
      pos: [4, 3, 8], 
      state: 14
    }, 
    {
      pos: [5, 3, 8], 
      state: 14
    }, 
    {
      pos: [6, 3, 8], 
      state: 14
    }, 
    {
      pos: [1, 4, 8], 
      state: 14
    }, 
    {
      pos: [2, 4, 8], 
      state: 14
    }, 
    {
      pos: [3, 4, 8], 
      state: 14
    }, 
    {
      pos: [4, 4, 8], 
      state: 14
    }, 
    {
      pos: [5, 4, 8], 
      state: 14
    }, 
    {
      pos: [0, 5, 8], 
      state: 14
    }, 
    {
      pos: [2, 5, 8], 
      state: 14
    }, 
    {
      pos: [3, 5, 8], 
      state: 14
    }, 
    {
      pos: [4, 5, 8], 
      state: 14
    }, 
    {
      pos: [6, 5, 8], 
      state: 14
    }, 
    {
      pos: [0, 6, 8], 
      state: 14
    }, 
    {
      pos: [1, 6, 8], 
      state: 14
    }, 
    {
      pos: [3, 6, 8], 
      state: 14
    }, 
    {
      pos: [5, 6, 8], 
      state: 14
    }, 
    {
      pos: [6, 6, 8], 
      state: 14
    }, 
    {
      pos: [0, 7, 8], 
      state: 14
    }, 
    {
      pos: [1, 7, 8], 
      state: 14
    }, 
    {
      pos: [2, 7, 8], 
      state: 14
    }, 
    {
      pos: [4, 7, 8], 
      state: 14
    }, 
    {
      pos: [5, 7, 8], 
      state: 14
    }, 
    {
      pos: [6, 7, 8], 
      state: 14
    }
  ], 
  palette: [
    {
      Properties: {
        axis: "z"
      }, 
      Name: "minecraft:spruce_log"
    }, 
    {
      Name: "minecraft:dirt"
    }, 
    {
      Properties: {
        snowy: "false"
      }, 
      Name: "minecraft:grass_block"
    }, 
    {
      Properties: {
        axis: "y"
      }, 
      Name: "minecraft:spruce_log"
    }, 
    {
      Properties: {
        axis: "x"
      }, 
      Name: "minecraft:spruce_log"
    }, 
    {
      Name: "minecraft:cobblestone"
    }, 
    {
      Name: "minecraft:spruce_planks"
    }, 
    {
      Properties: {
        facing: "north"
      }, 
      Name: "minecraft:jigsaw"
    }, 
    {
      Properties: {
        facing: "up"
      }, 
      Name: "minecraft:jigsaw"
    }, 
    {
      Properties: {
        waterlogged: "false", 
        facing: "north"
      }, 
      Name: "minecraft:spruce_wall_sign"
    }, 
    {
      Properties: {
        part: "foot", 
        facing: "south", 
        occupied: "false"
      }, 
      Name: "minecraft:purple_bed"
    }, 
    {
      Properties: {
        part: "head", 
        facing: "south", 
        occupied: "false"
      }, 
      Name: "minecraft:purple_bed"
    }, 
    {
      Properties: {
        waterlogged: "false", 
        facing: "south"
      }, 
      Name: "minecraft:spruce_wall_sign"
    }, 
    {
      Name: "minecraft:grass_path"
    }, 
    {
      Name: "minecraft:air"
    }, 
    {
      Properties: {
        east: "false", 
        waterlogged: "false", 
        south: "true", 
        north: "false", 
        west: "true", 
        up: "true"
      }, 
      Name: "minecraft:cobblestone_wall"
    }, 
    {
      Properties: {
        half: "bottom", 
        waterlogged: "false", 
        shape: "straight", 
        facing: "south"
      }, 
      Name: "minecraft:cobblestone_stairs"
    }, 
    {
      Properties: {
        east: "true", 
        waterlogged: "false", 
        south: "true", 
        north: "false", 
        west: "false", 
        up: "true"
      }, 
      Name: "minecraft:cobblestone_wall"
    }, 
    {
      Name: "minecraft:torch"
    }, 
    {
      Properties: {
        hinge: "right", 
        half: "lower", 
        powered: "false", 
        facing: "south", 
        open: "false"
      }, 
      Name: "minecraft:spruce_door"
    }, 
    {
      Properties: {
        hinge: "right", 
        half: "upper", 
        powered: "false", 
        facing: "south", 
        open: "false"
      }, 
      Name: "minecraft:spruce_door"
    }, 
    {
      Properties: {
        half: "top", 
        waterlogged: "false", 
        powered: "false", 
        facing: "west", 
        open: "true"
      }, 
      Name: "minecraft:spruce_trapdoor"
    }, 
    {
      Properties: {
        half: "top", 
        waterlogged: "false", 
        powered: "false", 
        facing: "east", 
        open: "true"
      }, 
      Name: "minecraft:spruce_trapdoor"
    }, 
    {
      Properties: {
        facing: "south"
      }, 
      Name: "minecraft:wall_torch"
    }, 
    {
      Properties: {
        half: "bottom", 
        waterlogged: "false", 
        shape: "straight", 
        facing: "east"
      }, 
      Name: "minecraft:spruce_stairs"
    }, 
    {
      Properties: {
        east: "false", 
        waterlogged: "false", 
        south: "true", 
        north: "true", 
        west: "false"
      }, 
      Name: "minecraft:glass_pane"
    }, 
    {
      Properties: {
        east: "true", 
        waterlogged: "false", 
        south: "false", 
        north: "false", 
        west: "true"
      }, 
      Name: "minecraft:glass_pane"
    }, 
    {
      Properties: {
        half: "top", 
        waterlogged: "false", 
        powered: "false", 
        facing: "south", 
        open: "true"
      }, 
      Name: "minecraft:spruce_trapdoor"
    }
  ]
}
