{
  size: [6, 5, 7], 
  entities: [], 
  blocks: [
    {
      pos: [0, 0, 0], 
      state: 0
    }, 
    {
      pos: [2, 0, 0], 
      state: 0
    }, 
    {
      pos: [0, 0, 1], 
      state: 0
    }, 
    {
      pos: [1, 0, 1], 
      state: 0
    }, 
    {
      pos: [4, 0, 1], 
      state: 0
    }, 
    {
      pos: [5, 0, 1], 
      state: 0
    }, 
    {
      pos: [0, 0, 2], 
      state: 0
    }, 
    {
      pos: [4, 0, 2], 
      state: 0
    }, 
    {
      pos: [0, 0, 3], 
      state: 0
    }, 
    {
      pos: [2, 0, 3], 
      state: 1
    }, 
    {
      pos: [4, 0, 3], 
      state: 0
    }, 
    {
      pos: [0, 0, 4], 
      state: 0
    }, 
    {
      pos: [1, 0, 4], 
      state: 0
    }, 
    {
      pos: [3, 0, 4], 
      state: 0
    }, 
    {
      pos: [4, 0, 4], 
      state: 0
    }, 
    {
      pos: [0, 0, 5], 
      state: 0
    }, 
    {
      pos: [1, 0, 5], 
      state: 0
    }, 
    {
      pos: [2, 0, 5], 
      state: 0
    }, 
    {
      pos: [3, 0, 5], 
      state: 0
    }, 
    {
      pos: [4, 0, 5], 
      state: 0
    }, 
    {
      pos: [0, 0, 6], 
      state: 2
    }, 
    {
      pos: [1, 0, 6], 
      state: 2
    }, 
    {
      pos: [2, 0, 6], 
      state: 2
    }, 
    {
      pos: [3, 0, 6], 
      state: 2
    }, 
    {
      pos: [4, 0, 6], 
      state: 2
    }, 
    {
      nbt: {
        final_state: "minecraft:grass_block", 
        name: "minecraft:bottom", 
        pool: "minecraft:village/taiga/decor", 
        id: "minecraft:jigsaw", 
        target: "minecraft:bottom"
      }, 
      pos: [5, 0, 2], 
      state: 3
    }, 
    {
      pos: [1, 0, 0], 
      state: 4
    }, 
    {
      pos: [3, 0, 0], 
      state: 4
    }, 
    {
      pos: [4, 0, 0], 
      state: 4
    }, 
    {
      pos: [2, 0, 1], 
      state: 4
    }, 
    {
      pos: [3, 0, 1], 
      state: 4
    }, 
    {
      pos: [1, 0, 2], 
      state: 4
    }, 
    {
      pos: [2, 0, 2], 
      state: 4
    }, 
    {
      pos: [3, 0, 2], 
      state: 4
    }, 
    {
      pos: [1, 0, 3], 
      state: 4
    }, 
    {
      pos: [3, 0, 3], 
      state: 4
    }, 
    {
      pos: [2, 0, 4], 
      state: 4
    }, 
    {
      pos: [0, 1, 6], 
      state: 5
    }, 
    {
      pos: [1, 1, 6], 
      state: 5
    }, 
    {
      pos: [2, 1, 6], 
      state: 5
    }, 
    {
      pos: [3, 1, 6], 
      state: 5
    }, 
    {
      pos: [4, 1, 6], 
      state: 5
    }, 
    {
      nbt: {
        final_state: "minecraft:structure_void", 
        name: "minecraft:building_entrance", 
        pool: "minecraft:empty", 
        id: "minecraft:jigsaw", 
        target: "minecraft:building_entrance"
      }, 
      pos: [2, 1, 0], 
      state: 6
    }, 
    {
      pos: [0, 1, 0], 
      state: 7
    }, 
    {
      pos: [1, 1, 0], 
      state: 8
    }, 
    {
      pos: [3, 1, 0], 
      state: 8
    }, 
    {
      pos: [4, 1, 0], 
      state: 8
    }, 
    {
      pos: [5, 1, 0], 
      state: 8
    }, 
    {
      pos: [0, 1, 1], 
      state: 9
    }, 
    {
      pos: [1, 1, 1], 
      state: 8
    }, 
    {
      pos: [2, 1, 1], 
      state: 8
    }, 
    {
      pos: [3, 1, 1], 
      state: 8
    }, 
    {
      pos: [4, 1, 1], 
      state: 9
    }, 
    {
      pos: [5, 1, 1], 
      state: 10
    }, 
    {
      pos: [0, 1, 2], 
      state: 11
    }, 
    {
      pos: [1, 1, 2], 
      state: 8
    }, 
    {
      pos: [2, 1, 2], 
      state: 8
    }, 
    {
      pos: [3, 1, 2], 
      state: 8
    }, 
    {
      pos: [4, 1, 2], 
      state: 11
    }, 
    {
      pos: [5, 1, 2], 
      state: 8
    }, 
    {
      pos: [0, 1, 3], 
      state: 12
    }, 
    {
      pos: [1, 1, 3], 
      state: 8
    }, 
    {
      pos: [2, 1, 3], 
      state: 13
    }, 
    {
      pos: [3, 1, 3], 
      state: 8
    }, 
    {
      pos: [4, 1, 3], 
      state: 12
    }, 
    {
      pos: [5, 1, 3], 
      state: 8
    }, 
    {
      pos: [0, 1, 4], 
      state: 8
    }, 
    {
      pos: [1, 1, 4], 
      state: 7
    }, 
    {
      pos: [2, 1, 4], 
      state: 8
    }, 
    {
      pos: [3, 1, 4], 
      state: 10
    }, 
    {
      pos: [4, 1, 4], 
      state: 7
    }, 
    {
      pos: [0, 1, 5], 
      state: 9
    }, 
    {
      pos: [1, 1, 5], 
      state: 7
    }, 
    {
      pos: [2, 1, 5], 
      state: 9
    }, 
    {
      pos: [3, 1, 5], 
      state: 8
    }, 
    {
      pos: [4, 1, 5], 
      state: 9
    }, 
    {
      pos: [5, 1, 5], 
      state: 8
    }, 
    {
      pos: [5, 1, 6], 
      state: 8
    }, 
    {
      pos: [0, 2, 5], 
      state: 5
    }, 
    {
      pos: [1, 2, 5], 
      state: 5
    }, 
    {
      pos: [2, 2, 5], 
      state: 5
    }, 
    {
      pos: [3, 2, 5], 
      state: 5
    }, 
    {
      pos: [4, 2, 5], 
      state: 5
    }, 
    {
      pos: [0, 2, 0], 
      state: 8
    }, 
    {
      pos: [1, 2, 0], 
      state: 8
    }, 
    {
      pos: [2, 2, 0], 
      state: 8
    }, 
    {
      pos: [3, 2, 0], 
      state: 8
    }, 
    {
      pos: [4, 2, 0], 
      state: 8
    }, 
    {
      pos: [5, 2, 0], 
      state: 8
    }, 
    {
      pos: [0, 2, 1], 
      state: 14
    }, 
    {
      pos: [1, 2, 1], 
      state: 8
    }, 
    {
      pos: [2, 2, 1], 
      state: 8
    }, 
    {
      pos: [3, 2, 1], 
      state: 8
    }, 
    {
      pos: [4, 2, 1], 
      state: 14
    }, 
    {
      pos: [5, 2, 1], 
      state: 15
    }, 
    {
      pos: [0, 2, 2], 
      state: 8
    }, 
    {
      pos: [1, 2, 2], 
      state: 8
    }, 
    {
      pos: [2, 2, 2], 
      state: 8
    }, 
    {
      pos: [3, 2, 2], 
      state: 8
    }, 
    {
      pos: [4, 2, 2], 
      state: 8
    }, 
    {
      pos: [5, 2, 2], 
      state: 8
    }, 
    {
      pos: [0, 2, 3], 
      state: 16
    }, 
    {
      pos: [1, 2, 3], 
      state: 8
    }, 
    {
      pos: [2, 2, 3], 
      state: 8
    }, 
    {
      pos: [3, 2, 3], 
      state: 8
    }, 
    {
      pos: [4, 2, 3], 
      state: 16
    }, 
    {
      pos: [5, 2, 3], 
      state: 8
    }, 
    {
      pos: [0, 2, 4], 
      state: 8
    }, 
    {
      pos: [1, 2, 4], 
      state: 8
    }, 
    {
      pos: [2, 2, 4], 
      state: 8
    }, 
    {
      pos: [3, 2, 4], 
      state: 15
    }, 
    {
      pos: [4, 2, 4], 
      state: 8
    }, 
    {
      pos: [5, 2, 4], 
      state: 8
    }, 
    {
      pos: [5, 2, 5], 
      state: 8
    }, 
    {
      pos: [0, 2, 6], 
      state: 8
    }, 
    {
      pos: [1, 2, 6], 
      state: 8
    }, 
    {
      pos: [2, 2, 6], 
      state: 8
    }, 
    {
      pos: [3, 2, 6], 
      state: 8
    }, 
    {
      pos: [4, 2, 6], 
      state: 8
    }, 
    {
      pos: [5, 2, 6], 
      state: 8
    }, 
    {
      pos: [0, 3, 4], 
      state: 5
    }, 
    {
      pos: [1, 3, 4], 
      state: 5
    }, 
    {
      pos: [2, 3, 4], 
      state: 5
    }, 
    {
      pos: [3, 3, 4], 
      state: 5
    }, 
    {
      pos: [4, 3, 4], 
      state: 5
    }, 
    {
      pos: [0, 3, 0], 
      state: 8
    }, 
    {
      pos: [1, 3, 0], 
      state: 8
    }, 
    {
      pos: [2, 3, 0], 
      state: 8
    }, 
    {
      pos: [3, 3, 0], 
      state: 8
    }, 
    {
      pos: [4, 3, 0], 
      state: 8
    }, 
    {
      pos: [5, 3, 0], 
      state: 8
    }, 
    {
      pos: [0, 3, 1], 
      state: 8
    }, 
    {
      pos: [1, 3, 1], 
      state: 8
    }, 
    {
      pos: [2, 3, 1], 
      state: 8
    }, 
    {
      pos: [3, 3, 1], 
      state: 8
    }, 
    {
      pos: [4, 3, 1], 
      state: 8
    }, 
    {
      pos: [5, 3, 1], 
      state: 8
    }, 
    {
      pos: [0, 3, 2], 
      state: 8
    }, 
    {
      pos: [1, 3, 2], 
      state: 8
    }, 
    {
      pos: [2, 3, 2], 
      state: 8
    }, 
    {
      pos: [3, 3, 2], 
      state: 8
    }, 
    {
      pos: [4, 3, 2], 
      state: 8
    }, 
    {
      pos: [5, 3, 2], 
      state: 8
    }, 
    {
      pos: [0, 3, 3], 
      state: 9
    }, 
    {
      pos: [1, 3, 3], 
      state: 8
    }, 
    {
      pos: [2, 3, 3], 
      state: 8
    }, 
    {
      pos: [3, 3, 3], 
      state: 8
    }, 
    {
      pos: [4, 3, 3], 
      state: 9
    }, 
    {
      pos: [5, 3, 3], 
      state: 8
    }, 
    {
      pos: [5, 3, 4], 
      state: 8
    }, 
    {
      pos: [0, 3, 5], 
      state: 8
    }, 
    {
      pos: [1, 3, 5], 
      state: 8
    }, 
    {
      pos: [2, 3, 5], 
      state: 8
    }, 
    {
      pos: [3, 3, 5], 
      state: 8
    }, 
    {
      pos: [4, 3, 5], 
      state: 8
    }, 
    {
      pos: [5, 3, 5], 
      state: 8
    }, 
    {
      pos: [0, 3, 6], 
      state: 8
    }, 
    {
      pos: [1, 3, 6], 
      state: 8
    }, 
    {
      pos: [2, 3, 6], 
      state: 8
    }, 
    {
      pos: [3, 3, 6], 
      state: 8
    }, 
    {
      pos: [4, 3, 6], 
      state: 8
    }, 
    {
      pos: [5, 3, 6], 
      state: 8
    }, 
    {
      pos: [0, 4, 3], 
      state: 5
    }, 
    {
      pos: [1, 4, 3], 
      state: 5
    }, 
    {
      pos: [2, 4, 3], 
      state: 5
    }, 
    {
      pos: [3, 4, 3], 
      state: 5
    }, 
    {
      pos: [4, 4, 3], 
      state: 5
    }, 
    {
      pos: [0, 4, 0], 
      state: 8
    }, 
    {
      pos: [1, 4, 0], 
      state: 8
    }, 
    {
      pos: [2, 4, 0], 
      state: 8
    }, 
    {
      pos: [3, 4, 0], 
      state: 8
    }, 
    {
      pos: [4, 4, 0], 
      state: 8
    }, 
    {
      pos: [5, 4, 0], 
      state: 8
    }, 
    {
      pos: [0, 4, 1], 
      state: 8
    }, 
    {
      pos: [1, 4, 1], 
      state: 8
    }, 
    {
      pos: [2, 4, 1], 
      state: 8
    }, 
    {
      pos: [3, 4, 1], 
      state: 8
    }, 
    {
      pos: [4, 4, 1], 
      state: 8
    }, 
    {
      pos: [5, 4, 1], 
      state: 8
    }, 
    {
      pos: [0, 4, 2], 
      state: 8
    }, 
    {
      pos: [1, 4, 2], 
      state: 8
    }, 
    {
      pos: [2, 4, 2], 
      state: 8
    }, 
    {
      pos: [3, 4, 2], 
      state: 8
    }, 
    {
      pos: [4, 4, 2], 
      state: 8
    }, 
    {
      pos: [5, 4, 2], 
      state: 8
    }, 
    {
      pos: [5, 4, 3], 
      state: 8
    }, 
    {
      pos: [0, 4, 4], 
      state: 8
    }, 
    {
      pos: [1, 4, 4], 
      state: 8
    }, 
    {
      pos: [2, 4, 4], 
      state: 8
    }, 
    {
      pos: [3, 4, 4], 
      state: 8
    }, 
    {
      pos: [4, 4, 4], 
      state: 8
    }, 
    {
      pos: [5, 4, 4], 
      state: 8
    }, 
    {
      pos: [0, 4, 5], 
      state: 8
    }, 
    {
      pos: [1, 4, 5], 
      state: 8
    }, 
    {
      pos: [2, 4, 5], 
      state: 8
    }, 
    {
      pos: [3, 4, 5], 
      state: 8
    }, 
    {
      pos: [4, 4, 5], 
      state: 8
    }, 
    {
      pos: [5, 4, 5], 
      state: 8
    }, 
    {
      pos: [0, 4, 6], 
      state: 8
    }, 
    {
      pos: [1, 4, 6], 
      state: 8
    }, 
    {
      pos: [2, 4, 6], 
      state: 8
    }, 
    {
      pos: [3, 4, 6], 
      state: 8
    }, 
    {
      pos: [4, 4, 6], 
      state: 8
    }, 
    {
      pos: [5, 4, 6], 
      state: 8
    }
  ], 
  palette: [
    {
      Properties: {
        snowy: "false"
      }, 
      Name: "minecraft:grass_block"
    }, 
    {
      Name: "minecraft:cobblestone"
    }, 
    {
      Name: "minecraft:dirt"
    }, 
    {
      Properties: {
        orientation: "up_north"
      }, 
      Name: "minecraft:jigsaw"
    }, 
    {
      Name: "minecraft:grass_path"
    }, 
    {
      Properties: {
        axis: "x"
      }, 
      Name: "minecraft:spruce_log"
    }, 
    {
      Properties: {
        orientation: "north_up"
      }, 
      Name: "minecraft:jigsaw"
    }, 
    {
      Name: "minecraft:fern"
    }, 
    {
      Name: "minecraft:air"
    }, 
    {
      Properties: {
        east: "none", 
        waterlogged: "false", 
        south: "low", 
        north: "none", 
        west: "none", 
        up: "true"
      }, 
      Name: "minecraft:cobblestone_wall"
    }, 
    {
      Properties: {
        half: "lower"
      }, 
      Name: "minecraft:large_fern"
    }, 
    {
      Properties: {
        east: "none", 
        waterlogged: "false", 
        south: "low", 
        north: "low", 
        west: "none", 
        up: "false"
      }, 
      Name: "minecraft:cobblestone_wall"
    }, 
    {
      Properties: {
        east: "none", 
        waterlogged: "false", 
        south: "none", 
        north: "low", 
        west: "none", 
        up: "true"
      }, 
      Name: "minecraft:cobblestone_wall"
    }, 
    {
      Properties: {
        face: "floor", 
        facing: "south"
      }, 
      Name: "minecraft:grindstone"
    }, 
    {
      Name: "minecraft:torch"
    }, 
    {
      Properties: {
        half: "upper"
      }, 
      Name: "minecraft:large_fern"
    }, 
    {
      Properties: {
        east: "none", 
        waterlogged: "false", 
        south: "none", 
        north: "none", 
        west: "none", 
        up: "true"
      }, 
      Name: "minecraft:cobblestone_wall"
    }
  ]
}
