{
  size: [9, 6, 9], 
  entities: [], 
  blocks: [
    {
      pos: [1, 2, 0], 
      state: 0
    }, 
    {
      pos: [2, 2, 0], 
      state: 0
    }, 
    {
      pos: [3, 2, 0], 
      state: 0
    }, 
    {
      pos: [4, 2, 0], 
      state: 0
    }, 
    {
      pos: [5, 2, 0], 
      state: 0
    }, 
    {
      pos: [6, 2, 0], 
      state: 0
    }, 
    {
      pos: [7, 2, 0], 
      state: 0
    }, 
    {
      pos: [8, 2, 0], 
      state: 0
    }, 
    {
      pos: [1, 0, 1], 
      state: 1
    }, 
    {
      pos: [2, 0, 1], 
      state: 2
    }, 
    {
      pos: [3, 0, 1], 
      state: 2
    }, 
    {
      pos: [4, 0, 1], 
      state: 2
    }, 
    {
      pos: [5, 0, 1], 
      state: 2
    }, 
    {
      pos: [6, 0, 1], 
      state: 2
    }, 
    {
      pos: [7, 0, 1], 
      state: 2
    }, 
    {
      pos: [2, 1, 1], 
      state: 2
    }, 
    {
      pos: [3, 1, 1], 
      state: 2
    }, 
    {
      pos: [4, 1, 1], 
      state: 2
    }, 
    {
      pos: [5, 1, 1], 
      state: 2
    }, 
    {
      pos: [6, 1, 1], 
      state: 2
    }, 
    {
      pos: [7, 1, 1], 
      state: 2
    }, 
    {
      pos: [2, 2, 1], 
      state: 2
    }, 
    {
      pos: [3, 2, 1], 
      state: 2
    }, 
    {
      pos: [4, 2, 1], 
      state: 2
    }, 
    {
      pos: [5, 2, 1], 
      state: 2
    }, 
    {
      pos: [6, 2, 1], 
      state: 2
    }, 
    {
      pos: [7, 2, 1], 
      state: 2
    }, 
    {
      pos: [1, 3, 1], 
      state: 0
    }, 
    {
      pos: [2, 3, 1], 
      state: 0
    }, 
    {
      pos: [3, 3, 1], 
      state: 0
    }, 
    {
      pos: [4, 3, 1], 
      state: 0
    }, 
    {
      pos: [5, 3, 1], 
      state: 0
    }, 
    {
      pos: [6, 3, 1], 
      state: 0
    }, 
    {
      pos: [7, 3, 1], 
      state: 0
    }, 
    {
      pos: [8, 3, 1], 
      state: 0
    }, 
    {
      pos: [1, 0, 2], 
      state: 1
    }, 
    {
      pos: [2, 0, 2], 
      state: 2
    }, 
    {
      pos: [3, 0, 2], 
      state: 2
    }, 
    {
      pos: [4, 0, 2], 
      state: 2
    }, 
    {
      pos: [5, 0, 2], 
      state: 2
    }, 
    {
      pos: [6, 0, 2], 
      state: 2
    }, 
    {
      pos: [7, 0, 2], 
      state: 2
    }, 
    {
      pos: [2, 1, 2], 
      state: 2
    }, 
    {
      pos: [7, 1, 2], 
      state: 2
    }, 
    {
      pos: [2, 2, 2], 
      state: 2
    }, 
    {
      pos: [7, 2, 2], 
      state: 2
    }, 
    {
      pos: [2, 3, 2], 
      state: 2
    }, 
    {
      pos: [7, 3, 2], 
      state: 2
    }, 
    {
      pos: [1, 4, 2], 
      state: 0
    }, 
    {
      pos: [2, 4, 2], 
      state: 0
    }, 
    {
      pos: [3, 4, 2], 
      state: 0
    }, 
    {
      pos: [4, 4, 2], 
      state: 0
    }, 
    {
      pos: [5, 4, 2], 
      state: 0
    }, 
    {
      pos: [6, 4, 2], 
      state: 0
    }, 
    {
      pos: [7, 4, 2], 
      state: 0
    }, 
    {
      pos: [8, 4, 2], 
      state: 0
    }, 
    {
      pos: [1, 0, 3], 
      state: 1
    }, 
    {
      pos: [2, 0, 3], 
      state: 2
    }, 
    {
      pos: [3, 0, 3], 
      state: 2
    }, 
    {
      pos: [4, 0, 3], 
      state: 2
    }, 
    {
      pos: [5, 0, 3], 
      state: 2
    }, 
    {
      pos: [6, 0, 3], 
      state: 2
    }, 
    {
      pos: [7, 0, 3], 
      state: 2
    }, 
    {
      pos: [2, 1, 3], 
      state: 2
    }, 
    {
      pos: [7, 1, 3], 
      state: 2
    }, 
    {
      pos: [2, 3, 3], 
      state: 2
    }, 
    {
      pos: [7, 3, 3], 
      state: 2
    }, 
    {
      pos: [2, 4, 3], 
      state: 2
    }, 
    {
      pos: [7, 4, 3], 
      state: 2
    }, 
    {
      pos: [1, 5, 3], 
      state: 0
    }, 
    {
      pos: [2, 5, 3], 
      state: 0
    }, 
    {
      pos: [3, 5, 3], 
      state: 0
    }, 
    {
      pos: [4, 5, 3], 
      state: 0
    }, 
    {
      pos: [5, 5, 3], 
      state: 0
    }, 
    {
      pos: [6, 5, 3], 
      state: 0
    }, 
    {
      pos: [7, 5, 3], 
      state: 0
    }, 
    {
      pos: [8, 5, 3], 
      state: 0
    }, 
    {
      pos: [1, 0, 4], 
      state: 1
    }, 
    {
      pos: [2, 0, 4], 
      state: 2
    }, 
    {
      pos: [3, 0, 4], 
      state: 2
    }, 
    {
      pos: [4, 0, 4], 
      state: 2
    }, 
    {
      pos: [5, 0, 4], 
      state: 2
    }, 
    {
      pos: [6, 0, 4], 
      state: 2
    }, 
    {
      pos: [7, 0, 4], 
      state: 2
    }, 
    {
      pos: [2, 1, 4], 
      state: 2
    }, 
    {
      pos: [7, 1, 4], 
      state: 2
    }, 
    {
      pos: [2, 2, 4], 
      state: 2
    }, 
    {
      pos: [7, 2, 4], 
      state: 2
    }, 
    {
      pos: [2, 3, 4], 
      state: 2
    }, 
    {
      pos: [7, 3, 4], 
      state: 2
    }, 
    {
      pos: [2, 4, 4], 
      state: 2
    }, 
    {
      pos: [4, 4, 4], 
      state: 2
    }, 
    {
      pos: [5, 4, 4], 
      state: 2
    }, 
    {
      pos: [7, 4, 4], 
      state: 2
    }, 
    {
      pos: [1, 5, 4], 
      state: 0
    }, 
    {
      pos: [2, 5, 4], 
      state: 0
    }, 
    {
      pos: [3, 5, 4], 
      state: 0
    }, 
    {
      pos: [4, 5, 4], 
      state: 0
    }, 
    {
      pos: [5, 5, 4], 
      state: 0
    }, 
    {
      pos: [6, 5, 4], 
      state: 0
    }, 
    {
      pos: [7, 5, 4], 
      state: 0
    }, 
    {
      pos: [8, 5, 4], 
      state: 0
    }, 
    {
      pos: [2, 0, 5], 
      state: 2
    }, 
    {
      pos: [3, 0, 5], 
      state: 2
    }, 
    {
      pos: [4, 0, 5], 
      state: 2
    }, 
    {
      pos: [5, 0, 5], 
      state: 2
    }, 
    {
      pos: [6, 0, 5], 
      state: 2
    }, 
    {
      pos: [7, 0, 5], 
      state: 2
    }, 
    {
      pos: [2, 1, 5], 
      state: 2
    }, 
    {
      pos: [7, 1, 5], 
      state: 2
    }, 
    {
      pos: [2, 2, 5], 
      state: 2
    }, 
    {
      pos: [2, 3, 5], 
      state: 2
    }, 
    {
      pos: [7, 3, 5], 
      state: 2
    }, 
    {
      pos: [2, 4, 5], 
      state: 2
    }, 
    {
      pos: [7, 4, 5], 
      state: 2
    }, 
    {
      pos: [1, 5, 5], 
      state: 0
    }, 
    {
      pos: [2, 5, 5], 
      state: 0
    }, 
    {
      pos: [3, 5, 5], 
      state: 0
    }, 
    {
      pos: [4, 5, 5], 
      state: 0
    }, 
    {
      pos: [5, 5, 5], 
      state: 0
    }, 
    {
      pos: [6, 5, 5], 
      state: 0
    }, 
    {
      pos: [7, 5, 5], 
      state: 0
    }, 
    {
      pos: [8, 5, 5], 
      state: 0
    }, 
    {
      pos: [2, 0, 6], 
      state: 2
    }, 
    {
      pos: [3, 0, 6], 
      state: 2
    }, 
    {
      pos: [4, 0, 6], 
      state: 2
    }, 
    {
      pos: [5, 0, 6], 
      state: 2
    }, 
    {
      pos: [6, 0, 6], 
      state: 2
    }, 
    {
      pos: [7, 0, 6], 
      state: 2
    }, 
    {
      pos: [7, 1, 6], 
      state: 2
    }, 
    {
      pos: [7, 2, 6], 
      state: 2
    }, 
    {
      pos: [2, 3, 6], 
      state: 2
    }, 
    {
      pos: [7, 3, 6], 
      state: 2
    }, 
    {
      pos: [1, 4, 6], 
      state: 0
    }, 
    {
      pos: [2, 4, 6], 
      state: 0
    }, 
    {
      pos: [3, 4, 6], 
      state: 0
    }, 
    {
      pos: [4, 4, 6], 
      state: 0
    }, 
    {
      pos: [5, 4, 6], 
      state: 0
    }, 
    {
      pos: [6, 4, 6], 
      state: 0
    }, 
    {
      pos: [7, 4, 6], 
      state: 0
    }, 
    {
      pos: [8, 4, 6], 
      state: 0
    }, 
    {
      pos: [1, 0, 7], 
      state: 2
    }, 
    {
      pos: [2, 0, 7], 
      state: 2
    }, 
    {
      pos: [3, 0, 7], 
      state: 2
    }, 
    {
      pos: [4, 0, 7], 
      state: 2
    }, 
    {
      pos: [5, 0, 7], 
      state: 2
    }, 
    {
      pos: [6, 0, 7], 
      state: 2
    }, 
    {
      pos: [7, 0, 7], 
      state: 2
    }, 
    {
      pos: [2, 1, 7], 
      state: 2
    }, 
    {
      pos: [3, 1, 7], 
      state: 2
    }, 
    {
      pos: [4, 1, 7], 
      state: 2
    }, 
    {
      pos: [5, 1, 7], 
      state: 2
    }, 
    {
      pos: [6, 1, 7], 
      state: 2
    }, 
    {
      pos: [7, 1, 7], 
      state: 2
    }, 
    {
      pos: [2, 2, 7], 
      state: 2
    }, 
    {
      pos: [3, 2, 7], 
      state: 2
    }, 
    {
      pos: [4, 2, 7], 
      state: 2
    }, 
    {
      pos: [5, 2, 7], 
      state: 2
    }, 
    {
      pos: [6, 2, 7], 
      state: 2
    }, 
    {
      pos: [7, 2, 7], 
      state: 2
    }, 
    {
      pos: [1, 3, 7], 
      state: 0
    }, 
    {
      pos: [2, 3, 7], 
      state: 0
    }, 
    {
      pos: [3, 3, 7], 
      state: 0
    }, 
    {
      pos: [4, 3, 7], 
      state: 0
    }, 
    {
      pos: [5, 3, 7], 
      state: 0
    }, 
    {
      pos: [6, 3, 7], 
      state: 0
    }, 
    {
      pos: [7, 3, 7], 
      state: 0
    }, 
    {
      pos: [8, 3, 7], 
      state: 0
    }, 
    {
      pos: [1, 2, 8], 
      state: 0
    }, 
    {
      pos: [2, 2, 8], 
      state: 0
    }, 
    {
      pos: [3, 2, 8], 
      state: 0
    }, 
    {
      pos: [4, 2, 8], 
      state: 0
    }, 
    {
      pos: [5, 2, 8], 
      state: 0
    }, 
    {
      pos: [6, 2, 8], 
      state: 0
    }, 
    {
      pos: [7, 2, 8], 
      state: 0
    }, 
    {
      pos: [8, 2, 8], 
      state: 0
    }, 
    {
      nbt: {
        LootTable: "minecraft:chests/village/village_tannery", 
        Items: [], 
        id: "minecraft:chest", 
        Lock: "", 
        LootTableSeed: 0L
      }, 
      pos: [6, 1, 2], 
      state: 3
    }, 
    {
      nbt: {
        target_pool: "minecraft:empty", 
        final_state: "minecraft:cobblestone", 
        id: "minecraft:jigsaw", 
        attachement_type: "minecraft:building_entrance"
      }, 
      pos: [1, 0, 5], 
      state: 4
    }, 
    {
      pos: [0, 0, 0], 
      state: 5
    }, 
    {
      pos: [1, 0, 0], 
      state: 6
    }, 
    {
      pos: [2, 0, 0], 
      state: 5
    }, 
    {
      pos: [3, 0, 0], 
      state: 5
    }, 
    {
      pos: [4, 0, 0], 
      state: 5
    }, 
    {
      pos: [5, 0, 0], 
      state: 5
    }, 
    {
      pos: [6, 0, 0], 
      state: 5
    }, 
    {
      pos: [7, 0, 0], 
      state: 5
    }, 
    {
      pos: [8, 0, 0], 
      state: 5
    }, 
    {
      pos: [0, 1, 0], 
      state: 5
    }, 
    {
      pos: [1, 1, 0], 
      state: 5
    }, 
    {
      pos: [2, 1, 0], 
      state: 5
    }, 
    {
      pos: [3, 1, 0], 
      state: 5
    }, 
    {
      pos: [4, 1, 0], 
      state: 5
    }, 
    {
      pos: [5, 1, 0], 
      state: 5
    }, 
    {
      pos: [6, 1, 0], 
      state: 5
    }, 
    {
      pos: [7, 1, 0], 
      state: 5
    }, 
    {
      pos: [8, 1, 0], 
      state: 5
    }, 
    {
      pos: [0, 2, 0], 
      state: 5
    }, 
    {
      pos: [0, 3, 0], 
      state: 5
    }, 
    {
      pos: [1, 3, 0], 
      state: 5
    }, 
    {
      pos: [2, 3, 0], 
      state: 5
    }, 
    {
      pos: [3, 3, 0], 
      state: 5
    }, 
    {
      pos: [4, 3, 0], 
      state: 5
    }, 
    {
      pos: [5, 3, 0], 
      state: 5
    }, 
    {
      pos: [6, 3, 0], 
      state: 5
    }, 
    {
      pos: [7, 3, 0], 
      state: 5
    }, 
    {
      pos: [8, 3, 0], 
      state: 5
    }, 
    {
      pos: [0, 4, 0], 
      state: 5
    }, 
    {
      pos: [1, 4, 0], 
      state: 5
    }, 
    {
      pos: [2, 4, 0], 
      state: 5
    }, 
    {
      pos: [3, 4, 0], 
      state: 5
    }, 
    {
      pos: [4, 4, 0], 
      state: 5
    }, 
    {
      pos: [5, 4, 0], 
      state: 5
    }, 
    {
      pos: [6, 4, 0], 
      state: 5
    }, 
    {
      pos: [7, 4, 0], 
      state: 5
    }, 
    {
      pos: [8, 4, 0], 
      state: 5
    }, 
    {
      pos: [0, 5, 0], 
      state: 5
    }, 
    {
      pos: [1, 5, 0], 
      state: 5
    }, 
    {
      pos: [2, 5, 0], 
      state: 5
    }, 
    {
      pos: [3, 5, 0], 
      state: 5
    }, 
    {
      pos: [4, 5, 0], 
      state: 5
    }, 
    {
      pos: [5, 5, 0], 
      state: 5
    }, 
    {
      pos: [6, 5, 0], 
      state: 5
    }, 
    {
      pos: [7, 5, 0], 
      state: 5
    }, 
    {
      pos: [8, 5, 0], 
      state: 5
    }, 
    {
      pos: [0, 0, 1], 
      state: 7
    }, 
    {
      pos: [8, 0, 1], 
      state: 5
    }, 
    {
      pos: [0, 1, 1], 
      state: 5
    }, 
    {
      pos: [1, 1, 1], 
      state: 8
    }, 
    {
      pos: [8, 1, 1], 
      state: 5
    }, 
    {
      pos: [0, 2, 1], 
      state: 5
    }, 
    {
      pos: [1, 2, 1], 
      state: 9
    }, 
    {
      pos: [8, 2, 1], 
      state: 5
    }, 
    {
      pos: [0, 3, 1], 
      state: 5
    }, 
    {
      pos: [0, 4, 1], 
      state: 5
    }, 
    {
      pos: [1, 4, 1], 
      state: 5
    }, 
    {
      pos: [2, 4, 1], 
      state: 5
    }, 
    {
      pos: [3, 4, 1], 
      state: 5
    }, 
    {
      pos: [4, 4, 1], 
      state: 5
    }, 
    {
      pos: [5, 4, 1], 
      state: 5
    }, 
    {
      pos: [6, 4, 1], 
      state: 5
    }, 
    {
      pos: [7, 4, 1], 
      state: 5
    }, 
    {
      pos: [8, 4, 1], 
      state: 5
    }, 
    {
      pos: [0, 5, 1], 
      state: 5
    }, 
    {
      pos: [1, 5, 1], 
      state: 5
    }, 
    {
      pos: [2, 5, 1], 
      state: 5
    }, 
    {
      pos: [3, 5, 1], 
      state: 5
    }, 
    {
      pos: [4, 5, 1], 
      state: 5
    }, 
    {
      pos: [5, 5, 1], 
      state: 5
    }, 
    {
      pos: [6, 5, 1], 
      state: 5
    }, 
    {
      pos: [7, 5, 1], 
      state: 5
    }, 
    {
      pos: [8, 5, 1], 
      state: 5
    }, 
    {
      pos: [0, 0, 2], 
      state: 7
    }, 
    {
      pos: [8, 0, 2], 
      state: 5
    }, 
    {
      pos: [0, 1, 2], 
      state: 5
    }, 
    {
      pos: [1, 1, 2], 
      state: 10
    }, 
    {
      pos: [3, 1, 2], 
      state: 5
    }, 
    {
      pos: [4, 1, 2], 
      state: 11
    }, 
    {
      pos: [5, 1, 2], 
      state: 11
    }, 
    {
      pos: [8, 1, 2], 
      state: 5
    }, 
    {
      pos: [0, 2, 2], 
      state: 5
    }, 
    {
      pos: [1, 2, 2], 
      state: 7
    }, 
    {
      pos: [3, 2, 2], 
      state: 5
    }, 
    {
      pos: [4, 2, 2], 
      state: 5
    }, 
    {
      pos: [5, 2, 2], 
      state: 5
    }, 
    {
      pos: [6, 2, 2], 
      state: 5
    }, 
    {
      pos: [8, 2, 2], 
      state: 12
    }, 
    {
      pos: [0, 3, 2], 
      state: 5
    }, 
    {
      pos: [1, 3, 2], 
      state: 5
    }, 
    {
      pos: [3, 3, 2], 
      state: 5
    }, 
    {
      pos: [4, 3, 2], 
      state: 5
    }, 
    {
      pos: [5, 3, 2], 
      state: 5
    }, 
    {
      pos: [6, 3, 2], 
      state: 5
    }, 
    {
      pos: [8, 3, 2], 
      state: 5
    }, 
    {
      pos: [0, 4, 2], 
      state: 5
    }, 
    {
      pos: [0, 5, 2], 
      state: 5
    }, 
    {
      pos: [1, 5, 2], 
      state: 5
    }, 
    {
      pos: [2, 5, 2], 
      state: 5
    }, 
    {
      pos: [3, 5, 2], 
      state: 5
    }, 
    {
      pos: [4, 5, 2], 
      state: 5
    }, 
    {
      pos: [5, 5, 2], 
      state: 5
    }, 
    {
      pos: [6, 5, 2], 
      state: 5
    }, 
    {
      pos: [7, 5, 2], 
      state: 5
    }, 
    {
      pos: [8, 5, 2], 
      state: 5
    }, 
    {
      pos: [0, 0, 3], 
      state: 7
    }, 
    {
      pos: [8, 0, 3], 
      state: 5
    }, 
    {
      pos: [0, 1, 3], 
      state: 5
    }, 
    {
      pos: [1, 1, 3], 
      state: 8
    }, 
    {
      pos: [3, 1, 3], 
      state: 13
    }, 
    {
      pos: [4, 1, 3], 
      state: 5
    }, 
    {
      pos: [5, 1, 3], 
      state: 5
    }, 
    {
      pos: [6, 1, 3], 
      state: 14
    }, 
    {
      pos: [8, 1, 3], 
      state: 5
    }, 
    {
      pos: [0, 2, 3], 
      state: 5
    }, 
    {
      pos: [1, 2, 3], 
      state: 9
    }, 
    {
      pos: [2, 2, 3], 
      state: 15
    }, 
    {
      pos: [3, 2, 3], 
      state: 5
    }, 
    {
      pos: [4, 2, 3], 
      state: 5
    }, 
    {
      pos: [5, 2, 3], 
      state: 5
    }, 
    {
      pos: [6, 2, 3], 
      state: 5
    }, 
    {
      pos: [7, 2, 3], 
      state: 15
    }, 
    {
      pos: [8, 2, 3], 
      state: 5
    }, 
    {
      pos: [0, 3, 3], 
      state: 5
    }, 
    {
      pos: [1, 3, 3], 
      state: 5
    }, 
    {
      pos: [3, 3, 3], 
      state: 5
    }, 
    {
      pos: [4, 3, 3], 
      state: 5
    }, 
    {
      pos: [5, 3, 3], 
      state: 5
    }, 
    {
      pos: [6, 3, 3], 
      state: 5
    }, 
    {
      pos: [8, 3, 3], 
      state: 5
    }, 
    {
      pos: [0, 4, 3], 
      state: 5
    }, 
    {
      pos: [1, 4, 3], 
      state: 5
    }, 
    {
      pos: [3, 4, 3], 
      state: 5
    }, 
    {
      pos: [4, 4, 3], 
      state: 5
    }, 
    {
      pos: [5, 4, 3], 
      state: 5
    }, 
    {
      pos: [6, 4, 3], 
      state: 5
    }, 
    {
      pos: [8, 4, 3], 
      state: 5
    }, 
    {
      pos: [0, 5, 3], 
      state: 5
    }, 
    {
      pos: [0, 0, 4], 
      state: 7
    }, 
    {
      pos: [8, 0, 4], 
      state: 5
    }, 
    {
      pos: [0, 1, 4], 
      state: 5
    }, 
    {
      pos: [1, 1, 4], 
      state: 16
    }, 
    {
      pos: [3, 1, 4], 
      state: 5
    }, 
    {
      pos: [4, 1, 4], 
      state: 17
    }, 
    {
      pos: [5, 1, 4], 
      state: 17
    }, 
    {
      pos: [6, 1, 4], 
      state: 5
    }, 
    {
      pos: [8, 1, 4], 
      state: 5
    }, 
    {
      pos: [0, 2, 4], 
      state: 5
    }, 
    {
      pos: [1, 2, 4], 
      state: 7
    }, 
    {
      pos: [3, 2, 4], 
      state: 5
    }, 
    {
      pos: [4, 2, 4], 
      state: 5
    }, 
    {
      pos: [5, 2, 4], 
      state: 5
    }, 
    {
      pos: [6, 2, 4], 
      state: 5
    }, 
    {
      pos: [8, 2, 4], 
      state: 12
    }, 
    {
      pos: [0, 3, 4], 
      state: 5
    }, 
    {
      pos: [1, 3, 4], 
      state: 5
    }, 
    {
      pos: [3, 3, 4], 
      state: 5
    }, 
    {
      pos: [4, 3, 4], 
      state: 5
    }, 
    {
      pos: [5, 3, 4], 
      state: 5
    }, 
    {
      pos: [6, 3, 4], 
      state: 5
    }, 
    {
      pos: [8, 3, 4], 
      state: 5
    }, 
    {
      pos: [0, 4, 4], 
      state: 5
    }, 
    {
      pos: [1, 4, 4], 
      state: 5
    }, 
    {
      pos: [3, 4, 4], 
      state: 18
    }, 
    {
      pos: [6, 4, 4], 
      state: 19
    }, 
    {
      pos: [8, 4, 4], 
      state: 5
    }, 
    {
      pos: [0, 5, 4], 
      state: 5
    }, 
    {
      pos: [0, 0, 5], 
      state: 5
    }, 
    {
      pos: [8, 0, 5], 
      state: 5
    }, 
    {
      pos: [0, 1, 5], 
      state: 5
    }, 
    {
      pos: [1, 1, 5], 
      state: 20
    }, 
    {
      pos: [3, 1, 5], 
      state: 5
    }, 
    {
      pos: [4, 1, 5], 
      state: 5
    }, 
    {
      pos: [5, 1, 5], 
      state: 5
    }, 
    {
      pos: [6, 1, 5], 
      state: 5
    }, 
    {
      pos: [8, 1, 5], 
      state: 5
    }, 
    {
      pos: [0, 2, 5], 
      state: 5
    }, 
    {
      pos: [1, 2, 5], 
      state: 5
    }, 
    {
      pos: [3, 2, 5], 
      state: 5
    }, 
    {
      pos: [4, 2, 5], 
      state: 5
    }, 
    {
      pos: [5, 2, 5], 
      state: 5
    }, 
    {
      pos: [6, 2, 5], 
      state: 5
    }, 
    {
      pos: [7, 2, 5], 
      state: 15
    }, 
    {
      pos: [8, 2, 5], 
      state: 5
    }, 
    {
      pos: [0, 3, 5], 
      state: 5
    }, 
    {
      pos: [1, 3, 5], 
      state: 5
    }, 
    {
      pos: [3, 3, 5], 
      state: 5
    }, 
    {
      pos: [4, 3, 5], 
      state: 5
    }, 
    {
      pos: [5, 3, 5], 
      state: 5
    }, 
    {
      pos: [6, 3, 5], 
      state: 5
    }, 
    {
      pos: [8, 3, 5], 
      state: 5
    }, 
    {
      pos: [0, 4, 5], 
      state: 5
    }, 
    {
      pos: [1, 4, 5], 
      state: 5
    }, 
    {
      pos: [3, 4, 5], 
      state: 5
    }, 
    {
      pos: [4, 4, 5], 
      state: 5
    }, 
    {
      pos: [5, 4, 5], 
      state: 5
    }, 
    {
      pos: [6, 4, 5], 
      state: 5
    }, 
    {
      pos: [8, 4, 5], 
      state: 5
    }, 
    {
      pos: [0, 5, 5], 
      state: 5
    }, 
    {
      pos: [0, 0, 6], 
      state: 5
    }, 
    {
      pos: [1, 0, 6], 
      state: 21
    }, 
    {
      pos: [8, 0, 6], 
      state: 5
    }, 
    {
      pos: [0, 1, 6], 
      state: 5
    }, 
    {
      pos: [1, 1, 6], 
      state: 5
    }, 
    {
      pos: [2, 1, 6], 
      state: 22
    }, 
    {
      pos: [3, 1, 6], 
      state: 5
    }, 
    {
      pos: [4, 1, 6], 
      state: 5
    }, 
    {
      pos: [5, 1, 6], 
      state: 23
    }, 
    {
      pos: [6, 1, 6], 
      state: 23
    }, 
    {
      pos: [8, 1, 6], 
      state: 5
    }, 
    {
      pos: [0, 2, 6], 
      state: 5
    }, 
    {
      pos: [1, 2, 6], 
      state: 5
    }, 
    {
      pos: [2, 2, 6], 
      state: 24
    }, 
    {
      pos: [3, 2, 6], 
      state: 5
    }, 
    {
      pos: [4, 2, 6], 
      state: 5
    }, 
    {
      pos: [5, 2, 6], 
      state: 5
    }, 
    {
      pos: [6, 2, 6], 
      state: 5
    }, 
    {
      pos: [8, 2, 6], 
      state: 12
    }, 
    {
      pos: [0, 3, 6], 
      state: 5
    }, 
    {
      pos: [1, 3, 6], 
      state: 5
    }, 
    {
      pos: [3, 3, 6], 
      state: 5
    }, 
    {
      pos: [4, 3, 6], 
      state: 5
    }, 
    {
      pos: [5, 3, 6], 
      state: 5
    }, 
    {
      pos: [6, 3, 6], 
      state: 5
    }, 
    {
      pos: [8, 3, 6], 
      state: 5
    }, 
    {
      pos: [0, 4, 6], 
      state: 5
    }, 
    {
      pos: [0, 5, 6], 
      state: 5
    }, 
    {
      pos: [1, 5, 6], 
      state: 5
    }, 
    {
      pos: [2, 5, 6], 
      state: 5
    }, 
    {
      pos: [3, 5, 6], 
      state: 5
    }, 
    {
      pos: [4, 5, 6], 
      state: 5
    }, 
    {
      pos: [5, 5, 6], 
      state: 5
    }, 
    {
      pos: [6, 5, 6], 
      state: 5
    }, 
    {
      pos: [7, 5, 6], 
      state: 5
    }, 
    {
      pos: [8, 5, 6], 
      state: 5
    }, 
    {
      pos: [0, 0, 7], 
      state: 5
    }, 
    {
      pos: [8, 0, 7], 
      state: 5
    }, 
    {
      pos: [0, 1, 7], 
      state: 5
    }, 
    {
      pos: [1, 1, 7], 
      state: 20
    }, 
    {
      pos: [8, 1, 7], 
      state: 5
    }, 
    {
      pos: [0, 2, 7], 
      state: 5
    }, 
    {
      pos: [1, 2, 7], 
      state: 5
    }, 
    {
      pos: [8, 2, 7], 
      state: 5
    }, 
    {
      pos: [0, 3, 7], 
      state: 5
    }, 
    {
      pos: [0, 4, 7], 
      state: 5
    }, 
    {
      pos: [1, 4, 7], 
      state: 5
    }, 
    {
      pos: [2, 4, 7], 
      state: 5
    }, 
    {
      pos: [3, 4, 7], 
      state: 5
    }, 
    {
      pos: [4, 4, 7], 
      state: 5
    }, 
    {
      pos: [5, 4, 7], 
      state: 5
    }, 
    {
      pos: [6, 4, 7], 
      state: 5
    }, 
    {
      pos: [7, 4, 7], 
      state: 5
    }, 
    {
      pos: [8, 4, 7], 
      state: 5
    }, 
    {
      pos: [0, 5, 7], 
      state: 5
    }, 
    {
      pos: [1, 5, 7], 
      state: 5
    }, 
    {
      pos: [2, 5, 7], 
      state: 5
    }, 
    {
      pos: [3, 5, 7], 
      state: 5
    }, 
    {
      pos: [4, 5, 7], 
      state: 5
    }, 
    {
      pos: [5, 5, 7], 
      state: 5
    }, 
    {
      pos: [6, 5, 7], 
      state: 5
    }, 
    {
      pos: [7, 5, 7], 
      state: 5
    }, 
    {
      pos: [8, 5, 7], 
      state: 5
    }, 
    {
      pos: [0, 0, 8], 
      state: 5
    }, 
    {
      pos: [1, 0, 8], 
      state: 5
    }, 
    {
      pos: [2, 0, 8], 
      state: 5
    }, 
    {
      pos: [3, 0, 8], 
      state: 5
    }, 
    {
      pos: [4, 0, 8], 
      state: 5
    }, 
    {
      pos: [5, 0, 8], 
      state: 5
    }, 
    {
      pos: [6, 0, 8], 
      state: 5
    }, 
    {
      pos: [7, 0, 8], 
      state: 5
    }, 
    {
      pos: [8, 0, 8], 
      state: 5
    }, 
    {
      pos: [0, 1, 8], 
      state: 5
    }, 
    {
      pos: [1, 1, 8], 
      state: 5
    }, 
    {
      pos: [2, 1, 8], 
      state: 5
    }, 
    {
      pos: [3, 1, 8], 
      state: 5
    }, 
    {
      pos: [4, 1, 8], 
      state: 5
    }, 
    {
      pos: [5, 1, 8], 
      state: 5
    }, 
    {
      pos: [6, 1, 8], 
      state: 5
    }, 
    {
      pos: [7, 1, 8], 
      state: 5
    }, 
    {
      pos: [8, 1, 8], 
      state: 5
    }, 
    {
      pos: [0, 2, 8], 
      state: 5
    }, 
    {
      pos: [0, 3, 8], 
      state: 5
    }, 
    {
      pos: [1, 3, 8], 
      state: 5
    }, 
    {
      pos: [2, 3, 8], 
      state: 5
    }, 
    {
      pos: [3, 3, 8], 
      state: 5
    }, 
    {
      pos: [4, 3, 8], 
      state: 5
    }, 
    {
      pos: [5, 3, 8], 
      state: 5
    }, 
    {
      pos: [6, 3, 8], 
      state: 5
    }, 
    {
      pos: [7, 3, 8], 
      state: 5
    }, 
    {
      pos: [8, 3, 8], 
      state: 5
    }, 
    {
      pos: [0, 4, 8], 
      state: 5
    }, 
    {
      pos: [1, 4, 8], 
      state: 5
    }, 
    {
      pos: [2, 4, 8], 
      state: 5
    }, 
    {
      pos: [3, 4, 8], 
      state: 5
    }, 
    {
      pos: [4, 4, 8], 
      state: 5
    }, 
    {
      pos: [5, 4, 8], 
      state: 5
    }, 
    {
      pos: [6, 4, 8], 
      state: 5
    }, 
    {
      pos: [7, 4, 8], 
      state: 5
    }, 
    {
      pos: [8, 4, 8], 
      state: 5
    }, 
    {
      pos: [0, 5, 8], 
      state: 5
    }, 
    {
      pos: [1, 5, 8], 
      state: 5
    }, 
    {
      pos: [2, 5, 8], 
      state: 5
    }, 
    {
      pos: [3, 5, 8], 
      state: 5
    }, 
    {
      pos: [4, 5, 8], 
      state: 5
    }, 
    {
      pos: [5, 5, 8], 
      state: 5
    }, 
    {
      pos: [6, 5, 8], 
      state: 5
    }, 
    {
      pos: [7, 5, 8], 
      state: 5
    }, 
    {
      pos: [8, 5, 8], 
      state: 5
    }
  ], 
  palette: [
    {
      Properties: {
        axis: "x"
      }, 
      Name: "minecraft:spruce_log"
    }, 
    {
      Properties: {
        snowy: "false"
      }, 
      Name: "minecraft:grass_block"
    }, 
    {
      Name: "minecraft:cobblestone"
    }, 
    {
      Properties: {
        waterlogged: "false", 
        facing: "south", 
        type: "single"
      }, 
      Name: "minecraft:chest"
    }, 
    {
      Properties: {
        facing: "west"
      }, 
      Name: "minecraft:jigsaw"
    }, 
    {
      Name: "minecraft:air"
    }, 
    {
      Properties: {
        half: "top", 
        waterlogged: "false", 
        powered: "false", 
        facing: "north", 
        open: "true"
      }, 
      Name: "minecraft:spruce_trapdoor"
    }, 
    {
      Properties: {
        half: "top", 
        waterlogged: "false", 
        powered: "false", 
        facing: "west", 
        open: "true"
      }, 
      Name: "minecraft:spruce_trapdoor"
    }, 
    {
      Properties: {
        half: "lower"
      }, 
      Name: "minecraft:large_fern"
    }, 
    {
      Properties: {
        half: "upper"
      }, 
      Name: "minecraft:large_fern"
    }, 
    {
      Name: "minecraft:poppy"
    }, 
    {
      Properties: {
        half: "bottom", 
        waterlogged: "false", 
        powered: "false", 
        facing: "north", 
        open: "true"
      }, 
      Name: "minecraft:spruce_trapdoor"
    }, 
    {
      Properties: {
        half: "top", 
        waterlogged: "false", 
        powered: "false", 
        facing: "east", 
        open: "true"
      }, 
      Name: "minecraft:spruce_trapdoor"
    }, 
    {
      Properties: {
        half: "bottom", 
        waterlogged: "false", 
        powered: "false", 
        facing: "west", 
        open: "true"
      }, 
      Name: "minecraft:spruce_trapdoor"
    }, 
    {
      Properties: {
        half: "bottom", 
        waterlogged: "false", 
        powered: "false", 
        facing: "east", 
        open: "true"
      }, 
      Name: "minecraft:spruce_trapdoor"
    }, 
    {
      Properties: {
        east: "false", 
        waterlogged: "false", 
        south: "true", 
        north: "true", 
        west: "false"
      }, 
      Name: "minecraft:glass_pane"
    }, 
    {
      Name: "minecraft:fern"
    }, 
    {
      Properties: {
        half: "bottom", 
        waterlogged: "false", 
        powered: "false", 
        facing: "south", 
        open: "true"
      }, 
      Name: "minecraft:spruce_trapdoor"
    }, 
    {
      Properties: {
        facing: "west"
      }, 
      Name: "minecraft:wall_torch"
    }, 
    {
      Properties: {
        facing: "east"
      }, 
      Name: "minecraft:wall_torch"
    }, 
    {
      Name: "minecraft:torch"
    }, 
    {
      Properties: {
        half: "bottom", 
        waterlogged: "false", 
        shape: "straight", 
        facing: "east"
      }, 
      Name: "minecraft:cobblestone_stairs"
    }, 
    {
      Properties: {
        hinge: "left", 
        half: "lower", 
        powered: "false", 
        facing: "east", 
        open: "false"
      }, 
      Name: "minecraft:spruce_door"
    }, 
    {
      Properties: {
        level: "3"
      }, 
      Name: "minecraft:cauldron"
    }, 
    {
      Properties: {
        hinge: "left", 
        half: "upper", 
        powered: "false", 
        facing: "east", 
        open: "false"
      }, 
      Name: "minecraft:spruce_door"
    }
  ]
}
