{
  size: [8, 11, 7], 
  entities: [], 
  blocks: [
    {
      pos: [0, 0, 0], 
      state: 0
    }, 
    {
      pos: [1, 0, 0], 
      state: 0
    }, 
    {
      pos: [5, 0, 0], 
      state: 0
    }, 
    {
      pos: [6, 0, 0], 
      state: 0
    }, 
    {
      pos: [7, 0, 0], 
      state: 0
    }, 
    {
      pos: [0, 0, 1], 
      state: 0
    }, 
    {
      pos: [1, 0, 1], 
      state: 0
    }, 
    {
      pos: [5, 0, 1], 
      state: 0
    }, 
    {
      pos: [6, 0, 1], 
      state: 0
    }, 
    {
      pos: [7, 0, 1], 
      state: 0
    }, 
    {
      pos: [0, 0, 2], 
      state: 0
    }, 
    {
      pos: [1, 0, 2], 
      state: 0
    }, 
    {
      pos: [5, 0, 2], 
      state: 0
    }, 
    {
      pos: [6, 0, 2], 
      state: 0
    }, 
    {
      pos: [7, 0, 2], 
      state: 0
    }, 
    {
      pos: [0, 0, 3], 
      state: 0
    }, 
    {
      pos: [1, 0, 3], 
      state: 0
    }, 
    {
      pos: [2, 0, 3], 
      state: 1
    }, 
    {
      pos: [4, 0, 3], 
      state: 1
    }, 
    {
      pos: [5, 0, 3], 
      state: 0
    }, 
    {
      pos: [6, 0, 3], 
      state: 0
    }, 
    {
      pos: [7, 0, 3], 
      state: 0
    }, 
    {
      pos: [0, 0, 4], 
      state: 0
    }, 
    {
      pos: [1, 0, 4], 
      state: 0
    }, 
    {
      pos: [2, 0, 4], 
      state: 0
    }, 
    {
      pos: [3, 0, 4], 
      state: 1
    }, 
    {
      pos: [4, 0, 4], 
      state: 0
    }, 
    {
      pos: [5, 0, 4], 
      state: 0
    }, 
    {
      pos: [6, 0, 4], 
      state: 0
    }, 
    {
      pos: [7, 0, 4], 
      state: 0
    }, 
    {
      pos: [0, 0, 5], 
      state: 0
    }, 
    {
      pos: [1, 0, 5], 
      state: 0
    }, 
    {
      pos: [2, 0, 5], 
      state: 2
    }, 
    {
      pos: [3, 0, 5], 
      state: 2
    }, 
    {
      pos: [4, 0, 5], 
      state: 2
    }, 
    {
      pos: [5, 0, 5], 
      state: 0
    }, 
    {
      pos: [6, 0, 5], 
      state: 0
    }, 
    {
      pos: [7, 0, 5], 
      state: 0
    }, 
    {
      pos: [0, 0, 6], 
      state: 0
    }, 
    {
      pos: [1, 0, 6], 
      state: 0
    }, 
    {
      pos: [2, 0, 6], 
      state: 2
    }, 
    {
      pos: [3, 0, 6], 
      state: 2
    }, 
    {
      pos: [4, 0, 6], 
      state: 0
    }, 
    {
      pos: [5, 0, 6], 
      state: 0
    }, 
    {
      pos: [6, 0, 6], 
      state: 0
    }, 
    {
      pos: [7, 0, 6], 
      state: 0
    }, 
    {
      nbt: {
        id: "minecraft:bed"
      }, 
      pos: [4, 0, 0], 
      state: 3
    }, 
    {
      nbt: {
        id: "minecraft:bed"
      }, 
      pos: [4, 0, 1], 
      state: 4
    }, 
    {
      nbt: {
        LootTable: "minecraft:chests/village/village_taiga_house", 
        Items: [], 
        id: "minecraft:chest", 
        LootTableSeed: 0L
      }, 
      pos: [2, 0, 2], 
      state: 5
    }, 
    {
      pos: [2, 0, 0], 
      state: 6
    }, 
    {
      pos: [3, 0, 0], 
      state: 7
    }, 
    {
      pos: [2, 0, 1], 
      state: 6
    }, 
    {
      pos: [3, 0, 1], 
      state: 7
    }, 
    {
      pos: [3, 0, 2], 
      state: 7
    }, 
    {
      pos: [4, 0, 2], 
      state: 7
    }, 
    {
      pos: [3, 0, 3], 
      state: 8
    }, 
    {
      pos: [0, 1, 0], 
      state: 2
    }, 
    {
      pos: [1, 1, 0], 
      state: 2
    }, 
    {
      pos: [5, 1, 0], 
      state: 0
    }, 
    {
      pos: [6, 1, 0], 
      state: 0
    }, 
    {
      pos: [7, 1, 0], 
      state: 0
    }, 
    {
      pos: [0, 1, 1], 
      state: 2
    }, 
    {
      pos: [1, 1, 1], 
      state: 2
    }, 
    {
      pos: [5, 1, 1], 
      state: 2
    }, 
    {
      pos: [6, 1, 1], 
      state: 2
    }, 
    {
      pos: [7, 1, 1], 
      state: 0
    }, 
    {
      pos: [0, 1, 2], 
      state: 2
    }, 
    {
      pos: [1, 1, 2], 
      state: 2
    }, 
    {
      pos: [5, 1, 2], 
      state: 2
    }, 
    {
      pos: [6, 1, 2], 
      state: 0
    }, 
    {
      pos: [7, 1, 2], 
      state: 0
    }, 
    {
      pos: [0, 1, 3], 
      state: 2
    }, 
    {
      pos: [1, 1, 3], 
      state: 2
    }, 
    {
      pos: [2, 1, 3], 
      state: 1
    }, 
    {
      pos: [4, 1, 3], 
      state: 1
    }, 
    {
      pos: [5, 1, 3], 
      state: 2
    }, 
    {
      pos: [6, 1, 3], 
      state: 0
    }, 
    {
      pos: [7, 1, 3], 
      state: 0
    }, 
    {
      pos: [0, 1, 4], 
      state: 2
    }, 
    {
      pos: [1, 1, 4], 
      state: 0
    }, 
    {
      pos: [2, 1, 4], 
      state: 1
    }, 
    {
      pos: [4, 1, 4], 
      state: 1
    }, 
    {
      pos: [5, 1, 4], 
      state: 0
    }, 
    {
      pos: [6, 1, 4], 
      state: 0
    }, 
    {
      pos: [7, 1, 4], 
      state: 2
    }, 
    {
      pos: [0, 1, 5], 
      state: 2
    }, 
    {
      pos: [1, 1, 5], 
      state: 0
    }, 
    {
      pos: [5, 1, 5], 
      state: 0
    }, 
    {
      pos: [6, 1, 5], 
      state: 0
    }, 
    {
      pos: [7, 1, 5], 
      state: 0
    }, 
    {
      pos: [0, 1, 6], 
      state: 2
    }, 
    {
      pos: [1, 1, 6], 
      state: 2
    }, 
    {
      pos: [5, 1, 6], 
      state: 0
    }, 
    {
      pos: [6, 1, 6], 
      state: 0
    }, 
    {
      pos: [7, 1, 6], 
      state: 2
    }, 
    {
      pos: [2, 1, 0], 
      state: 7
    }, 
    {
      pos: [3, 1, 0], 
      state: 9
    }, 
    {
      pos: [4, 1, 0], 
      state: 7
    }, 
    {
      pos: [2, 1, 1], 
      state: 7
    }, 
    {
      pos: [3, 1, 1], 
      state: 7
    }, 
    {
      pos: [4, 1, 1], 
      state: 7
    }, 
    {
      pos: [2, 1, 2], 
      state: 7
    }, 
    {
      pos: [3, 1, 2], 
      state: 7
    }, 
    {
      pos: [4, 1, 2], 
      state: 7
    }, 
    {
      pos: [3, 1, 3], 
      state: 7
    }, 
    {
      pos: [3, 1, 4], 
      state: 10
    }, 
    {
      pos: [2, 1, 5], 
      state: 7
    }, 
    {
      pos: [3, 1, 5], 
      state: 7
    }, 
    {
      pos: [4, 1, 5], 
      state: 7
    }, 
    {
      pos: [2, 1, 6], 
      state: 7
    }, 
    {
      pos: [3, 1, 6], 
      state: 7
    }, 
    {
      pos: [4, 1, 6], 
      state: 11
    }, 
    {
      pos: [2, 2, 0], 
      state: 2
    }, 
    {
      pos: [3, 2, 0], 
      state: 2
    }, 
    {
      pos: [4, 2, 0], 
      state: 2
    }, 
    {
      pos: [5, 2, 0], 
      state: 2
    }, 
    {
      pos: [6, 2, 0], 
      state: 0
    }, 
    {
      pos: [2, 2, 1], 
      state: 2
    }, 
    {
      pos: [3, 2, 1], 
      state: 2
    }, 
    {
      pos: [4, 2, 1], 
      state: 2
    }, 
    {
      pos: [2, 2, 2], 
      state: 0
    }, 
    {
      pos: [4, 2, 2], 
      state: 0
    }, 
    {
      pos: [2, 2, 3], 
      state: 1
    }, 
    {
      pos: [4, 2, 3], 
      state: 1
    }, 
    {
      pos: [7, 2, 3], 
      state: 2
    }, 
    {
      pos: [1, 2, 4], 
      state: 2
    }, 
    {
      pos: [2, 2, 4], 
      state: 1
    }, 
    {
      pos: [4, 2, 4], 
      state: 1
    }, 
    {
      pos: [5, 2, 4], 
      state: 2
    }, 
    {
      pos: [1, 2, 5], 
      state: 2
    }, 
    {
      pos: [5, 2, 5], 
      state: 2
    }, 
    {
      pos: [7, 2, 5], 
      state: 2
    }, 
    {
      pos: [7, 2, 0], 
      state: 12
    }, 
    {
      pos: [7, 2, 1], 
      state: 12
    }, 
    {
      pos: [3, 2, 2], 
      state: 7
    }, 
    {
      pos: [6, 2, 2], 
      state: 12
    }, 
    {
      pos: [7, 2, 2], 
      state: 12
    }, 
    {
      pos: [3, 2, 3], 
      state: 7
    }, 
    {
      pos: [6, 2, 3], 
      state: 12
    }, 
    {
      pos: [3, 2, 4], 
      state: 13
    }, 
    {
      pos: [6, 2, 4], 
      state: 12
    }, 
    {
      pos: [2, 2, 5], 
      state: 7
    }, 
    {
      pos: [3, 2, 5], 
      state: 7
    }, 
    {
      pos: [4, 2, 5], 
      state: 7
    }, 
    {
      pos: [6, 2, 5], 
      state: 12
    }, 
    {
      pos: [2, 2, 6], 
      state: 7
    }, 
    {
      pos: [3, 2, 6], 
      state: 7
    }, 
    {
      pos: [4, 2, 6], 
      state: 7
    }, 
    {
      pos: [5, 2, 6], 
      state: 11
    }, 
    {
      pos: [6, 2, 6], 
      state: 12
    }, 
    {
      pos: [2, 3, 2], 
      state: 1
    }, 
    {
      pos: [3, 3, 2], 
      state: 1
    }, 
    {
      pos: [4, 3, 2], 
      state: 1
    }, 
    {
      pos: [2, 3, 3], 
      state: 1
    }, 
    {
      pos: [4, 3, 3], 
      state: 1
    }, 
    {
      pos: [2, 3, 4], 
      state: 1
    }, 
    {
      pos: [3, 3, 4], 
      state: 1
    }, 
    {
      pos: [4, 3, 4], 
      state: 1
    }, 
    {
      nbt: {
        final_state: "minecraft:air", 
        name: "minecraft:building_entrance", 
        pool: "minecraft:empty", 
        id: "minecraft:jigsaw", 
        target: "minecraft:building_entrance"
      }, 
      pos: [5, 3, 6], 
      state: 14
    }, 
    {
      pos: [0, 3, 0], 
      state: 7
    }, 
    {
      pos: [1, 3, 0], 
      state: 7
    }, 
    {
      pos: [2, 3, 0], 
      state: 7
    }, 
    {
      pos: [3, 3, 0], 
      state: 15
    }, 
    {
      pos: [4, 3, 0], 
      state: 7
    }, 
    {
      pos: [5, 3, 0], 
      state: 16
    }, 
    {
      pos: [6, 3, 0], 
      state: 6
    }, 
    {
      pos: [7, 3, 0], 
      state: 7
    }, 
    {
      pos: [0, 3, 1], 
      state: 7
    }, 
    {
      pos: [1, 3, 1], 
      state: 7
    }, 
    {
      pos: [2, 3, 1], 
      state: 7
    }, 
    {
      pos: [3, 3, 1], 
      state: 7
    }, 
    {
      pos: [4, 3, 1], 
      state: 7
    }, 
    {
      pos: [5, 3, 1], 
      state: 7
    }, 
    {
      pos: [6, 3, 1], 
      state: 7
    }, 
    {
      pos: [7, 3, 1], 
      state: 7
    }, 
    {
      pos: [0, 3, 2], 
      state: 7
    }, 
    {
      pos: [1, 3, 2], 
      state: 7
    }, 
    {
      pos: [5, 3, 2], 
      state: 7
    }, 
    {
      pos: [6, 3, 2], 
      state: 7
    }, 
    {
      pos: [7, 3, 2], 
      state: 7
    }, 
    {
      pos: [0, 3, 3], 
      state: 7
    }, 
    {
      pos: [1, 3, 3], 
      state: 7
    }, 
    {
      pos: [3, 3, 3], 
      state: 17
    }, 
    {
      pos: [5, 3, 3], 
      state: 7
    }, 
    {
      pos: [6, 3, 3], 
      state: 7
    }, 
    {
      pos: [7, 3, 3], 
      state: 7
    }, 
    {
      pos: [0, 3, 4], 
      state: 7
    }, 
    {
      pos: [1, 3, 4], 
      state: 18
    }, 
    {
      pos: [5, 3, 4], 
      state: 18
    }, 
    {
      pos: [6, 3, 4], 
      state: 7
    }, 
    {
      pos: [7, 3, 4], 
      state: 7
    }, 
    {
      pos: [0, 3, 5], 
      state: 7
    }, 
    {
      pos: [1, 3, 5], 
      state: 18
    }, 
    {
      pos: [2, 3, 5], 
      state: 7
    }, 
    {
      pos: [3, 3, 5], 
      state: 9
    }, 
    {
      pos: [4, 3, 5], 
      state: 7
    }, 
    {
      pos: [5, 3, 5], 
      state: 19
    }, 
    {
      pos: [6, 3, 5], 
      state: 7
    }, 
    {
      pos: [7, 3, 5], 
      state: 19
    }, 
    {
      pos: [0, 3, 6], 
      state: 7
    }, 
    {
      pos: [1, 3, 6], 
      state: 7
    }, 
    {
      pos: [2, 3, 6], 
      state: 7
    }, 
    {
      pos: [3, 3, 6], 
      state: 7
    }, 
    {
      pos: [4, 3, 6], 
      state: 7
    }, 
    {
      pos: [6, 3, 6], 
      state: 7
    }, 
    {
      pos: [7, 3, 6], 
      state: 7
    }, 
    {
      pos: [2, 4, 2], 
      state: 1
    }, 
    {
      pos: [3, 4, 2], 
      state: 1
    }, 
    {
      pos: [4, 4, 2], 
      state: 1
    }, 
    {
      pos: [2, 4, 3], 
      state: 1
    }, 
    {
      pos: [4, 4, 3], 
      state: 1
    }, 
    {
      pos: [2, 4, 4], 
      state: 1
    }, 
    {
      pos: [3, 4, 4], 
      state: 1
    }, 
    {
      pos: [4, 4, 4], 
      state: 1
    }, 
    {
      pos: [0, 4, 0], 
      state: 7
    }, 
    {
      pos: [1, 4, 0], 
      state: 7
    }, 
    {
      pos: [2, 4, 0], 
      state: 7
    }, 
    {
      pos: [3, 4, 0], 
      state: 15
    }, 
    {
      pos: [4, 4, 0], 
      state: 16
    }, 
    {
      pos: [5, 4, 0], 
      state: 6
    }, 
    {
      pos: [6, 4, 0], 
      state: 7
    }, 
    {
      pos: [7, 4, 0], 
      state: 7
    }, 
    {
      pos: [0, 4, 1], 
      state: 7
    }, 
    {
      pos: [1, 4, 1], 
      state: 7
    }, 
    {
      pos: [2, 4, 1], 
      state: 7
    }, 
    {
      pos: [3, 4, 1], 
      state: 7
    }, 
    {
      pos: [4, 4, 1], 
      state: 7
    }, 
    {
      pos: [5, 4, 1], 
      state: 7
    }, 
    {
      pos: [6, 4, 1], 
      state: 7
    }, 
    {
      pos: [7, 4, 1], 
      state: 7
    }, 
    {
      pos: [0, 4, 2], 
      state: 7
    }, 
    {
      pos: [1, 4, 2], 
      state: 7
    }, 
    {
      pos: [5, 4, 2], 
      state: 7
    }, 
    {
      pos: [6, 4, 2], 
      state: 7
    }, 
    {
      pos: [7, 4, 2], 
      state: 7
    }, 
    {
      pos: [0, 4, 3], 
      state: 7
    }, 
    {
      pos: [1, 4, 3], 
      state: 20
    }, 
    {
      pos: [3, 4, 3], 
      state: 7
    }, 
    {
      pos: [5, 4, 3], 
      state: 21
    }, 
    {
      pos: [6, 4, 3], 
      state: 7
    }, 
    {
      pos: [7, 4, 3], 
      state: 7
    }, 
    {
      pos: [0, 4, 4], 
      state: 7
    }, 
    {
      pos: [1, 4, 4], 
      state: 22
    }, 
    {
      pos: [5, 4, 4], 
      state: 22
    }, 
    {
      pos: [6, 4, 4], 
      state: 7
    }, 
    {
      pos: [7, 4, 4], 
      state: 7
    }, 
    {
      pos: [0, 4, 5], 
      state: 7
    }, 
    {
      pos: [1, 4, 5], 
      state: 22
    }, 
    {
      pos: [2, 4, 5], 
      state: 7
    }, 
    {
      pos: [3, 4, 5], 
      state: 7
    }, 
    {
      pos: [4, 4, 5], 
      state: 7
    }, 
    {
      pos: [5, 4, 5], 
      state: 7
    }, 
    {
      pos: [6, 4, 5], 
      state: 7
    }, 
    {
      pos: [7, 4, 5], 
      state: 7
    }, 
    {
      pos: [0, 4, 6], 
      state: 7
    }, 
    {
      pos: [1, 4, 6], 
      state: 7
    }, 
    {
      pos: [2, 4, 6], 
      state: 7
    }, 
    {
      pos: [3, 4, 6], 
      state: 7
    }, 
    {
      pos: [4, 4, 6], 
      state: 7
    }, 
    {
      pos: [5, 4, 6], 
      state: 7
    }, 
    {
      pos: [6, 4, 6], 
      state: 7
    }, 
    {
      pos: [7, 4, 6], 
      state: 7
    }, 
    {
      pos: [3, 5, 0], 
      state: 23
    }, 
    {
      pos: [3, 5, 2], 
      state: 23
    }, 
    {
      pos: [4, 5, 2], 
      state: 23
    }, 
    {
      pos: [2, 5, 3], 
      state: 23
    }, 
    {
      pos: [4, 5, 3], 
      state: 23
    }, 
    {
      pos: [2, 5, 4], 
      state: 23
    }, 
    {
      pos: [3, 5, 4], 
      state: 23
    }, 
    {
      pos: [4, 5, 4], 
      state: 23
    }, 
    {
      nbt: {
        final_state: "minecraft:spruce_planks", 
        name: "minecraft:bottom", 
        pool: "minecraft:village/taiga/villagers", 
        id: "minecraft:jigsaw", 
        target: "minecraft:bottom"
      }, 
      pos: [2, 5, 2], 
      state: 24
    }, 
    {
      nbt: {
        final_state: "minecraft:spruce_planks", 
        name: "minecraft:bottom", 
        pool: "minecraft:village/taiga/villagers", 
        id: "minecraft:jigsaw", 
        target: "minecraft:bottom"
      }, 
      pos: [3, 5, 3], 
      state: 24
    }, 
    {
      pos: [0, 5, 0], 
      state: 7
    }, 
    {
      pos: [1, 5, 0], 
      state: 7
    }, 
    {
      pos: [2, 5, 0], 
      state: 7
    }, 
    {
      pos: [4, 5, 0], 
      state: 6
    }, 
    {
      pos: [5, 5, 0], 
      state: 7
    }, 
    {
      pos: [6, 5, 0], 
      state: 7
    }, 
    {
      pos: [7, 5, 0], 
      state: 7
    }, 
    {
      pos: [0, 5, 1], 
      state: 7
    }, 
    {
      pos: [1, 5, 1], 
      state: 25
    }, 
    {
      pos: [2, 5, 1], 
      state: 26
    }, 
    {
      pos: [3, 5, 1], 
      state: 26
    }, 
    {
      pos: [4, 5, 1], 
      state: 26
    }, 
    {
      pos: [5, 5, 1], 
      state: 27
    }, 
    {
      pos: [6, 5, 1], 
      state: 7
    }, 
    {
      pos: [7, 5, 1], 
      state: 7
    }, 
    {
      pos: [0, 5, 2], 
      state: 7
    }, 
    {
      pos: [1, 5, 2], 
      state: 28
    }, 
    {
      pos: [5, 5, 2], 
      state: 29
    }, 
    {
      pos: [6, 5, 2], 
      state: 7
    }, 
    {
      pos: [7, 5, 2], 
      state: 7
    }, 
    {
      pos: [0, 5, 3], 
      state: 7
    }, 
    {
      pos: [1, 5, 3], 
      state: 28
    }, 
    {
      pos: [5, 5, 3], 
      state: 29
    }, 
    {
      pos: [6, 5, 3], 
      state: 7
    }, 
    {
      pos: [7, 5, 3], 
      state: 7
    }, 
    {
      pos: [0, 5, 4], 
      state: 7
    }, 
    {
      pos: [1, 5, 4], 
      state: 28
    }, 
    {
      pos: [5, 5, 4], 
      state: 29
    }, 
    {
      pos: [6, 5, 4], 
      state: 7
    }, 
    {
      pos: [7, 5, 4], 
      state: 7
    }, 
    {
      pos: [0, 5, 5], 
      state: 7
    }, 
    {
      pos: [1, 5, 5], 
      state: 30
    }, 
    {
      pos: [2, 5, 5], 
      state: 31
    }, 
    {
      pos: [3, 5, 5], 
      state: 31
    }, 
    {
      pos: [4, 5, 5], 
      state: 31
    }, 
    {
      pos: [5, 5, 5], 
      state: 32
    }, 
    {
      pos: [6, 5, 5], 
      state: 7
    }, 
    {
      pos: [7, 5, 5], 
      state: 7
    }, 
    {
      pos: [0, 5, 6], 
      state: 7
    }, 
    {
      pos: [1, 5, 6], 
      state: 7
    }, 
    {
      pos: [2, 5, 6], 
      state: 7
    }, 
    {
      pos: [3, 5, 6], 
      state: 7
    }, 
    {
      pos: [4, 5, 6], 
      state: 7
    }, 
    {
      pos: [5, 5, 6], 
      state: 7
    }, 
    {
      pos: [6, 5, 6], 
      state: 7
    }, 
    {
      pos: [7, 5, 6], 
      state: 7
    }, 
    {
      pos: [1, 6, 1], 
      state: 33
    }, 
    {
      pos: [2, 6, 1], 
      state: 23
    }, 
    {
      pos: [4, 6, 1], 
      state: 23
    }, 
    {
      pos: [5, 6, 1], 
      state: 33
    }, 
    {
      pos: [1, 6, 2], 
      state: 23
    }, 
    {
      pos: [5, 6, 2], 
      state: 23
    }, 
    {
      pos: [1, 6, 3], 
      state: 23
    }, 
    {
      pos: [5, 6, 3], 
      state: 23
    }, 
    {
      pos: [1, 6, 4], 
      state: 23
    }, 
    {
      pos: [5, 6, 4], 
      state: 23
    }, 
    {
      pos: [1, 6, 5], 
      state: 33
    }, 
    {
      pos: [2, 6, 5], 
      state: 23
    }, 
    {
      pos: [3, 6, 5], 
      state: 23
    }, 
    {
      pos: [4, 6, 5], 
      state: 23
    }, 
    {
      pos: [5, 6, 5], 
      state: 33
    }, 
    {
      nbt: {
        id: "minecraft:bed"
      }, 
      pos: [2, 6, 3], 
      state: 34
    }, 
    {
      nbt: {
        id: "minecraft:bed"
      }, 
      pos: [2, 6, 4], 
      state: 35
    }, 
    {
      pos: [0, 6, 0], 
      state: 7
    }, 
    {
      pos: [1, 6, 0], 
      state: 7
    }, 
    {
      pos: [2, 6, 0], 
      state: 7
    }, 
    {
      pos: [3, 6, 0], 
      state: 7
    }, 
    {
      pos: [4, 6, 0], 
      state: 7
    }, 
    {
      pos: [5, 6, 0], 
      state: 7
    }, 
    {
      pos: [6, 6, 0], 
      state: 7
    }, 
    {
      pos: [7, 6, 0], 
      state: 7
    }, 
    {
      pos: [0, 6, 1], 
      state: 7
    }, 
    {
      pos: [3, 6, 1], 
      state: 36
    }, 
    {
      pos: [6, 6, 1], 
      state: 7
    }, 
    {
      pos: [7, 6, 1], 
      state: 7
    }, 
    {
      pos: [0, 6, 2], 
      state: 7
    }, 
    {
      pos: [2, 6, 2], 
      state: 7
    }, 
    {
      pos: [3, 6, 2], 
      state: 7
    }, 
    {
      pos: [4, 6, 2], 
      state: 37
    }, 
    {
      pos: [6, 6, 2], 
      state: 7
    }, 
    {
      pos: [7, 6, 2], 
      state: 7
    }, 
    {
      pos: [0, 6, 3], 
      state: 7
    }, 
    {
      pos: [3, 6, 3], 
      state: 7
    }, 
    {
      pos: [4, 6, 3], 
      state: 38
    }, 
    {
      pos: [6, 6, 3], 
      state: 7
    }, 
    {
      pos: [7, 6, 3], 
      state: 7
    }, 
    {
      pos: [0, 6, 4], 
      state: 7
    }, 
    {
      pos: [3, 6, 4], 
      state: 7
    }, 
    {
      pos: [4, 6, 4], 
      state: 39
    }, 
    {
      pos: [6, 6, 4], 
      state: 7
    }, 
    {
      pos: [7, 6, 4], 
      state: 7
    }, 
    {
      pos: [0, 6, 5], 
      state: 7
    }, 
    {
      pos: [6, 6, 5], 
      state: 7
    }, 
    {
      pos: [7, 6, 5], 
      state: 7
    }, 
    {
      pos: [0, 6, 6], 
      state: 7
    }, 
    {
      pos: [1, 6, 6], 
      state: 7
    }, 
    {
      pos: [2, 6, 6], 
      state: 7
    }, 
    {
      pos: [3, 6, 6], 
      state: 7
    }, 
    {
      pos: [4, 6, 6], 
      state: 7
    }, 
    {
      pos: [5, 6, 6], 
      state: 7
    }, 
    {
      pos: [6, 6, 6], 
      state: 7
    }, 
    {
      pos: [7, 6, 6], 
      state: 7
    }, 
    {
      pos: [0, 7, 0], 
      state: 40
    }, 
    {
      pos: [6, 7, 0], 
      state: 40
    }, 
    {
      pos: [0, 7, 1], 
      state: 40
    }, 
    {
      pos: [1, 7, 1], 
      state: 33
    }, 
    {
      pos: [2, 7, 1], 
      state: 23
    }, 
    {
      pos: [4, 7, 1], 
      state: 23
    }, 
    {
      pos: [5, 7, 1], 
      state: 33
    }, 
    {
      pos: [6, 7, 1], 
      state: 40
    }, 
    {
      pos: [0, 7, 2], 
      state: 40
    }, 
    {
      pos: [1, 7, 2], 
      state: 23
    }, 
    {
      pos: [5, 7, 2], 
      state: 23
    }, 
    {
      pos: [6, 7, 2], 
      state: 40
    }, 
    {
      pos: [0, 7, 3], 
      state: 40
    }, 
    {
      pos: [1, 7, 3], 
      state: 23
    }, 
    {
      pos: [5, 7, 3], 
      state: 23
    }, 
    {
      pos: [6, 7, 3], 
      state: 40
    }, 
    {
      pos: [0, 7, 4], 
      state: 40
    }, 
    {
      pos: [1, 7, 4], 
      state: 23
    }, 
    {
      pos: [5, 7, 4], 
      state: 23
    }, 
    {
      pos: [6, 7, 4], 
      state: 40
    }, 
    {
      pos: [0, 7, 5], 
      state: 40
    }, 
    {
      pos: [1, 7, 5], 
      state: 33
    }, 
    {
      pos: [2, 7, 5], 
      state: 23
    }, 
    {
      pos: [4, 7, 5], 
      state: 23
    }, 
    {
      pos: [5, 7, 5], 
      state: 33
    }, 
    {
      pos: [6, 7, 5], 
      state: 40
    }, 
    {
      pos: [0, 7, 6], 
      state: 40
    }, 
    {
      pos: [6, 7, 6], 
      state: 40
    }, 
    {
      pos: [1, 7, 0], 
      state: 7
    }, 
    {
      pos: [2, 7, 0], 
      state: 7
    }, 
    {
      pos: [3, 7, 0], 
      state: 7
    }, 
    {
      pos: [4, 7, 0], 
      state: 7
    }, 
    {
      pos: [5, 7, 0], 
      state: 7
    }, 
    {
      pos: [7, 7, 0], 
      state: 7
    }, 
    {
      pos: [3, 7, 1], 
      state: 41
    }, 
    {
      pos: [7, 7, 1], 
      state: 7
    }, 
    {
      pos: [2, 7, 2], 
      state: 7
    }, 
    {
      pos: [3, 7, 2], 
      state: 7
    }, 
    {
      pos: [4, 7, 2], 
      state: 7
    }, 
    {
      pos: [7, 7, 2], 
      state: 7
    }, 
    {
      pos: [2, 7, 3], 
      state: 7
    }, 
    {
      pos: [3, 7, 3], 
      state: 7
    }, 
    {
      pos: [4, 7, 3], 
      state: 42
    }, 
    {
      pos: [7, 7, 3], 
      state: 7
    }, 
    {
      pos: [2, 7, 4], 
      state: 7
    }, 
    {
      pos: [3, 7, 4], 
      state: 7
    }, 
    {
      pos: [4, 7, 4], 
      state: 7
    }, 
    {
      pos: [7, 7, 4], 
      state: 7
    }, 
    {
      pos: [3, 7, 5], 
      state: 43
    }, 
    {
      pos: [7, 7, 5], 
      state: 7
    }, 
    {
      pos: [1, 7, 6], 
      state: 7
    }, 
    {
      pos: [2, 7, 6], 
      state: 44
    }, 
    {
      pos: [3, 7, 6], 
      state: 7
    }, 
    {
      pos: [4, 7, 6], 
      state: 44
    }, 
    {
      pos: [5, 7, 6], 
      state: 7
    }, 
    {
      pos: [7, 7, 6], 
      state: 7
    }, 
    {
      pos: [1, 8, 0], 
      state: 40
    }, 
    {
      pos: [5, 8, 0], 
      state: 40
    }, 
    {
      pos: [1, 8, 1], 
      state: 40
    }, 
    {
      pos: [2, 8, 1], 
      state: 23
    }, 
    {
      pos: [3, 8, 1], 
      state: 23
    }, 
    {
      pos: [4, 8, 1], 
      state: 23
    }, 
    {
      pos: [5, 8, 1], 
      state: 40
    }, 
    {
      pos: [1, 8, 2], 
      state: 40
    }, 
    {
      pos: [5, 8, 2], 
      state: 40
    }, 
    {
      pos: [1, 8, 3], 
      state: 40
    }, 
    {
      pos: [5, 8, 3], 
      state: 40
    }, 
    {
      pos: [1, 8, 4], 
      state: 40
    }, 
    {
      pos: [5, 8, 4], 
      state: 40
    }, 
    {
      pos: [1, 8, 5], 
      state: 40
    }, 
    {
      pos: [2, 8, 5], 
      state: 23
    }, 
    {
      pos: [3, 8, 5], 
      state: 23
    }, 
    {
      pos: [4, 8, 5], 
      state: 23
    }, 
    {
      pos: [5, 8, 5], 
      state: 40
    }, 
    {
      pos: [1, 8, 6], 
      state: 40
    }, 
    {
      pos: [5, 8, 6], 
      state: 40
    }, 
    {
      pos: [0, 8, 0], 
      state: 7
    }, 
    {
      pos: [2, 8, 0], 
      state: 7
    }, 
    {
      pos: [3, 8, 0], 
      state: 17
    }, 
    {
      pos: [4, 8, 0], 
      state: 7
    }, 
    {
      pos: [6, 8, 0], 
      state: 7
    }, 
    {
      pos: [7, 8, 0], 
      state: 7
    }, 
    {
      pos: [0, 8, 1], 
      state: 7
    }, 
    {
      pos: [6, 8, 1], 
      state: 7
    }, 
    {
      pos: [7, 8, 1], 
      state: 7
    }, 
    {
      pos: [0, 8, 2], 
      state: 7
    }, 
    {
      pos: [2, 8, 2], 
      state: 7
    }, 
    {
      pos: [3, 8, 2], 
      state: 7
    }, 
    {
      pos: [4, 8, 2], 
      state: 7
    }, 
    {
      pos: [6, 8, 2], 
      state: 7
    }, 
    {
      pos: [7, 8, 2], 
      state: 7
    }, 
    {
      pos: [0, 8, 3], 
      state: 7
    }, 
    {
      pos: [2, 8, 3], 
      state: 7
    }, 
    {
      pos: [3, 8, 3], 
      state: 7
    }, 
    {
      pos: [4, 8, 3], 
      state: 7
    }, 
    {
      pos: [6, 8, 3], 
      state: 7
    }, 
    {
      pos: [7, 8, 3], 
      state: 7
    }, 
    {
      pos: [0, 8, 4], 
      state: 7
    }, 
    {
      pos: [2, 8, 4], 
      state: 7
    }, 
    {
      pos: [3, 8, 4], 
      state: 17
    }, 
    {
      pos: [4, 8, 4], 
      state: 7
    }, 
    {
      pos: [6, 8, 4], 
      state: 7
    }, 
    {
      pos: [7, 8, 4], 
      state: 7
    }, 
    {
      pos: [0, 8, 5], 
      state: 7
    }, 
    {
      pos: [6, 8, 5], 
      state: 7
    }, 
    {
      pos: [7, 8, 5], 
      state: 7
    }, 
    {
      pos: [0, 8, 6], 
      state: 7
    }, 
    {
      pos: [2, 8, 6], 
      state: 7
    }, 
    {
      pos: [3, 8, 6], 
      state: 7
    }, 
    {
      pos: [4, 8, 6], 
      state: 7
    }, 
    {
      pos: [6, 8, 6], 
      state: 7
    }, 
    {
      pos: [7, 8, 6], 
      state: 7
    }, 
    {
      pos: [2, 9, 0], 
      state: 40
    }, 
    {
      pos: [4, 9, 0], 
      state: 40
    }, 
    {
      pos: [2, 9, 1], 
      state: 40
    }, 
    {
      pos: [3, 9, 1], 
      state: 23
    }, 
    {
      pos: [4, 9, 1], 
      state: 40
    }, 
    {
      pos: [2, 9, 2], 
      state: 40
    }, 
    {
      pos: [4, 9, 2], 
      state: 40
    }, 
    {
      pos: [2, 9, 3], 
      state: 40
    }, 
    {
      pos: [4, 9, 3], 
      state: 40
    }, 
    {
      pos: [2, 9, 4], 
      state: 40
    }, 
    {
      pos: [4, 9, 4], 
      state: 40
    }, 
    {
      pos: [2, 9, 5], 
      state: 40
    }, 
    {
      pos: [3, 9, 5], 
      state: 23
    }, 
    {
      pos: [4, 9, 5], 
      state: 40
    }, 
    {
      pos: [2, 9, 6], 
      state: 40
    }, 
    {
      pos: [4, 9, 6], 
      state: 40
    }, 
    {
      pos: [0, 9, 0], 
      state: 7
    }, 
    {
      pos: [1, 9, 0], 
      state: 7
    }, 
    {
      pos: [3, 9, 0], 
      state: 7
    }, 
    {
      pos: [5, 9, 0], 
      state: 7
    }, 
    {
      pos: [6, 9, 0], 
      state: 7
    }, 
    {
      pos: [7, 9, 0], 
      state: 7
    }, 
    {
      pos: [0, 9, 1], 
      state: 7
    }, 
    {
      pos: [1, 9, 1], 
      state: 7
    }, 
    {
      pos: [5, 9, 1], 
      state: 7
    }, 
    {
      pos: [6, 9, 1], 
      state: 7
    }, 
    {
      pos: [7, 9, 1], 
      state: 7
    }, 
    {
      pos: [0, 9, 2], 
      state: 7
    }, 
    {
      pos: [1, 9, 2], 
      state: 7
    }, 
    {
      pos: [3, 9, 2], 
      state: 7
    }, 
    {
      pos: [5, 9, 2], 
      state: 7
    }, 
    {
      pos: [6, 9, 2], 
      state: 7
    }, 
    {
      pos: [7, 9, 2], 
      state: 7
    }, 
    {
      pos: [0, 9, 3], 
      state: 7
    }, 
    {
      pos: [1, 9, 3], 
      state: 7
    }, 
    {
      pos: [3, 9, 3], 
      state: 7
    }, 
    {
      pos: [5, 9, 3], 
      state: 7
    }, 
    {
      pos: [6, 9, 3], 
      state: 7
    }, 
    {
      pos: [7, 9, 3], 
      state: 7
    }, 
    {
      pos: [0, 9, 4], 
      state: 7
    }, 
    {
      pos: [1, 9, 4], 
      state: 7
    }, 
    {
      pos: [3, 9, 4], 
      state: 7
    }, 
    {
      pos: [5, 9, 4], 
      state: 7
    }, 
    {
      pos: [6, 9, 4], 
      state: 7
    }, 
    {
      pos: [7, 9, 4], 
      state: 7
    }, 
    {
      pos: [0, 9, 5], 
      state: 7
    }, 
    {
      pos: [1, 9, 5], 
      state: 7
    }, 
    {
      pos: [5, 9, 5], 
      state: 7
    }, 
    {
      pos: [6, 9, 5], 
      state: 7
    }, 
    {
      pos: [7, 9, 5], 
      state: 7
    }, 
    {
      pos: [0, 9, 6], 
      state: 7
    }, 
    {
      pos: [1, 9, 6], 
      state: 7
    }, 
    {
      pos: [3, 9, 6], 
      state: 7
    }, 
    {
      pos: [5, 9, 6], 
      state: 7
    }, 
    {
      pos: [6, 9, 6], 
      state: 7
    }, 
    {
      pos: [7, 9, 6], 
      state: 7
    }, 
    {
      pos: [3, 10, 0], 
      state: 40
    }, 
    {
      pos: [3, 10, 1], 
      state: 40
    }, 
    {
      pos: [3, 10, 2], 
      state: 40
    }, 
    {
      pos: [3, 10, 3], 
      state: 40
    }, 
    {
      pos: [3, 10, 4], 
      state: 40
    }, 
    {
      pos: [3, 10, 5], 
      state: 40
    }, 
    {
      pos: [3, 10, 6], 
      state: 40
    }, 
    {
      pos: [0, 10, 0], 
      state: 7
    }, 
    {
      pos: [1, 10, 0], 
      state: 7
    }, 
    {
      pos: [2, 10, 0], 
      state: 7
    }, 
    {
      pos: [4, 10, 0], 
      state: 7
    }, 
    {
      pos: [5, 10, 0], 
      state: 7
    }, 
    {
      pos: [6, 10, 0], 
      state: 7
    }, 
    {
      pos: [7, 10, 0], 
      state: 7
    }, 
    {
      pos: [0, 10, 1], 
      state: 7
    }, 
    {
      pos: [1, 10, 1], 
      state: 7
    }, 
    {
      pos: [2, 10, 1], 
      state: 7
    }, 
    {
      pos: [4, 10, 1], 
      state: 7
    }, 
    {
      pos: [5, 10, 1], 
      state: 7
    }, 
    {
      pos: [6, 10, 1], 
      state: 7
    }, 
    {
      pos: [7, 10, 1], 
      state: 7
    }, 
    {
      pos: [0, 10, 2], 
      state: 7
    }, 
    {
      pos: [1, 10, 2], 
      state: 7
    }, 
    {
      pos: [2, 10, 2], 
      state: 7
    }, 
    {
      pos: [4, 10, 2], 
      state: 7
    }, 
    {
      pos: [5, 10, 2], 
      state: 7
    }, 
    {
      pos: [6, 10, 2], 
      state: 7
    }, 
    {
      pos: [7, 10, 2], 
      state: 7
    }, 
    {
      pos: [0, 10, 3], 
      state: 7
    }, 
    {
      pos: [1, 10, 3], 
      state: 7
    }, 
    {
      pos: [2, 10, 3], 
      state: 7
    }, 
    {
      pos: [4, 10, 3], 
      state: 7
    }, 
    {
      pos: [5, 10, 3], 
      state: 7
    }, 
    {
      pos: [6, 10, 3], 
      state: 7
    }, 
    {
      pos: [7, 10, 3], 
      state: 7
    }, 
    {
      pos: [0, 10, 4], 
      state: 7
    }, 
    {
      pos: [1, 10, 4], 
      state: 7
    }, 
    {
      pos: [2, 10, 4], 
      state: 7
    }, 
    {
      pos: [4, 10, 4], 
      state: 7
    }, 
    {
      pos: [5, 10, 4], 
      state: 7
    }, 
    {
      pos: [6, 10, 4], 
      state: 7
    }, 
    {
      pos: [7, 10, 4], 
      state: 7
    }, 
    {
      pos: [0, 10, 5], 
      state: 7
    }, 
    {
      pos: [1, 10, 5], 
      state: 7
    }, 
    {
      pos: [2, 10, 5], 
      state: 7
    }, 
    {
      pos: [4, 10, 5], 
      state: 7
    }, 
    {
      pos: [5, 10, 5], 
      state: 7
    }, 
    {
      pos: [6, 10, 5], 
      state: 7
    }, 
    {
      pos: [7, 10, 5], 
      state: 7
    }, 
    {
      pos: [0, 10, 6], 
      state: 7
    }, 
    {
      pos: [1, 10, 6], 
      state: 7
    }, 
    {
      pos: [2, 10, 6], 
      state: 7
    }, 
    {
      pos: [4, 10, 6], 
      state: 7
    }, 
    {
      pos: [5, 10, 6], 
      state: 7
    }, 
    {
      pos: [6, 10, 6], 
      state: 7
    }, 
    {
      pos: [7, 10, 6], 
      state: 7
    }
  ], 
  palette: [
    {
      Name: "minecraft:dirt"
    }, 
    {
      Name: "minecraft:cobblestone"
    }, 
    {
      Properties: {
        snowy: "false"
      }, 
      Name: "minecraft:grass_block"
    }, 
    {
      Properties: {
        part: "head", 
        facing: "north", 
        occupied: "false"
      }, 
      Name: "minecraft:purple_bed"
    }, 
    {
      Properties: {
        part: "foot", 
        facing: "north", 
        occupied: "false"
      }, 
      Name: "minecraft:purple_bed"
    }, 
    {
      Properties: {
        waterlogged: "false", 
        facing: "east", 
        type: "single"
      }, 
      Name: "minecraft:chest"
    }, 
    {
      Properties: {
        half: "bottom", 
        waterlogged: "false", 
        shape: "straight", 
        facing: "west"
      }, 
      Name: "minecraft:spruce_stairs"
    }, 
    {
      Name: "minecraft:air"
    }, 
    {
      Properties: {
        half: "bottom", 
        waterlogged: "false", 
        shape: "straight", 
        facing: "south"
      }, 
      Name: "minecraft:cobblestone_stairs"
    }, 
    {
      Properties: {
        facing: "south"
      }, 
      Name: "minecraft:wall_torch"
    }, 
    {
      Properties: {
        hinge: "left", 
        half: "lower", 
        powered: "false", 
        facing: "north", 
        open: "false"
      }, 
      Name: "minecraft:spruce_door"
    }, 
    {
      Properties: {
        half: "bottom", 
        waterlogged: "false", 
        shape: "straight", 
        facing: "east"
      }, 
      Name: "minecraft:cobblestone_stairs"
    }, 
    {
      Name: "minecraft:grass_path"
    }, 
    {
      Properties: {
        hinge: "left", 
        half: "upper", 
        powered: "false", 
        facing: "north", 
        open: "false"
      }, 
      Name: "minecraft:spruce_door"
    }, 
    {
      Properties: {
        orientation: "south_up"
      }, 
      Name: "minecraft:jigsaw"
    }, 
    {
      Properties: {
        east: "false", 
        waterlogged: "false", 
        south: "false", 
        north: "false", 
        west: "false"
      }, 
      Name: "minecraft:spruce_fence"
    }, 
    {
      Properties: {
        waterlogged: "false", 
        type: "top"
      }, 
      Name: "minecraft:spruce_slab"
    }, 
    {
      Properties: {
        facing: "north"
      }, 
      Name: "minecraft:wall_torch"
    }, 
    {
      Properties: {
        half: "lower"
      }, 
      Name: "minecraft:large_fern"
    }, 
    {
      Name: "minecraft:fern"
    }, 
    {
      Properties: {
        facing: "west"
      }, 
      Name: "minecraft:wall_torch"
    }, 
    {
      Properties: {
        facing: "east"
      }, 
      Name: "minecraft:wall_torch"
    }, 
    {
      Properties: {
        half: "upper"
      }, 
      Name: "minecraft:large_fern"
    }, 
    {
      Name: "minecraft:spruce_planks"
    }, 
    {
      Properties: {
        orientation: "up_north"
      }, 
      Name: "minecraft:jigsaw"
    }, 
    {
      Properties: {
        half: "top", 
        waterlogged: "false", 
        shape: "outer_right", 
        facing: "east"
      }, 
      Name: "minecraft:spruce_stairs"
    }, 
    {
      Properties: {
        half: "top", 
        waterlogged: "false", 
        shape: "straight", 
        facing: "south"
      }, 
      Name: "minecraft:spruce_stairs"
    }, 
    {
      Properties: {
        half: "top", 
        waterlogged: "false", 
        shape: "outer_right", 
        facing: "south"
      }, 
      Name: "minecraft:spruce_stairs"
    }, 
    {
      Properties: {
        half: "top", 
        waterlogged: "false", 
        shape: "straight", 
        facing: "east"
      }, 
      Name: "minecraft:spruce_stairs"
    }, 
    {
      Properties: {
        half: "top", 
        waterlogged: "false", 
        shape: "straight", 
        facing: "west"
      }, 
      Name: "minecraft:spruce_stairs"
    }, 
    {
      Properties: {
        half: "top", 
        waterlogged: "false", 
        shape: "outer_right", 
        facing: "north"
      }, 
      Name: "minecraft:spruce_stairs"
    }, 
    {
      Properties: {
        half: "top", 
        waterlogged: "false", 
        shape: "straight", 
        facing: "north"
      }, 
      Name: "minecraft:spruce_stairs"
    }, 
    {
      Properties: {
        half: "top", 
        waterlogged: "false", 
        shape: "outer_right", 
        facing: "west"
      }, 
      Name: "minecraft:spruce_stairs"
    }, 
    {
      Properties: {
        axis: "y"
      }, 
      Name: "minecraft:spruce_log"
    }, 
    {
      Properties: {
        part: "foot", 
        facing: "south", 
        occupied: "false"
      }, 
      Name: "minecraft:blue_bed"
    }, 
    {
      Properties: {
        part: "head", 
        facing: "south", 
        occupied: "false"
      }, 
      Name: "minecraft:blue_bed"
    }, 
    {
      Properties: {
        hinge: "right", 
        half: "lower", 
        powered: "false", 
        facing: "south", 
        open: "false"
      }, 
      Name: "minecraft:spruce_door"
    }, 
    {
      Properties: {
        half: "bottom", 
        waterlogged: "false", 
        shape: "straight", 
        facing: "north"
      }, 
      Name: "minecraft:spruce_stairs"
    }, 
    {
      Properties: {
        east: "true", 
        waterlogged: "false", 
        south: "false", 
        north: "false", 
        west: "false"
      }, 
      Name: "minecraft:spruce_fence"
    }, 
    {
      Properties: {
        half: "bottom", 
        waterlogged: "false", 
        shape: "straight", 
        facing: "south"
      }, 
      Name: "minecraft:spruce_stairs"
    }, 
    {
      Properties: {
        axis: "z"
      }, 
      Name: "minecraft:spruce_log"
    }, 
    {
      Properties: {
        hinge: "right", 
        half: "upper", 
        powered: "false", 
        facing: "south", 
        open: "false"
      }, 
      Name: "minecraft:spruce_door"
    }, 
    {
      Properties: {
        powered: "false"
      }, 
      Name: "minecraft:spruce_pressure_plate"
    }, 
    {
      Properties: {
        east: "true", 
        waterlogged: "false", 
        south: "false", 
        north: "false", 
        west: "true"
      }, 
      Name: "minecraft:glass_pane"
    }, 
    {
      Properties: {
        half: "top", 
        waterlogged: "false", 
        powered: "false", 
        facing: "south", 
        open: "true"
      }, 
      Name: "minecraft:spruce_trapdoor"
    }
  ]
}
