{
  size: [7, 8, 7], 
  entities: [
    {
      nbt: {
        HurtByTimestamp: 0, 
        Attributes: [
          {
            Base: 20.0d, 
            Name: "generic.maxHealth"
          }, 
          {
            Base: 0.0d, 
            Name: "generic.knockbackResistance"
          }, 
          {
            Base: 0.699999988079071d, 
            Name: "generic.movementSpeed"
          }, 
          {
            Base: 0.0d, 
            Name: "generic.armor"
          }, 
          {
            Base: 0.0d, 
            Name: "generic.armorToughness"
          }
        ], 
        FallFlying: 0b, 
        Invulnerable: 0b, 
        ShowArms: 0b, 
        AbsorptionAmount: 0.0f, 
        PortalCooldown: 0, 
        FallDistance: 0.0f, 
        DisabledSlots: 0, 
        DeathTime: 0s, 
        Pose: {
          Head: [3.9788169860839844f, 1.545424461364746f, 0.0f], 
          Body: [0.0f, 1.4669723510742188f, 0.0f]
        }, 
        Invisible: 0b, 
        id: "minecraft:armor_stand", 
        Motion: [0.0d, -0.0784000015258789d, 0.0d], 
        Small: 0b, 
        Health: 20.0f, 
        UUIDLeast: -5479752224688706890L, 
        Air: 300s, 
        Dimension: 0, 
        OnGround: 1b, 
        Rotation: [45.0f, 0.0f], 
        HandItems: [
          {}, 
          {}
        ], 
        UUIDMost: 7491130232775920388L, 
        Pos: [-28.5d, 65.0d, 30.5d], 
        ArmorItems: [
          {}, 
          {}, 
          {}, 
          {
            Count: 1b, 
            id: "minecraft:iron_helmet", 
            tag: {
              Damage: 0
            }
          }
        ], 
        Fire: -1s, 
        NoBasePlate: 0b, 
        HurtTime: 0s
      }, 
      blockPos: [2, 1, 1], 
      pos: [2.5d, 1.0d, 1.5d]
    }, 
    {
      nbt: {
        HurtByTimestamp: 0, 
        Attributes: [
          {
            Base: 20.0d, 
            Name: "generic.maxHealth"
          }, 
          {
            Base: 0.0d, 
            Name: "generic.knockbackResistance"
          }, 
          {
            Base: 0.699999988079071d, 
            Name: "generic.movementSpeed"
          }, 
          {
            Base: 0.0d, 
            Name: "generic.armor"
          }, 
          {
            Base: 0.0d, 
            Name: "generic.armorToughness"
          }
        ], 
        FallFlying: 0b, 
        Invulnerable: 0b, 
        ShowArms: 0b, 
        AbsorptionAmount: 0.0f, 
        PortalCooldown: 0, 
        FallDistance: 0.0f, 
        DisabledSlots: 0, 
        DeathTime: 0s, 
        Pose: {
          Head: [2.9511940479278564f, -8.386092185974121f, 0.0f], 
          Body: [0.0f, 3.0253400802612305f, 0.0f]
        }, 
        Invisible: 0b, 
        id: "minecraft:armor_stand", 
        Motion: [0.0d, -0.0784000015258789d, 0.0d], 
        Small: 0b, 
        Health: 20.0f, 
        UUIDLeast: -5413349416069499639L, 
        Air: 300s, 
        Dimension: 0, 
        OnGround: 1b, 
        Rotation: [90.0f, 0.0f], 
        HandItems: [
          {}, 
          {}
        ], 
        UUIDMost: 5340855241689287412L, 
        Pos: [-26.5d, 65.0d, 34.5d], 
        ArmorItems: [
          {}, 
          {}, 
          {
            Count: 1b, 
            id: "minecraft:iron_chestplate", 
            tag: {
              Damage: 0
            }
          }, 
          {}
        ], 
        Fire: -1s, 
        NoBasePlate: 0b, 
        HurtTime: 0s
      }, 
      blockPos: [4, 1, 5], 
      pos: [4.5d, 1.0d, 5.5d]
    }
  ], 
  blocks: [
    {
      pos: [3, 0, 0], 
      state: 0
    }, 
    {
      pos: [4, 0, 0], 
      state: 0
    }, 
    {
      pos: [3, 4, 0], 
      state: 1
    }, 
    {
      pos: [2, 0, 1], 
      state: 0
    }, 
    {
      pos: [4, 0, 1], 
      state: 0
    }, 
    {
      pos: [2, 4, 1], 
      state: 1
    }, 
    {
      pos: [3, 4, 1], 
      state: 1
    }, 
    {
      pos: [4, 4, 1], 
      state: 1
    }, 
    {
      pos: [3, 5, 1], 
      state: 1
    }, 
    {
      pos: [2, 0, 2], 
      state: 2
    }, 
    {
      pos: [3, 0, 2], 
      state: 0
    }, 
    {
      pos: [4, 0, 2], 
      state: 0
    }, 
    {
      pos: [5, 0, 2], 
      state: 0
    }, 
    {
      pos: [6, 0, 2], 
      state: 0
    }, 
    {
      pos: [2, 4, 2], 
      state: 1
    }, 
    {
      pos: [3, 4, 2], 
      state: 1
    }, 
    {
      pos: [4, 4, 2], 
      state: 1
    }, 
    {
      pos: [3, 5, 2], 
      state: 1
    }, 
    {
      pos: [2, 0, 3], 
      state: 2
    }, 
    {
      pos: [3, 0, 3], 
      state: 2
    }, 
    {
      pos: [4, 0, 3], 
      state: 3
    }, 
    {
      pos: [5, 0, 3], 
      state: 0
    }, 
    {
      pos: [2, 4, 3], 
      state: 1
    }, 
    {
      pos: [3, 4, 3], 
      state: 1
    }, 
    {
      pos: [4, 4, 3], 
      state: 2
    }, 
    {
      pos: [3, 5, 3], 
      state: 1
    }, 
    {
      pos: [2, 0, 4], 
      state: 2
    }, 
    {
      pos: [3, 0, 4], 
      state: 0
    }, 
    {
      pos: [4, 0, 4], 
      state: 0
    }, 
    {
      pos: [5, 0, 4], 
      state: 0
    }, 
    {
      pos: [2, 4, 4], 
      state: 1
    }, 
    {
      pos: [3, 4, 4], 
      state: 1
    }, 
    {
      pos: [4, 4, 4], 
      state: 1
    }, 
    {
      pos: [3, 5, 4], 
      state: 1
    }, 
    {
      pos: [1, 0, 5], 
      state: 0
    }, 
    {
      pos: [4, 0, 5], 
      state: 0
    }, 
    {
      pos: [6, 0, 5], 
      state: 0
    }, 
    {
      pos: [2, 4, 5], 
      state: 1
    }, 
    {
      pos: [3, 4, 5], 
      state: 1
    }, 
    {
      pos: [4, 4, 5], 
      state: 1
    }, 
    {
      pos: [3, 5, 5], 
      state: 1
    }, 
    {
      pos: [3, 0, 6], 
      state: 0
    }, 
    {
      pos: [3, 4, 6], 
      state: 1
    }, 
    {
      nbt: {
        target_pool: "minecraft:village/taiga/decor", 
        final_state: "minecraft:grass_block", 
        id: "minecraft:jigsaw", 
        attachement_type: "minecraft:bottom"
      }, 
      pos: [0, 0, 0], 
      state: 4
    }, 
    {
      nbt: {
        target_pool: "minecraft:empty", 
        final_state: "minecraft:structure_void", 
        id: "minecraft:jigsaw", 
        attachement_type: "minecraft:building_entrance"
      }, 
      pos: [0, 1, 3], 
      state: 5
    }, 
    {
      nbt: {
        CookTime: 0s, 
        BurnTime: 0s, 
        Items: [], 
        RecipesUsedSize: 0s, 
        id: "minecraft:blast_furnace", 
        CookTimeTotal: 0s
      }, 
      pos: [4, 1, 3], 
      state: 6
    }, 
    {
      nbt: {
        target_pool: "minecraft:village/common/cats", 
        final_state: "minecraft:grass_block", 
        id: "minecraft:jigsaw", 
        attachement_type: "minecraft:bottom"
      }, 
      pos: [6, 0, 4], 
      state: 4
    }, 
    {
      nbt: {
        Items: [], 
        CookingTimes: [I; 0, 0, 0, 0], 
        CookingTotalTimes: [I; 0, 0, 0, 0], 
        id: "minecraft:campfire"
      }, 
      pos: [1, 1, 5], 
      state: 7
    }, 
    {
      pos: [2, 0, 0], 
      state: 8
    }, 
    {
      pos: [0, 1, 0], 
      state: 9
    }, 
    {
      pos: [1, 1, 0], 
      state: 9
    }, 
    {
      pos: [2, 1, 0], 
      state: 9
    }, 
    {
      pos: [3, 1, 0], 
      state: 10
    }, 
    {
      pos: [4, 1, 0], 
      state: 11
    }, 
    {
      pos: [5, 1, 0], 
      state: 9
    }, 
    {
      pos: [6, 1, 0], 
      state: 9
    }, 
    {
      pos: [0, 2, 0], 
      state: 9
    }, 
    {
      pos: [1, 2, 0], 
      state: 9
    }, 
    {
      pos: [2, 2, 0], 
      state: 9
    }, 
    {
      pos: [3, 2, 0], 
      state: 10
    }, 
    {
      pos: [4, 2, 0], 
      state: 12
    }, 
    {
      pos: [5, 2, 0], 
      state: 9
    }, 
    {
      pos: [6, 2, 0], 
      state: 9
    }, 
    {
      pos: [0, 3, 0], 
      state: 9
    }, 
    {
      pos: [1, 3, 0], 
      state: 9
    }, 
    {
      pos: [2, 3, 0], 
      state: 9
    }, 
    {
      pos: [3, 3, 0], 
      state: 10
    }, 
    {
      pos: [4, 3, 0], 
      state: 9
    }, 
    {
      pos: [5, 3, 0], 
      state: 9
    }, 
    {
      pos: [6, 3, 0], 
      state: 9
    }, 
    {
      pos: [0, 4, 0], 
      state: 9
    }, 
    {
      pos: [1, 4, 0], 
      state: 9
    }, 
    {
      pos: [2, 4, 0], 
      state: 9
    }, 
    {
      pos: [4, 4, 0], 
      state: 9
    }, 
    {
      pos: [5, 4, 0], 
      state: 9
    }, 
    {
      pos: [6, 4, 0], 
      state: 9
    }, 
    {
      pos: [0, 5, 0], 
      state: 9
    }, 
    {
      pos: [1, 5, 0], 
      state: 9
    }, 
    {
      pos: [2, 5, 0], 
      state: 9
    }, 
    {
      pos: [3, 5, 0], 
      state: 9
    }, 
    {
      pos: [4, 5, 0], 
      state: 9
    }, 
    {
      pos: [5, 5, 0], 
      state: 9
    }, 
    {
      pos: [6, 5, 0], 
      state: 9
    }, 
    {
      pos: [0, 6, 0], 
      state: 9
    }, 
    {
      pos: [1, 6, 0], 
      state: 9
    }, 
    {
      pos: [2, 6, 0], 
      state: 9
    }, 
    {
      pos: [3, 6, 0], 
      state: 9
    }, 
    {
      pos: [4, 6, 0], 
      state: 9
    }, 
    {
      pos: [5, 6, 0], 
      state: 9
    }, 
    {
      pos: [6, 6, 0], 
      state: 9
    }, 
    {
      pos: [0, 7, 0], 
      state: 9
    }, 
    {
      pos: [1, 7, 0], 
      state: 9
    }, 
    {
      pos: [2, 7, 0], 
      state: 9
    }, 
    {
      pos: [3, 7, 0], 
      state: 9
    }, 
    {
      pos: [4, 7, 0], 
      state: 9
    }, 
    {
      pos: [5, 7, 0], 
      state: 9
    }, 
    {
      pos: [6, 7, 0], 
      state: 9
    }, 
    {
      pos: [1, 0, 1], 
      state: 8
    }, 
    {
      pos: [3, 0, 1], 
      state: 8
    }, 
    {
      pos: [5, 0, 1], 
      state: 8
    }, 
    {
      pos: [0, 1, 1], 
      state: 9
    }, 
    {
      pos: [1, 1, 1], 
      state: 9
    }, 
    {
      pos: [2, 1, 1], 
      state: 9
    }, 
    {
      pos: [3, 1, 1], 
      state: 9
    }, 
    {
      pos: [4, 1, 1], 
      state: 9
    }, 
    {
      pos: [5, 1, 1], 
      state: 9
    }, 
    {
      pos: [6, 1, 1], 
      state: 9
    }, 
    {
      pos: [0, 2, 1], 
      state: 9
    }, 
    {
      pos: [1, 2, 1], 
      state: 9
    }, 
    {
      pos: [2, 2, 1], 
      state: 9
    }, 
    {
      pos: [3, 2, 1], 
      state: 9
    }, 
    {
      pos: [4, 2, 1], 
      state: 9
    }, 
    {
      pos: [5, 2, 1], 
      state: 9
    }, 
    {
      pos: [6, 2, 1], 
      state: 9
    }, 
    {
      pos: [0, 3, 1], 
      state: 9
    }, 
    {
      pos: [1, 3, 1], 
      state: 9
    }, 
    {
      pos: [2, 3, 1], 
      state: 9
    }, 
    {
      pos: [3, 3, 1], 
      state: 9
    }, 
    {
      pos: [4, 3, 1], 
      state: 9
    }, 
    {
      pos: [5, 3, 1], 
      state: 9
    }, 
    {
      pos: [6, 3, 1], 
      state: 9
    }, 
    {
      pos: [0, 4, 1], 
      state: 9
    }, 
    {
      pos: [1, 4, 1], 
      state: 9
    }, 
    {
      pos: [5, 4, 1], 
      state: 9
    }, 
    {
      pos: [6, 4, 1], 
      state: 9
    }, 
    {
      pos: [0, 5, 1], 
      state: 9
    }, 
    {
      pos: [1, 5, 1], 
      state: 9
    }, 
    {
      pos: [2, 5, 1], 
      state: 9
    }, 
    {
      pos: [4, 5, 1], 
      state: 9
    }, 
    {
      pos: [5, 5, 1], 
      state: 9
    }, 
    {
      pos: [6, 5, 1], 
      state: 9
    }, 
    {
      pos: [0, 6, 1], 
      state: 9
    }, 
    {
      pos: [1, 6, 1], 
      state: 9
    }, 
    {
      pos: [2, 6, 1], 
      state: 9
    }, 
    {
      pos: [3, 6, 1], 
      state: 9
    }, 
    {
      pos: [4, 6, 1], 
      state: 9
    }, 
    {
      pos: [5, 6, 1], 
      state: 9
    }, 
    {
      pos: [6, 6, 1], 
      state: 9
    }, 
    {
      pos: [0, 7, 1], 
      state: 9
    }, 
    {
      pos: [1, 7, 1], 
      state: 9
    }, 
    {
      pos: [2, 7, 1], 
      state: 9
    }, 
    {
      pos: [3, 7, 1], 
      state: 9
    }, 
    {
      pos: [4, 7, 1], 
      state: 9
    }, 
    {
      pos: [5, 7, 1], 
      state: 9
    }, 
    {
      pos: [6, 7, 1], 
      state: 9
    }, 
    {
      pos: [0, 0, 2], 
      state: 8
    }, 
    {
      pos: [1, 0, 2], 
      state: 8
    }, 
    {
      pos: [0, 1, 2], 
      state: 9
    }, 
    {
      pos: [1, 1, 2], 
      state: 9
    }, 
    {
      pos: [2, 1, 2], 
      state: 9
    }, 
    {
      pos: [3, 1, 2], 
      state: 13
    }, 
    {
      pos: [4, 1, 2], 
      state: 14
    }, 
    {
      pos: [5, 1, 2], 
      state: 15
    }, 
    {
      pos: [6, 1, 2], 
      state: 11
    }, 
    {
      pos: [0, 2, 2], 
      state: 9
    }, 
    {
      pos: [1, 2, 2], 
      state: 9
    }, 
    {
      pos: [2, 2, 2], 
      state: 9
    }, 
    {
      pos: [3, 2, 2], 
      state: 9
    }, 
    {
      pos: [4, 2, 2], 
      state: 9
    }, 
    {
      pos: [5, 2, 2], 
      state: 9
    }, 
    {
      pos: [6, 2, 2], 
      state: 12
    }, 
    {
      pos: [0, 3, 2], 
      state: 9
    }, 
    {
      pos: [1, 3, 2], 
      state: 9
    }, 
    {
      pos: [2, 3, 2], 
      state: 9
    }, 
    {
      pos: [3, 3, 2], 
      state: 9
    }, 
    {
      pos: [4, 3, 2], 
      state: 9
    }, 
    {
      pos: [5, 3, 2], 
      state: 9
    }, 
    {
      pos: [6, 3, 2], 
      state: 9
    }, 
    {
      pos: [0, 4, 2], 
      state: 9
    }, 
    {
      pos: [1, 4, 2], 
      state: 9
    }, 
    {
      pos: [5, 4, 2], 
      state: 9
    }, 
    {
      pos: [6, 4, 2], 
      state: 9
    }, 
    {
      pos: [0, 5, 2], 
      state: 9
    }, 
    {
      pos: [1, 5, 2], 
      state: 9
    }, 
    {
      pos: [2, 5, 2], 
      state: 9
    }, 
    {
      pos: [4, 5, 2], 
      state: 9
    }, 
    {
      pos: [5, 5, 2], 
      state: 9
    }, 
    {
      pos: [6, 5, 2], 
      state: 9
    }, 
    {
      pos: [0, 6, 2], 
      state: 9
    }, 
    {
      pos: [1, 6, 2], 
      state: 9
    }, 
    {
      pos: [2, 6, 2], 
      state: 9
    }, 
    {
      pos: [3, 6, 2], 
      state: 9
    }, 
    {
      pos: [4, 6, 2], 
      state: 9
    }, 
    {
      pos: [5, 6, 2], 
      state: 9
    }, 
    {
      pos: [6, 6, 2], 
      state: 9
    }, 
    {
      pos: [0, 7, 2], 
      state: 9
    }, 
    {
      pos: [1, 7, 2], 
      state: 9
    }, 
    {
      pos: [2, 7, 2], 
      state: 9
    }, 
    {
      pos: [3, 7, 2], 
      state: 9
    }, 
    {
      pos: [4, 7, 2], 
      state: 9
    }, 
    {
      pos: [5, 7, 2], 
      state: 9
    }, 
    {
      pos: [6, 7, 2], 
      state: 9
    }, 
    {
      pos: [0, 0, 3], 
      state: 8
    }, 
    {
      pos: [1, 0, 3], 
      state: 8
    }, 
    {
      pos: [6, 0, 3], 
      state: 8
    }, 
    {
      pos: [1, 1, 3], 
      state: 9
    }, 
    {
      pos: [2, 1, 3], 
      state: 9
    }, 
    {
      pos: [3, 1, 3], 
      state: 9
    }, 
    {
      pos: [5, 1, 3], 
      state: 16
    }, 
    {
      pos: [6, 1, 3], 
      state: 9
    }, 
    {
      pos: [0, 2, 3], 
      state: 9
    }, 
    {
      pos: [1, 2, 3], 
      state: 9
    }, 
    {
      pos: [2, 2, 3], 
      state: 9
    }, 
    {
      pos: [3, 2, 3], 
      state: 9
    }, 
    {
      pos: [4, 2, 3], 
      state: 10
    }, 
    {
      pos: [5, 2, 3], 
      state: 9
    }, 
    {
      pos: [6, 2, 3], 
      state: 9
    }, 
    {
      pos: [0, 3, 3], 
      state: 9
    }, 
    {
      pos: [1, 3, 3], 
      state: 9
    }, 
    {
      pos: [2, 3, 3], 
      state: 9
    }, 
    {
      pos: [3, 3, 3], 
      state: 9
    }, 
    {
      pos: [4, 3, 3], 
      state: 10
    }, 
    {
      pos: [5, 3, 3], 
      state: 9
    }, 
    {
      pos: [6, 3, 3], 
      state: 9
    }, 
    {
      pos: [0, 4, 3], 
      state: 9
    }, 
    {
      pos: [1, 4, 3], 
      state: 17
    }, 
    {
      pos: [5, 4, 3], 
      state: 9
    }, 
    {
      pos: [6, 4, 3], 
      state: 9
    }, 
    {
      pos: [0, 5, 3], 
      state: 9
    }, 
    {
      pos: [1, 5, 3], 
      state: 9
    }, 
    {
      pos: [2, 5, 3], 
      state: 9
    }, 
    {
      pos: [4, 5, 3], 
      state: 18
    }, 
    {
      pos: [5, 5, 3], 
      state: 9
    }, 
    {
      pos: [6, 5, 3], 
      state: 9
    }, 
    {
      pos: [0, 6, 3], 
      state: 9
    }, 
    {
      pos: [1, 6, 3], 
      state: 9
    }, 
    {
      pos: [2, 6, 3], 
      state: 9
    }, 
    {
      pos: [3, 6, 3], 
      state: 9
    }, 
    {
      pos: [4, 6, 3], 
      state: 10
    }, 
    {
      pos: [5, 6, 3], 
      state: 9
    }, 
    {
      pos: [6, 6, 3], 
      state: 9
    }, 
    {
      pos: [0, 7, 3], 
      state: 9
    }, 
    {
      pos: [1, 7, 3], 
      state: 9
    }, 
    {
      pos: [2, 7, 3], 
      state: 9
    }, 
    {
      pos: [3, 7, 3], 
      state: 9
    }, 
    {
      pos: [4, 7, 3], 
      state: 10
    }, 
    {
      pos: [5, 7, 3], 
      state: 9
    }, 
    {
      pos: [6, 7, 3], 
      state: 9
    }, 
    {
      pos: [0, 0, 4], 
      state: 8
    }, 
    {
      pos: [1, 0, 4], 
      state: 8
    }, 
    {
      pos: [0, 1, 4], 
      state: 9
    }, 
    {
      pos: [1, 1, 4], 
      state: 9
    }, 
    {
      pos: [2, 1, 4], 
      state: 9
    }, 
    {
      pos: [3, 1, 4], 
      state: 19
    }, 
    {
      pos: [4, 1, 4], 
      state: 20
    }, 
    {
      pos: [5, 1, 4], 
      state: 21
    }, 
    {
      pos: [6, 1, 4], 
      state: 9
    }, 
    {
      pos: [0, 2, 4], 
      state: 9
    }, 
    {
      pos: [1, 2, 4], 
      state: 9
    }, 
    {
      pos: [2, 2, 4], 
      state: 9
    }, 
    {
      pos: [3, 2, 4], 
      state: 9
    }, 
    {
      pos: [4, 2, 4], 
      state: 9
    }, 
    {
      pos: [5, 2, 4], 
      state: 9
    }, 
    {
      pos: [6, 2, 4], 
      state: 9
    }, 
    {
      pos: [0, 3, 4], 
      state: 9
    }, 
    {
      pos: [1, 3, 4], 
      state: 9
    }, 
    {
      pos: [2, 3, 4], 
      state: 9
    }, 
    {
      pos: [3, 3, 4], 
      state: 9
    }, 
    {
      pos: [4, 3, 4], 
      state: 9
    }, 
    {
      pos: [5, 3, 4], 
      state: 9
    }, 
    {
      pos: [6, 3, 4], 
      state: 9
    }, 
    {
      pos: [0, 4, 4], 
      state: 9
    }, 
    {
      pos: [1, 4, 4], 
      state: 9
    }, 
    {
      pos: [5, 4, 4], 
      state: 9
    }, 
    {
      pos: [6, 4, 4], 
      state: 9
    }, 
    {
      pos: [0, 5, 4], 
      state: 9
    }, 
    {
      pos: [1, 5, 4], 
      state: 9
    }, 
    {
      pos: [2, 5, 4], 
      state: 9
    }, 
    {
      pos: [4, 5, 4], 
      state: 9
    }, 
    {
      pos: [5, 5, 4], 
      state: 9
    }, 
    {
      pos: [6, 5, 4], 
      state: 9
    }, 
    {
      pos: [0, 6, 4], 
      state: 9
    }, 
    {
      pos: [1, 6, 4], 
      state: 9
    }, 
    {
      pos: [2, 6, 4], 
      state: 9
    }, 
    {
      pos: [3, 6, 4], 
      state: 9
    }, 
    {
      pos: [4, 6, 4], 
      state: 9
    }, 
    {
      pos: [5, 6, 4], 
      state: 9
    }, 
    {
      pos: [6, 6, 4], 
      state: 9
    }, 
    {
      pos: [0, 7, 4], 
      state: 9
    }, 
    {
      pos: [1, 7, 4], 
      state: 9
    }, 
    {
      pos: [2, 7, 4], 
      state: 9
    }, 
    {
      pos: [3, 7, 4], 
      state: 9
    }, 
    {
      pos: [4, 7, 4], 
      state: 9
    }, 
    {
      pos: [5, 7, 4], 
      state: 9
    }, 
    {
      pos: [6, 7, 4], 
      state: 9
    }, 
    {
      pos: [2, 0, 5], 
      state: 8
    }, 
    {
      pos: [3, 0, 5], 
      state: 8
    }, 
    {
      pos: [5, 0, 5], 
      state: 8
    }, 
    {
      pos: [0, 1, 5], 
      state: 9
    }, 
    {
      pos: [2, 1, 5], 
      state: 9
    }, 
    {
      pos: [3, 1, 5], 
      state: 9
    }, 
    {
      pos: [4, 1, 5], 
      state: 9
    }, 
    {
      pos: [5, 1, 5], 
      state: 9
    }, 
    {
      pos: [6, 1, 5], 
      state: 22
    }, 
    {
      pos: [0, 2, 5], 
      state: 9
    }, 
    {
      pos: [1, 2, 5], 
      state: 9
    }, 
    {
      pos: [2, 2, 5], 
      state: 9
    }, 
    {
      pos: [3, 2, 5], 
      state: 9
    }, 
    {
      pos: [4, 2, 5], 
      state: 9
    }, 
    {
      pos: [5, 2, 5], 
      state: 9
    }, 
    {
      pos: [6, 2, 5], 
      state: 9
    }, 
    {
      pos: [0, 3, 5], 
      state: 9
    }, 
    {
      pos: [1, 3, 5], 
      state: 9
    }, 
    {
      pos: [2, 3, 5], 
      state: 9
    }, 
    {
      pos: [3, 3, 5], 
      state: 9
    }, 
    {
      pos: [4, 3, 5], 
      state: 9
    }, 
    {
      pos: [5, 3, 5], 
      state: 9
    }, 
    {
      pos: [6, 3, 5], 
      state: 9
    }, 
    {
      pos: [0, 4, 5], 
      state: 9
    }, 
    {
      pos: [1, 4, 5], 
      state: 9
    }, 
    {
      pos: [5, 4, 5], 
      state: 9
    }, 
    {
      pos: [6, 4, 5], 
      state: 9
    }, 
    {
      pos: [0, 5, 5], 
      state: 9
    }, 
    {
      pos: [1, 5, 5], 
      state: 9
    }, 
    {
      pos: [2, 5, 5], 
      state: 9
    }, 
    {
      pos: [4, 5, 5], 
      state: 9
    }, 
    {
      pos: [5, 5, 5], 
      state: 9
    }, 
    {
      pos: [6, 5, 5], 
      state: 9
    }, 
    {
      pos: [0, 6, 5], 
      state: 9
    }, 
    {
      pos: [1, 6, 5], 
      state: 9
    }, 
    {
      pos: [2, 6, 5], 
      state: 9
    }, 
    {
      pos: [3, 6, 5], 
      state: 9
    }, 
    {
      pos: [4, 6, 5], 
      state: 9
    }, 
    {
      pos: [5, 6, 5], 
      state: 9
    }, 
    {
      pos: [6, 6, 5], 
      state: 9
    }, 
    {
      pos: [0, 7, 5], 
      state: 9
    }, 
    {
      pos: [1, 7, 5], 
      state: 9
    }, 
    {
      pos: [2, 7, 5], 
      state: 9
    }, 
    {
      pos: [3, 7, 5], 
      state: 9
    }, 
    {
      pos: [4, 7, 5], 
      state: 9
    }, 
    {
      pos: [5, 7, 5], 
      state: 9
    }, 
    {
      pos: [6, 7, 5], 
      state: 9
    }, 
    {
      pos: [0, 0, 6], 
      state: 8
    }, 
    {
      pos: [2, 0, 6], 
      state: 8
    }, 
    {
      pos: [6, 0, 6], 
      state: 8
    }, 
    {
      pos: [0, 1, 6], 
      state: 9
    }, 
    {
      pos: [1, 1, 6], 
      state: 9
    }, 
    {
      pos: [2, 1, 6], 
      state: 9
    }, 
    {
      pos: [3, 1, 6], 
      state: 10
    }, 
    {
      pos: [4, 1, 6], 
      state: 9
    }, 
    {
      pos: [5, 1, 6], 
      state: 9
    }, 
    {
      pos: [6, 1, 6], 
      state: 9
    }, 
    {
      pos: [0, 2, 6], 
      state: 9
    }, 
    {
      pos: [1, 2, 6], 
      state: 9
    }, 
    {
      pos: [2, 2, 6], 
      state: 9
    }, 
    {
      pos: [3, 2, 6], 
      state: 10
    }, 
    {
      pos: [4, 2, 6], 
      state: 9
    }, 
    {
      pos: [5, 2, 6], 
      state: 9
    }, 
    {
      pos: [6, 2, 6], 
      state: 9
    }, 
    {
      pos: [0, 3, 6], 
      state: 9
    }, 
    {
      pos: [1, 3, 6], 
      state: 9
    }, 
    {
      pos: [2, 3, 6], 
      state: 9
    }, 
    {
      pos: [3, 3, 6], 
      state: 10
    }, 
    {
      pos: [4, 3, 6], 
      state: 9
    }, 
    {
      pos: [5, 3, 6], 
      state: 9
    }, 
    {
      pos: [6, 3, 6], 
      state: 9
    }, 
    {
      pos: [0, 4, 6], 
      state: 9
    }, 
    {
      pos: [1, 4, 6], 
      state: 9
    }, 
    {
      pos: [2, 4, 6], 
      state: 9
    }, 
    {
      pos: [4, 4, 6], 
      state: 9
    }, 
    {
      pos: [5, 4, 6], 
      state: 9
    }, 
    {
      pos: [6, 4, 6], 
      state: 9
    }, 
    {
      pos: [0, 5, 6], 
      state: 9
    }, 
    {
      pos: [1, 5, 6], 
      state: 9
    }, 
    {
      pos: [2, 5, 6], 
      state: 9
    }, 
    {
      pos: [3, 5, 6], 
      state: 9
    }, 
    {
      pos: [4, 5, 6], 
      state: 9
    }, 
    {
      pos: [5, 5, 6], 
      state: 9
    }, 
    {
      pos: [6, 5, 6], 
      state: 9
    }, 
    {
      pos: [0, 6, 6], 
      state: 9
    }, 
    {
      pos: [1, 6, 6], 
      state: 9
    }, 
    {
      pos: [2, 6, 6], 
      state: 9
    }, 
    {
      pos: [3, 6, 6], 
      state: 9
    }, 
    {
      pos: [4, 6, 6], 
      state: 9
    }, 
    {
      pos: [5, 6, 6], 
      state: 9
    }, 
    {
      pos: [6, 6, 6], 
      state: 9
    }, 
    {
      pos: [0, 7, 6], 
      state: 9
    }, 
    {
      pos: [1, 7, 6], 
      state: 9
    }, 
    {
      pos: [2, 7, 6], 
      state: 9
    }, 
    {
      pos: [3, 7, 6], 
      state: 9
    }, 
    {
      pos: [4, 7, 6], 
      state: 9
    }, 
    {
      pos: [5, 7, 6], 
      state: 9
    }, 
    {
      pos: [6, 7, 6], 
      state: 9
    }
  ], 
  palette: [
    {
      Properties: {
        snowy: "false"
      }, 
      Name: "minecraft:grass_block"
    }, 
    {
      Properties: {
        axis: "z"
      }, 
      Name: "minecraft:spruce_log"
    }, 
    {
      Name: "minecraft:cobblestone"
    }, 
    {
      Name: "minecraft:dirt"
    }, 
    {
      Properties: {
        facing: "up"
      }, 
      Name: "minecraft:jigsaw"
    }, 
    {
      Properties: {
        facing: "west"
      }, 
      Name: "minecraft:jigsaw"
    }, 
    {
      Properties: {
        lit: "false", 
        facing: "west"
      }, 
      Name: "minecraft:blast_furnace"
    }, 
    {
      Properties: {
        waterlogged: "false", 
        signal_fire: "false", 
        lit: "true", 
        facing: "north"
      }, 
      Name: "minecraft:campfire"
    }, 
    {
      Name: "minecraft:grass_path"
    }, 
    {
      Name: "minecraft:air"
    }, 
    {
      Properties: {
        east: "false", 
        waterlogged: "false", 
        south: "false", 
        north: "false", 
        west: "false", 
        up: "true"
      }, 
      Name: "minecraft:cobblestone_wall"
    }, 
    {
      Properties: {
        half: "lower"
      }, 
      Name: "minecraft:large_fern"
    }, 
    {
      Properties: {
        half: "upper"
      }, 
      Name: "minecraft:large_fern"
    }, 
    {
      Properties: {
        half: "bottom", 
        waterlogged: "false", 
        shape: "outer_right", 
        facing: "east"
      }, 
      Name: "minecraft:cobblestone_stairs"
    }, 
    {
      Properties: {
        half: "bottom", 
        waterlogged: "false", 
        shape: "straight", 
        facing: "south"
      }, 
      Name: "minecraft:cobblestone_stairs"
    }, 
    {
      Properties: {
        half: "bottom", 
        waterlogged: "false", 
        shape: "outer_left", 
        facing: "west"
      }, 
      Name: "minecraft:cobblestone_stairs"
    }, 
    {
      Properties: {
        half: "bottom", 
        waterlogged: "false", 
        shape: "straight", 
        facing: "west"
      }, 
      Name: "minecraft:cobblestone_stairs"
    }, 
    {
      Properties: {
        facing: "west"
      }, 
      Name: "minecraft:wall_torch"
    }, 
    {
      Properties: {
        east: "false", 
        waterlogged: "false", 
        south: "false", 
        north: "false", 
        west: "true", 
        up: "true"
      }, 
      Name: "minecraft:cobblestone_wall"
    }, 
    {
      Properties: {
        half: "bottom", 
        waterlogged: "false", 
        shape: "outer_left", 
        facing: "east"
      }, 
      Name: "minecraft:cobblestone_stairs"
    }, 
    {
      Properties: {
        half: "bottom", 
        waterlogged: "false", 
        shape: "straight", 
        facing: "north"
      }, 
      Name: "minecraft:cobblestone_stairs"
    }, 
    {
      Properties: {
        half: "bottom", 
        waterlogged: "false", 
        shape: "outer_right", 
        facing: "west"
      }, 
      Name: "minecraft:cobblestone_stairs"
    }, 
    {
      Name: "minecraft:fern"
    }
  ]
}
