{
  size: [4, 4, 4], 
  entities: [], 
  blocks: [
    {
      pos: [0, 0, 0], 
      state: 0
    }, 
    {
      pos: [3, 0, 0], 
      state: 0
    }, 
    {
      pos: [1, 0, 1], 
      state: 1
    }, 
    {
      pos: [2, 0, 1], 
      state: 1
    }, 
    {
      pos: [1, 0, 2], 
      state: 1
    }, 
    {
      pos: [2, 0, 2], 
      state: 1
    }, 
    {
      pos: [0, 1, 0], 
      state: 0
    }, 
    {
      pos: [1, 1, 0], 
      state: 1
    }, 
    {
      pos: [2, 1, 0], 
      state: 1
    }, 
    {
      pos: [3, 1, 0], 
      state: 0
    }, 
    {
      pos: [0, 1, 1], 
      state: 0
    }, 
    {
      pos: [3, 1, 1], 
      state: 0
    }, 
    {
      pos: [0, 1, 2], 
      state: 0
    }, 
    {
      pos: [3, 1, 2], 
      state: 0
    }, 
    {
      pos: [1, 1, 3], 
      state: 0
    }, 
    {
      pos: [2, 1, 3], 
      state: 0
    }, 
    {
      pos: [0, 2, 0], 
      state: 0
    }, 
    {
      pos: [3, 2, 0], 
      state: 0
    }, 
    {
      pos: [0, 2, 1], 
      state: 0
    }, 
    {
      pos: [3, 2, 1], 
      state: 0
    }, 
    {
      pos: [0, 2, 2], 
      state: 0
    }, 
    {
      pos: [3, 2, 2], 
      state: 0
    }, 
    {
      pos: [1, 2, 3], 
      state: 0
    }, 
    {
      pos: [2, 2, 3], 
      state: 0
    }, 
    {
      pos: [0, 3, 0], 
      state: 1
    }, 
    {
      pos: [1, 3, 0], 
      state: 1
    }, 
    {
      pos: [2, 3, 0], 
      state: 1
    }, 
    {
      pos: [3, 3, 0], 
      state: 1
    }, 
    {
      pos: [1, 3, 1], 
      state: 1
    }, 
    {
      pos: [2, 3, 1], 
      state: 1
    }, 
    {
      pos: [1, 3, 2], 
      state: 1
    }, 
    {
      pos: [2, 3, 2], 
      state: 1
    }
  ], 
  palette: [
    {
      Properties: {
        axis: "y"
      }, 
      Name: "minecraft:bone_block"
    }, 
    {
      Properties: {
        axis: "x"
      }, 
      Name: "minecraft:bone_block"
    }
  ]
}
