{
  size: [7, 6, 8], 
  entities: [], 
  blocks: [
    {
      pos: [0, 0, 0], 
      state: 0
    }, 
    {
      pos: [0, 0, 1], 
      state: 1
    }, 
    {
      pos: [0, 0, 2], 
      state: 1
    }, 
    {
      pos: [0, 0, 5], 
      state: 1
    }, 
    {
      pos: [0, 0, 6], 
      state: 1
    }, 
    {
      pos: [0, 0, 7], 
      state: 1
    }, 
    {
      pos: [1, 0, 0], 
      state: 1
    }, 
    {
      pos: [1, 0, 1], 
      state: 1
    }, 
    {
      pos: [1, 0, 2], 
      state: 1
    }, 
    {
      pos: [1, 0, 5], 
      state: 1
    }, 
    {
      pos: [1, 0, 6], 
      state: 1
    }, 
    {
      pos: [1, 0, 7], 
      state: 1
    }, 
    {
      pos: [2, 0, 0], 
      state: 1
    }, 
    {
      pos: [2, 0, 1], 
      state: 1
    }, 
    {
      pos: [2, 0, 2], 
      state: 1
    }, 
    {
      pos: [2, 0, 5], 
      state: 1
    }, 
    {
      pos: [2, 0, 6], 
      state: 1
    }, 
    {
      pos: [2, 0, 7], 
      state: 1
    }, 
    {
      pos: [5, 0, 0], 
      state: 1
    }, 
    {
      pos: [5, 0, 1], 
      state: 1
    }, 
    {
      pos: [5, 0, 2], 
      state: 1
    }, 
    {
      pos: [5, 0, 3], 
      state: 1
    }, 
    {
      pos: [5, 0, 4], 
      state: 1
    }, 
    {
      pos: [5, 0, 5], 
      state: 1
    }, 
    {
      pos: [5, 0, 6], 
      state: 1
    }, 
    {
      pos: [5, 0, 7], 
      state: 1
    }, 
    {
      pos: [6, 0, 0], 
      state: 1
    }, 
    {
      pos: [6, 0, 1], 
      state: 1
    }, 
    {
      pos: [6, 0, 2], 
      state: 1
    }, 
    {
      pos: [6, 0, 3], 
      state: 1
    }, 
    {
      pos: [6, 0, 4], 
      state: 1
    }, 
    {
      pos: [6, 0, 5], 
      state: 1
    }, 
    {
      pos: [6, 0, 6], 
      state: 1
    }, 
    {
      pos: [6, 0, 7], 
      state: 1
    }, 
    {
      pos: [0, 1, 1], 
      state: 1
    }, 
    {
      pos: [0, 1, 2], 
      state: 1
    }, 
    {
      pos: [0, 1, 7], 
      state: 1
    }, 
    {
      pos: [1, 1, 1], 
      state: 1
    }, 
    {
      pos: [1, 1, 2], 
      state: 1
    }, 
    {
      pos: [1, 1, 7], 
      state: 1
    }, 
    {
      pos: [2, 1, 6], 
      state: 1
    }, 
    {
      pos: [2, 1, 7], 
      state: 1
    }, 
    {
      pos: [5, 1, 2], 
      state: 1
    }, 
    {
      pos: [5, 1, 3], 
      state: 1
    }, 
    {
      pos: [5, 1, 5], 
      state: 1
    }, 
    {
      pos: [5, 1, 7], 
      state: 1
    }, 
    {
      pos: [6, 1, 2], 
      state: 1
    }, 
    {
      pos: [6, 1, 3], 
      state: 1
    }, 
    {
      pos: [6, 1, 4], 
      state: 1
    }, 
    {
      pos: [6, 1, 5], 
      state: 1
    }, 
    {
      pos: [6, 1, 6], 
      state: 1
    }, 
    {
      pos: [6, 1, 7], 
      state: 1
    }, 
    {
      pos: [0, 2, 0], 
      state: 0
    }, 
    {
      pos: [0, 2, 2], 
      state: 1
    }, 
    {
      pos: [0, 2, 3], 
      state: 0
    }, 
    {
      pos: [1, 2, 0], 
      state: 1
    }, 
    {
      pos: [1, 2, 1], 
      state: 1
    }, 
    {
      pos: [1, 2, 2], 
      state: 1
    }, 
    {
      pos: [2, 2, 1], 
      state: 1
    }, 
    {
      pos: [2, 2, 2], 
      state: 1
    }, 
    {
      pos: [2, 2, 3], 
      state: 1
    }, 
    {
      pos: [2, 2, 4], 
      state: 1
    }, 
    {
      pos: [2, 2, 6], 
      state: 1
    }, 
    {
      pos: [2, 2, 7], 
      state: 1
    }, 
    {
      pos: [3, 2, 1], 
      state: 1
    }, 
    {
      pos: [3, 2, 2], 
      state: 1
    }, 
    {
      pos: [3, 2, 6], 
      state: 1
    }, 
    {
      pos: [3, 2, 7], 
      state: 1
    }, 
    {
      pos: [4, 2, 5], 
      state: 1
    }, 
    {
      pos: [4, 2, 6], 
      state: 1
    }, 
    {
      pos: [4, 2, 7], 
      state: 1
    }, 
    {
      pos: [5, 2, 7], 
      state: 1
    }, 
    {
      pos: [6, 2, 3], 
      state: 1
    }, 
    {
      pos: [6, 2, 7], 
      state: 1
    }, 
    {
      pos: [1, 3, 1], 
      state: 1
    }, 
    {
      pos: [2, 3, 0], 
      state: 1
    }, 
    {
      pos: [2, 3, 1], 
      state: 2
    }, 
    {
      pos: [2, 3, 2], 
      state: 2
    }, 
    {
      pos: [3, 3, 1], 
      state: 2
    }, 
    {
      pos: [3, 3, 2], 
      state: 2
    }, 
    {
      pos: [3, 3, 6], 
      state: 2
    }, 
    {
      pos: [4, 3, 5], 
      state: 2
    }, 
    {
      pos: [4, 3, 6], 
      state: 2
    }, 
    {
      pos: [2, 4, 0], 
      state: 2
    }, 
    {
      pos: [2, 4, 1], 
      state: 2
    }, 
    {
      pos: [2, 4, 2], 
      state: 2
    }, 
    {
      pos: [3, 4, 0], 
      state: 0
    }, 
    {
      pos: [3, 4, 1], 
      state: 2
    }, 
    {
      pos: [3, 4, 6], 
      state: 2
    }, 
    {
      pos: [2, 5, 1], 
      state: 2
    }, 
    {
      pos: [3, 2, 5], 
      state: 3
    }, 
    {
      pos: [3, 3, 5], 
      state: 4
    }, 
    {
      nbt: {
        joint: "rollable", 
        final_state: "minecraft:taterstone", 
        name: "minecraft:empty", 
        pool: "minecraft:colosseum/mobs/plaguewhale", 
        id: "minecraft:jigsaw", 
        target: "minecraft:mob_connector"
      }, 
      pos: [1, 1, 6], 
      state: 5
    }, 
    {
      nbt: {
        joint: "rollable", 
        final_state: "minecraft:baked_potato_bricks", 
        name: "minecraft:treasure", 
        pool: "minecraft:empty", 
        id: "minecraft:jigsaw", 
        target: "minecraft:empty"
      }, 
      pos: [6, 2, 2], 
      state: 6
    }
  ], 
  palette: [
    {
      Name: "minecraft:taterstone"
    }, 
    {
      Name: "minecraft:baked_potato_bricks"
    }, 
    {
      Name: "minecraft:gold_block"
    }, 
    {
      Name: "minecraft:pedestal"
    }, 
    {
      Name: "minecraft:cave_air"
    }, 
    {
      Properties: {
        orientation: "up_north"
      }, 
      Name: "minecraft:jigsaw"
    }, 
    {
      Properties: {
        orientation: "east_up"
      }, 
      Name: "minecraft:jigsaw"
    }
  ]
}
