{
  size: [11, 6, 8], 
  entities: [], 
  blocks: [
    {
      pos: [0, 3, 0], 
      state: 0
    }, 
    {
      pos: [1, 3, 0], 
      state: 0
    }, 
    {
      pos: [2, 3, 0], 
      state: 0
    }, 
    {
      pos: [3, 3, 0], 
      state: 0
    }, 
    {
      pos: [4, 3, 0], 
      state: 0
    }, 
    {
      pos: [5, 3, 0], 
      state: 0
    }, 
    {
      pos: [6, 3, 0], 
      state: 0
    }, 
    {
      pos: [7, 3, 0], 
      state: 0
    }, 
    {
      pos: [8, 3, 0], 
      state: 0
    }, 
    {
      pos: [9, 3, 0], 
      state: 0
    }, 
    {
      pos: [10, 3, 0], 
      state: 0
    }, 
    {
      pos: [1, 0, 1], 
      state: 1
    }, 
    {
      pos: [2, 0, 1], 
      state: 1
    }, 
    {
      pos: [3, 0, 1], 
      state: 1
    }, 
    {
      pos: [4, 0, 1], 
      state: 1
    }, 
    {
      pos: [5, 0, 1], 
      state: 1
    }, 
    {
      pos: [6, 0, 1], 
      state: 1
    }, 
    {
      pos: [7, 0, 1], 
      state: 1
    }, 
    {
      pos: [8, 0, 1], 
      state: 1
    }, 
    {
      pos: [9, 0, 1], 
      state: 1
    }, 
    {
      pos: [1, 1, 1], 
      state: 2
    }, 
    {
      pos: [2, 1, 1], 
      state: 2
    }, 
    {
      pos: [3, 1, 1], 
      state: 2
    }, 
    {
      pos: [4, 1, 1], 
      state: 2
    }, 
    {
      pos: [5, 1, 1], 
      state: 2
    }, 
    {
      pos: [6, 1, 1], 
      state: 2
    }, 
    {
      pos: [7, 1, 1], 
      state: 2
    }, 
    {
      pos: [8, 1, 1], 
      state: 2
    }, 
    {
      pos: [9, 1, 1], 
      state: 2
    }, 
    {
      pos: [1, 2, 1], 
      state: 2
    }, 
    {
      pos: [2, 2, 1], 
      state: 2
    }, 
    {
      pos: [4, 2, 1], 
      state: 2
    }, 
    {
      pos: [6, 2, 1], 
      state: 2
    }, 
    {
      pos: [8, 2, 1], 
      state: 2
    }, 
    {
      pos: [9, 2, 1], 
      state: 2
    }, 
    {
      pos: [1, 3, 1], 
      state: 2
    }, 
    {
      pos: [2, 3, 1], 
      state: 2
    }, 
    {
      pos: [3, 3, 1], 
      state: 2
    }, 
    {
      pos: [4, 3, 1], 
      state: 2
    }, 
    {
      pos: [5, 3, 1], 
      state: 2
    }, 
    {
      pos: [6, 3, 1], 
      state: 2
    }, 
    {
      pos: [7, 3, 1], 
      state: 2
    }, 
    {
      pos: [8, 3, 1], 
      state: 2
    }, 
    {
      pos: [9, 3, 1], 
      state: 2
    }, 
    {
      pos: [0, 4, 1], 
      state: 0
    }, 
    {
      pos: [1, 4, 1], 
      state: 0
    }, 
    {
      pos: [2, 4, 1], 
      state: 0
    }, 
    {
      pos: [3, 4, 1], 
      state: 0
    }, 
    {
      pos: [4, 4, 1], 
      state: 0
    }, 
    {
      pos: [5, 4, 1], 
      state: 0
    }, 
    {
      pos: [6, 4, 1], 
      state: 0
    }, 
    {
      pos: [7, 4, 1], 
      state: 0
    }, 
    {
      pos: [8, 4, 1], 
      state: 0
    }, 
    {
      pos: [9, 4, 1], 
      state: 0
    }, 
    {
      pos: [10, 4, 1], 
      state: 0
    }, 
    {
      pos: [1, 0, 2], 
      state: 1
    }, 
    {
      pos: [2, 0, 2], 
      state: 2
    }, 
    {
      pos: [3, 0, 2], 
      state: 2
    }, 
    {
      pos: [4, 0, 2], 
      state: 2
    }, 
    {
      pos: [5, 0, 2], 
      state: 2
    }, 
    {
      pos: [6, 0, 2], 
      state: 2
    }, 
    {
      pos: [7, 0, 2], 
      state: 2
    }, 
    {
      pos: [8, 0, 2], 
      state: 2
    }, 
    {
      pos: [9, 0, 2], 
      state: 1
    }, 
    {
      pos: [1, 1, 2], 
      state: 2
    }, 
    {
      pos: [2, 1, 2], 
      state: 3
    }, 
    {
      pos: [9, 1, 2], 
      state: 2
    }, 
    {
      pos: [1, 2, 2], 
      state: 2
    }, 
    {
      pos: [9, 2, 2], 
      state: 2
    }, 
    {
      pos: [1, 3, 2], 
      state: 2
    }, 
    {
      pos: [9, 3, 2], 
      state: 2
    }, 
    {
      pos: [1, 4, 2], 
      state: 2
    }, 
    {
      pos: [9, 4, 2], 
      state: 2
    }, 
    {
      pos: [0, 5, 2], 
      state: 0
    }, 
    {
      pos: [1, 5, 2], 
      state: 0
    }, 
    {
      pos: [2, 5, 2], 
      state: 0
    }, 
    {
      pos: [3, 5, 2], 
      state: 0
    }, 
    {
      pos: [4, 5, 2], 
      state: 0
    }, 
    {
      pos: [5, 5, 2], 
      state: 0
    }, 
    {
      pos: [6, 5, 2], 
      state: 0
    }, 
    {
      pos: [7, 5, 2], 
      state: 0
    }, 
    {
      pos: [8, 5, 2], 
      state: 0
    }, 
    {
      pos: [9, 5, 2], 
      state: 0
    }, 
    {
      pos: [10, 5, 2], 
      state: 0
    }, 
    {
      pos: [1, 0, 3], 
      state: 1
    }, 
    {
      pos: [2, 0, 3], 
      state: 2
    }, 
    {
      pos: [3, 0, 3], 
      state: 2
    }, 
    {
      pos: [4, 0, 3], 
      state: 2
    }, 
    {
      pos: [5, 0, 3], 
      state: 2
    }, 
    {
      pos: [6, 0, 3], 
      state: 2
    }, 
    {
      pos: [7, 0, 3], 
      state: 2
    }, 
    {
      pos: [8, 0, 3], 
      state: 2
    }, 
    {
      pos: [9, 0, 3], 
      state: 1
    }, 
    {
      pos: [1, 1, 3], 
      state: 2
    }, 
    {
      pos: [2, 1, 3], 
      state: 2
    }, 
    {
      pos: [9, 1, 3], 
      state: 2
    }, 
    {
      pos: [1, 2, 3], 
      state: 2
    }, 
    {
      pos: [9, 2, 3], 
      state: 2
    }, 
    {
      pos: [1, 3, 3], 
      state: 2
    }, 
    {
      pos: [9, 3, 3], 
      state: 2
    }, 
    {
      pos: [1, 4, 3], 
      state: 2
    }, 
    {
      pos: [9, 4, 3], 
      state: 2
    }, 
    {
      pos: [0, 5, 3], 
      state: 0
    }, 
    {
      pos: [1, 5, 3], 
      state: 0
    }, 
    {
      pos: [2, 5, 3], 
      state: 0
    }, 
    {
      pos: [3, 5, 3], 
      state: 0
    }, 
    {
      pos: [4, 5, 3], 
      state: 0
    }, 
    {
      pos: [5, 5, 3], 
      state: 0
    }, 
    {
      pos: [6, 5, 3], 
      state: 0
    }, 
    {
      pos: [7, 5, 3], 
      state: 0
    }, 
    {
      pos: [8, 5, 3], 
      state: 0
    }, 
    {
      pos: [9, 5, 3], 
      state: 0
    }, 
    {
      pos: [10, 5, 3], 
      state: 0
    }, 
    {
      pos: [1, 0, 4], 
      state: 1
    }, 
    {
      pos: [2, 0, 4], 
      state: 1
    }, 
    {
      pos: [3, 0, 4], 
      state: 1
    }, 
    {
      pos: [4, 0, 4], 
      state: 1
    }, 
    {
      pos: [5, 0, 4], 
      state: 2
    }, 
    {
      pos: [6, 0, 4], 
      state: 1
    }, 
    {
      pos: [7, 0, 4], 
      state: 1
    }, 
    {
      pos: [8, 0, 4], 
      state: 1
    }, 
    {
      pos: [9, 0, 4], 
      state: 1
    }, 
    {
      pos: [1, 1, 4], 
      state: 2
    }, 
    {
      pos: [2, 1, 4], 
      state: 2
    }, 
    {
      pos: [3, 1, 4], 
      state: 2
    }, 
    {
      pos: [4, 1, 4], 
      state: 2
    }, 
    {
      pos: [6, 1, 4], 
      state: 2
    }, 
    {
      pos: [7, 1, 4], 
      state: 2
    }, 
    {
      pos: [8, 1, 4], 
      state: 2
    }, 
    {
      pos: [9, 1, 4], 
      state: 2
    }, 
    {
      pos: [1, 2, 4], 
      state: 2
    }, 
    {
      pos: [3, 2, 4], 
      state: 2
    }, 
    {
      pos: [4, 2, 4], 
      state: 2
    }, 
    {
      pos: [6, 2, 4], 
      state: 2
    }, 
    {
      pos: [7, 2, 4], 
      state: 2
    }, 
    {
      pos: [9, 2, 4], 
      state: 2
    }, 
    {
      pos: [1, 3, 4], 
      state: 2
    }, 
    {
      pos: [2, 3, 4], 
      state: 2
    }, 
    {
      pos: [3, 3, 4], 
      state: 2
    }, 
    {
      pos: [4, 3, 4], 
      state: 2
    }, 
    {
      pos: [5, 3, 4], 
      state: 2
    }, 
    {
      pos: [6, 3, 4], 
      state: 2
    }, 
    {
      pos: [7, 3, 4], 
      state: 2
    }, 
    {
      pos: [8, 3, 4], 
      state: 2
    }, 
    {
      pos: [9, 3, 4], 
      state: 2
    }, 
    {
      pos: [0, 4, 4], 
      state: 0
    }, 
    {
      pos: [1, 4, 4], 
      state: 0
    }, 
    {
      pos: [2, 4, 4], 
      state: 0
    }, 
    {
      pos: [3, 4, 4], 
      state: 0
    }, 
    {
      pos: [4, 4, 4], 
      state: 4
    }, 
    {
      pos: [5, 4, 4], 
      state: 0
    }, 
    {
      pos: [6, 4, 4], 
      state: 4
    }, 
    {
      pos: [7, 4, 4], 
      state: 0
    }, 
    {
      pos: [8, 4, 4], 
      state: 0
    }, 
    {
      pos: [9, 4, 4], 
      state: 0
    }, 
    {
      pos: [10, 4, 4], 
      state: 0
    }, 
    {
      pos: [5, 5, 4], 
      state: 4
    }, 
    {
      pos: [4, 0, 5], 
      state: 1
    }, 
    {
      pos: [5, 0, 5], 
      state: 5
    }, 
    {
      pos: [6, 0, 5], 
      state: 1
    }, 
    {
      pos: [4, 1, 5], 
      state: 5
    }, 
    {
      pos: [6, 1, 5], 
      state: 5
    }, 
    {
      pos: [4, 2, 5], 
      state: 5
    }, 
    {
      pos: [6, 2, 5], 
      state: 5
    }, 
    {
      pos: [0, 3, 5], 
      state: 0
    }, 
    {
      pos: [1, 3, 5], 
      state: 0
    }, 
    {
      pos: [2, 3, 5], 
      state: 0
    }, 
    {
      pos: [3, 3, 5], 
      state: 0
    }, 
    {
      pos: [4, 3, 5], 
      state: 5
    }, 
    {
      pos: [6, 3, 5], 
      state: 5
    }, 
    {
      pos: [7, 3, 5], 
      state: 0
    }, 
    {
      pos: [8, 3, 5], 
      state: 0
    }, 
    {
      pos: [9, 3, 5], 
      state: 0
    }, 
    {
      pos: [10, 3, 5], 
      state: 0
    }, 
    {
      pos: [4, 4, 5], 
      state: 4
    }, 
    {
      pos: [5, 4, 5], 
      state: 5
    }, 
    {
      pos: [6, 4, 5], 
      state: 4
    }, 
    {
      pos: [5, 5, 5], 
      state: 4
    }, 
    {
      pos: [4, 0, 6], 
      state: 1
    }, 
    {
      pos: [5, 0, 6], 
      state: 5
    }, 
    {
      pos: [6, 0, 6], 
      state: 1
    }, 
    {
      pos: [4, 1, 6], 
      state: 5
    }, 
    {
      pos: [6, 1, 6], 
      state: 5
    }, 
    {
      pos: [4, 2, 6], 
      state: 5
    }, 
    {
      pos: [6, 2, 6], 
      state: 5
    }, 
    {
      pos: [3, 3, 6], 
      state: 4
    }, 
    {
      pos: [4, 3, 6], 
      state: 5
    }, 
    {
      pos: [5, 3, 6], 
      state: 5
    }, 
    {
      pos: [6, 3, 6], 
      state: 5
    }, 
    {
      pos: [7, 3, 6], 
      state: 4
    }, 
    {
      pos: [4, 4, 6], 
      state: 4
    }, 
    {
      pos: [5, 4, 6], 
      state: 5
    }, 
    {
      pos: [6, 4, 6], 
      state: 4
    }, 
    {
      pos: [5, 5, 6], 
      state: 4
    }, 
    {
      pos: [3, 3, 7], 
      state: 4
    }, 
    {
      pos: [7, 3, 7], 
      state: 4
    }, 
    {
      pos: [4, 4, 7], 
      state: 4
    }, 
    {
      pos: [6, 4, 7], 
      state: 4
    }, 
    {
      pos: [5, 5, 7], 
      state: 4
    }, 
    {
      nbt: {
        LootTable: "minecraft:chests/village/village_toolsmith", 
        Items: [], 
        id: "minecraft:chest", 
        Lock: "", 
        LootTableSeed: 0L
      }, 
      pos: [6, 1, 3], 
      state: 6
    }, 
    {
      nbt: {
        target_pool: "minecraft:village/taiga/zombie/decor", 
        final_state: "minecraft:grass_block", 
        id: "minecraft:jigsaw", 
        attachement_type: "minecraft:bottom"
      }, 
      pos: [1, 0, 7], 
      state: 7
    }, 
    {
      nbt: {
        target_pool: "minecraft:village/common/cats", 
        final_state: "minecraft:grass_block", 
        id: "minecraft:jigsaw", 
        attachement_type: "minecraft:bottom"
      }, 
      pos: [9, 0, 7], 
      state: 7
    }, 
    {
      nbt: {
        target_pool: "minecraft:empty", 
        final_state: "minecraft:structure_void", 
        id: "minecraft:jigsaw", 
        attachement_type: "minecraft:building_entrance"
      }, 
      pos: [5, 1, 7], 
      state: 8
    }, 
    {
      pos: [0, 1, 0], 
      state: 9
    }, 
    {
      pos: [2, 1, 0], 
      state: 9
    }, 
    {
      pos: [3, 1, 0], 
      state: 9
    }, 
    {
      pos: [5, 1, 0], 
      state: 9
    }, 
    {
      pos: [6, 1, 0], 
      state: 9
    }, 
    {
      pos: [7, 1, 0], 
      state: 9
    }, 
    {
      pos: [8, 1, 0], 
      state: 9
    }, 
    {
      pos: [9, 1, 0], 
      state: 9
    }, 
    {
      pos: [10, 1, 0], 
      state: 9
    }, 
    {
      pos: [0, 2, 0], 
      state: 9
    }, 
    {
      pos: [1, 2, 0], 
      state: 9
    }, 
    {
      pos: [2, 2, 0], 
      state: 10
    }, 
    {
      pos: [3, 2, 0], 
      state: 9
    }, 
    {
      pos: [4, 2, 0], 
      state: 10
    }, 
    {
      pos: [5, 2, 0], 
      state: 9
    }, 
    {
      pos: [6, 2, 0], 
      state: 10
    }, 
    {
      pos: [7, 2, 0], 
      state: 9
    }, 
    {
      pos: [8, 2, 0], 
      state: 10
    }, 
    {
      pos: [9, 2, 0], 
      state: 9
    }, 
    {
      pos: [10, 2, 0], 
      state: 9
    }, 
    {
      pos: [0, 4, 0], 
      state: 9
    }, 
    {
      pos: [1, 4, 0], 
      state: 9
    }, 
    {
      pos: [2, 4, 0], 
      state: 9
    }, 
    {
      pos: [3, 4, 0], 
      state: 9
    }, 
    {
      pos: [4, 4, 0], 
      state: 9
    }, 
    {
      pos: [5, 4, 0], 
      state: 9
    }, 
    {
      pos: [6, 4, 0], 
      state: 9
    }, 
    {
      pos: [7, 4, 0], 
      state: 9
    }, 
    {
      pos: [8, 4, 0], 
      state: 9
    }, 
    {
      pos: [9, 4, 0], 
      state: 9
    }, 
    {
      pos: [10, 4, 0], 
      state: 9
    }, 
    {
      pos: [0, 5, 0], 
      state: 9
    }, 
    {
      pos: [1, 5, 0], 
      state: 9
    }, 
    {
      pos: [2, 5, 0], 
      state: 9
    }, 
    {
      pos: [3, 5, 0], 
      state: 9
    }, 
    {
      pos: [4, 5, 0], 
      state: 9
    }, 
    {
      pos: [5, 5, 0], 
      state: 9
    }, 
    {
      pos: [6, 5, 0], 
      state: 9
    }, 
    {
      pos: [7, 5, 0], 
      state: 9
    }, 
    {
      pos: [8, 5, 0], 
      state: 9
    }, 
    {
      pos: [9, 5, 0], 
      state: 9
    }, 
    {
      pos: [10, 5, 0], 
      state: 9
    }, 
    {
      pos: [0, 1, 1], 
      state: 9
    }, 
    {
      pos: [10, 1, 1], 
      state: 9
    }, 
    {
      pos: [0, 2, 1], 
      state: 9
    }, 
    {
      pos: [3, 2, 1], 
      state: 11
    }, 
    {
      pos: [5, 2, 1], 
      state: 11
    }, 
    {
      pos: [7, 2, 1], 
      state: 11
    }, 
    {
      pos: [10, 2, 1], 
      state: 9
    }, 
    {
      pos: [0, 3, 1], 
      state: 9
    }, 
    {
      pos: [10, 3, 1], 
      state: 9
    }, 
    {
      pos: [0, 5, 1], 
      state: 9
    }, 
    {
      pos: [1, 5, 1], 
      state: 9
    }, 
    {
      pos: [2, 5, 1], 
      state: 9
    }, 
    {
      pos: [3, 5, 1], 
      state: 9
    }, 
    {
      pos: [4, 5, 1], 
      state: 9
    }, 
    {
      pos: [5, 5, 1], 
      state: 9
    }, 
    {
      pos: [6, 5, 1], 
      state: 9
    }, 
    {
      pos: [7, 5, 1], 
      state: 9
    }, 
    {
      pos: [8, 5, 1], 
      state: 9
    }, 
    {
      pos: [9, 5, 1], 
      state: 9
    }, 
    {
      pos: [10, 5, 1], 
      state: 9
    }, 
    {
      pos: [0, 1, 2], 
      state: 9
    }, 
    {
      pos: [3, 1, 2], 
      state: 9
    }, 
    {
      pos: [4, 1, 2], 
      state: 9
    }, 
    {
      pos: [5, 1, 2], 
      state: 9
    }, 
    {
      pos: [6, 1, 2], 
      state: 9
    }, 
    {
      pos: [7, 1, 2], 
      state: 9
    }, 
    {
      pos: [8, 1, 2], 
      state: 12
    }, 
    {
      pos: [10, 1, 2], 
      state: 9
    }, 
    {
      pos: [0, 2, 2], 
      state: 9
    }, 
    {
      pos: [2, 2, 2], 
      state: 9
    }, 
    {
      pos: [3, 2, 2], 
      state: 9
    }, 
    {
      pos: [4, 2, 2], 
      state: 9
    }, 
    {
      pos: [5, 2, 2], 
      state: 9
    }, 
    {
      pos: [6, 2, 2], 
      state: 9
    }, 
    {
      pos: [7, 2, 2], 
      state: 9
    }, 
    {
      pos: [8, 2, 2], 
      state: 9
    }, 
    {
      pos: [10, 2, 2], 
      state: 9
    }, 
    {
      pos: [0, 3, 2], 
      state: 9
    }, 
    {
      pos: [2, 3, 2], 
      state: 9
    }, 
    {
      pos: [3, 3, 2], 
      state: 9
    }, 
    {
      pos: [4, 3, 2], 
      state: 9
    }, 
    {
      pos: [5, 3, 2], 
      state: 9
    }, 
    {
      pos: [6, 3, 2], 
      state: 9
    }, 
    {
      pos: [7, 3, 2], 
      state: 9
    }, 
    {
      pos: [8, 3, 2], 
      state: 9
    }, 
    {
      pos: [10, 3, 2], 
      state: 9
    }, 
    {
      pos: [0, 4, 2], 
      state: 9
    }, 
    {
      pos: [2, 4, 2], 
      state: 13
    }, 
    {
      pos: [3, 4, 2], 
      state: 9
    }, 
    {
      pos: [4, 4, 2], 
      state: 9
    }, 
    {
      pos: [5, 4, 2], 
      state: 9
    }, 
    {
      pos: [6, 4, 2], 
      state: 9
    }, 
    {
      pos: [7, 4, 2], 
      state: 9
    }, 
    {
      pos: [8, 4, 2], 
      state: 14
    }, 
    {
      pos: [10, 4, 2], 
      state: 9
    }, 
    {
      pos: [0, 1, 3], 
      state: 9
    }, 
    {
      pos: [3, 1, 3], 
      state: 9
    }, 
    {
      pos: [4, 1, 3], 
      state: 9
    }, 
    {
      pos: [5, 1, 3], 
      state: 9
    }, 
    {
      pos: [7, 1, 3], 
      state: 9
    }, 
    {
      pos: [8, 1, 3], 
      state: 12
    }, 
    {
      pos: [10, 1, 3], 
      state: 9
    }, 
    {
      pos: [0, 2, 3], 
      state: 9
    }, 
    {
      pos: [2, 2, 3], 
      state: 9
    }, 
    {
      pos: [3, 2, 3], 
      state: 9
    }, 
    {
      pos: [4, 2, 3], 
      state: 9
    }, 
    {
      pos: [5, 2, 3], 
      state: 9
    }, 
    {
      pos: [6, 2, 3], 
      state: 9
    }, 
    {
      pos: [7, 2, 3], 
      state: 9
    }, 
    {
      pos: [8, 2, 3], 
      state: 9
    }, 
    {
      pos: [10, 2, 3], 
      state: 9
    }, 
    {
      pos: [0, 3, 3], 
      state: 9
    }, 
    {
      pos: [2, 3, 3], 
      state: 9
    }, 
    {
      pos: [3, 3, 3], 
      state: 9
    }, 
    {
      pos: [4, 3, 3], 
      state: 9
    }, 
    {
      pos: [5, 3, 3], 
      state: 15
    }, 
    {
      pos: [6, 3, 3], 
      state: 9
    }, 
    {
      pos: [7, 3, 3], 
      state: 9
    }, 
    {
      pos: [8, 3, 3], 
      state: 9
    }, 
    {
      pos: [10, 3, 3], 
      state: 9
    }, 
    {
      pos: [0, 4, 3], 
      state: 9
    }, 
    {
      pos: [2, 4, 3], 
      state: 13
    }, 
    {
      pos: [3, 4, 3], 
      state: 9
    }, 
    {
      pos: [4, 4, 3], 
      state: 9
    }, 
    {
      pos: [5, 4, 3], 
      state: 9
    }, 
    {
      pos: [6, 4, 3], 
      state: 9
    }, 
    {
      pos: [7, 4, 3], 
      state: 9
    }, 
    {
      pos: [8, 4, 3], 
      state: 14
    }, 
    {
      pos: [10, 4, 3], 
      state: 9
    }, 
    {
      pos: [0, 1, 4], 
      state: 9
    }, 
    {
      pos: [5, 1, 4], 
      state: 16
    }, 
    {
      pos: [10, 1, 4], 
      state: 9
    }, 
    {
      pos: [0, 2, 4], 
      state: 9
    }, 
    {
      pos: [2, 2, 4], 
      state: 11
    }, 
    {
      pos: [5, 2, 4], 
      state: 17
    }, 
    {
      pos: [8, 2, 4], 
      state: 11
    }, 
    {
      pos: [10, 2, 4], 
      state: 9
    }, 
    {
      pos: [0, 3, 4], 
      state: 9
    }, 
    {
      pos: [10, 3, 4], 
      state: 9
    }, 
    {
      pos: [0, 5, 4], 
      state: 9
    }, 
    {
      pos: [1, 5, 4], 
      state: 9
    }, 
    {
      pos: [2, 5, 4], 
      state: 9
    }, 
    {
      pos: [3, 5, 4], 
      state: 9
    }, 
    {
      pos: [4, 5, 4], 
      state: 9
    }, 
    {
      pos: [6, 5, 4], 
      state: 9
    }, 
    {
      pos: [7, 5, 4], 
      state: 9
    }, 
    {
      pos: [8, 5, 4], 
      state: 9
    }, 
    {
      pos: [9, 5, 4], 
      state: 9
    }, 
    {
      pos: [10, 5, 4], 
      state: 9
    }, 
    {
      pos: [0, 1, 5], 
      state: 9
    }, 
    {
      pos: [1, 1, 5], 
      state: 9
    }, 
    {
      pos: [2, 1, 5], 
      state: 9
    }, 
    {
      pos: [3, 1, 5], 
      state: 9
    }, 
    {
      pos: [5, 1, 5], 
      state: 9
    }, 
    {
      pos: [7, 1, 5], 
      state: 9
    }, 
    {
      pos: [8, 1, 5], 
      state: 9
    }, 
    {
      pos: [9, 1, 5], 
      state: 9
    }, 
    {
      pos: [10, 1, 5], 
      state: 9
    }, 
    {
      pos: [0, 2, 5], 
      state: 9
    }, 
    {
      pos: [1, 2, 5], 
      state: 18
    }, 
    {
      pos: [2, 2, 5], 
      state: 9
    }, 
    {
      pos: [3, 2, 5], 
      state: 18
    }, 
    {
      pos: [5, 2, 5], 
      state: 9
    }, 
    {
      pos: [7, 2, 5], 
      state: 18
    }, 
    {
      pos: [8, 2, 5], 
      state: 9
    }, 
    {
      pos: [9, 2, 5], 
      state: 18
    }, 
    {
      pos: [10, 2, 5], 
      state: 9
    }, 
    {
      pos: [5, 3, 5], 
      state: 9
    }, 
    {
      pos: [0, 4, 5], 
      state: 9
    }, 
    {
      pos: [1, 4, 5], 
      state: 9
    }, 
    {
      pos: [2, 4, 5], 
      state: 9
    }, 
    {
      pos: [3, 4, 5], 
      state: 9
    }, 
    {
      pos: [7, 4, 5], 
      state: 9
    }, 
    {
      pos: [8, 4, 5], 
      state: 9
    }, 
    {
      pos: [9, 4, 5], 
      state: 9
    }, 
    {
      pos: [10, 4, 5], 
      state: 9
    }, 
    {
      pos: [0, 5, 5], 
      state: 9
    }, 
    {
      pos: [1, 5, 5], 
      state: 9
    }, 
    {
      pos: [2, 5, 5], 
      state: 9
    }, 
    {
      pos: [3, 5, 5], 
      state: 9
    }, 
    {
      pos: [4, 5, 5], 
      state: 9
    }, 
    {
      pos: [6, 5, 5], 
      state: 9
    }, 
    {
      pos: [7, 5, 5], 
      state: 9
    }, 
    {
      pos: [8, 5, 5], 
      state: 9
    }, 
    {
      pos: [9, 5, 5], 
      state: 9
    }, 
    {
      pos: [10, 5, 5], 
      state: 9
    }, 
    {
      pos: [0, 1, 6], 
      state: 9
    }, 
    {
      pos: [1, 1, 6], 
      state: 9
    }, 
    {
      pos: [2, 1, 6], 
      state: 9
    }, 
    {
      pos: [3, 1, 6], 
      state: 9
    }, 
    {
      pos: [5, 1, 6], 
      state: 16
    }, 
    {
      pos: [7, 1, 6], 
      state: 9
    }, 
    {
      pos: [8, 1, 6], 
      state: 9
    }, 
    {
      pos: [9, 1, 6], 
      state: 9
    }, 
    {
      pos: [10, 1, 6], 
      state: 9
    }, 
    {
      pos: [0, 2, 6], 
      state: 9
    }, 
    {
      pos: [1, 2, 6], 
      state: 9
    }, 
    {
      pos: [2, 2, 6], 
      state: 9
    }, 
    {
      pos: [3, 2, 6], 
      state: 9
    }, 
    {
      pos: [5, 2, 6], 
      state: 17
    }, 
    {
      pos: [7, 2, 6], 
      state: 9
    }, 
    {
      pos: [8, 2, 6], 
      state: 9
    }, 
    {
      pos: [9, 2, 6], 
      state: 9
    }, 
    {
      pos: [10, 2, 6], 
      state: 9
    }, 
    {
      pos: [0, 3, 6], 
      state: 9
    }, 
    {
      pos: [1, 3, 6], 
      state: 9
    }, 
    {
      pos: [2, 3, 6], 
      state: 9
    }, 
    {
      pos: [8, 3, 6], 
      state: 9
    }, 
    {
      pos: [9, 3, 6], 
      state: 9
    }, 
    {
      pos: [10, 3, 6], 
      state: 9
    }, 
    {
      pos: [0, 4, 6], 
      state: 9
    }, 
    {
      pos: [1, 4, 6], 
      state: 9
    }, 
    {
      pos: [2, 4, 6], 
      state: 9
    }, 
    {
      pos: [3, 4, 6], 
      state: 9
    }, 
    {
      pos: [7, 4, 6], 
      state: 9
    }, 
    {
      pos: [8, 4, 6], 
      state: 9
    }, 
    {
      pos: [9, 4, 6], 
      state: 9
    }, 
    {
      pos: [10, 4, 6], 
      state: 9
    }, 
    {
      pos: [0, 5, 6], 
      state: 9
    }, 
    {
      pos: [1, 5, 6], 
      state: 9
    }, 
    {
      pos: [2, 5, 6], 
      state: 9
    }, 
    {
      pos: [3, 5, 6], 
      state: 9
    }, 
    {
      pos: [4, 5, 6], 
      state: 9
    }, 
    {
      pos: [6, 5, 6], 
      state: 9
    }, 
    {
      pos: [7, 5, 6], 
      state: 9
    }, 
    {
      pos: [8, 5, 6], 
      state: 9
    }, 
    {
      pos: [9, 5, 6], 
      state: 9
    }, 
    {
      pos: [10, 5, 6], 
      state: 9
    }, 
    {
      pos: [5, 0, 7], 
      state: 19
    }, 
    {
      pos: [0, 1, 7], 
      state: 9
    }, 
    {
      pos: [1, 1, 7], 
      state: 9
    }, 
    {
      pos: [2, 1, 7], 
      state: 9
    }, 
    {
      pos: [3, 1, 7], 
      state: 9
    }, 
    {
      pos: [4, 1, 7], 
      state: 9
    }, 
    {
      pos: [6, 1, 7], 
      state: 9
    }, 
    {
      pos: [7, 1, 7], 
      state: 9
    }, 
    {
      pos: [8, 1, 7], 
      state: 9
    }, 
    {
      pos: [9, 1, 7], 
      state: 9
    }, 
    {
      pos: [10, 1, 7], 
      state: 9
    }, 
    {
      pos: [0, 2, 7], 
      state: 9
    }, 
    {
      pos: [1, 2, 7], 
      state: 9
    }, 
    {
      pos: [2, 2, 7], 
      state: 9
    }, 
    {
      pos: [3, 2, 7], 
      state: 9
    }, 
    {
      pos: [4, 2, 7], 
      state: 9
    }, 
    {
      pos: [5, 2, 7], 
      state: 9
    }, 
    {
      pos: [6, 2, 7], 
      state: 9
    }, 
    {
      pos: [7, 2, 7], 
      state: 9
    }, 
    {
      pos: [8, 2, 7], 
      state: 9
    }, 
    {
      pos: [9, 2, 7], 
      state: 9
    }, 
    {
      pos: [10, 2, 7], 
      state: 9
    }, 
    {
      pos: [0, 3, 7], 
      state: 9
    }, 
    {
      pos: [1, 3, 7], 
      state: 9
    }, 
    {
      pos: [2, 3, 7], 
      state: 9
    }, 
    {
      pos: [4, 3, 7], 
      state: 9
    }, 
    {
      pos: [5, 3, 7], 
      state: 20
    }, 
    {
      pos: [6, 3, 7], 
      state: 9
    }, 
    {
      pos: [8, 3, 7], 
      state: 9
    }, 
    {
      pos: [9, 3, 7], 
      state: 9
    }, 
    {
      pos: [10, 3, 7], 
      state: 9
    }, 
    {
      pos: [0, 4, 7], 
      state: 9
    }, 
    {
      pos: [1, 4, 7], 
      state: 9
    }, 
    {
      pos: [2, 4, 7], 
      state: 9
    }, 
    {
      pos: [3, 4, 7], 
      state: 9
    }, 
    {
      pos: [5, 4, 7], 
      state: 9
    }, 
    {
      pos: [7, 4, 7], 
      state: 9
    }, 
    {
      pos: [8, 4, 7], 
      state: 9
    }, 
    {
      pos: [9, 4, 7], 
      state: 9
    }, 
    {
      pos: [10, 4, 7], 
      state: 9
    }, 
    {
      pos: [0, 5, 7], 
      state: 9
    }, 
    {
      pos: [1, 5, 7], 
      state: 9
    }, 
    {
      pos: [2, 5, 7], 
      state: 9
    }, 
    {
      pos: [3, 5, 7], 
      state: 9
    }, 
    {
      pos: [4, 5, 7], 
      state: 9
    }, 
    {
      pos: [6, 5, 7], 
      state: 9
    }, 
    {
      pos: [7, 5, 7], 
      state: 9
    }, 
    {
      pos: [8, 5, 7], 
      state: 9
    }, 
    {
      pos: [9, 5, 7], 
      state: 9
    }, 
    {
      pos: [10, 5, 7], 
      state: 9
    }
  ], 
  palette: [
    {
      Properties: {
        axis: "x"
      }, 
      Name: "minecraft:spruce_log"
    }, 
    {
      Name: "minecraft:dirt"
    }, 
    {
      Name: "minecraft:cobblestone"
    }, 
    {
      Name: "minecraft:smithing_table"
    }, 
    {
      Properties: {
        axis: "z"
      }, 
      Name: "minecraft:spruce_log"
    }, 
    {
      Name: "minecraft:spruce_planks"
    }, 
    {
      Properties: {
        waterlogged: "false", 
        facing: "north", 
        type: "single"
      }, 
      Name: "minecraft:chest"
    }, 
    {
      Properties: {
        facing: "up"
      }, 
      Name: "minecraft:jigsaw"
    }, 
    {
      Properties: {
        facing: "south"
      }, 
      Name: "minecraft:jigsaw"
    }, 
    {
      Name: "minecraft:air"
    }, 
    {
      Properties: {
        half: "top", 
        waterlogged: "false", 
        powered: "false", 
        facing: "north", 
        open: "true"
      }, 
      Name: "minecraft:spruce_trapdoor"
    }, 
    {
      Properties: {
        east: "true", 
        waterlogged: "false", 
        south: "false", 
        north: "false", 
        west: "true"
      }, 
      Name: "minecraft:glass_pane"
    }, 
    {
      Properties: {
        half: "bottom", 
        waterlogged: "false", 
        shape: "straight", 
        facing: "east"
      }, 
      Name: "minecraft:cobblestone_stairs"
    }, 
    {
      Properties: {
        facing: "east"
      }, 
      Name: "minecraft:wall_torch"
    }, 
    {
      Properties: {
        facing: "west"
      }, 
      Name: "minecraft:wall_torch"
    }, 
    {
      Properties: {
        facing: "north"
      }, 
      Name: "minecraft:wall_torch"
    }, 
    {
      Properties: {
        hinge: "right", 
        half: "lower", 
        powered: "false", 
        facing: "north", 
        open: "false"
      }, 
      Name: "minecraft:spruce_door"
    }, 
    {
      Properties: {
        hinge: "right", 
        half: "upper", 
        powered: "false", 
        facing: "north", 
        open: "false"
      }, 
      Name: "minecraft:spruce_door"
    }, 
    {
      Properties: {
        half: "top", 
        waterlogged: "false", 
        powered: "false", 
        facing: "south", 
        open: "true"
      }, 
      Name: "minecraft:spruce_trapdoor"
    }, 
    {
      Name: "minecraft:grass_path"
    }, 
    {
      Properties: {
        facing: "south"
      }, 
      Name: "minecraft:wall_torch"
    }
  ]
}
