{
  size: [8, 7, 9], 
  entities: [], 
  blocks: [
    {
      pos: [1, 0, 0], 
      state: 0
    }, 
    {
      pos: [2, 0, 0], 
      state: 0
    }, 
    {
      pos: [5, 0, 0], 
      state: 1
    }, 
    {
      pos: [0, 0, 1], 
      state: 1
    }, 
    {
      pos: [1, 0, 1], 
      state: 0
    }, 
    {
      pos: [2, 0, 1], 
      state: 0
    }, 
    {
      pos: [3, 0, 1], 
      state: 0
    }, 
    {
      pos: [4, 0, 1], 
      state: 0
    }, 
    {
      pos: [5, 0, 1], 
      state: 0
    }, 
    {
      pos: [6, 0, 1], 
      state: 0
    }, 
    {
      pos: [1, 0, 2], 
      state: 0
    }, 
    {
      pos: [2, 0, 2], 
      state: 0
    }, 
    {
      pos: [3, 0, 2], 
      state: 1
    }, 
    {
      pos: [4, 0, 2], 
      state: 0
    }, 
    {
      pos: [5, 0, 2], 
      state: 0
    }, 
    {
      pos: [7, 0, 2], 
      state: 1
    }, 
    {
      pos: [1, 0, 3], 
      state: 0
    }, 
    {
      pos: [2, 0, 3], 
      state: 0
    }, 
    {
      pos: [3, 0, 3], 
      state: 0
    }, 
    {
      pos: [4, 0, 3], 
      state: 0
    }, 
    {
      pos: [5, 0, 3], 
      state: 0
    }, 
    {
      pos: [2, 0, 4], 
      state: 0
    }, 
    {
      pos: [3, 0, 4], 
      state: 0
    }, 
    {
      pos: [4, 0, 4], 
      state: 0
    }, 
    {
      pos: [5, 0, 4], 
      state: 0
    }, 
    {
      pos: [0, 0, 5], 
      state: 1
    }, 
    {
      pos: [3, 0, 5], 
      state: 0
    }, 
    {
      pos: [4, 0, 5], 
      state: 1
    }, 
    {
      pos: [5, 0, 5], 
      state: 0
    }, 
    {
      pos: [7, 0, 5], 
      state: 0
    }, 
    {
      pos: [0, 0, 6], 
      state: 0
    }, 
    {
      pos: [1, 0, 6], 
      state: 0
    }, 
    {
      pos: [4, 0, 6], 
      state: 0
    }, 
    {
      pos: [5, 0, 6], 
      state: 0
    }, 
    {
      pos: [0, 0, 7], 
      state: 0
    }, 
    {
      pos: [2, 0, 7], 
      state: 1
    }, 
    {
      pos: [3, 0, 8], 
      state: 1
    }, 
    {
      pos: [4, 0, 8], 
      state: 0
    }, 
    {
      pos: [5, 0, 8], 
      state: 0
    }, 
    {
      pos: [6, 0, 8], 
      state: 0
    }, 
    {
      nbt: {
        target_pool: "minecraft:village/taiga/zombie/decor", 
        final_state: "minecraft:grass_block", 
        id: "minecraft:jigsaw", 
        attachement_type: "minecraft:bottom"
      }, 
      pos: [7, 0, 6], 
      state: 2
    }, 
    {
      pos: [0, 0, 0], 
      state: 3
    }, 
    {
      pos: [3, 0, 0], 
      state: 3
    }, 
    {
      pos: [4, 0, 0], 
      state: 3
    }, 
    {
      pos: [6, 0, 0], 
      state: 3
    }, 
    {
      pos: [7, 0, 0], 
      state: 3
    }, 
    {
      pos: [7, 0, 1], 
      state: 3
    }, 
    {
      pos: [0, 0, 2], 
      state: 3
    }, 
    {
      pos: [6, 0, 2], 
      state: 3
    }, 
    {
      pos: [0, 0, 3], 
      state: 3
    }, 
    {
      pos: [6, 0, 3], 
      state: 3
    }, 
    {
      pos: [7, 0, 3], 
      state: 3
    }, 
    {
      pos: [0, 0, 4], 
      state: 4
    }, 
    {
      pos: [1, 0, 4], 
      state: 4
    }, 
    {
      pos: [6, 0, 4], 
      state: 3
    }, 
    {
      pos: [7, 0, 4], 
      state: 3
    }, 
    {
      pos: [1, 0, 5], 
      state: 4
    }, 
    {
      pos: [2, 0, 5], 
      state: 4
    }, 
    {
      pos: [6, 0, 5], 
      state: 3
    }, 
    {
      pos: [2, 0, 6], 
      state: 4
    }, 
    {
      pos: [3, 0, 6], 
      state: 4
    }, 
    {
      pos: [6, 0, 6], 
      state: 3
    }, 
    {
      pos: [1, 0, 7], 
      state: 3
    }, 
    {
      pos: [3, 0, 7], 
      state: 4
    }, 
    {
      pos: [4, 0, 7], 
      state: 4
    }, 
    {
      pos: [5, 0, 7], 
      state: 4
    }, 
    {
      pos: [6, 0, 7], 
      state: 4
    }, 
    {
      pos: [7, 0, 7], 
      state: 4
    }, 
    {
      pos: [0, 0, 8], 
      state: 3
    }, 
    {
      pos: [1, 0, 8], 
      state: 3
    }, 
    {
      pos: [2, 0, 8], 
      state: 3
    }, 
    {
      pos: [7, 0, 8], 
      state: 3
    }, 
    {
      pos: [5, 1, 0], 
      state: 5
    }, 
    {
      pos: [0, 1, 1], 
      state: 5
    }, 
    {
      pos: [7, 1, 2], 
      state: 5
    }, 
    {
      pos: [0, 1, 5], 
      state: 5
    }, 
    {
      pos: [2, 1, 7], 
      state: 5
    }, 
    {
      nbt: {
        target_pool: "minecraft:empty", 
        final_state: "minecraft:structure_void", 
        id: "minecraft:jigsaw", 
        attachement_type: "minecraft:building_entrance"
      }, 
      pos: [3, 1, 8], 
      state: 6
    }, 
    {
      pos: [0, 1, 0], 
      state: 3
    }, 
    {
      pos: [1, 1, 0], 
      state: 7
    }, 
    {
      pos: [2, 1, 0], 
      state: 8
    }, 
    {
      pos: [3, 1, 0], 
      state: 8
    }, 
    {
      pos: [4, 1, 0], 
      state: 3
    }, 
    {
      pos: [6, 1, 0], 
      state: 3
    }, 
    {
      pos: [7, 1, 0], 
      state: 3
    }, 
    {
      pos: [1, 1, 1], 
      state: 9
    }, 
    {
      pos: [2, 1, 1], 
      state: 10
    }, 
    {
      pos: [3, 1, 1], 
      state: 10
    }, 
    {
      pos: [4, 1, 1], 
      state: 11
    }, 
    {
      pos: [5, 1, 1], 
      state: 3
    }, 
    {
      pos: [6, 1, 1], 
      state: 7
    }, 
    {
      pos: [7, 1, 1], 
      state: 3
    }, 
    {
      pos: [0, 1, 2], 
      state: 9
    }, 
    {
      pos: [1, 1, 2], 
      state: 10
    }, 
    {
      pos: [2, 1, 2], 
      state: 10
    }, 
    {
      pos: [3, 1, 2], 
      state: 12
    }, 
    {
      pos: [4, 1, 2], 
      state: 10
    }, 
    {
      pos: [5, 1, 2], 
      state: 11
    }, 
    {
      pos: [6, 1, 2], 
      state: 3
    }, 
    {
      pos: [0, 1, 3], 
      state: 9
    }, 
    {
      pos: [1, 1, 3], 
      state: 10
    }, 
    {
      pos: [2, 1, 3], 
      state: 10
    }, 
    {
      pos: [3, 1, 3], 
      state: 10
    }, 
    {
      pos: [4, 1, 3], 
      state: 10
    }, 
    {
      pos: [5, 1, 3], 
      state: 10
    }, 
    {
      pos: [6, 1, 3], 
      state: 11
    }, 
    {
      pos: [7, 1, 3], 
      state: 3
    }, 
    {
      pos: [0, 1, 4], 
      state: 3
    }, 
    {
      pos: [1, 1, 4], 
      state: 3
    }, 
    {
      pos: [2, 1, 4], 
      state: 13
    }, 
    {
      pos: [3, 1, 4], 
      state: 10
    }, 
    {
      pos: [4, 1, 4], 
      state: 10
    }, 
    {
      pos: [5, 1, 4], 
      state: 10
    }, 
    {
      pos: [6, 1, 4], 
      state: 11
    }, 
    {
      pos: [7, 1, 4], 
      state: 3
    }, 
    {
      pos: [1, 1, 5], 
      state: 3
    }, 
    {
      pos: [2, 1, 5], 
      state: 3
    }, 
    {
      pos: [3, 1, 5], 
      state: 10
    }, 
    {
      pos: [4, 1, 5], 
      state: 12
    }, 
    {
      pos: [5, 1, 5], 
      state: 10
    }, 
    {
      pos: [6, 1, 5], 
      state: 11
    }, 
    {
      pos: [7, 1, 5], 
      state: 14
    }, 
    {
      pos: [0, 1, 6], 
      state: 3
    }, 
    {
      pos: [1, 1, 6], 
      state: 15
    }, 
    {
      pos: [2, 1, 6], 
      state: 3
    }, 
    {
      pos: [3, 1, 6], 
      state: 3
    }, 
    {
      pos: [4, 1, 6], 
      state: 10
    }, 
    {
      pos: [5, 1, 6], 
      state: 10
    }, 
    {
      pos: [6, 1, 6], 
      state: 11
    }, 
    {
      pos: [7, 1, 6], 
      state: 3
    }, 
    {
      pos: [0, 1, 7], 
      state: 7
    }, 
    {
      pos: [1, 1, 7], 
      state: 3
    }, 
    {
      pos: [3, 1, 7], 
      state: 3
    }, 
    {
      pos: [4, 1, 7], 
      state: 3
    }, 
    {
      pos: [5, 1, 7], 
      state: 3
    }, 
    {
      pos: [6, 1, 7], 
      state: 3
    }, 
    {
      pos: [7, 1, 7], 
      state: 3
    }, 
    {
      pos: [0, 1, 8], 
      state: 3
    }, 
    {
      pos: [1, 1, 8], 
      state: 3
    }, 
    {
      pos: [2, 1, 8], 
      state: 3
    }, 
    {
      pos: [4, 1, 8], 
      state: 7
    }, 
    {
      pos: [5, 1, 8], 
      state: 16
    }, 
    {
      pos: [6, 1, 8], 
      state: 15
    }, 
    {
      pos: [7, 1, 8], 
      state: 3
    }, 
    {
      pos: [0, 2, 0], 
      state: 3
    }, 
    {
      pos: [1, 2, 0], 
      state: 17
    }, 
    {
      pos: [2, 2, 0], 
      state: 3
    }, 
    {
      pos: [3, 2, 0], 
      state: 3
    }, 
    {
      pos: [4, 2, 0], 
      state: 3
    }, 
    {
      pos: [5, 2, 0], 
      state: 3
    }, 
    {
      pos: [6, 2, 0], 
      state: 3
    }, 
    {
      pos: [7, 2, 0], 
      state: 3
    }, 
    {
      pos: [0, 2, 1], 
      state: 3
    }, 
    {
      pos: [1, 2, 1], 
      state: 3
    }, 
    {
      pos: [2, 2, 1], 
      state: 18
    }, 
    {
      pos: [3, 2, 1], 
      state: 19
    }, 
    {
      pos: [4, 2, 1], 
      state: 3
    }, 
    {
      pos: [5, 2, 1], 
      state: 3
    }, 
    {
      pos: [6, 2, 1], 
      state: 17
    }, 
    {
      pos: [7, 2, 1], 
      state: 3
    }, 
    {
      pos: [0, 2, 2], 
      state: 3
    }, 
    {
      pos: [1, 2, 2], 
      state: 19
    }, 
    {
      pos: [2, 2, 2], 
      state: 19
    }, 
    {
      pos: [3, 2, 2], 
      state: 3
    }, 
    {
      pos: [4, 2, 2], 
      state: 20
    }, 
    {
      pos: [5, 2, 2], 
      state: 3
    }, 
    {
      pos: [6, 2, 2], 
      state: 3
    }, 
    {
      pos: [7, 2, 2], 
      state: 3
    }, 
    {
      pos: [0, 2, 3], 
      state: 3
    }, 
    {
      pos: [1, 2, 3], 
      state: 19
    }, 
    {
      pos: [2, 2, 3], 
      state: 19
    }, 
    {
      pos: [3, 2, 3], 
      state: 21
    }, 
    {
      pos: [4, 2, 3], 
      state: 19
    }, 
    {
      pos: [5, 2, 3], 
      state: 19
    }, 
    {
      pos: [6, 2, 3], 
      state: 3
    }, 
    {
      pos: [7, 2, 3], 
      state: 3
    }, 
    {
      pos: [0, 2, 4], 
      state: 3
    }, 
    {
      pos: [1, 2, 4], 
      state: 3
    }, 
    {
      pos: [2, 2, 4], 
      state: 3
    }, 
    {
      pos: [3, 2, 4], 
      state: 20
    }, 
    {
      pos: [4, 2, 4], 
      state: 19
    }, 
    {
      pos: [5, 2, 4], 
      state: 19
    }, 
    {
      pos: [6, 2, 4], 
      state: 3
    }, 
    {
      pos: [7, 2, 4], 
      state: 3
    }, 
    {
      pos: [0, 2, 5], 
      state: 3
    }, 
    {
      pos: [1, 2, 5], 
      state: 3
    }, 
    {
      pos: [2, 2, 5], 
      state: 3
    }, 
    {
      pos: [3, 2, 5], 
      state: 19
    }, 
    {
      pos: [4, 2, 5], 
      state: 3
    }, 
    {
      pos: [5, 2, 5], 
      state: 20
    }, 
    {
      pos: [6, 2, 5], 
      state: 3
    }, 
    {
      pos: [7, 2, 5], 
      state: 3
    }, 
    {
      pos: [0, 2, 6], 
      state: 3
    }, 
    {
      pos: [1, 2, 6], 
      state: 15
    }, 
    {
      pos: [2, 2, 6], 
      state: 3
    }, 
    {
      pos: [3, 2, 6], 
      state: 3
    }, 
    {
      pos: [4, 2, 6], 
      state: 19
    }, 
    {
      pos: [5, 2, 6], 
      state: 20
    }, 
    {
      pos: [6, 2, 6], 
      state: 3
    }, 
    {
      pos: [7, 2, 6], 
      state: 3
    }, 
    {
      pos: [0, 2, 7], 
      state: 17
    }, 
    {
      pos: [1, 2, 7], 
      state: 3
    }, 
    {
      pos: [2, 2, 7], 
      state: 3
    }, 
    {
      pos: [3, 2, 7], 
      state: 3
    }, 
    {
      pos: [4, 2, 7], 
      state: 3
    }, 
    {
      pos: [5, 2, 7], 
      state: 3
    }, 
    {
      pos: [6, 2, 7], 
      state: 3
    }, 
    {
      pos: [7, 2, 7], 
      state: 3
    }, 
    {
      pos: [0, 2, 8], 
      state: 3
    }, 
    {
      pos: [1, 2, 8], 
      state: 3
    }, 
    {
      pos: [2, 2, 8], 
      state: 3
    }, 
    {
      pos: [3, 2, 8], 
      state: 3
    }, 
    {
      pos: [4, 2, 8], 
      state: 17
    }, 
    {
      pos: [5, 2, 8], 
      state: 3
    }, 
    {
      pos: [6, 2, 8], 
      state: 15
    }, 
    {
      pos: [7, 2, 8], 
      state: 3
    }, 
    {
      pos: [0, 3, 0], 
      state: 3
    }, 
    {
      pos: [1, 3, 0], 
      state: 3
    }, 
    {
      pos: [2, 3, 0], 
      state: 3
    }, 
    {
      pos: [3, 3, 0], 
      state: 3
    }, 
    {
      pos: [4, 3, 0], 
      state: 3
    }, 
    {
      pos: [5, 3, 0], 
      state: 3
    }, 
    {
      pos: [6, 3, 0], 
      state: 3
    }, 
    {
      pos: [7, 3, 0], 
      state: 3
    }, 
    {
      pos: [0, 3, 1], 
      state: 3
    }, 
    {
      pos: [1, 3, 1], 
      state: 3
    }, 
    {
      pos: [2, 3, 1], 
      state: 3
    }, 
    {
      pos: [3, 3, 1], 
      state: 3
    }, 
    {
      pos: [4, 3, 1], 
      state: 3
    }, 
    {
      pos: [5, 3, 1], 
      state: 3
    }, 
    {
      pos: [6, 3, 1], 
      state: 3
    }, 
    {
      pos: [7, 3, 1], 
      state: 3
    }, 
    {
      pos: [0, 3, 2], 
      state: 3
    }, 
    {
      pos: [1, 3, 2], 
      state: 3
    }, 
    {
      pos: [2, 3, 2], 
      state: 3
    }, 
    {
      pos: [3, 3, 2], 
      state: 3
    }, 
    {
      pos: [4, 3, 2], 
      state: 3
    }, 
    {
      pos: [5, 3, 2], 
      state: 3
    }, 
    {
      pos: [6, 3, 2], 
      state: 3
    }, 
    {
      pos: [7, 3, 2], 
      state: 3
    }, 
    {
      pos: [0, 3, 3], 
      state: 3
    }, 
    {
      pos: [1, 3, 3], 
      state: 3
    }, 
    {
      pos: [2, 3, 3], 
      state: 3
    }, 
    {
      pos: [3, 3, 3], 
      state: 3
    }, 
    {
      pos: [4, 3, 3], 
      state: 3
    }, 
    {
      pos: [5, 3, 3], 
      state: 3
    }, 
    {
      pos: [6, 3, 3], 
      state: 3
    }, 
    {
      pos: [7, 3, 3], 
      state: 3
    }, 
    {
      pos: [0, 3, 4], 
      state: 3
    }, 
    {
      pos: [1, 3, 4], 
      state: 3
    }, 
    {
      pos: [2, 3, 4], 
      state: 3
    }, 
    {
      pos: [3, 3, 4], 
      state: 3
    }, 
    {
      pos: [4, 3, 4], 
      state: 3
    }, 
    {
      pos: [5, 3, 4], 
      state: 3
    }, 
    {
      pos: [6, 3, 4], 
      state: 3
    }, 
    {
      pos: [7, 3, 4], 
      state: 3
    }, 
    {
      pos: [0, 3, 5], 
      state: 3
    }, 
    {
      pos: [1, 3, 5], 
      state: 3
    }, 
    {
      pos: [2, 3, 5], 
      state: 3
    }, 
    {
      pos: [3, 3, 5], 
      state: 3
    }, 
    {
      pos: [4, 3, 5], 
      state: 3
    }, 
    {
      pos: [5, 3, 5], 
      state: 3
    }, 
    {
      pos: [6, 3, 5], 
      state: 3
    }, 
    {
      pos: [7, 3, 5], 
      state: 3
    }, 
    {
      pos: [0, 3, 6], 
      state: 3
    }, 
    {
      pos: [1, 3, 6], 
      state: 22
    }, 
    {
      pos: [2, 3, 6], 
      state: 3
    }, 
    {
      pos: [3, 3, 6], 
      state: 3
    }, 
    {
      pos: [4, 3, 6], 
      state: 3
    }, 
    {
      pos: [5, 3, 6], 
      state: 3
    }, 
    {
      pos: [6, 3, 6], 
      state: 3
    }, 
    {
      pos: [7, 3, 6], 
      state: 3
    }, 
    {
      pos: [0, 3, 7], 
      state: 3
    }, 
    {
      pos: [1, 3, 7], 
      state: 3
    }, 
    {
      pos: [2, 3, 7], 
      state: 3
    }, 
    {
      pos: [3, 3, 7], 
      state: 3
    }, 
    {
      pos: [4, 3, 7], 
      state: 3
    }, 
    {
      pos: [5, 3, 7], 
      state: 3
    }, 
    {
      pos: [6, 3, 7], 
      state: 3
    }, 
    {
      pos: [7, 3, 7], 
      state: 3
    }, 
    {
      pos: [0, 3, 8], 
      state: 3
    }, 
    {
      pos: [1, 3, 8], 
      state: 3
    }, 
    {
      pos: [2, 3, 8], 
      state: 3
    }, 
    {
      pos: [3, 3, 8], 
      state: 3
    }, 
    {
      pos: [4, 3, 8], 
      state: 3
    }, 
    {
      pos: [5, 3, 8], 
      state: 3
    }, 
    {
      pos: [6, 3, 8], 
      state: 22
    }, 
    {
      pos: [7, 3, 8], 
      state: 3
    }
  ], 
  palette: [
    {
      Properties: {
        snowy: "false"
      }, 
      Name: "minecraft:grass_block"
    }, 
    {
      Name: "minecraft:dirt"
    }, 
    {
      Properties: {
        facing: "up"
      }, 
      Name: "minecraft:jigsaw"
    }, 
    {
      Name: "minecraft:air"
    }, 
    {
      Name: "minecraft:grass_path"
    }, 
    {
      Name: "minecraft:pumpkin"
    }, 
    {
      Properties: {
        facing: "south"
      }, 
      Name: "minecraft:jigsaw"
    }, 
    {
      Properties: {
        half: "lower"
      }, 
      Name: "minecraft:large_fern"
    }, 
    {
      Properties: {
        half: "bottom", 
        waterlogged: "false", 
        powered: "false", 
        facing: "north", 
        open: "true"
      }, 
      Name: "minecraft:spruce_trapdoor"
    }, 
    {
      Properties: {
        half: "bottom", 
        waterlogged: "false", 
        powered: "false", 
        facing: "west", 
        open: "true"
      }, 
      Name: "minecraft:spruce_trapdoor"
    }, 
    {
      Properties: {
        moisture: "7"
      }, 
      Name: "minecraft:farmland"
    }, 
    {
      Properties: {
        half: "bottom", 
        waterlogged: "false", 
        powered: "false", 
        facing: "east", 
        open: "true"
      }, 
      Name: "minecraft:spruce_trapdoor"
    }, 
    {
      Properties: {
        level: "0"
      }, 
      Name: "minecraft:water"
    }, 
    {
      Properties: {
        half: "bottom", 
        waterlogged: "false", 
        shape: "straight", 
        facing: "north"
      }, 
      Name: "minecraft:cobblestone_stairs"
    }, 
    {
      Name: "minecraft:fern"
    }, 
    {
      Properties: {
        east: "none", 
        waterlogged: "false", 
        south: "none", 
        north: "none", 
        west: "none", 
        up: "true"
      }, 
      Name: "minecraft:cobblestone_wall"
    }, 
    {
      Properties: {
        level: "0"
      }, 
      Name: "minecraft:composter"
    }, 
    {
      Properties: {
        half: "upper"
      }, 
      Name: "minecraft:large_fern"
    }, 
    {
      Properties: {
        age: "3"
      }, 
      Name: "minecraft:wheat"
    }, 
    {
      Properties: {
        age: "7"
      }, 
      Name: "minecraft:wheat"
    }, 
    {
      Properties: {
        age: "0"
      }, 
      Name: "minecraft:wheat"
    }, 
    {
      Properties: {
        age: "1"
      }, 
      Name: "minecraft:wheat"
    }, 
    {
      Name: "minecraft:torch"
    }
  ]
}
