{
  size: [3, 12, 3], 
  entities: [], 
  blocks: [
    {
      pos: [0, 0, 0], 
      state: 0
    }, 
    {
      pos: [0, 0, 1], 
      state: 0
    }, 
    {
      pos: [0, 0, 2], 
      state: 0
    }, 
    {
      pos: [1, 0, 0], 
      state: 0
    }, 
    {
      pos: [1, 0, 2], 
      state: 0
    }, 
    {
      pos: [2, 0, 0], 
      state: 0
    }, 
    {
      pos: [2, 0, 1], 
      state: 0
    }, 
    {
      pos: [2, 0, 2], 
      state: 0
    }, 
    {
      pos: [0, 5, 0], 
      state: 1
    }, 
    {
      pos: [0, 5, 1], 
      state: 1
    }, 
    {
      pos: [0, 5, 2], 
      state: 1
    }, 
    {
      pos: [1, 5, 0], 
      state: 1
    }, 
    {
      pos: [1, 5, 1], 
      state: 1
    }, 
    {
      pos: [1, 5, 2], 
      state: 1
    }, 
    {
      pos: [2, 5, 0], 
      state: 1
    }, 
    {
      pos: [2, 5, 1], 
      state: 1
    }, 
    {
      pos: [2, 5, 2], 
      state: 1
    }, 
    {
      pos: [0, 6, 0], 
      state: 2
    }, 
    {
      pos: [0, 6, 1], 
      state: 2
    }, 
    {
      pos: [0, 6, 2], 
      state: 2
    }, 
    {
      pos: [1, 6, 0], 
      state: 2
    }, 
    {
      pos: [1, 6, 1], 
      state: 3
    }, 
    {
      pos: [1, 6, 2], 
      state: 2
    }, 
    {
      pos: [2, 6, 0], 
      state: 2
    }, 
    {
      pos: [2, 6, 1], 
      state: 2
    }, 
    {
      pos: [2, 6, 2], 
      state: 2
    }, 
    {
      pos: [0, 7, 0], 
      state: 3
    }, 
    {
      pos: [0, 7, 1], 
      state: 3
    }, 
    {
      pos: [0, 7, 2], 
      state: 3
    }, 
    {
      pos: [1, 7, 0], 
      state: 3
    }, 
    {
      pos: [1, 7, 1], 
      state: 3
    }, 
    {
      pos: [1, 7, 2], 
      state: 3
    }, 
    {
      pos: [2, 7, 0], 
      state: 3
    }, 
    {
      pos: [2, 7, 1], 
      state: 3
    }, 
    {
      pos: [2, 7, 2], 
      state: 3
    }, 
    {
      pos: [0, 8, 0], 
      state: 3
    }, 
    {
      pos: [0, 8, 1], 
      state: 3
    }, 
    {
      pos: [0, 8, 2], 
      state: 3
    }, 
    {
      pos: [1, 8, 0], 
      state: 3
    }, 
    {
      pos: [1, 8, 1], 
      state: 3
    }, 
    {
      pos: [1, 8, 2], 
      state: 3
    }, 
    {
      pos: [2, 8, 0], 
      state: 3
    }, 
    {
      pos: [2, 8, 1], 
      state: 3
    }, 
    {
      pos: [2, 8, 2], 
      state: 3
    }, 
    {
      pos: [0, 9, 0], 
      state: 4
    }, 
    {
      pos: [0, 9, 1], 
      state: 4
    }, 
    {
      pos: [0, 9, 2], 
      state: 4
    }, 
    {
      pos: [1, 9, 0], 
      state: 4
    }, 
    {
      pos: [1, 9, 1], 
      state: 3
    }, 
    {
      pos: [1, 9, 2], 
      state: 4
    }, 
    {
      pos: [2, 9, 0], 
      state: 4
    }, 
    {
      pos: [2, 9, 1], 
      state: 4
    }, 
    {
      pos: [2, 9, 2], 
      state: 4
    }, 
    {
      pos: [0, 10, 0], 
      state: 2
    }, 
    {
      pos: [0, 10, 1], 
      state: 2
    }, 
    {
      pos: [0, 10, 2], 
      state: 2
    }, 
    {
      pos: [1, 10, 0], 
      state: 2
    }, 
    {
      pos: [1, 10, 1], 
      state: 0
    }, 
    {
      pos: [1, 10, 2], 
      state: 2
    }, 
    {
      pos: [2, 10, 0], 
      state: 2
    }, 
    {
      pos: [2, 10, 1], 
      state: 2
    }, 
    {
      pos: [2, 10, 2], 
      state: 2
    }, 
    {
      pos: [0, 11, 0], 
      state: 3
    }, 
    {
      pos: [0, 11, 1], 
      state: 3
    }, 
    {
      pos: [0, 11, 2], 
      state: 3
    }, 
    {
      pos: [1, 11, 0], 
      state: 3
    }, 
    {
      pos: [1, 11, 1], 
      state: 3
    }, 
    {
      pos: [1, 11, 2], 
      state: 3
    }, 
    {
      pos: [2, 11, 0], 
      state: 3
    }, 
    {
      pos: [2, 11, 1], 
      state: 3
    }, 
    {
      pos: [2, 11, 2], 
      state: 3
    }, 
    {
      pos: [0, 1, 0], 
      state: 5
    }, 
    {
      pos: [0, 1, 1], 
      state: 5
    }, 
    {
      pos: [0, 1, 2], 
      state: 5
    }, 
    {
      pos: [1, 1, 0], 
      state: 5
    }, 
    {
      pos: [1, 1, 1], 
      state: 5
    }, 
    {
      pos: [1, 1, 2], 
      state: 5
    }, 
    {
      pos: [2, 1, 0], 
      state: 5
    }, 
    {
      pos: [2, 1, 1], 
      state: 5
    }, 
    {
      pos: [2, 1, 2], 
      state: 5
    }, 
    {
      pos: [0, 2, 0], 
      state: 5
    }, 
    {
      pos: [0, 2, 1], 
      state: 5
    }, 
    {
      pos: [0, 2, 2], 
      state: 5
    }, 
    {
      pos: [1, 2, 0], 
      state: 5
    }, 
    {
      pos: [1, 2, 1], 
      state: 5
    }, 
    {
      pos: [1, 2, 2], 
      state: 5
    }, 
    {
      pos: [2, 2, 0], 
      state: 5
    }, 
    {
      pos: [2, 2, 1], 
      state: 5
    }, 
    {
      pos: [2, 2, 2], 
      state: 5
    }, 
    {
      pos: [0, 3, 0], 
      state: 5
    }, 
    {
      pos: [0, 3, 1], 
      state: 5
    }, 
    {
      pos: [0, 3, 2], 
      state: 5
    }, 
    {
      pos: [1, 3, 0], 
      state: 5
    }, 
    {
      pos: [1, 3, 1], 
      state: 5
    }, 
    {
      pos: [1, 3, 2], 
      state: 5
    }, 
    {
      pos: [2, 3, 0], 
      state: 5
    }, 
    {
      pos: [2, 3, 1], 
      state: 5
    }, 
    {
      pos: [2, 3, 2], 
      state: 5
    }, 
    {
      pos: [0, 4, 0], 
      state: 5
    }, 
    {
      pos: [0, 4, 1], 
      state: 5
    }, 
    {
      pos: [0, 4, 2], 
      state: 5
    }, 
    {
      pos: [1, 4, 0], 
      state: 5
    }, 
    {
      pos: [1, 4, 1], 
      state: 5
    }, 
    {
      pos: [1, 4, 2], 
      state: 5
    }, 
    {
      pos: [2, 4, 0], 
      state: 5
    }, 
    {
      pos: [2, 4, 1], 
      state: 5
    }, 
    {
      pos: [2, 4, 2], 
      state: 5
    }, 
    {
      nbt: {
        joint: "rollable", 
        final_state: "minecraft:waxed_oxidized_copper", 
        name: "minecraft:lower_addon", 
        placement_priority: 0, 
        pool: "minecraft:empty", 
        selection_priority: 0, 
        id: "minecraft:jigsaw", 
        target: "minecraft:empty"
      }, 
      pos: [1, 0, 1], 
      state: 6
    }
  ], 
  palette: [
    {
      Name: "minecraft:waxed_oxidized_copper"
    }, 
    {
      Name: "minecraft:polished_tuff"
    }, 
    {
      Name: "minecraft:waxed_copper_block"
    }, 
    {
      Name: "minecraft:tuff_bricks"
    }, 
    {
      Name: "minecraft:chiseled_tuff_bricks"
    }, 
    {
      Name: "minecraft:air"
    }, 
    {
      Properties: {
        orientation: "down_west"
      }, 
      Name: "minecraft:jigsaw"
    }
  ]
}
