{
  size: [7, 8, 15], 
  entities: [], 
  blocks: [
    {
      pos: [0, 0, 0], 
      state: 0
    }, 
    {
      pos: [1, 0, 0], 
      state: 0
    }, 
    {
      pos: [2, 0, 0], 
      state: 0
    }, 
    {
      pos: [3, 0, 0], 
      state: 0
    }, 
    {
      pos: [4, 0, 0], 
      state: 0
    }, 
    {
      pos: [5, 0, 0], 
      state: 0
    }, 
    {
      pos: [6, 0, 0], 
      state: 0
    }, 
    {
      pos: [0, 0, 1], 
      state: 0
    }, 
    {
      pos: [1, 0, 1], 
      state: 0
    }, 
    {
      pos: [2, 0, 1], 
      state: 0
    }, 
    {
      pos: [3, 0, 1], 
      state: 0
    }, 
    {
      pos: [4, 0, 1], 
      state: 0
    }, 
    {
      pos: [5, 0, 1], 
      state: 0
    }, 
    {
      pos: [6, 0, 1], 
      state: 0
    }, 
    {
      pos: [0, 0, 2], 
      state: 0
    }, 
    {
      pos: [1, 0, 2], 
      state: 0
    }, 
    {
      pos: [2, 0, 2], 
      state: 0
    }, 
    {
      pos: [3, 0, 2], 
      state: 0
    }, 
    {
      pos: [4, 0, 2], 
      state: 0
    }, 
    {
      pos: [5, 0, 2], 
      state: 0
    }, 
    {
      pos: [6, 0, 2], 
      state: 0
    }, 
    {
      pos: [0, 0, 3], 
      state: 0
    }, 
    {
      pos: [1, 0, 3], 
      state: 0
    }, 
    {
      pos: [2, 0, 3], 
      state: 0
    }, 
    {
      pos: [3, 0, 3], 
      state: 0
    }, 
    {
      pos: [4, 0, 3], 
      state: 0
    }, 
    {
      pos: [5, 0, 3], 
      state: 0
    }, 
    {
      pos: [6, 0, 3], 
      state: 0
    }, 
    {
      pos: [0, 0, 4], 
      state: 0
    }, 
    {
      pos: [1, 0, 4], 
      state: 0
    }, 
    {
      pos: [2, 0, 4], 
      state: 0
    }, 
    {
      pos: [3, 0, 4], 
      state: 0
    }, 
    {
      pos: [4, 0, 4], 
      state: 0
    }, 
    {
      pos: [5, 0, 4], 
      state: 0
    }, 
    {
      pos: [6, 0, 4], 
      state: 0
    }, 
    {
      pos: [0, 0, 5], 
      state: 0
    }, 
    {
      pos: [1, 0, 5], 
      state: 0
    }, 
    {
      pos: [2, 0, 5], 
      state: 0
    }, 
    {
      pos: [3, 0, 5], 
      state: 0
    }, 
    {
      pos: [4, 0, 5], 
      state: 0
    }, 
    {
      pos: [5, 0, 5], 
      state: 0
    }, 
    {
      pos: [6, 0, 5], 
      state: 0
    }, 
    {
      pos: [0, 0, 6], 
      state: 0
    }, 
    {
      pos: [1, 0, 6], 
      state: 0
    }, 
    {
      pos: [2, 0, 6], 
      state: 0
    }, 
    {
      pos: [3, 0, 6], 
      state: 0
    }, 
    {
      pos: [4, 0, 6], 
      state: 0
    }, 
    {
      pos: [5, 0, 6], 
      state: 0
    }, 
    {
      pos: [6, 0, 6], 
      state: 0
    }, 
    {
      pos: [0, 0, 7], 
      state: 0
    }, 
    {
      pos: [1, 0, 7], 
      state: 0
    }, 
    {
      pos: [2, 0, 7], 
      state: 0
    }, 
    {
      pos: [3, 0, 7], 
      state: 0
    }, 
    {
      pos: [4, 0, 7], 
      state: 0
    }, 
    {
      pos: [5, 0, 7], 
      state: 0
    }, 
    {
      pos: [6, 0, 7], 
      state: 0
    }, 
    {
      pos: [0, 0, 8], 
      state: 0
    }, 
    {
      pos: [1, 0, 8], 
      state: 0
    }, 
    {
      pos: [2, 0, 8], 
      state: 0
    }, 
    {
      pos: [3, 0, 8], 
      state: 0
    }, 
    {
      pos: [4, 0, 8], 
      state: 0
    }, 
    {
      pos: [5, 0, 8], 
      state: 0
    }, 
    {
      pos: [6, 0, 8], 
      state: 0
    }, 
    {
      pos: [0, 0, 9], 
      state: 0
    }, 
    {
      pos: [1, 0, 9], 
      state: 0
    }, 
    {
      pos: [2, 0, 9], 
      state: 0
    }, 
    {
      pos: [3, 0, 9], 
      state: 0
    }, 
    {
      pos: [4, 0, 9], 
      state: 0
    }, 
    {
      pos: [5, 0, 9], 
      state: 0
    }, 
    {
      pos: [6, 0, 9], 
      state: 0
    }, 
    {
      pos: [0, 0, 10], 
      state: 0
    }, 
    {
      pos: [1, 0, 10], 
      state: 0
    }, 
    {
      pos: [2, 0, 10], 
      state: 0
    }, 
    {
      pos: [3, 0, 10], 
      state: 0
    }, 
    {
      pos: [4, 0, 10], 
      state: 0
    }, 
    {
      pos: [5, 0, 10], 
      state: 0
    }, 
    {
      pos: [6, 0, 10], 
      state: 0
    }, 
    {
      pos: [0, 0, 11], 
      state: 0
    }, 
    {
      pos: [1, 0, 11], 
      state: 0
    }, 
    {
      pos: [2, 0, 11], 
      state: 0
    }, 
    {
      pos: [3, 0, 11], 
      state: 0
    }, 
    {
      pos: [4, 0, 11], 
      state: 0
    }, 
    {
      pos: [5, 0, 11], 
      state: 0
    }, 
    {
      pos: [6, 0, 11], 
      state: 0
    }, 
    {
      pos: [0, 0, 12], 
      state: 0
    }, 
    {
      pos: [1, 0, 12], 
      state: 0
    }, 
    {
      pos: [2, 0, 12], 
      state: 0
    }, 
    {
      pos: [3, 0, 12], 
      state: 0
    }, 
    {
      pos: [4, 0, 12], 
      state: 0
    }, 
    {
      pos: [5, 0, 12], 
      state: 0
    }, 
    {
      pos: [6, 0, 12], 
      state: 0
    }, 
    {
      pos: [0, 0, 13], 
      state: 0
    }, 
    {
      pos: [1, 0, 13], 
      state: 0
    }, 
    {
      pos: [2, 0, 13], 
      state: 0
    }, 
    {
      pos: [3, 0, 13], 
      state: 0
    }, 
    {
      pos: [4, 0, 13], 
      state: 0
    }, 
    {
      pos: [5, 0, 13], 
      state: 0
    }, 
    {
      pos: [6, 0, 13], 
      state: 0
    }, 
    {
      pos: [0, 0, 14], 
      state: 0
    }, 
    {
      pos: [1, 0, 14], 
      state: 0
    }, 
    {
      pos: [2, 0, 14], 
      state: 0
    }, 
    {
      pos: [3, 0, 14], 
      state: 0
    }, 
    {
      pos: [4, 0, 14], 
      state: 0
    }, 
    {
      pos: [5, 0, 14], 
      state: 0
    }, 
    {
      pos: [6, 0, 14], 
      state: 0
    }, 
    {
      pos: [0, 1, 0], 
      state: 1
    }, 
    {
      pos: [1, 1, 0], 
      state: 1
    }, 
    {
      pos: [2, 1, 0], 
      state: 1
    }, 
    {
      pos: [3, 1, 0], 
      state: 1
    }, 
    {
      pos: [4, 1, 0], 
      state: 1
    }, 
    {
      pos: [5, 1, 0], 
      state: 1
    }, 
    {
      pos: [6, 1, 0], 
      state: 1
    }, 
    {
      pos: [0, 1, 1], 
      state: 1
    }, 
    {
      pos: [6, 1, 1], 
      state: 2
    }, 
    {
      pos: [0, 1, 2], 
      state: 1
    }, 
    {
      pos: [0, 1, 3], 
      state: 1
    }, 
    {
      pos: [0, 1, 4], 
      state: 1
    }, 
    {
      pos: [0, 1, 5], 
      state: 1
    }, 
    {
      pos: [3, 1, 5], 
      state: 2
    }, 
    {
      pos: [4, 1, 5], 
      state: 1
    }, 
    {
      pos: [6, 1, 5], 
      state: 2
    }, 
    {
      pos: [0, 1, 6], 
      state: 1
    }, 
    {
      pos: [3, 1, 6], 
      state: 2
    }, 
    {
      pos: [4, 1, 6], 
      state: 1
    }, 
    {
      pos: [6, 1, 6], 
      state: 1
    }, 
    {
      pos: [0, 1, 7], 
      state: 1
    }, 
    {
      pos: [6, 1, 7], 
      state: 1
    }, 
    {
      pos: [0, 1, 8], 
      state: 1
    }, 
    {
      pos: [3, 1, 8], 
      state: 2
    }, 
    {
      pos: [4, 1, 8], 
      state: 1
    }, 
    {
      pos: [6, 1, 8], 
      state: 1
    }, 
    {
      pos: [0, 1, 9], 
      state: 1
    }, 
    {
      pos: [3, 1, 9], 
      state: 2
    }, 
    {
      pos: [4, 1, 9], 
      state: 1
    }, 
    {
      pos: [6, 1, 9], 
      state: 1
    }, 
    {
      pos: [0, 1, 10], 
      state: 1
    }, 
    {
      pos: [6, 1, 10], 
      state: 1
    }, 
    {
      pos: [0, 1, 11], 
      state: 1
    }, 
    {
      pos: [1, 1, 11], 
      state: 2
    }, 
    {
      pos: [2, 1, 11], 
      state: 2
    }, 
    {
      pos: [3, 1, 11], 
      state: 2
    }, 
    {
      pos: [6, 1, 11], 
      state: 1
    }, 
    {
      pos: [0, 1, 12], 
      state: 1
    }, 
    {
      pos: [1, 1, 12], 
      state: 1
    }, 
    {
      pos: [2, 1, 12], 
      state: 1
    }, 
    {
      pos: [3, 1, 12], 
      state: 1
    }, 
    {
      pos: [6, 1, 12], 
      state: 1
    }, 
    {
      pos: [0, 1, 13], 
      state: 1
    }, 
    {
      pos: [1, 1, 13], 
      state: 1
    }, 
    {
      pos: [2, 1, 13], 
      state: 1
    }, 
    {
      pos: [3, 1, 13], 
      state: 1
    }, 
    {
      pos: [4, 1, 13], 
      state: 1
    }, 
    {
      pos: [6, 1, 13], 
      state: 1
    }, 
    {
      pos: [0, 1, 14], 
      state: 1
    }, 
    {
      pos: [1, 1, 14], 
      state: 1
    }, 
    {
      pos: [2, 1, 14], 
      state: 1
    }, 
    {
      pos: [3, 1, 14], 
      state: 1
    }, 
    {
      pos: [4, 1, 14], 
      state: 1
    }, 
    {
      pos: [5, 1, 14], 
      state: 1
    }, 
    {
      pos: [6, 1, 14], 
      state: 1
    }, 
    {
      pos: [1, 1, 1], 
      state: 3
    }, 
    {
      pos: [2, 1, 1], 
      state: 3
    }, 
    {
      pos: [3, 1, 1], 
      state: 3
    }, 
    {
      pos: [4, 1, 1], 
      state: 3
    }, 
    {
      pos: [5, 1, 1], 
      state: 3
    }, 
    {
      pos: [1, 1, 2], 
      state: 3
    }, 
    {
      pos: [2, 1, 2], 
      state: 3
    }, 
    {
      pos: [3, 1, 2], 
      state: 3
    }, 
    {
      pos: [4, 1, 2], 
      state: 3
    }, 
    {
      pos: [5, 1, 2], 
      state: 3
    }, 
    {
      pos: [6, 1, 2], 
      state: 3
    }, 
    {
      pos: [1, 1, 3], 
      state: 3
    }, 
    {
      pos: [2, 1, 3], 
      state: 3
    }, 
    {
      pos: [3, 1, 3], 
      state: 3
    }, 
    {
      pos: [4, 1, 3], 
      state: 3
    }, 
    {
      pos: [5, 1, 3], 
      state: 3
    }, 
    {
      pos: [6, 1, 3], 
      state: 3
    }, 
    {
      pos: [1, 1, 4], 
      state: 3
    }, 
    {
      pos: [2, 1, 4], 
      state: 3
    }, 
    {
      pos: [3, 1, 4], 
      state: 3
    }, 
    {
      pos: [4, 1, 4], 
      state: 3
    }, 
    {
      pos: [5, 1, 4], 
      state: 3
    }, 
    {
      pos: [6, 1, 4], 
      state: 3
    }, 
    {
      pos: [1, 1, 5], 
      state: 3
    }, 
    {
      pos: [2, 1, 5], 
      state: 3
    }, 
    {
      pos: [5, 1, 5], 
      state: 3
    }, 
    {
      pos: [1, 1, 6], 
      state: 3
    }, 
    {
      pos: [2, 1, 6], 
      state: 3
    }, 
    {
      pos: [5, 1, 6], 
      state: 3
    }, 
    {
      pos: [1, 1, 7], 
      state: 3
    }, 
    {
      pos: [2, 1, 7], 
      state: 3
    }, 
    {
      pos: [3, 1, 7], 
      state: 3
    }, 
    {
      pos: [4, 1, 7], 
      state: 3
    }, 
    {
      pos: [5, 1, 7], 
      state: 3
    }, 
    {
      pos: [1, 1, 8], 
      state: 3
    }, 
    {
      pos: [2, 1, 8], 
      state: 3
    }, 
    {
      pos: [5, 1, 8], 
      state: 3
    }, 
    {
      pos: [1, 1, 9], 
      state: 3
    }, 
    {
      pos: [2, 1, 9], 
      state: 3
    }, 
    {
      pos: [5, 1, 9], 
      state: 3
    }, 
    {
      pos: [1, 1, 10], 
      state: 3
    }, 
    {
      pos: [2, 1, 10], 
      state: 3
    }, 
    {
      pos: [3, 1, 10], 
      state: 3
    }, 
    {
      pos: [4, 1, 10], 
      state: 3
    }, 
    {
      pos: [5, 1, 10], 
      state: 3
    }, 
    {
      pos: [4, 1, 11], 
      state: 3
    }, 
    {
      pos: [5, 1, 11], 
      state: 3
    }, 
    {
      pos: [4, 1, 12], 
      state: 3
    }, 
    {
      pos: [5, 1, 12], 
      state: 3
    }, 
    {
      pos: [5, 1, 13], 
      state: 3
    }, 
    {
      pos: [0, 2, 0], 
      state: 1
    }, 
    {
      pos: [1, 2, 0], 
      state: 1
    }, 
    {
      pos: [2, 2, 0], 
      state: 1
    }, 
    {
      pos: [3, 2, 0], 
      state: 1
    }, 
    {
      pos: [4, 2, 0], 
      state: 1
    }, 
    {
      pos: [5, 2, 0], 
      state: 1
    }, 
    {
      pos: [6, 2, 0], 
      state: 1
    }, 
    {
      pos: [0, 2, 1], 
      state: 1
    }, 
    {
      pos: [6, 2, 1], 
      state: 2
    }, 
    {
      pos: [0, 2, 2], 
      state: 1
    }, 
    {
      pos: [0, 2, 3], 
      state: 1
    }, 
    {
      pos: [0, 2, 4], 
      state: 1
    }, 
    {
      pos: [0, 2, 5], 
      state: 1
    }, 
    {
      pos: [4, 2, 5], 
      state: 1
    }, 
    {
      pos: [6, 2, 5], 
      state: 2
    }, 
    {
      pos: [0, 2, 6], 
      state: 1
    }, 
    {
      pos: [4, 2, 6], 
      state: 1
    }, 
    {
      pos: [6, 2, 6], 
      state: 1
    }, 
    {
      pos: [0, 2, 7], 
      state: 1
    }, 
    {
      pos: [6, 2, 7], 
      state: 1
    }, 
    {
      pos: [0, 2, 8], 
      state: 1
    }, 
    {
      pos: [4, 2, 8], 
      state: 1
    }, 
    {
      pos: [6, 2, 8], 
      state: 1
    }, 
    {
      pos: [0, 2, 9], 
      state: 1
    }, 
    {
      pos: [4, 2, 9], 
      state: 1
    }, 
    {
      pos: [6, 2, 9], 
      state: 1
    }, 
    {
      pos: [0, 2, 10], 
      state: 1
    }, 
    {
      pos: [6, 2, 10], 
      state: 1
    }, 
    {
      pos: [0, 2, 11], 
      state: 1
    }, 
    {
      pos: [6, 2, 11], 
      state: 1
    }, 
    {
      pos: [0, 2, 12], 
      state: 1
    }, 
    {
      pos: [1, 2, 12], 
      state: 1
    }, 
    {
      pos: [2, 2, 12], 
      state: 1
    }, 
    {
      pos: [3, 2, 12], 
      state: 1
    }, 
    {
      pos: [6, 2, 12], 
      state: 1
    }, 
    {
      pos: [0, 2, 13], 
      state: 1
    }, 
    {
      pos: [3, 2, 13], 
      state: 1
    }, 
    {
      pos: [6, 2, 13], 
      state: 1
    }, 
    {
      pos: [0, 2, 14], 
      state: 1
    }, 
    {
      pos: [1, 2, 14], 
      state: 1
    }, 
    {
      pos: [2, 2, 14], 
      state: 1
    }, 
    {
      pos: [3, 2, 14], 
      state: 1
    }, 
    {
      pos: [4, 2, 14], 
      state: 1
    }, 
    {
      pos: [5, 2, 14], 
      state: 1
    }, 
    {
      pos: [6, 2, 14], 
      state: 1
    }, 
    {
      nbt: {
        metadata: "Warrior", 
        mirror: "NONE", 
        ignoreEntities: 1b, 
        powered: 0b, 
        seed: 0L, 
        author: "Player855", 
        rotation: "NONE", 
        mode: "DATA", 
        posX: 0, 
        posY: 1, 
        sizeX: 0, 
        integrity: 1.0f, 
        posZ: 0, 
        showair: 0b, 
        name: "", 
        id: "minecraft:structure_block", 
        sizeY: 0, 
        showboundingbox: 0b, 
        sizeZ: 0
      }, 
      pos: [3, 2, 8], 
      state: 4
    }, 
    {
      pos: [1, 2, 1], 
      state: 5
    }, 
    {
      pos: [2, 2, 1], 
      state: 5
    }, 
    {
      pos: [3, 2, 1], 
      state: 5
    }, 
    {
      pos: [4, 2, 1], 
      state: 5
    }, 
    {
      pos: [5, 2, 1], 
      state: 5
    }, 
    {
      pos: [1, 2, 2], 
      state: 5
    }, 
    {
      pos: [2, 2, 2], 
      state: 5
    }, 
    {
      pos: [3, 2, 2], 
      state: 5
    }, 
    {
      pos: [4, 2, 2], 
      state: 5
    }, 
    {
      pos: [5, 2, 2], 
      state: 5
    }, 
    {
      pos: [6, 2, 2], 
      state: 5
    }, 
    {
      pos: [1, 2, 3], 
      state: 5
    }, 
    {
      pos: [2, 2, 3], 
      state: 5
    }, 
    {
      pos: [3, 2, 3], 
      state: 5
    }, 
    {
      pos: [4, 2, 3], 
      state: 5
    }, 
    {
      pos: [5, 2, 3], 
      state: 5
    }, 
    {
      pos: [6, 2, 3], 
      state: 5
    }, 
    {
      pos: [1, 2, 4], 
      state: 5
    }, 
    {
      pos: [2, 2, 4], 
      state: 5
    }, 
    {
      pos: [3, 2, 4], 
      state: 5
    }, 
    {
      pos: [4, 2, 4], 
      state: 5
    }, 
    {
      pos: [5, 2, 4], 
      state: 5
    }, 
    {
      pos: [6, 2, 4], 
      state: 5
    }, 
    {
      pos: [1, 2, 5], 
      state: 5
    }, 
    {
      pos: [2, 2, 5], 
      state: 5
    }, 
    {
      pos: [3, 2, 5], 
      state: 5
    }, 
    {
      pos: [5, 2, 5], 
      state: 5
    }, 
    {
      pos: [1, 2, 6], 
      state: 5
    }, 
    {
      pos: [2, 2, 6], 
      state: 5
    }, 
    {
      pos: [3, 2, 6], 
      state: 5
    }, 
    {
      pos: [5, 2, 6], 
      state: 5
    }, 
    {
      pos: [1, 2, 7], 
      state: 5
    }, 
    {
      pos: [2, 2, 7], 
      state: 5
    }, 
    {
      pos: [3, 2, 7], 
      state: 5
    }, 
    {
      pos: [4, 2, 7], 
      state: 5
    }, 
    {
      pos: [5, 2, 7], 
      state: 5
    }, 
    {
      pos: [1, 2, 8], 
      state: 5
    }, 
    {
      pos: [2, 2, 8], 
      state: 5
    }, 
    {
      pos: [5, 2, 8], 
      state: 5
    }, 
    {
      pos: [1, 2, 9], 
      state: 5
    }, 
    {
      pos: [2, 2, 9], 
      state: 5
    }, 
    {
      pos: [3, 2, 9], 
      state: 5
    }, 
    {
      pos: [5, 2, 9], 
      state: 5
    }, 
    {
      pos: [1, 2, 10], 
      state: 5
    }, 
    {
      pos: [2, 2, 10], 
      state: 5
    }, 
    {
      pos: [3, 2, 10], 
      state: 5
    }, 
    {
      pos: [4, 2, 10], 
      state: 5
    }, 
    {
      pos: [5, 2, 10], 
      state: 5
    }, 
    {
      pos: [1, 2, 11], 
      state: 5
    }, 
    {
      pos: [2, 2, 11], 
      state: 5
    }, 
    {
      pos: [3, 2, 11], 
      state: 5
    }, 
    {
      pos: [4, 2, 11], 
      state: 5
    }, 
    {
      pos: [5, 2, 11], 
      state: 5
    }, 
    {
      pos: [4, 2, 12], 
      state: 5
    }, 
    {
      pos: [5, 2, 12], 
      state: 5
    }, 
    {
      pos: [1, 2, 13], 
      state: 6
    }, 
    {
      pos: [2, 2, 13], 
      state: 6
    }, 
    {
      pos: [4, 2, 13], 
      state: 7
    }, 
    {
      pos: [5, 2, 13], 
      state: 5
    }, 
    {
      pos: [6, 3, 1], 
      state: 2
    }, 
    {
      pos: [6, 3, 5], 
      state: 2
    }, 
    {
      pos: [0, 3, 8], 
      state: 1
    }, 
    {
      pos: [6, 3, 8], 
      state: 1
    }, 
    {
      pos: [0, 3, 11], 
      state: 1
    }, 
    {
      pos: [0, 3, 12], 
      state: 1
    }, 
    {
      pos: [0, 3, 13], 
      state: 1
    }, 
    {
      pos: [0, 3, 14], 
      state: 1
    }, 
    {
      pos: [1, 3, 14], 
      state: 1
    }, 
    {
      pos: [2, 3, 14], 
      state: 1
    }, 
    {
      pos: [3, 3, 14], 
      state: 1
    }, 
    {
      pos: [4, 3, 14], 
      state: 1
    }, 
    {
      pos: [6, 3, 14], 
      state: 1
    }, 
    {
      pos: [0, 3, 0], 
      state: 5
    }, 
    {
      pos: [1, 3, 0], 
      state: 5
    }, 
    {
      pos: [2, 3, 0], 
      state: 5
    }, 
    {
      pos: [3, 3, 0], 
      state: 5
    }, 
    {
      pos: [4, 3, 0], 
      state: 5
    }, 
    {
      pos: [5, 3, 0], 
      state: 5
    }, 
    {
      pos: [6, 3, 0], 
      state: 5
    }, 
    {
      pos: [0, 3, 1], 
      state: 5
    }, 
    {
      pos: [1, 3, 1], 
      state: 5
    }, 
    {
      pos: [2, 3, 1], 
      state: 5
    }, 
    {
      pos: [3, 3, 1], 
      state: 5
    }, 
    {
      pos: [4, 3, 1], 
      state: 5
    }, 
    {
      pos: [5, 3, 1], 
      state: 5
    }, 
    {
      pos: [0, 3, 2], 
      state: 5
    }, 
    {
      pos: [1, 3, 2], 
      state: 5
    }, 
    {
      pos: [2, 3, 2], 
      state: 5
    }, 
    {
      pos: [3, 3, 2], 
      state: 5
    }, 
    {
      pos: [4, 3, 2], 
      state: 5
    }, 
    {
      pos: [5, 3, 2], 
      state: 5
    }, 
    {
      pos: [6, 3, 2], 
      state: 5
    }, 
    {
      pos: [0, 3, 3], 
      state: 5
    }, 
    {
      pos: [1, 3, 3], 
      state: 5
    }, 
    {
      pos: [2, 3, 3], 
      state: 5
    }, 
    {
      pos: [3, 3, 3], 
      state: 5
    }, 
    {
      pos: [4, 3, 3], 
      state: 5
    }, 
    {
      pos: [5, 3, 3], 
      state: 5
    }, 
    {
      pos: [6, 3, 3], 
      state: 5
    }, 
    {
      pos: [0, 3, 4], 
      state: 5
    }, 
    {
      pos: [1, 3, 4], 
      state: 5
    }, 
    {
      pos: [2, 3, 4], 
      state: 5
    }, 
    {
      pos: [3, 3, 4], 
      state: 5
    }, 
    {
      pos: [4, 3, 4], 
      state: 5
    }, 
    {
      pos: [5, 3, 4], 
      state: 5
    }, 
    {
      pos: [6, 3, 4], 
      state: 5
    }, 
    {
      pos: [0, 3, 5], 
      state: 5
    }, 
    {
      pos: [1, 3, 5], 
      state: 5
    }, 
    {
      pos: [2, 3, 5], 
      state: 5
    }, 
    {
      pos: [3, 3, 5], 
      state: 5
    }, 
    {
      pos: [4, 3, 5], 
      state: 5
    }, 
    {
      pos: [5, 3, 5], 
      state: 5
    }, 
    {
      pos: [0, 3, 6], 
      state: 5
    }, 
    {
      pos: [1, 3, 6], 
      state: 5
    }, 
    {
      pos: [2, 3, 6], 
      state: 5
    }, 
    {
      pos: [3, 3, 6], 
      state: 5
    }, 
    {
      pos: [4, 3, 6], 
      state: 5
    }, 
    {
      pos: [5, 3, 6], 
      state: 5
    }, 
    {
      pos: [6, 3, 6], 
      state: 5
    }, 
    {
      pos: [0, 3, 7], 
      state: 5
    }, 
    {
      pos: [1, 3, 7], 
      state: 5
    }, 
    {
      pos: [2, 3, 7], 
      state: 5
    }, 
    {
      pos: [3, 3, 7], 
      state: 5
    }, 
    {
      pos: [4, 3, 7], 
      state: 5
    }, 
    {
      pos: [5, 3, 7], 
      state: 5
    }, 
    {
      pos: [6, 3, 7], 
      state: 5
    }, 
    {
      pos: [1, 3, 8], 
      state: 5
    }, 
    {
      pos: [2, 3, 8], 
      state: 5
    }, 
    {
      pos: [3, 3, 8], 
      state: 5
    }, 
    {
      pos: [4, 3, 8], 
      state: 5
    }, 
    {
      pos: [5, 3, 8], 
      state: 5
    }, 
    {
      pos: [0, 3, 9], 
      state: 5
    }, 
    {
      pos: [1, 3, 9], 
      state: 5
    }, 
    {
      pos: [2, 3, 9], 
      state: 5
    }, 
    {
      pos: [3, 3, 9], 
      state: 5
    }, 
    {
      pos: [4, 3, 9], 
      state: 5
    }, 
    {
      pos: [5, 3, 9], 
      state: 5
    }, 
    {
      pos: [6, 3, 9], 
      state: 5
    }, 
    {
      pos: [0, 3, 10], 
      state: 5
    }, 
    {
      pos: [1, 3, 10], 
      state: 5
    }, 
    {
      pos: [2, 3, 10], 
      state: 5
    }, 
    {
      pos: [3, 3, 10], 
      state: 5
    }, 
    {
      pos: [4, 3, 10], 
      state: 5
    }, 
    {
      pos: [5, 3, 10], 
      state: 5
    }, 
    {
      pos: [6, 3, 10], 
      state: 5
    }, 
    {
      pos: [1, 3, 11], 
      state: 5
    }, 
    {
      pos: [2, 3, 11], 
      state: 5
    }, 
    {
      pos: [3, 3, 11], 
      state: 5
    }, 
    {
      pos: [4, 3, 11], 
      state: 5
    }, 
    {
      pos: [5, 3, 11], 
      state: 5
    }, 
    {
      pos: [6, 3, 11], 
      state: 5
    }, 
    {
      pos: [1, 3, 12], 
      state: 5
    }, 
    {
      pos: [2, 3, 12], 
      state: 5
    }, 
    {
      pos: [3, 3, 12], 
      state: 5
    }, 
    {
      pos: [4, 3, 12], 
      state: 5
    }, 
    {
      pos: [5, 3, 12], 
      state: 5
    }, 
    {
      pos: [6, 3, 12], 
      state: 5
    }, 
    {
      pos: [1, 3, 13], 
      state: 5
    }, 
    {
      pos: [2, 3, 13], 
      state: 5
    }, 
    {
      pos: [3, 3, 13], 
      state: 5
    }, 
    {
      pos: [4, 3, 13], 
      state: 5
    }, 
    {
      pos: [5, 3, 13], 
      state: 5
    }, 
    {
      pos: [6, 3, 13], 
      state: 5
    }, 
    {
      pos: [5, 3, 14], 
      state: 5
    }, 
    {
      pos: [6, 4, 1], 
      state: 2
    }, 
    {
      pos: [6, 4, 5], 
      state: 2
    }, 
    {
      pos: [0, 4, 8], 
      state: 1
    }, 
    {
      pos: [6, 4, 8], 
      state: 1
    }, 
    {
      pos: [0, 4, 11], 
      state: 1
    }, 
    {
      pos: [0, 4, 12], 
      state: 1
    }, 
    {
      pos: [0, 4, 13], 
      state: 1
    }, 
    {
      pos: [0, 4, 14], 
      state: 1
    }, 
    {
      pos: [1, 4, 14], 
      state: 1
    }, 
    {
      pos: [2, 4, 14], 
      state: 1
    }, 
    {
      pos: [3, 4, 14], 
      state: 1
    }, 
    {
      pos: [4, 4, 14], 
      state: 1
    }, 
    {
      pos: [6, 4, 14], 
      state: 1
    }, 
    {
      pos: [0, 4, 0], 
      state: 5
    }, 
    {
      pos: [1, 4, 0], 
      state: 5
    }, 
    {
      pos: [2, 4, 0], 
      state: 5
    }, 
    {
      pos: [3, 4, 0], 
      state: 5
    }, 
    {
      pos: [4, 4, 0], 
      state: 5
    }, 
    {
      pos: [5, 4, 0], 
      state: 5
    }, 
    {
      pos: [6, 4, 0], 
      state: 5
    }, 
    {
      pos: [0, 4, 1], 
      state: 5
    }, 
    {
      pos: [1, 4, 1], 
      state: 5
    }, 
    {
      pos: [2, 4, 1], 
      state: 5
    }, 
    {
      pos: [3, 4, 1], 
      state: 5
    }, 
    {
      pos: [4, 4, 1], 
      state: 5
    }, 
    {
      pos: [5, 4, 1], 
      state: 5
    }, 
    {
      pos: [0, 4, 2], 
      state: 5
    }, 
    {
      pos: [1, 4, 2], 
      state: 5
    }, 
    {
      pos: [2, 4, 2], 
      state: 5
    }, 
    {
      pos: [3, 4, 2], 
      state: 5
    }, 
    {
      pos: [4, 4, 2], 
      state: 5
    }, 
    {
      pos: [5, 4, 2], 
      state: 5
    }, 
    {
      pos: [6, 4, 2], 
      state: 5
    }, 
    {
      pos: [0, 4, 3], 
      state: 5
    }, 
    {
      pos: [1, 4, 3], 
      state: 5
    }, 
    {
      pos: [2, 4, 3], 
      state: 5
    }, 
    {
      pos: [3, 4, 3], 
      state: 5
    }, 
    {
      pos: [4, 4, 3], 
      state: 5
    }, 
    {
      pos: [5, 4, 3], 
      state: 5
    }, 
    {
      pos: [6, 4, 3], 
      state: 5
    }, 
    {
      pos: [0, 4, 4], 
      state: 5
    }, 
    {
      pos: [1, 4, 4], 
      state: 5
    }, 
    {
      pos: [2, 4, 4], 
      state: 5
    }, 
    {
      pos: [3, 4, 4], 
      state: 5
    }, 
    {
      pos: [4, 4, 4], 
      state: 5
    }, 
    {
      pos: [5, 4, 4], 
      state: 5
    }, 
    {
      pos: [6, 4, 4], 
      state: 5
    }, 
    {
      pos: [0, 4, 5], 
      state: 5
    }, 
    {
      pos: [1, 4, 5], 
      state: 5
    }, 
    {
      pos: [2, 4, 5], 
      state: 5
    }, 
    {
      pos: [3, 4, 5], 
      state: 5
    }, 
    {
      pos: [4, 4, 5], 
      state: 5
    }, 
    {
      pos: [5, 4, 5], 
      state: 5
    }, 
    {
      pos: [0, 4, 6], 
      state: 5
    }, 
    {
      pos: [1, 4, 6], 
      state: 5
    }, 
    {
      pos: [2, 4, 6], 
      state: 5
    }, 
    {
      pos: [3, 4, 6], 
      state: 5
    }, 
    {
      pos: [4, 4, 6], 
      state: 5
    }, 
    {
      pos: [5, 4, 6], 
      state: 5
    }, 
    {
      pos: [6, 4, 6], 
      state: 5
    }, 
    {
      pos: [0, 4, 7], 
      state: 5
    }, 
    {
      pos: [1, 4, 7], 
      state: 5
    }, 
    {
      pos: [2, 4, 7], 
      state: 5
    }, 
    {
      pos: [3, 4, 7], 
      state: 5
    }, 
    {
      pos: [4, 4, 7], 
      state: 5
    }, 
    {
      pos: [5, 4, 7], 
      state: 5
    }, 
    {
      pos: [6, 4, 7], 
      state: 5
    }, 
    {
      pos: [1, 4, 8], 
      state: 5
    }, 
    {
      pos: [2, 4, 8], 
      state: 5
    }, 
    {
      pos: [3, 4, 8], 
      state: 5
    }, 
    {
      pos: [4, 4, 8], 
      state: 5
    }, 
    {
      pos: [5, 4, 8], 
      state: 5
    }, 
    {
      pos: [0, 4, 9], 
      state: 5
    }, 
    {
      pos: [1, 4, 9], 
      state: 5
    }, 
    {
      pos: [2, 4, 9], 
      state: 5
    }, 
    {
      pos: [3, 4, 9], 
      state: 5
    }, 
    {
      pos: [4, 4, 9], 
      state: 5
    }, 
    {
      pos: [5, 4, 9], 
      state: 5
    }, 
    {
      pos: [6, 4, 9], 
      state: 5
    }, 
    {
      pos: [0, 4, 10], 
      state: 5
    }, 
    {
      pos: [1, 4, 10], 
      state: 5
    }, 
    {
      pos: [2, 4, 10], 
      state: 5
    }, 
    {
      pos: [3, 4, 10], 
      state: 5
    }, 
    {
      pos: [4, 4, 10], 
      state: 5
    }, 
    {
      pos: [5, 4, 10], 
      state: 5
    }, 
    {
      pos: [6, 4, 10], 
      state: 5
    }, 
    {
      pos: [1, 4, 11], 
      state: 5
    }, 
    {
      pos: [2, 4, 11], 
      state: 5
    }, 
    {
      pos: [3, 4, 11], 
      state: 5
    }, 
    {
      pos: [4, 4, 11], 
      state: 5
    }, 
    {
      pos: [5, 4, 11], 
      state: 5
    }, 
    {
      pos: [6, 4, 11], 
      state: 5
    }, 
    {
      pos: [1, 4, 12], 
      state: 5
    }, 
    {
      pos: [2, 4, 12], 
      state: 5
    }, 
    {
      pos: [3, 4, 12], 
      state: 5
    }, 
    {
      pos: [4, 4, 12], 
      state: 5
    }, 
    {
      pos: [5, 4, 12], 
      state: 5
    }, 
    {
      pos: [6, 4, 12], 
      state: 5
    }, 
    {
      pos: [1, 4, 13], 
      state: 5
    }, 
    {
      pos: [2, 4, 13], 
      state: 5
    }, 
    {
      pos: [3, 4, 13], 
      state: 5
    }, 
    {
      pos: [4, 4, 13], 
      state: 5
    }, 
    {
      pos: [5, 4, 13], 
      state: 5
    }, 
    {
      pos: [6, 4, 13], 
      state: 5
    }, 
    {
      pos: [5, 4, 14], 
      state: 5
    }, 
    {
      pos: [6, 5, 1], 
      state: 1
    }, 
    {
      pos: [6, 5, 5], 
      state: 1
    }, 
    {
      pos: [0, 5, 8], 
      state: 1
    }, 
    {
      pos: [6, 5, 8], 
      state: 1
    }, 
    {
      pos: [0, 5, 14], 
      state: 1
    }, 
    {
      pos: [6, 5, 14], 
      state: 1
    }, 
    {
      pos: [0, 5, 0], 
      state: 5
    }, 
    {
      pos: [1, 5, 0], 
      state: 5
    }, 
    {
      pos: [2, 5, 0], 
      state: 5
    }, 
    {
      pos: [3, 5, 0], 
      state: 5
    }, 
    {
      pos: [4, 5, 0], 
      state: 5
    }, 
    {
      pos: [5, 5, 0], 
      state: 5
    }, 
    {
      pos: [6, 5, 0], 
      state: 5
    }, 
    {
      pos: [0, 5, 1], 
      state: 5
    }, 
    {
      pos: [1, 5, 1], 
      state: 5
    }, 
    {
      pos: [2, 5, 1], 
      state: 5
    }, 
    {
      pos: [3, 5, 1], 
      state: 5
    }, 
    {
      pos: [4, 5, 1], 
      state: 5
    }, 
    {
      pos: [5, 5, 1], 
      state: 5
    }, 
    {
      pos: [0, 5, 2], 
      state: 5
    }, 
    {
      pos: [1, 5, 2], 
      state: 5
    }, 
    {
      pos: [2, 5, 2], 
      state: 5
    }, 
    {
      pos: [3, 5, 2], 
      state: 5
    }, 
    {
      pos: [4, 5, 2], 
      state: 5
    }, 
    {
      pos: [5, 5, 2], 
      state: 5
    }, 
    {
      pos: [6, 5, 2], 
      state: 8
    }, 
    {
      pos: [0, 5, 3], 
      state: 5
    }, 
    {
      pos: [1, 5, 3], 
      state: 5
    }, 
    {
      pos: [2, 5, 3], 
      state: 5
    }, 
    {
      pos: [3, 5, 3], 
      state: 5
    }, 
    {
      pos: [4, 5, 3], 
      state: 5
    }, 
    {
      pos: [5, 5, 3], 
      state: 5
    }, 
    {
      pos: [6, 5, 3], 
      state: 8
    }, 
    {
      pos: [0, 5, 4], 
      state: 5
    }, 
    {
      pos: [1, 5, 4], 
      state: 5
    }, 
    {
      pos: [2, 5, 4], 
      state: 5
    }, 
    {
      pos: [3, 5, 4], 
      state: 5
    }, 
    {
      pos: [4, 5, 4], 
      state: 5
    }, 
    {
      pos: [5, 5, 4], 
      state: 5
    }, 
    {
      pos: [6, 5, 4], 
      state: 8
    }, 
    {
      pos: [0, 5, 5], 
      state: 5
    }, 
    {
      pos: [1, 5, 5], 
      state: 5
    }, 
    {
      pos: [2, 5, 5], 
      state: 5
    }, 
    {
      pos: [3, 5, 5], 
      state: 5
    }, 
    {
      pos: [4, 5, 5], 
      state: 5
    }, 
    {
      pos: [5, 5, 5], 
      state: 5
    }, 
    {
      pos: [0, 5, 6], 
      state: 5
    }, 
    {
      pos: [1, 5, 6], 
      state: 5
    }, 
    {
      pos: [2, 5, 6], 
      state: 5
    }, 
    {
      pos: [3, 5, 6], 
      state: 5
    }, 
    {
      pos: [4, 5, 6], 
      state: 5
    }, 
    {
      pos: [5, 5, 6], 
      state: 5
    }, 
    {
      pos: [6, 5, 6], 
      state: 5
    }, 
    {
      pos: [0, 5, 7], 
      state: 5
    }, 
    {
      pos: [1, 5, 7], 
      state: 5
    }, 
    {
      pos: [2, 5, 7], 
      state: 5
    }, 
    {
      pos: [3, 5, 7], 
      state: 5
    }, 
    {
      pos: [4, 5, 7], 
      state: 5
    }, 
    {
      pos: [5, 5, 7], 
      state: 5
    }, 
    {
      pos: [6, 5, 7], 
      state: 5
    }, 
    {
      pos: [1, 5, 8], 
      state: 5
    }, 
    {
      pos: [2, 5, 8], 
      state: 5
    }, 
    {
      pos: [3, 5, 8], 
      state: 5
    }, 
    {
      pos: [4, 5, 8], 
      state: 5
    }, 
    {
      pos: [5, 5, 8], 
      state: 5
    }, 
    {
      pos: [0, 5, 9], 
      state: 5
    }, 
    {
      pos: [1, 5, 9], 
      state: 5
    }, 
    {
      pos: [2, 5, 9], 
      state: 5
    }, 
    {
      pos: [3, 5, 9], 
      state: 5
    }, 
    {
      pos: [4, 5, 9], 
      state: 5
    }, 
    {
      pos: [5, 5, 9], 
      state: 5
    }, 
    {
      pos: [6, 5, 9], 
      state: 5
    }, 
    {
      pos: [0, 5, 10], 
      state: 5
    }, 
    {
      pos: [1, 5, 10], 
      state: 5
    }, 
    {
      pos: [2, 5, 10], 
      state: 5
    }, 
    {
      pos: [3, 5, 10], 
      state: 5
    }, 
    {
      pos: [4, 5, 10], 
      state: 5
    }, 
    {
      pos: [5, 5, 10], 
      state: 5
    }, 
    {
      pos: [6, 5, 10], 
      state: 5
    }, 
    {
      pos: [0, 5, 11], 
      state: 5
    }, 
    {
      pos: [1, 5, 11], 
      state: 5
    }, 
    {
      pos: [2, 5, 11], 
      state: 5
    }, 
    {
      pos: [3, 5, 11], 
      state: 5
    }, 
    {
      pos: [4, 5, 11], 
      state: 5
    }, 
    {
      pos: [5, 5, 11], 
      state: 5
    }, 
    {
      pos: [6, 5, 11], 
      state: 5
    }, 
    {
      pos: [0, 5, 12], 
      state: 5
    }, 
    {
      pos: [1, 5, 12], 
      state: 5
    }, 
    {
      pos: [2, 5, 12], 
      state: 5
    }, 
    {
      pos: [3, 5, 12], 
      state: 5
    }, 
    {
      pos: [4, 5, 12], 
      state: 5
    }, 
    {
      pos: [5, 5, 12], 
      state: 5
    }, 
    {
      pos: [6, 5, 12], 
      state: 5
    }, 
    {
      pos: [0, 5, 13], 
      state: 5
    }, 
    {
      pos: [1, 5, 13], 
      state: 5
    }, 
    {
      pos: [2, 5, 13], 
      state: 5
    }, 
    {
      pos: [3, 5, 13], 
      state: 5
    }, 
    {
      pos: [4, 5, 13], 
      state: 5
    }, 
    {
      pos: [5, 5, 13], 
      state: 5
    }, 
    {
      pos: [6, 5, 13], 
      state: 5
    }, 
    {
      pos: [1, 5, 14], 
      state: 5
    }, 
    {
      pos: [2, 5, 14], 
      state: 5
    }, 
    {
      pos: [3, 5, 14], 
      state: 5
    }, 
    {
      pos: [4, 5, 14], 
      state: 5
    }, 
    {
      pos: [5, 5, 14], 
      state: 5
    }, 
    {
      pos: [6, 6, 3], 
      state: 1
    }, 
    {
      pos: [0, 6, 8], 
      state: 1
    }, 
    {
      pos: [6, 6, 8], 
      state: 1
    }, 
    {
      pos: [0, 6, 14], 
      state: 1
    }, 
    {
      pos: [6, 6, 14], 
      state: 1
    }, 
    {
      pos: [0, 6, 0], 
      state: 5
    }, 
    {
      pos: [1, 6, 0], 
      state: 5
    }, 
    {
      pos: [2, 6, 0], 
      state: 5
    }, 
    {
      pos: [3, 6, 0], 
      state: 5
    }, 
    {
      pos: [4, 6, 0], 
      state: 5
    }, 
    {
      pos: [5, 6, 0], 
      state: 5
    }, 
    {
      pos: [6, 6, 0], 
      state: 5
    }, 
    {
      pos: [0, 6, 1], 
      state: 5
    }, 
    {
      pos: [1, 6, 1], 
      state: 5
    }, 
    {
      pos: [2, 6, 1], 
      state: 5
    }, 
    {
      pos: [3, 6, 1], 
      state: 5
    }, 
    {
      pos: [4, 6, 1], 
      state: 5
    }, 
    {
      pos: [5, 6, 1], 
      state: 5
    }, 
    {
      pos: [6, 6, 1], 
      state: 3
    }, 
    {
      pos: [0, 6, 2], 
      state: 5
    }, 
    {
      pos: [1, 6, 2], 
      state: 5
    }, 
    {
      pos: [2, 6, 2], 
      state: 5
    }, 
    {
      pos: [3, 6, 2], 
      state: 5
    }, 
    {
      pos: [4, 6, 2], 
      state: 5
    }, 
    {
      pos: [5, 6, 2], 
      state: 5
    }, 
    {
      pos: [6, 6, 2], 
      state: 5
    }, 
    {
      pos: [0, 6, 3], 
      state: 5
    }, 
    {
      pos: [1, 6, 3], 
      state: 5
    }, 
    {
      pos: [2, 6, 3], 
      state: 5
    }, 
    {
      pos: [3, 6, 3], 
      state: 5
    }, 
    {
      pos: [4, 6, 3], 
      state: 5
    }, 
    {
      pos: [5, 6, 3], 
      state: 5
    }, 
    {
      pos: [0, 6, 4], 
      state: 5
    }, 
    {
      pos: [1, 6, 4], 
      state: 5
    }, 
    {
      pos: [2, 6, 4], 
      state: 5
    }, 
    {
      pos: [3, 6, 4], 
      state: 5
    }, 
    {
      pos: [4, 6, 4], 
      state: 5
    }, 
    {
      pos: [5, 6, 4], 
      state: 5
    }, 
    {
      pos: [6, 6, 4], 
      state: 5
    }, 
    {
      pos: [0, 6, 5], 
      state: 5
    }, 
    {
      pos: [1, 6, 5], 
      state: 5
    }, 
    {
      pos: [2, 6, 5], 
      state: 5
    }, 
    {
      pos: [3, 6, 5], 
      state: 5
    }, 
    {
      pos: [4, 6, 5], 
      state: 5
    }, 
    {
      pos: [5, 6, 5], 
      state: 5
    }, 
    {
      pos: [6, 6, 5], 
      state: 3
    }, 
    {
      pos: [0, 6, 6], 
      state: 5
    }, 
    {
      pos: [1, 6, 6], 
      state: 5
    }, 
    {
      pos: [2, 6, 6], 
      state: 5
    }, 
    {
      pos: [3, 6, 6], 
      state: 5
    }, 
    {
      pos: [4, 6, 6], 
      state: 5
    }, 
    {
      pos: [5, 6, 6], 
      state: 5
    }, 
    {
      pos: [6, 6, 6], 
      state: 5
    }, 
    {
      pos: [0, 6, 7], 
      state: 5
    }, 
    {
      pos: [1, 6, 7], 
      state: 5
    }, 
    {
      pos: [2, 6, 7], 
      state: 5
    }, 
    {
      pos: [3, 6, 7], 
      state: 5
    }, 
    {
      pos: [4, 6, 7], 
      state: 5
    }, 
    {
      pos: [5, 6, 7], 
      state: 5
    }, 
    {
      pos: [6, 6, 7], 
      state: 5
    }, 
    {
      pos: [1, 6, 8], 
      state: 5
    }, 
    {
      pos: [2, 6, 8], 
      state: 5
    }, 
    {
      pos: [3, 6, 8], 
      state: 5
    }, 
    {
      pos: [4, 6, 8], 
      state: 5
    }, 
    {
      pos: [5, 6, 8], 
      state: 5
    }, 
    {
      pos: [0, 6, 9], 
      state: 5
    }, 
    {
      pos: [1, 6, 9], 
      state: 5
    }, 
    {
      pos: [2, 6, 9], 
      state: 5
    }, 
    {
      pos: [3, 6, 9], 
      state: 5
    }, 
    {
      pos: [4, 6, 9], 
      state: 5
    }, 
    {
      pos: [5, 6, 9], 
      state: 5
    }, 
    {
      pos: [6, 6, 9], 
      state: 5
    }, 
    {
      pos: [0, 6, 10], 
      state: 5
    }, 
    {
      pos: [1, 6, 10], 
      state: 5
    }, 
    {
      pos: [2, 6, 10], 
      state: 5
    }, 
    {
      pos: [3, 6, 10], 
      state: 5
    }, 
    {
      pos: [4, 6, 10], 
      state: 5
    }, 
    {
      pos: [5, 6, 10], 
      state: 5
    }, 
    {
      pos: [6, 6, 10], 
      state: 5
    }, 
    {
      pos: [0, 6, 11], 
      state: 5
    }, 
    {
      pos: [1, 6, 11], 
      state: 5
    }, 
    {
      pos: [2, 6, 11], 
      state: 5
    }, 
    {
      pos: [3, 6, 11], 
      state: 5
    }, 
    {
      pos: [4, 6, 11], 
      state: 5
    }, 
    {
      pos: [5, 6, 11], 
      state: 5
    }, 
    {
      pos: [6, 6, 11], 
      state: 5
    }, 
    {
      pos: [0, 6, 12], 
      state: 5
    }, 
    {
      pos: [1, 6, 12], 
      state: 5
    }, 
    {
      pos: [2, 6, 12], 
      state: 5
    }, 
    {
      pos: [3, 6, 12], 
      state: 5
    }, 
    {
      pos: [4, 6, 12], 
      state: 5
    }, 
    {
      pos: [5, 6, 12], 
      state: 5
    }, 
    {
      pos: [6, 6, 12], 
      state: 5
    }, 
    {
      pos: [0, 6, 13], 
      state: 5
    }, 
    {
      pos: [1, 6, 13], 
      state: 5
    }, 
    {
      pos: [2, 6, 13], 
      state: 5
    }, 
    {
      pos: [3, 6, 13], 
      state: 5
    }, 
    {
      pos: [4, 6, 13], 
      state: 5
    }, 
    {
      pos: [5, 6, 13], 
      state: 5
    }, 
    {
      pos: [6, 6, 13], 
      state: 5
    }, 
    {
      pos: [1, 6, 14], 
      state: 5
    }, 
    {
      pos: [2, 6, 14], 
      state: 5
    }, 
    {
      pos: [3, 6, 14], 
      state: 5
    }, 
    {
      pos: [4, 6, 14], 
      state: 5
    }, 
    {
      pos: [5, 6, 14], 
      state: 5
    }, 
    {
      pos: [0, 7, 8], 
      state: 1
    }, 
    {
      pos: [1, 7, 8], 
      state: 1
    }, 
    {
      pos: [2, 7, 8], 
      state: 1
    }, 
    {
      pos: [3, 7, 8], 
      state: 1
    }, 
    {
      pos: [4, 7, 8], 
      state: 1
    }, 
    {
      pos: [5, 7, 8], 
      state: 1
    }, 
    {
      pos: [6, 7, 8], 
      state: 1
    }, 
    {
      pos: [0, 7, 9], 
      state: 1
    }, 
    {
      pos: [6, 7, 9], 
      state: 1
    }, 
    {
      pos: [0, 7, 10], 
      state: 1
    }, 
    {
      pos: [6, 7, 10], 
      state: 1
    }, 
    {
      pos: [0, 7, 11], 
      state: 1
    }, 
    {
      pos: [6, 7, 11], 
      state: 1
    }, 
    {
      pos: [0, 7, 12], 
      state: 1
    }, 
    {
      pos: [6, 7, 12], 
      state: 1
    }, 
    {
      pos: [0, 7, 13], 
      state: 1
    }, 
    {
      pos: [6, 7, 13], 
      state: 1
    }, 
    {
      pos: [0, 7, 14], 
      state: 1
    }, 
    {
      pos: [1, 7, 14], 
      state: 1
    }, 
    {
      pos: [2, 7, 14], 
      state: 1
    }, 
    {
      pos: [3, 7, 14], 
      state: 1
    }, 
    {
      pos: [4, 7, 14], 
      state: 1
    }, 
    {
      pos: [5, 7, 14], 
      state: 1
    }, 
    {
      pos: [6, 7, 14], 
      state: 1
    }, 
    {
      pos: [0, 7, 0], 
      state: 5
    }, 
    {
      pos: [1, 7, 0], 
      state: 5
    }, 
    {
      pos: [2, 7, 0], 
      state: 5
    }, 
    {
      pos: [3, 7, 0], 
      state: 5
    }, 
    {
      pos: [4, 7, 0], 
      state: 5
    }, 
    {
      pos: [5, 7, 0], 
      state: 5
    }, 
    {
      pos: [6, 7, 0], 
      state: 5
    }, 
    {
      pos: [0, 7, 1], 
      state: 5
    }, 
    {
      pos: [1, 7, 1], 
      state: 5
    }, 
    {
      pos: [2, 7, 1], 
      state: 5
    }, 
    {
      pos: [3, 7, 1], 
      state: 5
    }, 
    {
      pos: [4, 7, 1], 
      state: 5
    }, 
    {
      pos: [5, 7, 1], 
      state: 5
    }, 
    {
      pos: [6, 7, 1], 
      state: 5
    }, 
    {
      pos: [0, 7, 2], 
      state: 5
    }, 
    {
      pos: [1, 7, 2], 
      state: 5
    }, 
    {
      pos: [2, 7, 2], 
      state: 5
    }, 
    {
      pos: [3, 7, 2], 
      state: 5
    }, 
    {
      pos: [4, 7, 2], 
      state: 5
    }, 
    {
      pos: [5, 7, 2], 
      state: 5
    }, 
    {
      pos: [6, 7, 2], 
      state: 5
    }, 
    {
      pos: [0, 7, 3], 
      state: 5
    }, 
    {
      pos: [1, 7, 3], 
      state: 5
    }, 
    {
      pos: [2, 7, 3], 
      state: 5
    }, 
    {
      pos: [3, 7, 3], 
      state: 5
    }, 
    {
      pos: [4, 7, 3], 
      state: 5
    }, 
    {
      pos: [5, 7, 3], 
      state: 5
    }, 
    {
      pos: [6, 7, 3], 
      state: 5
    }, 
    {
      pos: [0, 7, 4], 
      state: 5
    }, 
    {
      pos: [1, 7, 4], 
      state: 5
    }, 
    {
      pos: [2, 7, 4], 
      state: 5
    }, 
    {
      pos: [3, 7, 4], 
      state: 5
    }, 
    {
      pos: [4, 7, 4], 
      state: 5
    }, 
    {
      pos: [5, 7, 4], 
      state: 5
    }, 
    {
      pos: [6, 7, 4], 
      state: 5
    }, 
    {
      pos: [0, 7, 5], 
      state: 5
    }, 
    {
      pos: [1, 7, 5], 
      state: 5
    }, 
    {
      pos: [2, 7, 5], 
      state: 5
    }, 
    {
      pos: [3, 7, 5], 
      state: 5
    }, 
    {
      pos: [4, 7, 5], 
      state: 5
    }, 
    {
      pos: [5, 7, 5], 
      state: 5
    }, 
    {
      pos: [6, 7, 5], 
      state: 5
    }, 
    {
      pos: [0, 7, 6], 
      state: 5
    }, 
    {
      pos: [1, 7, 6], 
      state: 5
    }, 
    {
      pos: [2, 7, 6], 
      state: 5
    }, 
    {
      pos: [3, 7, 6], 
      state: 5
    }, 
    {
      pos: [4, 7, 6], 
      state: 5
    }, 
    {
      pos: [5, 7, 6], 
      state: 5
    }, 
    {
      pos: [6, 7, 6], 
      state: 5
    }, 
    {
      pos: [0, 7, 7], 
      state: 5
    }, 
    {
      pos: [1, 7, 7], 
      state: 5
    }, 
    {
      pos: [2, 7, 7], 
      state: 5
    }, 
    {
      pos: [3, 7, 7], 
      state: 5
    }, 
    {
      pos: [4, 7, 7], 
      state: 5
    }, 
    {
      pos: [5, 7, 7], 
      state: 5
    }, 
    {
      pos: [6, 7, 7], 
      state: 5
    }, 
    {
      pos: [1, 7, 9], 
      state: 5
    }, 
    {
      pos: [2, 7, 9], 
      state: 5
    }, 
    {
      pos: [3, 7, 9], 
      state: 5
    }, 
    {
      pos: [4, 7, 9], 
      state: 5
    }, 
    {
      pos: [5, 7, 9], 
      state: 5
    }, 
    {
      pos: [1, 7, 10], 
      state: 5
    }, 
    {
      pos: [2, 7, 10], 
      state: 5
    }, 
    {
      pos: [3, 7, 10], 
      state: 5
    }, 
    {
      pos: [4, 7, 10], 
      state: 5
    }, 
    {
      pos: [5, 7, 10], 
      state: 5
    }, 
    {
      pos: [1, 7, 11], 
      state: 5
    }, 
    {
      pos: [2, 7, 11], 
      state: 5
    }, 
    {
      pos: [3, 7, 11], 
      state: 5
    }, 
    {
      pos: [4, 7, 11], 
      state: 5
    }, 
    {
      pos: [5, 7, 11], 
      state: 5
    }, 
    {
      pos: [1, 7, 12], 
      state: 5
    }, 
    {
      pos: [2, 7, 12], 
      state: 5
    }, 
    {
      pos: [3, 7, 12], 
      state: 5
    }, 
    {
      pos: [4, 7, 12], 
      state: 5
    }, 
    {
      pos: [5, 7, 12], 
      state: 5
    }, 
    {
      pos: [1, 7, 13], 
      state: 5
    }, 
    {
      pos: [2, 7, 13], 
      state: 5
    }, 
    {
      pos: [3, 7, 13], 
      state: 5
    }, 
    {
      pos: [4, 7, 13], 
      state: 5
    }, 
    {
      pos: [5, 7, 13], 
      state: 5
    }
  ], 
  palette: [
    {
      Name: "minecraft:birch_planks"
    }, 
    {
      Name: "minecraft:polished_andesite"
    }, 
    {
      Properties: {
        waterlogged: "false", 
        type: "double"
      }, 
      Name: "minecraft:smooth_stone_slab"
    }, 
    {
      Properties: {
        waterlogged: "false", 
        type: "bottom"
      }, 
      Name: "minecraft:smooth_stone_slab"
    }, 
    {
      Properties: {
        mode: "data"
      }, 
      Name: "minecraft:structure_block"
    }, 
    {
      Name: "minecraft:air"
    }, 
    {
      Properties: {
        level: "0"
      }, 
      Name: "minecraft:lava"
    }, 
    {
      Properties: {
        facing: "west"
      }, 
      Name: "minecraft:damaged_anvil"
    }, 
    {
      Properties: {
        waterlogged: "false", 
        type: "top"
      }, 
      Name: "minecraft:smooth_stone_slab"
    }
  ]
}
