{
  size: [4, 4, 8], 
  entities: [], 
  blocks: [
    {
      pos: [1, 0, 0], 
      state: 0
    }, 
    {
      pos: [2, 0, 0], 
      state: 0
    }, 
    {
      pos: [1, 0, 1], 
      state: 0
    }, 
    {
      pos: [2, 0, 1], 
      state: 0
    }, 
    {
      pos: [1, 0, 2], 
      state: 0
    }, 
    {
      pos: [2, 0, 2], 
      state: 0
    }, 
    {
      pos: [1, 0, 3], 
      state: 0
    }, 
    {
      pos: [2, 0, 3], 
      state: 0
    }, 
    {
      pos: [1, 0, 4], 
      state: 0
    }, 
    {
      pos: [2, 0, 4], 
      state: 0
    }, 
    {
      pos: [1, 0, 5], 
      state: 0
    }, 
    {
      pos: [2, 0, 5], 
      state: 0
    }, 
    {
      pos: [1, 0, 6], 
      state: 0
    }, 
    {
      pos: [2, 0, 6], 
      state: 0
    }, 
    {
      pos: [1, 0, 7], 
      state: 0
    }, 
    {
      pos: [2, 0, 7], 
      state: 0
    }, 
    {
      pos: [0, 0, 0], 
      state: 1
    }, 
    {
      pos: [3, 0, 0], 
      state: 1
    }, 
    {
      pos: [0, 0, 1], 
      state: 1
    }, 
    {
      pos: [3, 0, 1], 
      state: 1
    }, 
    {
      pos: [0, 0, 2], 
      state: 1
    }, 
    {
      pos: [3, 0, 2], 
      state: 1
    }, 
    {
      pos: [0, 0, 3], 
      state: 1
    }, 
    {
      pos: [3, 0, 3], 
      state: 1
    }, 
    {
      pos: [0, 0, 4], 
      state: 1
    }, 
    {
      pos: [3, 0, 4], 
      state: 1
    }, 
    {
      pos: [0, 0, 5], 
      state: 1
    }, 
    {
      pos: [3, 0, 5], 
      state: 1
    }, 
    {
      pos: [0, 0, 6], 
      state: 1
    }, 
    {
      pos: [3, 0, 6], 
      state: 1
    }, 
    {
      pos: [3, 0, 7], 
      state: 1
    }, 
    {
      pos: [1, 1, 0], 
      state: 2
    }, 
    {
      pos: [2, 1, 0], 
      state: 2
    }, 
    {
      pos: [1, 1, 1], 
      state: 2
    }, 
    {
      pos: [2, 1, 1], 
      state: 2
    }, 
    {
      pos: [1, 1, 2], 
      state: 2
    }, 
    {
      pos: [2, 1, 2], 
      state: 2
    }, 
    {
      pos: [1, 1, 3], 
      state: 2
    }, 
    {
      pos: [2, 1, 3], 
      state: 2
    }, 
    {
      pos: [1, 1, 4], 
      state: 2
    }, 
    {
      pos: [2, 1, 4], 
      state: 2
    }, 
    {
      pos: [1, 1, 5], 
      state: 2
    }, 
    {
      pos: [2, 1, 5], 
      state: 2
    }, 
    {
      pos: [1, 1, 6], 
      state: 2
    }, 
    {
      pos: [2, 1, 6], 
      state: 2
    }, 
    {
      pos: [1, 1, 7], 
      state: 2
    }, 
    {
      pos: [2, 1, 7], 
      state: 2
    }, 
    {
      pos: [0, 1, 0], 
      state: 1
    }, 
    {
      pos: [3, 1, 0], 
      state: 3
    }, 
    {
      pos: [0, 1, 1], 
      state: 1
    }, 
    {
      pos: [3, 1, 1], 
      state: 3
    }, 
    {
      pos: [0, 1, 2], 
      state: 1
    }, 
    {
      pos: [3, 1, 2], 
      state: 3
    }, 
    {
      pos: [0, 1, 3], 
      state: 1
    }, 
    {
      pos: [3, 1, 3], 
      state: 3
    }, 
    {
      pos: [0, 1, 4], 
      state: 1
    }, 
    {
      pos: [3, 1, 4], 
      state: 3
    }, 
    {
      pos: [0, 1, 5], 
      state: 1
    }, 
    {
      pos: [3, 1, 5], 
      state: 3
    }, 
    {
      pos: [0, 1, 6], 
      state: 1
    }, 
    {
      pos: [3, 1, 6], 
      state: 3
    }, 
    {
      pos: [3, 1, 7], 
      state: 3
    }, 
    {
      pos: [1, 2, 0], 
      state: 2
    }, 
    {
      pos: [1, 2, 1], 
      state: 2
    }, 
    {
      pos: [1, 2, 2], 
      state: 2
    }, 
    {
      pos: [1, 2, 3], 
      state: 2
    }, 
    {
      pos: [1, 2, 4], 
      state: 2
    }, 
    {
      pos: [1, 2, 5], 
      state: 2
    }, 
    {
      pos: [1, 2, 6], 
      state: 2
    }, 
    {
      pos: [1, 2, 7], 
      state: 2
    }, 
    {
      pos: [0, 2, 0], 
      state: 4
    }, 
    {
      pos: [2, 2, 0], 
      state: 3
    }, 
    {
      pos: [3, 2, 0], 
      state: 1
    }, 
    {
      pos: [0, 2, 1], 
      state: 4
    }, 
    {
      pos: [2, 2, 1], 
      state: 3
    }, 
    {
      pos: [3, 2, 1], 
      state: 1
    }, 
    {
      pos: [0, 2, 2], 
      state: 4
    }, 
    {
      pos: [2, 2, 2], 
      state: 3
    }, 
    {
      pos: [3, 2, 2], 
      state: 1
    }, 
    {
      pos: [0, 2, 3], 
      state: 4
    }, 
    {
      pos: [2, 2, 3], 
      state: 3
    }, 
    {
      pos: [3, 2, 3], 
      state: 1
    }, 
    {
      pos: [0, 2, 4], 
      state: 4
    }, 
    {
      pos: [2, 2, 4], 
      state: 3
    }, 
    {
      pos: [3, 2, 4], 
      state: 1
    }, 
    {
      pos: [0, 2, 5], 
      state: 4
    }, 
    {
      pos: [2, 2, 5], 
      state: 3
    }, 
    {
      pos: [3, 2, 5], 
      state: 1
    }, 
    {
      pos: [0, 2, 6], 
      state: 4
    }, 
    {
      pos: [2, 2, 6], 
      state: 3
    }, 
    {
      pos: [3, 2, 6], 
      state: 1
    }, 
    {
      pos: [0, 2, 7], 
      state: 4
    }, 
    {
      pos: [2, 2, 7], 
      state: 3
    }, 
    {
      pos: [3, 2, 7], 
      state: 1
    }, 
    {
      pos: [0, 3, 0], 
      state: 2
    }, 
    {
      pos: [0, 3, 1], 
      state: 2
    }, 
    {
      pos: [0, 3, 2], 
      state: 2
    }, 
    {
      pos: [0, 3, 3], 
      state: 2
    }, 
    {
      pos: [0, 3, 4], 
      state: 2
    }, 
    {
      pos: [0, 3, 5], 
      state: 2
    }, 
    {
      pos: [0, 3, 6], 
      state: 2
    }, 
    {
      pos: [0, 3, 7], 
      state: 2
    }, 
    {
      pos: [1, 3, 0], 
      state: 3
    }, 
    {
      pos: [2, 3, 0], 
      state: 1
    }, 
    {
      pos: [3, 3, 0], 
      state: 1
    }, 
    {
      pos: [1, 3, 1], 
      state: 3
    }, 
    {
      pos: [2, 3, 1], 
      state: 1
    }, 
    {
      pos: [3, 3, 1], 
      state: 1
    }, 
    {
      pos: [1, 3, 2], 
      state: 3
    }, 
    {
      pos: [2, 3, 2], 
      state: 1
    }, 
    {
      pos: [3, 3, 2], 
      state: 1
    }, 
    {
      pos: [1, 3, 3], 
      state: 3
    }, 
    {
      pos: [2, 3, 3], 
      state: 1
    }, 
    {
      pos: [3, 3, 3], 
      state: 1
    }, 
    {
      pos: [1, 3, 4], 
      state: 3
    }, 
    {
      pos: [2, 3, 4], 
      state: 1
    }, 
    {
      pos: [3, 3, 4], 
      state: 1
    }, 
    {
      pos: [1, 3, 5], 
      state: 3
    }, 
    {
      pos: [2, 3, 5], 
      state: 1
    }, 
    {
      pos: [3, 3, 5], 
      state: 1
    }, 
    {
      pos: [1, 3, 6], 
      state: 3
    }, 
    {
      pos: [2, 3, 6], 
      state: 1
    }, 
    {
      pos: [3, 3, 6], 
      state: 1
    }, 
    {
      pos: [1, 3, 7], 
      state: 3
    }, 
    {
      pos: [2, 3, 7], 
      state: 1
    }, 
    {
      pos: [3, 3, 7], 
      state: 1
    }
  ], 
  palette: [
    {
      Name: "minecraft:cobblestone"
    }, 
    {
      Name: "minecraft:air"
    }, 
    {
      Name: "minecraft:dark_oak_planks"
    }, 
    {
      Properties: {
        half: "bottom", 
        waterlogged: "false", 
        shape: "straight", 
        facing: "west"
      }, 
      Name: "minecraft:dark_oak_stairs"
    }, 
    {
      Properties: {
        half: "top", 
        waterlogged: "false", 
        shape: "straight", 
        facing: "east"
      }, 
      Name: "minecraft:dark_oak_stairs"
    }
  ]
}
