{
  size: [14, 6, 8], 
  entities: [], 
  blocks: [
    {
      pos: [1, 0, 0], 
      state: 0
    }, 
    {
      pos: [2, 0, 0], 
      state: 0
    }, 
    {
      pos: [3, 0, 0], 
      state: 0
    }, 
    {
      pos: [4, 0, 0], 
      state: 0
    }, 
    {
      pos: [5, 0, 0], 
      state: 1
    }, 
    {
      pos: [6, 0, 0], 
      state: 0
    }, 
    {
      pos: [7, 0, 0], 
      state: 0
    }, 
    {
      pos: [8, 0, 0], 
      state: 0
    }, 
    {
      pos: [9, 0, 0], 
      state: 0
    }, 
    {
      pos: [10, 0, 0], 
      state: 0
    }, 
    {
      pos: [11, 0, 0], 
      state: 1
    }, 
    {
      pos: [0, 0, 1], 
      state: 0
    }, 
    {
      pos: [1, 0, 1], 
      state: 0
    }, 
    {
      pos: [2, 0, 1], 
      state: 0
    }, 
    {
      pos: [3, 0, 1], 
      state: 0
    }, 
    {
      pos: [4, 0, 1], 
      state: 1
    }, 
    {
      pos: [5, 0, 1], 
      state: 1
    }, 
    {
      pos: [6, 0, 1], 
      state: 1
    }, 
    {
      pos: [7, 0, 1], 
      state: 1
    }, 
    {
      pos: [8, 0, 1], 
      state: 0
    }, 
    {
      pos: [9, 0, 1], 
      state: 0
    }, 
    {
      pos: [10, 0, 1], 
      state: 0
    }, 
    {
      pos: [11, 0, 1], 
      state: 0
    }, 
    {
      pos: [12, 0, 1], 
      state: 1
    }, 
    {
      pos: [13, 0, 1], 
      state: 1
    }, 
    {
      pos: [0, 0, 2], 
      state: 0
    }, 
    {
      pos: [1, 0, 2], 
      state: 0
    }, 
    {
      pos: [2, 0, 2], 
      state: 2
    }, 
    {
      pos: [3, 0, 2], 
      state: 3
    }, 
    {
      pos: [4, 0, 2], 
      state: 1
    }, 
    {
      pos: [5, 0, 2], 
      state: 1
    }, 
    {
      pos: [6, 0, 2], 
      state: 2
    }, 
    {
      pos: [7, 0, 2], 
      state: 2
    }, 
    {
      pos: [8, 0, 2], 
      state: 0
    }, 
    {
      pos: [9, 0, 2], 
      state: 0
    }, 
    {
      pos: [10, 0, 2], 
      state: 0
    }, 
    {
      pos: [11, 0, 2], 
      state: 0
    }, 
    {
      pos: [12, 0, 2], 
      state: 1
    }, 
    {
      pos: [13, 0, 2], 
      state: 2
    }, 
    {
      pos: [0, 0, 3], 
      state: 0
    }, 
    {
      pos: [1, 0, 3], 
      state: 1
    }, 
    {
      pos: [2, 0, 3], 
      state: 3
    }, 
    {
      pos: [3, 0, 3], 
      state: 2
    }, 
    {
      pos: [4, 0, 3], 
      state: 1
    }, 
    {
      pos: [5, 0, 3], 
      state: 2
    }, 
    {
      pos: [6, 0, 3], 
      state: 2
    }, 
    {
      pos: [7, 0, 3], 
      state: 2
    }, 
    {
      pos: [8, 0, 3], 
      state: 2
    }, 
    {
      pos: [9, 0, 3], 
      state: 0
    }, 
    {
      pos: [10, 0, 3], 
      state: 2
    }, 
    {
      pos: [11, 0, 3], 
      state: 2
    }, 
    {
      pos: [12, 0, 3], 
      state: 2
    }, 
    {
      pos: [0, 0, 4], 
      state: 0
    }, 
    {
      pos: [1, 0, 4], 
      state: 0
    }, 
    {
      pos: [2, 0, 4], 
      state: 2
    }, 
    {
      pos: [3, 0, 4], 
      state: 2
    }, 
    {
      pos: [4, 0, 4], 
      state: 0
    }, 
    {
      pos: [5, 0, 4], 
      state: 0
    }, 
    {
      pos: [6, 0, 4], 
      state: 0
    }, 
    {
      pos: [7, 0, 4], 
      state: 0
    }, 
    {
      pos: [8, 0, 4], 
      state: 0
    }, 
    {
      pos: [9, 0, 4], 
      state: 2
    }, 
    {
      pos: [10, 0, 4], 
      state: 2
    }, 
    {
      pos: [11, 0, 4], 
      state: 2
    }, 
    {
      pos: [12, 0, 4], 
      state: 2
    }, 
    {
      pos: [0, 0, 5], 
      state: 0
    }, 
    {
      pos: [1, 0, 5], 
      state: 0
    }, 
    {
      pos: [2, 0, 5], 
      state: 2
    }, 
    {
      pos: [3, 0, 5], 
      state: 2
    }, 
    {
      pos: [4, 0, 5], 
      state: 2
    }, 
    {
      pos: [5, 0, 5], 
      state: 0
    }, 
    {
      pos: [6, 0, 5], 
      state: 0
    }, 
    {
      pos: [7, 0, 5], 
      state: 0
    }, 
    {
      pos: [8, 0, 5], 
      state: 0
    }, 
    {
      pos: [9, 0, 5], 
      state: 0
    }, 
    {
      pos: [10, 0, 5], 
      state: 1
    }, 
    {
      pos: [11, 0, 5], 
      state: 1
    }, 
    {
      pos: [12, 0, 5], 
      state: 2
    }, 
    {
      pos: [0, 0, 6], 
      state: 0
    }, 
    {
      pos: [1, 0, 6], 
      state: 0
    }, 
    {
      pos: [2, 0, 6], 
      state: 0
    }, 
    {
      pos: [3, 0, 6], 
      state: 2
    }, 
    {
      pos: [4, 0, 6], 
      state: 2
    }, 
    {
      pos: [5, 0, 6], 
      state: 0
    }, 
    {
      pos: [6, 0, 6], 
      state: 0
    }, 
    {
      pos: [7, 0, 6], 
      state: 0
    }, 
    {
      pos: [8, 0, 6], 
      state: 0
    }, 
    {
      pos: [9, 0, 6], 
      state: 0
    }, 
    {
      pos: [10, 0, 6], 
      state: 0
    }, 
    {
      pos: [11, 0, 6], 
      state: 1
    }, 
    {
      pos: [12, 0, 6], 
      state: 1
    }, 
    {
      pos: [1, 0, 7], 
      state: 0
    }, 
    {
      pos: [2, 0, 7], 
      state: 0
    }, 
    {
      pos: [3, 0, 7], 
      state: 0
    }, 
    {
      pos: [4, 0, 7], 
      state: 0
    }, 
    {
      pos: [5, 0, 7], 
      state: 0
    }, 
    {
      pos: [6, 0, 7], 
      state: 0
    }, 
    {
      pos: [7, 0, 7], 
      state: 0
    }, 
    {
      pos: [8, 0, 7], 
      state: 0
    }, 
    {
      pos: [9, 0, 7], 
      state: 0
    }, 
    {
      pos: [10, 0, 7], 
      state: 0
    }, 
    {
      pos: [11, 0, 7], 
      state: 0
    }, 
    {
      nbt: {
        joint: "rollable", 
        final_state: "minecraft:polished_blackstone_bricks", 
        name: "minecraft:outer_connector_left", 
        pool: "minecraft:empty", 
        id: "minecraft:jigsaw", 
        target: "minecraft:empty"
      }, 
      pos: [0, 0, 0], 
      state: 4
    }, 
    {
      nbt: {
        joint: "rollable", 
        final_state: "minecraft:polished_blackstone_bricks", 
        name: "minecraft:outer_connector_right", 
        pool: "minecraft:empty", 
        id: "minecraft:jigsaw", 
        target: "minecraft:empty"
      }, 
      pos: [0, 0, 7], 
      state: 5
    }, 
    {
      pos: [12, 0, 0], 
      state: 6
    }, 
    {
      pos: [13, 0, 0], 
      state: 6
    }, 
    {
      pos: [0, 1, 0], 
      state: 0
    }, 
    {
      pos: [1, 1, 0], 
      state: 0
    }, 
    {
      pos: [2, 1, 0], 
      state: 0
    }, 
    {
      pos: [3, 1, 0], 
      state: 1
    }, 
    {
      pos: [4, 1, 0], 
      state: 0
    }, 
    {
      pos: [5, 1, 0], 
      state: 0
    }, 
    {
      pos: [6, 1, 0], 
      state: 0
    }, 
    {
      pos: [7, 1, 0], 
      state: 0
    }, 
    {
      pos: [8, 1, 0], 
      state: 0
    }, 
    {
      pos: [9, 1, 0], 
      state: 0
    }, 
    {
      pos: [0, 1, 1], 
      state: 0
    }, 
    {
      pos: [1, 1, 1], 
      state: 0
    }, 
    {
      pos: [4, 1, 1], 
      state: 0
    }, 
    {
      pos: [8, 1, 1], 
      state: 1
    }, 
    {
      pos: [9, 1, 1], 
      state: 0
    }, 
    {
      pos: [0, 1, 2], 
      state: 0
    }, 
    {
      pos: [4, 1, 2], 
      state: 0
    }, 
    {
      pos: [0, 1, 3], 
      state: 1
    }, 
    {
      pos: [4, 1, 3], 
      state: 0
    }, 
    {
      pos: [0, 1, 4], 
      state: 0
    }, 
    {
      pos: [4, 1, 4], 
      state: 0
    }, 
    {
      pos: [0, 1, 5], 
      state: 0
    }, 
    {
      pos: [4, 1, 5], 
      state: 0
    }, 
    {
      pos: [0, 1, 6], 
      state: 0
    }, 
    {
      pos: [1, 1, 6], 
      state: 0
    }, 
    {
      pos: [4, 1, 6], 
      state: 0
    }, 
    {
      pos: [8, 1, 6], 
      state: 0
    }, 
    {
      pos: [9, 1, 6], 
      state: 0
    }, 
    {
      pos: [0, 1, 7], 
      state: 0
    }, 
    {
      pos: [1, 1, 7], 
      state: 0
    }, 
    {
      pos: [2, 1, 7], 
      state: 0
    }, 
    {
      pos: [3, 1, 7], 
      state: 1
    }, 
    {
      pos: [4, 1, 7], 
      state: 0
    }, 
    {
      pos: [5, 1, 7], 
      state: 1
    }, 
    {
      pos: [8, 1, 7], 
      state: 1
    }, 
    {
      pos: [9, 1, 7], 
      state: 0
    }, 
    {
      pos: [10, 1, 0], 
      state: 6
    }, 
    {
      pos: [11, 1, 0], 
      state: 6
    }, 
    {
      pos: [12, 1, 0], 
      state: 6
    }, 
    {
      pos: [13, 1, 0], 
      state: 6
    }, 
    {
      pos: [2, 1, 1], 
      state: 6
    }, 
    {
      pos: [3, 1, 1], 
      state: 6
    }, 
    {
      pos: [5, 1, 1], 
      state: 6
    }, 
    {
      pos: [6, 1, 1], 
      state: 6
    }, 
    {
      pos: [7, 1, 1], 
      state: 6
    }, 
    {
      pos: [1, 1, 2], 
      state: 7
    }, 
    {
      pos: [2, 1, 2], 
      state: 8
    }, 
    {
      pos: [3, 1, 2], 
      state: 6
    }, 
    {
      pos: [5, 1, 2], 
      state: 6
    }, 
    {
      pos: [6, 1, 2], 
      state: 6
    }, 
    {
      pos: [7, 1, 2], 
      state: 6
    }, 
    {
      pos: [9, 1, 2], 
      state: 9
    }, 
    {
      pos: [10, 1, 2], 
      state: 6
    }, 
    {
      pos: [1, 1, 3], 
      state: 10
    }, 
    {
      pos: [2, 1, 3], 
      state: 7
    }, 
    {
      pos: [3, 1, 3], 
      state: 8
    }, 
    {
      pos: [5, 1, 3], 
      state: 6
    }, 
    {
      pos: [6, 1, 3], 
      state: 6
    }, 
    {
      pos: [7, 1, 3], 
      state: 6
    }, 
    {
      pos: [8, 1, 3], 
      state: 6
    }, 
    {
      pos: [9, 1, 3], 
      state: 6
    }, 
    {
      pos: [10, 1, 3], 
      state: 6
    }, 
    {
      pos: [1, 1, 4], 
      state: 11
    }, 
    {
      pos: [2, 1, 4], 
      state: 10
    }, 
    {
      pos: [3, 1, 4], 
      state: 7
    }, 
    {
      pos: [5, 1, 4], 
      state: 6
    }, 
    {
      pos: [6, 1, 4], 
      state: 6
    }, 
    {
      pos: [7, 1, 4], 
      state: 6
    }, 
    {
      pos: [8, 1, 4], 
      state: 6
    }, 
    {
      pos: [9, 1, 4], 
      state: 6
    }, 
    {
      pos: [10, 1, 4], 
      state: 6
    }, 
    {
      pos: [11, 1, 4], 
      state: 6
    }, 
    {
      pos: [1, 1, 5], 
      state: 10
    }, 
    {
      pos: [2, 1, 5], 
      state: 7
    }, 
    {
      pos: [3, 1, 5], 
      state: 8
    }, 
    {
      pos: [5, 1, 5], 
      state: 6
    }, 
    {
      pos: [6, 1, 5], 
      state: 6
    }, 
    {
      pos: [7, 1, 5], 
      state: 6
    }, 
    {
      pos: [8, 1, 5], 
      state: 6
    }, 
    {
      pos: [9, 1, 5], 
      state: 12
    }, 
    {
      pos: [10, 1, 5], 
      state: 6
    }, 
    {
      pos: [2, 1, 6], 
      state: 8
    }, 
    {
      pos: [3, 1, 6], 
      state: 6
    }, 
    {
      pos: [5, 1, 6], 
      state: 6
    }, 
    {
      pos: [6, 1, 6], 
      state: 6
    }, 
    {
      pos: [7, 1, 6], 
      state: 6
    }, 
    {
      pos: [11, 1, 6], 
      state: 6
    }, 
    {
      pos: [6, 1, 7], 
      state: 6
    }, 
    {
      pos: [7, 1, 7], 
      state: 6
    }, 
    {
      pos: [12, 1, 7], 
      state: 6
    }, 
    {
      pos: [13, 1, 7], 
      state: 6
    }, 
    {
      pos: [0, 2, 0], 
      state: 0
    }, 
    {
      pos: [1, 2, 0], 
      state: 0
    }, 
    {
      pos: [2, 2, 0], 
      state: 0
    }, 
    {
      pos: [4, 2, 0], 
      state: 0
    }, 
    {
      pos: [6, 2, 0], 
      state: 1
    }, 
    {
      pos: [7, 2, 0], 
      state: 0
    }, 
    {
      pos: [8, 2, 0], 
      state: 0
    }, 
    {
      pos: [9, 2, 0], 
      state: 0
    }, 
    {
      pos: [0, 2, 1], 
      state: 0
    }, 
    {
      pos: [1, 2, 1], 
      state: 0
    }, 
    {
      pos: [8, 2, 1], 
      state: 0
    }, 
    {
      pos: [9, 2, 1], 
      state: 0
    }, 
    {
      pos: [0, 2, 2], 
      state: 0
    }, 
    {
      pos: [0, 2, 3], 
      state: 2
    }, 
    {
      pos: [0, 2, 4], 
      state: 2
    }, 
    {
      pos: [0, 2, 5], 
      state: 0
    }, 
    {
      pos: [0, 2, 6], 
      state: 0
    }, 
    {
      pos: [1, 2, 6], 
      state: 0
    }, 
    {
      pos: [8, 2, 6], 
      state: 0
    }, 
    {
      pos: [9, 2, 6], 
      state: 0
    }, 
    {
      pos: [0, 2, 7], 
      state: 0
    }, 
    {
      pos: [1, 2, 7], 
      state: 0
    }, 
    {
      pos: [2, 2, 7], 
      state: 0
    }, 
    {
      pos: [4, 2, 7], 
      state: 1
    }, 
    {
      pos: [6, 2, 7], 
      state: 1
    }, 
    {
      pos: [7, 2, 7], 
      state: 1
    }, 
    {
      pos: [8, 2, 7], 
      state: 0
    }, 
    {
      pos: [9, 2, 7], 
      state: 0
    }, 
    {
      pos: [5, 2, 0], 
      state: 6
    }, 
    {
      pos: [10, 2, 0], 
      state: 6
    }, 
    {
      pos: [11, 2, 0], 
      state: 6
    }, 
    {
      pos: [12, 2, 0], 
      state: 6
    }, 
    {
      pos: [13, 2, 0], 
      state: 6
    }, 
    {
      pos: [2, 2, 1], 
      state: 6
    }, 
    {
      pos: [3, 2, 1], 
      state: 6
    }, 
    {
      pos: [4, 2, 1], 
      state: 6
    }, 
    {
      pos: [5, 2, 1], 
      state: 6
    }, 
    {
      pos: [6, 2, 1], 
      state: 6
    }, 
    {
      pos: [7, 2, 1], 
      state: 6
    }, 
    {
      pos: [1, 2, 2], 
      state: 6
    }, 
    {
      pos: [2, 2, 2], 
      state: 6
    }, 
    {
      pos: [3, 2, 2], 
      state: 6
    }, 
    {
      pos: [4, 2, 2], 
      state: 6
    }, 
    {
      pos: [5, 2, 2], 
      state: 6
    }, 
    {
      pos: [6, 2, 2], 
      state: 6
    }, 
    {
      pos: [7, 2, 2], 
      state: 6
    }, 
    {
      pos: [8, 2, 2], 
      state: 6
    }, 
    {
      pos: [9, 2, 2], 
      state: 6
    }, 
    {
      pos: [10, 2, 2], 
      state: 6
    }, 
    {
      pos: [11, 2, 2], 
      state: 6
    }, 
    {
      pos: [13, 2, 2], 
      state: 6
    }, 
    {
      pos: [1, 2, 3], 
      state: 6
    }, 
    {
      pos: [2, 2, 3], 
      state: 6
    }, 
    {
      pos: [3, 2, 3], 
      state: 6
    }, 
    {
      pos: [4, 2, 3], 
      state: 6
    }, 
    {
      pos: [5, 2, 3], 
      state: 6
    }, 
    {
      pos: [6, 2, 3], 
      state: 6
    }, 
    {
      pos: [7, 2, 3], 
      state: 6
    }, 
    {
      pos: [8, 2, 3], 
      state: 6
    }, 
    {
      pos: [9, 2, 3], 
      state: 6
    }, 
    {
      pos: [10, 2, 3], 
      state: 6
    }, 
    {
      pos: [11, 2, 3], 
      state: 6
    }, 
    {
      pos: [12, 2, 3], 
      state: 6
    }, 
    {
      pos: [13, 2, 3], 
      state: 6
    }, 
    {
      pos: [1, 2, 4], 
      state: 11
    }, 
    {
      pos: [2, 2, 4], 
      state: 6
    }, 
    {
      pos: [3, 2, 4], 
      state: 6
    }, 
    {
      pos: [4, 2, 4], 
      state: 6
    }, 
    {
      pos: [5, 2, 4], 
      state: 6
    }, 
    {
      pos: [6, 2, 4], 
      state: 6
    }, 
    {
      pos: [7, 2, 4], 
      state: 6
    }, 
    {
      pos: [8, 2, 4], 
      state: 6
    }, 
    {
      pos: [9, 2, 4], 
      state: 6
    }, 
    {
      pos: [10, 2, 4], 
      state: 6
    }, 
    {
      pos: [11, 2, 4], 
      state: 6
    }, 
    {
      pos: [12, 2, 4], 
      state: 6
    }, 
    {
      pos: [13, 2, 4], 
      state: 6
    }, 
    {
      pos: [1, 2, 5], 
      state: 6
    }, 
    {
      pos: [2, 2, 5], 
      state: 6
    }, 
    {
      pos: [3, 2, 5], 
      state: 6
    }, 
    {
      pos: [4, 2, 5], 
      state: 6
    }, 
    {
      pos: [5, 2, 5], 
      state: 6
    }, 
    {
      pos: [6, 2, 5], 
      state: 6
    }, 
    {
      pos: [7, 2, 5], 
      state: 6
    }, 
    {
      pos: [8, 2, 5], 
      state: 6
    }, 
    {
      pos: [9, 2, 5], 
      state: 12
    }, 
    {
      pos: [10, 2, 5], 
      state: 6
    }, 
    {
      pos: [11, 2, 5], 
      state: 6
    }, 
    {
      pos: [12, 2, 5], 
      state: 6
    }, 
    {
      pos: [13, 2, 5], 
      state: 6
    }, 
    {
      pos: [2, 2, 6], 
      state: 6
    }, 
    {
      pos: [3, 2, 6], 
      state: 6
    }, 
    {
      pos: [4, 2, 6], 
      state: 6
    }, 
    {
      pos: [5, 2, 6], 
      state: 6
    }, 
    {
      pos: [6, 2, 6], 
      state: 6
    }, 
    {
      pos: [7, 2, 6], 
      state: 6
    }, 
    {
      pos: [10, 2, 6], 
      state: 6
    }, 
    {
      pos: [11, 2, 6], 
      state: 6
    }, 
    {
      pos: [12, 2, 6], 
      state: 6
    }, 
    {
      pos: [10, 2, 7], 
      state: 6
    }, 
    {
      pos: [11, 2, 7], 
      state: 6
    }, 
    {
      pos: [13, 2, 7], 
      state: 6
    }, 
    {
      pos: [0, 3, 0], 
      state: 0
    }, 
    {
      pos: [1, 3, 0], 
      state: 0
    }, 
    {
      pos: [2, 3, 0], 
      state: 0
    }, 
    {
      pos: [4, 3, 0], 
      state: 0
    }, 
    {
      pos: [6, 3, 0], 
      state: 1
    }, 
    {
      pos: [7, 3, 0], 
      state: 0
    }, 
    {
      pos: [8, 3, 0], 
      state: 0
    }, 
    {
      pos: [9, 3, 0], 
      state: 0
    }, 
    {
      pos: [0, 3, 1], 
      state: 0
    }, 
    {
      pos: [1, 3, 1], 
      state: 0
    }, 
    {
      pos: [8, 3, 1], 
      state: 0
    }, 
    {
      pos: [9, 3, 1], 
      state: 0
    }, 
    {
      pos: [0, 3, 2], 
      state: 2
    }, 
    {
      pos: [0, 3, 5], 
      state: 0
    }, 
    {
      pos: [0, 3, 6], 
      state: 0
    }, 
    {
      pos: [1, 3, 6], 
      state: 0
    }, 
    {
      pos: [8, 3, 6], 
      state: 0
    }, 
    {
      pos: [9, 3, 6], 
      state: 0
    }, 
    {
      pos: [0, 3, 7], 
      state: 2
    }, 
    {
      pos: [1, 3, 7], 
      state: 0
    }, 
    {
      pos: [2, 3, 7], 
      state: 0
    }, 
    {
      pos: [4, 3, 7], 
      state: 0
    }, 
    {
      pos: [7, 3, 7], 
      state: 1
    }, 
    {
      pos: [8, 3, 7], 
      state: 0
    }, 
    {
      pos: [9, 3, 7], 
      state: 0
    }, 
    {
      pos: [3, 3, 0], 
      state: 6
    }, 
    {
      pos: [11, 3, 0], 
      state: 6
    }, 
    {
      pos: [12, 3, 0], 
      state: 6
    }, 
    {
      pos: [13, 3, 0], 
      state: 6
    }, 
    {
      pos: [2, 3, 1], 
      state: 6
    }, 
    {
      pos: [3, 3, 1], 
      state: 6
    }, 
    {
      pos: [4, 3, 1], 
      state: 6
    }, 
    {
      pos: [5, 3, 1], 
      state: 6
    }, 
    {
      pos: [6, 3, 1], 
      state: 6
    }, 
    {
      pos: [7, 3, 1], 
      state: 6
    }, 
    {
      pos: [10, 3, 1], 
      state: 6
    }, 
    {
      pos: [11, 3, 1], 
      state: 6
    }, 
    {
      pos: [12, 3, 1], 
      state: 6
    }, 
    {
      pos: [13, 3, 1], 
      state: 6
    }, 
    {
      pos: [1, 3, 2], 
      state: 6
    }, 
    {
      pos: [2, 3, 2], 
      state: 6
    }, 
    {
      pos: [3, 3, 2], 
      state: 6
    }, 
    {
      pos: [4, 3, 2], 
      state: 6
    }, 
    {
      pos: [5, 3, 2], 
      state: 6
    }, 
    {
      pos: [6, 3, 2], 
      state: 6
    }, 
    {
      pos: [7, 3, 2], 
      state: 6
    }, 
    {
      pos: [8, 3, 2], 
      state: 6
    }, 
    {
      pos: [9, 3, 2], 
      state: 13
    }, 
    {
      pos: [10, 3, 2], 
      state: 6
    }, 
    {
      pos: [11, 3, 2], 
      state: 6
    }, 
    {
      pos: [0, 3, 3], 
      state: 6
    }, 
    {
      pos: [1, 3, 3], 
      state: 6
    }, 
    {
      pos: [2, 3, 3], 
      state: 6
    }, 
    {
      pos: [3, 3, 3], 
      state: 6
    }, 
    {
      pos: [4, 3, 3], 
      state: 6
    }, 
    {
      pos: [5, 3, 3], 
      state: 6
    }, 
    {
      pos: [6, 3, 3], 
      state: 6
    }, 
    {
      pos: [7, 3, 3], 
      state: 6
    }, 
    {
      pos: [8, 3, 3], 
      state: 6
    }, 
    {
      pos: [9, 3, 3], 
      state: 6
    }, 
    {
      pos: [10, 3, 3], 
      state: 6
    }, 
    {
      pos: [11, 3, 3], 
      state: 6
    }, 
    {
      pos: [12, 3, 3], 
      state: 6
    }, 
    {
      pos: [13, 3, 3], 
      state: 6
    }, 
    {
      pos: [0, 3, 4], 
      state: 6
    }, 
    {
      pos: [1, 3, 4], 
      state: 11
    }, 
    {
      pos: [2, 3, 4], 
      state: 6
    }, 
    {
      pos: [3, 3, 4], 
      state: 6
    }, 
    {
      pos: [4, 3, 4], 
      state: 6
    }, 
    {
      pos: [5, 3, 4], 
      state: 6
    }, 
    {
      pos: [6, 3, 4], 
      state: 6
    }, 
    {
      pos: [7, 3, 4], 
      state: 14
    }, 
    {
      pos: [8, 3, 4], 
      state: 6
    }, 
    {
      pos: [9, 3, 4], 
      state: 6
    }, 
    {
      pos: [10, 3, 4], 
      state: 6
    }, 
    {
      pos: [11, 3, 4], 
      state: 6
    }, 
    {
      pos: [12, 3, 4], 
      state: 6
    }, 
    {
      pos: [13, 3, 4], 
      state: 6
    }, 
    {
      pos: [1, 3, 5], 
      state: 6
    }, 
    {
      pos: [2, 3, 5], 
      state: 6
    }, 
    {
      pos: [3, 3, 5], 
      state: 6
    }, 
    {
      pos: [4, 3, 5], 
      state: 6
    }, 
    {
      pos: [5, 3, 5], 
      state: 6
    }, 
    {
      pos: [6, 3, 5], 
      state: 6
    }, 
    {
      pos: [7, 3, 5], 
      state: 6
    }, 
    {
      pos: [8, 3, 5], 
      state: 6
    }, 
    {
      pos: [9, 3, 5], 
      state: 12
    }, 
    {
      pos: [10, 3, 5], 
      state: 6
    }, 
    {
      pos: [11, 3, 5], 
      state: 6
    }, 
    {
      pos: [12, 3, 5], 
      state: 6
    }, 
    {
      pos: [13, 3, 5], 
      state: 6
    }, 
    {
      pos: [2, 3, 6], 
      state: 6
    }, 
    {
      pos: [3, 3, 6], 
      state: 6
    }, 
    {
      pos: [4, 3, 6], 
      state: 6
    }, 
    {
      pos: [5, 3, 6], 
      state: 6
    }, 
    {
      pos: [6, 3, 6], 
      state: 6
    }, 
    {
      pos: [7, 3, 6], 
      state: 6
    }, 
    {
      pos: [11, 3, 6], 
      state: 6
    }, 
    {
      pos: [12, 3, 6], 
      state: 6
    }, 
    {
      pos: [13, 3, 6], 
      state: 6
    }, 
    {
      pos: [3, 3, 7], 
      state: 6
    }, 
    {
      pos: [5, 3, 7], 
      state: 6
    }, 
    {
      pos: [6, 3, 7], 
      state: 6
    }, 
    {
      pos: [11, 3, 7], 
      state: 6
    }, 
    {
      pos: [12, 3, 7], 
      state: 6
    }, 
    {
      pos: [13, 3, 7], 
      state: 6
    }, 
    {
      pos: [0, 4, 0], 
      state: 0
    }, 
    {
      pos: [1, 4, 0], 
      state: 0
    }, 
    {
      pos: [2, 4, 0], 
      state: 0
    }, 
    {
      pos: [3, 4, 0], 
      state: 0
    }, 
    {
      pos: [4, 4, 0], 
      state: 0
    }, 
    {
      pos: [5, 4, 0], 
      state: 0
    }, 
    {
      pos: [6, 4, 0], 
      state: 0
    }, 
    {
      pos: [7, 4, 0], 
      state: 0
    }, 
    {
      pos: [8, 4, 0], 
      state: 0
    }, 
    {
      pos: [9, 4, 0], 
      state: 0
    }, 
    {
      pos: [10, 4, 0], 
      state: 0
    }, 
    {
      pos: [11, 4, 0], 
      state: 0
    }, 
    {
      pos: [12, 4, 0], 
      state: 0
    }, 
    {
      pos: [13, 4, 0], 
      state: 0
    }, 
    {
      pos: [0, 4, 1], 
      state: 0
    }, 
    {
      pos: [1, 4, 1], 
      state: 0
    }, 
    {
      pos: [7, 4, 1], 
      state: 0
    }, 
    {
      pos: [8, 4, 1], 
      state: 0
    }, 
    {
      pos: [11, 4, 1], 
      state: 0
    }, 
    {
      pos: [13, 4, 1], 
      state: 0
    }, 
    {
      pos: [7, 4, 2], 
      state: 0
    }, 
    {
      pos: [8, 4, 2], 
      state: 0
    }, 
    {
      pos: [9, 4, 2], 
      state: 0
    }, 
    {
      pos: [10, 4, 2], 
      state: 0
    }, 
    {
      pos: [11, 4, 2], 
      state: 0
    }, 
    {
      pos: [12, 4, 2], 
      state: 0
    }, 
    {
      pos: [13, 4, 2], 
      state: 0
    }, 
    {
      pos: [7, 4, 3], 
      state: 0
    }, 
    {
      pos: [10, 4, 3], 
      state: 0
    }, 
    {
      pos: [11, 4, 3], 
      state: 0
    }, 
    {
      pos: [12, 4, 3], 
      state: 0
    }, 
    {
      pos: [7, 4, 4], 
      state: 0
    }, 
    {
      pos: [11, 4, 4], 
      state: 0
    }, 
    {
      pos: [12, 4, 4], 
      state: 0
    }, 
    {
      pos: [13, 4, 4], 
      state: 0
    }, 
    {
      pos: [7, 4, 5], 
      state: 0
    }, 
    {
      pos: [8, 4, 5], 
      state: 0
    }, 
    {
      pos: [9, 4, 5], 
      state: 0
    }, 
    {
      pos: [10, 4, 5], 
      state: 0
    }, 
    {
      pos: [11, 4, 5], 
      state: 0
    }, 
    {
      pos: [12, 4, 5], 
      state: 0
    }, 
    {
      pos: [13, 4, 5], 
      state: 0
    }, 
    {
      pos: [0, 4, 6], 
      state: 0
    }, 
    {
      pos: [1, 4, 6], 
      state: 0
    }, 
    {
      pos: [7, 4, 6], 
      state: 0
    }, 
    {
      pos: [8, 4, 6], 
      state: 0
    }, 
    {
      pos: [9, 4, 6], 
      state: 0
    }, 
    {
      pos: [10, 4, 6], 
      state: 0
    }, 
    {
      pos: [11, 4, 6], 
      state: 0
    }, 
    {
      pos: [0, 4, 7], 
      state: 2
    }, 
    {
      pos: [1, 4, 7], 
      state: 2
    }, 
    {
      pos: [2, 4, 7], 
      state: 0
    }, 
    {
      pos: [3, 4, 7], 
      state: 0
    }, 
    {
      pos: [4, 4, 7], 
      state: 0
    }, 
    {
      pos: [5, 4, 7], 
      state: 1
    }, 
    {
      pos: [7, 4, 7], 
      state: 0
    }, 
    {
      pos: [8, 4, 7], 
      state: 0
    }, 
    {
      pos: [9, 4, 7], 
      state: 0
    }, 
    {
      pos: [10, 4, 7], 
      state: 0
    }, 
    {
      pos: [11, 4, 7], 
      state: 0
    }, 
    {
      pos: [2, 4, 1], 
      state: 6
    }, 
    {
      pos: [3, 4, 1], 
      state: 6
    }, 
    {
      pos: [4, 4, 1], 
      state: 6
    }, 
    {
      pos: [5, 4, 1], 
      state: 6
    }, 
    {
      pos: [6, 4, 1], 
      state: 6
    }, 
    {
      pos: [9, 4, 1], 
      state: 6
    }, 
    {
      pos: [10, 4, 1], 
      state: 6
    }, 
    {
      pos: [12, 4, 1], 
      state: 6
    }, 
    {
      pos: [0, 4, 2], 
      state: 6
    }, 
    {
      pos: [1, 4, 2], 
      state: 6
    }, 
    {
      pos: [2, 4, 2], 
      state: 6
    }, 
    {
      pos: [3, 4, 2], 
      state: 6
    }, 
    {
      pos: [4, 4, 2], 
      state: 6
    }, 
    {
      pos: [5, 4, 2], 
      state: 6
    }, 
    {
      pos: [6, 4, 2], 
      state: 6
    }, 
    {
      pos: [0, 4, 3], 
      state: 6
    }, 
    {
      pos: [1, 4, 3], 
      state: 6
    }, 
    {
      pos: [2, 4, 3], 
      state: 6
    }, 
    {
      pos: [3, 4, 3], 
      state: 6
    }, 
    {
      pos: [4, 4, 3], 
      state: 6
    }, 
    {
      pos: [5, 4, 3], 
      state: 6
    }, 
    {
      pos: [6, 4, 3], 
      state: 6
    }, 
    {
      pos: [8, 4, 3], 
      state: 6
    }, 
    {
      pos: [9, 4, 3], 
      state: 6
    }, 
    {
      pos: [13, 4, 3], 
      state: 6
    }, 
    {
      pos: [0, 4, 4], 
      state: 6
    }, 
    {
      pos: [1, 4, 4], 
      state: 11
    }, 
    {
      pos: [2, 4, 4], 
      state: 6
    }, 
    {
      pos: [3, 4, 4], 
      state: 6
    }, 
    {
      pos: [4, 4, 4], 
      state: 6
    }, 
    {
      pos: [5, 4, 4], 
      state: 6
    }, 
    {
      pos: [6, 4, 4], 
      state: 6
    }, 
    {
      pos: [8, 4, 4], 
      state: 6
    }, 
    {
      pos: [9, 4, 4], 
      state: 6
    }, 
    {
      pos: [10, 4, 4], 
      state: 6
    }, 
    {
      pos: [0, 4, 5], 
      state: 6
    }, 
    {
      pos: [1, 4, 5], 
      state: 6
    }, 
    {
      pos: [2, 4, 5], 
      state: 6
    }, 
    {
      pos: [3, 4, 5], 
      state: 6
    }, 
    {
      pos: [4, 4, 5], 
      state: 6
    }, 
    {
      pos: [5, 4, 5], 
      state: 6
    }, 
    {
      pos: [6, 4, 5], 
      state: 6
    }, 
    {
      pos: [2, 4, 6], 
      state: 6
    }, 
    {
      pos: [3, 4, 6], 
      state: 6
    }, 
    {
      pos: [4, 4, 6], 
      state: 6
    }, 
    {
      pos: [5, 4, 6], 
      state: 6
    }, 
    {
      pos: [6, 4, 6], 
      state: 6
    }, 
    {
      pos: [13, 4, 6], 
      state: 6
    }, 
    {
      pos: [6, 4, 7], 
      state: 6
    }, 
    {
      pos: [13, 4, 7], 
      state: 6
    }, 
    {
      pos: [2, 5, 0], 
      state: 0
    }, 
    {
      pos: [3, 5, 0], 
      state: 0
    }, 
    {
      pos: [4, 5, 0], 
      state: 0
    }, 
    {
      pos: [5, 5, 0], 
      state: 0
    }, 
    {
      pos: [6, 5, 0], 
      state: 0
    }, 
    {
      pos: [12, 5, 0], 
      state: 0
    }, 
    {
      pos: [13, 5, 0], 
      state: 0
    }, 
    {
      pos: [2, 5, 1], 
      state: 0
    }, 
    {
      pos: [3, 5, 1], 
      state: 0
    }, 
    {
      pos: [4, 5, 1], 
      state: 0
    }, 
    {
      pos: [5, 5, 1], 
      state: 0
    }, 
    {
      pos: [6, 5, 1], 
      state: 0
    }, 
    {
      pos: [1, 5, 2], 
      state: 0
    }, 
    {
      pos: [2, 5, 2], 
      state: 0
    }, 
    {
      pos: [3, 5, 2], 
      state: 0
    }, 
    {
      pos: [4, 5, 2], 
      state: 0
    }, 
    {
      pos: [5, 5, 2], 
      state: 0
    }, 
    {
      pos: [6, 5, 2], 
      state: 0
    }, 
    {
      pos: [7, 5, 2], 
      state: 0
    }, 
    {
      pos: [1, 5, 3], 
      state: 3
    }, 
    {
      pos: [2, 5, 3], 
      state: 0
    }, 
    {
      pos: [3, 5, 3], 
      state: 0
    }, 
    {
      pos: [4, 5, 3], 
      state: 0
    }, 
    {
      pos: [5, 5, 3], 
      state: 0
    }, 
    {
      pos: [6, 5, 3], 
      state: 0
    }, 
    {
      pos: [7, 5, 3], 
      state: 0
    }, 
    {
      pos: [0, 5, 4], 
      state: 3
    }, 
    {
      pos: [2, 5, 4], 
      state: 0
    }, 
    {
      pos: [3, 5, 4], 
      state: 0
    }, 
    {
      pos: [4, 5, 4], 
      state: 0
    }, 
    {
      pos: [5, 5, 4], 
      state: 0
    }, 
    {
      pos: [6, 5, 4], 
      state: 0
    }, 
    {
      pos: [7, 5, 4], 
      state: 0
    }, 
    {
      pos: [12, 5, 4], 
      state: 0
    }, 
    {
      pos: [13, 5, 4], 
      state: 0
    }, 
    {
      pos: [0, 5, 5], 
      state: 0
    }, 
    {
      pos: [1, 5, 5], 
      state: 0
    }, 
    {
      pos: [2, 5, 5], 
      state: 0
    }, 
    {
      pos: [3, 5, 5], 
      state: 0
    }, 
    {
      pos: [4, 5, 5], 
      state: 0
    }, 
    {
      pos: [5, 5, 5], 
      state: 0
    }, 
    {
      pos: [6, 5, 5], 
      state: 0
    }, 
    {
      pos: [7, 5, 5], 
      state: 0
    }, 
    {
      pos: [8, 5, 5], 
      state: 0
    }, 
    {
      pos: [12, 5, 5], 
      state: 0
    }, 
    {
      pos: [0, 5, 6], 
      state: 2
    }, 
    {
      pos: [1, 5, 6], 
      state: 0
    }, 
    {
      pos: [2, 5, 6], 
      state: 0
    }, 
    {
      pos: [3, 5, 6], 
      state: 0
    }, 
    {
      pos: [4, 5, 6], 
      state: 0
    }, 
    {
      pos: [5, 5, 6], 
      state: 0
    }, 
    {
      pos: [6, 5, 6], 
      state: 0
    }, 
    {
      pos: [7, 5, 6], 
      state: 0
    }, 
    {
      pos: [8, 5, 6], 
      state: 0
    }, 
    {
      pos: [9, 5, 6], 
      state: 0
    }, 
    {
      pos: [10, 5, 6], 
      state: 0
    }, 
    {
      pos: [0, 5, 7], 
      state: 2
    }, 
    {
      pos: [1, 5, 7], 
      state: 2
    }, 
    {
      pos: [2, 5, 7], 
      state: 0
    }, 
    {
      pos: [3, 5, 7], 
      state: 0
    }, 
    {
      pos: [4, 5, 7], 
      state: 0
    }, 
    {
      pos: [5, 5, 7], 
      state: 1
    }, 
    {
      pos: [6, 5, 7], 
      state: 1
    }, 
    {
      pos: [7, 5, 7], 
      state: 0
    }, 
    {
      pos: [8, 5, 7], 
      state: 0
    }, 
    {
      pos: [9, 5, 7], 
      state: 0
    }, 
    {
      pos: [10, 5, 7], 
      state: 0
    }, 
    {
      pos: [11, 5, 7], 
      state: 0
    }, 
    {
      pos: [0, 5, 0], 
      state: 6
    }, 
    {
      pos: [1, 5, 0], 
      state: 6
    }, 
    {
      pos: [7, 5, 0], 
      state: 6
    }, 
    {
      pos: [8, 5, 0], 
      state: 6
    }, 
    {
      pos: [9, 5, 0], 
      state: 6
    }, 
    {
      pos: [10, 5, 0], 
      state: 6
    }, 
    {
      pos: [11, 5, 0], 
      state: 6
    }, 
    {
      pos: [0, 5, 1], 
      state: 6
    }, 
    {
      pos: [1, 5, 1], 
      state: 6
    }, 
    {
      pos: [7, 5, 1], 
      state: 6
    }, 
    {
      pos: [8, 5, 1], 
      state: 6
    }, 
    {
      pos: [9, 5, 1], 
      state: 6
    }, 
    {
      pos: [10, 5, 1], 
      state: 6
    }, 
    {
      pos: [11, 5, 1], 
      state: 6
    }, 
    {
      pos: [12, 5, 1], 
      state: 6
    }, 
    {
      pos: [13, 5, 1], 
      state: 6
    }, 
    {
      pos: [0, 5, 2], 
      state: 6
    }, 
    {
      pos: [8, 5, 2], 
      state: 6
    }, 
    {
      pos: [9, 5, 2], 
      state: 6
    }, 
    {
      pos: [10, 5, 2], 
      state: 6
    }, 
    {
      pos: [11, 5, 2], 
      state: 6
    }, 
    {
      pos: [12, 5, 2], 
      state: 6
    }, 
    {
      pos: [13, 5, 2], 
      state: 6
    }, 
    {
      pos: [0, 5, 3], 
      state: 6
    }, 
    {
      pos: [8, 5, 3], 
      state: 6
    }, 
    {
      pos: [9, 5, 3], 
      state: 6
    }, 
    {
      pos: [10, 5, 3], 
      state: 6
    }, 
    {
      pos: [11, 5, 3], 
      state: 6
    }, 
    {
      pos: [12, 5, 3], 
      state: 6
    }, 
    {
      pos: [13, 5, 3], 
      state: 6
    }, 
    {
      pos: [1, 5, 4], 
      state: 15
    }, 
    {
      pos: [8, 5, 4], 
      state: 6
    }, 
    {
      pos: [9, 5, 4], 
      state: 6
    }, 
    {
      pos: [10, 5, 4], 
      state: 6
    }, 
    {
      pos: [11, 5, 4], 
      state: 6
    }, 
    {
      pos: [9, 5, 5], 
      state: 6
    }, 
    {
      pos: [10, 5, 5], 
      state: 6
    }, 
    {
      pos: [11, 5, 5], 
      state: 6
    }, 
    {
      pos: [13, 5, 5], 
      state: 6
    }, 
    {
      pos: [12, 5, 6], 
      state: 6
    }, 
    {
      pos: [13, 5, 6], 
      state: 6
    }, 
    {
      pos: [12, 5, 7], 
      state: 6
    }, 
    {
      pos: [13, 5, 7], 
      state: 6
    }
  ], 
  palette: [
    {
      Name: "minecraft:polished_blackstone_bricks"
    }, 
    {
      Name: "minecraft:cracked_polished_blackstone_bricks"
    }, 
    {
      Properties: {
        axis: "y"
      }, 
      Name: "minecraft:basalt"
    }, 
    {
      Name: "minecraft:blackstone"
    }, 
    {
      Properties: {
        orientation: "north_up"
      }, 
      Name: "minecraft:jigsaw"
    }, 
    {
      Properties: {
        orientation: "south_up"
      }, 
      Name: "minecraft:jigsaw"
    }, 
    {
      Name: "minecraft:air"
    }, 
    {
      Properties: {
        level: "4"
      }, 
      Name: "minecraft:lava"
    }, 
    {
      Properties: {
        level: "6"
      }, 
      Name: "minecraft:lava"
    }, 
    {
      Properties: {
        east: "none", 
        waterlogged: "false", 
        south: "none", 
        north: "low", 
        west: "none", 
        up: "true"
      }, 
      Name: "minecraft:blackstone_wall"
    }, 
    {
      Properties: {
        level: "2"
      }, 
      Name: "minecraft:lava"
    }, 
    {
      Properties: {
        level: "8"
      }, 
      Name: "minecraft:lava"
    }, 
    {
      Properties: {
        east: "none", 
        waterlogged: "false", 
        south: "tall", 
        north: "none", 
        west: "none", 
        up: "true"
      }, 
      Name: "minecraft:blackstone_wall"
    }, 
    {
      Properties: {
        east: "none", 
        waterlogged: "false", 
        south: "none", 
        north: "tall", 
        west: "none", 
        up: "true"
      }, 
      Name: "minecraft:blackstone_wall"
    }, 
    {
      Properties: {
        hanging: "true"
      }, 
      Name: "minecraft:lantern"
    }, 
    {
      Properties: {
        level: "0"
      }, 
      Name: "minecraft:lava"
    }
  ]
}
