{
  size: [5, 5, 5], 
  entities: [], 
  blocks: [
    {
      pos: [0, 0, 0], 
      state: 0
    }, 
    {
      pos: [0, 0, 1], 
      state: 0
    }, 
    {
      pos: [0, 0, 2], 
      state: 0
    }, 
    {
      pos: [0, 0, 3], 
      state: 0
    }, 
    {
      pos: [0, 0, 4], 
      state: 0
    }, 
    {
      pos: [1, 0, 0], 
      state: 0
    }, 
    {
      pos: [1, 0, 1], 
      state: 0
    }, 
    {
      pos: [1, 0, 2], 
      state: 0
    }, 
    {
      pos: [1, 0, 3], 
      state: 0
    }, 
    {
      pos: [1, 0, 4], 
      state: 0
    }, 
    {
      pos: [2, 0, 0], 
      state: 0
    }, 
    {
      pos: [2, 0, 1], 
      state: 0
    }, 
    {
      pos: [2, 0, 2], 
      state: 0
    }, 
    {
      pos: [2, 0, 3], 
      state: 0
    }, 
    {
      pos: [2, 0, 4], 
      state: 0
    }, 
    {
      pos: [3, 0, 0], 
      state: 0
    }, 
    {
      pos: [3, 0, 1], 
      state: 0
    }, 
    {
      pos: [3, 0, 2], 
      state: 0
    }, 
    {
      pos: [3, 0, 3], 
      state: 0
    }, 
    {
      pos: [3, 0, 4], 
      state: 0
    }, 
    {
      pos: [4, 0, 0], 
      state: 0
    }, 
    {
      pos: [4, 0, 1], 
      state: 0
    }, 
    {
      pos: [4, 0, 2], 
      state: 0
    }, 
    {
      pos: [4, 0, 3], 
      state: 0
    }, 
    {
      pos: [4, 0, 4], 
      state: 0
    }, 
    {
      pos: [0, 1, 0], 
      state: 1
    }, 
    {
      pos: [0, 1, 1], 
      state: 0
    }, 
    {
      pos: [0, 1, 2], 
      state: 2
    }, 
    {
      pos: [0, 1, 3], 
      state: 0
    }, 
    {
      pos: [0, 1, 4], 
      state: 2
    }, 
    {
      pos: [1, 1, 0], 
      state: 3
    }, 
    {
      pos: [1, 1, 1], 
      state: 0
    }, 
    {
      pos: [1, 1, 2], 
      state: 2
    }, 
    {
      pos: [1, 1, 3], 
      state: 0
    }, 
    {
      pos: [1, 1, 4], 
      state: 2
    }, 
    {
      pos: [2, 1, 0], 
      state: 3
    }, 
    {
      pos: [2, 1, 1], 
      state: 1
    }, 
    {
      pos: [2, 1, 2], 
      state: 1
    }, 
    {
      pos: [2, 1, 3], 
      state: 0
    }, 
    {
      pos: [2, 1, 4], 
      state: 1
    }, 
    {
      pos: [3, 1, 0], 
      state: 0
    }, 
    {
      pos: [3, 1, 1], 
      state: 1
    }, 
    {
      pos: [3, 1, 2], 
      state: 3
    }, 
    {
      pos: [3, 1, 3], 
      state: 1
    }, 
    {
      pos: [3, 1, 4], 
      state: 0
    }, 
    {
      pos: [4, 1, 0], 
      state: 2
    }, 
    {
      pos: [4, 1, 1], 
      state: 0
    }, 
    {
      pos: [4, 1, 3], 
      state: 0
    }, 
    {
      pos: [4, 1, 4], 
      state: 0
    }, 
    {
      pos: [0, 2, 0], 
      state: 4
    }, 
    {
      pos: [0, 2, 1], 
      state: 4
    }, 
    {
      pos: [0, 2, 3], 
      state: 4
    }, 
    {
      pos: [0, 2, 4], 
      state: 4
    }, 
    {
      pos: [1, 2, 0], 
      state: 4
    }, 
    {
      pos: [1, 2, 1], 
      state: 4
    }, 
    {
      pos: [1, 2, 2], 
      state: 4
    }, 
    {
      pos: [1, 2, 3], 
      state: 4
    }, 
    {
      pos: [2, 2, 0], 
      state: 4
    }, 
    {
      pos: [2, 2, 1], 
      state: 4
    }, 
    {
      pos: [2, 2, 2], 
      state: 4
    }, 
    {
      pos: [2, 2, 3], 
      state: 4
    }, 
    {
      pos: [3, 2, 0], 
      state: 4
    }, 
    {
      pos: [3, 2, 1], 
      state: 4
    }, 
    {
      pos: [3, 2, 2], 
      state: 4
    }, 
    {
      pos: [3, 2, 3], 
      state: 4
    }, 
    {
      pos: [4, 2, 0], 
      state: 4
    }, 
    {
      pos: [4, 2, 1], 
      state: 4
    }, 
    {
      pos: [4, 2, 2], 
      state: 4
    }, 
    {
      pos: [4, 2, 3], 
      state: 4
    }, 
    {
      pos: [4, 2, 4], 
      state: 4
    }, 
    {
      pos: [0, 3, 1], 
      state: 4
    }, 
    {
      pos: [0, 3, 2], 
      state: 4
    }, 
    {
      pos: [0, 3, 3], 
      state: 4
    }, 
    {
      pos: [0, 3, 4], 
      state: 4
    }, 
    {
      pos: [1, 3, 0], 
      state: 4
    }, 
    {
      pos: [1, 3, 1], 
      state: 4
    }, 
    {
      pos: [1, 3, 2], 
      state: 4
    }, 
    {
      pos: [1, 3, 3], 
      state: 4
    }, 
    {
      pos: [1, 3, 4], 
      state: 4
    }, 
    {
      pos: [2, 3, 0], 
      state: 4
    }, 
    {
      pos: [2, 3, 1], 
      state: 4
    }, 
    {
      pos: [2, 3, 2], 
      state: 4
    }, 
    {
      pos: [2, 3, 3], 
      state: 4
    }, 
    {
      pos: [2, 3, 4], 
      state: 4
    }, 
    {
      pos: [3, 3, 0], 
      state: 4
    }, 
    {
      pos: [3, 3, 1], 
      state: 4
    }, 
    {
      pos: [3, 3, 2], 
      state: 4
    }, 
    {
      pos: [3, 3, 3], 
      state: 4
    }, 
    {
      pos: [3, 3, 4], 
      state: 4
    }, 
    {
      pos: [4, 3, 0], 
      state: 4
    }, 
    {
      pos: [4, 3, 1], 
      state: 4
    }, 
    {
      pos: [4, 3, 2], 
      state: 4
    }, 
    {
      pos: [4, 3, 3], 
      state: 4
    }, 
    {
      pos: [4, 3, 4], 
      state: 4
    }, 
    {
      pos: [0, 4, 1], 
      state: 4
    }, 
    {
      pos: [0, 4, 2], 
      state: 4
    }, 
    {
      pos: [1, 4, 1], 
      state: 4
    }, 
    {
      pos: [1, 4, 2], 
      state: 4
    }, 
    {
      pos: [1, 4, 3], 
      state: 4
    }, 
    {
      pos: [2, 4, 1], 
      state: 4
    }, 
    {
      pos: [2, 4, 2], 
      state: 4
    }, 
    {
      pos: [2, 4, 3], 
      state: 4
    }, 
    {
      pos: [3, 4, 1], 
      state: 4
    }, 
    {
      pos: [3, 4, 2], 
      state: 4
    }, 
    {
      pos: [3, 4, 3], 
      state: 4
    }, 
    {
      pos: [4, 4, 2], 
      state: 4
    }, 
    {
      pos: [4, 4, 3], 
      state: 4
    }, 
    {
      nbt: {
        joint: "rollable", 
        final_state: "minecraft:cobblestone", 
        name: "minecraft:road_out", 
        pool: "minecraft:trail_ruins/roads", 
        id: "minecraft:jigsaw", 
        target: "minecraft:road_in"
      }, 
      pos: [4, 1, 2], 
      state: 5
    }, 
    {
      nbt: {
        joint: "rollable", 
        final_state: "minecraft:cobblestone", 
        name: "minecraft:road_in", 
        pool: "minecraft:trail_ruins/roads", 
        id: "minecraft:jigsaw", 
        target: "minecraft:road_out"
      }, 
      pos: [0, 2, 2], 
      state: 6
    }, 
    {
      nbt: {
        joint: "rollable", 
        final_state: "minecraft:air", 
        name: "minecraft:road_anchor", 
        pool: "minecraft:trail_ruins/buildings", 
        id: "minecraft:jigsaw", 
        target: "minecraft:building_anchor"
      }, 
      pos: [1, 2, 4], 
      state: 7
    }, 
    {
      nbt: {
        joint: "rollable", 
        final_state: "minecraft:air", 
        name: "minecraft:road_anchor", 
        pool: "minecraft:trail_ruins/buildings", 
        id: "minecraft:jigsaw", 
        target: "minecraft:building_anchor"
      }, 
      pos: [2, 2, 4], 
      state: 7
    }, 
    {
      nbt: {
        joint: "rollable", 
        final_state: "minecraft:air", 
        name: "minecraft:road_anchor", 
        pool: "minecraft:trail_ruins/buildings", 
        id: "minecraft:jigsaw", 
        target: "minecraft:building_anchor"
      }, 
      pos: [3, 2, 4], 
      state: 7
    }
  ], 
  palette: [
    {
      Name: "minecraft:cobblestone"
    }, 
    {
      Name: "minecraft:cracked_stone_bricks"
    }, 
    {
      Name: "minecraft:stone"
    }, 
    {
      Name: "minecraft:stone_bricks"
    }, 
    {
      Name: "minecraft:gravel"
    }, 
    {
      Properties: {
        orientation: "east_up"
      }, 
      Name: "minecraft:jigsaw"
    }, 
    {
      Properties: {
        orientation: "west_up"
      }, 
      Name: "minecraft:jigsaw"
    }, 
    {
      Properties: {
        orientation: "south_up"
      }, 
      Name: "minecraft:jigsaw"
    }
  ]
}
