{
  size: [9, 6, 9], 
  entities: [], 
  blocks: [
    {
      pos: [0, 0, 0], 
      state: 0
    }, 
    {
      pos: [0, 0, 1], 
      state: 1
    }, 
    {
      pos: [0, 0, 2], 
      state: 1
    }, 
    {
      pos: [0, 0, 3], 
      state: 1
    }, 
    {
      pos: [0, 0, 4], 
      state: 0
    }, 
    {
      pos: [0, 0, 5], 
      state: 1
    }, 
    {
      pos: [0, 0, 6], 
      state: 1
    }, 
    {
      pos: [0, 0, 7], 
      state: 1
    }, 
    {
      pos: [0, 0, 8], 
      state: 0
    }, 
    {
      pos: [1, 0, 0], 
      state: 1
    }, 
    {
      pos: [1, 0, 1], 
      state: 0
    }, 
    {
      pos: [1, 0, 2], 
      state: 0
    }, 
    {
      pos: [1, 0, 3], 
      state: 0
    }, 
    {
      pos: [1, 0, 4], 
      state: 1
    }, 
    {
      pos: [1, 0, 5], 
      state: 0
    }, 
    {
      pos: [1, 0, 6], 
      state: 0
    }, 
    {
      pos: [1, 0, 7], 
      state: 0
    }, 
    {
      pos: [1, 0, 8], 
      state: 1
    }, 
    {
      pos: [2, 0, 0], 
      state: 1
    }, 
    {
      pos: [2, 0, 1], 
      state: 0
    }, 
    {
      pos: [2, 0, 2], 
      state: 0
    }, 
    {
      pos: [2, 0, 3], 
      state: 0
    }, 
    {
      pos: [2, 0, 4], 
      state: 1
    }, 
    {
      pos: [2, 0, 5], 
      state: 0
    }, 
    {
      pos: [2, 0, 6], 
      state: 0
    }, 
    {
      pos: [2, 0, 7], 
      state: 0
    }, 
    {
      pos: [2, 0, 8], 
      state: 1
    }, 
    {
      pos: [3, 0, 0], 
      state: 1
    }, 
    {
      pos: [3, 0, 1], 
      state: 0
    }, 
    {
      pos: [3, 0, 2], 
      state: 0
    }, 
    {
      pos: [3, 0, 3], 
      state: 0
    }, 
    {
      pos: [3, 0, 4], 
      state: 1
    }, 
    {
      pos: [3, 0, 5], 
      state: 0
    }, 
    {
      pos: [3, 0, 6], 
      state: 0
    }, 
    {
      pos: [3, 0, 7], 
      state: 0
    }, 
    {
      pos: [3, 0, 8], 
      state: 1
    }, 
    {
      pos: [4, 0, 0], 
      state: 0
    }, 
    {
      pos: [4, 0, 1], 
      state: 1
    }, 
    {
      pos: [4, 0, 2], 
      state: 1
    }, 
    {
      pos: [4, 0, 3], 
      state: 1
    }, 
    {
      pos: [4, 0, 4], 
      state: 1
    }, 
    {
      pos: [4, 0, 5], 
      state: 1
    }, 
    {
      pos: [4, 0, 6], 
      state: 1
    }, 
    {
      pos: [4, 0, 7], 
      state: 1
    }, 
    {
      pos: [4, 0, 8], 
      state: 0
    }, 
    {
      pos: [5, 0, 0], 
      state: 1
    }, 
    {
      pos: [5, 0, 1], 
      state: 0
    }, 
    {
      pos: [5, 0, 2], 
      state: 0
    }, 
    {
      pos: [5, 0, 3], 
      state: 0
    }, 
    {
      pos: [5, 0, 4], 
      state: 1
    }, 
    {
      pos: [5, 0, 5], 
      state: 0
    }, 
    {
      pos: [5, 0, 6], 
      state: 0
    }, 
    {
      pos: [5, 0, 7], 
      state: 0
    }, 
    {
      pos: [5, 0, 8], 
      state: 1
    }, 
    {
      pos: [6, 0, 0], 
      state: 1
    }, 
    {
      pos: [6, 0, 1], 
      state: 0
    }, 
    {
      pos: [6, 0, 2], 
      state: 0
    }, 
    {
      pos: [6, 0, 3], 
      state: 0
    }, 
    {
      pos: [6, 0, 4], 
      state: 1
    }, 
    {
      pos: [6, 0, 5], 
      state: 0
    }, 
    {
      pos: [6, 0, 6], 
      state: 0
    }, 
    {
      pos: [6, 0, 7], 
      state: 0
    }, 
    {
      pos: [6, 0, 8], 
      state: 1
    }, 
    {
      pos: [7, 0, 0], 
      state: 1
    }, 
    {
      pos: [7, 0, 1], 
      state: 0
    }, 
    {
      pos: [7, 0, 2], 
      state: 0
    }, 
    {
      pos: [7, 0, 3], 
      state: 0
    }, 
    {
      pos: [7, 0, 4], 
      state: 1
    }, 
    {
      pos: [7, 0, 5], 
      state: 0
    }, 
    {
      pos: [7, 0, 6], 
      state: 0
    }, 
    {
      pos: [7, 0, 7], 
      state: 0
    }, 
    {
      pos: [7, 0, 8], 
      state: 1
    }, 
    {
      pos: [8, 0, 0], 
      state: 0
    }, 
    {
      pos: [8, 0, 1], 
      state: 1
    }, 
    {
      pos: [8, 0, 2], 
      state: 1
    }, 
    {
      pos: [8, 0, 3], 
      state: 1
    }, 
    {
      pos: [8, 0, 4], 
      state: 0
    }, 
    {
      pos: [8, 0, 5], 
      state: 1
    }, 
    {
      pos: [8, 0, 6], 
      state: 1
    }, 
    {
      pos: [8, 0, 7], 
      state: 1
    }, 
    {
      pos: [8, 0, 8], 
      state: 0
    }, 
    {
      pos: [0, 1, 1], 
      state: 2
    }, 
    {
      pos: [0, 1, 2], 
      state: 2
    }, 
    {
      pos: [0, 1, 3], 
      state: 2
    }, 
    {
      pos: [0, 1, 5], 
      state: 2
    }, 
    {
      pos: [0, 1, 6], 
      state: 2
    }, 
    {
      pos: [0, 1, 7], 
      state: 2
    }, 
    {
      pos: [1, 1, 0], 
      state: 2
    }, 
    {
      pos: [1, 1, 4], 
      state: 3
    }, 
    {
      pos: [1, 1, 8], 
      state: 2
    }, 
    {
      pos: [2, 1, 0], 
      state: 2
    }, 
    {
      pos: [2, 1, 4], 
      state: 3
    }, 
    {
      pos: [2, 1, 8], 
      state: 2
    }, 
    {
      pos: [3, 1, 0], 
      state: 2
    }, 
    {
      pos: [3, 1, 4], 
      state: 3
    }, 
    {
      pos: [4, 1, 1], 
      state: 3
    }, 
    {
      pos: [4, 1, 2], 
      state: 3
    }, 
    {
      pos: [4, 1, 3], 
      state: 3
    }, 
    {
      pos: [4, 1, 4], 
      state: 3
    }, 
    {
      pos: [4, 1, 5], 
      state: 3
    }, 
    {
      pos: [4, 1, 6], 
      state: 3
    }, 
    {
      pos: [4, 1, 7], 
      state: 3
    }, 
    {
      pos: [5, 1, 0], 
      state: 2
    }, 
    {
      pos: [5, 1, 4], 
      state: 3
    }, 
    {
      pos: [5, 1, 8], 
      state: 2
    }, 
    {
      pos: [6, 1, 0], 
      state: 2
    }, 
    {
      pos: [6, 1, 4], 
      state: 3
    }, 
    {
      pos: [6, 1, 8], 
      state: 2
    }, 
    {
      pos: [7, 1, 0], 
      state: 2
    }, 
    {
      pos: [7, 1, 4], 
      state: 3
    }, 
    {
      pos: [7, 1, 8], 
      state: 2
    }, 
    {
      pos: [8, 1, 1], 
      state: 2
    }, 
    {
      pos: [8, 1, 2], 
      state: 2
    }, 
    {
      pos: [8, 1, 3], 
      state: 2
    }, 
    {
      pos: [8, 1, 5], 
      state: 2
    }, 
    {
      pos: [8, 1, 6], 
      state: 2
    }, 
    {
      pos: [8, 1, 7], 
      state: 2
    }, 
    {
      pos: [0, 1, 0], 
      state: 4
    }, 
    {
      pos: [0, 1, 4], 
      state: 5
    }, 
    {
      pos: [0, 1, 8], 
      state: 6
    }, 
    {
      pos: [1, 1, 1], 
      state: 7
    }, 
    {
      pos: [1, 1, 2], 
      state: 7
    }, 
    {
      pos: [1, 1, 3], 
      state: 7
    }, 
    {
      pos: [1, 1, 5], 
      state: 7
    }, 
    {
      pos: [1, 1, 6], 
      state: 7
    }, 
    {
      pos: [1, 1, 7], 
      state: 7
    }, 
    {
      pos: [2, 1, 1], 
      state: 7
    }, 
    {
      pos: [2, 1, 2], 
      state: 7
    }, 
    {
      pos: [2, 1, 3], 
      state: 7
    }, 
    {
      pos: [2, 1, 5], 
      state: 7
    }, 
    {
      pos: [2, 1, 6], 
      state: 7
    }, 
    {
      pos: [2, 1, 7], 
      state: 7
    }, 
    {
      pos: [3, 1, 1], 
      state: 7
    }, 
    {
      pos: [3, 1, 2], 
      state: 7
    }, 
    {
      pos: [3, 1, 3], 
      state: 8
    }, 
    {
      pos: [3, 1, 5], 
      state: 8
    }, 
    {
      pos: [3, 1, 6], 
      state: 7
    }, 
    {
      pos: [3, 1, 7], 
      state: 7
    }, 
    {
      pos: [4, 1, 0], 
      state: 9
    }, 
    {
      pos: [4, 1, 8], 
      state: 10
    }, 
    {
      pos: [5, 1, 1], 
      state: 7
    }, 
    {
      pos: [5, 1, 2], 
      state: 7
    }, 
    {
      pos: [5, 1, 3], 
      state: 8
    }, 
    {
      pos: [5, 1, 5], 
      state: 8
    }, 
    {
      pos: [5, 1, 6], 
      state: 7
    }, 
    {
      pos: [5, 1, 7], 
      state: 7
    }, 
    {
      pos: [6, 1, 1], 
      state: 7
    }, 
    {
      pos: [6, 1, 2], 
      state: 7
    }, 
    {
      pos: [6, 1, 3], 
      state: 7
    }, 
    {
      pos: [6, 1, 5], 
      state: 7
    }, 
    {
      pos: [6, 1, 6], 
      state: 7
    }, 
    {
      pos: [6, 1, 7], 
      state: 7
    }, 
    {
      pos: [7, 1, 1], 
      state: 7
    }, 
    {
      pos: [7, 1, 2], 
      state: 7
    }, 
    {
      pos: [7, 1, 3], 
      state: 7
    }, 
    {
      pos: [7, 1, 5], 
      state: 7
    }, 
    {
      pos: [7, 1, 6], 
      state: 7
    }, 
    {
      pos: [7, 1, 7], 
      state: 7
    }, 
    {
      pos: [8, 1, 0], 
      state: 11
    }, 
    {
      pos: [8, 1, 4], 
      state: 12
    }, 
    {
      pos: [8, 1, 8], 
      state: 4
    }, 
    {
      pos: [0, 2, 0], 
      state: 11
    }, 
    {
      pos: [0, 2, 1], 
      state: 11
    }, 
    {
      pos: [0, 2, 2], 
      state: 11
    }, 
    {
      pos: [0, 2, 3], 
      state: 11
    }, 
    {
      pos: [0, 2, 4], 
      state: 11
    }, 
    {
      pos: [0, 2, 5], 
      state: 11
    }, 
    {
      pos: [0, 2, 6], 
      state: 11
    }, 
    {
      pos: [0, 2, 7], 
      state: 11
    }, 
    {
      pos: [0, 2, 8], 
      state: 11
    }, 
    {
      pos: [1, 2, 0], 
      state: 11
    }, 
    {
      pos: [1, 2, 1], 
      state: 13
    }, 
    {
      pos: [1, 2, 2], 
      state: 13
    }, 
    {
      pos: [1, 2, 3], 
      state: 13
    }, 
    {
      pos: [1, 2, 4], 
      state: 11
    }, 
    {
      pos: [1, 2, 5], 
      state: 13
    }, 
    {
      pos: [1, 2, 6], 
      state: 13
    }, 
    {
      pos: [1, 2, 7], 
      state: 13
    }, 
    {
      pos: [1, 2, 8], 
      state: 11
    }, 
    {
      pos: [2, 2, 0], 
      state: 11
    }, 
    {
      pos: [2, 2, 1], 
      state: 13
    }, 
    {
      pos: [2, 2, 2], 
      state: 13
    }, 
    {
      pos: [2, 2, 3], 
      state: 13
    }, 
    {
      pos: [2, 2, 4], 
      state: 11
    }, 
    {
      pos: [2, 2, 5], 
      state: 13
    }, 
    {
      pos: [2, 2, 6], 
      state: 13
    }, 
    {
      pos: [2, 2, 7], 
      state: 13
    }, 
    {
      pos: [2, 2, 8], 
      state: 11
    }, 
    {
      pos: [3, 2, 0], 
      state: 11
    }, 
    {
      pos: [3, 2, 1], 
      state: 13
    }, 
    {
      pos: [3, 2, 2], 
      state: 13
    }, 
    {
      pos: [3, 2, 3], 
      state: 11
    }, 
    {
      pos: [3, 2, 4], 
      state: 11
    }, 
    {
      pos: [3, 2, 5], 
      state: 11
    }, 
    {
      pos: [3, 2, 6], 
      state: 13
    }, 
    {
      pos: [3, 2, 7], 
      state: 13
    }, 
    {
      pos: [3, 2, 8], 
      state: 11
    }, 
    {
      pos: [4, 2, 0], 
      state: 11
    }, 
    {
      pos: [4, 2, 1], 
      state: 11
    }, 
    {
      pos: [4, 2, 2], 
      state: 11
    }, 
    {
      pos: [4, 2, 3], 
      state: 11
    }, 
    {
      pos: [4, 2, 4], 
      state: 11
    }, 
    {
      pos: [4, 2, 5], 
      state: 11
    }, 
    {
      pos: [4, 2, 6], 
      state: 11
    }, 
    {
      pos: [4, 2, 7], 
      state: 11
    }, 
    {
      pos: [4, 2, 8], 
      state: 11
    }, 
    {
      pos: [5, 2, 0], 
      state: 11
    }, 
    {
      pos: [5, 2, 1], 
      state: 13
    }, 
    {
      pos: [5, 2, 2], 
      state: 13
    }, 
    {
      pos: [5, 2, 3], 
      state: 11
    }, 
    {
      pos: [5, 2, 4], 
      state: 11
    }, 
    {
      pos: [5, 2, 5], 
      state: 11
    }, 
    {
      pos: [5, 2, 6], 
      state: 13
    }, 
    {
      pos: [5, 2, 7], 
      state: 13
    }, 
    {
      pos: [5, 2, 8], 
      state: 11
    }, 
    {
      pos: [6, 2, 0], 
      state: 11
    }, 
    {
      pos: [6, 2, 1], 
      state: 13
    }, 
    {
      pos: [6, 2, 2], 
      state: 13
    }, 
    {
      pos: [6, 2, 3], 
      state: 13
    }, 
    {
      pos: [6, 2, 4], 
      state: 11
    }, 
    {
      pos: [6, 2, 5], 
      state: 13
    }, 
    {
      pos: [6, 2, 6], 
      state: 13
    }, 
    {
      pos: [6, 2, 7], 
      state: 13
    }, 
    {
      pos: [6, 2, 8], 
      state: 11
    }, 
    {
      pos: [7, 2, 0], 
      state: 11
    }, 
    {
      pos: [7, 2, 1], 
      state: 13
    }, 
    {
      pos: [7, 2, 2], 
      state: 13
    }, 
    {
      pos: [7, 2, 3], 
      state: 13
    }, 
    {
      pos: [7, 2, 4], 
      state: 11
    }, 
    {
      pos: [7, 2, 5], 
      state: 13
    }, 
    {
      pos: [7, 2, 6], 
      state: 13
    }, 
    {
      pos: [7, 2, 7], 
      state: 13
    }, 
    {
      pos: [7, 2, 8], 
      state: 11
    }, 
    {
      pos: [8, 2, 0], 
      state: 11
    }, 
    {
      pos: [8, 2, 1], 
      state: 11
    }, 
    {
      pos: [8, 2, 2], 
      state: 11
    }, 
    {
      pos: [8, 2, 3], 
      state: 11
    }, 
    {
      pos: [8, 2, 4], 
      state: 11
    }, 
    {
      pos: [8, 2, 5], 
      state: 11
    }, 
    {
      pos: [8, 2, 6], 
      state: 11
    }, 
    {
      pos: [8, 2, 7], 
      state: 11
    }, 
    {
      pos: [8, 2, 8], 
      state: 11
    }, 
    {
      nbt: {
        final_state: "minecraft:acacia_log", 
        name: "minecraft:building_entrance", 
        pool: "minecraft:empty", 
        joint: "aligned", 
        id: "minecraft:jigsaw", 
        target: "minecraft:building_entrance"
      }, 
      pos: [3, 1, 8], 
      state: 14
    }
  ], 
  palette: [
    {
      Properties: {
        snowy: "false"
      }, 
      Name: "minecraft:grass_block"
    }, 
    {
      Name: "minecraft:dirt"
    }, 
    {
      Properties: {
        axis: "y"
      }, 
      Name: "minecraft:acacia_log"
    }, 
    {
      Name: "minecraft:acacia_planks"
    }, 
    {
      Properties: {
        level: "0"
      }, 
      Name: "minecraft:composter"
    }, 
    {
      Properties: {
        half: "bottom", 
        waterlogged: "false", 
        shape: "straight", 
        facing: "east"
      }, 
      Name: "minecraft:acacia_stairs"
    }, 
    {
      Name: "minecraft:short_grass"
    }, 
    {
      Properties: {
        moisture: "7"
      }, 
      Name: "minecraft:farmland"
    }, 
    {
      Properties: {
        level: "0"
      }, 
      Name: "minecraft:water"
    }, 
    {
      Properties: {
        half: "bottom", 
        waterlogged: "false", 
        shape: "straight", 
        facing: "south"
      }, 
      Name: "minecraft:acacia_stairs"
    }, 
    {
      Properties: {
        half: "bottom", 
        waterlogged: "false", 
        shape: "straight", 
        facing: "north"
      }, 
      Name: "minecraft:acacia_stairs"
    }, 
    {
      Name: "minecraft:air"
    }, 
    {
      Properties: {
        half: "bottom", 
        waterlogged: "false", 
        shape: "straight", 
        facing: "west"
      }, 
      Name: "minecraft:acacia_stairs"
    }, 
    {
      Properties: {
        age: "7"
      }, 
      Name: "minecraft:wheat"
    }, 
    {
      Properties: {
        orientation: "south_up"
      }, 
      Name: "minecraft:jigsaw"
    }
  ]
}
