{
  size: [7, 7, 7], 
  entities: [], 
  blocks: [
    {
      pos: [0, 0, 0], 
      state: 0
    }, 
    {
      pos: [0, 0, 1], 
      state: 0
    }, 
    {
      pos: [0, 0, 2], 
      state: 0
    }, 
    {
      pos: [0, 0, 3], 
      state: 0
    }, 
    {
      pos: [0, 0, 4], 
      state: 0
    }, 
    {
      pos: [0, 0, 5], 
      state: 0
    }, 
    {
      pos: [0, 0, 6], 
      state: 0
    }, 
    {
      pos: [1, 0, 0], 
      state: 0
    }, 
    {
      pos: [1, 0, 1], 
      state: 0
    }, 
    {
      pos: [1, 0, 2], 
      state: 1
    }, 
    {
      pos: [1, 0, 3], 
      state: 1
    }, 
    {
      pos: [1, 0, 4], 
      state: 1
    }, 
    {
      pos: [1, 0, 5], 
      state: 0
    }, 
    {
      pos: [1, 0, 6], 
      state: 0
    }, 
    {
      pos: [2, 0, 0], 
      state: 0
    }, 
    {
      pos: [2, 0, 1], 
      state: 1
    }, 
    {
      pos: [2, 0, 2], 
      state: 2
    }, 
    {
      pos: [2, 0, 3], 
      state: 2
    }, 
    {
      pos: [2, 0, 4], 
      state: 2
    }, 
    {
      pos: [2, 0, 5], 
      state: 1
    }, 
    {
      pos: [3, 0, 0], 
      state: 0
    }, 
    {
      pos: [3, 0, 1], 
      state: 1
    }, 
    {
      pos: [3, 0, 2], 
      state: 2
    }, 
    {
      pos: [3, 0, 3], 
      state: 2
    }, 
    {
      pos: [3, 0, 4], 
      state: 2
    }, 
    {
      pos: [3, 0, 5], 
      state: 2
    }, 
    {
      pos: [3, 0, 6], 
      state: 1
    }, 
    {
      pos: [4, 0, 0], 
      state: 0
    }, 
    {
      pos: [4, 0, 1], 
      state: 1
    }, 
    {
      pos: [4, 0, 2], 
      state: 2
    }, 
    {
      pos: [4, 0, 3], 
      state: 2
    }, 
    {
      pos: [4, 0, 4], 
      state: 2
    }, 
    {
      pos: [4, 0, 5], 
      state: 1
    }, 
    {
      pos: [4, 0, 6], 
      state: 0
    }, 
    {
      pos: [5, 0, 0], 
      state: 0
    }, 
    {
      pos: [5, 0, 1], 
      state: 0
    }, 
    {
      pos: [5, 0, 2], 
      state: 1
    }, 
    {
      pos: [5, 0, 3], 
      state: 1
    }, 
    {
      pos: [5, 0, 4], 
      state: 1
    }, 
    {
      pos: [5, 0, 5], 
      state: 0
    }, 
    {
      pos: [5, 0, 6], 
      state: 0
    }, 
    {
      pos: [6, 0, 0], 
      state: 0
    }, 
    {
      pos: [6, 0, 1], 
      state: 0
    }, 
    {
      pos: [6, 0, 2], 
      state: 0
    }, 
    {
      pos: [6, 0, 3], 
      state: 0
    }, 
    {
      pos: [6, 0, 4], 
      state: 0
    }, 
    {
      pos: [6, 0, 5], 
      state: 0
    }, 
    {
      pos: [6, 0, 6], 
      state: 0
    }, 
    {
      pos: [1, 1, 2], 
      state: 3
    }, 
    {
      pos: [1, 1, 3], 
      state: 3
    }, 
    {
      pos: [1, 1, 4], 
      state: 3
    }, 
    {
      pos: [2, 1, 1], 
      state: 3
    }, 
    {
      pos: [2, 1, 5], 
      state: 3
    }, 
    {
      pos: [3, 1, 1], 
      state: 3
    }, 
    {
      pos: [4, 1, 1], 
      state: 3
    }, 
    {
      pos: [4, 1, 5], 
      state: 3
    }, 
    {
      pos: [5, 1, 2], 
      state: 3
    }, 
    {
      pos: [5, 1, 3], 
      state: 3
    }, 
    {
      pos: [5, 1, 4], 
      state: 3
    }, 
    {
      pos: [1, 2, 2], 
      state: 3
    }, 
    {
      pos: [1, 2, 4], 
      state: 3
    }, 
    {
      pos: [2, 2, 1], 
      state: 3
    }, 
    {
      pos: [2, 2, 5], 
      state: 3
    }, 
    {
      pos: [4, 2, 1], 
      state: 3
    }, 
    {
      pos: [4, 2, 5], 
      state: 3
    }, 
    {
      pos: [5, 2, 2], 
      state: 3
    }, 
    {
      pos: [5, 2, 4], 
      state: 3
    }, 
    {
      pos: [1, 3, 2], 
      state: 3
    }, 
    {
      pos: [1, 3, 3], 
      state: 3
    }, 
    {
      pos: [1, 3, 4], 
      state: 3
    }, 
    {
      pos: [2, 3, 1], 
      state: 3
    }, 
    {
      pos: [2, 3, 5], 
      state: 3
    }, 
    {
      pos: [3, 3, 1], 
      state: 3
    }, 
    {
      pos: [3, 3, 5], 
      state: 3
    }, 
    {
      pos: [4, 3, 1], 
      state: 3
    }, 
    {
      pos: [4, 3, 5], 
      state: 3
    }, 
    {
      pos: [5, 3, 2], 
      state: 3
    }, 
    {
      pos: [5, 3, 3], 
      state: 3
    }, 
    {
      pos: [5, 3, 4], 
      state: 3
    }, 
    {
      pos: [1, 4, 1], 
      state: 4
    }, 
    {
      pos: [1, 4, 2], 
      state: 4
    }, 
    {
      pos: [1, 4, 3], 
      state: 4
    }, 
    {
      pos: [1, 4, 4], 
      state: 4
    }, 
    {
      pos: [1, 4, 5], 
      state: 4
    }, 
    {
      pos: [2, 4, 1], 
      state: 4
    }, 
    {
      pos: [2, 4, 5], 
      state: 4
    }, 
    {
      pos: [3, 4, 1], 
      state: 4
    }, 
    {
      pos: [3, 4, 5], 
      state: 4
    }, 
    {
      pos: [4, 4, 1], 
      state: 4
    }, 
    {
      pos: [4, 4, 5], 
      state: 4
    }, 
    {
      pos: [5, 4, 1], 
      state: 4
    }, 
    {
      pos: [5, 4, 2], 
      state: 4
    }, 
    {
      pos: [5, 4, 3], 
      state: 4
    }, 
    {
      pos: [5, 4, 4], 
      state: 4
    }, 
    {
      pos: [5, 4, 5], 
      state: 4
    }, 
    {
      pos: [2, 5, 2], 
      state: 4
    }, 
    {
      pos: [2, 5, 3], 
      state: 4
    }, 
    {
      pos: [2, 5, 4], 
      state: 4
    }, 
    {
      pos: [3, 5, 2], 
      state: 4
    }, 
    {
      pos: [3, 5, 3], 
      state: 4
    }, 
    {
      pos: [3, 5, 4], 
      state: 4
    }, 
    {
      pos: [4, 5, 2], 
      state: 4
    }, 
    {
      pos: [4, 5, 3], 
      state: 4
    }, 
    {
      pos: [4, 5, 4], 
      state: 4
    }, 
    {
      pos: [3, 6, 3], 
      state: 4
    }, 
    {
      pos: [0, 1, 0], 
      state: 5
    }, 
    {
      pos: [0, 1, 1], 
      state: 6
    }, 
    {
      pos: [0, 1, 2], 
      state: 7
    }, 
    {
      pos: [0, 1, 3], 
      state: 5
    }, 
    {
      pos: [0, 1, 4], 
      state: 6
    }, 
    {
      pos: [0, 1, 5], 
      state: 6
    }, 
    {
      pos: [0, 1, 6], 
      state: 6
    }, 
    {
      pos: [1, 1, 0], 
      state: 5
    }, 
    {
      pos: [1, 1, 1], 
      state: 5
    }, 
    {
      pos: [1, 1, 5], 
      state: 5
    }, 
    {
      pos: [1, 1, 6], 
      state: 5
    }, 
    {
      pos: [2, 1, 0], 
      state: 6
    }, 
    {
      pos: [2, 1, 2], 
      state: 8
    }, 
    {
      pos: [2, 1, 3], 
      state: 6
    }, 
    {
      pos: [2, 1, 4], 
      state: 6
    }, 
    {
      pos: [2, 1, 6], 
      state: 6
    }, 
    {
      pos: [3, 1, 0], 
      state: 5
    }, 
    {
      pos: [3, 1, 2], 
      state: 6
    }, 
    {
      pos: [3, 1, 3], 
      state: 6
    }, 
    {
      pos: [3, 1, 4], 
      state: 6
    }, 
    {
      pos: [3, 1, 5], 
      state: 9
    }, 
    {
      pos: [4, 1, 0], 
      state: 5
    }, 
    {
      pos: [4, 1, 2], 
      state: 10
    }, 
    {
      pos: [4, 1, 3], 
      state: 11
    }, 
    {
      pos: [4, 1, 4], 
      state: 6
    }, 
    {
      pos: [4, 1, 6], 
      state: 5
    }, 
    {
      pos: [5, 1, 0], 
      state: 5
    }, 
    {
      pos: [5, 1, 1], 
      state: 5
    }, 
    {
      pos: [5, 1, 5], 
      state: 6
    }, 
    {
      pos: [5, 1, 6], 
      state: 6
    }, 
    {
      pos: [6, 1, 0], 
      state: 5
    }, 
    {
      pos: [6, 1, 1], 
      state: 6
    }, 
    {
      pos: [6, 1, 2], 
      state: 5
    }, 
    {
      pos: [6, 1, 3], 
      state: 6
    }, 
    {
      pos: [6, 1, 4], 
      state: 5
    }, 
    {
      pos: [6, 1, 5], 
      state: 6
    }, 
    {
      pos: [6, 1, 6], 
      state: 6
    }, 
    {
      pos: [0, 2, 0], 
      state: 6
    }, 
    {
      pos: [0, 2, 1], 
      state: 6
    }, 
    {
      pos: [0, 2, 2], 
      state: 12
    }, 
    {
      pos: [0, 2, 3], 
      state: 6
    }, 
    {
      pos: [0, 2, 4], 
      state: 6
    }, 
    {
      pos: [0, 2, 5], 
      state: 6
    }, 
    {
      pos: [0, 2, 6], 
      state: 6
    }, 
    {
      pos: [1, 2, 0], 
      state: 6
    }, 
    {
      pos: [1, 2, 1], 
      state: 6
    }, 
    {
      pos: [1, 2, 3], 
      state: 13
    }, 
    {
      pos: [1, 2, 5], 
      state: 6
    }, 
    {
      pos: [1, 2, 6], 
      state: 6
    }, 
    {
      pos: [2, 2, 0], 
      state: 6
    }, 
    {
      pos: [2, 2, 2], 
      state: 14
    }, 
    {
      pos: [2, 2, 3], 
      state: 6
    }, 
    {
      pos: [2, 2, 4], 
      state: 6
    }, 
    {
      pos: [2, 2, 6], 
      state: 6
    }, 
    {
      pos: [3, 2, 0], 
      state: 6
    }, 
    {
      pos: [3, 2, 1], 
      state: 15
    }, 
    {
      pos: [3, 2, 2], 
      state: 6
    }, 
    {
      pos: [3, 2, 3], 
      state: 6
    }, 
    {
      pos: [3, 2, 4], 
      state: 6
    }, 
    {
      pos: [3, 2, 5], 
      state: 16
    }, 
    {
      pos: [3, 2, 6], 
      state: 6
    }, 
    {
      pos: [4, 2, 0], 
      state: 6
    }, 
    {
      pos: [4, 2, 2], 
      state: 6
    }, 
    {
      pos: [4, 2, 3], 
      state: 6
    }, 
    {
      pos: [4, 2, 4], 
      state: 6
    }, 
    {
      pos: [4, 2, 6], 
      state: 6
    }, 
    {
      pos: [5, 2, 0], 
      state: 6
    }, 
    {
      pos: [5, 2, 1], 
      state: 6
    }, 
    {
      pos: [5, 2, 3], 
      state: 13
    }, 
    {
      pos: [5, 2, 5], 
      state: 6
    }, 
    {
      pos: [5, 2, 6], 
      state: 6
    }, 
    {
      pos: [6, 2, 0], 
      state: 6
    }, 
    {
      pos: [6, 2, 1], 
      state: 6
    }, 
    {
      pos: [6, 2, 2], 
      state: 6
    }, 
    {
      pos: [6, 2, 3], 
      state: 6
    }, 
    {
      pos: [6, 2, 4], 
      state: 6
    }, 
    {
      pos: [6, 2, 5], 
      state: 6
    }, 
    {
      pos: [6, 2, 6], 
      state: 6
    }, 
    {
      pos: [0, 3, 0], 
      state: 6
    }, 
    {
      pos: [0, 3, 1], 
      state: 6
    }, 
    {
      pos: [0, 3, 2], 
      state: 6
    }, 
    {
      pos: [0, 3, 3], 
      state: 6
    }, 
    {
      pos: [0, 3, 4], 
      state: 6
    }, 
    {
      pos: [0, 3, 5], 
      state: 6
    }, 
    {
      pos: [0, 3, 6], 
      state: 6
    }, 
    {
      pos: [1, 3, 0], 
      state: 6
    }, 
    {
      pos: [1, 3, 1], 
      state: 6
    }, 
    {
      pos: [1, 3, 5], 
      state: 6
    }, 
    {
      pos: [1, 3, 6], 
      state: 6
    }, 
    {
      pos: [2, 3, 0], 
      state: 6
    }, 
    {
      pos: [2, 3, 2], 
      state: 6
    }, 
    {
      pos: [2, 3, 3], 
      state: 6
    }, 
    {
      pos: [2, 3, 4], 
      state: 6
    }, 
    {
      pos: [2, 3, 6], 
      state: 6
    }, 
    {
      pos: [3, 3, 0], 
      state: 6
    }, 
    {
      pos: [3, 3, 2], 
      state: 17
    }, 
    {
      pos: [3, 3, 3], 
      state: 6
    }, 
    {
      pos: [3, 3, 4], 
      state: 6
    }, 
    {
      pos: [3, 3, 6], 
      state: 6
    }, 
    {
      pos: [4, 3, 0], 
      state: 6
    }, 
    {
      pos: [4, 3, 2], 
      state: 6
    }, 
    {
      pos: [4, 3, 3], 
      state: 6
    }, 
    {
      pos: [4, 3, 4], 
      state: 6
    }, 
    {
      pos: [4, 3, 6], 
      state: 6
    }, 
    {
      pos: [5, 3, 0], 
      state: 6
    }, 
    {
      pos: [5, 3, 1], 
      state: 6
    }, 
    {
      pos: [5, 3, 5], 
      state: 6
    }, 
    {
      pos: [5, 3, 6], 
      state: 6
    }, 
    {
      pos: [6, 3, 0], 
      state: 6
    }, 
    {
      pos: [6, 3, 1], 
      state: 6
    }, 
    {
      pos: [6, 3, 2], 
      state: 6
    }, 
    {
      pos: [6, 3, 3], 
      state: 6
    }, 
    {
      pos: [6, 3, 4], 
      state: 6
    }, 
    {
      pos: [6, 3, 5], 
      state: 6
    }, 
    {
      pos: [6, 3, 6], 
      state: 6
    }, 
    {
      pos: [0, 4, 0], 
      state: 6
    }, 
    {
      pos: [0, 4, 1], 
      state: 18
    }, 
    {
      pos: [0, 4, 2], 
      state: 18
    }, 
    {
      pos: [0, 4, 3], 
      state: 18
    }, 
    {
      pos: [0, 4, 4], 
      state: 18
    }, 
    {
      pos: [0, 4, 5], 
      state: 18
    }, 
    {
      pos: [0, 4, 6], 
      state: 6
    }, 
    {
      pos: [1, 4, 0], 
      state: 19
    }, 
    {
      pos: [1, 4, 6], 
      state: 20
    }, 
    {
      pos: [2, 4, 0], 
      state: 19
    }, 
    {
      pos: [2, 4, 2], 
      state: 6
    }, 
    {
      pos: [2, 4, 3], 
      state: 6
    }, 
    {
      pos: [2, 4, 4], 
      state: 6
    }, 
    {
      pos: [2, 4, 6], 
      state: 20
    }, 
    {
      pos: [3, 4, 0], 
      state: 19
    }, 
    {
      pos: [3, 4, 2], 
      state: 6
    }, 
    {
      pos: [3, 4, 3], 
      state: 6
    }, 
    {
      pos: [3, 4, 4], 
      state: 6
    }, 
    {
      pos: [3, 4, 6], 
      state: 20
    }, 
    {
      pos: [4, 4, 0], 
      state: 19
    }, 
    {
      pos: [4, 4, 2], 
      state: 6
    }, 
    {
      pos: [4, 4, 3], 
      state: 6
    }, 
    {
      pos: [4, 4, 4], 
      state: 6
    }, 
    {
      pos: [4, 4, 6], 
      state: 20
    }, 
    {
      pos: [5, 4, 0], 
      state: 19
    }, 
    {
      pos: [5, 4, 6], 
      state: 20
    }, 
    {
      pos: [6, 4, 0], 
      state: 6
    }, 
    {
      pos: [6, 4, 1], 
      state: 21
    }, 
    {
      pos: [6, 4, 2], 
      state: 21
    }, 
    {
      pos: [6, 4, 3], 
      state: 21
    }, 
    {
      pos: [6, 4, 4], 
      state: 21
    }, 
    {
      pos: [6, 4, 5], 
      state: 21
    }, 
    {
      pos: [6, 4, 6], 
      state: 6
    }, 
    {
      pos: [0, 5, 0], 
      state: 6
    }, 
    {
      pos: [0, 5, 1], 
      state: 6
    }, 
    {
      pos: [0, 5, 2], 
      state: 6
    }, 
    {
      pos: [0, 5, 3], 
      state: 6
    }, 
    {
      pos: [0, 5, 4], 
      state: 6
    }, 
    {
      pos: [0, 5, 5], 
      state: 6
    }, 
    {
      pos: [0, 5, 6], 
      state: 6
    }, 
    {
      pos: [1, 5, 0], 
      state: 6
    }, 
    {
      pos: [1, 5, 1], 
      state: 22
    }, 
    {
      pos: [1, 5, 2], 
      state: 18
    }, 
    {
      pos: [1, 5, 3], 
      state: 18
    }, 
    {
      pos: [1, 5, 4], 
      state: 18
    }, 
    {
      pos: [1, 5, 5], 
      state: 23
    }, 
    {
      pos: [1, 5, 6], 
      state: 6
    }, 
    {
      pos: [2, 5, 0], 
      state: 6
    }, 
    {
      pos: [2, 5, 1], 
      state: 19
    }, 
    {
      pos: [2, 5, 5], 
      state: 20
    }, 
    {
      pos: [2, 5, 6], 
      state: 6
    }, 
    {
      pos: [3, 5, 0], 
      state: 6
    }, 
    {
      pos: [3, 5, 1], 
      state: 19
    }, 
    {
      pos: [3, 5, 5], 
      state: 20
    }, 
    {
      pos: [3, 5, 6], 
      state: 6
    }, 
    {
      pos: [4, 5, 0], 
      state: 6
    }, 
    {
      pos: [4, 5, 1], 
      state: 19
    }, 
    {
      pos: [4, 5, 5], 
      state: 20
    }, 
    {
      pos: [4, 5, 6], 
      state: 6
    }, 
    {
      pos: [5, 5, 0], 
      state: 6
    }, 
    {
      pos: [5, 5, 1], 
      state: 24
    }, 
    {
      pos: [5, 5, 2], 
      state: 21
    }, 
    {
      pos: [5, 5, 3], 
      state: 21
    }, 
    {
      pos: [5, 5, 4], 
      state: 21
    }, 
    {
      pos: [5, 5, 5], 
      state: 25
    }, 
    {
      pos: [5, 5, 6], 
      state: 6
    }, 
    {
      pos: [6, 5, 0], 
      state: 6
    }, 
    {
      pos: [6, 5, 1], 
      state: 6
    }, 
    {
      pos: [6, 5, 2], 
      state: 6
    }, 
    {
      pos: [6, 5, 3], 
      state: 6
    }, 
    {
      pos: [6, 5, 4], 
      state: 6
    }, 
    {
      pos: [6, 5, 5], 
      state: 6
    }, 
    {
      pos: [6, 5, 6], 
      state: 6
    }, 
    {
      pos: [0, 6, 0], 
      state: 6
    }, 
    {
      pos: [0, 6, 1], 
      state: 6
    }, 
    {
      pos: [0, 6, 2], 
      state: 6
    }, 
    {
      pos: [0, 6, 3], 
      state: 6
    }, 
    {
      pos: [0, 6, 4], 
      state: 6
    }, 
    {
      pos: [0, 6, 5], 
      state: 6
    }, 
    {
      pos: [0, 6, 6], 
      state: 6
    }, 
    {
      pos: [1, 6, 0], 
      state: 6
    }, 
    {
      pos: [1, 6, 1], 
      state: 6
    }, 
    {
      pos: [1, 6, 2], 
      state: 6
    }, 
    {
      pos: [1, 6, 3], 
      state: 6
    }, 
    {
      pos: [1, 6, 4], 
      state: 6
    }, 
    {
      pos: [1, 6, 5], 
      state: 6
    }, 
    {
      pos: [1, 6, 6], 
      state: 6
    }, 
    {
      pos: [2, 6, 0], 
      state: 6
    }, 
    {
      pos: [2, 6, 1], 
      state: 6
    }, 
    {
      pos: [2, 6, 2], 
      state: 26
    }, 
    {
      pos: [2, 6, 3], 
      state: 18
    }, 
    {
      pos: [2, 6, 4], 
      state: 23
    }, 
    {
      pos: [2, 6, 5], 
      state: 6
    }, 
    {
      pos: [2, 6, 6], 
      state: 6
    }, 
    {
      pos: [3, 6, 0], 
      state: 6
    }, 
    {
      pos: [3, 6, 1], 
      state: 6
    }, 
    {
      pos: [3, 6, 2], 
      state: 19
    }, 
    {
      pos: [3, 6, 4], 
      state: 20
    }, 
    {
      pos: [3, 6, 5], 
      state: 6
    }, 
    {
      pos: [3, 6, 6], 
      state: 6
    }, 
    {
      pos: [4, 6, 0], 
      state: 6
    }, 
    {
      pos: [4, 6, 1], 
      state: 6
    }, 
    {
      pos: [4, 6, 2], 
      state: 27
    }, 
    {
      pos: [4, 6, 3], 
      state: 21
    }, 
    {
      pos: [4, 6, 4], 
      state: 25
    }, 
    {
      pos: [4, 6, 5], 
      state: 6
    }, 
    {
      pos: [4, 6, 6], 
      state: 6
    }, 
    {
      pos: [5, 6, 0], 
      state: 6
    }, 
    {
      pos: [5, 6, 1], 
      state: 6
    }, 
    {
      pos: [5, 6, 2], 
      state: 6
    }, 
    {
      pos: [5, 6, 3], 
      state: 6
    }, 
    {
      pos: [5, 6, 4], 
      state: 6
    }, 
    {
      pos: [5, 6, 5], 
      state: 6
    }, 
    {
      pos: [5, 6, 6], 
      state: 6
    }, 
    {
      pos: [6, 6, 0], 
      state: 6
    }, 
    {
      pos: [6, 6, 1], 
      state: 6
    }, 
    {
      pos: [6, 6, 2], 
      state: 6
    }, 
    {
      pos: [6, 6, 3], 
      state: 6
    }, 
    {
      pos: [6, 6, 4], 
      state: 6
    }, 
    {
      pos: [6, 6, 5], 
      state: 6
    }, 
    {
      pos: [6, 6, 6], 
      state: 6
    }, 
    {
      nbt: {
        joint: "rollable", 
        final_state: "minecraft:grass_block", 
        name: "minecraft:bottom", 
        pool: "minecraft:village/savanna/villagers", 
        id: "minecraft:jigsaw", 
        target: "minecraft:bottom"
      }, 
      pos: [2, 0, 6], 
      state: 28
    }, 
    {
      nbt: {
        joint: "aligned", 
        final_state: "minecraft:structure_void", 
        name: "minecraft:building_entrance", 
        pool: "minecraft:empty", 
        id: "minecraft:jigsaw", 
        target: "minecraft:building_entrance"
      }, 
      pos: [3, 1, 6], 
      state: 29
    }
  ], 
  palette: [
    {
      Properties: {
        snowy: "false"
      }, 
      Name: "minecraft:grass_block"
    }, 
    {
      Name: "minecraft:dirt"
    }, 
    {
      Properties: {
        axis: "z"
      }, 
      Name: "minecraft:acacia_wood"
    }, 
    {
      Name: "minecraft:yellow_terracotta"
    }, 
    {
      Name: "minecraft:acacia_planks"
    }, 
    {
      Name: "minecraft:short_grass"
    }, 
    {
      Name: "minecraft:air"
    }, 
    {
      Properties: {
        half: "lower"
      }, 
      Name: "minecraft:tall_grass"
    }, 
    {
      Properties: {
        east: "false", 
        waterlogged: "false", 
        south: "false", 
        north: "true", 
        west: "true"
      }, 
      Name: "minecraft:acacia_fence"
    }, 
    {
      Properties: {
        hinge: "right", 
        half: "lower", 
        powered: "false", 
        facing: "south", 
        open: "false"
      }, 
      Name: "minecraft:acacia_door"
    }, 
    {
      Properties: {
        part: "head", 
        facing: "north", 
        occupied: "false"
      }, 
      Name: "minecraft:orange_bed"
    }, 
    {
      Properties: {
        part: "foot", 
        facing: "north", 
        occupied: "false"
      }, 
      Name: "minecraft:orange_bed"
    }, 
    {
      Properties: {
        half: "upper"
      }, 
      Name: "minecraft:tall_grass"
    }, 
    {
      Properties: {
        east: "false", 
        waterlogged: "false", 
        south: "true", 
        north: "true", 
        west: "false"
      }, 
      Name: "minecraft:glass_pane"
    }, 
    {
      Properties: {
        powered: "false"
      }, 
      Name: "minecraft:acacia_pressure_plate"
    }, 
    {
      Properties: {
        east: "true", 
        waterlogged: "false", 
        south: "false", 
        north: "false", 
        west: "true"
      }, 
      Name: "minecraft:glass_pane"
    }, 
    {
      Properties: {
        hinge: "right", 
        half: "upper", 
        powered: "false", 
        facing: "south", 
        open: "false"
      }, 
      Name: "minecraft:acacia_door"
    }, 
    {
      Properties: {
        facing: "south"
      }, 
      Name: "minecraft:wall_torch"
    }, 
    {
      Properties: {
        half: "bottom", 
        waterlogged: "false", 
        shape: "straight", 
        facing: "east"
      }, 
      Name: "minecraft:acacia_stairs"
    }, 
    {
      Properties: {
        half: "bottom", 
        waterlogged: "false", 
        shape: "straight", 
        facing: "south"
      }, 
      Name: "minecraft:acacia_stairs"
    }, 
    {
      Properties: {
        half: "bottom", 
        waterlogged: "false", 
        shape: "straight", 
        facing: "north"
      }, 
      Name: "minecraft:acacia_stairs"
    }, 
    {
      Properties: {
        half: "bottom", 
        waterlogged: "false", 
        shape: "straight", 
        facing: "west"
      }, 
      Name: "minecraft:acacia_stairs"
    }, 
    {
      Properties: {
        half: "bottom", 
        waterlogged: "false", 
        shape: "outer_right", 
        facing: "east"
      }, 
      Name: "minecraft:acacia_stairs"
    }, 
    {
      Properties: {
        half: "bottom", 
        waterlogged: "false", 
        shape: "outer_left", 
        facing: "east"
      }, 
      Name: "minecraft:acacia_stairs"
    }, 
    {
      Properties: {
        half: "bottom", 
        waterlogged: "false", 
        shape: "outer_right", 
        facing: "south"
      }, 
      Name: "minecraft:acacia_stairs"
    }, 
    {
      Properties: {
        half: "bottom", 
        waterlogged: "false", 
        shape: "outer_left", 
        facing: "north"
      }, 
      Name: "minecraft:acacia_stairs"
    }, 
    {
      Properties: {
        half: "bottom", 
        waterlogged: "false", 
        shape: "outer_left", 
        facing: "south"
      }, 
      Name: "minecraft:acacia_stairs"
    }, 
    {
      Properties: {
        half: "bottom", 
        waterlogged: "false", 
        shape: "outer_left", 
        facing: "west"
      }, 
      Name: "minecraft:acacia_stairs"
    }, 
    {
      Properties: {
        orientation: "up_north"
      }, 
      Name: "minecraft:jigsaw"
    }, 
    {
      Properties: {
        orientation: "south_up"
      }, 
      Name: "minecraft:jigsaw"
    }
  ]
}
