{
  size: [13, 14, 11], 
  entities: [], 
  blocks: [
    {
      pos: [0, 0, 0], 
      state: 0
    }, 
    {
      pos: [1, 0, 0], 
      state: 0
    }, 
    {
      pos: [2, 0, 0], 
      state: 1
    }, 
    {
      pos: [4, 0, 0], 
      state: 1
    }, 
    {
      pos: [5, 0, 0], 
      state: 1
    }, 
    {
      pos: [6, 0, 0], 
      state: 1
    }, 
    {
      pos: [7, 0, 0], 
      state: 1
    }, 
    {
      pos: [8, 0, 0], 
      state: 1
    }, 
    {
      pos: [9, 0, 0], 
      state: 1
    }, 
    {
      pos: [10, 0, 0], 
      state: 1
    }, 
    {
      pos: [11, 0, 0], 
      state: 1
    }, 
    {
      pos: [12, 0, 0], 
      state: 1
    }, 
    {
      pos: [0, 0, 1], 
      state: 0
    }, 
    {
      pos: [1, 0, 1], 
      state: 1
    }, 
    {
      pos: [2, 0, 1], 
      state: 1
    }, 
    {
      pos: [3, 0, 1], 
      state: 1
    }, 
    {
      pos: [4, 0, 1], 
      state: 1
    }, 
    {
      pos: [5, 0, 1], 
      state: 1
    }, 
    {
      pos: [6, 0, 1], 
      state: 1
    }, 
    {
      pos: [7, 0, 1], 
      state: 1
    }, 
    {
      pos: [8, 0, 1], 
      state: 1
    }, 
    {
      pos: [9, 0, 1], 
      state: 1
    }, 
    {
      pos: [10, 0, 1], 
      state: 1
    }, 
    {
      pos: [11, 0, 1], 
      state: 1
    }, 
    {
      pos: [12, 0, 1], 
      state: 1
    }, 
    {
      pos: [0, 0, 2], 
      state: 1
    }, 
    {
      pos: [1, 0, 2], 
      state: 1
    }, 
    {
      pos: [2, 0, 2], 
      state: 1
    }, 
    {
      pos: [3, 0, 2], 
      state: 1
    }, 
    {
      pos: [4, 0, 2], 
      state: 1
    }, 
    {
      pos: [5, 0, 2], 
      state: 1
    }, 
    {
      pos: [6, 0, 2], 
      state: 1
    }, 
    {
      pos: [7, 0, 2], 
      state: 1
    }, 
    {
      pos: [8, 0, 2], 
      state: 1
    }, 
    {
      pos: [9, 0, 2], 
      state: 1
    }, 
    {
      pos: [10, 0, 2], 
      state: 1
    }, 
    {
      pos: [11, 0, 2], 
      state: 1
    }, 
    {
      pos: [12, 0, 2], 
      state: 1
    }, 
    {
      pos: [0, 0, 3], 
      state: 1
    }, 
    {
      pos: [1, 0, 3], 
      state: 1
    }, 
    {
      pos: [2, 0, 3], 
      state: 1
    }, 
    {
      pos: [3, 0, 3], 
      state: 1
    }, 
    {
      pos: [4, 0, 3], 
      state: 1
    }, 
    {
      pos: [5, 0, 3], 
      state: 1
    }, 
    {
      pos: [6, 0, 3], 
      state: 1
    }, 
    {
      pos: [7, 0, 3], 
      state: 1
    }, 
    {
      pos: [8, 0, 3], 
      state: 1
    }, 
    {
      pos: [9, 0, 3], 
      state: 1
    }, 
    {
      pos: [10, 0, 3], 
      state: 1
    }, 
    {
      pos: [11, 0, 3], 
      state: 1
    }, 
    {
      pos: [12, 0, 3], 
      state: 1
    }, 
    {
      pos: [0, 0, 4], 
      state: 1
    }, 
    {
      pos: [1, 0, 4], 
      state: 1
    }, 
    {
      pos: [2, 0, 4], 
      state: 1
    }, 
    {
      pos: [3, 0, 4], 
      state: 1
    }, 
    {
      pos: [4, 0, 4], 
      state: 1
    }, 
    {
      pos: [5, 0, 4], 
      state: 1
    }, 
    {
      pos: [6, 0, 4], 
      state: 1
    }, 
    {
      pos: [7, 0, 4], 
      state: 1
    }, 
    {
      pos: [8, 0, 4], 
      state: 1
    }, 
    {
      pos: [9, 0, 4], 
      state: 1
    }, 
    {
      pos: [10, 0, 4], 
      state: 1
    }, 
    {
      pos: [11, 0, 4], 
      state: 0
    }, 
    {
      pos: [12, 0, 4], 
      state: 1
    }, 
    {
      pos: [0, 0, 5], 
      state: 1
    }, 
    {
      pos: [1, 0, 5], 
      state: 1
    }, 
    {
      pos: [2, 0, 5], 
      state: 1
    }, 
    {
      pos: [3, 0, 5], 
      state: 1
    }, 
    {
      pos: [4, 0, 5], 
      state: 1
    }, 
    {
      pos: [5, 0, 5], 
      state: 1
    }, 
    {
      pos: [6, 0, 5], 
      state: 1
    }, 
    {
      pos: [7, 0, 5], 
      state: 1
    }, 
    {
      pos: [8, 0, 5], 
      state: 1
    }, 
    {
      pos: [9, 0, 5], 
      state: 1
    }, 
    {
      pos: [10, 0, 5], 
      state: 1
    }, 
    {
      pos: [11, 0, 5], 
      state: 1
    }, 
    {
      pos: [12, 0, 5], 
      state: 1
    }, 
    {
      pos: [0, 0, 6], 
      state: 1
    }, 
    {
      pos: [1, 0, 6], 
      state: 1
    }, 
    {
      pos: [2, 0, 6], 
      state: 1
    }, 
    {
      pos: [3, 0, 6], 
      state: 1
    }, 
    {
      pos: [4, 0, 6], 
      state: 1
    }, 
    {
      pos: [5, 0, 6], 
      state: 1
    }, 
    {
      pos: [6, 0, 6], 
      state: 1
    }, 
    {
      pos: [7, 0, 6], 
      state: 1
    }, 
    {
      pos: [8, 0, 6], 
      state: 1
    }, 
    {
      pos: [9, 0, 6], 
      state: 1
    }, 
    {
      pos: [10, 0, 6], 
      state: 1
    }, 
    {
      pos: [11, 0, 6], 
      state: 1
    }, 
    {
      pos: [12, 0, 6], 
      state: 1
    }, 
    {
      pos: [0, 0, 7], 
      state: 1
    }, 
    {
      pos: [1, 0, 7], 
      state: 1
    }, 
    {
      pos: [2, 0, 7], 
      state: 1
    }, 
    {
      pos: [3, 0, 7], 
      state: 1
    }, 
    {
      pos: [4, 0, 7], 
      state: 1
    }, 
    {
      pos: [5, 0, 7], 
      state: 1
    }, 
    {
      pos: [6, 0, 7], 
      state: 1
    }, 
    {
      pos: [7, 0, 7], 
      state: 1
    }, 
    {
      pos: [8, 0, 7], 
      state: 1
    }, 
    {
      pos: [9, 0, 7], 
      state: 1
    }, 
    {
      pos: [10, 0, 7], 
      state: 1
    }, 
    {
      pos: [11, 0, 7], 
      state: 1
    }, 
    {
      pos: [12, 0, 7], 
      state: 1
    }, 
    {
      pos: [0, 0, 8], 
      state: 1
    }, 
    {
      pos: [1, 0, 8], 
      state: 1
    }, 
    {
      pos: [2, 0, 8], 
      state: 1
    }, 
    {
      pos: [3, 0, 8], 
      state: 1
    }, 
    {
      pos: [4, 0, 8], 
      state: 1
    }, 
    {
      pos: [5, 0, 8], 
      state: 1
    }, 
    {
      pos: [6, 0, 8], 
      state: 1
    }, 
    {
      pos: [7, 0, 8], 
      state: 1
    }, 
    {
      pos: [8, 0, 8], 
      state: 1
    }, 
    {
      pos: [9, 0, 8], 
      state: 1
    }, 
    {
      pos: [10, 0, 8], 
      state: 1
    }, 
    {
      pos: [11, 0, 8], 
      state: 1
    }, 
    {
      pos: [12, 0, 8], 
      state: 1
    }, 
    {
      pos: [0, 0, 9], 
      state: 1
    }, 
    {
      pos: [1, 0, 9], 
      state: 1
    }, 
    {
      pos: [2, 0, 9], 
      state: 1
    }, 
    {
      pos: [3, 0, 9], 
      state: 1
    }, 
    {
      pos: [4, 0, 9], 
      state: 1
    }, 
    {
      pos: [5, 0, 9], 
      state: 1
    }, 
    {
      pos: [6, 0, 9], 
      state: 1
    }, 
    {
      pos: [7, 0, 9], 
      state: 1
    }, 
    {
      pos: [8, 0, 9], 
      state: 1
    }, 
    {
      pos: [9, 0, 9], 
      state: 1
    }, 
    {
      pos: [10, 0, 9], 
      state: 1
    }, 
    {
      pos: [11, 0, 9], 
      state: 1
    }, 
    {
      pos: [12, 0, 9], 
      state: 1
    }, 
    {
      pos: [0, 0, 10], 
      state: 1
    }, 
    {
      pos: [1, 0, 10], 
      state: 1
    }, 
    {
      pos: [2, 0, 10], 
      state: 1
    }, 
    {
      pos: [3, 0, 10], 
      state: 1
    }, 
    {
      pos: [4, 0, 10], 
      state: 1
    }, 
    {
      pos: [5, 0, 10], 
      state: 1
    }, 
    {
      pos: [6, 0, 10], 
      state: 1
    }, 
    {
      pos: [7, 0, 10], 
      state: 1
    }, 
    {
      pos: [8, 0, 10], 
      state: 1
    }, 
    {
      pos: [9, 0, 10], 
      state: 1
    }, 
    {
      pos: [10, 0, 10], 
      state: 1
    }, 
    {
      pos: [11, 0, 10], 
      state: 1
    }, 
    {
      pos: [12, 0, 10], 
      state: 1
    }, 
    {
      pos: [3, 0, 0], 
      state: 2
    }, 
    {
      pos: [2, 1, 0], 
      state: 0
    }, 
    {
      pos: [3, 1, 0], 
      state: 0
    }, 
    {
      pos: [4, 1, 0], 
      state: 0
    }, 
    {
      pos: [5, 1, 0], 
      state: 0
    }, 
    {
      pos: [6, 1, 0], 
      state: 0
    }, 
    {
      pos: [7, 1, 0], 
      state: 0
    }, 
    {
      pos: [8, 1, 0], 
      state: 0
    }, 
    {
      pos: [9, 1, 0], 
      state: 0
    }, 
    {
      pos: [10, 1, 0], 
      state: 0
    }, 
    {
      pos: [11, 1, 0], 
      state: 0
    }, 
    {
      pos: [12, 1, 0], 
      state: 0
    }, 
    {
      pos: [1, 1, 1], 
      state: 0
    }, 
    {
      pos: [2, 1, 1], 
      state: 0
    }, 
    {
      pos: [3, 1, 1], 
      state: 0
    }, 
    {
      pos: [4, 1, 1], 
      state: 0
    }, 
    {
      pos: [5, 1, 1], 
      state: 0
    }, 
    {
      pos: [6, 1, 1], 
      state: 0
    }, 
    {
      pos: [7, 1, 1], 
      state: 0
    }, 
    {
      pos: [8, 1, 1], 
      state: 0
    }, 
    {
      pos: [9, 1, 1], 
      state: 0
    }, 
    {
      pos: [10, 1, 1], 
      state: 0
    }, 
    {
      pos: [11, 1, 1], 
      state: 0
    }, 
    {
      pos: [12, 1, 1], 
      state: 0
    }, 
    {
      pos: [0, 1, 2], 
      state: 0
    }, 
    {
      pos: [1, 1, 2], 
      state: 0
    }, 
    {
      pos: [2, 1, 2], 
      state: 0
    }, 
    {
      pos: [3, 1, 2], 
      state: 0
    }, 
    {
      pos: [4, 1, 2], 
      state: 0
    }, 
    {
      pos: [5, 1, 2], 
      state: 0
    }, 
    {
      pos: [6, 1, 2], 
      state: 0
    }, 
    {
      pos: [7, 1, 2], 
      state: 0
    }, 
    {
      pos: [8, 1, 2], 
      state: 0
    }, 
    {
      pos: [10, 1, 2], 
      state: 0
    }, 
    {
      pos: [11, 1, 2], 
      state: 0
    }, 
    {
      pos: [12, 1, 2], 
      state: 0
    }, 
    {
      pos: [0, 1, 3], 
      state: 0
    }, 
    {
      pos: [1, 1, 3], 
      state: 0
    }, 
    {
      pos: [2, 1, 3], 
      state: 1
    }, 
    {
      pos: [3, 1, 3], 
      state: 1
    }, 
    {
      pos: [4, 1, 3], 
      state: 1
    }, 
    {
      pos: [5, 1, 3], 
      state: 0
    }, 
    {
      pos: [6, 1, 3], 
      state: 0
    }, 
    {
      pos: [7, 1, 3], 
      state: 0
    }, 
    {
      pos: [11, 1, 3], 
      state: 0
    }, 
    {
      pos: [12, 1, 3], 
      state: 0
    }, 
    {
      pos: [0, 1, 4], 
      state: 0
    }, 
    {
      pos: [1, 1, 4], 
      state: 1
    }, 
    {
      pos: [2, 1, 4], 
      state: 3
    }, 
    {
      pos: [3, 1, 4], 
      state: 3
    }, 
    {
      pos: [4, 1, 4], 
      state: 3
    }, 
    {
      pos: [5, 1, 4], 
      state: 1
    }, 
    {
      pos: [6, 1, 4], 
      state: 0
    }, 
    {
      pos: [8, 1, 4], 
      state: 0
    }, 
    {
      pos: [12, 1, 4], 
      state: 0
    }, 
    {
      pos: [1, 1, 5], 
      state: 4
    }, 
    {
      pos: [2, 1, 5], 
      state: 3
    }, 
    {
      pos: [3, 1, 5], 
      state: 5
    }, 
    {
      pos: [4, 1, 5], 
      state: 3
    }, 
    {
      pos: [5, 1, 5], 
      state: 4
    }, 
    {
      pos: [6, 1, 5], 
      state: 0
    }, 
    {
      pos: [7, 1, 5], 
      state: 0
    }, 
    {
      pos: [8, 1, 5], 
      state: 0
    }, 
    {
      pos: [9, 1, 5], 
      state: 0
    }, 
    {
      pos: [11, 1, 5], 
      state: 0
    }, 
    {
      pos: [12, 1, 5], 
      state: 0
    }, 
    {
      pos: [0, 1, 6], 
      state: 0
    }, 
    {
      pos: [1, 1, 6], 
      state: 1
    }, 
    {
      pos: [2, 1, 6], 
      state: 3
    }, 
    {
      pos: [3, 1, 6], 
      state: 3
    }, 
    {
      pos: [4, 1, 6], 
      state: 3
    }, 
    {
      pos: [5, 1, 6], 
      state: 1
    }, 
    {
      pos: [6, 1, 6], 
      state: 0
    }, 
    {
      pos: [7, 1, 6], 
      state: 0
    }, 
    {
      pos: [8, 1, 6], 
      state: 0
    }, 
    {
      pos: [9, 1, 6], 
      state: 0
    }, 
    {
      pos: [10, 1, 6], 
      state: 0
    }, 
    {
      pos: [11, 1, 6], 
      state: 0
    }, 
    {
      pos: [12, 1, 6], 
      state: 0
    }, 
    {
      pos: [0, 1, 7], 
      state: 0
    }, 
    {
      pos: [1, 1, 7], 
      state: 0
    }, 
    {
      pos: [2, 1, 7], 
      state: 1
    }, 
    {
      pos: [3, 1, 7], 
      state: 1
    }, 
    {
      pos: [4, 1, 7], 
      state: 1
    }, 
    {
      pos: [5, 1, 7], 
      state: 0
    }, 
    {
      pos: [6, 1, 7], 
      state: 0
    }, 
    {
      pos: [7, 1, 7], 
      state: 0
    }, 
    {
      pos: [8, 1, 7], 
      state: 0
    }, 
    {
      pos: [9, 1, 7], 
      state: 0
    }, 
    {
      pos: [10, 1, 7], 
      state: 0
    }, 
    {
      pos: [11, 1, 7], 
      state: 0
    }, 
    {
      pos: [12, 1, 7], 
      state: 0
    }, 
    {
      pos: [0, 1, 8], 
      state: 0
    }, 
    {
      pos: [1, 1, 8], 
      state: 0
    }, 
    {
      pos: [2, 1, 8], 
      state: 0
    }, 
    {
      pos: [3, 1, 8], 
      state: 0
    }, 
    {
      pos: [4, 1, 8], 
      state: 0
    }, 
    {
      pos: [5, 1, 8], 
      state: 0
    }, 
    {
      pos: [6, 1, 8], 
      state: 0
    }, 
    {
      pos: [7, 1, 8], 
      state: 0
    }, 
    {
      pos: [8, 1, 8], 
      state: 0
    }, 
    {
      pos: [9, 1, 8], 
      state: 0
    }, 
    {
      pos: [11, 1, 8], 
      state: 0
    }, 
    {
      pos: [12, 1, 8], 
      state: 0
    }, 
    {
      pos: [0, 1, 9], 
      state: 0
    }, 
    {
      pos: [1, 1, 9], 
      state: 0
    }, 
    {
      pos: [2, 1, 9], 
      state: 0
    }, 
    {
      pos: [3, 1, 9], 
      state: 0
    }, 
    {
      pos: [4, 1, 9], 
      state: 0
    }, 
    {
      pos: [5, 1, 9], 
      state: 0
    }, 
    {
      pos: [6, 1, 9], 
      state: 0
    }, 
    {
      pos: [7, 1, 9], 
      state: 0
    }, 
    {
      pos: [8, 1, 9], 
      state: 0
    }, 
    {
      pos: [9, 1, 9], 
      state: 0
    }, 
    {
      pos: [10, 1, 9], 
      state: 0
    }, 
    {
      pos: [11, 1, 9], 
      state: 0
    }, 
    {
      pos: [12, 1, 9], 
      state: 0
    }, 
    {
      pos: [0, 1, 10], 
      state: 0
    }, 
    {
      pos: [1, 1, 10], 
      state: 0
    }, 
    {
      pos: [2, 1, 10], 
      state: 0
    }, 
    {
      pos: [3, 1, 10], 
      state: 0
    }, 
    {
      pos: [4, 1, 10], 
      state: 0
    }, 
    {
      pos: [5, 1, 10], 
      state: 0
    }, 
    {
      pos: [6, 1, 10], 
      state: 0
    }, 
    {
      pos: [7, 1, 10], 
      state: 0
    }, 
    {
      pos: [8, 1, 10], 
      state: 0
    }, 
    {
      pos: [9, 1, 10], 
      state: 0
    }, 
    {
      pos: [10, 1, 10], 
      state: 0
    }, 
    {
      pos: [11, 1, 10], 
      state: 0
    }, 
    {
      pos: [12, 1, 10], 
      state: 0
    }, 
    {
      nbt: {
        final_state: "minecraft:grass_block", 
        name: "minecraft:bottom", 
        pool: "minecraft:village/common/sheep", 
        id: "minecraft:jigsaw", 
        target: "minecraft:bottom"
      }, 
      pos: [7, 1, 4], 
      state: 6
    }, 
    {
      nbt: {
        final_state: "minecraft:dirt", 
        name: "minecraft:bottom", 
        pool: "minecraft:village/savanna/trees", 
        id: "minecraft:jigsaw", 
        target: "minecraft:bottom"
      }, 
      pos: [10, 1, 8], 
      state: 6
    }, 
    {
      pos: [0, 1, 0], 
      state: 2
    }, 
    {
      pos: [1, 1, 0], 
      state: 2
    }, 
    {
      pos: [0, 1, 1], 
      state: 2
    }, 
    {
      pos: [9, 1, 2], 
      state: 7
    }, 
    {
      pos: [8, 1, 3], 
      state: 7
    }, 
    {
      pos: [9, 1, 3], 
      state: 7
    }, 
    {
      pos: [10, 1, 3], 
      state: 7
    }, 
    {
      pos: [9, 1, 4], 
      state: 7
    }, 
    {
      pos: [10, 1, 4], 
      state: 7
    }, 
    {
      pos: [11, 1, 4], 
      state: 7
    }, 
    {
      pos: [0, 1, 5], 
      state: 8
    }, 
    {
      pos: [10, 1, 5], 
      state: 7
    }, 
    {
      pos: [2, 2, 3], 
      state: 5
    }, 
    {
      pos: [3, 2, 3], 
      state: 5
    }, 
    {
      pos: [4, 2, 3], 
      state: 5
    }, 
    {
      pos: [1, 2, 4], 
      state: 5
    }, 
    {
      pos: [5, 2, 4], 
      state: 5
    }, 
    {
      pos: [1, 2, 6], 
      state: 5
    }, 
    {
      pos: [2, 2, 6], 
      state: 9
    }, 
    {
      pos: [3, 2, 6], 
      state: 10
    }, 
    {
      pos: [4, 2, 6], 
      state: 9
    }, 
    {
      pos: [5, 2, 6], 
      state: 5
    }, 
    {
      pos: [2, 2, 7], 
      state: 5
    }, 
    {
      pos: [3, 2, 7], 
      state: 5
    }, 
    {
      pos: [4, 2, 7], 
      state: 5
    }, 
    {
      nbt: {
        final_state: "minecraft:air", 
        name: "minecraft:building_entrance", 
        pool: "minecraft:empty", 
        id: "minecraft:jigsaw", 
        target: "minecraft:building_entrance"
      }, 
      pos: [0, 2, 5], 
      state: 11
    }, 
    {
      pos: [0, 2, 0], 
      state: 2
    }, 
    {
      pos: [1, 2, 0], 
      state: 2
    }, 
    {
      pos: [2, 2, 0], 
      state: 2
    }, 
    {
      pos: [3, 2, 0], 
      state: 2
    }, 
    {
      pos: [4, 2, 0], 
      state: 12
    }, 
    {
      pos: [5, 2, 0], 
      state: 13
    }, 
    {
      pos: [6, 2, 0], 
      state: 13
    }, 
    {
      pos: [7, 2, 0], 
      state: 13
    }, 
    {
      pos: [8, 2, 0], 
      state: 13
    }, 
    {
      pos: [9, 2, 0], 
      state: 13
    }, 
    {
      pos: [10, 2, 0], 
      state: 13
    }, 
    {
      pos: [11, 2, 0], 
      state: 13
    }, 
    {
      pos: [12, 2, 0], 
      state: 14
    }, 
    {
      pos: [0, 2, 1], 
      state: 2
    }, 
    {
      pos: [1, 2, 1], 
      state: 2
    }, 
    {
      pos: [2, 2, 1], 
      state: 2
    }, 
    {
      pos: [3, 2, 1], 
      state: 2
    }, 
    {
      pos: [4, 2, 1], 
      state: 15
    }, 
    {
      pos: [5, 2, 1], 
      state: 2
    }, 
    {
      pos: [6, 2, 1], 
      state: 2
    }, 
    {
      pos: [7, 2, 1], 
      state: 2
    }, 
    {
      pos: [8, 2, 1], 
      state: 2
    }, 
    {
      pos: [9, 2, 1], 
      state: 16
    }, 
    {
      pos: [10, 2, 1], 
      state: 16
    }, 
    {
      pos: [11, 2, 1], 
      state: 2
    }, 
    {
      pos: [12, 2, 1], 
      state: 15
    }, 
    {
      pos: [0, 2, 2], 
      state: 2
    }, 
    {
      pos: [1, 2, 2], 
      state: 2
    }, 
    {
      pos: [2, 2, 2], 
      state: 2
    }, 
    {
      pos: [3, 2, 2], 
      state: 2
    }, 
    {
      pos: [4, 2, 2], 
      state: 15
    }, 
    {
      pos: [5, 2, 2], 
      state: 2
    }, 
    {
      pos: [6, 2, 2], 
      state: 2
    }, 
    {
      pos: [7, 2, 2], 
      state: 16
    }, 
    {
      pos: [8, 2, 2], 
      state: 16
    }, 
    {
      pos: [9, 2, 2], 
      state: 2
    }, 
    {
      pos: [10, 2, 2], 
      state: 16
    }, 
    {
      pos: [11, 2, 2], 
      state: 17
    }, 
    {
      pos: [12, 2, 2], 
      state: 15
    }, 
    {
      pos: [0, 2, 3], 
      state: 2
    }, 
    {
      pos: [1, 2, 3], 
      state: 2
    }, 
    {
      pos: [5, 2, 3], 
      state: 2
    }, 
    {
      pos: [6, 2, 3], 
      state: 16
    }, 
    {
      pos: [7, 2, 3], 
      state: 16
    }, 
    {
      pos: [8, 2, 3], 
      state: 2
    }, 
    {
      pos: [9, 2, 3], 
      state: 2
    }, 
    {
      pos: [10, 2, 3], 
      state: 2
    }, 
    {
      pos: [11, 2, 3], 
      state: 2
    }, 
    {
      pos: [12, 2, 3], 
      state: 15
    }, 
    {
      pos: [0, 2, 4], 
      state: 2
    }, 
    {
      pos: [2, 2, 4], 
      state: 2
    }, 
    {
      pos: [3, 2, 4], 
      state: 2
    }, 
    {
      pos: [4, 2, 4], 
      state: 2
    }, 
    {
      pos: [6, 2, 4], 
      state: 2
    }, 
    {
      pos: [7, 2, 4], 
      state: 2
    }, 
    {
      pos: [8, 2, 4], 
      state: 16
    }, 
    {
      pos: [9, 2, 4], 
      state: 2
    }, 
    {
      pos: [10, 2, 4], 
      state: 2
    }, 
    {
      pos: [11, 2, 4], 
      state: 2
    }, 
    {
      pos: [12, 2, 4], 
      state: 15
    }, 
    {
      pos: [1, 2, 5], 
      state: 18
    }, 
    {
      pos: [2, 2, 5], 
      state: 2
    }, 
    {
      pos: [3, 2, 5], 
      state: 2
    }, 
    {
      pos: [4, 2, 5], 
      state: 2
    }, 
    {
      pos: [5, 2, 5], 
      state: 19
    }, 
    {
      pos: [6, 2, 5], 
      state: 2
    }, 
    {
      pos: [7, 2, 5], 
      state: 16
    }, 
    {
      pos: [8, 2, 5], 
      state: 16
    }, 
    {
      pos: [9, 2, 5], 
      state: 2
    }, 
    {
      pos: [10, 2, 5], 
      state: 2
    }, 
    {
      pos: [11, 2, 5], 
      state: 16
    }, 
    {
      pos: [12, 2, 5], 
      state: 15
    }, 
    {
      pos: [0, 2, 6], 
      state: 2
    }, 
    {
      pos: [6, 2, 6], 
      state: 2
    }, 
    {
      pos: [7, 2, 6], 
      state: 2
    }, 
    {
      pos: [8, 2, 6], 
      state: 16
    }, 
    {
      pos: [9, 2, 6], 
      state: 2
    }, 
    {
      pos: [10, 2, 6], 
      state: 2
    }, 
    {
      pos: [11, 2, 6], 
      state: 16
    }, 
    {
      pos: [12, 2, 6], 
      state: 15
    }, 
    {
      pos: [0, 2, 7], 
      state: 2
    }, 
    {
      pos: [1, 2, 7], 
      state: 2
    }, 
    {
      pos: [5, 2, 7], 
      state: 16
    }, 
    {
      pos: [6, 2, 7], 
      state: 16
    }, 
    {
      pos: [7, 2, 7], 
      state: 16
    }, 
    {
      pos: [8, 2, 7], 
      state: 16
    }, 
    {
      pos: [9, 2, 7], 
      state: 16
    }, 
    {
      pos: [10, 2, 7], 
      state: 16
    }, 
    {
      pos: [11, 2, 7], 
      state: 2
    }, 
    {
      pos: [12, 2, 7], 
      state: 15
    }, 
    {
      pos: [0, 2, 8], 
      state: 2
    }, 
    {
      pos: [1, 2, 8], 
      state: 2
    }, 
    {
      pos: [2, 2, 8], 
      state: 2
    }, 
    {
      pos: [3, 2, 8], 
      state: 2
    }, 
    {
      pos: [4, 2, 8], 
      state: 15
    }, 
    {
      pos: [5, 2, 8], 
      state: 2
    }, 
    {
      pos: [6, 2, 8], 
      state: 2
    }, 
    {
      pos: [7, 2, 8], 
      state: 16
    }, 
    {
      pos: [8, 2, 8], 
      state: 16
    }, 
    {
      pos: [9, 2, 8], 
      state: 2
    }, 
    {
      pos: [10, 2, 8], 
      state: 2
    }, 
    {
      pos: [11, 2, 8], 
      state: 16
    }, 
    {
      pos: [12, 2, 8], 
      state: 15
    }, 
    {
      pos: [0, 2, 9], 
      state: 2
    }, 
    {
      pos: [1, 2, 9], 
      state: 2
    }, 
    {
      pos: [2, 2, 9], 
      state: 2
    }, 
    {
      pos: [3, 2, 9], 
      state: 2
    }, 
    {
      pos: [4, 2, 9], 
      state: 15
    }, 
    {
      pos: [5, 2, 9], 
      state: 16
    }, 
    {
      pos: [6, 2, 9], 
      state: 2
    }, 
    {
      pos: [7, 2, 9], 
      state: 16
    }, 
    {
      pos: [8, 2, 9], 
      state: 16
    }, 
    {
      pos: [9, 2, 9], 
      state: 2
    }, 
    {
      pos: [10, 2, 9], 
      state: 16
    }, 
    {
      pos: [11, 2, 9], 
      state: 16
    }, 
    {
      pos: [12, 2, 9], 
      state: 15
    }, 
    {
      pos: [0, 2, 10], 
      state: 2
    }, 
    {
      pos: [1, 2, 10], 
      state: 2
    }, 
    {
      pos: [2, 2, 10], 
      state: 2
    }, 
    {
      pos: [3, 2, 10], 
      state: 2
    }, 
    {
      pos: [4, 2, 10], 
      state: 20
    }, 
    {
      pos: [5, 2, 10], 
      state: 13
    }, 
    {
      pos: [6, 2, 10], 
      state: 13
    }, 
    {
      pos: [7, 2, 10], 
      state: 13
    }, 
    {
      pos: [8, 2, 10], 
      state: 13
    }, 
    {
      pos: [9, 2, 10], 
      state: 13
    }, 
    {
      pos: [10, 2, 10], 
      state: 13
    }, 
    {
      pos: [11, 2, 10], 
      state: 13
    }, 
    {
      pos: [12, 2, 10], 
      state: 21
    }, 
    {
      pos: [2, 3, 3], 
      state: 5
    }, 
    {
      pos: [4, 3, 3], 
      state: 5
    }, 
    {
      pos: [1, 3, 4], 
      state: 5
    }, 
    {
      pos: [5, 3, 4], 
      state: 5
    }, 
    {
      pos: [1, 3, 6], 
      state: 5
    }, 
    {
      pos: [5, 3, 6], 
      state: 5
    }, 
    {
      pos: [2, 3, 7], 
      state: 5
    }, 
    {
      pos: [4, 3, 7], 
      state: 5
    }, 
    {
      pos: [0, 3, 0], 
      state: 2
    }, 
    {
      pos: [1, 3, 0], 
      state: 2
    }, 
    {
      pos: [2, 3, 0], 
      state: 2
    }, 
    {
      pos: [3, 3, 0], 
      state: 2
    }, 
    {
      pos: [4, 3, 0], 
      state: 2
    }, 
    {
      pos: [5, 3, 0], 
      state: 2
    }, 
    {
      pos: [6, 3, 0], 
      state: 2
    }, 
    {
      pos: [7, 3, 0], 
      state: 2
    }, 
    {
      pos: [8, 3, 0], 
      state: 2
    }, 
    {
      pos: [9, 3, 0], 
      state: 2
    }, 
    {
      pos: [10, 3, 0], 
      state: 2
    }, 
    {
      pos: [11, 3, 0], 
      state: 2
    }, 
    {
      pos: [12, 3, 0], 
      state: 2
    }, 
    {
      pos: [0, 3, 1], 
      state: 2
    }, 
    {
      pos: [1, 3, 1], 
      state: 2
    }, 
    {
      pos: [2, 3, 1], 
      state: 2
    }, 
    {
      pos: [3, 3, 1], 
      state: 2
    }, 
    {
      pos: [4, 3, 1], 
      state: 2
    }, 
    {
      pos: [5, 3, 1], 
      state: 2
    }, 
    {
      pos: [6, 3, 1], 
      state: 2
    }, 
    {
      pos: [7, 3, 1], 
      state: 2
    }, 
    {
      pos: [8, 3, 1], 
      state: 2
    }, 
    {
      pos: [9, 3, 1], 
      state: 2
    }, 
    {
      pos: [10, 3, 1], 
      state: 2
    }, 
    {
      pos: [11, 3, 1], 
      state: 2
    }, 
    {
      pos: [12, 3, 1], 
      state: 2
    }, 
    {
      pos: [0, 3, 2], 
      state: 2
    }, 
    {
      pos: [1, 3, 2], 
      state: 2
    }, 
    {
      pos: [2, 3, 2], 
      state: 2
    }, 
    {
      pos: [3, 3, 2], 
      state: 2
    }, 
    {
      pos: [4, 3, 2], 
      state: 2
    }, 
    {
      pos: [5, 3, 2], 
      state: 2
    }, 
    {
      pos: [6, 3, 2], 
      state: 2
    }, 
    {
      pos: [7, 3, 2], 
      state: 2
    }, 
    {
      pos: [8, 3, 2], 
      state: 2
    }, 
    {
      pos: [9, 3, 2], 
      state: 2
    }, 
    {
      pos: [10, 3, 2], 
      state: 2
    }, 
    {
      pos: [11, 3, 2], 
      state: 22
    }, 
    {
      pos: [12, 3, 2], 
      state: 2
    }, 
    {
      pos: [0, 3, 3], 
      state: 2
    }, 
    {
      pos: [1, 3, 3], 
      state: 2
    }, 
    {
      pos: [3, 3, 3], 
      state: 23
    }, 
    {
      pos: [5, 3, 3], 
      state: 2
    }, 
    {
      pos: [6, 3, 3], 
      state: 2
    }, 
    {
      pos: [7, 3, 3], 
      state: 2
    }, 
    {
      pos: [8, 3, 3], 
      state: 2
    }, 
    {
      pos: [9, 3, 3], 
      state: 2
    }, 
    {
      pos: [10, 3, 3], 
      state: 2
    }, 
    {
      pos: [11, 3, 3], 
      state: 2
    }, 
    {
      pos: [12, 3, 3], 
      state: 2
    }, 
    {
      pos: [0, 3, 4], 
      state: 24
    }, 
    {
      pos: [2, 3, 4], 
      state: 2
    }, 
    {
      pos: [3, 3, 4], 
      state: 2
    }, 
    {
      pos: [4, 3, 4], 
      state: 2
    }, 
    {
      pos: [6, 3, 4], 
      state: 2
    }, 
    {
      pos: [7, 3, 4], 
      state: 2
    }, 
    {
      pos: [8, 3, 4], 
      state: 2
    }, 
    {
      pos: [9, 3, 4], 
      state: 2
    }, 
    {
      pos: [10, 3, 4], 
      state: 2
    }, 
    {
      pos: [11, 3, 4], 
      state: 2
    }, 
    {
      pos: [12, 3, 4], 
      state: 2
    }, 
    {
      pos: [0, 3, 5], 
      state: 2
    }, 
    {
      pos: [1, 3, 5], 
      state: 25
    }, 
    {
      pos: [2, 3, 5], 
      state: 2
    }, 
    {
      pos: [3, 3, 5], 
      state: 2
    }, 
    {
      pos: [4, 3, 5], 
      state: 2
    }, 
    {
      pos: [5, 3, 5], 
      state: 26
    }, 
    {
      pos: [6, 3, 5], 
      state: 2
    }, 
    {
      pos: [7, 3, 5], 
      state: 2
    }, 
    {
      pos: [8, 3, 5], 
      state: 2
    }, 
    {
      pos: [9, 3, 5], 
      state: 2
    }, 
    {
      pos: [10, 3, 5], 
      state: 2
    }, 
    {
      pos: [11, 3, 5], 
      state: 2
    }, 
    {
      pos: [12, 3, 5], 
      state: 2
    }, 
    {
      pos: [0, 3, 6], 
      state: 24
    }, 
    {
      pos: [2, 3, 6], 
      state: 2
    }, 
    {
      pos: [3, 3, 6], 
      state: 2
    }, 
    {
      pos: [4, 3, 6], 
      state: 2
    }, 
    {
      pos: [6, 3, 6], 
      state: 2
    }, 
    {
      pos: [7, 3, 6], 
      state: 2
    }, 
    {
      pos: [8, 3, 6], 
      state: 2
    }, 
    {
      pos: [9, 3, 6], 
      state: 2
    }, 
    {
      pos: [10, 3, 6], 
      state: 2
    }, 
    {
      pos: [11, 3, 6], 
      state: 2
    }, 
    {
      pos: [12, 3, 6], 
      state: 27
    }, 
    {
      pos: [0, 3, 7], 
      state: 2
    }, 
    {
      pos: [1, 3, 7], 
      state: 2
    }, 
    {
      pos: [3, 3, 7], 
      state: 23
    }, 
    {
      pos: [5, 3, 7], 
      state: 2
    }, 
    {
      pos: [6, 3, 7], 
      state: 2
    }, 
    {
      pos: [7, 3, 7], 
      state: 2
    }, 
    {
      pos: [8, 3, 7], 
      state: 2
    }, 
    {
      pos: [9, 3, 7], 
      state: 2
    }, 
    {
      pos: [10, 3, 7], 
      state: 2
    }, 
    {
      pos: [11, 3, 7], 
      state: 2
    }, 
    {
      pos: [12, 3, 7], 
      state: 2
    }, 
    {
      pos: [0, 3, 8], 
      state: 2
    }, 
    {
      pos: [1, 3, 8], 
      state: 2
    }, 
    {
      pos: [2, 3, 8], 
      state: 2
    }, 
    {
      pos: [3, 3, 8], 
      state: 2
    }, 
    {
      pos: [4, 3, 8], 
      state: 2
    }, 
    {
      pos: [5, 3, 8], 
      state: 2
    }, 
    {
      pos: [6, 3, 8], 
      state: 2
    }, 
    {
      pos: [7, 3, 8], 
      state: 2
    }, 
    {
      pos: [8, 3, 8], 
      state: 2
    }, 
    {
      pos: [9, 3, 8], 
      state: 2
    }, 
    {
      pos: [10, 3, 8], 
      state: 2
    }, 
    {
      pos: [11, 3, 8], 
      state: 2
    }, 
    {
      pos: [12, 3, 8], 
      state: 2
    }, 
    {
      pos: [0, 3, 9], 
      state: 2
    }, 
    {
      pos: [1, 3, 9], 
      state: 2
    }, 
    {
      pos: [2, 3, 9], 
      state: 2
    }, 
    {
      pos: [3, 3, 9], 
      state: 2
    }, 
    {
      pos: [4, 3, 9], 
      state: 2
    }, 
    {
      pos: [5, 3, 9], 
      state: 2
    }, 
    {
      pos: [6, 3, 9], 
      state: 2
    }, 
    {
      pos: [7, 3, 9], 
      state: 2
    }, 
    {
      pos: [8, 3, 9], 
      state: 2
    }, 
    {
      pos: [9, 3, 9], 
      state: 2
    }, 
    {
      pos: [10, 3, 9], 
      state: 2
    }, 
    {
      pos: [11, 3, 9], 
      state: 2
    }, 
    {
      pos: [12, 3, 9], 
      state: 2
    }, 
    {
      pos: [0, 3, 10], 
      state: 2
    }, 
    {
      pos: [1, 3, 10], 
      state: 2
    }, 
    {
      pos: [2, 3, 10], 
      state: 2
    }, 
    {
      pos: [3, 3, 10], 
      state: 2
    }, 
    {
      pos: [4, 3, 10], 
      state: 2
    }, 
    {
      pos: [5, 3, 10], 
      state: 2
    }, 
    {
      pos: [6, 3, 10], 
      state: 2
    }, 
    {
      pos: [7, 3, 10], 
      state: 2
    }, 
    {
      pos: [8, 3, 10], 
      state: 27
    }, 
    {
      pos: [9, 3, 10], 
      state: 2
    }, 
    {
      pos: [10, 3, 10], 
      state: 2
    }, 
    {
      pos: [11, 3, 10], 
      state: 2
    }, 
    {
      pos: [12, 3, 10], 
      state: 27
    }, 
    {
      pos: [2, 4, 3], 
      state: 5
    }, 
    {
      pos: [3, 4, 3], 
      state: 4
    }, 
    {
      pos: [4, 4, 3], 
      state: 5
    }, 
    {
      pos: [1, 4, 4], 
      state: 5
    }, 
    {
      pos: [5, 4, 4], 
      state: 5
    }, 
    {
      pos: [1, 4, 5], 
      state: 28
    }, 
    {
      pos: [5, 4, 5], 
      state: 28
    }, 
    {
      pos: [1, 4, 6], 
      state: 5
    }, 
    {
      pos: [5, 4, 6], 
      state: 5
    }, 
    {
      pos: [2, 4, 7], 
      state: 5
    }, 
    {
      pos: [3, 4, 7], 
      state: 4
    }, 
    {
      pos: [4, 4, 7], 
      state: 5
    }, 
    {
      pos: [0, 4, 0], 
      state: 2
    }, 
    {
      pos: [1, 4, 0], 
      state: 2
    }, 
    {
      pos: [2, 4, 0], 
      state: 2
    }, 
    {
      pos: [3, 4, 0], 
      state: 2
    }, 
    {
      pos: [4, 4, 0], 
      state: 2
    }, 
    {
      pos: [5, 4, 0], 
      state: 2
    }, 
    {
      pos: [6, 4, 0], 
      state: 2
    }, 
    {
      pos: [7, 4, 0], 
      state: 2
    }, 
    {
      pos: [8, 4, 0], 
      state: 2
    }, 
    {
      pos: [9, 4, 0], 
      state: 2
    }, 
    {
      pos: [10, 4, 0], 
      state: 2
    }, 
    {
      pos: [11, 4, 0], 
      state: 2
    }, 
    {
      pos: [12, 4, 0], 
      state: 2
    }, 
    {
      pos: [0, 4, 1], 
      state: 2
    }, 
    {
      pos: [1, 4, 1], 
      state: 2
    }, 
    {
      pos: [2, 4, 1], 
      state: 2
    }, 
    {
      pos: [3, 4, 1], 
      state: 2
    }, 
    {
      pos: [4, 4, 1], 
      state: 2
    }, 
    {
      pos: [5, 4, 1], 
      state: 2
    }, 
    {
      pos: [6, 4, 1], 
      state: 2
    }, 
    {
      pos: [7, 4, 1], 
      state: 2
    }, 
    {
      pos: [8, 4, 1], 
      state: 2
    }, 
    {
      pos: [9, 4, 1], 
      state: 2
    }, 
    {
      pos: [10, 4, 1], 
      state: 2
    }, 
    {
      pos: [11, 4, 1], 
      state: 2
    }, 
    {
      pos: [12, 4, 1], 
      state: 2
    }, 
    {
      pos: [0, 4, 2], 
      state: 2
    }, 
    {
      pos: [1, 4, 2], 
      state: 2
    }, 
    {
      pos: [2, 4, 2], 
      state: 2
    }, 
    {
      pos: [3, 4, 2], 
      state: 2
    }, 
    {
      pos: [4, 4, 2], 
      state: 2
    }, 
    {
      pos: [5, 4, 2], 
      state: 2
    }, 
    {
      pos: [6, 4, 2], 
      state: 2
    }, 
    {
      pos: [7, 4, 2], 
      state: 2
    }, 
    {
      pos: [8, 4, 2], 
      state: 2
    }, 
    {
      pos: [9, 4, 2], 
      state: 2
    }, 
    {
      pos: [10, 4, 2], 
      state: 2
    }, 
    {
      pos: [11, 4, 2], 
      state: 2
    }, 
    {
      pos: [12, 4, 2], 
      state: 2
    }, 
    {
      pos: [0, 4, 3], 
      state: 2
    }, 
    {
      pos: [1, 4, 3], 
      state: 2
    }, 
    {
      pos: [5, 4, 3], 
      state: 2
    }, 
    {
      pos: [6, 4, 3], 
      state: 2
    }, 
    {
      pos: [7, 4, 3], 
      state: 2
    }, 
    {
      pos: [8, 4, 3], 
      state: 2
    }, 
    {
      pos: [9, 4, 3], 
      state: 2
    }, 
    {
      pos: [10, 4, 3], 
      state: 2
    }, 
    {
      pos: [11, 4, 3], 
      state: 2
    }, 
    {
      pos: [12, 4, 3], 
      state: 2
    }, 
    {
      pos: [0, 4, 4], 
      state: 2
    }, 
    {
      pos: [2, 4, 4], 
      state: 2
    }, 
    {
      pos: [3, 4, 4], 
      state: 2
    }, 
    {
      pos: [4, 4, 4], 
      state: 2
    }, 
    {
      pos: [6, 4, 4], 
      state: 2
    }, 
    {
      pos: [7, 4, 4], 
      state: 2
    }, 
    {
      pos: [8, 4, 4], 
      state: 2
    }, 
    {
      pos: [9, 4, 4], 
      state: 2
    }, 
    {
      pos: [10, 4, 4], 
      state: 2
    }, 
    {
      pos: [11, 4, 4], 
      state: 2
    }, 
    {
      pos: [12, 4, 4], 
      state: 2
    }, 
    {
      pos: [0, 4, 5], 
      state: 2
    }, 
    {
      pos: [2, 4, 5], 
      state: 2
    }, 
    {
      pos: [3, 4, 5], 
      state: 2
    }, 
    {
      pos: [4, 4, 5], 
      state: 24
    }, 
    {
      pos: [6, 4, 5], 
      state: 2
    }, 
    {
      pos: [7, 4, 5], 
      state: 2
    }, 
    {
      pos: [8, 4, 5], 
      state: 2
    }, 
    {
      pos: [9, 4, 5], 
      state: 2
    }, 
    {
      pos: [10, 4, 5], 
      state: 2
    }, 
    {
      pos: [11, 4, 5], 
      state: 2
    }, 
    {
      pos: [12, 4, 5], 
      state: 2
    }, 
    {
      pos: [0, 4, 6], 
      state: 2
    }, 
    {
      pos: [2, 4, 6], 
      state: 2
    }, 
    {
      pos: [3, 4, 6], 
      state: 2
    }, 
    {
      pos: [4, 4, 6], 
      state: 2
    }, 
    {
      pos: [6, 4, 6], 
      state: 2
    }, 
    {
      pos: [7, 4, 6], 
      state: 2
    }, 
    {
      pos: [8, 4, 6], 
      state: 2
    }, 
    {
      pos: [9, 4, 6], 
      state: 2
    }, 
    {
      pos: [10, 4, 6], 
      state: 2
    }, 
    {
      pos: [11, 4, 6], 
      state: 2
    }, 
    {
      pos: [12, 4, 6], 
      state: 2
    }, 
    {
      pos: [0, 4, 7], 
      state: 2
    }, 
    {
      pos: [1, 4, 7], 
      state: 2
    }, 
    {
      pos: [5, 4, 7], 
      state: 2
    }, 
    {
      pos: [6, 4, 7], 
      state: 2
    }, 
    {
      pos: [7, 4, 7], 
      state: 2
    }, 
    {
      pos: [8, 4, 7], 
      state: 2
    }, 
    {
      pos: [9, 4, 7], 
      state: 2
    }, 
    {
      pos: [10, 4, 7], 
      state: 2
    }, 
    {
      pos: [11, 4, 7], 
      state: 2
    }, 
    {
      pos: [12, 4, 7], 
      state: 2
    }, 
    {
      pos: [0, 4, 8], 
      state: 2
    }, 
    {
      pos: [1, 4, 8], 
      state: 2
    }, 
    {
      pos: [2, 4, 8], 
      state: 2
    }, 
    {
      pos: [3, 4, 8], 
      state: 2
    }, 
    {
      pos: [4, 4, 8], 
      state: 2
    }, 
    {
      pos: [5, 4, 8], 
      state: 2
    }, 
    {
      pos: [6, 4, 8], 
      state: 2
    }, 
    {
      pos: [7, 4, 8], 
      state: 2
    }, 
    {
      pos: [8, 4, 8], 
      state: 2
    }, 
    {
      pos: [9, 4, 8], 
      state: 2
    }, 
    {
      pos: [10, 4, 8], 
      state: 2
    }, 
    {
      pos: [11, 4, 8], 
      state: 2
    }, 
    {
      pos: [12, 4, 8], 
      state: 2
    }, 
    {
      pos: [0, 4, 9], 
      state: 2
    }, 
    {
      pos: [1, 4, 9], 
      state: 2
    }, 
    {
      pos: [2, 4, 9], 
      state: 2
    }, 
    {
      pos: [3, 4, 9], 
      state: 2
    }, 
    {
      pos: [4, 4, 9], 
      state: 2
    }, 
    {
      pos: [5, 4, 9], 
      state: 2
    }, 
    {
      pos: [6, 4, 9], 
      state: 2
    }, 
    {
      pos: [7, 4, 9], 
      state: 2
    }, 
    {
      pos: [8, 4, 9], 
      state: 2
    }, 
    {
      pos: [9, 4, 9], 
      state: 2
    }, 
    {
      pos: [10, 4, 9], 
      state: 2
    }, 
    {
      pos: [11, 4, 9], 
      state: 2
    }, 
    {
      pos: [12, 4, 9], 
      state: 2
    }, 
    {
      pos: [0, 4, 10], 
      state: 2
    }, 
    {
      pos: [1, 4, 10], 
      state: 2
    }, 
    {
      pos: [2, 4, 10], 
      state: 2
    }, 
    {
      pos: [3, 4, 10], 
      state: 2
    }, 
    {
      pos: [4, 4, 10], 
      state: 2
    }, 
    {
      pos: [5, 4, 10], 
      state: 2
    }, 
    {
      pos: [6, 4, 10], 
      state: 2
    }, 
    {
      pos: [7, 4, 10], 
      state: 2
    }, 
    {
      pos: [8, 4, 10], 
      state: 2
    }, 
    {
      pos: [9, 4, 10], 
      state: 2
    }, 
    {
      pos: [10, 4, 10], 
      state: 2
    }, 
    {
      pos: [11, 4, 10], 
      state: 2
    }, 
    {
      pos: [12, 4, 10], 
      state: 2
    }, 
    {
      pos: [1, 5, 3], 
      state: 3
    }, 
    {
      pos: [2, 5, 3], 
      state: 3
    }, 
    {
      pos: [3, 5, 3], 
      state: 3
    }, 
    {
      pos: [4, 5, 3], 
      state: 3
    }, 
    {
      pos: [5, 5, 3], 
      state: 3
    }, 
    {
      pos: [1, 5, 4], 
      state: 3
    }, 
    {
      pos: [5, 5, 4], 
      state: 3
    }, 
    {
      pos: [1, 5, 5], 
      state: 3
    }, 
    {
      pos: [5, 5, 5], 
      state: 3
    }, 
    {
      pos: [1, 5, 6], 
      state: 3
    }, 
    {
      pos: [5, 5, 6], 
      state: 3
    }, 
    {
      pos: [1, 5, 7], 
      state: 3
    }, 
    {
      pos: [2, 5, 7], 
      state: 3
    }, 
    {
      pos: [3, 5, 7], 
      state: 3
    }, 
    {
      pos: [4, 5, 7], 
      state: 3
    }, 
    {
      pos: [5, 5, 7], 
      state: 3
    }, 
    {
      pos: [0, 5, 0], 
      state: 2
    }, 
    {
      pos: [1, 5, 0], 
      state: 2
    }, 
    {
      pos: [2, 5, 0], 
      state: 2
    }, 
    {
      pos: [3, 5, 0], 
      state: 2
    }, 
    {
      pos: [4, 5, 0], 
      state: 2
    }, 
    {
      pos: [5, 5, 0], 
      state: 2
    }, 
    {
      pos: [6, 5, 0], 
      state: 2
    }, 
    {
      pos: [7, 5, 0], 
      state: 2
    }, 
    {
      pos: [8, 5, 0], 
      state: 2
    }, 
    {
      pos: [9, 5, 0], 
      state: 2
    }, 
    {
      pos: [10, 5, 0], 
      state: 2
    }, 
    {
      pos: [11, 5, 0], 
      state: 2
    }, 
    {
      pos: [12, 5, 0], 
      state: 2
    }, 
    {
      pos: [0, 5, 1], 
      state: 2
    }, 
    {
      pos: [1, 5, 1], 
      state: 2
    }, 
    {
      pos: [2, 5, 1], 
      state: 2
    }, 
    {
      pos: [3, 5, 1], 
      state: 2
    }, 
    {
      pos: [4, 5, 1], 
      state: 2
    }, 
    {
      pos: [5, 5, 1], 
      state: 2
    }, 
    {
      pos: [6, 5, 1], 
      state: 2
    }, 
    {
      pos: [7, 5, 1], 
      state: 2
    }, 
    {
      pos: [8, 5, 1], 
      state: 2
    }, 
    {
      pos: [9, 5, 1], 
      state: 2
    }, 
    {
      pos: [10, 5, 1], 
      state: 2
    }, 
    {
      pos: [11, 5, 1], 
      state: 2
    }, 
    {
      pos: [12, 5, 1], 
      state: 2
    }, 
    {
      pos: [0, 5, 2], 
      state: 2
    }, 
    {
      pos: [1, 5, 2], 
      state: 29
    }, 
    {
      pos: [2, 5, 2], 
      state: 29
    }, 
    {
      pos: [3, 5, 2], 
      state: 29
    }, 
    {
      pos: [4, 5, 2], 
      state: 29
    }, 
    {
      pos: [5, 5, 2], 
      state: 29
    }, 
    {
      pos: [6, 5, 2], 
      state: 2
    }, 
    {
      pos: [7, 5, 2], 
      state: 2
    }, 
    {
      pos: [8, 5, 2], 
      state: 2
    }, 
    {
      pos: [9, 5, 2], 
      state: 2
    }, 
    {
      pos: [10, 5, 2], 
      state: 2
    }, 
    {
      pos: [11, 5, 2], 
      state: 2
    }, 
    {
      pos: [12, 5, 2], 
      state: 2
    }, 
    {
      pos: [0, 5, 3], 
      state: 30
    }, 
    {
      pos: [6, 5, 3], 
      state: 31
    }, 
    {
      pos: [7, 5, 3], 
      state: 2
    }, 
    {
      pos: [8, 5, 3], 
      state: 2
    }, 
    {
      pos: [9, 5, 3], 
      state: 2
    }, 
    {
      pos: [10, 5, 3], 
      state: 2
    }, 
    {
      pos: [11, 5, 3], 
      state: 2
    }, 
    {
      pos: [12, 5, 3], 
      state: 2
    }, 
    {
      pos: [0, 5, 4], 
      state: 30
    }, 
    {
      pos: [2, 5, 4], 
      state: 2
    }, 
    {
      pos: [3, 5, 4], 
      state: 2
    }, 
    {
      pos: [4, 5, 4], 
      state: 2
    }, 
    {
      pos: [6, 5, 4], 
      state: 31
    }, 
    {
      pos: [7, 5, 4], 
      state: 2
    }, 
    {
      pos: [8, 5, 4], 
      state: 2
    }, 
    {
      pos: [9, 5, 4], 
      state: 2
    }, 
    {
      pos: [10, 5, 4], 
      state: 2
    }, 
    {
      pos: [11, 5, 4], 
      state: 2
    }, 
    {
      pos: [12, 5, 4], 
      state: 2
    }, 
    {
      pos: [0, 5, 5], 
      state: 30
    }, 
    {
      pos: [2, 5, 5], 
      state: 2
    }, 
    {
      pos: [3, 5, 5], 
      state: 2
    }, 
    {
      pos: [4, 5, 5], 
      state: 2
    }, 
    {
      pos: [6, 5, 5], 
      state: 31
    }, 
    {
      pos: [7, 5, 5], 
      state: 2
    }, 
    {
      pos: [8, 5, 5], 
      state: 2
    }, 
    {
      pos: [9, 5, 5], 
      state: 2
    }, 
    {
      pos: [10, 5, 5], 
      state: 2
    }, 
    {
      pos: [11, 5, 5], 
      state: 2
    }, 
    {
      pos: [12, 5, 5], 
      state: 2
    }, 
    {
      pos: [0, 5, 6], 
      state: 30
    }, 
    {
      pos: [2, 5, 6], 
      state: 2
    }, 
    {
      pos: [3, 5, 6], 
      state: 2
    }, 
    {
      pos: [4, 5, 6], 
      state: 2
    }, 
    {
      pos: [6, 5, 6], 
      state: 31
    }, 
    {
      pos: [7, 5, 6], 
      state: 2
    }, 
    {
      pos: [8, 5, 6], 
      state: 2
    }, 
    {
      pos: [9, 5, 6], 
      state: 2
    }, 
    {
      pos: [10, 5, 6], 
      state: 2
    }, 
    {
      pos: [11, 5, 6], 
      state: 2
    }, 
    {
      pos: [12, 5, 6], 
      state: 2
    }, 
    {
      pos: [0, 5, 7], 
      state: 30
    }, 
    {
      pos: [6, 5, 7], 
      state: 31
    }, 
    {
      pos: [7, 5, 7], 
      state: 2
    }, 
    {
      pos: [8, 5, 7], 
      state: 2
    }, 
    {
      pos: [9, 5, 7], 
      state: 2
    }, 
    {
      pos: [10, 5, 7], 
      state: 2
    }, 
    {
      pos: [11, 5, 7], 
      state: 2
    }, 
    {
      pos: [12, 5, 7], 
      state: 2
    }, 
    {
      pos: [0, 5, 8], 
      state: 2
    }, 
    {
      pos: [1, 5, 8], 
      state: 32
    }, 
    {
      pos: [2, 5, 8], 
      state: 32
    }, 
    {
      pos: [3, 5, 8], 
      state: 32
    }, 
    {
      pos: [4, 5, 8], 
      state: 32
    }, 
    {
      pos: [5, 5, 8], 
      state: 32
    }, 
    {
      pos: [6, 5, 8], 
      state: 2
    }, 
    {
      pos: [7, 5, 8], 
      state: 2
    }, 
    {
      pos: [8, 5, 8], 
      state: 2
    }, 
    {
      pos: [9, 5, 8], 
      state: 2
    }, 
    {
      pos: [10, 5, 8], 
      state: 2
    }, 
    {
      pos: [11, 5, 8], 
      state: 2
    }, 
    {
      pos: [12, 5, 8], 
      state: 2
    }, 
    {
      pos: [0, 5, 9], 
      state: 2
    }, 
    {
      pos: [1, 5, 9], 
      state: 2
    }, 
    {
      pos: [2, 5, 9], 
      state: 2
    }, 
    {
      pos: [3, 5, 9], 
      state: 2
    }, 
    {
      pos: [4, 5, 9], 
      state: 2
    }, 
    {
      pos: [5, 5, 9], 
      state: 2
    }, 
    {
      pos: [6, 5, 9], 
      state: 2
    }, 
    {
      pos: [7, 5, 9], 
      state: 2
    }, 
    {
      pos: [8, 5, 9], 
      state: 2
    }, 
    {
      pos: [9, 5, 9], 
      state: 2
    }, 
    {
      pos: [10, 5, 9], 
      state: 2
    }, 
    {
      pos: [11, 5, 9], 
      state: 2
    }, 
    {
      pos: [12, 5, 9], 
      state: 2
    }, 
    {
      pos: [0, 5, 10], 
      state: 2
    }, 
    {
      pos: [1, 5, 10], 
      state: 2
    }, 
    {
      pos: [2, 5, 10], 
      state: 2
    }, 
    {
      pos: [3, 5, 10], 
      state: 2
    }, 
    {
      pos: [4, 5, 10], 
      state: 2
    }, 
    {
      pos: [5, 5, 10], 
      state: 2
    }, 
    {
      pos: [6, 5, 10], 
      state: 2
    }, 
    {
      pos: [7, 5, 10], 
      state: 2
    }, 
    {
      pos: [8, 5, 10], 
      state: 2
    }, 
    {
      pos: [9, 5, 10], 
      state: 2
    }, 
    {
      pos: [10, 5, 10], 
      state: 2
    }, 
    {
      pos: [11, 5, 10], 
      state: 2
    }, 
    {
      pos: [12, 5, 10], 
      state: 2
    }, 
    {
      pos: [2, 6, 4], 
      state: 3
    }, 
    {
      pos: [3, 6, 4], 
      state: 3
    }, 
    {
      pos: [4, 6, 4], 
      state: 3
    }, 
    {
      pos: [2, 6, 5], 
      state: 3
    }, 
    {
      pos: [3, 6, 5], 
      state: 3
    }, 
    {
      pos: [4, 6, 5], 
      state: 3
    }, 
    {
      pos: [2, 6, 6], 
      state: 3
    }, 
    {
      pos: [3, 6, 6], 
      state: 3
    }, 
    {
      pos: [4, 6, 6], 
      state: 3
    }, 
    {
      pos: [0, 6, 0], 
      state: 2
    }, 
    {
      pos: [1, 6, 0], 
      state: 2
    }, 
    {
      pos: [2, 6, 0], 
      state: 2
    }, 
    {
      pos: [3, 6, 0], 
      state: 2
    }, 
    {
      pos: [4, 6, 0], 
      state: 2
    }, 
    {
      pos: [5, 6, 0], 
      state: 2
    }, 
    {
      pos: [6, 6, 0], 
      state: 2
    }, 
    {
      pos: [7, 6, 0], 
      state: 2
    }, 
    {
      pos: [8, 6, 0], 
      state: 2
    }, 
    {
      pos: [9, 6, 0], 
      state: 2
    }, 
    {
      pos: [10, 6, 0], 
      state: 2
    }, 
    {
      pos: [11, 6, 0], 
      state: 2
    }, 
    {
      pos: [12, 6, 0], 
      state: 2
    }, 
    {
      pos: [0, 6, 1], 
      state: 2
    }, 
    {
      pos: [1, 6, 1], 
      state: 2
    }, 
    {
      pos: [2, 6, 1], 
      state: 2
    }, 
    {
      pos: [3, 6, 1], 
      state: 2
    }, 
    {
      pos: [4, 6, 1], 
      state: 2
    }, 
    {
      pos: [5, 6, 1], 
      state: 2
    }, 
    {
      pos: [6, 6, 1], 
      state: 2
    }, 
    {
      pos: [7, 6, 1], 
      state: 2
    }, 
    {
      pos: [8, 6, 1], 
      state: 2
    }, 
    {
      pos: [9, 6, 1], 
      state: 2
    }, 
    {
      pos: [10, 6, 1], 
      state: 2
    }, 
    {
      pos: [11, 6, 1], 
      state: 2
    }, 
    {
      pos: [12, 6, 1], 
      state: 2
    }, 
    {
      pos: [0, 6, 2], 
      state: 2
    }, 
    {
      pos: [1, 6, 2], 
      state: 2
    }, 
    {
      pos: [2, 6, 2], 
      state: 2
    }, 
    {
      pos: [3, 6, 2], 
      state: 2
    }, 
    {
      pos: [4, 6, 2], 
      state: 2
    }, 
    {
      pos: [5, 6, 2], 
      state: 2
    }, 
    {
      pos: [6, 6, 2], 
      state: 2
    }, 
    {
      pos: [7, 6, 2], 
      state: 2
    }, 
    {
      pos: [8, 6, 2], 
      state: 2
    }, 
    {
      pos: [9, 6, 2], 
      state: 2
    }, 
    {
      pos: [10, 6, 2], 
      state: 2
    }, 
    {
      pos: [11, 6, 2], 
      state: 2
    }, 
    {
      pos: [12, 6, 2], 
      state: 2
    }, 
    {
      pos: [0, 6, 3], 
      state: 2
    }, 
    {
      pos: [1, 6, 3], 
      state: 33
    }, 
    {
      pos: [2, 6, 3], 
      state: 29
    }, 
    {
      pos: [3, 6, 3], 
      state: 29
    }, 
    {
      pos: [4, 6, 3], 
      state: 29
    }, 
    {
      pos: [5, 6, 3], 
      state: 34
    }, 
    {
      pos: [6, 6, 3], 
      state: 2
    }, 
    {
      pos: [7, 6, 3], 
      state: 2
    }, 
    {
      pos: [8, 6, 3], 
      state: 2
    }, 
    {
      pos: [9, 6, 3], 
      state: 2
    }, 
    {
      pos: [10, 6, 3], 
      state: 2
    }, 
    {
      pos: [11, 6, 3], 
      state: 2
    }, 
    {
      pos: [12, 6, 3], 
      state: 2
    }, 
    {
      pos: [0, 6, 4], 
      state: 2
    }, 
    {
      pos: [1, 6, 4], 
      state: 30
    }, 
    {
      pos: [5, 6, 4], 
      state: 31
    }, 
    {
      pos: [6, 6, 4], 
      state: 2
    }, 
    {
      pos: [7, 6, 4], 
      state: 2
    }, 
    {
      pos: [8, 6, 4], 
      state: 2
    }, 
    {
      pos: [9, 6, 4], 
      state: 2
    }, 
    {
      pos: [10, 6, 4], 
      state: 2
    }, 
    {
      pos: [11, 6, 4], 
      state: 2
    }, 
    {
      pos: [12, 6, 4], 
      state: 2
    }, 
    {
      pos: [0, 6, 5], 
      state: 2
    }, 
    {
      pos: [1, 6, 5], 
      state: 30
    }, 
    {
      pos: [5, 6, 5], 
      state: 31
    }, 
    {
      pos: [6, 6, 5], 
      state: 2
    }, 
    {
      pos: [7, 6, 5], 
      state: 2
    }, 
    {
      pos: [8, 6, 5], 
      state: 2
    }, 
    {
      pos: [9, 6, 5], 
      state: 2
    }, 
    {
      pos: [10, 6, 5], 
      state: 2
    }, 
    {
      pos: [11, 6, 5], 
      state: 2
    }, 
    {
      pos: [12, 6, 5], 
      state: 2
    }, 
    {
      pos: [0, 6, 6], 
      state: 2
    }, 
    {
      pos: [1, 6, 6], 
      state: 30
    }, 
    {
      pos: [5, 6, 6], 
      state: 31
    }, 
    {
      pos: [6, 6, 6], 
      state: 2
    }, 
    {
      pos: [7, 6, 6], 
      state: 2
    }, 
    {
      pos: [8, 6, 6], 
      state: 2
    }, 
    {
      pos: [9, 6, 6], 
      state: 2
    }, 
    {
      pos: [10, 6, 6], 
      state: 2
    }, 
    {
      pos: [11, 6, 6], 
      state: 2
    }, 
    {
      pos: [12, 6, 6], 
      state: 2
    }, 
    {
      pos: [0, 6, 7], 
      state: 2
    }, 
    {
      pos: [1, 6, 7], 
      state: 35
    }, 
    {
      pos: [2, 6, 7], 
      state: 32
    }, 
    {
      pos: [3, 6, 7], 
      state: 32
    }, 
    {
      pos: [4, 6, 7], 
      state: 32
    }, 
    {
      pos: [5, 6, 7], 
      state: 36
    }, 
    {
      pos: [6, 6, 7], 
      state: 2
    }, 
    {
      pos: [7, 6, 7], 
      state: 2
    }, 
    {
      pos: [8, 6, 7], 
      state: 2
    }, 
    {
      pos: [9, 6, 7], 
      state: 2
    }, 
    {
      pos: [10, 6, 7], 
      state: 2
    }, 
    {
      pos: [11, 6, 7], 
      state: 2
    }, 
    {
      pos: [12, 6, 7], 
      state: 2
    }, 
    {
      pos: [0, 6, 8], 
      state: 2
    }, 
    {
      pos: [1, 6, 8], 
      state: 2
    }, 
    {
      pos: [2, 6, 8], 
      state: 2
    }, 
    {
      pos: [3, 6, 8], 
      state: 2
    }, 
    {
      pos: [4, 6, 8], 
      state: 2
    }, 
    {
      pos: [5, 6, 8], 
      state: 2
    }, 
    {
      pos: [6, 6, 8], 
      state: 2
    }, 
    {
      pos: [7, 6, 8], 
      state: 2
    }, 
    {
      pos: [8, 6, 8], 
      state: 2
    }, 
    {
      pos: [9, 6, 8], 
      state: 2
    }, 
    {
      pos: [10, 6, 8], 
      state: 2
    }, 
    {
      pos: [11, 6, 8], 
      state: 2
    }, 
    {
      pos: [12, 6, 8], 
      state: 2
    }, 
    {
      pos: [0, 6, 9], 
      state: 2
    }, 
    {
      pos: [1, 6, 9], 
      state: 2
    }, 
    {
      pos: [2, 6, 9], 
      state: 2
    }, 
    {
      pos: [3, 6, 9], 
      state: 2
    }, 
    {
      pos: [4, 6, 9], 
      state: 2
    }, 
    {
      pos: [5, 6, 9], 
      state: 2
    }, 
    {
      pos: [6, 6, 9], 
      state: 2
    }, 
    {
      pos: [7, 6, 9], 
      state: 2
    }, 
    {
      pos: [8, 6, 9], 
      state: 2
    }, 
    {
      pos: [9, 6, 9], 
      state: 2
    }, 
    {
      pos: [10, 6, 9], 
      state: 2
    }, 
    {
      pos: [11, 6, 9], 
      state: 2
    }, 
    {
      pos: [12, 6, 9], 
      state: 2
    }, 
    {
      pos: [0, 6, 10], 
      state: 2
    }, 
    {
      pos: [1, 6, 10], 
      state: 2
    }, 
    {
      pos: [2, 6, 10], 
      state: 2
    }, 
    {
      pos: [3, 6, 10], 
      state: 2
    }, 
    {
      pos: [4, 6, 10], 
      state: 2
    }, 
    {
      pos: [5, 6, 10], 
      state: 2
    }, 
    {
      pos: [6, 6, 10], 
      state: 2
    }, 
    {
      pos: [7, 6, 10], 
      state: 2
    }, 
    {
      pos: [8, 6, 10], 
      state: 2
    }, 
    {
      pos: [9, 6, 10], 
      state: 2
    }, 
    {
      pos: [10, 6, 10], 
      state: 2
    }, 
    {
      pos: [11, 6, 10], 
      state: 2
    }, 
    {
      pos: [12, 6, 10], 
      state: 2
    }, 
    {
      pos: [3, 7, 5], 
      state: 3
    }, 
    {
      pos: [0, 7, 0], 
      state: 2
    }, 
    {
      pos: [1, 7, 0], 
      state: 2
    }, 
    {
      pos: [2, 7, 0], 
      state: 2
    }, 
    {
      pos: [3, 7, 0], 
      state: 2
    }, 
    {
      pos: [4, 7, 0], 
      state: 2
    }, 
    {
      pos: [5, 7, 0], 
      state: 2
    }, 
    {
      pos: [6, 7, 0], 
      state: 2
    }, 
    {
      pos: [7, 7, 0], 
      state: 2
    }, 
    {
      pos: [8, 7, 0], 
      state: 2
    }, 
    {
      pos: [9, 7, 0], 
      state: 2
    }, 
    {
      pos: [10, 7, 0], 
      state: 2
    }, 
    {
      pos: [11, 7, 0], 
      state: 2
    }, 
    {
      pos: [12, 7, 0], 
      state: 2
    }, 
    {
      pos: [0, 7, 1], 
      state: 2
    }, 
    {
      pos: [1, 7, 1], 
      state: 2
    }, 
    {
      pos: [2, 7, 1], 
      state: 2
    }, 
    {
      pos: [3, 7, 1], 
      state: 2
    }, 
    {
      pos: [4, 7, 1], 
      state: 2
    }, 
    {
      pos: [5, 7, 1], 
      state: 2
    }, 
    {
      pos: [6, 7, 1], 
      state: 2
    }, 
    {
      pos: [7, 7, 1], 
      state: 2
    }, 
    {
      pos: [8, 7, 1], 
      state: 2
    }, 
    {
      pos: [9, 7, 1], 
      state: 2
    }, 
    {
      pos: [10, 7, 1], 
      state: 2
    }, 
    {
      pos: [11, 7, 1], 
      state: 2
    }, 
    {
      pos: [12, 7, 1], 
      state: 2
    }, 
    {
      pos: [0, 7, 2], 
      state: 2
    }, 
    {
      pos: [1, 7, 2], 
      state: 2
    }, 
    {
      pos: [2, 7, 2], 
      state: 2
    }, 
    {
      pos: [3, 7, 2], 
      state: 2
    }, 
    {
      pos: [4, 7, 2], 
      state: 2
    }, 
    {
      pos: [5, 7, 2], 
      state: 2
    }, 
    {
      pos: [6, 7, 2], 
      state: 2
    }, 
    {
      pos: [7, 7, 2], 
      state: 2
    }, 
    {
      pos: [8, 7, 2], 
      state: 2
    }, 
    {
      pos: [9, 7, 2], 
      state: 2
    }, 
    {
      pos: [10, 7, 2], 
      state: 2
    }, 
    {
      pos: [11, 7, 2], 
      state: 2
    }, 
    {
      pos: [12, 7, 2], 
      state: 2
    }, 
    {
      pos: [0, 7, 3], 
      state: 2
    }, 
    {
      pos: [1, 7, 3], 
      state: 2
    }, 
    {
      pos: [2, 7, 3], 
      state: 2
    }, 
    {
      pos: [3, 7, 3], 
      state: 2
    }, 
    {
      pos: [4, 7, 3], 
      state: 2
    }, 
    {
      pos: [5, 7, 3], 
      state: 2
    }, 
    {
      pos: [6, 7, 3], 
      state: 2
    }, 
    {
      pos: [7, 7, 3], 
      state: 2
    }, 
    {
      pos: [8, 7, 3], 
      state: 2
    }, 
    {
      pos: [9, 7, 3], 
      state: 2
    }, 
    {
      pos: [10, 7, 3], 
      state: 2
    }, 
    {
      pos: [11, 7, 3], 
      state: 2
    }, 
    {
      pos: [12, 7, 3], 
      state: 2
    }, 
    {
      pos: [0, 7, 4], 
      state: 2
    }, 
    {
      pos: [1, 7, 4], 
      state: 2
    }, 
    {
      pos: [2, 7, 4], 
      state: 37
    }, 
    {
      pos: [3, 7, 4], 
      state: 29
    }, 
    {
      pos: [4, 7, 4], 
      state: 34
    }, 
    {
      pos: [5, 7, 4], 
      state: 2
    }, 
    {
      pos: [6, 7, 4], 
      state: 2
    }, 
    {
      pos: [7, 7, 4], 
      state: 2
    }, 
    {
      pos: [8, 7, 4], 
      state: 2
    }, 
    {
      pos: [9, 7, 4], 
      state: 2
    }, 
    {
      pos: [10, 7, 4], 
      state: 2
    }, 
    {
      pos: [11, 7, 4], 
      state: 2
    }, 
    {
      pos: [12, 7, 4], 
      state: 2
    }, 
    {
      pos: [0, 7, 5], 
      state: 2
    }, 
    {
      pos: [1, 7, 5], 
      state: 2
    }, 
    {
      pos: [2, 7, 5], 
      state: 30
    }, 
    {
      pos: [4, 7, 5], 
      state: 31
    }, 
    {
      pos: [5, 7, 5], 
      state: 2
    }, 
    {
      pos: [6, 7, 5], 
      state: 2
    }, 
    {
      pos: [7, 7, 5], 
      state: 2
    }, 
    {
      pos: [8, 7, 5], 
      state: 2
    }, 
    {
      pos: [9, 7, 5], 
      state: 2
    }, 
    {
      pos: [10, 7, 5], 
      state: 2
    }, 
    {
      pos: [11, 7, 5], 
      state: 2
    }, 
    {
      pos: [12, 7, 5], 
      state: 2
    }, 
    {
      pos: [0, 7, 6], 
      state: 2
    }, 
    {
      pos: [1, 7, 6], 
      state: 2
    }, 
    {
      pos: [2, 7, 6], 
      state: 38
    }, 
    {
      pos: [3, 7, 6], 
      state: 32
    }, 
    {
      pos: [4, 7, 6], 
      state: 36
    }, 
    {
      pos: [5, 7, 6], 
      state: 2
    }, 
    {
      pos: [6, 7, 6], 
      state: 2
    }, 
    {
      pos: [7, 7, 6], 
      state: 2
    }, 
    {
      pos: [8, 7, 6], 
      state: 2
    }, 
    {
      pos: [9, 7, 6], 
      state: 2
    }, 
    {
      pos: [10, 7, 6], 
      state: 2
    }, 
    {
      pos: [11, 7, 6], 
      state: 2
    }, 
    {
      pos: [12, 7, 6], 
      state: 2
    }, 
    {
      pos: [0, 7, 7], 
      state: 2
    }, 
    {
      pos: [1, 7, 7], 
      state: 2
    }, 
    {
      pos: [2, 7, 7], 
      state: 2
    }, 
    {
      pos: [3, 7, 7], 
      state: 2
    }, 
    {
      pos: [4, 7, 7], 
      state: 2
    }, 
    {
      pos: [5, 7, 7], 
      state: 2
    }, 
    {
      pos: [6, 7, 7], 
      state: 2
    }, 
    {
      pos: [7, 7, 7], 
      state: 2
    }, 
    {
      pos: [8, 7, 7], 
      state: 2
    }, 
    {
      pos: [9, 7, 7], 
      state: 2
    }, 
    {
      pos: [10, 7, 7], 
      state: 2
    }, 
    {
      pos: [11, 7, 7], 
      state: 2
    }, 
    {
      pos: [12, 7, 7], 
      state: 2
    }, 
    {
      pos: [0, 7, 8], 
      state: 2
    }, 
    {
      pos: [1, 7, 8], 
      state: 2
    }, 
    {
      pos: [2, 7, 8], 
      state: 2
    }, 
    {
      pos: [3, 7, 8], 
      state: 2
    }, 
    {
      pos: [4, 7, 8], 
      state: 2
    }, 
    {
      pos: [5, 7, 8], 
      state: 2
    }, 
    {
      pos: [6, 7, 8], 
      state: 2
    }, 
    {
      pos: [7, 7, 8], 
      state: 2
    }, 
    {
      pos: [8, 7, 8], 
      state: 2
    }, 
    {
      pos: [9, 7, 8], 
      state: 2
    }, 
    {
      pos: [10, 7, 8], 
      state: 2
    }, 
    {
      pos: [11, 7, 8], 
      state: 2
    }, 
    {
      pos: [12, 7, 8], 
      state: 2
    }, 
    {
      pos: [0, 7, 9], 
      state: 2
    }, 
    {
      pos: [1, 7, 9], 
      state: 2
    }, 
    {
      pos: [2, 7, 9], 
      state: 2
    }, 
    {
      pos: [3, 7, 9], 
      state: 2
    }, 
    {
      pos: [4, 7, 9], 
      state: 2
    }, 
    {
      pos: [5, 7, 9], 
      state: 2
    }, 
    {
      pos: [6, 7, 9], 
      state: 2
    }, 
    {
      pos: [7, 7, 9], 
      state: 2
    }, 
    {
      pos: [8, 7, 9], 
      state: 2
    }, 
    {
      pos: [9, 7, 9], 
      state: 2
    }, 
    {
      pos: [10, 7, 9], 
      state: 2
    }, 
    {
      pos: [11, 7, 9], 
      state: 2
    }, 
    {
      pos: [12, 7, 9], 
      state: 2
    }, 
    {
      pos: [0, 7, 10], 
      state: 2
    }, 
    {
      pos: [1, 7, 10], 
      state: 2
    }, 
    {
      pos: [2, 7, 10], 
      state: 2
    }, 
    {
      pos: [3, 7, 10], 
      state: 2
    }, 
    {
      pos: [4, 7, 10], 
      state: 2
    }, 
    {
      pos: [5, 7, 10], 
      state: 2
    }, 
    {
      pos: [6, 7, 10], 
      state: 2
    }, 
    {
      pos: [7, 7, 10], 
      state: 2
    }, 
    {
      pos: [8, 7, 10], 
      state: 2
    }, 
    {
      pos: [9, 7, 10], 
      state: 2
    }, 
    {
      pos: [10, 7, 10], 
      state: 2
    }, 
    {
      pos: [11, 7, 10], 
      state: 2
    }, 
    {
      pos: [12, 7, 10], 
      state: 2
    }, 
    {
      pos: [0, 8, 0], 
      state: 2
    }, 
    {
      pos: [1, 8, 0], 
      state: 2
    }, 
    {
      pos: [2, 8, 0], 
      state: 2
    }, 
    {
      pos: [3, 8, 0], 
      state: 2
    }, 
    {
      pos: [4, 8, 0], 
      state: 2
    }, 
    {
      pos: [5, 8, 0], 
      state: 2
    }, 
    {
      pos: [6, 8, 0], 
      state: 2
    }, 
    {
      pos: [7, 8, 0], 
      state: 2
    }, 
    {
      pos: [8, 8, 0], 
      state: 2
    }, 
    {
      pos: [9, 8, 0], 
      state: 2
    }, 
    {
      pos: [10, 8, 0], 
      state: 2
    }, 
    {
      pos: [11, 8, 0], 
      state: 2
    }, 
    {
      pos: [12, 8, 0], 
      state: 2
    }, 
    {
      pos: [0, 8, 1], 
      state: 2
    }, 
    {
      pos: [1, 8, 1], 
      state: 2
    }, 
    {
      pos: [2, 8, 1], 
      state: 2
    }, 
    {
      pos: [3, 8, 1], 
      state: 2
    }, 
    {
      pos: [4, 8, 1], 
      state: 2
    }, 
    {
      pos: [5, 8, 1], 
      state: 2
    }, 
    {
      pos: [6, 8, 1], 
      state: 2
    }, 
    {
      pos: [7, 8, 1], 
      state: 2
    }, 
    {
      pos: [8, 8, 1], 
      state: 2
    }, 
    {
      pos: [9, 8, 1], 
      state: 2
    }, 
    {
      pos: [10, 8, 1], 
      state: 2
    }, 
    {
      pos: [11, 8, 1], 
      state: 2
    }, 
    {
      pos: [12, 8, 1], 
      state: 2
    }, 
    {
      pos: [0, 8, 2], 
      state: 2
    }, 
    {
      pos: [1, 8, 2], 
      state: 2
    }, 
    {
      pos: [2, 8, 2], 
      state: 2
    }, 
    {
      pos: [3, 8, 2], 
      state: 2
    }, 
    {
      pos: [4, 8, 2], 
      state: 2
    }, 
    {
      pos: [5, 8, 2], 
      state: 2
    }, 
    {
      pos: [6, 8, 2], 
      state: 2
    }, 
    {
      pos: [7, 8, 2], 
      state: 2
    }, 
    {
      pos: [8, 8, 2], 
      state: 2
    }, 
    {
      pos: [9, 8, 2], 
      state: 2
    }, 
    {
      pos: [10, 8, 2], 
      state: 2
    }, 
    {
      pos: [11, 8, 2], 
      state: 2
    }, 
    {
      pos: [12, 8, 2], 
      state: 2
    }, 
    {
      pos: [0, 8, 3], 
      state: 2
    }, 
    {
      pos: [1, 8, 3], 
      state: 2
    }, 
    {
      pos: [2, 8, 3], 
      state: 2
    }, 
    {
      pos: [3, 8, 3], 
      state: 2
    }, 
    {
      pos: [4, 8, 3], 
      state: 2
    }, 
    {
      pos: [5, 8, 3], 
      state: 2
    }, 
    {
      pos: [6, 8, 3], 
      state: 2
    }, 
    {
      pos: [7, 8, 3], 
      state: 2
    }, 
    {
      pos: [8, 8, 3], 
      state: 2
    }, 
    {
      pos: [9, 8, 3], 
      state: 2
    }, 
    {
      pos: [10, 8, 3], 
      state: 2
    }, 
    {
      pos: [11, 8, 3], 
      state: 2
    }, 
    {
      pos: [12, 8, 3], 
      state: 2
    }, 
    {
      pos: [0, 8, 4], 
      state: 2
    }, 
    {
      pos: [1, 8, 4], 
      state: 2
    }, 
    {
      pos: [2, 8, 4], 
      state: 2
    }, 
    {
      pos: [3, 8, 4], 
      state: 2
    }, 
    {
      pos: [4, 8, 4], 
      state: 2
    }, 
    {
      pos: [5, 8, 4], 
      state: 2
    }, 
    {
      pos: [6, 8, 4], 
      state: 2
    }, 
    {
      pos: [7, 8, 4], 
      state: 2
    }, 
    {
      pos: [8, 8, 4], 
      state: 2
    }, 
    {
      pos: [9, 8, 4], 
      state: 2
    }, 
    {
      pos: [10, 8, 4], 
      state: 2
    }, 
    {
      pos: [11, 8, 4], 
      state: 2
    }, 
    {
      pos: [12, 8, 4], 
      state: 2
    }, 
    {
      pos: [0, 8, 5], 
      state: 2
    }, 
    {
      pos: [1, 8, 5], 
      state: 2
    }, 
    {
      pos: [2, 8, 5], 
      state: 2
    }, 
    {
      pos: [3, 8, 5], 
      state: 2
    }, 
    {
      pos: [4, 8, 5], 
      state: 2
    }, 
    {
      pos: [5, 8, 5], 
      state: 2
    }, 
    {
      pos: [6, 8, 5], 
      state: 2
    }, 
    {
      pos: [7, 8, 5], 
      state: 2
    }, 
    {
      pos: [8, 8, 5], 
      state: 2
    }, 
    {
      pos: [9, 8, 5], 
      state: 2
    }, 
    {
      pos: [10, 8, 5], 
      state: 2
    }, 
    {
      pos: [11, 8, 5], 
      state: 2
    }, 
    {
      pos: [12, 8, 5], 
      state: 2
    }, 
    {
      pos: [0, 8, 6], 
      state: 2
    }, 
    {
      pos: [1, 8, 6], 
      state: 2
    }, 
    {
      pos: [2, 8, 6], 
      state: 2
    }, 
    {
      pos: [3, 8, 6], 
      state: 2
    }, 
    {
      pos: [4, 8, 6], 
      state: 2
    }, 
    {
      pos: [5, 8, 6], 
      state: 2
    }, 
    {
      pos: [6, 8, 6], 
      state: 2
    }, 
    {
      pos: [7, 8, 6], 
      state: 2
    }, 
    {
      pos: [8, 8, 6], 
      state: 2
    }, 
    {
      pos: [9, 8, 6], 
      state: 2
    }, 
    {
      pos: [10, 8, 6], 
      state: 2
    }, 
    {
      pos: [11, 8, 6], 
      state: 2
    }, 
    {
      pos: [12, 8, 6], 
      state: 2
    }, 
    {
      pos: [0, 8, 7], 
      state: 2
    }, 
    {
      pos: [1, 8, 7], 
      state: 2
    }, 
    {
      pos: [2, 8, 7], 
      state: 2
    }, 
    {
      pos: [3, 8, 7], 
      state: 2
    }, 
    {
      pos: [4, 8, 7], 
      state: 2
    }, 
    {
      pos: [5, 8, 7], 
      state: 2
    }, 
    {
      pos: [6, 8, 7], 
      state: 2
    }, 
    {
      pos: [7, 8, 7], 
      state: 2
    }, 
    {
      pos: [8, 8, 7], 
      state: 2
    }, 
    {
      pos: [9, 8, 7], 
      state: 2
    }, 
    {
      pos: [10, 8, 7], 
      state: 2
    }, 
    {
      pos: [11, 8, 7], 
      state: 2
    }, 
    {
      pos: [12, 8, 7], 
      state: 2
    }, 
    {
      pos: [0, 8, 8], 
      state: 2
    }, 
    {
      pos: [1, 8, 8], 
      state: 2
    }, 
    {
      pos: [2, 8, 8], 
      state: 2
    }, 
    {
      pos: [3, 8, 8], 
      state: 2
    }, 
    {
      pos: [4, 8, 8], 
      state: 2
    }, 
    {
      pos: [5, 8, 8], 
      state: 2
    }, 
    {
      pos: [6, 8, 8], 
      state: 2
    }, 
    {
      pos: [7, 8, 8], 
      state: 2
    }, 
    {
      pos: [8, 8, 8], 
      state: 2
    }, 
    {
      pos: [9, 8, 8], 
      state: 2
    }, 
    {
      pos: [10, 8, 8], 
      state: 2
    }, 
    {
      pos: [11, 8, 8], 
      state: 2
    }, 
    {
      pos: [12, 8, 8], 
      state: 2
    }, 
    {
      pos: [0, 8, 9], 
      state: 2
    }, 
    {
      pos: [1, 8, 9], 
      state: 2
    }, 
    {
      pos: [2, 8, 9], 
      state: 2
    }, 
    {
      pos: [3, 8, 9], 
      state: 2
    }, 
    {
      pos: [4, 8, 9], 
      state: 2
    }, 
    {
      pos: [5, 8, 9], 
      state: 2
    }, 
    {
      pos: [6, 8, 9], 
      state: 2
    }, 
    {
      pos: [7, 8, 9], 
      state: 2
    }, 
    {
      pos: [8, 8, 9], 
      state: 2
    }, 
    {
      pos: [9, 8, 9], 
      state: 2
    }, 
    {
      pos: [10, 8, 9], 
      state: 2
    }, 
    {
      pos: [11, 8, 9], 
      state: 2
    }, 
    {
      pos: [12, 8, 9], 
      state: 2
    }, 
    {
      pos: [0, 8, 10], 
      state: 2
    }, 
    {
      pos: [1, 8, 10], 
      state: 2
    }, 
    {
      pos: [2, 8, 10], 
      state: 2
    }, 
    {
      pos: [3, 8, 10], 
      state: 2
    }, 
    {
      pos: [4, 8, 10], 
      state: 2
    }, 
    {
      pos: [5, 8, 10], 
      state: 2
    }, 
    {
      pos: [6, 8, 10], 
      state: 2
    }, 
    {
      pos: [7, 8, 10], 
      state: 2
    }, 
    {
      pos: [8, 8, 10], 
      state: 2
    }, 
    {
      pos: [9, 8, 10], 
      state: 2
    }, 
    {
      pos: [10, 8, 10], 
      state: 2
    }, 
    {
      pos: [11, 8, 10], 
      state: 2
    }, 
    {
      pos: [12, 8, 10], 
      state: 2
    }, 
    {
      pos: [0, 9, 0], 
      state: 2
    }, 
    {
      pos: [1, 9, 0], 
      state: 2
    }, 
    {
      pos: [2, 9, 0], 
      state: 2
    }, 
    {
      pos: [3, 9, 0], 
      state: 2
    }, 
    {
      pos: [4, 9, 0], 
      state: 2
    }, 
    {
      pos: [5, 9, 0], 
      state: 2
    }, 
    {
      pos: [6, 9, 0], 
      state: 2
    }, 
    {
      pos: [7, 9, 0], 
      state: 2
    }, 
    {
      pos: [8, 9, 0], 
      state: 2
    }, 
    {
      pos: [9, 9, 0], 
      state: 2
    }, 
    {
      pos: [10, 9, 0], 
      state: 2
    }, 
    {
      pos: [11, 9, 0], 
      state: 2
    }, 
    {
      pos: [12, 9, 0], 
      state: 2
    }, 
    {
      pos: [0, 9, 1], 
      state: 2
    }, 
    {
      pos: [1, 9, 1], 
      state: 2
    }, 
    {
      pos: [2, 9, 1], 
      state: 2
    }, 
    {
      pos: [3, 9, 1], 
      state: 2
    }, 
    {
      pos: [4, 9, 1], 
      state: 2
    }, 
    {
      pos: [5, 9, 1], 
      state: 2
    }, 
    {
      pos: [6, 9, 1], 
      state: 2
    }, 
    {
      pos: [7, 9, 1], 
      state: 2
    }, 
    {
      pos: [8, 9, 1], 
      state: 2
    }, 
    {
      pos: [9, 9, 1], 
      state: 2
    }, 
    {
      pos: [10, 9, 1], 
      state: 2
    }, 
    {
      pos: [11, 9, 1], 
      state: 2
    }, 
    {
      pos: [12, 9, 1], 
      state: 2
    }, 
    {
      pos: [0, 9, 2], 
      state: 2
    }, 
    {
      pos: [1, 9, 2], 
      state: 2
    }, 
    {
      pos: [2, 9, 2], 
      state: 2
    }, 
    {
      pos: [3, 9, 2], 
      state: 2
    }, 
    {
      pos: [4, 9, 2], 
      state: 2
    }, 
    {
      pos: [5, 9, 2], 
      state: 2
    }, 
    {
      pos: [6, 9, 2], 
      state: 2
    }, 
    {
      pos: [7, 9, 2], 
      state: 2
    }, 
    {
      pos: [8, 9, 2], 
      state: 2
    }, 
    {
      pos: [9, 9, 2], 
      state: 2
    }, 
    {
      pos: [10, 9, 2], 
      state: 2
    }, 
    {
      pos: [11, 9, 2], 
      state: 2
    }, 
    {
      pos: [12, 9, 2], 
      state: 2
    }, 
    {
      pos: [0, 9, 3], 
      state: 2
    }, 
    {
      pos: [1, 9, 3], 
      state: 2
    }, 
    {
      pos: [2, 9, 3], 
      state: 2
    }, 
    {
      pos: [3, 9, 3], 
      state: 2
    }, 
    {
      pos: [4, 9, 3], 
      state: 2
    }, 
    {
      pos: [5, 9, 3], 
      state: 2
    }, 
    {
      pos: [6, 9, 3], 
      state: 2
    }, 
    {
      pos: [7, 9, 3], 
      state: 2
    }, 
    {
      pos: [8, 9, 3], 
      state: 2
    }, 
    {
      pos: [9, 9, 3], 
      state: 2
    }, 
    {
      pos: [10, 9, 3], 
      state: 2
    }, 
    {
      pos: [11, 9, 3], 
      state: 2
    }, 
    {
      pos: [12, 9, 3], 
      state: 2
    }, 
    {
      pos: [0, 9, 4], 
      state: 2
    }, 
    {
      pos: [1, 9, 4], 
      state: 2
    }, 
    {
      pos: [2, 9, 4], 
      state: 2
    }, 
    {
      pos: [3, 9, 4], 
      state: 2
    }, 
    {
      pos: [4, 9, 4], 
      state: 2
    }, 
    {
      pos: [5, 9, 4], 
      state: 2
    }, 
    {
      pos: [6, 9, 4], 
      state: 2
    }, 
    {
      pos: [7, 9, 4], 
      state: 2
    }, 
    {
      pos: [8, 9, 4], 
      state: 2
    }, 
    {
      pos: [9, 9, 4], 
      state: 2
    }, 
    {
      pos: [10, 9, 4], 
      state: 2
    }, 
    {
      pos: [11, 9, 4], 
      state: 2
    }, 
    {
      pos: [12, 9, 4], 
      state: 2
    }, 
    {
      pos: [0, 9, 5], 
      state: 2
    }, 
    {
      pos: [1, 9, 5], 
      state: 2
    }, 
    {
      pos: [2, 9, 5], 
      state: 2
    }, 
    {
      pos: [3, 9, 5], 
      state: 2
    }, 
    {
      pos: [4, 9, 5], 
      state: 2
    }, 
    {
      pos: [5, 9, 5], 
      state: 2
    }, 
    {
      pos: [6, 9, 5], 
      state: 2
    }, 
    {
      pos: [7, 9, 5], 
      state: 2
    }, 
    {
      pos: [8, 9, 5], 
      state: 2
    }, 
    {
      pos: [9, 9, 5], 
      state: 2
    }, 
    {
      pos: [10, 9, 5], 
      state: 2
    }, 
    {
      pos: [11, 9, 5], 
      state: 2
    }, 
    {
      pos: [12, 9, 5], 
      state: 2
    }, 
    {
      pos: [0, 9, 6], 
      state: 2
    }, 
    {
      pos: [1, 9, 6], 
      state: 2
    }, 
    {
      pos: [2, 9, 6], 
      state: 2
    }, 
    {
      pos: [3, 9, 6], 
      state: 2
    }, 
    {
      pos: [4, 9, 6], 
      state: 2
    }, 
    {
      pos: [5, 9, 6], 
      state: 2
    }, 
    {
      pos: [6, 9, 6], 
      state: 2
    }, 
    {
      pos: [7, 9, 6], 
      state: 2
    }, 
    {
      pos: [8, 9, 6], 
      state: 2
    }, 
    {
      pos: [9, 9, 6], 
      state: 2
    }, 
    {
      pos: [10, 9, 6], 
      state: 2
    }, 
    {
      pos: [11, 9, 6], 
      state: 2
    }, 
    {
      pos: [12, 9, 6], 
      state: 2
    }, 
    {
      pos: [0, 9, 7], 
      state: 2
    }, 
    {
      pos: [1, 9, 7], 
      state: 2
    }, 
    {
      pos: [2, 9, 7], 
      state: 2
    }, 
    {
      pos: [3, 9, 7], 
      state: 2
    }, 
    {
      pos: [4, 9, 7], 
      state: 2
    }, 
    {
      pos: [5, 9, 7], 
      state: 2
    }, 
    {
      pos: [6, 9, 7], 
      state: 2
    }, 
    {
      pos: [7, 9, 7], 
      state: 2
    }, 
    {
      pos: [8, 9, 7], 
      state: 2
    }, 
    {
      pos: [9, 9, 7], 
      state: 2
    }, 
    {
      pos: [10, 9, 7], 
      state: 2
    }, 
    {
      pos: [11, 9, 7], 
      state: 2
    }, 
    {
      pos: [12, 9, 7], 
      state: 2
    }, 
    {
      pos: [0, 9, 8], 
      state: 2
    }, 
    {
      pos: [1, 9, 8], 
      state: 2
    }, 
    {
      pos: [2, 9, 8], 
      state: 2
    }, 
    {
      pos: [3, 9, 8], 
      state: 2
    }, 
    {
      pos: [4, 9, 8], 
      state: 2
    }, 
    {
      pos: [5, 9, 8], 
      state: 2
    }, 
    {
      pos: [6, 9, 8], 
      state: 2
    }, 
    {
      pos: [7, 9, 8], 
      state: 2
    }, 
    {
      pos: [8, 9, 8], 
      state: 2
    }, 
    {
      pos: [9, 9, 8], 
      state: 2
    }, 
    {
      pos: [10, 9, 8], 
      state: 2
    }, 
    {
      pos: [11, 9, 8], 
      state: 2
    }, 
    {
      pos: [12, 9, 8], 
      state: 2
    }, 
    {
      pos: [0, 9, 9], 
      state: 2
    }, 
    {
      pos: [1, 9, 9], 
      state: 2
    }, 
    {
      pos: [2, 9, 9], 
      state: 2
    }, 
    {
      pos: [3, 9, 9], 
      state: 2
    }, 
    {
      pos: [4, 9, 9], 
      state: 2
    }, 
    {
      pos: [5, 9, 9], 
      state: 2
    }, 
    {
      pos: [6, 9, 9], 
      state: 2
    }, 
    {
      pos: [7, 9, 9], 
      state: 2
    }, 
    {
      pos: [8, 9, 9], 
      state: 2
    }, 
    {
      pos: [9, 9, 9], 
      state: 2
    }, 
    {
      pos: [10, 9, 9], 
      state: 2
    }, 
    {
      pos: [11, 9, 9], 
      state: 2
    }, 
    {
      pos: [12, 9, 9], 
      state: 2
    }, 
    {
      pos: [0, 9, 10], 
      state: 2
    }, 
    {
      pos: [1, 9, 10], 
      state: 2
    }, 
    {
      pos: [2, 9, 10], 
      state: 2
    }, 
    {
      pos: [3, 9, 10], 
      state: 2
    }, 
    {
      pos: [4, 9, 10], 
      state: 2
    }, 
    {
      pos: [5, 9, 10], 
      state: 2
    }, 
    {
      pos: [6, 9, 10], 
      state: 2
    }, 
    {
      pos: [7, 9, 10], 
      state: 2
    }, 
    {
      pos: [8, 9, 10], 
      state: 2
    }, 
    {
      pos: [9, 9, 10], 
      state: 2
    }, 
    {
      pos: [10, 9, 10], 
      state: 2
    }, 
    {
      pos: [11, 9, 10], 
      state: 2
    }, 
    {
      pos: [12, 9, 10], 
      state: 2
    }, 
    {
      pos: [0, 10, 0], 
      state: 2
    }, 
    {
      pos: [1, 10, 0], 
      state: 2
    }, 
    {
      pos: [2, 10, 0], 
      state: 2
    }, 
    {
      pos: [3, 10, 0], 
      state: 2
    }, 
    {
      pos: [4, 10, 0], 
      state: 2
    }, 
    {
      pos: [5, 10, 0], 
      state: 2
    }, 
    {
      pos: [6, 10, 0], 
      state: 2
    }, 
    {
      pos: [7, 10, 0], 
      state: 2
    }, 
    {
      pos: [8, 10, 0], 
      state: 2
    }, 
    {
      pos: [9, 10, 0], 
      state: 2
    }, 
    {
      pos: [10, 10, 0], 
      state: 2
    }, 
    {
      pos: [11, 10, 0], 
      state: 2
    }, 
    {
      pos: [12, 10, 0], 
      state: 2
    }, 
    {
      pos: [0, 10, 1], 
      state: 2
    }, 
    {
      pos: [1, 10, 1], 
      state: 2
    }, 
    {
      pos: [2, 10, 1], 
      state: 2
    }, 
    {
      pos: [3, 10, 1], 
      state: 2
    }, 
    {
      pos: [4, 10, 1], 
      state: 2
    }, 
    {
      pos: [5, 10, 1], 
      state: 2
    }, 
    {
      pos: [6, 10, 1], 
      state: 2
    }, 
    {
      pos: [7, 10, 1], 
      state: 2
    }, 
    {
      pos: [8, 10, 1], 
      state: 2
    }, 
    {
      pos: [9, 10, 1], 
      state: 2
    }, 
    {
      pos: [10, 10, 1], 
      state: 2
    }, 
    {
      pos: [11, 10, 1], 
      state: 2
    }, 
    {
      pos: [12, 10, 1], 
      state: 2
    }, 
    {
      pos: [0, 10, 2], 
      state: 2
    }, 
    {
      pos: [1, 10, 2], 
      state: 2
    }, 
    {
      pos: [2, 10, 2], 
      state: 2
    }, 
    {
      pos: [3, 10, 2], 
      state: 2
    }, 
    {
      pos: [4, 10, 2], 
      state: 2
    }, 
    {
      pos: [5, 10, 2], 
      state: 2
    }, 
    {
      pos: [6, 10, 2], 
      state: 2
    }, 
    {
      pos: [7, 10, 2], 
      state: 2
    }, 
    {
      pos: [8, 10, 2], 
      state: 2
    }, 
    {
      pos: [9, 10, 2], 
      state: 2
    }, 
    {
      pos: [10, 10, 2], 
      state: 2
    }, 
    {
      pos: [11, 10, 2], 
      state: 2
    }, 
    {
      pos: [12, 10, 2], 
      state: 2
    }, 
    {
      pos: [0, 10, 3], 
      state: 2
    }, 
    {
      pos: [1, 10, 3], 
      state: 2
    }, 
    {
      pos: [2, 10, 3], 
      state: 2
    }, 
    {
      pos: [3, 10, 3], 
      state: 2
    }, 
    {
      pos: [4, 10, 3], 
      state: 2
    }, 
    {
      pos: [5, 10, 3], 
      state: 2
    }, 
    {
      pos: [6, 10, 3], 
      state: 2
    }, 
    {
      pos: [7, 10, 3], 
      state: 2
    }, 
    {
      pos: [8, 10, 3], 
      state: 2
    }, 
    {
      pos: [9, 10, 3], 
      state: 2
    }, 
    {
      pos: [10, 10, 3], 
      state: 2
    }, 
    {
      pos: [11, 10, 3], 
      state: 2
    }, 
    {
      pos: [12, 10, 3], 
      state: 2
    }, 
    {
      pos: [0, 10, 4], 
      state: 2
    }, 
    {
      pos: [1, 10, 4], 
      state: 2
    }, 
    {
      pos: [2, 10, 4], 
      state: 2
    }, 
    {
      pos: [3, 10, 4], 
      state: 2
    }, 
    {
      pos: [4, 10, 4], 
      state: 2
    }, 
    {
      pos: [5, 10, 4], 
      state: 2
    }, 
    {
      pos: [6, 10, 4], 
      state: 2
    }, 
    {
      pos: [7, 10, 4], 
      state: 2
    }, 
    {
      pos: [8, 10, 4], 
      state: 2
    }, 
    {
      pos: [9, 10, 4], 
      state: 2
    }, 
    {
      pos: [10, 10, 4], 
      state: 2
    }, 
    {
      pos: [11, 10, 4], 
      state: 2
    }, 
    {
      pos: [12, 10, 4], 
      state: 2
    }, 
    {
      pos: [0, 10, 5], 
      state: 2
    }, 
    {
      pos: [1, 10, 5], 
      state: 2
    }, 
    {
      pos: [2, 10, 5], 
      state: 2
    }, 
    {
      pos: [3, 10, 5], 
      state: 2
    }, 
    {
      pos: [4, 10, 5], 
      state: 2
    }, 
    {
      pos: [5, 10, 5], 
      state: 2
    }, 
    {
      pos: [6, 10, 5], 
      state: 2
    }, 
    {
      pos: [7, 10, 5], 
      state: 2
    }, 
    {
      pos: [8, 10, 5], 
      state: 2
    }, 
    {
      pos: [9, 10, 5], 
      state: 2
    }, 
    {
      pos: [10, 10, 5], 
      state: 2
    }, 
    {
      pos: [11, 10, 5], 
      state: 2
    }, 
    {
      pos: [12, 10, 5], 
      state: 2
    }, 
    {
      pos: [0, 10, 6], 
      state: 2
    }, 
    {
      pos: [1, 10, 6], 
      state: 2
    }, 
    {
      pos: [2, 10, 6], 
      state: 2
    }, 
    {
      pos: [3, 10, 6], 
      state: 2
    }, 
    {
      pos: [4, 10, 6], 
      state: 2
    }, 
    {
      pos: [5, 10, 6], 
      state: 2
    }, 
    {
      pos: [6, 10, 6], 
      state: 2
    }, 
    {
      pos: [7, 10, 6], 
      state: 2
    }, 
    {
      pos: [8, 10, 6], 
      state: 2
    }, 
    {
      pos: [9, 10, 6], 
      state: 2
    }, 
    {
      pos: [10, 10, 6], 
      state: 2
    }, 
    {
      pos: [11, 10, 6], 
      state: 2
    }, 
    {
      pos: [12, 10, 6], 
      state: 2
    }, 
    {
      pos: [0, 10, 7], 
      state: 2
    }, 
    {
      pos: [1, 10, 7], 
      state: 2
    }, 
    {
      pos: [2, 10, 7], 
      state: 2
    }, 
    {
      pos: [3, 10, 7], 
      state: 2
    }, 
    {
      pos: [4, 10, 7], 
      state: 2
    }, 
    {
      pos: [5, 10, 7], 
      state: 2
    }, 
    {
      pos: [6, 10, 7], 
      state: 2
    }, 
    {
      pos: [7, 10, 7], 
      state: 2
    }, 
    {
      pos: [8, 10, 7], 
      state: 2
    }, 
    {
      pos: [9, 10, 7], 
      state: 2
    }, 
    {
      pos: [10, 10, 7], 
      state: 2
    }, 
    {
      pos: [11, 10, 7], 
      state: 2
    }, 
    {
      pos: [12, 10, 7], 
      state: 2
    }, 
    {
      pos: [0, 10, 8], 
      state: 2
    }, 
    {
      pos: [1, 10, 8], 
      state: 2
    }, 
    {
      pos: [2, 10, 8], 
      state: 2
    }, 
    {
      pos: [3, 10, 8], 
      state: 2
    }, 
    {
      pos: [4, 10, 8], 
      state: 2
    }, 
    {
      pos: [5, 10, 8], 
      state: 2
    }, 
    {
      pos: [6, 10, 8], 
      state: 2
    }, 
    {
      pos: [7, 10, 8], 
      state: 2
    }, 
    {
      pos: [8, 10, 8], 
      state: 2
    }, 
    {
      pos: [9, 10, 8], 
      state: 2
    }, 
    {
      pos: [10, 10, 8], 
      state: 2
    }, 
    {
      pos: [11, 10, 8], 
      state: 2
    }, 
    {
      pos: [12, 10, 8], 
      state: 2
    }, 
    {
      pos: [0, 10, 9], 
      state: 2
    }, 
    {
      pos: [1, 10, 9], 
      state: 2
    }, 
    {
      pos: [2, 10, 9], 
      state: 2
    }, 
    {
      pos: [3, 10, 9], 
      state: 2
    }, 
    {
      pos: [4, 10, 9], 
      state: 2
    }, 
    {
      pos: [5, 10, 9], 
      state: 2
    }, 
    {
      pos: [6, 10, 9], 
      state: 2
    }, 
    {
      pos: [7, 10, 9], 
      state: 2
    }, 
    {
      pos: [8, 10, 9], 
      state: 2
    }, 
    {
      pos: [9, 10, 9], 
      state: 2
    }, 
    {
      pos: [10, 10, 9], 
      state: 2
    }, 
    {
      pos: [11, 10, 9], 
      state: 2
    }, 
    {
      pos: [12, 10, 9], 
      state: 2
    }, 
    {
      pos: [0, 10, 10], 
      state: 2
    }, 
    {
      pos: [1, 10, 10], 
      state: 2
    }, 
    {
      pos: [2, 10, 10], 
      state: 2
    }, 
    {
      pos: [3, 10, 10], 
      state: 2
    }, 
    {
      pos: [4, 10, 10], 
      state: 2
    }, 
    {
      pos: [5, 10, 10], 
      state: 2
    }, 
    {
      pos: [6, 10, 10], 
      state: 2
    }, 
    {
      pos: [7, 10, 10], 
      state: 2
    }, 
    {
      pos: [8, 10, 10], 
      state: 2
    }, 
    {
      pos: [9, 10, 10], 
      state: 2
    }, 
    {
      pos: [10, 10, 10], 
      state: 2
    }, 
    {
      pos: [11, 10, 10], 
      state: 2
    }, 
    {
      pos: [12, 10, 10], 
      state: 2
    }, 
    {
      pos: [0, 11, 0], 
      state: 2
    }, 
    {
      pos: [1, 11, 0], 
      state: 2
    }, 
    {
      pos: [2, 11, 0], 
      state: 2
    }, 
    {
      pos: [3, 11, 0], 
      state: 2
    }, 
    {
      pos: [4, 11, 0], 
      state: 2
    }, 
    {
      pos: [5, 11, 0], 
      state: 2
    }, 
    {
      pos: [6, 11, 0], 
      state: 2
    }, 
    {
      pos: [7, 11, 0], 
      state: 2
    }, 
    {
      pos: [8, 11, 0], 
      state: 2
    }, 
    {
      pos: [9, 11, 0], 
      state: 2
    }, 
    {
      pos: [10, 11, 0], 
      state: 2
    }, 
    {
      pos: [11, 11, 0], 
      state: 2
    }, 
    {
      pos: [12, 11, 0], 
      state: 2
    }, 
    {
      pos: [0, 11, 1], 
      state: 2
    }, 
    {
      pos: [1, 11, 1], 
      state: 2
    }, 
    {
      pos: [2, 11, 1], 
      state: 2
    }, 
    {
      pos: [3, 11, 1], 
      state: 2
    }, 
    {
      pos: [4, 11, 1], 
      state: 2
    }, 
    {
      pos: [5, 11, 1], 
      state: 2
    }, 
    {
      pos: [6, 11, 1], 
      state: 2
    }, 
    {
      pos: [7, 11, 1], 
      state: 2
    }, 
    {
      pos: [8, 11, 1], 
      state: 2
    }, 
    {
      pos: [9, 11, 1], 
      state: 2
    }, 
    {
      pos: [10, 11, 1], 
      state: 2
    }, 
    {
      pos: [11, 11, 1], 
      state: 2
    }, 
    {
      pos: [12, 11, 1], 
      state: 2
    }, 
    {
      pos: [0, 11, 2], 
      state: 2
    }, 
    {
      pos: [1, 11, 2], 
      state: 2
    }, 
    {
      pos: [2, 11, 2], 
      state: 2
    }, 
    {
      pos: [3, 11, 2], 
      state: 2
    }, 
    {
      pos: [4, 11, 2], 
      state: 2
    }, 
    {
      pos: [5, 11, 2], 
      state: 2
    }, 
    {
      pos: [6, 11, 2], 
      state: 2
    }, 
    {
      pos: [7, 11, 2], 
      state: 2
    }, 
    {
      pos: [8, 11, 2], 
      state: 2
    }, 
    {
      pos: [9, 11, 2], 
      state: 2
    }, 
    {
      pos: [10, 11, 2], 
      state: 2
    }, 
    {
      pos: [11, 11, 2], 
      state: 2
    }, 
    {
      pos: [12, 11, 2], 
      state: 2
    }, 
    {
      pos: [0, 11, 3], 
      state: 2
    }, 
    {
      pos: [1, 11, 3], 
      state: 2
    }, 
    {
      pos: [2, 11, 3], 
      state: 2
    }, 
    {
      pos: [3, 11, 3], 
      state: 2
    }, 
    {
      pos: [4, 11, 3], 
      state: 2
    }, 
    {
      pos: [5, 11, 3], 
      state: 2
    }, 
    {
      pos: [6, 11, 3], 
      state: 2
    }, 
    {
      pos: [7, 11, 3], 
      state: 2
    }, 
    {
      pos: [8, 11, 3], 
      state: 2
    }, 
    {
      pos: [9, 11, 3], 
      state: 2
    }, 
    {
      pos: [10, 11, 3], 
      state: 2
    }, 
    {
      pos: [11, 11, 3], 
      state: 2
    }, 
    {
      pos: [12, 11, 3], 
      state: 2
    }, 
    {
      pos: [0, 11, 4], 
      state: 2
    }, 
    {
      pos: [1, 11, 4], 
      state: 2
    }, 
    {
      pos: [2, 11, 4], 
      state: 2
    }, 
    {
      pos: [3, 11, 4], 
      state: 2
    }, 
    {
      pos: [4, 11, 4], 
      state: 2
    }, 
    {
      pos: [5, 11, 4], 
      state: 2
    }, 
    {
      pos: [6, 11, 4], 
      state: 2
    }, 
    {
      pos: [7, 11, 4], 
      state: 2
    }, 
    {
      pos: [8, 11, 4], 
      state: 2
    }, 
    {
      pos: [9, 11, 4], 
      state: 2
    }, 
    {
      pos: [10, 11, 4], 
      state: 2
    }, 
    {
      pos: [11, 11, 4], 
      state: 2
    }, 
    {
      pos: [12, 11, 4], 
      state: 2
    }, 
    {
      pos: [0, 11, 5], 
      state: 2
    }, 
    {
      pos: [1, 11, 5], 
      state: 2
    }, 
    {
      pos: [2, 11, 5], 
      state: 2
    }, 
    {
      pos: [3, 11, 5], 
      state: 2
    }, 
    {
      pos: [4, 11, 5], 
      state: 2
    }, 
    {
      pos: [5, 11, 5], 
      state: 2
    }, 
    {
      pos: [6, 11, 5], 
      state: 2
    }, 
    {
      pos: [7, 11, 5], 
      state: 2
    }, 
    {
      pos: [8, 11, 5], 
      state: 2
    }, 
    {
      pos: [9, 11, 5], 
      state: 2
    }, 
    {
      pos: [10, 11, 5], 
      state: 2
    }, 
    {
      pos: [11, 11, 5], 
      state: 2
    }, 
    {
      pos: [12, 11, 5], 
      state: 2
    }, 
    {
      pos: [0, 11, 6], 
      state: 2
    }, 
    {
      pos: [1, 11, 6], 
      state: 2
    }, 
    {
      pos: [2, 11, 6], 
      state: 2
    }, 
    {
      pos: [3, 11, 6], 
      state: 2
    }, 
    {
      pos: [4, 11, 6], 
      state: 2
    }, 
    {
      pos: [5, 11, 6], 
      state: 2
    }, 
    {
      pos: [6, 11, 6], 
      state: 2
    }, 
    {
      pos: [7, 11, 6], 
      state: 2
    }, 
    {
      pos: [8, 11, 6], 
      state: 2
    }, 
    {
      pos: [9, 11, 6], 
      state: 2
    }, 
    {
      pos: [10, 11, 6], 
      state: 2
    }, 
    {
      pos: [11, 11, 6], 
      state: 2
    }, 
    {
      pos: [12, 11, 6], 
      state: 2
    }, 
    {
      pos: [0, 11, 7], 
      state: 2
    }, 
    {
      pos: [1, 11, 7], 
      state: 2
    }, 
    {
      pos: [2, 11, 7], 
      state: 2
    }, 
    {
      pos: [3, 11, 7], 
      state: 2
    }, 
    {
      pos: [4, 11, 7], 
      state: 2
    }, 
    {
      pos: [5, 11, 7], 
      state: 2
    }, 
    {
      pos: [6, 11, 7], 
      state: 2
    }, 
    {
      pos: [7, 11, 7], 
      state: 2
    }, 
    {
      pos: [8, 11, 7], 
      state: 2
    }, 
    {
      pos: [9, 11, 7], 
      state: 2
    }, 
    {
      pos: [10, 11, 7], 
      state: 2
    }, 
    {
      pos: [11, 11, 7], 
      state: 2
    }, 
    {
      pos: [12, 11, 7], 
      state: 2
    }, 
    {
      pos: [0, 11, 8], 
      state: 2
    }, 
    {
      pos: [1, 11, 8], 
      state: 2
    }, 
    {
      pos: [2, 11, 8], 
      state: 2
    }, 
    {
      pos: [3, 11, 8], 
      state: 2
    }, 
    {
      pos: [4, 11, 8], 
      state: 2
    }, 
    {
      pos: [5, 11, 8], 
      state: 2
    }, 
    {
      pos: [6, 11, 8], 
      state: 2
    }, 
    {
      pos: [7, 11, 8], 
      state: 2
    }, 
    {
      pos: [8, 11, 8], 
      state: 2
    }, 
    {
      pos: [9, 11, 8], 
      state: 2
    }, 
    {
      pos: [10, 11, 8], 
      state: 2
    }, 
    {
      pos: [11, 11, 8], 
      state: 2
    }, 
    {
      pos: [12, 11, 8], 
      state: 2
    }, 
    {
      pos: [0, 11, 9], 
      state: 2
    }, 
    {
      pos: [1, 11, 9], 
      state: 2
    }, 
    {
      pos: [2, 11, 9], 
      state: 2
    }, 
    {
      pos: [3, 11, 9], 
      state: 2
    }, 
    {
      pos: [4, 11, 9], 
      state: 2
    }, 
    {
      pos: [5, 11, 9], 
      state: 2
    }, 
    {
      pos: [6, 11, 9], 
      state: 2
    }, 
    {
      pos: [7, 11, 9], 
      state: 2
    }, 
    {
      pos: [8, 11, 9], 
      state: 2
    }, 
    {
      pos: [9, 11, 9], 
      state: 2
    }, 
    {
      pos: [10, 11, 9], 
      state: 2
    }, 
    {
      pos: [11, 11, 9], 
      state: 2
    }, 
    {
      pos: [12, 11, 9], 
      state: 2
    }, 
    {
      pos: [0, 11, 10], 
      state: 2
    }, 
    {
      pos: [1, 11, 10], 
      state: 2
    }, 
    {
      pos: [2, 11, 10], 
      state: 2
    }, 
    {
      pos: [3, 11, 10], 
      state: 2
    }, 
    {
      pos: [4, 11, 10], 
      state: 2
    }, 
    {
      pos: [5, 11, 10], 
      state: 2
    }, 
    {
      pos: [6, 11, 10], 
      state: 2
    }, 
    {
      pos: [7, 11, 10], 
      state: 2
    }, 
    {
      pos: [8, 11, 10], 
      state: 2
    }, 
    {
      pos: [9, 11, 10], 
      state: 2
    }, 
    {
      pos: [10, 11, 10], 
      state: 2
    }, 
    {
      pos: [11, 11, 10], 
      state: 2
    }, 
    {
      pos: [12, 11, 10], 
      state: 2
    }, 
    {
      pos: [0, 12, 0], 
      state: 2
    }, 
    {
      pos: [1, 12, 0], 
      state: 2
    }, 
    {
      pos: [2, 12, 0], 
      state: 2
    }, 
    {
      pos: [3, 12, 0], 
      state: 2
    }, 
    {
      pos: [4, 12, 0], 
      state: 2
    }, 
    {
      pos: [5, 12, 0], 
      state: 2
    }, 
    {
      pos: [6, 12, 0], 
      state: 2
    }, 
    {
      pos: [7, 12, 0], 
      state: 2
    }, 
    {
      pos: [8, 12, 0], 
      state: 2
    }, 
    {
      pos: [9, 12, 0], 
      state: 2
    }, 
    {
      pos: [10, 12, 0], 
      state: 2
    }, 
    {
      pos: [11, 12, 0], 
      state: 2
    }, 
    {
      pos: [12, 12, 0], 
      state: 2
    }, 
    {
      pos: [0, 12, 1], 
      state: 2
    }, 
    {
      pos: [1, 12, 1], 
      state: 2
    }, 
    {
      pos: [2, 12, 1], 
      state: 2
    }, 
    {
      pos: [3, 12, 1], 
      state: 2
    }, 
    {
      pos: [4, 12, 1], 
      state: 2
    }, 
    {
      pos: [5, 12, 1], 
      state: 2
    }, 
    {
      pos: [6, 12, 1], 
      state: 2
    }, 
    {
      pos: [7, 12, 1], 
      state: 2
    }, 
    {
      pos: [8, 12, 1], 
      state: 2
    }, 
    {
      pos: [9, 12, 1], 
      state: 2
    }, 
    {
      pos: [10, 12, 1], 
      state: 2
    }, 
    {
      pos: [11, 12, 1], 
      state: 2
    }, 
    {
      pos: [12, 12, 1], 
      state: 2
    }, 
    {
      pos: [0, 12, 2], 
      state: 2
    }, 
    {
      pos: [1, 12, 2], 
      state: 2
    }, 
    {
      pos: [2, 12, 2], 
      state: 2
    }, 
    {
      pos: [3, 12, 2], 
      state: 2
    }, 
    {
      pos: [4, 12, 2], 
      state: 2
    }, 
    {
      pos: [5, 12, 2], 
      state: 2
    }, 
    {
      pos: [6, 12, 2], 
      state: 2
    }, 
    {
      pos: [7, 12, 2], 
      state: 2
    }, 
    {
      pos: [8, 12, 2], 
      state: 2
    }, 
    {
      pos: [9, 12, 2], 
      state: 2
    }, 
    {
      pos: [10, 12, 2], 
      state: 2
    }, 
    {
      pos: [11, 12, 2], 
      state: 2
    }, 
    {
      pos: [12, 12, 2], 
      state: 2
    }, 
    {
      pos: [0, 12, 3], 
      state: 2
    }, 
    {
      pos: [1, 12, 3], 
      state: 2
    }, 
    {
      pos: [2, 12, 3], 
      state: 2
    }, 
    {
      pos: [3, 12, 3], 
      state: 2
    }, 
    {
      pos: [4, 12, 3], 
      state: 2
    }, 
    {
      pos: [5, 12, 3], 
      state: 2
    }, 
    {
      pos: [6, 12, 3], 
      state: 2
    }, 
    {
      pos: [7, 12, 3], 
      state: 2
    }, 
    {
      pos: [8, 12, 3], 
      state: 2
    }, 
    {
      pos: [9, 12, 3], 
      state: 2
    }, 
    {
      pos: [10, 12, 3], 
      state: 2
    }, 
    {
      pos: [11, 12, 3], 
      state: 2
    }, 
    {
      pos: [12, 12, 3], 
      state: 2
    }, 
    {
      pos: [0, 12, 4], 
      state: 2
    }, 
    {
      pos: [1, 12, 4], 
      state: 2
    }, 
    {
      pos: [2, 12, 4], 
      state: 2
    }, 
    {
      pos: [3, 12, 4], 
      state: 2
    }, 
    {
      pos: [4, 12, 4], 
      state: 2
    }, 
    {
      pos: [5, 12, 4], 
      state: 2
    }, 
    {
      pos: [6, 12, 4], 
      state: 2
    }, 
    {
      pos: [7, 12, 4], 
      state: 2
    }, 
    {
      pos: [8, 12, 4], 
      state: 2
    }, 
    {
      pos: [9, 12, 4], 
      state: 2
    }, 
    {
      pos: [10, 12, 4], 
      state: 2
    }, 
    {
      pos: [11, 12, 4], 
      state: 2
    }, 
    {
      pos: [12, 12, 4], 
      state: 2
    }, 
    {
      pos: [0, 12, 5], 
      state: 2
    }, 
    {
      pos: [1, 12, 5], 
      state: 2
    }, 
    {
      pos: [2, 12, 5], 
      state: 2
    }, 
    {
      pos: [3, 12, 5], 
      state: 2
    }, 
    {
      pos: [4, 12, 5], 
      state: 2
    }, 
    {
      pos: [5, 12, 5], 
      state: 2
    }, 
    {
      pos: [6, 12, 5], 
      state: 2
    }, 
    {
      pos: [7, 12, 5], 
      state: 2
    }, 
    {
      pos: [8, 12, 5], 
      state: 2
    }, 
    {
      pos: [9, 12, 5], 
      state: 2
    }, 
    {
      pos: [10, 12, 5], 
      state: 2
    }, 
    {
      pos: [11, 12, 5], 
      state: 2
    }, 
    {
      pos: [12, 12, 5], 
      state: 2
    }, 
    {
      pos: [0, 12, 6], 
      state: 2
    }, 
    {
      pos: [1, 12, 6], 
      state: 2
    }, 
    {
      pos: [2, 12, 6], 
      state: 2
    }, 
    {
      pos: [3, 12, 6], 
      state: 2
    }, 
    {
      pos: [4, 12, 6], 
      state: 2
    }, 
    {
      pos: [5, 12, 6], 
      state: 2
    }, 
    {
      pos: [6, 12, 6], 
      state: 2
    }, 
    {
      pos: [7, 12, 6], 
      state: 2
    }, 
    {
      pos: [8, 12, 6], 
      state: 2
    }, 
    {
      pos: [9, 12, 6], 
      state: 2
    }, 
    {
      pos: [10, 12, 6], 
      state: 2
    }, 
    {
      pos: [11, 12, 6], 
      state: 2
    }, 
    {
      pos: [12, 12, 6], 
      state: 2
    }, 
    {
      pos: [0, 12, 7], 
      state: 2
    }, 
    {
      pos: [1, 12, 7], 
      state: 2
    }, 
    {
      pos: [2, 12, 7], 
      state: 2
    }, 
    {
      pos: [3, 12, 7], 
      state: 2
    }, 
    {
      pos: [4, 12, 7], 
      state: 2
    }, 
    {
      pos: [5, 12, 7], 
      state: 2
    }, 
    {
      pos: [6, 12, 7], 
      state: 2
    }, 
    {
      pos: [7, 12, 7], 
      state: 2
    }, 
    {
      pos: [8, 12, 7], 
      state: 2
    }, 
    {
      pos: [9, 12, 7], 
      state: 2
    }, 
    {
      pos: [10, 12, 7], 
      state: 2
    }, 
    {
      pos: [11, 12, 7], 
      state: 2
    }, 
    {
      pos: [12, 12, 7], 
      state: 2
    }, 
    {
      pos: [0, 12, 8], 
      state: 2
    }, 
    {
      pos: [1, 12, 8], 
      state: 2
    }, 
    {
      pos: [2, 12, 8], 
      state: 2
    }, 
    {
      pos: [3, 12, 8], 
      state: 2
    }, 
    {
      pos: [4, 12, 8], 
      state: 2
    }, 
    {
      pos: [5, 12, 8], 
      state: 2
    }, 
    {
      pos: [6, 12, 8], 
      state: 2
    }, 
    {
      pos: [7, 12, 8], 
      state: 2
    }, 
    {
      pos: [8, 12, 8], 
      state: 2
    }, 
    {
      pos: [9, 12, 8], 
      state: 2
    }, 
    {
      pos: [10, 12, 8], 
      state: 2
    }, 
    {
      pos: [11, 12, 8], 
      state: 2
    }, 
    {
      pos: [12, 12, 8], 
      state: 2
    }, 
    {
      pos: [0, 12, 9], 
      state: 2
    }, 
    {
      pos: [1, 12, 9], 
      state: 2
    }, 
    {
      pos: [2, 12, 9], 
      state: 2
    }, 
    {
      pos: [3, 12, 9], 
      state: 2
    }, 
    {
      pos: [4, 12, 9], 
      state: 2
    }, 
    {
      pos: [5, 12, 9], 
      state: 2
    }, 
    {
      pos: [6, 12, 9], 
      state: 2
    }, 
    {
      pos: [7, 12, 9], 
      state: 2
    }, 
    {
      pos: [8, 12, 9], 
      state: 2
    }, 
    {
      pos: [9, 12, 9], 
      state: 2
    }, 
    {
      pos: [10, 12, 9], 
      state: 2
    }, 
    {
      pos: [11, 12, 9], 
      state: 2
    }, 
    {
      pos: [12, 12, 9], 
      state: 2
    }, 
    {
      pos: [0, 12, 10], 
      state: 2
    }, 
    {
      pos: [1, 12, 10], 
      state: 2
    }, 
    {
      pos: [2, 12, 10], 
      state: 2
    }, 
    {
      pos: [3, 12, 10], 
      state: 2
    }, 
    {
      pos: [4, 12, 10], 
      state: 2
    }, 
    {
      pos: [5, 12, 10], 
      state: 2
    }, 
    {
      pos: [6, 12, 10], 
      state: 2
    }, 
    {
      pos: [7, 12, 10], 
      state: 2
    }, 
    {
      pos: [8, 12, 10], 
      state: 2
    }, 
    {
      pos: [9, 12, 10], 
      state: 2
    }, 
    {
      pos: [10, 12, 10], 
      state: 2
    }, 
    {
      pos: [11, 12, 10], 
      state: 2
    }, 
    {
      pos: [12, 12, 10], 
      state: 2
    }, 
    {
      pos: [0, 13, 0], 
      state: 2
    }, 
    {
      pos: [1, 13, 0], 
      state: 2
    }, 
    {
      pos: [2, 13, 0], 
      state: 2
    }, 
    {
      pos: [3, 13, 0], 
      state: 2
    }, 
    {
      pos: [4, 13, 0], 
      state: 2
    }, 
    {
      pos: [5, 13, 0], 
      state: 2
    }, 
    {
      pos: [6, 13, 0], 
      state: 2
    }, 
    {
      pos: [7, 13, 0], 
      state: 2
    }, 
    {
      pos: [8, 13, 0], 
      state: 2
    }, 
    {
      pos: [9, 13, 0], 
      state: 2
    }, 
    {
      pos: [10, 13, 0], 
      state: 2
    }, 
    {
      pos: [11, 13, 0], 
      state: 2
    }, 
    {
      pos: [12, 13, 0], 
      state: 2
    }, 
    {
      pos: [0, 13, 1], 
      state: 2
    }, 
    {
      pos: [1, 13, 1], 
      state: 2
    }, 
    {
      pos: [2, 13, 1], 
      state: 2
    }, 
    {
      pos: [3, 13, 1], 
      state: 2
    }, 
    {
      pos: [4, 13, 1], 
      state: 2
    }, 
    {
      pos: [5, 13, 1], 
      state: 2
    }, 
    {
      pos: [6, 13, 1], 
      state: 2
    }, 
    {
      pos: [7, 13, 1], 
      state: 2
    }, 
    {
      pos: [8, 13, 1], 
      state: 2
    }, 
    {
      pos: [9, 13, 1], 
      state: 2
    }, 
    {
      pos: [10, 13, 1], 
      state: 2
    }, 
    {
      pos: [11, 13, 1], 
      state: 2
    }, 
    {
      pos: [12, 13, 1], 
      state: 2
    }, 
    {
      pos: [0, 13, 2], 
      state: 2
    }, 
    {
      pos: [1, 13, 2], 
