{
  size: [13, 10, 9], 
  entities: [], 
  blocks: [
    {
      pos: [0, 0, 0], 
      state: 0
    }, 
    {
      pos: [1, 0, 0], 
      state: 0
    }, 
    {
      pos: [2, 0, 0], 
      state: 0
    }, 
    {
      pos: [3, 0, 0], 
      state: 0
    }, 
    {
      pos: [4, 0, 0], 
      state: 0
    }, 
    {
      pos: [5, 0, 0], 
      state: 0
    }, 
    {
      pos: [6, 0, 0], 
      state: 0
    }, 
    {
      pos: [7, 0, 0], 
      state: 0
    }, 
    {
      pos: [8, 0, 0], 
      state: 0
    }, 
    {
      pos: [9, 0, 0], 
      state: 0
    }, 
    {
      pos: [10, 0, 0], 
      state: 0
    }, 
    {
      pos: [11, 0, 0], 
      state: 0
    }, 
    {
      pos: [12, 0, 0], 
      state: 0
    }, 
    {
      pos: [0, 0, 1], 
      state: 0
    }, 
    {
      pos: [1, 0, 1], 
      state: 0
    }, 
    {
      pos: [2, 0, 1], 
      state: 0
    }, 
    {
      pos: [3, 0, 1], 
      state: 0
    }, 
    {
      pos: [4, 0, 1], 
      state: 0
    }, 
    {
      pos: [5, 0, 1], 
      state: 0
    }, 
    {
      pos: [6, 0, 1], 
      state: 0
    }, 
    {
      pos: [7, 0, 1], 
      state: 0
    }, 
    {
      pos: [8, 0, 1], 
      state: 0
    }, 
    {
      pos: [9, 0, 1], 
      state: 0
    }, 
    {
      pos: [10, 0, 1], 
      state: 0
    }, 
    {
      pos: [11, 0, 1], 
      state: 0
    }, 
    {
      pos: [12, 0, 1], 
      state: 0
    }, 
    {
      pos: [0, 0, 2], 
      state: 0
    }, 
    {
      pos: [1, 0, 2], 
      state: 0
    }, 
    {
      pos: [2, 0, 2], 
      state: 0
    }, 
    {
      pos: [3, 0, 2], 
      state: 0
    }, 
    {
      pos: [4, 0, 2], 
      state: 0
    }, 
    {
      pos: [5, 0, 2], 
      state: 0
    }, 
    {
      pos: [6, 0, 2], 
      state: 0
    }, 
    {
      pos: [7, 0, 2], 
      state: 0
    }, 
    {
      pos: [8, 0, 2], 
      state: 0
    }, 
    {
      pos: [9, 0, 2], 
      state: 0
    }, 
    {
      pos: [11, 0, 2], 
      state: 0
    }, 
    {
      pos: [12, 0, 2], 
      state: 0
    }, 
    {
      pos: [0, 0, 3], 
      state: 1
    }, 
    {
      pos: [1, 0, 3], 
      state: 1
    }, 
    {
      pos: [2, 0, 3], 
      state: 0
    }, 
    {
      pos: [3, 0, 3], 
      state: 0
    }, 
    {
      pos: [4, 0, 3], 
      state: 0
    }, 
    {
      pos: [5, 0, 3], 
      state: 0
    }, 
    {
      pos: [6, 0, 3], 
      state: 0
    }, 
    {
      pos: [7, 0, 3], 
      state: 0
    }, 
    {
      pos: [8, 0, 3], 
      state: 0
    }, 
    {
      pos: [9, 0, 3], 
      state: 0
    }, 
    {
      pos: [10, 0, 3], 
      state: 0
    }, 
    {
      pos: [11, 0, 3], 
      state: 0
    }, 
    {
      pos: [12, 0, 3], 
      state: 0
    }, 
    {
      pos: [0, 0, 4], 
      state: 1
    }, 
    {
      pos: [1, 0, 4], 
      state: 1
    }, 
    {
      pos: [2, 0, 4], 
      state: 0
    }, 
    {
      pos: [3, 0, 4], 
      state: 0
    }, 
    {
      pos: [4, 0, 4], 
      state: 0
    }, 
    {
      pos: [5, 0, 4], 
      state: 0
    }, 
    {
      pos: [6, 0, 4], 
      state: 0
    }, 
    {
      pos: [7, 0, 4], 
      state: 0
    }, 
    {
      pos: [8, 0, 4], 
      state: 0
    }, 
    {
      pos: [9, 0, 4], 
      state: 0
    }, 
    {
      pos: [10, 0, 4], 
      state: 0
    }, 
    {
      pos: [11, 0, 4], 
      state: 0
    }, 
    {
      pos: [12, 0, 4], 
      state: 0
    }, 
    {
      pos: [0, 0, 5], 
      state: 1
    }, 
    {
      pos: [1, 0, 5], 
      state: 1
    }, 
    {
      pos: [2, 0, 5], 
      state: 0
    }, 
    {
      pos: [3, 0, 5], 
      state: 0
    }, 
    {
      pos: [4, 0, 5], 
      state: 0
    }, 
    {
      pos: [5, 0, 5], 
      state: 0
    }, 
    {
      pos: [6, 0, 5], 
      state: 0
    }, 
    {
      pos: [7, 0, 5], 
      state: 0
    }, 
    {
      pos: [8, 0, 5], 
      state: 0
    }, 
    {
      pos: [9, 0, 5], 
      state: 0
    }, 
    {
      pos: [10, 0, 5], 
      state: 0
    }, 
    {
      pos: [11, 0, 5], 
      state: 0
    }, 
    {
      pos: [12, 0, 5], 
      state: 0
    }, 
    {
      pos: [0, 0, 6], 
      state: 0
    }, 
    {
      pos: [1, 0, 6], 
      state: 0
    }, 
    {
      pos: [2, 0, 6], 
      state: 0
    }, 
    {
      pos: [3, 0, 6], 
      state: 0
    }, 
    {
      pos: [4, 0, 6], 
      state: 0
    }, 
    {
      pos: [5, 0, 6], 
      state: 0
    }, 
    {
      pos: [6, 0, 6], 
      state: 0
    }, 
    {
      pos: [7, 0, 6], 
      state: 0
    }, 
    {
      pos: [8, 0, 6], 
      state: 0
    }, 
    {
      pos: [9, 0, 6], 
      state: 0
    }, 
    {
      pos: [10, 0, 6], 
      state: 1
    }, 
    {
      pos: [11, 0, 6], 
      state: 0
    }, 
    {
      pos: [12, 0, 6], 
      state: 0
    }, 
    {
      pos: [4, 0, 7], 
      state: 0
    }, 
    {
      pos: [5, 0, 7], 
      state: 0
    }, 
    {
      pos: [6, 0, 7], 
      state: 0
    }, 
    {
      pos: [7, 0, 7], 
      state: 0
    }, 
    {
      pos: [8, 0, 7], 
      state: 0
    }, 
    {
      pos: [9, 0, 7], 
      state: 0
    }, 
    {
      pos: [10, 0, 7], 
      state: 0
    }, 
    {
      pos: [11, 0, 7], 
      state: 0
    }, 
    {
      pos: [12, 0, 7], 
      state: 0
    }, 
    {
      pos: [3, 0, 8], 
      state: 0
    }, 
    {
      pos: [4, 0, 8], 
      state: 0
    }, 
    {
      pos: [5, 0, 8], 
      state: 0
    }, 
    {
      pos: [6, 0, 8], 
      state: 0
    }, 
    {
      pos: [7, 0, 8], 
      state: 0
    }, 
    {
      pos: [8, 0, 8], 
      state: 0
    }, 
    {
      pos: [9, 0, 8], 
      state: 0
    }, 
    {
      pos: [10, 0, 8], 
      state: 0
    }, 
    {
      pos: [11, 0, 8], 
      state: 0
    }, 
    {
      pos: [12, 0, 8], 
      state: 0
    }, 
    {
      nbt: {
        final_state: "minecraft:grass_block", 
        name: "minecraft:bottom", 
        pool: "minecraft:village/common/butcher_animals", 
        id: "minecraft:jigsaw", 
        target: "minecraft:bottom"
      }, 
      pos: [10, 0, 2], 
      state: 2
    }, 
    {
      pos: [0, 0, 7], 
      state: 3
    }, 
    {
      pos: [1, 0, 7], 
      state: 4
    }, 
    {
      pos: [2, 0, 7], 
      state: 4
    }, 
    {
      pos: [3, 0, 7], 
      state: 4
    }, 
    {
      pos: [0, 0, 8], 
      state: 4
    }, 
    {
      pos: [1, 0, 8], 
      state: 3
    }, 
    {
      pos: [2, 0, 8], 
      state: 3
    }, 
    {
      pos: [1, 1, 3], 
      state: 5
    }, 
    {
      pos: [1, 1, 4], 
      state: 5
    }, 
    {
      pos: [1, 1, 5], 
      state: 5
    }, 
    {
      nbt: {
        final_state: "minecraft:acacia_stairs[facing=east]", 
        name: "minecraft:building_entrance", 
        pool: "minecraft:empty", 
        id: "minecraft:jigsaw", 
        target: "minecraft:building_entrance"
      }, 
      pos: [0, 1, 4], 
      state: 6
    }, 
    {
      pos: [1, 1, 0], 
      state: 3
    }, 
    {
      pos: [4, 1, 0], 
      state: 7
    }, 
    {
      pos: [5, 1, 0], 
      state: 8
    }, 
    {
      pos: [6, 1, 0], 
      state: 8
    }, 
    {
      pos: [7, 1, 0], 
      state: 8
    }, 
    {
      pos: [8, 1, 0], 
      state: 8
    }, 
    {
      pos: [9, 1, 0], 
      state: 8
    }, 
    {
      pos: [10, 1, 0], 
      state: 8
    }, 
    {
      pos: [11, 1, 0], 
      state: 8
    }, 
    {
      pos: [12, 1, 0], 
      state: 9
    }, 
    {
      pos: [0, 1, 1], 
      state: 3
    }, 
    {
      pos: [2, 1, 1], 
      state: 3
    }, 
    {
      pos: [3, 1, 1], 
      state: 3
    }, 
    {
      pos: [4, 1, 1], 
      state: 10
    }, 
    {
      pos: [5, 1, 1], 
      state: 3
    }, 
    {
      pos: [7, 1, 1], 
      state: 3
    }, 
    {
      pos: [8, 1, 1], 
      state: 3
    }, 
    {
      pos: [9, 1, 1], 
      state: 3
    }, 
    {
      pos: [10, 1, 1], 
      state: 3
    }, 
    {
      pos: [12, 1, 1], 
      state: 10
    }, 
    {
      pos: [0, 1, 2], 
      state: 3
    }, 
    {
      pos: [1, 1, 2], 
      state: 7
    }, 
    {
      pos: [2, 1, 2], 
      state: 8
    }, 
    {
      pos: [3, 1, 2], 
      state: 8
    }, 
    {
      pos: [4, 1, 2], 
      state: 11
    }, 
    {
      pos: [7, 1, 2], 
      state: 12
    }, 
    {
      pos: [11, 1, 2], 
      state: 3
    }, 
    {
      pos: [12, 1, 2], 
      state: 10
    }, 
    {
      pos: [0, 1, 3], 
      state: 13
    }, 
    {
      pos: [5, 1, 3], 
      state: 3
    }, 
    {
      pos: [9, 1, 3], 
      state: 3
    }, 
    {
      pos: [10, 1, 3], 
      state: 3
    }, 
    {
      pos: [11, 1, 3], 
      state: 3
    }, 
    {
      pos: [12, 1, 3], 
      state: 10
    }, 
    {
      pos: [4, 1, 4], 
      state: 12
    }, 
    {
      pos: [5, 1, 4], 
      state: 14
    }, 
    {
      pos: [7, 1, 4], 
      state: 12
    }, 
    {
      pos: [8, 1, 4], 
      state: 3
    }, 
    {
      pos: [10, 1, 4], 
      state: 3
    }, 
    {
      pos: [12, 1, 4], 
      state: 10
    }, 
    {
      pos: [0, 1, 5], 
      state: 13
    }, 
    {
      pos: [6, 1, 5], 
      state: 3
    }, 
    {
      pos: [8, 1, 5], 
      state: 12
    }, 
    {
      pos: [9, 1, 5], 
      state: 3
    }, 
    {
      pos: [10, 1, 5], 
      state: 3
    }, 
    {
      pos: [11, 1, 5], 
      state: 3
    }, 
    {
      pos: [12, 1, 5], 
      state: 10
    }, 
    {
      pos: [0, 1, 6], 
      state: 3
    }, 
    {
      pos: [1, 1, 6], 
      state: 15
    }, 
    {
      pos: [2, 1, 6], 
      state: 8
    }, 
    {
      pos: [3, 1, 6], 
      state: 8
    }, 
    {
      pos: [4, 1, 6], 
      state: 9
    }, 
    {
      pos: [5, 1, 6], 
      state: 3
    }, 
    {
      pos: [6, 1, 6], 
      state: 3
    }, 
    {
      pos: [7, 1, 6], 
      state: 12
    }, 
    {
      pos: [9, 1, 6], 
      state: 16
    }, 
    {
      pos: [10, 1, 6], 
      state: 17
    }, 
    {
      pos: [11, 1, 6], 
      state: 3
    }, 
    {
      pos: [12, 1, 6], 
      state: 10
    }, 
    {
      pos: [1, 1, 7], 
      state: 4
    }, 
    {
      pos: [2, 1, 7], 
      state: 4
    }, 
    {
      pos: [3, 1, 7], 
      state: 4
    }, 
    {
      pos: [4, 1, 7], 
      state: 10
    }, 
    {
      pos: [5, 1, 7], 
      state: 3
    }, 
    {
      pos: [6, 1, 7], 
      state: 3
    }, 
    {
      pos: [8, 1, 7], 
      state: 3
    }, 
    {
      pos: [9, 1, 7], 
      state: 3
    }, 
    {
      pos: [10, 1, 7], 
      state: 3
    }, 
    {
      pos: [12, 1, 7], 
      state: 10
    }, 
    {
      pos: [4, 1, 8], 
      state: 15
    }, 
    {
      pos: [5, 1, 8], 
      state: 8
    }, 
    {
      pos: [6, 1, 8], 
      state: 8
    }, 
    {
      pos: [7, 1, 8], 
      state: 8
    }, 
    {
      pos: [8, 1, 8], 
      state: 8
    }, 
    {
      pos: [9, 1, 8], 
      state: 8
    }, 
    {
      pos: [10, 1, 8], 
      state: 8
    }, 
    {
      pos: [11, 1, 8], 
      state: 8
    }, 
    {
      pos: [12, 1, 8], 
      state: 11
    }, 
    {
      pos: [12, 2, 0], 
      state: 14
    }, 
    {
      pos: [4, 2, 2], 
      state: 12
    }, 
    {
      pos: [7, 2, 2], 
      state: 12
    }, 
    {
      pos: [1, 2, 3], 
      state: 13
    }, 
    {
      pos: [2, 2, 3], 
      state: 16
    }, 
    {
      pos: [1, 2, 4], 
      state: 13
    }, 
    {
      pos: [2, 2, 4], 
      state: 16
    }, 
    {
      pos: [4, 2, 4], 
      state: 12
    }, 
    {
      pos: [7, 2, 4], 
      state: 12
    }, 
    {
      pos: [1, 2, 5], 
      state: 13
    }, 
    {
      pos: [2, 2, 5], 
      state: 16
    }, 
    {
      pos: [8, 2, 5], 
      state: 12
    }, 
    {
      pos: [4, 2, 6], 
      state: 12
    }, 
    {
      pos: [7, 2, 6], 
      state: 12
    }, 
    {
      pos: [8, 2, 6], 
      state: 16
    }, 
    {
      pos: [9, 2, 6], 
      state: 17
    }, 
    {
      pos: [4, 2, 8], 
      state: 14
    }, 
    {
      pos: [12, 2, 8], 
      state: 14
    }, 
    {
      pos: [4, 3, 2], 
      state: 5
    }, 
    {
      pos: [5, 3, 2], 
      state: 5
    }, 
    {
      pos: [6, 3, 2], 
      state: 5
    }, 
    {
      pos: [7, 3, 2], 
      state: 5
    }, 
    {
      pos: [3, 3, 3], 
      state: 5
    }, 
    {
      pos: [4, 3, 3], 
      state: 5
    }, 
    {
      pos: [5, 3, 3], 
      state: 5
    }, 
    {
      pos: [6, 3, 3], 
      state: 5
    }, 
    {
      pos: [7, 3, 3], 
      state: 5
    }, 
    {
      pos: [3, 3, 4], 
      state: 5
    }, 
    {
      pos: [4, 3, 4], 
      state: 18
    }, 
    {
      pos: [5, 3, 4], 
      state: 5
    }, 
    {
      pos: [6, 3, 4], 
      state: 5
    }, 
    {
      pos: [7, 3, 4], 
      state: 18
    }, 
    {
      pos: [3, 3, 5], 
      state: 5
    }, 
    {
      pos: [4, 3, 5], 
      state: 5
    }, 
    {
      pos: [5, 3, 5], 
      state: 5
    }, 
    {
      pos: [6, 3, 5], 
      state: 5
    }, 
    {
      pos: [7, 3, 5], 
      state: 5
    }, 
    {
      pos: [4, 3, 6], 
      state: 5
    }, 
    {
      pos: [5, 3, 6], 
      state: 5
    }, 
    {
      pos: [6, 3, 6], 
      state: 5
    }, 
    {
      pos: [7, 3, 6], 
      state: 5
    }, 
    {
      pos: [2, 3, 3], 
      state: 13
    }, 
    {
      pos: [8, 3, 3], 
      state: 16
    }, 
    {
      pos: [2, 3, 4], 
      state: 13
    }, 
    {
      pos: [8, 3, 4], 
      state: 16
    }, 
    {
      pos: [2, 3, 5], 
      state: 13
    }, 
    {
      pos: [8, 3, 5], 
      state: 19
    }, 
    {
      pos: [4, 4, 2], 
      state: 20
    }, 
    {
      pos: [5, 4, 2], 
      state: 18
    }, 
    {
      pos: [6, 4, 2], 
      state: 18
    }, 
    {
      pos: [7, 4, 2], 
      state: 20
    }, 
    {
      pos: [4, 4, 3], 
      state: 20
    }, 
    {
      pos: [7, 4, 3], 
      state: 20
    }, 
    {
      pos: [4, 4, 5], 
      state: 20
    }, 
    {
      pos: [7, 4, 5], 
      state: 20
    }, 
    {
      pos: [4, 4, 6], 
      state: 20
    }, 
    {
      pos: [5, 4, 6], 
      state: 18
    }, 
    {
      pos: [6, 4, 6], 
      state: 18
    }, 
    {
      pos: [7, 4, 6], 
      state: 20
    }, 
    {
      nbt: {
        CookTime: 0s, 
        BurnTime: 0s, 
        Items: [], 
        id: "minecraft:smoker", 
        CookTimeTotal: 0s, 
        RecipesUsed: {}
      }, 
      pos: [8, 4, 3], 
      state: 21
    }, 
    {
      nbt: {
        LootTable: "minecraft:chests/village/village_butcher", 
        Items: [], 
        id: "minecraft:chest", 
        Lock: "", 
        LootTableSeed: 0L
      }, 
      pos: [6, 4, 5], 
      state: 22
    }, 
    {
      pos: [5, 4, 3], 
      state: 19
    }, 
    {
      pos: [6, 4, 3], 
      state: 19
    }, 
    {
      pos: [4, 4, 4], 
      state: 23
    }, 
    {
      pos: [7, 4, 4], 
      state: 24
    }, 
    {
      pos: [4, 5, 2], 
      state: 20
    }, 
    {
      pos: [7, 5, 2], 
      state: 20
    }, 
    {
      pos: [4, 5, 3], 
      state: 20
    }, 
    {
      pos: [7, 5, 3], 
      state: 20
    }, 
    {
      pos: [4, 5, 5], 
      state: 20
    }, 
    {
      pos: [7, 5, 5], 
      state: 20
    }, 
    {
      pos: [4, 5, 6], 
      state: 20
    }, 
    {
      pos: [7, 5, 6], 
      state: 20
    }, 
    {
      pos: [5, 5, 2], 
      state: 25
    }, 
    {
      pos: [6, 5, 2], 
      state: 25
    }, 
    {
      pos: [3, 5, 3], 
      state: 26
    }, 
    {
      pos: [4, 5, 4], 
      state: 27
    }, 
    {
      pos: [7, 5, 4], 
      state: 28
    }, 
    {
      pos: [3, 5, 5], 
      state: 26
    }, 
    {
      pos: [5, 5, 6], 
      state: 25
    }, 
    {
      pos: [6, 5, 6], 
      state: 25
    }, 
    {
      pos: [4, 6, 2], 
      state: 20
    }, 
    {
      pos: [5, 6, 2], 
      state: 18
    }, 
    {
      pos: [6, 6, 2], 
      state: 18
    }, 
    {
      pos: [7, 6, 2], 
      state: 20
    }, 
    {
      pos: [4, 6, 3], 
      state: 20
    }, 
    {
      pos: [7, 6, 3], 
      state: 20
    }, 
    {
      pos: [4, 6, 4], 
      state: 29
    }, 
    {
      pos: [7, 6, 4], 
      state: 29
    }, 
    {
      pos: [4, 6, 5], 
      state: 20
    }, 
    {
      pos: [7, 6, 5], 
      state: 20
    }, 
    {
      pos: [4, 6, 6], 
      state: 20
    }, 
    {
      pos: [5, 6, 6], 
      state: 18
    }, 
    {
      pos: [6, 6, 6], 
      state: 18
    }, 
    {
      pos: [7, 6, 6], 
      state: 20
    }, 
    {
      pos: [6, 6, 4], 
      state: 26
    }, 
    {
      pos: [8, 6, 4], 
      state: 30
    }, 
    {
      pos: [4, 7, 2], 
      state: 5
    }, 
    {
      pos: [5, 7, 2], 
      state: 5
    }, 
    {
      pos: [6, 7, 2], 
      state: 5
    }, 
    {
      pos: [7, 7, 2], 
      state: 5
    }, 
    {
      pos: [4, 7, 3], 
      state: 5
    }, 
    {
      pos: [7, 7, 3], 
      state: 5
    }, 
    {
      pos: [4, 7, 4], 
      state: 5
    }, 
    {
      pos: [7, 7, 4], 
      state: 5
    }, 
    {
      pos: [4, 7, 5], 
      state: 5
    }, 
    {
      pos: [7, 7, 5], 
      state: 5
    }, 
    {
      pos: [4, 7, 6], 
      state: 5
    }, 
    {
      pos: [5, 7, 6], 
      state: 5
    }, 
    {
      pos: [6, 7, 6], 
      state: 5
    }, 
    {
      pos: [7, 7, 6], 
      state: 5
    }, 
    {
      pos: [4, 7, 1], 
      state: 31
    }, 
    {
      pos: [5, 7, 1], 
      state: 31
    }, 
    {
      pos: [6, 7, 1], 
      state: 31
    }, 
    {
      pos: [7, 7, 1], 
      state: 31
    }, 
    {
      pos: [3, 7, 2], 
      state: 13
    }, 
    {
      pos: [8, 7, 2], 
      state: 17
    }, 
    {
      pos: [3, 7, 3], 
      state: 13
    }, 
    {
      pos: [8, 7, 3], 
      state: 17
    }, 
    {
      pos: [3, 7, 4], 
      state: 13
    }, 
    {
      pos: [8, 7, 4], 
      state: 17
    }, 
    {
      pos: [3, 7, 5], 
      state: 13
    }, 
    {
      pos: [8, 7, 5], 
      state: 17
    }, 
    {
      pos: [3, 7, 6], 
      state: 13
    }, 
    {
      pos: [8, 7, 6], 
      state: 17
    }, 
    {
      pos: [4, 7, 7], 
      state: 19
    }, 
    {
      pos: [5, 7, 7], 
      state: 19
    }, 
    {
      pos: [6, 7, 7], 
      state: 19
    }, 
    {
      pos: [7, 7, 7], 
      state: 19
    }, 
    {
      pos: [5, 8, 3], 
      state: 5
    }, 
    {
      pos: [6, 8, 3], 
      state: 5
    }, 
    {
      pos: [5, 8, 4], 
      state: 5
    }, 
    {
      pos: [6, 8, 4], 
      state: 5
    }, 
    {
      pos: [5, 8, 5], 
      state: 5
    }, 
    {
      pos: [6, 8, 5], 
      state: 5
    }, 
    {
      pos: [4, 8, 2], 
      state: 32
    }, 
    {
      pos: [5, 8, 2], 
      state: 31
    }, 
    {
      pos: [6, 8, 2], 
      state: 31
    }, 
    {
      pos: [7, 8, 2], 
      state: 33
    }, 
    {
      pos: [4, 8, 3], 
      state: 13
    }, 
    {
      pos: [7, 8, 3], 
      state: 17
    }, 
    {
      pos: [4, 8, 4], 
      state: 13
    }, 
    {
      pos: [7, 8, 4], 
      state: 17
    }, 
    {
      pos: [4, 8, 5], 
      state: 13
    }, 
    {
      pos: [7, 8, 5], 
      state: 17
    }, 
    {
      pos: [4, 8, 6], 
      state: 34
    }, 
    {
      pos: [5, 8, 6], 
      state: 19
    }, 
    {
      pos: [6, 8, 6], 
      state: 19
    }, 
    {
      pos: [7, 8, 6], 
      state: 35
    }
  ], 
  palette: [
    {
      Properties: {
        snowy: "false"
      }, 
      Name: "minecraft:grass_block"
    }, 
    {
      Name: "minecraft:dirt"
    }, 
    {
      Properties: {
        orientation: "up_north"
      }, 
      Name: "minecraft:jigsaw"
    }, 
    {
      Name: "minecraft:grass"
    }, 
    {
      Name: "minecraft:air"
    }, 
    {
      Name: "minecraft:acacia_planks"
    }, 
    {
      Properties: {
        orientation: "west_up"
      }, 
      Name: "minecraft:jigsaw"
    }, 
    {
      Properties: {
        east: "true", 
        waterlogged: "false", 
        south: "true", 
        north: "false", 
        west: "false"
      }, 
      Name: "minecraft:acacia_fence"
    }, 
    {
      Properties: {
        east: "true", 
        waterlogged: "false", 
        south: "false", 
        north: "false", 
        west: "true"
      }, 
      Name: "minecraft:acacia_fence"
    }, 
    {
      Properties: {
        east: "false", 
        waterlogged: "false", 
        south: "true", 
        north: "false", 
        west: "true"
      }, 
      Name: "minecraft:acacia_fence"
    }, 
    {
      Properties: {
        east: "false", 
        waterlogged: "false", 
        south: "true", 
        north: "true", 
        west: "false"
      }, 
      Name: "minecraft:acacia_fence"
    }, 
    {
      Properties: {
        east: "false", 
        waterlogged: "false", 
        south: "false", 
        north: "true", 
        west: "true"
      }, 
      Name: "minecraft:acacia_fence"
    }, 
    {
      Properties: {
        east: "false", 
        waterlogged: "false", 
        south: "false", 
        north: "false", 
        west: "false"
      }, 
      Name: "minecraft:acacia_fence"
    }, 
    {
      Properties: {
        half: "bottom", 
        waterlogged: "false", 
        shape: "straight", 
        facing: "east"
      }, 
      Name: "minecraft:acacia_stairs"
    }, 
    {
      Name: "minecraft:torch"
    }, 
    {
      Properties: {
        east: "true", 
        waterlogged: "false", 
        south: "false", 
        north: "true", 
        west: "false"
      }, 
      Name: "minecraft:acacia_fence"
    }, 
    {
      Properties: {
        waterlogged: "false", 
        type: "top"
      }, 
      Name: "minecraft:acacia_slab"
    }, 
    {
      Properties: {
        half: "bottom", 
        waterlogged: "false", 
        shape: "straight", 
        facing: "west"
      }, 
      Name: "minecraft:acacia_stairs"
    }, 
    {
      Properties: {
        axis: "x"
      }, 
      Name: "minecraft:acacia_wood"
    }, 
    {
      Properties: {
        half: "bottom", 
        waterlogged: "false", 
        shape: "straight", 
        facing: "north"
      }, 
      Name: "minecraft:acacia_stairs"
    }, 
    {
      Properties: {
        axis: "y"
      }, 
      Name: "minecraft:acacia_wood"
    }, 
    {
      Properties: {
        lit: "false", 
        facing: "east"
      }, 
      Name: "minecraft:smoker"
    }, 
    {
      Properties: {
        waterlogged: "false", 
        facing: "north", 
        type: "single"
      }, 
      Name: "minecraft:chest"
    }, 
    {
      Properties: {
        hinge: "left", 
        half: "lower", 
        powered: "false", 
        facing: "west", 
        open: "false"
      }, 
      Name: "minecraft:acacia_door"
    }, 
    {
      Properties: {
        hinge: "right", 
        half: "lower", 
        powered: "false", 
        facing: "east", 
        open: "false"
      }, 
      Name: "minecraft:acacia_door"
    }, 
    {
      Properties: {
        east: "true", 
        waterlogged: "false", 
        south: "false", 
        north: "false", 
        west: "true"
      }, 
      Name: "minecraft:glass_pane"
    }, 
    {
      Properties: {
        facing: "west"
      }, 
      Name: "minecraft:wall_torch"
    }, 
    {
      Properties: {
        hinge: "left", 
        half: "upper", 
        powered: "false", 
        facing: "west", 
        open: "false"
      }, 
      Name: "minecraft:acacia_door"
    }, 
    {
      Properties: {
        hinge: "right", 
        half: "upper", 
        powered: "false", 
        facing: "east", 
        open: "false"
      }, 
      Name: "minecraft:acacia_door"
    }, 
    {
      Properties: {
        axis: "z"
      }, 
      Name: "minecraft:acacia_wood"
    }, 
    {
      Properties: {
        facing: "east"
      }, 
      Name: "minecraft:wall_torch"
    }, 
    {
      Properties: {
        half: "bottom", 
        waterlogged: "false", 
        shape: "straight", 
        facing: "south"
      }, 
      Name: "minecraft:acacia_stairs"
    }, 
    {
      Properties: {
        half: "bottom", 
        waterlogged: "false", 
        shape: "outer_right", 
        facing: "east"
      }, 
      Name: "minecraft:acacia_stairs"
    }, 
    {
      Properties: {
        half: "bottom", 
        waterlogged: "false", 
        shape: "outer_left", 
        facing: "west"
      }, 
      Name: "minecraft:acacia_stairs"
    }, 
    {
      Properties: {
        half: "bottom", 
        waterlogged: "false", 
        shape: "outer_right", 
        facing: "north"
      }, 
      Name: "minecraft:acacia_stairs"
    }, 
    {
      Properties: {
        half: "bottom", 
        waterlogged: "false", 
        shape: "outer_left", 
        facing: "north"
      }, 
      Name: "minecraft:acacia_stairs"
    }
  ]
}
