{
  size: [6, 7, 9], 
  entities: [], 
  blocks: [
    {
      pos: [0, 0, 0], 
      state: 0
    }, 
    {
      pos: [1, 0, 0], 
      state: 0
    }, 
    {
      pos: [2, 0, 0], 
      state: 1
    }, 
    {
      pos: [3, 0, 0], 
      state: 1
    }, 
    {
      pos: [4, 0, 0], 
      state: 1
    }, 
    {
      pos: [5, 0, 0], 
      state: 1
    }, 
    {
      pos: [1, 0, 1], 
      state: 0
    }, 
    {
      pos: [2, 0, 1], 
      state: 1
    }, 
    {
      pos: [3, 0, 1], 
      state: 1
    }, 
    {
      pos: [4, 0, 1], 
      state: 1
    }, 
    {
      pos: [5, 0, 1], 
      state: 1
    }, 
    {
      pos: [1, 0, 2], 
      state: 1
    }, 
    {
      pos: [2, 0, 2], 
      state: 1
    }, 
    {
      pos: [3, 0, 2], 
      state: 1
    }, 
    {
      pos: [4, 0, 2], 
      state: 1
    }, 
    {
      pos: [5, 0, 2], 
      state: 0
    }, 
    {
      pos: [0, 0, 3], 
      state: 1
    }, 
    {
      pos: [1, 0, 3], 
      state: 1
    }, 
    {
      pos: [2, 0, 3], 
      state: 1
    }, 
    {
      pos: [3, 0, 3], 
      state: 1
    }, 
    {
      pos: [4, 0, 3], 
      state: 1
    }, 
    {
      pos: [5, 0, 3], 
      state: 1
    }, 
    {
      pos: [0, 0, 4], 
      state: 1
    }, 
    {
      pos: [1, 0, 4], 
      state: 1
    }, 
    {
      pos: [2, 0, 4], 
      state: 0
    }, 
    {
      pos: [3, 0, 4], 
      state: 1
    }, 
    {
      pos: [4, 0, 4], 
      state: 1
    }, 
    {
      pos: [5, 0, 4], 
      state: 1
    }, 
    {
      pos: [0, 0, 5], 
      state: 1
    }, 
    {
      pos: [1, 0, 5], 
      state: 1
    }, 
    {
      pos: [2, 0, 5], 
      state: 1
    }, 
    {
      pos: [3, 0, 5], 
      state: 1
    }, 
    {
      pos: [4, 0, 5], 
      state: 0
    }, 
    {
      pos: [5, 0, 5], 
      state: 0
    }, 
    {
      pos: [0, 0, 6], 
      state: 0
    }, 
    {
      pos: [1, 0, 6], 
      state: 1
    }, 
    {
      pos: [2, 0, 6], 
      state: 1
    }, 
    {
      pos: [3, 0, 6], 
      state: 1
    }, 
    {
      pos: [4, 0, 6], 
      state: 1
    }, 
    {
      pos: [0, 0, 7], 
      state: 1
    }, 
    {
      pos: [1, 0, 7], 
      state: 1
    }, 
    {
      pos: [2, 0, 7], 
      state: 1
    }, 
    {
      pos: [3, 0, 7], 
      state: 1
    }, 
    {
      pos: [4, 0, 7], 
      state: 0
    }, 
    {
      pos: [5, 0, 7], 
      state: 0
    }, 
    {
      pos: [0, 0, 8], 
      state: 1
    }, 
    {
      pos: [1, 0, 8], 
      state: 0
    }, 
    {
      pos: [2, 0, 8], 
      state: 1
    }, 
    {
      pos: [3, 0, 8], 
      state: 1
    }, 
    {
      pos: [4, 0, 8], 
      state: 0
    }, 
    {
      pos: [0, 1, 0], 
      state: 1
    }, 
    {
      pos: [1, 1, 0], 
      state: 0
    }, 
    {
      pos: [1, 1, 1], 
      state: 1
    }, 
    {
      pos: [5, 1, 2], 
      state: 1
    }, 
    {
      pos: [2, 1, 4], 
      state: 1
    }, 
    {
      pos: [4, 1, 5], 
      state: 1
    }, 
    {
      pos: [5, 1, 5], 
      state: 1
    }, 
    {
      pos: [0, 1, 6], 
      state: 1
    }, 
    {
      pos: [4, 1, 7], 
      state: 1
    }, 
    {
      pos: [5, 1, 7], 
      state: 1
    }, 
    {
      pos: [1, 1, 8], 
      state: 1
    }, 
    {
      pos: [4, 1, 8], 
      state: 0
    }, 
    {
      pos: [2, 1, 0], 
      state: 2
    }, 
    {
      pos: [3, 1, 0], 
      state: 2
    }, 
    {
      pos: [4, 1, 0], 
      state: 3
    }, 
    {
      pos: [5, 1, 0], 
      state: 2
    }, 
    {
      pos: [2, 1, 1], 
      state: 2
    }, 
    {
      pos: [3, 1, 1], 
      state: 2
    }, 
    {
      pos: [4, 1, 1], 
      state: 4
    }, 
    {
      pos: [5, 1, 1], 
      state: 2
    }, 
    {
      pos: [1, 1, 2], 
      state: 2
    }, 
    {
      pos: [2, 1, 2], 
      state: 4
    }, 
    {
      pos: [3, 1, 2], 
      state: 2
    }, 
    {
      pos: [4, 1, 2], 
      state: 2
    }, 
    {
      pos: [0, 1, 3], 
      state: 2
    }, 
    {
      pos: [1, 1, 3], 
      state: 2
    }, 
    {
      pos: [2, 1, 3], 
      state: 2
    }, 
    {
      pos: [3, 1, 3], 
      state: 2
    }, 
    {
      pos: [4, 1, 3], 
      state: 2
    }, 
    {
      pos: [5, 1, 3], 
      state: 2
    }, 
    {
      pos: [0, 1, 4], 
      state: 2
    }, 
    {
      pos: [1, 1, 4], 
      state: 2
    }, 
    {
      pos: [3, 1, 4], 
      state: 2
    }, 
    {
      pos: [4, 1, 4], 
      state: 2
    }, 
    {
      pos: [5, 1, 4], 
      state: 2
    }, 
    {
      pos: [0, 1, 5], 
      state: 2
    }, 
    {
      pos: [1, 1, 5], 
      state: 2
    }, 
    {
      pos: [2, 1, 5], 
      state: 4
    }, 
    {
      pos: [3, 1, 5], 
      state: 2
    }, 
    {
      pos: [1, 1, 6], 
      state: 2
    }, 
    {
      pos: [2, 1, 6], 
      state: 2
    }, 
    {
      pos: [3, 1, 6], 
      state: 2
    }, 
    {
      pos: [4, 1, 6], 
      state: 2
    }, 
    {
      pos: [0, 1, 7], 
      state: 2
    }, 
    {
      pos: [1, 1, 7], 
      state: 2
    }, 
    {
      pos: [2, 1, 7], 
      state: 2
    }, 
    {
      pos: [3, 1, 7], 
      state: 2
    }, 
    {
      pos: [0, 1, 8], 
      state: 2
    }, 
    {
      pos: [2, 1, 8], 
      state: 2
    }, 
    {
      pos: [3, 1, 8], 
      state: 2
    }, 
    {
      pos: [4, 2, 8], 
      state: 5
    }, 
    {
      nbt: {
        target_pool: "minecraft:empty", 
        final_state: "minecraft:structure_void", 
        id: "minecraft:jigsaw", 
        attachement_type: "minecraft:building_entrance"
      }, 
      pos: [1, 2, 0], 
      state: 6
    }, 
    {
      pos: [0, 2, 0], 
      state: 7
    }, 
    {
      pos: [2, 2, 0], 
      state: 8
    }, 
    {
      pos: [3, 2, 0], 
      state: 9
    }, 
    {
      pos: [4, 2, 0], 
      state: 8
    }, 
    {
      pos: [5, 2, 0], 
      state: 10
    }, 
    {
      pos: [0, 2, 1], 
      state: 11
    }, 
    {
      pos: [1, 2, 1], 
      state: 7
    }, 
    {
      pos: [2, 2, 1], 
      state: 9
    }, 
    {
      pos: [3, 2, 1], 
      state: 10
    }, 
    {
      pos: [4, 2, 1], 
      state: 11
    }, 
    {
      pos: [5, 2, 1], 
      state: 10
    }, 
    {
      pos: [0, 2, 2], 
      state: 11
    }, 
    {
      pos: [1, 2, 2], 
      state: 10
    }, 
    {
      pos: [2, 2, 2], 
      state: 11
    }, 
    {
      pos: [3, 2, 2], 
      state: 10
    }, 
    {
      pos: [4, 2, 2], 
      state: 8
    }, 
    {
      pos: [5, 2, 2], 
      state: 7
    }, 
    {
      pos: [0, 2, 3], 
      state: 10
    }, 
    {
      pos: [1, 2, 3], 
      state: 10
    }, 
    {
      pos: [2, 2, 3], 
      state: 10
    }, 
    {
      pos: [3, 2, 3], 
      state: 8
    }, 
    {
      pos: [4, 2, 3], 
      state: 10
    }, 
    {
      pos: [5, 2, 3], 
      state: 10
    }, 
    {
      pos: [0, 2, 4], 
      state: 10
    }, 
    {
      pos: [1, 2, 4], 
      state: 10
    }, 
    {
      pos: [2, 2, 4], 
      state: 7
    }, 
    {
      pos: [3, 2, 4], 
      state: 9
    }, 
    {
      pos: [4, 2, 4], 
      state: 10
    }, 
    {
      pos: [5, 2, 4], 
      state: 10
    }, 
    {
      pos: [0, 2, 5], 
      state: 12
    }, 
    {
      pos: [1, 2, 5], 
      state: 13
    }, 
    {
      pos: [2, 2, 5], 
      state: 11
    }, 
    {
      pos: [3, 2, 5], 
      state: 10
    }, 
    {
      pos: [4, 2, 5], 
      state: 14
    }, 
    {
      pos: [5, 2, 5], 
      state: 7
    }, 
    {
      pos: [0, 2, 6], 
      state: 7
    }, 
    {
      pos: [1, 2, 6], 
      state: 10
    }, 
    {
      pos: [2, 2, 6], 
      state: 8
    }, 
    {
      pos: [3, 2, 6], 
      state: 10
    }, 
    {
      pos: [4, 2, 6], 
      state: 10
    }, 
    {
      pos: [5, 2, 6], 
      state: 11
    }, 
    {
      pos: [0, 2, 7], 
      state: 13
    }, 
    {
      pos: [1, 2, 7], 
      state: 10
    }, 
    {
      pos: [2, 2, 7], 
      state: 8
    }, 
    {
      pos: [3, 2, 7], 
      state: 8
    }, 
    {
      pos: [4, 2, 7], 
      state: 7
    }, 
    {
      pos: [5, 2, 7], 
      state: 15
    }, 
    {
      pos: [0, 2, 8], 
      state: 12
    }, 
    {
      pos: [1, 2, 8], 
      state: 15
    }, 
    {
      pos: [2, 2, 8], 
      state: 8
    }, 
    {
      pos: [3, 2, 8], 
      state: 8
    }, 
    {
      pos: [5, 2, 8], 
      state: 11
    }, 
    {
      pos: [0, 3, 0], 
      state: 16
    }, 
    {
      pos: [1, 3, 0], 
      state: 11
    }, 
    {
      pos: [2, 3, 0], 
      state: 11
    }, 
    {
      pos: [3, 3, 0], 
      state: 11
    }, 
    {
      pos: [4, 3, 0], 
      state: 11
    }, 
    {
      pos: [5, 3, 0], 
      state: 11
    }, 
    {
      pos: [0, 3, 1], 
      state: 11
    }, 
    {
      pos: [1, 3, 1], 
      state: 16
    }, 
    {
      pos: [2, 3, 1], 
      state: 11
    }, 
    {
      pos: [3, 3, 1], 
      state: 11
    }, 
    {
      pos: [4, 3, 1], 
      state: 11
    }, 
    {
      pos: [5, 3, 1], 
      state: 11
    }, 
    {
      pos: [0, 3, 2], 
      state: 11
    }, 
    {
      pos: [1, 3, 2], 
      state: 11
    }, 
    {
      pos: [2, 3, 2], 
      state: 11
    }, 
    {
      pos: [3, 3, 2], 
      state: 11
    }, 
    {
      pos: [4, 3, 2], 
      state: 11
    }, 
    {
      pos: [5, 3, 2], 
      state: 16
    }, 
    {
      pos: [0, 3, 3], 
      state: 11
    }, 
    {
      pos: [1, 3, 3], 
      state: 11
    }, 
    {
      pos: [2, 3, 3], 
      state: 11
    }, 
    {
      pos: [3, 3, 3], 
      state: 11
    }, 
    {
      pos: [4, 3, 3], 
      state: 11
    }, 
    {
      pos: [5, 3, 3], 
      state: 11
    }, 
    {
      pos: [0, 3, 4], 
      state: 11
    }, 
    {
      pos: [1, 3, 4], 
      state: 11
    }, 
    {
      pos: [2, 3, 4], 
      state: 16
    }, 
    {
      pos: [3, 3, 4], 
      state: 11
    }, 
    {
      pos: [4, 3, 4], 
      state: 11
    }, 
    {
      pos: [5, 3, 4], 
      state: 11
    }, 
    {
      pos: [0, 3, 5], 
      state: 11
    }, 
    {
      pos: [1, 3, 5], 
      state: 11
    }, 
    {
      pos: [2, 3, 5], 
      state: 11
    }, 
    {
      pos: [3, 3, 5], 
      state: 11
    }, 
    {
      pos: [4, 3, 5], 
      state: 11
    }, 
    {
      pos: [5, 3, 5], 
      state: 16
    }, 
    {
      pos: [0, 3, 6], 
      state: 16
    }, 
    {
      pos: [1, 3, 6], 
      state: 11
    }, 
    {
      pos: [2, 3, 6], 
      state: 11
    }, 
    {
      pos: [3, 3, 6], 
      state: 11
    }, 
    {
      pos: [4, 3, 6], 
      state: 11
    }, 
    {
      pos: [5, 3, 6], 
      state: 11
    }, 
    {
      pos: [0, 3, 7], 
      state: 11
    }, 
    {
      pos: [1, 3, 7], 
      state: 11
    }, 
    {
      pos: [2, 3, 7], 
      state: 11
    }, 
    {
      pos: [3, 3, 7], 
      state: 11
    }, 
    {
      pos: [4, 3, 7], 
      state: 16
    }, 
    {
      pos: [5, 3, 7], 
      state: 11
    }, 
    {
      pos: [0, 3, 8], 
      state: 11
    }, 
    {
      pos: [1, 3, 8], 
      state: 11
    }, 
    {
      pos: [2, 3, 8], 
      state: 11
    }, 
    {
      pos: [3, 3, 8], 
      state: 11
    }, 
    {
      pos: [4, 3, 8], 
      state: 11
    }, 
    {
      pos: [5, 3, 8], 
      state: 11
    }
  ], 
  palette: [
    {
      Name: "minecraft:dirt"
    }, 
    {
      Properties: {
        snowy: "false"
      }, 
      Name: "minecraft:grass_block"
    }, 
    {
      Properties: {
        moisture: "7"
      }, 
      Name: "minecraft:farmland"
    }, 
    {
      Properties: {
        moisture: "0"
      }, 
      Name: "minecraft:farmland"
    }, 
    {
      Properties: {
        level: "0"
      }, 
      Name: "minecraft:water"
    }, 
    {
      Name: "minecraft:melon"
    }, 
    {
      Properties: {
        facing: "north"
      }, 
      Name: "minecraft:jigsaw"
    }, 
    {
      Properties: {
        half: "lower"
      }, 
      Name: "minecraft:tall_grass"
    }, 
    {
      Properties: {
        age: "0"
      }, 
      Name: "minecraft:wheat"
    }, 
    {
      Properties: {
        age: "1"
      }, 
      Name: "minecraft:wheat"
    }, 
    {
      Properties: {
        age: "7"
      }, 
      Name: "minecraft:wheat"
    }, 
    {
      Name: "minecraft:air"
    }, 
    {
      Properties: {
        age: "6"
      }, 
      Name: "minecraft:wheat"
    }, 
    {
      Properties: {
        age: "5"
      }, 
      Name: "minecraft:wheat"
    }, 
    {
      Properties: {
        level: "0"
      }, 
      Name: "minecraft:composter"
    }, 
    {
      Name: "minecraft:grass"
    }, 
    {
      Properties: {
        half: "upper"
      }, 
      Name: "minecraft:tall_grass"
    }
  ]
}
