{
  size: [10, 8, 11], 
  entities: [], 
  blocks: [
    {
      pos: [2, 0, 1], 
      state: 0
    }, 
    {
      pos: [3, 0, 1], 
      state: 0
    }, 
    {
      pos: [4, 0, 1], 
      state: 0
    }, 
    {
      pos: [1, 0, 2], 
      state: 0
    }, 
    {
      pos: [2, 0, 2], 
      state: 1
    }, 
    {
      pos: [3, 0, 2], 
      state: 1
    }, 
    {
      pos: [4, 0, 2], 
      state: 1
    }, 
    {
      pos: [5, 0, 2], 
      state: 0
    }, 
    {
      pos: [1, 0, 3], 
      state: 2
    }, 
    {
      pos: [2, 0, 3], 
      state: 1
    }, 
    {
      pos: [4, 0, 3], 
      state: 1
    }, 
    {
      pos: [5, 0, 3], 
      state: 0
    }, 
    {
      pos: [1, 0, 4], 
      state: 0
    }, 
    {
      pos: [2, 0, 4], 
      state: 1
    }, 
    {
      pos: [3, 0, 4], 
      state: 1
    }, 
    {
      pos: [4, 0, 4], 
      state: 1
    }, 
    {
      pos: [5, 0, 4], 
      state: 0
    }, 
    {
      pos: [0, 0, 5], 
      state: 0
    }, 
    {
      pos: [2, 0, 5], 
      state: 0
    }, 
    {
      pos: [3, 0, 5], 
      state: 0
    }, 
    {
      pos: [4, 0, 5], 
      state: 0
    }, 
    {
      pos: [5, 0, 5], 
      state: 0
    }, 
    {
      pos: [6, 0, 5], 
      state: 0
    }, 
    {
      pos: [7, 0, 5], 
      state: 0
    }, 
    {
      pos: [4, 0, 6], 
      state: 0
    }, 
    {
      pos: [5, 0, 6], 
      state: 1
    }, 
    {
      pos: [6, 0, 6], 
      state: 1
    }, 
    {
      pos: [7, 0, 6], 
      state: 1
    }, 
    {
      pos: [8, 0, 6], 
      state: 0
    }, 
    {
      pos: [4, 0, 7], 
      state: 0
    }, 
    {
      pos: [5, 0, 7], 
      state: 1
    }, 
    {
      pos: [6, 0, 7], 
      state: 1
    }, 
    {
      pos: [7, 0, 7], 
      state: 1
    }, 
    {
      pos: [8, 0, 7], 
      state: 0
    }, 
    {
      pos: [4, 0, 8], 
      state: 0
    }, 
    {
      pos: [5, 0, 8], 
      state: 1
    }, 
    {
      pos: [6, 0, 8], 
      state: 1
    }, 
    {
      pos: [8, 0, 8], 
      state: 0
    }, 
    {
      pos: [5, 0, 9], 
      state: 0
    }, 
    {
      pos: [6, 0, 9], 
      state: 2
    }, 
    {
      pos: [7, 0, 9], 
      state: 0
    }, 
    {
      nbt: {
        final_state: "minecraft:grass_block", 
        name: "minecraft:bottom", 
        pool: "minecraft:village/savanna/decor", 
        id: "minecraft:jigsaw", 
        target: "minecraft:bottom"
      }, 
      pos: [7, 0, 2], 
      state: 3
    }, 
    {
      nbt: {
        final_state: "minecraft:acacia_planks", 
        name: "minecraft:bottom", 
        pool: "minecraft:village/savanna/villagers", 
        id: "minecraft:jigsaw", 
        target: "minecraft:bottom"
      }, 
      pos: [3, 0, 3], 
      state: 3
    }, 
    {
      nbt: {
        final_state: "minecraft:acacia_planks", 
        name: "minecraft:bottom", 
        pool: "minecraft:village/savanna/villagers", 
        id: "minecraft:jigsaw", 
        target: "minecraft:bottom"
      }, 
      pos: [7, 0, 8], 
      state: 3
    }, 
    {
      pos: [0, 0, 3], 
      state: 4
    }, 
    {
      pos: [0, 0, 4], 
      state: 4
    }, 
    {
      pos: [0, 0, 6], 
      state: 4
    }, 
    {
      pos: [1, 0, 6], 
      state: 4
    }, 
    {
      pos: [2, 0, 6], 
      state: 5
    }, 
    {
      pos: [3, 0, 6], 
      state: 6
    }, 
    {
      pos: [1, 0, 7], 
      state: 4
    }, 
    {
      pos: [2, 0, 7], 
      state: 5
    }, 
    {
      pos: [3, 0, 7], 
      state: 5
    }, 
    {
      pos: [2, 0, 8], 
      state: 4
    }, 
    {
      pos: [3, 0, 8], 
      state: 5
    }, 
    {
      pos: [2, 0, 9], 
      state: 4
    }, 
    {
      pos: [3, 0, 9], 
      state: 4
    }, 
    {
      pos: [4, 0, 10], 
      state: 4
    }, 
    {
      pos: [5, 0, 10], 
      state: 4
    }, 
    {
      pos: [6, 0, 10], 
      state: 4
    }, 
    {
      pos: [2, 1, 1], 
      state: 2
    }, 
    {
      pos: [3, 1, 1], 
      state: 7
    }, 
    {
      pos: [4, 1, 1], 
      state: 2
    }, 
    {
      pos: [1, 1, 2], 
      state: 2
    }, 
    {
      pos: [2, 1, 2], 
      state: 8
    }, 
    {
      pos: [5, 1, 2], 
      state: 2
    }, 
    {
      pos: [5, 1, 3], 
      state: 9
    }, 
    {
      pos: [1, 1, 4], 
      state: 2
    }, 
    {
      pos: [4, 1, 4], 
      state: 1
    }, 
    {
      pos: [5, 1, 4], 
      state: 2
    }, 
    {
      pos: [2, 1, 5], 
      state: 2
    }, 
    {
      pos: [3, 1, 5], 
      state: 7
    }, 
    {
      pos: [4, 1, 5], 
      state: 2
    }, 
    {
      pos: [5, 1, 5], 
      state: 2
    }, 
    {
      pos: [6, 1, 5], 
      state: 7
    }, 
    {
      pos: [7, 1, 5], 
      state: 2
    }, 
    {
      pos: [4, 1, 6], 
      state: 2
    }, 
    {
      pos: [8, 1, 6], 
      state: 2
    }, 
    {
      pos: [4, 1, 7], 
      state: 9
    }, 
    {
      pos: [8, 1, 7], 
      state: 9
    }, 
    {
      pos: [4, 1, 8], 
      state: 2
    }, 
    {
      pos: [8, 1, 8], 
      state: 2
    }, 
    {
      pos: [5, 1, 9], 
      state: 2
    }, 
    {
      pos: [7, 1, 9], 
      state: 2
    }, 
    {
      nbt: {
        id: "minecraft:bed"
      }, 
      pos: [3, 1, 2], 
      state: 10
    }, 
    {
      nbt: {
        id: "minecraft:bed"
      }, 
      pos: [4, 1, 2], 
      state: 11
    }, 
    {
      nbt: {
        final_state: "minecraft:structure_void", 
        name: "minecraft:building_entrance", 
        pool: "minecraft:empty", 
        id: "minecraft:jigsaw", 
        target: "minecraft:building_entrance"
      }, 
      pos: [0, 1, 5], 
      state: 12
    }, 
    {
      nbt: {
        id: "minecraft:bed"
      }, 
      pos: [5, 1, 6], 
      state: 13
    }, 
    {
      nbt: {
        LootTable: "minecraft:chests/village/village_savanna_house", 
        Items: [], 
        id: "minecraft:chest", 
        Lock: "", 
        LootTableSeed: 0L
      }, 
      pos: [7, 1, 6], 
      state: 14
    }, 
    {
      nbt: {
        id: "minecraft:bed"
      }, 
      pos: [5, 1, 7], 
      state: 15
    }, 
    {
      pos: [9, 1, 0], 
      state: 16
    }, 
    {
      pos: [1, 1, 3], 
      state: 17
    }, 
    {
      pos: [3, 1, 3], 
      state: 16
    }, 
    {
      pos: [2, 1, 4], 
      state: 18
    }, 
    {
      pos: [3, 1, 4], 
      state: 18
    }, 
    {
      pos: [2, 1, 6], 
      state: 19
    }, 
    {
      pos: [2, 1, 7], 
      state: 19
    }, 
    {
      pos: [3, 1, 7], 
      state: 20
    }, 
    {
      pos: [3, 1, 8], 
      state: 19
    }, 
    {
      pos: [5, 1, 8], 
      state: 21
    }, 
    {
      pos: [7, 1, 8], 
      state: 16
    }, 
    {
      pos: [6, 1, 9], 
      state: 22
    }, 
    {
      pos: [9, 1, 9], 
      state: 16
    }, 
    {
      pos: [9, 1, 10], 
      state: 16
    }, 
    {
      pos: [2, 2, 1], 
      state: 2
    }, 
    {
      pos: [4, 2, 1], 
      state: 2
    }, 
    {
      pos: [1, 2, 2], 
      state: 2
    }, 
    {
      pos: [5, 2, 2], 
      state: 2
    }, 
    {
      pos: [1, 2, 4], 
      state: 2
    }, 
    {
      pos: [5, 2, 4], 
      state: 2
    }, 
    {
      pos: [2, 2, 5], 
      state: 2
    }, 
    {
      pos: [4, 2, 5], 
      state: 2
    }, 
    {
      pos: [5, 2, 5], 
      state: 2
    }, 
    {
      pos: [7, 2, 5], 
      state: 2
    }, 
    {
      pos: [4, 2, 6], 
      state: 2
    }, 
    {
      pos: [8, 2, 6], 
      state: 2
    }, 
    {
      pos: [4, 2, 8], 
      state: 2
    }, 
    {
      pos: [8, 2, 8], 
      state: 2
    }, 
    {
      pos: [5, 2, 9], 
      state: 2
    }, 
    {
      pos: [7, 2, 9], 
      state: 2
    }, 
    {
      pos: [3, 2, 1], 
      state: 23
    }, 
    {
      pos: [1, 2, 3], 
      state: 24
    }, 
    {
      pos: [5, 2, 3], 
      state: 25
    }, 
    {
      pos: [4, 2, 4], 
      state: 26
    }, 
    {
      pos: [3, 2, 5], 
      state: 23
    }, 
    {
      pos: [6, 2, 5], 
      state: 23
    }, 
    {
      pos: [4, 2, 7], 
      state: 25
    }, 
    {
      pos: [8, 2, 7], 
      state: 25
    }, 
    {
      pos: [6, 2, 9], 
      state: 27
    }, 
    {
      pos: [2, 3, 1], 
      state: 2
    }, 
    {
      pos: [3, 3, 1], 
      state: 7
    }, 
    {
      pos: [4, 3, 1], 
      state: 2
    }, 
    {
      pos: [1, 3, 2], 
      state: 2
    }, 
    {
      pos: [5, 3, 2], 
      state: 2
    }, 
    {
      pos: [1, 3, 3], 
      state: 9
    }, 
    {
      pos: [5, 3, 3], 
      state: 9
    }, 
    {
      pos: [1, 3, 4], 
      state: 2
    }, 
    {
      pos: [5, 3, 4], 
      state: 2
    }, 
    {
      pos: [2, 3, 5], 
      state: 2
    }, 
    {
      pos: [3, 3, 5], 
      state: 7
    }, 
    {
      pos: [4, 3, 5], 
      state: 2
    }, 
    {
      pos: [5, 3, 5], 
      state: 2
    }, 
    {
      pos: [6, 3, 5], 
      state: 7
    }, 
    {
      pos: [7, 3, 5], 
      state: 2
    }, 
    {
      pos: [4, 3, 6], 
      state: 2
    }, 
    {
      pos: [8, 3, 6], 
      state: 2
    }, 
    {
      pos: [4, 3, 7], 
      state: 9
    }, 
    {
      pos: [8, 3, 7], 
      state: 9
    }, 
    {
      pos: [4, 3, 8], 
      state: 2
    }, 
    {
      pos: [8, 3, 8], 
      state: 2
    }, 
    {
      pos: [5, 3, 9], 
      state: 2
    }, 
    {
      pos: [6, 3, 9], 
      state: 7
    }, 
    {
      pos: [7, 3, 9], 
      state: 2
    }, 
    {
      pos: [4, 3, 3], 
      state: 28
    }, 
    {
      pos: [6, 3, 6], 
      state: 29
    }, 
    {
      pos: [1, 4, 1], 
      state: 1
    }, 
    {
      pos: [2, 4, 1], 
      state: 1
    }, 
    {
      pos: [3, 4, 1], 
      state: 1
    }, 
    {
      pos: [4, 4, 1], 
      state: 1
    }, 
    {
      pos: [5, 4, 1], 
      state: 1
    }, 
    {
      pos: [1, 4, 2], 
      state: 1
    }, 
    {
      pos: [5, 4, 2], 
      state: 1
    }, 
    {
      pos: [1, 4, 3], 
      state: 1
    }, 
    {
      pos: [5, 4, 3], 
      state: 1
    }, 
    {
      pos: [1, 4, 4], 
      state: 1
    }, 
    {
      pos: [5, 4, 4], 
      state: 1
    }, 
    {
      pos: [1, 4, 5], 
      state: 1
    }, 
    {
      pos: [2, 4, 5], 
      state: 1
    }, 
    {
      pos: [3, 4, 5], 
      state: 1
    }, 
    {
      pos: [4, 4, 5], 
      state: 1
    }, 
    {
      pos: [5, 4, 5], 
      state: 1
    }, 
    {
      pos: [6, 4, 5], 
      state: 1
    }, 
    {
      pos: [7, 4, 5], 
      state: 1
    }, 
    {
      pos: [8, 4, 5], 
      state: 1
    }, 
    {
      pos: [4, 4, 6], 
      state: 1
    }, 
    {
      pos: [8, 4, 6], 
      state: 1
    }, 
    {
      pos: [4, 4, 7], 
      state: 1
    }, 
    {
      pos: [8, 4, 7], 
      state: 1
    }, 
    {
      pos: [4, 4, 8], 
      state: 1
    }, 
    {
      pos: [8, 4, 8], 
      state: 1
    }, 
    {
      pos: [4, 4, 9], 
      state: 1
    }, 
    {
      pos: [5, 4, 9], 
      state: 1
    }, 
    {
      pos: [6, 4, 9], 
      state: 1
    }, 
    {
      pos: [7, 4, 9], 
      state: 1
    }, 
    {
      pos: [8, 4, 9], 
      state: 1
    }, 
    {
      pos: [1, 4, 0], 
      state: 18
    }, 
    {
      pos: [2, 4, 0], 
      state: 18
    }, 
    {
      pos: [3, 4, 0], 
      state: 18
    }, 
    {
      pos: [4, 4, 0], 
      state: 18
    }, 
    {
      pos: [5, 4, 0], 
      state: 18
    }, 
    {
      pos: [0, 4, 1], 
      state: 30
    }, 
    {
      pos: [6, 4, 1], 
      state: 21
    }, 
    {
      pos: [0, 4, 2], 
      state: 30
    }, 
    {
      pos: [6, 4, 2], 
      state: 21
    }, 
    {
      pos: [0, 4, 3], 
      state: 30
    }, 
    {
      pos: [6, 4, 3], 
      state: 21
    }, 
    {
      pos: [0, 4, 4], 
      state: 30
    }, 
    {
      pos: [6, 4, 4], 
      state: 31
    }, 
    {
      pos: [7, 4, 4], 
      state: 18
    }, 
    {
      pos: [8, 4, 4], 
      state: 18
    }, 
    {
      pos: [0, 4, 5], 
      state: 30
    }, 
    {
      pos: [9, 4, 5], 
      state: 21
    }, 
    {
      pos: [1, 4, 6], 
      state: 32
    }, 
    {
      pos: [2, 4, 6], 
      state: 32
    }, 
    {
      pos: [3, 4, 6], 
      state: 33
    }, 
    {
      pos: [9, 4, 6], 
      state: 21
    }, 
    {
      pos: [3, 4, 7], 
      state: 30
    }, 
    {
      pos: [9, 4, 7], 
      state: 21
    }, 
    {
      pos: [3, 4, 8], 
      state: 30
    }, 
    {
      pos: [9, 4, 8], 
      state: 21
    }, 
    {
      pos: [3, 4, 9], 
      state: 30
    }, 
    {
      pos: [9, 4, 9], 
      state: 21
    }, 
    {
      pos: [4, 4, 10], 
      state: 32
    }, 
    {
      pos: [5, 4, 10], 
      state: 32
    }, 
    {
      pos: [6, 4, 10], 
      state: 32
    }, 
    {
      pos: [7, 4, 10], 
      state: 32
    }, 
    {
      pos: [8, 4, 10], 
      state: 32
    }, 
    {
      pos: [1, 5, 1], 
      state: 34
    }, 
    {
      pos: [2, 5, 1], 
      state: 18
    }, 
    {
      pos: [3, 5, 1], 
      state: 18
    }, 
    {
      pos: [4, 5, 1], 
      state: 18
    }, 
    {
      pos: [5, 5, 1], 
      state: 35
    }, 
    {
      pos: [1, 5, 2], 
      state: 30
    }, 
    {
      pos: [2, 5, 2], 
      state: 36
    }, 
    {
      pos: [3, 5, 2], 
      state: 36
    }, 
    {
      pos: [4, 5, 2], 
      state: 36
    }, 
    {
      pos: [5, 5, 2], 
      state: 21
    }, 
    {
      pos: [1, 5, 3], 
      state: 30
    }, 
    {
      pos: [2, 5, 3], 
      state: 36
    }, 
    {
      pos: [3, 5, 3], 
      state: 36
    }, 
    {
      pos: [4, 5, 3], 
      state: 36
    }, 
    {
      pos: [5, 5, 3], 
      state: 21
    }, 
    {
      pos: [1, 5, 4], 
      state: 30
    }, 
    {
      pos: [2, 5, 4], 
      state: 36
    }, 
    {
      pos: [3, 5, 4], 
      state: 36
    }, 
    {
      pos: [4, 5, 4], 
      state: 36
    }, 
    {
      pos: [5, 5, 4], 
      state: 21
    }, 
    {
      pos: [1, 5, 5], 
      state: 37
    }, 
    {
      pos: [2, 5, 5], 
      state: 32
    }, 
    {
      pos: [3, 5, 5], 
      state: 32
    }, 
    {
      pos: [4, 5, 5], 
      state: 33
    }, 
    {
      pos: [5, 5, 5], 
      state: 31
    }, 
    {
      pos: [6, 5, 5], 
      state: 18
    }, 
    {
      pos: [7, 5, 5], 
      state: 18
    }, 
    {
      pos: [8, 5, 5], 
      state: 35
    }, 
    {
      pos: [4, 5, 6], 
      state: 30
    }, 
    {
      pos: [5, 5, 6], 
      state: 36
    }, 
    {
      pos: [6, 5, 6], 
      state: 36
    }, 
    {
      pos: [7, 5, 6], 
      state: 36
    }, 
    {
      pos: [8, 5, 6], 
      state: 21
    }, 
    {
      pos: [4, 5, 7], 
      state: 30
    }, 
    {
      pos: [5, 5, 7], 
      state: 36
    }, 
    {
      pos: [6, 5, 7], 
      state: 36
    }, 
    {
      pos: [7, 5, 7], 
      state: 36
    }, 
    {
      pos: [8, 5, 7], 
      state: 21
    }, 
    {
      pos: [4, 5, 8], 
      state: 30
    }, 
    {
      pos: [5, 5, 8], 
      state: 36
    }, 
    {
      pos: [6, 5, 8], 
      state: 36
    }, 
    {
      pos: [7, 5, 8], 
      state: 36
    }, 
    {
      pos: [8, 5, 8], 
      state: 21
    }, 
    {
      pos: [4, 5, 9], 
      state: 38
    }, 
    {
      pos: [5, 5, 9], 
      state: 32
    }, 
    {
      pos: [6, 5, 9], 
      state: 32
    }, 
    {
      pos: [7, 5, 9], 
      state: 32
    }, 
    {
      pos: [8, 5, 9], 
      state: 39
    }
  ], 
  palette: [
    {
      Name: "minecraft:dirt"
    }, 
    {
      Name: "minecraft:acacia_planks"
    }, 
    {
      Properties: {
        axis: "y"
      }, 
      Name: "minecraft:acacia_wood"
    }, 
    {
      Properties: {
        orientation: "up_north"
      }, 
      Name: "minecraft:jigsaw"
    }, 
    {
      Name: "minecraft:grass_path"
    }, 
    {
      Properties: {
        moisture: "7"
      }, 
      Name: "minecraft:farmland"
    }, 
    {
      Properties: {
        level: "0"
      }, 
      Name: "minecraft:water"
    }, 
    {
      Properties: {
        axis: "x"
      }, 
      Name: "minecraft:acacia_wood"
    }, 
    {
      Name: "minecraft:crafting_table"
    }, 
    {
      Properties: {
        axis: "z"
      }, 
      Name: "minecraft:acacia_wood"
    }, 
    {
      Properties: {
        part: "foot", 
        facing: "east", 
        occupied: "false"
      }, 
      Name: "minecraft:orange_bed"
    }, 
    {
      Properties: {
        part: "head", 
        facing: "east", 
        occupied: "false"
      }, 
      Name: "minecraft:orange_bed"
    }, 
    {
      Properties: {
        orientation: "west_up"
      }, 
      Name: "minecraft:jigsaw"
    }, 
    {
      Properties: {
        part: "head", 
        facing: "north", 
        occupied: "false"
      }, 
      Name: "minecraft:orange_bed"
    }, 
    {
      Properties: {
        waterlogged: "false", 
        facing: "west", 
        type: "single"
      }, 
      Name: "minecraft:chest"
    }, 
    {
      Properties: {
        part: "foot", 
        facing: "north", 
        occupied: "false"
      }, 
      Name: "minecraft:orange_bed"
    }, 
    {
      Name: "minecraft:air"
    }, 
    {
      Properties: {
        hinge: "left", 
        half: "lower", 
        powered: "false", 
        facing: "south", 
        open: "true"
      }, 
      Name: "minecraft:acacia_door"
    }, 
    {
      Properties: {
        half: "bottom", 
        waterlogged: "false", 
        shape: "straight", 
        facing: "south"
      }, 
      Name: "minecraft:acacia_stairs"
    }, 
    {
      Properties: {
        age: "0"
      }, 
      Name: "minecraft:wheat"
    }, 
    {
      Properties: {
        age: "1"
      }, 
      Name: "minecraft:wheat"
    }, 
    {
      Properties: {
        half: "bottom", 
        waterlogged: "false", 
        shape: "straight", 
        facing: "west"
      }, 
      Name: "minecraft:acacia_stairs"
    }, 
    {
      Properties: {
        hinge: "right", 
        half: "lower", 
        powered: "false", 
        facing: "south", 
        open: "false"
      }, 
      Name: "minecraft:acacia_door"
    }, 
    {
      Properties: {
        east: "true", 
        waterlogged: "false", 
        south: "false", 
        north: "false", 
        west: "true"
      }, 
      Name: "minecraft:glass_pane"
    }, 
    {
      Properties: {
        hinge: "left", 
        half: "upper", 
        powered: "false", 
        facing: "south", 
        open: "true"
      }, 
      Name: "minecraft:acacia_door"
    }, 
    {
      Properties: {
        east: "false", 
        waterlogged: "false", 
        south: "true", 
        north: "true", 
        west: "false"
      }, 
      Name: "minecraft:glass_pane"
    }, 
    {
      Name: "minecraft:potted_dandelion"
    }, 
    {
      Properties: {
        hinge: "right", 
        half: "upper", 
        powered: "false", 
        facing: "south", 
        open: "false"
      }, 
      Name: "minecraft:acacia_door"
    }, 
    {
      Properties: {
        facing: "west"
      }, 
      Name: "minecraft:wall_torch"
    }, 
    {
      Properties: {
        facing: "south"
      }, 
      Name: "minecraft:wall_torch"
    }, 
    {
      Properties: {
        half: "bottom", 
        waterlogged: "false", 
        shape: "straight", 
        facing: "east"
      }, 
      Name: "minecraft:acacia_stairs"
    }, 
    {
      Properties: {
        half: "bottom", 
        waterlogged: "false", 
        shape: "inner_right", 
        facing: "south"
      }, 
      Name: "minecraft:acacia_stairs"
    }, 
    {
      Properties: {
        half: "bottom", 
        waterlogged: "false", 
        shape: "straight", 
        facing: "north"
      }, 
      Name: "minecraft:acacia_stairs"
    }, 
    {
      Properties: {
        half: "bottom", 
        waterlogged: "false", 
        shape: "inner_right", 
        facing: "north"
      }, 
      Name: "minecraft:acacia_stairs"
    }, 
    {
      Properties: {
        half: "bottom", 
        waterlogged: "false", 
        shape: "outer_right", 
        facing: "east"
      }, 
      Name: "minecraft:acacia_stairs"
    }, 
    {
      Properties: {
        half: "bottom", 
        waterlogged: "false", 
        shape: "outer_left", 
        facing: "west"
      }, 
      Name: "minecraft:acacia_stairs"
    }, 
    {
      Properties: {
        waterlogged: "false", 
        type: "top"
      }, 
      Name: "minecraft:acacia_slab"
    }, 
    {
      Properties: {
        half: "bottom", 
        waterlogged: "false", 
        shape: "outer_right", 
        facing: "north"
      }, 
      Name: "minecraft:acacia_stairs"
    }, 
    {
      Properties: {
        half: "bottom", 
        waterlogged: "false", 
        shape: "outer_left", 
        facing: "east"
      }, 
      Name: "minecraft:acacia_stairs"
    }, 
    {
      Properties: {
        half: "bottom", 
        waterlogged: "false", 
        shape: "outer_left", 
        facing: "north"
      }, 
      Name: "minecraft:acacia_stairs"
    }
  ]
}
