{
  size: [7, 7, 9], 
  entities: [], 
  blocks: [
    {
      pos: [2, 0, 1], 
      state: 0
    }, 
    {
      pos: [3, 0, 1], 
      state: 0
    }, 
    {
      pos: [4, 0, 1], 
      state: 0
    }, 
    {
      pos: [1, 0, 2], 
      state: 0
    }, 
    {
      pos: [2, 0, 2], 
      state: 1
    }, 
    {
      pos: [3, 0, 2], 
      state: 1
    }, 
    {
      pos: [4, 0, 2], 
      state: 1
    }, 
    {
      pos: [5, 0, 2], 
      state: 0
    }, 
    {
      pos: [1, 0, 3], 
      state: 0
    }, 
    {
      pos: [2, 0, 3], 
      state: 2
    }, 
    {
      pos: [3, 0, 3], 
      state: 1
    }, 
    {
      pos: [4, 0, 3], 
      state: 2
    }, 
    {
      pos: [5, 0, 3], 
      state: 0
    }, 
    {
      pos: [1, 0, 4], 
      state: 3
    }, 
    {
      pos: [2, 0, 4], 
      state: 4
    }, 
    {
      pos: [3, 0, 4], 
      state: 4
    }, 
    {
      pos: [4, 0, 4], 
      state: 4
    }, 
    {
      pos: [5, 0, 4], 
      state: 0
    }, 
    {
      pos: [1, 0, 5], 
      state: 0
    }, 
    {
      pos: [2, 0, 5], 
      state: 1
    }, 
    {
      pos: [3, 0, 5], 
      state: 1
    }, 
    {
      pos: [4, 0, 5], 
      state: 1
    }, 
    {
      pos: [5, 0, 5], 
      state: 0
    }, 
    {
      pos: [1, 0, 6], 
      state: 0
    }, 
    {
      pos: [2, 0, 6], 
      state: 1
    }, 
    {
      pos: [3, 0, 6], 
      state: 1
    }, 
    {
      pos: [4, 0, 6], 
      state: 1
    }, 
    {
      pos: [5, 0, 6], 
      state: 0
    }, 
    {
      pos: [2, 0, 7], 
      state: 0
    }, 
    {
      pos: [3, 0, 7], 
      state: 0
    }, 
    {
      pos: [4, 0, 7], 
      state: 0
    }, 
    {
      pos: [0, 0, 4], 
      state: 5
    }, 
    {
      pos: [2, 1, 1], 
      state: 2
    }, 
    {
      pos: [3, 1, 1], 
      state: 3
    }, 
    {
      pos: [4, 1, 1], 
      state: 1
    }, 
    {
      pos: [1, 1, 2], 
      state: 1
    }, 
    {
      pos: [5, 1, 2], 
      state: 1
    }, 
    {
      pos: [1, 1, 3], 
      state: 1
    }, 
    {
      pos: [5, 1, 3], 
      state: 2
    }, 
    {
      pos: [5, 1, 4], 
      state: 1
    }, 
    {
      pos: [1, 1, 5], 
      state: 1
    }, 
    {
      pos: [5, 1, 5], 
      state: 2
    }, 
    {
      pos: [1, 1, 6], 
      state: 1
    }, 
    {
      pos: [5, 1, 6], 
      state: 1
    }, 
    {
      pos: [2, 1, 7], 
      state: 1
    }, 
    {
      pos: [3, 1, 7], 
      state: 3
    }, 
    {
      pos: [4, 1, 7], 
      state: 1
    }, 
    {
      nbt: {
        Fuel: 0b, 
        Items: [], 
        id: "minecraft:brewing_stand", 
        BrewTime: 0s, 
        Lock: ""
      }, 
      pos: [3, 1, 2], 
      state: 6
    }, 
    {
      nbt: {
        target_pool: "minecraft:empty", 
        final_state: "minecraft:structure_void", 
        id: "minecraft:jigsaw", 
        attachement_type: "minecraft:building_entrance"
      }, 
      pos: [0, 1, 4], 
      state: 7
    }, 
    {
      pos: [1, 1, 4], 
      state: 8
    }, 
    {
      pos: [2, 1, 6], 
      state: 9
    }, 
    {
      pos: [3, 1, 6], 
      state: 9
    }, 
    {
      pos: [4, 1, 6], 
      state: 9
    }, 
    {
      pos: [2, 2, 1], 
      state: 1
    }, 
    {
      pos: [4, 2, 1], 
      state: 1
    }, 
    {
      pos: [1, 2, 2], 
      state: 1
    }, 
    {
      pos: [5, 2, 2], 
      state: 1
    }, 
    {
      pos: [1, 2, 3], 
      state: 1
    }, 
    {
      pos: [5, 2, 4], 
      state: 1
    }, 
    {
      pos: [1, 2, 5], 
      state: 1
    }, 
    {
      pos: [1, 2, 6], 
      state: 1
    }, 
    {
      pos: [5, 2, 6], 
      state: 1
    }, 
    {
      pos: [2, 2, 7], 
      state: 1
    }, 
    {
      pos: [4, 2, 7], 
      state: 1
    }, 
    {
      pos: [3, 2, 1], 
      state: 10
    }, 
    {
      pos: [2, 2, 3], 
      state: 11
    }, 
    {
      pos: [5, 2, 3], 
      state: 12
    }, 
    {
      pos: [1, 2, 4], 
      state: 13
    }, 
    {
      pos: [4, 2, 4], 
      state: 14
    }, 
    {
      pos: [2, 2, 5], 
      state: 11
    }, 
    {
      pos: [5, 2, 5], 
      state: 12
    }, 
    {
      pos: [3, 2, 7], 
      state: 10
    }, 
    {
      pos: [2, 3, 1], 
      state: 1
    }, 
    {
      pos: [3, 3, 1], 
      state: 3
    }, 
    {
      pos: [4, 3, 1], 
      state: 1
    }, 
    {
      pos: [1, 3, 2], 
      state: 1
    }, 
    {
      pos: [5, 3, 2], 
      state: 1
    }, 
    {
      pos: [1, 3, 3], 
      state: 1
    }, 
    {
      pos: [5, 3, 3], 
      state: 2
    }, 
    {
      pos: [1, 3, 4], 
      state: 2
    }, 
    {
      pos: [5, 3, 4], 
      state: 1
    }, 
    {
      pos: [1, 3, 5], 
      state: 1
    }, 
    {
      pos: [5, 3, 5], 
      state: 2
    }, 
    {
      pos: [1, 3, 6], 
      state: 1
    }, 
    {
      pos: [5, 3, 6], 
      state: 1
    }, 
    {
      pos: [2, 3, 7], 
      state: 1
    }, 
    {
      pos: [3, 3, 7], 
      state: 3
    }, 
    {
      pos: [4, 3, 7], 
      state: 1
    }, 
    {
      pos: [1, 4, 1], 
      state: 15
    }, 
    {
      pos: [2, 4, 1], 
      state: 15
    }, 
    {
      pos: [3, 4, 1], 
      state: 15
    }, 
    {
      pos: [4, 4, 1], 
      state: 15
    }, 
    {
      pos: [5, 4, 1], 
      state: 15
    }, 
    {
      pos: [1, 4, 2], 
      state: 15
    }, 
    {
      pos: [2, 4, 2], 
      state: 15
    }, 
    {
      pos: [3, 4, 2], 
      state: 15
    }, 
    {
      pos: [4, 4, 2], 
      state: 15
    }, 
    {
      pos: [5, 4, 2], 
      state: 15
    }, 
    {
      pos: [1, 4, 3], 
      state: 4
    }, 
    {
      pos: [2, 4, 3], 
      state: 16
    }, 
    {
      pos: [3, 4, 3], 
      state: 4
    }, 
    {
      pos: [4, 4, 3], 
      state: 16
    }, 
    {
      pos: [5, 4, 3], 
      state: 4
    }, 
    {
      pos: [1, 4, 4], 
      state: 16
    }, 
    {
      pos: [5, 4, 4], 
      state: 16
    }, 
    {
      pos: [1, 4, 5], 
      state: 4
    }, 
    {
      pos: [2, 4, 5], 
      state: 16
    }, 
    {
      pos: [3, 4, 5], 
      state: 4
    }, 
    {
      pos: [4, 4, 5], 
      state: 16
    }, 
    {
      pos: [5, 4, 5], 
      state: 4
    }, 
    {
      pos: [1, 4, 6], 
      state: 15
    }, 
    {
      pos: [2, 4, 6], 
      state: 15
    }, 
    {
      pos: [3, 4, 6], 
      state: 15
    }, 
    {
      pos: [4, 4, 6], 
      state: 15
    }, 
    {
      pos: [5, 4, 6], 
      state: 15
    }, 
    {
      pos: [1, 4, 7], 
      state: 15
    }, 
    {
      pos: [2, 4, 7], 
      state: 15
    }, 
    {
      pos: [3, 4, 7], 
      state: 15
    }, 
    {
      pos: [4, 4, 7], 
      state: 15
    }, 
    {
      pos: [5, 4, 7], 
      state: 15
    }, 
    {
      pos: [1, 4, 0], 
      state: 9
    }, 
    {
      pos: [2, 4, 0], 
      state: 9
    }, 
    {
      pos: [3, 4, 0], 
      state: 9
    }, 
    {
      pos: [4, 4, 0], 
      state: 9
    }, 
    {
      pos: [5, 4, 0], 
      state: 9
    }, 
    {
      pos: [0, 4, 1], 
      state: 17
    }, 
    {
      pos: [6, 4, 1], 
      state: 18
    }, 
    {
      pos: [0, 4, 2], 
      state: 17
    }, 
    {
      pos: [6, 4, 2], 
      state: 18
    }, 
    {
      pos: [0, 4, 4], 
      state: 14
    }, 
    {
      pos: [6, 4, 4], 
      state: 11
    }, 
    {
      pos: [0, 4, 6], 
      state: 17
    }, 
    {
      pos: [6, 4, 6], 
      state: 18
    }, 
    {
      pos: [0, 4, 7], 
      state: 17
    }, 
    {
      pos: [6, 4, 7], 
      state: 18
    }, 
    {
      pos: [1, 4, 8], 
      state: 19
    }, 
    {
      pos: [2, 4, 8], 
      state: 19
    }, 
    {
      pos: [3, 4, 8], 
      state: 19
    }, 
    {
      pos: [4, 4, 8], 
      state: 19
    }, 
    {
      pos: [5, 4, 8], 
      state: 19
    }, 
    {
      pos: [1, 5, 3], 
      state: 1
    }, 
    {
      pos: [2, 5, 3], 
      state: 1
    }, 
    {
      pos: [3, 5, 3], 
      state: 1
    }, 
    {
      pos: [4, 5, 3], 
      state: 1
    }, 
    {
      pos: [5, 5, 3], 
      state: 1
    }, 
    {
      pos: [1, 5, 4], 
      state: 1
    }, 
    {
      pos: [5, 5, 4], 
      state: 1
    }, 
    {
      pos: [1, 5, 5], 
      state: 1
    }, 
    {
      pos: [2, 5, 5], 
      state: 1
    }, 
    {
      pos: [3, 5, 5], 
      state: 1
    }, 
    {
      pos: [4, 5, 5], 
      state: 1
    }, 
    {
      pos: [5, 5, 5], 
      state: 1
    }, 
    {
      pos: [1, 6, 3], 
      state: 15
    }, 
    {
      pos: [2, 6, 3], 
      state: 15
    }, 
    {
      pos: [3, 6, 3], 
      state: 15
    }, 
    {
      pos: [4, 6, 3], 
      state: 15
    }, 
    {
      pos: [5, 6, 3], 
      state: 15
    }, 
    {
      pos: [1, 6, 4], 
      state: 15
    }, 
    {
      pos: [2, 6, 4], 
      state: 15
    }, 
    {
      pos: [3, 6, 4], 
      state: 15
    }, 
    {
      pos: [4, 6, 4], 
      state: 15
    }, 
    {
      pos: [5, 6, 4], 
      state: 15
    }, 
    {
      pos: [1, 6, 5], 
      state: 15
    }, 
    {
      pos: [2, 6, 5], 
      state: 15
    }, 
    {
      pos: [3, 6, 5], 
      state: 15
    }, 
    {
      pos: [4, 6, 5], 
      state: 15
    }, 
    {
      pos: [5, 6, 5], 
      state: 15
    }, 
    {
      pos: [1, 6, 2], 
      state: 9
    }, 
    {
      pos: [2, 6, 2], 
      state: 9
    }, 
    {
      pos: [3, 6, 2], 
      state: 9
    }, 
    {
      pos: [4, 6, 2], 
      state: 9
    }, 
    {
      pos: [5, 6, 2], 
      state: 9
    }, 
    {
      pos: [0, 6, 3], 
      state: 17
    }, 
    {
      pos: [6, 6, 3], 
      state: 18
    }, 
    {
      pos: [0, 6, 4], 
      state: 17
    }, 
    {
      pos: [6, 6, 4], 
      state: 18
    }, 
    {
      pos: [0, 6, 5], 
      state: 17
    }, 
    {
      pos: [6, 6, 5], 
      state: 18
    }, 
    {
      pos: [1, 6, 6], 
      state: 19
    }, 
    {
      pos: [2, 6, 6], 
      state: 19
    }, 
    {
      pos: [3, 6, 6], 
      state: 19
    }, 
    {
      pos: [4, 6, 6], 
      state: 19
    }, 
    {
      pos: [5, 6, 6], 
      state: 19
    }
  ], 
  palette: [
    {
      Name: "minecraft:dirt"
    }, 
    {
      Properties: {
        axis: "y"
      }, 
      Name: "minecraft:acacia_wood"
    }, 
    {
      Properties: {
        axis: "z"
      }, 
      Name: "minecraft:acacia_wood"
    }, 
    {
      Properties: {
        axis: "x"
      }, 
      Name: "minecraft:acacia_wood"
    }, 
    {
      Name: "minecraft:red_terracotta"
    }, 
    {
      Name: "minecraft:grass_path"
    }, 
    {
      Properties: {
        has_bottle_0: "false", 
        has_bottle_1: "false", 
        has_bottle_2: "false"
      }, 
      Name: "minecraft:brewing_stand"
    }, 
    {
      Properties: {
        facing: "west"
      }, 
      Name: "minecraft:jigsaw"
    }, 
    {
      Properties: {
        hinge: "right", 
        half: "lower", 
        powered: "false", 
        facing: "west", 
        open: "false"
      }, 
      Name: "minecraft:acacia_door"
    }, 
    {
      Properties: {
        half: "bottom", 
        waterlogged: "false", 
        shape: "straight", 
        facing: "south"
      }, 
      Name: "minecraft:acacia_stairs"
    }, 
    {
      Properties: {
        east: "true", 
        waterlogged: "false", 
        south: "false", 
        north: "false", 
        west: "true"
      }, 
      Name: "minecraft:glass_pane"
    }, 
    {
      Properties: {
        facing: "east"
      }, 
      Name: "minecraft:wall_torch"
    }, 
    {
      Properties: {
        east: "false", 
        waterlogged: "false", 
        south: "true", 
        north: "true", 
        west: "false"
      }, 
      Name: "minecraft:glass_pane"
    }, 
    {
      Properties: {
        hinge: "right", 
        half: "upper", 
        powered: "false", 
        facing: "west", 
        open: "false"
      }, 
      Name: "minecraft:acacia_door"
    }, 
    {
      Properties: {
        facing: "west"
      }, 
      Name: "minecraft:wall_torch"
    }, 
    {
      Name: "minecraft:acacia_planks"
    }, 
    {
      Name: "minecraft:yellow_terracotta"
    }, 
    {
      Properties: {
        half: "bottom", 
        waterlogged: "false", 
        shape: "straight", 
        facing: "east"
      }, 
      Name: "minecraft:acacia_stairs"
    }, 
    {
      Properties: {
        half: "bottom", 
        waterlogged: "false", 
        shape: "straight", 
        facing: "west"
      }, 
      Name: "minecraft:acacia_stairs"
    }, 
    {
      Properties: {
        half: "bottom", 
        waterlogged: "false", 
        shape: "straight", 
        facing: "north"
      }, 
      Name: "minecraft:acacia_stairs"
    }
  ]
}
