{
  size: [7, 10, 7], 
  entities: [], 
  blocks: [
    {
      pos: [0, 0, 0], 
      state: 0
    }, 
    {
      pos: [1, 0, 0], 
      state: 0
    }, 
    {
      pos: [2, 0, 0], 
      state: 0
    }, 
    {
      pos: [3, 0, 0], 
      state: 0
    }, 
    {
      pos: [4, 0, 0], 
      state: 0
    }, 
    {
      pos: [5, 0, 0], 
      state: 0
    }, 
    {
      pos: [6, 0, 0], 
      state: 0
    }, 
    {
      pos: [0, 0, 1], 
      state: 0
    }, 
    {
      pos: [1, 0, 1], 
      state: 0
    }, 
    {
      pos: [2, 0, 1], 
      state: 1
    }, 
    {
      pos: [3, 0, 1], 
      state: 1
    }, 
    {
      pos: [4, 0, 1], 
      state: 1
    }, 
    {
      pos: [5, 0, 1], 
      state: 0
    }, 
    {
      pos: [6, 0, 1], 
      state: 0
    }, 
    {
      pos: [0, 0, 2], 
      state: 0
    }, 
    {
      pos: [1, 0, 2], 
      state: 1
    }, 
    {
      pos: [2, 0, 2], 
      state: 2
    }, 
    {
      pos: [3, 0, 2], 
      state: 2
    }, 
    {
      pos: [4, 0, 2], 
      state: 2
    }, 
    {
      pos: [5, 0, 2], 
      state: 1
    }, 
    {
      pos: [6, 0, 2], 
      state: 0
    }, 
    {
      pos: [0, 0, 3], 
      state: 0
    }, 
    {
      pos: [1, 0, 3], 
      state: 1
    }, 
    {
      pos: [2, 0, 3], 
      state: 2
    }, 
    {
      pos: [3, 0, 3], 
      state: 2
    }, 
    {
      pos: [5, 0, 3], 
      state: 2
    }, 
    {
      pos: [6, 0, 3], 
      state: 1
    }, 
    {
      pos: [0, 0, 4], 
      state: 0
    }, 
    {
      pos: [1, 0, 4], 
      state: 1
    }, 
    {
      pos: [2, 0, 4], 
      state: 2
    }, 
    {
      pos: [3, 0, 4], 
      state: 2
    }, 
    {
      pos: [4, 0, 4], 
      state: 2
    }, 
    {
      pos: [5, 0, 4], 
      state: 1
    }, 
    {
      pos: [6, 0, 4], 
      state: 0
    }, 
    {
      pos: [0, 0, 5], 
      state: 0
    }, 
    {
      pos: [1, 0, 5], 
      state: 0
    }, 
    {
      pos: [2, 0, 5], 
      state: 1
    }, 
    {
      pos: [3, 0, 5], 
      state: 1
    }, 
    {
      pos: [4, 0, 5], 
      state: 1
    }, 
    {
      pos: [5, 0, 5], 
      state: 0
    }, 
    {
      pos: [6, 0, 5], 
      state: 0
    }, 
    {
      pos: [0, 0, 6], 
      state: 0
    }, 
    {
      pos: [1, 0, 6], 
      state: 0
    }, 
    {
      pos: [2, 0, 6], 
      state: 0
    }, 
    {
      pos: [3, 0, 6], 
      state: 0
    }, 
    {
      pos: [4, 0, 6], 
      state: 0
    }, 
    {
      pos: [5, 0, 6], 
      state: 0
    }, 
    {
      pos: [6, 0, 6], 
      state: 0
    }, 
    {
      nbt: {
        target_pool: "minecraft:village/savanna/villagers", 
        final_state: "minecraft:acacia_planks", 
        id: "minecraft:jigsaw", 
        attachement_type: "minecraft:bottom"
      }, 
      pos: [4, 0, 3], 
      state: 3
    }, 
    {
      pos: [2, 1, 1], 
      state: 4
    }, 
    {
      pos: [3, 1, 1], 
      state: 5
    }, 
    {
      pos: [4, 1, 1], 
      state: 4
    }, 
    {
      pos: [1, 1, 2], 
      state: 4
    }, 
    {
      pos: [5, 1, 2], 
      state: 4
    }, 
    {
      pos: [1, 1, 3], 
      state: 6
    }, 
    {
      pos: [1, 1, 4], 
      state: 4
    }, 
    {
      pos: [5, 1, 4], 
      state: 4
    }, 
    {
      pos: [2, 1, 5], 
      state: 4
    }, 
    {
      pos: [3, 1, 5], 
      state: 5
    }, 
    {
      pos: [4, 1, 5], 
      state: 4
    }, 
    {
      nbt: {
        id: "minecraft:bed"
      }, 
      pos: [2, 1, 3], 
      state: 7
    }, 
    {
      nbt: {
        target_pool: "minecraft:empty", 
        final_state: "minecraft:structure_void", 
        id: "minecraft:jigsaw", 
        attachement_type: "minecraft:building_entrance"
      }, 
      pos: [6, 1, 3], 
      state: 8
    }, 
    {
      nbt: {
        id: "minecraft:bed"
      }, 
      pos: [2, 1, 4], 
      state: 9
    }, 
    {
      pos: [0, 1, 0], 
      state: 10
    }, 
    {
      pos: [1, 1, 0], 
      state: 11
    }, 
    {
      pos: [2, 1, 0], 
      state: 10
    }, 
    {
      pos: [3, 1, 0], 
      state: 12
    }, 
    {
      pos: [4, 1, 0], 
      state: 10
    }, 
    {
      pos: [5, 1, 0], 
      state: 11
    }, 
    {
      pos: [6, 1, 0], 
      state: 12
    }, 
    {
      pos: [0, 1, 1], 
      state: 11
    }, 
    {
      pos: [1, 1, 1], 
      state: 10
    }, 
    {
      pos: [5, 1, 1], 
      state: 10
    }, 
    {
      pos: [6, 1, 1], 
      state: 11
    }, 
    {
      pos: [0, 1, 2], 
      state: 10
    }, 
    {
      pos: [2, 1, 2], 
      state: 13
    }, 
    {
      pos: [3, 1, 2], 
      state: 10
    }, 
    {
      pos: [4, 1, 2], 
      state: 10
    }, 
    {
      pos: [6, 1, 2], 
      state: 12
    }, 
    {
      pos: [0, 1, 3], 
      state: 10
    }, 
    {
      pos: [3, 1, 3], 
      state: 10
    }, 
    {
      pos: [4, 1, 3], 
      state: 10
    }, 
    {
      pos: [5, 1, 3], 
      state: 14
    }, 
    {
      pos: [0, 1, 4], 
      state: 10
    }, 
    {
      pos: [3, 1, 4], 
      state: 10
    }, 
    {
      pos: [4, 1, 4], 
      state: 10
    }, 
    {
      pos: [6, 1, 4], 
      state: 12
    }, 
    {
      pos: [0, 1, 5], 
      state: 11
    }, 
    {
      pos: [1, 1, 5], 
      state: 10
    }, 
    {
      pos: [5, 1, 5], 
      state: 12
    }, 
    {
      pos: [6, 1, 5], 
      state: 11
    }, 
    {
      pos: [0, 1, 6], 
      state: 12
    }, 
    {
      pos: [1, 1, 6], 
      state: 11
    }, 
    {
      pos: [2, 1, 6], 
      state: 12
    }, 
    {
      pos: [3, 1, 6], 
      state: 10
    }, 
    {
      pos: [4, 1, 6], 
      state: 12
    }, 
    {
      pos: [5, 1, 6], 
      state: 11
    }, 
    {
      pos: [6, 1, 6], 
      state: 12
    }, 
    {
      pos: [2, 2, 1], 
      state: 4
    }, 
    {
      pos: [4, 2, 1], 
      state: 4
    }, 
    {
      pos: [1, 2, 2], 
      state: 4
    }, 
    {
      pos: [5, 2, 2], 
      state: 4
    }, 
    {
      pos: [1, 2, 4], 
      state: 4
    }, 
    {
      pos: [5, 2, 4], 
      state: 4
    }, 
    {
      pos: [2, 2, 5], 
      state: 4
    }, 
    {
      pos: [4, 2, 5], 
      state: 4
    }, 
    {
      pos: [0, 2, 0], 
      state: 10
    }, 
    {
      pos: [1, 2, 0], 
      state: 11
    }, 
    {
      pos: [2, 2, 0], 
      state: 10
    }, 
    {
      pos: [3, 2, 0], 
      state: 10
    }, 
    {
      pos: [4, 2, 0], 
      state: 10
    }, 
    {
      pos: [5, 2, 0], 
      state: 11
    }, 
    {
      pos: [6, 2, 0], 
      state: 10
    }, 
    {
      pos: [0, 2, 1], 
      state: 11
    }, 
    {
      pos: [1, 2, 1], 
      state: 10
    }, 
    {
      pos: [3, 2, 1], 
      state: 15
    }, 
    {
      pos: [5, 2, 1], 
      state: 10
    }, 
    {
      pos: [6, 2, 1], 
      state: 11
    }, 
    {
      pos: [0, 2, 2], 
      state: 10
    }, 
    {
      pos: [2, 2, 2], 
      state: 16
    }, 
    {
      pos: [3, 2, 2], 
      state: 10
    }, 
    {
      pos: [4, 2, 2], 
      state: 10
    }, 
    {
      pos: [6, 2, 2], 
      state: 10
    }, 
    {
      pos: [0, 2, 3], 
      state: 10
    }, 
    {
      pos: [1, 2, 3], 
      state: 17
    }, 
    {
      pos: [2, 2, 3], 
      state: 10
    }, 
    {
      pos: [3, 2, 3], 
      state: 10
    }, 
    {
      pos: [4, 2, 3], 
      state: 10
    }, 
    {
      pos: [5, 2, 3], 
      state: 18
    }, 
    {
      pos: [6, 2, 3], 
      state: 10
    }, 
    {
      pos: [0, 2, 4], 
      state: 10
    }, 
    {
      pos: [2, 2, 4], 
      state: 10
    }, 
    {
      pos: [3, 2, 4], 
      state: 10
    }, 
    {
      pos: [4, 2, 4], 
      state: 10
    }, 
    {
      pos: [6, 2, 4], 
      state: 10
    }, 
    {
      pos: [0, 2, 5], 
      state: 11
    }, 
    {
      pos: [1, 2, 5], 
      state: 10
    }, 
    {
      pos: [3, 2, 5], 
      state: 15
    }, 
    {
      pos: [5, 2, 5], 
      state: 10
    }, 
    {
      pos: [6, 2, 5], 
      state: 11
    }, 
    {
      pos: [0, 2, 6], 
      state: 10
    }, 
    {
      pos: [1, 2, 6], 
      state: 11
    }, 
    {
      pos: [2, 2, 6], 
      state: 10
    }, 
    {
      pos: [3, 2, 6], 
      state: 10
    }, 
    {
      pos: [4, 2, 6], 
      state: 10
    }, 
    {
      pos: [5, 2, 6], 
      state: 11
    }, 
    {
      pos: [6, 2, 6], 
      state: 10
    }, 
    {
      pos: [2, 3, 1], 
      state: 4
    }, 
    {
      pos: [3, 3, 1], 
      state: 5
    }, 
    {
      pos: [4, 3, 1], 
      state: 4
    }, 
    {
      pos: [1, 3, 2], 
      state: 4
    }, 
    {
      pos: [5, 3, 2], 
      state: 4
    }, 
    {
      pos: [1, 3, 3], 
      state: 6
    }, 
    {
      pos: [5, 3, 3], 
      state: 6
    }, 
    {
      pos: [1, 3, 4], 
      state: 4
    }, 
    {
      pos: [5, 3, 4], 
      state: 4
    }, 
    {
      pos: [2, 3, 5], 
      state: 4
    }, 
    {
      pos: [3, 3, 5], 
      state: 5
    }, 
    {
      pos: [4, 3, 5], 
      state: 4
    }, 
    {
      pos: [0, 3, 0], 
      state: 10
    }, 
    {
      pos: [1, 3, 0], 
      state: 11
    }, 
    {
      pos: [2, 3, 0], 
      state: 10
    }, 
    {
      pos: [3, 3, 0], 
      state: 10
    }, 
    {
      pos: [4, 3, 0], 
      state: 10
    }, 
    {
      pos: [5, 3, 0], 
      state: 11
    }, 
    {
      pos: [6, 3, 0], 
      state: 10
    }, 
    {
      pos: [0, 3, 1], 
      state: 11
    }, 
    {
      pos: [1, 3, 1], 
      state: 10
    }, 
    {
      pos: [5, 3, 1], 
      state: 10
    }, 
    {
      pos: [6, 3, 1], 
      state: 11
    }, 
    {
      pos: [0, 3, 2], 
      state: 10
    }, 
    {
      pos: [2, 3, 2], 
      state: 10
    }, 
    {
      pos: [3, 3, 2], 
      state: 10
    }, 
    {
      pos: [4, 3, 2], 
      state: 10
    }, 
    {
      pos: [6, 3, 2], 
      state: 10
    }, 
    {
      pos: [0, 3, 3], 
      state: 10
    }, 
    {
      pos: [2, 3, 3], 
      state: 19
    }, 
    {
      pos: [3, 3, 3], 
      state: 10
    }, 
    {
      pos: [4, 3, 3], 
      state: 20
    }, 
    {
      pos: [6, 3, 3], 
      state: 19
    }, 
    {
      pos: [0, 3, 4], 
      state: 10
    }, 
    {
      pos: [2, 3, 4], 
      state: 10
    }, 
    {
      pos: [3, 3, 4], 
      state: 10
    }, 
    {
      pos: [4, 3, 4], 
      state: 10
    }, 
    {
      pos: [6, 3, 4], 
      state: 10
    }, 
    {
      pos: [0, 3, 5], 
      state: 11
    }, 
    {
      pos: [1, 3, 5], 
      state: 10
    }, 
    {
      pos: [5, 3, 5], 
      state: 10
    }, 
    {
      pos: [6, 3, 5], 
      state: 11
    }, 
    {
      pos: [0, 3, 6], 
      state: 10
    }, 
    {
      pos: [1, 3, 6], 
      state: 11
    }, 
    {
      pos: [2, 3, 6], 
      state: 10
    }, 
    {
      pos: [3, 3, 6], 
      state: 10
    }, 
    {
      pos: [4, 3, 6], 
      state: 10
    }, 
    {
      pos: [5, 3, 6], 
      state: 11
    }, 
    {
      pos: [6, 3, 6], 
      state: 10
    }, 
    {
      pos: [2, 4, 1], 
      state: 21
    }, 
    {
      pos: [3, 4, 1], 
      state: 21
    }, 
    {
      pos: [4, 4, 1], 
      state: 21
    }, 
    {
      pos: [1, 4, 2], 
      state: 21
    }, 
    {
      pos: [5, 4, 2], 
      state: 21
    }, 
    {
      pos: [1, 4, 3], 
      state: 21
    }, 
    {
      pos: [5, 4, 3], 
      state: 21
    }, 
    {
      pos: [1, 4, 4], 
      state: 21
    }, 
    {
      pos: [5, 4, 4], 
      state: 21
    }, 
    {
      pos: [2, 4, 5], 
      state: 21
    }, 
    {
      pos: [3, 4, 5], 
      state: 21
    }, 
    {
      pos: [4, 4, 5], 
      state: 21
    }, 
    {
      pos: [0, 4, 0], 
      state: 10
    }, 
    {
      pos: [1, 4, 0], 
      state: 11
    }, 
    {
      pos: [2, 4, 0], 
      state: 10
    }, 
    {
      pos: [3, 4, 0], 
      state: 10
    }, 
    {
      pos: [4, 4, 0], 
      state: 10
    }, 
    {
      pos: [5, 4, 0], 
      state: 11
    }, 
    {
      pos: [6, 4, 0], 
      state: 10
    }, 
    {
      pos: [0, 4, 1], 
      state: 11
    }, 
    {
      pos: [1, 4, 1], 
      state: 10
    }, 
    {
      pos: [5, 4, 1], 
      state: 10
    }, 
    {
      pos: [6, 4, 1], 
      state: 11
    }, 
    {
      pos: [0, 4, 2], 
      state: 10
    }, 
    {
      pos: [2, 4, 2], 
      state: 10
    }, 
    {
      pos: [3, 4, 2], 
      state: 10
    }, 
    {
      pos: [4, 4, 2], 
      state: 10
    }, 
    {
      pos: [6, 4, 2], 
      state: 10
    }, 
    {
      pos: [0, 4, 3], 
      state: 10
    }, 
    {
      pos: [2, 4, 3], 
      state: 10
    }, 
    {
      pos: [3, 4, 3], 
      state: 10
    }, 
    {
      pos: [4, 4, 3], 
      state: 10
    }, 
    {
      pos: [6, 4, 3], 
      state: 10
    }, 
    {
      pos: [0, 4, 4], 
      state: 10
    }, 
    {
      pos: [2, 4, 4], 
      state: 10
    }, 
    {
      pos: [3, 4, 4], 
      state: 10
    }, 
    {
      pos: [4, 4, 4], 
      state: 10
    }, 
    {
      pos: [6, 4, 4], 
      state: 10
    }, 
    {
      pos: [0, 4, 5], 
      state: 11
    }, 
    {
      pos: [1, 4, 5], 
      state: 10
    }, 
    {
      pos: [5, 4, 5], 
      state: 10
    }, 
    {
      pos: [6, 4, 5], 
      state: 11
    }, 
    {
      pos: [0, 4, 6], 
      state: 10
    }, 
    {
      pos: [1, 4, 6], 
      state: 11
    }, 
    {
      pos: [2, 4, 6], 
      state: 10
    }, 
    {
      pos: [3, 4, 6], 
      state: 10
    }, 
    {
      pos: [4, 4, 6], 
      state: 10
    }, 
    {
      pos: [5, 4, 6], 
      state: 11
    }, 
    {
      pos: [6, 4, 6], 
      state: 10
    }, 
    {
      pos: [2, 5, 2], 
      state: 21
    }, 
    {
      pos: [3, 5, 2], 
      state: 21
    }, 
    {
      pos: [4, 5, 2], 
      state: 21
    }, 
    {
      pos: [2, 5, 3], 
      state: 21
    }, 
    {
      pos: [4, 5, 3], 
      state: 21
    }, 
    {
      pos: [2, 5, 4], 
      state: 21
    }, 
    {
      pos: [3, 5, 4], 
      state: 21
    }, 
    {
      pos: [4, 5, 4], 
      state: 21
    }, 
    {
      pos: [0, 5, 0], 
      state: 10
    }, 
    {
      pos: [1, 5, 0], 
      state: 22
    }, 
    {
      pos: [2, 5, 0], 
      state: 22
    }, 
    {
      pos: [3, 5, 0], 
      state: 22
    }, 
    {
      pos: [4, 5, 0], 
      state: 22
    }, 
    {
      pos: [5, 5, 0], 
      state: 22
    }, 
    {
      pos: [6, 5, 0], 
      state: 10
    }, 
    {
      pos: [0, 5, 1], 
      state: 22
    }, 
    {
      pos: [1, 5, 1], 
      state: 22
    }, 
    {
      pos: [2, 5, 1], 
      state: 22
    }, 
    {
      pos: [3, 5, 1], 
      state: 22
    }, 
    {
      pos: [4, 5, 1], 
      state: 22
    }, 
    {
      pos: [5, 5, 1], 
      state: 22
    }, 
    {
      pos: [6, 5, 1], 
      state: 22
    }, 
    {
      pos: [0, 5, 2], 
      state: 22
    }, 
    {
      pos: [1, 5, 2], 
      state: 22
    }, 
    {
      pos: [5, 5, 2], 
      state: 22
    }, 
    {
      pos: [6, 5, 2], 
      state: 22
    }, 
    {
      pos: [0, 5, 3], 
      state: 22
    }, 
    {
      pos: [1, 5, 3], 
      state: 22
    }, 
    {
      pos: [3, 5, 3], 
      state: 10
    }, 
    {
      pos: [5, 5, 3], 
      state: 22
    }, 
    {
      pos: [6, 5, 3], 
      state: 22
    }, 
    {
      pos: [0, 5, 4], 
      state: 22
    }, 
    {
      pos: [1, 5, 4], 
      state: 22
    }, 
    {
      pos: [5, 5, 4], 
      state: 22
    }, 
    {
      pos: [6, 5, 4], 
      state: 22
    }, 
    {
      pos: [0, 5, 5], 
      state: 22
    }, 
    {
      pos: [1, 5, 5], 
      state: 22
    }, 
    {
      pos: [2, 5, 5], 
      state: 22
    }, 
    {
      pos: [3, 5, 5], 
      state: 22
    }, 
    {
      pos: [4, 5, 5], 
      state: 22
    }, 
    {
      pos: [5, 5, 5], 
      state: 22
    }, 
    {
      pos: [6, 5, 5], 
      state: 22
    }, 
    {
      pos: [0, 5, 6], 
      state: 10
    }, 
    {
      pos: [1, 5, 6], 
      state: 22
    }, 
    {
      pos: [2, 5, 6], 
      state: 22
    }, 
    {
      pos: [3, 5, 6], 
      state: 22
    }, 
    {
      pos: [4, 5, 6], 
      state: 22
    }, 
    {
      pos: [5, 5, 6], 
      state: 22
    }, 
    {
      pos: [6, 5, 6], 
      state: 10
    }, 
    {
      pos: [2, 6, 2], 
      state: 21
    }, 
    {
      pos: [4, 6, 2], 
      state: 21
    }, 
    {
      pos: [2, 6, 4], 
      state: 21
    }, 
    {
      pos: [4, 6, 4], 
      state: 21
    }, 
    {
      pos: [0, 6, 0], 
      state: 10
    }, 
    {
      pos: [1, 6, 0], 
      state: 10
    }, 
    {
      pos: [2, 6, 0], 
      state: 10
    }, 
    {
      pos: [3, 6, 0], 
      state: 10
    }, 
    {
      pos: [4, 6, 0], 
      state: 10
    }, 
    {
      pos: [5, 6, 0], 
      state: 10
    }, 
    {
      pos: [6, 6, 0], 
      state: 10
    }, 
    {
      pos: [0, 6, 1], 
      state: 10
    }, 
    {
      pos: [1, 6, 1], 
      state: 10
    }, 
    {
      pos: [2, 6, 1], 
      state: 10
    }, 
    {
      pos: [3, 6, 1], 
      state: 10
    }, 
    {
      pos: [4, 6, 1], 
      state: 10
    }, 
    {
      pos: [5, 6, 1], 
      state: 10
    }, 
    {
      pos: [6, 6, 1], 
      state: 10
    }, 
    {
      pos: [0, 6, 2], 
      state: 10
    }, 
    {
      pos: [1, 6, 2], 
      state: 10
    }, 
    {
      pos: [3, 6, 2], 
      state: 23
    }, 
    {
      pos: [5, 6, 2], 
      state: 10
    }, 
    {
      pos: [6, 6, 2], 
      state: 10
    }, 
    {
      pos: [0, 6, 3], 
      state: 10
    }, 
    {
      pos: [1, 6, 3], 
      state: 10
    }, 
    {
      pos: [2, 6, 3], 
      state: 24
    }, 
    {
      pos: [3, 6, 3], 
      state: 10
    }, 
    {
      pos: [4, 6, 3], 
      state: 24
    }, 
    {
      pos: [5, 6, 3], 
      state: 10
    }, 
    {
      pos: [6, 6, 3], 
      state: 10
    }, 
    {
      pos: [0, 6, 4], 
      state: 10
    }, 
    {
      pos: [1, 6, 4], 
      state: 10
    }, 
    {
      pos: [3, 6, 4], 
      state: 23
    }, 
    {
      pos: [5, 6, 4], 
      state: 10
    }, 
    {
      pos: [6, 6, 4], 
      state: 10
    }, 
    {
      pos: [0, 6, 5], 
      state: 10
    }, 
    {
      pos: [1, 6, 5], 
      state: 10
    }, 
    {
      pos: [2, 6, 5], 
      state: 10
    }, 
    {
      pos: [3, 6, 5], 
      state: 10
    }, 
    {
      pos: [4, 6, 5], 
      state: 10
    }, 
    {
      pos: [5, 6, 5], 
      state: 10
    }, 
    {
      pos: [6, 6, 5], 
      state: 10
    }, 
    {
      pos: [0, 6, 6], 
      state: 10
    }, 
    {
      pos: [1, 6, 6], 
      state: 10
    }, 
    {
      pos: [2, 6, 6], 
      state: 10
    }, 
    {
      pos: [3, 6, 6], 
      state: 10
    }, 
    {
      pos: [4, 6, 6], 
      state: 10
    }, 
    {
      pos: [5, 6, 6], 
      state: 10
    }, 
    {
      pos: [6, 6, 6], 
      state: 10
    }, 
    {
      pos: [2, 7, 2], 
      state: 21
    }, 
    {
      pos: [3, 7, 2], 
      state: 21
    }, 
    {
      pos: [4, 7, 2], 
      state: 21
    }, 
    {
      pos: [2, 7, 3], 
      state: 21
    }, 
    {
      pos: [4, 7, 3], 
      state: 21
    }, 
    {
      pos: [2, 7, 4], 
      state: 21
    }, 
    {
      pos: [3, 7, 4], 
      state: 21
    }, 
    {
      pos: [4, 7, 4], 
      state: 21
    }, 
    {
      pos: [0, 7, 0], 
      state: 10
    }, 
    {
      pos: [1, 7, 0], 
      state: 10
    }, 
    {
      pos: [2, 7, 0], 
      state: 10
    }, 
    {
      pos: [3, 7, 0], 
      state: 10
    }, 
    {
      pos: [4, 7, 0], 
      state: 10
    }, 
    {
      pos: [5, 7, 0], 
      state: 10
    }, 
    {
      pos: [6, 7, 0], 
      state: 10
    }, 
    {
      pos: [0, 7, 1], 
      state: 10
    }, 
    {
      pos: [1, 7, 1], 
      state: 10
    }, 
    {
      pos: [2, 7, 1], 
      state: 10
    }, 
    {
      pos: [3, 7, 1], 
      state: 10
    }, 
    {
      pos: [4, 7, 1], 
      state: 10
    }, 
    {
      pos: [5, 7, 1], 
      state: 10
    }, 
    {
      pos: [6, 7, 1], 
      state: 10
    }, 
    {
      pos: [0, 7, 2], 
      state: 10
    }, 
    {
      pos: [1, 7, 2], 
      state: 10
    }, 
    {
      pos: [5, 7, 2], 
      state: 10
    }, 
    {
      pos: [6, 7, 2], 
      state: 10
    }, 
    {
      pos: [0, 7, 3], 
      state: 10
    }, 
    {
      pos: [1, 7, 3], 
      state: 10
    }, 
    {
      pos: [3, 7, 3], 
      state: 10
    }, 
    {
      pos: [5, 7, 3], 
      state: 10
    }, 
    {
      pos: [6, 7, 3], 
      state: 10
    }, 
    {
      pos: [0, 7, 4], 
      state: 10
    }, 
    {
      pos: [1, 7, 4], 
      state: 10
    }, 
    {
      pos: [5, 7, 4], 
      state: 10
    }, 
    {
      pos: [6, 7, 4], 
      state: 10
    }, 
    {
      pos: [0, 7, 5], 
      state: 10
    }, 
    {
      pos: [1, 7, 5], 
      state: 10
    }, 
    {
      pos: [2, 7, 5], 
      state: 10
    }, 
    {
      pos: [3, 7, 5], 
      state: 10
    }, 
    {
      pos: [4, 7, 5], 
      state: 10
    }, 
    {
      pos: [5, 7, 5], 
      state: 10
    }, 
    {
      pos: [6, 7, 5], 
      state: 10
    }, 
    {
      pos: [0, 7, 6], 
      state: 10
    }, 
    {
      pos: [1, 7, 6], 
      state: 10
    }, 
    {
      pos: [2, 7, 6], 
      state: 10
    }, 
    {
      pos: [3, 7, 6], 
      state: 10
    }, 
    {
      pos: [4, 7, 6], 
      state: 10
    }, 
    {
      pos: [5, 7, 6], 
      state: 10
    }, 
    {
      pos: [6, 7, 6], 
      state: 10
    }, 
    {
      pos: [2, 8, 2], 
      state: 2
    }, 
    {
      pos: [3, 8, 2], 
      state: 2
    }, 
    {
      pos: [4, 8, 2], 
      state: 2
    }, 
    {
      pos: [2, 8, 3], 
      state: 2
    }, 
    {
      pos: [3, 8, 3], 
      state: 2
    }, 
    {
      pos: [4, 8, 3], 
      state: 2
    }, 
    {
      pos: [2, 8, 4], 
      state: 2
    }, 
    {
      pos: [3, 8, 4], 
      state: 2
    }, 
    {
      pos: [4, 8, 4], 
      state: 2
    }, 
    {
      pos: [0, 8, 0], 
      state: 10
    }, 
    {
      pos: [1, 8, 0], 
      state: 10
    }, 
    {
      pos: [2, 8, 0], 
      state: 10
    }, 
    {
      pos: [3, 8, 0], 
      state: 10
    }, 
    {
      pos: [4, 8, 0], 
      state: 10
    }, 
    {
      pos: [5, 8, 0], 
      state: 10
    }, 
    {
      pos: [6, 8, 0], 
      state: 10
    }, 
    {
      pos: [0, 8, 1], 
      state: 10
    }, 
    {
      pos: [1, 8, 1], 
      state: 25
    }, 
    {
      pos: [2, 8, 1], 
      state: 26
    }, 
    {
      pos: [3, 8, 1], 
      state: 26
    }, 
    {
      pos: [4, 8, 1], 
      state: 26
    }, 
    {
      pos: [5, 8, 1], 
      state: 27
    }, 
    {
      pos: [6, 8, 1], 
      state: 10
    }, 
    {
      pos: [0, 8, 2], 
      state: 10
    }, 
    {
      pos: [1, 8, 2], 
      state: 28
    }, 
    {
      pos: [5, 8, 2], 
      state: 29
    }, 
    {
      pos: [6, 8, 2], 
      state: 10
    }, 
    {
      pos: [0, 8, 3], 
      state: 10
    }, 
    {
      pos: [1, 8, 3], 
      state: 28
    }, 
    {
      pos: [5, 8, 3], 
      state: 29
    }, 
    {
      pos: [6, 8, 3], 
      state: 10
    }, 
    {
      pos: [0, 8, 4], 
      state: 10
    }, 
    {
      pos: [1, 8, 4], 
      state: 28
    }, 
    {
      pos: [5, 8, 4], 
      state: 29
    }, 
    {
      pos: [6, 8, 4], 
      state: 10
    }, 
    {
      pos: [0, 8, 5], 
      state: 10
    }, 
    {
      pos: [1, 8, 5], 
      state: 30
    }, 
    {
      pos: [2, 8, 5], 
      state: 31
    }, 
    {
      pos: [3, 8, 5], 
      state: 31
    }, 
    {
      pos: [4, 8, 5], 
      state: 31
    }, 
    {
      pos: [5, 8, 5], 
      state: 32
    }, 
    {
      pos: [6, 8, 5], 
      state: 10
    }, 
    {
      pos: [0, 8, 6], 
      state: 10
    }, 
    {
      pos: [1, 8, 6], 
      state: 10
    }, 
    {
      pos: [2, 8, 6], 
      state: 10
    }, 
    {
      pos: [3, 8, 6], 
      state: 10
    }, 
    {
      pos: [4, 8, 6], 
      state: 10
    }, 
    {
      pos: [5, 8, 6], 
      state: 10
    }, 
    {
      pos: [6, 8, 6], 
      state: 10
    }, 
    {
      pos: [3, 9, 3], 
      state: 2
    }, 
    {
      pos: [0, 9, 0], 
      state: 10
    }, 
    {
      pos: [1, 9, 0], 
      state: 10
    }, 
    {
      pos: [2, 9, 0], 
      state: 10
    }, 
    {
      pos: [3, 9, 0], 
      state: 10
    }, 
    {
      pos: [4, 9, 0], 
      state: 10
    }, 
    {
      pos: [5, 9, 0], 
      state: 10
    }, 
    {
      pos: [6, 9, 0], 
      state: 10
    }, 
    {
      pos: [0, 9, 1], 
      state: 10
    }, 
    {
      pos: [1, 9, 1], 
      state: 10
    }, 
    {
      pos: [2, 9, 1], 
      state: 10
    }, 
    {
      pos: [3, 9, 1], 
      state: 10
    }, 
    {
      pos: [4, 9, 1], 
      state: 10
    }, 
    {
      pos: [5, 9, 1], 
      state: 10
    }, 
    {
      pos: [6, 9, 1], 
      state: 10
    }, 
    {
      pos: [0, 9, 2], 
      state: 10
    }, 
    {
      pos: [1, 9, 2], 
      state: 10
    }, 
    {
      pos: [2, 9, 2], 
      state: 33
    }, 
    {
      pos: [3, 9, 2], 
      state: 26
    }, 
    {
      pos: [4, 9, 2], 
      state: 34
    }, 
    {
      pos: [5, 9, 2], 
      state: 10
    }, 
    {
      pos: [6, 9, 2], 
      state: 10
    }, 
    {
      pos: [0, 9, 3], 
      state: 10
    }, 
    {
      pos: [1, 9, 3], 
      state: 10
    }, 
    {
      pos: [2, 9, 3], 
      state: 28
    }, 
    {
      pos: [4, 9, 3], 
      state: 29
    }, 
    {
      pos: [5, 9, 3], 
      state: 10
    }, 
    {
      pos: [6, 9, 3], 
      state: 10
    }, 
    {
      pos: [0, 9, 4], 
      state: 10
    }, 
    {
      pos: [1, 9, 4], 
      state: 10
    }, 
    {
      pos: [2, 9, 4], 
      state: 35
    }, 
    {
      pos: [3, 9, 4], 
      state: 31
    }, 
    {
      pos: [4, 9, 4], 
      state: 36
    }, 
    {
      pos: [5, 9, 4], 
      state: 10
    }, 
    {
      pos: [6, 9, 4], 
      state: 10
    }, 
    {
      pos: [0, 9, 5], 
      state: 10
    }, 
    {
      pos: [1, 9, 5], 
      state: 10
    }, 
    {
      pos: [2, 9, 5], 
      state: 10
    }, 
    {
      pos: [3, 9, 5], 
      state: 10
    }, 
    {
      pos: [4, 9, 5], 
      state: 10
    }, 
    {
      pos: [5, 9, 5], 
      state: 10
    }, 
    {
      pos: [6, 9, 5], 
      state: 10
    }, 
    {
      pos: [0, 9, 6], 
      state: 10
    }, 
    {
      pos: [1, 9, 6], 
      state: 10
    }, 
    {
      pos: [2, 9, 6], 
      state: 10
    }, 
    {
      pos: [3, 9, 6], 
      state: 10
    }, 
    {
      pos: [4, 9, 6], 
      state: 10
    }, 
    {
      pos: [5, 9, 6], 
      state: 10
    }, 
    {
      pos: [6, 9, 6], 
      state: 10
    }
  ], 
  palette: [
    {
      Properties: {
        snowy: "false"
      }, 
      Name: "minecraft:grass_block"
    }, 
    {
      Name: "minecraft:dirt"
    }, 
    {
      Name: "minecraft:acacia_planks"
    }, 
    {
      Properties: {
        facing: "up"
      }, 
      Name: "minecraft:jigsaw"
    }, 
    {
      Properties: {
        axis: "y"
      }, 
      Name: "minecraft:acacia_log"
    }, 
    {
      Properties: {
        axis: "x"
      }, 
      Name: "minecraft:acacia_log"
    }, 
    {
      Properties: {
        axis: "z"
      }, 
      Name: "minecraft:acacia_log"
    }, 
    {
      Properties: {
        part: "foot", 
        facing: "south", 
        occupied: "false"
      }, 
      Name: "minecraft:orange_bed"
    }, 
    {
      Properties: {
        facing: "east"
      }, 
      Name: "minecraft:jigsaw"
    }, 
    {
      Properties: {
        part: "head", 
        facing: "south", 
        occupied: "false"
      }, 
      Name: "minecraft:orange_bed"
    }, 
    {
      Name: "minecraft:air"
    }, 
    {
      Properties: {
        east: "false", 
        waterlogged: "false", 
        south: "false", 
        north: "false", 
        west: "false"
      }, 
      Name: "minecraft:acacia_fence"
    }, 
    {
      Name: "minecraft:grass"
    }, 
    {
      Properties: {
        east: "false", 
        waterlogged: "false", 
        south: "false", 
        north: "true", 
        west: "true"
      }, 
      Name: "minecraft:acacia_fence"
    }, 
    {
      Properties: {
        hinge: "left", 
        half: "lower", 
        powered: "false", 
        facing: "east", 
        open: "false"
      }, 
      Name: "minecraft:acacia_door"
    }, 
    {
      Properties: {
        east: "true", 
        waterlogged: "false", 
        south: "false", 
        north: "false", 
        west: "true"
      }, 
      Name: "minecraft:glass_pane"
    }, 
    {
      Properties: {
        powered: "false"
      }, 
      Name: "minecraft:acacia_pressure_plate"
    }, 
    {
      Properties: {
        east: "false", 
        waterlogged: "false", 
        south: "true", 
        north: "true", 
        west: "false"
      }, 
      Name: "minecraft:glass_pane"
    }, 
    {
      Properties: {
        hinge: "left", 
        half: "upper", 
        powered: "false", 
        facing: "east", 
        open: "false"
      }, 
      Name: "minecraft:acacia_door"
    }, 
    {
      Properties: {
        facing: "east"
      }, 
      Name: "minecraft:wall_torch"
    }, 
    {
      Properties: {
        facing: "west"
      }, 
      Name: "minecraft:wall_torch"
    }, 
    {
      Name: "minecraft:yellow_terracotta"
    }, 
    {
      Properties: {
        waterlogged: "false", 
        type: "bottom"
      }, 
      Name: "minecraft:acacia_slab"
    }, 
    {
      Properties: {
        east: "true", 
        waterlogged: "false", 
        south: "false", 
        north: "false", 
        west: "true"
      }, 
      Name: "minecraft:acacia_fence"
    }, 
    {
      Properties: {
        east: "false", 
        waterlogged: "false", 
        south: "true", 
        north: "true", 
        west: "false"
      }, 
      Name: "minecraft:acacia_fence"
    }, 
    {
      Properties: {
        half: "bottom", 
        waterlogged: "false", 
        shape: "outer_left", 
        facing: "south"
      }, 
      Name: "minecraft:acacia_stairs"
    }, 
    {
      Properties: {
        half: "bottom", 
        waterlogged: "false", 
        shape: "straight", 
        facing: "south"
      }, 
      Name: "minecraft:acacia_stairs"
    }, 
    {
      Properties: {
        half: "bottom", 
        waterlogged: "false", 
        shape: "outer_left", 
        facing: "west"
      }, 
      Name: "minecraft:acacia_stairs"
    }, 
    {
      Properties: {
        half: "bottom", 
        waterlogged: "false", 
        shape: "straight", 
        facing: "east"
      }, 
      Name: "minecraft:acacia_stairs"
    }, 
    {
      Properties: {
        half: "bottom", 
        waterlogged: "false", 
        shape: "straight", 
        facing: "west"
      }, 
      Name: "minecraft:acacia_stairs"
    }, 
    {
      Properties: {
        half: "bottom", 
        waterlogged: "false", 
        shape: "outer_left", 
        facing: "east"
      }, 
      Name: "minecraft:acacia_stairs"
    }, 
    {
      Properties: {
        half: "bottom", 
        waterlogged: "false", 
        shape: "straight", 
        facing: "north"
      }, 
      Name: "minecraft:acacia_stairs"
    }, 
    {
      Properties: {
        half: "bottom", 
        waterlogged: "false", 
        shape: "outer_left", 
        facing: "north"
      }, 
      Name: "minecraft:acacia_stairs"
    }, 
    {
      Properties: {
        half: "bottom", 
        waterlogged: "false", 
        shape: "outer_right", 
        facing: "east"
      }, 
      Name: "minecraft:acacia_stairs"
    }, 
    {
      Properties: {
        half: "bottom", 
        waterlogged: "false", 
        shape: "outer_right", 
        facing: "south"
      }, 
      Name: "minecraft:acacia_stairs"
    }, 
    {
      Properties: {
        half: "bottom", 
        waterlogged: "false", 
        shape: "outer_right", 
        facing: "north"
      }, 
      Name: "minecraft:acacia_stairs"
    }, 
    {
      Properties: {
        half: "bottom", 
        waterlogged: "false", 
        shape: "outer_right", 
        facing: "west"
      }, 
      Name: "minecraft:acacia_stairs"
    }
  ]
}
