{
  size: [7, 7, 7], 
  entities: [], 
  blocks: [
    {
      pos: [2, 0, 2], 
      state: 0
    }, 
    {
      pos: [2, 0, 4], 
      state: 0
    }, 
    {
      pos: [4, 0, 2], 
      state: 0
    }, 
    {
      pos: [4, 0, 4], 
      state: 0
    }, 
    {
      pos: [2, 4, 2], 
      state: 1
    }, 
    {
      pos: [2, 4, 3], 
      state: 1
    }, 
    {
      pos: [2, 4, 4], 
      state: 1
    }, 
    {
      pos: [3, 4, 2], 
      state: 2
    }, 
    {
      pos: [3, 4, 3], 
      state: 1
    }, 
    {
      pos: [3, 4, 4], 
      state: 2
    }, 
    {
      pos: [4, 4, 2], 
      state: 2
    }, 
    {
      pos: [4, 4, 3], 
      state: 1
    }, 
    {
      pos: [4, 4, 4], 
      state: 1
    }, 
    {
      pos: [3, 5, 3], 
      state: 1
    }, 
    {
      pos: [0, 0, 2], 
      state: 3
    }, 
    {
      pos: [0, 0, 3], 
      state: 3
    }, 
    {
      pos: [0, 0, 4], 
      state: 3
    }, 
    {
      pos: [1, 0, 1], 
      state: 3
    }, 
    {
      pos: [1, 0, 2], 
      state: 3
    }, 
    {
      pos: [1, 0, 3], 
      state: 3
    }, 
    {
      pos: [1, 0, 4], 
      state: 3
    }, 
    {
      pos: [1, 0, 5], 
      state: 3
    }, 
    {
      pos: [2, 0, 0], 
      state: 3
    }, 
    {
      pos: [2, 0, 1], 
      state: 3
    }, 
    {
      pos: [2, 0, 3], 
      state: 3
    }, 
    {
      pos: [2, 0, 5], 
      state: 3
    }, 
    {
      pos: [2, 0, 6], 
      state: 3
    }, 
    {
      pos: [3, 0, 0], 
      state: 3
    }, 
    {
      pos: [3, 0, 1], 
      state: 3
    }, 
    {
      pos: [3, 0, 2], 
      state: 3
    }, 
    {
      pos: [3, 0, 3], 
      state: 3
    }, 
    {
      pos: [3, 0, 4], 
      state: 3
    }, 
    {
      pos: [3, 0, 5], 
      state: 3
    }, 
    {
      pos: [3, 0, 6], 
      state: 3
    }, 
    {
      pos: [4, 0, 0], 
      state: 3
    }, 
    {
      pos: [4, 0, 1], 
      state: 3
    }, 
    {
      pos: [4, 0, 3], 
      state: 3
    }, 
    {
      pos: [4, 0, 5], 
      state: 3
    }, 
    {
      pos: [4, 0, 6], 
      state: 3
    }, 
    {
      pos: [5, 0, 1], 
      state: 3
    }, 
    {
      pos: [5, 0, 2], 
      state: 3
    }, 
    {
      pos: [5, 0, 3], 
      state: 3
    }, 
    {
      pos: [5, 0, 4], 
      state: 3
    }, 
    {
      pos: [5, 0, 5], 
      state: 3
    }, 
    {
      pos: [6, 0, 2], 
      state: 3
    }, 
    {
      pos: [6, 0, 3], 
      state: 3
    }, 
    {
      pos: [6, 0, 4], 
      state: 3
    }, 
    {
      pos: [2, 1, 2], 
      state: 4
    }, 
    {
      pos: [2, 1, 4], 
      state: 4
    }, 
    {
      pos: [4, 1, 2], 
      state: 4
    }, 
    {
      pos: [4, 1, 4], 
      state: 4
    }, 
    {
      pos: [2, 2, 2], 
      state: 4
    }, 
    {
      pos: [2, 2, 4], 
      state: 4
    }, 
    {
      pos: [4, 2, 2], 
      state: 4
    }, 
    {
      pos: [4, 2, 4], 
      state: 4
    }, 
    {
      pos: [1, 3, 3], 
      state: 5
    }, 
    {
      pos: [2, 3, 2], 
      state: 4
    }, 
    {
      pos: [2, 3, 4], 
      state: 4
    }, 
    {
      pos: [3, 3, 1], 
      state: 5
    }, 
    {
      pos: [3, 3, 5], 
      state: 5
    }, 
    {
      pos: [4, 3, 2], 
      state: 4
    }, 
    {
      pos: [4, 3, 4], 
      state: 4
    }, 
    {
      pos: [5, 3, 3], 
      state: 5
    }, 
    {
      pos: [1, 4, 3], 
      state: 6
    }, 
    {
      pos: [3, 4, 1], 
      state: 7
    }, 
    {
      pos: [3, 4, 5], 
      state: 8
    }, 
    {
      pos: [5, 4, 3], 
      state: 9
    }, 
    {
      nbt: {
        joint: "rollable", 
        final_state: "minecraft:grass_block", 
        name: "minecraft:bottom", 
        pool: "minecraft:village/common/cats", 
        id: "minecraft:jigsaw", 
        target: "minecraft:bottom"
      }, 
      pos: [0, 0, 1], 
      state: 10
    }, 
    {
      nbt: {
        joint: "rollable", 
        final_state: "minecraft:grass_block", 
        name: "minecraft:bottom", 
        pool: "minecraft:village/common/cats", 
        id: "minecraft:jigsaw", 
        target: "minecraft:bottom"
      }, 
      pos: [6, 0, 6], 
      state: 10
    }, 
    {
      nbt: {
        joint: "aligned", 
        final_state: "minecraft:structure_void", 
        name: "minecraft:street", 
        pool: "minecraft:village/snowy/zombie/streets", 
        id: "minecraft:jigsaw", 
        target: "minecraft:street"
      }, 
      pos: [0, 1, 3], 
      state: 11
    }, 
    {
      nbt: {
        joint: "aligned", 
        final_state: "minecraft:structure_void", 
        name: "minecraft:street", 
        pool: "minecraft:village/snowy/zombie/streets", 
        id: "minecraft:jigsaw", 
        target: "minecraft:street"
      }, 
      pos: [3, 1, 0], 
      state: 12
    }, 
    {
      nbt: {
        joint: "aligned", 
        final_state: "minecraft:structure_void", 
        name: "minecraft:street", 
        pool: "minecraft:village/snowy/zombie/streets", 
        id: "minecraft:jigsaw", 
        target: "minecraft:street"
      }, 
      pos: [3, 1, 6], 
      state: 13
    }, 
    {
      nbt: {
        joint: "aligned", 
        final_state: "minecraft:structure_void", 
        name: "minecraft:street", 
        pool: "minecraft:village/snowy/zombie/streets", 
        id: "minecraft:jigsaw", 
        target: "minecraft:street"
      }, 
      pos: [6, 1, 3], 
      state: 14
    }, 
    {
      nbt: {
        id: "minecraft:bell"
      }, 
      pos: [3, 3, 3], 
      state: 15
    }
  ], 
  palette: [
    {
      id: "minecraft:grass_block", 
      properties: {
        snowy: "false"
      }
    }, 
    {
      id: "minecraft:stripped_spruce_wood", 
      properties: {
        axis: "z"
      }
    }, 
    {
      id: "minecraft:stripped_spruce_wood", 
      properties: {
        axis: "x"
      }
    }, 
    {
      id: "minecraft:dirt_path"
    }, 
    {
      id: "minecraft:spruce_fence", 
      properties: {
        east: "false", 
        waterlogged: "false", 
        south: "false", 
        north: "false", 
        west: "false"
      }
    }, 
    {
      id: "minecraft:lantern", 
      properties: {
        waterlogged: "false", 
        hanging: "true"
      }
    }, 
    {
      id: "minecraft:spruce_fence", 
      properties: {
        east: "true", 
        waterlogged: "false", 
        south: "false", 
        north: "false", 
        west: "false"
      }
    }, 
    {
      id: "minecraft:spruce_fence", 
      properties: {
        east: "false", 
        waterlogged: "false", 
        south: "true", 
        north: "false", 
        west: "false"
      }
    }, 
    {
      id: "minecraft:spruce_fence", 
      properties: {
        east: "false", 
        waterlogged: "false", 
        south: "false", 
        north: "true", 
        west: "false"
      }
    }, 
    {
      id: "minecraft:spruce_fence", 
      properties: {
        east: "false", 
        waterlogged: "false", 
        south: "false", 
        north: "false", 
        west: "true"
      }
    }, 
    {
      id: "minecraft:jigsaw", 
      properties: {
        orientation: "up_north"
      }
    }, 
    {
      id: "minecraft:jigsaw", 
      properties: {
        orientation: "west_up"
      }
    }, 
    {
      id: "minecraft:jigsaw", 
      properties: {
        orientation: "north_up"
      }
    }, 
    {
      id: "minecraft:jigsaw", 
      properties: {
        orientation: "south_up"
      }
    }, 
    {
      id: "minecraft:jigsaw", 
      properties: {
        orientation: "east_up"
      }
    }, 
    {
      id: "minecraft:bell", 
      properties: {
        attachment: "ceiling", 
        powered: "false", 
        facing: "east"
      }
    }
  ]
}
