{
  size: [10, 12, 10], 
  entities: [
    {
      nbt: {
        Motion: [0.0d, 0.0d, 0.0d], 
        color: "red", 
        block_pos: [I; -90, -61, -74], 
        Invulnerable: 0b, 
        Air: 300s, 
        OnGround: 0b, 
        fall_distance: 0.0d, 
        PortalCooldown: 0, 
        Rotation: [90.0f, 0.0f], 
        Pos: [-89.5d, -60.0625d, -73.5d], 
        Fire: 0s, 
        id: "minecraft:cushion", 
        UUID: [I; 1769704749, 67715306, -1324283751, -1284985202]
      }, 
      blockPos: [4, 0, 4], 
      pos: [4.5d, 0.9375d, 4.5d]
    }
  ], 
  blocks: [
    {
      pos: [1, 0, 2], 
      state: 0
    }, 
    {
      pos: [2, 0, 1], 
      state: 0
    }, 
    {
      pos: [2, 0, 2], 
      state: 0
    }, 
    {
      pos: [2, 0, 7], 
      state: 1
    }, 
    {
      pos: [3, 0, 1], 
      state: 0
    }, 
    {
      pos: [3, 0, 2], 
      state: 1
    }, 
    {
      pos: [3, 0, 3], 
      state: 0
    }, 
    {
      pos: [3, 0, 4], 
      state: 0
    }, 
    {
      pos: [4, 0, 0], 
      state: 0
    }, 
    {
      pos: [4, 0, 1], 
      state: 0
    }, 
    {
      pos: [4, 0, 3], 
      state: 0
    }, 
    {
      pos: [4, 0, 7], 
      state: 1
    }, 
    {
      pos: [5, 0, 0], 
      state: 0
    }, 
    {
      pos: [5, 0, 1], 
      state: 0
    }, 
    {
      pos: [5, 0, 5], 
      state: 0
    }, 
    {
      pos: [5, 0, 6], 
      state: 0
    }, 
    {
      pos: [5, 0, 7], 
      state: 1
    }, 
    {
      pos: [6, 0, 0], 
      state: 0
    }, 
    {
      pos: [6, 0, 1], 
      state: 0
    }, 
    {
      pos: [6, 0, 2], 
      state: 0
    }, 
    {
      pos: [6, 0, 7], 
      state: 1
    }, 
    {
      pos: [7, 0, 1], 
      state: 0
    }, 
    {
      pos: [7, 0, 2], 
      state: 0
    }, 
    {
      pos: [7, 0, 3], 
      state: 0
    }, 
    {
      pos: [7, 0, 6], 
      state: 1
    }, 
    {
      pos: [8, 0, 2], 
      state: 0
    }, 
    {
      pos: [2, 1, 7], 
      state: 2
    }, 
    {
      pos: [3, 1, 2], 
      state: 2
    }, 
    {
      pos: [4, 1, 7], 
      state: 3
    }, 
    {
      pos: [5, 1, 7], 
      state: 3
    }, 
    {
      pos: [6, 1, 7], 
      state: 3
    }, 
    {
      pos: [2, 2, 7], 
      state: 2
    }, 
    {
      pos: [3, 2, 2], 
      state: 2
    }, 
    {
      pos: [2, 3, 7], 
      state: 2
    }, 
    {
      pos: [3, 3, 2], 
      state: 2
    }, 
    {
      pos: [2, 4, 7], 
      state: 2
    }, 
    {
      pos: [3, 4, 2], 
      state: 2
    }, 
    {
      pos: [2, 5, 7], 
      state: 2
    }, 
    {
      pos: [3, 5, 2], 
      state: 2
    }, 
    {
      pos: [2, 6, 7], 
      state: 2
    }, 
    {
      pos: [3, 6, 2], 
      state: 2
    }, 
    {
      pos: [0, 7, 5], 
      state: 4
    }, 
    {
      pos: [0, 7, 6], 
      state: 5
    }, 
    {
      pos: [0, 7, 7], 
      state: 6
    }, 
    {
      pos: [0, 7, 8], 
      state: 5
    }, 
    {
      pos: [1, 7, 0], 
      state: 4
    }, 
    {
      pos: [1, 7, 1], 
      state: 5
    }, 
    {
      pos: [1, 7, 2], 
      state: 6
    }, 
    {
      pos: [1, 7, 3], 
      state: 5
    }, 
    {
      pos: [1, 7, 5], 
      state: 5
    }, 
    {
      pos: [1, 7, 6], 
      state: 6
    }, 
    {
      pos: [1, 7, 7], 
      state: 7
    }, 
    {
      pos: [1, 7, 8], 
      state: 6
    }, 
    {
      pos: [1, 7, 9], 
      state: 5
    }, 
    {
      pos: [2, 7, 0], 
      state: 5
    }, 
    {
      pos: [2, 7, 1], 
      state: 6
    }, 
    {
      pos: [2, 7, 2], 
      state: 7
    }, 
    {
      pos: [2, 7, 3], 
      state: 6
    }, 
    {
      pos: [2, 7, 4], 
      state: 5
    }, 
    {
      pos: [2, 7, 5], 
      state: 6
    }, 
    {
      pos: [2, 7, 6], 
      state: 7
    }, 
    {
      pos: [2, 7, 7], 
      state: 2
    }, 
    {
      pos: [2, 7, 8], 
      state: 7
    }, 
    {
      pos: [2, 7, 9], 
      state: 6
    }, 
    {
      pos: [3, 7, 0], 
      state: 6
    }, 
    {
      pos: [3, 7, 1], 
      state: 7
    }, 
    {
      pos: [3, 7, 2], 
      state: 2
    }, 
    {
      pos: [3, 7, 3], 
      state: 7
    }, 
    {
      pos: [3, 7, 4], 
      state: 6
    }, 
    {
      pos: [3, 7, 5], 
      state: 5
    }, 
    {
      pos: [3, 7, 6], 
      state: 6
    }, 
    {
      pos: [3, 7, 7], 
      state: 7
    }, 
    {
      pos: [3, 7, 8], 
      state: 6
    }, 
    {
      pos: [3, 7, 9], 
      state: 5
    }, 
    {
      pos: [4, 7, 0], 
      state: 5
    }, 
    {
      pos: [4, 7, 1], 
      state: 6
    }, 
    {
      pos: [4, 7, 2], 
      state: 7
    }, 
    {
      pos: [4, 7, 3], 
      state: 6
    }, 
    {
      pos: [4, 7, 4], 
      state: 5
    }, 
    {
      pos: [4, 7, 6], 
      state: 5
    }, 
    {
      pos: [4, 7, 7], 
      state: 6
    }, 
    {
      pos: [4, 7, 8], 
      state: 5
    }, 
    {
      pos: [4, 7, 9], 
      state: 4
    }, 
    {
      pos: [5, 7, 1], 
      state: 5
    }, 
    {
      pos: [5, 7, 2], 
      state: 6
    }, 
    {
      pos: [5, 7, 3], 
      state: 5
    }, 
    {
      pos: [0, 8, 6], 
      state: 5
    }, 
    {
      pos: [0, 8, 7], 
      state: 6
    }, 
    {
      pos: [0, 8, 8], 
      state: 5
    }, 
    {
      pos: [1, 8, 0], 
      state: 4
    }, 
    {
      pos: [1, 8, 1], 
      state: 5
    }, 
    {
      pos: [1, 8, 2], 
      state: 6
    }, 
    {
      pos: [1, 8, 3], 
      state: 5
    }, 
    {
      pos: [1, 8, 4], 
      state: 4
    }, 
    {
      pos: [1, 8, 5], 
      state: 5
    }, 
    {
      pos: [1, 8, 6], 
      state: 6
    }, 
    {
      pos: [1, 8, 7], 
      state: 7
    }, 
    {
      pos: [1, 8, 8], 
      state: 6
    }, 
    {
      pos: [1, 8, 9], 
      state: 5
    }, 
    {
      pos: [2, 8, 0], 
      state: 5
    }, 
    {
      pos: [2, 8, 1], 
      state: 6
    }, 
    {
      pos: [2, 8, 2], 
      state: 7
    }, 
    {
      pos: [2, 8, 3], 
      state: 6
    }, 
    {
      pos: [2, 8, 4], 
      state: 5
    }, 
    {
      pos: [2, 8, 5], 
      state: 6
    }, 
    {
      pos: [2, 8, 6], 
      state: 7
    }, 
    {
      pos: [2, 8, 7], 
      state: 2
    }, 
    {
      pos: [2, 8, 8], 
      state: 7
    }, 
    {
      pos: [2, 8, 9], 
      state: 6
    }, 
    {
      pos: [3, 8, 0], 
      state: 6
    }, 
    {
      pos: [3, 8, 1], 
      state: 7
    }, 
    {
      pos: [3, 8, 2], 
      state: 2
    }, 
    {
      pos: [3, 8, 3], 
      state: 7
    }, 
    {
      pos: [3, 8, 4], 
      state: 6
    }, 
    {
      pos: [3, 8, 5], 
      state: 5
    }, 
    {
      pos: [3, 8, 6], 
      state: 8
    }, 
    {
      pos: [3, 8, 7], 
      state: 7
    }, 
    {
      pos: [3, 8, 8], 
      state: 6
    }, 
    {
      pos: [3, 8, 9], 
      state: 5
    }, 
    {
      pos: [4, 8, 0], 
      state: 5
    }, 
    {
      pos: [4, 8, 1], 
      state: 6
    }, 
    {
      pos: [4, 8, 2], 
      state: 7
    }, 
    {
      pos: [4, 8, 3], 
      state: 6
    }, 
    {
      pos: [4, 8, 4], 
      state: 5
    }, 
    {
      pos: [4, 8, 5], 
      state: 4
    }, 
    {
      pos: [4, 8, 6], 
      state: 5
    }, 
    {
      pos: [4, 8, 7], 
      state: 6
    }, 
    {
      pos: [4, 8, 8], 
      state: 5
    }, 
    {
      pos: [5, 8, 1], 
      state: 5
    }, 
    {
      pos: [5, 8, 2], 
      state: 6
    }, 
    {
      pos: [5, 8, 3], 
      state: 5
    }, 
    {
      pos: [5, 8, 4], 
      state: 4
    }, 
    {
      pos: [1, 9, 7], 
      state: 7
    }, 
    {
      pos: [2, 9, 1], 
      state: 6
    }, 
    {
      pos: [2, 9, 2], 
      state: 7
    }, 
    {
      pos: [2, 9, 6], 
      state: 9
    }, 
    {
      pos: [2, 9, 7], 
      state: 2
    }, 
    {
      pos: [2, 9, 8], 
      state: 7
    }, 
    {
      pos: [3, 9, 1], 
      state: 7
    }, 
    {
      pos: [3, 9, 2], 
      state: 2
    }, 
    {
      pos: [3, 9, 3], 
      state: 7
    }, 
    {
      pos: [3, 9, 7], 
      state: 9
    }, 
    {
      pos: [3, 9, 8], 
      state: 8
    }, 
    {
      pos: [4, 9, 2], 
      state: 7
    }, 
    {
      pos: [4, 9, 3], 
      state: 6
    }, 
    {
      pos: [1, 10, 7], 
      state: 6
    }, 
    {
      pos: [2, 10, 2], 
      state: 6
    }, 
    {
      pos: [2, 10, 6], 
      state: 6
    }, 
    {
      pos: [2, 10, 7], 
      state: 7
    }, 
    {
      pos: [2, 10, 8], 
      state: 6
    }, 
    {
      pos: [3, 10, 1], 
      state: 6
    }, 
    {
      pos: [3, 10, 2], 
      state: 7
    }, 
    {
      pos: [3, 10, 3], 
      state: 6
    }, 
    {
      pos: [3, 10, 7], 
      state: 6
    }, 
    {
      pos: [4, 10, 2], 
      state: 6
    }, 
    {
      pos: [1, 0, 7], 
      state: 10
    }, 
    {
      pos: [2, 0, 4], 
      state: 11
    }, 
    {
      pos: [2, 0, 5], 
      state: 11
    }, 
    {
      pos: [2, 0, 6], 
      state: 12
    }, 
    {
      pos: [2, 0, 8], 
      state: 13
    }, 
    {
      pos: [3, 0, 5], 
      state: 11
    }, 
    {
      pos: [3, 0, 7], 
      state: 14
    }, 
    {
      pos: [4, 0, 4], 
      state: 11
    }, 
    {
      pos: [4, 0, 6], 
      state: 12
    }, 
    {
      pos: [5, 0, 2], 
      state: 11
    }, 
    {
      pos: [6, 0, 4], 
      state: 11
    }, 
    {
      pos: [7, 0, 4], 
      state: 11
    }, 
    {
      pos: [8, 0, 4], 
      state: 11
    }, 
    {
      pos: [8, 0, 5], 
      state: 11
    }, 
    {
      pos: [9, 0, 5], 
      state: 11
    }, 
    {
      pos: [1, 1, 7], 
      state: 10
    }, 
    {
      pos: [2, 1, 6], 
      state: 12
    }, 
    {
      pos: [2, 1, 8], 
      state: 13
    }, 
    {
      pos: [3, 1, 7], 
      state: 14
    }, 
    {
      pos: [4, 1, 5], 
      state: 15
    }, 
    {
      pos: [4, 1, 6], 
      state: 12
    }, 
    {
      pos: [5, 1, 4], 
      state: 15
    }, 
    {
      pos: [5, 1, 6], 
      state: 12
    }, 
    {
      pos: [6, 1, 2], 
      state: 16
    }, 
    {
      pos: [6, 1, 5], 
      state: 15
    }, 
    {
      pos: [1, 2, 7], 
      state: 10
    }, 
    {
      pos: [2, 2, 6], 
      state: 17
    }, 
    {
      pos: [2, 2, 8], 
      state: 13
    }, 
    {
      pos: [3, 2, 7], 
      state: 14
    }, 
    {
      pos: [1, 3, 7], 
      state: 10
    }, 
    {
      pos: [2, 3, 6], 
      state: 12
    }, 
    {
      pos: [2, 3, 8], 
      state: 13
    }, 
    {
      pos: [3, 3, 3], 
      state: 18
    }, 
    {
      pos: [3, 3, 7], 
      state: 14
    }, 
    {
      pos: [1, 4, 7], 
      state: 10
    }, 
    {
      pos: [2, 4, 6], 
      state: 12
    }, 
    {
      pos: [2, 4, 8], 
      state: 13
    }, 
    {
      pos: [3, 4, 7], 
      state: 14
    }, 
    {
      pos: [1, 5, 7], 
      state: 10
    }, 
    {
      pos: [2, 5, 8], 
      state: 13
    }, 
    {
      pos: [3, 5, 7], 
      state: 14
    }, 
    {
      pos: [1, 6, 7], 
      state: 19
    }, 
    {
      pos: [2, 6, 8], 
      state: 20
    }, 
    {
      pos: [3, 6, 7], 
      state: 21
    }, 
    {
      nbt: {
        LootTable: "minecraft:chests/abandoned_camp_secret_chest", 
        components: {}, 
        Items: [], 
        id: "minecraft:chest"
      }, 
      pos: [4, 0, 2], 
      state: 22
    }, 
    {
      nbt: {
        components: {}, 
        joint: "rollable", 
        final_state: "minecraft:dirt_path", 
        name: "minecraft:end_connector", 
        placement_priority: 0, 
        pool: "minecraft:empty", 
        selection_priority: 0, 
        id: "minecraft:jigsaw", 
        target: "minecraft:connector"
      }, 
      pos: [9, 0, 4], 
      state: 23
    }, 
    {
      nbt: {
        LootTable: "minecraft:barrels/abandoned_camp_barrel", 
        components: {}, 
        Items: [], 
        id: "minecraft:barrel"
      }, 
      pos: [4, 1, 2], 
      state: 24
    }, 
    {
      nbt: {
        components: {}, 
        Items: [], 
        CookingTimes: [I; 0, 0, 0, 0], 
        CookingTotalTimes: [I; 0, 0, 0, 0], 
        id: "minecraft:campfire"
      }, 
      pos: [5, 1, 5], 
      state: 25
    }, 
    {
      nbt: {
        LootTable: "minecraft:barrels/abandoned_camp_barrel", 
        components: {}, 
        Items: [], 
        id: "minecraft:barrel"
      }, 
      pos: [7, 1, 6], 
      state: 26
    }
  ], 
  palette: [
    {
      Properties: {
        snowy: "false"
      }, 
      Name: "minecraft:grass_block"
    }, 
    {
      Name: "minecraft:dirt"
    }, 
    {
      Properties: {
        axis: "y"
      }, 
      Name: "minecraft:jungle_log"
    }, 
    {
      Properties: {
        axis: "x"
      }, 
      Name: "minecraft:jungle_log"
    }, 
    {
      Properties: {
        waterlogged: "false", 
        distance: "4", 
        persistent: "false"
      }, 
      Name: "minecraft:jungle_leaves"
    }, 
    {
      Properties: {
        waterlogged: "false", 
        distance: "3", 
        persistent: "false"
      }, 
      Name: "minecraft:jungle_leaves"
    }, 
    {
      Properties: {
        waterlogged: "false", 
        distance: "2", 
        persistent: "false"
      }, 
      Name: "minecraft:jungle_leaves"
    }, 
    {
      Properties: {
        waterlogged: "false", 
        distance: "1", 
        persistent: "false"
      }, 
      Name: "minecraft:jungle_leaves"
    }, 
    {
      Properties: {
        waterlogged: "false", 
        distance: "2", 
        persistent: "true"
      }, 
      Name: "minecraft:jungle_leaves"
    }, 
    {
      Properties: {
        waterlogged: "false", 
        distance: "1", 
        persistent: "true"
      }, 
      Name: "minecraft:jungle_leaves"
    }, 
    {
      Properties: {
        east: "true", 
        south: "false", 
        north: "false", 
        west: "false", 
        up: "false"
      }, 
      Name: "minecraft:vine"
    }, 
    {
      Name: "minecraft:dirt_path"
    }, 
    {
      Properties: {
        east: "false", 
        south: "true", 
        north: "false", 
        west: "false", 
        up: "false"
      }, 
      Name: "minecraft:vine"
    }, 
    {
      Properties: {
        east: "false", 
        south: "false", 
        north: "true", 
        west: "false", 
        up: "false"
      }, 
      Name: "minecraft:vine"
    }, 
    {
      Properties: {
        east: "false", 
        south: "false", 
        north: "false", 
        west: "true", 
        up: "false"
      }, 
      Name: "minecraft:vine"
    }, 
    {
      Name: "minecraft:cobweb"
    }, 
    {
      Properties: {
        east: "false", 
        waterlogged: "false", 
        south: "false", 
        north: "false", 
        west: "false"
      }, 
      Name: "minecraft:jungle_fence"
    }, 
    {
      Properties: {
        facing: "south", 
        age: "2"
      }, 
      Name: "minecraft:cocoa"
    }, 
    {
      Properties: {
        facing: "north", 
        age: "2"
      }, 
      Name: "minecraft:cocoa"
    }, 
    {
      Properties: {
        east: "true", 
        south: "false", 
        north: "false", 
        west: "false", 
        up: "true"
      }, 
      Name: "minecraft:vine"
    }, 
    {
      Properties: {
        east: "false", 
        south: "false", 
        north: "true", 
        west: "false", 
        up: "true"
      }, 
      Name: "minecraft:vine"
    }, 
    {
      Properties: {
        east: "false", 
        south: "false", 
        north: "false", 
        west: "true", 
        up: "true"
      }, 
      Name: "minecraft:vine"
    }, 
    {
      Properties: {
        waterlogged: "false", 
        facing: "south", 
        type: "single"
      }, 
      Name: "minecraft:oxidized_copper_chest"
    }, 
    {
      Properties: {
        orientation: "east_up"
      }, 
      Name: "minecraft:jigsaw"
    }, 
    {
      Properties: {
        facing: "east", 
        open: "false"
      }, 
      Name: "minecraft:barrel"
    }, 
    {
      Properties: {
        waterlogged: "false", 
        signal_fire: "false", 
        lit: "false", 
        facing: "west"
      }, 
      Name: "minecraft:campfire"
    }, 
    {
      Properties: {
        facing: "up", 
        open: "false"
      }, 
      Name: "minecraft:barrel"
    }
  ]
}
