{
  size: [10, 14, 11], 
  entities: [
    {
      nbt: {
        Motion: [0.0d, 0.0d, 0.0d], 
        color: "gray", 
        block_pos: [I; -90, -61, -89], 
        Invulnerable: 0b, 
        Air: 300s, 
        OnGround: 0b, 
        fall_distance: 0.0d, 
        PortalCooldown: 0, 
        Rotation: [0.0f, 0.0f], 
        Pos: [-89.5d, -60.0625d, -88.5d], 
        Fire: 0s, 
        id: "minecraft:cushion", 
        UUID: [I; 896961967, -1383775627, -1422356559, 1794368294]
      }, 
      blockPos: [4, 0, 4], 
      pos: [4.5d, 0.9375d, 4.5d]
    }, 
    {
      nbt: {
        Motion: [0.0d, 0.0d, 0.0d], 
        color: "light_gray", 
        block_pos: [I; -89, -59, -91], 
        Invulnerable: 0b, 
        Air: 300s, 
        OnGround: 0b, 
        fall_distance: 0.0d, 
        PortalCooldown: 0, 
        Rotation: [90.0f, 0.0f], 
        Pos: [-88.5d, -59.0d, -90.5d], 
        Fire: 0s, 
        id: "minecraft:cushion", 
        UUID: [I; -1451871467, -938262222, -1591486214, -2014523993]
      }, 
      blockPos: [5, 2, 2], 
      pos: [5.5d, 2.0d, 2.5d]
    }
  ], 
  blocks: [
    {
      pos: [5, 0, 4], 
      state: 0
    }, 
    {
      pos: [2, 1, 3], 
      state: 1
    }, 
    {
      pos: [2, 1, 7], 
      state: 1
    }, 
    {
      pos: [4, 1, 2], 
      state: 2
    }, 
    {
      pos: [5, 1, 2], 
      state: 2
    }, 
    {
      pos: [5, 1, 6], 
      state: 2
    }, 
    {
      pos: [6, 1, 6], 
      state: 2
    }, 
    {
      pos: [6, 1, 8], 
      state: 1
    }, 
    {
      pos: [7, 1, 6], 
      state: 2
    }, 
    {
      pos: [2, 2, 3], 
      state: 1
    }, 
    {
      pos: [2, 2, 7], 
      state: 1
    }, 
    {
      pos: [3, 2, 7], 
      state: 3
    }, 
    {
      pos: [3, 2, 8], 
      state: 4
    }, 
    {
      pos: [6, 2, 8], 
      state: 1
    }, 
    {
      pos: [0, 3, 5], 
      state: 5
    }, 
    {
      pos: [0, 3, 6], 
      state: 6
    }, 
    {
      pos: [0, 3, 7], 
      state: 7
    }, 
    {
      pos: [0, 3, 8], 
      state: 6
    }, 
    {
      pos: [0, 3, 9], 
      state: 5
    }, 
    {
      pos: [1, 3, 5], 
      state: 6
    }, 
    {
      pos: [1, 3, 6], 
      state: 7
    }, 
    {
      pos: [1, 3, 7], 
      state: 8
    }, 
    {
      pos: [1, 3, 8], 
      state: 7
    }, 
    {
      pos: [1, 3, 9], 
      state: 6
    }, 
    {
      pos: [2, 3, 3], 
      state: 1
    }, 
    {
      pos: [2, 3, 5], 
      state: 7
    }, 
    {
      pos: [2, 3, 6], 
      state: 8
    }, 
    {
      pos: [2, 3, 7], 
      state: 1
    }, 
    {
      pos: [2, 3, 8], 
      state: 8
    }, 
    {
      pos: [2, 3, 9], 
      state: 7
    }, 
    {
      pos: [3, 3, 5], 
      state: 6
    }, 
    {
      pos: [3, 3, 6], 
      state: 7
    }, 
    {
      pos: [3, 3, 7], 
      state: 8
    }, 
    {
      pos: [3, 3, 8], 
      state: 7
    }, 
    {
      pos: [3, 3, 9], 
      state: 6
    }, 
    {
      pos: [4, 3, 5], 
      state: 5
    }, 
    {
      pos: [4, 3, 6], 
      state: 6
    }, 
    {
      pos: [4, 3, 7], 
      state: 7
    }, 
    {
      pos: [4, 3, 8], 
      state: 6
    }, 
    {
      pos: [6, 3, 8], 
      state: 1
    }, 
    {
      pos: [0, 4, 5], 
      state: 5
    }, 
    {
      pos: [0, 4, 6], 
      state: 6
    }, 
    {
      pos: [0, 4, 7], 
      state: 7
    }, 
    {
      pos: [0, 4, 8], 
      state: 6
    }, 
    {
      pos: [0, 4, 9], 
      state: 5
    }, 
    {
      pos: [1, 4, 5], 
      state: 6
    }, 
    {
      pos: [1, 4, 6], 
      state: 7
    }, 
    {
      pos: [1, 4, 7], 
      state: 8
    }, 
    {
      pos: [1, 4, 8], 
      state: 7
    }, 
    {
      pos: [1, 4, 9], 
      state: 6
    }, 
    {
      pos: [2, 4, 3], 
      state: 1
    }, 
    {
      pos: [2, 4, 5], 
      state: 7
    }, 
    {
      pos: [2, 4, 6], 
      state: 8
    }, 
    {
      pos: [2, 4, 7], 
      state: 1
    }, 
    {
      pos: [2, 4, 8], 
      state: 8
    }, 
    {
      pos: [2, 4, 9], 
      state: 7
    }, 
    {
      pos: [3, 4, 5], 
      state: 6
    }, 
    {
      pos: [3, 4, 6], 
      state: 7
    }, 
    {
      pos: [3, 4, 7], 
      state: 8
    }, 
    {
      pos: [3, 4, 8], 
      state: 7
    }, 
    {
      pos: [3, 4, 9], 
      state: 6
    }, 
    {
      pos: [4, 4, 5], 
      state: 5
    }, 
    {
      pos: [4, 4, 6], 
      state: 6
    }, 
    {
      pos: [4, 4, 7], 
      state: 7
    }, 
    {
      pos: [4, 4, 8], 
      state: 6
    }, 
    {
      pos: [4, 4, 9], 
      state: 5
    }, 
    {
      pos: [6, 4, 8], 
      state: 1
    }, 
    {
      pos: [1, 5, 7], 
      state: 8
    }, 
    {
      pos: [2, 5, 3], 
      state: 1
    }, 
    {
      pos: [2, 5, 6], 
      state: 8
    }, 
    {
      pos: [2, 5, 7], 
      state: 1
    }, 
    {
      pos: [2, 5, 8], 
      state: 8
    }, 
    {
      pos: [3, 5, 7], 
      state: 8
    }, 
    {
      pos: [3, 5, 8], 
      state: 7
    }, 
    {
      pos: [6, 5, 8], 
      state: 1
    }, 
    {
      pos: [1, 6, 7], 
      state: 7
    }, 
    {
      pos: [2, 6, 3], 
      state: 1
    }, 
    {
      pos: [2, 6, 6], 
      state: 7
    }, 
    {
      pos: [2, 6, 7], 
      state: 8
    }, 
    {
      pos: [2, 6, 8], 
      state: 7
    }, 
    {
      pos: [3, 6, 7], 
      state: 7
    }, 
    {
      pos: [6, 6, 8], 
      state: 1
    }, 
    {
      pos: [2, 7, 3], 
      state: 1
    }, 
    {
      pos: [6, 7, 8], 
      state: 1
    }, 
    {
      pos: [2, 8, 3], 
      state: 1
    }, 
    {
      pos: [6, 8, 8], 
      state: 1
    }, 
    {
      pos: [2, 9, 3], 
      state: 1
    }, 
    {
      pos: [4, 9, 7], 
      state: 6
    }, 
    {
      pos: [4, 9, 8], 
      state: 7
    }, 
    {
      pos: [4, 9, 9], 
      state: 6
    }, 
    {
      pos: [4, 9, 10], 
      state: 5
    }, 
    {
      pos: [5, 9, 6], 
      state: 6
    }, 
    {
      pos: [5, 9, 7], 
      state: 7
    }, 
    {
      pos: [5, 9, 8], 
      state: 8
    }, 
    {
      pos: [5, 9, 9], 
      state: 7
    }, 
    {
      pos: [5, 9, 10], 
      state: 6
    }, 
    {
      pos: [6, 9, 6], 
      state: 7
    }, 
    {
      pos: [6, 9, 7], 
      state: 8
    }, 
    {
      pos: [6, 9, 8], 
      state: 1
    }, 
    {
      pos: [6, 9, 9], 
      state: 8
    }, 
    {
      pos: [6, 9, 10], 
      state: 7
    }, 
    {
      pos: [7, 9, 6], 
      state: 6
    }, 
    {
      pos: [7, 9, 7], 
      state: 7
    }, 
    {
      pos: [7, 9, 8], 
      state: 8
    }, 
    {
      pos: [7, 9, 9], 
      state: 7
    }, 
    {
      pos: [7, 9, 10], 
      state: 6
    }, 
    {
      pos: [8, 9, 6], 
      state: 5
    }, 
    {
      pos: [8, 9, 7], 
      state: 6
    }, 
    {
      pos: [8, 9, 8], 
      state: 7
    }, 
    {
      pos: [8, 9, 9], 
      state: 6
    }, 
    {
      pos: [8, 9, 10], 
      state: 5
    }, 
    {
      pos: [0, 10, 2], 
      state: 6
    }, 
    {
      pos: [0, 10, 3], 
      state: 7
    }, 
    {
      pos: [0, 10, 4], 
      state: 6
    }, 
    {
      pos: [1, 10, 1], 
      state: 6
    }, 
    {
      pos: [1, 10, 2], 
      state: 7
    }, 
    {
      pos: [1, 10, 3], 
      state: 8
    }, 
    {
      pos: [1, 10, 4], 
      state: 7
    }, 
    {
      pos: [1, 10, 5], 
      state: 6
    }, 
    {
      pos: [2, 10, 1], 
      state: 7
    }, 
    {
      pos: [2, 10, 2], 
      state: 8
    }, 
    {
      pos: [2, 10, 3], 
      state: 1
    }, 
    {
      pos: [2, 10, 4], 
      state: 8
    }, 
    {
      pos: [2, 10, 5], 
      state: 7
    }, 
    {
      pos: [3, 10, 1], 
      state: 6
    }, 
    {
      pos: [3, 10, 2], 
      state: 7
    }, 
    {
      pos: [3, 10, 3], 
      state: 8
    }, 
    {
      pos: [3, 10, 4], 
      state: 7
    }, 
    {
      pos: [3, 10, 5], 
      state: 6
    }, 
    {
      pos: [4, 10, 1], 
      state: 5
    }, 
    {
      pos: [4, 10, 2], 
      state: 6
    }, 
    {
      pos: [4, 10, 3], 
      state: 7
    }, 
    {
      pos: [4, 10, 4], 
      state: 6
    }, 
    {
      pos: [4, 10, 5], 
      state: 5
    }, 
    {
      pos: [4, 10, 7], 
      state: 6
    }, 
    {
      pos: [4, 10, 8], 
      state: 7
    }, 
    {
      pos: [4, 10, 9], 
      state: 6
    }, 
    {
      pos: [5, 10, 6], 
      state: 6
    }, 
    {
      pos: [5, 10, 7], 
      state: 7
    }, 
    {
      pos: [5, 10, 8], 
      state: 8
    }, 
    {
      pos: [5, 10, 9], 
      state: 7
    }, 
    {
      pos: [5, 10, 10], 
      state: 6
    }, 
    {
      pos: [6, 10, 6], 
      state: 7
    }, 
    {
      pos: [6, 10, 7], 
      state: 8
    }, 
    {
      pos: [6, 10, 8], 
      state: 1
    }, 
    {
      pos: [6, 10, 9], 
      state: 8
    }, 
    {
      pos: [6, 10, 10], 
      state: 7
    }, 
    {
      pos: [7, 10, 6], 
      state: 6
    }, 
    {
      pos: [7, 10, 7], 
      state: 7
    }, 
    {
      pos: [7, 10, 8], 
      state: 8
    }, 
    {
      pos: [7, 10, 9], 
      state: 7
    }, 
    {
      pos: [7, 10, 10], 
      state: 6
    }, 
    {
      pos: [8, 10, 6], 
      state: 5
    }, 
    {
      pos: [8, 10, 7], 
      state: 6
    }, 
    {
      pos: [8, 10, 8], 
      state: 7
    }, 
    {
      pos: [8, 10, 9], 
      state: 6
    }, 
    {
      pos: [0, 11, 2], 
      state: 6
    }, 
    {
      pos: [0, 11, 3], 
      state: 7
    }, 
    {
      pos: [0, 11, 4], 
      state: 6
    }, 
    {
      pos: [0, 11, 5], 
      state: 5
    }, 
    {
      pos: [1, 11, 1], 
      state: 6
    }, 
    {
      pos: [1, 11, 2], 
      state: 7
    }, 
    {
      pos: [1, 11, 3], 
      state: 8
    }, 
    {
      pos: [1, 11, 4], 
      state: 7
    }, 
    {
      pos: [1, 11, 5], 
      state: 6
    }, 
    {
      pos: [2, 11, 1], 
      state: 7
    }, 
    {
      pos: [2, 11, 2], 
      state: 8
    }, 
    {
      pos: [2, 11, 3], 
      state: 1
    }, 
    {
      pos: [2, 11, 4], 
      state: 8
    }, 
    {
      pos: [2, 11, 5], 
      state: 7
    }, 
    {
      pos: [3, 11, 1], 
      state: 6
    }, 
    {
      pos: [3, 11, 2], 
      state: 7
    }, 
    {
      pos: [3, 11, 3], 
      state: 8
    }, 
    {
      pos: [3, 11, 4], 
      state: 7
    }, 
    {
      pos: [3, 11, 5], 
      state: 6
    }, 
    {
      pos: [4, 11, 2], 
      state: 6
    }, 
    {
      pos: [4, 11, 3], 
      state: 7
    }, 
    {
      pos: [4, 11, 4], 
      state: 6
    }, 
    {
      pos: [4, 11, 5], 
      state: 5
    }, 
    {
      pos: [5, 11, 7], 
      state: 7
    }, 
    {
      pos: [5, 11, 8], 
      state: 8
    }, 
    {
      pos: [5, 11, 9], 
      state: 7
    }, 
    {
      pos: [6, 11, 7], 
      state: 8
    }, 
    {
      pos: [6, 11, 8], 
      state: 1
    }, 
    {
      pos: [6, 11, 9], 
      state: 8
    }, 
    {
      pos: [7, 11, 8], 
      state: 8
    }, 
    {
      pos: [1, 12, 2], 
      state: 7
    }, 
    {
      pos: [1, 12, 3], 
      state: 8
    }, 
    {
      pos: [2, 12, 2], 
      state: 8
    }, 
    {
      pos: [2, 12, 3], 
      state: 1
    }, 
    {
      pos: [2, 12, 4], 
      state: 8
    }, 
    {
      pos: [3, 12, 3], 
      state: 8
    }, 
    {
      pos: [5, 12, 8], 
      state: 7
    }, 
    {
      pos: [6, 12, 7], 
      state: 7
    }, 
    {
      pos: [6, 12, 8], 
      state: 8
    }, 
    {
      pos: [6, 12, 9], 
      state: 7
    }, 
    {
      pos: [7, 12, 8], 
      state: 7
    }, 
    {
      pos: [1, 13, 3], 
      state: 7
    }, 
    {
      pos: [2, 13, 2], 
      state: 7
    }, 
    {
      pos: [2, 13, 3], 
      state: 8
    }, 
    {
      pos: [2, 13, 4], 
      state: 7
    }, 
    {
      pos: [3, 13, 3], 
      state: 7
    }, 
    {
      pos: [3, 0, 4], 
      state: 9
    }, 
    {
      pos: [3, 0, 5], 
      state: 9
    }, 
    {
      pos: [3, 0, 6], 
      state: 9
    }, 
    {
      pos: [4, 0, 3], 
      state: 9
    }, 
    {
      pos: [4, 0, 4], 
      state: 9
    }, 
    {
      pos: [4, 0, 5], 
      state: 9
    }, 
    {
      pos: [4, 0, 7], 
      state: 9
    }, 
    {
      pos: [5, 0, 3], 
      state: 9
    }, 
    {
      pos: [5, 0, 7], 
      state: 9
    }, 
    {
      pos: [6, 0, 3], 
      state: 9
    }, 
    {
      pos: [6, 0, 4], 
      state: 9
    }, 
    {
      pos: [6, 0, 5], 
      state: 9
    }, 
    {
      pos: [7, 0, 4], 
      state: 9
    }, 
    {
      pos: [7, 0, 5], 
      state: 9
    }, 
    {
      pos: [8, 0, 5], 
      state: 9
    }, 
    {
      pos: [8, 0, 6], 
      state: 9
    }, 
    {
      pos: [9, 0, 5], 
      state: 9
    }, 
    {
      pos: [9, 0, 6], 
      state: 9
    }, 
    {
      pos: [9, 0, 7], 
      state: 9
    }, 
    {
      pos: [1, 1, 3], 
      state: 10
    }, 
    {
      pos: [2, 1, 2], 
      state: 11
    }, 
    {
      pos: [4, 1, 3], 
      state: 12
    }, 
    {
      pos: [5, 1, 8], 
      state: 10
    }, 
    {
      pos: [6, 1, 5], 
      state: 11
    }, 
    {
      pos: [6, 1, 7], 
      state: 12
    }, 
    {
      pos: [6, 1, 9], 
      state: 12
    }, 
    {
      pos: [7, 1, 2], 
      state: 13
    }, 
    {
      pos: [7, 1, 5], 
      state: 11
    }, 
    {
      pos: [7, 1, 7], 
      state: 12
    }, 
    {
      pos: [7, 1, 8], 
      state: 14
    }, 
    {
      pos: [8, 1, 6], 
      state: 14
    }, 
    {
      pos: [1, 2, 3], 
      state: 10
    }, 
    {
      pos: [2, 2, 2], 
      state: 11
    }, 
    {
      pos: [2, 2, 4], 
      state: 15
    }, 
    {
      pos: [5, 2, 8], 
      state: 10
    }, 
    {
      pos: [6, 2, 9], 
      state: 12
    }, 
    {
      pos: [7, 2, 8], 
      state: 14
    }, 
    {
      pos: [1, 3, 3], 
      state: 10
    }, 
    {
      pos: [2, 3, 2], 
      state: 11
    }, 
    {
      pos: [2, 3, 4], 
      state: 12
    }, 
    {
      pos: [3, 3, 3], 
      state: 16
    }, 
    {
      pos: [5, 3, 8], 
      state: 10
    }, 
    {
      pos: [6, 3, 7], 
      state: 17
    }, 
    {
      pos: [6, 3, 9], 
      state: 12
    }, 
    {
      pos: [7, 3, 8], 
      state: 14
    }, 
    {
      pos: [1, 4, 3], 
      state: 10
    }, 
    {
      pos: [2, 4, 2], 
      state: 11
    }, 
    {
      pos: [2, 4, 4], 
      state: 12
    }, 
    {
      pos: [3, 4, 3], 
      state: 14
    }, 
    {
      pos: [5, 4, 8], 
      state: 10
    }, 
    {
      pos: [6, 4, 7], 
      state: 11
    }, 
    {
      pos: [6, 4, 9], 
      state: 12
    }, 
    {
      pos: [7, 4, 8], 
      state: 14
    }, 
    {
      pos: [1, 5, 3], 
      state: 10
    }, 
    {
      pos: [2, 5, 2], 
      state: 11
    }, 
    {
      pos: [2, 5, 4], 
      state: 12
    }, 
    {
      pos: [1, 6, 3], 
      state: 10
    }, 
    {
      pos: [2, 6, 2], 
      state: 11
    }, 
    {
      pos: [2, 6, 4], 
      state: 12
    }, 
    {
      nbt: {
        components: {}, 
        joint: "rollable", 
        final_state: "minecraft:dirt_path", 
        name: "minecraft:end_connector", 
        placement_priority: 0, 
        pool: "minecraft:empty", 
        selection_priority: 0, 
        id: "minecraft:jigsaw", 
        target: "minecraft:connector"
      }, 
      pos: [9, 0, 4], 
      state: 18
    }, 
    {
      nbt: {
        components: {}, 
        Items: [], 
        CookingTimes: [I; 0, 0, 0, 0], 
        CookingTotalTimes: [I; 0, 0, 0, 0], 
        id: "minecraft:campfire"
      }, 
      pos: [5, 1, 4], 
      state: 19
    }, 
    {
      nbt: {
        LootTable: "minecraft:chests/abandoned_camp_common_chest", 
        components: {}, 
        id: "minecraft:chest"
      }, 
      pos: [6, 1, 2], 
      state: 20
    }
  ], 
  palette: [
    {
      Properties: {
        snowy: "false"
      }, 
      Name: "minecraft:grass_block"
    }, 
    {
      Properties: {
        axis: "y"
      }, 
      Name: "minecraft:jungle_log"
    }, 
    {
      Properties: {
        axis: "x"
      }, 
      Name: "minecraft:jungle_log"
    }, 
    {
      Properties: {
        waterlogged: "false", 
        distance: "1", 
        persistent: "true"
      }, 
      Name: "minecraft:jungle_leaves"
    }, 
    {
      Properties: {
        waterlogged: "false", 
        distance: "2", 
        persistent: "true"
      }, 
      Name: "minecraft:jungle_leaves"
    }, 
    {
      Properties: {
        waterlogged: "false", 
        distance: "4", 
        persistent: "false"
      }, 
      Name: "minecraft:jungle_leaves"
    }, 
    {
      Properties: {
        waterlogged: "false", 
        distance: "3", 
        persistent: "false"
      }, 
      Name: "minecraft:jungle_leaves"
    }, 
    {
      Properties: {
        waterlogged: "false", 
        distance: "2", 
        persistent: "false"
      }, 
      Name: "minecraft:jungle_leaves"
    }, 
    {
      Properties: {
        waterlogged: "false", 
        distance: "1", 
        persistent: "false"
      }, 
      Name: "minecraft:jungle_leaves"
    }, 
    {
      Name: "minecraft:dirt_path"
    }, 
    {
      Properties: {
        east: "true", 
        south: "false", 
        north: "false", 
        west: "false", 
        up: "false"
      }, 
      Name: "minecraft:vine"
    }, 
    {
      Properties: {
        east: "false", 
        south: "true", 
        north: "false", 
        west: "false", 
        up: "false"
      }, 
      Name: "minecraft:vine"
    }, 
    {
      Properties: {
        east: "false", 
        south: "false", 
        north: "true", 
        west: "false", 
        up: "false"
      }, 
      Name: "minecraft:vine"
    }, 
    {
      Properties: {
        east: "false", 
        waterlogged: "false", 
        south: "false", 
        north: "false", 
        west: "false"
      }, 
      Name: "minecraft:jungle_fence"
    }, 
    {
      Properties: {
        east: "false", 
        south: "false", 
        north: "false", 
        west: "true", 
        up: "false"
      }, 
      Name: "minecraft:vine"
    }, 
    {
      Properties: {
        facing: "north", 
        age: "2"
      }, 
      Name: "minecraft:cocoa"
    }, 
    {
      Properties: {
        facing: "west", 
        age: "2"
      }, 
      Name: "minecraft:cocoa"
    }, 
    {
      Properties: {
        facing: "south", 
        age: "2"
      }, 
      Name: "minecraft:cocoa"
    }, 
    {
      Properties: {
        orientation: "east_up"
      }, 
      Name: "minecraft:jigsaw"
    }, 
    {
      Properties: {
        waterlogged: "false", 
        signal_fire: "false", 
        lit: "false", 
        facing: "west"
      }, 
      Name: "minecraft:campfire"
    }, 
    {
      Properties: {
        waterlogged: "false", 
        facing: "south", 
        type: "single"
      }, 
      Name: "minecraft:chest"
    }
  ]
}
