{
  size: [7, 6, 8], 
  entities: [], 
  blocks: [
    {
      pos: [0, 0, 0], 
      state: 0
    }, 
    {
      pos: [1, 0, 0], 
      state: 0
    }, 
    {
      pos: [2, 0, 0], 
      state: 0
    }, 
    {
      pos: [3, 0, 0], 
      state: 0
    }, 
    {
      pos: [4, 0, 0], 
      state: 0
    }, 
    {
      pos: [5, 0, 0], 
      state: 0
    }, 
    {
      pos: [6, 0, 0], 
      state: 0
    }, 
    {
      pos: [0, 0, 1], 
      state: 0
    }, 
    {
      pos: [1, 0, 1], 
      state: 0
    }, 
    {
      pos: [6, 0, 1], 
      state: 0
    }, 
    {
      pos: [0, 0, 2], 
      state: 0
    }, 
    {
      pos: [6, 0, 2], 
      state: 0
    }, 
    {
      pos: [0, 0, 3], 
      state: 0
    }, 
    {
      pos: [6, 0, 3], 
      state: 0
    }, 
    {
      pos: [0, 0, 4], 
      state: 0
    }, 
    {
      pos: [6, 0, 4], 
      state: 0
    }, 
    {
      pos: [0, 0, 5], 
      state: 0
    }, 
    {
      pos: [6, 0, 5], 
      state: 0
    }, 
    {
      pos: [0, 0, 6], 
      state: 0
    }, 
    {
      pos: [6, 0, 6], 
      state: 0
    }, 
    {
      pos: [0, 0, 7], 
      state: 0
    }, 
    {
      pos: [1, 0, 7], 
      state: 0
    }, 
    {
      pos: [2, 0, 7], 
      state: 0
    }, 
    {
      pos: [3, 0, 7], 
      state: 0
    }, 
    {
      pos: [4, 0, 7], 
      state: 0
    }, 
    {
      pos: [5, 0, 7], 
      state: 0
    }, 
    {
      pos: [6, 0, 7], 
      state: 0
    }, 
    {
      pos: [0, 1, 0], 
      state: 0
    }, 
    {
      pos: [1, 1, 0], 
      state: 0
    }, 
    {
      pos: [2, 1, 0], 
      state: 0
    }, 
    {
      pos: [3, 1, 0], 
      state: 0
    }, 
    {
      pos: [4, 1, 0], 
      state: 0
    }, 
    {
      pos: [5, 1, 0], 
      state: 0
    }, 
    {
      pos: [6, 1, 0], 
      state: 0
    }, 
    {
      pos: [0, 1, 1], 
      state: 0
    }, 
    {
      pos: [2, 1, 1], 
      state: 0
    }, 
    {
      pos: [3, 1, 1], 
      state: 1
    }, 
    {
      pos: [4, 1, 1], 
      state: 0
    }, 
    {
      pos: [5, 1, 1], 
      state: 0
    }, 
    {
      pos: [6, 1, 1], 
      state: 0
    }, 
    {
      pos: [0, 1, 2], 
      state: 0
    }, 
    {
      pos: [1, 1, 2], 
      state: 0
    }, 
    {
      pos: [2, 1, 2], 
      state: 1
    }, 
    {
      pos: [4, 1, 2], 
      state: 1
    }, 
    {
      pos: [5, 1, 2], 
      state: 0
    }, 
    {
      pos: [6, 1, 2], 
      state: 0
    }, 
    {
      pos: [0, 1, 3], 
      state: 0
    }, 
    {
      pos: [1, 1, 3], 
      state: 1
    }, 
    {
      pos: [5, 1, 3], 
      state: 1
    }, 
    {
      pos: [6, 1, 3], 
      state: 0
    }, 
    {
      pos: [0, 1, 4], 
      state: 0
    }, 
    {
      pos: [1, 1, 4], 
      state: 1
    }, 
    {
      pos: [5, 1, 4], 
      state: 1
    }, 
    {
      pos: [6, 1, 4], 
      state: 0
    }, 
    {
      pos: [0, 1, 5], 
      state: 0
    }, 
    {
      pos: [1, 1, 5], 
      state: 0
    }, 
    {
      pos: [2, 1, 5], 
      state: 1
    }, 
    {
      pos: [4, 1, 5], 
      state: 1
    }, 
    {
      pos: [5, 1, 5], 
      state: 0
    }, 
    {
      pos: [6, 1, 5], 
      state: 0
    }, 
    {
      pos: [0, 1, 6], 
      state: 0
    }, 
    {
      pos: [1, 1, 6], 
      state: 0
    }, 
    {
      pos: [2, 1, 6], 
      state: 0
    }, 
    {
      pos: [3, 1, 6], 
      state: 1
    }, 
    {
      pos: [5, 1, 6], 
      state: 0
    }, 
    {
      pos: [6, 1, 6], 
      state: 0
    }, 
    {
      pos: [0, 1, 7], 
      state: 0
    }, 
    {
      pos: [1, 1, 7], 
      state: 0
    }, 
    {
      pos: [2, 1, 7], 
      state: 0
    }, 
    {
      pos: [3, 1, 7], 
      state: 0
    }, 
    {
      pos: [4, 1, 7], 
      state: 0
    }, 
    {
      pos: [5, 1, 7], 
      state: 0
    }, 
    {
      pos: [6, 1, 7], 
      state: 0
    }, 
    {
      nbt: {
        joint: "rollable", 
        final_state: "minecraft:blackstone", 
        name: "minecraft:empty", 
        pool: "minecraft:bastion/mobs/piglin_melee", 
        id: "minecraft:jigsaw", 
        target: "minecraft:melee_connector"
      }, 
      pos: [1, 1, 1], 
      state: 2
    }, 
    {
      nbt: {
        joint: "rollable", 
        final_state: "minecraft:air", 
        name: "minecraft:empty", 
        pool: "minecraft:bastion/mobs/piglin", 
        id: "minecraft:jigsaw", 
        target: "minecraft:mob_connector"
      }, 
      pos: [4, 1, 6], 
      state: 3
    }, 
    {
      pos: [2, 1, 3], 
      state: 4
    }, 
    {
      pos: [3, 1, 3], 
      state: 5
    }, 
    {
      pos: [4, 1, 3], 
      state: 4
    }, 
    {
      pos: [2, 1, 4], 
      state: 4
    }, 
    {
      pos: [3, 1, 4], 
      state: 6
    }, 
    {
      pos: [4, 1, 4], 
      state: 4
    }, 
    {
      pos: [0, 2, 0], 
      state: 0
    }, 
    {
      pos: [1, 2, 0], 
      state: 7
    }, 
    {
      pos: [3, 2, 0], 
      state: 0
    }, 
    {
      pos: [5, 2, 0], 
      state: 7
    }, 
    {
      pos: [6, 2, 0], 
      state: 0
    }, 
    {
      pos: [5, 2, 1], 
      state: 7
    }, 
    {
      pos: [5, 2, 2], 
      state: 7
    }, 
    {
      pos: [0, 2, 3], 
      state: 0
    }, 
    {
      pos: [5, 2, 3], 
      state: 7
    }, 
    {
      pos: [6, 2, 3], 
      state: 0
    }, 
    {
      pos: [0, 2, 4], 
      state: 0
    }, 
    {
      pos: [5, 2, 4], 
      state: 7
    }, 
    {
      pos: [6, 2, 4], 
      state: 0
    }, 
    {
      pos: [0, 2, 5], 
      state: 7
    }, 
    {
      pos: [1, 2, 5], 
      state: 7
    }, 
    {
      pos: [2, 2, 5], 
      state: 7
    }, 
    {
      pos: [4, 2, 5], 
      state: 7
    }, 
    {
      pos: [1, 2, 6], 
      state: 7
    }, 
    {
      pos: [5, 2, 6], 
      state: 7
    }, 
    {
      pos: [0, 2, 7], 
      state: 0
    }, 
    {
      pos: [3, 2, 7], 
      state: 0
    }, 
    {
      pos: [5, 2, 7], 
      state: 7
    }, 
    {
      pos: [6, 2, 7], 
      state: 0
    }, 
    {
      nbt: {
        joint: "rollable", 
        final_state: "minecraft:polished_blackstone_bricks", 
        name: "minecraft:treasure", 
        pool: "minecraft:empty", 
        id: "minecraft:jigsaw", 
        target: "minecraft:empty"
      }, 
      pos: [6, 2, 2], 
      state: 8
    }, 
    {
      nbt: {
        LootTable: "minecraft:chests/bastion_treasure", 
        id: "minecraft:chest"
      }, 
      pos: [1, 2, 4], 
      state: 9
    }, 
    {
      pos: [0, 3, 0], 
      state: 0
    }, 
    {
      pos: [6, 3, 0], 
      state: 0
    }, 
    {
      pos: [5, 3, 3], 
      state: 7
    }, 
    {
      pos: [5, 3, 4], 
      state: 7
    }, 
    {
      pos: [5, 3, 6], 
      state: 7
    }, 
    {
      pos: [0, 3, 7], 
      state: 0
    }, 
    {
      pos: [6, 3, 7], 
      state: 0
    }, 
    {
      pos: [2, 3, 1], 
      state: 10
    }, 
    {
      pos: [0, 4, 0], 
      state: 0
    }, 
    {
      pos: [1, 4, 0], 
      state: 0
    }, 
    {
      pos: [5, 4, 0], 
      state: 0
    }, 
    {
      pos: [6, 4, 0], 
      state: 0
    }, 
    {
      pos: [0, 4, 1], 
      state: 0
    }, 
    {
      pos: [6, 4, 1], 
      state: 0
    }, 
    {
      pos: [0, 4, 2], 
      state: 0
    }, 
    {
      pos: [6, 4, 2], 
      state: 0
    }, 
    {
      pos: [0, 4, 5], 
      state: 0
    }, 
    {
      pos: [6, 4, 5], 
      state: 0
    }, 
    {
      pos: [0, 4, 6], 
      state: 0
    }, 
    {
      pos: [6, 4, 6], 
      state: 0
    }, 
    {
      pos: [0, 4, 7], 
      state: 0
    }, 
    {
      pos: [1, 4, 7], 
      state: 0
    }, 
    {
      pos: [5, 4, 7], 
      state: 0
    }, 
    {
      pos: [6, 4, 7], 
      state: 0
    }, 
    {
      pos: [0, 5, 0], 
      state: 0
    }, 
    {
      pos: [1, 5, 0], 
      state: 0
    }, 
    {
      pos: [2, 5, 0], 
      state: 0
    }, 
    {
      pos: [3, 5, 0], 
      state: 0
    }, 
    {
      pos: [4, 5, 0], 
      state: 0
    }, 
    {
      pos: [5, 5, 0], 
      state: 0
    }, 
    {
      pos: [6, 5, 0], 
      state: 0
    }, 
    {
      pos: [0, 5, 1], 
      state: 0
    }, 
    {
      pos: [3, 5, 1], 
      state: 0
    }, 
    {
      pos: [6, 5, 1], 
      state: 0
    }, 
    {
      pos: [0, 5, 2], 
      state: 0
    }, 
    {
      pos: [3, 5, 2], 
      state: 0
    }, 
    {
      pos: [6, 5, 2], 
      state: 0
    }, 
    {
      pos: [0, 5, 3], 
      state: 0
    }, 
    {
      pos: [1, 5, 3], 
      state: 0
    }, 
    {
      pos: [2, 5, 3], 
      state: 0
    }, 
    {
      pos: [3, 5, 3], 
      state: 0
    }, 
    {
      pos: [4, 5, 3], 
      state: 0
    }, 
    {
      pos: [5, 5, 3], 
      state: 0
    }, 
    {
      pos: [6, 5, 3], 
      state: 0
    }, 
    {
      pos: [0, 5, 4], 
      state: 0
    }, 
    {
      pos: [1, 5, 4], 
      state: 0
    }, 
    {
      pos: [2, 5, 4], 
      state: 0
    }, 
    {
      pos: [3, 5, 4], 
      state: 0
    }, 
    {
      pos: [4, 5, 4], 
      state: 0
    }, 
    {
      pos: [5, 5, 4], 
      state: 0
    }, 
    {
      pos: [6, 5, 4], 
      state: 0
    }, 
    {
      pos: [0, 5, 5], 
      state: 0
    }, 
    {
      pos: [3, 5, 5], 
      state: 0
    }, 
    {
      pos: [6, 5, 5], 
      state: 0
    }, 
    {
      pos: [0, 5, 6], 
      state: 0
    }, 
    {
      pos: [3, 5, 6], 
      state: 0
    }, 
    {
      pos: [6, 5, 6], 
      state: 0
    }, 
    {
      pos: [0, 5, 7], 
      state: 0
    }, 
    {
      pos: [1, 5, 7], 
      state: 0
    }, 
    {
      pos: [2, 5, 7], 
      state: 0
    }, 
    {
      pos: [3, 5, 7], 
      state: 0
    }, 
    {
      pos: [4, 5, 7], 
      state: 0
    }, 
    {
      pos: [5, 5, 7], 
      state: 0
    }, 
    {
      pos: [6, 5, 7], 
      state: 0
    }
  ], 
  palette: [
    {
      Name: "minecraft:polished_blackstone_bricks"
    }, 
    {
      Name: "minecraft:blackstone"
    }, 
    {
      Properties: {
        orientation: "up_east"
      }, 
      Name: "minecraft:jigsaw"
    }, 
    {
      Properties: {
        orientation: "up_west"
      }, 
      Name: "minecraft:jigsaw"
    }, 
    {
      Properties: {
        east: "low", 
        waterlogged: "false", 
        south: "low", 
        north: "low", 
        west: "low", 
        up: "true"
      }, 
      Name: "minecraft:blackstone_wall"
    }, 
    {
      Properties: {
        east: "low", 
        waterlogged: "false", 
        south: "low", 
        north: "none", 
        west: "low", 
        up: "true"
      }, 
      Name: "minecraft:blackstone_wall"
    }, 
    {
      Properties: {
        east: "low", 
        waterlogged: "false", 
        south: "none", 
        north: "low", 
        west: "low", 
        up: "true"
      }, 
      Name: "minecraft:blackstone_wall"
    }, 
    {
      Name: "minecraft:gold_block"
    }, 
    {
      Properties: {
        orientation: "east_up"
      }, 
      Name: "minecraft:jigsaw"
    }, 
    {
      Properties: {
        waterlogged: "false", 
        facing: "east", 
        type: "single"
      }, 
      Name: "minecraft:chest"
    }, 
    {
      Name: "minecraft:air"
    }
  ]
}
