{
  size: [11, 9, 7], 
  entities: [], 
  blocks: [
    {
      pos: [0, 0, 0], 
      state: 0
    }, 
    {
      pos: [1, 0, 0], 
      state: 0
    }, 
    {
      pos: [2, 0, 0], 
      state: 0
    }, 
    {
      pos: [3, 0, 0], 
      state: 0
    }, 
    {
      pos: [4, 0, 0], 
      state: 1
    }, 
    {
      pos: [5, 0, 0], 
      state: 0
    }, 
    {
      pos: [6, 0, 0], 
      state: 0
    }, 
    {
      pos: [7, 0, 0], 
      state: 0
    }, 
    {
      pos: [8, 0, 0], 
      state: 0
    }, 
    {
      pos: [9, 0, 0], 
      state: 0
    }, 
    {
      pos: [10, 0, 0], 
      state: 0
    }, 
    {
      pos: [0, 0, 1], 
      state: 0
    }, 
    {
      pos: [1, 0, 1], 
      state: 0
    }, 
    {
      pos: [2, 0, 1], 
      state: 0
    }, 
    {
      pos: [3, 0, 1], 
      state: 0
    }, 
    {
      pos: [4, 0, 1], 
      state: 1
    }, 
    {
      pos: [5, 0, 1], 
      state: 0
    }, 
    {
      pos: [6, 0, 1], 
      state: 0
    }, 
    {
      pos: [7, 0, 1], 
      state: 0
    }, 
    {
      pos: [8, 0, 1], 
      state: 0
    }, 
    {
      pos: [9, 0, 1], 
      state: 0
    }, 
    {
      pos: [10, 0, 1], 
      state: 0
    }, 
    {
      pos: [0, 0, 2], 
      state: 0
    }, 
    {
      pos: [1, 0, 2], 
      state: 0
    }, 
    {
      pos: [2, 0, 2], 
      state: 1
    }, 
    {
      pos: [3, 0, 2], 
      state: 1
    }, 
    {
      pos: [5, 0, 2], 
      state: 0
    }, 
    {
      pos: [6, 0, 2], 
      state: 0
    }, 
    {
      pos: [7, 0, 2], 
      state: 0
    }, 
    {
      pos: [8, 0, 2], 
      state: 0
    }, 
    {
      pos: [9, 0, 2], 
      state: 0
    }, 
    {
      pos: [10, 0, 2], 
      state: 0
    }, 
    {
      pos: [0, 0, 3], 
      state: 0
    }, 
    {
      pos: [1, 0, 3], 
      state: 0
    }, 
    {
      pos: [2, 0, 3], 
      state: 1
    }, 
    {
      pos: [3, 0, 3], 
      state: 1
    }, 
    {
      pos: [4, 0, 3], 
      state: 1
    }, 
    {
      pos: [5, 0, 3], 
      state: 0
    }, 
    {
      pos: [6, 0, 3], 
      state: 0
    }, 
    {
      pos: [7, 0, 3], 
      state: 0
    }, 
    {
      pos: [8, 0, 3], 
      state: 0
    }, 
    {
      pos: [9, 0, 3], 
      state: 0
    }, 
    {
      pos: [10, 0, 3], 
      state: 0
    }, 
    {
      pos: [0, 0, 4], 
      state: 0
    }, 
    {
      pos: [1, 0, 4], 
      state: 0
    }, 
    {
      pos: [2, 0, 4], 
      state: 1
    }, 
    {
      pos: [3, 0, 4], 
      state: 1
    }, 
    {
      pos: [4, 0, 4], 
      state: 1
    }, 
    {
      pos: [5, 0, 4], 
      state: 0
    }, 
    {
      pos: [6, 0, 4], 
      state: 0
    }, 
    {
      pos: [7, 0, 4], 
      state: 0
    }, 
    {
      pos: [8, 0, 4], 
      state: 0
    }, 
    {
      pos: [9, 0, 4], 
      state: 0
    }, 
    {
      pos: [10, 0, 4], 
      state: 0
    }, 
    {
      pos: [0, 0, 5], 
      state: 0
    }, 
    {
      pos: [1, 0, 5], 
      state: 0
    }, 
    {
      pos: [2, 0, 5], 
      state: 0
    }, 
    {
      pos: [3, 0, 5], 
      state: 0
    }, 
    {
      pos: [4, 0, 5], 
      state: 0
    }, 
    {
      pos: [5, 0, 5], 
      state: 0
    }, 
    {
      pos: [6, 0, 5], 
      state: 0
    }, 
    {
      pos: [7, 0, 5], 
      state: 0
    }, 
    {
      pos: [8, 0, 5], 
      state: 0
    }, 
    {
      pos: [9, 0, 5], 
      state: 0
    }, 
    {
      pos: [10, 0, 5], 
      state: 0
    }, 
    {
      pos: [0, 0, 6], 
      state: 0
    }, 
    {
      pos: [1, 0, 6], 
      state: 0
    }, 
    {
      pos: [2, 0, 6], 
      state: 0
    }, 
    {
      pos: [3, 0, 6], 
      state: 0
    }, 
    {
      pos: [4, 0, 6], 
      state: 0
    }, 
    {
      pos: [5, 0, 6], 
      state: 0
    }, 
    {
      pos: [6, 0, 6], 
      state: 0
    }, 
    {
      pos: [7, 0, 6], 
      state: 0
    }, 
    {
      pos: [8, 0, 6], 
      state: 0
    }, 
    {
      pos: [9, 0, 6], 
      state: 0
    }, 
    {
      pos: [10, 0, 6], 
      state: 0
    }, 
    {
      nbt: {
        final_state: "minecraft:smooth_sandstone", 
        name: "minecraft:bottom", 
        pool: "minecraft:village/desert/zombie/villagers", 
        id: "minecraft:jigsaw", 
        target: "minecraft:bottom"
      }, 
      pos: [4, 0, 2], 
      state: 2
    }, 
    {
      pos: [6, 1, 0], 
      state: 1
    }, 
    {
      pos: [7, 1, 0], 
      state: 1
    }, 
    {
      pos: [8, 1, 0], 
      state: 1
    }, 
    {
      pos: [1, 1, 1], 
      state: 1
    }, 
    {
      pos: [2, 1, 1], 
      state: 1
    }, 
    {
      pos: [3, 1, 1], 
      state: 1
    }, 
    {
      pos: [5, 1, 1], 
      state: 1
    }, 
    {
      pos: [6, 1, 1], 
      state: 1
    }, 
    {
      pos: [7, 1, 1], 
      state: 1
    }, 
    {
      pos: [8, 1, 1], 
      state: 1
    }, 
    {
      pos: [9, 1, 1], 
      state: 1
    }, 
    {
      pos: [1, 1, 2], 
      state: 1
    }, 
    {
      pos: [5, 1, 2], 
      state: 1
    }, 
    {
      pos: [6, 1, 2], 
      state: 1
    }, 
    {
      pos: [7, 1, 2], 
      state: 1
    }, 
    {
      pos: [8, 1, 2], 
      state: 1
    }, 
    {
      pos: [9, 1, 2], 
      state: 1
    }, 
    {
      pos: [1, 1, 3], 
      state: 1
    }, 
    {
      pos: [5, 1, 3], 
      state: 1
    }, 
    {
      pos: [6, 1, 3], 
      state: 1
    }, 
    {
      pos: [7, 1, 3], 
      state: 1
    }, 
    {
      pos: [8, 1, 3], 
      state: 1
    }, 
    {
      pos: [9, 1, 3], 
      state: 1
    }, 
    {
      pos: [1, 1, 4], 
      state: 1
    }, 
    {
      pos: [5, 1, 4], 
      state: 1
    }, 
    {
      pos: [6, 1, 4], 
      state: 1
    }, 
    {
      pos: [7, 1, 4], 
      state: 1
    }, 
    {
      pos: [8, 1, 4], 
      state: 1
    }, 
    {
      pos: [9, 1, 4], 
      state: 1
    }, 
    {
      pos: [1, 1, 5], 
      state: 1
    }, 
    {
      pos: [2, 1, 5], 
      state: 1
    }, 
    {
      pos: [3, 1, 5], 
      state: 1
    }, 
    {
      pos: [4, 1, 5], 
      state: 1
    }, 
    {
      pos: [5, 1, 5], 
      state: 1
    }, 
    {
      nbt: {
        final_state: "minecraft:structure_void", 
        name: "minecraft:building_entrance", 
        pool: "minecraft:empty", 
        id: "minecraft:jigsaw", 
        target: "minecraft:building_entrance"
      }, 
      pos: [4, 1, 0], 
      state: 3
    }, 
    {
      nbt: {
        id: "minecraft:bed"
      }, 
      pos: [2, 1, 3], 
      state: 4
    }, 
    {
      nbt: {
        id: "minecraft:bed"
      }, 
      pos: [2, 1, 4], 
      state: 5
    }, 
    {
      pos: [0, 1, 0], 
      state: 6
    }, 
    {
      pos: [1, 1, 0], 
      state: 6
    }, 
    {
      pos: [2, 1, 0], 
      state: 6
    }, 
    {
      pos: [3, 1, 0], 
      state: 7
    }, 
    {
      pos: [5, 1, 0], 
      state: 8
    }, 
    {
      pos: [9, 1, 0], 
      state: 9
    }, 
    {
      pos: [10, 1, 0], 
      state: 6
    }, 
    {
      pos: [0, 1, 1], 
      state: 6
    }, 
    {
      pos: [4, 1, 1], 
      state: 10
    }, 
    {
      pos: [10, 1, 1], 
      state: 6
    }, 
    {
      pos: [0, 1, 2], 
      state: 6
    }, 
    {
      pos: [2, 1, 2], 
      state: 6
    }, 
    {
      pos: [3, 1, 2], 
      state: 6
    }, 
    {
      pos: [4, 1, 2], 
      state: 6
    }, 
    {
      pos: [10, 1, 2], 
      state: 6
    }, 
    {
      pos: [0, 1, 3], 
      state: 6
    }, 
    {
      pos: [3, 1, 3], 
      state: 6
    }, 
    {
      pos: [4, 1, 3], 
      state: 6
    }, 
    {
      pos: [10, 1, 3], 
      state: 6
    }, 
    {
      pos: [0, 1, 4], 
      state: 6
    }, 
    {
      pos: [3, 1, 4], 
      state: 6
    }, 
    {
      pos: [4, 1, 4], 
      state: 6
    }, 
    {
      pos: [10, 1, 4], 
      state: 6
    }, 
    {
      pos: [0, 1, 5], 
      state: 6
    }, 
    {
      pos: [6, 1, 5], 
      state: 6
    }, 
    {
      pos: [7, 1, 5], 
      state: 6
    }, 
    {
      pos: [8, 1, 5], 
      state: 6
    }, 
    {
      pos: [9, 1, 5], 
      state: 6
    }, 
    {
      pos: [10, 1, 5], 
      state: 6
    }, 
    {
      pos: [0, 1, 6], 
      state: 6
    }, 
    {
      pos: [1, 1, 6], 
      state: 6
    }, 
    {
      pos: [2, 1, 6], 
      state: 6
    }, 
    {
      pos: [3, 1, 6], 
      state: 6
    }, 
    {
      pos: [4, 1, 6], 
      state: 6
    }, 
    {
      pos: [5, 1, 6], 
      state: 6
    }, 
    {
      pos: [6, 1, 6], 
      state: 6
    }, 
    {
      pos: [7, 1, 6], 
      state: 6
    }, 
    {
      pos: [8, 1, 6], 
      state: 6
    }, 
    {
      pos: [9, 1, 6], 
      state: 6
    }, 
    {
      pos: [10, 1, 6], 
      state: 6
    }, 
    {
      pos: [7, 2, 0], 
      state: 1
    }, 
    {
      pos: [1, 2, 1], 
      state: 1
    }, 
    {
      pos: [2, 2, 1], 
      state: 1
    }, 
    {
      pos: [3, 2, 1], 
      state: 1
    }, 
    {
      pos: [5, 2, 1], 
      state: 1
    }, 
    {
      pos: [6, 2, 1], 
      state: 1
    }, 
    {
      pos: [7, 2, 1], 
      state: 1
    }, 
    {
      pos: [8, 2, 1], 
      state: 1
    }, 
    {
      pos: [9, 2, 1], 
      state: 1
    }, 
    {
      pos: [1, 2, 2], 
      state: 1
    }, 
    {
      pos: [5, 2, 2], 
      state: 1
    }, 
    {
      pos: [6, 2, 2], 
      state: 1
    }, 
    {
      pos: [8, 2, 2], 
      state: 1
    }, 
    {
      pos: [9, 2, 2], 
      state: 1
    }, 
    {
      pos: [1, 2, 3], 
      state: 1
    }, 
    {
      pos: [5, 2, 3], 
      state: 1
    }, 
    {
      pos: [6, 2, 3], 
      state: 1
    }, 
    {
      pos: [7, 2, 3], 
      state: 1
    }, 
    {
      pos: [8, 2, 3], 
      state: 1
    }, 
    {
      pos: [9, 2, 3], 
      state: 1
    }, 
    {
      pos: [1, 2, 4], 
      state: 1
    }, 
    {
      pos: [5, 2, 4], 
      state: 1
    }, 
    {
      pos: [6, 2, 4], 
      state: 1
    }, 
    {
      pos: [7, 2, 4], 
      state: 1
    }, 
    {
      pos: [8, 2, 4], 
      state: 1
    }, 
    {
      pos: [9, 2, 4], 
      state: 1
    }, 
    {
      pos: [1, 2, 5], 
      state: 1
    }, 
    {
      pos: [2, 2, 5], 
      state: 1
    }, 
    {
      pos: [3, 2, 5], 
      state: 1
    }, 
    {
      pos: [4, 2, 5], 
      state: 1
    }, 
    {
      pos: [5, 2, 5], 
      state: 1
    }, 
    {
      nbt: {
        final_state: "minecraft:smooth_sandstone", 
        name: "minecraft:bottom", 
        pool: "minecraft:village/desert/zombie/villagers", 
        id: "minecraft:jigsaw", 
        target: "minecraft:bottom"
      }, 
      pos: [7, 2, 2], 
      state: 2
    }, 
    {
      pos: [0, 2, 0], 
      state: 6
    }, 
    {
      pos: [1, 2, 0], 
      state: 6
    }, 
    {
      pos: [2, 2, 0], 
      state: 6
    }, 
    {
      pos: [3, 2, 0], 
      state: 6
    }, 
    {
      pos: [4, 2, 0], 
      state: 6
    }, 
    {
      pos: [5, 2, 0], 
      state: 6
    }, 
    {
      pos: [6, 2, 0], 
      state: 8
    }, 
    {
      pos: [8, 2, 0], 
      state: 9
    }, 
    {
      pos: [9, 2, 0], 
      state: 6
    }, 
    {
      pos: [10, 2, 0], 
      state: 6
    }, 
    {
      pos: [0, 2, 1], 
      state: 6
    }, 
    {
      pos: [4, 2, 1], 
      state: 11
    }, 
    {
      pos: [10, 2, 1], 
      state: 6
    }, 
    {
      pos: [0, 2, 2], 
      state: 6
    }, 
    {
      pos: [2, 2, 2], 
      state: 6
    }, 
    {
      pos: [3, 2, 2], 
      state: 6
    }, 
    {
      pos: [4, 2, 2], 
      state: 6
    }, 
    {
      pos: [10, 2, 2], 
      state: 6
    }, 
    {
      pos: [0, 2, 3], 
      state: 6
    }, 
    {
      pos: [2, 2, 3], 
      state: 12
    }, 
    {
      pos: [3, 2, 3], 
      state: 6
    }, 
    {
      pos: [4, 2, 3], 
      state: 6
    }, 
    {
      pos: [10, 2, 3], 
      state: 6
    }, 
    {
      pos: [0, 2, 4], 
      state: 6
    }, 
    {
      pos: [2, 2, 4], 
      state: 6
    }, 
    {
      pos: [3, 2, 4], 
      state: 6
    }, 
    {
      pos: [4, 2, 4], 
      state: 13
    }, 
    {
      pos: [10, 2, 4], 
      state: 6
    }, 
    {
      pos: [0, 2, 5], 
      state: 6
    }, 
    {
      pos: [6, 2, 5], 
      state: 6
    }, 
    {
      pos: [7, 2, 5], 
      state: 6
    }, 
    {
      pos: [8, 2, 5], 
      state: 6
    }, 
    {
      pos: [9, 2, 5], 
      state: 6
    }, 
    {
      pos: [10, 2, 5], 
      state: 6
    }, 
    {
      pos: [0, 2, 6], 
      state: 6
    }, 
    {
      pos: [1, 2, 6], 
      state: 6
    }, 
    {
      pos: [2, 2, 6], 
      state: 6
    }, 
    {
      pos: [3, 2, 6], 
      state: 6
    }, 
    {
      pos: [4, 2, 6], 
      state: 6
    }, 
    {
      pos: [5, 2, 6], 
      state: 6
    }, 
    {
      pos: [6, 2, 6], 
      state: 6
    }, 
    {
      pos: [7, 2, 6], 
      state: 6
    }, 
    {
      pos: [8, 2, 6], 
      state: 6
    }, 
    {
      pos: [9, 2, 6], 
      state: 6
    }, 
    {
      pos: [10, 2, 6], 
      state: 6
    }, 
    {
      pos: [1, 3, 1], 
      state: 1
    }, 
    {
      pos: [2, 3, 1], 
      state: 1
    }, 
    {
      pos: [3, 3, 1], 
      state: 1
    }, 
    {
      pos: [4, 3, 1], 
      state: 1
    }, 
    {
      pos: [5, 3, 1], 
      state: 1
    }, 
    {
      pos: [6, 3, 1], 
      state: 1
    }, 
    {
      pos: [8, 3, 1], 
      state: 1
    }, 
    {
      pos: [9, 3, 1], 
      state: 1
    }, 
    {
      pos: [1, 3, 2], 
      state: 1
    }, 
    {
      pos: [2, 3, 2], 
      state: 1
    }, 
    {
      pos: [3, 3, 2], 
      state: 1
    }, 
    {
      pos: [4, 3, 2], 
      state: 1
    }, 
    {
      pos: [5, 3, 2], 
      state: 1
    }, 
    {
      pos: [9, 3, 2], 
      state: 1
    }, 
    {
      pos: [1, 3, 3], 
      state: 1
    }, 
    {
      pos: [2, 3, 3], 
      state: 1
    }, 
    {
      pos: [3, 3, 3], 
      state: 1
    }, 
    {
      pos: [4, 3, 3], 
      state: 1
    }, 
    {
      pos: [5, 3, 3], 
      state: 1
    }, 
    {
      pos: [9, 3, 3], 
      state: 1
    }, 
    {
      pos: [1, 3, 4], 
      state: 1
    }, 
    {
      pos: [2, 3, 4], 
      state: 1
    }, 
    {
      pos: [3, 3, 4], 
      state: 1
    }, 
    {
      pos: [5, 3, 4], 
      state: 1
    }, 
    {
      pos: [6, 3, 4], 
      state: 1
    }, 
    {
      pos: [7, 3, 4], 
      state: 1
    }, 
    {
      pos: [8, 3, 4], 
      state: 1
    }, 
    {
      pos: [9, 3, 4], 
      state: 1
    }, 
    {
      pos: [1, 3, 5], 
      state: 1
    }, 
    {
      pos: [2, 3, 5], 
      state: 1
    }, 
    {
      pos: [3, 3, 5], 
      state: 1
    }, 
    {
      pos: [4, 3, 5], 
      state: 1
    }, 
    {
      pos: [5, 3, 5], 
      state: 1
    }, 
    {
      nbt: {
        id: "minecraft:bed"
      }, 
      pos: [6, 3, 3], 
      state: 14
    }, 
    {
      nbt: {
        id: "minecraft:bed"
      }, 
      pos: [7, 3, 3], 
      state: 15
    }, 
    {
      nbt: {
        LootTable: "minecraft:chests/village/village_desert_house", 
        Items: [], 
        id: "minecraft:chest", 
        LootTableSeed: 0L
      }, 
      pos: [8, 3, 3], 
      state: 16
    }, 
    {
      pos: [0, 3, 0], 
      state: 6
    }, 
    {
      pos: [1, 3, 0], 
      state: 17
    }, 
    {
      pos: [2, 3, 0], 
      state: 17
    }, 
    {
      pos: [3, 3, 0], 
      state: 17
    }, 
    {
      pos: [4, 3, 0], 
      state: 17
    }, 
    {
      pos: [5, 3, 0], 
      state: 17
    }, 
    {
      pos: [6, 3, 0], 
      state: 17
    }, 
    {
      pos: [7, 3, 0], 
      state: 6
    }, 
    {
      pos: [8, 3, 0], 
      state: 17
    }, 
    {
      pos: [9, 3, 0], 
      state: 17
    }, 
    {
      pos: [10, 3, 0], 
      state: 6
    }, 
    {
      pos: [0, 3, 1], 
      state: 18
    }, 
    {
      pos: [7, 3, 1], 
      state: 10
    }, 
    {
      pos: [10, 3, 1], 
      state: 19
    }, 
    {
      pos: [0, 3, 2], 
      state: 18
    }, 
    {
      pos: [6, 3, 2], 
      state: 6
    }, 
    {
      pos: [7, 3, 2], 
      state: 6
    }, 
    {
      pos: [8, 3, 2], 
      state: 6
    }, 
    {
      pos: [10, 3, 2], 
      state: 19
    }, 
    {
      pos: [0, 3, 3], 
      state: 18
    }, 
    {
      pos: [10, 3, 3], 
      state: 19
    }, 
    {
      pos: [0, 3, 4], 
      state: 18
    }, 
    {
      pos: [4, 3, 4], 
      state: 13
    }, 
    {
      pos: [10, 3, 4], 
      state: 19
    }, 
    {
      pos: [0, 3, 5], 
      state: 18
    }, 
    {
      pos: [6, 3, 5], 
      state: 20
    }, 
    {
      pos: [7, 3, 5], 
      state: 20
    }, 
    {
      pos: [8, 3, 5], 
      state: 20
    }, 
    {
      pos: [9, 3, 5], 
      state: 20
    }, 
    {
      pos: [10, 3, 5], 
      state: 6
    }, 
    {
      pos: [0, 3, 6], 
      state: 6
    }, 
    {
      pos: [1, 3, 6], 
      state: 20
    }, 
    {
      pos: [2, 3, 6], 
      state: 20
    }, 
    {
      pos: [3, 3, 6], 
      state: 20
    }, 
    {
      pos: [4, 3, 6], 
      state: 20
    }, 
    {
      pos: [5, 3, 6], 
      state: 20
    }, 
    {
      pos: [6, 3, 6], 
      state: 6
    }, 
    {
      pos: [7, 3, 6], 
      state: 6
    }, 
    {
      pos: [8, 3, 6], 
      state: 6
    }, 
    {
      pos: [9, 3, 6], 
      state: 6
    }, 
    {
      pos: [10, 3, 6], 
      state: 6
    }, 
    {
      pos: [5, 4, 1], 
      state: 1
    }, 
    {
      pos: [6, 4, 1], 
      state: 1
    }, 
    {
      pos: [8, 4, 1], 
      state: 1
    }, 
    {
      pos: [9, 4, 1], 
      state: 1
    }, 
    {
      pos: [5, 4, 2], 
      state: 1
    }, 
    {
      pos: [9, 4, 2], 
      state: 1
    }, 
    {
      pos: [1, 4, 3], 
      state: 1
    }, 
    {
      pos: [2, 4, 3], 
      state: 1
    }, 
    {
      pos: [4, 4, 3], 
      state: 1
    }, 
    {
      pos: [5, 4, 3], 
      state: 1
    }, 
    {
      pos: [9, 4, 3], 
      state: 1
    }, 
    {
      pos: [1, 4, 4], 
      state: 1
    }, 
    {
      pos: [5, 4, 4], 
      state: 1
    }, 
    {
      pos: [6, 4, 4], 
      state: 1
    }, 
    {
      pos: [7, 4, 4], 
      state: 1
    }, 
    {
      pos: [8, 4, 4], 
      state: 1
    }, 
    {
      pos: [9, 4, 4], 
      state: 1
    }, 
    {
      pos: [1, 4, 5], 
      state: 1
    }, 
    {
      pos: [2, 4, 5], 
      state: 1
    }, 
    {
      pos: [3, 4, 5], 
      state: 1
    }, 
    {
      pos: [4, 4, 5], 
      state: 1
    }, 
    {
      pos: [5, 4, 5], 
      state: 1
    }, 
    {
      pos: [0, 4, 0], 
      state: 6
    }, 
    {
      pos: [1, 4, 0], 
      state: 6
    }, 
    {
      pos: [2, 4, 0], 
      state: 6
    }, 
    {
      pos: [3, 4, 0], 
      state: 6
    }, 
    {
      pos: [4, 4, 0], 
      state: 6
    }, 
    {
      pos: [5, 4, 0], 
      state: 6
    }, 
    {
      pos: [6, 4, 0], 
      state: 6
    }, 
    {
      pos: [7, 4, 0], 
      state: 6
    }, 
    {
      pos: [8, 4, 0], 
      state: 6
    }, 
    {
      pos: [9, 4, 0], 
      state: 6
    }, 
    {
      pos: [10, 4, 0], 
      state: 6
    }, 
    {
      pos: [0, 4, 1], 
      state: 6
    }, 
    {
      pos: [1, 4, 1], 
      state: 21
    }, 
    {
      pos: [2, 4, 1], 
      state: 21
    }, 
    {
      pos: [3, 4, 1], 
      state: 21
    }, 
    {
      pos: [4, 4, 1], 
      state: 21
    }, 
    {
      pos: [7, 4, 1], 
      state: 11
    }, 
    {
      pos: [10, 4, 1], 
      state: 6
    }, 
    {
      pos: [0, 4, 2], 
      state: 6
    }, 
    {
      pos: [1, 4, 2], 
      state: 21
    }, 
    {
      pos: [2, 4, 2], 
      state: 6
    }, 
    {
      pos: [3, 4, 2], 
      state: 6
    }, 
    {
      pos: [4, 4, 2], 
      state: 7
    }, 
    {
      pos: [6, 4, 2], 
      state: 22
    }, 
    {
      pos: [7, 4, 2], 
      state: 6
    }, 
    {
      pos: [8, 4, 2], 
      state: 22
    }, 
    {
      pos: [10, 4, 2], 
      state: 6
    }, 
    {
      pos: [0, 4, 3], 
      state: 6
    }, 
    {
      pos: [3, 4, 3], 
      state: 10
    }, 
    {
      pos: [6, 4, 3], 
      state: 6
    }, 
    {
      pos: [7, 4, 3], 
      state: 6
    }, 
    {
      pos: [8, 4, 3], 
      state: 6
    }, 
    {
      pos: [10, 4, 3], 
      state: 6
    }, 
    {
      pos: [0, 4, 4], 
      state: 6
    }, 
    {
      pos: [2, 4, 4], 
      state: 6
    }, 
    {
      pos: [3, 4, 4], 
      state: 6
    }, 
    {
      pos: [4, 4, 4], 
      state: 6
    }, 
    {
      pos: [10, 4, 4], 
      state: 6
    }, 
    {
      pos: [0, 4, 5], 
      state: 6
    }, 
    {
      pos: [6, 4, 5], 
      state: 6
    }, 
    {
      pos: [7, 4, 5], 
      state: 6
    }, 
    {
      pos: [8, 4, 5], 
      state: 6
    }, 
    {
      pos: [9, 4, 5], 
      state: 6
    }, 
    {
      pos: [10, 4, 5], 
      state: 6
    }, 
    {
      pos: [0, 4, 6], 
      state: 6
    }, 
    {
      pos: [1, 4, 6], 
      state: 6
    }, 
    {
      pos: [2, 4, 6], 
      state: 6
    }, 
    {
      pos: [3, 4, 6], 
      state: 6
    }, 
    {
      pos: [4, 4, 6], 
      state: 6
    }, 
    {
      pos: [5, 4, 6], 
      state: 6
    }, 
    {
      pos: [6, 4, 6], 
      state: 6
    }, 
    {
      pos: [7, 4, 6], 
      state: 6
    }, 
    {
      pos: [8, 4, 6], 
      state: 6
    }, 
    {
      pos: [9, 4, 6], 
      state: 6
    }, 
    {
      pos: [10, 4, 6], 
      state: 6
    }, 
    {
      pos: [5, 5, 1], 
      state: 1
    }, 
    {
      pos: [6, 5, 1], 
      state: 1
    }, 
    {
      pos: [7, 5, 1], 
      state: 1
    }, 
    {
      pos: [8, 5, 1], 
      state: 1
    }, 
    {
      pos: [9, 5, 1], 
      state: 1
    }, 
    {
      pos: [5, 5, 2], 
      state: 1
    }, 
    {
      pos: [9, 5, 2], 
      state: 1
    }, 
    {
      pos: [1, 5, 3], 
      state: 1
    }, 
    {
      pos: [2, 5, 3], 
      state: 1
    }, 
    {
      pos: [4, 5, 3], 
      state: 1
    }, 
    {
      pos: [5, 5, 3], 
      state: 1
    }, 
    {
      pos: [9, 5, 3], 
      state: 1
    }, 
    {
      pos: [1, 5, 4], 
      state: 1
    }, 
    {
      pos: [5, 5, 4], 
      state: 1
    }, 
    {
      pos: [6, 5, 4], 
      state: 1
    }, 
    {
      pos: [7, 5, 4], 
      state: 1
    }, 
    {
      pos: [8, 5, 4], 
      state: 1
    }, 
    {
      pos: [9, 5, 4], 
      state: 1
    }, 
    {
      pos: [1, 5, 5], 
      state: 1
    }, 
    {
      pos: [2, 5, 5], 
      state: 1
    }, 
    {
      pos: [3, 5, 5], 
      state: 1
    }, 
    {
      pos: [4, 5, 5], 
      state: 1
    }, 
    {
      pos: [5, 5, 5], 
      state: 1
    }, 
    {
      pos: [0, 5, 0], 
      state: 6
    }, 
    {
      pos: [1, 5, 0], 
      state: 6
    }, 
    {
      pos: [2, 5, 0], 
      state: 6
    }, 
    {
      pos: [3, 5, 0], 
      state: 6
    }, 
    {
      pos: [4, 5, 0], 
      state: 6
    }, 
    {
      pos: [5, 5, 0], 
      state: 6
    }, 
    {
      pos: [6, 5, 0], 
      state: 6
    }, 
    {
      pos: [7, 5, 0], 
      state: 23
    }, 
    {
      pos: [8, 5, 0], 
      state: 6
    }, 
    {
      pos: [9, 5, 0], 
      state: 6
    }, 
    {
      pos: [10, 5, 0], 
      state: 6
    }, 
    {
      pos: [0, 5, 1], 
      state: 6
    }, 
    {
      pos: [1, 5, 1], 
      state: 6
    }, 
    {
      pos: [2, 5, 1], 
      state: 6
    }, 
    {
      pos: [3, 5, 1], 
      state: 6
    }, 
    {
      pos: [4, 5, 1], 
      state: 6
    }, 
    {
      pos: [10, 5, 1], 
      state: 6
    }, 
    {
      pos: [0, 5, 2], 
      state: 6
    }, 
    {
      pos: [1, 5, 2], 
      state: 6
    }, 
    {
      pos: [2, 5, 2], 
      state: 6
    }, 
    {
      pos: [3, 5, 2], 
      state: 6
    }, 
    {
      pos: [4, 5, 2], 
      state: 6
    }, 
    {
      pos: [6, 5, 2], 
      state: 24
    }, 
    {
      pos: [7, 5, 2], 
      state: 24
    }, 
    {
      pos: [8, 5, 2], 
      state: 24
    }, 
    {
      pos: [10, 5, 2], 
      state: 6
    }, 
    {
      pos: [0, 5, 3], 
      state: 6
    }, 
    {
      pos: [3, 5, 3], 
      state: 11
    }, 
    {
      pos: [6, 5, 3], 
      state: 24
    }, 
    {
      pos: [7, 5, 3], 
      state: 24
    }, 
    {
      pos: [8, 5, 3], 
      state: 24
    }, 
    {
      pos: [10, 5, 3], 
      state: 6
    }, 
    {
      pos: [0, 5, 4], 
      state: 6
    }, 
    {
      pos: [2, 5, 4], 
      state: 12
    }, 
    {
      pos: [3, 5, 4], 
      state: 6
    }, 
    {
      pos: [4, 5, 4], 
      state: 6
    }, 
    {
      pos: [10, 5, 4], 
      state: 6
    }, 
    {
      pos: [0, 5, 5], 
      state: 6
    }, 
    {
      pos: [6, 5, 5], 
      state: 6
    }, 
    {
      pos: [7, 5, 5], 
      state: 6
    }, 
    {
      pos: [8, 5, 5], 
      state: 6
    }, 
    {
      pos: [9, 5, 5], 
      state: 6
    }, 
    {
      pos: [10, 5, 5], 
      state: 6
    }, 
    {
      pos: [0, 5, 6], 
      state: 6
    }, 
    {
      pos: [1, 5, 6], 
      state: 6
    }, 
    {
      pos: [2, 5, 6], 
      state: 6
    }, 
    {
      pos: [3, 5, 6], 
      state: 6
    }, 
    {
      pos: [4, 5, 6], 
      state: 6
    }, 
    {
      pos: [5, 5, 6], 
      state: 6
    }, 
    {
      pos: [6, 5, 6], 
      state: 6
    }, 
    {
      pos: [7, 5, 6], 
      state: 6
    }, 
    {
      pos: [8, 5, 6], 
      state: 6
    }, 
    {
      pos: [9, 5, 6], 
      state: 6
    }, 
    {
      pos: [10, 5, 6], 
      state: 6
    }, 
    {
      pos: [1, 6, 3], 
      state: 1
    }, 
    {
      pos: [2, 6, 3], 
      state: 1
    }, 
    {
      pos: [3, 6, 3], 
      state: 1
    }, 
    {
      pos: [4, 6, 3], 
      state: 1
    }, 
    {
      pos: [5, 6, 3], 
      state: 1
    }, 
    {
      pos: [1, 6, 4], 
      state: 1
    }, 
    {
      pos: [5, 6, 4], 
      state: 1
    }, 
    {
      pos: [1, 6, 5], 
      state: 1
    }, 
    {
      pos: [2, 6, 5], 
      state: 1
    }, 
    {
      pos: [3, 6, 5], 
      state: 1
    }, 
    {
      pos: [4, 6, 5], 
      state: 1
    }, 
    {
      pos: [5, 6, 5], 
      state: 1
    }, 
    {
      pos: [0, 6, 0], 
      state: 6
    }, 
    {
      pos: [1, 6, 0], 
      state: 6
    }, 
    {
      pos: [2, 6, 0], 
      state: 6
    }, 
    {
      pos: [3, 6, 0], 
      state: 6
    }, 
    {
      pos: [4, 6, 0], 
      state: 6
    }, 
    {
      pos: [5, 6, 0], 
      state: 6
    }, 
    {
      pos: [6, 6, 0], 
      state: 6
    }, 
    {
      pos: [7, 6, 0], 
      state: 6
    }, 
    {
      pos: [8, 6, 0], 
      state: 6
    }, 
    {
      pos: [9, 6, 0], 
      state: 6
    }, 
    {
      pos: [10, 6, 0], 
      state: 6
    }, 
    {
      pos: [0, 6, 1], 
      state: 6
    }, 
    {
      pos: [1, 6, 1], 
      state: 6
    }, 
    {
      pos: [2, 6, 1], 
      state: 6
    }, 
    {
      pos: [3, 6, 1], 
      state: 6
    }, 
    {
      pos: [4, 6, 1], 
      state: 6
    }, 
    {
      pos: [5, 6, 1], 
      state: 21
    }, 
    {
      pos: [6, 6, 1], 
      state: 6
    }, 
    {
      pos: [7, 6, 1], 
      state: 6
    }, 
    {
      pos: [8, 6, 1], 
      state: 6
    }, 
    {
      pos: [9, 6, 1], 
      state: 21
    }, 
    {
      pos: [10, 6, 1], 
      state: 6
    }, 
    {
      pos: [0, 6, 2], 
      state: 6
    }, 
    {
      pos: [1, 6, 2], 
      state: 17
    }, 
    {
      pos: [2, 6, 2], 
      state: 17
    }, 
    {
      pos: [3, 6, 2], 
      state: 17
    }, 
    {
      pos: [4, 6, 2], 
      state: 17
    }, 
    {
      pos: [5, 6, 2], 
      state: 17
    }, 
    {
      pos: [6, 6, 2], 
      state: 6
    }, 
    {
      pos: [7, 6, 2], 
      state: 6
    }, 
    {
      pos: [8, 6, 2], 
      state: 6
    }, 
    {
      pos: [9, 6, 2], 
      state: 6
    }, 
    {
      pos: [10, 6, 2], 
      state: 6
    }, 
    {
      pos: [0, 6, 3], 
      state: 18
    }, 
    {
      pos: [6, 6, 3], 
      state: 19
    }, 
    {
      pos: [7, 6, 3], 
      state: 6
    }, 
    {
      pos: [8, 6, 3], 
      state: 6
    }, 
    {
      pos: [9, 6, 3], 
      state: 6
    }, 
    {
      pos: [10, 6, 3], 
      state: 6
    }, 
    {
      pos: [0, 6, 4], 
      state: 18
    }, 
    {
      pos: [2, 6, 4], 
      state: 6
    }, 
    {
      pos: [3, 6, 4], 
      state: 6
    }, 
    {
      pos: [4, 6, 4], 
      state: 6
    }, 
    {
      pos: [6, 6, 4], 
      state: 21
    }, 
    {
      pos: [7, 6, 4], 
      state: 6
    }, 
    {
      pos: [8, 6, 4], 
      state: 6
    }, 
    {
      pos: [9, 6, 4], 
      state: 21
    }, 
    {
      pos: [10, 6, 4], 
      state: 6
    }, 
    {
      pos: [0, 6, 5], 
      state: 18
    }, 
    {
      pos: [6, 6, 5], 
      state: 19
    }, 
    {
      pos: [7, 6, 5], 
      state: 6
    }, 
    {
      pos: [8, 6, 5], 
      state: 6
    }, 
    {
      pos: [9, 6, 5], 
      state: 6
    }, 
    {
      pos: [10, 6, 5], 
      state: 6
    }, 
    {
      pos: [0, 6, 6], 
      state: 6
    }, 
    {
      pos: [1, 6, 6], 
      state: 20
    }, 
    {
      pos: [2, 6, 6], 
      state: 20
    }, 
    {
      pos: [3, 6, 6], 
      state: 20
    }, 
    {
      pos: [4, 6, 6], 
      state: 20
    }, 
    {
      pos: [5, 6, 6], 
      state: 20
    }, 
    {
      pos: [6, 6, 6], 
      state: 6
    }, 
    {
      pos: [7, 6, 6], 
      state: 6
    }, 
    {
      pos: [8, 6, 6], 
      state: 6
    }, 
    {
      pos: [9, 6, 6], 
      state: 6
    }, 
    {
      pos: [10, 6, 6], 
      state: 6
    }, 
    {
      pos: [1, 7, 3], 
      state: 25
    }, 
    {
      pos: [5, 7, 3], 
      state: 25
    }, 
    {
      pos: [1, 7, 5], 
      state: 25
    }, 
    {
      pos: [5, 7, 5], 
      state: 25
    }, 
    {
      pos: [0, 7, 0], 
      state: 6
    }, 
    {
      pos: [1, 7, 0], 
      state: 6
    }, 
    {
      pos: [2, 7, 0], 
      state: 6
    }, 
    {
      pos: [3, 7, 0], 
      state: 6
    }, 
    {
      pos: [4, 7, 0], 
      state: 6
    }, 
    {
      pos: [5, 7, 0], 
      state: 6
    }, 
    {
      pos: [6, 7, 0], 
      state: 6
    }, 
    {
      pos: [7, 7, 0], 
      state: 6
    }, 
    {
      pos: [8, 7, 0], 
      state: 6
    }, 
    {
      pos: [9, 7, 0], 
      state: 6
    }, 
    {
      pos: [10, 7, 0], 
      state: 6
    }, 
    {
      pos: [0, 7, 1], 
      state: 6
    }, 
    {
      pos: [1, 7, 1], 
      state: 6
    }, 
    {
      pos: [2, 7, 1], 
      state: 6
    }, 
    {
      pos: [3, 7, 1], 
      state: 6
    }, 
    {
      pos: [4, 7, 1], 
      state: 6
    }, 
    {
      pos: [5, 7, 1], 
      state: 6
    }, 
    {
      pos: [6, 7, 1], 
      state: 6
    }, 
    {
      pos: [7, 7, 1], 
      state: 6
    }, 
    {
      pos: [8, 7, 1], 
      state: 6
    }, 
    {
      pos: [9, 7, 1], 
      state: 6
    }, 
    {
      pos: [10, 7, 1], 
      state: 6
    }, 
    {
      pos: [0, 7, 2], 
      state: 6
    }, 
    {
      pos: [1, 7, 2], 
      state: 6
    }, 
    {
      pos: [2, 7, 2], 
      state: 6
    }, 
    {
      pos: [3, 7, 2], 
      state: 6
    }, 
    {
      pos: [4, 7, 2], 
      state: 6
    }, 
    {
      pos: [5, 7, 2], 
      state: 6
    }, 
    {
      pos: [6, 7, 2], 
      state: 6
    }, 
    {
      pos: [7, 7, 2], 
      state: 6
    }, 
    {
      pos: [8, 7, 2], 
      state: 6
    }, 
    {
      pos: [9, 7, 2], 
      state: 6
    }, 
    {
      pos: [10, 7, 2], 
      state: 6
    }, 
    {
      pos: [0, 7, 3], 
      state: 6
    }, 
    {
      pos: [2, 7, 3], 
      state: 21
    }, 
    {
      pos: [3, 7, 3], 
      state: 21
    }, 
    {
      pos: [4, 7, 3], 
      state: 21
    }, 
    {
      pos: [6, 7, 3], 
      state: 6
    }, 
    {
      pos: [7, 7, 3], 
      state: 6
    }, 
    {
      pos: [8, 7, 3], 
      state: 6
    }, 
    {
      pos: [9, 7, 3], 
      state: 6
    }, 
    {
      pos: [10, 7, 3], 
      state: 6
    }, 
    {
      pos: [0, 7, 4], 
      state: 6
    }, 
    {
      pos: [1, 7, 4], 
      state: 21
    }, 
    {
      pos: [2, 7, 4], 
      state: 21
    }, 
    {
      pos: [3, 7, 4], 
      state: 21
    }, 
    {
      pos: [4, 7, 4], 
      state: 21
    }, 
    {
      pos: [5, 7, 4], 
      state: 21
    }, 
    {
      pos: [6, 7, 4], 
      state: 6
    }, 
    {
      pos: [7, 7, 4], 
      state: 6
    }, 
    {
      pos: [8, 7, 4], 
      state: 6
    }, 
    {
      pos: [9, 7, 4], 
      state: 6
    }, 
    {
      pos: [10, 7, 4], 
      state: 6
    }, 
    {
      pos: [0, 7, 5], 
      state: 6
    }, 
    {
      pos: [2, 7, 5], 
      state: 21
    }, 
    {
      pos: [3, 7, 5], 
      state: 21
    }, 
    {
      pos: [4, 7, 5], 
      state: 21
    }, 
    {
      pos: [6, 7, 5], 
      state: 6
    }, 
    {
      pos: [7, 7, 5], 
      state: 6
    }, 
    {
      pos: [8, 7, 5], 
      state: 6
    }, 
    {
      pos: [9, 7, 5], 
      state: 6
    }, 
    {
      pos: [10, 7, 5], 
      state: 6
    }, 
    {
      pos: [0, 7, 6], 
      state: 6
    }, 
    {
      pos: [1, 7, 6], 
      state: 6
    }, 
    {
      pos: [2, 7, 6], 
      state: 6
    }, 
    {
      pos: [3, 7, 6], 
      state: 6
    }, 
    {
      pos: [4, 7, 6], 
      state: 6
    }, 
    {
      pos: [5, 7, 6], 
      state: 6
    }, 
    {
      pos: [6, 7, 6], 
      state: 6
    }, 
    {
      pos: [7, 7, 6], 
      state: 6
    }, 
    {
      pos: [8, 7, 6], 
      state: 6
    }, 
    {
      pos: [9, 7, 6], 
      state: 6
    }, 
    {
      pos: [10, 7, 6], 
      state: 6
    }, 
    {
      pos: [0, 8, 0], 
      state: 6
    }, 
    {
      pos: [1, 8, 0], 
      state: 6
    }, 
    {
      pos: [2, 8, 0], 
      state: 6
    }, 
    {
      pos: [3, 8, 0], 
      state: 6
    }, 
    {
      pos: [4, 8, 0], 
      state: 6
    }, 
    {
      pos: [5, 8, 0], 
      state: 6
    }, 
    {
      pos: [6, 8, 0], 
      state: 6
    }, 
    {
      pos: [7, 8, 0], 
      state: 6
    }, 
    {
      pos: [8, 8, 0], 
      state: 6
    }, 
    {
      pos: [9, 8, 0], 
      state: 6
    }, 
    {
      pos: [10, 8, 0], 
      state: 6
    }, 
    {
      pos: [0, 8, 1], 
      state: 6
    }, 
    {
      pos: [1, 8, 1], 
      state: 6
    }, 
    {
      pos: [2, 8, 1], 
      state: 6
    }, 
    {
      pos: [3, 8, 1], 
      state: 6
    }, 
    {
      pos: [4, 8, 1], 
      state: 6
    }, 
    {
      pos: [5, 8, 1], 
      state: 6
    }, 
    {
      pos: [6, 8, 1], 
      state: 6
    }, 
    {
      pos: [7, 8, 1], 
      state: 6
    }, 
    {
      pos: [8, 8, 1], 
      state: 6
    }, 
    {
      pos: [9, 8, 1], 
      state: 6
    }, 
    {
      pos: [10, 8, 1], 
      state: 6
    }, 
    {
      pos: [0, 8, 2], 
      state: 6
    }, 
    {
      pos: [1, 8, 2], 
      state: 6
    }, 
    {
      pos: [2, 8, 2], 
      state: 6
    }, 
    {
      pos: [3, 8, 2], 
      state: 6
    }, 
    {
      pos: [4, 8, 2], 
      state: 6
    }, 
    {
      pos: [5, 8, 2], 
      state: 6
    }, 
    {
      pos: [6, 8, 2], 
      state: 6
    }, 
    {
      pos: [7, 8, 2], 
      state: 6
    }, 
    {
      pos: [8, 8, 2], 
      state: 6
    }, 
    {
      pos: [9, 8, 2], 
      state: 6
    }, 
    {
      pos: [10, 8, 2], 
      state: 6
    }, 
    {
      pos: [0, 8, 3], 
      state: 6
    }, 
    {
      pos: [1, 8, 3], 
      state: 6
    }, 
    {
      pos: [2, 8, 3], 
      state: 6
    }, 
    {
      pos: [3, 8, 3], 
      state: 6
    }, 
    {
      pos: [4, 8, 3], 
      state: 6
    }, 
    {
      pos: [5, 8, 3], 
      state: 6
    }, 
    {
      pos: [6, 8, 3], 
      state: 6
    }, 
    {
      pos: [7, 8, 3], 
      state: 6
    }, 
    {
      pos: [8, 8, 3], 
      state: 6
    }, 
    {
      pos: [9, 8, 3], 
      state: 6
    }, 
    {
      pos: [10, 8, 3], 
      state: 6
    }, 
    {
      pos: [0, 8, 4], 
      state: 6
    }, 
    {
      pos: [1, 8, 4], 
      state: 6
    }, 
    {
      pos: [2, 8, 4], 
      state: 6
    }, 
    {
      pos: [3, 8, 4], 
      state: 6
    }, 
    {
      pos: [4, 8, 4], 
      state: 6
    }, 
    {
      pos: [5, 8, 4], 
      state: 6
    }, 
    {
      pos: [6, 8, 4], 
      state: 6
    }, 
    {
      pos: [7, 8, 4], 
      state: 6
    }, 
    {
      pos: [8, 8, 4], 
      state: 6
    }, 
    {
      pos: [9, 8, 4], 
      state: 6
    }, 
    {
      pos: [10, 8, 4], 
      state: 6
    }, 
    {
      pos: [0, 8, 5], 
      state: 6
    }, 
    {
      pos: [1, 8, 5], 
      state: 6
    }, 
    {
      pos: [2, 8, 5], 
      state: 6
    }, 
    {
      pos: [3, 8, 5], 
      state: 6
    }, 
    {
      pos: [4, 8, 5], 
      state: 6
    }, 
    {
      pos: [5, 8, 5], 
      state: 6
    }, 
    {
      pos: [6, 8, 5], 
      state: 6
    }, 
    {
      pos: [7, 8, 5], 
      state: 6
    }, 
    {
      pos: [8, 8, 5], 
      state: 6
    }, 
    {
      pos: [9, 8, 5], 
      state: 6
    }, 
    {
      pos: [10, 8, 5], 
      state: 6
    }, 
    {
      pos: [0, 8, 6], 
      state: 6
    }, 
    {
      pos: [1, 8, 6], 
      state: 6
    }, 
    {
      pos: [2, 8, 6], 
      state: 6
    }, 
    {
      pos: [3, 8, 6], 
      state: 6
    }, 
    {
      pos: [4, 8, 6], 
      state: 6
    }, 
    {
      pos: [5, 8, 6], 
      state: 6
    }, 
    {
      pos: [6, 8, 6], 
      state: 6
    }, 
    {
      pos: [7, 8, 6], 
      state: 6
    }, 
    {
      pos: [8, 8, 6], 
      state: 6
    }, 
    {
      pos: [9, 8, 6], 
      state: 6
    }, 
    {
      pos: [10, 8, 6], 
      state: 6
    }
  ], 
  palette: [
    {
      Name: "minecraft:sand"
    }, 
    {
      Name: "minecraft:smooth_sandstone"
    }, 
    {
      Properties: {
        orientation: "up_north"
      }, 
      Name: "minecraft:jigsaw"
    }, 
    {
      Properties: {
        orientation: "north_up"
      }, 
      Name: "minecraft:jigsaw"
    }, 
    {
      Properties: {
        part: "foot", 
        facing: "south", 
        occupied: "false"
      }, 
      Name: "minecraft:green_bed"
    }, 
    {
      Properties: {
        part: "head", 
        facing: "south", 
        occupied: "false"
      }, 
      Name: "minecraft:green_bed"
    }, 
    {
      Name: "minecraft:air"
    }, 
    {
      Name: "minecraft:potted_cactus"
    }, 
    {
      Properties: {
        half: "bottom", 
        waterlogged: "false", 
        shape: "straight", 
        facing: "east"
      }, 
      Name: "minecraft:smooth_sandstone_stairs"
    }, 
    {
      Properties: {
        half: "bottom", 
        waterlogged: "false", 
        shape: "straight", 
        facing: "west"
      }, 
      Name: "minecraft:smooth_sandstone_stairs"
    }, 
    {
      Properties: {
        hinge: "right", 
        half: "lower", 
        powered: "false", 
        facing: "north", 
        open: "false"
      }, 
      Name: "minecraft:jungle_door"
    }, 
    {
      Properties: {
        hinge: "right", 
        half: "upper", 
        powered: "false", 
        facing: "north", 
        open: "false"
      }, 
      Name: "minecraft:jungle_door"
    }, 
    {
      Properties: {
        facing: "east"
      }, 
      Name: "minecraft:wall_torch"
    }, 
    {
      Properties: {
        waterlogged: "false", 
        facing: "west"
      }, 
      Name: "minecraft:ladder"
    }, 
    {
      Properties: {
        part: "head", 
        facing: "west", 
        occupied: "false"
      }, 
      Name: "minecraft:lime_bed"
    }, 
    {
      Properties: {
        part: "foot", 
        facing: "west", 
        occupied: "false"
      }, 
      Name: "minecraft:lime_bed"
    }, 
    {
      Properties: {
        waterlogged: "false", 
        facing: "north", 
        type: "single"
      }, 
      Name: "minecraft:chest"
    }, 
    {
      Properties: {
        face: "wall", 
        powered: "false", 
        facing: "north"
      }, 
      Name: "minecraft:jungle_button"
    }, 
    {
      Properties: {
        face: "wall", 
        powered: "false", 
        facing: "west"
      }, 
      Name: "minecraft:jungle_button"
    }, 
    {
      Properties: {
        face: "wall", 
        powered: "false", 
        facing: "east"
      }, 
      Name: "minecraft:jungle_button"
    }, 
    {
      Properties: {
        face: "wall", 
        powered: "false", 
        facing: "south"
      }, 
      Name: "minecraft:jungle_button"
    }, 
    {
      Properties: {
        waterlogged: "false", 
        type: "bottom"
      }, 
      Name: "minecraft:smooth_sandstone_slab"
    }, 
    {
      Properties: {
        facing: "south"
      }, 
      Name: "minecraft:wall_torch"
    }, 
    {
      Properties: {
        facing: "north"
      }, 
      Name: "minecraft:wall_torch"
    }, 
    {
      Properties: {
        waterlogged: "false", 
        type: "top"
      }, 
      Name: "minecraft:smooth_sandstone_slab"
    }, 
    {
      Properties: {
        waterlogged: "false", 
        type: "double"
      }, 
      Name: "minecraft:smooth_sandstone_slab"
    }
  ]
}
