{
  size: [10, 10, 10], 
  entities: [
    {
      nbt: {
        Motion: [0.0d, 0.0d, 0.0d], 
        color: "orange", 
        block_pos: [I; -88, -61, 543], 
        Invulnerable: 0b, 
        Air: 300s, 
        OnGround: 0b, 
        fall_distance: 0.0d, 
        PortalCooldown: 0, 
        Rotation: [90.0f, 0.0f], 
        Pos: [-87.5d, -60.0625d, 543.5d], 
        Fire: 0s, 
        id: "minecraft:cushion", 
        UUID: [I; -353834068, -786150777, -1520057711, -2081567563]
      }, 
      blockPos: [6, 0, 6], 
      pos: [6.5d, 0.9375d, 6.5d]
    }, 
    {
      nbt: {
        Motion: [0.0d, 0.0d, 0.0d], 
        color: "orange", 
        block_pos: [I; -87, -61, 541], 
        Invulnerable: 0b, 
        Air: 300s, 
        OnGround: 0b, 
        fall_distance: 0.0d, 
        PortalCooldown: 0, 
        Rotation: [90.0f, 0.0f], 
        Pos: [-86.5d, -60.0625d, 541.5d], 
        Fire: 0s, 
        id: "minecraft:cushion", 
        UUID: [I; 507535882, 442846502, -1870556383, -1527043987]
      }, 
      blockPos: [7, 0, 4], 
      pos: [7.5d, 0.9375d, 4.5d]
    }, 
    {
      nbt: {
        Motion: [0.0d, 0.0d, 0.0d], 
        color: "orange", 
        block_pos: [I; -86, -61, 543], 
        Invulnerable: 0b, 
        Air: 300s, 
        OnGround: 0b, 
        fall_distance: 0.0d, 
        PortalCooldown: 0, 
        Rotation: [90.0f, 0.0f], 
        Pos: [-85.5d, -60.0625d, 543.5d], 
        Fire: 0s, 
        id: "minecraft:cushion", 
        UUID: [I; -1935473125, 907298204, -1557468351, 2118149694]
      }, 
      blockPos: [8, 0, 6], 
      pos: [8.5d, 0.9375d, 6.5d]
    }
  ], 
  blocks: [
    {
      pos: [1, 0, 5], 
      state: 0
    }, 
    {
      pos: [1, 0, 6], 
      state: 0
    }, 
    {
      pos: [2, 0, 2], 
      state: 1
    }, 
    {
      pos: [2, 0, 3], 
      state: 2
    }, 
    {
      pos: [2, 0, 4], 
      state: 0
    }, 
    {
      pos: [2, 0, 5], 
      state: 0
    }, 
    {
      pos: [2, 0, 6], 
      state: 0
    }, 
    {
      pos: [2, 0, 7], 
      state: 0
    }, 
    {
      pos: [3, 0, 1], 
      state: 1
    }, 
    {
      pos: [3, 0, 2], 
      state: 0
    }, 
    {
      pos: [3, 0, 3], 
      state: 0
    }, 
    {
      pos: [3, 0, 4], 
      state: 0
    }, 
    {
      pos: [3, 0, 5], 
      state: 0
    }, 
    {
      pos: [3, 0, 6], 
      state: 0
    }, 
    {
      pos: [3, 0, 7], 
      state: 0
    }, 
    {
      pos: [3, 0, 8], 
      state: 0
    }, 
    {
      pos: [4, 0, 1], 
      state: 1
    }, 
    {
      pos: [4, 0, 2], 
      state: 0
    }, 
    {
      pos: [4, 0, 3], 
      state: 0
    }, 
    {
      pos: [4, 0, 4], 
      state: 0
    }, 
    {
      pos: [4, 0, 5], 
      state: 0
    }, 
    {
      pos: [4, 0, 6], 
      state: 0
    }, 
    {
      pos: [4, 0, 7], 
      state: 0
    }, 
    {
      pos: [4, 0, 8], 
      state: 0
    }, 
    {
      pos: [5, 0, 1], 
      state: 1
    }, 
    {
      pos: [5, 0, 2], 
      state: 1
    }, 
    {
      pos: [5, 0, 3], 
      state: 1
    }, 
    {
      pos: [5, 0, 4], 
      state: 1
    }, 
    {
      pos: [5, 0, 7], 
      state: 1
    }, 
    {
      pos: [7, 0, 2], 
      state: 2
    }, 
    {
      pos: [7, 0, 5], 
      state: 1
    }, 
    {
      pos: [8, 0, 8], 
      state: 2
    }, 
    {
      pos: [1, 1, 5], 
      state: 0
    }, 
    {
      pos: [1, 1, 6], 
      state: 0
    }, 
    {
      pos: [2, 1, 2], 
      state: 2
    }, 
    {
      pos: [2, 1, 3], 
      state: 2
    }, 
    {
      pos: [2, 1, 4], 
      state: 0
    }, 
    {
      pos: [2, 1, 5], 
      state: 0
    }, 
    {
      pos: [2, 1, 6], 
      state: 0
    }, 
    {
      pos: [2, 1, 7], 
      state: 0
    }, 
    {
      pos: [3, 1, 1], 
      state: 2
    }, 
    {
      pos: [3, 1, 2], 
      state: 0
    }, 
    {
      pos: [3, 1, 3], 
      state: 0
    }, 
    {
      pos: [3, 1, 4], 
      state: 0
    }, 
    {
      pos: [3, 1, 5], 
      state: 0
    }, 
    {
      pos: [3, 1, 6], 
      state: 0
    }, 
    {
      pos: [3, 1, 7], 
      state: 0
    }, 
    {
      pos: [3, 1, 8], 
      state: 0
    }, 
    {
      pos: [4, 1, 1], 
      state: 0
    }, 
    {
      pos: [4, 1, 2], 
      state: 0
    }, 
    {
      pos: [4, 1, 3], 
      state: 0
    }, 
    {
      pos: [4, 1, 4], 
      state: 0
    }, 
    {
      pos: [4, 1, 6], 
      state: 0
    }, 
    {
      pos: [4, 1, 7], 
      state: 0
    }, 
    {
      pos: [4, 1, 8], 
      state: 0
    }, 
    {
      pos: [5, 1, 1], 
      state: 0
    }, 
    {
      pos: [5, 1, 2], 
      state: 0
    }, 
    {
      pos: [5, 1, 3], 
      state: 0
    }, 
    {
      pos: [5, 1, 7], 
      state: 0
    }, 
    {
      pos: [1, 2, 5], 
      state: 3
    }, 
    {
      pos: [1, 2, 6], 
      state: 3
    }, 
    {
      pos: [2, 2, 4], 
      state: 4
    }, 
    {
      pos: [2, 2, 5], 
      state: 4
    }, 
    {
      pos: [2, 2, 6], 
      state: 4
    }, 
    {
      pos: [2, 2, 7], 
      state: 3
    }, 
    {
      pos: [3, 2, 1], 
      state: 2
    }, 
    {
      pos: [3, 2, 2], 
      state: 4
    }, 
    {
      pos: [3, 2, 3], 
      state: 4
    }, 
    {
      pos: [3, 2, 4], 
      state: 4
    }, 
    {
      pos: [3, 2, 5], 
      state: 3
    }, 
    {
      pos: [3, 2, 6], 
      state: 3
    }, 
    {
      pos: [3, 2, 7], 
      state: 3
    }, 
    {
      pos: [3, 2, 8], 
      state: 3
    }, 
    {
      pos: [4, 2, 1], 
      state: 4
    }, 
    {
      pos: [4, 2, 2], 
      state: 4
    }, 
    {
      pos: [4, 2, 3], 
      state: 4
    }, 
    {
      pos: [4, 2, 4], 
      state: 3
    }, 
    {
      pos: [4, 2, 6], 
      state: 3
    }, 
    {
      pos: [4, 2, 7], 
      state: 4
    }, 
    {
      pos: [4, 2, 8], 
      state: 3
    }, 
    {
      pos: [5, 2, 2], 
      state: 4
    }, 
    {
      pos: [5, 2, 7], 
      state: 3
    }, 
    {
      pos: [1, 3, 5], 
      state: 4
    }, 
    {
      pos: [1, 3, 6], 
      state: 4
    }, 
    {
      pos: [2, 3, 4], 
      state: 4
    }, 
    {
      pos: [2, 3, 5], 
      state: 4
    }, 
    {
      pos: [2, 3, 6], 
      state: 4
    }, 
    {
      pos: [2, 3, 7], 
      state: 4
    }, 
    {
      pos: [3, 3, 2], 
      state: 2
    }, 
    {
      pos: [3, 3, 3], 
      state: 4
    }, 
    {
      pos: [3, 3, 4], 
      state: 4
    }, 
    {
      pos: [3, 3, 5], 
      state: 4
    }, 
    {
      pos: [3, 3, 6], 
      state: 4
    }, 
    {
      pos: [3, 3, 7], 
      state: 4
    }, 
    {
      pos: [3, 3, 8], 
      state: 2
    }, 
    {
      pos: [4, 3, 3], 
      state: 2
    }, 
    {
      pos: [4, 3, 4], 
      state: 2
    }, 
    {
      pos: [4, 3, 6], 
      state: 4
    }, 
    {
      pos: [4, 3, 7], 
      state: 4
    }, 
    {
      pos: [2, 4, 5], 
      state: 2
    }, 
    {
      pos: [2, 4, 6], 
      state: 2
    }, 
    {
      pos: [3, 4, 3], 
      state: 2
    }, 
    {
      pos: [3, 4, 4], 
      state: 2
    }, 
    {
      pos: [3, 4, 5], 
      state: 2
    }, 
    {
      pos: [3, 4, 6], 
      state: 2
    }, 
    {
      pos: [3, 4, 7], 
      state: 2
    }, 
    {
      pos: [4, 4, 4], 
      state: 2
    }, 
    {
      pos: [4, 4, 6], 
      state: 2
    }, 
    {
      pos: [3, 5, 6], 
      state: 2
    }, 
    {
      pos: [5, 0, 5], 
      state: 5
    }, 
    {
      pos: [5, 0, 6], 
      state: 5
    }, 
    {
      pos: [6, 0, 5], 
      state: 5
    }, 
    {
      pos: [6, 0, 6], 
      state: 5
    }, 
    {
      pos: [6, 0, 7], 
      state: 5
    }, 
    {
      pos: [7, 0, 4], 
      state: 5
    }, 
    {
      pos: [7, 0, 6], 
      state: 5
    }, 
    {
      pos: [8, 0, 4], 
      state: 5
    }, 
    {
      pos: [8, 0, 5], 
      state: 5
    }, 
    {
      pos: [8, 0, 6], 
      state: 5
    }, 
    {
      pos: [9, 0, 2], 
      state: 5
    }, 
    {
      pos: [9, 0, 3], 
      state: 5
    }, 
    {
      pos: [9, 0, 5], 
      state: 5
    }, 
    {
      pos: [9, 0, 6], 
      state: 5
    }, 
    {
      pos: [7, 1, 2], 
      state: 6
    }, 
    {
      pos: [8, 1, 8], 
      state: 6
    }, 
    {
      pos: [2, 2, 2], 
      state: 7
    }, 
    {
      pos: [7, 2, 2], 
      state: 6
    }, 
    {
      pos: [8, 2, 8], 
      state: 6
    }, 
    {
      pos: [3, 3, 1], 
      state: 8
    }, 
    {
      pos: [7, 3, 2], 
      state: 9
    }, 
    {
      pos: [8, 3, 8], 
      state: 6
    }, 
    {
      pos: [8, 4, 8], 
      state: 9
    }, 
    {
      pos: [3, 5, 4], 
      state: 7
    }, 
    {
      nbt: {
        components: {}, 
        joint: "rollable", 
        final_state: "minecraft:dirt_path", 
        name: "minecraft:end_connector", 
        placement_priority: 0, 
        pool: "minecraft:empty", 
        selection_priority: 0, 
        id: "minecraft:jigsaw", 
        target: "minecraft:connector"
      }, 
      pos: [9, 0, 4], 
      state: 10
    }, 
    {
      nbt: {
        LootTable: "minecraft:barrels/abandoned_camp_barrel", 
        components: {}, 
        id: "minecraft:barrel"
      }, 
      pos: [4, 1, 5], 
      state: 11
    }, 
    {
      nbt: {
        LootTable: "minecraft:barrels/abandoned_camp_barrel", 
        components: {}, 
        id: "minecraft:barrel"
      }, 
      pos: [5, 1, 4], 
      state: 12
    }, 
    {
      nbt: {
        components: {}, 
        Items: [], 
        CookingTimes: [I; 0, 0, 0, 0], 
        CookingTotalTimes: [I; 0, 0, 0, 0], 
        id: "minecraft:campfire"
      }, 
      pos: [7, 1, 5], 
      state: 13
    }
  ], 
  palette: [
    {
      id: "minecraft:terracotta"
    }, 
    {
      id: "minecraft:dirt"
    }, 
    {
      id: "minecraft:red_sand"
    }, 
    {
      id: "minecraft:white_terracotta"
    }, 
    {
      id: "minecraft:red_sandstone"
    }, 
    {
      id: "minecraft:dirt_path"
    }, 
    {
      id: "minecraft:cactus", 
      properties: {
        age: "0"
      }
    }, 
    {
      id: "minecraft:short_dry_grass"
    }, 
    {
      id: "minecraft:tall_dry_grass"
    }, 
    {
      id: "minecraft:cactus_flower"
    }, 
    {
      id: "minecraft:jigsaw", 
      properties: {
        orientation: "east_up"
      }
    }, 
    {
      id: "minecraft:barrel", 
      properties: {
        facing: "east", 
        open: "false"
      }
    }, 
    {
      id: "minecraft:barrel", 
      properties: {
        facing: "up", 
        open: "false"
      }
    }, 
    {
      id: "minecraft:campfire", 
      properties: {
        waterlogged: "false", 
        signal_fire: "false", 
        lit: "false", 
        facing: "west"
      }
    }
  ]
}
