{
  size: [12, 11, 7], 
  entities: [], 
  blocks: [
    {
      pos: [0, 0, 0], 
      state: 0
    }, 
    {
      pos: [0, 0, 1], 
      state: 0
    }, 
    {
      pos: [0, 0, 2], 
      state: 0
    }, 
    {
      pos: [0, 0, 3], 
      state: 0
    }, 
    {
      pos: [0, 0, 4], 
      state: 0
    }, 
    {
      pos: [0, 0, 5], 
      state: 0
    }, 
    {
      pos: [0, 0, 6], 
      state: 0
    }, 
    {
      pos: [1, 0, 0], 
      state: 0
    }, 
    {
      pos: [1, 0, 1], 
      state: 1
    }, 
    {
      pos: [1, 0, 2], 
      state: 1
    }, 
    {
      pos: [1, 0, 3], 
      state: 1
    }, 
    {
      pos: [1, 0, 4], 
      state: 1
    }, 
    {
      pos: [1, 0, 5], 
      state: 1
    }, 
    {
      pos: [1, 0, 6], 
      state: 0
    }, 
    {
      pos: [2, 0, 0], 
      state: 0
    }, 
    {
      pos: [2, 0, 1], 
      state: 1
    }, 
    {
      pos: [2, 0, 2], 
      state: 1
    }, 
    {
      pos: [2, 0, 3], 
      state: 1
    }, 
    {
      pos: [2, 0, 4], 
      state: 1
    }, 
    {
      pos: [2, 0, 5], 
      state: 1
    }, 
    {
      pos: [2, 0, 6], 
      state: 0
    }, 
    {
      pos: [3, 0, 0], 
      state: 0
    }, 
    {
      pos: [3, 0, 1], 
      state: 1
    }, 
    {
      pos: [3, 0, 2], 
      state: 1
    }, 
    {
      pos: [3, 0, 4], 
      state: 1
    }, 
    {
      pos: [3, 0, 5], 
      state: 1
    }, 
    {
      pos: [3, 0, 6], 
      state: 0
    }, 
    {
      pos: [4, 0, 0], 
      state: 0
    }, 
    {
      pos: [4, 0, 1], 
      state: 1
    }, 
    {
      pos: [4, 0, 2], 
      state: 1
    }, 
    {
      pos: [4, 0, 3], 
      state: 1
    }, 
    {
      pos: [4, 0, 4], 
      state: 1
    }, 
    {
      pos: [4, 0, 5], 
      state: 1
    }, 
    {
      pos: [4, 0, 6], 
      state: 0
    }, 
    {
      pos: [5, 0, 0], 
      state: 0
    }, 
    {
      pos: [5, 0, 1], 
      state: 1
    }, 
    {
      pos: [5, 0, 2], 
      state: 1
    }, 
    {
      pos: [5, 0, 3], 
      state: 1
    }, 
    {
      pos: [5, 0, 4], 
      state: 1
    }, 
    {
      pos: [5, 0, 5], 
      state: 1
    }, 
    {
      pos: [5, 0, 6], 
      state: 0
    }, 
    {
      pos: [6, 0, 0], 
      state: 0
    }, 
    {
      pos: [6, 0, 1], 
      state: 1
    }, 
    {
      pos: [6, 0, 2], 
      state: 1
    }, 
    {
      pos: [6, 0, 3], 
      state: 1
    }, 
    {
      pos: [6, 0, 4], 
      state: 1
    }, 
    {
      pos: [6, 0, 5], 
      state: 1
    }, 
    {
      pos: [6, 0, 6], 
      state: 0
    }, 
    {
      pos: [7, 0, 0], 
      state: 0
    }, 
    {
      pos: [7, 0, 1], 
      state: 1
    }, 
    {
      pos: [7, 0, 2], 
      state: 1
    }, 
    {
      pos: [7, 0, 3], 
      state: 1
    }, 
    {
      pos: [7, 0, 4], 
      state: 1
    }, 
    {
      pos: [7, 0, 5], 
      state: 1
    }, 
    {
      pos: [7, 0, 6], 
      state: 0
    }, 
    {
      pos: [8, 0, 0], 
      state: 0
    }, 
    {
      pos: [8, 0, 1], 
      state: 1
    }, 
    {
      pos: [8, 0, 2], 
      state: 1
    }, 
    {
      pos: [8, 0, 4], 
      state: 1
    }, 
    {
      pos: [8, 0, 5], 
      state: 1
    }, 
    {
      pos: [8, 0, 6], 
      state: 0
    }, 
    {
      pos: [9, 0, 0], 
      state: 0
    }, 
    {
      pos: [9, 0, 1], 
      state: 1
    }, 
    {
      pos: [9, 0, 2], 
      state: 1
    }, 
    {
      pos: [9, 0, 3], 
      state: 1
    }, 
    {
      pos: [9, 0, 4], 
      state: 1
    }, 
    {
      pos: [9, 0, 5], 
      state: 1
    }, 
    {
      pos: [9, 0, 6], 
      state: 0
    }, 
    {
      pos: [10, 0, 0], 
      state: 0
    }, 
    {
      pos: [10, 0, 1], 
      state: 1
    }, 
    {
      pos: [10, 0, 2], 
      state: 1
    }, 
    {
      pos: [10, 0, 3], 
      state: 1
    }, 
    {
      pos: [10, 0, 4], 
      state: 1
    }, 
    {
      pos: [10, 0, 5], 
      state: 1
    }, 
    {
      pos: [10, 0, 6], 
      state: 0
    }, 
    {
      pos: [11, 0, 0], 
      state: 0
    }, 
    {
      pos: [11, 0, 1], 
      state: 0
    }, 
    {
      pos: [11, 0, 2], 
      state: 0
    }, 
    {
      pos: [11, 0, 3], 
      state: 0
    }, 
    {
      pos: [11, 0, 4], 
      state: 0
    }, 
    {
      pos: [11, 0, 5], 
      state: 0
    }, 
    {
      pos: [11, 0, 6], 
      state: 0
    }, 
    {
      pos: [1, 1, 1], 
      state: 2
    }, 
    {
      pos: [1, 1, 2], 
      state: 2
    }, 
    {
      pos: [1, 1, 3], 
      state: 2
    }, 
    {
      pos: [1, 1, 4], 
      state: 2
    }, 
    {
      pos: [1, 1, 5], 
      state: 2
    }, 
    {
      pos: [2, 1, 1], 
      state: 2
    }, 
    {
      pos: [2, 1, 2], 
      state: 1
    }, 
    {
      pos: [2, 1, 3], 
      state: 1
    }, 
    {
      pos: [2, 1, 4], 
      state: 1
    }, 
    {
      pos: [2, 1, 5], 
      state: 2
    }, 
    {
      pos: [3, 1, 1], 
      state: 2
    }, 
    {
      pos: [3, 1, 2], 
      state: 1
    }, 
    {
      pos: [3, 1, 3], 
      state: 1
    }, 
    {
      pos: [3, 1, 4], 
      state: 1
    }, 
    {
      pos: [3, 1, 5], 
      state: 2
    }, 
    {
      pos: [4, 1, 1], 
      state: 2
    }, 
    {
      pos: [4, 1, 2], 
      state: 1
    }, 
    {
      pos: [4, 1, 3], 
      state: 1
    }, 
    {
      pos: [4, 1, 4], 
      state: 1
    }, 
    {
      pos: [4, 1, 5], 
      state: 2
    }, 
    {
      pos: [5, 1, 1], 
      state: 2
    }, 
    {
      pos: [5, 1, 2], 
      state: 1
    }, 
    {
      pos: [5, 1, 3], 
      state: 1
    }, 
    {
      pos: [5, 1, 4], 
      state: 1
    }, 
    {
      pos: [5, 1, 5], 
      state: 2
    }, 
    {
      pos: [6, 1, 1], 
      state: 2
    }, 
    {
      pos: [6, 1, 2], 
      state: 1
    }, 
    {
      pos: [6, 1, 3], 
      state: 1
    }, 
    {
      pos: [6, 1, 4], 
      state: 1
    }, 
    {
      pos: [6, 1, 5], 
      state: 2
    }, 
    {
      pos: [7, 1, 1], 
      state: 2
    }, 
    {
      pos: [7, 1, 2], 
      state: 1
    }, 
    {
      pos: [7, 1, 3], 
      state: 1
    }, 
    {
      pos: [7, 1, 4], 
      state: 1
    }, 
    {
      pos: [7, 1, 5], 
      state: 2
    }, 
    {
      pos: [8, 1, 1], 
      state: 2
    }, 
    {
      pos: [8, 1, 2], 
      state: 1
    }, 
    {
      pos: [8, 1, 3], 
      state: 1
    }, 
    {
      pos: [8, 1, 4], 
      state: 1
    }, 
    {
      pos: [8, 1, 5], 
      state: 2
    }, 
    {
      pos: [9, 1, 1], 
      state: 2
    }, 
    {
      pos: [9, 1, 2], 
      state: 1
    }, 
    {
      pos: [9, 1, 3], 
      state: 1
    }, 
    {
      pos: [9, 1, 4], 
      state: 1
    }, 
    {
      pos: [9, 1, 5], 
      state: 2
    }, 
    {
      pos: [10, 1, 1], 
      state: 2
    }, 
    {
      pos: [10, 1, 2], 
      state: 2
    }, 
    {
      pos: [10, 1, 3], 
      state: 2
    }, 
    {
      pos: [10, 1, 4], 
      state: 2
    }, 
    {
      pos: [10, 1, 5], 
      state: 2
    }, 
    {
      pos: [1, 2, 1], 
      state: 1
    }, 
    {
      pos: [1, 2, 2], 
      state: 1
    }, 
    {
      pos: [1, 2, 3], 
      state: 3
    }, 
    {
      pos: [1, 2, 4], 
      state: 1
    }, 
    {
      pos: [1, 2, 5], 
      state: 1
    }, 
    {
      pos: [2, 2, 1], 
      state: 1
    }, 
    {
      pos: [2, 2, 2], 
      state: 1
    }, 
    {
      pos: [2, 2, 3], 
      state: 1
    }, 
    {
      pos: [2, 2, 4], 
      state: 1
    }, 
    {
      pos: [2, 2, 5], 
      state: 1
    }, 
    {
      pos: [3, 2, 1], 
      state: 3
    }, 
    {
      pos: [3, 2, 2], 
      state: 1
    }, 
    {
      pos: [3, 2, 3], 
      state: 1
    }, 
    {
      pos: [3, 2, 4], 
      state: 1
    }, 
    {
      pos: [3, 2, 5], 
      state: 3
    }, 
    {
      pos: [4, 2, 1], 
      state: 1
    }, 
    {
      pos: [4, 2, 2], 
      state: 1
    }, 
    {
      pos: [4, 2, 3], 
      state: 1
    }, 
    {
      pos: [4, 2, 4], 
      state: 1
    }, 
    {
      pos: [4, 2, 5], 
      state: 1
    }, 
    {
      pos: [5, 2, 1], 
      state: 1
    }, 
    {
      pos: [5, 2, 2], 
      state: 1
    }, 
    {
      pos: [5, 2, 3], 
      state: 1
    }, 
    {
      pos: [5, 2, 4], 
      state: 1
    }, 
    {
      pos: [5, 2, 5], 
      state: 1
    }, 
    {
      pos: [6, 2, 1], 
      state: 1
    }, 
    {
      pos: [6, 2, 2], 
      state: 1
    }, 
    {
      pos: [6, 2, 3], 
      state: 1
    }, 
    {
      pos: [6, 2, 4], 
      state: 1
    }, 
    {
      pos: [6, 2, 5], 
      state: 1
    }, 
    {
      pos: [7, 2, 1], 
      state: 1
    }, 
    {
      pos: [7, 2, 2], 
      state: 1
    }, 
    {
      pos: [7, 2, 3], 
      state: 1
    }, 
    {
      pos: [7, 2, 4], 
      state: 1
    }, 
    {
      pos: [7, 2, 5], 
      state: 1
    }, 
    {
      pos: [8, 2, 1], 
      state: 3
    }, 
    {
      pos: [8, 2, 2], 
      state: 1
    }, 
    {
      pos: [8, 2, 3], 
      state: 1
    }, 
    {
      pos: [8, 2, 4], 
      state: 1
    }, 
    {
      pos: [8, 2, 5], 
      state: 3
    }, 
    {
      pos: [9, 2, 1], 
      state: 1
    }, 
    {
      pos: [9, 2, 2], 
      state: 1
    }, 
    {
      pos: [9, 2, 3], 
      state: 1
    }, 
    {
      pos: [9, 2, 4], 
      state: 1
    }, 
    {
      pos: [9, 2, 5], 
      state: 1
    }, 
    {
      pos: [10, 2, 1], 
      state: 1
    }, 
    {
      pos: [10, 2, 2], 
      state: 1
    }, 
    {
      pos: [10, 2, 3], 
      state: 3
    }, 
    {
      pos: [10, 2, 4], 
      state: 1
    }, 
    {
      pos: [10, 2, 5], 
      state: 1
    }, 
    {
      pos: [1, 3, 1], 
      state: 4
    }, 
    {
      pos: [1, 3, 2], 
      state: 4
    }, 
    {
      pos: [1, 3, 3], 
      state: 4
    }, 
    {
      pos: [1, 3, 4], 
      state: 4
    }, 
    {
      pos: [1, 3, 5], 
      state: 4
    }, 
    {
      pos: [2, 3, 1], 
      state: 4
    }, 
    {
      pos: [2, 3, 2], 
      state: 1
    }, 
    {
      pos: [2, 3, 3], 
      state: 1
    }, 
    {
      pos: [2, 3, 4], 
      state: 1
    }, 
    {
      pos: [2, 3, 5], 
      state: 4
    }, 
    {
      pos: [3, 3, 1], 
      state: 4
    }, 
    {
      pos: [3, 3, 2], 
      state: 1
    }, 
    {
      pos: [3, 3, 3], 
      state: 1
    }, 
    {
      pos: [3, 3, 4], 
      state: 1
    }, 
    {
      pos: [3, 3, 5], 
      state: 4
    }, 
    {
      pos: [4, 3, 1], 
      state: 4
    }, 
    {
      pos: [4, 3, 2], 
      state: 1
    }, 
    {
      pos: [4, 3, 3], 
      state: 1
    }, 
    {
      pos: [4, 3, 4], 
      state: 1
    }, 
    {
      pos: [4, 3, 5], 
      state: 4
    }, 
    {
      pos: [5, 3, 1], 
      state: 4
    }, 
    {
      pos: [5, 3, 2], 
      state: 1
    }, 
    {
      pos: [5, 3, 3], 
      state: 1
    }, 
    {
      pos: [5, 3, 4], 
      state: 1
    }, 
    {
      pos: [5, 3, 5], 
      state: 4
    }, 
    {
      pos: [6, 3, 1], 
      state: 4
    }, 
    {
      pos: [6, 3, 2], 
      state: 1
    }, 
    {
      pos: [6, 3, 3], 
      state: 1
    }, 
    {
      pos: [6, 3, 4], 
      state: 1
    }, 
    {
      pos: [6, 3, 5], 
      state: 4
    }, 
    {
      pos: [7, 3, 1], 
      state: 4
    }, 
    {
      pos: [7, 3, 2], 
      state: 1
    }, 
    {
      pos: [7, 3, 3], 
      state: 1
    }, 
    {
      pos: [7, 3, 4], 
      state: 1
    }, 
    {
      pos: [7, 3, 5], 
      state: 4
    }, 
    {
      pos: [8, 3, 1], 
      state: 4
    }, 
    {
      pos: [8, 3, 2], 
      state: 1
    }, 
    {
      pos: [8, 3, 3], 
      state: 1
    }, 
    {
      pos: [8, 3, 4], 
      state: 1
    }, 
    {
      pos: [8, 3, 5], 
      state: 4
    }, 
    {
      pos: [9, 3, 1], 
      state: 4
    }, 
    {
      pos: [9, 3, 2], 
      state: 1
    }, 
    {
      pos: [9, 3, 3], 
      state: 1
    }, 
    {
      pos: [9, 3, 4], 
      state: 1
    }, 
    {
      pos: [9, 3, 5], 
      state: 4
    }, 
    {
      pos: [10, 3, 1], 
      state: 4
    }, 
    {
      pos: [10, 3, 2], 
      state: 4
    }, 
    {
      pos: [10, 3, 3], 
      state: 4
    }, 
    {
      pos: [10, 3, 4], 
      state: 4
    }, 
    {
      pos: [10, 3, 5], 
      state: 4
    }, 
    {
      pos: [1, 4, 1], 
      state: 1
    }, 
    {
      pos: [1, 4, 3], 
      state: 1
    }, 
    {
      pos: [1, 4, 4], 
      state: 1
    }, 
    {
      pos: [1, 4, 5], 
      state: 1
    }, 
    {
      pos: [2, 4, 1], 
      state: 1
    }, 
    {
      pos: [2, 4, 2], 
      state: 1
    }, 
    {
      pos: [2, 4, 3], 
      state: 1
    }, 
    {
      pos: [2, 4, 4], 
      state: 1
    }, 
    {
      pos: [3, 4, 1], 
      state: 1
    }, 
    {
      pos: [3, 4, 2], 
      state: 1
    }, 
    {
      pos: [3, 4, 3], 
      state: 1
    }, 
    {
      pos: [3, 4, 4], 
      state: 1
    }, 
    {
      pos: [3, 4, 5], 
      state: 1
    }, 
    {
      pos: [4, 4, 2], 
      state: 1
    }, 
    {
      pos: [4, 4, 3], 
      state: 1
    }, 
    {
      pos: [4, 4, 4], 
      state: 1
    }, 
    {
      pos: [4, 4, 5], 
      state: 1
    }, 
    {
      pos: [5, 4, 1], 
      state: 1
    }, 
    {
      pos: [5, 4, 2], 
      state: 1
    }, 
    {
      pos: [5, 4, 3], 
      state: 1
    }, 
    {
      pos: [5, 4, 4], 
      state: 1
    }, 
    {
      pos: [5, 4, 5], 
      state: 1
    }, 
    {
      pos: [6, 4, 1], 
      state: 1
    }, 
    {
      pos: [6, 4, 2], 
      state: 1
    }, 
    {
      pos: [6, 4, 3], 
      state: 1
    }, 
    {
      pos: [6, 4, 4], 
      state: 1
    }, 
    {
      pos: [6, 4, 5], 
      state: 1
    }, 
    {
      pos: [7, 4, 1], 
      state: 1
    }, 
    {
      pos: [7, 4, 2], 
      state: 1
    }, 
    {
      pos: [7, 4, 3], 
      state: 1
    }, 
    {
      pos: [7, 4, 4], 
      state: 1
    }, 
    {
      pos: [8, 4, 1], 
      state: 1
    }, 
    {
      pos: [8, 4, 2], 
      state: 1
    }, 
    {
      pos: [8, 4, 3], 
      state: 1
    }, 
    {
      pos: [8, 4, 4], 
      state: 1
    }, 
    {
      pos: [8, 4, 5], 
      state: 1
    }, 
    {
      pos: [9, 4, 2], 
      state: 1
    }, 
    {
      pos: [9, 4, 3], 
      state: 1
    }, 
    {
      pos: [9, 4, 4], 
      state: 1
    }, 
    {
      pos: [9, 4, 5], 
      state: 1
    }, 
    {
      pos: [10, 4, 1], 
      state: 1
    }, 
    {
      pos: [10, 4, 2], 
      state: 1
    }, 
    {
      pos: [10, 4, 3], 
      state: 1
    }, 
    {
      pos: [10, 4, 5], 
      state: 1
    }, 
    {
      pos: [1, 5, 1], 
      state: 1
    }, 
    {
      pos: [1, 5, 2], 
      state: 1
    }, 
    {
      pos: [1, 5, 3], 
      state: 1
    }, 
    {
      pos: [1, 5, 4], 
      state: 1
    }, 
    {
      pos: [1, 5, 5], 
      state: 1
    }, 
    {
      pos: [2, 5, 1], 
      state: 1
    }, 
    {
      pos: [2, 5, 2], 
      state: 1
    }, 
    {
      pos: [2, 5, 3], 
      state: 1
    }, 
    {
      pos: [2, 5, 4], 
      state: 1
    }, 
    {
      pos: [2, 5, 5], 
      state: 1
    }, 
    {
      pos: [3, 5, 1], 
      state: 1
    }, 
    {
      pos: [3, 5, 2], 
      state: 1
    }, 
    {
      pos: [3, 5, 3], 
      state: 1
    }, 
    {
      pos: [3, 5, 4], 
      state: 1
    }, 
    {
      pos: [3, 5, 5], 
      state: 1
    }, 
    {
      pos: [4, 5, 1], 
      state: 1
    }, 
    {
      pos: [4, 5, 2], 
      state: 1
    }, 
    {
      pos: [4, 5, 3], 
      state: 1
    }, 
    {
      pos: [4, 5, 4], 
      state: 1
    }, 
    {
      pos: [4, 5, 5], 
      state: 1
    }, 
    {
      pos: [5, 5, 1], 
      state: 1
    }, 
    {
      pos: [5, 5, 2], 
      state: 1
    }, 
    {
      pos: [5, 5, 3], 
      state: 1
    }, 
    {
      pos: [5, 5, 4], 
      state: 1
    }, 
    {
      pos: [5, 5, 5], 
      state: 1
    }, 
    {
      pos: [6, 5, 1], 
      state: 1
    }, 
    {
      pos: [6, 5, 2], 
      state: 1
    }, 
    {
      pos: [6, 5, 3], 
      state: 1
    }, 
    {
      pos: [6, 5, 4], 
      state: 1
    }, 
    {
      pos: [6, 5, 5], 
      state: 1
    }, 
    {
      pos: [7, 5, 1], 
      state: 1
    }, 
    {
      pos: [7, 5, 2], 
      state: 1
    }, 
    {
      pos: [7, 5, 3], 
      state: 1
    }, 
    {
      pos: [7, 5, 4], 
      state: 1
    }, 
    {
      pos: [7, 5, 5], 
      state: 1
    }, 
    {
      pos: [8, 5, 1], 
      state: 1
    }, 
    {
      pos: [8, 5, 2], 
      state: 1
    }, 
    {
      pos: [8, 5, 3], 
      state: 1
    }, 
    {
      pos: [8, 5, 4], 
      state: 1
    }, 
    {
      pos: [8, 5, 5], 
      state: 1
    }, 
    {
      pos: [9, 5, 1], 
      state: 1
    }, 
    {
      pos: [9, 5, 2], 
      state: 1
    }, 
    {
      pos: [9, 5, 3], 
      state: 1
    }, 
    {
      pos: [9, 5, 4], 
      state: 1
    }, 
    {
      pos: [9, 5, 5], 
      state: 1
    }, 
    {
      pos: [10, 5, 1], 
      state: 1
    }, 
    {
      pos: [10, 5, 2], 
      state: 1
    }, 
    {
      pos: [10, 5, 3], 
      state: 1
    }, 
    {
      pos: [10, 5, 4], 
      state: 1
    }, 
    {
      pos: [10, 5, 5], 
      state: 1
    }, 
    {
      pos: [1, 6, 1], 
      state: 2
    }, 
    {
      pos: [1, 6, 2], 
      state: 2
    }, 
    {
      pos: [1, 6, 3], 
      state: 2
    }, 
    {
      pos: [1, 6, 4], 
      state: 2
    }, 
    {
      pos: [1, 6, 5], 
      state: 2
    }, 
    {
      pos: [2, 6, 1], 
      state: 2
    }, 
    {
      pos: [2, 6, 2], 
      state: 5
    }, 
    {
      pos: [2, 6, 3], 
      state: 5
    }, 
    {
      pos: [2, 6, 4], 
      state: 5
    }, 
    {
      pos: [2, 6, 5], 
      state: 2
    }, 
    {
      pos: [3, 6, 1], 
      state: 2
    }, 
    {
      pos: [3, 6, 2], 
      state: 5
    }, 
    {
      pos: [3, 6, 3], 
      state: 5
    }, 
    {
      pos: [3, 6, 4], 
      state: 5
    }, 
    {
      pos: [3, 6, 5], 
      state: 2
    }, 
    {
      pos: [4, 6, 1], 
      state: 2
    }, 
    {
      pos: [4, 6, 2], 
      state: 5
    }, 
    {
      pos: [4, 6, 3], 
      state: 5
    }, 
    {
      pos: [4, 6, 4], 
      state: 5
    }, 
    {
      pos: [4, 6, 5], 
      state: 2
    }, 
    {
      pos: [5, 6, 1], 
      state: 2
    }, 
    {
      pos: [5, 6, 2], 
      state: 5
    }, 
    {
      pos: [5, 6, 3], 
      state: 5
    }, 
    {
      pos: [5, 6, 4], 
      state: 5
    }, 
    {
      pos: [5, 6, 5], 
      state: 2
    }, 
    {
      pos: [6, 6, 1], 
      state: 2
    }, 
    {
      pos: [6, 6, 2], 
      state: 5
    }, 
    {
      pos: [6, 6, 3], 
      state: 5
    }, 
    {
      pos: [6, 6, 5], 
      state: 2
    }, 
    {
      pos: [7, 6, 1], 
      state: 2
    }, 
    {
      pos: [7, 6, 2], 
      state: 5
    }, 
    {
      pos: [7, 6, 3], 
      state: 5
    }, 
    {
      pos: [7, 6, 4], 
      state: 5
    }, 
    {
      pos: [7, 6, 5], 
      state: 2
    }, 
    {
      pos: [8, 6, 1], 
      state: 2
    }, 
    {
      pos: [8, 6, 2], 
      state: 5
    }, 
    {
      pos: [8, 6, 3], 
      state: 5
    }, 
    {
      pos: [8, 6, 5], 
      state: 2
    }, 
    {
      pos: [9, 6, 1], 
      state: 2
    }, 
    {
      pos: [9, 6, 2], 
      state: 5
    }, 
    {
      pos: [9, 6, 3], 
      state: 5
    }, 
    {
      pos: [9, 6, 4], 
      state: 5
    }, 
    {
      pos: [9, 6, 5], 
      state: 2
    }, 
    {
      pos: [10, 6, 1], 
      state: 2
    }, 
    {
      pos: [10, 6, 2], 
      state: 2
    }, 
    {
      pos: [10, 6, 3], 
      state: 2
    }, 
    {
      pos: [10, 6, 4], 
      state: 2
    }, 
    {
      pos: [10, 6, 5], 
      state: 2
    }, 
    {
      nbt: {
        joint: "rollable", 
        final_state: "minecraft:tuff_bricks", 
        name: "minecraft:c6_addon", 
        placement_priority: 0, 
        pool: "minecraft:empty", 
        selection_priority: 0, 
        id: "minecraft:jigsaw", 
        target: "minecraft:empty"
      }, 
      pos: [3, 0, 3], 
      state: 6
    }, 
    {
      nbt: {
        joint: "rollable", 
        final_state: "minecraft:tuff_bricks", 
        name: "minecraft:c6_addon", 
        placement_priority: 0, 
        pool: "minecraft:empty", 
        selection_priority: 0, 
        id: "minecraft:jigsaw", 
        target: "minecraft:empty"
      }, 
      pos: [8, 0, 3], 
      state: 7
    }, 
    {
      nbt: {
        joint: "aligned", 
        final_state: "minecraft:tuff_bricks", 
        name: "minecraft:empty", 
        placement_priority: 0, 
        pool: "minecraft:trial_chambers/dispensers/chamber", 
        selection_priority: 0, 
        id: "minecraft:jigsaw", 
        target: "minecraft:dispenser"
      }, 
      pos: [1, 4, 2], 
      state: 6
    }, 
    {
      nbt: {
        joint: "aligned", 
        final_state: "minecraft:tuff_bricks", 
        name: "minecraft:empty", 
        placement_priority: 0, 
        pool: "minecraft:trial_chambers/dispensers/chamber", 
        selection_priority: 0, 
        id: "minecraft:jigsaw", 
        target: "minecraft:dispenser"
      }, 
      pos: [2, 4, 5], 
      state: 8
    }, 
    {
      nbt: {
        joint: "aligned", 
        final_state: "minecraft:tuff_bricks", 
        name: "minecraft:empty", 
        placement_priority: 0, 
        pool: "minecraft:trial_chambers/dispensers/chamber", 
        selection_priority: 0, 
        id: "minecraft:jigsaw", 
        target: "minecraft:dispenser"
      }, 
      pos: [4, 4, 1], 
      state: 7
    }, 
    {
      nbt: {
        joint: "aligned", 
        final_state: "minecraft:tuff_bricks", 
        name: "minecraft:empty", 
        placement_priority: 0, 
        pool: "minecraft:trial_chambers/dispensers/chamber", 
        selection_priority: 0, 
        id: "minecraft:jigsaw", 
        target: "minecraft:dispenser"
      }, 
      pos: [7, 4, 5], 
      state: 8
    }, 
    {
      nbt: {
        joint: "aligned", 
        final_state: "minecraft:tuff_bricks", 
        name: "minecraft:empty", 
        placement_priority: 0, 
        pool: "minecraft:trial_chambers/dispensers/chamber", 
        selection_priority: 0, 
        id: "minecraft:jigsaw", 
        target: "minecraft:dispenser"
      }, 
      pos: [9, 4, 1], 
      state: 7
    }, 
    {
      nbt: {
        joint: "aligned", 
        final_state: "minecraft:tuff_bricks", 
        name: "minecraft:empty", 
        placement_priority: 0, 
        pool: "minecraft:trial_chambers/dispensers/chamber", 
        selection_priority: 0, 
        id: "minecraft:jigsaw", 
        target: "minecraft:dispenser"
      }, 
      pos: [10, 4, 4], 
      state: 9
    }, 
    {
      nbt: {
        joint: "aligned", 
        final_state: "minecraft:waxed_oxidized_copper", 
        name: "minecraft:decor_connector", 
        placement_priority: 0, 
        pool: "minecraft:trial_chambers/decor_chamber", 
        selection_priority: 0, 
        id: "minecraft:jigsaw", 
        target: "minecraft:decor"
      }, 
      pos: [6, 6, 4], 
      state: 10
    }, 
    {
      nbt: {
        joint: "aligned", 
        final_state: "minecraft:waxed_oxidized_copper", 
        name: "minecraft:decor_connector", 
        placement_priority: 0, 
        pool: "minecraft:trial_chambers/decor_chamber", 
        selection_priority: 0, 
        id: "minecraft:jigsaw", 
        target: "minecraft:decor"
      }, 
      pos: [8, 6, 4], 
      state: 10
    }, 
    {
      nbt: {
        joint: "aligned", 
        final_state: "minecraft:air", 
        name: "minecraft:empty", 
        placement_priority: 1, 
        pool: "minecraft:trial_chambers/spawner/ranged", 
        selection_priority: 1, 
        id: "minecraft:jigsaw", 
        target: "minecraft:spawner_connector"
      }, 
      pos: [3, 8, 3], 
      state: 11
    }
  ], 
  palette: [
    {
      Name: "minecraft:waxed_oxidized_cut_copper"
    }, 
    {
      Name: "minecraft:tuff_bricks"
    }, 
    {
      Name: "minecraft:waxed_copper_block"
    }, 
    {
      Properties: {
        powered: "false", 
        lit: "true"
      }, 
      Name: "minecraft:waxed_copper_bulb"
    }, 
    {
      Name: "minecraft:chiseled_tuff_bricks"
    }, 
    {
      Name: "minecraft:waxed_oxidized_copper"
    }, 
    {
      Properties: {
        orientation: "down_west"
      }, 
      Name: "minecraft:jigsaw"
    }, 
    {
      Properties: {
        orientation: "down_north"
      }, 
      Name: "minecraft:jigsaw"
    }, 
    {
      Properties: {
        orientation: "down_south"
      }, 
      Name: "minecraft:jigsaw"
    }, 
    {
      Properties: {
        orientation: "down_east"
      }, 
      Name: "minecraft:jigsaw"
    }, 
    {
      Properties: {
        orientation: "north_up"
      }, 
      Name: "minecraft:jigsaw"
    }, 
    {
      Properties: {
        orientation: "east_up"
      }, 
      Name: "minecraft:jigsaw"
    }
  ]
}
