{
  size: [6, 6, 26], 
  entities: [], 
  blocks: [
    {
      pos: [0, 0, 1], 
      state: 0
    }, 
    {
      pos: [0, 0, 2], 
      state: 0
    }, 
    {
      pos: [0, 0, 3], 
      state: 0
    }, 
    {
      pos: [0, 0, 6], 
      state: 0
    }, 
    {
      pos: [0, 0, 7], 
      state: 0
    }, 
    {
      pos: [0, 0, 8], 
      state: 0
    }, 
    {
      pos: [0, 0, 11], 
      state: 0
    }, 
    {
      pos: [0, 0, 12], 
      state: 0
    }, 
    {
      pos: [0, 0, 13], 
      state: 0
    }, 
    {
      pos: [0, 0, 16], 
      state: 0
    }, 
    {
      pos: [0, 0, 17], 
      state: 0
    }, 
    {
      pos: [0, 0, 18], 
      state: 0
    }, 
    {
      pos: [0, 0, 21], 
      state: 0
    }, 
    {
      pos: [0, 0, 22], 
      state: 0
    }, 
    {
      pos: [0, 0, 23], 
      state: 0
    }, 
    {
      pos: [0, 0, 25], 
      state: 1
    }, 
    {
      pos: [1, 0, 0], 
      state: 0
    }, 
    {
      pos: [1, 0, 1], 
      state: 0
    }, 
    {
      pos: [1, 0, 2], 
      state: 0
    }, 
    {
      pos: [1, 0, 3], 
      state: 0
    }, 
    {
      pos: [1, 0, 4], 
      state: 0
    }, 
    {
      pos: [1, 0, 5], 
      state: 0
    }, 
    {
      pos: [1, 0, 6], 
      state: 0
    }, 
    {
      pos: [1, 0, 7], 
      state: 0
    }, 
    {
      pos: [1, 0, 8], 
      state: 0
    }, 
    {
      pos: [1, 0, 9], 
      state: 0
    }, 
    {
      pos: [1, 0, 10], 
      state: 0
    }, 
    {
      pos: [1, 0, 11], 
      state: 0
    }, 
    {
      pos: [1, 0, 12], 
      state: 0
    }, 
    {
      pos: [1, 0, 13], 
      state: 0
    }, 
    {
      pos: [1, 0, 14], 
      state: 0
    }, 
    {
      pos: [1, 0, 15], 
      state: 0
    }, 
    {
      pos: [1, 0, 16], 
      state: 0
    }, 
    {
      pos: [1, 0, 17], 
      state: 0
    }, 
    {
      pos: [1, 0, 18], 
      state: 0
    }, 
    {
      pos: [1, 0, 19], 
      state: 0
    }, 
    {
      pos: [1, 0, 20], 
      state: 0
    }, 
    {
      pos: [1, 0, 21], 
      state: 0
    }, 
    {
      pos: [1, 0, 22], 
      state: 0
    }, 
    {
      pos: [1, 0, 23], 
      state: 0
    }, 
    {
      pos: [1, 0, 24], 
      state: 0
    }, 
    {
      pos: [1, 0, 25], 
      state: 1
    }, 
    {
      pos: [2, 0, 0], 
      state: 0
    }, 
    {
      pos: [2, 0, 1], 
      state: 0
    }, 
    {
      pos: [2, 0, 2], 
      state: 0
    }, 
    {
      pos: [2, 0, 3], 
      state: 0
    }, 
    {
      pos: [2, 0, 4], 
      state: 0
    }, 
    {
      pos: [2, 0, 5], 
      state: 0
    }, 
    {
      pos: [2, 0, 6], 
      state: 0
    }, 
    {
      pos: [2, 0, 7], 
      state: 0
    }, 
    {
      pos: [2, 0, 8], 
      state: 0
    }, 
    {
      pos: [2, 0, 9], 
      state: 0
    }, 
    {
      pos: [2, 0, 10], 
      state: 0
    }, 
    {
      pos: [2, 0, 11], 
      state: 0
    }, 
    {
      pos: [2, 0, 12], 
      state: 0
    }, 
    {
      pos: [2, 0, 13], 
      state: 0
    }, 
    {
      pos: [2, 0, 14], 
      state: 0
    }, 
    {
      pos: [2, 0, 15], 
      state: 0
    }, 
    {
      pos: [2, 0, 16], 
      state: 0
    }, 
    {
      pos: [2, 0, 17], 
      state: 0
    }, 
    {
      pos: [2, 0, 18], 
      state: 0
    }, 
    {
      pos: [2, 0, 19], 
      state: 0
    }, 
    {
      pos: [2, 0, 20], 
      state: 0
    }, 
    {
      pos: [2, 0, 21], 
      state: 0
    }, 
    {
      pos: [2, 0, 23], 
      state: 0
    }, 
    {
      pos: [2, 0, 24], 
      state: 0
    }, 
    {
      pos: [2, 0, 25], 
      state: 1
    }, 
    {
      pos: [3, 0, 0], 
      state: 0
    }, 
    {
      pos: [3, 0, 1], 
      state: 0
    }, 
    {
      pos: [3, 0, 2], 
      state: 0
    }, 
    {
      pos: [3, 0, 3], 
      state: 0
    }, 
    {
      pos: [3, 0, 4], 
      state: 0
    }, 
    {
      pos: [3, 0, 5], 
      state: 0
    }, 
    {
      pos: [3, 0, 6], 
      state: 0
    }, 
    {
      pos: [3, 0, 7], 
      state: 0
    }, 
    {
      pos: [3, 0, 8], 
      state: 0
    }, 
    {
      pos: [3, 0, 9], 
      state: 0
    }, 
    {
      pos: [3, 0, 10], 
      state: 0
    }, 
    {
      pos: [3, 0, 11], 
      state: 0
    }, 
    {
      pos: [3, 0, 12], 
      state: 0
    }, 
    {
      pos: [3, 0, 13], 
      state: 0
    }, 
    {
      pos: [3, 0, 14], 
      state: 0
    }, 
    {
      pos: [3, 0, 15], 
      state: 0
    }, 
    {
      pos: [3, 0, 16], 
      state: 0
    }, 
    {
      pos: [3, 0, 17], 
      state: 0
    }, 
    {
      pos: [3, 0, 18], 
      state: 0
    }, 
    {
      pos: [3, 0, 19], 
      state: 0
    }, 
    {
      pos: [3, 0, 20], 
      state: 0
    }, 
    {
      pos: [3, 0, 21], 
      state: 0
    }, 
    {
      pos: [3, 0, 22], 
      state: 0
    }, 
    {
      pos: [3, 0, 23], 
      state: 0
    }, 
    {
      pos: [3, 0, 24], 
      state: 0
    }, 
    {
      pos: [3, 0, 25], 
      state: 1
    }, 
    {
      pos: [4, 0, 1], 
      state: 0
    }, 
    {
      pos: [4, 0, 2], 
      state: 0
    }, 
    {
      pos: [4, 0, 3], 
      state: 0
    }, 
    {
      pos: [4, 0, 4], 
      state: 0
    }, 
    {
      pos: [4, 0, 5], 
      state: 0
    }, 
    {
      pos: [4, 0, 6], 
      state: 0
    }, 
    {
      pos: [4, 0, 7], 
      state: 0
    }, 
    {
      pos: [4, 0, 8], 
      state: 0
    }, 
    {
      pos: [4, 0, 9], 
      state: 0
    }, 
    {
      pos: [4, 0, 10], 
      state: 0
    }, 
    {
      pos: [4, 0, 11], 
      state: 0
    }, 
    {
      pos: [4, 0, 12], 
      state: 0
    }, 
    {
      pos: [4, 0, 13], 
      state: 0
    }, 
    {
      pos: [4, 0, 14], 
      state: 0
    }, 
    {
      pos: [4, 0, 15], 
      state: 0
    }, 
    {
      pos: [4, 0, 16], 
      state: 0
    }, 
    {
      pos: [4, 0, 17], 
      state: 0
    }, 
    {
      pos: [4, 0, 18], 
      state: 0
    }, 
    {
      pos: [4, 0, 19], 
      state: 0
    }, 
    {
      pos: [4, 0, 20], 
      state: 0
    }, 
    {
      pos: [4, 0, 21], 
      state: 0
    }, 
    {
      pos: [4, 0, 22], 
      state: 0
    }, 
    {
      pos: [4, 0, 23], 
      state: 0
    }, 
    {
      pos: [4, 0, 24], 
      state: 0
    }, 
    {
      pos: [4, 0, 25], 
      state: 1
    }, 
    {
      pos: [5, 0, 0], 
      state: 1
    }, 
    {
      pos: [5, 0, 1], 
      state: 1
    }, 
    {
      pos: [5, 0, 2], 
      state: 1
    }, 
    {
      pos: [5, 0, 3], 
      state: 1
    }, 
    {
      pos: [5, 0, 4], 
      state: 1
    }, 
    {
      pos: [5, 0, 5], 
      state: 1
    }, 
    {
      pos: [5, 0, 6], 
      state: 1
    }, 
    {
      pos: [5, 0, 7], 
      state: 1
    }, 
    {
      pos: [5, 0, 8], 
      state: 1
    }, 
    {
      pos: [5, 0, 9], 
      state: 1
    }, 
    {
      pos: [5, 0, 10], 
      state: 1
    }, 
    {
      pos: [5, 0, 11], 
      state: 1
    }, 
    {
      pos: [5, 0, 12], 
      state: 1
    }, 
    {
      pos: [5, 0, 13], 
      state: 1
    }, 
    {
      pos: [5, 0, 14], 
      state: 1
    }, 
    {
      pos: [5, 0, 15], 
      state: 1
    }, 
    {
      pos: [5, 0, 16], 
      state: 1
    }, 
    {
      pos: [5, 0, 17], 
      state: 1
    }, 
    {
      pos: [5, 0, 18], 
      state: 1
    }, 
    {
      pos: [5, 0, 19], 
      state: 1
    }, 
    {
      pos: [5, 0, 20], 
      state: 1
    }, 
    {
      pos: [5, 0, 21], 
      state: 1
    }, 
    {
      pos: [5, 0, 22], 
      state: 1
    }, 
    {
      pos: [5, 0, 23], 
      state: 1
    }, 
    {
      pos: [5, 0, 24], 
      state: 1
    }, 
    {
      pos: [5, 0, 25], 
      state: 1
    }, 
    {
      pos: [0, 1, 1], 
      state: 0
    }, 
    {
      pos: [0, 1, 2], 
      state: 0
    }, 
    {
      pos: [0, 1, 3], 
      state: 0
    }, 
    {
      pos: [0, 1, 6], 
      state: 0
    }, 
    {
      pos: [0, 1, 7], 
      state: 0
    }, 
    {
      pos: [0, 1, 8], 
      state: 0
    }, 
    {
      pos: [0, 1, 11], 
      state: 0
    }, 
    {
      pos: [0, 1, 12], 
      state: 0
    }, 
    {
      pos: [0, 1, 13], 
      state: 0
    }, 
    {
      pos: [0, 1, 16], 
      state: 0
    }, 
    {
      pos: [0, 1, 17], 
      state: 0
    }, 
    {
      pos: [0, 1, 18], 
      state: 0
    }, 
    {
      pos: [0, 1, 21], 
      state: 0
    }, 
    {
      pos: [0, 1, 22], 
      state: 0
    }, 
    {
      pos: [0, 1, 23], 
      state: 0
    }, 
    {
      pos: [1, 1, 0], 
      state: 0
    }, 
    {
      pos: [1, 1, 1], 
      state: 0
    }, 
    {
      pos: [1, 1, 2], 
      state: 0
    }, 
    {
      pos: [1, 1, 3], 
      state: 0
    }, 
    {
      pos: [1, 1, 4], 
      state: 0
    }, 
    {
      pos: [1, 1, 5], 
      state: 0
    }, 
    {
      pos: [1, 1, 6], 
      state: 0
    }, 
    {
      pos: [1, 1, 7], 
      state: 0
    }, 
    {
      pos: [1, 1, 8], 
      state: 0
    }, 
    {
      pos: [1, 1, 9], 
      state: 0
    }, 
    {
      pos: [1, 1, 10], 
      state: 0
    }, 
    {
      pos: [1, 1, 11], 
      state: 0
    }, 
    {
      pos: [1, 1, 12], 
      state: 0
    }, 
    {
      pos: [1, 1, 13], 
      state: 0
    }, 
    {
      pos: [1, 1, 14], 
      state: 0
    }, 
    {
      pos: [1, 1, 15], 
      state: 0
    }, 
    {
      pos: [1, 1, 16], 
      state: 0
    }, 
    {
      pos: [1, 1, 17], 
      state: 0
    }, 
    {
      pos: [1, 1, 18], 
      state: 0
    }, 
    {
      pos: [1, 1, 19], 
      state: 0
    }, 
    {
      pos: [1, 1, 20], 
      state: 0
    }, 
    {
      pos: [1, 1, 21], 
      state: 0
    }, 
    {
      pos: [1, 1, 22], 
      state: 0
    }, 
    {
      pos: [1, 1, 23], 
      state: 0
    }, 
    {
      pos: [1, 1, 24], 
      state: 0
    }, 
    {
      pos: [2, 1, 0], 
      state: 0
    }, 
    {
      pos: [2, 1, 1], 
      state: 0
    }, 
    {
      pos: [2, 1, 2], 
      state: 0
    }, 
    {
      pos: [2, 1, 3], 
      state: 0
    }, 
    {
      pos: [2, 1, 4], 
      state: 0
    }, 
    {
      pos: [2, 1, 5], 
      state: 0
    }, 
    {
      pos: [2, 1, 6], 
      state: 0
    }, 
    {
      pos: [2, 1, 7], 
      state: 0
    }, 
    {
      pos: [2, 1, 8], 
      state: 0
    }, 
    {
      pos: [2, 1, 9], 
      state: 0
    }, 
    {
      pos: [2, 1, 10], 
      state: 0
    }, 
    {
      pos: [2, 1, 11], 
      state: 0
    }, 
    {
      pos: [2, 1, 12], 
      state: 0
    }, 
    {
      pos: [2, 1, 13], 
      state: 0
    }, 
    {
      pos: [2, 1, 14], 
      state: 0
    }, 
    {
      pos: [2, 1, 15], 
      state: 0
    }, 
    {
      pos: [2, 1, 16], 
      state: 0
    }, 
    {
      pos: [2, 1, 17], 
      state: 0
    }, 
    {
      pos: [2, 1, 18], 
      state: 0
    }, 
    {
      pos: [2, 1, 19], 
      state: 0
    }, 
    {
      pos: [2, 1, 20], 
      state: 0
    }, 
    {
      pos: [2, 1, 21], 
      state: 0
    }, 
    {
      pos: [2, 1, 22], 
      state: 0
    }, 
    {
      pos: [2, 1, 23], 
      state: 0
    }, 
    {
      pos: [2, 1, 24], 
      state: 0
    }, 
    {
      pos: [3, 1, 0], 
      state: 0
    }, 
    {
      pos: [3, 1, 1], 
      state: 0
    }, 
    {
      pos: [3, 1, 2], 
      state: 0
    }, 
    {
      pos: [3, 1, 3], 
      state: 0
    }, 
    {
      pos: [3, 1, 4], 
      state: 0
    }, 
    {
      pos: [3, 1, 5], 
      state: 0
    }, 
    {
      pos: [3, 1, 6], 
      state: 0
    }, 
    {
      pos: [3, 1, 7], 
      state: 0
    }, 
    {
      pos: [3, 1, 8], 
      state: 0
    }, 
    {
      pos: [3, 1, 9], 
      state: 0
    }, 
    {
      pos: [3, 1, 10], 
      state: 0
    }, 
    {
      pos: [3, 1, 11], 
      state: 0
    }, 
    {
      pos: [3, 1, 12], 
      state: 0
    }, 
    {
      pos: [3, 1, 13], 
      state: 0
    }, 
    {
      pos: [3, 1, 14], 
      state: 0
    }, 
    {
      pos: [3, 1, 15], 
      state: 0
    }, 
    {
      pos: [3, 1, 16], 
      state: 0
    }, 
    {
      pos: [3, 1, 17], 
      state: 0
    }, 
    {
      pos: [3, 1, 18], 
      state: 0
    }, 
    {
      pos: [3, 1, 19], 
      state: 0
    }, 
    {
      pos: [3, 1, 20], 
      state: 0
    }, 
    {
      pos: [3, 1, 21], 
      state: 0
    }, 
    {
      pos: [3, 1, 22], 
      state: 0
    }, 
    {
      pos: [3, 1, 23], 
      state: 0
    }, 
    {
      pos: [3, 1, 24], 
      state: 0
    }, 
    {
      pos: [4, 1, 1], 
      state: 0
    }, 
    {
      pos: [4, 1, 2], 
      state: 0
    }, 
    {
      pos: [4, 1, 3], 
      state: 0
    }, 
    {
      pos: [4, 1, 4], 
      state: 0
    }, 
    {
      pos: [4, 1, 5], 
      state: 0
    }, 
    {
      pos: [4, 1, 6], 
      state: 0
    }, 
    {
      pos: [4, 1, 7], 
      state: 0
    }, 
    {
      pos: [4, 1, 8], 
      state: 0
    }, 
    {
      pos: [4, 1, 9], 
      state: 0
    }, 
    {
      pos: [4, 1, 10], 
      state: 0
    }, 
    {
      pos: [4, 1, 11], 
      state: 0
    }, 
    {
      pos: [4, 1, 12], 
      state: 0
    }, 
    {
      pos: [4, 1, 13], 
      state: 0
    }, 
    {
      pos: [4, 1, 14], 
      state: 0
    }, 
    {
      pos: [4, 1, 15], 
      state: 0
    }, 
    {
      pos: [4, 1, 16], 
      state: 0
    }, 
    {
      pos: [4, 1, 17], 
      state: 0
    }, 
    {
      pos: [4, 1, 18], 
      state: 0
    }, 
    {
      pos: [4, 1, 19], 
      state: 0
    }, 
    {
      pos: [4, 1, 20], 
      state: 0
    }, 
    {
      pos: [4, 1, 21], 
      state: 0
    }, 
    {
      pos: [4, 1, 22], 
      state: 0
    }, 
    {
      pos: [4, 1, 23], 
      state: 0
    }, 
    {
      pos: [4, 1, 24], 
      state: 0
    }, 
    {
      pos: [0, 2, 1], 
      state: 1
    }, 
    {
      pos: [0, 2, 2], 
      state: 1
    }, 
    {
      pos: [0, 2, 3], 
      state: 1
    }, 
    {
      pos: [0, 2, 6], 
      state: 1
    }, 
    {
      pos: [0, 2, 7], 
      state: 1
    }, 
    {
      pos: [0, 2, 8], 
      state: 1
    }, 
    {
      pos: [0, 2, 11], 
      state: 1
    }, 
    {
      pos: [0, 2, 12], 
      state: 1
    }, 
    {
      pos: [0, 2, 13], 
      state: 1
    }, 
    {
      pos: [0, 2, 16], 
      state: 1
    }, 
    {
      pos: [0, 2, 17], 
      state: 1
    }, 
    {
      pos: [0, 2, 18], 
      state: 1
    }, 
    {
      pos: [0, 2, 21], 
      state: 1
    }, 
    {
      pos: [0, 2, 22], 
      state: 1
    }, 
    {
      pos: [0, 2, 23], 
      state: 1
    }, 
    {
      pos: [1, 2, 0], 
      state: 1
    }, 
    {
      pos: [1, 2, 1], 
      state: 2
    }, 
    {
      pos: [1, 2, 2], 
      state: 2
    }, 
    {
      pos: [1, 2, 3], 
      state: 2
    }, 
    {
      pos: [1, 2, 4], 
      state: 2
    }, 
    {
      pos: [1, 2, 5], 
      state: 2
    }, 
    {
      pos: [1, 2, 6], 
      state: 2
    }, 
    {
      pos: [1, 2, 7], 
      state: 2
    }, 
    {
      pos: [1, 2, 8], 
      state: 2
    }, 
    {
      pos: [1, 2, 9], 
      state: 2
    }, 
    {
      pos: [1, 2, 10], 
      state: 2
    }, 
    {
      pos: [1, 2, 11], 
      state: 2
    }, 
    {
      pos: [1, 2, 12], 
      state: 2
    }, 
    {
      pos: [1, 2, 13], 
      state: 2
    }, 
    {
      pos: [1, 2, 14], 
      state: 2
    }, 
    {
      pos: [1, 2, 15], 
      state: 2
    }, 
    {
      pos: [1, 2, 16], 
      state: 2
    }, 
    {
      pos: [1, 2, 17], 
      state: 2
    }, 
    {
      pos: [1, 2, 18], 
      state: 2
    }, 
    {
      pos: [1, 2, 19], 
      state: 2
    }, 
    {
      pos: [1, 2, 20], 
      state: 2
    }, 
    {
      pos: [1, 2, 21], 
      state: 2
    }, 
    {
      pos: [1, 2, 22], 
      state: 2
    }, 
    {
      pos: [1, 2, 23], 
      state: 2
    }, 
    {
      pos: [1, 2, 24], 
      state: 3
    }, 
    {
      pos: [2, 2, 0], 
      state: 1
    }, 
    {
      pos: [2, 2, 1], 
      state: 2
    }, 
    {
      pos: [2, 2, 2], 
      state: 2
    }, 
    {
      pos: [2, 2, 3], 
      state: 2
    }, 
    {
      pos: [2, 2, 4], 
      state: 2
    }, 
    {
      pos: [2, 2, 5], 
      state: 2
    }, 
    {
      pos: [2, 2, 6], 
      state: 2
    }, 
    {
      pos: [2, 2, 7], 
      state: 2
    }, 
    {
      pos: [2, 2, 8], 
      state: 2
    }, 
    {
      pos: [2, 2, 9], 
      state: 2
    }, 
    {
      pos: [2, 2, 10], 
      state: 2
    }, 
    {
      pos: [2, 2, 11], 
      state: 2
    }, 
    {
      pos: [2, 2, 12], 
      state: 2
    }, 
    {
      pos: [2, 2, 13], 
      state: 2
    }, 
    {
      pos: [2, 2, 14], 
      state: 2
    }, 
    {
      pos: [2, 2, 15], 
      state: 2
    }, 
    {
      pos: [2, 2, 16], 
      state: 2
    }, 
    {
      pos: [2, 2, 17], 
      state: 2
    }, 
    {
      pos: [2, 2, 18], 
      state: 2
    }, 
    {
      pos: [2, 2, 19], 
      state: 2
    }, 
    {
      pos: [2, 2, 20], 
      state: 2
    }, 
    {
      pos: [2, 2, 21], 
      state: 2
    }, 
    {
      pos: [2, 2, 22], 
      state: 2
    }, 
    {
      pos: [2, 2, 23], 
      state: 2
    }, 
    {
      pos: [2, 2, 24], 
      state: 3
    }, 
    {
      pos: [3, 2, 0], 
      state: 1
    }, 
    {
      pos: [3, 2, 1], 
      state: 2
    }, 
    {
      pos: [3, 2, 2], 
      state: 2
    }, 
    {
      pos: [3, 2, 3], 
      state: 2
    }, 
    {
      pos: [3, 2, 4], 
      state: 2
    }, 
    {
      pos: [3, 2, 5], 
      state: 2
    }, 
    {
      pos: [3, 2, 6], 
      state: 2
    }, 
    {
      pos: [3, 2, 7], 
      state: 2
    }, 
    {
      pos: [3, 2, 8], 
      state: 2
    }, 
    {
      pos: [3, 2, 9], 
      state: 2
    }, 
    {
      pos: [3, 2, 10], 
      state: 2
    }, 
    {
      pos: [3, 2, 11], 
      state: 2
    }, 
    {
      pos: [3, 2, 12], 
      state: 2
    }, 
    {
      pos: [3, 2, 13], 
      state: 2
    }, 
    {
      pos: [3, 2, 14], 
      state: 2
    }, 
    {
      pos: [3, 2, 15], 
      state: 2
    }, 
    {
      pos: [3, 2, 16], 
      state: 2
    }, 
    {
      pos: [3, 2, 17], 
      state: 2
    }, 
    {
      pos: [3, 2, 18], 
      state: 2
    }, 
    {
      pos: [3, 2, 19], 
      state: 2
    }, 
    {
      pos: [3, 2, 20], 
      state: 2
    }, 
    {
      pos: [3, 2, 21], 
      state: 2
    }, 
    {
      pos: [3, 2, 22], 
      state: 2
    }, 
    {
      pos: [3, 2, 23], 
      state: 2
    }, 
    {
      pos: [3, 2, 24], 
      state: 3
    }, 
    {
      pos: [4, 2, 1], 
      state: 3
    }, 
    {
      pos: [4, 2, 2], 
      state: 3
    }, 
    {
      pos: [4, 2, 3], 
      state: 3
    }, 
    {
      pos: [4, 2, 4], 
      state: 3
    }, 
    {
      pos: [4, 2, 5], 
      state: 3
    }, 
    {
      pos: [4, 2, 6], 
      state: 3
    }, 
    {
      pos: [4, 2, 7], 
      state: 3
    }, 
    {
      pos: [4, 2, 8], 
      state: 3
    }, 
    {
      pos: [4, 2, 9], 
      state: 3
    }, 
    {
      pos: [4, 2, 10], 
      state: 3
    }, 
    {
      pos: [4, 2, 11], 
      state: 3
    }, 
    {
      pos: [4, 2, 12], 
      state: 3
    }, 
    {
      pos: [4, 2, 13], 
      state: 3
    }, 
    {
      pos: [4, 2, 14], 
      state: 3
    }, 
    {
      pos: [4, 2, 15], 
      state: 3
    }, 
    {
      pos: [4, 2, 16], 
      state: 3
    }, 
    {
      pos: [4, 2, 17], 
      state: 3
    }, 
    {
      pos: [4, 2, 18], 
      state: 3
    }, 
    {
      pos: [4, 2, 19], 
      state: 3
    }, 
    {
      pos: [4, 2, 20], 
      state: 3
    }, 
    {
      pos: [4, 2, 21], 
      state: 3
    }, 
    {
      pos: [4, 2, 22], 
      state: 3
    }, 
    {
      pos: [4, 2, 23], 
      state: 3
    }, 
    {
      pos: [4, 2, 24], 
      state: 3
    }, 
    {
      nbt: {
        joint: "aligned", 
        final_state: "minecraft:tuff_bricks", 
        name: "minecraft:wide_platform", 
        placement_priority: 0, 
        pool: "minecraft:empty", 
        selection_priority: 0, 
        id: "minecraft:jigsaw", 
        target: "minecraft:empty"
      }, 
      pos: [2, 0, 22], 
      state: 4
    }, 
    {
      nbt: {
        joint: "aligned", 
        final_state: "minecraft:air", 
        name: "minecraft:empty", 
        placement_priority: 0, 
        pool: "minecraft:trial_chambers/reward/all", 
        selection_priority: 0, 
        id: "minecraft:jigsaw", 
        target: "minecraft:reward_connector"
      }, 
      pos: [2, 4, 2], 
      state: 5
    }, 
    {
      nbt: {
        joint: "aligned", 
        final_state: "minecraft:air", 
        name: "minecraft:empty", 
        placement_priority: 1, 
        pool: "minecraft:trial_chambers/spawner/ranged", 
        selection_priority: 1, 
        id: "minecraft:jigsaw", 
        target: "minecraft:spawner_connector"
      }, 
      pos: [2, 4, 7], 
      state: 5
    }, 
    {
      nbt: {
        joint: "aligned", 
        final_state: "minecraft:air", 
        name: "minecraft:empty", 
        placement_priority: 1, 
        pool: "minecraft:trial_chambers/spawner/breeze", 
        selection_priority: 1, 
        id: "minecraft:jigsaw", 
        target: "minecraft:spawner_connector"
      }, 
      pos: [2, 4, 17], 
      state: 6
    }
  ], 
  palette: [
    {
      Name: "minecraft:tuff_bricks"
    }, 
    {
      Name: "minecraft:waxed_oxidized_cut_copper"
    }, 
    {
      Name: "minecraft:waxed_oxidized_copper"
    }, 
    {
      Name: "minecraft:waxed_copper_block"
    }, 
    {
      Properties: {
        orientation: "down_east"
      }, 
      Name: "minecraft:jigsaw"
    }, 
    {
      Properties: {
        orientation: "east_up"
      }, 
      Name: "minecraft:jigsaw"
    }, 
    {
      Properties: {
        orientation: "west_up"
      }, 
      Name: "minecraft:jigsaw"
    }
  ]
}
