{
  size: [9, 7, 6], 
  entities: [], 
  blocks: [
    {
      pos: [0, 0, 0], 
      state: 0
    }, 
    {
      pos: [0, 0, 1], 
      state: 1
    }, 
    {
      pos: [0, 0, 2], 
      state: 1
    }, 
    {
      pos: [0, 0, 3], 
      state: 1
    }, 
    {
      pos: [0, 0, 4], 
      state: 1
    }, 
    {
      pos: [0, 0, 5], 
      state: 1
    }, 
    {
      pos: [1, 0, 0], 
      state: 0
    }, 
    {
      pos: [1, 0, 1], 
      state: 1
    }, 
    {
      pos: [1, 0, 2], 
      state: 1
    }, 
    {
      pos: [1, 0, 3], 
      state: 1
    }, 
    {
      pos: [1, 0, 4], 
      state: 1
    }, 
    {
      pos: [1, 0, 5], 
      state: 1
    }, 
    {
      pos: [2, 0, 0], 
      state: 0
    }, 
    {
      pos: [2, 0, 1], 
      state: 1
    }, 
    {
      pos: [2, 0, 2], 
      state: 1
    }, 
    {
      pos: [2, 0, 3], 
      state: 1
    }, 
    {
      pos: [2, 0, 4], 
      state: 1
    }, 
    {
      pos: [2, 0, 5], 
      state: 1
    }, 
    {
      pos: [3, 0, 0], 
      state: 0
    }, 
    {
      pos: [3, 0, 1], 
      state: 1
    }, 
    {
      pos: [3, 0, 2], 
      state: 1
    }, 
    {
      pos: [3, 0, 3], 
      state: 1
    }, 
    {
      pos: [3, 0, 4], 
      state: 1
    }, 
    {
      pos: [3, 0, 5], 
      state: 1
    }, 
    {
      pos: [4, 0, 0], 
      state: 1
    }, 
    {
      pos: [4, 0, 1], 
      state: 1
    }, 
    {
      pos: [4, 0, 2], 
      state: 1
    }, 
    {
      pos: [4, 0, 3], 
      state: 1
    }, 
    {
      pos: [4, 0, 4], 
      state: 1
    }, 
    {
      pos: [4, 0, 5], 
      state: 1
    }, 
    {
      pos: [5, 0, 0], 
      state: 1
    }, 
    {
      pos: [5, 0, 1], 
      state: 1
    }, 
    {
      pos: [5, 0, 2], 
      state: 1
    }, 
    {
      pos: [5, 0, 3], 
      state: 1
    }, 
    {
      pos: [5, 0, 4], 
      state: 1
    }, 
    {
      pos: [5, 0, 5], 
      state: 1
    }, 
    {
      pos: [6, 0, 0], 
      state: 1
    }, 
    {
      pos: [6, 0, 1], 
      state: 1
    }, 
    {
      pos: [6, 0, 2], 
      state: 1
    }, 
    {
      pos: [6, 0, 3], 
      state: 1
    }, 
    {
      pos: [6, 0, 4], 
      state: 1
    }, 
    {
      pos: [6, 0, 5], 
      state: 1
    }, 
    {
      pos: [7, 0, 0], 
      state: 1
    }, 
    {
      pos: [7, 0, 1], 
      state: 1
    }, 
    {
      pos: [7, 0, 2], 
      state: 1
    }, 
    {
      pos: [7, 0, 3], 
      state: 1
    }, 
    {
      pos: [7, 0, 4], 
      state: 1
    }, 
    {
      pos: [7, 0, 5], 
      state: 1
    }, 
    {
      pos: [8, 0, 0], 
      state: 1
    }, 
    {
      pos: [8, 0, 1], 
      state: 1
    }, 
    {
      pos: [8, 0, 2], 
      state: 1
    }, 
    {
      pos: [8, 0, 3], 
      state: 1
    }, 
    {
      pos: [8, 0, 4], 
      state: 1
    }, 
    {
      pos: [8, 0, 5], 
      state: 1
    }, 
    {
      pos: [0, 1, 0], 
      state: 2
    }, 
    {
      pos: [0, 1, 1], 
      state: 1
    }, 
    {
      pos: [0, 1, 2], 
      state: 3
    }, 
    {
      pos: [0, 1, 3], 
      state: 1
    }, 
    {
      pos: [0, 1, 4], 
      state: 4
    }, 
    {
      pos: [0, 1, 5], 
      state: 1
    }, 
    {
      pos: [1, 1, 0], 
      state: 5
    }, 
    {
      pos: [1, 1, 1], 
      state: 1
    }, 
    {
      pos: [1, 1, 2], 
      state: 6
    }, 
    {
      pos: [1, 1, 3], 
      state: 1
    }, 
    {
      pos: [1, 1, 4], 
      state: 7
    }, 
    {
      pos: [1, 1, 5], 
      state: 1
    }, 
    {
      pos: [2, 1, 0], 
      state: 8
    }, 
    {
      pos: [2, 1, 1], 
      state: 1
    }, 
    {
      pos: [2, 1, 2], 
      state: 3
    }, 
    {
      pos: [2, 1, 3], 
      state: 1
    }, 
    {
      pos: [2, 1, 4], 
      state: 4
    }, 
    {
      pos: [2, 1, 5], 
      state: 1
    }, 
    {
      pos: [3, 1, 0], 
      state: 2
    }, 
    {
      pos: [3, 1, 1], 
      state: 1
    }, 
    {
      pos: [3, 1, 2], 
      state: 6
    }, 
    {
      pos: [3, 1, 3], 
      state: 1
    }, 
    {
      pos: [3, 1, 4], 
      state: 7
    }, 
    {
      pos: [3, 1, 5], 
      state: 1
    }, 
    {
      pos: [4, 1, 0], 
      state: 1
    }, 
    {
      pos: [4, 1, 1], 
      state: 1
    }, 
    {
      pos: [4, 1, 2], 
      state: 3
    }, 
    {
      pos: [4, 1, 3], 
      state: 1
    }, 
    {
      pos: [4, 1, 4], 
      state: 4
    }, 
    {
      pos: [4, 1, 5], 
      state: 1
    }, 
    {
      pos: [5, 1, 0], 
      state: 1
    }, 
    {
      pos: [5, 1, 1], 
      state: 1
    }, 
    {
      pos: [5, 1, 2], 
      state: 1
    }, 
    {
      pos: [5, 1, 3], 
      state: 1
    }, 
    {
      pos: [5, 1, 4], 
      state: 1
    }, 
    {
      pos: [5, 1, 5], 
      state: 1
    }, 
    {
      pos: [6, 1, 1], 
      state: 1
    }, 
    {
      pos: [6, 1, 2], 
      state: 1
    }, 
    {
      pos: [6, 1, 3], 
      state: 1
    }, 
    {
      pos: [6, 1, 4], 
      state: 1
    }, 
    {
      pos: [7, 1, 0], 
      state: 1
    }, 
    {
      pos: [7, 1, 1], 
      state: 1
    }, 
    {
      pos: [7, 1, 2], 
      state: 1
    }, 
    {
      pos: [7, 1, 3], 
      state: 1
    }, 
    {
      pos: [7, 1, 4], 
      state: 1
    }, 
    {
      pos: [7, 1, 5], 
      state: 1
    }, 
    {
      pos: [8, 1, 0], 
      state: 1
    }, 
    {
      pos: [8, 1, 1], 
      state: 1
    }, 
    {
      pos: [8, 1, 3], 
      state: 1
    }, 
    {
      pos: [8, 1, 4], 
      state: 1
    }, 
    {
      pos: [8, 1, 5], 
      state: 1
    }, 
    {
      pos: [0, 2, 1], 
      state: 1
    }, 
    {
      pos: [0, 2, 2], 
      state: 9
    }, 
    {
      pos: [0, 2, 3], 
      state: 9
    }, 
    {
      pos: [0, 2, 4], 
      state: 9
    }, 
    {
      pos: [0, 2, 5], 
      state: 1
    }, 
    {
      pos: [1, 2, 0], 
      state: 9
    }, 
    {
      pos: [1, 2, 1], 
      state: 9
    }, 
    {
      pos: [1, 2, 2], 
      state: 9
    }, 
    {
      pos: [1, 2, 3], 
      state: 9
    }, 
    {
      pos: [1, 2, 4], 
      state: 9
    }, 
    {
      pos: [1, 2, 5], 
      state: 10
    }, 
    {
      pos: [2, 2, 0], 
      state: 9
    }, 
    {
      pos: [2, 2, 1], 
      state: 9
    }, 
    {
      pos: [2, 2, 2], 
      state: 9
    }, 
    {
      pos: [2, 2, 3], 
      state: 9
    }, 
    {
      pos: [2, 2, 4], 
      state: 10
    }, 
    {
      pos: [2, 2, 5], 
      state: 9
    }, 
    {
      pos: [3, 2, 0], 
      state: 9
    }, 
    {
      pos: [3, 2, 1], 
      state: 9
    }, 
    {
      pos: [3, 2, 2], 
      state: 9
    }, 
    {
      pos: [3, 2, 3], 
      state: 10
    }, 
    {
      pos: [3, 2, 4], 
      state: 9
    }, 
    {
      pos: [3, 2, 5], 
      state: 9
    }, 
    {
      pos: [4, 2, 0], 
      state: 1
    }, 
    {
      pos: [4, 2, 1], 
      state: 1
    }, 
    {
      pos: [4, 2, 2], 
      state: 9
    }, 
    {
      pos: [4, 2, 3], 
      state: 9
    }, 
    {
      pos: [4, 2, 4], 
      state: 9
    }, 
    {
      pos: [4, 2, 5], 
      state: 1
    }, 
    {
      pos: [5, 2, 0], 
      state: 1
    }, 
    {
      pos: [5, 2, 1], 
      state: 9
    }, 
    {
      pos: [5, 2, 2], 
      state: 9
    }, 
    {
      pos: [5, 2, 3], 
      state: 9
    }, 
    {
      pos: [5, 2, 4], 
      state: 9
    }, 
    {
      pos: [5, 2, 5], 
      state: 9
    }, 
    {
      pos: [6, 2, 0], 
      state: 9
    }, 
    {
      pos: [6, 2, 1], 
      state: 9
    }, 
    {
      pos: [6, 2, 2], 
      state: 9
    }, 
    {
      pos: [6, 2, 3], 
      state: 11
    }, 
    {
      pos: [6, 2, 4], 
      state: 9
    }, 
    {
      pos: [6, 2, 5], 
      state: 9
    }, 
    {
      pos: [7, 2, 0], 
      state: 1
    }, 
    {
      pos: [7, 2, 2], 
      state: 9
    }, 
    {
      pos: [7, 2, 3], 
      state: 1
    }, 
    {
      pos: [7, 2, 4], 
      state: 10
    }, 
    {
      pos: [7, 2, 5], 
      state: 1
    }, 
    {
      pos: [8, 2, 0], 
      state: 1
    }, 
    {
      pos: [8, 2, 1], 
      state: 1
    }, 
    {
      pos: [8, 2, 2], 
      state: 9
    }, 
    {
      pos: [8, 2, 3], 
      state: 1
    }, 
    {
      pos: [8, 2, 4], 
      state: 1
    }, 
    {
      pos: [8, 2, 5], 
      state: 1
    }, 
    {
      pos: [0, 3, 1], 
      state: 12
    }, 
    {
      pos: [0, 3, 2], 
      state: 9
    }, 
    {
      pos: [0, 3, 3], 
      state: 9
    }, 
    {
      pos: [0, 3, 4], 
      state: 9
    }, 
    {
      pos: [0, 3, 5], 
      state: 12
    }, 
    {
      pos: [1, 3, 0], 
      state: 9
    }, 
    {
      pos: [1, 3, 1], 
      state: 9
    }, 
    {
      pos: [1, 3, 2], 
      state: 9
    }, 
    {
      pos: [1, 3, 3], 
      state: 9
    }, 
    {
      pos: [1, 3, 4], 
      state: 9
    }, 
    {
      pos: [1, 3, 5], 
      state: 9
    }, 
    {
      pos: [2, 3, 0], 
      state: 9
    }, 
    {
      pos: [2, 3, 1], 
      state: 9
    }, 
    {
      pos: [2, 3, 2], 
      state: 9
    }, 
    {
      pos: [2, 3, 3], 
      state: 9
    }, 
    {
      pos: [2, 3, 4], 
      state: 9
    }, 
    {
      pos: [2, 3, 5], 
      state: 9
    }, 
    {
      pos: [3, 3, 0], 
      state: 9
    }, 
    {
      pos: [3, 3, 1], 
      state: 9
    }, 
    {
      pos: [3, 3, 2], 
      state: 9
    }, 
    {
      pos: [3, 3, 3], 
      state: 9
    }, 
    {
      pos: [3, 3, 4], 
      state: 9
    }, 
    {
      pos: [3, 3, 5], 
      state: 9
    }, 
    {
      pos: [4, 3, 0], 
      state: 12
    }, 
    {
      pos: [4, 3, 1], 
      state: 12
    }, 
    {
      pos: [4, 3, 2], 
      state: 9
    }, 
    {
      pos: [4, 3, 3], 
      state: 9
    }, 
    {
      pos: [4, 3, 4], 
      state: 9
    }, 
    {
      pos: [4, 3, 5], 
      state: 12
    }, 
    {
      pos: [5, 3, 0], 
      state: 12
    }, 
    {
      pos: [5, 3, 1], 
      state: 9
    }, 
    {
      pos: [5, 3, 2], 
      state: 9
    }, 
    {
      pos: [5, 3, 3], 
      state: 9
    }, 
    {
      pos: [5, 3, 4], 
      state: 9
    }, 
    {
      pos: [5, 3, 5], 
      state: 9
    }, 
    {
      pos: [6, 3, 0], 
      state: 9
    }, 
    {
      pos: [6, 3, 1], 
      state: 9
    }, 
    {
      pos: [6, 3, 2], 
      state: 9
    }, 
    {
      pos: [6, 3, 3], 
      state: 9
    }, 
    {
      pos: [6, 3, 4], 
      state: 9
    }, 
    {
      pos: [6, 3, 5], 
      state: 9
    }, 
    {
      pos: [7, 3, 0], 
      state: 12
    }, 
    {
      pos: [7, 3, 1], 
      state: 9
    }, 
    {
      pos: [7, 3, 2], 
      state: 9
    }, 
    {
      pos: [7, 3, 3], 
      state: 9
    }, 
    {
      pos: [7, 3, 4], 
      state: 9
    }, 
    {
      pos: [7, 3, 5], 
      state: 12
    }, 
    {
      pos: [8, 3, 0], 
      state: 12
    }, 
    {
      pos: [8, 3, 1], 
      state: 12
    }, 
    {
      pos: [8, 3, 2], 
      state: 9
    }, 
    {
      pos: [8, 3, 3], 
      state: 12
    }, 
    {
      pos: [8, 3, 4], 
      state: 12
    }, 
    {
      pos: [8, 3, 5], 
      state: 12
    }, 
    {
      pos: [0, 4, 1], 
      state: 1
    }, 
    {
      pos: [0, 4, 2], 
      state: 9
    }, 
    {
      pos: [0, 4, 3], 
      state: 9
    }, 
    {
      pos: [0, 4, 4], 
      state: 9
    }, 
    {
      pos: [0, 4, 5], 
      state: 1
    }, 
    {
      pos: [1, 4, 0], 
      state: 9
    }, 
    {
      pos: [1, 4, 1], 
      state: 9
    }, 
    {
      pos: [1, 4, 2], 
      state: 9
    }, 
    {
      pos: [1, 4, 3], 
      state: 9
    }, 
    {
      pos: [1, 4, 4], 
      state: 9
    }, 
    {
      pos: [1, 4, 5], 
      state: 9
    }, 
    {
      pos: [2, 4, 0], 
      state: 9
    }, 
    {
      pos: [2, 4, 1], 
      state: 9
    }, 
    {
      pos: [2, 4, 2], 
      state: 9
    }, 
    {
      pos: [2, 4, 3], 
      state: 9
    }, 
    {
      pos: [2, 4, 4], 
      state: 9
    }, 
    {
      pos: [2, 4, 5], 
      state: 9
    }, 
    {
      pos: [3, 4, 0], 
      state: 9
    }, 
    {
      pos: [3, 4, 1], 
      state: 9
    }, 
    {
      pos: [3, 4, 2], 
      state: 9
    }, 
    {
      pos: [3, 4, 3], 
      state: 9
    }, 
    {
      pos: [3, 4, 4], 
      state: 9
    }, 
    {
      pos: [3, 4, 5], 
      state: 9
    }, 
    {
      pos: [4, 4, 0], 
      state: 1
    }, 
    {
      pos: [4, 4, 1], 
      state: 1
    }, 
    {
      pos: [4, 4, 2], 
      state: 9
    }, 
    {
      pos: [4, 4, 3], 
      state: 9
    }, 
    {
      pos: [4, 4, 4], 
      state: 9
    }, 
    {
      pos: [4, 4, 5], 
      state: 1
    }, 
    {
      pos: [5, 4, 0], 
      state: 1
    }, 
    {
      pos: [5, 4, 1], 
      state: 9
    }, 
    {
      pos: [5, 4, 2], 
      state: 9
    }, 
    {
      pos: [5, 4, 3], 
      state: 9
    }, 
    {
      pos: [5, 4, 4], 
      state: 9
    }, 
    {
      pos: [5, 4, 5], 
      state: 9
    }, 
    {
      pos: [6, 4, 0], 
      state: 1
    }, 
    {
      pos: [6, 4, 1], 
      state: 9
    }, 
    {
      pos: [6, 4, 2], 
      state: 9
    }, 
    {
      pos: [6, 4, 3], 
      state: 9
    }, 
    {
      pos: [6, 4, 4], 
      state: 9
    }, 
    {
      pos: [6, 4, 5], 
      state: 9
    }, 
    {
      pos: [7, 4, 0], 
      state: 1
    }, 
    {
      pos: [7, 4, 2], 
      state: 9
    }, 
    {
      pos: [7, 4, 3], 
      state: 9
    }, 
    {
      pos: [7, 4, 4], 
      state: 9
    }, 
    {
      pos: [7, 4, 5], 
      state: 1
    }, 
    {
      pos: [8, 4, 0], 
      state: 1
    }, 
    {
      pos: [8, 4, 1], 
      state: 1
    }, 
    {
      pos: [8, 4, 2], 
      state: 9
    }, 
    {
      pos: [8, 4, 3], 
      state: 1
    }, 
    {
      pos: [8, 4, 4], 
      state: 9
    }, 
    {
      pos: [0, 5, 1], 
      state: 10
    }, 
    {
      pos: [0, 5, 5], 
      state: 10
    }, 
    {
      pos: [1, 5, 0], 
      state: 9
    }, 
    {
      pos: [1, 5, 1], 
      state: 9
    }, 
    {
      pos: [1, 5, 2], 
      state: 9
    }, 
    {
      pos: [1, 5, 3], 
      state: 9
    }, 
    {
      pos: [1, 5, 5], 
      state: 10
    }, 
    {
      pos: [2, 5, 1], 
      state: 10
    }, 
    {
      pos: [2, 5, 2], 
      state: 9
    }, 
    {
      pos: [2, 5, 3], 
      state: 9
    }, 
    {
      pos: [2, 5, 4], 
      state: 9
    }, 
    {
      pos: [2, 5, 5], 
      state: 10
    }, 
    {
      pos: [3, 5, 1], 
      state: 10
    }, 
    {
      pos: [3, 5, 2], 
      state: 9
    }, 
    {
      pos: [3, 5, 3], 
      state: 9
    }, 
    {
      pos: [3, 5, 4], 
      state: 9
    }, 
    {
      pos: [3, 5, 5], 
      state: 10
    }, 
    {
      pos: [4, 5, 0], 
      state: 1
    }, 
    {
      pos: [4, 5, 1], 
      state: 10
    }, 
    {
      pos: [4, 5, 2], 
      state: 9
    }, 
    {
      pos: [4, 5, 3], 
      state: 9
    }, 
    {
      pos: [4, 5, 4], 
      state: 9
    }, 
    {
      pos: [4, 5, 5], 
      state: 10
    }, 
    {
      pos: [5, 5, 0], 
      state: 13
    }, 
    {
      pos: [5, 5, 1], 
      state: 9
    }, 
    {
      pos: [5, 5, 2], 
      state: 9
    }, 
    {
      pos: [5, 5, 3], 
      state: 9
    }, 
    {
      pos: [5, 5, 4], 
      state: 9
    }, 
    {
      pos: [5, 5, 5], 
      state: 10
    }, 
    {
      pos: [6, 5, 0], 
      state: 13
    }, 
    {
      pos: [6, 5, 1], 
      state: 9
    }, 
    {
      pos: [6, 5, 2], 
      state: 9
    }, 
    {
      pos: [6, 5, 3], 
      state: 9
    }, 
    {
      pos: [6, 5, 4], 
      state: 9
    }, 
    {
      pos: [6, 5, 5], 
      state: 10
    }, 
    {
      pos: [7, 5, 0], 
      state: 13
    }, 
    {
      pos: [7, 5, 1], 
      state: 9
    }, 
    {
      pos: [7, 5, 2], 
      state: 9
    }, 
    {
      pos: [7, 5, 3], 
      state: 9
    }, 
    {
      pos: [8, 5, 0], 
      state: 1
    }, 
    {
      pos: [8, 5, 1], 
      state: 1
    }, 
    {
      pos: [8, 5, 2], 
      state: 1
    }, 
    {
      pos: [8, 5, 3], 
      state: 1
    }, 
    {
      pos: [1, 6, 2], 
      state: 10
    }, 
    {
      pos: [2, 6, 2], 
      state: 10
    }, 
    {
      pos: [2, 6, 3], 
      state: 9
    }, 
    {
      pos: [3, 6, 2], 
      state: 10
    }, 
    {
      pos: [3, 6, 3], 
      state: 10
    }, 
    {
      pos: [3, 6, 4], 
      state: 10
    }, 
    {
      pos: [4, 6, 0], 
      state: 10
    }, 
    {
      pos: [4, 6, 2], 
      state: 10
    }, 
    {
      pos: [4, 6, 3], 
      state: 9
    }, 
    {
      pos: [4, 6, 4], 
      state: 10
    }, 
    {
      pos: [5, 6, 0], 
      state: 10
    }, 
    {
      pos: [5, 6, 1], 
      state: 10
    }, 
    {
      pos: [5, 6, 2], 
      state: 10
    }, 
    {
      pos: [5, 6, 3], 
      state: 10
    }, 
    {
      pos: [5, 6, 4], 
      state: 10
    }, 
    {
      pos: [6, 6, 0], 
      state: 10
    }, 
    {
      pos: [6, 6, 1], 
      state: 10
    }, 
    {
      pos: [6, 6, 2], 
      state: 10
    }, 
    {
      pos: [6, 6, 3], 
      state: 10
    }, 
    {
      pos: [6, 6, 4], 
      state: 10
    }, 
    {
      pos: [7, 6, 0], 
      state: 10
    }, 
    {
      pos: [7, 6, 2], 
      state: 10
    }, 
    {
      pos: [7, 6, 3], 
      state: 10
    }, 
    {
      pos: [8, 6, 0], 
      state: 10
    }, 
    {
      pos: [8, 6, 1], 
      state: 10
    }, 
    {
      pos: [8, 6, 2], 
      state: 10
    }, 
    {
      pos: [7, 2, 1], 
      state: 14
    }, 
    {
      pos: [7, 4, 1], 
      state: 14
    }, 
    {
      nbt: {
        joint: "rollable", 
        final_state: "minecraft:mud_bricks", 
        name: "minecraft:road_hall_anchor", 
        pool: "minecraft:trail_ruins/tower", 
        id: "minecraft:jigsaw", 
        target: "minecraft:road_anchor"
      }, 
      pos: [6, 1, 0], 
      state: 15
    }, 
    {
      nbt: {
        joint: "rollable", 
        final_state: "minecraft:mud_bricks", 
        name: "minecraft:hall_room_anchor", 
        pool: "minecraft:trail_ruins/tower/additions", 
        id: "minecraft:jigsaw", 
        target: "minecraft:room_anchor"
      }, 
      pos: [6, 1, 5], 
      state: 16
    }, 
    {
      nbt: {
        joint: "rollable", 
        final_state: "minecraft:mud_bricks", 
        name: "minecraft:hall_room_anchor", 
        pool: "minecraft:trail_ruins/tower/additions", 
        id: "minecraft:jigsaw", 
        target: "minecraft:room_anchor"
      }, 
      pos: [8, 1, 2], 
      state: 17
    }
  ], 
  palette: [
    {
      Name: "minecraft:cobblestone"
    }, 
    {
      Name: "minecraft:mud_bricks"
    }, 
    {
      Name: "minecraft:stone_bricks"
    }, 
    {
      Properties: {
        facing: "east"
      }, 
      Name: "minecraft:yellow_glazed_terracotta"
    }, 
    {
      Properties: {
        facing: "south"
      }, 
      Name: "minecraft:yellow_glazed_terracotta"
    }, 
    {
      Name: "minecraft:stone"
    }, 
    {
      Properties: {
        facing: "north"
      }, 
      Name: "minecraft:yellow_glazed_terracotta"
    }, 
    {
      Properties: {
        facing: "west"
      }, 
      Name: "minecraft:yellow_glazed_terracotta"
    }, 
    {
      Name: "minecraft:cracked_stone_bricks"
    }, 
    {
      Name: "minecraft:gravel"
    }, 
    {
      Name: "minecraft:blue_terracotta"
    }, 
    {
      Name: "minecraft:crafting_table"
    }, 
    {
      Name: "minecraft:red_terracotta"
    }, 
    {
      Name: "minecraft:yellow_terracotta"
    }, 
    {
      Properties: {
        waterlogged: "false", 
        facing: "south"
      }, 
      Name: "minecraft:ladder"
    }, 
    {
      Properties: {
        orientation: "north_up"
      }, 
      Name: "minecraft:jigsaw"
    }, 
    {
      Properties: {
        orientation: "south_up"
      }, 
      Name: "minecraft:jigsaw"
    }, 
    {
      Properties: {
        orientation: "east_up"
      }, 
      Name: "minecraft:jigsaw"
    }
  ]
}
