{
  size: [7, 7, 7], 
  entities: [], 
  blocks: [
    {
      pos: [2, 0, 2], 
      state: 0
    }, 
    {
      pos: [4, 0, 2], 
      state: 0
    }, 
    {
      pos: [2, 4, 2], 
      state: 1
    }, 
    {
      pos: [3, 4, 2], 
      state: 2
    }, 
    {
      pos: [4, 4, 2], 
      state: 2
    }, 
    {
      pos: [2, 4, 3], 
      state: 1
    }, 
    {
      pos: [3, 4, 3], 
      state: 1
    }, 
    {
      pos: [4, 4, 3], 
      state: 1
    }, 
    {
      pos: [3, 5, 3], 
      state: 1
    }, 
    {
      pos: [2, 0, 4], 
      state: 0
    }, 
    {
      pos: [4, 0, 4], 
      state: 0
    }, 
    {
      pos: [2, 4, 4], 
      state: 1
    }, 
    {
      pos: [3, 4, 4], 
      state: 2
    }, 
    {
      pos: [4, 4, 4], 
      state: 1
    }, 
    {
      nbt: {
        target_pool: "minecraft:village/snowy/zombie/streets", 
        final_state: "minecraft:structure_void", 
        id: "minecraft:jigsaw", 
        attachement_type: "minecraft:street"
      }, 
      pos: [3, 1, 0], 
      state: 3
    }, 
    {
      nbt: {
        target_pool: "minecraft:village/common/cats", 
        final_state: "minecraft:grass_block", 
        id: "minecraft:jigsaw", 
        attachement_type: "minecraft:bottom"
      }, 
      pos: [0, 0, 1], 
      state: 4
    }, 
    {
      nbt: {
        target_pool: "minecraft:village/snowy/zombie/streets", 
        final_state: "minecraft:structure_void", 
        id: "minecraft:jigsaw", 
        attachement_type: "minecraft:street"
      }, 
      pos: [0, 1, 3], 
      state: 5
    }, 
    {
      nbt: {
        target_pool: "minecraft:village/snowy/zombie/streets", 
        final_state: "minecraft:structure_void", 
        id: "minecraft:jigsaw", 
        attachement_type: "minecraft:street"
      }, 
      pos: [6, 1, 3], 
      state: 6
    }, 
    {
      nbt: {
        id: "minecraft:bell"
      }, 
      pos: [3, 3, 3], 
      state: 7
    }, 
    {
      nbt: {
        target_pool: "minecraft:village/common/cats", 
        final_state: "minecraft:grass_block", 
        id: "minecraft:jigsaw", 
        attachement_type: "minecraft:bottom"
      }, 
      pos: [6, 0, 6], 
      state: 4
    }, 
    {
      nbt: {
        target_pool: "minecraft:village/snowy/zombie/streets", 
        final_state: "minecraft:structure_void", 
        id: "minecraft:jigsaw", 
        attachement_type: "minecraft:street"
      }, 
      pos: [3, 1, 6], 
      state: 8
    }, 
    {
      pos: [2, 0, 0], 
      state: 9
    }, 
    {
      pos: [3, 0, 0], 
      state: 9
    }, 
    {
      pos: [4, 0, 0], 
      state: 9
    }, 
    {
      pos: [1, 0, 1], 
      state: 9
    }, 
    {
      pos: [2, 0, 1], 
      state: 9
    }, 
    {
      pos: [3, 0, 1], 
      state: 9
    }, 
    {
      pos: [4, 0, 1], 
      state: 9
    }, 
    {
      pos: [5, 0, 1], 
      state: 9
    }, 
    {
      pos: [3, 3, 1], 
      state: 10
    }, 
    {
      pos: [3, 4, 1], 
      state: 11
    }, 
    {
      pos: [0, 0, 2], 
      state: 9
    }, 
    {
      pos: [1, 0, 2], 
      state: 9
    }, 
    {
      pos: [3, 0, 2], 
      state: 9
    }, 
    {
      pos: [5, 0, 2], 
      state: 9
    }, 
    {
      pos: [6, 0, 2], 
      state: 9
    }, 
    {
      pos: [2, 1, 2], 
      state: 12
    }, 
    {
      pos: [4, 1, 2], 
      state: 12
    }, 
    {
      pos: [2, 2, 2], 
      state: 12
    }, 
    {
      pos: [4, 2, 2], 
      state: 12
    }, 
    {
      pos: [2, 3, 2], 
      state: 12
    }, 
    {
      pos: [4, 3, 2], 
      state: 12
    }, 
    {
      pos: [0, 0, 3], 
      state: 9
    }, 
    {
      pos: [1, 0, 3], 
      state: 9
    }, 
    {
      pos: [2, 0, 3], 
      state: 9
    }, 
    {
      pos: [3, 0, 3], 
      state: 9
    }, 
    {
      pos: [4, 0, 3], 
      state: 9
    }, 
    {
      pos: [5, 0, 3], 
      state: 9
    }, 
    {
      pos: [6, 0, 3], 
      state: 9
    }, 
    {
      pos: [1, 3, 3], 
      state: 10
    }, 
    {
      pos: [5, 3, 3], 
      state: 10
    }, 
    {
      pos: [1, 4, 3], 
      state: 13
    }, 
    {
      pos: [5, 4, 3], 
      state: 14
    }, 
    {
      pos: [0, 0, 4], 
      state: 9
    }, 
    {
      pos: [1, 0, 4], 
      state: 9
    }, 
    {
      pos: [3, 0, 4], 
      state: 9
    }, 
    {
      pos: [5, 0, 4], 
      state: 9
    }, 
    {
      pos: [6, 0, 4], 
      state: 9
    }, 
    {
      pos: [2, 1, 4], 
      state: 12
    }, 
    {
      pos: [4, 1, 4], 
      state: 12
    }, 
    {
      pos: [2, 2, 4], 
      state: 12
    }, 
    {
      pos: [4, 2, 4], 
      state: 12
    }, 
    {
      pos: [2, 3, 4], 
      state: 12
    }, 
    {
      pos: [4, 3, 4], 
      state: 12
    }, 
    {
      pos: [1, 0, 5], 
      state: 9
    }, 
    {
      pos: [2, 0, 5], 
      state: 9
    }, 
    {
      pos: [3, 0, 5], 
      state: 9
    }, 
    {
      pos: [4, 0, 5], 
      state: 9
    }, 
    {
      pos: [5, 0, 5], 
      state: 9
    }, 
    {
      pos: [3, 3, 5], 
      state: 10
    }, 
    {
      pos: [3, 4, 5], 
      state: 15
    }, 
    {
      pos: [2, 0, 6], 
      state: 9
    }, 
    {
      pos: [3, 0, 6], 
      state: 9
    }, 
    {
      pos: [4, 0, 6], 
      state: 9
    }
  ], 
  palette: [
    {
      Properties: {
        snowy: "false"
      }, 
      Name: "minecraft:grass_block"
    }, 
    {
      Properties: {
        axis: "z"
      }, 
      Name: "minecraft:stripped_spruce_wood"
    }, 
    {
      Properties: {
        axis: "x"
      }, 
      Name: "minecraft:stripped_spruce_wood"
    }, 
    {
      Properties: {
        facing: "north"
      }, 
      Name: "minecraft:jigsaw"
    }, 
    {
      Properties: {
        facing: "up"
      }, 
      Name: "minecraft:jigsaw"
    }, 
    {
      Properties: {
        facing: "west"
      }, 
      Name: "minecraft:jigsaw"
    }, 
    {
      Properties: {
        facing: "east"
      }, 
      Name: "minecraft:jigsaw"
    }, 
    {
      Properties: {
        attachment: "ceiling", 
        facing: "east"
      }, 
      Name: "minecraft:bell"
    }, 
    {
      Properties: {
        facing: "south"
      }, 
      Name: "minecraft:jigsaw"
    }, 
    {
      Name: "minecraft:grass_path"
    }, 
    {
      Properties: {
        hanging: "true"
      }, 
      Name: "minecraft:lantern"
    }, 
    {
      Properties: {
        east: "false", 
        waterlogged: "false", 
        south: "true", 
        north: "false", 
        west: "false"
      }, 
      Name: "minecraft:spruce_fence"
    }, 
    {
      Properties: {
        east: "false", 
        waterlogged: "false", 
        south: "false", 
        north: "false", 
        west: "false"
      }, 
      Name: "minecraft:spruce_fence"
    }, 
    {
      Properties: {
        east: "true", 
        waterlogged: "false", 
        south: "false", 
        north: "false", 
        west: "false"
      }, 
      Name: "minecraft:spruce_fence"
    }, 
    {
      Properties: {
        east: "false", 
        waterlogged: "false", 
        south: "false", 
        north: "false", 
        west: "true"
      }, 
      Name: "minecraft:spruce_fence"
    }, 
    {
      Properties: {
        east: "false", 
        waterlogged: "false", 
        south: "false", 
        north: "true", 
        west: "false"
      }, 
      Name: "minecraft:spruce_fence"
    }
  ]
}
