{
  size: [5, 10, 5], 
  entities: [], 
  blocks: [
    {
      pos: [0, 0, 1], 
      state: 0
    }, 
    {
      pos: [0, 0, 2], 
      state: 0
    }, 
    {
      pos: [0, 0, 3], 
      state: 0
    }, 
    {
      pos: [0, 0, 4], 
      state: 1
    }, 
    {
      pos: [1, 0, 0], 
      state: 0
    }, 
    {
      pos: [1, 0, 1], 
      state: 0
    }, 
    {
      pos: [1, 0, 2], 
      state: 0
    }, 
    {
      pos: [1, 0, 3], 
      state: 0
    }, 
    {
      pos: [1, 0, 4], 
      state: 1
    }, 
    {
      pos: [2, 0, 0], 
      state: 1
    }, 
    {
      pos: [2, 0, 2], 
      state: 1
    }, 
    {
      pos: [2, 0, 3], 
      state: 1
    }, 
    {
      pos: [2, 0, 4], 
      state: 1
    }, 
    {
      pos: [3, 0, 0], 
      state: 1
    }, 
    {
      pos: [3, 0, 1], 
      state: 1
    }, 
    {
      pos: [3, 0, 2], 
      state: 1
    }, 
    {
      pos: [3, 0, 3], 
      state: 1
    }, 
    {
      pos: [4, 0, 2], 
      state: 1
    }, 
    {
      pos: [4, 0, 3], 
      state: 1
    }, 
    {
      pos: [0, 1, 1], 
      state: 0
    }, 
    {
      pos: [0, 1, 2], 
      state: 0
    }, 
    {
      pos: [0, 1, 3], 
      state: 0
    }, 
    {
      pos: [0, 1, 4], 
      state: 0
    }, 
    {
      pos: [1, 1, 1], 
      state: 0
    }, 
    {
      pos: [1, 1, 2], 
      state: 0
    }, 
    {
      pos: [1, 1, 3], 
      state: 0
    }, 
    {
      pos: [1, 1, 4], 
      state: 0
    }, 
    {
      pos: [2, 1, 0], 
      state: 1
    }, 
    {
      pos: [2, 1, 2], 
      state: 0
    }, 
    {
      pos: [2, 1, 3], 
      state: 0
    }, 
    {
      pos: [2, 1, 4], 
      state: 1
    }, 
    {
      pos: [3, 1, 0], 
      state: 1
    }, 
    {
      pos: [3, 1, 1], 
      state: 0
    }, 
    {
      pos: [3, 1, 2], 
      state: 0
    }, 
    {
      pos: [3, 1, 3], 
      state: 0
    }, 
    {
      pos: [3, 1, 4], 
      state: 1
    }, 
    {
      pos: [4, 1, 0], 
      state: 1
    }, 
    {
      pos: [4, 1, 1], 
      state: 1
    }, 
    {
      pos: [4, 1, 2], 
      state: 1
    }, 
    {
      pos: [4, 1, 3], 
      state: 1
    }, 
    {
      pos: [0, 2, 3], 
      state: 0
    }, 
    {
      pos: [0, 2, 4], 
      state: 1
    }, 
    {
      pos: [1, 2, 2], 
      state: 0
    }, 
    {
      pos: [1, 2, 3], 
      state: 0
    }, 
    {
      pos: [1, 2, 4], 
      state: 0
    }, 
    {
      pos: [2, 2, 0], 
      state: 1
    }, 
    {
      pos: [2, 2, 1], 
      state: 0
    }, 
    {
      pos: [2, 2, 2], 
      state: 0
    }, 
    {
      pos: [2, 2, 3], 
      state: 0
    }, 
    {
      pos: [2, 2, 4], 
      state: 1
    }, 
    {
      pos: [3, 2, 0], 
      state: 1
    }, 
    {
      pos: [3, 2, 1], 
      state: 0
    }, 
    {
      pos: [3, 2, 2], 
      state: 0
    }, 
    {
      pos: [3, 2, 3], 
      state: 0
    }, 
    {
      pos: [3, 2, 4], 
      state: 1
    }, 
    {
      pos: [4, 2, 0], 
      state: 1
    }, 
    {
      pos: [4, 2, 1], 
      state: 1
    }, 
    {
      pos: [4, 2, 2], 
      state: 1
    }, 
    {
      pos: [4, 2, 3], 
      state: 1
    }, 
    {
      pos: [4, 2, 4], 
      state: 1
    }, 
    {
      pos: [0, 3, 0], 
      state: 1
    }, 
    {
      pos: [0, 3, 4], 
      state: 1
    }, 
    {
      pos: [1, 3, 0], 
      state: 1
    }, 
    {
      pos: [1, 3, 4], 
      state: 1
    }, 
    {
      pos: [2, 3, 0], 
      state: 0
    }, 
    {
      pos: [2, 3, 1], 
      state: 0
    }, 
    {
      pos: [2, 3, 2], 
      state: 0
    }, 
    {
      pos: [2, 3, 4], 
      state: 1
    }, 
    {
      pos: [3, 3, 0], 
      state: 0
    }, 
    {
      pos: [3, 3, 1], 
      state: 0
    }, 
    {
      pos: [3, 3, 2], 
      state: 0
    }, 
    {
      pos: [3, 3, 3], 
      state: 0
    }, 
    {
      pos: [3, 3, 4], 
      state: 1
    }, 
    {
      pos: [4, 3, 0], 
      state: 0
    }, 
    {
      pos: [4, 3, 1], 
      state: 0
    }, 
    {
      pos: [4, 3, 2], 
      state: 1
    }, 
    {
      pos: [4, 3, 3], 
      state: 1
    }, 
    {
      pos: [4, 3, 4], 
      state: 1
    }, 
    {
      pos: [0, 4, 0], 
      state: 1
    }, 
    {
      pos: [0, 4, 1], 
      state: 1
    }, 
    {
      pos: [0, 4, 2], 
      state: 1
    }, 
    {
      pos: [0, 4, 3], 
      state: 1
    }, 
    {
      pos: [0, 4, 4], 
      state: 1
    }, 
    {
      pos: [1, 4, 0], 
      state: 1
    }, 
    {
      pos: [1, 4, 1], 
      state: 1
    }, 
    {
      pos: [1, 4, 3], 
      state: 1
    }, 
    {
      pos: [1, 4, 4], 
      state: 1
    }, 
    {
      pos: [2, 4, 0], 
      state: 0
    }, 
    {
      pos: [2, 4, 1], 
      state: 0
    }, 
    {
      pos: [2, 4, 3], 
      state: 0
    }, 
    {
      pos: [2, 4, 4], 
      state: 1
    }, 
    {
      pos: [3, 4, 0], 
      state: 0
    }, 
    {
      pos: [3, 4, 1], 
      state: 0
    }, 
    {
      pos: [3, 4, 2], 
      state: 0
    }, 
    {
      pos: [3, 4, 3], 
      state: 1
    }, 
    {
      pos: [3, 4, 4], 
      state: 1
    }, 
    {
      pos: [4, 4, 0], 
      state: 0
    }, 
    {
      pos: [4, 4, 1], 
      state: 0
    }, 
    {
      pos: [4, 4, 2], 
      state: 0
    }, 
    {
      pos: [4, 4, 3], 
      state: 0
    }, 
    {
      pos: [4, 4, 4], 
      state: 1
    }, 
    {
      pos: [0, 5, 0], 
      state: 1
    }, 
    {
      pos: [0, 5, 1], 
      state: 1
    }, 
    {
      pos: [0, 5, 3], 
      state: 0
    }, 
    {
      pos: [0, 5, 4], 
      state: 1
    }, 
    {
      pos: [1, 5, 0], 
      state: 0
    }, 
    {
      pos: [1, 5, 1], 
      state: 0
    }, 
    {
      pos: [1, 5, 2], 
      state: 0
    }, 
    {
      pos: [1, 5, 3], 
      state: 0
    }, 
    {
      pos: [1, 5, 4], 
      state: 1
    }, 
    {
      pos: [2, 5, 0], 
      state: 0
    }, 
    {
      pos: [2, 5, 1], 
      state: 0
    }, 
    {
      pos: [2, 5, 2], 
      state: 0
    }, 
    {
      pos: [2, 5, 3], 
      state: 0
    }, 
    {
      pos: [2, 5, 4], 
      state: 1
    }, 
    {
      pos: [3, 5, 0], 
      state: 0
    }, 
    {
      pos: [3, 5, 1], 
      state: 0
    }, 
    {
      pos: [3, 5, 2], 
      state: 0
    }, 
    {
      pos: [3, 5, 3], 
      state: 0
    }, 
    {
      pos: [3, 5, 4], 
      state: 1
    }, 
    {
      pos: [4, 5, 0], 
      state: 0
    }, 
    {
      pos: [4, 5, 1], 
      state: 0
    }, 
    {
      pos: [4, 5, 2], 
      state: 0
    }, 
    {
      pos: [4, 5, 3], 
      state: 0
    }, 
    {
      pos: [0, 6, 0], 
      state: 1
    }, 
    {
      pos: [0, 6, 1], 
      state: 2
    }, 
    {
      pos: [0, 6, 2], 
      state: 0
    }, 
    {
      pos: [0, 6, 3], 
      state: 0
    }, 
    {
      pos: [0, 6, 4], 
      state: 1
    }, 
    {
      pos: [1, 6, 0], 
      state: 0
    }, 
    {
      pos: [1, 6, 1], 
      state: 0
    }, 
    {
      pos: [1, 6, 2], 
      state: 0
    }, 
    {
      pos: [1, 6, 3], 
      state: 0
    }, 
    {
      pos: [1, 6, 4], 
      state: 2
    }, 
    {
      pos: [2, 6, 0], 
      state: 0
    }, 
    {
      pos: [2, 6, 1], 
      state: 0
    }, 
    {
      pos: [2, 6, 2], 
      state: 0
    }, 
    {
      pos: [2, 6, 3], 
      state: 0
    }, 
    {
      pos: [2, 6, 4], 
      state: 2
    }, 
    {
      pos: [3, 6, 0], 
      state: 0
    }, 
    {
      pos: [3, 6, 1], 
      state: 0
    }, 
    {
      pos: [3, 6, 2], 
      state: 0
    }, 
    {
      pos: [3, 6, 3], 
      state: 0
    }, 
    {
      pos: [3, 6, 4], 
      state: 2
    }, 
    {
      pos: [4, 6, 0], 
      state: 0
    }, 
    {
      pos: [4, 6, 1], 
      state: 2
    }, 
    {
      pos: [4, 6, 2], 
      state: 0
    }, 
    {
      pos: [4, 6, 3], 
      state: 0
    }, 
    {
      pos: [0, 7, 0], 
      state: 1
    }, 
    {
      pos: [0, 7, 1], 
      state: 3
    }, 
    {
      pos: [0, 7, 2], 
      state: 0
    }, 
    {
      pos: [0, 7, 3], 
      state: 0
    }, 
    {
      pos: [0, 7, 4], 
      state: 1
    }, 
    {
      pos: [1, 7, 0], 
      state: 0
    }, 
    {
      pos: [1, 7, 1], 
      state: 0
    }, 
    {
      pos: [1, 7, 2], 
      state: 0
    }, 
    {
      pos: [1, 7, 3], 
      state: 0
    }, 
    {
      pos: [1, 7, 4], 
      state: 3
    }, 
    {
      pos: [2, 7, 0], 
      state: 0
    }, 
    {
      pos: [2, 7, 1], 
      state: 0
    }, 
    {
      pos: [2, 7, 2], 
      state: 0
    }, 
    {
      pos: [2, 7, 3], 
      state: 0
    }, 
    {
      pos: [2, 7, 4], 
      state: 3
    }, 
    {
      pos: [3, 7, 0], 
      state: 0
    }, 
    {
      pos: [3, 7, 1], 
      state: 0
    }, 
    {
      pos: [3, 7, 2], 
      state: 0
    }, 
    {
      pos: [3, 7, 3], 
      state: 0
    }, 
    {
      pos: [3, 7, 4], 
      state: 0
    }, 
    {
      pos: [4, 7, 0], 
      state: 1
    }, 
    {
      pos: [4, 7, 1], 
      state: 0
    }, 
    {
      pos: [4, 7, 2], 
      state: 0
    }, 
    {
      pos: [0, 8, 0], 
      state: 0
    }, 
    {
      pos: [0, 8, 1], 
      state: 3
    }, 
    {
      pos: [0, 8, 2], 
      state: 3
    }, 
    {
      pos: [0, 8, 3], 
      state: 0
    }, 
    {
      pos: [0, 8, 4], 
      state: 3
    }, 
    {
      pos: [1, 8, 0], 
      state: 0
    }, 
    {
      pos: [1, 8, 1], 
      state: 0
    }, 
    {
      pos: [1, 8, 2], 
      state: 0
    }, 
    {
      pos: [1, 8, 3], 
      state: 0
    }, 
    {
      pos: [1, 8, 4], 
      state: 3
    }, 
    {
      pos: [2, 8, 0], 
      state: 0
    }, 
    {
      pos: [2, 8, 1], 
      state: 0
    }, 
    {
      pos: [2, 8, 2], 
      state: 0
    }, 
    {
      pos: [2, 8, 3], 
      state: 0
    }, 
    {
      pos: [2, 8, 4], 
      state: 3
    }, 
    {
      pos: [3, 8, 0], 
      state: 0
    }, 
    {
      pos: [3, 8, 1], 
      state: 0
    }, 
    {
      pos: [3, 8, 2], 
      state: 0
    }, 
    {
      pos: [3, 8, 3], 
      state: 0
    }, 
    {
      pos: [3, 8, 4], 
      state: 3
    }, 
    {
      pos: [4, 8, 0], 
      state: 3
    }, 
    {
      pos: [4, 8, 1], 
      state: 0
    }, 
    {
      pos: [4, 8, 4], 
      state: 3
    }, 
    {
      pos: [0, 9, 1], 
      state: 3
    }, 
    {
      pos: [0, 9, 2], 
      state: 1
    }, 
    {
      pos: [0, 9, 3], 
      state: 3
    }, 
    {
      pos: [1, 9, 1], 
      state: 3
    }, 
    {
      pos: [1, 9, 2], 
      state: 3
    }, 
    {
      pos: [1, 9, 3], 
      state: 3
    }, 
    {
      pos: [2, 9, 1], 
      state: 3
    }, 
    {
      pos: [2, 9, 2], 
      state: 3
    }, 
    {
      pos: [2, 9, 3], 
      state: 3
    }, 
    {
      pos: [3, 9, 1], 
      state: 3
    }, 
    {
      pos: [3, 9, 2], 
      state: 3
    }, 
    {
      pos: [3, 9, 3], 
      state: 3
    }, 
    {
      pos: [2, 1, 1], 
      state: 4
    }, 
    {
      pos: [0, 2, 2], 
      state: 5
    }, 
    {
      pos: [1, 2, 1], 
      state: 5
    }, 
    {
      pos: [0, 3, 1], 
      state: 5
    }, 
    {
      pos: [0, 3, 2], 
      state: 5
    }, 
    {
      pos: [0, 3, 3], 
      state: 5
    }, 
    {
      pos: [1, 3, 1], 
      state: 5
    }, 
    {
      pos: [1, 3, 2], 
      state: 5
    }, 
    {
      pos: [2, 3, 3], 
      state: 6
    }, 
    {
      pos: [1, 4, 2], 
      state: 4
    }, 
    {
      pos: [2, 4, 2], 
      state: 4
    }, 
    {
      nbt: {
        final_state: "minecraft:dirt", 
        name: "minecraft:room", 
        pool: "minecraft:trail_ruins/buildings/grouped", 
        joint: "rollable", 
        id: "minecraft:jigsaw", 
        target: "minecraft:hall"
      }, 
      pos: [0, 5, 2], 
      state: 7
    }
  ], 
  palette: [
    {
      Name: "minecraft:gravel"
    }, 
    {
      Name: "minecraft:mud_bricks"
    }, 
    {
      Name: "minecraft:white_terracotta"
    }, 
    {
      Name: "minecraft:orange_terracotta"
    }, 
    {
      Properties: {
        waterlogged: "false", 
        type: "top"
      }, 
      Name: "minecraft:mud_brick_slab"
    }, 
    {
      Name: "minecraft:air"
    }, 
    {
      Properties: {
        waterlogged: "false", 
        facing: "north"
      }, 
      Name: "minecraft:ladder"
    }, 
    {
      Properties: {
        orientation: "west_up"
      }, 
      Name: "minecraft:jigsaw"
    }
  ]
}
