{
  size: [15, 15, 11], 
  entities: [], 
  blocks: [
    {
      pos: [5, 3, 0], 
      state: 0
    }, 
    {
      pos: [5, 3, 1], 
      state: 0
    }, 
    {
      pos: [5, 3, 2], 
      state: 0
    }, 
    {
      pos: [5, 3, 3], 
      state: 0
    }, 
    {
      pos: [5, 3, 4], 
      state: 0
    }, 
    {
      pos: [5, 3, 5], 
      state: 0
    }, 
    {
      pos: [5, 3, 6], 
      state: 0
    }, 
    {
      pos: [5, 3, 7], 
      state: 0
    }, 
    {
      pos: [5, 3, 8], 
      state: 0
    }, 
    {
      pos: [5, 3, 10], 
      state: 0
    }, 
    {
      pos: [6, 3, 0], 
      state: 0
    }, 
    {
      pos: [6, 3, 1], 
      state: 0
    }, 
    {
      pos: [6, 3, 2], 
      state: 0
    }, 
    {
      pos: [6, 3, 3], 
      state: 0
    }, 
    {
      pos: [6, 3, 4], 
      state: 0
    }, 
    {
      pos: [6, 3, 5], 
      state: 0
    }, 
    {
      pos: [6, 3, 6], 
      state: 0
    }, 
    {
      pos: [6, 3, 7], 
      state: 0
    }, 
    {
      pos: [6, 3, 8], 
      state: 0
    }, 
    {
      pos: [6, 3, 9], 
      state: 0
    }, 
    {
      pos: [6, 3, 10], 
      state: 0
    }, 
    {
      pos: [7, 3, 0], 
      state: 0
    }, 
    {
      pos: [7, 3, 1], 
      state: 0
    }, 
    {
      pos: [7, 3, 2], 
      state: 0
    }, 
    {
      pos: [7, 3, 3], 
      state: 0
    }, 
    {
      pos: [7, 3, 4], 
      state: 0
    }, 
    {
      pos: [7, 3, 5], 
      state: 0
    }, 
    {
      pos: [7, 3, 6], 
      state: 0
    }, 
    {
      pos: [7, 3, 7], 
      state: 0
    }, 
    {
      pos: [7, 3, 8], 
      state: 0
    }, 
    {
      pos: [7, 3, 9], 
      state: 0
    }, 
    {
      pos: [7, 3, 10], 
      state: 0
    }, 
    {
      pos: [8, 3, 0], 
      state: 0
    }, 
    {
      pos: [8, 3, 1], 
      state: 0
    }, 
    {
      pos: [8, 3, 2], 
      state: 0
    }, 
    {
      pos: [8, 3, 3], 
      state: 0
    }, 
    {
      pos: [8, 3, 4], 
      state: 0
    }, 
    {
      pos: [8, 3, 5], 
      state: 0
    }, 
    {
      pos: [8, 3, 6], 
      state: 0
    }, 
    {
      pos: [8, 3, 7], 
      state: 0
    }, 
    {
      pos: [8, 3, 8], 
      state: 0
    }, 
    {
      pos: [8, 3, 9], 
      state: 0
    }, 
    {
      pos: [8, 3, 10], 
      state: 0
    }, 
    {
      pos: [9, 3, 0], 
      state: 0
    }, 
    {
      pos: [9, 3, 1], 
      state: 0
    }, 
    {
      pos: [9, 3, 2], 
      state: 0
    }, 
    {
      pos: [9, 3, 3], 
      state: 0
    }, 
    {
      pos: [9, 3, 4], 
      state: 0
    }, 
    {
      pos: [9, 3, 5], 
      state: 0
    }, 
    {
      pos: [9, 3, 6], 
      state: 0
    }, 
    {
      pos: [9, 3, 7], 
      state: 0
    }, 
    {
      pos: [9, 3, 8], 
      state: 0
    }, 
    {
      pos: [9, 3, 9], 
      state: 0
    }, 
    {
      pos: [9, 3, 10], 
      state: 0
    }, 
    {
      pos: [5, 4, 0], 
      state: 0
    }, 
    {
      pos: [5, 4, 1], 
      state: 0
    }, 
    {
      pos: [5, 4, 2], 
      state: 0
    }, 
    {
      pos: [5, 4, 3], 
      state: 0
    }, 
    {
      pos: [5, 4, 4], 
      state: 0
    }, 
    {
      pos: [5, 4, 5], 
      state: 0
    }, 
    {
      pos: [5, 4, 6], 
      state: 1
    }, 
    {
      pos: [5, 4, 7], 
      state: 0
    }, 
    {
      pos: [5, 4, 8], 
      state: 0
    }, 
    {
      pos: [5, 4, 9], 
      state: 0
    }, 
    {
      pos: [5, 4, 10], 
      state: 0
    }, 
    {
      pos: [6, 4, 0], 
      state: 0
    }, 
    {
      pos: [6, 4, 1], 
      state: 0
    }, 
    {
      pos: [6, 4, 2], 
      state: 0
    }, 
    {
      pos: [6, 4, 3], 
      state: 0
    }, 
    {
      pos: [6, 4, 4], 
      state: 0
    }, 
    {
      pos: [6, 4, 5], 
      state: 1
    }, 
    {
      pos: [6, 4, 6], 
      state: 2
    }, 
    {
      pos: [6, 4, 7], 
      state: 3
    }, 
    {
      pos: [6, 4, 8], 
      state: 0
    }, 
    {
      pos: [6, 4, 9], 
      state: 0
    }, 
    {
      pos: [6, 4, 10], 
      state: 0
    }, 
    {
      pos: [7, 4, 0], 
      state: 0
    }, 
    {
      pos: [7, 4, 1], 
      state: 0
    }, 
    {
      pos: [7, 4, 2], 
      state: 0
    }, 
    {
      pos: [7, 4, 3], 
      state: 0
    }, 
    {
      pos: [7, 4, 4], 
      state: 3
    }, 
    {
      pos: [7, 4, 5], 
      state: 2
    }, 
    {
      pos: [7, 4, 6], 
      state: 0
    }, 
    {
      pos: [7, 4, 7], 
      state: 4
    }, 
    {
      pos: [7, 4, 8], 
      state: 5
    }, 
    {
      pos: [7, 4, 9], 
      state: 0
    }, 
    {
      pos: [7, 4, 10], 
      state: 0
    }, 
    {
      pos: [8, 4, 0], 
      state: 0
    }, 
    {
      pos: [8, 4, 1], 
      state: 0
    }, 
    {
      pos: [8, 4, 2], 
      state: 0
    }, 
    {
      pos: [8, 4, 3], 
      state: 0
    }, 
    {
      pos: [8, 4, 4], 
      state: 0
    }, 
    {
      pos: [8, 4, 5], 
      state: 5
    }, 
    {
      pos: [8, 4, 6], 
      state: 5
    }, 
    {
      pos: [8, 4, 7], 
      state: 3
    }, 
    {
      pos: [8, 4, 8], 
      state: 0
    }, 
    {
      pos: [8, 4, 9], 
      state: 0
    }, 
    {
      pos: [8, 4, 10], 
      state: 0
    }, 
    {
      pos: [9, 4, 0], 
      state: 0
    }, 
    {
      pos: [9, 4, 1], 
      state: 0
    }, 
    {
      pos: [9, 4, 2], 
      state: 0
    }, 
    {
      pos: [9, 4, 3], 
      state: 0
    }, 
    {
      pos: [9, 4, 4], 
      state: 0
    }, 
    {
      pos: [9, 4, 5], 
      state: 0
    }, 
    {
      pos: [9, 4, 6], 
      state: 1
    }, 
    {
      pos: [9, 4, 7], 
      state: 0
    }, 
    {
      pos: [9, 4, 8], 
      state: 0
    }, 
    {
      pos: [9, 4, 9], 
      state: 0
    }, 
    {
      pos: [9, 4, 10], 
      state: 0
    }, 
    {
      pos: [5, 5, 0], 
      state: 0
    }, 
    {
      pos: [5, 5, 1], 
      state: 0
    }, 
    {
      pos: [5, 5, 2], 
      state: 5
    }, 
    {
      pos: [5, 5, 4], 
      state: 5
    }, 
    {
      pos: [5, 5, 5], 
      state: 5
    }, 
    {
      pos: [5, 5, 6], 
      state: 5
    }, 
    {
      pos: [5, 5, 7], 
      state: 5
    }, 
    {
      pos: [5, 5, 9], 
      state: 5
    }, 
    {
      pos: [5, 5, 10], 
      state: 5
    }, 
    {
      pos: [6, 5, 0], 
      state: 5
    }, 
    {
      pos: [6, 5, 1], 
      state: 5
    }, 
    {
      pos: [6, 5, 2], 
      state: 0
    }, 
    {
      pos: [6, 5, 3], 
      state: 5
    }, 
    {
      pos: [6, 5, 4], 
      state: 5
    }, 
    {
      pos: [6, 5, 5], 
      state: 5
    }, 
    {
      pos: [6, 5, 6], 
      state: 0
    }, 
    {
      pos: [6, 5, 7], 
      state: 0
    }, 
    {
      pos: [6, 5, 8], 
      state: 5
    }, 
    {
      pos: [6, 5, 9], 
      state: 5
    }, 
    {
      pos: [6, 5, 10], 
      state: 5
    }, 
    {
      pos: [7, 5, 1], 
      state: 5
    }, 
    {
      pos: [7, 5, 2], 
      state: 5
    }, 
    {
      pos: [7, 5, 3], 
      state: 5
    }, 
    {
      pos: [7, 5, 4], 
      state: 5
    }, 
    {
      pos: [7, 5, 5], 
      state: 0
    }, 
    {
      pos: [7, 5, 7], 
      state: 5
    }, 
    {
      pos: [7, 5, 8], 
      state: 5
    }, 
    {
      pos: [7, 5, 9], 
      state: 5
    }, 
    {
      pos: [7, 5, 10], 
      state: 5
    }, 
    {
      pos: [8, 5, 0], 
      state: 5
    }, 
    {
      pos: [8, 5, 1], 
      state: 5
    }, 
    {
      pos: [8, 5, 2], 
      state: 0
    }, 
    {
      pos: [8, 5, 3], 
      state: 5
    }, 
    {
      pos: [8, 5, 4], 
      state: 5
    }, 
    {
      pos: [8, 5, 5], 
      state: 5
    }, 
    {
      pos: [8, 5, 6], 
      state: 5
    }, 
    {
      pos: [8, 5, 7], 
      state: 5
    }, 
    {
      pos: [8, 5, 8], 
      state: 5
    }, 
    {
      pos: [8, 5, 9], 
      state: 5
    }, 
    {
      pos: [8, 5, 10], 
      state: 0
    }, 
    {
      pos: [9, 5, 0], 
      state: 0
    }, 
    {
      pos: [9, 5, 1], 
      state: 0
    }, 
    {
      pos: [9, 5, 2], 
      state: 5
    }, 
    {
      pos: [9, 5, 4], 
      state: 5
    }, 
    {
      pos: [9, 5, 5], 
      state: 5
    }, 
    {
      pos: [9, 5, 6], 
      state: 5
    }, 
    {
      pos: [9, 5, 7], 
      state: 5
    }, 
    {
      pos: [9, 5, 9], 
      state: 5
    }, 
    {
      pos: [9, 5, 10], 
      state: 0
    }, 
    {
      pos: [5, 6, 0], 
      state: 6
    }, 
    {
      pos: [5, 6, 1], 
      state: 6
    }, 
    {
      pos: [5, 6, 2], 
      state: 5
    }, 
    {
      pos: [5, 6, 3], 
      state: 5
    }, 
    {
      pos: [5, 6, 4], 
      state: 5
    }, 
    {
      pos: [5, 6, 5], 
      state: 5
    }, 
    {
      pos: [5, 6, 6], 
      state: 5
    }, 
    {
      pos: [5, 6, 7], 
      state: 5
    }, 
    {
      pos: [5, 6, 8], 
      state: 5
    }, 
    {
      pos: [5, 6, 9], 
      state: 5
    }, 
    {
      pos: [5, 6, 10], 
      state: 5
    }, 
    {
      pos: [6, 6, 0], 
      state: 5
    }, 
    {
      pos: [6, 6, 1], 
      state: 5
    }, 
    {
      pos: [6, 6, 2], 
      state: 6
    }, 
    {
      pos: [6, 6, 3], 
      state: 5
    }, 
    {
      pos: [6, 6, 4], 
      state: 5
    }, 
    {
      pos: [6, 6, 5], 
      state: 5
    }, 
    {
      pos: [6, 6, 6], 
      state: 5
    }, 
    {
      pos: [6, 6, 7], 
      state: 5
    }, 
    {
      pos: [6, 6, 8], 
      state: 5
    }, 
    {
      pos: [6, 6, 9], 
      state: 5
    }, 
    {
      pos: [6, 6, 10], 
      state: 5
    }, 
    {
      pos: [7, 6, 0], 
      state: 5
    }, 
    {
      pos: [7, 6, 1], 
      state: 5
    }, 
    {
      pos: [7, 6, 2], 
      state: 5
    }, 
    {
      pos: [7, 6, 3], 
      state: 5
    }, 
    {
      pos: [7, 6, 4], 
      state: 5
    }, 
    {
      pos: [7, 6, 5], 
      state: 5
    }, 
    {
      pos: [7, 6, 6], 
      state: 5
    }, 
    {
      pos: [7, 6, 7], 
      state: 5
    }, 
    {
      pos: [7, 6, 8], 
      state: 5
    }, 
    {
      pos: [7, 6, 9], 
      state: 5
    }, 
    {
      pos: [7, 6, 10], 
      state: 5
    }, 
    {
      pos: [8, 6, 0], 
      state: 5
    }, 
    {
      pos: [8, 6, 1], 
      state: 5
    }, 
    {
      pos: [8, 6, 2], 
      state: 6
    }, 
    {
      pos: [8, 6, 3], 
      state: 5
    }, 
    {
      pos: [8, 6, 4], 
      state: 5
    }, 
    {
      pos: [8, 6, 5], 
      state: 5
    }, 
    {
      pos: [8, 6, 6], 
      state: 5
    }, 
    {
      pos: [8, 6, 7], 
      state: 5
    }, 
    {
      pos: [8, 6, 8], 
      state: 5
    }, 
    {
      pos: [8, 6, 9], 
      state: 5
    }, 
    {
      pos: [9, 6, 0], 
      state: 6
    }, 
    {
      pos: [9, 6, 1], 
      state: 6
    }, 
    {
      pos: [9, 6, 2], 
      state: 5
    }, 
    {
      pos: [9, 6, 3], 
      state: 5
    }, 
    {
      pos: [9, 6, 4], 
      state: 5
    }, 
    {
      pos: [9, 6, 5], 
      state: 5
    }, 
    {
      pos: [9, 6, 6], 
      state: 5
    }, 
    {
      pos: [9, 6, 7], 
      state: 5
    }, 
    {
      pos: [9, 6, 8], 
      state: 5
    }, 
    {
      pos: [9, 6, 9], 
      state: 5
    }, 
    {
      pos: [9, 6, 10], 
      state: 6
    }, 
    {
      pos: [5, 7, 0], 
      state: 0
    }, 
    {
      pos: [5, 7, 1], 
      state: 0
    }, 
    {
      pos: [5, 7, 3], 
      state: 5
    }, 
    {
      pos: [5, 7, 4], 
      state: 5
    }, 
    {
      pos: [5, 7, 5], 
      state: 5
    }, 
    {
      pos: [5, 7, 6], 
      state: 5
    }, 
    {
      pos: [5, 7, 7], 
      state: 5
    }, 
    {
      pos: [5, 7, 8], 
      state: 5
    }, 
    {
      pos: [5, 7, 9], 
      state: 5
    }, 
    {
      pos: [5, 7, 10], 
      state: 5
    }, 
    {
      pos: [6, 7, 0], 
      state: 5
    }, 
    {
      pos: [6, 7, 1], 
      state: 5
    }, 
    {
      pos: [6, 7, 2], 
      state: 0
    }, 
    {
      pos: [6, 7, 3], 
      state: 5
    }, 
    {
      pos: [6, 7, 4], 
      state: 5
    }, 
    {
      pos: [6, 7, 5], 
      state: 5
    }, 
    {
      pos: [6, 7, 6], 
      state: 5
    }, 
    {
      pos: [6, 7, 7], 
      state: 5
    }, 
    {
      pos: [6, 7, 8], 
      state: 5
    }, 
    {
      pos: [6, 7, 9], 
      state: 5
    }, 
    {
      pos: [6, 7, 10], 
      state: 5
    }, 
    {
      pos: [7, 7, 0], 
      state: 5
    }, 
    {
      pos: [7, 7, 1], 
      state: 5
    }, 
    {
      pos: [7, 7, 2], 
      state: 0
    }, 
    {
      pos: [7, 7, 3], 
      state: 5
    }, 
    {
      pos: [7, 7, 4], 
      state: 5
    }, 
    {
      pos: [7, 7, 5], 
      state: 5
    }, 
    {
      pos: [7, 7, 6], 
      state: 5
    }, 
    {
      pos: [7, 7, 7], 
      state: 5
    }, 
    {
      pos: [7, 7, 8], 
      state: 5
    }, 
    {
      pos: [7, 7, 9], 
      state: 5
    }, 
    {
      pos: [8, 7, 0], 
      state: 5
    }, 
    {
      pos: [8, 7, 1], 
      state: 5
    }, 
    {
      pos: [8, 7, 2], 
      state: 0
    }, 
    {
      pos: [8, 7, 3], 
      state: 5
    }, 
    {
      pos: [8, 7, 4], 
      state: 5
    }, 
    {
      pos: [8, 7, 5], 
      state: 5
    }, 
    {
      pos: [8, 7, 6], 
      state: 5
    }, 
    {
      pos: [8, 7, 7], 
      state: 5
    }, 
    {
      pos: [8, 7, 8], 
      state: 5
    }, 
    {
      pos: [8, 7, 9], 
      state: 5
    }, 
    {
      pos: [9, 7, 0], 
      state: 0
    }, 
    {
      pos: [9, 7, 1], 
      state: 0
    }, 
    {
      pos: [9, 7, 2], 
      state: 5
    }, 
    {
      pos: [9, 7, 3], 
      state: 5
    }, 
    {
      pos: [9, 7, 4], 
      state: 5
    }, 
    {
      pos: [9, 7, 5], 
      state: 5
    }, 
    {
      pos: [9, 7, 6], 
      state: 5
    }, 
    {
      pos: [9, 7, 7], 
      state: 5
    }, 
    {
      pos: [9, 7, 8], 
      state: 5
    }, 
    {
      pos: [9, 7, 9], 
      state: 5
    }, 
    {
      pos: [9, 7, 10], 
      state: 0
    }, 
    {
      pos: [5, 8, 0], 
      state: 7
    }, 
    {
      pos: [5, 8, 1], 
      state: 7
    }, 
    {
      pos: [5, 8, 2], 
      state: 7
    }, 
    {
      pos: [5, 8, 3], 
      state: 5
    }, 
    {
      pos: [5, 8, 4], 
      state: 5
    }, 
    {
      pos: [5, 8, 5], 
      state: 5
    }, 
    {
      pos: [5, 8, 6], 
      state: 5
    }, 
    {
      pos: [5, 8, 7], 
      state: 5
    }, 
    {
      pos: [5, 8, 8], 
      state: 5
    }, 
    {
      pos: [5, 8, 9], 
      state: 5
    }, 
    {
      pos: [6, 8, 0], 
      state: 7
    }, 
    {
      pos: [6, 8, 1], 
      state: 7
    }, 
    {
      pos: [6, 8, 2], 
      state: 7
    }, 
    {
      pos: [6, 8, 3], 
      state: 5
    }, 
    {
      pos: [6, 8, 4], 
      state: 5
    }, 
    {
      pos: [6, 8, 5], 
      state: 5
    }, 
    {
      pos: [6, 8, 6], 
      state: 5
    }, 
    {
      pos: [6, 8, 7], 
      state: 5
    }, 
    {
      pos: [6, 8, 8], 
      state: 5
    }, 
    {
      pos: [6, 8, 9], 
      state: 5
    }, 
    {
      pos: [7, 8, 0], 
      state: 7
    }, 
    {
      pos: [7, 8, 1], 
      state: 7
    }, 
    {
      pos: [7, 8, 2], 
      state: 7
    }, 
    {
      pos: [7, 8, 3], 
      state: 5
    }, 
    {
      pos: [7, 8, 4], 
      state: 5
    }, 
    {
      pos: [7, 8, 5], 
      state: 5
    }, 
    {
      pos: [7, 8, 6], 
      state: 5
    }, 
    {
      pos: [7, 8, 7], 
      state: 5
    }, 
    {
      pos: [7, 8, 8], 
      state: 5
    }, 
    {
      pos: [7, 8, 9], 
      state: 5
    }, 
    {
      pos: [8, 8, 0], 
      state: 7
    }, 
    {
      pos: [8, 8, 1], 
      state: 7
    }, 
    {
      pos: [8, 8, 2], 
      state: 7
    }, 
    {
      pos: [8, 8, 3], 
      state: 5
    }, 
    {
      pos: [8, 8, 4], 
      state: 5
    }, 
    {
      pos: [8, 8, 5], 
      state: 5
    }, 
    {
      pos: [8, 8, 6], 
      state: 5
    }, 
    {
      pos: [8, 8, 7], 
      state: 5
    }, 
    {
      pos: [8, 8, 8], 
      state: 5
    }, 
    {
      pos: [8, 8, 9], 
      state: 5
    }, 
    {
      pos: [8, 8, 10], 
      state: 7
    }, 
    {
      pos: [9, 8, 0], 
      state: 7
    }, 
    {
      pos: [9, 8, 1], 
      state: 7
    }, 
    {
      pos: [9, 8, 2], 
      state: 7
    }, 
    {
      pos: [9, 8, 3], 
      state: 5
    }, 
    {
      pos: [9, 8, 4], 
      state: 5
    }, 
    {
      pos: [9, 8, 5], 
      state: 5
    }, 
    {
      pos: [9, 8, 6], 
      state: 5
    }, 
    {
      pos: [9, 8, 7], 
      state: 5
    }, 
    {
      pos: [9, 8, 8], 
      state: 5
    }, 
    {
      pos: [9, 8, 9], 
      state: 5
    }, 
    {
      pos: [9, 8, 10], 
      state: 7
    }, 
    {
      pos: [5, 9, 1], 
      state: 7
    }, 
    {
      pos: [5, 9, 2], 
      state: 7
    }, 
    {
      pos: [5, 9, 3], 
      state: 0
    }, 
    {
      pos: [5, 9, 4], 
      state: 7
    }, 
    {
      pos: [5, 9, 5], 
      state: 7
    }, 
    {
      pos: [5, 9, 6], 
      state: 7
    }, 
    {
      pos: [5, 9, 7], 
      state: 7
    }, 
    {
      pos: [5, 9, 8], 
      state: 0
    }, 
    {
      pos: [5, 9, 9], 
      state: 7
    }, 
    {
      pos: [6, 9, 1], 
      state: 7
    }, 
    {
      pos: [6, 9, 2], 
      state: 0
    }, 
    {
      pos: [6, 9, 3], 
      state: 0
    }, 
    {
      pos: [6, 9, 4], 
      state: 5
    }, 
    {
      pos: [6, 9, 5], 
      state: 5
    }, 
    {
      pos: [6, 9, 7], 
      state: 0
    }, 
    {
      pos: [6, 9, 8], 
      state: 0
    }, 
    {
      pos: [6, 9, 9], 
      state: 7
    }, 
    {
      pos: [7, 9, 1], 
      state: 7
    }, 
    {
      pos: [7, 9, 2], 
      state: 0
    }, 
    {
      pos: [7, 9, 3], 
      state: 0
    }, 
    {
      pos: [7, 9, 4], 
      state: 0
    }, 
    {
      pos: [7, 9, 5], 
      state: 5
    }, 
    {
      pos: [7, 9, 6], 
      state: 5
    }, 
    {
      pos: [7, 9, 7], 
      state: 0
    }, 
    {
      pos: [7, 9, 8], 
      state: 0
    }, 
    {
      pos: [7, 9, 9], 
      state: 7
    }, 
    {
      pos: [8, 9, 1], 
      state: 7
    }, 
    {
      pos: [8, 9, 2], 
      state: 0
    }, 
    {
      pos: [8, 9, 3], 
      state: 0
    }, 
    {
      pos: [8, 9, 4], 
      state: 0
    }, 
    {
      pos: [8, 9, 5], 
      state: 5
    }, 
    {
      pos: [8, 9, 6], 
      state: 5
    }, 
    {
      pos: [8, 9, 7], 
      state: 0
    }, 
    {
      pos: [8, 9, 8], 
      state: 0
    }, 
    {
      pos: [8, 9, 9], 
      state: 7
    }, 
    {
      pos: [9, 9, 1], 
      state: 7
    }, 
    {
      pos: [9, 9, 2], 
      state: 7
    }, 
    {
      pos: [9, 9, 3], 
      state: 0
    }, 
    {
      pos: [9, 9, 4], 
      state: 7
    }, 
    {
      pos: [9, 9, 5], 
      state: 7
    }, 
    {
      pos: [9, 9, 6], 
      state: 7
    }, 
    {
      pos: [9, 9, 7], 
      state: 7
    }, 
    {
      pos: [9, 9, 8], 
      state: 0
    }, 
    {
      pos: [9, 9, 9], 
      state: 7
    }, 
    {
      pos: [7, 5, 6], 
      state: 8
    }, 
    {
      nbt: {
        final_state: "minecraft:dirt", 
        name: "minecraft:hall", 
        pool: "minecraft:trail_ruins/buildings/grouped", 
        joint: "rollable", 
        id: "minecraft:jigsaw", 
        target: "minecraft:room"
      }, 
      pos: [5, 5, 3], 
      state: 9
    }, 
    {
      nbt: {
        final_state: "minecraft:dirt", 
        name: "minecraft:hall", 
        pool: "minecraft:trail_ruins/buildings/grouped", 
        joint: "rollable", 
        id: "minecraft:jigsaw", 
        target: "minecraft:room"
      }, 
      pos: [5, 5, 8], 
      state: 9
    }, 
    {
      nbt: {
        final_state: "minecraft:dirt", 
        name: "minecraft:building_anchor", 
        pool: "minecraft:trail_ruins/roads", 
        joint: "rollable", 
        id: "minecraft:jigsaw", 
        target: "minecraft:road_anchor"
      }, 
      pos: [7, 5, 0], 
      state: 10
    }, 
    {
      nbt: {
        final_state: "minecraft:dirt", 
        name: "minecraft:hall", 
        pool: "minecraft:trail_ruins/buildings/grouped", 
        joint: "rollable", 
        id: "minecraft:jigsaw", 
        target: "minecraft:room"
      }, 
      pos: [9, 5, 3], 
      state: 11
    }, 
    {
      nbt: {
        final_state: "minecraft:dirt", 
        name: "minecraft:hall", 
        pool: "minecraft:trail_ruins/buildings/grouped", 
        joint: "rollable", 
        id: "minecraft:jigsaw", 
        target: "minecraft:room"
      }, 
      pos: [9, 5, 8], 
      state: 11
    }
  ], 
  palette: [
    {
      Name: "minecraft:mud_bricks"
    }, 
    {
      Properties: {
        facing: "south"
      }, 
      Name: "minecraft:yellow_glazed_terracotta"
    }, 
    {
      Properties: {
        facing: "west"
      }, 
      Name: "minecraft:yellow_glazed_terracotta"
    }, 
    {
      Properties: {
        facing: "north"
      }, 
      Name: "minecraft:yellow_glazed_terracotta"
    }, 
    {
      Properties: {
        facing: "east"
      }, 
      Name: "minecraft:yellow_glazed_terracotta"
    }, 
    {
      Name: "minecraft:gravel"
    }, 
    {
      Name: "minecraft:red_terracotta"
    }, 
    {
      Name: "minecraft:blue_terracotta"
    }, 
    {
      Properties: {
        facing: "west"
      }, 
      Name: "minecraft:damaged_anvil"
    }, 
    {
      Properties: {
        orientation: "west_up"
      }, 
      Name: "minecraft:jigsaw"
    }, 
    {
      Properties: {
        orientation: "north_up"
      }, 
      Name: "minecraft:jigsaw"
    }, 
    {
      Properties: {
        orientation: "east_up"
      }, 
      Name: "minecraft:jigsaw"
    }
  ]
}
