{
  size: [7, 7, 7], 
  entities: [], 
  blocks: [
    {
      pos: [0, 0, 2], 
      state: 0
    }, 
    {
      pos: [0, 0, 3], 
      state: 0
    }, 
    {
      pos: [0, 0, 4], 
      state: 0
    }, 
    {
      pos: [0, 0, 5], 
      state: 1
    }, 
    {
      pos: [1, 0, 1], 
      state: 0
    }, 
    {
      pos: [1, 0, 2], 
      state: 0
    }, 
    {
      pos: [1, 0, 3], 
      state: 0
    }, 
    {
      pos: [1, 0, 4], 
      state: 0
    }, 
    {
      pos: [1, 0, 5], 
      state: 0
    }, 
    {
      pos: [1, 0, 6], 
      state: 1
    }, 
    {
      pos: [2, 0, 0], 
      state: 0
    }, 
    {
      pos: [2, 0, 1], 
      state: 0
    }, 
    {
      pos: [2, 0, 2], 
      state: 1
    }, 
    {
      pos: [2, 0, 3], 
      state: 1
    }, 
    {
      pos: [2, 0, 4], 
      state: 1
    }, 
    {
      pos: [2, 0, 5], 
      state: 0
    }, 
    {
      pos: [2, 0, 6], 
      state: 0
    }, 
    {
      pos: [3, 0, 0], 
      state: 0
    }, 
    {
      pos: [3, 0, 1], 
      state: 0
    }, 
    {
      pos: [3, 0, 2], 
      state: 1
    }, 
    {
      pos: [3, 0, 3], 
      state: 1
    }, 
    {
      pos: [3, 0, 4], 
      state: 1
    }, 
    {
      pos: [3, 0, 5], 
      state: 0
    }, 
    {
      pos: [3, 0, 6], 
      state: 0
    }, 
    {
      pos: [4, 0, 0], 
      state: 0
    }, 
    {
      pos: [4, 0, 1], 
      state: 0
    }, 
    {
      pos: [4, 0, 2], 
      state: 0
    }, 
    {
      pos: [4, 0, 3], 
      state: 0
    }, 
    {
      pos: [4, 0, 4], 
      state: 1
    }, 
    {
      pos: [4, 0, 5], 
      state: 0
    }, 
    {
      pos: [4, 0, 6], 
      state: 0
    }, 
    {
      pos: [5, 0, 1], 
      state: 0
    }, 
    {
      pos: [5, 0, 2], 
      state: 0
    }, 
    {
      pos: [5, 0, 3], 
      state: 0
    }, 
    {
      pos: [5, 0, 4], 
      state: 0
    }, 
    {
      pos: [5, 0, 5], 
      state: 0
    }, 
    {
      pos: [5, 0, 6], 
      state: 1
    }, 
    {
      pos: [6, 0, 2], 
      state: 0
    }, 
    {
      pos: [6, 0, 3], 
      state: 0
    }, 
    {
      pos: [6, 0, 4], 
      state: 0
    }, 
    {
      pos: [0, 1, 2], 
      state: 0
    }, 
    {
      pos: [0, 1, 3], 
      state: 0
    }, 
    {
      pos: [0, 1, 4], 
      state: 0
    }, 
    {
      pos: [0, 1, 5], 
      state: 1
    }, 
    {
      pos: [1, 1, 1], 
      state: 0
    }, 
    {
      pos: [1, 1, 2], 
      state: 1
    }, 
    {
      pos: [1, 1, 3], 
      state: 1
    }, 
    {
      pos: [1, 1, 4], 
      state: 1
    }, 
    {
      pos: [1, 1, 5], 
      state: 1
    }, 
    {
      pos: [1, 1, 6], 
      state: 1
    }, 
    {
      pos: [2, 1, 0], 
      state: 0
    }, 
    {
      pos: [2, 1, 1], 
      state: 1
    }, 
    {
      pos: [2, 1, 2], 
      state: 1
    }, 
    {
      pos: [2, 1, 3], 
      state: 1
    }, 
    {
      pos: [2, 1, 4], 
      state: 1
    }, 
    {
      pos: [2, 1, 5], 
      state: 1
    }, 
    {
      pos: [2, 1, 6], 
      state: 1
    }, 
    {
      pos: [3, 1, 0], 
      state: 0
    }, 
    {
      pos: [3, 1, 1], 
      state: 1
    }, 
    {
      pos: [3, 1, 2], 
      state: 1
    }, 
    {
      pos: [3, 1, 3], 
      state: 1
    }, 
    {
      pos: [3, 1, 4], 
      state: 1
    }, 
    {
      pos: [3, 1, 5], 
      state: 1
    }, 
    {
      pos: [3, 1, 6], 
      state: 1
    }, 
    {
      pos: [4, 1, 0], 
      state: 0
    }, 
    {
      pos: [4, 1, 1], 
      state: 1
    }, 
    {
      pos: [4, 1, 2], 
      state: 1
    }, 
    {
      pos: [4, 1, 3], 
      state: 1
    }, 
    {
      pos: [4, 1, 4], 
      state: 1
    }, 
    {
      pos: [4, 1, 5], 
      state: 1
    }, 
    {
      pos: [4, 1, 6], 
      state: 1
    }, 
    {
      pos: [5, 1, 1], 
      state: 1
    }, 
    {
      pos: [5, 1, 2], 
      state: 1
    }, 
    {
      pos: [5, 1, 3], 
      state: 1
    }, 
    {
      pos: [5, 1, 4], 
      state: 1
    }, 
    {
      pos: [5, 1, 5], 
      state: 1
    }, 
    {
      pos: [6, 1, 2], 
      state: 0
    }, 
    {
      pos: [6, 1, 3], 
      state: 2
    }, 
    {
      pos: [6, 1, 4], 
      state: 0
    }, 
    {
      pos: [0, 2, 2], 
      state: 0
    }, 
    {
      pos: [0, 2, 3], 
      state: 1
    }, 
    {
      pos: [0, 2, 4], 
      state: 1
    }, 
    {
      pos: [1, 2, 1], 
      state: 0
    }, 
    {
      pos: [1, 2, 2], 
      state: 1
    }, 
    {
      pos: [1, 2, 3], 
      state: 1
    }, 
    {
      pos: [1, 2, 4], 
      state: 1
    }, 
    {
      pos: [1, 2, 5], 
      state: 1
    }, 
    {
      pos: [1, 2, 6], 
      state: 1
    }, 
    {
      pos: [2, 2, 0], 
      state: 0
    }, 
    {
      pos: [2, 2, 1], 
      state: 1
    }, 
    {
      pos: [2, 2, 2], 
      state: 1
    }, 
    {
      pos: [2, 2, 3], 
      state: 1
    }, 
    {
      pos: [2, 2, 4], 
      state: 1
    }, 
    {
      pos: [2, 2, 5], 
      state: 1
    }, 
    {
      pos: [2, 2, 6], 
      state: 1
    }, 
    {
      pos: [3, 2, 0], 
      state: 0
    }, 
    {
      pos: [3, 2, 1], 
      state: 1
    }, 
    {
      pos: [3, 2, 3], 
      state: 1
    }, 
    {
      pos: [3, 2, 5], 
      state: 1
    }, 
    {
      pos: [4, 2, 0], 
      state: 0
    }, 
    {
      pos: [4, 2, 1], 
      state: 1
    }, 
    {
      pos: [4, 2, 2], 
      state: 1
    }, 
    {
      pos: [4, 2, 3], 
      state: 1
    }, 
    {
      pos: [4, 2, 4], 
      state: 1
    }, 
    {
      pos: [4, 2, 5], 
      state: 1
    }, 
    {
      pos: [4, 2, 6], 
      state: 1
    }, 
    {
      pos: [5, 2, 1], 
      state: 1
    }, 
    {
      pos: [5, 2, 2], 
      state: 1
    }, 
    {
      pos: [5, 2, 3], 
      state: 1
    }, 
    {
      pos: [5, 2, 4], 
      state: 1
    }, 
    {
      pos: [5, 2, 5], 
      state: 1
    }, 
    {
      pos: [6, 2, 2], 
      state: 0
    }, 
    {
      pos: [6, 2, 3], 
      state: 0
    }, 
    {
      pos: [6, 2, 4], 
      state: 0
    }, 
    {
      pos: [0, 3, 2], 
      state: 1
    }, 
    {
      pos: [0, 3, 3], 
      state: 1
    }, 
    {
      pos: [0, 3, 4], 
      state: 1
    }, 
    {
      pos: [1, 3, 1], 
      state: 1
    }, 
    {
      pos: [1, 3, 2], 
      state: 1
    }, 
    {
      pos: [1, 3, 3], 
      state: 1
    }, 
    {
      pos: [1, 3, 4], 
      state: 1
    }, 
    {
      pos: [1, 3, 5], 
      state: 1
    }, 
    {
      pos: [2, 3, 0], 
      state: 2
    }, 
    {
      pos: [2, 3, 1], 
      state: 1
    }, 
    {
      pos: [2, 3, 2], 
      state: 1
    }, 
    {
      pos: [2, 3, 3], 
      state: 1
    }, 
    {
      pos: [2, 3, 4], 
      state: 1
    }, 
    {
      pos: [2, 3, 5], 
      state: 1
    }, 
    {
      pos: [2, 3, 6], 
      state: 1
    }, 
    {
      pos: [3, 3, 0], 
      state: 2
    }, 
    {
      pos: [3, 3, 1], 
      state: 1
    }, 
    {
      pos: [3, 3, 5], 
      state: 1
    }, 
    {
      pos: [3, 3, 6], 
      state: 1
    }, 
    {
      pos: [4, 3, 0], 
      state: 2
    }, 
    {
      pos: [4, 3, 1], 
      state: 1
    }, 
    {
      pos: [4, 3, 2], 
      state: 1
    }, 
    {
      pos: [4, 3, 3], 
      state: 1
    }, 
    {
      pos: [4, 3, 5], 
      state: 1
    }, 
    {
      pos: [4, 3, 6], 
      state: 1
    }, 
    {
      pos: [5, 3, 1], 
      state: 1
    }, 
    {
      pos: [5, 3, 2], 
      state: 1
    }, 
    {
      pos: [5, 3, 3], 
      state: 1
    }, 
    {
      pos: [5, 3, 4], 
      state: 1
    }, 
    {
      pos: [5, 3, 5], 
      state: 1
    }, 
    {
      pos: [6, 3, 2], 
      state: 2
    }, 
    {
      pos: [6, 3, 3], 
      state: 2
    }, 
    {
      pos: [6, 3, 4], 
      state: 2
    }, 
    {
      pos: [0, 4, 2], 
      state: 1
    }, 
    {
      pos: [0, 4, 3], 
      state: 1
    }, 
    {
      pos: [0, 4, 4], 
      state: 1
    }, 
    {
      pos: [1, 4, 1], 
      state: 1
    }, 
    {
      pos: [1, 4, 2], 
      state: 1
    }, 
    {
      pos: [1, 4, 3], 
      state: 1
    }, 
    {
      pos: [1, 4, 4], 
      state: 1
    }, 
    {
      pos: [1, 4, 5], 
      state: 1
    }, 
    {
      pos: [2, 4, 0], 
      state: 1
    }, 
    {
      pos: [2, 4, 1], 
      state: 1
    }, 
    {
      pos: [2, 4, 2], 
      state: 1
    }, 
    {
      pos: [2, 4, 3], 
      state: 1
    }, 
    {
      pos: [2, 4, 5], 
      state: 1
    }, 
    {
      pos: [2, 4, 6], 
      state: 3
    }, 
    {
      pos: [3, 4, 0], 
      state: 3
    }, 
    {
      pos: [3, 4, 1], 
      state: 1
    }, 
    {
      pos: [3, 4, 5], 
      state: 1
    }, 
    {
      pos: [3, 4, 6], 
      state: 1
    }, 
    {
      pos: [4, 4, 0], 
      state: 1
    }, 
    {
      pos: [4, 4, 1], 
      state: 1
    }, 
    {
      pos: [4, 4, 2], 
      state: 1
    }, 
    {
      pos: [4, 4, 3], 
      state: 1
    }, 
    {
      pos: [4, 4, 5], 
      state: 1
    }, 
    {
      pos: [4, 4, 6], 
      state: 1
    }, 
    {
      pos: [5, 4, 1], 
      state: 1
    }, 
    {
      pos: [5, 4, 2], 
      state: 1
    }, 
    {
      pos: [5, 4, 3], 
      state: 1
    }, 
    {
      pos: [5, 4, 4], 
      state: 1
    }, 
    {
      pos: [5, 4, 5], 
      state: 1
    }, 
    {
      pos: [6, 4, 2], 
      state: 1
    }, 
    {
      pos: [6, 4, 3], 
      state: 3
    }, 
    {
      pos: [6, 4, 4], 
      state: 3
    }, 
    {
      pos: [0, 5, 2], 
      state: 1
    }, 
    {
      pos: [0, 5, 4], 
      state: 1
    }, 
    {
      pos: [1, 5, 1], 
      state: 1
    }, 
    {
      pos: [1, 5, 2], 
      state: 1
    }, 
    {
      pos: [1, 5, 3], 
      state: 1
    }, 
    {
      pos: [1, 5, 4], 
      state: 1
    }, 
    {
      pos: [1, 5, 5], 
      state: 1
    }, 
    {
      pos: [2, 5, 0], 
      state: 1
    }, 
    {
      pos: [2, 5, 1], 
      state: 1
    }, 
    {
      pos: [2, 5, 2], 
      state: 1
    }, 
    {
      pos: [2, 5, 5], 
      state: 3
    }, 
    {
      pos: [2, 5, 6], 
      state: 1
    }, 
    {
      pos: [3, 5, 0], 
      state: 1
    }, 
    {
      pos: [3, 5, 1], 
      state: 1
    }, 
    {
      pos: [3, 5, 5], 
      state: 1
    }, 
    {
      pos: [3, 5, 6], 
      state: 3
    }, 
    {
      pos: [4, 5, 1], 
      state: 1
    }, 
    {
      pos: [4, 5, 2], 
      state: 1
    }, 
    {
      pos: [4, 5, 3], 
      state: 1
    }, 
    {
      pos: [4, 5, 5], 
      state: 3
    }, 
    {
      pos: [4, 5, 6], 
      state: 1
    }, 
    {
      pos: [5, 5, 1], 
      state: 1
    }, 
    {
      pos: [5, 5, 2], 
      state: 1
    }, 
    {
      pos: [5, 5, 3], 
      state: 1
    }, 
    {
      pos: [5, 5, 4], 
      state: 3
    }, 
    {
      pos: [5, 5, 5], 
      state: 1
    }, 
    {
      pos: [6, 5, 2], 
      state: 1
    }, 
    {
      pos: [6, 5, 3], 
      state: 1
    }, 
    {
      pos: [6, 5, 4], 
      state: 1
    }, 
    {
      pos: [1, 6, 4], 
      state: 1
    }, 
    {
      pos: [3, 6, 4], 
      state: 3
    }, 
    {
      pos: [4, 6, 3], 
      state: 1
    }, 
    {
      pos: [4, 6, 4], 
      state: 3
    }, 
    {
      pos: [5, 6, 3], 
      state: 1
    }, 
    {
      nbt: {
        joint: "rollable", 
        final_state: "minecraft:dirt", 
        name: "minecraft:building_anchor", 
        pool: "minecraft:trail_ruins/roads", 
        id: "minecraft:jigsaw", 
        target: "minecraft:road_anchor"
      }, 
      pos: [3, 2, 6], 
      state: 4
    }
  ], 
  palette: [
    {
      Name: "minecraft:bricks"
    }, 
    {
      Name: "minecraft:gravel"
    }, 
    {
      Name: "minecraft:red_terracotta"
    }, 
    {
      Name: "minecraft:gray_terracotta"
    }, 
    {
      Properties: {
        orientation: "south_up"
      }, 
      Name: "minecraft:jigsaw"
    }
  ]
}
