{
  size: [9, 6, 9], 
  entities: [], 
  blocks: [
    {
      pos: [1, 0, 7], 
      state: 0
    }, 
    {
      pos: [3, 0, 4], 
      state: 0
    }, 
    {
      pos: [4, 0, 3], 
      state: 0
    }, 
    {
      pos: [4, 0, 4], 
      state: 0
    }, 
    {
      pos: [4, 0, 5], 
      state: 0
    }, 
    {
      pos: [5, 0, 4], 
      state: 0
    }, 
    {
      pos: [2, 1, 3], 
      state: 0
    }, 
    {
      pos: [2, 1, 4], 
      state: 0
    }, 
    {
      pos: [2, 1, 5], 
      state: 1
    }, 
    {
      pos: [3, 1, 2], 
      state: 0
    }, 
    {
      pos: [3, 1, 3], 
      state: 0
    }, 
    {
      pos: [3, 1, 5], 
      state: 0
    }, 
    {
      pos: [3, 1, 6], 
      state: 0
    }, 
    {
      pos: [4, 1, 2], 
      state: 0
    }, 
    {
      pos: [4, 1, 6], 
      state: 0
    }, 
    {
      pos: [5, 1, 2], 
      state: 0
    }, 
    {
      pos: [5, 1, 3], 
      state: 0
    }, 
    {
      pos: [5, 1, 5], 
      state: 0
    }, 
    {
      pos: [5, 1, 6], 
      state: 0
    }, 
    {
      pos: [6, 1, 3], 
      state: 0
    }, 
    {
      pos: [6, 1, 4], 
      state: 0
    }, 
    {
      pos: [6, 1, 5], 
      state: 0
    }, 
    {
      pos: [4, 4, 4], 
      state: 2
    }, 
    {
      pos: [0, 0, 0], 
      state: 3
    }, 
    {
      pos: [0, 0, 3], 
      state: 4
    }, 
    {
      pos: [0, 0, 4], 
      state: 4
    }, 
    {
      pos: [0, 0, 5], 
      state: 4
    }, 
    {
      pos: [1, 0, 0], 
      state: 3
    }, 
    {
      pos: [1, 0, 1], 
      state: 4
    }, 
    {
      pos: [1, 0, 2], 
      state: 4
    }, 
    {
      pos: [1, 0, 3], 
      state: 4
    }, 
    {
      pos: [1, 0, 4], 
      state: 4
    }, 
    {
      pos: [1, 0, 5], 
      state: 4
    }, 
    {
      pos: [1, 0, 6], 
      state: 4
    }, 
    {
      pos: [2, 0, 0], 
      state: 3
    }, 
    {
      pos: [2, 0, 1], 
      state: 4
    }, 
    {
      pos: [2, 0, 2], 
      state: 4
    }, 
    {
      pos: [2, 0, 3], 
      state: 4
    }, 
    {
      pos: [2, 0, 4], 
      state: 4
    }, 
    {
      pos: [2, 0, 5], 
      state: 4
    }, 
    {
      pos: [2, 0, 6], 
      state: 4
    }, 
    {
      pos: [2, 0, 7], 
      state: 4
    }, 
    {
      pos: [3, 0, 0], 
      state: 4
    }, 
    {
      pos: [3, 0, 1], 
      state: 4
    }, 
    {
      pos: [3, 0, 2], 
      state: 4
    }, 
    {
      pos: [3, 0, 3], 
      state: 4
    }, 
    {
      pos: [3, 0, 5], 
      state: 4
    }, 
    {
      pos: [3, 0, 6], 
      state: 4
    }, 
    {
      pos: [3, 0, 7], 
      state: 4
    }, 
    {
      pos: [3, 0, 8], 
      state: 4
    }, 
    {
      pos: [4, 0, 0], 
      state: 4
    }, 
    {
      pos: [4, 0, 1], 
      state: 4
    }, 
    {
      pos: [4, 0, 2], 
      state: 4
    }, 
    {
      pos: [4, 0, 6], 
      state: 4
    }, 
    {
      pos: [4, 0, 7], 
      state: 4
    }, 
    {
      pos: [4, 0, 8], 
      state: 4
    }, 
    {
      pos: [5, 0, 0], 
      state: 4
    }, 
    {
      pos: [5, 0, 1], 
      state: 4
    }, 
    {
      pos: [5, 0, 2], 
      state: 4
    }, 
    {
      pos: [5, 0, 3], 
      state: 4
    }, 
    {
      pos: [5, 0, 5], 
      state: 4
    }, 
    {
      pos: [5, 0, 6], 
      state: 4
    }, 
    {
      pos: [5, 0, 7], 
      state: 4
    }, 
    {
      pos: [5, 0, 8], 
      state: 4
    }, 
    {
      pos: [6, 0, 0], 
      state: 3
    }, 
    {
      pos: [6, 0, 1], 
      state: 4
    }, 
    {
      pos: [6, 0, 2], 
      state: 4
    }, 
    {
      pos: [6, 0, 3], 
      state: 4
    }, 
    {
      pos: [6, 0, 4], 
      state: 4
    }, 
    {
      pos: [6, 0, 5], 
      state: 4
    }, 
    {
      pos: [6, 0, 6], 
      state: 4
    }, 
    {
      pos: [6, 0, 7], 
      state: 4
    }, 
    {
      pos: [7, 0, 0], 
      state: 3
    }, 
    {
      pos: [7, 0, 1], 
      state: 4
    }, 
    {
      pos: [7, 0, 2], 
      state: 4
    }, 
    {
      pos: [7, 0, 3], 
      state: 4
    }, 
    {
      pos: [7, 0, 4], 
      state: 4
    }, 
    {
      pos: [7, 0, 5], 
      state: 4
    }, 
    {
      pos: [7, 0, 6], 
      state: 4
    }, 
    {
      pos: [7, 0, 7], 
      state: 4
    }, 
    {
      pos: [8, 0, 3], 
      state: 4
    }, 
    {
      pos: [8, 0, 4], 
      state: 4
    }, 
    {
      pos: [8, 0, 5], 
      state: 4
    }, 
    {
      pos: [0, 1, 0], 
      state: 3
    }, 
    {
      pos: [1, 1, 0], 
      state: 3
    }, 
    {
      pos: [2, 1, 0], 
      state: 3
    }, 
    {
      pos: [3, 1, 0], 
      state: 3
    }, 
    {
      pos: [3, 1, 4], 
      state: 5
    }, 
    {
      pos: [4, 1, 3], 
      state: 5
    }, 
    {
      pos: [4, 1, 4], 
      state: 5
    }, 
    {
      pos: [4, 1, 5], 
      state: 5
    }, 
    {
      pos: [5, 1, 0], 
      state: 3
    }, 
    {
      pos: [5, 1, 4], 
      state: 5
    }, 
    {
      pos: [6, 1, 0], 
      state: 3
    }, 
    {
      pos: [7, 1, 0], 
      state: 3
    }, 
    {
      pos: [8, 1, 0], 
      state: 3
    }, 
    {
      pos: [0, 2, 0], 
      state: 3
    }, 
    {
      pos: [1, 2, 0], 
      state: 3
    }, 
    {
      pos: [2, 2, 0], 
      state: 3
    }, 
    {
      pos: [2, 2, 4], 
      state: 6
    }, 
    {
      pos: [3, 2, 0], 
      state: 3
    }, 
    {
      pos: [3, 2, 3], 
      state: 7
    }, 
    {
      pos: [3, 2, 5], 
      state: 7
    }, 
    {
      pos: [4, 2, 0], 
      state: 3
    }, 
    {
      pos: [4, 2, 2], 
      state: 6
    }, 
    {
      pos: [4, 2, 6], 
      state: 6
    }, 
    {
      pos: [5, 2, 0], 
      state: 3
    }, 
    {
      pos: [5, 2, 3], 
      state: 7
    }, 
    {
      pos: [5, 2, 5], 
      state: 7
    }, 
    {
      pos: [6, 2, 0], 
      state: 3
    }, 
    {
      pos: [6, 2, 4], 
      state: 6
    }, 
    {
      pos: [7, 2, 0], 
      state: 3
    }, 
    {
      pos: [8, 2, 0], 
      state: 3
    }, 
    {
      pos: [0, 3, 0], 
      state: 3
    }, 
    {
      pos: [1, 3, 0], 
      state: 3
    }, 
    {
      pos: [2, 3, 0], 
      state: 3
    }, 
    {
      pos: [3, 3, 0], 
      state: 3
    }, 
    {
      pos: [3, 3, 3], 
      state: 7
    }, 
    {
      pos: [3, 3, 5], 
      state: 7
    }, 
    {
      pos: [4, 3, 0], 
      state: 3
    }, 
    {
      pos: [5, 3, 0], 
      state: 3
    }, 
    {
      pos: [5, 3, 3], 
      state: 7
    }, 
    {
      pos: [5, 3, 5], 
      state: 7
    }, 
    {
      pos: [6, 3, 0], 
      state: 3
    }, 
    {
      pos: [7, 3, 0], 
      state: 3
    }, 
    {
      pos: [8, 3, 0], 
      state: 3
    }, 
    {
      pos: [0, 4, 0], 
      state: 3
    }, 
    {
      pos: [1, 4, 0], 
      state: 3
    }, 
    {
      pos: [2, 4, 0], 
      state: 3
    }, 
    {
      pos: [3, 4, 0], 
      state: 3
    }, 
    {
      pos: [3, 4, 3], 
      state: 8
    }, 
    {
      pos: [3, 4, 4], 
      state: 9
    }, 
    {
      pos: [3, 4, 5], 
      state: 10
    }, 
    {
      pos: [4, 4, 0], 
      state: 3
    }, 
    {
      pos: [4, 4, 3], 
      state: 11
    }, 
    {
      pos: [4, 4, 5], 
      state: 12
    }, 
    {
      pos: [5, 4, 0], 
      state: 3
    }, 
    {
      pos: [5, 4, 3], 
      state: 13
    }, 
    {
      pos: [5, 4, 4], 
      state: 14
    }, 
    {
      pos: [5, 4, 5], 
      state: 15
    }, 
    {
      pos: [6, 4, 0], 
      state: 3
    }, 
    {
      pos: [7, 4, 0], 
      state: 3
    }, 
    {
      pos: [8, 4, 0], 
      state: 3
    }, 
    {
      pos: [0, 5, 0], 
      state: 3
    }, 
    {
      pos: [1, 5, 0], 
      state: 3
    }, 
    {
      pos: [2, 5, 0], 
      state: 3
    }, 
    {
      pos: [3, 5, 0], 
      state: 3
    }, 
    {
      pos: [4, 5, 0], 
      state: 3
    }, 
    {
      pos: [5, 5, 0], 
      state: 3
    }, 
    {
      pos: [6, 5, 0], 
      state: 3
    }, 
    {
      pos: [7, 5, 0], 
      state: 3
    }, 
    {
      pos: [8, 5, 0], 
      state: 3
    }, 
    {
      nbt: {
        joint: "rollable", 
        final_state: "minecraft:grass_block", 
        name: "minecraft:bottom", 
        pool: "minecraft:village/common/cats", 
        id: "minecraft:jigsaw", 
        target: "minecraft:bottom"
      }, 
      pos: [7, 0, 8], 
      state: 16
    }, 
    {
      nbt: {
        joint: "rollable", 
        final_state: "minecraft:grass_block", 
        name: "minecraft:bottom", 
        pool: "minecraft:village/common/cats", 
        id: "minecraft:jigsaw", 
        target: "minecraft:bottom"
      }, 
      pos: [8, 0, 0], 
      state: 16
    }, 
    {
      nbt: {
        joint: "aligned", 
        final_state: "minecraft:structure_void", 
        name: "minecraft:street", 
        pool: "minecraft:village/savanna/zombie/streets", 
        id: "minecraft:jigsaw", 
        target: "minecraft:street"
      }, 
      pos: [0, 1, 4], 
      state: 17
    }, 
    {
      nbt: {
        id: "minecraft:bell"
      }, 
      pos: [1, 1, 7], 
      state: 18
    }, 
    {
      nbt: {
        joint: "aligned", 
        final_state: "minecraft:structure_void", 
        name: "minecraft:street", 
        pool: "minecraft:village/savanna/zombie/streets", 
        id: "minecraft:jigsaw", 
        target: "minecraft:street"
      }, 
      pos: [4, 1, 0], 
      state: 19
    }, 
    {
      nbt: {
        joint: "aligned", 
        final_state: "minecraft:structure_void", 
        name: "minecraft:street", 
        pool: "minecraft:village/savanna/zombie/streets", 
        id: "minecraft:jigsaw", 
        target: "minecraft:street"
      }, 
      pos: [4, 1, 8], 
      state: 20
    }, 
    {
      nbt: {
        joint: "aligned", 
        final_state: "minecraft:structure_void", 
        name: "minecraft:street", 
        pool: "minecraft:village/savanna/zombie/streets", 
        id: "minecraft:jigsaw", 
        target: "minecraft:street"
      }, 
      pos: [8, 1, 4], 
      state: 21
    }
  ], 
  palette: [
    {
      Properties: {
        axis: "y"
      }, 
      Name: "minecraft:acacia_wood"
    }, 
    {
      Properties: {
        axis: "z"
      }, 
      Name: "minecraft:acacia_wood"
    }, 
    {
      Properties: {
        waterlogged: "false", 
        type: "double"
      }, 
      Name: "minecraft:acacia_slab"
    }, 
    {
      Name: "minecraft:air"
    }, 
    {
      Name: "minecraft:dirt_path"
    }, 
    {
      Properties: {
        level: "0"
      }, 
      Name: "minecraft:water"
    }, 
    {
      Name: "minecraft:torch"
    }, 
    {
      Properties: {
        east: "false", 
        waterlogged: "false", 
        south: "false", 
        north: "false", 
        west: "false"
      }, 
      Name: "minecraft:acacia_fence"
    }, 
    {
      Properties: {
        half: "bottom", 
        waterlogged: "false", 
        shape: "outer_right", 
        facing: "east"
      }, 
      Name: "minecraft:acacia_stairs"
    }, 
    {
      Properties: {
        half: "bottom", 
        waterlogged: "false", 
        shape: "straight", 
        facing: "east"
      }, 
      Name: "minecraft:acacia_stairs"
    }, 
    {
      Properties: {
        half: "bottom", 
        waterlogged: "false", 
        shape: "outer_left", 
        facing: "east"
      }, 
      Name: "minecraft:acacia_stairs"
    }, 
    {
      Properties: {
        half: "bottom", 
        waterlogged: "false", 
        shape: "straight", 
        facing: "south"
      }, 
      Name: "minecraft:acacia_stairs"
    }, 
    {
      Properties: {
        half: "bottom", 
        waterlogged: "false", 
        shape: "straight", 
        facing: "north"
      }, 
      Name: "minecraft:acacia_stairs"
    }, 
    {
      Properties: {
        half: "bottom", 
        waterlogged: "false", 
        shape: "outer_right", 
        facing: "south"
      }, 
      Name: "minecraft:acacia_stairs"
    }, 
    {
      Properties: {
        half: "bottom", 
        waterlogged: "false", 
        shape: "straight", 
        facing: "west"
      }, 
      Name: "minecraft:acacia_stairs"
    }, 
    {
      Properties: {
        half: "bottom", 
        waterlogged: "false", 
        shape: "outer_right", 
        facing: "west"
      }, 
      Name: "minecraft:acacia_stairs"
    }, 
    {
      Properties: {
        orientation: "up_north"
      }, 
      Name: "minecraft:jigsaw"
    }, 
    {
      Properties: {
        orientation: "west_up"
      }, 
      Name: "minecraft:jigsaw"
    }, 
    {
      Properties: {
        attachment: "floor", 
        powered: "false", 
        facing: "east"
      }, 
      Name: "minecraft:bell"
    }, 
    {
      Properties: {
        orientation: "north_up"
      }, 
      Name: "minecraft:jigsaw"
    }, 
    {
      Properties: {
        orientation: "south_up"
      }, 
      Name: "minecraft:jigsaw"
    }, 
    {
      Properties: {
        orientation: "east_up"
      }, 
      Name: "minecraft:jigsaw"
    }
  ]
}
