{
  size: [9, 6, 11], 
  entities: [], 
  blocks: [
    {
      pos: [4, 0, 3], 
      state: 0
    }, 
    {
      pos: [4, 0, 7], 
      state: 1
    }, 
    {
      pos: [3, 1, 2], 
      state: 0
    }, 
    {
      pos: [3, 1, 3], 
      state: 0
    }, 
    {
      pos: [3, 1, 4], 
      state: 0
    }, 
    {
      pos: [3, 1, 6], 
      state: 0
    }, 
    {
      pos: [3, 1, 7], 
      state: 0
    }, 
    {
      pos: [3, 1, 8], 
      state: 0
    }, 
    {
      pos: [4, 1, 2], 
      state: 1
    }, 
    {
      pos: [4, 1, 4], 
      state: 1
    }, 
    {
      pos: [4, 1, 6], 
      state: 1
    }, 
    {
      pos: [4, 1, 8], 
      state: 1
    }, 
    {
      pos: [5, 1, 2], 
      state: 0
    }, 
    {
      pos: [5, 1, 3], 
      state: 0
    }, 
    {
      pos: [5, 1, 4], 
      state: 0
    }, 
    {
      pos: [5, 1, 6], 
      state: 0
    }, 
    {
      pos: [5, 1, 7], 
      state: 0
    }, 
    {
      pos: [5, 1, 8], 
      state: 0
    }, 
    {
      pos: [4, 4, 5], 
      state: 2
    }, 
    {
      pos: [0, 0, 4], 
      state: 3
    }, 
    {
      pos: [0, 0, 5], 
      state: 3
    }, 
    {
      pos: [0, 0, 6], 
      state: 3
    }, 
    {
      pos: [1, 0, 3], 
      state: 3
    }, 
    {
      pos: [1, 0, 4], 
      state: 3
    }, 
    {
      pos: [1, 0, 5], 
      state: 3
    }, 
    {
      pos: [1, 0, 6], 
      state: 3
    }, 
    {
      pos: [1, 0, 7], 
      state: 3
    }, 
    {
      pos: [2, 0, 1], 
      state: 3
    }, 
    {
      pos: [2, 0, 2], 
      state: 3
    }, 
    {
      pos: [2, 0, 3], 
      state: 3
    }, 
    {
      pos: [2, 0, 4], 
      state: 3
    }, 
    {
      pos: [2, 0, 5], 
      state: 3
    }, 
    {
      pos: [2, 0, 6], 
      state: 3
    }, 
    {
      pos: [2, 0, 7], 
      state: 3
    }, 
    {
      pos: [2, 0, 8], 
      state: 3
    }, 
    {
      pos: [2, 0, 9], 
      state: 3
    }, 
    {
      pos: [3, 0, 0], 
      state: 3
    }, 
    {
      pos: [3, 0, 1], 
      state: 3
    }, 
    {
      pos: [3, 0, 2], 
      state: 3
    }, 
    {
      pos: [3, 0, 3], 
      state: 3
    }, 
    {
      pos: [3, 0, 4], 
      state: 3
    }, 
    {
      pos: [3, 0, 5], 
      state: 3
    }, 
    {
      pos: [3, 0, 6], 
      state: 3
    }, 
    {
      pos: [3, 0, 7], 
      state: 3
    }, 
    {
      pos: [3, 0, 8], 
      state: 3
    }, 
    {
      pos: [3, 0, 9], 
      state: 3
    }, 
    {
      pos: [3, 0, 10], 
      state: 3
    }, 
    {
      pos: [4, 0, 0], 
      state: 3
    }, 
    {
      pos: [4, 0, 1], 
      state: 3
    }, 
    {
      pos: [4, 0, 2], 
      state: 3
    }, 
    {
      pos: [4, 0, 4], 
      state: 3
    }, 
    {
      pos: [4, 0, 5], 
      state: 3
    }, 
    {
      pos: [4, 0, 6], 
      state: 3
    }, 
    {
      pos: [4, 0, 8], 
      state: 3
    }, 
    {
      pos: [4, 0, 9], 
      state: 3
    }, 
    {
      pos: [4, 0, 10], 
      state: 3
    }, 
    {
      pos: [5, 0, 0], 
      state: 3
    }, 
    {
      pos: [5, 0, 1], 
      state: 3
    }, 
    {
      pos: [5, 0, 2], 
      state: 3
    }, 
    {
      pos: [5, 0, 3], 
      state: 3
    }, 
    {
      pos: [5, 0, 4], 
      state: 3
    }, 
    {
      pos: [5, 0, 5], 
      state: 3
    }, 
    {
      pos: [5, 0, 6], 
      state: 3
    }, 
    {
      pos: [5, 0, 7], 
      state: 3
    }, 
    {
      pos: [5, 0, 8], 
      state: 3
    }, 
    {
      pos: [5, 0, 9], 
      state: 3
    }, 
    {
      pos: [5, 0, 10], 
      state: 3
    }, 
    {
      pos: [6, 0, 1], 
      state: 3
    }, 
    {
      pos: [6, 0, 2], 
      state: 3
    }, 
    {
      pos: [6, 0, 3], 
      state: 3
    }, 
    {
      pos: [6, 0, 4], 
      state: 3
    }, 
    {
      pos: [6, 0, 5], 
      state: 3
    }, 
    {
      pos: [6, 0, 6], 
      state: 3
    }, 
    {
      pos: [6, 0, 7], 
      state: 3
    }, 
    {
      pos: [6, 0, 8], 
      state: 3
    }, 
    {
      pos: [6, 0, 9], 
      state: 3
    }, 
    {
      pos: [7, 0, 3], 
      state: 3
    }, 
    {
      pos: [7, 0, 4], 
      state: 3
    }, 
    {
      pos: [7, 0, 5], 
      state: 3
    }, 
    {
      pos: [7, 0, 6], 
      state: 3
    }, 
    {
      pos: [7, 0, 7], 
      state: 3
    }, 
    {
      pos: [8, 0, 4], 
      state: 3
    }, 
    {
      pos: [8, 0, 5], 
      state: 3
    }, 
    {
      pos: [8, 0, 6], 
      state: 3
    }, 
    {
      pos: [4, 1, 3], 
      state: 4
    }, 
    {
      pos: [4, 1, 7], 
      state: 4
    }, 
    {
      pos: [3, 2, 4], 
      state: 5
    }, 
    {
      pos: [3, 2, 6], 
      state: 5
    }, 
    {
      pos: [5, 2, 4], 
      state: 5
    }, 
    {
      pos: [5, 2, 6], 
      state: 5
    }, 
    {
      pos: [3, 3, 4], 
      state: 5
    }, 
    {
      pos: [3, 3, 6], 
      state: 5
    }, 
    {
      pos: [5, 3, 4], 
      state: 5
    }, 
    {
      pos: [5, 3, 6], 
      state: 5
    }, 
    {
      pos: [3, 4, 4], 
      state: 6
    }, 
    {
      pos: [3, 4, 5], 
      state: 6
    }, 
    {
      pos: [3, 4, 6], 
      state: 6
    }, 
    {
      pos: [4, 4, 4], 
      state: 6
    }, 
    {
      pos: [4, 4, 6], 
      state: 6
    }, 
    {
      pos: [5, 4, 4], 
      state: 6
    }, 
    {
      pos: [5, 4, 5], 
      state: 6
    }, 
    {
      pos: [5, 4, 6], 
      state: 6
    }, 
    {
      pos: [4, 5, 5], 
      state: 7
    }, 
    {
      nbt: {
        joint: "rollable", 
        final_state: "minecraft:grass_block", 
        name: "minecraft:bottom", 
        pool: "minecraft:village/common/cats", 
        id: "minecraft:jigsaw", 
        target: "minecraft:bottom"
      }, 
      pos: [1, 0, 2], 
      state: 8
    }, 
    {
      nbt: {
        joint: "rollable", 
        final_state: "minecraft:grass_block", 
        name: "minecraft:bottom", 
        pool: "minecraft:village/common/cats", 
        id: "minecraft:jigsaw", 
        target: "minecraft:bottom"
      }, 
      pos: [7, 0, 1], 
      state: 8
    }, 
    {
      nbt: {
        joint: "rollable", 
        final_state: "minecraft:grass_block", 
        name: "minecraft:bottom", 
        pool: "minecraft:village/common/cats", 
        id: "minecraft:jigsaw", 
        target: "minecraft:bottom"
      }, 
      pos: [8, 0, 9], 
      state: 8
    }, 
    {
      nbt: {
        joint: "aligned", 
        final_state: "minecraft:structure_void", 
        name: "minecraft:street", 
        pool: "minecraft:village/savanna/zombie/streets", 
        id: "minecraft:jigsaw", 
        target: "minecraft:street"
      }, 
      pos: [0, 1, 5], 
      state: 9
    }, 
    {
      nbt: {
        joint: "aligned", 
        final_state: "minecraft:structure_void", 
        name: "minecraft:street", 
        pool: "minecraft:village/savanna/zombie/streets", 
        id: "minecraft:jigsaw", 
        target: "minecraft:street"
      }, 
      pos: [4, 1, 0], 
      state: 10
    }, 
    {
      nbt: {
        joint: "aligned", 
        final_state: "minecraft:structure_void", 
        name: "minecraft:street", 
        pool: "minecraft:village/savanna/zombie/streets", 
        id: "minecraft:jigsaw", 
        target: "minecraft:street"
      }, 
      pos: [4, 1, 10], 
      state: 11
    }, 
    {
      nbt: {
        joint: "aligned", 
        final_state: "minecraft:structure_void", 
        name: "minecraft:street", 
        pool: "minecraft:village/savanna/zombie/streets", 
        id: "minecraft:jigsaw", 
        target: "minecraft:street"
      }, 
      pos: [8, 1, 5], 
      state: 12
    }, 
    {
      nbt: {
        id: "minecraft:bell"
      }, 
      pos: [4, 3, 5], 
      state: 13
    }
  ], 
  palette: [
    {
      id: "minecraft:acacia_wood", 
      properties: {
        axis: "y"
      }
    }, 
    {
      id: "minecraft:acacia_wood", 
      properties: {
        axis: "x"
      }
    }, 
    {
      id: "minecraft:acacia_slab", 
      properties: {
        waterlogged: "false", 
        type: "double"
      }
    }, 
    {
      id: "minecraft:dirt_path"
    }, 
    {
      id: "minecraft:water", 
      properties: {
        level: "0"
      }
    }, 
    {
      id: "minecraft:acacia_fence", 
      properties: {
        east: "false", 
        waterlogged: "false", 
        south: "false", 
        north: "false", 
        west: "false"
      }
    }, 
    {
      id: "minecraft:acacia_slab", 
      properties: {
        waterlogged: "false", 
        type: "bottom"
      }
    }, 
    {
      id: "minecraft:torch"
    }, 
    {
      id: "minecraft:jigsaw", 
      properties: {
        orientation: "up_north"
      }
    }, 
    {
      id: "minecraft:jigsaw", 
      properties: {
        orientation: "west_up"
      }
    }, 
    {
      id: "minecraft:jigsaw", 
      properties: {
        orientation: "north_up"
      }
    }, 
    {
      id: "minecraft:jigsaw", 
      properties: {
        orientation: "south_up"
      }
    }, 
    {
      id: "minecraft:jigsaw", 
      properties: {
        orientation: "east_up"
      }
    }, 
    {
      id: "minecraft:bell", 
      properties: {
        attachment: "ceiling", 
        powered: "false", 
        facing: "east"
      }
    }
  ]
}
