{
  size: [8, 7, 9], 
  entities: [], 
  blocks: [
    {
      pos: [2, 0, 1], 
      state: 0
    }, 
    {
      pos: [3, 0, 1], 
      state: 0
    }, 
    {
      pos: [4, 0, 1], 
      state: 0
    }, 
    {
      pos: [5, 0, 1], 
      state: 0
    }, 
    {
      pos: [6, 0, 1], 
      state: 0
    }, 
    {
      pos: [2, 1, 1], 
      state: 1
    }, 
    {
      pos: [3, 1, 1], 
      state: 2
    }, 
    {
      pos: [4, 1, 1], 
      state: 2
    }, 
    {
      pos: [5, 1, 1], 
      state: 2
    }, 
    {
      pos: [6, 1, 1], 
      state: 1
    }, 
    {
      pos: [2, 2, 1], 
      state: 1
    }, 
    {
      pos: [3, 2, 1], 
      state: 2
    }, 
    {
      pos: [5, 2, 1], 
      state: 2
    }, 
    {
      pos: [6, 2, 1], 
      state: 1
    }, 
    {
      pos: [2, 3, 1], 
      state: 1
    }, 
    {
      pos: [3, 3, 1], 
      state: 2
    }, 
    {
      pos: [4, 3, 1], 
      state: 2
    }, 
    {
      pos: [5, 3, 1], 
      state: 2
    }, 
    {
      pos: [6, 3, 1], 
      state: 1
    }, 
    {
      pos: [1, 0, 2], 
      state: 3
    }, 
    {
      pos: [2, 0, 2], 
      state: 0
    }, 
    {
      pos: [3, 0, 2], 
      state: 0
    }, 
    {
      pos: [4, 0, 2], 
      state: 0
    }, 
    {
      pos: [5, 0, 2], 
      state: 0
    }, 
    {
      pos: [6, 0, 2], 
      state: 0
    }, 
    {
      pos: [2, 1, 2], 
      state: 2
    }, 
    {
      pos: [4, 1, 2], 
      state: 4
    }, 
    {
      pos: [5, 1, 2], 
      state: 4
    }, 
    {
      pos: [6, 1, 2], 
      state: 2
    }, 
    {
      pos: [2, 2, 2], 
      state: 2
    }, 
    {
      pos: [5, 2, 2], 
      state: 4
    }, 
    {
      pos: [6, 2, 2], 
      state: 2
    }, 
    {
      pos: [2, 3, 2], 
      state: 2
    }, 
    {
      pos: [5, 3, 2], 
      state: 5
    }, 
    {
      pos: [6, 3, 2], 
      state: 2
    }, 
    {
      pos: [2, 4, 2], 
      state: 6
    }, 
    {
      pos: [6, 4, 2], 
      state: 6
    }, 
    {
      pos: [1, 0, 3], 
      state: 0
    }, 
    {
      pos: [2, 0, 3], 
      state: 0
    }, 
    {
      pos: [3, 0, 3], 
      state: 0
    }, 
    {
      pos: [4, 0, 3], 
      state: 7
    }, 
    {
      pos: [5, 0, 3], 
      state: 0
    }, 
    {
      pos: [6, 0, 3], 
      state: 0
    }, 
    {
      pos: [5, 1, 3], 
      state: 4
    }, 
    {
      pos: [6, 1, 3], 
      state: 2
    }, 
    {
      pos: [2, 3, 3], 
      state: 2
    }, 
    {
      pos: [6, 3, 3], 
      state: 2
    }, 
    {
      pos: [2, 4, 3], 
      state: 6
    }, 
    {
      pos: [6, 4, 3], 
      state: 6
    }, 
    {
      pos: [2, 5, 3], 
      state: 2
    }, 
    {
      pos: [6, 5, 3], 
      state: 2
    }, 
    {
      pos: [0, 0, 4], 
      state: 0
    }, 
    {
      pos: [1, 0, 4], 
      state: 0
    }, 
    {
      pos: [2, 0, 4], 
      state: 0
    }, 
    {
      pos: [3, 0, 4], 
      state: 0
    }, 
    {
      pos: [4, 0, 4], 
      state: 7
    }, 
    {
      pos: [5, 0, 4], 
      state: 0
    }, 
    {
      pos: [6, 0, 4], 
      state: 0
    }, 
    {
      pos: [2, 1, 4], 
      state: 2
    }, 
    {
      pos: [5, 1, 4], 
      state: 5
    }, 
    {
      pos: [6, 1, 4], 
      state: 2
    }, 
    {
      pos: [2, 2, 4], 
      state: 2
    }, 
    {
      pos: [6, 2, 4], 
      state: 2
    }, 
    {
      pos: [2, 3, 4], 
      state: 2
    }, 
    {
      pos: [6, 3, 4], 
      state: 2
    }, 
    {
      pos: [2, 4, 4], 
      state: 6
    }, 
    {
      pos: [6, 4, 4], 
      state: 6
    }, 
    {
      pos: [2, 5, 4], 
      state: 2
    }, 
    {
      pos: [6, 5, 4], 
      state: 2
    }, 
    {
      pos: [1, 6, 4], 
      state: 7
    }, 
    {
      pos: [2, 6, 4], 
      state: 7
    }, 
    {
      pos: [3, 6, 4], 
      state: 7
    }, 
    {
      pos: [4, 6, 4], 
      state: 7
    }, 
    {
      pos: [5, 6, 4], 
      state: 7
    }, 
    {
      pos: [6, 6, 4], 
      state: 7
    }, 
    {
      pos: [7, 6, 4], 
      state: 7
    }, 
    {
      pos: [0, 0, 5], 
      state: 0
    }, 
    {
      pos: [1, 0, 5], 
      state: 0
    }, 
    {
      pos: [2, 0, 5], 
      state: 0
    }, 
    {
      pos: [3, 0, 5], 
      state: 0
    }, 
    {
      pos: [4, 0, 5], 
      state: 7
    }, 
    {
      pos: [5, 0, 5], 
      state: 0
    }, 
    {
      pos: [6, 0, 5], 
      state: 0
    }, 
    {
      pos: [2, 1, 5], 
      state: 2
    }, 
    {
      pos: [6, 1, 5], 
      state: 2
    }, 
    {
      pos: [2, 3, 5], 
      state: 2
    }, 
    {
      pos: [6, 3, 5], 
      state: 2
    }, 
    {
      pos: [2, 4, 5], 
      state: 6
    }, 
    {
      pos: [6, 4, 5], 
      state: 6
    }, 
    {
      pos: [2, 5, 5], 
      state: 2
    }, 
    {
      pos: [6, 5, 5], 
      state: 2
    }, 
    {
      pos: [0, 0, 6], 
      state: 0
    }, 
    {
      pos: [1, 0, 6], 
      state: 0
    }, 
    {
      pos: [2, 0, 6], 
      state: 0
    }, 
    {
      pos: [3, 0, 6], 
      state: 0
    }, 
    {
      pos: [4, 0, 6], 
      state: 0
    }, 
    {
      pos: [5, 0, 6], 
      state: 0
    }, 
    {
      pos: [6, 0, 6], 
      state: 0
    }, 
    {
      pos: [2, 1, 6], 
      state: 2
    }, 
    {
      pos: [6, 1, 6], 
      state: 2
    }, 
    {
      pos: [2, 2, 6], 
      state: 2
    }, 
    {
      pos: [6, 2, 6], 
      state: 2
    }, 
    {
      pos: [2, 3, 6], 
      state: 2
    }, 
    {
      pos: [6, 3, 6], 
      state: 2
    }, 
    {
      pos: [2, 4, 6], 
      state: 6
    }, 
    {
      pos: [6, 4, 6], 
      state: 6
    }, 
    {
      pos: [0, 0, 7], 
      state: 0
    }, 
    {
      pos: [1, 0, 7], 
      state: 0
    }, 
    {
      pos: [2, 0, 7], 
      state: 0
    }, 
    {
      pos: [3, 0, 7], 
      state: 0
    }, 
    {
      pos: [4, 0, 7], 
      state: 0
    }, 
    {
      pos: [5, 0, 7], 
      state: 0
    }, 
    {
      pos: [6, 0, 7], 
      state: 0
    }, 
    {
      pos: [2, 1, 7], 
      state: 1
    }, 
    {
      pos: [3, 1, 7], 
      state: 2
    }, 
    {
      pos: [4, 1, 7], 
      state: 2
    }, 
    {
      pos: [5, 1, 7], 
      state: 2
    }, 
    {
      pos: [6, 1, 7], 
      state: 1
    }, 
    {
      pos: [2, 2, 7], 
      state: 1
    }, 
    {
      pos: [3, 2, 7], 
      state: 2
    }, 
    {
      pos: [5, 2, 7], 
      state: 2
    }, 
    {
      pos: [6, 2, 7], 
      state: 1
    }, 
    {
      pos: [2, 3, 7], 
      state: 1
    }, 
    {
      pos: [3, 3, 7], 
      state: 2
    }, 
    {
      pos: [4, 3, 7], 
      state: 2
    }, 
    {
      pos: [5, 3, 7], 
      state: 2
    }, 
    {
      pos: [6, 3, 7], 
      state: 1
    }, 
    {
      nbt: {
        target_pool: "minecraft:village/plains/streets", 
        final_state: "minecraft:cobblestone_stairs[facing=east,half=bottom,shape=straight,waterlogged=false]", 
        id: "minecraft:jigsaw", 
        attachement_type: "minecraft:building_entrance"
      }, 
      pos: [0, 0, 3], 
      state: 8
    }, 
    {
      pos: [0, 0, 0], 
      state: 9
    }, 
    {
      pos: [1, 0, 0], 
      state: 9
    }, 
    {
      pos: [2, 0, 0], 
      state: 9
    }, 
    {
      pos: [3, 0, 0], 
      state: 9
    }, 
    {
      pos: [4, 0, 0], 
      state: 9
    }, 
    {
      pos: [5, 0, 0], 
      state: 9
    }, 
    {
      pos: [6, 0, 0], 
      state: 9
    }, 
    {
      pos: [7, 0, 0], 
      state: 9
    }, 
    {
      pos: [0, 1, 0], 
      state: 9
    }, 
    {
      pos: [1, 1, 0], 
      state: 9
    }, 
    {
      pos: [2, 1, 0], 
      state: 9
    }, 
    {
      pos: [3, 1, 0], 
      state: 9
    }, 
    {
      pos: [4, 1, 0], 
      state: 9
    }, 
    {
      pos: [5, 1, 0], 
      state: 9
    }, 
    {
      pos: [6, 1, 0], 
      state: 9
    }, 
    {
      pos: [7, 1, 0], 
      state: 9
    }, 
    {
      pos: [0, 2, 0], 
      state: 9
    }, 
    {
      pos: [1, 2, 0], 
      state: 9
    }, 
    {
      pos: [2, 2, 0], 
      state: 9
    }, 
    {
      pos: [3, 2, 0], 
      state: 9
    }, 
    {
      pos: [4, 2, 0], 
      state: 9
    }, 
    {
      pos: [5, 2, 0], 
      state: 9
    }, 
    {
      pos: [6, 2, 0], 
      state: 9
    }, 
    {
      pos: [7, 2, 0], 
      state: 9
    }, 
    {
      pos: [0, 3, 0], 
      state: 9
    }, 
    {
      pos: [1, 3, 0], 
      state: 10
    }, 
    {
      pos: [2, 3, 0], 
      state: 10
    }, 
    {
      pos: [3, 3, 0], 
      state: 10
    }, 
    {
      pos: [4, 3, 0], 
      state: 10
    }, 
    {
      pos: [5, 3, 0], 
      state: 10
    }, 
    {
      pos: [6, 3, 0], 
      state: 10
    }, 
    {
      pos: [7, 3, 0], 
      state: 10
    }, 
    {
      pos: [0, 4, 0], 
      state: 9
    }, 
    {
      pos: [1, 4, 0], 
      state: 9
    }, 
    {
      pos: [2, 4, 0], 
      state: 9
    }, 
    {
      pos: [3, 4, 0], 
      state: 9
    }, 
    {
      pos: [4, 4, 0], 
      state: 9
    }, 
    {
      pos: [5, 4, 0], 
      state: 9
    }, 
    {
      pos: [6, 4, 0], 
      state: 9
    }, 
    {
      pos: [7, 4, 0], 
      state: 9
    }, 
    {
      pos: [0, 5, 0], 
      state: 9
    }, 
    {
      pos: [1, 5, 0], 
      state: 9
    }, 
    {
      pos: [2, 5, 0], 
      state: 9
    }, 
    {
      pos: [3, 5, 0], 
      state: 9
    }, 
    {
      pos: [4, 5, 0], 
      state: 9
    }, 
    {
      pos: [5, 5, 0], 
      state: 9
    }, 
    {
      pos: [6, 5, 0], 
      state: 9
    }, 
    {
      pos: [7, 5, 0], 
      state: 9
    }, 
    {
      pos: [0, 6, 0], 
      state: 9
    }, 
    {
      pos: [1, 6, 0], 
      state: 9
    }, 
    {
      pos: [2, 6, 0], 
      state: 9
    }, 
    {
      pos: [3, 6, 0], 
      state: 9
    }, 
    {
      pos: [4, 6, 0], 
      state: 9
    }, 
    {
      pos: [5, 6, 0], 
      state: 9
    }, 
    {
      pos: [6, 6, 0], 
      state: 9
    }, 
    {
      pos: [7, 6, 0], 
      state: 9
    }, 
    {
      pos: [0, 0, 1], 
      state: 9
    }, 
    {
      pos: [1, 0, 1], 
      state: 11
    }, 
    {
      pos: [7, 0, 1], 
      state: 9
    }, 
    {
      pos: [0, 1, 1], 
      state: 9
    }, 
    {
      pos: [1, 1, 1], 
      state: 9
    }, 
    {
      pos: [7, 1, 1], 
      state: 9
    }, 
    {
      pos: [0, 2, 1], 
      state: 9
    }, 
    {
      pos: [1, 2, 1], 
      state: 9
    }, 
    {
      pos: [4, 2, 1], 
      state: 12
    }, 
    {
      pos: [7, 2, 1], 
      state: 9
    }, 
    {
      pos: [0, 3, 1], 
      state: 9
    }, 
    {
      pos: [1, 3, 1], 
      state: 13
    }, 
    {
      pos: [7, 3, 1], 
      state: 13
    }, 
    {
      pos: [0, 4, 1], 
      state: 9
    }, 
    {
      pos: [1, 4, 1], 
      state: 10
    }, 
    {
      pos: [2, 4, 1], 
      state: 10
    }, 
    {
      pos: [3, 4, 1], 
      state: 10
    }, 
    {
      pos: [4, 4, 1], 
      state: 10
    }, 
    {
      pos: [5, 4, 1], 
      state: 10
    }, 
    {
      pos: [6, 4, 1], 
      state: 10
    }, 
    {
      pos: [7, 4, 1], 
      state: 10
    }, 
    {
      pos: [0, 5, 1], 
      state: 9
    }, 
    {
      pos: [1, 5, 1], 
      state: 9
    }, 
    {
      pos: [2, 5, 1], 
      state: 9
    }, 
    {
      pos: [3, 5, 1], 
      state: 9
    }, 
    {
      pos: [4, 5, 1], 
      state: 9
    }, 
    {
      pos: [5, 5, 1], 
      state: 9
    }, 
    {
      pos: [6, 5, 1], 
      state: 9
    }, 
    {
      pos: [7, 5, 1], 
      state: 9
    }, 
    {
      pos: [0, 6, 1], 
      state: 9
    }, 
    {
      pos: [1, 6, 1], 
      state: 9
    }, 
    {
      pos: [2, 6, 1], 
      state: 9
    }, 
    {
      pos: [3, 6, 1], 
      state: 9
    }, 
    {
      pos: [4, 6, 1], 
      state: 9
    }, 
    {
      pos: [5, 6, 1], 
      state: 9
    }, 
    {
      pos: [6, 6, 1], 
      state: 9
    }, 
    {
      pos: [7, 6, 1], 
      state: 9
    }, 
    {
      pos: [0, 0, 2], 
      state: 14
    }, 
    {
      pos: [7, 0, 2], 
      state: 9
    }, 
    {
      pos: [0, 1, 2], 
      state: 9
    }, 
    {
      pos: [1, 1, 2], 
      state: 15
    }, 
    {
      pos: [3, 1, 2], 
      state: 9
    }, 
    {
      pos: [7, 1, 2], 
      state: 9
    }, 
    {
      pos: [0, 2, 2], 
      state: 9
    }, 
    {
      pos: [1, 2, 2], 
      state: 9
    }, 
    {
      pos: [3, 2, 2], 
      state: 9
    }, 
    {
      pos: [4, 2, 2], 
      state: 9
    }, 
    {
      pos: [7, 2, 2], 
      state: 9
    }, 
    {
      pos: [0, 3, 2], 
      state: 9
    }, 
    {
      pos: [1, 3, 2], 
      state: 9
    }, 
    {
      pos: [3, 3, 2], 
      state: 9
    }, 
    {
      pos: [4, 3, 2], 
      state: 9
    }, 
    {
      pos: [7, 3, 2], 
      state: 9
    }, 
    {
      pos: [0, 4, 2], 
      state: 9
    }, 
    {
      pos: [1, 4, 2], 
      state: 13
    }, 
    {
      pos: [3, 4, 2], 
      state: 9
    }, 
    {
      pos: [4, 4, 2], 
      state: 9
    }, 
    {
      pos: [5, 4, 2], 
      state: 9
    }, 
    {
      pos: [7, 4, 2], 
      state: 13
    }, 
    {
      pos: [0, 5, 2], 
      state: 9
    }, 
    {
      pos: [1, 5, 2], 
      state: 10
    }, 
    {
      pos: [2, 5, 2], 
      state: 10
    }, 
    {
      pos: [3, 5, 2], 
      state: 10
    }, 
    {
      pos: [4, 5, 2], 
      state: 10
    }, 
    {
      pos: [5, 5, 2], 
      state: 10
    }, 
    {
      pos: [6, 5, 2], 
      state: 10
    }, 
    {
      pos: [7, 5, 2], 
      state: 10
    }, 
    {
      pos: [0, 6, 2], 
      state: 9
    }, 
    {
      pos: [1, 6, 2], 
      state: 9
    }, 
    {
      pos: [2, 6, 2], 
      state: 9
    }, 
    {
      pos: [3, 6, 2], 
      state: 9
    }, 
    {
      pos: [4, 6, 2], 
      state: 9
    }, 
    {
      pos: [5, 6, 2], 
      state: 9
    }, 
    {
      pos: [6, 6, 2], 
      state: 9
    }, 
    {
      pos: [7, 6, 2], 
      state: 9
    }, 
    {
      pos: [7, 0, 3], 
      state: 9
    }, 
    {
      pos: [0, 1, 3], 
      state: 9
    }, 
    {
      pos: [1, 1, 3], 
      state: 9
    }, 
    {
      pos: [2, 1, 3], 
      state: 16
    }, 
    {
      pos: [3, 1, 3], 
      state: 9
    }, 
    {
      pos: [4, 1, 3], 
      state: 9
    }, 
    {
      pos: [7, 1, 3], 
      state: 9
    }, 
    {
      pos: [0, 2, 3], 
      state: 9
    }, 
    {
      pos: [1, 2, 3], 
      state: 9
    }, 
    {
      pos: [2, 2, 3], 
      state: 17
    }, 
    {
      pos: [3, 2, 3], 
      state: 9
    }, 
    {
      pos: [4, 2, 3], 
      state: 9
    }, 
    {
      pos: [5, 2, 3], 
      state: 9
    }, 
    {
      pos: [6, 2, 3], 
      state: 18
    }, 
    {
      pos: [7, 2, 3], 
      state: 9
    }, 
    {
      pos: [0, 3, 3], 
      state: 9
    }, 
    {
      pos: [1, 3, 3], 
      state: 9
    }, 
    {
      pos: [3, 3, 3], 
      state: 9
    }, 
    {
      pos: [4, 3, 3], 
      state: 9
    }, 
    {
      pos: [5, 3, 3], 
      state: 9
    }, 
    {
      pos: [7, 3, 3], 
      state: 9
    }, 
    {
      pos: [0, 4, 3], 
      state: 9
    }, 
    {
      pos: [1, 4, 3], 
      state: 9
    }, 
    {
      pos: [3, 4, 3], 
      state: 9
    }, 
    {
      pos: [4, 4, 3], 
      state: 9
    }, 
    {
      pos: [5, 4, 3], 
      state: 9
    }, 
    {
      pos: [7, 4, 3], 
      state: 9
    }, 
    {
      pos: [0, 5, 3], 
      state: 9
    }, 
    {
      pos: [1, 5, 3], 
      state: 13
    }, 
    {
      pos: [3, 5, 3], 
      state: 9
    }, 
    {
      pos: [4, 5, 3], 
      state: 9
    }, 
    {
      pos: [5, 5, 3], 
      state: 9
    }, 
    {
      pos: [7, 5, 3], 
      state: 13
    }, 
    {
      pos: [0, 6, 3], 
      state: 9
    }, 
    {
      pos: [1, 6, 3], 
      state: 10
    }, 
    {
      pos: [2, 6, 3], 
      state: 10
    }, 
    {
      pos: [3, 6, 3], 
      state: 10
    }, 
    {
      pos: [4, 6, 3], 
      state: 10
    }, 
    {
      pos: [5, 6, 3], 
      state: 10
    }, 
    {
      pos: [6, 6, 3], 
      state: 10
    }, 
    {
      pos: [7, 6, 3], 
      state: 10
    }, 
    {
      pos: [7, 0, 4], 
      state: 9
    }, 
    {
      pos: [0, 1, 4], 
      state: 19
    }, 
    {
      pos: [1, 1, 4], 
      state: 9
    }, 
    {
      pos: [3, 1, 4], 
      state: 9
    }, 
    {
      pos: [4, 1, 4], 
      state: 9
    }, 
    {
      pos: [7, 1, 4], 
      state: 9
    }, 
    {
      pos: [0, 2, 4], 
      state: 20
    }, 
    {
      pos: [1, 2, 4], 
      state: 9
    }, 
    {
      pos: [3, 2, 4], 
      state: 9
    }, 
    {
      pos: [4, 2, 4], 
      state: 9
    }, 
    {
      pos: [5, 2, 4], 
      state: 9
    }, 
    {
      pos: [7, 2, 4], 
      state: 9
    }, 
    {
      pos: [0, 3, 4], 
      state: 9
    }, 
    {
      pos: [1, 3, 4], 
      state: 9
    }, 
    {
      pos: [3, 3, 4], 
      state: 9
    }, 
    {
      pos: [4, 3, 4], 
      state: 9
    }, 
    {
      pos: [5, 3, 4], 
      state: 9
    }, 
    {
      pos: [7, 3, 4], 
      state: 9
    }, 
    {
      pos: [0, 4, 4], 
      state: 9
    }, 
    {
      pos: [1, 4, 4], 
      state: 9
    }, 
    {
      pos: [3, 4, 4], 
      state: 21
    }, 
    {
      pos: [4, 4, 4], 
      state: 9
    }, 
    {
      pos: [5, 4, 4], 
      state: 22
    }, 
    {
      pos: [7, 4, 4], 
      state: 9
    }, 
    {
      pos: [0, 5, 4], 
      state: 9
    }, 
    {
      pos: [1, 5, 4], 
      state: 9
    }, 
    {
      pos: [3, 5, 4], 
      state: 9
    }, 
    {
      pos: [4, 5, 4], 
      state: 9
    }, 
    {
      pos: [5, 5, 4], 
      state: 9
    }, 
    {
      pos: [7, 5, 4], 
      state: 9
    }, 
    {
      pos: [0, 6, 4], 
      state: 9
    }, 
    {
      pos: [7, 0, 5], 
      state: 9
    }, 
    {
      pos: [0, 1, 5], 
      state: 23
    }, 
    {
      pos: [1, 1, 5], 
      state: 9
    }, 
    {
      pos: [3, 1, 5], 
      state: 9
    }, 
    {
      pos: [4, 1, 5], 
      state: 9
    }, 
    {
      pos: [5, 1, 5], 
      state: 9
    }, 
    {
      pos: [7, 1, 5], 
      state: 9
    }, 
    {
      pos: [0, 2, 5], 
      state: 9
    }, 
    {
      pos: [1, 2, 5], 
      state: 9
    }, 
    {
      pos: [2, 2, 5], 
      state: 18
    }, 
    {
      pos: [3, 2, 5], 
      state: 9
    }, 
    {
      pos: [4, 2, 5], 
      state: 9
    }, 
    {
      pos: [5, 2, 5], 
      state: 9
    }, 
    {
      pos: [6, 2, 5], 
      state: 18
    }, 
    {
      pos: [7, 2, 5], 
      state: 9
    }, 
    {
      pos: [0, 3, 5], 
      state: 9
    }, 
    {
      pos: [1, 3, 5], 
      state: 9
    }, 
    {
      pos: [3, 3, 5], 
      state: 9
    }, 
    {
      pos: [4, 3, 5], 
      state: 9
    }, 
    {
      pos: [5, 3, 5], 
      state: 9
    }, 
    {
      pos: [7, 3, 5], 
      state: 9
    }, 
    {
      pos: [0, 4, 5], 
      state: 9
    }, 
    {
      pos: [1, 4, 5], 
      state: 9
    }, 
    {
      pos: [3, 4, 5], 
      state: 9
    }, 
    {
      pos: [4, 4, 5], 
      state: 9
    }, 
    {
      pos: [5, 4, 5], 
      state: 9
    }, 
    {
      pos: [7, 4, 5], 
      state: 9
    }, 
    {
      pos: [0, 5, 5], 
      state: 9
    }, 
    {
      pos: [1, 5, 5], 
      state: 24
    }, 
    {
      pos: [3, 5, 5], 
      state: 9
    }, 
    {
      pos: [4, 5, 5], 
      state: 9
    }, 
    {
      pos: [5, 5, 5], 
      state: 9
    }, 
    {
      pos: [7, 5, 5], 
      state: 24
    }, 
    {
      pos: [0, 6, 5], 
      state: 9
    }, 
    {
      pos: [1, 6, 5], 
      state: 25
    }, 
    {
      pos: [2, 6, 5], 
      state: 25
    }, 
    {
      pos: [3, 6, 5], 
      state: 25
    }, 
    {
      pos: [4, 6, 5], 
      state: 25
    }, 
    {
      pos: [5, 6, 5], 
      state: 25
    }, 
    {
      pos: [6, 6, 5], 
      state: 25
    }, 
    {
      pos: [7, 6, 5], 
      state: 25
    }, 
    {
      pos: [7, 0, 6], 
      state: 9
    }, 
    {
      pos: [0, 1, 6], 
      state: 23
    }, 
    {
      pos: [1, 1, 6], 
      state: 9
    }, 
    {
      pos: [3, 1, 6], 
      state: 9
    }, 
    {
      pos: [4, 1, 6], 
      state: 26
    }, 
    {
      pos: [5, 1, 6], 
      state: 9
    }, 
    {
      pos: [7, 1, 6], 
      state: 9
    }, 
    {
      pos: [0, 2, 6], 
      state: 9
    }, 
    {
      pos: [1, 2, 6], 
      state: 9
    }, 
    {
      pos: [3, 2, 6], 
      state: 9
    }, 
    {
      pos: [4, 2, 6], 
      state: 9
    }, 
    {
      pos: [5, 2, 6], 
      state: 9
    }, 
    {
      pos: [7, 2, 6], 
      state: 9
    }, 
    {
      pos: [0, 3, 6], 
      state: 9
    }, 
    {
      pos: [1, 3, 6], 
      state: 9
    }, 
    {
      pos: [3, 3, 6], 
      state: 9
    }, 
    {
      pos: [4, 3, 6], 
      state: 9
    }, 
    {
      pos: [5, 3, 6], 
      state: 9
    }, 
    {
      pos: [7, 3, 6], 
      state: 9
    }, 
    {
      pos: [0, 4, 6], 
      state: 9
    }, 
    {
      pos: [1, 4, 6], 
      state: 24
    }, 
    {
      pos: [3, 4, 6], 
      state: 9
    }, 
    {
      pos: [4, 4, 6], 
      state: 9
    }, 
    {
      pos: [5, 4, 6], 
      state: 9
    }, 
    {
      pos: [7, 4, 6], 
      state: 24
    }, 
    {
      pos: [0, 5, 6], 
      state: 9
    }, 
    {
      pos: [1, 5, 6], 
      state: 25
    }, 
    {
      pos: [2, 5, 6], 
      state: 25
    }, 
    {
      pos: [3, 5, 6], 
      state: 25
    }, 
    {
      pos: [4, 5, 6], 
      state: 25
    }, 
    {
      pos: [5, 5, 6], 
      state: 25
    }, 
    {
      pos: [6, 5, 6], 
      state: 25
    }, 
    {
      pos: [7, 5, 6], 
      state: 25
    }, 
    {
      pos: [0, 6, 6], 
      state: 9
    }, 
    {
      pos: [1, 6, 6], 
      state: 9
    }, 
    {
      pos: [2, 6, 6], 
      state: 9
    }, 
    {
      pos: [3, 6, 6], 
      state: 9
    }, 
    {
      pos: [4, 6, 6], 
      state: 9
    }, 
    {
      pos: [5, 6, 6], 
      state: 9
    }, 
    {
      pos: [6, 6, 6], 
      state: 9
    }, 
    {
      pos: [7, 6, 6], 
      state: 9
    }, 
    {
      pos: [7, 0, 7], 
      state: 9
    }, 
    {
      pos: [0, 1, 7], 
      state: 27
    }, 
    {
      pos: [1, 1, 7], 
      state: 28
    }, 
    {
      pos: [7, 1, 7], 
      state: 9
    }, 
    {
      pos: [0, 2, 7], 
      state: 20
    }, 
    {
      pos: [1, 2, 7], 
      state: 9
    }, 
    {
      pos: [4, 2, 7], 
      state: 12
    }, 
    {
      pos: [7, 2, 7], 
      state: 9
    }, 
    {
      pos: [0, 3, 7], 
      state: 9
    }, 
    {
      pos: [1, 3, 7], 
      state: 24
    }, 
    {
      pos: [7, 3, 7], 
      state: 24
    }, 
    {
      pos: [0, 4, 7], 
      state: 9
    }, 
    {
      pos: [1, 4, 7], 
      state: 25
    }, 
    {
      pos: [2, 4, 7], 
      state: 25
    }, 
    {
      pos: [3, 4, 7], 
      state: 25
    }, 
    {
      pos: [4, 4, 7], 
      state: 25
    }, 
    {
      pos: [5, 4, 7], 
      state: 25
    }, 
    {
      pos: [6, 4, 7], 
      state: 25
    }, 
    {
      pos: [7, 4, 7], 
      state: 25
    }, 
    {
      pos: [0, 5, 7], 
      state: 9
    }, 
    {
      pos: [1, 5, 7], 
      state: 9
    }, 
    {
      pos: [2, 5, 7], 
      state: 9
    }, 
    {
      pos: [3, 5, 7], 
      state: 9
    }, 
    {
      pos: [4, 5, 7], 
      state: 9
    }, 
    {
      pos: [5, 5, 7], 
      state: 9
    }, 
    {
      pos: [6, 5, 7], 
      state: 9
    }, 
    {
      pos: [7, 5, 7], 
      state: 9
    }, 
    {
      pos: [0, 6, 7], 
      state: 9
    }, 
    {
      pos: [1, 6, 7], 
      state: 9
    }, 
    {
      pos: [2, 6, 7], 
      state: 9
    }, 
    {
      pos: [3, 6, 7], 
      state: 9
    }, 
    {
      pos: [4, 6, 7], 
      state: 9
    }, 
    {
      pos: [5, 6, 7], 
      state: 9
    }, 
    {
      pos: [6, 6, 7], 
      state: 9
    }, 
    {
      pos: [7, 6, 7], 
      state: 9
    }, 
    {
      pos: [0, 0, 8], 
      state: 9
    }, 
    {
      pos: [1, 0, 8], 
      state: 9
    }, 
    {
      pos: [2, 0, 8], 
      state: 9
    }, 
    {
      pos: [3, 0, 8], 
      state: 9
    }, 
    {
      pos: [4, 0, 8], 
      state: 9
    }, 
    {
      pos: [5, 0, 8], 
      state: 9
    }, 
    {
      pos: [6, 0, 8], 
      state: 9
    }, 
    {
      pos: [7, 0, 8], 
      state: 9
    }, 
    {
      pos: [0, 1, 8], 
      state: 9
    }, 
    {
      pos: [1, 1, 8], 
      state: 9
    }, 
    {
      pos: [2, 1, 8], 
      state: 9
    }, 
    {
      pos: [3, 1, 8], 
      state: 9
    }, 
    {
      pos: [4, 1, 8], 
      state: 9
    }, 
    {
      pos: [5, 1, 8], 
      state: 9
    }, 
    {
      pos: [6, 1, 8], 
      state: 9
    }, 
    {
      pos: [7, 1, 8], 
      state: 9
    }, 
    {
      pos: [0, 2, 8], 
      state: 9
    }, 
    {
      pos: [1, 2, 8], 
      state: 9
    }, 
    {
      pos: [2, 2, 8], 
      state: 9
    }, 
    {
      pos: [3, 2, 8], 
      state: 9
    }, 
    {
      pos: [4, 2, 8], 
      state: 9
    }, 
    {
      pos: [5, 2, 8], 
      state: 9
    }, 
    {
      pos: [6, 2, 8], 
      state: 9
    }, 
    {
      pos: [7, 2, 8], 
      state: 9
    }, 
    {
      pos: [0, 3, 8], 
      state: 9
    }, 
    {
      pos: [1, 3, 8], 
      state: 25
    }, 
    {
      pos: [2, 3, 8], 
      state: 25
    }, 
    {
      pos: [3, 3, 8], 
      state: 25
    }, 
    {
      pos: [4, 3, 8], 
      state: 25
    }, 
    {
      pos: [5, 3, 8], 
      state: 25
    }, 
    {
      pos: [6, 3, 8], 
      state: 25
    }, 
    {
      pos: [7, 3, 8], 
      state: 25
    }, 
    {
      pos: [0, 4, 8], 
      state: 9
    }, 
    {
      pos: [1, 4, 8], 
      state: 9
    }, 
    {
      pos: [2, 4, 8], 
      state: 9
    }, 
    {
      pos: [3, 4, 8], 
      state: 9
    }, 
    {
      pos: [4, 4, 8], 
      state: 9
    }, 
    {
      pos: [5, 4, 8], 
      state: 9
    }, 
    {
      pos: [6, 4, 8], 
      state: 9
    }, 
    {
      pos: [7, 4, 8], 
      state: 9
    }, 
    {
      pos: [0, 5, 8], 
      state: 9
    }, 
    {
      pos: [1, 5, 8], 
      state: 9
    }, 
    {
      pos: [2, 5, 8], 
      state: 9
    }, 
    {
      pos: [3, 5, 8], 
      state: 9
    }, 
    {
      pos: [4, 5, 8], 
      state: 9
    }, 
    {
      pos: [5, 5, 8], 
      state: 9
    }, 
    {
      pos: [6, 5, 8], 
      state: 9
    }, 
    {
      pos: [7, 5, 8], 
      state: 9
    }, 
    {
      pos: [0, 6, 8], 
      state: 9
    }, 
    {
      pos: [1, 6, 8], 
      state: 9
    }, 
    {
      pos: [2, 6, 8], 
      state: 9
    }, 
    {
      pos: [3, 6, 8], 
      state: 9
    }, 
    {
      pos: [4, 6, 8], 
      state: 9
    }, 
    {
      pos: [5, 6, 8], 
      state: 9
    }, 
    {
      pos: [6, 6, 8], 
      state: 9
    }, 
    {
      pos: [7, 6, 8], 
      state: 9
    }
  ], 
  palette: [
    {
      Name: "minecraft:cobblestone"
    }, 
    {
      Properties: {
        axis: "y"
      }, 
      Name: "minecraft:oak_log"
    }, 
    {
      Name: "minecraft:white_terracotta"
    }, 
    {
      Properties: {
        snowy: "false"
      }, 
      Name: "minecraft:grass_block"
    }, 
    {
      Name: "minecraft:clay"
    }, 
    {
      Name: "minecraft:terracotta"
    }, 
    {
      Properties: {
        axis: "z"
      }, 
      Name: "minecraft:oak_log"
    }, 
    {
      Name: "minecraft:oak_planks"
    }, 
    {
      Properties: {
        facing: "west"
      }, 
      Name: "minecraft:jigsaw"
    }, 
    {
      Name: "minecraft:air"
    }, 
    {
      Properties: {
        half: "bottom", 
        waterlogged: "false", 
        shape: "straight", 
        facing: "south"
      }, 
      Name: "minecraft:oak_stairs"
    }, 
    {
      Properties: {
        half: "top", 
        waterlogged: "false", 
        powered: "false", 
        facing: "north", 
        open: "true"
      }, 
      Name: "minecraft:oak_trapdoor"
    }, 
    {
      Properties: {
        east: "true", 
        waterlogged: "false", 
        south: "false", 
        north: "false", 
        west: "true"
      }, 
      Name: "minecraft:glass_pane"
    }, 
    {
      Properties: {
        half: "top", 
        waterlogged: "false", 
        shape: "straight", 
        facing: "north"
      }, 
      Name: "minecraft:oak_stairs"
    }, 
    {
      Properties: {
        half: "top", 
        waterlogged: "false", 
        powered: "false", 
        facing: "west", 
        open: "true"
      }, 
      Name: "minecraft:oak_trapdoor"
    }, 
    {
      Name: "minecraft:dandelion"
    }, 
    {
      Properties: {
        hinge: "left", 
        half: "lower", 
        powered: "false", 
        facing: "east", 
        open: "false"
      }, 
      Name: "minecraft:oak_door"
    }, 
    {
      Properties: {
        hinge: "left", 
        half: "upper", 
        powered: "false", 
        facing: "east", 
        open: "false"
      }, 
      Name: "minecraft:oak_door"
    }, 
    {
      Properties: {
        east: "false", 
        waterlogged: "false", 
        south: "true", 
        north: "true", 
        west: "false"
      }, 
      Name: "minecraft:glass_pane"
    }, 
    {
      Properties: {
        east: "false", 
        waterlogged: "false", 
        south: "true", 
        north: "false", 
        west: "false"
      }, 
      Name: "minecraft:oak_fence"
    }, 
    {
      Name: "minecraft:torch"
    }, 
    {
      Properties: {
        facing: "east"
      }, 
      Name: "minecraft:wall_torch"
    }, 
    {
      Properties: {
        facing: "west"
      }, 
      Name: "minecraft:wall_torch"
    }, 
    {
      Properties: {
        east: "false", 
        waterlogged: "false", 
        south: "true", 
        north: "true", 
        west: "false"
      }, 
      Name: "minecraft:oak_fence"
    }, 
    {
      Properties: {
        half: "top", 
        waterlogged: "false", 
        shape: "straight", 
        facing: "south"
      }, 
      Name: "minecraft:oak_stairs"
    }, 
    {
      Properties: {
        half: "bottom", 
        waterlogged: "false", 
        shape: "straight", 
        facing: "north"
      }, 
      Name: "minecraft:oak_stairs"
    }, 
    {
      Name: "minecraft:stonecutter"
    }, 
    {
      Properties: {
        east: "true", 
        waterlogged: "false", 
        south: "false", 
        north: "true", 
        west: "false"
      }, 
      Name: "minecraft:oak_fence"
    }, 
    {
      Properties: {
        east: "true", 
        waterlogged: "false", 
        south: "false", 
        north: "false", 
        west: "true"
      }, 
      Name: "minecraft:oak_fence"
    }
  ]
}
