{
  size: [8, 6, 11], 
  entities: [], 
  blocks: [
    {
      pos: [2, 0, 0], 
      state: 0
    }, 
    {
      pos: [3, 0, 0], 
      state: 0
    }, 
    {
      pos: [4, 0, 0], 
      state: 0
    }, 
    {
      pos: [5, 0, 0], 
      state: 0
    }, 
    {
      pos: [6, 0, 0], 
      state: 0
    }, 
    {
      pos: [2, 0, 1], 
      state: 0
    }, 
    {
      pos: [3, 0, 1], 
      state: 0
    }, 
    {
      pos: [5, 0, 1], 
      state: 0
    }, 
    {
      pos: [6, 0, 1], 
      state: 0
    }, 
    {
      pos: [0, 0, 2], 
      state: 0
    }, 
    {
      pos: [1, 0, 2], 
      state: 0
    }, 
    {
      pos: [2, 0, 2], 
      state: 0
    }, 
    {
      pos: [3, 0, 2], 
      state: 0
    }, 
    {
      pos: [4, 0, 2], 
      state: 0
    }, 
    {
      pos: [5, 0, 2], 
      state: 0
    }, 
    {
      pos: [6, 0, 2], 
      state: 0
    }, 
    {
      pos: [0, 0, 3], 
      state: 0
    }, 
    {
      pos: [1, 0, 3], 
      state: 0
    }, 
    {
      pos: [2, 0, 3], 
      state: 0
    }, 
    {
      pos: [3, 0, 3], 
      state: 0
    }, 
    {
      pos: [5, 0, 3], 
      state: 0
    }, 
    {
      pos: [6, 0, 3], 
      state: 0
    }, 
    {
      pos: [7, 0, 3], 
      state: 0
    }, 
    {
      pos: [0, 0, 4], 
      state: 0
    }, 
    {
      pos: [1, 0, 4], 
      state: 0
    }, 
    {
      pos: [2, 0, 4], 
      state: 0
    }, 
    {
      pos: [3, 0, 4], 
      state: 0
    }, 
    {
      pos: [4, 0, 4], 
      state: 0
    }, 
    {
      pos: [5, 0, 4], 
      state: 0
    }, 
    {
      pos: [6, 0, 4], 
      state: 0
    }, 
    {
      pos: [7, 0, 4], 
      state: 0
    }, 
    {
      pos: [0, 0, 5], 
      state: 1
    }, 
    {
      pos: [1, 0, 5], 
      state: 0
    }, 
    {
      pos: [3, 0, 5], 
      state: 0
    }, 
    {
      pos: [4, 0, 5], 
      state: 0
    }, 
    {
      pos: [6, 0, 5], 
      state: 0
    }, 
    {
      pos: [7, 0, 5], 
      state: 0
    }, 
    {
      pos: [0, 0, 6], 
      state: 0
    }, 
    {
      pos: [1, 0, 6], 
      state: 0
    }, 
    {
      pos: [2, 0, 6], 
      state: 0
    }, 
    {
      pos: [3, 0, 6], 
      state: 0
    }, 
    {
      pos: [4, 0, 6], 
      state: 0
    }, 
    {
      pos: [6, 0, 6], 
      state: 0
    }, 
    {
      pos: [7, 0, 6], 
      state: 0
    }, 
    {
      pos: [0, 0, 7], 
      state: 0
    }, 
    {
      pos: [1, 0, 7], 
      state: 0
    }, 
    {
      pos: [2, 0, 7], 
      state: 0
    }, 
    {
      pos: [7, 0, 7], 
      state: 0
    }, 
    {
      pos: [0, 0, 8], 
      state: 0
    }, 
    {
      pos: [1, 0, 8], 
      state: 0
    }, 
    {
      pos: [2, 0, 8], 
      state: 0
    }, 
    {
      pos: [3, 0, 8], 
      state: 0
    }, 
    {
      pos: [4, 0, 8], 
      state: 0
    }, 
    {
      pos: [6, 0, 8], 
      state: 0
    }, 
    {
      pos: [7, 0, 8], 
      state: 0
    }, 
    {
      pos: [3, 0, 9], 
      state: 0
    }, 
    {
      pos: [4, 0, 9], 
      state: 0
    }, 
    {
      pos: [5, 0, 9], 
      state: 0
    }, 
    {
      pos: [6, 0, 9], 
      state: 0
    }, 
    {
      pos: [7, 0, 9], 
      state: 0
    }, 
    {
      pos: [3, 0, 10], 
      state: 0
    }, 
    {
      pos: [4, 0, 10], 
      state: 0
    }, 
    {
      pos: [5, 0, 10], 
      state: 0
    }, 
    {
      pos: [6, 0, 10], 
      state: 0
    }, 
    {
      pos: [7, 0, 10], 
      state: 0
    }, 
    {
      nbt: {
        target_pool: "minecraft:village/plains/decor", 
        final_state: "minecraft:dirt", 
        id: "minecraft:jigsaw", 
        attachement_type: "minecraft:bottom"
      }, 
      pos: [0, 0, 0], 
      state: 2
    }, 
    {
      nbt: {
        target_pool: "minecraft:village/common/animals", 
        final_state: "minecraft:dirt", 
        id: "minecraft:jigsaw", 
        attachement_type: "minecraft:bottom"
      }, 
      pos: [4, 0, 1], 
      state: 2
    }, 
    {
      nbt: {
        target_pool: "minecraft:village/plains/decor", 
        final_state: "minecraft:dirt", 
        id: "minecraft:jigsaw", 
        attachement_type: "minecraft:bottom"
      }, 
      pos: [4, 0, 3], 
      state: 2
    }, 
    {
      nbt: {
        target_pool: "minecraft:village/common/animals", 
        final_state: "minecraft:dirt", 
        id: "minecraft:jigsaw", 
        attachement_type: "minecraft:bottom"
      }, 
      pos: [2, 0, 5], 
      state: 2
    }, 
    {
      nbt: {
        target_pool: "minecraft:village/common/animals", 
        final_state: "minecraft:dirt", 
        id: "minecraft:jigsaw", 
        attachement_type: "minecraft:bottom"
      }, 
      pos: [5, 0, 5], 
      state: 2
    }, 
    {
      nbt: {
        target_pool: "minecraft:village/plains/decor", 
        final_state: "minecraft:dirt", 
        id: "minecraft:jigsaw", 
        attachement_type: "minecraft:bottom"
      }, 
      pos: [3, 0, 7], 
      state: 2
    }, 
    {
      nbt: {
        target_pool: "minecraft:village/plains/decor", 
        final_state: "minecraft:dirt", 
        id: "minecraft:jigsaw", 
        attachement_type: "minecraft:bottom"
      }, 
      pos: [1, 0, 10], 
      state: 2
    }, 
    {
      pos: [5, 0, 6], 
      state: 3
    }, 
    {
      pos: [4, 0, 7], 
      state: 3
    }, 
    {
      pos: [5, 0, 7], 
      state: 3
    }, 
    {
      pos: [6, 0, 7], 
      state: 3
    }, 
    {
      pos: [5, 0, 8], 
      state: 3
    }, 
    {
      nbt: {
        target_pool: "minecraft:empty", 
        final_state: "minecraft:oak_fence_gate[facing=east,in_wall=false,open=false,powered=false]", 
        id: "minecraft:jigsaw", 
        attachement_type: "minecraft:building_entrance"
      }, 
      pos: [0, 1, 5], 
      state: 4
    }, 
    {
      pos: [0, 1, 0], 
      state: 5
    }, 
    {
      pos: [1, 1, 0], 
      state: 5
    }, 
    {
      pos: [2, 1, 0], 
      state: 6
    }, 
    {
      pos: [3, 1, 0], 
      state: 7
    }, 
    {
      pos: [4, 1, 0], 
      state: 7
    }, 
    {
      pos: [5, 1, 0], 
      state: 7
    }, 
    {
      pos: [6, 1, 0], 
      state: 8
    }, 
    {
      pos: [7, 1, 0], 
      state: 5
    }, 
    {
      pos: [0, 1, 1], 
      state: 5
    }, 
    {
      pos: [1, 1, 1], 
      state: 5
    }, 
    {
      pos: [2, 1, 1], 
      state: 9
    }, 
    {
      pos: [3, 1, 1], 
      state: 5
    }, 
    {
      pos: [4, 1, 1], 
      state: 5
    }, 
    {
      pos: [5, 1, 1], 
      state: 5
    }, 
    {
      pos: [6, 1, 1], 
      state: 9
    }, 
    {
      pos: [7, 1, 1], 
      state: 5
    }, 
    {
      pos: [0, 1, 2], 
      state: 6
    }, 
    {
      pos: [1, 1, 2], 
      state: 7
    }, 
    {
      pos: [2, 1, 2], 
      state: 10
    }, 
    {
      pos: [3, 1, 2], 
      state: 5
    }, 
    {
      pos: [4, 1, 2], 
      state: 5
    }, 
    {
      pos: [5, 1, 2], 
      state: 5
    }, 
    {
      pos: [6, 1, 2], 
      state: 9
    }, 
    {
      pos: [7, 1, 2], 
      state: 5
    }, 
    {
      pos: [0, 1, 3], 
      state: 9
    }, 
    {
      pos: [1, 1, 3], 
      state: 5
    }, 
    {
      pos: [2, 1, 3], 
      state: 5
    }, 
    {
      pos: [3, 1, 3], 
      state: 5
    }, 
    {
      pos: [4, 1, 3], 
      state: 5
    }, 
    {
      pos: [5, 1, 3], 
      state: 5
    }, 
    {
      pos: [6, 1, 3], 
      state: 11
    }, 
    {
      pos: [7, 1, 3], 
      state: 8
    }, 
    {
      pos: [0, 1, 4], 
      state: 9
    }, 
    {
      pos: [1, 1, 4], 
      state: 5
    }, 
    {
      pos: [2, 1, 4], 
      state: 5
    }, 
    {
      pos: [3, 1, 4], 
      state: 5
    }, 
    {
      pos: [4, 1, 4], 
      state: 5
    }, 
    {
      pos: [5, 1, 4], 
      state: 5
    }, 
    {
      pos: [6, 1, 4], 
      state: 5
    }, 
    {
      pos: [7, 1, 4], 
      state: 9
    }, 
    {
      pos: [1, 1, 5], 
      state: 5
    }, 
    {
      pos: [2, 1, 5], 
      state: 5
    }, 
    {
      pos: [3, 1, 5], 
      state: 5
    }, 
    {
      pos: [4, 1, 5], 
      state: 5
    }, 
    {
      pos: [5, 1, 5], 
      state: 5
    }, 
    {
      pos: [6, 1, 5], 
      state: 5
    }, 
    {
      pos: [7, 1, 5], 
      state: 9
    }, 
    {
      pos: [0, 1, 6], 
      state: 9
    }, 
    {
      pos: [1, 1, 6], 
      state: 5
    }, 
    {
      pos: [2, 1, 6], 
      state: 5
    }, 
    {
      pos: [3, 1, 6], 
      state: 5
    }, 
    {
      pos: [4, 1, 6], 
      state: 5
    }, 
    {
      pos: [5, 1, 6], 
      state: 5
    }, 
    {
      pos: [6, 1, 6], 
      state: 5
    }, 
    {
      pos: [7, 1, 6], 
      state: 9
    }, 
    {
      pos: [0, 1, 7], 
      state: 9
    }, 
    {
      pos: [1, 1, 7], 
      state: 5
    }, 
    {
      pos: [2, 1, 7], 
      state: 5
    }, 
    {
      pos: [3, 1, 7], 
      state: 5
    }, 
    {
      pos: [4, 1, 7], 
      state: 5
    }, 
    {
      pos: [5, 1, 7], 
      state: 5
    }, 
    {
      pos: [6, 1, 7], 
      state: 5
    }, 
    {
      pos: [7, 1, 7], 
      state: 9
    }, 
    {
      pos: [0, 1, 8], 
      state: 11
    }, 
    {
      pos: [1, 1, 8], 
      state: 7
    }, 
    {
      pos: [2, 1, 8], 
      state: 7
    }, 
    {
      pos: [3, 1, 8], 
      state: 8
    }, 
    {
      pos: [4, 1, 8], 
      state: 5
    }, 
    {
      pos: [5, 1, 8], 
      state: 5
    }, 
    {
      pos: [6, 1, 8], 
      state: 5
    }, 
    {
      pos: [7, 1, 8], 
      state: 9
    }, 
    {
      pos: [0, 1, 9], 
      state: 5
    }, 
    {
      pos: [1, 1, 9], 
      state: 5
    }, 
    {
      pos: [2, 1, 9], 
      state: 5
    }, 
    {
      pos: [3, 1, 9], 
      state: 9
    }, 
    {
      pos: [4, 1, 9], 
      state: 5
    }, 
    {
      pos: [5, 1, 9], 
      state: 5
    }, 
    {
      pos: [6, 1, 9], 
      state: 5
    }, 
    {
      pos: [7, 1, 9], 
      state: 9
    }, 
    {
      pos: [0, 1, 10], 
      state: 5
    }, 
    {
      pos: [1, 1, 10], 
      state: 5
    }, 
    {
      pos: [2, 1, 10], 
      state: 5
    }, 
    {
      pos: [3, 1, 10], 
      state: 11
    }, 
    {
      pos: [4, 1, 10], 
      state: 7
    }, 
    {
      pos: [5, 1, 10], 
      state: 7
    }, 
    {
      pos: [6, 1, 10], 
      state: 7
    }, 
    {
      pos: [7, 1, 10], 
      state: 10
    }, 
    {
      pos: [0, 2, 0], 
      state: 5
    }, 
    {
      pos: [1, 2, 0], 
      state: 5
    }, 
    {
      pos: [2, 2, 0], 
      state: 5
    }, 
    {
      pos: [3, 2, 0], 
      state: 5
    }, 
    {
      pos: [4, 2, 0], 
      state: 5
    }, 
    {
      pos: [5, 2, 0], 
      state: 5
    }, 
    {
      pos: [6, 2, 0], 
      state: 5
    }, 
    {
      pos: [7, 2, 0], 
      state: 5
    }, 
    {
      pos: [0, 2, 1], 
      state: 5
    }, 
    {
      pos: [1, 2, 1], 
      state: 5
    }, 
    {
      pos: [2, 2, 1], 
      state: 5
    }, 
    {
      pos: [3, 2, 1], 
      state: 5
    }, 
    {
      pos: [4, 2, 1], 
      state: 5
    }, 
    {
      pos: [5, 2, 1], 
      state: 5
    }, 
    {
      pos: [6, 2, 1], 
      state: 5
    }, 
    {
      pos: [7, 2, 1], 
      state: 5
    }, 
    {
      pos: [0, 2, 2], 
      state: 5
    }, 
    {
      pos: [1, 2, 2], 
      state: 5
    }, 
    {
      pos: [2, 2, 2], 
      state: 5
    }, 
    {
      pos: [3, 2, 2], 
      state: 5
    }, 
    {
      pos: [4, 2, 2], 
      state: 5
    }, 
    {
      pos: [5, 2, 2], 
      state: 5
    }, 
    {
      pos: [6, 2, 2], 
      state: 5
    }, 
    {
      pos: [7, 2, 2], 
      state: 5
    }, 
    {
      pos: [0, 2, 3], 
      state: 5
    }, 
    {
      pos: [1, 2, 3], 
      state: 5
    }, 
    {
      pos: [2, 2, 3], 
      state: 5
    }, 
    {
      pos: [3, 2, 3], 
      state: 5
    }, 
    {
      pos: [4, 2, 3], 
      state: 5
    }, 
    {
      pos: [5, 2, 3], 
      state: 5
    }, 
    {
      pos: [6, 2, 3], 
      state: 5
    }, 
    {
      pos: [7, 2, 3], 
      state: 5
    }, 
    {
      pos: [0, 2, 4], 
      state: 12
    }, 
    {
      pos: [1, 2, 4], 
      state: 5
    }, 
    {
      pos: [2, 2, 4], 
      state: 5
    }, 
    {
      pos: [3, 2, 4], 
      state: 5
    }, 
    {
      pos: [4, 2, 4], 
      state: 5
    }, 
    {
      pos: [5, 2, 4], 
      state: 5
    }, 
    {
      pos: [6, 2, 4], 
      state: 5
    }, 
    {
      pos: [7, 2, 4], 
      state: 5
    }, 
    {
      pos: [0, 2, 5], 
      state: 5
    }, 
    {
      pos: [1, 2, 5], 
      state: 5
    }, 
    {
      pos: [2, 2, 5], 
      state: 5
    }, 
    {
      pos: [3, 2, 5], 
      state: 5
    }, 
    {
      pos: [4, 2, 5], 
      state: 5
    }, 
    {
      pos: [5, 2, 5], 
      state: 5
    }, 
    {
      pos: [6, 2, 5], 
      state: 5
    }, 
    {
      pos: [7, 2, 5], 
      state: 5
    }, 
    {
      pos: [0, 2, 6], 
      state: 12
    }, 
    {
      pos: [1, 2, 6], 
      state: 5
    }, 
    {
      pos: [2, 2, 6], 
      state: 5
    }, 
    {
      pos: [3, 2, 6], 
      state: 5
    }, 
    {
      pos: [4, 2, 6], 
      state: 5
    }, 
    {
      pos: [5, 2, 6], 
      state: 5
    }, 
    {
      pos: [6, 2, 6], 
      state: 5
    }, 
    {
      pos: [7, 2, 6], 
      state: 5
    }, 
    {
      pos: [0, 2, 7], 
      state: 5
    }, 
    {
      pos: [1, 2, 7], 
      state: 5
    }, 
    {
      pos: [2, 2, 7], 
      state: 5
    }, 
    {
      pos: [3, 2, 7], 
      state: 5
    }, 
    {
      pos: [4, 2, 7], 
      state: 5
    }, 
    {
      pos: [5, 2, 7], 
      state: 5
    }, 
    {
      pos: [6, 2, 7], 
      state: 5
    }, 
    {
      pos: [7, 2, 7], 
      state: 5
    }, 
    {
      pos: [0, 2, 8], 
      state: 5
    }, 
    {
      pos: [1, 2, 8], 
      state: 5
    }, 
    {
      pos: [2, 2, 8], 
      state: 5
    }, 
    {
      pos: [3, 2, 8], 
      state: 5
    }, 
    {
      pos: [4, 2, 8], 
      state: 5
    }, 
    {
      pos: [5, 2, 8], 
      state: 5
    }, 
    {
      pos: [6, 2, 8], 
      state: 5
    }, 
    {
      pos: [7, 2, 8], 
      state: 5
    }, 
    {
      pos: [0, 2, 9], 
      state: 5
    }, 
    {
      pos: [1, 2, 9], 
      state: 5
    }, 
    {
      pos: [2, 2, 9], 
      state: 5
    }, 
    {
      pos: [3, 2, 9], 
      state: 5
    }, 
    {
      pos: [4, 2, 9], 
      state: 5
    }, 
    {
      pos: [5, 2, 9], 
      state: 5
    }, 
    {
      pos: [6, 2, 9], 
      state: 5
    }, 
    {
      pos: [7, 2, 9], 
      state: 5
    }, 
    {
      pos: [0, 2, 10], 
      state: 5
    }, 
    {
      pos: [1, 2, 10], 
      state: 5
    }, 
    {
      pos: [2, 2, 10], 
      state: 5
    }, 
    {
      pos: [3, 2, 10], 
      state: 5
    }, 
    {
      pos: [4, 2, 10], 
      state: 5
    }, 
    {
      pos: [5, 2, 10], 
      state: 5
    }, 
    {
      pos: [6, 2, 10], 
      state: 5
    }, 
    {
      pos: [7, 2, 10], 
      state: 5
    }
  ], 
  palette: [
    {
      Properties: {
        snowy: "false"
      }, 
      Name: "minecraft:grass_block"
    }, 
    {
      Name: "minecraft:dirt"
    }, 
    {
      Properties: {
        facing: "up"
      }, 
      Name: "minecraft:jigsaw"
    }, 
    {
      Properties: {
        level: "0"
      }, 
      Name: "minecraft:water"
    }, 
    {
      Properties: {
        facing: "west"
      }, 
      Name: "minecraft:jigsaw"
    }, 
    {
      Name: "minecraft:air"
    }, 
    {
      Properties: {
        east: "true", 
        waterlogged: "false", 
        south: "true", 
        north: "false", 
        west: "false"
      }, 
      Name: "minecraft:oak_fence"
    }, 
    {
      Properties: {
        east: "true", 
        waterlogged: "false", 
        south: "false", 
        north: "false", 
        west: "true"
      }, 
      Name: "minecraft:oak_fence"
    }, 
    {
      Properties: {
        east: "false", 
        waterlogged: "false", 
        south: "true", 
        north: "false", 
        west: "true"
      }, 
      Name: "minecraft:oak_fence"
    }, 
    {
      Properties: {
        east: "false", 
        waterlogged: "false", 
        south: "true", 
        north: "true", 
        west: "false"
      }, 
      Name: "minecraft:oak_fence"
    }, 
    {
      Properties: {
        east: "false", 
        waterlogged: "false", 
        south: "false", 
        north: "true", 
        west: "true"
      }, 
      Name: "minecraft:oak_fence"
    }, 
    {
      Properties: {
        east: "true", 
        waterlogged: "false", 
        south: "false", 
        north: "true", 
        west: "false"
      }, 
      Name: "minecraft:oak_fence"
    }, 
    {
      Name: "minecraft:torch"
    }
  ]
}
