{
  size: [9, 7, 16], 
  entities: [], 
  blocks: [
    {
      pos: [0, 0, 0], 
      state: 0
    }, 
    {
      pos: [1, 0, 0], 
      state: 0
    }, 
    {
      pos: [2, 0, 0], 
      state: 0
    }, 
    {
      pos: [3, 0, 0], 
      state: 0
    }, 
    {
      pos: [4, 0, 0], 
      state: 0
    }, 
    {
      pos: [5, 0, 0], 
      state: 0
    }, 
    {
      pos: [6, 0, 0], 
      state: 0
    }, 
    {
      pos: [7, 0, 0], 
      state: 0
    }, 
    {
      pos: [8, 0, 0], 
      state: 0
    }, 
    {
      pos: [0, 0, 1], 
      state: 0
    }, 
    {
      pos: [1, 0, 1], 
      state: 0
    }, 
    {
      pos: [2, 0, 1], 
      state: 0
    }, 
    {
      pos: [3, 0, 1], 
      state: 0
    }, 
    {
      pos: [4, 0, 1], 
      state: 0
    }, 
    {
      pos: [5, 0, 1], 
      state: 0
    }, 
    {
      pos: [7, 0, 1], 
      state: 0
    }, 
    {
      pos: [8, 0, 1], 
      state: 0
    }, 
    {
      pos: [0, 0, 2], 
      state: 0
    }, 
    {
      pos: [1, 0, 2], 
      state: 0
    }, 
    {
      pos: [3, 0, 2], 
      state: 0
    }, 
    {
      pos: [4, 0, 2], 
      state: 0
    }, 
    {
      pos: [5, 0, 2], 
      state: 0
    }, 
    {
      pos: [6, 0, 2], 
      state: 0
    }, 
    {
      pos: [7, 0, 2], 
      state: 0
    }, 
    {
      pos: [8, 0, 2], 
      state: 0
    }, 
    {
      pos: [0, 0, 3], 
      state: 0
    }, 
    {
      pos: [1, 0, 3], 
      state: 0
    }, 
    {
      pos: [2, 0, 3], 
      state: 0
    }, 
    {
      pos: [3, 0, 3], 
      state: 1
    }, 
    {
      pos: [4, 0, 3], 
      state: 0
    }, 
    {
      pos: [5, 0, 3], 
      state: 0
    }, 
    {
      pos: [6, 0, 3], 
      state: 0
    }, 
    {
      pos: [7, 0, 3], 
      state: 0
    }, 
    {
      pos: [8, 0, 3], 
      state: 0
    }, 
    {
      pos: [0, 0, 4], 
      state: 0
    }, 
    {
      pos: [1, 0, 4], 
      state: 0
    }, 
    {
      pos: [2, 0, 4], 
      state: 0
    }, 
    {
      pos: [3, 0, 4], 
      state: 0
    }, 
    {
      pos: [4, 0, 4], 
      state: 0
    }, 
    {
      pos: [5, 0, 4], 
      state: 0
    }, 
    {
      pos: [6, 0, 4], 
      state: 0
    }, 
    {
      pos: [7, 0, 4], 
      state: 0
    }, 
    {
      pos: [8, 0, 4], 
      state: 0
    }, 
    {
      pos: [0, 0, 5], 
      state: 0
    }, 
    {
      pos: [1, 0, 5], 
      state: 0
    }, 
    {
      pos: [2, 0, 5], 
      state: 1
    }, 
    {
      pos: [3, 0, 5], 
      state: 0
    }, 
    {
      pos: [4, 0, 5], 
      state: 0
    }, 
    {
      pos: [5, 0, 5], 
      state: 1
    }, 
    {
      pos: [6, 0, 5], 
      state: 1
    }, 
    {
      pos: [7, 0, 5], 
      state: 0
    }, 
    {
      pos: [8, 0, 5], 
      state: 0
    }, 
    {
      pos: [2, 0, 6], 
      state: 1
    }, 
    {
      pos: [3, 0, 6], 
      state: 0
    }, 
    {
      pos: [4, 0, 6], 
      state: 0
    }, 
    {
      pos: [5, 0, 6], 
      state: 0
    }, 
    {
      pos: [6, 0, 6], 
      state: 1
    }, 
    {
      pos: [2, 0, 7], 
      state: 0
    }, 
    {
      pos: [3, 0, 7], 
      state: 0
    }, 
    {
      pos: [4, 0, 7], 
      state: 0
    }, 
    {
      pos: [5, 0, 7], 
      state: 0
    }, 
    {
      pos: [6, 0, 7], 
      state: 1
    }, 
    {
      pos: [2, 0, 8], 
      state: 1
    }, 
    {
      pos: [3, 0, 8], 
      state: 1
    }, 
    {
      pos: [4, 0, 8], 
      state: 0
    }, 
    {
      pos: [5, 0, 8], 
      state: 0
    }, 
    {
      pos: [6, 0, 8], 
      state: 1
    }, 
    {
      pos: [2, 0, 9], 
      state: 1
    }, 
    {
      pos: [3, 0, 9], 
      state: 1
    }, 
    {
      pos: [4, 0, 9], 
      state: 0
    }, 
    {
      pos: [5, 0, 9], 
      state: 0
    }, 
    {
      pos: [6, 0, 9], 
      state: 1
    }, 
    {
      pos: [2, 0, 10], 
      state: 1
    }, 
    {
      pos: [3, 0, 10], 
      state: 0
    }, 
    {
      pos: [5, 0, 10], 
      state: 0
    }, 
    {
      pos: [6, 0, 10], 
      state: 1
    }, 
    {
      pos: [2, 0, 11], 
      state: 1
    }, 
    {
      pos: [3, 0, 11], 
      state: 0
    }, 
    {
      pos: [4, 0, 11], 
      state: 0
    }, 
    {
      pos: [5, 0, 11], 
      state: 0
    }, 
    {
      pos: [6, 0, 11], 
      state: 1
    }, 
    {
      pos: [2, 0, 12], 
      state: 1
    }, 
    {
      pos: [3, 0, 12], 
      state: 1
    }, 
    {
      pos: [4, 0, 12], 
      state: 1
    }, 
    {
      pos: [5, 0, 12], 
      state: 1
    }, 
    {
      pos: [6, 0, 12], 
      state: 1
    }, 
    {
      pos: [2, 0, 13], 
      state: 1
    }, 
    {
      pos: [3, 0, 13], 
      state: 0
    }, 
    {
      pos: [4, 0, 13], 
      state: 0
    }, 
    {
      pos: [5, 0, 13], 
      state: 0
    }, 
    {
      pos: [6, 0, 13], 
      state: 1
    }, 
    {
      pos: [2, 0, 14], 
      state: 1
    }, 
    {
      pos: [3, 0, 14], 
      state: 1
    }, 
    {
      pos: [4, 0, 14], 
      state: 1
    }, 
    {
      pos: [5, 0, 14], 
      state: 1
    }, 
    {
      pos: [6, 0, 14], 
      state: 1
    }, 
    {
      nbt: {
        target_pool: "minecraft:village/plains/decor", 
        final_state: "minecraft:dirt", 
        id: "minecraft:jigsaw", 
        attachement_type: "minecraft:bottom"
      }, 
      pos: [6, 0, 1], 
      state: 2
    }, 
    {
      nbt: {
        target_pool: "minecraft:village/common/animals", 
        final_state: "minecraft:dirt", 
        id: "minecraft:jigsaw", 
        attachement_type: "minecraft:bottom"
      }, 
      pos: [2, 0, 2], 
      state: 2
    }, 
    {
      nbt: {
        target_pool: "minecraft:village/common/cats", 
        final_state: "minecraft:grass_block", 
        id: "minecraft:jigsaw", 
        attachement_type: "minecraft:bottom"
      }, 
      pos: [7, 0, 7], 
      state: 2
    }, 
    {
      nbt: {
        target_pool: "minecraft:village/common/animals", 
        final_state: "minecraft:dirt", 
        id: "minecraft:jigsaw", 
        attachement_type: "minecraft:bottom"
      }, 
      pos: [4, 0, 10], 
      state: 2
    }, 
    {
      nbt: {
        target_pool: "minecraft:village/plains/decor", 
        final_state: "minecraft:dirt", 
        id: "minecraft:jigsaw", 
        attachement_type: "minecraft:bottom"
      }, 
      pos: [0, 0, 11], 
      state: 2
    }, 
    {
      nbt: {
        target_pool: "minecraft:village/common/cats", 
        final_state: "minecraft:grass_block", 
        id: "minecraft:jigsaw", 
        attachement_type: "minecraft:bottom"
      }, 
      pos: [7, 0, 14], 
      state: 2
    }, 
    {
      nbt: {
        target_pool: "minecraft:village/plains/decor", 
        final_state: "minecraft:dirt", 
        id: "minecraft:jigsaw", 
        attachement_type: "minecraft:bottom"
      }, 
      pos: [0, 0, 15], 
      state: 2
    }, 
    {
      pos: [0, 0, 7], 
      state: 3
    }, 
    {
      pos: [1, 0, 7], 
      state: 3
    }, 
    {
      pos: [3, 1, 3], 
      state: 4
    }, 
    {
      pos: [2, 1, 5], 
      state: 5
    }, 
    {
      pos: [5, 1, 5], 
      state: 4
    }, 
    {
      pos: [6, 1, 5], 
      state: 5
    }, 
    {
      pos: [2, 1, 6], 
      state: 5
    }, 
    {
      pos: [6, 1, 6], 
      state: 5
    }, 
    {
      pos: [6, 1, 7], 
      state: 5
    }, 
    {
      pos: [2, 1, 8], 
      state: 5
    }, 
    {
      pos: [3, 1, 8], 
      state: 4
    }, 
    {
      pos: [6, 1, 8], 
      state: 5
    }, 
    {
      pos: [2, 1, 9], 
      state: 5
    }, 
    {
      pos: [3, 1, 9], 
      state: 4
    }, 
    {
      pos: [6, 1, 9], 
      state: 5
    }, 
    {
      pos: [2, 1, 10], 
      state: 5
    }, 
    {
      pos: [6, 1, 10], 
      state: 5
    }, 
    {
      pos: [2, 1, 11], 
      state: 5
    }, 
    {
      pos: [6, 1, 11], 
      state: 5
    }, 
    {
      pos: [2, 1, 12], 
      state: 5
    }, 
    {
      pos: [3, 1, 12], 
      state: 6
    }, 
    {
      pos: [4, 1, 12], 
      state: 6
    }, 
    {
      pos: [5, 1, 12], 
      state: 6
    }, 
    {
      pos: [6, 1, 12], 
      state: 5
    }, 
    {
      pos: [2, 1, 13], 
      state: 5
    }, 
    {
      pos: [6, 1, 13], 
      state: 5
    }, 
    {
      pos: [2, 1, 14], 
      state: 5
    }, 
    {
      pos: [3, 1, 14], 
      state: 5
    }, 
    {
      pos: [4, 1, 14], 
      state: 5
    }, 
    {
      pos: [5, 1, 14], 
      state: 5
    }, 
    {
      pos: [6, 1, 14], 
      state: 5
    }, 
    {
      nbt: {
        target_pool: "minecraft:village/plains/streets", 
        final_state: "minecraft:structure_void", 
        id: "minecraft:jigsaw", 
        attachement_type: "minecraft:building_entrance"
      }, 
      pos: [0, 1, 8], 
      state: 7
    }, 
    {
      pos: [0, 1, 0], 
      state: 8
    }, 
    {
      pos: [1, 1, 0], 
      state: 9
    }, 
    {
      pos: [2, 1, 0], 
      state: 9
    }, 
    {
      pos: [3, 1, 0], 
      state: 9
    }, 
    {
      pos: [4, 1, 0], 
      state: 9
    }, 
    {
      pos: [5, 1, 0], 
      state: 9
    }, 
    {
      pos: [6, 1, 0], 
      state: 9
    }, 
    {
      pos: [7, 1, 0], 
      state: 9
    }, 
    {
      pos: [8, 1, 0], 
      state: 10
    }, 
    {
      pos: [0, 1, 1], 
      state: 11
    }, 
    {
      pos: [1, 1, 1], 
      state: 12
    }, 
    {
      pos: [2, 1, 1], 
      state: 12
    }, 
    {
      pos: [3, 1, 1], 
      state: 12
    }, 
    {
      pos: [4, 1, 1], 
      state: 12
    }, 
    {
      pos: [5, 1, 1], 
      state: 12
    }, 
    {
      pos: [6, 1, 1], 
      state: 12
    }, 
    {
      pos: [7, 1, 1], 
      state: 12
    }, 
    {
      pos: [8, 1, 1], 
      state: 11
    }, 
    {
      pos: [0, 1, 2], 
      state: 11
    }, 
    {
      pos: [1, 1, 2], 
      state: 12
    }, 
    {
      pos: [2, 1, 2], 
      state: 12
    }, 
    {
      pos: [3, 1, 2], 
      state: 12
    }, 
    {
      pos: [4, 1, 2], 
      state: 12
    }, 
    {
      pos: [5, 1, 2], 
      state: 12
    }, 
    {
      pos: [6, 1, 2], 
      state: 12
    }, 
    {
      pos: [7, 1, 2], 
      state: 12
    }, 
    {
      pos: [8, 1, 2], 
      state: 11
    }, 
    {
      pos: [0, 1, 3], 
      state: 11
    }, 
    {
      pos: [1, 1, 3], 
      state: 12
    }, 
    {
      pos: [2, 1, 3], 
      state: 12
    }, 
    {
      pos: [4, 1, 3], 
      state: 12
    }, 
    {
      pos: [5, 1, 3], 
      state: 12
    }, 
    {
      pos: [6, 1, 3], 
      state: 12
    }, 
    {
      pos: [7, 1, 3], 
      state: 12
    }, 
    {
      pos: [8, 1, 3], 
      state: 11
    }, 
    {
      pos: [0, 1, 4], 
      state: 11
    }, 
    {
      pos: [1, 1, 4], 
      state: 12
    }, 
    {
      pos: [2, 1, 4], 
      state: 12
    }, 
    {
      pos: [3, 1, 4], 
      state: 12
    }, 
    {
      pos: [4, 1, 4], 
      state: 12
    }, 
    {
      pos: [5, 1, 4], 
      state: 12
    }, 
    {
      pos: [6, 1, 4], 
      state: 12
    }, 
    {
      pos: [7, 1, 4], 
      state: 12
    }, 
    {
      pos: [8, 1, 4], 
      state: 11
    }, 
    {
      pos: [0, 1, 5], 
      state: 13
    }, 
    {
      pos: [1, 1, 5], 
      state: 9
    }, 
    {
      pos: [3, 1, 5], 
      state: 12
    }, 
    {
      pos: [4, 1, 5], 
      state: 12
    }, 
    {
      pos: [7, 1, 5], 
      state: 9
    }, 
    {
      pos: [8, 1, 5], 
      state: 14
    }, 
    {
      pos: [0, 1, 6], 
      state: 12
    }, 
    {
      pos: [1, 1, 6], 
      state: 12
    }, 
    {
      pos: [3, 1, 6], 
      state: 12
    }, 
    {
      pos: [4, 1, 6], 
      state: 12
    }, 
    {
      pos: [5, 1, 6], 
      state: 12
    }, 
    {
      pos: [7, 1, 6], 
      state: 12
    }, 
    {
      pos: [8, 1, 6], 
      state: 12
    }, 
    {
      pos: [0, 1, 7], 
      state: 12
    }, 
    {
      pos: [1, 1, 7], 
      state: 12
    }, 
    {
      pos: [2, 1, 7], 
      state: 15
    }, 
    {
      pos: [3, 1, 7], 
      state: 12
    }, 
    {
      pos: [4, 1, 7], 
      state: 12
    }, 
    {
      pos: [5, 1, 7], 
      state: 12
    }, 
    {
      pos: [7, 1, 7], 
      state: 12
    }, 
    {
      pos: [8, 1, 7], 
      state: 12
    }, 
    {
      pos: [1, 1, 8], 
      state: 12
    }, 
    {
      pos: [4, 1, 8], 
      state: 12
    }, 
    {
      pos: [5, 1, 8], 
      state: 12
    }, 
    {
      pos: [7, 1, 8], 
      state: 12
    }, 
    {
      pos: [8, 1, 8], 
      state: 12
    }, 
    {
      pos: [0, 1, 9], 
      state: 12
    }, 
    {
      pos: [1, 1, 9], 
      state: 12
    }, 
    {
      pos: [4, 1, 9], 
      state: 12
    }, 
    {
      pos: [5, 1, 9], 
      state: 12
    }, 
    {
      pos: [7, 1, 9], 
      state: 12
    }, 
    {
      pos: [8, 1, 9], 
      state: 12
    }, 
    {
      pos: [0, 1, 10], 
      state: 12
    }, 
    {
      pos: [1, 1, 10], 
      state: 12
    }, 
    {
      pos: [3, 1, 10], 
      state: 12
    }, 
    {
      pos: [4, 1, 10], 
      state: 12
    }, 
    {
      pos: [5, 1, 10], 
      state: 12
    }, 
    {
      pos: [7, 1, 10], 
      state: 12
    }, 
    {
      pos: [8, 1, 10], 
      state: 12
    }, 
    {
      pos: [0, 1, 11], 
      state: 12
    }, 
    {
      pos: [1, 1, 11], 
      state: 12
    }, 
    {
      pos: [3, 1, 11], 
      state: 12
    }, 
    {
      pos: [4, 1, 11], 
      state: 12
    }, 
    {
      pos: [5, 1, 11], 
      state: 12
    }, 
    {
      pos: [7, 1, 11], 
      state: 12
    }, 
    {
      pos: [8, 1, 11], 
      state: 12
    }, 
    {
      pos: [0, 1, 12], 
      state: 12
    }, 
    {
      pos: [1, 1, 12], 
      state: 12
    }, 
    {
      pos: [7, 1, 12], 
      state: 12
    }, 
    {
      pos: [8, 1, 12], 
      state: 12
    }, 
    {
      pos: [0, 1, 13], 
      state: 12
    }, 
    {
      pos: [1, 1, 13], 
      state: 12
    }, 
    {
      pos: [3, 1, 13], 
      state: 16
    }, 
    {
      pos: [4, 1, 13], 
      state: 16
    }, 
    {
      pos: [5, 1, 13], 
      state: 16
    }, 
    {
      pos: [7, 1, 13], 
      state: 12
    }, 
    {
      pos: [8, 1, 13], 
      state: 12
    }, 
    {
      pos: [0, 1, 14], 
      state: 12
    }, 
    {
      pos: [1, 1, 14], 
      state: 12
    }, 
    {
      pos: [7, 1, 14], 
      state: 12
    }, 
    {
      pos: [8, 1, 14], 
      state: 12
    }, 
    {
      pos: [0, 1, 15], 
      state: 12
    }, 
    {
      pos: [1, 1, 15], 
      state: 12
    }, 
    {
      pos: [2, 1, 15], 
      state: 12
    }, 
    {
      pos: [3, 1, 15], 
      state: 12
    }, 
    {
      pos: [4, 1, 15], 
      state: 12
    }, 
    {
      pos: [5, 1, 15], 
      state: 12
    }, 
    {
      pos: [6, 1, 15], 
      state: 12
    }, 
    {
      pos: [7, 1, 15], 
      state: 12
    }, 
    {
      pos: [8, 1, 15], 
      state: 12
    }, 
    {
      pos: [2, 2, 5], 
      state: 5
    }, 
    {
      pos: [6, 2, 5], 
      state: 5
    }, 
    {
      pos: [2, 2, 6], 
      state: 5
    }, 
    {
      pos: [6, 2, 6], 
      state: 5
    }, 
    {
      pos: [6, 2, 7], 
      state: 5
    }, 
    {
      pos: [2, 2, 8], 
      state: 5
    }, 
    {
      pos: [3, 2, 8], 
      state: 4
    }, 
    {
      pos: [6, 2, 8], 
      state: 17
    }, 
    {
      pos: [2, 2, 9], 
      state: 17
    }, 
    {
      pos: [6, 2, 10], 
      state: 17
    }, 
    {
      pos: [2, 2, 11], 
      state: 17
    }, 
    {
      pos: [6, 2, 12], 
      state: 17
    }, 
    {
      pos: [2, 2, 13], 
      state: 17
    }, 
    {
      pos: [6, 2, 13], 
      state: 5
    }, 
    {
      pos: [2, 2, 14], 
      state: 5
    }, 
    {
      pos: [3, 2, 14], 
      state: 6
    }, 
    {
      pos: [5, 2, 14], 
      state: 6
    }, 
    {
      pos: [6, 2, 14], 
      state: 5
    }, 
    {
      pos: [0, 2, 0], 
      state: 18
    }, 
    {
      pos: [1, 2, 0], 
      state: 12
    }, 
    {
      pos: [2, 2, 0], 
      state: 12
    }, 
    {
      pos: [3, 2, 0], 
      state: 12
    }, 
    {
      pos: [4, 2, 0], 
      state: 12
    }, 
    {
      pos: [5, 2, 0], 
      state: 12
    }, 
    {
      pos: [6, 2, 0], 
      state: 12
    }, 
    {
      pos: [7, 2, 0], 
      state: 12
    }, 
    {
      pos: [8, 2, 0], 
      state: 18
    }, 
    {
      pos: [0, 2, 1], 
      state: 12
    }, 
    {
      pos: [1, 2, 1], 
      state: 12
    }, 
    {
      pos: [2, 2, 1], 
      state: 12
    }, 
    {
      pos: [3, 2, 1], 
      state: 12
    }, 
    {
      pos: [4, 2, 1], 
      state: 12
    }, 
    {
      pos: [5, 2, 1], 
      state: 12
    }, 
    {
      pos: [6, 2, 1], 
      state: 12
    }, 
    {
      pos: [7, 2, 1], 
      state: 12
    }, 
    {
      pos: [8, 2, 1], 
      state: 12
    }, 
    {
      pos: [0, 2, 2], 
      state: 12
    }, 
    {
      pos: [1, 2, 2], 
      state: 12
    }, 
    {
      pos: [2, 2, 2], 
      state: 12
    }, 
    {
      pos: [3, 2, 2], 
      state: 12
    }, 
    {
      pos: [4, 2, 2], 
      state: 12
    }, 
    {
      pos: [5, 2, 2], 
      state: 12
    }, 
    {
      pos: [6, 2, 2], 
      state: 12
    }, 
    {
      pos: [7, 2, 2], 
      state: 12
    }, 
    {
      pos: [8, 2, 2], 
      state: 12
    }, 
    {
      pos: [0, 2, 3], 
      state: 12
    }, 
    {
      pos: [1, 2, 3], 
      state: 12
    }, 
    {
      pos: [2, 2, 3], 
      state: 12
    }, 
    {
      pos: [3, 2, 3], 
      state: 12
    }, 
    {
      pos: [4, 2, 3], 
      state: 12
    }, 
    {
      pos: [5, 2, 3], 
      state: 12
    }, 
    {
      pos: [6, 2, 3], 
      state: 12
    }, 
    {
      pos: [7, 2, 3], 
      state: 12
    }, 
    {
      pos: [8, 2, 3], 
      state: 12
    }, 
    {
      pos: [0, 2, 4], 
      state: 12
    }, 
    {
      pos: [1, 2, 4], 
      state: 12
    }, 
    {
      pos: [2, 2, 4], 
      state: 12
    }, 
    {
      pos: [3, 2, 4], 
      state: 12
    }, 
    {
      pos: [4, 2, 4], 
      state: 12
    }, 
    {
      pos: [5, 2, 4], 
      state: 12
    }, 
    {
      pos: [6, 2, 4], 
      state: 12
    }, 
    {
      pos: [7, 2, 4], 
      state: 12
    }, 
    {
      pos: [8, 2, 4], 
      state: 12
    }, 
    {
      pos: [0, 2, 5], 
      state: 18
    }, 
    {
      pos: [1, 2, 5], 
      state: 12
    }, 
    {
      pos: [3, 2, 5], 
      state: 12
    }, 
    {
      pos: [4, 2, 5], 
      state: 12
    }, 
    {
      pos: [5, 2, 5], 
      state: 12
    }, 
    {
      pos: [7, 2, 5], 
      state: 12
    }, 
    {
      pos: [8, 2, 5], 
      state: 18
    }, 
    {
      pos: [0, 2, 6], 
      state: 12
    }, 
    {
      pos: [1, 2, 6], 
      state: 12
    }, 
    {
      pos: [3, 2, 6], 
      state: 12
    }, 
    {
      pos: [4, 2, 6], 
      state: 12
    }, 
    {
      pos: [5, 2, 6], 
      state: 12
    }, 
    {
      pos: [7, 2, 6], 
      state: 12
    }, 
    {
      pos: [8, 2, 6], 
      state: 12
    }, 
    {
      pos: [0, 2, 7], 
      state: 12
    }, 
    {
      pos: [1, 2, 7], 
      state: 12
    }, 
    {
      pos: [2, 2, 7], 
      state: 19
    }, 
    {
      pos: [3, 2, 7], 
      state: 12
    }, 
    {
      pos: [4, 2, 7], 
      state: 12
    }, 
    {
      pos: [5, 2, 7], 
      state: 12
    }, 
    {
      pos: [7, 2, 7], 
      state: 12
    }, 
    {
      pos: [8, 2, 7], 
      state: 12
    }, 
    {
      pos: [0, 2, 8], 
      state: 12
    }, 
    {
      pos: [1, 2, 8], 
      state: 12
    }, 
    {
      pos: [4, 2, 8], 
      state: 12
    }, 
    {
      pos: [5, 2, 8], 
      state: 12
    }, 
    {
      pos: [7, 2, 8], 
      state: 12
    }, 
    {
      pos: [8, 2, 8], 
      state: 12
    }, 
    {
      pos: [0, 2, 9], 
      state: 12
    }, 
    {
      pos: [1, 2, 9], 
      state: 12
    }, 
    {
      pos: [3, 2, 9], 
      state: 12
    }, 
    {
      pos: [4, 2, 9], 
      state: 12
    }, 
    {
      pos: [5, 2, 9], 
      state: 12
    }, 
    {
      pos: [6, 2, 9], 
      state: 20
    }, 
    {
      pos: [7, 2, 9], 
      state: 12
    }, 
    {
      pos: [8, 2, 9], 
      state: 12
    }, 
    {
      pos: [0, 2, 10], 
      state: 12
    }, 
    {
      pos: [1, 2, 10], 
      state: 12
    }, 
    {
      pos: [2, 2, 10], 
      state: 20
    }, 
    {
      pos: [3, 2, 10], 
      state: 12
    }, 
    {
      pos: [4, 2, 10], 
      state: 12
    }, 
    {
      pos: [5, 2, 10], 
      state: 12
    }, 
    {
      pos: [7, 2, 10], 
      state: 12
    }, 
    {
      pos: [8, 2, 10], 
      state: 12
    }, 
    {
      pos: [0, 2, 11], 
      state: 12
    }, 
    {
      pos: [1, 2, 11], 
      state: 12
    }, 
    {
      pos: [3, 2, 11], 
      state: 12
    }, 
    {
      pos: [4, 2, 11], 
      state: 12
    }, 
    {
      pos: [5, 2, 11], 
      state: 12
    }, 
    {
      pos: [6, 2, 11], 
      state: 20
    }, 
    {
      pos: [7, 2, 11], 
      state: 12
    }, 
    {
      pos: [8, 2, 11], 
      state: 12
    }, 
    {
      pos: [0, 2, 12], 
      state: 12
    }, 
    {
      pos: [1, 2, 12], 
      state: 12
    }, 
    {
      pos: [2, 2, 12], 
      state: 20
    }, 
    {
      pos: [3, 2, 12], 
      state: 12
    }, 
    {
      pos: [4, 2, 12], 
      state: 12
    }, 
    {
      pos: [5, 2, 12], 
      state: 12
    }, 
    {
      pos: [7, 2, 12], 
      state: 12
    }, 
    {
      pos: [8, 2, 12], 
      state: 12
    }, 
    {
      pos: [0, 2, 13], 
      state: 12
    }, 
    {
      pos: [1, 2, 13], 
      state: 12
    }, 
    {
      pos: [3, 2, 13], 
      state: 12
    }, 
    {
      pos: [4, 2, 13], 
      state: 12
    }, 
    {
      pos: [5, 2, 13], 
      state: 12
    }, 
    {
      pos: [7, 2, 13], 
      state: 12
    }, 
    {
      pos: [8, 2, 13], 
      state: 12
    }, 
    {
      pos: [0, 2, 14], 
      state: 12
    }, 
    {
      pos: [1, 2, 14], 
      state: 12
    }, 
    {
      pos: [4, 2, 14], 
      state: 21
    }, 
    {
      pos: [7, 2, 14], 
      state: 12
    }, 
    {
      pos: [8, 2, 14], 
      state: 12
    }, 
    {
      pos: [0, 2, 15], 
      state: 12
    }, 
    {
      pos: [1, 2, 15], 
      state: 12
    }, 
    {
      pos: [2, 2, 15], 
      state: 12
    }, 
    {
      pos: [3, 2, 15], 
      state: 12
    }, 
    {
      pos: [4, 2, 15], 
      state: 12
    }, 
    {
      pos: [5, 2, 15], 
      state: 12
    }, 
    {
      pos: [6, 2, 15], 
      state: 12
    }, 
    {
      pos: [7, 2, 15], 
      state: 12
    }, 
    {
      pos: [8, 2, 15], 
      state: 12
    }, 
    {
      pos: [2, 3, 5], 
      state: 5
    }, 
    {
      pos: [6, 3, 5], 
      state: 5
    }, 
    {
      pos: [2, 3, 6], 
      state: 5
    }, 
    {
      pos: [6, 3, 6], 
      state: 5
    }, 
    {
      pos: [2, 3, 7], 
      state: 5
    }, 
    {
      pos: [6, 3, 7], 
      state: 5
    }, 
    {
      pos: [2, 3, 8], 
      state: 5
    }, 
    {
      pos: [6, 3, 8], 
      state: 5
    }, 
    {
      pos: [2, 3, 9], 
      state: 5
    }, 
    {
      pos: [6, 3, 9], 
      state: 5
    }, 
    {
      pos: [2, 3, 10], 
      state: 5
    }, 
    {
      pos: [6, 3, 10], 
      state: 5
    }, 
    {
      pos: [2, 3, 11], 
      state: 5
    }, 
    {
      pos: [6, 3, 11], 
      state: 5
    }, 
    {
      pos: [2, 3, 12], 
      state: 5
    }, 
    {
      pos: [6, 3, 12], 
      state: 5
    }, 
    {
      pos: [2, 3, 13], 
      state: 5
    }, 
    {
      pos: [6, 3, 13], 
      state: 5
    }, 
    {
      pos: [2, 3, 14], 
      state: 5
    }, 
    {
      pos: [3, 3, 14], 
      state: 5
    }, 
    {
      pos: [4, 3, 14], 
      state: 5
    }, 
    {
      pos: [5, 3, 14], 
      state: 5
    }, 
    {
      pos: [6, 3, 14], 
      state: 5
    }, 
    {
      pos: [0, 3, 0], 
      state: 12
    }, 
    {
      pos: [1, 3, 0], 
      state: 12
    }, 
    {
      pos: [2, 3, 0], 
      state: 12
    }, 
    {
      pos: [3, 3, 0], 
      state: 12
    }, 
    {
      pos: [4, 3, 0], 
      state: 12
    }, 
    {
      pos: [5, 3, 0], 
      state: 12
    }, 
    {
      pos: [6, 3, 0], 
      state: 12
    }, 
    {
      pos: [7, 3, 0], 
      state: 12
    }, 
    {
      pos: [8, 3, 0], 
      state: 12
    }, 
    {
      pos: [0, 3, 1], 
      state: 12
    }, 
    {
      pos: [1, 3, 1], 
      state: 12
    }, 
    {
      pos: [2, 3, 1], 
      state: 12
    }, 
    {
      pos: [3, 3, 1], 
      state: 12
    }, 
    {
      pos: [4, 3, 1], 
      state: 12
    }, 
    {
      pos: [5, 3, 1], 
      state: 12
    }, 
    {
      pos: [6, 3, 1], 
      state: 12
    }, 
    {
      pos: [7, 3, 1], 
      state: 12
    }, 
    {
      pos: [8, 3, 1], 
      state: 12
    }, 
    {
      pos: [0, 3, 2], 
      state: 12
    }, 
    {
      pos: [1, 3, 2], 
      state: 12
    }, 
    {
      pos: [2, 3, 2], 
      state: 12
    }, 
    {
      pos: [3, 3, 2], 
      state: 12
    }, 
    {
      pos: [4, 3, 2], 
      state: 12
    }, 
    {
      pos: [5, 3, 2], 
      state: 12
    }, 
    {
      pos: [6, 3, 2], 
      state: 12
    }, 
    {
      pos: [7, 3, 2], 
      state: 12
    }, 
    {
      pos: [8, 3, 2], 
      state: 12
    }, 
    {
      pos: [0, 3, 3], 
      state: 12
    }, 
    {
      pos: [1, 3, 3], 
      state: 12
    }, 
    {
      pos: [2, 3, 3], 
      state: 12
    }, 
    {
      pos: [3, 3, 3], 
      state: 12
    }, 
    {
      pos: [4, 3, 3], 
      state: 12
    }, 
    {
      pos: [5, 3, 3], 
      state: 12
    }, 
    {
      pos: [6, 3, 3], 
      state: 12
    }, 
    {
      pos: [7, 3, 3], 
      state: 12
    }, 
    {
      pos: [8, 3, 3], 
      state: 12
    }, 
    {
      pos: [0, 3, 4], 
      state: 12
    }, 
    {
      pos: [1, 3, 4], 
      state: 12
    }, 
    {
      pos: [2, 3, 4], 
      state: 12
    }, 
    {
      pos: [3, 3, 4], 
      state: 12
    }, 
    {
      pos: [4, 3, 4], 
      state: 12
    }, 
    {
      pos: [5, 3, 4], 
      state: 12
    }, 
    {
      pos: [6, 3, 4], 
      state: 12
    }, 
    {
      pos: [7, 3, 4], 
      state: 12
    }, 
    {
      pos: [8, 3, 4], 
      state: 12
    }, 
    {
      pos: [0, 3, 5], 
      state: 12
    }, 
    {
      pos: [1, 3, 5], 
      state: 12
    }, 
    {
      pos: [3, 3, 5], 
      state: 22
    }, 
    {
      pos: [4, 3, 5], 
      state: 12
    }, 
    {
      pos: [5, 3, 5], 
      state: 23
    }, 
    {
      pos: [7, 3, 5], 
      state: 12
    }, 
    {
      pos: [8, 3, 5], 
      state: 12
    }, 
    {
      pos: [0, 3, 6], 
      state: 12
    }, 
    {
      pos: [1, 3, 6], 
      state: 12
    }, 
    {
      pos: [3, 3, 6], 
      state: 12
    }, 
    {
      pos: [4, 3, 6], 
      state: 12
    }, 
    {
      pos: [5, 3, 6], 
      state: 12
    }, 
    {
      pos: [7, 3, 6], 
      state: 12
    }, 
    {
      pos: [8, 3, 6], 
      state: 12
    }, 
    {
      pos: [0, 3, 7], 
      state: 12
    }, 
    {
      pos: [1, 3, 7], 
      state: 12
    }, 
    {
      pos: [3, 3, 7], 
      state: 12
    }, 
    {
      pos: [4, 3, 7], 
      state: 12
    }, 
    {
      pos: [5, 3, 7], 
      state: 12
    }, 
    {
      pos: [7, 3, 7], 
      state: 12
    }, 
    {
      pos: [8, 3, 7], 
      state: 12
    }, 
    {
      pos: [0, 3, 8], 
      state: 12
    }, 
    {
      pos: [1, 3, 8], 
      state: 12
    }, 
    {
      pos: [3, 3, 8], 
      state: 12
    }, 
    {
      pos: [4, 3, 8], 
      state: 12
    }, 
    {
      pos: [5, 3, 8], 
      state: 12
    }, 
    {
      pos: [7, 3, 8], 
      state: 12
    }, 
    {
      pos: [8, 3, 8], 
      state: 12
    }, 
    {
      pos: [0, 3, 9], 
      state: 12
    }, 
    {
      pos: [1, 3, 9], 
      state: 12
    }, 
    {
      pos: [3, 3, 9], 
      state: 12
    }, 
    {
      pos: [4, 3, 9], 
      state: 12
    }, 
    {
      pos: [5, 3, 9], 
      state: 12
    }, 
    {
      pos: [7, 3, 9], 
      state: 12
    }, 
    {
      pos: [8, 3, 9], 
      state: 12
    }, 
    {
      pos: [0, 3, 10], 
      state: 12
    }, 
    {
      pos: [1, 3, 10], 
      state: 12
    }, 
    {
      pos: [3, 3, 10], 
      state: 12
    }, 
    {
      pos: [4, 3, 10], 
      state: 12
    }, 
    {
      pos: [5, 3, 10], 
      state: 12
    }, 
    {
      pos: [7, 3, 10], 
      state: 12
    }, 
    {
      pos: [8, 3, 10], 
      state: 12
    }, 
    {
      pos: [0, 3, 11], 
      state: 12
    }, 
    {
      pos: [1, 3, 11], 
      state: 12
    }, 
    {
      pos: [3, 3, 11], 
      state: 12
    }, 
    {
      pos: [4, 3, 11], 
      state: 12
    }, 
    {
      pos: [5, 3, 11], 
      state: 12
    }, 
    {
      pos: [7, 3, 11], 
      state: 12
    }, 
    {
      pos: [8, 3, 11], 
      state: 12
    }, 
    {
      pos: [0, 3, 12], 
      state: 12
    }, 
    {
      pos: [1, 3, 12], 
      state: 12
    }, 
    {
      pos: [3, 3, 12], 
      state: 12
    }, 
    {
      pos: [4, 3, 12], 
      state: 12
    }, 
    {
      pos: [5, 3, 12], 
      state: 12
    }, 
    {
      pos: [7, 3, 12], 
      state: 12
    }, 
    {
      pos: [8, 3, 12], 
      state: 12
    }, 
    {
      pos: [0, 3, 13], 
      state: 12
    }, 
    {
      pos: [1, 3, 13], 
      state: 12
    }, 
    {
      pos: [3, 3, 13], 
      state: 12
    }, 
    {
      pos: [4, 3, 13], 
      state: 12
    }, 
    {
      pos: [5, 3, 13], 
      state: 12
    }, 
    {
      pos: [7, 3, 13], 
      state: 12
    }, 
    {
      pos: [8, 3, 13], 
      state: 12
    }, 
    {
      pos: [0, 3, 14], 
      state: 12
    }, 
    {
      pos: [1, 3, 14], 
      state: 12
    }, 
    {
      pos: [7, 3, 14], 
      state: 12
    }, 
    {
      pos: [8, 3, 14], 
      state: 12
    }, 
    {
      pos: [0, 3, 15], 
      state: 12
    }, 
    {
      pos: [1, 3, 15], 
      state: 12
    }, 
    {
      pos: [2, 3, 15], 
      state: 12
    }, 
    {
      pos: [3, 3, 15], 
      state: 12
    }, 
    {
      pos: [4, 3, 15], 
      state: 12
    }, 
    {
      pos: [5, 3, 15], 
      state: 12
    }, 
    {
      pos: [6, 3, 15], 
      state: 12
    }, 
    {
      pos: [7, 3, 15], 
      state: 12
    }, 
    {
      pos: [8, 3, 15], 
      state: 12
    }, 
    {
      pos: [2, 4, 5], 
      state: 5
    }, 
    {
      pos: [3, 4, 5], 
      state: 5
    }, 
    {
      pos: [4, 4, 5], 
      state: 5
    }, 
    {
      pos: [5, 4, 5], 
      state: 5
    }, 
    {
      pos: [6, 4, 5], 
      state: 5
    }, 
    {
      pos: [2, 4, 6], 
      state: 5
    }, 
    {
      pos: [6, 4, 6], 
      state: 5
    }, 
    {
      pos: [2, 4, 7], 
      state: 5
    }, 
    {
      pos: [6, 4, 7], 
      state: 5
    }, 
    {
      pos: [2, 4, 8], 
      state: 5
    }, 
    {
      pos: [6, 4, 8], 
      state: 5
    }, 
    {
      pos: [2, 4, 9], 
      state: 5
    }, 
    {
      pos: [6, 4, 9], 
      state: 5
    }, 
    {
      pos: [2, 4, 10], 
      state: 5
    }, 
    {
      pos: [6, 4, 10], 
      state: 5
    }, 
    {
      pos: [2, 4, 11], 
      state: 5
    }, 
    {
      pos: [6, 4, 11], 
      state: 5
    }, 
    {
      pos: [2, 4, 12], 
      state: 5
    }, 
    {
      pos: [6, 4, 12], 
      state: 5
    }, 
    {
      pos: [2, 4, 13], 
      state: 5
    }, 
    {
      pos: [6, 4, 13], 
      state: 5
    }, 
    {
      pos: [2, 4, 14], 
      state: 5
    }, 
    {
      pos: [3, 4, 14], 
      state: 5
    }, 
    {
      pos: [4, 4, 14], 
      state: 5
    }, 
    {
      pos: [5, 4, 14], 
      state: 5
    }, 
    {
      pos: [6, 4, 14], 
      state: 5
    }, 
    {
      pos: [0, 4, 0], 
      state: 12
    }, 
    {
      pos: [1, 4, 0], 
      state: 12
    }, 
    {
      pos: [2, 4, 0], 
      state: 12
    }, 
    {
      pos: [3, 4, 0], 
      state: 12
    }, 
    {
      pos: [4, 4, 0], 
      state: 12
    }, 
    {
      pos: [5, 4, 0], 
      state: 12
    }, 
    {
      pos: [6, 4, 0], 
      state: 12
    }, 
    {
      pos: [7, 4, 0], 
      state: 12
    }, 
    {
      pos: [8, 4, 0], 
      state: 12
    }, 
    {
      pos: [0, 4, 1], 
      state: 12
    }, 
    {
      pos: [1, 4, 1], 
      state: 12
    }, 
    {
      pos: [2, 4, 1], 
      state: 12
    }, 
    {
      pos: [3, 4, 1], 
      state: 12
    }, 
    {
      pos: [4, 4, 1], 
      state: 12
    }, 
    {
      pos: [5, 4, 1], 
      state: 12
    }, 
    {
      pos: [6, 4, 1], 
      state: 12
    }, 
    {
      pos: [7, 4, 1], 
      state: 12
    }, 
    {
      pos: [8, 4, 1], 
      state: 12
    }, 
    {
      pos: [0, 4, 2], 
      state: 12
    }, 
    {
      pos: [1, 4, 2], 
      state: 12
    }, 
    {
      pos: [2, 4, 2], 
      state: 12
    }, 
    {
      pos: [3, 4, 2], 
      state: 12
    }, 
    {
      pos: [4, 4, 2], 
      state: 12
    }, 
    {
      pos: [5, 4, 2], 
      state: 12
    }, 
    {
      pos: [6, 4, 2], 
      state: 12
    }, 
    {
      pos: [7, 4, 2], 
      state: 12
    }, 
    {
      pos: [8, 4, 2], 
      state: 12
    }, 
    {
      pos: [0, 4, 3], 
      state: 12
    }, 
    {
      pos: [1, 4, 3], 
      state: 12
    }, 
    {
      pos: [2, 4, 3], 
      state: 12
    }, 
    {
      pos: [3, 4, 3], 
      state: 12
    }, 
    {
      pos: [4, 4, 3], 
      state: 12
    }, 
    {
      pos: [5, 4, 3], 
      state: 12
    }, 
    {
      pos: [6, 4, 3], 
      state: 12
    }, 
    {
      pos: [7, 4, 3], 
      state: 12
    }, 
    {
      pos: [8, 4, 3], 
      state: 12
    }, 
    {
      pos: [0, 4, 4], 
      state: 12
    }, 
    {
      pos: [1, 4, 4], 
      state: 24
    }, 
    {
      pos: [2, 4, 4], 
      state: 25
    }, 
    {
      pos: [3, 4, 4], 
      state: 12
    }, 
    {
      pos: [4, 4, 4], 
      state: 26
    }, 
    {
      pos: [5, 4, 4], 
      state: 12
    }, 
    {
      pos: [6, 4, 4], 
      state: 27
    }, 
    {
      pos: [7, 4, 4], 
      state: 28
    }, 
    {
      pos: [8, 4, 4], 
      state: 12
    }, 
    {
      pos: [0, 4, 5], 
      state: 12
    }, 
    {
      pos: [1, 4, 5], 
      state: 24
    }, 
    {
      pos: [7, 4, 5], 
      state: 28
    }, 
    {
      pos: [8, 4, 5], 
      state: 12
    }, 
    {
      pos: [0, 4, 6], 
      state: 12
    }, 
    {
      pos: [1, 4, 6], 
      state: 24
    }, 
    {
      pos: [3, 4, 6], 
      state: 12
    }, 
    {
      pos: [4, 4, 6], 
      state: 29
    }, 
    {
      pos: [5, 4, 6], 
      state: 12
    }, 
    {
      pos: [7, 4, 6], 
      state: 28
    }, 
    {
      pos: [8, 4, 6], 
      state: 12
    }, 
    {
      pos: [0, 4, 7], 
      state: 12
    }, 
    {
      pos: [1, 4, 7], 
      state: 24
    }, 
    {
      pos: [3, 4, 7], 
      state: 12
    }, 
    {
      pos: [4, 4, 7], 
      state: 12
    }, 
    {
      pos: [5, 4, 7], 
      state: 12
    }, 
    {
      pos: [7, 4, 7], 
      state: 28
    }, 
    {
      pos: [8, 4, 7], 
      state: 12
    }, 
    {
      pos: [0, 4, 8], 
      state: 12
    }, 
    {
      pos: [1, 4, 8], 
      state: 24
    }, 
    {
      pos: [3, 4, 8], 
      state: 12
    }, 
    {
      pos: [4, 4, 8], 
      state: 12
    }, 
    {
      pos: [5, 4, 8], 
      state: 12
    }, 
    {
      pos: [7, 4, 8], 
      state: 28
    }, 
    {
      pos: [8, 4, 8], 
      state: 12
    }, 
    {
      pos: [0, 4, 9], 
      state: 12
    }, 
    {
      pos: [1, 4, 9], 
      state: 24
    }, 
    {
      pos: [3, 4, 9], 
      state: 12
    }, 
    {
      pos: [4, 4, 9], 
      state: 12
    }, 
    {
      pos: [5, 4, 9], 
      state: 12
    }, 
    {
      pos: [7, 4, 9], 
      state: 28
    }, 
    {
      pos: [8, 4, 9], 
      state: 12
    }, 
    {
      pos: [0, 4, 10], 
      state: 12
    }, 
    {
      pos: [1, 4, 10], 
      state: 24
    }, 
    {
      pos: [3, 4, 10], 
      state: 30
    }, 
    {
      pos: [4, 4, 10], 
      state: 12
    }, 
    {
      pos: [5, 4, 10], 
      state: 31
    }, 
    {
      pos: [7, 4, 10], 
      state: 28
    }, 
    {
      pos: [8, 4, 10], 
      state: 12
    }, 
    {
      pos: [0, 4, 11], 
      state: 12
    }, 
    {
      pos: [1, 4, 11], 
      state: 24
    }, 
    {
      pos: [3, 4, 11], 
      state: 12
    }, 
    {
      pos: [4, 4, 11], 
      state: 12
    }, 
    {
      pos: [5, 4, 11], 
      state: 12
    }, 
    {
      pos: [7, 4, 11], 
      state: 28
    }, 
    {
      pos: [8, 4, 11], 
      state: 12
    }, 
    {
      pos: [0, 4, 12], 
      state: 12
    }, 
    {
      pos: [1, 4, 12], 
      state: 24
    }, 
    {
      pos: [3, 4, 12], 
      state: 12
    }, 
    {
      pos: [4, 4, 12], 
      state: 12
    }, 
    {
      pos: [5, 4, 12], 
      state: 12
    }, 
    {
      pos: [7, 4, 12], 
      state: 28
    }, 
    {
      pos: [8, 4, 12], 
      state: 12
    }, 
    {
      pos: [0, 4, 13], 
      state: 12
    }, 
    {
      pos: [1, 4, 13], 
      state: 24
    }, 
    {
      pos: [3, 4, 13], 
      state: 12
    }, 
    {
      pos: [4, 4, 13], 
      state: 26
    }, 
    {
      pos: [5, 4, 13], 
      state: 12
    }, 
    {
      pos: [7, 4, 13], 
      state: 28
    }, 
    {
      pos: [8, 4, 13], 
      state: 12
    }, 
    {
      pos: [0, 4, 14], 
      state: 12
    }, 
    {
      pos: [1, 4, 14], 
      state: 24
    }, 
    {
      pos: [7, 4, 14], 
      state: 28
    }, 
    {
      pos: [8, 4, 14], 
      state: 12
    }, 
    {
      pos: [0, 4, 15], 
      state: 12
    }, 
    {
      pos: [1, 4, 15], 
      state: 24
    }, 
    {
      pos: [2, 4, 15], 
      state: 25
    }, 
    {
      pos: [3, 4, 15], 
      state: 12
    }, 
    {
      pos: [4, 4, 15], 
      state: 12
    }, 
    {
      pos: [5, 4, 15], 
      state: 12
    }, 
    {
      pos: [6, 4, 15], 
      state: 27
    }, 
    {
      pos: [7, 4, 15], 
      state: 28
    }, 
    {
      pos: [8, 4, 15], 
      state: 12
    }, 
    {
      pos: [3, 5, 5], 
      state: 5
    }, 
    {
      pos: [4, 5, 5], 
      state: 5
    }, 
    {
      pos: [5, 5, 5], 
      state: 5
    }, 
    {
      pos: [3, 5, 14], 
      state: 5
    }, 
    {
      pos: [4, 5, 14], 
      state: 5
    }, 
    {
      pos: [5, 5, 14], 
      state: 5
    }, 
    {
      pos: [0, 5, 0], 
      state: 12
    }, 
    {
      pos: [1, 5, 0], 
      state: 12
    }, 
    {
      pos: [2, 5, 0], 
      state: 12
    }, 
    {
      pos: [3, 5, 0], 
      state: 12
    }, 
    {
      pos: [4, 5, 0], 
      state: 12
    }, 
    {
      pos: [5, 5, 0], 
      state: 12
    }, 
    {
      pos: [6, 5, 0], 
      state: 12
    }, 
    {
      pos: [7, 5, 0], 
      state: 12
    }, 
    {
      pos: [8, 5, 0], 
      state: 12
    }, 
    {
      pos: [0, 5, 1], 
      state: 12
    }, 
    {
      pos: [1, 5, 1], 
      state: 12
    }, 
    {
      pos: [2, 5, 1], 
      state: 12
    }, 
    {
      pos: [3, 5, 1], 
      state: 12
    }, 
    {
      pos: [4, 5, 1], 
      state: 12
    }, 
    {
      pos: [5, 5, 1], 
      state: 12
    }, 
    {
      pos: [6, 5, 1], 
      state: 12
    }, 
    {
      pos: [7, 5, 1], 
      state: 12
    }, 
    {
      pos: [8, 5, 1], 
      state: 12
    }, 
    {
      pos: [0, 5, 2], 
      state: 12
    }, 
    {
      pos: [1, 5, 2], 
      state: 12
    }, 
    {
      pos: [2, 5, 2], 
      state: 12
    }, 
    {
      pos: [3, 5, 2], 
      state: 12
    }, 
    {
      pos: [4, 5, 2], 
      state: 12
    }, 
    {
      pos: [5, 5, 2], 
      state: 12
    }, 
    {
      pos: [6, 5, 2], 
      state: 12
    }, 
    {
      pos: [7, 5, 2], 
      state: 12
    }, 
    {
      pos: [8, 5, 2], 
      state: 12
    }, 
    {
      pos: [0, 5, 3], 
      state: 12
    }, 
    {
      pos: [1, 5, 3], 
      state: 12
    }, 
    {
      pos: [2, 5, 3], 
      state: 12
    }, 
    {
      pos: [3, 5, 3], 
      state: 12
    }, 
    {
      pos: [4, 5, 3], 
      state: 12
    }, 
    {
      pos: [5, 5, 3], 
      state: 12
    }, 
    {
      pos: [6, 5, 3], 
      state: 12
    }, 
    {
      pos: [7, 5, 3], 
      state: 12
    }, 
    {
      pos: [8, 5, 3], 
      state: 12
    }, 
    {
      pos: [0, 5, 4], 
      state: 12
    }, 
    {
      pos: [1, 5, 4], 
      state: 12
    }, 
    {
      pos: [2, 5, 4], 
      state: 24
    }, 
    {
      pos: [3, 5, 4], 
      state: 25
    }, 
    {
      pos: [4, 5, 4], 
      state: 12
    }, 
    {
      pos: [5, 5, 4], 
      state: 27
    }, 
    {
      pos: [6, 5, 4], 
      state: 28
    }, 
    {
      pos: [7, 5, 4], 
      state: 12
    }, 
    {
      pos: [8, 5, 4], 
      state: 12
    }, 
    {
      pos: [0, 5, 5], 
      state: 12
    }, 
    {
      pos: [1, 5, 5], 
      state: 12
    }, 
    {
      pos: [2, 5, 5], 
      state: 24
    }, 
    {
      pos: [6, 5, 5], 
      state: 28
    }, 
    {
      pos: [7, 5, 5], 
      state: 12
    }, 
    {
      pos: [8, 5, 5], 
      state: 12
    }, 
    {
      pos: [0, 5, 6], 
      state: 12
    }, 
    {
      pos: [1, 5, 6], 
      state: 12
    }, 
    {
      pos: [2, 5, 6], 
      state: 24
    }, 
    {
      pos: [3, 5, 6], 
      state: 12
    }, 
    {
      pos: [4, 5, 6], 
      state: 12
    }, 
    {
      pos: [5, 5, 6], 
      state: 12
    }, 
    {
      pos: [6, 5, 6], 
      state: 28
    }, 
    {
      pos: [7, 5, 6], 
      state: 12
    }, 
    {
      pos: [8, 5, 6], 
      state: 12
    }, 
    {
      pos: [0, 5, 7], 
      state: 12
    }, 
    {
      pos: [1, 5, 7], 
      state: 12
    }, 
    {
      pos: [2, 5, 7], 
      state: 24
    }, 
    {
      pos: [3, 5, 7], 
      state: 12
    }, 
    {
      pos: [4, 5, 7], 
      state: 12
    }, 
    {
      pos: [5, 5, 7], 
      state: 12
    }, 
    {
      pos: [6, 5, 7], 
      state: 28
    }, 
    {
      pos: [7, 5, 7], 
      state: 12
    }, 
    {
      pos: [8, 5, 7], 
      state: 12
    }, 
    {
      pos: [0, 5, 8], 
      state: 12
    }, 
    {
      pos: [1, 5, 8], 
      state: 12
    }, 
    {
      pos: [2, 5, 8], 
      state: 24
    }, 
    {
      pos: [3, 5, 8], 
      state: 12
    }, 
    {
      pos: [4, 5, 8], 
      state: 12
    }, 
    {
      pos: [5, 5, 8], 
      state: 12
    }, 
    {
      pos: [6, 5, 8], 
      state: 28
    }, 
    {
      pos: [7, 5, 8], 
      state: 12
    }, 
    {
      pos: [8, 5, 8], 
      state: 12
    }, 
    {
      pos: [0, 5, 9], 
      state: 12
    }, 
    {
      pos: [1, 5, 9], 
      state: 12
    }, 
    {
      pos: [2, 5, 9], 
      state: 24
    }, 
    {
      pos: [3, 5, 9], 
      state: 12
    }, 
    {
      pos: [4, 5, 9], 
      state: 12
    }, 
    {
      pos: [5, 5, 9], 
      state: 12
    }, 
    {
      pos: [6, 5, 9], 
      state: 28
    }, 
    {
      pos: [7, 5, 9], 
      state: 12
    }, 
    {
      pos: [8, 5, 9], 
      state: 12
    }, 
    {
      pos: [0, 5, 10], 
      state: 12
    }, 
    {
      pos: [1, 5, 10], 
      state: 12
    }, 
    {
      pos: [2, 5, 10], 
      state: 24
    }, 
    {
      pos: [3, 5, 10], 
      state: 12
    }, 
    {
      pos: [4, 5, 10], 
      state: 12
    }, 
    {
      pos: [5, 5, 10], 
      state: 12
    }, 
    {
      pos: [6, 5, 10], 
      state: 28
    }, 
    {
      pos: [7, 5, 10], 
      state: 12
    }, 
    {
      pos: [8, 5, 10], 
      state: 12
    }, 
    {
      pos: [0, 5, 11], 
      state: 12
    }, 
    {
      pos: [1, 5, 11], 
      state: 12
    }, 
    {
      pos: [2, 5, 11], 
      state: 24
    }, 
    {
      pos: [3, 5, 11], 
      state: 12
    }, 
    {
      pos: [4, 5, 11], 
      state: 12
    }, 
    {
      pos: [5, 5, 11], 
      state: 12
    }, 
    {
      pos: [6, 5, 11], 
      state: 28
    }, 
    {
      pos: [7, 5, 11], 
      state: 12
    }, 
    {
      pos: [8, 5, 11], 
      state: 12
    }, 
    {
      pos: [0, 5, 12], 
      state: 12
    }, 
    {
      pos: [1, 5, 12], 
      state: 12
    }, 
    {
      pos: [2, 5, 12], 
      state: 24
    }, 
    {
      pos: [3, 5, 12], 
      state: 12
    }, 
    {
      pos: [4, 5, 12], 
      state: 12
    }, 
    {
      pos: [5, 5, 12], 
      state: 12
    }, 
    {
      pos: [6, 5, 12], 
      state: 28
    }, 
    {
      pos: [7, 5, 12], 
      state: 12
    }, 
    {
      pos: [8, 5, 12], 
      state: 12
    }, 
    {
      pos: [0, 5, 13], 
      state: 12
    }, 
    {
      pos: [1, 5, 13], 
      state: 12
    }, 
    {
      pos: [2, 5, 13], 
      state: 24
    }, 
    {
      pos: [3, 5, 13], 
      state: 12
    }, 
    {
      pos: [4, 5, 13], 
      state: 12
    }, 
    {
      pos: [5, 5, 13], 
      state: 12
    }, 
    {
      pos: [6, 5, 13], 
      state: 28
    }, 
    {
      pos: [7, 5, 13], 
      state: 12
    }, 
    {
      pos: [8, 5, 13], 
      state: 12
    }, 
    {
      pos: [0, 5, 14], 
      state: 12
    }, 
    {
      pos: [1, 5, 14], 
      state: 12
    }, 
    {
      pos: [2, 5, 14], 
      state: 24
    }, 
    {
      pos: [6, 5, 14], 
      state: 28
    }, 
    {
      pos: [7, 5, 14], 
      state: 12
    }, 
    {
      pos: [8, 5, 14], 
      state: 12
    }, 
    {
      pos: [0, 5, 15], 
      state: 12
    }, 
    {
      pos: [1, 5, 15], 
      state: 12
    }, 
    {
      pos: [2, 5, 15], 
      state: 24
    }, 
    {
      pos: [3, 5, 15], 
      state: 25
    }, 
    {
      pos: [4, 5, 15], 
      state: 29
    }, 
    {
      pos: [5, 5, 15], 
      state: 27
    }, 
    {
      pos: [6, 5, 15], 
      state: 28
    }, 
    {
      pos: [7, 5, 15], 
      state: 12
    }, 
    {
      pos: [8, 5, 15], 
      state: 12
    }, 
    {
      pos: [4, 6, 4], 
      state: 32
    }, 
    {
      pos: [4, 6, 5], 
      state: 32
    }, 
    {
      pos: [4, 6, 6], 
      state: 32
    }, 
    {
      pos: [4, 6, 7], 
      state: 32
    }, 
    {
      pos: [4, 6, 8], 
      state: 32
    }, 
    {
      pos: [4, 6, 9], 
      state: 32
    }, 
    {
      pos: [4, 6, 10], 
      state: 32
    }, 
    {
      pos: [4, 6, 11], 
      state: 32
    }, 
    {
      pos: [4, 6, 12], 
      state: 32
    }, 
    {
      pos: [4, 6, 13], 
      state: 32
    }, 
    {
      pos: [4, 6, 14], 
      state: 32
    }, 
    {
      pos: [4, 6, 15], 
      state: 32
    }, 
    {
      pos: [0, 6, 0], 
      state: 12
    }, 
    {
      pos: [1, 6, 0], 
      state: 12
    }, 
    {
      pos: [2, 6, 0], 
      state: 12
    }, 
    {
      pos: [3, 6, 0], 
      state: 12
    }, 
    {
      pos: [4, 6, 0], 
      state: 12
    }, 
    {
      pos: [5, 6, 0], 
      state: 12
    }, 
    {
      pos: [6, 6, 0], 
      state: 12
    }, 
    {
      pos: [7, 6, 0], 
      state: 12
    }, 
    {
      pos: [8, 6, 0], 
      state: 12
    }, 
    {
      pos: [0, 6, 1], 
      state: 12
    }, 
    {
      pos: [1, 6, 1], 
      state: 12
    }, 
    {
      pos: [2, 6, 1], 
      state: 12
    }, 
    {
      pos: [3, 6, 1], 
      state: 12
    }, 
    {
      pos: [4, 6, 1], 
      state: 12
    }, 
    {
      pos: [5, 6, 1], 
      state: 12
    }, 
    {
      pos: [6, 6, 1], 
      state: 12
    }, 
    {
      pos: [7, 6, 1], 
      state: 12
    }, 
    {
      pos: [8, 6, 1], 
      state: 12
    }, 
    {
      pos: [0, 6, 2], 
      state: 12
    }, 
    {
      pos: [1, 6, 2], 
      state: 12
    }, 
    {
      pos: [2, 6, 2], 
      state: 12
    }, 
    {
      pos: [3, 6, 2], 
      state: 12
    }, 
    {
      pos: [4, 6, 2], 
      state: 12
    }, 
    {
      pos: [5, 6, 2], 
      state: 12
    }, 
    {
      pos: [6, 6, 2], 
      state: 12
    }, 
    {
      pos: [7, 6, 2], 
      state: 12
    }, 
    {
      pos: [8, 6, 2], 
      state: 12
    }, 
    {
      pos: [0, 6, 3], 
      state: 12
    }, 
    {
      pos: [1, 6, 3], 
      state: 12
    }, 
    {
      pos: [2, 6, 3], 
      state: 12
    }, 
    {
      pos: [3, 6, 3], 
      state: 12
    }, 
    {
      pos: [4, 6, 3], 
      state: 12
    }, 
    {
      pos: [5, 6, 3], 
      state: 12
    }, 
    {
      pos: [6, 6, 3], 
      state: 12
    }, 
    {
      pos: [7, 6, 3], 
      state: 12
    }, 
    {
      pos: [8, 6, 3], 
      state: 12
    }, 
    {
      pos: [0, 6, 4], 
      state: 12
    }, 
    {
      pos: [1, 6, 4], 
      state: 12
    }, 
    {
      pos: [2, 6, 4], 
      state: 12
    }, 
    {
      pos: [3, 6, 4], 
      state: 24
    }, 
    {
      pos: [5, 6, 4], 
      state: 28
    }, 
    {
      pos: [6, 6, 4], 
      state: 12
    }, 
    {
      pos: [7, 6, 4], 
      state: 12
    }, 
    {
      pos: [8, 6, 4], 
      state: 12
    }, 
    {
      pos: [0, 6, 5], 
      state: 12
    }, 
    {
      pos: [1, 6, 5], 
      state: 12
    }, 
    {
      pos: [2, 6, 5], 
      state: 12
    }, 
    {
      pos: [3, 6, 5], 
      state: 24
    }, 
    {
      pos: [5, 6, 5], 
      state: 28
    }, 
    {
      pos: [6, 6, 5], 
      state: 12
    }, 
    {
      pos: [7, 6, 5], 
      state: 12
    }, 
    {
      pos: [8, 6, 5], 
      state: 12
    }, 
    {
      pos: [0, 6, 6], 
      state: 12
    }, 
    {
      pos: [1, 6, 6], 
      state: 12
    }, 
    {
      pos: [2, 6, 6], 
      state: 12
    }, 
    {
      pos: [3, 6, 6], 
      state: 24
    }, 
    {
      pos: [5, 6, 6], 
      state: 28
    }, 
    {
      pos: [6, 6, 6], 
      state: 12
    }, 
    {
      pos: [7, 6, 6], 
      state: 12
    }, 
    {
      pos: [8, 6, 6], 
      state: 12
    }, 
    {
      pos: [0, 6, 7], 
      state: 12
    }, 
    {
      pos: [1, 6, 7], 
      state: 12
    }, 
    {
      pos: [2, 6, 7], 
      state: 12
    }, 
    {
      pos: [3, 6, 7], 
      state: 24
    }, 
    {
      pos: [5, 6, 7], 
      state: 28
    }, 
    {
      pos: [6, 6, 7], 
      state: 12
    }, 
    {
      pos: [7, 6, 7], 
      state: 12
    }, 
    {
      pos: [8, 6, 7], 
      state: 12
    }, 
    {
      pos: [0, 6, 8], 
      state: 12
    }, 
    {
      pos: [1, 6, 8], 
      state: 12
    }, 
    {
      pos: [2, 6, 8], 
      state: 12
    }, 
    {
      pos: [3, 6, 8], 
      state: 24
    }, 
    {
      pos: [5, 6, 8], 
      state: 28
    }, 
    {
      pos: [6, 6, 8], 
      state: 12
    }, 
    {
      pos: [7, 6, 8], 
      state: 12
    }, 
    {
      pos: [8, 6, 8], 
      state: 12
    }, 
    {
      pos: [0, 6, 9], 
      state: 12
    }, 
    {
      pos: [1, 6, 9], 
      state: 12
    }, 
    {
      pos: [2, 6, 9], 
      state: 12
    }, 
    {
      pos: [3, 6, 9], 
      state: 24
    }, 
    {
      pos: [5, 6, 9], 
      state: 28
    }, 
    {
      pos: [6, 6, 9], 
      state: 12
    }, 
    {
      pos: [7, 6, 9], 
      state: 12
    }, 
    {
      pos: [8, 6, 9], 
      state: 12
    }, 
    {
      pos: [0, 6, 10], 
      state: 12
    }, 
    {
      pos: [1, 6, 10], 
      state: 12
    }, 
    {
      pos: [2, 6, 10], 
      state: 12
    }, 
    {
      pos: [3, 6, 10], 
      state: 24
    }, 
    {
      pos: [5, 6, 10], 
      state: 28
    }, 
    {
      pos: [6, 6, 10], 
      state: 12
    }, 
    {
      pos: [7, 6, 10], 
      state: 12
    }, 
    {
      pos: [8, 6, 10], 
      state: 12
    }, 
    {
      pos: [0, 6, 11], 
      state: 12
    }, 
    {
      pos: [1, 6, 11], 
      state: 12
    }, 
    {
      pos: [2, 6, 11], 
      state: 12
    }, 
    {
      pos: [3, 6, 11], 
      state: 24
    }, 
    {
      pos: [5, 6, 11], 
      state: 28
    }, 
    {
      pos: [6, 6, 11], 
      state: 12
    }, 
    {
      pos: [7, 6, 11], 
      state: 12
    }, 
    {
      pos: [8, 6, 11], 
      state: 12
    }, 
    {
      pos: [0, 6, 12], 
      state: 12
    }, 
    {
      pos: [1, 6, 12], 
      state: 12
    }, 
    {
      pos: [2, 6, 12], 
      state: 12
    }, 
    {
      pos: [3, 6, 12], 
      state: 24
    }, 
    {
      pos: [5, 6, 12], 
      state: 28
    }, 
    {
      pos: [6, 6, 12], 
      state: 12
    }, 
    {
      pos: [7, 6, 12], 
      state: 12
    }, 
    {
      pos: [8, 6, 12], 
      state: 12
    }, 
    {
      pos: [0, 6, 13], 
      state: 12
    }, 
    {
      pos: [1, 6, 13], 
      state: 12
    }, 
    {
      pos: [2, 6, 13], 
      state: 12
    }, 
    {
      pos: [3, 6, 13], 
      state: 24
    }, 
    {
      pos: [5, 6, 13], 
      state: 28
    }, 
    {
      pos: [6, 6, 13], 
      state: 12
    }, 
    {
      pos: [7, 6, 13], 
      state: 12
    }, 
    {
      pos: [8, 6, 13], 
      state: 12
    }, 
    {
      pos: [0, 6, 14], 
      state: 12
    }, 
    {
      pos: [1, 6, 14], 
      state: 12
    }, 
    {
      pos: [2, 6, 14], 
      state: 12
    }, 
    {
      pos: [3, 6, 14], 
      state: 24
    }, 
    {
      pos: [5, 6, 14], 
      state: 28
    }, 
    {
      pos: [6, 6, 14], 
      state: 12
    }, 
    {
      pos: [7, 6, 14], 
      state: 12
    }, 
    {
      pos: [8, 6, 14], 
      state: 12
    }, 
    {
      pos: [0, 6, 15], 
      state: 12
    }, 
    {
      pos: [1, 6, 15], 
      state: 12
    }, 
    {
      pos: [2, 6, 15], 
      state: 12
    }, 
    {
      pos: [3, 6, 15], 
      state: 24
    }, 
    {
      pos: [5, 6, 15], 
      state: 28
    }, 
    {
      pos: [6, 6, 15], 
      state: 12
    }, 
    {
      pos: [7, 6, 15], 
      state: 12
    }, 
    {
      pos: [8, 6, 15], 
      state: 12
    }
  ], 
  palette: [
    {
      Properties: {
        snowy: "false"
      }, 
      Name: "minecraft:grass_block"
    }, 
    {
      Name: "minecraft:dirt"
    }, 
    {
      Properties: {
        facing: "up"
      }, 
      Name: "minecraft:jigsaw"
    }, 
    {
      Name: "minecraft:grass_path"
    }, 
    {
      Properties: {
        axis: "y"
      }, 
      Name: "minecraft:hay_block"
    }, 
    {
      Name: "minecraft:cobblestone"
    }, 
    {
      Properties: {
        axis: "x"
      }, 
      Name: "minecraft:oak_log"
    }, 
    {
      Properties: {
        facing: "west"
      }, 
      Name: "minecraft:jigsaw"
    }, 
    {
      Properties: {
        east: "true", 
        waterlogged: "false", 
        south: "true", 
        north: "false", 
        west: "false"
      }, 
      Name: "minecraft:oak_fence"
    }, 
    {
      Properties: {
        east: "true", 
        waterlogged: "false", 
        south: "false", 
        north: "false", 
        west: "true"
      }, 
      Name: "minecraft:oak_fence"
    }, 
    {
      Properties: {
        east: "false", 
        waterlogged: "false", 
        south: "true", 
        north: "false", 
        west: "true"
      }, 
      Name: "minecraft:oak_fence"
    }, 
    {
      Properties: {
        east: "false", 
        waterlogged: "false", 
        south: "true", 
        north: "true", 
        west: "false"
      }, 
      Name: "minecraft:oak_fence"
    }, 
    {
      Name: "minecraft:air"
    }, 
    {
      Properties: {
        east: "true", 
        waterlogged: "false", 
        south: "false", 
        north: "true", 
        west: "false"
      }, 
      Name: "minecraft:oak_fence"
    }, 
    {
      Properties: {
        east: "false", 
        waterlogged: "false", 
        south: "false", 
        north: "true", 
        west: "true"
      }, 
      Name: "minecraft:oak_fence"
    }, 
    {
      Properties: {
        hinge: "right", 
        half: "lower", 
        powered: "false", 
        facing: "east", 
        open: "false"
      }, 
      Name: "minecraft:oak_door"
    }, 
    {
      Properties: {
        level: "0"
      }, 
      Name: "minecraft:water"
    }, 
    {
      Properties: {
        axis: "z"
      }, 
      Name: "minecraft:oak_log"
    }, 
    {
      Name: "minecraft:torch"
    }, 
    {
      Properties: {
        hinge: "right", 
        half: "upper", 
        powered: "false", 
        facing: "east", 
        open: "false"
      }, 
      Name: "minecraft:oak_door"
    }, 
    {
      Properties: {
        east: "false", 
        waterlogged: "false", 
        south: "true", 
        north: "true", 
        west: "false"
      }, 
      Name: "minecraft:glass_pane"
    }, 
    {
      Properties: {
        east: "true", 
        waterlogged: "false", 
        south: "false", 
        north: "false", 
        west: "true"
      }, 
      Name: "minecraft:glass_pane"
    }, 
    {
      Properties: {
        half: "top", 
        waterlogged: "false", 
        shape: "straight", 
        facing: "west"
      }, 
      Name: "minecraft:cobblestone_stairs"
    }, 
    {
      Properties: {
        half: "top", 
        waterlogged: "false", 
        shape: "straight", 
        facing: "east"
      }, 
      Name: "minecraft:cobblestone_stairs"
    }, 
    {
      Properties: {
        half: "bottom", 
        waterlogged: "false", 
        shape: "straight", 
        facing: "east"
      }, 
      Name: "minecraft:oak_stairs"
    }, 
    {
      Properties: {
        half: "top", 
        waterlogged: "false", 
        shape: "straight", 
        facing: "west"
      }, 
      Name: "minecraft:oak_stairs"
    }, 
    {
      Properties: {
        facing: "north"
      }, 
      Name: "minecraft:wall_torch"
    }, 
    {
      Properties: {
        half: "top", 
        waterlogged: "false", 
        shape: "straight", 
        facing: "east"
      }, 
      Name: "minecraft:oak_stairs"
    }, 
    {
      Properties: {
        half: "bottom", 
        waterlogged: "false", 
        shape: "straight", 
        facing: "west"
      }, 
      Name: "minecraft:oak_stairs"
    }, 
    {
      Properties: {
        facing: "south"
      }, 
      Name: "minecraft:wall_torch"
    }, 
    {
      Properties: {
        facing: "east"
      }, 
      Name: "minecraft:wall_torch"
    }, 
    {
      Properties: {
        facing: "west"
      }, 
      Name: "minecraft:wall_torch"
    }, 
    {
      Name: "minecraft:oak_planks"
    }
  ]
}
