{
  size: [10, 12, 7], 
  entities: [], 
  blocks: [
    {
      pos: [2, 0, 0], 
      state: 0
    }, 
    {
      pos: [3, 0, 0], 
      state: 0
    }, 
    {
      pos: [4, 0, 0], 
      state: 0
    }, 
    {
      pos: [0, 0, 1], 
      state: 0
    }, 
    {
      pos: [1, 0, 1], 
      state: 0
    }, 
    {
      pos: [2, 0, 1], 
      state: 0
    }, 
    {
      pos: [3, 0, 1], 
      state: 0
    }, 
    {
      pos: [4, 0, 1], 
      state: 0
    }, 
    {
      pos: [5, 0, 1], 
      state: 0
    }, 
    {
      pos: [6, 0, 1], 
      state: 0
    }, 
    {
      pos: [7, 0, 1], 
      state: 0
    }, 
    {
      pos: [8, 0, 1], 
      state: 0
    }, 
    {
      pos: [1, 0, 2], 
      state: 0
    }, 
    {
      pos: [2, 0, 2], 
      state: 0
    }, 
    {
      pos: [3, 0, 2], 
      state: 0
    }, 
    {
      pos: [4, 0, 2], 
      state: 0
    }, 
    {
      pos: [5, 0, 2], 
      state: 0
    }, 
    {
      pos: [6, 0, 2], 
      state: 0
    }, 
    {
      pos: [7, 0, 2], 
      state: 0
    }, 
    {
      pos: [8, 0, 2], 
      state: 0
    }, 
    {
      pos: [9, 0, 2], 
      state: 0
    }, 
    {
      pos: [3, 0, 3], 
      state: 0
    }, 
    {
      pos: [4, 0, 3], 
      state: 0
    }, 
    {
      pos: [5, 0, 3], 
      state: 0
    }, 
    {
      pos: [6, 0, 3], 
      state: 0
    }, 
    {
      pos: [7, 0, 3], 
      state: 0
    }, 
    {
      pos: [8, 0, 3], 
      state: 0
    }, 
    {
      pos: [9, 0, 3], 
      state: 0
    }, 
    {
      pos: [1, 0, 4], 
      state: 0
    }, 
    {
      pos: [2, 0, 4], 
      state: 0
    }, 
    {
      pos: [3, 0, 4], 
      state: 0
    }, 
    {
      pos: [4, 0, 4], 
      state: 0
    }, 
    {
      pos: [5, 0, 4], 
      state: 0
    }, 
    {
      pos: [6, 0, 4], 
      state: 0
    }, 
    {
      pos: [7, 0, 4], 
      state: 0
    }, 
    {
      pos: [8, 0, 4], 
      state: 0
    }, 
    {
      pos: [9, 0, 4], 
      state: 0
    }, 
    {
      pos: [0, 0, 5], 
      state: 0
    }, 
    {
      pos: [1, 0, 5], 
      state: 0
    }, 
    {
      pos: [2, 0, 5], 
      state: 0
    }, 
    {
      pos: [3, 0, 5], 
      state: 0
    }, 
    {
      pos: [4, 0, 5], 
      state: 0
    }, 
    {
      pos: [5, 0, 5], 
      state: 0
    }, 
    {
      pos: [6, 0, 5], 
      state: 0
    }, 
    {
      pos: [7, 0, 5], 
      state: 0
    }, 
    {
      pos: [8, 0, 5], 
      state: 0
    }, 
    {
      pos: [2, 0, 6], 
      state: 0
    }, 
    {
      pos: [3, 0, 6], 
      state: 0
    }, 
    {
      pos: [4, 0, 6], 
      state: 0
    }, 
    {
      nbt: {
        target_pool: "minecraft:empty", 
        final_state: "minecraft:structure_void", 
        id: "minecraft:jigsaw", 
        attachement_type: "minecraft:building_entrance"
      }, 
      pos: [0, 0, 3], 
      state: 1
    }, 
    {
      pos: [0, 0, 0], 
      state: 2
    }, 
    {
      pos: [1, 0, 0], 
      state: 2
    }, 
    {
      pos: [5, 0, 0], 
      state: 2
    }, 
    {
      pos: [6, 0, 0], 
      state: 2
    }, 
    {
      pos: [7, 0, 0], 
      state: 2
    }, 
    {
      pos: [8, 0, 0], 
      state: 2
    }, 
    {
      pos: [9, 0, 0], 
      state: 2
    }, 
    {
      pos: [9, 0, 1], 
      state: 2
    }, 
    {
      pos: [0, 0, 2], 
      state: 2
    }, 
    {
      pos: [1, 0, 3], 
      state: 2
    }, 
    {
      pos: [2, 0, 3], 
      state: 3
    }, 
    {
      pos: [0, 0, 4], 
      state: 2
    }, 
    {
      pos: [9, 0, 5], 
      state: 2
    }, 
    {
      pos: [0, 0, 6], 
      state: 2
    }, 
    {
      pos: [1, 0, 6], 
      state: 2
    }, 
    {
      pos: [5, 0, 6], 
      state: 2
    }, 
    {
      pos: [6, 0, 6], 
      state: 2
    }, 
    {
      pos: [7, 0, 6], 
      state: 2
    }, 
    {
      pos: [8, 0, 6], 
      state: 2
    }, 
    {
      pos: [9, 0, 6], 
      state: 2
    }, 
    {
      pos: [2, 1, 0], 
      state: 0
    }, 
    {
      pos: [3, 1, 0], 
      state: 0
    }, 
    {
      pos: [4, 1, 0], 
      state: 0
    }, 
    {
      pos: [1, 1, 1], 
      state: 0
    }, 
    {
      pos: [2, 1, 1], 
      state: 0
    }, 
    {
      pos: [4, 1, 1], 
      state: 0
    }, 
    {
      pos: [5, 1, 1], 
      state: 0
    }, 
    {
      pos: [6, 1, 1], 
      state: 0
    }, 
    {
      pos: [7, 1, 1], 
      state: 0
    }, 
    {
      pos: [8, 1, 1], 
      state: 0
    }, 
    {
      pos: [1, 1, 2], 
      state: 0
    }, 
    {
      pos: [7, 1, 2], 
      state: 0
    }, 
    {
      pos: [8, 1, 2], 
      state: 0
    }, 
    {
      pos: [9, 1, 2], 
      state: 0
    }, 
    {
      pos: [8, 1, 3], 
      state: 0
    }, 
    {
      pos: [9, 1, 3], 
      state: 0
    }, 
    {
      pos: [1, 1, 4], 
      state: 0
    }, 
    {
      pos: [7, 1, 4], 
      state: 0
    }, 
    {
      pos: [8, 1, 4], 
      state: 0
    }, 
    {
      pos: [9, 1, 4], 
      state: 0
    }, 
    {
      pos: [1, 1, 5], 
      state: 0
    }, 
    {
      pos: [2, 1, 5], 
      state: 0
    }, 
    {
      pos: [4, 1, 5], 
      state: 0
    }, 
    {
      pos: [5, 1, 5], 
      state: 0
    }, 
    {
      pos: [6, 1, 5], 
      state: 0
    }, 
    {
      pos: [7, 1, 5], 
      state: 0
    }, 
    {
      pos: [8, 1, 5], 
      state: 0
    }, 
    {
      pos: [2, 1, 6], 
      state: 0
    }, 
    {
      pos: [3, 1, 6], 
      state: 0
    }, 
    {
      pos: [4, 1, 6], 
      state: 0
    }, 
    {
      nbt: {
        Fuel: 0b, 
        Items: [], 
        id: "minecraft:brewing_stand", 
        BrewTime: 0s
      }, 
      pos: [4, 1, 2], 
      state: 4
    }, 
    {
      pos: [0, 1, 0], 
      state: 2
    }, 
    {
      pos: [1, 1, 0], 
      state: 2
    }, 
    {
      pos: [5, 1, 0], 
      state: 2
    }, 
    {
      pos: [6, 1, 0], 
      state: 2
    }, 
    {
      pos: [7, 1, 0], 
      state: 2
    }, 
    {
      pos: [8, 1, 0], 
      state: 2
    }, 
    {
      pos: [9, 1, 0], 
      state: 2
    }, 
    {
      pos: [0, 1, 1], 
      state: 5
    }, 
    {
      pos: [3, 1, 1], 
      state: 6
    }, 
    {
      pos: [9, 1, 1], 
      state: 2
    }, 
    {
      pos: [0, 1, 2], 
      state: 2
    }, 
    {
      pos: [2, 1, 2], 
      state: 2
    }, 
    {
      pos: [3, 1, 2], 
      state: 2
    }, 
    {
      pos: [5, 1, 2], 
      state: 2
    }, 
    {
      pos: [6, 1, 2], 
      state: 3
    }, 
    {
      pos: [0, 1, 3], 
      state: 2
    }, 
    {
      pos: [1, 1, 3], 
      state: 2
    }, 
    {
      pos: [2, 1, 3], 
      state: 2
    }, 
    {
      pos: [3, 1, 3], 
      state: 2
    }, 
    {
      pos: [4, 1, 3], 
      state: 2
    }, 
    {
      pos: [5, 1, 3], 
      state: 2
    }, 
    {
      pos: [6, 1, 3], 
      state: 2
    }, 
    {
      pos: [7, 1, 3], 
      state: 3
    }, 
    {
      pos: [0, 1, 4], 
      state: 2
    }, 
    {
      pos: [2, 1, 4], 
      state: 2
    }, 
    {
      pos: [3, 1, 4], 
      state: 2
    }, 
    {
      pos: [4, 1, 4], 
      state: 7
    }, 
    {
      pos: [5, 1, 4], 
      state: 2
    }, 
    {
      pos: [6, 1, 4], 
      state: 3
    }, 
    {
      pos: [0, 1, 5], 
      state: 5
    }, 
    {
      pos: [3, 1, 5], 
      state: 8
    }, 
    {
      pos: [9, 1, 5], 
      state: 2
    }, 
    {
      pos: [0, 1, 6], 
      state: 2
    }, 
    {
      pos: [1, 1, 6], 
      state: 2
    }, 
    {
      pos: [5, 1, 6], 
      state: 2
    }, 
    {
      pos: [6, 1, 6], 
      state: 2
    }, 
    {
      pos: [7, 1, 6], 
      state: 2
    }, 
    {
      pos: [8, 1, 6], 
      state: 2
    }, 
    {
      pos: [9, 1, 6], 
      state: 2
    }, 
    {
      pos: [2, 2, 0], 
      state: 0
    }, 
    {
      pos: [4, 2, 0], 
      state: 0
    }, 
    {
      pos: [1, 2, 1], 
      state: 0
    }, 
    {
      pos: [2, 2, 1], 
      state: 0
    }, 
    {
      pos: [4, 2, 1], 
      state: 0
    }, 
    {
      pos: [5, 2, 1], 
      state: 0
    }, 
    {
      pos: [6, 2, 1], 
      state: 0
    }, 
    {
      pos: [8, 2, 1], 
      state: 0
    }, 
    {
      pos: [1, 2, 2], 
      state: 0
    }, 
    {
      pos: [9, 2, 2], 
      state: 0
    }, 
    {
      pos: [1, 2, 3], 
      state: 0
    }, 
    {
      pos: [1, 2, 4], 
      state: 0
    }, 
    {
      pos: [9, 2, 4], 
      state: 0
    }, 
    {
      pos: [1, 2, 5], 
      state: 0
    }, 
    {
      pos: [2, 2, 5], 
      state: 0
    }, 
    {
      pos: [4, 2, 5], 
      state: 0
    }, 
    {
      pos: [5, 2, 5], 
      state: 0
    }, 
    {
      pos: [6, 2, 5], 
      state: 0
    }, 
    {
      pos: [8, 2, 5], 
      state: 0
    }, 
    {
      pos: [2, 2, 6], 
      state: 0
    }, 
    {
      pos: [4, 2, 6], 
      state: 0
    }, 
    {
      pos: [0, 2, 0], 
      state: 2
    }, 
    {
      pos: [1, 2, 0], 
      state: 2
    }, 
    {
      pos: [3, 2, 0], 
      state: 9
    }, 
    {
      pos: [5, 2, 0], 
      state: 2
    }, 
    {
      pos: [6, 2, 0], 
      state: 2
    }, 
    {
      pos: [7, 2, 0], 
      state: 2
    }, 
    {
      pos: [8, 2, 0], 
      state: 2
    }, 
    {
      pos: [9, 2, 0], 
      state: 2
    }, 
    {
      pos: [0, 2, 1], 
      state: 10
    }, 
    {
      pos: [3, 2, 1], 
      state: 2
    }, 
    {
      pos: [7, 2, 1], 
      state: 9
    }, 
    {
      pos: [9, 2, 1], 
      state: 2
    }, 
    {
      pos: [0, 2, 2], 
      state: 2
    }, 
    {
      pos: [2, 2, 2], 
      state: 2
    }, 
    {
      pos: [3, 2, 2], 
      state: 2
    }, 
    {
      pos: [4, 2, 2], 
      state: 2
    }, 
    {
      pos: [5, 2, 2], 
      state: 2
    }, 
    {
      pos: [6, 2, 2], 
      state: 2
    }, 
    {
      pos: [7, 2, 2], 
      state: 2
    }, 
    {
      pos: [8, 2, 2], 
      state: 6
    }, 
    {
      pos: [0, 2, 3], 
      state: 2
    }, 
    {
      pos: [2, 2, 3], 
      state: 11
    }, 
    {
      pos: [3, 2, 3], 
      state: 2
    }, 
    {
      pos: [4, 2, 3], 
      state: 2
    }, 
    {
      pos: [5, 2, 3], 
      state: 2
    }, 
    {
      pos: [6, 2, 3], 
      state: 2
    }, 
    {
      pos: [7, 2, 3], 
      state: 2
    }, 
    {
      pos: [8, 2, 3], 
      state: 2
    }, 
    {
      pos: [9, 2, 3], 
      state: 12
    }, 
    {
      pos: [0, 2, 4], 
      state: 2
    }, 
    {
      pos: [2, 2, 4], 
      state: 2
    }, 
    {
      pos: [3, 2, 4], 
      state: 2
    }, 
    {
      pos: [4, 2, 4], 
      state: 7
    }, 
    {
      pos: [5, 2, 4], 
      state: 2
    }, 
    {
      pos: [6, 2, 4], 
      state: 2
    }, 
    {
      pos: [7, 2, 4], 
      state: 2
    }, 
    {
      pos: [8, 2, 4], 
      state: 8
    }, 
    {
      pos: [0, 2, 5], 
      state: 10
    }, 
    {
      pos: [3, 2, 5], 
      state: 2
    }, 
    {
      pos: [7, 2, 5], 
      state: 9
    }, 
    {
      pos: [9, 2, 5], 
      state: 2
    }, 
    {
      pos: [0, 2, 6], 
      state: 2
    }, 
    {
      pos: [1, 2, 6], 
      state: 2
    }, 
    {
      pos: [3, 2, 6], 
      state: 9
    }, 
    {
      pos: [5, 2, 6], 
      state: 2
    }, 
    {
      pos: [6, 2, 6], 
      state: 2
    }, 
    {
      pos: [7, 2, 6], 
      state: 2
    }, 
    {
      pos: [8, 2, 6], 
      state: 2
    }, 
    {
      pos: [9, 2, 6], 
      state: 2
    }, 
    {
      pos: [2, 3, 0], 
      state: 0
    }, 
    {
      pos: [4, 3, 0], 
      state: 0
    }, 
    {
      pos: [1, 3, 1], 
      state: 0
    }, 
    {
      pos: [2, 3, 1], 
      state: 0
    }, 
    {
      pos: [4, 3, 1], 
      state: 0
    }, 
    {
      pos: [5, 3, 1], 
      state: 0
    }, 
    {
      pos: [6, 3, 1], 
      state: 0
    }, 
    {
      pos: [8, 3, 1], 
      state: 0
    }, 
    {
      pos: [1, 3, 2], 
      state: 0
    }, 
    {
      pos: [9, 3, 2], 
      state: 0
    }, 
    {
      pos: [1, 3, 4], 
      state: 0
    }, 
    {
      pos: [9, 3, 4], 
      state: 0
    }, 
    {
      pos: [1, 3, 5], 
      state: 0
    }, 
    {
      pos: [2, 3, 5], 
      state: 0
    }, 
    {
      pos: [4, 3, 5], 
      state: 0
    }, 
    {
      pos: [5, 3, 5], 
      state: 0
    }, 
    {
      pos: [6, 3, 5], 
      state: 0
    }, 
    {
      pos: [8, 3, 5], 
      state: 0
    }, 
    {
      pos: [2, 3, 6], 
      state: 0
    }, 
    {
      pos: [4, 3, 6], 
      state: 0
    }, 
    {
      pos: [0, 3, 0], 
      state: 2
    }, 
    {
      pos: [1, 3, 0], 
      state: 2
    }, 
    {
      pos: [3, 3, 0], 
      state: 13
    }, 
    {
      pos: [5, 3, 0], 
      state: 2
    }, 
    {
      pos: [6, 3, 0], 
      state: 2
    }, 
    {
      pos: [7, 3, 0], 
      state: 2
    }, 
    {
      pos: [8, 3, 0], 
      state: 2
    }, 
    {
      pos: [9, 3, 0], 
      state: 2
    }, 
    {
      pos: [0, 3, 1], 
      state: 2
    }, 
    {
      pos: [3, 3, 1], 
      state: 2
    }, 
    {
      pos: [7, 3, 1], 
      state: 13
    }, 
    {
      pos: [9, 3, 1], 
      state: 2
    }, 
    {
      pos: [0, 3, 2], 
      state: 2
    }, 
    {
      pos: [2, 3, 2], 
      state: 2
    }, 
    {
      pos: [3, 3, 2], 
      state: 2
    }, 
    {
      pos: [4, 3, 2], 
      state: 2
    }, 
    {
      pos: [5, 3, 2], 
      state: 2
    }, 
    {
      pos: [6, 3, 2], 
      state: 2
    }, 
    {
      pos: [7, 3, 2], 
      state: 2
    }, 
    {
      pos: [8, 3, 2], 
      state: 2
    }, 
    {
      pos: [0, 3, 3], 
      state: 2
    }, 
    {
      pos: [1, 3, 3], 
      state: 12
    }, 
    {
      pos: [2, 3, 3], 
      state: 2
    }, 
    {
      pos: [3, 3, 3], 
      state: 2
    }, 
    {
      pos: [4, 3, 3], 
      state: 2
    }, 
    {
      pos: [5, 3, 3], 
      state: 2
    }, 
    {
      pos: [6, 3, 3], 
      state: 2
    }, 
    {
      pos: [7, 3, 3], 
      state: 2
    }, 
    {
      pos: [8, 3, 3], 
      state: 2
    }, 
    {
      pos: [9, 3, 3], 
      state: 14
    }, 
    {
      pos: [0, 3, 4], 
      state: 2
    }, 
    {
      pos: [2, 3, 4], 
      state: 2
    }, 
    {
      pos: [3, 3, 4], 
      state: 2
    }, 
    {
      pos: [4, 3, 4], 
      state: 7
    }, 
    {
      pos: [5, 3, 4], 
      state: 2
    }, 
    {
      pos: [6, 3, 4], 
      state: 2
    }, 
    {
      pos: [7, 3, 4], 
      state: 2
    }, 
    {
      pos: [8, 3, 4], 
      state: 2
    }, 
    {
      pos: [0, 3, 5], 
      state: 2
    }, 
    {
      pos: [3, 3, 5], 
      state: 2
    }, 
    {
      pos: [7, 3, 5], 
      state: 13
    }, 
    {
      pos: [9, 3, 5], 
      state: 2
    }, 
    {
      pos: [0, 3, 6], 
      state: 2
    }, 
    {
      pos: [1, 3, 6], 
      state: 2
    }, 
    {
      pos: [3, 3, 6], 
      state: 13
    }, 
    {
      pos: [5, 3, 6], 
      state: 2
    }, 
    {
      pos: [6, 3, 6], 
      state: 2
    }, 
    {
      pos: [7, 3, 6], 
      state: 2
    }, 
    {
      pos: [8, 3, 6], 
      state: 2
    }, 
    {
      pos: [9, 3, 6], 
      state: 2
    }, 
    {
      pos: [3, 4, 0], 
      state: 0
    }, 
    {
      pos: [2, 4, 1], 
      state: 0
    }, 
    {
      pos: [3, 4, 1], 
      state: 0
    }, 
    {
      pos: [4, 4, 1], 
      state: 0
    }, 
    {
      pos: [5, 4, 1], 
      state: 0
    }, 
    {
      pos: [6, 4, 1], 
      state: 0
    }, 
    {
      pos: [7, 4, 1], 
      state: 0
    }, 
    {
      pos: [8, 4, 1], 
      state: 0
    }, 
    {
      pos: [1, 4, 2], 
      state: 0
    }, 
    {
      pos: [9, 4, 2], 
      state: 0
    }, 
    {
      pos: [9, 4, 3], 
      state: 0
    }, 
    {
      pos: [1, 4, 4], 
      state: 0
    }, 
    {
      pos: [9, 4, 4], 
      state: 0
    }, 
    {
      pos: [2, 4, 5], 
      state: 0
    }, 
    {
      pos: [3, 4, 5], 
      state: 0
    }, 
    {
      pos: [4, 4, 5], 
      state: 0
    }, 
    {
      pos: [5, 4, 5], 
      state: 0
    }, 
    {
      pos: [6, 4, 5], 
      state: 0
    }, 
    {
      pos: [7, 4, 5], 
      state: 0
    }, 
    {
      pos: [8, 4, 5], 
      state: 0
    }, 
    {
      pos: [3, 4, 6], 
      state: 0
    }, 
    {
      pos: [0, 4, 0], 
      state: 2
    }, 
    {
      pos: [1, 4, 0], 
      state: 2
    }, 
    {
      pos: [2, 4, 0], 
      state: 3
    }, 
    {
      pos: [4, 4, 0], 
      state: 15
    }, 
    {
      pos: [5, 4, 0], 
      state: 2
    }, 
    {
      pos: [6, 4, 0], 
      state: 2
    }, 
    {
      pos: [7, 4, 0], 
      state: 2
    }, 
    {
      pos: [8, 4, 0], 
      state: 2
    }, 
    {
      pos: [9, 4, 0], 
      state: 2
    }, 
    {
      pos: [0, 4, 1], 
      state: 2
    }, 
    {
      pos: [1, 4, 1], 
      state: 8
    }, 
    {
      pos: [9, 4, 1], 
      state: 2
    }, 
    {
      pos: [0, 4, 2], 
      state: 2
    }, 
    {
      pos: [2, 4, 2], 
      state: 2
    }, 
    {
      pos: [3, 4, 2], 
      state: 2
    }, 
    {
      pos: [4, 4, 2], 
      state: 2
    }, 
    {
      pos: [5, 4, 2], 
      state: 2
    }, 
    {
      pos: [6, 4, 2], 
      state: 2
    }, 
    {
      pos: [7, 4, 2], 
      state: 16
    }, 
    {
      pos: [8, 4, 2], 
      state: 2
    }, 
    {
      pos: [0, 4, 3], 
      state: 2
    }, 
    {
      pos: [1, 4, 3], 
      state: 14
    }, 
    {
      pos: [2, 4, 3], 
      state: 2
    }, 
    {
      pos: [3, 4, 3], 
      state: 2
    }, 
    {
      pos: [4, 4, 3], 
      state: 2
    }, 
    {
      pos: [5, 4, 3], 
      state: 2
    }, 
    {
      pos: [6, 4, 3], 
      state: 2
    }, 
    {
      pos: [7, 4, 3], 
      state: 2
    }, 
    {
      pos: [8, 4, 3], 
      state: 17
    }, 
    {
      pos: [0, 4, 4], 
      state: 2
    }, 
    {
      pos: [2, 4, 4], 
      state: 2
    }, 
    {
      pos: [3, 4, 4], 
      state: 2
    }, 
    {
      pos: [4, 4, 4], 
      state: 7
    }, 
    {
      pos: [5, 4, 4], 
      state: 2
    }, 
    {
      pos: [6, 4, 4], 
      state: 2
    }, 
    {
      pos: [7, 4, 4], 
      state: 18
    }, 
    {
      pos: [8, 4, 4], 
      state: 2
    }, 
    {
      pos: [0, 4, 5], 
      state: 2
    }, 
    {
      pos: [1, 4, 5], 
      state: 6
    }, 
    {
      pos: [9, 4, 5], 
      state: 2
    }, 
    {
      pos: [0, 4, 6], 
      state: 2
    }, 
    {
      pos: [1, 4, 6], 
      state: 2
    }, 
    {
      pos: [2, 4, 6], 
      state: 3
    }, 
    {
      pos: [4, 4, 6], 
      state: 15
    }, 
    {
      pos: [5, 4, 6], 
      state: 2
    }, 
    {
      pos: [6, 4, 6], 
      state: 2
    }, 
    {
      pos: [7, 4, 6], 
      state: 2
    }, 
    {
      pos: [8, 4, 6], 
      state: 2
    }, 
    {
      pos: [9, 4, 6], 
      state: 2
    }, 
    {
      pos: [2, 5, 1], 
      state: 0
    }, 
    {
      pos: [3, 5, 1], 
      state: 0
    }, 
    {
      pos: [4, 5, 1], 
      state: 0
    }, 
    {
      pos: [1, 5, 2], 
      state: 0
    }, 
    {
      pos: [2, 5, 2], 
      state: 0
    }, 
    {
      pos: [3, 5, 2], 
      state: 0
    }, 
    {
      pos: [4, 5, 2], 
      state: 0
    }, 
    {
      pos: [5, 5, 2], 
      state: 0
    }, 
    {
      pos: [6, 5, 2], 
      state: 0
    }, 
    {
      pos: [7, 5, 2], 
      state: 0
    }, 
    {
      pos: [8, 5, 2], 
      state: 0
    }, 
    {
      pos: [1, 5, 3], 
      state: 0
    }, 
    {
      pos: [2, 5, 3], 
      state: 0
    }, 
    {
      pos: [3, 5, 3], 
      state: 0
    }, 
    {
      pos: [4, 5, 3], 
      state: 0
    }, 
    {
      pos: [5, 5, 3], 
      state: 0
    }, 
    {
      pos: [6, 5, 3], 
      state: 0
    }, 
    {
      pos: [7, 5, 3], 
      state: 0
    }, 
    {
      pos: [8, 5, 3], 
      state: 0
    }, 
    {
      pos: [1, 5, 4], 
      state: 0
    }, 
    {
      pos: [2, 5, 4], 
      state: 0
    }, 
    {
      pos: [3, 5, 4], 
      state: 0
    }, 
    {
      pos: [5, 5, 4], 
      state: 0
    }, 
    {
      pos: [6, 5, 4], 
      state: 0
    }, 
    {
      pos: [7, 5, 4], 
      state: 0
    }, 
    {
      pos: [8, 5, 4], 
      state: 0
    }, 
    {
      pos: [2, 5, 5], 
      state: 0
    }, 
    {
      pos: [3, 5, 5], 
      state: 0
    }, 
    {
      pos: [4, 5, 5], 
      state: 0
    }, 
    {
      pos: [0, 5, 0], 
      state: 2
    }, 
    {
      pos: [1, 5, 0], 
      state: 2
    }, 
    {
      pos: [2, 5, 0], 
      state: 2
    }, 
    {
      pos: [3, 5, 0], 
      state: 19
    }, 
    {
      pos: [4, 5, 0], 
      state: 2
    }, 
    {
      pos: [5, 5, 0], 
      state: 2
    }, 
    {
      pos: [6, 5, 0], 
      state: 2
    }, 
    {
      pos: [7, 5, 0], 
      state: 2
    }, 
    {
      pos: [8, 5, 0], 
      state: 2
    }, 
    {
      pos: [9, 5, 0], 
      state: 2
    }, 
    {
      pos: [0, 5, 1], 
      state: 2
    }, 
    {
      pos: [1, 5, 1], 
      state: 2
    }, 
    {
      pos: [5, 5, 1], 
      state: 2
    }, 
    {
      pos: [6, 5, 1], 
      state: 2
    }, 
    {
      pos: [7, 5, 1], 
      state: 2
    }, 
    {
      pos: [8, 5, 1], 
      state: 2
    }, 
    {
      pos: [9, 5, 1], 
      state: 2
    }, 
    {
      pos: [0, 5, 2], 
      state: 2
    }, 
    {
      pos: [9, 5, 2], 
      state: 2
    }, 
    {
      pos: [0, 5, 3], 
      state: 2
    }, 
    {
      pos: [9, 5, 3], 
      state: 2
    }, 
    {
      pos: [0, 5, 4], 
      state: 2
    }, 
    {
      pos: [4, 5, 4], 
      state: 7
    }, 
    {
      pos: [9, 5, 4], 
      state: 2
    }, 
    {
      pos: [0, 5, 5], 
      state: 2
    }, 
    {
      pos: [1, 5, 5], 
      state: 2
    }, 
    {
      pos: [5, 5, 5], 
      state: 2
    }, 
    {
      pos: [6, 5, 5], 
      state: 2
    }, 
    {
      pos: [7, 5, 5], 
      state: 2
    }, 
    {
      pos: [8, 5, 5], 
      state: 2
    }, 
    {
      pos: [9, 5, 5], 
      state: 2
    }, 
    {
      pos: [0, 5, 6], 
      state: 2
    }, 
    {
      pos: [1, 5, 6], 
      state: 2
    }, 
    {
      pos: [2, 5, 6], 
      state: 2
    }, 
    {
      pos: [3, 5, 6], 
      state: 19
    }, 
    {
      pos: [4, 5, 6], 
      state: 2
    }, 
    {
      pos: [5, 5, 6], 
      state: 2
    }, 
    {
      pos: [6, 5, 6], 
      state: 2
    }, 
    {
      pos: [7, 5, 6], 
      state: 2
    }, 
    {
      pos: [8, 5, 6], 
      state: 2
    }, 
    {
      pos: [9, 5, 6], 
      state: 2
    }, 
    {
      pos: [2, 6, 1], 
      state: 0
    }, 
    {
      pos: [3, 6, 1], 
      state: 0
    }, 
    {
      pos: [4, 6, 1], 
      state: 0
    }, 
    {
      pos: [1, 6, 2], 
      state: 0
    }, 
    {
      pos: [5, 6, 2], 
      state: 0
    }, 
    {
      pos: [1, 6, 3], 
      state: 0
    }, 
    {
      pos: [5, 6, 3], 
      state: 0
    }, 
    {
      pos: [1, 6, 4], 
      state: 0
    }, 
    {
      pos: [5, 6, 4], 
      state: 0
    }, 
    {
      pos: [2, 6, 5], 
      state: 0
    }, 
    {
      pos: [3, 6, 5], 
      state: 0
    }, 
    {
      pos: [4, 6, 5], 
      state: 0
    }, 
    {
      pos: [0, 6, 0], 
      state: 2
    }, 
    {
      pos: [1, 6, 0], 
      state: 2
    }, 
    {
      pos: [2, 6, 0], 
      state: 2
    }, 
    {
      pos: [3, 6, 0], 
      state: 2
    }, 
    {
      pos: [4, 6, 0], 
      state: 2
    }, 
    {
      pos: [5, 6, 0], 
      state: 2
    }, 
    {
      pos: [6, 6, 0], 
      state: 2
    }, 
    {
      pos: [7, 6, 0], 
      state: 2
    }, 
    {
      pos: [8, 6, 0], 
      state: 2
    }, 
    {
      pos: [9, 6, 0], 
      state: 2
    }, 
    {
      pos: [0, 6, 1], 
      state: 2
    }, 
    {
      pos: [1, 6, 1], 
      state: 2
    }, 
    {
      pos: [5, 6, 1], 
      state: 2
    }, 
    {
      pos: [6, 6, 1], 
      state: 2
    }, 
    {
      pos: [7, 6, 1], 
      state: 2
    }, 
    {
      pos: [8, 6, 1], 
      state: 2
    }, 
    {
      pos: [9, 6, 1], 
      state: 2
    }, 
    {
      pos: [0, 6, 2], 
      state: 2
    }, 
    {
      pos: [2, 6, 2], 
      state: 2
    }, 
    {
      pos: [3, 6, 2], 
      state: 2
    }, 
    {
      pos: [4, 6, 2], 
      state: 2
    }, 
    {
      pos: [6, 6, 2], 
      state: 2
    }, 
    {
      pos: [7, 6, 2], 
      state: 2
    }, 
    {
      pos: [8, 6, 2], 
      state: 2
    }, 
    {
      pos: [9, 6, 2], 
      state: 2
    }, 
    {
      pos: [0, 6, 3], 
      state: 2
    }, 
    {
      pos: [2, 6, 3], 
      state: 2
    }, 
    {
      pos: [3, 6, 3], 
      state: 2
    }, 
    {
      pos: [4, 6, 3], 
      state: 2
    }, 
    {
      pos: [6, 6, 3], 
      state: 2
    }, 
    {
      pos: [7, 6, 3], 
      state: 10
    }, 
    {
      pos: [8, 6, 3], 
      state: 2
    }, 
    {
      pos: [9, 6, 3], 
      state: 2
    }, 
    {
      pos: [0, 6, 4], 
      state: 2
    }, 
    {
      pos: [2, 6, 4], 
      state: 2
    }, 
    {
      pos: [3, 6, 4], 
      state: 2
    }, 
    {
      pos: [4, 6, 4], 
      state: 7
    }, 
    {
      pos: [6, 6, 4], 
      state: 2
    }, 
    {
      pos: [7, 6, 4], 
      state: 2
    }, 
    {
      pos: [8, 6, 4], 
      state: 2
    }, 
    {
      pos: [9, 6, 4], 
      state: 2
    }, 
    {
      pos: [0, 6, 5], 
      state: 2
    }, 
    {
      pos: [1, 6, 5], 
      state: 2
    }, 
    {
      pos: [5, 6, 5], 
      state: 2
    }, 
    {
      pos: [6, 6, 5], 
      state: 2
    }, 
    {
      pos: [7, 6, 5], 
      state: 2
    }, 
    {
      pos: [8, 6, 5], 
      state: 2
    }, 
    {
      pos: [9, 6, 5], 
      state: 2
    }, 
    {
      pos: [0, 6, 6], 
      state: 2
    }, 
    {
      pos: [1, 6, 6], 
      state: 2
    }, 
    {
      pos: [2, 6, 6], 
      state: 2
    }, 
    {
      pos: [3, 6, 6], 
      state: 2
    }, 
    {
      pos: [4, 6, 6], 
      state: 2
    }, 
    {
      pos: [5, 6, 6], 
      state: 2
    }, 
    {
      pos: [6, 6, 6], 
      state: 2
    }, 
    {
      pos: [7, 6, 6], 
      state: 2
    }, 
    {
      pos: [8, 6, 6], 
      state: 2
    }, 
    {
      pos: [9, 6, 6], 
      state: 2
    }, 
    {
      pos: [2, 7, 1], 
      state: 0
    }, 
    {
      pos: [4, 7, 1], 
      state: 0
    }, 
    {
      pos: [1, 7, 2], 
      state: 0
    }, 
    {
      pos: [5, 7, 2], 
      state: 0
    }, 
    {
      pos: [1, 7, 4], 
      state: 0
    }, 
    {
      pos: [5, 7, 4], 
      state: 0
    }, 
    {
      pos: [2, 7, 5], 
      state: 0
    }, 
    {
      pos: [4, 7, 5], 
      state: 0
    }, 
    {
      pos: [0, 7, 0], 
      state: 2
    }, 
    {
      pos: [1, 7, 0], 
      state: 2
    }, 
    {
      pos: [2, 7, 0], 
      state: 2
    }, 
    {
      pos: [3, 7, 0], 
      state: 2
    }, 
    {
      pos: [4, 7, 0], 
      state: 2
    }, 
    {
      pos: [5, 7, 0], 
      state: 2
    }, 
    {
      pos: [6, 7, 0], 
      state: 2
    }, 
    {
      pos: [7, 7, 0], 
      state: 2
    }, 
    {
      pos: [8, 7, 0], 
      state: 2
    }, 
    {
      pos: [9, 7, 0], 
      state: 2
    }, 
    {
      pos: [0, 7, 1], 
      state: 2
    }, 
    {
      pos: [1, 7, 1], 
      state: 2
    }, 
    {
      pos: [3, 7, 1], 
      state: 9
    }, 
    {
      pos: [5, 7, 1], 
      state: 2
    }, 
    {
      pos: [6, 7, 1], 
      state: 2
    }, 
    {
      pos: [7, 7, 1], 
      state: 2
    }, 
    {
      pos: [8, 7, 1], 
      state: 2
    }, 
    {
      pos: [9, 7, 1], 
      state: 2
    }, 
    {
      pos: [0, 7, 2], 
      state: 2
    }, 
    {
      pos: [2, 7, 2], 
      state: 16
    }, 
    {
      pos: [3, 7, 2], 
      state: 2
    }, 
    {
      pos: [4, 7, 2], 
      state: 2
    }, 
    {
      pos: [6, 7, 2], 
      state: 2
    }, 
    {
      pos: [7, 7, 2], 
      state: 2
    }, 
    {
      pos: [8, 7, 2], 
      state: 2
    }, 
    {
      pos: [9, 7, 2], 
      state: 2
    }, 
    {
      pos: [0, 7, 3], 
      state: 2
    }, 
    {
      pos: [1, 7, 3], 
      state: 12
    }, 
    {
      pos: [2, 7, 3], 
      state: 2
    }, 
    {
      pos: [3, 7, 3], 
      state: 2
    }, 
    {
      pos: [4, 7, 3], 
      state: 2
    }, 
    {
      pos: [5, 7, 3], 
      state: 12
    }, 
    {
      pos: [6, 7, 3], 
      state: 2
    }, 
    {
      pos: [7, 7, 3], 
      state: 2
    }, 
    {
      pos: [8, 7, 3], 
      state: 2
    }, 
    {
      pos: [9, 7, 3], 
      state: 2
    }, 
    {
      pos: [0, 7, 4], 
      state: 2
    }, 
    {
      pos: [2, 7, 4], 
      state: 18
    }, 
    {
      pos: [3, 7, 4], 
      state: 2
    }, 
    {
      pos: [4, 7, 4], 
      state: 7
    }, 
    {
      pos: [6, 7, 4], 
      state: 2
    }, 
    {
      pos: [7, 7, 4], 
      state: 2
    }, 
    {
      pos: [8, 7, 4], 
      state: 2
    }, 
    {
      pos: [9, 7, 4], 
      state: 2
    }, 
    {
      pos: [0, 7, 5], 
      state: 2
    }, 
    {
      pos: [1, 7, 5], 
      state: 2
    }, 
    {
      pos: [3, 7, 5], 
      state: 9
    }, 
    {
      pos: [5, 7, 5], 
      state: 2
    }, 
    {
      pos: [6, 7, 5], 
      state: 2
    }, 
    {
      pos: [7, 7, 5], 
      state: 2
    }, 
    {
      pos: [8, 7, 5], 
      state: 2
    }, 
    {
      pos: [9, 7, 5], 
      state: 2
    }, 
    {
      pos: [0, 7, 6], 
      state: 2
    }, 
    {
      pos: [1, 7, 6], 
      state: 2
    }, 
    {
      pos: [2, 7, 6], 
      state: 2
    }, 
    {
      pos: [3, 7, 6], 
      state: 2
    }, 
    {
      pos: [4, 7, 6], 
      state: 2
    }, 
    {
      pos: [5, 7, 6], 
      state: 2
    }, 
    {
      pos: [6, 7, 6], 
      state: 2
    }, 
    {
      pos: [7, 7, 6], 
      state: 2
    }, 
    {
      pos: [8, 7, 6], 
      state: 2
    }, 
    {
      pos: [9, 7, 6], 
      state: 2
    }, 
    {
      pos: [2, 8, 1], 
      state: 0
    }, 
    {
      pos: [4, 8, 1], 
      state: 0
    }, 
    {
      pos: [1, 8, 2], 
      state: 0
    }, 
    {
      pos: [5, 8, 2], 
      state: 0
    }, 
    {
      pos: [1, 8, 4], 
      state: 0
    }, 
    {
      pos: [5, 8, 4], 
      state: 0
    }, 
    {
      pos: [2, 8, 5], 
      state: 0
    }, 
    {
      pos: [4, 8, 5], 
      state: 0
    }, 
    {
      pos: [0, 8, 0], 
      state: 2
    }, 
    {
      pos: [1, 8, 0], 
      state: 2
    }, 
    {
      pos: [2, 8, 0], 
      state: 2
    }, 
    {
      pos: [3, 8, 0], 
      state: 2
    }, 
    {
      pos: [4, 8, 0], 
      state: 2
    }, 
    {
      pos: [5, 8, 0], 
      state: 2
    }, 
    {
      pos: [6, 8, 0], 
      state: 2
    }, 
    {
      pos: [7, 8, 0], 
      state: 2
    }, 
    {
      pos: [8, 8, 0], 
      state: 2
    }, 
    {
      pos: [9, 8, 0], 
      state: 2
    }, 
    {
      pos: [0, 8, 1], 
      state: 2
    }, 
    {
      pos: [1, 8, 1], 
      state: 20
    }, 
    {
      pos: [3, 8, 1], 
      state: 13
    }, 
    {
      pos: [5, 8, 1], 
      state: 20
    }, 
    {
      pos: [6, 8, 1], 
      state: 2
    }, 
    {
      pos: [7, 8, 1], 
      state: 2
    }, 
    {
      pos: [8, 8, 1], 
      state: 2
    }, 
    {
      pos: [9, 8, 1], 
      state: 2
    }, 
    {
      pos: [0, 8, 2], 
      state: 2
    }, 
    {
      pos: [2, 8, 2], 
      state: 2
    }, 
    {
      pos: [3, 8, 2], 
      state: 2
    }, 
    {
      pos: [4, 8, 2], 
      state: 2
    }, 
    {
      pos: [6, 8, 2], 
      state: 2
    }, 
    {
      pos: [7, 8, 2], 
      state: 2
    }, 
    {
      pos: [8, 8, 2], 
      state: 2
    }, 
    {
      pos: [9, 8, 2], 
      state: 2
    }, 
    {
      pos: [0, 8, 3], 
      state: 2
    }, 
    {
      pos: [1, 8, 3], 
      state: 14
    }, 
    {
      pos: [2, 8, 3], 
      state: 2
    }, 
    {
      pos: [3, 8, 3], 
      state: 2
    }, 
    {
      pos: [4, 8, 3], 
      state: 2
    }, 
    {
      pos: [5, 8, 3], 
      state: 14
    }, 
    {
      pos: [6, 8, 3], 
      state: 2
    }, 
    {
      pos: [7, 8, 3], 
      state: 2
    }, 
    {
      pos: [8, 8, 3], 
      state: 2
    }, 
    {
      pos: [9, 8, 3], 
      state: 2
    }, 
    {
      pos: [0, 8, 4], 
      state: 2
    }, 
    {
      pos: [2, 8, 4], 
      state: 2
    }, 
    {
      pos: [3, 8, 4], 
      state: 2
    }, 
    {
      pos: [4, 8, 4], 
      state: 7
    }, 
    {
      pos: [6, 8, 4], 
      state: 2
    }, 
    {
      pos: [7, 8, 4], 
      state: 2
    }, 
    {
      pos: [8, 8, 4], 
      state: 2
    }, 
    {
      pos: [9, 8, 4], 
      state: 2
    }, 
    {
      pos: [0, 8, 5], 
      state: 2
    }, 
    {
      pos: [1, 8, 5], 
      state: 21
    }, 
    {
      pos: [3, 8, 5], 
      state: 13
    }, 
    {
      pos: [5, 8, 5], 
      state: 21
    }, 
    {
      pos: [6, 8, 5], 
      state: 2
    }, 
    {
      pos: [7, 8, 5], 
      state: 2
    }, 
    {
      pos: [8, 8, 5], 
      state: 2
    }, 
    {
      pos: [9, 8, 5], 
      state: 2
    }, 
    {
      pos: [0, 8, 6], 
      state: 2
    }, 
    {
      pos: [1, 8, 6], 
      state: 2
    }, 
    {
      pos: [2, 8, 6], 
      state: 2
    }, 
    {
      pos: [3, 8, 6], 
      state: 2
    }, 
    {
      pos: [4, 8, 6], 
      state: 2
    }, 
    {
      pos: [5, 8, 6], 
      state: 2
    }, 
    {
      pos: [6, 8, 6], 
      state: 2
    }, 
    {
      pos: [7, 8, 6], 
      state: 2
    }, 
    {
      pos: [8, 8, 6], 
      state: 2
    }, 
    {
      pos: [9, 8, 6], 
      state: 2
    }, 
    {
      pos: [1, 9, 1], 
      state: 0
    }, 
    {
      pos: [2, 9, 1], 
      state: 0
    }, 
    {
      pos: [3, 9, 1], 
      state: 0
    }, 
    {
      pos: [4, 9, 1], 
      state: 0
    }, 
    {
      pos: [5, 9, 1], 
      state: 0
    }, 
    {
      pos: [1, 9, 2], 
      state: 0
    }, 
    {
      pos: [2, 9, 2], 
      state: 0
    }, 
    {
      pos: [3, 9, 2], 
      state: 0
    }, 
    {
      pos: [4, 9, 2], 
      state: 0
    }, 
    {
      pos: [5, 9, 2], 
      state: 0
    }, 
    {
      pos: [1, 9, 3], 
      state: 0
    }, 
    {
      pos: [2, 9, 3], 
      state: 0
    }, 
    {
      pos: [3, 9, 3], 
      state: 0
    }, 
    {
      pos: [4, 9, 3], 
      state: 0
    }, 
    {
      pos: [5, 9, 3], 
      state: 0
    }, 
    {
      pos: [1, 9, 4], 
      state: 0
    }, 
    {
      pos: [2, 9, 4], 
      state: 0
    }, 
    {
      pos: [3, 9, 4], 
      state: 0
    }, 
    {
      pos: [5, 9, 4], 
      state: 0
    }, 
    {
      pos: [1, 9, 5], 
      state: 0
    }, 
    {
      pos: [2, 9, 5], 
      state: 0
    }, 
    {
      pos: [3, 9, 5], 
      state: 0
    }, 
    {
      pos: [4, 9, 5], 
      state: 0
    }, 
    {
      pos: [5, 9, 5], 
      state: 0
    }, 
    {
      pos: [0, 9, 0], 
      state: 2
    }, 
    {
      pos: [1, 9, 0], 
      state: 2
    }, 
    {
      pos: [2, 9, 0], 
      state: 2
    }, 
    {
      pos: [3, 9, 0], 
      state: 2
    }, 
    {
      pos: [4, 9, 0], 
      state: 2
    }, 
    {
      pos: [5, 9, 0], 
      state: 2
    }, 
    {
      pos: [6, 9, 0], 
      state: 2
    }, 
    {
      pos: [7, 9, 0], 
      state: 2
    }, 
    {
      pos: [8, 9, 0], 
      state: 2
    }, 
    {
      pos: [9, 9, 0], 
      state: 2
    }, 
    {
      pos: [0, 9, 1], 
      state: 2
    }, 
    {
      pos: [6, 9, 1], 
      state: 2
    }, 
    {
      pos: [7, 9, 1], 
      state: 2
    }, 
    {
      pos: [8, 9, 1], 
      state: 2
    }, 
    {
      pos: [9, 9, 1], 
      state: 2
    }, 
    {
      pos: [0, 9, 2], 
      state: 2
    }, 
    {
      pos: [6, 9, 2], 
      state: 2
    }, 
    {
      pos: [7, 9, 2], 
      state: 2
    }, 
    {
      pos: [8, 9, 2], 
      state: 2
    }, 
    {
      pos: [9, 9, 2], 
      state: 2
    }, 
    {
      pos: [0, 9, 3], 
      state: 2
    }, 
    {
      pos: [6, 9, 3], 
      state: 2
    }, 
    {
      pos: [7, 9, 3], 
      state: 2
    }, 
    {
      pos: [8, 9, 3], 
      state: 2
    }, 
    {
      pos: [9, 9, 3], 
      state: 2
    }, 
    {
      pos: [0, 9, 4], 
      state: 2
    }, 
    {
      pos: [4, 9, 4], 
      state: 7
    }, 
    {
      pos: [6, 9, 4], 
      state: 2
    }, 
    {
      pos: [7, 9, 4], 
      state: 2
    }, 
    {
      pos: [8, 9, 4], 
      state: 2
    }, 
    {
      pos: [9, 9, 4], 
      state: 2
    }, 
    {
      pos: [0, 9, 5], 
      state: 2
    }, 
    {
      pos: [6, 9, 5], 
      state: 2
    }, 
    {
      pos: [7, 9, 5], 
      state: 2
    }, 
    {
      pos: [8, 9, 5], 
      state: 2
    }, 
    {
      pos: [9, 9, 5], 
      state: 2
    }, 
    {
      pos: [0, 9, 6], 
      state: 2
    }, 
    {
      pos: [1, 9, 6], 
      state: 2
    }, 
    {
      pos: [2, 9, 6], 
      state: 2
    }, 
    {
      pos: [3, 9, 6], 
      state: 2
    }, 
    {
      pos: [4, 9, 6], 
      state: 2
    }, 
    {
      pos: [5, 9, 6], 
      state: 2
    }, 
    {
      pos: [6, 9, 6], 
      state: 2
    }, 
    {
      pos: [7, 9, 6], 
      state: 2
    }, 
    {
      pos: [8, 9, 6], 
      state: 2
    }, 
    {
      pos: [9, 9, 6], 
      state: 2
    }, 
    {
      pos: [2, 10, 1], 
      state: 0
    }, 
    {
      pos: [3, 10, 1], 
      state: 0
    }, 
    {
      pos: [4, 10, 1], 
      state: 0
    }, 
    {
      pos: [1, 10, 2], 
      state: 0
    }, 
    {
      pos: [5, 10, 2], 
      state: 0
    }, 
    {
      pos: [1, 10, 3], 
      state: 0
    }, 
    {
      pos: [5, 10, 3], 
      state: 0
    }, 
    {
      pos: [1, 10, 4], 
      state: 0
    }, 
    {
      pos: [5, 10, 4], 
      state: 0
    }, 
    {
      pos: [2, 10, 5], 
      state: 0
    }, 
    {
      pos: [3, 10, 5], 
      state: 0
    }, 
    {
      pos: [4, 10, 5], 
      state: 0
    }, 
    {
      pos: [0, 10, 0], 
      state: 2
    }, 
    {
      pos: [1, 10, 0], 
      state: 2
    }, 
    {
      pos: [2, 10, 0], 
      state: 2
    }, 
    {
      pos: [3, 10, 0], 
      state: 2
    }, 
    {
      pos: [4, 10, 0], 
      state: 2
    }, 
    {
      pos: [5, 10, 0], 
      state: 2
    }, 
    {
      pos: [6, 10, 0], 
      state: 2
    }, 
    {
      pos: [7, 10, 0], 
      state: 2
    }, 
    {
      pos: [8, 10, 0], 
      state: 2
    }, 
    {
      pos: [9, 10, 0], 
      state: 2
    }, 
    {
      pos: [0, 10, 1], 
      state: 2
    }, 
    {
      pos: [1, 10, 1], 
      state: 2
    }, 
    {
      pos: [5, 10, 1], 
      state: 2
    }, 
    {
      pos: [6, 10, 1], 
      state: 2
    }, 
    {
      pos: [7, 10, 1], 
      state: 2
    }, 
    {
      pos: [8, 10, 1], 
      state: 2
    }, 
    {
      pos: [9, 10, 1], 
      state: 2
    }, 
    {
      pos: [0, 10, 2], 
      state: 2
    }, 
    {
      pos: [2, 10, 2], 
      state: 2
    }, 
    {
      pos: [3, 10, 2], 
      state: 2
    }, 
    {
      pos: [4, 10, 2], 
      state: 2
    }, 
    {
      pos: [6, 10, 2], 
      state: 2
    }, 
    {
      pos: [7, 10, 2], 
      state: 2
    }, 
    {
      pos: [8, 10, 2], 
      state: 2
    }, 
    {
      pos: [9, 10, 2], 
      state: 2
    }, 
    {
      pos: [0, 10, 3], 
      state: 2
    }, 
    {
      pos: [2, 10, 3], 
      state: 2
    }, 
    {
      pos: [3, 10, 3], 
      state: 10
    }, 
    {
      pos: [4, 10, 3], 
      state: 2
    }, 
    {
      pos: [6, 10, 3], 
      state: 2
    }, 
    {
      pos: [7, 10, 3], 
      state: 2
    }, 
    {
      pos: [8, 10, 3], 
      state: 2
    }, 
    {
      pos: [9, 10, 3], 
      state: 2
    }, 
    {
      pos: [0, 10, 4], 
      state: 2
    }, 
    {
      pos: [2, 10, 4], 
      state: 2
    }, 
    {
      pos: [3, 10, 4], 
      state: 2
    }, 
    {
      pos: [4, 10, 4], 
      state: 7
    }, 
    {
      pos: [6, 10, 4], 
      state: 2
    }, 
    {
      pos: [7, 10, 4], 
      state: 2
    }, 
    {
      pos: [8, 10, 4], 
      state: 2
    }, 
    {
      pos: [9, 10, 4], 
      state: 2
    }, 
    {
      pos: [0, 10, 5], 
      state: 2
    }, 
    {
      pos: [1, 10, 5], 
      state: 2
    }, 
    {
      pos: [5, 10, 5], 
      state: 2
    }, 
    {
      pos: [6, 10, 5], 
      state: 2
    }, 
    {
      pos: [7, 10, 5], 
      state: 2
    }, 
    {
      pos: [8, 10, 5], 
      state: 2
    }, 
    {
      pos: [9, 10, 5], 
      state: 2
    }, 
    {
      pos: [0, 10, 6], 
      state: 2
    }, 
    {
      pos: [1, 10, 6], 
      state: 2
    }, 
    {
      pos: [2, 10, 6], 
      state: 2
    }, 
    {
      pos: [3, 10, 6], 
      state: 2
    }, 
    {
      pos: [4, 10, 6], 
      state: 2
    }, 
    {
      pos: [5, 10, 6], 
      state: 2
    }, 
    {
      pos: [6, 10, 6], 
      state: 2
    }, 
    {
      pos: [7, 10, 6], 
      state: 2
    }, 
    {
      pos: [8, 10, 6], 
      state: 2
    }, 
    {
      pos: [9, 10, 6], 
      state: 2
    }, 
    {
      pos: [3, 11, 1], 
      state: 0
    }, 
    {
      pos: [1, 11, 3], 
      state: 0
    }, 
    {
      pos: [5, 11, 3], 
      state: 0
    }, 
    {
      pos: [3, 11, 5], 
      state: 0
    }, 
    {
      pos: [0, 11, 0], 
      state: 2
    }, 
    {
      pos: [1, 11, 0], 
      state: 2
    }, 
    {
      pos: [2, 11, 0], 
      state: 2
    }, 
    {
      pos: [3, 11, 0], 
      state: 2
    }, 
    {
      pos: [4, 11, 0], 
      state: 2
    }, 
    {
      pos: [5, 11, 0], 
      state: 2
    }, 
    {
      pos: [6, 11, 0], 
      state: 2
    }, 
    {
      pos: [7, 11, 0], 
      state: 2
    }, 
    {
      pos: [8, 11, 0], 
      state: 2
    }, 
    {
      pos: [9, 11, 0], 
      state: 2
    }, 
    {
      pos: [0, 11, 1], 
      state: 2
    }, 
    {
      pos: [1, 11, 1], 
      state: 2
    }, 
    {
      pos: [2, 11, 1], 
      state: 2
    }, 
    {
      pos: [4, 11, 1], 
      state: 2
    }, 
    {
      pos: [5, 11, 1], 
      state: 2
    }, 
    {
      pos: [6, 11, 1], 
      state: 2
    }, 
    {
      pos: [7, 11, 1], 
      state: 2
    }, 
    {
      pos: [8, 11, 1], 
      state: 2
    }, 
    {
      pos: [9, 11, 1], 
      state: 2
    }, 
    {
      pos: [0, 11, 2], 
      state: 2
    }, 
    {
      pos: [1, 11, 2], 
      state: 2
    }, 
    {
      pos: [2, 11, 2], 
      state: 2
    }, 
    {
      pos: [3, 11, 2], 
      state: 2
    }, 
    {
      pos: [4, 11, 2], 
      state: 2
    }, 
    {
      pos: [5, 11, 2], 
      state: 2
    }, 
    {
      pos: [6, 11, 2], 
      state: 2
    }, 
    {
      pos: [7, 11, 2], 
      state: 2
    }, 
    {
      pos: [8, 11, 2], 
      state: 2
    }, 
    {
      pos: [9, 11, 2], 
      state: 2
    }, 
    {
      pos: [0, 11, 3], 
      state: 2
    }, 
    {
      pos: [2, 11, 3], 
      state: 2
    }, 
    {
      pos: [3, 11, 3], 
      state: 2
    }, 
    {
      pos: [4, 11, 3], 
      state: 2
    }, 
    {
      pos: [6, 11, 3], 
      state: 2
    }, 
    {
      pos: [7, 11, 3], 
      state: 2
    }, 
    {
      pos: [8, 11, 3], 
      state: 2
    }, 
    {
      pos: [9, 11, 3], 
      state: 2
    }, 
    {
      pos: [0, 11, 4], 
      state: 2
    }, 
    {
      pos: [1, 11, 4], 
      state: 2
    }, 
    {
      pos: [2, 11, 4], 
      state: 2
    }, 
    {
      pos: [3, 11, 4], 
      state: 2
    }, 
    {
      pos: [4, 11, 4], 
      state: 2
    }, 
    {
      pos: [5, 11, 4], 
      state: 2
    }, 
    {
      pos: [6, 11, 4], 
      state: 2
    }, 
    {
      pos: [7, 11, 4], 
      state: 2
    }, 
    {
      pos: [8, 11, 4], 
      state: 2
    }, 
    {
      pos: [9, 11, 4], 
      state: 2
    }, 
    {
      pos: [0, 11, 5], 
      state: 2
    }, 
    {
      pos: [1, 11, 5], 
      state: 2
    }, 
    {
      pos: [2, 11, 5], 
      state: 2
    }, 
    {
      pos: [4, 11, 5], 
      state: 2
    }, 
    {
      pos: [5, 11, 5], 
      state: 2
    }, 
    {
      pos: [6, 11, 5], 
      state: 2
    }, 
    {
      pos: [7, 11, 5], 
      state: 2
    }, 
    {
      pos: [8, 11, 5], 
      state: 2
    }, 
    {
      pos: [9, 11, 5], 
      state: 2
    }, 
    {
      pos: [0, 11, 6], 
      state: 2
    }, 
    {
      pos: [1, 11, 6], 
      state: 2
    }, 
    {
      pos: [2, 11, 6], 
      state: 2
    }, 
    {
      pos: [3, 11, 6], 
      state: 2
    }, 
    {
      pos: [4, 11, 6], 
      state: 2
    }, 
    {
      pos: [5, 11, 6], 
      state: 2
    }, 
    {
      pos: [6, 11, 6], 
      state: 2
    }, 
    {
      pos: [7, 11, 6], 
      state: 2
    }, 
    {
      pos: [8, 11, 6], 
      state: 2
    }, 
    {
      pos: [9, 11, 6], 
      state: 2
    }
  ], 
  palette: [
    {
      Name: "minecraft:cobblestone"
    }, 
    {
      Properties: {
        facing: "west"
      }, 
      Name: "minecraft:jigsaw"
    }, 
    {
      Name: "minecraft:air"
    }, 
    {
      Properties: {
        half: "bottom", 
        waterlogged: "false", 
        shape: "straight", 
        facing: "east"
      }, 
      Name: "minecraft:cobblestone_stairs"
    }, 
    {
      Properties: {
        has_bottle_0: "false", 
        has_bottle_1: "false", 
        has_bottle_2: "false"
      }, 
      Name: "minecraft:brewing_stand"
    }, 
    {
      Properties: {
        east: "low", 
        waterlogged: "false", 
        south: "none", 
        north: "none", 
        west: "none", 
        up: "true"
      }, 
      Name: "minecraft:cobblestone_wall"
    }, 
    {
      Properties: {
        half: "bottom", 
        waterlogged: "false", 
        shape: "straight", 
        facing: "north"
      }, 
      Name: "minecraft:cobblestone_stairs"
    }, 
    {
      Properties: {
        waterlogged: "false", 
        facing: "north"
      }, 
      Name: "minecraft:ladder"
    }, 
    {
      Properties: {
        half: "bottom", 
        waterlogged: "false", 
        shape: "straight", 
        facing: "south"
      }, 
      Name: "minecraft:cobblestone_stairs"
    }, 
    {
      Properties: {
        east: "true", 
        waterlogged: "false", 
        south: "false", 
        north: "false", 
        west: "true"
      }, 
      Name: "minecraft:yellow_stained_glass_pane"
    }, 
    {
      Name: "minecraft:torch"
    }, 
    {
      Properties: {
        facing: "east"
      }, 
      Name: "minecraft:wall_torch"
    }, 
    {
      Properties: {
        east: "false", 
        waterlogged: "false", 
        south: "true", 
        north: "true", 
        west: "false"
      }, 
      Name: "minecraft:yellow_stained_glass_pane"
    }, 
    {
      Properties: {
        east: "true", 
        waterlogged: "false", 
        south: "false", 
        north: "false", 
        west: "true"
      }, 
      Name: "minecraft:white_stained_glass_pane"
    }, 
    {
      Properties: {
        east: "false", 
        waterlogged: "false", 
        south: "true", 
        north: "true", 
        west: "false"
      }, 
      Name: "minecraft:white_stained_glass_pane"
    }, 
    {
      Properties: {
        half: "bottom", 
        waterlogged: "false", 
        shape: "straight", 
        facing: "west"
      }, 
      Name: "minecraft:cobblestone_stairs"
    }, 
    {
      Properties: {
        facing: "south"
      }, 
      Name: "minecraft:wall_torch"
    }, 
    {
      Properties: {
        facing: "west"
      }, 
      Name: "minecraft:wall_torch"
    }, 
    {
      Properties: {
        facing: "north"
      }, 
      Name: "minecraft:wall_torch"
    }, 
    {
      Properties: {
        waterlogged: "false", 
        type: "bottom"
      }, 
      Name: "minecraft:cobblestone_slab"
    }, 
    {
      Properties: {
        half: "top", 
        waterlogged: "false", 
        shape: "straight", 
        facing: "south"
      }, 
      Name: "minecraft:cobblestone_stairs"
    }, 
    {
      Properties: {
        half: "top", 
        waterlogged: "false", 
        shape: "straight", 
        facing: "north"
      }, 
      Name: "minecraft:cobblestone_stairs"
    }
  ]
}
