{
  size: [7, 6, 17], 
  entities: [], 
  blocks: [
    {
      pos: [1, 0, 0], 
      state: 0
    }, 
    {
      pos: [2, 0, 0], 
      state: 0
    }, 
    {
      pos: [3, 0, 0], 
      state: 0
    }, 
    {
      pos: [4, 0, 0], 
      state: 0
    }, 
    {
      pos: [5, 0, 0], 
      state: 0
    }, 
    {
      pos: [1, 0, 1], 
      state: 0
    }, 
    {
      pos: [2, 0, 1], 
      state: 0
    }, 
    {
      pos: [3, 0, 1], 
      state: 0
    }, 
    {
      pos: [4, 0, 1], 
      state: 0
    }, 
    {
      pos: [5, 0, 1], 
      state: 0
    }, 
    {
      pos: [1, 0, 2], 
      state: 0
    }, 
    {
      pos: [2, 0, 2], 
      state: 0
    }, 
    {
      pos: [4, 0, 2], 
      state: 0
    }, 
    {
      pos: [5, 0, 2], 
      state: 0
    }, 
    {
      pos: [2, 4, 2], 
      state: 1
    }, 
    {
      pos: [4, 4, 2], 
      state: 1
    }, 
    {
      pos: [1, 0, 3], 
      state: 0
    }, 
    {
      pos: [2, 0, 3], 
      state: 0
    }, 
    {
      pos: [3, 0, 3], 
      state: 0
    }, 
    {
      pos: [4, 0, 3], 
      state: 0
    }, 
    {
      pos: [5, 0, 3], 
      state: 0
    }, 
    {
      pos: [2, 4, 3], 
      state: 1
    }, 
    {
      pos: [4, 4, 3], 
      state: 1
    }, 
    {
      pos: [1, 0, 4], 
      state: 0
    }, 
    {
      pos: [2, 0, 4], 
      state: 0
    }, 
    {
      pos: [4, 0, 4], 
      state: 0
    }, 
    {
      pos: [5, 0, 4], 
      state: 0
    }, 
    {
      pos: [2, 4, 4], 
      state: 1
    }, 
    {
      pos: [4, 4, 4], 
      state: 1
    }, 
    {
      pos: [3, 5, 4], 
      state: 2
    }, 
    {
      pos: [1, 0, 5], 
      state: 3
    }, 
    {
      pos: [2, 0, 5], 
      state: 0
    }, 
    {
      pos: [3, 0, 5], 
      state: 0
    }, 
    {
      pos: [4, 0, 5], 
      state: 0
    }, 
    {
      pos: [5, 0, 5], 
      state: 3
    }, 
    {
      pos: [1, 1, 5], 
      state: 4
    }, 
    {
      pos: [5, 1, 5], 
      state: 4
    }, 
    {
      pos: [1, 2, 5], 
      state: 4
    }, 
    {
      pos: [5, 2, 5], 
      state: 4
    }, 
    {
      pos: [1, 3, 5], 
      state: 4
    }, 
    {
      pos: [2, 3, 5], 
      state: 5
    }, 
    {
      pos: [3, 3, 5], 
      state: 5
    }, 
    {
      pos: [4, 3, 5], 
      state: 5
    }, 
    {
      pos: [5, 3, 5], 
      state: 4
    }, 
    {
      pos: [2, 4, 5], 
      state: 6
    }, 
    {
      pos: [3, 4, 5], 
      state: 6
    }, 
    {
      pos: [4, 4, 5], 
      state: 6
    }, 
    {
      pos: [3, 5, 5], 
      state: 2
    }, 
    {
      pos: [1, 0, 6], 
      state: 3
    }, 
    {
      pos: [2, 0, 6], 
      state: 3
    }, 
    {
      pos: [3, 0, 6], 
      state: 0
    }, 
    {
      pos: [4, 0, 6], 
      state: 0
    }, 
    {
      pos: [5, 0, 6], 
      state: 3
    }, 
    {
      pos: [1, 1, 6], 
      state: 6
    }, 
    {
      pos: [2, 1, 6], 
      state: 7
    }, 
    {
      pos: [5, 1, 6], 
      state: 6
    }, 
    {
      pos: [1, 2, 6], 
      state: 6
    }, 
    {
      pos: [5, 2, 6], 
      state: 6
    }, 
    {
      pos: [1, 3, 6], 
      state: 6
    }, 
    {
      pos: [5, 3, 6], 
      state: 6
    }, 
    {
      pos: [3, 5, 6], 
      state: 2
    }, 
    {
      pos: [1, 0, 7], 
      state: 3
    }, 
    {
      pos: [2, 0, 7], 
      state: 0
    }, 
    {
      pos: [3, 0, 7], 
      state: 0
    }, 
    {
      pos: [4, 0, 7], 
      state: 3
    }, 
    {
      pos: [5, 0, 7], 
      state: 3
    }, 
    {
      pos: [1, 1, 7], 
      state: 6
    }, 
    {
      pos: [4, 1, 7], 
      state: 7
    }, 
    {
      pos: [5, 1, 7], 
      state: 6
    }, 
    {
      pos: [1, 2, 7], 
      state: 6
    }, 
    {
      pos: [5, 2, 7], 
      state: 6
    }, 
    {
      pos: [1, 3, 7], 
      state: 6
    }, 
    {
      pos: [5, 3, 7], 
      state: 6
    }, 
    {
      pos: [3, 5, 7], 
      state: 2
    }, 
    {
      pos: [1, 0, 8], 
      state: 3
    }, 
    {
      pos: [2, 0, 8], 
      state: 0
    }, 
    {
      pos: [3, 0, 8], 
      state: 0
    }, 
    {
      pos: [4, 0, 8], 
      state: 3
    }, 
    {
      pos: [5, 0, 8], 
      state: 3
    }, 
    {
      pos: [1, 1, 8], 
      state: 4
    }, 
    {
      pos: [4, 1, 8], 
      state: 7
    }, 
    {
      pos: [5, 1, 8], 
      state: 4
    }, 
    {
      pos: [1, 2, 8], 
      state: 4
    }, 
    {
      pos: [4, 2, 8], 
      state: 7
    }, 
    {
      pos: [5, 2, 8], 
      state: 4
    }, 
    {
      pos: [1, 3, 8], 
      state: 4
    }, 
    {
      pos: [5, 3, 8], 
      state: 4
    }, 
    {
      pos: [3, 5, 8], 
      state: 2
    }, 
    {
      pos: [0, 0, 9], 
      state: 3
    }, 
    {
      pos: [1, 0, 9], 
      state: 3
    }, 
    {
      pos: [2, 0, 9], 
      state: 0
    }, 
    {
      pos: [3, 0, 9], 
      state: 0
    }, 
    {
      pos: [4, 0, 9], 
      state: 3
    }, 
    {
      pos: [5, 0, 9], 
      state: 3
    }, 
    {
      pos: [1, 1, 9], 
      state: 6
    }, 
    {
      pos: [4, 1, 9], 
      state: 8
    }, 
    {
      pos: [5, 1, 9], 
      state: 6
    }, 
    {
      pos: [1, 2, 9], 
      state: 6
    }, 
    {
      pos: [5, 2, 9], 
      state: 6
    }, 
    {
      pos: [1, 3, 9], 
      state: 6
    }, 
    {
      pos: [5, 3, 9], 
      state: 6
    }, 
    {
      pos: [1, 4, 9], 
      state: 2
    }, 
    {
      pos: [5, 4, 9], 
      state: 2
    }, 
    {
      pos: [3, 5, 9], 
      state: 2
    }, 
    {
      pos: [1, 0, 10], 
      state: 0
    }, 
    {
      pos: [2, 0, 10], 
      state: 0
    }, 
    {
      pos: [3, 0, 10], 
      state: 0
    }, 
    {
      pos: [4, 0, 10], 
      state: 0
    }, 
    {
      pos: [5, 0, 10], 
      state: 3
    }, 
    {
      pos: [5, 1, 10], 
      state: 6
    }, 
    {
      pos: [1, 3, 10], 
      state: 6
    }, 
    {
      pos: [5, 3, 10], 
      state: 6
    }, 
    {
      pos: [1, 4, 10], 
      state: 2
    }, 
    {
      pos: [5, 4, 10], 
      state: 2
    }, 
    {
      pos: [3, 5, 10], 
      state: 2
    }, 
    {
      pos: [1, 0, 11], 
      state: 3
    }, 
    {
      pos: [2, 0, 11], 
      state: 0
    }, 
    {
      pos: [3, 0, 11], 
      state: 0
    }, 
    {
      pos: [4, 0, 11], 
      state: 0
    }, 
    {
      pos: [5, 0, 11], 
      state: 3
    }, 
    {
      pos: [1, 1, 11], 
      state: 6
    }, 
    {
      pos: [5, 1, 11], 
      state: 6
    }, 
    {
      pos: [1, 2, 11], 
      state: 6
    }, 
    {
      pos: [5, 2, 11], 
      state: 6
    }, 
    {
      pos: [1, 3, 11], 
      state: 6
    }, 
    {
      pos: [5, 3, 11], 
      state: 6
    }, 
    {
      pos: [1, 4, 11], 
      state: 2
    }, 
    {
      pos: [5, 4, 11], 
      state: 2
    }, 
    {
      pos: [3, 5, 11], 
      state: 2
    }, 
    {
      pos: [1, 0, 12], 
      state: 3
    }, 
    {
      pos: [2, 0, 12], 
      state: 0
    }, 
    {
      pos: [3, 0, 12], 
      state: 0
    }, 
    {
      pos: [4, 0, 12], 
      state: 0
    }, 
    {
      pos: [5, 0, 12], 
      state: 3
    }, 
    {
      pos: [1, 1, 12], 
      state: 4
    }, 
    {
      pos: [5, 1, 12], 
      state: 4
    }, 
    {
      pos: [1, 2, 12], 
      state: 4
    }, 
    {
      pos: [5, 2, 12], 
      state: 4
    }, 
    {
      pos: [1, 3, 12], 
      state: 4
    }, 
    {
      pos: [5, 3, 12], 
      state: 4
    }, 
    {
      pos: [3, 5, 12], 
      state: 2
    }, 
    {
      pos: [1, 0, 13], 
      state: 3
    }, 
    {
      pos: [2, 0, 13], 
      state: 3
    }, 
    {
      pos: [3, 0, 13], 
      state: 3
    }, 
    {
      pos: [4, 0, 13], 
      state: 3
    }, 
    {
      pos: [5, 0, 13], 
      state: 3
    }, 
    {
      pos: [1, 1, 13], 
      state: 6
    }, 
    {
      pos: [2, 1, 13], 
      state: 5
    }, 
    {
      pos: [3, 1, 13], 
      state: 5
    }, 
    {
      pos: [4, 1, 13], 
      state: 5
    }, 
    {
      pos: [5, 1, 13], 
      state: 6
    }, 
    {
      pos: [1, 2, 13], 
      state: 6
    }, 
    {
      pos: [5, 2, 13], 
      state: 6
    }, 
    {
      pos: [1, 3, 13], 
      state: 6
    }, 
    {
      pos: [5, 3, 13], 
      state: 6
    }, 
    {
      pos: [3, 5, 13], 
      state: 2
    }, 
    {
      pos: [1, 0, 14], 
      state: 3
    }, 
    {
      pos: [2, 0, 14], 
      state: 0
    }, 
    {
      pos: [3, 0, 14], 
      state: 0
    }, 
    {
      pos: [4, 0, 14], 
      state: 0
    }, 
    {
      pos: [5, 0, 14], 
      state: 3
    }, 
    {
      pos: [1, 1, 14], 
      state: 6
    }, 
    {
      pos: [5, 1, 14], 
      state: 6
    }, 
    {
      pos: [1, 2, 14], 
      state: 6
    }, 
    {
      pos: [5, 2, 14], 
      state: 6
    }, 
    {
      pos: [1, 3, 14], 
      state: 6
    }, 
    {
      pos: [5, 3, 14], 
      state: 6
    }, 
    {
      pos: [3, 5, 14], 
      state: 2
    }, 
    {
      pos: [1, 0, 15], 
      state: 3
    }, 
    {
      pos: [2, 0, 15], 
      state: 3
    }, 
    {
      pos: [3, 0, 15], 
      state: 3
    }, 
    {
      pos: [4, 0, 15], 
      state: 3
    }, 
    {
      pos: [5, 0, 15], 
      state: 3
    }, 
    {
      pos: [1, 1, 15], 
      state: 4
    }, 
    {
      pos: [2, 1, 15], 
      state: 6
    }, 
    {
      pos: [3, 1, 15], 
      state: 6
    }, 
    {
      pos: [4, 1, 15], 
      state: 6
    }, 
    {
      pos: [5, 1, 15], 
      state: 4
    }, 
    {
      pos: [1, 2, 15], 
      state: 4
    }, 
    {
      pos: [2, 2, 15], 
      state: 6
    }, 
    {
      pos: [4, 2, 15], 
      state: 6
    }, 
    {
      pos: [5, 2, 15], 
      state: 4
    }, 
    {
      pos: [1, 3, 15], 
      state: 4
    }, 
    {
      pos: [2, 3, 15], 
      state: 6
    }, 
    {
      pos: [3, 3, 15], 
      state: 6
    }, 
    {
      pos: [4, 3, 15], 
      state: 6
    }, 
    {
      pos: [5, 3, 15], 
      state: 4
    }, 
    {
      pos: [2, 4, 15], 
      state: 6
    }, 
    {
      pos: [3, 4, 15], 
      state: 6
    }, 
    {
      pos: [4, 4, 15], 
      state: 6
    }, 
    {
      pos: [3, 5, 15], 
      state: 2
    }, 
    {
      pos: [3, 5, 16], 
      state: 2
    }, 
    {
      nbt: {
        target_pool: "minecraft:village/common/cats", 
        final_state: "minecraft:grass_block", 
        id: "minecraft:jigsaw", 
        attachement_type: "minecraft:bottom"
      }, 
      pos: [6, 0, 1], 
      state: 9
    }, 
    {
      nbt: {
        target_pool: "minecraft:village/common/animals", 
        final_state: "minecraft:dirt", 
        id: "minecraft:jigsaw", 
        attachement_type: "minecraft:bottom"
      }, 
      pos: [3, 0, 2], 
      state: 9
    }, 
    {
      nbt: {
        target_pool: "minecraft:village/common/cats", 
        final_state: "minecraft:grass_block", 
        id: "minecraft:jigsaw", 
        attachement_type: "minecraft:bottom"
      }, 
      pos: [0, 0, 3], 
      state: 9
    }, 
    {
      nbt: {
        target_pool: "minecraft:village/common/animals", 
        final_state: "minecraft:dirt", 
        id: "minecraft:jigsaw", 
        attachement_type: "minecraft:bottom"
      }, 
      pos: [3, 0, 4], 
      state: 9
    }, 
    {
      nbt: {
        target_pool: "minecraft:village/plains/streets", 
        final_state: "minecraft:structure_void", 
        id: "minecraft:jigsaw", 
        attachement_type: "minecraft:building_entrance"
      }, 
      pos: [0, 1, 9], 
      state: 10
    }, 
    {
      pos: [0, 0, 0], 
      state: 11
    }, 
    {
      pos: [6, 0, 0], 
      state: 11
    }, 
    {
      pos: [0, 1, 0], 
      state: 11
    }, 
    {
      pos: [1, 1, 0], 
      state: 12
    }, 
    {
      pos: [2, 1, 0], 
      state: 13
    }, 
    {
      pos: [3, 1, 0], 
      state: 13
    }, 
    {
      pos: [4, 1, 0], 
      state: 13
    }, 
    {
      pos: [5, 1, 0], 
      state: 14
    }, 
    {
      pos: [6, 1, 0], 
      state: 11
    }, 
    {
      pos: [0, 2, 0], 
      state: 11
    }, 
    {
      pos: [1, 2, 0], 
      state: 11
    }, 
    {
      pos: [2, 2, 0], 
      state: 11
    }, 
    {
      pos: [3, 2, 0], 
      state: 11
    }, 
    {
      pos: [4, 2, 0], 
      state: 11
    }, 
    {
      pos: [5, 2, 0], 
      state: 11
    }, 
    {
      pos: [6, 2, 0], 
      state: 11
    }, 
    {
      pos: [0, 3, 0], 
      state: 11
    }, 
    {
      pos: [1, 3, 0], 
      state: 11
    }, 
    {
      pos: [2, 3, 0], 
      state: 11
    }, 
    {
      pos: [3, 3, 0], 
      state: 11
    }, 
    {
      pos: [4, 3, 0], 
      state: 11
    }, 
    {
      pos: [5, 3, 0], 
      state: 11
    }, 
    {
      pos: [6, 3, 0], 
      state: 11
    }, 
    {
      pos: [0, 4, 0], 
      state: 11
    }, 
    {
      pos: [1, 4, 0], 
      state: 11
    }, 
    {
      pos: [2, 4, 0], 
      state: 11
    }, 
    {
      pos: [3, 4, 0], 
      state: 11
    }, 
    {
      pos: [4, 4, 0], 
      state: 11
    }, 
    {
      pos: [5, 4, 0], 
      state: 11
    }, 
    {
      pos: [6, 4, 0], 
      state: 11
    }, 
    {
      pos: [0, 5, 0], 
      state: 11
    }, 
    {
      pos: [1, 5, 0], 
      state: 11
    }, 
    {
      pos: [2, 5, 0], 
      state: 11
    }, 
    {
      pos: [3, 5, 0], 
      state: 11
    }, 
    {
      pos: [4, 5, 0], 
      state: 11
    }, 
    {
      pos: [5, 5, 0], 
      state: 11
    }, 
    {
      pos: [6, 5, 0], 
      state: 11
    }, 
    {
      pos: [0, 0, 1], 
      state: 11
    }, 
    {
      pos: [0, 1, 1], 
      state: 11
    }, 
    {
      pos: [1, 1, 1], 
      state: 15
    }, 
    {
      pos: [2, 1, 1], 
      state: 11
    }, 
    {
      pos: [3, 1, 1], 
      state: 11
    }, 
    {
      pos: [4, 1, 1], 
      state: 11
    }, 
    {
      pos: [5, 1, 1], 
      state: 15
    }, 
    {
      pos: [6, 1, 1], 
      state: 11
    }, 
    {
      pos: [0, 2, 1], 
      state: 11
    }, 
    {
      pos: [1, 2, 1], 
      state: 11
    }, 
    {
      pos: [2, 2, 1], 
      state: 11
    }, 
    {
      pos: [3, 2, 1], 
      state: 11
    }, 
    {
      pos: [4, 2, 1], 
      state: 11
    }, 
    {
      pos: [5, 2, 1], 
      state: 11
    }, 
    {
      pos: [6, 2, 1], 
      state: 11
    }, 
    {
      pos: [0, 3, 1], 
      state: 11
    }, 
    {
      pos: [1, 3, 1], 
      state: 11
    }, 
    {
      pos: [2, 3, 1], 
      state: 11
    }, 
    {
      pos: [3, 3, 1], 
      state: 11
    }, 
    {
      pos: [4, 3, 1], 
      state: 11
    }, 
    {
      pos: [5, 3, 1], 
      state: 11
    }, 
    {
      pos: [6, 3, 1], 
      state: 11
    }, 
    {
      pos: [0, 4, 1], 
      state: 11
    }, 
    {
      pos: [1, 4, 1], 
      state: 11
    }, 
    {
      pos: [2, 4, 1], 
      state: 11
    }, 
    {
      pos: [3, 4, 1], 
      state: 11
    }, 
    {
      pos: [4, 4, 1], 
      state: 11
    }, 
    {
      pos: [5, 4, 1], 
      state: 11
    }, 
    {
      pos: [6, 4, 1], 
      state: 11
    }, 
    {
      pos: [0, 5, 1], 
      state: 11
    }, 
    {
      pos: [1, 5, 1], 
      state: 11
    }, 
    {
      pos: [2, 5, 1], 
      state: 11
    }, 
    {
      pos: [3, 5, 1], 
      state: 11
    }, 
    {
      pos: [4, 5, 1], 
      state: 11
    }, 
    {
      pos: [5, 5, 1], 
      state: 11
    }, 
    {
      pos: [6, 5, 1], 
      state: 11
    }, 
    {
      pos: [0, 0, 2], 
      state: 11
    }, 
    {
      pos: [6, 0, 2], 
      state: 11
    }, 
    {
      pos: [0, 1, 2], 
      state: 11
    }, 
    {
      pos: [1, 1, 2], 
      state: 15
    }, 
    {
      pos: [2, 1, 2], 
      state: 11
    }, 
    {
      pos: [3, 1, 2], 
      state: 11
    }, 
    {
      pos: [4, 1, 2], 
      state: 11
    }, 
    {
      pos: [5, 1, 2], 
      state: 15
    }, 
    {
      pos: [6, 1, 2], 
      state: 11
    }, 
    {
      pos: [0, 2, 2], 
      state: 11
    }, 
    {
      pos: [1, 2, 2], 
      state: 16
    }, 
    {
      pos: [2, 2, 2], 
      state: 11
    }, 
    {
      pos: [3, 2, 2], 
      state: 11
    }, 
    {
      pos: [4, 2, 2], 
      state: 11
    }, 
    {
      pos: [5, 2, 2], 
      state: 16
    }, 
    {
      pos: [6, 2, 2], 
      state: 11
    }, 
    {
      pos: [0, 3, 2], 
      state: 11
    }, 
    {
      pos: [1, 3, 2], 
      state: 16
    }, 
    {
      pos: [2, 3, 2], 
      state: 11
    }, 
    {
      pos: [3, 3, 2], 
      state: 11
    }, 
    {
      pos: [4, 3, 2], 
      state: 11
    }, 
    {
      pos: [5, 3, 2], 
      state: 16
    }, 
    {
      pos: [6, 3, 2], 
      state: 11
    }, 
    {
      pos: [0, 4, 2], 
      state: 11
    }, 
    {
      pos: [1, 4, 2], 
      state: 17
    }, 
    {
      pos: [3, 4, 2], 
      state: 18
    }, 
    {
      pos: [5, 4, 2], 
      state: 19
    }, 
    {
      pos: [6, 4, 2], 
      state: 11
    }, 
    {
      pos: [0, 5, 2], 
      state: 11
    }, 
    {
      pos: [1, 5, 2], 
      state: 11
    }, 
    {
      pos: [2, 5, 2], 
      state: 11
    }, 
    {
      pos: [3, 5, 2], 
      state: 20
    }, 
    {
      pos: [4, 5, 2], 
      state: 11
    }, 
    {
      pos: [5, 5, 2], 
      state: 11
    }, 
    {
      pos: [6, 5, 2], 
      state: 11
    }, 
    {
      pos: [6, 0, 3], 
      state: 11
    }, 
    {
      pos: [0, 1, 3], 
      state: 11
    }, 
    {
      pos: [1, 1, 3], 
      state: 15
    }, 
    {
      pos: [2, 1, 3], 
      state: 11
    }, 
    {
      pos: [3, 1, 3], 
      state: 11
    }, 
    {
      pos: [4, 1, 3], 
      state: 11
    }, 
    {
      pos: [5, 1, 3], 
      state: 15
    }, 
    {
      pos: [6, 1, 3], 
      state: 11
    }, 
    {
      pos: [0, 2, 3], 
      state: 11
    }, 
    {
      pos: [1, 2, 3], 
      state: 11
    }, 
    {
      pos: [2, 2, 3], 
      state: 11
    }, 
    {
      pos: [3, 2, 3], 
      state: 11
    }, 
    {
      pos: [4, 2, 3], 
      state: 11
    }, 
    {
      pos: [5, 2, 3], 
      state: 11
    }, 
    {
      pos: [6, 2, 3], 
      state: 11
    }, 
    {
      pos: [0, 3, 3], 
      state: 11
    }, 
    {
      pos: [1, 3, 3], 
      state: 11
    }, 
    {
      pos: [2, 3, 3], 
      state: 11
    }, 
    {
      pos: [3, 3, 3], 
      state: 11
    }, 
    {
      pos: [4, 3, 3], 
      state: 11
    }, 
    {
      pos: [5, 3, 3], 
      state: 11
    }, 
    {
      pos: [6, 3, 3], 
      state: 11
    }, 
    {
      pos: [0, 4, 3], 
      state: 11
    }, 
    {
      pos: [1, 4, 3], 
      state: 17
    }, 
    {
      pos: [3, 4, 3], 
      state: 18
    }, 
    {
      pos: [5, 4, 3], 
      state: 19
    }, 
    {
      pos: [6, 4, 3], 
      state: 11
    }, 
    {
      pos: [0, 5, 3], 
      state: 11
    }, 
    {
      pos: [1, 5, 3], 
      state: 11
    }, 
    {
      pos: [2, 5, 3], 
      state: 11
    }, 
    {
      pos: [3, 5, 3], 
      state: 20
    }, 
    {
      pos: [4, 5, 3], 
      state: 11
    }, 
    {
      pos: [5, 5, 3], 
      state: 11
    }, 
    {
      pos: [6, 5, 3], 
      state: 11
    }, 
    {
      pos: [0, 0, 4], 
      state: 11
    }, 
    {
      pos: [6, 0, 4], 
      state: 11
    }, 
    {
      pos: [0, 1, 4], 
      state: 11
    }, 
    {
      pos: [1, 1, 4], 
      state: 15
    }, 
    {
      pos: [2, 1, 4], 
      state: 11
    }, 
    {
      pos: [3, 1, 4], 
      state: 11
    }, 
    {
      pos: [4, 1, 4], 
      state: 11
    }, 
    {
      pos: [5, 1, 4], 
      state: 15
    }, 
    {
      pos: [6, 1, 4], 
      state: 11
    }, 
    {
      pos: [0, 2, 4], 
      state: 11
    }, 
    {
      pos: [1, 2, 4], 
      state: 11
    }, 
    {
      pos: [2, 2, 4], 
      state: 11
    }, 
    {
      pos: [3, 2, 4], 
      state: 11
    }, 
    {
      pos: [4, 2, 4], 
      state: 11
    }, 
    {
      pos: [5, 2, 4], 
      state: 11
    }, 
    {
      pos: [6, 2, 4], 
      state: 11
    }, 
    {
      pos: [0, 3, 4], 
      state: 17
    }, 
    {
      pos: [1, 3, 4], 
      state: 21
    }, 
    {
      pos: [2, 3, 4], 
      state: 11
    }, 
    {
      pos: [3, 3, 4], 
      state: 22
    }, 
    {
      pos: [4, 3, 4], 
      state: 11
    }, 
    {
      pos: [5, 3, 4], 
      state: 23
    }, 
    {
      pos: [6, 3, 4], 
      state: 19
    }, 
    {
      pos: [0, 4, 4], 
      state: 11
    }, 
    {
      pos: [1, 4, 4], 
      state: 17
    }, 
    {
      pos: [3, 4, 4], 
      state: 18
    }, 
    {
      pos: [5, 4, 4], 
      state: 19
    }, 
    {
      pos: [6, 4, 4], 
      state: 11
    }, 
    {
      pos: [0, 5, 4], 
      state: 11
    }, 
    {
      pos: [1, 5, 4], 
      state: 11
    }, 
    {
      pos: [2, 5, 4], 
      state: 17
    }, 
    {
      pos: [4, 5, 4], 
      state: 19
    }, 
    {
      pos: [5, 5, 4], 
      state: 11
    }, 
    {
      pos: [6, 5, 4], 
      state: 11
    }, 
    {
      pos: [0, 0, 5], 
      state: 11
    }, 
    {
      pos: [6, 0, 5], 
      state: 11
    }, 
    {
      pos: [0, 1, 5], 
      state: 11
    }, 
    {
      pos: [2, 1, 5], 
      state: 11
    }, 
    {
      pos: [3, 1, 5], 
      state: 11
    }, 
    {
      pos: [4, 1, 5], 
      state: 11
    }, 
    {
      pos: [6, 1, 5], 
      state: 11
    }, 
    {
      pos: [0, 2, 5], 
      state: 11
    }, 
    {
      pos: [2, 2, 5], 
      state: 11
    }, 
    {
      pos: [3, 2, 5], 
      state: 11
    }, 
    {
      pos: [4, 2, 5], 
      state: 11
    }, 
    {
      pos: [6, 2, 5], 
      state: 11
    }, 
    {
      pos: [0, 3, 5], 
      state: 17
    }, 
    {
      pos: [6, 3, 5], 
      state: 19
    }, 
    {
      pos: [0, 4, 5], 
      state: 11
    }, 
    {
      pos: [1, 4, 5], 
      state: 17
    }, 
    {
      pos: [5, 4, 5], 
      state: 19
    }, 
    {
      pos: [6, 4, 5], 
      state: 11
    }, 
    {
      pos: [0, 5, 5], 
      state: 11
    }, 
    {
      pos: [1, 5, 5], 
      state: 11
    }, 
    {
      pos: [2, 5, 5], 
      state: 17
    }, 
    {
      pos: [4, 5, 5], 
      state: 19
    }, 
    {
      pos: [5, 5, 5], 
      state: 11
    }, 
    {
      pos: [6, 5, 5], 
      state: 11
    }, 
    {
      pos: [0, 0, 6], 
      state: 11
    }, 
    {
      pos: [6, 0, 6], 
      state: 11
    }, 
    {
      pos: [0, 1, 6], 
      state: 11
    }, 
    {
      pos: [3, 1, 6], 
      state: 11
    }, 
    {
      pos: [4, 1, 6], 
      state: 11
    }, 
    {
      pos: [6, 1, 6], 
      state: 11
    }, 
    {
      pos: [0, 2, 6], 
      state: 11
    }, 
    {
      pos: [2, 2, 6], 
      state: 11
    }, 
    {
      pos: [3, 2, 6], 
      state: 11
    }, 
    {
      pos: [4, 2, 6], 
      state: 11
    }, 
    {
      pos: [6, 2, 6], 
      state: 11
    }, 
    {
      pos: [0, 3, 6], 
      state: 17
    }, 
    {
      pos: [2, 3, 6], 
      state: 11
    }, 
    {
      pos: [3, 3, 6], 
      state: 24
    }, 
    {
      pos: [4, 3, 6], 
      state: 11
    }, 
    {
      pos: [6, 3, 6], 
      state: 19
    }, 
    {
      pos: [0, 4, 6], 
      state: 11
    }, 
    {
      pos: [1, 4, 6], 
      state: 17
    }, 
    {
      pos: [2, 4, 6], 
      state: 11
    }, 
    {
      pos: [3, 4, 6], 
      state: 11
    }, 
    {
      pos: [4, 4, 6], 
      state: 11
    }, 
    {
      pos: [5, 4, 6], 
      state: 19
    }, 
    {
      pos: [6, 4, 6], 
      state: 11
    }, 
    {
      pos: [0, 5, 6], 
      state: 11
    }, 
    {
      pos: [1, 5, 6], 
      state: 11
    }, 
    {
      pos: [2, 5, 6], 
      state: 17
    }, 
    {
      pos: [4, 5, 6], 
      state: 19
    }, 
    {
      pos: [5, 5, 6], 
      state: 11
    }, 
    {
      pos: [6, 5, 6], 
      state: 11
    }, 
    {
      pos: [0, 0, 7], 
      state: 11
    }, 
    {
      pos: [6, 0, 7], 
      state: 11
    }, 
    {
      pos: [0, 1, 7], 
      state: 11
    }, 
    {
      pos: [2, 1, 7], 
      state: 11
    }, 
    {
      pos: [3, 1, 7], 
      state: 11
    }, 
    {
      pos: [6, 1, 7], 
      state: 11
    }, 
    {
      pos: [0, 2, 7], 
      state: 11
    }, 
    {
      pos: [2, 2, 7], 
      state: 11
    }, 
    {
      pos: [3, 2, 7], 
      state: 11
    }, 
    {
      pos: [4, 2, 7], 
      state: 11
    }, 
    {
      pos: [6, 2, 7], 
      state: 11
    }, 
    {
      pos: [0, 3, 7], 
      state: 17
    }, 
    {
      pos: [2, 3, 7], 
      state: 11
    }, 
    {
      pos: [3, 3, 7], 
      state: 11
    }, 
    {
      pos: [4, 3, 7], 
      state: 11
    }, 
    {
      pos: [6, 3, 7], 
      state: 19
    }, 
    {
      pos: [0, 4, 7], 
      state: 11
    }, 
    {
      pos: [1, 4, 7], 
      state: 17
    }, 
    {
      pos: [2, 4, 7], 
      state: 11
    }, 
    {
      pos: [3, 4, 7], 
      state: 11
    }, 
    {
      pos: [4, 4, 7], 
      state: 11
    }, 
    {
      pos: [5, 4, 7], 
      state: 19
    }, 
    {
      pos: [6, 4, 7], 
      state: 11
    }, 
    {
      pos: [0, 5, 7], 
      state: 11
    }, 
    {
      pos: [1, 5, 7], 
      state: 11
    }, 
    {
      pos: [2, 5, 7], 
      state: 17
    }, 
    {
      pos: [4, 5, 7], 
      state: 19
    }, 
    {
      pos: [5, 5, 7], 
      state: 11
    }, 
    {
      pos: [6, 5, 7], 
      state: 11
    }, 
    {
      pos: [0, 0, 8], 
      state: 11
    }, 
    {
      pos: [6, 0, 8], 
      state: 11
    }, 
    {
      pos: [0, 1, 8], 
      state: 11
    }, 
    {
      pos: [2, 1, 8], 
      state: 11
    }, 
    {
      pos: [3, 1, 8], 
      state: 11
    }, 
    {
      pos: [6, 1, 8], 
      state: 11
    }, 
    {
      pos: [0, 2, 8], 
      state: 11
    }, 
    {
      pos: [2, 2, 8], 
      state: 11
    }, 
    {
      pos: [3, 2, 8], 
      state: 11
    }, 
    {
      pos: [6, 2, 8], 
      state: 11
    }, 
    {
      pos: [0, 3, 8], 
      state: 17
    }, 
    {
      pos: [2, 3, 8], 
      state: 11
    }, 
    {
      pos: [3, 3, 8], 
      state: 11
    }, 
    {
      pos: [4, 3, 8], 
      state: 11
    }, 
    {
      pos: [6, 3, 8], 
      state: 19
    }, 
    {
      pos: [0, 4, 8], 
      state: 11
    }, 
    {
      pos: [1, 4, 8], 
      state: 17
    }, 
    {
      pos: [2, 4, 8], 
      state: 11
    }, 
    {
      pos: [3, 4, 8], 
      state: 11
    }, 
    {
      pos: [4, 4, 8], 
      state: 11
    }, 
    {
      pos: [5, 4, 8], 
      state: 19
    }, 
    {
      pos: [6, 4, 8], 
      state: 11
    }, 
    {
      pos: [0, 5, 8], 
      state: 11
    }, 
    {
      pos: [1, 5, 8], 
      state: 11
    }, 
    {
      pos: [2, 5, 8], 
      state: 17
    }, 
    {
      pos: [4, 5, 8], 
      state: 19
    }, 
    {
      pos: [5, 5, 8], 
      state: 11
    }, 
    {
      pos: [6, 5, 8], 
      state: 11
    }, 
    {
      pos: [6, 0, 9], 
      state: 11
    }, 
    {
      pos: [2, 1, 9], 
      state: 11
    }, 
    {
      pos: [3, 1, 9], 
      state: 11
    }, 
    {
      pos: [6, 1, 9], 
      state: 11
    }, 
    {
      pos: [0, 2, 9], 
      state: 11
    }, 
    {
      pos: [2, 2, 9], 
      state: 11
    }, 
    {
      pos: [3, 2, 9], 
      state: 11
    }, 
    {
      pos: [4, 2, 9], 
      state: 11
    }, 
    {
      pos: [6, 2, 9], 
      state: 11
    }, 
    {
      pos: [0, 3, 9], 
      state: 25
    }, 
    {
      pos: [2, 3, 9], 
      state: 11
    }, 
    {
      pos: [3, 3, 9], 
      state: 11
    }, 
    {
      pos: [4, 3, 9], 
      state: 11
    }, 
    {
      pos: [6, 3, 9], 
      state: 25
    }, 
    {
      pos: [0, 4, 9], 
      state: 17
    }, 
    {
      pos: [2, 4, 9], 
      state: 11
    }, 
    {
      pos: [3, 4, 9], 
      state: 11
    }, 
    {
      pos: [4, 4, 9], 
      state: 11
    }, 
    {
      pos: [6, 4, 9], 
      state: 19
    }, 
    {
      pos: [0, 5, 9], 
      state: 11
    }, 
    {
      pos: [1, 5, 9], 
      state: 11
    }, 
    {
      pos: [2, 5, 9], 
      state: 17
    }, 
    {
      pos: [4, 5, 9], 
      state: 19
    }, 
    {
      pos: [5, 5, 9], 
      state: 11
    }, 
    {
      pos: [6, 5, 9], 
      state: 11
    }, 
    {
      pos: [0, 0, 10], 
      state: 26
    }, 
    {
      pos: [6, 0, 10], 
      state: 11
    }, 
    {
      pos: [0, 1, 10], 
      state: 11
    }, 
    {
      pos: [1, 1, 10], 
      state: 27
    }, 
    {
      pos: [2, 1, 10], 
      state: 11
    }, 
    {
      pos: [3, 1, 10], 
      state: 11
    }, 
    {
      pos: [4, 1, 10], 
      state: 11
    }, 
    {
      pos: [6, 1, 10], 
      state: 11
    }, 
    {
      pos: [0, 2, 10], 
      state: 11
    }, 
    {
      pos: [1, 2, 10], 
      state: 28
    }, 
    {
      pos: [2, 2, 10], 
      state: 11
    }, 
    {
      pos: [3, 2, 10], 
      state: 11
    }, 
    {
      pos: [4, 2, 10], 
      state: 11
    }, 
    {
      pos: [5, 2, 10], 
      state: 29
    }, 
    {
      pos: [6, 2, 10], 
      state: 11
    }, 
    {
      pos: [0, 3, 10], 
      state: 11
    }, 
    {
      pos: [2, 3, 10], 
      state: 30
    }, 
    {
      pos: [3, 3, 10], 
      state: 11
    }, 
    {
      pos: [4, 3, 10], 
      state: 11
    }, 
    {
      pos: [6, 3, 10], 
      state: 11
    }, 
    {
      pos: [0, 4, 10], 
      state: 17
    }, 
    {
      pos: [2, 4, 10], 
      state: 11
    }, 
    {
      pos: [3, 4, 10], 
      state: 11
    }, 
    {
      pos: [4, 4, 10], 
      state: 11
    }, 
    {
      pos: [6, 4, 10], 
      state: 19
    }, 
    {
      pos: [0, 5, 10], 
      state: 11
    }, 
    {
      pos: [1, 5, 10], 
      state: 11
    }, 
    {
      pos: [2, 5, 10], 
      state: 17
    }, 
    {
      pos: [4, 5, 10], 
      state: 19
    }, 
    {
      pos: [5, 5, 10], 
      state: 11
    }, 
    {
      pos: [6, 5, 10], 
      state: 11
    }, 
    {
      pos: [0, 0, 11], 
      state: 11
    }, 
    {
      pos: [6, 0, 11], 
      state: 11
    }, 
    {
      pos: [0, 1, 11], 
      state: 11
    }, 
    {
      pos: [2, 1, 11], 
      state: 11
    }, 
    {
      pos: [3, 1, 11], 
      state: 11
    }, 
    {
      pos: [4, 1, 11], 
      state: 11
    }, 
    {
      pos: [6, 1, 11], 
      state: 11
    }, 
    {
      pos: [0, 2, 11], 
      state: 11
    }, 
    {
      pos: [2, 2, 11], 
      state: 11
    }, 
    {
      pos: [3, 2, 11], 
      state: 11
    }, 
    {
      pos: [4, 2, 11], 
      state: 11
    }, 
    {
      pos: [6, 2, 11], 
      state: 11
    }, 
    {
      pos: [0, 3, 11], 
      state: 31
    }, 
    {
      pos: [2, 3, 11], 
      state: 11
    }, 
    {
      pos: [3, 3, 11], 
      state: 11
    }, 
    {
      pos: [4, 3, 11], 
      state: 11
    }, 
    {
      pos: [6, 3, 11], 
      state: 31
    }, 
    {
      pos: [0, 4, 11], 
      state: 17
    }, 
    {
      pos: [2, 4, 11], 
      state: 11
    }, 
    {
      pos: [3, 4, 11], 
      state: 11
    }, 
    {
      pos: [4, 4, 11], 
      state: 11
    }, 
    {
      pos: [6, 4, 11], 
      state: 19
    }, 
    {
      pos: [0, 5, 11], 
      state: 11
    }, 
    {
      pos: [1, 5, 11], 
      state: 11
    }, 
    {
      pos: [2, 5, 11], 
      state: 17
    }, 
    {
      pos: [4, 5, 11], 
      state: 19
    }, 
    {
      pos: [5, 5, 11], 
      state: 11
    }, 
    {
      pos: [6, 5, 11], 
      state: 11
    }, 
    {
      pos: [0, 0, 12], 
      state: 11
    }, 
    {
      pos: [6, 0, 12], 
      state: 11
    }, 
    {
      pos: [0, 1, 12], 
      state: 11
    }, 
    {
      pos: [2, 1, 12], 
      state: 11
    }, 
    {
      pos: [3, 1, 12], 
      state: 11
    }, 
    {
      pos: [4, 1, 12], 
      state: 11
    }, 
    {
      pos: [6, 1, 12], 
      state: 11
    }, 
    {
      pos: [0, 2, 12], 
      state: 11
    }, 
    {
      pos: [2, 2, 12], 
      state: 11
    }, 
    {
      pos: [3, 2, 12], 
      state: 11
    }, 
    {
      pos: [4, 2, 12], 
      state: 11
    }, 
    {
      pos: [6, 2, 12], 
      state: 11
    }, 
    {
      pos: [0, 3, 12], 
      state: 17
    }, 
    {
      pos: [2, 3, 12], 
      state: 11
    }, 
    {
      pos: [3, 3, 12], 
      state: 11
    }, 
    {
      pos: [4, 3, 12], 
      state: 11
    }, 
    {
      pos: [6, 3, 12], 
      state: 19
    }, 
    {
      pos: [0, 4, 12], 
      state: 11
    }, 
    {
      pos: [1, 4, 12], 
      state: 17
    }, 
    {
      pos: [2, 4, 12], 
      state: 11
    }, 
    {
      pos: [3, 4, 12], 
      state: 11
    }, 
    {
      pos: [4, 4, 12], 
      state: 11
    }, 
    {
      pos: [5, 4, 12], 
      state: 19
    }, 
    {
      pos: [6, 4, 12], 
      state: 11
    }, 
    {
      pos: [0, 5, 12], 
      state: 11
    }, 
    {
      pos: [1, 5, 12], 
      state: 11
    }, 
    {
      pos: [2, 5, 12], 
      state: 17
    }, 
    {
      pos: [4, 5, 12], 
      state: 19
    }, 
    {
      pos: [5, 5, 12], 
      state: 11
    }, 
    {
      pos: [6, 5, 12], 
      state: 11
    }, 
    {
      pos: [0, 0, 13], 
      state: 11
    }, 
    {
      pos: [6, 0, 13], 
      state: 11
    }, 
    {
      pos: [0, 1, 13], 
      state: 11
    }, 
    {
      pos: [6, 1, 13], 
      state: 11
    }, 
    {
      pos: [0, 2, 13], 
      state: 11
    }, 
    {
      pos: [2, 2, 13], 
      state: 11
    }, 
    {
      pos: [3, 2, 13], 
      state: 11
    }, 
    {
      pos: [4, 2, 13], 
      state: 11
    }, 
    {
      pos: [6, 2, 13], 
      state: 11
    }, 
    {
      pos: [0, 3, 13], 
      state: 17
    }, 
    {
      pos: [2, 3, 13], 
      state: 11
    }, 
    {
      pos: [3, 3, 13], 
      state: 11
    }, 
    {
      pos: [4, 3, 13], 
      state: 11
    }, 
    {
      pos: [6, 3, 13], 
      state: 19
    }, 
    {
      pos: [0, 4, 13], 
      state: 11
    }, 
    {
      pos: [1, 4, 13], 
      state: 17
    }, 
    {
      pos: [2, 4, 13], 
      state: 11
    }, 
    {
      pos: [3, 4, 13], 
      state: 11
    }, 
    {
      pos: [4, 4, 13], 
      state: 11
    }, 
    {
      pos: [5, 4, 13], 
      state: 19
    }, 
    {
      pos: [6, 4, 13], 
      state: 11
    }, 
    {
      pos: [0, 5, 13], 
      state: 11
    }, 
    {
      pos: [1, 5, 13], 
      state: 11
    }, 
    {
      pos: [2, 5, 13], 
      state: 17
    }, 
    {
      pos: [4, 5, 13], 
      state: 19
    }, 
    {
      pos: [5, 5, 13], 
      state: 11
    }, 
    {
      pos: [6, 5, 13], 
      state: 11
    }, 
    {
      pos: [0, 0, 14], 
      state: 11
    }, 
    {
      pos: [6, 0, 14], 
      state: 11
    }, 
    {
      pos: [0, 1, 14], 
      state: 11
    }, 
    {
      pos: [2, 1, 14], 
      state: 32
    }, 
    {
      pos: [3, 1, 14], 
      state: 32
    }, 
    {
      pos: [4, 1, 14], 
      state: 32
    }, 
    {
      pos: [6, 1, 14], 
      state: 11
    }, 
    {
      pos: [0, 2, 14], 
      state: 11
    }, 
    {
      pos: [2, 2, 14], 
      state: 11
    }, 
    {
      pos: [3, 2, 14], 
      state: 11
    }, 
    {
      pos: [4, 2, 14], 
      state: 11
    }, 
    {
      pos: [6, 2, 14], 
      state: 11
    }, 
    {
      pos: [0, 3, 14], 
      state: 17
    }, 
    {
      pos: [2, 3, 14], 
      state: 11
    }, 
    {
      pos: [3, 3, 14], 
      state: 11
    }, 
    {
      pos: [4, 3, 14], 
      state: 11
    }, 
    {
      pos: [6, 3, 14], 
      state: 19
    }, 
    {
      pos: [0, 4, 14], 
      state: 11
    }, 
    {
      pos: [1, 4, 14], 
      state: 17
    }, 
    {
      pos: [2, 4, 14], 
      state: 11
    }, 
    {
      pos: [3, 4, 14], 
      state: 11
    }, 
    {
      pos: [4, 4, 14], 
      state: 11
    }, 
    {
      pos: [5, 4, 14], 
      state: 19
    }, 
    {
      pos: [6, 4, 14], 
      state: 11
    }, 
    {
      pos: [0, 5, 14], 
      state: 11
    }, 
    {
      pos: [1, 5, 14], 
      state: 11
    }, 
    {
      pos: [2, 5, 14], 
      state: 17
    }, 
    {
      pos: [4, 5, 14], 
      state: 19
    }, 
    {
      pos: [5, 5, 14], 
      state: 11
    }, 
    {
      pos: [6, 5, 14], 
      state: 11
    }, 
    {
      pos: [0, 0, 15], 
      state: 11
    }, 
    {
      pos: [6, 0, 15], 
      state: 11
    }, 
    {
      pos: [0, 1, 15], 
      state: 11
    }, 
    {
      pos: [6, 1, 15], 
      state: 11
    }, 
    {
      pos: [0, 2, 15], 
      state: 11
    }, 
    {
      pos: [3, 2, 15], 
      state: 33
    }, 
    {
      pos: [6, 2, 15], 
      state: 11
    }, 
    {
      pos: [0, 3, 15], 
      state: 17
    }, 
    {
      pos: [6, 3, 15], 
      state: 19
    }, 
    {
      pos: [0, 4, 15], 
      state: 11
    }, 
    {
      pos: [1, 4, 15], 
      state: 17
    }, 
    {
      pos: [5, 4, 15], 
      state: 19
    }, 
    {
      pos: [6, 4, 15], 
      state: 11
    }, 
    {
      pos: [0, 5, 15], 
      state: 11
    }, 
    {
      pos: [1, 5, 15], 
      state: 11
    }, 
    {
      pos: [2, 5, 15], 
      state: 17
    }, 
    {
      pos: [4, 5, 15], 
      state: 19
    }, 
    {
      pos: [5, 5, 15], 
      state: 11
    }, 
    {
      pos: [6, 5, 15], 
      state: 11
    }, 
    {
      pos: [0, 0, 16], 
      state: 11
    }, 
    {
      pos: [1, 0, 16], 
      state: 11
    }, 
    {
      pos: [2, 0, 16], 
      state: 11
    }, 
    {
      pos: [3, 0, 16], 
      state: 11
    }, 
    {
      pos: [4, 0, 16], 
      state: 11
    }, 
    {
      pos: [5, 0, 16], 
      state: 11
    }, 
    {
      pos: [6, 0, 16], 
      state: 11
    }, 
    {
      pos: [0, 1, 16], 
      state: 11
    }, 
    {
      pos: [1, 1, 16], 
      state: 11
    }, 
    {
      pos: [2, 1, 16], 
      state: 11
    }, 
    {
      pos: [3, 1, 16], 
      state: 11
    }, 
    {
      pos: [4, 1, 16], 
      state: 11
    }, 
    {
      pos: [5, 1, 16], 
      state: 11
    }, 
    {
      pos: [6, 1, 16], 
      state: 11
    }, 
    {
      pos: [0, 2, 16], 
      state: 11
    }, 
    {
      pos: [1, 2, 16], 
      state: 11
    }, 
    {
      pos: [2, 2, 16], 
      state: 11
    }, 
    {
      pos: [3, 2, 16], 
      state: 11
    }, 
    {
      pos: [4, 2, 16], 
      state: 11
    }, 
    {
      pos: [5, 2, 16], 
      state: 11
    }, 
    {
      pos: [6, 2, 16], 
      state: 11
    }, 
    {
      pos: [0, 3, 16], 
      state: 17
    }, 
    {
      pos: [1, 3, 16], 
      state: 21
    }, 
    {
      pos: [2, 3, 16], 
      state: 11
    }, 
    {
      pos: [3, 3, 16], 
      state: 11
    }, 
    {
      pos: [4, 3, 16], 
      state: 11
    }, 
    {
      pos: [5, 3, 16], 
      state: 23
    }, 
    {
      pos: [6, 3, 16], 
      state: 19
    }, 
    {
      pos: [0, 4, 16], 
      state: 11
    }, 
    {
      pos: [1, 4, 16], 
      state: 17
    }, 
    {
      pos: [2, 4, 16], 
      state: 21
    }, 
    {
      pos: [3, 4, 16], 
      state: 11
    }, 
    {
      pos: [4, 4, 16], 
      state: 23
    }, 
    {
      pos: [5, 4, 16], 
      state: 19
    }, 
    {
      pos: [6, 4, 16], 
      state: 11
    }, 
    {
      pos: [0, 5, 16], 
      state: 11
    }, 
    {
      pos: [1, 5, 16], 
      state: 11
    }, 
    {
      pos: [2, 5, 16], 
      state: 17
    }, 
    {
      pos: [4, 5, 16], 
      state: 19
    }, 
    {
      pos: [5, 5, 16], 
      state: 11
    }, 
    {
      pos: [6, 5, 16], 
      state: 11
    }
  ], 
  palette: [
    {
      Properties: {
        snowy: "false"
      }, 
      Name: "minecraft:grass_block"
    }, 
    {
      Properties: {
        waterlogged: "false", 
        type: "double"
      }, 
      Name: "minecraft:oak_slab"
    }, 
    {
      Name: "minecraft:oak_planks"
    }, 
    {
      Name: "minecraft:dirt"
    }, 
    {
      Properties: {
        axis: "y"
      }, 
      Name: "minecraft:oak_log"
    }, 
    {
      Properties: {
        axis: "x"
      }, 
      Name: "minecraft:oak_log"
    }, 
    {
      Name: "minecraft:white_terracotta"
    }, 
    {
      Properties: {
        axis: "y"
      }, 
      Name: "minecraft:hay_block"
    }, 
    {
      Properties: {
        axis: "z"
      }, 
      Name: "minecraft:hay_block"
    }, 
    {
      Properties: {
        facing: "up"
      }, 
      Name: "minecraft:jigsaw"
    }, 
    {
      Properties: {
        facing: "west"
      }, 
      Name: "minecraft:jigsaw"
    }, 
    {
      Name: "minecraft:air"
    }, 
    {
      Properties: {
        east: "true", 
        waterlogged: "false", 
        south: "true", 
        north: "false", 
        west: "false"
      }, 
      Name: "minecraft:oak_fence"
    }, 
    {
      Properties: {
        east: "true", 
        waterlogged: "false", 
        south: "false", 
        north: "false", 
        west: "true"
      }, 
      Name: "minecraft:oak_fence"
    }, 
    {
      Properties: {
        east: "false", 
        waterlogged: "false", 
        south: "true", 
        north: "false", 
        west: "true"
      }, 
      Name: "minecraft:oak_fence"
    }, 
    {
      Properties: {
        east: "false", 
        waterlogged: "false", 
        south: "true", 
        north: "true", 
        west: "false"
      }, 
      Name: "minecraft:oak_fence"
    }, 
    {
      Properties: {
        east: "false", 
        waterlogged: "false", 
        south: "false", 
        north: "false", 
        west: "false"
      }, 
      Name: "minecraft:oak_fence"
    }, 
    {
      Properties: {
        half: "bottom", 
        waterlogged: "false", 
        shape: "straight", 
        facing: "east"
      }, 
      Name: "minecraft:oak_stairs"
    }, 
    {
      Properties: {
        waterlogged: "false", 
        type: "top"
      }, 
      Name: "minecraft:oak_slab"
    }, 
    {
      Properties: {
        half: "bottom", 
        waterlogged: "false", 
        shape: "straight", 
        facing: "west"
      }, 
      Name: "minecraft:oak_stairs"
    }, 
    {
      Properties: {
        waterlogged: "false", 
        type: "bottom"
      }, 
      Name: "minecraft:oak_slab"
    }, 
    {
      Properties: {
        half: "top", 
        waterlogged: "false", 
        shape: "straight", 
        facing: "west"
      }, 
      Name: "minecraft:oak_stairs"
    }, 
    {
      Properties: {
        facing: "north"
      }, 
      Name: "minecraft:wall_torch"
    }, 
    {
      Properties: {
        half: "top", 
        waterlogged: "false", 
        shape: "straight", 
        facing: "east"
      }, 
      Name: "minecraft:oak_stairs"
    }, 
    {
      Properties: {
        facing: "south"
      }, 
      Name: "minecraft:wall_torch"
    }, 
    {
      Properties: {
        half: "top", 
        waterlogged: "false", 
        shape: "straight", 
        facing: "north"
      }, 
      Name: "minecraft:oak_stairs"
    }, 
    {
      Name: "minecraft:grass_path"
    }, 
    {
      Properties: {
        hinge: "left", 
        half: "lower", 
        powered: "false", 
        facing: "east", 
        open: "false"
      }, 
      Name: "minecraft:oak_door"
    }, 
    {
      Properties: {
        hinge: "left", 
        half: "upper", 
        powered: "false", 
        facing: "east", 
        open: "false"
      }, 
      Name: "minecraft:oak_door"
    }, 
    {
      Properties: {
        east: "false", 
        waterlogged: "false", 
        south: "true", 
        north: "true", 
        west: "false"
      }, 
      Name: "minecraft:glass_pane"
    }, 
    {
      Properties: {
        facing: "east"
      }, 
      Name: "minecraft:wall_torch"
    }, 
    {
      Properties: {
        half: "top", 
        waterlogged: "false", 
        shape: "straight", 
        facing: "south"
      }, 
      Name: "minecraft:oak_stairs"
    }, 
    {
      Properties: {
        level: "0"
      }, 
      Name: "minecraft:water"
    }, 
    {
      Properties: {
        east: "true", 
        waterlogged: "false", 
        south: "false", 
        north: "false", 
        west: "true"
      }, 
      Name: "minecraft:glass_pane"
    }
  ]
}
