{
  size: [11, 9, 10], 
  entities: [], 
  blocks: [
    {
      pos: [4, 0, 0], 
      state: 0
    }, 
    {
      pos: [5, 0, 0], 
      state: 0
    }, 
    {
      pos: [6, 0, 0], 
      state: 0
    }, 
    {
      pos: [4, 1, 0], 
      state: 1
    }, 
    {
      pos: [5, 1, 0], 
      state: 1
    }, 
    {
      pos: [6, 1, 0], 
      state: 1
    }, 
    {
      pos: [3, 0, 1], 
      state: 0
    }, 
    {
      pos: [4, 0, 1], 
      state: 0
    }, 
    {
      pos: [5, 0, 1], 
      state: 0
    }, 
    {
      pos: [6, 0, 1], 
      state: 0
    }, 
    {
      pos: [7, 0, 1], 
      state: 0
    }, 
    {
      pos: [3, 1, 1], 
      state: 1
    }, 
    {
      pos: [7, 1, 1], 
      state: 1
    }, 
    {
      pos: [2, 0, 2], 
      state: 0
    }, 
    {
      pos: [3, 0, 2], 
      state: 0
    }, 
    {
      pos: [4, 0, 2], 
      state: 0
    }, 
    {
      pos: [5, 0, 2], 
      state: 0
    }, 
    {
      pos: [6, 0, 2], 
      state: 0
    }, 
    {
      pos: [7, 0, 2], 
      state: 0
    }, 
    {
      pos: [8, 0, 2], 
      state: 0
    }, 
    {
      pos: [2, 1, 2], 
      state: 0
    }, 
    {
      pos: [8, 1, 2], 
      state: 1
    }, 
    {
      pos: [1, 0, 3], 
      state: 0
    }, 
    {
      pos: [2, 0, 3], 
      state: 0
    }, 
    {
      pos: [3, 0, 3], 
      state: 0
    }, 
    {
      pos: [4, 0, 3], 
      state: 0
    }, 
    {
      pos: [5, 0, 3], 
      state: 0
    }, 
    {
      pos: [6, 0, 3], 
      state: 0
    }, 
    {
      pos: [7, 0, 3], 
      state: 0
    }, 
    {
      pos: [8, 0, 3], 
      state: 0
    }, 
    {
      pos: [1, 1, 3], 
      state: 0
    }, 
    {
      pos: [2, 1, 3], 
      state: 0
    }, 
    {
      pos: [3, 1, 3], 
      state: 0
    }, 
    {
      pos: [4, 1, 3], 
      state: 0
    }, 
    {
      pos: [5, 1, 3], 
      state: 0
    }, 
    {
      pos: [8, 1, 3], 
      state: 1
    }, 
    {
      pos: [1, 2, 3], 
      state: 2
    }, 
    {
      pos: [2, 2, 3], 
      state: 3
    }, 
    {
      pos: [3, 2, 3], 
      state: 3
    }, 
    {
      pos: [4, 2, 3], 
      state: 3
    }, 
    {
      pos: [5, 2, 3], 
      state: 2
    }, 
    {
      pos: [1, 3, 3], 
      state: 2
    }, 
    {
      pos: [2, 3, 3], 
      state: 3
    }, 
    {
      pos: [3, 3, 3], 
      state: 3
    }, 
    {
      pos: [4, 3, 3], 
      state: 3
    }, 
    {
      pos: [5, 3, 3], 
      state: 2
    }, 
    {
      pos: [1, 4, 3], 
      state: 2
    }, 
    {
      pos: [2, 4, 3], 
      state: 3
    }, 
    {
      pos: [4, 4, 3], 
      state: 3
    }, 
    {
      pos: [5, 4, 3], 
      state: 2
    }, 
    {
      pos: [1, 5, 3], 
      state: 2
    }, 
    {
      pos: [2, 5, 3], 
      state: 3
    }, 
    {
      pos: [3, 5, 3], 
      state: 3
    }, 
    {
      pos: [4, 5, 3], 
      state: 3
    }, 
    {
      pos: [5, 5, 3], 
      state: 2
    }, 
    {
      pos: [1, 6, 3], 
      state: 2
    }, 
    {
      pos: [2, 6, 3], 
      state: 4
    }, 
    {
      pos: [3, 6, 3], 
      state: 4
    }, 
    {
      pos: [4, 6, 3], 
      state: 4
    }, 
    {
      pos: [5, 6, 3], 
      state: 2
    }, 
    {
      pos: [0, 0, 4], 
      state: 0
    }, 
    {
      pos: [1, 0, 4], 
      state: 0
    }, 
    {
      pos: [2, 0, 4], 
      state: 0
    }, 
    {
      pos: [3, 0, 4], 
      state: 0
    }, 
    {
      pos: [4, 0, 4], 
      state: 0
    }, 
    {
      pos: [5, 0, 4], 
      state: 0
    }, 
    {
      pos: [6, 0, 4], 
      state: 0
    }, 
    {
      pos: [7, 0, 4], 
      state: 0
    }, 
    {
      pos: [8, 0, 4], 
      state: 0
    }, 
    {
      pos: [9, 0, 4], 
      state: 0
    }, 
    {
      pos: [10, 0, 4], 
      state: 0
    }, 
    {
      pos: [0, 1, 4], 
      state: 1
    }, 
    {
      pos: [1, 1, 4], 
      state: 0
    }, 
    {
      pos: [2, 1, 4], 
      state: 3
    }, 
    {
      pos: [3, 1, 4], 
      state: 3
    }, 
    {
      pos: [4, 1, 4], 
      state: 3
    }, 
    {
      pos: [5, 1, 4], 
      state: 0
    }, 
    {
      pos: [9, 1, 4], 
      state: 1
    }, 
    {
      pos: [10, 1, 4], 
      state: 1
    }, 
    {
      pos: [1, 2, 4], 
      state: 3
    }, 
    {
      pos: [5, 2, 4], 
      state: 3
    }, 
    {
      pos: [1, 3, 4], 
      state: 3
    }, 
    {
      pos: [5, 3, 4], 
      state: 3
    }, 
    {
      pos: [1, 4, 4], 
      state: 3
    }, 
    {
      pos: [5, 4, 4], 
      state: 3
    }, 
    {
      pos: [1, 5, 4], 
      state: 3
    }, 
    {
      pos: [5, 5, 4], 
      state: 3
    }, 
    {
      pos: [1, 6, 4], 
      state: 5
    }, 
    {
      pos: [5, 6, 4], 
      state: 5
    }, 
    {
      pos: [1, 7, 4], 
      state: 3
    }, 
    {
      pos: [5, 7, 4], 
      state: 3
    }, 
    {
      pos: [0, 0, 5], 
      state: 0
    }, 
    {
      pos: [1, 0, 5], 
      state: 0
    }, 
    {
      pos: [2, 0, 5], 
      state: 0
    }, 
    {
      pos: [3, 0, 5], 
      state: 0
    }, 
    {
      pos: [4, 0, 5], 
      state: 0
    }, 
    {
      pos: [5, 0, 5], 
      state: 0
    }, 
    {
      pos: [6, 0, 5], 
      state: 0
    }, 
    {
      pos: [7, 0, 5], 
      state: 0
    }, 
    {
      pos: [8, 0, 5], 
      state: 0
    }, 
    {
      pos: [9, 0, 5], 
      state: 0
    }, 
    {
      pos: [10, 0, 5], 
      state: 0
    }, 
    {
      pos: [0, 1, 5], 
      state: 1
    }, 
    {
      pos: [1, 1, 5], 
      state: 0
    }, 
    {
      pos: [2, 1, 5], 
      state: 0
    }, 
    {
      pos: [3, 1, 5], 
      state: 0
    }, 
    {
      pos: [4, 1, 5], 
      state: 0
    }, 
    {
      pos: [5, 1, 5], 
      state: 0
    }, 
    {
      pos: [10, 1, 5], 
      state: 1
    }, 
    {
      pos: [1, 2, 5], 
      state: 3
    }, 
    {
      pos: [2, 2, 5], 
      state: 6
    }, 
    {
      pos: [3, 2, 5], 
      state: 6
    }, 
    {
      pos: [4, 2, 5], 
      state: 6
    }, 
    {
      pos: [5, 2, 5], 
      state: 3
    }, 
    {
      pos: [1, 5, 5], 
      state: 3
    }, 
    {
      pos: [5, 5, 5], 
      state: 3
    }, 
    {
      pos: [1, 6, 5], 
      state: 5
    }, 
    {
      pos: [5, 6, 5], 
      state: 5
    }, 
    {
      pos: [1, 7, 5], 
      state: 3
    }, 
    {
      pos: [5, 7, 5], 
      state: 3
    }, 
    {
      pos: [0, 8, 5], 
      state: 6
    }, 
    {
      pos: [1, 8, 5], 
      state: 6
    }, 
    {
      pos: [2, 8, 5], 
      state: 6
    }, 
    {
      pos: [3, 8, 5], 
      state: 6
    }, 
    {
      pos: [4, 8, 5], 
      state: 6
    }, 
    {
      pos: [5, 8, 5], 
      state: 6
    }, 
    {
      pos: [6, 8, 5], 
      state: 6
    }, 
    {
      pos: [0, 0, 6], 
      state: 0
    }, 
    {
      pos: [1, 0, 6], 
      state: 0
    }, 
    {
      pos: [2, 0, 6], 
      state: 0
    }, 
    {
      pos: [3, 0, 6], 
      state: 0
    }, 
    {
      pos: [4, 0, 6], 
      state: 0
    }, 
    {
      pos: [5, 0, 6], 
      state: 0
    }, 
    {
      pos: [6, 0, 6], 
      state: 0
    }, 
    {
      pos: [7, 0, 6], 
      state: 0
    }, 
    {
      pos: [8, 0, 6], 
      state: 0
    }, 
    {
      pos: [9, 0, 6], 
      state: 0
    }, 
    {
      pos: [10, 0, 6], 
      state: 0
    }, 
    {
      pos: [0, 1, 6], 
      state: 1
    }, 
    {
      pos: [1, 1, 6], 
      state: 0
    }, 
    {
      pos: [2, 1, 6], 
      state: 0
    }, 
    {
      pos: [3, 1, 6], 
      state: 0
    }, 
    {
      pos: [4, 1, 6], 
      state: 0
    }, 
    {
      pos: [5, 1, 6], 
      state: 0
    }, 
    {
      pos: [10, 1, 6], 
      state: 1
    }, 
    {
      pos: [1, 2, 6], 
      state: 3
    }, 
    {
      pos: [2, 2, 6], 
      state: 6
    }, 
    {
      pos: [3, 2, 6], 
      state: 6
    }, 
    {
      pos: [4, 2, 6], 
      state: 6
    }, 
    {
      pos: [5, 2, 6], 
      state: 3
    }, 
    {
      pos: [1, 3, 6], 
      state: 3
    }, 
    {
      pos: [5, 3, 6], 
      state: 3
    }, 
    {
      pos: [1, 4, 6], 
      state: 3
    }, 
    {
      pos: [5, 4, 6], 
      state: 3
    }, 
    {
      pos: [1, 5, 6], 
      state: 3
    }, 
    {
      pos: [5, 5, 6], 
      state: 3
    }, 
    {
      pos: [1, 6, 6], 
      state: 5
    }, 
    {
      pos: [5, 6, 6], 
      state: 5
    }, 
    {
      pos: [1, 7, 6], 
      state: 3
    }, 
    {
      pos: [5, 7, 6], 
      state: 3
    }, 
    {
      pos: [0, 0, 7], 
      state: 0
    }, 
    {
      pos: [1, 0, 7], 
      state: 0
    }, 
    {
      pos: [2, 0, 7], 
      state: 0
    }, 
    {
      pos: [3, 0, 7], 
      state: 0
    }, 
    {
      pos: [4, 0, 7], 
      state: 0
    }, 
    {
      pos: [5, 0, 7], 
      state: 0
    }, 
    {
      pos: [6, 0, 7], 
      state: 0
    }, 
    {
      pos: [7, 0, 7], 
      state: 0
    }, 
    {
      pos: [8, 0, 7], 
      state: 0
    }, 
    {
      pos: [9, 0, 7], 
      state: 0
    }, 
    {
      pos: [10, 0, 7], 
      state: 0
    }, 
    {
      pos: [0, 1, 7], 
      state: 0
    }, 
    {
      pos: [1, 1, 7], 
      state: 0
    }, 
    {
      pos: [2, 1, 7], 
      state: 0
    }, 
    {
      pos: [3, 1, 7], 
      state: 0
    }, 
    {
      pos: [4, 1, 7], 
      state: 0
    }, 
    {
      pos: [5, 1, 7], 
      state: 0
    }, 
    {
      pos: [9, 1, 7], 
      state: 0
    }, 
    {
      pos: [10, 1, 7], 
      state: 1
    }, 
    {
      pos: [1, 2, 7], 
      state: 2
    }, 
    {
      pos: [2, 2, 7], 
      state: 3
    }, 
    {
      pos: [3, 2, 7], 
      state: 3
    }, 
    {
      pos: [4, 2, 7], 
      state: 3
    }, 
    {
      pos: [5, 2, 7], 
      state: 2
    }, 
    {
      pos: [1, 3, 7], 
      state: 2
    }, 
    {
      pos: [2, 3, 7], 
      state: 3
    }, 
    {
      pos: [3, 3, 7], 
      state: 3
    }, 
    {
      pos: [4, 3, 7], 
      state: 3
    }, 
    {
      pos: [5, 3, 7], 
      state: 2
    }, 
    {
      pos: [1, 4, 7], 
      state: 2
    }, 
    {
      pos: [2, 4, 7], 
      state: 3
    }, 
    {
      pos: [4, 4, 7], 
      state: 3
    }, 
    {
      pos: [5, 4, 7], 
      state: 2
    }, 
    {
      pos: [1, 5, 7], 
      state: 2
    }, 
    {
      pos: [2, 5, 7], 
      state: 3
    }, 
    {
      pos: [3, 5, 7], 
      state: 3
    }, 
    {
      pos: [4, 5, 7], 
      state: 3
    }, 
    {
      pos: [5, 5, 7], 
      state: 2
    }, 
    {
      pos: [1, 6, 7], 
      state: 2
    }, 
    {
      pos: [2, 6, 7], 
      state: 4
    }, 
    {
      pos: [3, 6, 7], 
      state: 4
    }, 
    {
      pos: [4, 6, 7], 
      state: 4
    }, 
    {
      pos: [5, 6, 7], 
      state: 2
    }, 
    {
      pos: [3, 0, 8], 
      state: 0
    }, 
    {
      pos: [4, 0, 8], 
      state: 0
    }, 
    {
      pos: [5, 0, 8], 
      state: 0
    }, 
    {
      pos: [6, 0, 8], 
      state: 0
    }, 
    {
      pos: [7, 0, 8], 
      state: 0
    }, 
    {
      pos: [8, 0, 8], 
      state: 0
    }, 
    {
      pos: [3, 1, 8], 
      state: 1
    }, 
    {
      pos: [8, 1, 8], 
      state: 1
    }, 
    {
      pos: [4, 0, 9], 
      state: 0
    }, 
    {
      pos: [5, 0, 9], 
      state: 0
    }, 
    {
      pos: [6, 0, 9], 
      state: 0
    }, 
    {
      pos: [7, 0, 9], 
      state: 0
    }, 
    {
      pos: [8, 0, 9], 
      state: 0
    }, 
    {
      pos: [4, 1, 9], 
      state: 1
    }, 
    {
      pos: [5, 1, 9], 
      state: 1
    }, 
    {
      pos: [6, 1, 9], 
      state: 1
    }, 
    {
      pos: [7, 1, 9], 
      state: 1
    }, 
    {
      pos: [8, 1, 9], 
      state: 1
    }, 
    {
      nbt: {
        Items: [], 
        id: "minecraft:barrel"
      }, 
      pos: [2, 2, 2], 
      state: 7
    }, 
    {
      nbt: {
        LootTable: "minecraft:chests/village/village_fisher", 
        Items: [], 
        id: "minecraft:chest", 
        LootTableSeed: 0L
      }, 
      pos: [4, 3, 6], 
      state: 8
    }, 
    {
      nbt: {
        target_pool: "minecraft:empty", 
        final_state: "minecraft:structure_void", 
        id: "minecraft:jigsaw", 
        attachement_type: "minecraft:building_entrance"
      }, 
      pos: [0, 2, 7], 
      state: 9
    }, 
    {
      nbt: {
        Items: [], 
        id: "minecraft:barrel"
      }, 
      pos: [9, 2, 7], 
      state: 7
    }, 
    {
      pos: [0, 2, 0], 
      state: 10
    }, 
    {
      pos: [1, 2, 0], 
      state: 10
    }, 
    {
      pos: [2, 2, 0], 
      state: 10
    }, 
    {
      pos: [3, 2, 0], 
      state: 10
    }, 
    {
      pos: [4, 2, 0], 
      state: 10
    }, 
    {
      pos: [5, 2, 0], 
      state: 10
    }, 
    {
      pos: [6, 2, 0], 
      state: 10
    }, 
    {
      pos: [7, 2, 0], 
      state: 10
    }, 
    {
      pos: [8, 2, 0], 
      state: 10
    }, 
    {
      pos: [9, 2, 0], 
      state: 10
    }, 
    {
      pos: [10, 2, 0], 
      state: 10
    }, 
    {
      pos: [0, 3, 0], 
      state: 10
    }, 
    {
      pos: [1, 3, 0], 
      state: 10
    }, 
    {
      pos: [2, 3, 0], 
      state: 10
    }, 
    {
      pos: [3, 3, 0], 
      state: 10
    }, 
    {
      pos: [4, 3, 0], 
      state: 10
    }, 
    {
      pos: [5, 3, 0], 
      state: 10
    }, 
    {
      pos: [6, 3, 0], 
      state: 10
    }, 
    {
      pos: [7, 3, 0], 
      state: 10
    }, 
    {
      pos: [8, 3, 0], 
      state: 10
    }, 
    {
      pos: [9, 3, 0], 
      state: 10
    }, 
    {
      pos: [10, 3, 0], 
      state: 10
    }, 
    {
      pos: [0, 4, 0], 
      state: 10
    }, 
    {
      pos: [1, 4, 0], 
      state: 10
    }, 
    {
      pos: [2, 4, 0], 
      state: 10
    }, 
    {
      pos: [3, 4, 0], 
      state: 10
    }, 
    {
      pos: [4, 4, 0], 
      state: 10
    }, 
    {
      pos: [5, 4, 0], 
      state: 10
    }, 
    {
      pos: [6, 4, 0], 
      state: 10
    }, 
    {
      pos: [7, 4, 0], 
      state: 10
    }, 
    {
      pos: [8, 4, 0], 
      state: 10
    }, 
    {
      pos: [9, 4, 0], 
      state: 10
    }, 
    {
      pos: [10, 4, 0], 
      state: 10
    }, 
    {
      pos: [0, 5, 0], 
      state: 10
    }, 
    {
      pos: [1, 5, 0], 
      state: 10
    }, 
    {
      pos: [2, 5, 0], 
      state: 10
    }, 
    {
      pos: [3, 5, 0], 
      state: 10
    }, 
    {
      pos: [4, 5, 0], 
      state: 10
    }, 
    {
      pos: [5, 5, 0], 
      state: 10
    }, 
    {
      pos: [6, 5, 0], 
      state: 10
    }, 
    {
      pos: [7, 5, 0], 
      state: 10
    }, 
    {
      pos: [8, 5, 0], 
      state: 10
    }, 
    {
      pos: [9, 5, 0], 
      state: 10
    }, 
    {
      pos: [10, 5, 0], 
      state: 10
    }, 
    {
      pos: [0, 6, 0], 
      state: 10
    }, 
    {
      pos: [1, 6, 0], 
      state: 10
    }, 
    {
      pos: [2, 6, 0], 
      state: 10
    }, 
    {
      pos: [3, 6, 0], 
      state: 10
    }, 
    {
      pos: [4, 6, 0], 
      state: 10
    }, 
    {
      pos: [5, 6, 0], 
      state: 10
    }, 
    {
      pos: [6, 6, 0], 
      state: 10
    }, 
    {
      pos: [7, 6, 0], 
      state: 10
    }, 
    {
      pos: [8, 6, 0], 
      state: 10
    }, 
    {
      pos: [9, 6, 0], 
      state: 10
    }, 
    {
      pos: [10, 6, 0], 
      state: 10
    }, 
    {
      pos: [0, 7, 0], 
      state: 10
    }, 
    {
      pos: [1, 7, 0], 
      state: 10
    }, 
    {
      pos: [2, 7, 0], 
      state: 10
    }, 
    {
      pos: [3, 7, 0], 
      state: 10
    }, 
    {
      pos: [4, 7, 0], 
      state: 10
    }, 
    {
      pos: [5, 7, 0], 
      state: 10
    }, 
    {
      pos: [6, 7, 0], 
      state: 10
    }, 
    {
      pos: [7, 7, 0], 
      state: 10
    }, 
    {
      pos: [8, 7, 0], 
      state: 10
    }, 
    {
      pos: [9, 7, 0], 
      state: 10
    }, 
    {
      pos: [10, 7, 0], 
      state: 10
    }, 
    {
      pos: [0, 8, 0], 
      state: 10
    }, 
    {
      pos: [1, 8, 0], 
      state: 10
    }, 
    {
      pos: [2, 8, 0], 
      state: 10
    }, 
    {
      pos: [3, 8, 0], 
      state: 10
    }, 
    {
      pos: [4, 8, 0], 
      state: 10
    }, 
    {
      pos: [5, 8, 0], 
      state: 10
    }, 
    {
      pos: [6, 8, 0], 
      state: 10
    }, 
    {
      pos: [7, 8, 0], 
      state: 10
    }, 
    {
      pos: [8, 8, 0], 
      state: 10
    }, 
    {
      pos: [9, 8, 0], 
      state: 10
    }, 
    {
      pos: [10, 8, 0], 
      state: 10
    }, 
    {
      pos: [4, 1, 1], 
      state: 11
    }, 
    {
      pos: [5, 1, 1], 
      state: 11
    }, 
    {
      pos: [6, 1, 1], 
      state: 11
    }, 
    {
      pos: [10, 1, 1], 
      state: 10
    }, 
    {
      pos: [0, 2, 1], 
      state: 10
    }, 
    {
      pos: [1, 2, 1], 
      state: 10
    }, 
    {
      pos: [2, 2, 1], 
      state: 10
    }, 
    {
      pos: [3, 2, 1], 
      state: 10
    }, 
    {
      pos: [4, 2, 1], 
      state: 10
    }, 
    {
      pos: [5, 2, 1], 
      state: 10
    }, 
    {
      pos: [6, 2, 1], 
      state: 10
    }, 
    {
      pos: [7, 2, 1], 
      state: 10
    }, 
    {
      pos: [8, 2, 1], 
      state: 10
    }, 
    {
      pos: [9, 2, 1], 
      state: 10
    }, 
    {
      pos: [10, 2, 1], 
      state: 10
    }, 
    {
      pos: [0, 3, 1], 
      state: 10
    }, 
    {
      pos: [1, 3, 1], 
      state: 10
    }, 
    {
      pos: [2, 3, 1], 
      state: 10
    }, 
    {
      pos: [3, 3, 1], 
      state: 10
    }, 
    {
      pos: [4, 3, 1], 
      state: 10
    }, 
    {
      pos: [5, 3, 1], 
      state: 10
    }, 
    {
      pos: [6, 3, 1], 
      state: 10
    }, 
    {
      pos: [7, 3, 1], 
      state: 10
    }, 
    {
      pos: [8, 3, 1], 
      state: 10
    }, 
    {
      pos: [9, 3, 1], 
      state: 10
    }, 
    {
      pos: [10, 3, 1], 
      state: 10
    }, 
    {
      pos: [0, 4, 1], 
      state: 10
    }, 
    {
      pos: [1, 4, 1], 
      state: 10
    }, 
    {
      pos: [2, 4, 1], 
      state: 10
    }, 
    {
      pos: [3, 4, 1], 
      state: 10
    }, 
    {
      pos: [4, 4, 1], 
      state: 10
    }, 
    {
      pos: [5, 4, 1], 
      state: 10
    }, 
    {
      pos: [6, 4, 1], 
      state: 10
    }, 
    {
      pos: [7, 4, 1], 
      state: 10
    }, 
    {
      pos: [8, 4, 1], 
      state: 10
    }, 
    {
      pos: [9, 4, 1], 
      state: 10
    }, 
    {
      pos: [10, 4, 1], 
      state: 10
    }, 
    {
      pos: [0, 5, 1], 
      state: 10
    }, 
    {
      pos: [1, 5, 1], 
      state: 10
    }, 
    {
      pos: [2, 5, 1], 
      state: 10
    }, 
    {
      pos: [3, 5, 1], 
      state: 10
    }, 
    {
      pos: [4, 5, 1], 
      state: 10
    }, 
    {
      pos: [5, 5, 1], 
      state: 10
    }, 
    {
      pos: [6, 5, 1], 
      state: 10
    }, 
    {
      pos: [7, 5, 1], 
      state: 10
    }, 
    {
      pos: [8, 5, 1], 
      state: 10
    }, 
    {
      pos: [9, 5, 1], 
      state: 10
    }, 
    {
      pos: [10, 5, 1], 
      state: 10
    }, 
    {
      pos: [0, 6, 1], 
      state: 10
    }, 
    {
      pos: [1, 6, 1], 
      state: 10
    }, 
    {
      pos: [2, 6, 1], 
      state: 10
    }, 
    {
      pos: [3, 6, 1], 
      state: 10
    }, 
    {
      pos: [4, 6, 1], 
      state: 10
    }, 
    {
      pos: [5, 6, 1], 
      state: 10
    }, 
    {
      pos: [6, 6, 1], 
      state: 10
    }, 
    {
      pos: [7, 6, 1], 
      state: 10
    }, 
    {
      pos: [8, 6, 1], 
      state: 10
    }, 
    {
      pos: [9, 6, 1], 
      state: 10
    }, 
    {
      pos: [10, 6, 1], 
      state: 10
    }, 
    {
      pos: [0, 7, 1], 
      state: 10
    }, 
    {
      pos: [1, 7, 1], 
      state: 10
    }, 
    {
      pos: [2, 7, 1], 
      state: 10
    }, 
    {
      pos: [3, 7, 1], 
      state: 10
    }, 
    {
      pos: [4, 7, 1], 
      state: 10
    }, 
    {
      pos: [5, 7, 1], 
      state: 10
    }, 
    {
      pos: [6, 7, 1], 
      state: 10
    }, 
    {
      pos: [7, 7, 1], 
      state: 10
    }, 
    {
      pos: [8, 7, 1], 
      state: 10
    }, 
    {
      pos: [9, 7, 1], 
      state: 10
    }, 
    {
      pos: [10, 7, 1], 
      state: 10
    }, 
    {
      pos: [0, 8, 1], 
      state: 10
    }, 
    {
      pos: [1, 8, 1], 
      state: 10
    }, 
    {
      pos: [2, 8, 1], 
      state: 10
    }, 
    {
      pos: [3, 8, 1], 
      state: 10
    }, 
    {
      pos: [4, 8, 1], 
      state: 10
    }, 
    {
      pos: [5, 8, 1], 
      state: 10
    }, 
    {
      pos: [6, 8, 1], 
      state: 10
    }, 
    {
      pos: [7, 8, 1], 
      state: 10
    }, 
    {
      pos: [8, 8, 1], 
      state: 10
    }, 
    {
      pos: [9, 8, 1], 
      state: 10
    }, 
    {
      pos: [10, 8, 1], 
      state: 10
    }, 
    {
      pos: [3, 1, 2], 
      state: 11
    }, 
    {
      pos: [4, 1, 2], 
      state: 11
    }, 
    {
      pos: [5, 1, 2], 
      state: 11
    }, 
    {
      pos: [6, 1, 2], 
      state: 11
    }, 
    {
      pos: [7, 1, 2], 
      state: 11
    }, 
    {
      pos: [0, 2, 2], 
      state: 10
    }, 
    {
      pos: [1, 2, 2], 
      state: 10
    }, 
    {
      pos: [3, 2, 2], 
      state: 10
    }, 
    {
      pos: [4, 2, 2], 
      state: 10
    }, 
    {
      pos: [5, 2, 2], 
      state: 10
    }, 
    {
      pos: [6, 2, 2], 
      state: 10
    }, 
    {
      pos: [7, 2, 2], 
      state: 10
    }, 
    {
      pos: [8, 2, 2], 
      state: 10
    }, 
    {
      pos: [9, 2, 2], 
      state: 10
    }, 
    {
      pos: [10, 2, 2], 
      state: 10
    }, 
    {
      pos: [0, 3, 2], 
      state: 10
    }, 
    {
      pos: [1, 3, 2], 
      state: 10
    }, 
    {
      pos: [2, 3, 2], 
      state: 10
    }, 
    {
      pos: [3, 3, 2], 
      state: 10
    }, 
    {
      pos: [4, 3, 2], 
      state: 10
    }, 
    {
      pos: [5, 3, 2], 
      state: 10
    }, 
    {
      pos: [6, 3, 2], 
      state: 10
    }, 
    {
      pos: [7, 3, 2], 
      state: 10
    }, 
    {
      pos: [8, 3, 2], 
      state: 10
    }, 
    {
      pos: [9, 3, 2], 
      state: 10
    }, 
    {
      pos: [10, 3, 2], 
      state: 10
    }, 
    {
      pos: [0, 4, 2], 
      state: 10
    }, 
    {
      pos: [1, 4, 2], 
      state: 10
    }, 
    {
      pos: [2, 4, 2], 
      state: 10
    }, 
    {
      pos: [3, 4, 2], 
      state: 10
    }, 
    {
      pos: [4, 4, 2], 
      state: 10
    }, 
    {
      pos: [5, 4, 2], 
      state: 10
    }, 
    {
      pos: [6, 4, 2], 
      state: 10
    }, 
    {
      pos: [7, 4, 2], 
      state: 10
    }, 
    {
      pos: [8, 4, 2], 
      state: 10
    }, 
    {
      pos: [9, 4, 2], 
      state: 10
    }, 
    {
      pos: [10, 4, 2], 
      state: 10
    }, 
    {
      pos: [0, 5, 2], 
      state: 10
    }, 
    {
      pos: [1, 5, 2], 
      state: 10
    }, 
    {
      pos: [2, 5, 2], 
      state: 10
    }, 
    {
      pos: [3, 5, 2], 
      state: 10
    }, 
    {
      pos: [4, 5, 2], 
      state: 10
    }, 
    {
      pos: [5, 5, 2], 
      state: 10
    }, 
    {
      pos: [6, 5, 2], 
      state: 10
    }, 
    {
      pos: [7, 5, 2], 
      state: 10
    }, 
    {
      pos: [8, 5, 2], 
      state: 10
    }, 
    {
      pos: [9, 5, 2], 
      state: 10
    }, 
    {
      pos: [10, 5, 2], 
      state: 10
    }, 
    {
      pos: [0, 6, 2], 
      state: 12
    }, 
    {
      pos: [1, 6, 2], 
      state: 12
    }, 
    {
      pos: [2, 6, 2], 
      state: 12
    }, 
    {
      pos: [3, 6, 2], 
      state: 12
    }, 
    {
      pos: [4, 6, 2], 
      state: 12
    }, 
    {
      pos: [5, 6, 2], 
      state: 12
    }, 
    {
      pos: [6, 6, 2], 
      state: 12
    }, 
    {
      pos: [7, 6, 2], 
      state: 10
    }, 
    {
      pos: [8, 6, 2], 
      state: 10
    }, 
    {
      pos: [9, 6, 2], 
      state: 10
    }, 
    {
      pos: [10, 6, 2], 
      state: 10
    }, 
    {
      pos: [0, 7, 2], 
      state: 10
    }, 
    {
      pos: [1, 7, 2], 
      state: 10
    }, 
    {
      pos: [2, 7, 2], 
      state: 10
    }, 
    {
      pos: [3, 7, 2], 
      state: 10
    }, 
    {
      pos: [4, 7, 2], 
      state: 10
    }, 
    {
      pos: [5, 7, 2], 
      state: 10
    }, 
    {
      pos: [6, 7, 2], 
      state: 10
    }, 
    {
      pos: [7, 7, 2], 
      state: 10
    }, 
    {
      pos: [8, 7, 2], 
      state: 10
    }, 
    {
      pos: [9, 7, 2], 
      state: 10
    }, 
    {
      pos: [10, 7, 2], 
      state: 10
    }, 
    {
      pos: [0, 8, 2], 
      state: 10
    }, 
    {
      pos: [1, 8, 2], 
      state: 10
    }, 
    {
      pos: [2, 8, 2], 
      state: 10
    }, 
    {
      pos: [3, 8, 2], 
      state: 10
    }, 
    {
      pos: [4, 8, 2], 
      state: 10
    }, 
    {
      pos: [5, 8, 2], 
      state: 10
    }, 
    {
      pos: [6, 8, 2], 
      state: 10
    }, 
    {
      pos: [7, 8, 2], 
      state: 10
    }, 
    {
      pos: [8, 8, 2], 
      state: 10
    }, 
    {
      pos: [9, 8, 2], 
      state: 10
    }, 
    {
      pos: [10, 8, 2], 
      state: 10
    }, 
    {
      pos: [6, 1, 3], 
      state: 11
    }, 
    {
      pos: [7, 1, 3], 
      state: 11
    }, 
    {
      pos: [0, 2, 3], 
      state: 10
    }, 
    {
      pos: [6, 2, 3], 
      state: 10
    }, 
    {
      pos: [7, 2, 3], 
      state: 10
    }, 
    {
      pos: [8, 2, 3], 
      state: 10
    }, 
    {
      pos: [9, 2, 3], 
      state: 10
    }, 
    {
      pos: [10, 2, 3], 
      state: 10
    }, 
    {
      pos: [0, 3, 3], 
      state: 10
    }, 
    {
      pos: [6, 3, 3], 
      state: 10
    }, 
    {
      pos: [7, 3, 3], 
      state: 10
    }, 
    {
      pos: [8, 3, 3], 
      state: 10
    }, 
    {
      pos: [9, 3, 3], 
      state: 10
    }, 
    {
      pos: [10, 3, 3], 
      state: 10
    }, 
    {
      pos: [0, 4, 3], 
      state: 10
    }, 
    {
      pos: [3, 4, 3], 
      state: 13
    }, 
    {
      pos: [6, 4, 3], 
      state: 10
    }, 
    {
      pos: [7, 4, 3], 
      state: 10
    }, 
    {
      pos: [8, 4, 3], 
      state: 10
    }, 
    {
      pos: [9, 4, 3], 
      state: 10
    }, 
    {
      pos: [10, 4, 3], 
      state: 10
    }, 
    {
      pos: [0, 5, 3], 
      state: 10
    }, 
    {
      pos: [6, 5, 3], 
      state: 10
    }, 
    {
      pos: [7, 5, 3], 
      state: 10
    }, 
    {
      pos: [8, 5, 3], 
      state: 10
    }, 
    {
      pos: [9, 5, 3], 
      state: 10
    }, 
    {
      pos: [10, 5, 3], 
      state: 10
    }, 
    {
      pos: [0, 6, 3], 
      state: 14
    }, 
    {
      pos: [6, 6, 3], 
      state: 14
    }, 
    {
      pos: [7, 6, 3], 
      state: 10
    }, 
    {
      pos: [8, 6, 3], 
      state: 10
    }, 
    {
      pos: [9, 6, 3], 
      state: 10
    }, 
    {
      pos: [10, 6, 3], 
      state: 10
    }, 
    {
      pos: [0, 7, 3], 
      state: 12
    }, 
    {
      pos: [1, 7, 3], 
      state: 12
    }, 
    {
      pos: [2, 7, 3], 
      state: 12
    }, 
    {
      pos: [3, 7, 3], 
      state: 12
    }, 
    {
      pos: [4, 7, 3], 
      state: 12
    }, 
    {
      pos: [5, 7, 3], 
      state: 12
    }, 
    {
      pos: [6, 7, 3], 
      state: 12
    }, 
    {
      pos: [7, 7, 3], 
      state: 10
    }, 
    {
      pos: [8, 7, 3], 
      state: 10
    }, 
    {
      pos: [9, 7, 3], 
      state: 10
    }, 
    {
      pos: [10, 7, 3], 
      state: 10
    }, 
    {
      pos: [0, 8, 3], 
      state: 10
    }, 
    {
      pos: [1, 8, 3], 
      state: 10
    }, 
    {
      pos: [2, 8, 3], 
      state: 10
    }, 
    {
      pos: [3, 8, 3], 
      state: 10
    }, 
    {
      pos: [4, 8, 3], 
      state: 10
    }, 
    {
      pos: [5, 8, 3], 
      state: 10
    }, 
    {
      pos: [6, 8, 3], 
      state: 10
    }, 
    {
      pos: [7, 8, 3], 
      state: 10
    }, 
    {
      pos: [8, 8, 3], 
      state: 10
    }, 
    {
      pos: [9, 8, 3], 
      state: 10
    }, 
    {
      pos: [10, 8, 3], 
      state: 10
    }, 
    {
      pos: [6, 1, 4], 
      state: 11
    }, 
    {
      pos: [7, 1, 4], 
      state: 11
    }, 
    {
      pos: [8, 1, 4], 
      state: 11
    }, 
    {
      pos: [0, 2, 4], 
      state: 15
    }, 
    {
      pos: [2, 2, 4], 
      state: 11
    }, 
    {
      pos: [3, 2, 4], 
      state: 11
    }, 
    {
      pos: [4, 2, 4], 
      state: 11
    }, 
    {
      pos: [6, 2, 4], 
      state: 10
    }, 
    {
      pos: [7, 2, 4], 
      state: 10
    }, 
    {
      pos: [8, 2, 4], 
      state: 10
    }, 
    {
      pos: [9, 2, 4], 
      state: 10
    }, 
    {
      pos: [10, 2, 4], 
      state: 10
    }, 
    {
      pos: [0, 3, 4], 
      state: 10
    }, 
    {
      pos: [2, 3, 4], 
      state: 10
    }, 
    {
      pos: [3, 3, 4], 
      state: 10
    }, 
    {
      pos: [4, 3, 4], 
      state: 10
    }, 
    {
      pos: [6, 3, 4], 
      state: 10
    }, 
    {
      pos: [7, 3, 4], 
      state: 10
    }, 
    {
      pos: [8, 3, 4], 
      state: 10
    }, 
    {
      pos: [9, 3, 4], 
      state: 10
    }, 
    {
      pos: [10, 3, 4], 
      state: 10
    }, 
    {
      pos: [0, 4, 4], 
      state: 10
    }, 
    {
      pos: [2, 4, 4], 
      state: 10
    }, 
    {
      pos: [3, 4, 4], 
      state: 10
    }, 
    {
      pos: [4, 4, 4], 
      state: 10
    }, 
    {
      pos: [6, 4, 4], 
      state: 10
    }, 
    {
      pos: [7, 4, 4], 
      state: 10
    }, 
    {
      pos: [8, 4, 4], 
      state: 10
    }, 
    {
      pos: [9, 4, 4], 
      state: 10
    }, 
    {
      pos: [10, 4, 4], 
      state: 10
    }, 
    {
      pos: [0, 5, 4], 
      state: 10
    }, 
    {
      pos: [2, 5, 4], 
      state: 10
    }, 
    {
      pos: [3, 5, 4], 
      state: 10
    }, 
    {
      pos: [4, 5, 4], 
      state: 10
    }, 
    {
      pos: [6, 5, 4], 
      state: 10
    }, 
    {
      pos: [7, 5, 4], 
      state: 10
    }, 
    {
      pos: [8, 5, 4], 
      state: 10
    }, 
    {
      pos: [9, 5, 4], 
      state: 10
    }, 
    {
      pos: [10, 5, 4], 
      state: 10
    }, 
    {
      pos: [0, 6, 4], 
      state: 10
    }, 
    {
      pos: [2, 6, 4], 
      state: 10
    }, 
    {
      pos: [3, 6, 4], 
      state: 10
    }, 
    {
      pos: [4, 6, 4], 
      state: 10
    }, 
    {
      pos: [6, 6, 4], 
      state: 10
    }, 
    {
      pos: [7, 6, 4], 
      state: 10
    }, 
    {
      pos: [8, 6, 4], 
      state: 10
    }, 
    {
      pos: [9, 6, 4], 
      state: 10
    }, 
    {
      pos: [10, 6, 4], 
      state: 10
    }, 
    {
      pos: [0, 7, 4], 
      state: 14
    }, 
    {
      pos: [2, 7, 4], 
      state: 10
    }, 
    {
      pos: [3, 7, 4], 
      state: 10
    }, 
    {
      pos: [4, 7, 4], 
      state: 10
    }, 
    {
      pos: [6, 7, 4], 
      state: 14
    }, 
    {
      pos: [7, 7, 4], 
      state: 10
    }, 
    {
      pos: [8, 7, 4], 
      state: 10
    }, 
    {
      pos: [9, 7, 4], 
      state: 10
    }, 
    {
      pos: [10, 7, 4], 
      state: 10
    }, 
    {
      pos: [0, 8, 4], 
      state: 12
    }, 
    {
      pos: [1, 8, 4], 
      state: 12
    }, 
    {
      pos: [2, 8, 4], 
      state: 12
    }, 
    {
      pos: [3, 8, 4], 
      state: 12
    }, 
    {
      pos: [4, 8, 4], 
      state: 12
    }, 
    {
      pos: [5, 8, 4], 
      state: 12
    }, 
    {
      pos: [6, 8, 4], 
      state: 12
    }, 
    {
      pos: [7, 8, 4], 
      state: 10
    }, 
    {
      pos: [8, 8, 4], 
      state: 10
    }, 
    {
      pos: [9, 8, 4], 
      state: 10
    }, 
    {
      pos: [10, 8, 4], 
      state: 10
    }, 
    {
      pos: [6, 1, 5], 
      state: 16
    }, 
    {
      pos: [7, 1, 5], 
      state: 17
    }, 
    {
      pos: [8, 1, 5], 
      state: 11
    }, 
    {
      pos: [9, 1, 5], 
      state: 11
    }, 
    {
      pos: [0, 2, 5], 
      state: 18
    }, 
    {
      pos: [6, 2, 5], 
      state: 19
    }, 
    {
      pos: [7, 2, 5], 
      state: 20
    }, 
    {
      pos: [8, 2, 5], 
      state: 10
    }, 
    {
      pos: [9, 2, 5], 
      state: 10
    }, 
    {
      pos: [10, 2, 5], 
      state: 10
    }, 
    {
      pos: [0, 3, 5], 
      state: 10
    }, 
    {
      pos: [1, 3, 5], 
      state: 21
    }, 
    {
      pos: [2, 3, 5], 
      state: 22
    }, 
    {
      pos: [3, 3, 5], 
      state: 22
    }, 
    {
      pos: [4, 3, 5], 
      state: 22
    }, 
    {
      pos: [5, 3, 5], 
      state: 23
    }, 
    {
      pos: [6, 3, 5], 
      state: 10
    }, 
    {
      pos: [7, 3, 5], 
      state: 10
    }, 
    {
      pos: [8, 3, 5], 
      state: 10
    }, 
    {
      pos: [9, 3, 5], 
      state: 10
    }, 
    {
      pos: [10, 3, 5], 
      state: 10
    }, 
    {
      pos: [0, 4, 5], 
      state: 10
    }, 
    {
      pos: [1, 4, 5], 
      state: 24
    }, 
    {
      pos: [2, 4, 5], 
      state: 10
    }, 
    {
      pos: [3, 4, 5], 
      state: 10
    }, 
    {
      pos: [4, 4, 5], 
      state: 10
    }, 
    {
      pos: [5, 4, 5], 
      state: 25
    }, 
    {
      pos: [6, 4, 5], 
      state: 10
    }, 
    {
      pos: [7, 4, 5], 
      state: 10
    }, 
    {
      pos: [8, 4, 5], 
      state: 10
    }, 
    {
      pos: [9, 4, 5], 
      state: 10
    }, 
    {
      pos: [10, 4, 5], 
      state: 10
    }, 
    {
      pos: [0, 5, 5], 
      state: 26
    }, 
    {
      pos: [2, 5, 5], 
      state: 10
    }, 
    {
      pos: [3, 5, 5], 
      state: 10
    }, 
    {
      pos: [4, 5, 5], 
      state: 10
    }, 
    {
      pos: [6, 5, 5], 
      state: 27
    }, 
    {
      pos: [7, 5, 5], 
      state: 10
    }, 
    {
      pos: [8, 5, 5], 
      state: 10
    }, 
    {
      pos: [9, 5, 5], 
      state: 10
    }, 
    {
      pos: [10, 5, 5], 
      state: 10
    }, 
    {
      pos: [0, 6, 5], 
      state: 10
    }, 
    {
      pos: [2, 6, 5], 
      state: 10
    }, 
    {
      pos: [3, 6, 5], 
      state: 10
    }, 
    {
      pos: [4, 6, 5], 
      state: 10
    }, 
    {
      pos: [6, 6, 5], 
      state: 10
    }, 
    {
      pos: [7, 6, 5], 
      state: 10
    }, 
    {
      pos: [8, 6, 5], 
      state: 10
    }, 
    {
      pos: [9, 6, 5], 
      state: 10
    }, 
    {
      pos: [10, 6, 5], 
      state: 10
    }, 
    {
      pos: [0, 7, 5], 
      state: 10
    }, 
    {
      pos: [2, 7, 5], 
      state: 10
    }, 
    {
      pos: [3, 7, 5], 
      state: 10
    }, 
    {
      pos: [4, 7, 5], 
      state: 10
    }, 
    {
      pos: [6, 7, 5], 
      state: 10
    }, 
    {
      pos: [7, 7, 5], 
      state: 10
    }, 
    {
      pos: [8, 7, 5], 
      state: 10
    }, 
    {
      pos: [9, 7, 5], 
      state: 10
    }, 
    {
      pos: [10, 7, 5], 
      state: 10
    }, 
    {
      pos: [7, 8, 5], 
      state: 10
    }, 
    {
      pos: [8, 8, 5], 
      state: 10
    }, 
    {
      pos: [9, 8, 5], 
      state: 10
    }, 
    {
      pos: [10, 8, 5], 
      state: 10
    }, 
    {
      pos: [6, 1, 6], 
      state: 11
    }, 
    {
      pos: [7, 1, 6], 
      state: 11
    }, 
    {
      pos: [8, 1, 6], 
      state: 11
    }, 
    {
      pos: [9, 1, 6], 
      state: 11
    }, 
    {
      pos: [0, 2, 6], 
      state: 28
    }, 
    {
      pos: [6, 2, 6], 
      state: 10
    }, 
    {
      pos: [7, 2, 6], 
      state: 10
    }, 
    {
      pos: [8, 2, 6], 
      state: 10
    }, 
    {
      pos: [9, 2, 6], 
      state: 10
    }, 
    {
      pos: [10, 2, 6], 
      state: 10
    }, 
    {
      pos: [0, 3, 6], 
      state: 10
    }, 
    {
      pos: [2, 3, 6], 
      state: 10
    }, 
    {
      pos: [3, 3, 6], 
      state: 10
    }, 
    {
      pos: [6, 3, 6], 
      state: 10
    }, 
    {
      pos: [7, 3, 6], 
      state: 10
    }, 
    {
      pos: [8, 3, 6], 
      state: 10
    }, 
    {
      pos: [9, 3, 6], 
      state: 10
    }, 
    {
      pos: [10, 3, 6], 
      state: 10
    }, 
    {
      pos: [0, 4, 6], 
      state: 10
    }, 
    {
      pos: [2, 4, 6], 
      state: 10
    }, 
    {
      pos: [3, 4, 6], 
      state: 10
    }, 
    {
      pos: [4, 4, 6], 
      state: 10
    }, 
    {
      pos: [6, 4, 6], 
      state: 10
    }, 
    {
      pos: [7, 4, 6], 
      state: 10
    }, 
    {
      pos: [8, 4, 6], 
      state: 10
    }, 
    {
      pos: [9, 4, 6], 
      state: 10
    }, 
    {
      pos: [10, 4, 6], 
      state: 10
    }, 
    {
      pos: [0, 5, 6], 
      state: 10
    }, 
    {
      pos: [2, 5, 6], 
      state: 10
    }, 
    {
      pos: [3, 5, 6], 
      state: 10
    }, 
    {
      pos: [4, 5, 6], 
      state: 10
    }, 
    {
      pos: [6, 5, 6], 
      state: 10
    }, 
    {
      pos: [7, 5, 6], 
      state: 10
    }, 
    {
      pos: [8, 5, 6], 
      state: 10
    }, 
    {
      pos: [9, 5, 6], 
      state: 10
    }, 
    {
      pos: [10, 5, 6], 
      state: 10
    }, 
    {
      pos: [0, 6, 6], 
      state: 10
    }, 
    {
      pos: [2, 6, 6], 
      state: 10
    }, 
    {
      pos: [3, 6, 6], 
      state: 10
    }, 
    {
      pos: [4, 6, 6], 
      state: 10
    }, 
    {
      pos: [6, 6, 6], 
      state: 10
    }, 
    {
      pos: [7, 6, 6], 
      state: 10
    }, 
    {
      pos: [8, 6, 6], 
      state: 10
    }, 
    {
      pos: [9, 6, 6], 
      state: 10
    }, 
    {
      pos: [10, 6, 6], 
      state: 10
    }, 
    {
      pos: [0, 7, 6], 
      state: 29
    }, 
    {
      pos: [2, 7, 6], 
      state: 10
    }, 
    {
      pos: [3, 7, 6], 
      state: 10
    }, 
    {
      pos: [4, 7, 6], 
      state: 10
    }, 
    {
      pos: [6, 7, 6], 
      state: 29
    }, 
    {
      pos: [7, 7, 6], 
      state: 10
    }, 
    {
      pos: [8, 7, 6], 
      state: 10
    }, 
    {
      pos: [9, 7, 6], 
      state: 10
    }, 
    {
      pos: [10, 7, 6], 
      state: 10
    }, 
    {
      pos: [0, 8, 6], 
      state: 30
    }, 
    {
      pos: [1, 8, 6], 
      state: 30
    }, 
    {
      pos: [2, 8, 6], 
      state: 30
    }, 
    {
      pos: [3, 8, 6], 
      state: 30
    }, 
    {
      pos: [4, 8, 6], 
      state: 30
    }, 
    {
      pos: [5, 8, 6], 
      state: 30
    }, 
    {
      pos: [6, 8, 6], 
      state: 30
    }, 
    {
      pos: [7, 8, 6], 
      state: 10
    }, 
    {
      pos: [8, 8, 6], 
      state: 10
    }, 
    {
      pos: [9, 8, 6], 
      state: 10
    }, 
    {
      pos: [10, 8, 6], 
      state: 10
    }, 
    {
      pos: [6, 1, 7], 
      state: 11
    }, 
    {
      pos: [7, 1, 7], 
      state: 11
    }, 
    {
      pos: [8, 1, 7], 
      state: 11
    }, 
    {
      pos: [6, 2, 7], 
      state: 10
    }, 
    {
      pos: [7, 2, 7], 
      state: 10
    }, 
    {
      pos: [8, 2, 7], 
      state: 10
    }, 
    {
      pos: [10, 2, 7], 
      state: 10
    }, 
    {
      pos: [0, 3, 7], 
      state: 10
    }, 
    {
      pos: [6, 3, 7], 
      state: 10
    }, 
    {
      pos: [7, 3, 7], 
      state: 10
    }, 
    {
      pos: [8, 3, 7], 
      state: 10
    }, 
    {
      pos: [9, 3, 7], 
      state: 10
    }, 
    {
      pos: [10, 3, 7], 
      state: 10
    }, 
    {
      pos: [0, 4, 7], 
      state: 10
    }, 
    {
      pos: [3, 4, 7], 
      state: 13
    }, 
    {
      pos: [6, 4, 7], 
      state: 10
    }, 
    {
      pos: [7, 4, 7], 
      state: 10
    }, 
    {
      pos: [8, 4, 7], 
      state: 10
    }, 
    {
      pos: [9, 4, 7], 
      state: 10
    }, 
    {
      pos: [10, 4, 7], 
      state: 10
    }, 
    {
      pos: [0, 5, 7], 
      state: 10
    }, 
    {
      pos: [6, 5, 7], 
      state: 10
    }, 
    {
      pos: [7, 5, 7], 
      state: 10
    }, 
    {
      pos: [8, 5, 7], 
      state: 10
    }, 
    {
      pos: [9, 5, 7], 
      state: 10
    }, 
    {
      pos: [10, 5, 7], 
      state: 10
    }, 
    {
      pos: [0, 6, 7], 
      state: 29
    }, 
    {
      pos: [6, 6, 7], 
      state: 29
    }, 
    {
      pos: [7, 6, 7], 
      state: 10
    }, 
    {
      pos: [8, 6, 7], 
      state: 10
    }, 
    {
      pos: [9, 6, 7], 
      state: 10
    }, 
    {
      pos: [10, 6, 7], 
      state: 10
    }, 
    {
      pos: [0, 7, 7], 
      state: 30
    }, 
    {
      pos: [1, 7, 7], 
      state: 30
    }, 
    {
      pos: [2, 7, 7], 
      state: 30
    }, 
    {
      pos: [3, 7, 7], 
      state: 30
    }, 
    {
      pos: [4, 7, 7], 
      state: 30
    }, 
    {
      pos: [5, 7, 7], 
      state: 30
    }, 
    {
      pos: [6, 7, 7], 
      state: 30
    }, 
    {
      pos: [7, 7, 7], 
      state: 10
    }, 
    {
      pos: [8, 7, 7], 
      state: 10
    }, 
    {
      pos: [9, 7, 7], 
      state: 10
    }, 
    {
      pos: [10, 7, 7], 
      state: 10
    }, 
    {
      pos: [0, 8, 7], 
      state: 10
    }, 
    {
      pos: [1, 8, 7], 
      state: 10
    }, 
    {
      pos: [2, 8, 7], 
      state: 10
    }, 
    {
      pos: [3, 8, 7], 
      state: 10
    }, 
    {
      pos: [4, 8, 7], 
      state: 10
    }, 
    {
      pos: [5, 8, 7], 
      state: 10
    }, 
    {
      pos: [6, 8, 7], 
      state: 10
    }, 
    {
      pos: [7, 8, 7], 
      state: 10
    }, 
    {
      pos: [8, 8, 7], 
      state: 10
    }, 
    {
      pos: [9, 8, 7], 
      state: 10
    }, 
    {
      pos: [10, 8, 7], 
      state: 10
    }, 
    {
      pos: [4, 1, 8], 
      state: 11
    }, 
    {
      pos: [5, 1, 8], 
      state: 11
    }, 
    {
      pos: [6, 1, 8], 
      state: 11
    }, 
    {
      pos: [7, 1, 8], 
      state: 11
    }, 
    {
      pos: [0, 2, 8], 
      state: 10
    }, 
    {
      pos: [1, 2, 8], 
      state: 10
    }, 
    {
      pos: [2, 2, 8], 
      state: 10
    }, 
    {
      pos: [3, 2, 8], 
      state: 10
    }, 
    {
      pos: [4, 2, 8], 
      state: 10
    }, 
    {
      pos: [5, 2, 8], 
      state: 10
    }, 
    {
      pos: [6, 2, 8], 
      state: 10
    }, 
    {
      pos: [7, 2, 8], 
      state: 10
    }, 
    {
      pos: [8, 2, 8], 
      state: 10
    }, 
    {
      pos: [9, 2, 8], 
      state: 10
    }, 
    {
      pos: [10, 2, 8], 
      state: 10
    }, 
    {
      pos: [0, 3, 8], 
      state: 10
    }, 
    {
      pos: [1, 3, 8], 
      state: 10
    }, 
    {
      pos: [2, 3, 8], 
      state: 10
    }, 
    {
      pos: [3, 3, 8], 
      state: 10
    }, 
    {
      pos: [4, 3, 8], 
      state: 10
    }, 
    {
      pos: [5, 3, 8], 
      state: 10
    }, 
    {
      pos: [6, 3, 8], 
      state: 10
    }, 
    {
      pos: [7, 3, 8], 
      state: 10
    }, 
    {
      pos: [8, 3, 8], 
      state: 10
    }, 
    {
      pos: [9, 3, 8], 
      state: 10
    }, 
    {
      pos: [10, 3, 8], 
      state: 10
    }, 
    {
      pos: [0, 4, 8], 
      state: 10
    }, 
    {
      pos: [1, 4, 8], 
      state: 10
    }, 
    {
      pos: [2, 4, 8], 
      state: 10
    }, 
    {
      pos: [3, 4, 8], 
      state: 10
    }, 
    {
      pos: [4, 4, 8], 
      state: 10
    }, 
    {
      pos: [5, 4, 8], 
      state: 10
    }, 
    {
      pos: [6, 4, 8], 
      state: 10
    }, 
    {
      pos: [7, 4, 8], 
      state: 10
    }, 
    {
      pos: [8, 4, 8], 
      state: 10
    }, 
    {
      pos: [9, 4, 8], 
      state: 10
    }, 
    {
      pos: [10, 4, 8], 
      state: 10
    }, 
    {
      pos: [0, 5, 8], 
      state: 10
    }, 
    {
      pos: [1, 5, 8], 
      state: 10
    }, 
    {
      pos: [2, 5, 8], 
      state: 10
    }, 
    {
      pos: [3, 5, 8], 
      state: 10
    }, 
    {
      pos: [4, 5, 8], 
      state: 10
    }, 
    {
      pos: [5, 5, 8], 
      state: 10
    }, 
    {
      pos: [6, 5, 8], 
      state: 10
    }, 
    {
      pos: [7, 5, 8], 
      state: 10
    }, 
    {
      pos: [8, 5, 8], 
      state: 10
    }, 
    {
      pos: [9, 5, 8], 
      state: 10
    }, 
    {
      pos: [10, 5, 8], 
      state: 10
    }, 
    {
      pos: [0, 6, 8], 
      state: 30
    }, 
    {
      pos: [1, 6, 8], 
      state: 30
    }, 
    {
      pos: [2, 6, 8], 
      state: 30
    }, 
    {
      pos: [3, 6, 8], 
      state: 30
    }, 
    {
      pos: [4, 6, 8], 
      state: 30
    }, 
    {
      pos: [5, 6, 8], 
      state: 30
    }, 
    {
      pos: [6, 6, 8], 
      state: 30
    }, 
    {
      pos: [7, 6, 8], 
      state: 10
    }, 
    {
      pos: [8, 6, 8], 
      state: 10
    }, 
    {
      pos: [9, 6, 8], 
      state: 10
    }, 
    {
      pos: [10, 6, 8], 
      state: 10
    }, 
    {
      pos: [0, 7, 8], 
      state: 10
    }, 
    {
      pos: [1, 7, 8], 
      state: 10
    }, 
    {
      pos: [2, 7, 8], 
      state: 10
    }, 
    {
      pos: [3, 7, 8], 
      state: 10
    }, 
    {
      pos: [4, 7, 8], 
      state: 10
    }, 
    {
      pos: [5, 7, 8], 
      state: 10
    }, 
    {
      pos: [6, 7, 8], 
      state: 10
    }, 
    {
      pos: [7, 7, 8], 
      state: 10
    }, 
    {
      pos: [8, 7, 8], 
      state: 10
    }, 
    {
      pos: [9, 7, 8], 
      state: 10
    }, 
    {
      pos: [10, 7, 8], 
      state: 10
    }, 
    {
      pos: [0, 8, 8], 
      state: 10
    }, 
    {
      pos: [1, 8, 8], 
      state: 10
    }, 
    {
      pos: [2, 8, 8], 
      state: 10
    }, 
    {
      pos: [3, 8, 8], 
      state: 10
    }, 
    {
      pos: [4, 8, 8], 
      state: 10
    }, 
    {
      pos: [5, 8, 8], 
      state: 10
    }, 
    {
      pos: [6, 8, 8], 
      state: 10
    }, 
    {
      pos: [7, 8, 8], 
      state: 10
    }, 
    {
      pos: [8, 8, 8], 
      state: 10
    }, 
    {
      pos: [9, 8, 8], 
      state: 10
    }, 
    {
      pos: [10, 8, 8], 
      state: 10
    }, 
    {
      pos: [0, 2, 9], 
      state: 10
    }, 
    {
      pos: [1, 2, 9], 
      state: 10
    }, 
    {
      pos: [2, 2, 9], 
      state: 10
    }, 
    {
      pos: [3, 2, 9], 
      state: 10
    }, 
    {
      pos: [4, 2, 9], 
      state: 10
    }, 
    {
      pos: [5, 2, 9], 
      state: 10
    }, 
    {
      pos: [6, 2, 9], 
      state: 10
    }, 
    {
      pos: [7, 2, 9], 
      state: 10
    }, 
    {
      pos: [8, 2, 9], 
      state: 10
    }, 
    {
      pos: [9, 2, 9], 
      state: 10
    }, 
    {
      pos: [10, 2, 9], 
      state: 10
    }, 
    {
      pos: [0, 3, 9], 
      state: 10
    }, 
    {
      pos: [1, 3, 9], 
      state: 10
    }, 
    {
      pos: [2, 3, 9], 
      state: 10
    }, 
    {
      pos: [3, 3, 9], 
      state: 10
    }, 
    {
      pos: [4, 3, 9], 
      state: 10
    }, 
    {
      pos: [5, 3, 9], 
      state: 10
    }, 
    {
      pos: [6, 3, 9], 
      state: 10
    }, 
    {
      pos: [7, 3, 9], 
      state: 10
    }, 
    {
      pos: [8, 3, 9], 
      state: 10
    }, 
    {
      pos: [9, 3, 9], 
      state: 10
    }, 
    {
      pos: [10, 3, 9], 
      state: 10
    }, 
    {
      pos: [0, 4, 9], 
      state: 10
    }, 
    {
      pos: [1, 4, 9], 
      state: 10
    }, 
    {
      pos: [2, 4, 9], 
      state: 10
    }, 
    {
      pos: [3, 4, 9], 
      state: 10
    }, 
    {
      pos: [4, 4, 9], 
      state: 10
    }, 
    {
      pos: [5, 4, 9], 
      state: 10
    }, 
    {
      pos: [6, 4, 9], 
      state: 10
    }, 
    {
      pos: [7, 4, 9], 
      state: 10
    }, 
    {
      pos: [8, 4, 9], 
      state: 10
    }, 
    {
      pos: [9, 4, 9], 
      state: 10
    }, 
    {
      pos: [10, 4, 9], 
      state: 10
    }, 
    {
      pos: [0, 5, 9], 
      state: 10
    }, 
    {
      pos: [1, 5, 9], 
      state: 10
    }, 
    {
      pos: [2, 5, 9], 
      state: 10
    }, 
    {
      pos: [3, 5, 9], 
      state: 10
    }, 
    {
      pos: [4, 5, 9], 
      state: 10
    }, 
    {
      pos: [5, 5, 9], 
      state: 10
    }, 
    {
      pos: [6, 5, 9], 
      state: 10
    }, 
    {
      pos: [7, 5, 9], 
      state: 10
    }, 
    {
      pos: [8, 5, 9], 
      state: 10
    }, 
    {
      pos: [9, 5, 9], 
      state: 10
    }, 
    {
      pos: [10, 5, 9], 
      state: 10
    }, 
    {
      pos: [0, 6, 9], 
      state: 10
    }, 
    {
      pos: [1, 6, 9], 
      state: 10
    }, 
    {
      pos: [2, 6, 9], 
      state: 10
    }, 
    {
      pos: [3, 6, 9], 
      state: 10
    }, 
    {
      pos: [4, 6, 9], 
      state: 10
    }, 
    {
      pos: [5, 6, 9], 
      state: 10
    }, 
    {
      pos: [6, 6, 9], 
      state: 10
    }, 
    {
      pos: [7, 6, 9], 
      state: 10
    }, 
    {
      pos: [8, 6, 9], 
      state: 10
    }, 
    {
      pos: [9, 6, 9], 
      state: 10
    }, 
    {
      pos: [10, 6, 9], 
      state: 10
    }, 
    {
      pos: [0, 7, 9], 
      state: 10
    }, 
    {
      pos: [1, 7, 9], 
      state: 10
    }, 
    {
      pos: [2, 7, 9], 
      state: 10
    }, 
    {
      pos: [3, 7, 9], 
      state: 10
    }, 
    {
      pos: [4, 7, 9], 
      state: 10
    }, 
    {
      pos: [5, 7, 9], 
      state: 10
    }, 
    {
      pos: [6, 7, 9], 
      state: 10
    }, 
    {
      pos: [7, 7, 9], 
      state: 10
    }, 
    {
      pos: [8, 7, 9], 
      state: 10
    }, 
    {
      pos: [9, 7, 9], 
      state: 10
    }, 
    {
      pos: [10, 7, 9], 
      state: 10
    }, 
    {
      pos: [0, 8, 9], 
      state: 10
    }, 
    {
      pos: [1, 8, 9], 
      state: 10
    }, 
    {
      pos: [2, 8, 9], 
      state: 10
    }, 
    {
      pos: [3, 8, 9], 
      state: 10
    }, 
    {
      pos: [4, 8, 9], 
      state: 10
    }, 
    {
      pos: [5, 8, 9], 
      state: 10
    }, 
    {
      pos: [6, 8, 9], 
      state: 10
    }, 
    {
      pos: [7, 8, 9], 
      state: 10
    }, 
    {
      pos: [8, 8, 9], 
      state: 10
    }, 
    {
      pos: [9, 8, 9], 
      state: 10
    }, 
    {
      pos: [10, 8, 9], 
      state: 10
    }
  ], 
  palette: [
    {
      Name: "minecraft:dirt"
    }, 
    {
      Properties: {
        snowy: "false"
      }, 
      Name: "minecraft:grass_block"
    }, 
    {
      Properties: {
        axis: "y"
      }, 
      Name: "minecraft:oak_log"
    }, 
    {
      Name: "minecraft:cobblestone"
    }, 
    {
      Properties: {
        axis: "x"
      }, 
      Name: "minecraft:oak_log"
    }, 
    {
      Properties: {
        axis: "z"
      }, 
      Name: "minecraft:oak_log"
    }, 
    {
      Name: "minecraft:oak_planks"
    }, 
    {
      Properties: {
        facing: "up"
      }, 
      Name: "minecraft:barrel"
    }, 
    {
      Properties: {
        waterlogged: "false", 
        facing: "west", 
        type: "single"
      }, 
      Name: "minecraft:chest"
    }, 
    {
      Properties: {
        facing: "west"
      }, 
      Name: "minecraft:jigsaw"
    }, 
    {
      Name: "minecraft:air"
    }, 
    {
      Properties: {
        level: "0"
      }, 
      Name: "minecraft:water"
    }, 
    {
      Properties: {
        half: "bottom", 
        waterlogged: "false", 
        shape: "straight", 
        facing: "south"
      }, 
      Name: "minecraft:oak_stairs"
    }, 
    {
      Properties: {
        east: "true", 
        waterlogged: "false", 
        south: "false", 
        north: "false", 
        west: "true"
      }, 
      Name: "minecraft:glass_pane"
    }, 
    {
      Properties: {
        half: "top", 
        waterlogged: "false", 
        shape: "straight", 
        facing: "north"
      }, 
      Name: "minecraft:oak_stairs"
    }, 
    {
      Properties: {
        half: "bottom", 
        waterlogged: "false", 
        shape: "outer_left", 
        facing: "south"
      }, 
      Name: "minecraft:cobblestone_stairs"
    }, 
    {
      Properties: {
        east: "true", 
        waterlogged: "true", 
        south: "false", 
        north: "false", 
        west: "true"
      }, 
      Name: "minecraft:oak_fence"
    }, 
    {
      Properties: {
        east: "false", 
        waterlogged: "true", 
        south: "false", 
        north: "false", 
        west: "true"
      }, 
      Name: "minecraft:oak_fence"
    }, 
    {
      Properties: {
        half: "bottom", 
        waterlogged: "false", 
        shape: "straight", 
        facing: "east"
      }, 
      Name: "minecraft:cobblestone_stairs"
    }, 
    {
      Properties: {
        half: "bottom", 
        waterlogged: "false", 
        shape: "straight", 
        facing: "west"
      }, 
      Name: "minecraft:oak_stairs"
    }, 
    {
      Properties: {
        waterlogged: "false", 
        type: "bottom"
      }, 
      Name: "minecraft:oak_slab"
    }, 
    {
      Properties: {
        hinge: "left", 
        half: "lower", 
        powered: "false", 
        facing: "east", 
        open: "false"
      }, 
      Name: "minecraft:oak_door"
    }, 
    {
      Properties: {
        half: "bottom", 
        waterlogged: "false", 
        powered: "false", 
        facing: "south", 
        open: "true"
      }, 
      Name: "minecraft:oak_trapdoor"
    }, 
    {
      Properties: {
        hinge: "right", 
        half: "lower", 
        powered: "false", 
        facing: "west", 
        open: "false"
      }, 
      Name: "minecraft:oak_door"
    }, 
    {
      Properties: {
        hinge: "left", 
        half: "upper", 
        powered: "false", 
        facing: "east", 
        open: "false"
      }, 
      Name: "minecraft:oak_door"
    }, 
    {
      Properties: {
        hinge: "right", 
        half: "upper", 
        powered: "false", 
        facing: "west", 
        open: "false"
      }, 
      Name: "minecraft:oak_door"
    }, 
    {
      Properties: {
        facing: "west"
      }, 
      Name: "minecraft:wall_torch"
    }, 
    {
      Properties: {
        facing: "east"
      }, 
      Name: "minecraft:wall_torch"
    }, 
    {
      Properties: {
        half: "bottom", 
        waterlogged: "false", 
        shape: "outer_right", 
        facing: "north"
      }, 
      Name: "minecraft:cobblestone_stairs"
    }, 
    {
      Properties: {
        half: "top", 
        waterlogged: "false", 
        shape: "straight", 
        facing: "south"
      }, 
      Name: "minecraft:oak_stairs"
    }, 
    {
      Properties: {
        half: "bottom", 
        waterlogged: "false", 
        shape: "straight", 
        facing: "north"
      }, 
      Name: "minecraft:oak_stairs"
    }
  ]
}
