{
  size: [12, 7, 8], 
  entities: [], 
  blocks: [
    {
      pos: [0, 0, 0], 
      state: 0
    }, 
    {
      pos: [1, 0, 0], 
      state: 0
    }, 
    {
      pos: [2, 0, 0], 
      state: 0
    }, 
    {
      pos: [8, 0, 0], 
      state: 0
    }, 
    {
      pos: [9, 0, 0], 
      state: 0
    }, 
    {
      pos: [0, 0, 1], 
      state: 0
    }, 
    {
      pos: [1, 0, 1], 
      state: 0
    }, 
    {
      pos: [4, 0, 1], 
      state: 0
    }, 
    {
      pos: [5, 0, 1], 
      state: 0
    }, 
    {
      pos: [6, 0, 1], 
      state: 0
    }, 
    {
      pos: [8, 0, 1], 
      state: 0
    }, 
    {
      pos: [9, 0, 1], 
      state: 0
    }, 
    {
      pos: [0, 0, 2], 
      state: 0
    }, 
    {
      pos: [1, 0, 2], 
      state: 0
    }, 
    {
      pos: [2, 0, 2], 
      state: 0
    }, 
    {
      pos: [5, 0, 2], 
      state: 0
    }, 
    {
      pos: [6, 0, 2], 
      state: 0
    }, 
    {
      pos: [7, 0, 2], 
      state: 0
    }, 
    {
      pos: [8, 0, 2], 
      state: 0
    }, 
    {
      pos: [9, 0, 2], 
      state: 1
    }, 
    {
      pos: [0, 0, 3], 
      state: 0
    }, 
    {
      pos: [1, 0, 3], 
      state: 0
    }, 
    {
      pos: [2, 0, 3], 
      state: 0
    }, 
    {
      pos: [4, 0, 3], 
      state: 0
    }, 
    {
      pos: [5, 0, 3], 
      state: 0
    }, 
    {
      pos: [6, 0, 3], 
      state: 0
    }, 
    {
      pos: [7, 0, 3], 
      state: 0
    }, 
    {
      pos: [8, 0, 3], 
      state: 0
    }, 
    {
      pos: [9, 0, 3], 
      state: 0
    }, 
    {
      pos: [0, 0, 4], 
      state: 0
    }, 
    {
      pos: [1, 0, 4], 
      state: 0
    }, 
    {
      pos: [2, 0, 4], 
      state: 0
    }, 
    {
      pos: [3, 0, 4], 
      state: 0
    }, 
    {
      pos: [4, 0, 4], 
      state: 0
    }, 
    {
      pos: [5, 0, 4], 
      state: 0
    }, 
    {
      pos: [6, 0, 4], 
      state: 0
    }, 
    {
      pos: [7, 0, 4], 
      state: 0
    }, 
    {
      pos: [8, 0, 4], 
      state: 0
    }, 
    {
      pos: [9, 0, 4], 
      state: 0
    }, 
    {
      pos: [10, 0, 4], 
      state: 0
    }, 
    {
      pos: [11, 0, 4], 
      state: 0
    }, 
    {
      pos: [0, 0, 5], 
      state: 0
    }, 
    {
      pos: [1, 0, 5], 
      state: 0
    }, 
    {
      pos: [2, 0, 5], 
      state: 0
    }, 
    {
      pos: [3, 0, 5], 
      state: 0
    }, 
    {
      pos: [4, 0, 5], 
      state: 0
    }, 
    {
      pos: [5, 0, 5], 
      state: 0
    }, 
    {
      pos: [6, 0, 5], 
      state: 0
    }, 
    {
      pos: [9, 0, 5], 
      state: 0
    }, 
    {
      pos: [10, 0, 5], 
      state: 0
    }, 
    {
      pos: [11, 0, 5], 
      state: 0
    }, 
    {
      pos: [0, 0, 6], 
      state: 0
    }, 
    {
      pos: [1, 0, 6], 
      state: 0
    }, 
    {
      pos: [2, 0, 6], 
      state: 0
    }, 
    {
      pos: [3, 0, 6], 
      state: 0
    }, 
    {
      pos: [4, 0, 6], 
      state: 0
    }, 
    {
      pos: [5, 0, 6], 
      state: 0
    }, 
    {
      pos: [7, 0, 6], 
      state: 0
    }, 
    {
      pos: [8, 0, 6], 
      state: 0
    }, 
    {
      pos: [9, 0, 6], 
      state: 0
    }, 
    {
      pos: [10, 0, 6], 
      state: 0
    }, 
    {
      pos: [11, 0, 6], 
      state: 0
    }, 
    {
      pos: [0, 0, 7], 
      state: 0
    }, 
    {
      pos: [1, 0, 7], 
      state: 0
    }, 
    {
      pos: [2, 0, 7], 
      state: 0
    }, 
    {
      pos: [3, 0, 7], 
      state: 0
    }, 
    {
      pos: [4, 0, 7], 
      state: 0
    }, 
    {
      pos: [5, 0, 7], 
      state: 0
    }, 
    {
      pos: [6, 0, 7], 
      state: 0
    }, 
    {
      pos: [7, 0, 7], 
      state: 0
    }, 
    {
      pos: [8, 0, 7], 
      state: 0
    }, 
    {
      pos: [9, 0, 7], 
      state: 0
    }, 
    {
      pos: [10, 0, 7], 
      state: 0
    }, 
    {
      pos: [11, 0, 7], 
      state: 0
    }, 
    {
      pos: [3, 0, 0], 
      state: 2
    }, 
    {
      pos: [4, 0, 0], 
      state: 2
    }, 
    {
      pos: [5, 0, 0], 
      state: 2
    }, 
    {
      pos: [6, 0, 0], 
      state: 2
    }, 
    {
      pos: [7, 0, 0], 
      state: 2
    }, 
    {
      pos: [10, 0, 0], 
      state: 2
    }, 
    {
      pos: [11, 0, 0], 
      state: 2
    }, 
    {
      pos: [2, 0, 1], 
      state: 2
    }, 
    {
      pos: [3, 0, 1], 
      state: 2
    }, 
    {
      pos: [7, 0, 1], 
      state: 2
    }, 
    {
      pos: [10, 0, 1], 
      state: 2
    }, 
    {
      pos: [11, 0, 1], 
      state: 2
    }, 
    {
      pos: [3, 0, 2], 
      state: 2
    }, 
    {
      pos: [4, 0, 2], 
      state: 2
    }, 
    {
      pos: [10, 0, 2], 
      state: 2
    }, 
    {
      pos: [11, 0, 2], 
      state: 2
    }, 
    {
      pos: [3, 0, 3], 
      state: 2
    }, 
    {
      pos: [10, 0, 3], 
      state: 2
    }, 
    {
      pos: [7, 0, 5], 
      state: 2
    }, 
    {
      pos: [8, 0, 5], 
      state: 2
    }, 
    {
      pos: [6, 0, 6], 
      state: 2
    }, 
    {
      pos: [0, 1, 0], 
      state: 0
    }, 
    {
      pos: [1, 1, 0], 
      state: 0
    }, 
    {
      pos: [2, 1, 0], 
      state: 0
    }, 
    {
      pos: [3, 1, 0], 
      state: 0
    }, 
    {
      pos: [4, 1, 0], 
      state: 0
    }, 
    {
      pos: [0, 1, 1], 
      state: 0
    }, 
    {
      pos: [1, 1, 1], 
      state: 0
    }, 
    {
      pos: [2, 1, 1], 
      state: 0
    }, 
    {
      pos: [3, 1, 1], 
      state: 0
    }, 
    {
      pos: [4, 1, 1], 
      state: 0
    }, 
    {
      pos: [5, 1, 1], 
      state: 0
    }, 
    {
      pos: [6, 1, 1], 
      state: 0
    }, 
    {
      pos: [7, 1, 1], 
      state: 1
    }, 
    {
      pos: [0, 1, 2], 
      state: 3
    }, 
    {
      pos: [1, 1, 2], 
      state: 0
    }, 
    {
      pos: [2, 1, 2], 
      state: 0
    }, 
    {
      pos: [3, 1, 2], 
      state: 0
    }, 
    {
      pos: [0, 1, 3], 
      state: 3
    }, 
    {
      pos: [1, 1, 3], 
      state: 0
    }, 
    {
      pos: [2, 1, 3], 
      state: 0
    }, 
    {
      pos: [3, 1, 3], 
      state: 0
    }, 
    {
      pos: [5, 1, 3], 
      state: 0
    }, 
    {
      pos: [6, 1, 3], 
      state: 0
    }, 
    {
      pos: [8, 1, 3], 
      state: 1
    }, 
    {
      pos: [9, 1, 3], 
      state: 0
    }, 
    {
      pos: [5, 1, 4], 
      state: 0
    }, 
    {
      pos: [6, 1, 4], 
      state: 0
    }, 
    {
      pos: [5, 1, 5], 
      state: 0
    }, 
    {
      pos: [5, 1, 6], 
      state: 0
    }, 
    {
      pos: [6, 1, 6], 
      state: 0
    }, 
    {
      pos: [0, 1, 7], 
      state: 0
    }, 
    {
      pos: [1, 1, 7], 
      state: 0
    }, 
    {
      pos: [2, 1, 7], 
      state: 0
    }, 
    {
      pos: [3, 1, 7], 
      state: 0
    }, 
    {
      pos: [4, 1, 7], 
      state: 0
    }, 
    {
      pos: [5, 1, 7], 
      state: 0
    }, 
    {
      pos: [6, 1, 7], 
      state: 0
    }, 
    {
      pos: [7, 1, 7], 
      state: 0
    }, 
    {
      pos: [9, 1, 7], 
      state: 0
    }, 
    {
      pos: [10, 1, 7], 
      state: 0
    }, 
    {
      pos: [11, 1, 7], 
      state: 0
    }, 
    {
      nbt: {
        joint: "rollable", 
        final_state: "minecraft:polished_blackstone_bricks", 
        name: "minecraft:stage_0_entry", 
        pool: "minecraft:empty", 
        id: "minecraft:jigsaw", 
        target: "minecraft:empty"
      }, 
      pos: [5, 1, 0], 
      state: 4
    }, 
    {
      nbt: {
        joint: "rollable", 
        final_state: "minecraft:polished_blackstone_bricks", 
        name: "minecraft:stage_0_entry", 
        pool: "minecraft:empty", 
        id: "minecraft:jigsaw", 
        target: "minecraft:empty"
      }, 
      pos: [6, 1, 0], 
      state: 4
    }, 
    {
      nbt: {
        joint: "rollable", 
        final_state: "minecraft:cracked_polished_blackstone_bricks", 
        name: "minecraft:stage_0_entry", 
        pool: "minecraft:empty", 
        id: "minecraft:jigsaw", 
        target: "minecraft:empty"
      }, 
      pos: [7, 1, 0], 
      state: 4
    }, 
    {
      nbt: {
        joint: "rollable", 
        final_state: "minecraft:air", 
        name: "minecraft:empty", 
        pool: "minecraft:bastion/units/fillers/stage_0", 
        id: "minecraft:jigsaw", 
        target: "minecraft:filler_0_entry"
      }, 
      pos: [0, 1, 4], 
      state: 5
    }, 
    {
      nbt: {
        joint: "rollable", 
        final_state: "minecraft:air", 
        name: "minecraft:empty", 
        pool: "minecraft:bastion/units/fillers/stage_0", 
        id: "minecraft:jigsaw", 
        target: "minecraft:filler_0_entry"
      }, 
      pos: [11, 1, 4], 
      state: 6
    }, 
    {
      nbt: {
        joint: "rollable", 
        final_state: "minecraft:cracked_polished_blackstone_bricks", 
        name: "minecraft:empty", 
        pool: "minecraft:bastion/units/edges", 
        id: "minecraft:jigsaw", 
        target: "minecraft:edge_entry"
      }, 
      pos: [8, 1, 7], 
      state: 7
    }, 
    {
      pos: [8, 1, 0], 
      state: 8
    }, 
    {
      pos: [10, 1, 0], 
      state: 2
    }, 
    {
      pos: [11, 1, 0], 
      state: 2
    }, 
    {
      pos: [8, 1, 1], 
      state: 8
    }, 
    {
      pos: [9, 1, 1], 
      state: 2
    }, 
    {
      pos: [10, 1, 1], 
      state: 2
    }, 
    {
      pos: [11, 1, 1], 
      state: 2
    }, 
    {
      pos: [4, 1, 2], 
      state: 2
    }, 
    {
      pos: [5, 1, 2], 
      state: 2
    }, 
    {
      pos: [6, 1, 2], 
      state: 2
    }, 
    {
      pos: [7, 1, 2], 
      state: 2
    }, 
    {
      pos: [8, 1, 2], 
      state: 2
    }, 
    {
      pos: [9, 1, 2], 
      state: 2
    }, 
    {
      pos: [10, 1, 2], 
      state: 2
    }, 
    {
      pos: [11, 1, 2], 
      state: 2
    }, 
    {
      pos: [4, 1, 3], 
      state: 2
    }, 
    {
      pos: [7, 1, 3], 
      state: 2
    }, 
    {
      pos: [10, 1, 3], 
      state: 2
    }, 
    {
      pos: [1, 1, 4], 
      state: 2
    }, 
    {
      pos: [2, 1, 4], 
      state: 2
    }, 
    {
      pos: [3, 1, 4], 
      state: 2
    }, 
    {
      pos: [4, 1, 4], 
      state: 2
    }, 
    {
      pos: [7, 1, 4], 
      state: 2
    }, 
    {
      pos: [8, 1, 4], 
      state: 2
    }, 
    {
      pos: [9, 1, 4], 
      state: 2
    }, 
    {
      pos: [10, 1, 4], 
      state: 2
    }, 
    {
      pos: [0, 1, 5], 
      state: 2
    }, 
    {
      pos: [1, 1, 5], 
      state: 2
    }, 
    {
      pos: [2, 1, 5], 
      state: 2
    }, 
    {
      pos: [3, 1, 5], 
      state: 2
    }, 
    {
      pos: [4, 1, 5], 
      state: 2
    }, 
    {
      pos: [6, 1, 5], 
      state: 2
    }, 
    {
      pos: [7, 1, 5], 
      state: 2
    }, 
    {
      pos: [8, 1, 5], 
      state: 2
    }, 
    {
      pos: [9, 1, 5], 
      state: 2
    }, 
    {
      pos: [10, 1, 5], 
      state: 2
    }, 
    {
      pos: [11, 1, 5], 
      state: 2
    }, 
    {
      pos: [0, 1, 6], 
      state: 2
    }, 
    {
      pos: [1, 1, 6], 
      state: 2
    }, 
    {
      pos: [2, 1, 6], 
      state: 2
    }, 
    {
      pos: [3, 1, 6], 
      state: 2
    }, 
    {
      pos: [4, 1, 6], 
      state: 2
    }, 
    {
      pos: [7, 1, 6], 
      state: 2
    }, 
    {
      pos: [8, 1, 6], 
      state: 2
    }, 
    {
      pos: [9, 1, 6], 
      state: 2
    }, 
    {
      pos: [10, 1, 6], 
      state: 2
    }, 
    {
      pos: [11, 1, 6], 
      state: 2
    }, 
    {
      pos: [0, 2, 0], 
      state: 0
    }, 
    {
      pos: [1, 2, 0], 
      state: 0
    }, 
    {
      pos: [2, 2, 0], 
      state: 0
    }, 
    {
      pos: [3, 2, 0], 
      state: 0
    }, 
    {
      pos: [4, 2, 0], 
      state: 0
    }, 
    {
      pos: [5, 2, 0], 
      state: 0
    }, 
    {
      pos: [6, 2, 0], 
      state: 0
    }, 
    {
      pos: [0, 2, 1], 
      state: 0
    }, 
    {
      pos: [1, 2, 1], 
      state: 0
    }, 
    {
      pos: [2, 2, 1], 
      state: 0
    }, 
    {
      pos: [3, 2, 1], 
      state: 0
    }, 
    {
      pos: [4, 2, 1], 
      state: 0
    }, 
    {
      pos: [5, 2, 1], 
      state: 0
    }, 
    {
      pos: [0, 2, 2], 
      state: 0
    }, 
    {
      pos: [1, 2, 2], 
      state: 0
    }, 
    {
      pos: [2, 2, 2], 
      state: 0
    }, 
    {
      pos: [3, 2, 2], 
      state: 0
    }, 
    {
      pos: [9, 2, 2], 
      state: 1
    }, 
    {
      pos: [0, 2, 3], 
      state: 3
    }, 
    {
      pos: [1, 2, 3], 
      state: 3
    }, 
    {
      pos: [2, 2, 3], 
      state: 0
    }, 
    {
      pos: [3, 2, 3], 
      state: 0
    }, 
    {
      pos: [5, 2, 3], 
      state: 0
    }, 
    {
      pos: [6, 2, 3], 
      state: 0
    }, 
    {
      pos: [9, 2, 3], 
      state: 0
    }, 
    {
      pos: [10, 2, 3], 
      state: 0
    }, 
    {
      pos: [11, 2, 3], 
      state: 0
    }, 
    {
      pos: [5, 2, 4], 
      state: 0
    }, 
    {
      pos: [5, 2, 6], 
      state: 0
    }, 
    {
      pos: [0, 2, 7], 
      state: 0
    }, 
    {
      pos: [1, 2, 7], 
      state: 0
    }, 
    {
      pos: [2, 2, 7], 
      state: 0
    }, 
    {
      pos: [3, 2, 7], 
      state: 0
    }, 
    {
      pos: [4, 2, 7], 
      state: 0
    }, 
    {
      pos: [5, 2, 7], 
      state: 0
    }, 
    {
      pos: [6, 2, 7], 
      state: 0
    }, 
    {
      pos: [8, 2, 7], 
      state: 0
    }, 
    {
      pos: [9, 2, 7], 
      state: 0
    }, 
    {
      pos: [10, 2, 7], 
      state: 0
    }, 
    {
      pos: [11, 2, 7], 
      state: 0
    }, 
    {
      pos: [7, 2, 0], 
      state: 2
    }, 
    {
      pos: [8, 2, 0], 
      state: 2
    }, 
    {
      pos: [9, 2, 0], 
      state: 2
    }, 
    {
      pos: [10, 2, 0], 
      state: 2
    }, 
    {
      pos: [11, 2, 0], 
      state: 2
    }, 
    {
      pos: [7, 2, 1], 
      state: 2
    }, 
    {
      pos: [8, 2, 1], 
      state: 2
    }, 
    {
      pos: [9, 2, 1], 
      state: 2
    }, 
    {
      pos: [10, 2, 1], 
      state: 2
    }, 
    {
      pos: [11, 2, 1], 
      state: 2
    }, 
    {
      pos: [4, 2, 2], 
      state: 2
    }, 
    {
      pos: [5, 2, 2], 
      state: 2
    }, 
    {
      pos: [6, 2, 2], 
      state: 2
    }, 
    {
      pos: [7, 2, 2], 
      state: 2
    }, 
    {
      pos: [8, 2, 2], 
      state: 2
    }, 
    {
      pos: [10, 2, 2], 
      state: 2
    }, 
    {
      pos: [4, 2, 3], 
      state: 2
    }, 
    {
      pos: [7, 2, 3], 
      state: 2
    }, 
    {
      pos: [8, 2, 3], 
      state: 2
    }, 
    {
      pos: [0, 2, 4], 
      state: 2
    }, 
    {
      pos: [1, 2, 4], 
      state: 2
    }, 
    {
      pos: [2, 2, 4], 
      state: 2
    }, 
    {
      pos: [3, 2, 4], 
      state: 2
    }, 
    {
      pos: [4, 2, 4], 
      state: 2
    }, 
    {
      pos: [6, 2, 4], 
      state: 2
    }, 
    {
      pos: [7, 2, 4], 
      state: 2
    }, 
    {
      pos: [8, 2, 4], 
      state: 2
    }, 
    {
      pos: [9, 2, 4], 
      state: 2
    }, 
    {
      pos: [10, 2, 4], 
      state: 2
    }, 
    {
      pos: [11, 2, 4], 
      state: 2
    }, 
    {
      pos: [0, 2, 5], 
      state: 2
    }, 
    {
      pos: [1, 2, 5], 
      state: 2
    }, 
    {
      pos: [2, 2, 5], 
      state: 2
    }, 
    {
      pos: [3, 2, 5], 
      state: 2
    }, 
    {
      pos: [4, 2, 5], 
      state: 2
    }, 
    {
      pos: [5, 2, 5], 
      state: 2
    }, 
    {
      pos: [6, 2, 5], 
      state: 2
    }, 
    {
      pos: [7, 2, 5], 
      state: 2
    }, 
    {
      pos: [8, 2, 5], 
      state: 2
    }, 
    {
      pos: [9, 2, 5], 
      state: 2
    }, 
    {
      pos: [10, 2, 5], 
      state: 2
    }, 
    {
      pos: [11, 2, 5], 
      state: 2
    }, 
    {
      pos: [0, 2, 6], 
      state: 2
    }, 
    {
      pos: [1, 2, 6], 
      state: 2
    }, 
    {
      pos: [2, 2, 6], 
      state: 2
    }, 
    {
      pos: [3, 2, 6], 
      state: 2
    }, 
    {
      pos: [4, 2, 6], 
      state: 2
    }, 
    {
      pos: [6, 2, 6], 
      state: 2
    }, 
    {
      pos: [7, 2, 6], 
      state: 2
    }, 
    {
      pos: [8, 2, 6], 
      state: 2
    }, 
    {
      pos: [9, 2, 6], 
      state: 2
    }, 
    {
      pos: [10, 2, 6], 
      state: 2
    }, 
    {
      pos: [11, 2, 6], 
      state: 2
    }, 
    {
      pos: [7, 2, 7], 
      state: 2
    }, 
    {
      pos: [0, 3, 0], 
      state: 3
    }, 
    {
      pos: [1, 3, 0], 
      state: 0
    }, 
    {
      pos: [2, 3, 0], 
      state: 3
    }, 
    {
      pos: [3, 3, 0], 
      state: 0
    }, 
    {
      pos: [4, 3, 0], 
      state: 0
    }, 
    {
      pos: [5, 3, 0], 
      state: 0
    }, 
    {
      pos: [0, 3, 1], 
      state: 0
    }, 
    {
      pos: [1, 3, 1], 
      state: 0
    }, 
    {
      pos: [2, 3, 1], 
      state: 0
    }, 
    {
      pos: [3, 3, 1], 
      state: 0
    }, 
    {
      pos: [5, 3, 1], 
      state: 0
    }, 
    {
      pos: [1, 3, 2], 
      state: 0
    }, 
    {
      pos: [2, 3, 2], 
      state: 0
    }, 
    {
      pos: [3, 3, 2], 
      state: 0
    }, 
    {
      pos: [4, 3, 2], 
      state: 0
    }, 
    {
      pos: [5, 3, 2], 
      state: 0
    }, 
    {
      pos: [6, 3, 2], 
      state: 0
    }, 
    {
      pos: [9, 3, 2], 
      state: 1
    }, 
    {
      pos: [10, 3, 2], 
      state: 0
    }, 
    {
      pos: [11, 3, 2], 
      state: 0
    }, 
    {
      pos: [2, 3, 3], 
      state: 3
    }, 
    {
      pos: [3, 3, 3], 
      state: 0
    }, 
    {
      pos: [4, 3, 3], 
      state: 0
    }, 
    {
      pos: [5, 3, 3], 
      state: 0
    }, 
    {
      pos: [6, 3, 3], 
      state: 0
    }, 
    {
      pos: [8, 3, 3], 
      state: 0
    }, 
    {
      pos: [11, 3, 3], 
      state: 0
    }, 
    {
      pos: [0, 3, 4], 
      state: 3
    }, 
    {
      pos: [1, 3, 4], 
      state: 0
    }, 
    {
      pos: [3, 3, 4], 
      state: 0
    }, 
    {
      pos: [4, 3, 4], 
      state: 0
    }, 
    {
      pos: [5, 3, 4], 
      state: 0
    }, 
    {
      pos: [6, 3, 4], 
      state: 0
    }, 
    {
      pos: [7, 3, 4], 
      state: 0
    }, 
    {
      pos: [11, 3, 4], 
      state: 0
    }, 
    {
      pos: [0, 3, 5], 
      state: 0
    }, 
    {
      pos: [1, 3, 5], 
      state: 0
    }, 
    {
      pos: [2, 3, 5], 
      state: 0
    }, 
    {
      pos: [3, 3, 5], 
      state: 0
    }, 
    {
      pos: [4, 3, 5], 
      state: 0
    }, 
    {
      pos: [11, 3, 5], 
      state: 0
    }, 
    {
      pos: [0, 3, 6], 
      state: 0
    }, 
    {
      pos: [1, 3, 6], 
      state: 0
    }, 
    {
      pos: [2, 3, 6], 
      state: 0
    }, 
    {
      pos: [3, 3, 6], 
      state: 0
    }, 
    {
      pos: [4, 3, 6], 
      state: 0
    }, 
    {
      pos: [8, 3, 6], 
      state: 0
    }, 
    {
      pos: [9, 3, 6], 
      state: 0
    }, 
    {
      pos: [10, 3, 6], 
      state: 0
    }, 
    {
      pos: [11, 3, 6], 
      state: 0
    }, 
    {
      pos: [0, 3, 7], 
      state: 0
    }, 
    {
      pos: [1, 3, 7], 
      state: 0
    }, 
    {
      pos: [2, 3, 7], 
      state: 0
    }, 
    {
      pos: [3, 3, 7], 
      state: 0
    }, 
    {
      pos: [6, 3, 7], 
      state: 0
    }, 
    {
      pos: [7, 3, 7], 
      state: 0
    }, 
    {
      pos: [8, 3, 7], 
      state: 0
    }, 
    {
      pos: [9, 3, 7], 
      state: 0
    }, 
    {
      pos: [10, 3, 7], 
      state: 0
    }, 
    {
      pos: [11, 3, 7], 
      state: 3
    }, 
    {
      nbt: {
        joint: "aligned", 
        final_state: "minecraft:polished_blackstone_bricks", 
        name: "minecraft:empty", 
        pool: "minecraft:bastion/mobs/piglin", 
        id: "minecraft:jigsaw", 
        target: "minecraft:mob_connector"
      }, 
      pos: [4, 3, 1], 
      state: 9
    }, 
    {
      nbt: {
        joint: "rollable", 
        final_state: "minecraft:polished_blackstone_bricks", 
        name: "minecraft:empty", 
        pool: "minecraft:bastion/mobs/piglin_melee", 
        id: "minecraft:jigsaw", 
        target: "minecraft:mob_connector"
      }, 
      pos: [2, 3, 4], 
      state: 10
    }, 
    {
      nbt: {
        joint: "aligned", 
        final_state: "minecraft:polished_blackstone_bricks", 
        name: "minecraft:empty", 
        pool: "minecraft:bastion/blocks/gold", 
        id: "minecraft:jigsaw", 
        target: "minecraft:block_connector"
      }, 
      pos: [7, 3, 6], 
      state: 9
    }, 
    {
      pos: [6, 3, 0], 
      state: 8
    }, 
    {
      pos: [7, 3, 0], 
      state: 2
    }, 
    {
      pos: [8, 3, 0], 
      state: 2
    }, 
    {
      pos: [10, 3, 0], 
      state: 2
    }, 
    {
      pos: [11, 3, 0], 
      state: 2
    }, 
    {
      pos: [6, 3, 1], 
      state: 2
    }, 
    {
      pos: [7, 3, 1], 
      state: 2
    }, 
    {
      pos: [8, 3, 1], 
      state: 2
    }, 
    {
      pos: [9, 3, 1], 
      state: 2
    }, 
    {
      pos: [10, 3, 1], 
      state: 2
    }, 
    {
      pos: [0, 3, 2], 
      state: 2
    }, 
    {
      pos: [7, 3, 2], 
      state: 2
    }, 
    {
      pos: [8, 3, 2], 
      state: 2
    }, 
    {
      pos: [0, 3, 3], 
      state: 2
    }, 
    {
      pos: [1, 3, 3], 
      state: 2
    }, 
    {
      pos: [7, 3, 3], 
      state: 2
    }, 
    {
      pos: [9, 3, 3], 
      state: 2
    }, 
    {
      pos: [10, 3, 3], 
      state: 2
    }, 
    {
      pos: [8, 3, 4], 
      state: 2
    }, 
    {
      pos: [9, 3, 4], 
      state: 2
    }, 
    {
      pos: [10, 3, 4], 
      state: 2
    }, 
    {
      pos: [5, 3, 5], 
      state: 2
    }, 
    {
      pos: [6, 3, 5], 
      state: 2
    }, 
    {
      pos: [7, 3, 5], 
      state: 2
    }, 
    {
      pos: [8, 3, 5], 
      state: 2
    }, 
    {
      pos: [9, 3, 5], 
      state: 2
    }, 
    {
      pos: [10, 3, 5], 
      state: 2
    }, 
    {
      pos: [5, 3, 6], 
      state: 2
    }, 
    {
      pos: [6, 3, 6], 
      state: 2
    }, 
    {
      pos: [4, 3, 7], 
      state: 2
    }, 
    {
      pos: [0, 4, 0], 
      state: 3
    }, 
    {
      pos: [1, 4, 0], 
      state: 3
    }, 
    {
      pos: [2, 4, 0], 
      state: 3
    }, 
    {
      pos: [0, 4, 1], 
      state: 0
    }, 
    {
      pos: [1, 4, 1], 
      state: 0
    }, 
    {
      pos: [2, 4, 1], 
      state: 0
    }, 
    {
      pos: [0, 4, 2], 
      state: 0
    }, 
    {
      pos: [1, 4, 2], 
      state: 0
    }, 
    {
      pos: [2, 4, 2], 
      state: 0
    }, 
    {
      pos: [3, 4, 2], 
      state: 0
    }, 
    {
      pos: [11, 4, 2], 
      state: 0
    }, 
    {
      pos: [5, 4, 3], 
      state: 0
    }, 
    {
      pos: [6, 4, 3], 
      state: 0
    }, 
    {
      pos: [5, 4, 4], 
      state: 0
    }, 
    {
      pos: [0, 4, 7], 
      state: 0
    }, 
    {
      pos: [1, 4, 7], 
      state: 0
    }, 
    {
      pos: [2, 4, 7], 
      state: 0
    }, 
    {
      pos: [3, 4, 7], 
      state: 0
    }, 
    {
      pos: [6, 4, 7], 
      state: 0
    }, 
    {
      pos: [7, 4, 7], 
      state: 0
    }, 
    {
      pos: [8, 4, 7], 
      state: 0
    }, 
    {
      pos: [9, 4, 7], 
      state: 3
    }, 
    {
      pos: [10, 4, 7], 
      state: 0
    }, 
    {
      pos: [11, 4, 7], 
      state: 3
    }, 
    {
      nbt: {
        LootTable: "minecraft:chests/bastion_other", 
        id: "minecraft:chest"
      }, 
      pos: [1, 4, 6], 
      state: 11
    }, 
    {
      pos: [3, 4, 0], 
      state: 8
    }, 
    {
      pos: [4, 4, 0], 
      state: 2
    }, 
    {
      pos: [5, 4, 0], 
      state: 2
    }, 
    {
      pos: [6, 4, 0], 
      state: 2
    }, 
    {
      pos: [7, 4, 0], 
      state: 2
    }, 
    {
      pos: [8, 4, 0], 
      state: 2
    }, 
    {
      pos: [9, 4, 0], 
      state: 2
    }, 
    {
      pos: [10, 4, 0], 
      state: 2
    }, 
    {
      pos: [3, 4, 1], 
      state: 8
    }, 
    {
      pos: [4, 4, 1], 
      state: 2
    }, 
    {
      pos: [5, 4, 1], 
      state: 2
    }, 
    {
      pos: [6, 4, 1], 
      state: 2
    }, 
    {
      pos: [7, 4, 1], 
      state: 2
    }, 
    {
      pos: [8, 4, 1], 
      state: 2
    }, 
    {
      pos: [9, 4, 1], 
      state: 2
    }, 
    {
      pos: [10, 4, 1], 
      state: 2
    }, 
    {
      pos: [4, 4, 2], 
      state: 2
    }, 
    {
      pos: [5, 4, 2], 
      state: 2
    }, 
    {
      pos: [6, 4, 2], 
      state: 2
    }, 
    {
      pos: [7, 4, 2], 
      state: 2
    }, 
    {
      pos: [8, 4, 2], 
      state: 2
    }, 
    {
      pos: [9, 4, 2], 
      state: 2
    }, 
    {
      pos: [10, 4, 2], 
      state: 2
    }, 
    {
      pos: [0, 4, 3], 
      state: 2
    }, 
    {
      pos: [1, 4, 3], 
      state: 2
    }, 
    {
      pos: [2, 4, 3], 
      state: 2
    }, 
    {
      pos: [3, 4, 3], 
      state: 2
    }, 
    {
      pos: [4, 4, 3], 
      state: 2
    }, 
    {
      pos: [7, 4, 3], 
      state: 2
    }, 
    {
      pos: [8, 4, 3], 
      state: 2
    }, 
    {
      pos: [9, 4, 3], 
      state: 2
    }, 
    {
      pos: [10, 4, 3], 
      state: 2
    }, 
    {
      pos: [11, 4, 3], 
      state: 2
    }, 
    {
      pos: [0, 4, 4], 
      state: 2
    }, 
    {
      pos: [1, 4, 4], 
      state: 2
    }, 
    {
      pos: [2, 4, 4], 
      state: 2
    }, 
    {
      pos: [3, 4, 4], 
      state: 2
    }, 
    {
      pos: [4, 4, 4], 
      state: 2
    }, 
    {
      pos: [6, 4, 4], 
      state: 2
    }, 
    {
      pos: [7, 4, 4], 
      state: 2
    }, 
    {
      pos: [8, 4, 4], 
      state: 2
    }, 
    {
      pos: [9, 4, 4], 
      state: 2
    }, 
    {
      pos: [10, 4, 4], 
      state: 2
    }, 
    {
      pos: [0, 4, 5], 
      state: 2
    }, 
    {
      pos: [1, 4, 5], 
      state: 2
    }, 
    {
      pos: [2, 4, 5], 
      state: 2
    }, 
    {
      pos: [3, 4, 5], 
      state: 2
    }, 
    {
      pos: [4, 4, 5], 
      state: 2
    }, 
    {
      pos: [5, 4, 5], 
      state: 2
    }, 
    {
      pos: [6, 4, 5], 
      state: 2
    }, 
    {
      pos: [7, 4, 5], 
      state: 2
    }, 
    {
      pos: [8, 4, 5], 
      state: 2
    }, 
    {
      pos: [9, 4, 5], 
      state: 2
    }, 
    {
      pos: [10, 4, 5], 
      state: 2
    }, 
    {
      pos: [11, 4, 5], 
      state: 2
    }, 
    {
      pos: [0, 4, 6], 
      state: 2
    }, 
    {
      pos: [2, 4, 6], 
      state: 2
    }, 
    {
      pos: [3, 4, 6], 
      state: 2
    }, 
    {
      pos: [4, 4, 6], 
      state: 2
    }, 
    {
      pos: [5, 4, 6], 
      state: 2
    }, 
    {
      pos: [6, 4, 6], 
      state: 2
    }, 
    {
      pos: [7, 4, 6], 
      state: 2
    }, 
    {
      pos: [8, 4, 6], 
      state: 2
    }, 
    {
      pos: [9, 4, 6], 
      state: 2
    }, 
    {
      pos: [10, 4, 6], 
      state: 2
    }, 
    {
      pos: [4, 4, 7], 
      state: 2
    }, 
    {
      pos: [5, 4, 7], 
      state: 2
    }, 
    {
      pos: [0, 5, 0], 
      state: 3
    }, 
    {
      pos: [1, 5, 0], 
      state: 3
    }, 
    {
      pos: [0, 5, 1], 
      state: 0
    }, 
    {
      pos: [1, 5, 1], 
      state: 0
    }, 
    {
      pos: [0, 5, 2], 
      state: 0
    }, 
    {
      pos: [1, 5, 2], 
      state: 0
    }, 
    {
      pos: [2, 5, 2], 
      state: 0
    }, 
    {
      pos: [3, 5, 2], 
      state: 0
    }, 
    {
      pos: [5, 5, 3], 
      state: 0
    }, 
    {
      pos: [6, 5, 3], 
      state: 0
    }, 
    {
      pos: [5, 5, 4], 
      state: 0
    }, 
    {
      pos: [6, 5, 5], 
      state: 0
    }, 
    {
      pos: [6, 5, 6], 
      state: 0
    }, 
    {
      pos: [0, 5, 7], 
      state: 0
    }, 
    {
      pos: [1, 5, 7], 
      state: 0
    }, 
    {
      pos: [6, 5, 7], 
      state: 0
    }, 
    {
      pos: [7, 5, 7], 
      state: 0
    }, 
    {
      pos: [8, 5, 7], 
      state: 3
    }, 
    {
      pos: [9, 5, 7], 
      state: 3
    }, 
    {
      pos: [10, 5, 7], 
      state: 3
    }, 
    {
      pos: [11, 5, 7], 
      state: 3
    }, 
    {
      pos: [2, 5, 0], 
      state: 2
    }, 
    {
      pos: [3, 5, 0], 
      state: 2
    }, 
    {
      pos: [4, 5, 0], 
      state: 2
    }, 
    {
      pos: [5, 5, 0], 
      state: 2
    }, 
    {
      pos: [6, 5, 0], 
      state: 2
    }, 
    {
      pos: [7, 5, 0], 
      state: 2
    }, 
    {
      pos: [8, 5, 0], 
      state: 2
    }, 
    {
      pos: [9, 5, 0], 
      state: 2
    }, 
    {
      pos: [10, 5, 0], 
      state: 2
    }, 
    {
      pos: [11, 5, 0], 
      state: 2
    }, 
    {
      pos: [2, 5, 1], 
      state: 8
    }, 
    {
      pos: [3, 5, 1], 
      state: 2
    }, 
    {
      pos: [4, 5, 1], 
      state: 2
    }, 
    {
      pos: [5, 5, 1], 
      state: 2
    }, 
    {
      pos: [6, 5, 1], 
      state: 2
    }, 
    {
      pos: [7, 5, 1], 
      state: 2
    }, 
    {
      pos: [8, 5, 1], 
      state: 2
    }, 
    {
      pos: [9, 5, 1], 
      state: 2
    }, 
    {
      pos: [10, 5, 1], 
      state: 2
    }, 
    {
      pos: [11, 5, 1], 
      state: 2
    }, 
    {
      pos: [4, 5, 2], 
      state: 2
    }, 
    {
      pos: [5, 5, 2], 
      state: 2
    }, 
    {
      pos: [6, 5, 2], 
      state: 2
    }, 
    {
      pos: [7, 5, 2], 
      state: 2
    }, 
    {
      pos: [8, 5, 2], 
      state: 2
    }, 
    {
      pos: [9, 5, 2], 
      state: 2
    }, 
    {
      pos: [10, 5, 2], 
      state: 2
    }, 
    {
      pos: [11, 5, 2], 
      state: 2
    }, 
    {
      pos: [0, 5, 3], 
      state: 2
    }, 
    {
      pos: [1, 5, 3], 
      state: 2
    }, 
    {
      pos: [2, 5, 3], 
      state: 2
    }, 
    {
      pos: [3, 5, 3], 
      state: 2
    }, 
    {
      pos: [4, 5, 3], 
      state: 2
    }, 
    {
      pos: [7, 5, 3], 
      state: 2
    }, 
    {
      pos: [8, 5, 3], 
      state: 2
    }, 
    {
      pos: [9, 5, 3], 
      state: 2
    }, 
    {
      pos: [10, 5, 3], 
      state: 2
    }, 
    {
      pos: [11, 5, 3], 
      state: 2
    }, 
    {
      pos: [0, 5, 4], 
      state: 2
    }, 
    {
      pos: [1, 5, 4], 
      state: 2
    }, 
    {
      pos: [2, 5, 4], 
      state: 2
    }, 
    {
      pos: [3, 5, 4], 
      state: 2
    }, 
    {
      pos: [4, 5, 4], 
      state: 2
    }, 
    {
      pos: [6, 5, 4], 
      state: 2
    }, 
    {
      pos: [7, 5, 4], 
      state: 2
    }, 
    {
      pos: [8, 5, 4], 
      state: 2
    }, 
    {
      pos: [9, 5, 4], 
      state: 12
    }, 
    {
      pos: [10, 5, 4], 
      state: 2
    }, 
    {
      pos: [11, 5, 4], 
      state: 2
    }, 
    {
      pos: [0, 5, 5], 
      state: 2
    }, 
    {
      pos: [1, 5, 5], 
      state: 2
    }, 
    {
      pos: [2, 5, 5], 
      state: 13
    }, 
    {
      pos: [3, 5, 5], 
      state: 2
    }, 
    {
      pos: [4, 5, 5], 
      state: 2
    }, 
    {
      pos: [5, 5, 5], 
      state: 2
    }, 
    {
      pos: [7, 5, 5], 
      state: 2
    }, 
    {
      pos: [8, 5, 5], 
      state: 2
    }, 
    {
      pos: [9, 5, 5], 
      state: 2
    }, 
    {
      pos: [10, 5, 5], 
      state: 2
    }, 
    {
      pos: [11, 5, 5], 
      state: 2
    }, 
    {
      pos: [0, 5, 6], 
      state: 2
    }, 
    {
      pos: [1, 5, 6], 
      state: 2
    }, 
    {
      pos: [2, 5, 6], 
      state: 2
    }, 
    {
      pos: [3, 5, 6], 
      state: 2
    }, 
    {
      pos: [4, 5, 6], 
      state: 2
    }, 
    {
      pos: [5, 5, 6], 
      state: 2
    }, 
    {
      pos: [7, 5, 6], 
      state: 2
    }, 
    {
      pos: [8, 5, 6], 
      state: 2
    }, 
    {
      pos: [9, 5, 6], 
      state: 2
    }, 
    {
      pos: [10, 5, 6], 
      state: 2
    }, 
    {
      pos: [4, 5, 7], 
      state: 2
    }, 
    {
      pos: [0, 6, 0], 
      state: 3
    }, 
    {
      pos: [0, 6, 1], 
      state: 0
    }, 
    {
      pos: [1, 6, 2], 
      state: 0
    }, 
    {
      pos: [2, 6, 2], 
      state: 0
    }, 
    {
      pos: [3, 6, 2], 
      state: 0
    }, 
    {
      pos: [4, 6, 2], 
      state: 0
    }, 
    {
      pos: [6, 6, 2], 
      state: 0
    }, 
    {
      pos: [3, 6, 3], 
      state: 0
    }, 
    {
      pos: [4, 6, 3], 
      state: 0
    }, 
    {
      pos: [5, 6, 3], 
      state: 0
    }, 
    {
      pos: [6, 6, 3], 
      state: 0
    }, 
    {
      pos: [9, 6, 3], 
      state: 0
    }, 
    {
      pos: [0, 6, 4], 
      state: 0
    }, 
    {
      pos: [1, 6, 4], 
      state: 0
    }, 
    {
      pos: [4, 6, 4], 
      state: 0
    }, 
    {
      pos: [5, 6, 4], 
      state: 0
    }, 
    {
      pos: [8, 6, 4], 
      state: 0
    }, 
    {
      pos: [9, 6, 4], 
      state: 0
    }, 
    {
      pos: [0, 6, 5], 
      state: 0
    }, 
    {
      pos: [1, 6, 5], 
      state: 0
    }, 
    {
      pos: [2, 6, 5], 
      state: 0
    }, 
    {
      pos: [4, 6, 5], 
      state: 0
    }, 
    {
      pos: [5, 6, 5], 
      state: 0
    }, 
    {
      pos: [6, 6, 5], 
      state: 0
    }, 
    {
      pos: [7, 6, 5], 
      state: 0
    }, 
    {
      pos: [8, 6, 5], 
      state: 0
    }, 
    {
      pos: [9, 6, 5], 
      state: 0
    }, 
    {
      pos: [10, 6, 5], 
      state: 0
    }, 
    {
      pos: [0, 6, 6], 
      state: 0
    }, 
    {
      pos: [1, 6, 6], 
      state: 0
    }, 
    {
      pos: [2, 6, 6], 
      state: 0
    }, 
    {
      pos: [3, 6, 6], 
      state: 0
    }, 
    {
      pos: [6, 6, 6], 
      state: 0
    }, 
    {
      pos: [7, 6, 6], 
      state: 0
    }, 
    {
      pos: [8, 6, 6], 
      state: 3
    }, 
    {
      pos: [9, 6, 6], 
      state: 0
    }, 
    {
      pos: [10, 6, 6], 
      state: 0
    }, 
    {
      pos: [11, 6, 6], 
      state: 0
    }, 
    {
      pos: [0, 6, 7], 
      state: 3
    }, 
    {
      pos: [1, 6, 7], 
      state: 0
    }, 
    {
      pos: [2, 6, 7], 
      state: 0
    }, 
    {
      pos: [6, 6, 7], 
      state: 0
    }, 
    {
      pos: [7, 6, 7], 
      state: 3
    }, 
    {
      pos: [9, 6, 7], 
      state: 3
    }, 
    {
      pos: [10, 6, 7], 
      state: 3
    }, 
    {
      pos: [11, 6, 7], 
      state: 3
    }, 
    {
      nbt: {
        joint: "rollable", 
        final_state: "minecraft:air", 
        name: "minecraft:stage_0_top", 
        pool: "minecraft:bastion/units/stages/stage_1", 
        id: "minecraft:jigsaw", 
        target: "minecraft:stage_1_bottom"
      }, 
      pos: [6, 6, 4], 
      state: 14
    }, 
    {
      pos: [2, 6, 0], 
      state: 2
    }, 
    {
      pos: [3, 6, 0], 
      state: 2
    }, 
    {
      pos: [4, 6, 0], 
      state: 2
    }, 
    {
      pos: [5, 6, 0], 
      state: 2
    }, 
    {
      pos: [6, 6, 0], 
      state: 2
    }, 
    {
      pos: [7, 6, 0], 
      state: 2
    }, 
    {
      pos: [8, 6, 0], 
      state: 2
    }, 
    {
      pos: [9, 6, 0], 
      state: 2
    }, 
    {
      pos: [10, 6, 0], 
      state: 2
    }, 
    {
      pos: [11, 6, 0], 
      state: 2
    }, 
    {
      pos: [1, 6, 1], 
      state: 2
    }, 
    {
      pos: [2, 6, 1], 
      state: 2
    }, 
    {
      pos: [3, 6, 1], 
      state: 2
    }, 
    {
      pos: [4, 6, 1], 
      state: 2
    }, 
    {
      pos: [5, 6, 1], 
      state: 2
    }, 
    {
      pos: [6, 6, 1], 
      state: 2
    }, 
    {
      pos: [7, 6, 1], 
      state: 2
    }, 
    {
      pos: [8, 6, 1], 
      state: 2
    }, 
    {
      pos: [9, 6, 1], 
      state: 2
    }, 
    {
      pos: [10, 6, 1], 
      state: 2
    }, 
    {
      pos: [11, 6, 1], 
      state: 2
    }, 
    {
      pos: [5, 6, 2], 
      state: 2
    }, 
    {
      pos: [7, 6, 2], 
      state: 2
    }, 
    {
      pos: [8, 6, 2], 
      state: 2
    }, 
    {
      pos: [9, 6, 2], 
      state: 2
    }, 
    {
      pos: [10, 6, 2], 
      state: 2
    }, 
    {
      pos: [11, 6, 2], 
      state: 2
    }, 
    {
      pos: [0, 6, 3], 
      state: 2
    }, 
    {
      pos: [1, 6, 3], 
      state: 2
    }, 
    {
      pos: [2, 6, 3], 
      state: 2
    }, 
    {
      pos: [7, 6, 3], 
      state: 2
    }, 
    {
      pos: [8, 6, 3], 
      state: 2
    }, 
    {
      pos: [10, 6, 3], 
      state: 2
    }, 
    {
      pos: [11, 6, 3], 
      state: 2
    }, 
    {
      pos: [2, 6, 4], 
      state: 2
    }, 
    {
      pos: [3, 6, 4], 
      state: 2
    }, 
    {
      pos: [7, 6, 4], 
      state: 2
    }, 
    {
      pos: [10, 6, 4], 
      state: 2
    }, 
    {
      pos: [11, 6, 4], 
      state: 2
    }, 
    {
      pos: [3, 6, 5], 
      state: 2
    }, 
    {
      pos: [11, 6, 5], 
      state: 2
    }, 
    {
      pos: [4, 6, 6], 
      state: 2
    }, 
    {
      pos: [5, 6, 6], 
      state: 2
    }, 
    {
      pos: [3, 6, 7], 
      state: 2
    }, 
    {
      pos: [4, 6, 7], 
      state: 2
    }, 
    {
      pos: [5, 6, 7], 
      state: 2
    }
  ], 
  palette: [
    {
      Name: "minecraft:polished_blackstone_bricks"
    }, 
    {
      Name: "minecraft:cracked_polished_blackstone_bricks"
    }, 
    {
      Name: "minecraft:air"
    }, 
    {
      Properties: {
        axis: "y"
      }, 
      Name: "minecraft:basalt"
    }, 
    {
      Properties: {
        orientation: "north_up"
      }, 
      Name: "minecraft:jigsaw"
    }, 
    {
      Properties: {
        orientation: "west_up"
      }, 
      Name: "minecraft:jigsaw"
    }, 
    {
      Properties: {
        orientation: "east_up"
      }, 
      Name: "minecraft:jigsaw"
    }, 
    {
      Properties: {
        orientation: "south_up"
      }, 
      Name: "minecraft:jigsaw"
    }, 
    {
      Properties: {
        half: "bottom", 
        waterlogged: "false", 
        shape: "straight", 
        facing: "west"
      }, 
      Name: "minecraft:polished_blackstone_brick_stairs"
    }, 
    {
      Properties: {
        orientation: "up_north"
      }, 
      Name: "minecraft:jigsaw"
    }, 
    {
      Properties: {
        orientation: "up_west"
      }, 
      Name: "minecraft:jigsaw"
    }, 
    {
      Properties: {
        waterlogged: "false", 
        facing: "north", 
        type: "single"
      }, 
      Name: "minecraft:chest"
    }, 
    {
      Properties: {
        waterlogged: "false"
      }, 
      Name: "minecraft:chain"
    }, 
    {
      Properties: {
        hanging: "true"
      }, 
      Name: "minecraft:lantern"
    }, 
    {
      Properties: {
        orientation: "up_east"
      }, 
      Name: "minecraft:jigsaw"
    }
  ]
}
