{
  size: [6, 7, 7], 
  entities: [], 
  blocks: [
    {
      pos: [0, 0, 0], 
      state: 0
    }, 
    {
      pos: [1, 0, 0], 
      state: 0
    }, 
    {
      pos: [2, 0, 0], 
      state: 0
    }, 
    {
      pos: [3, 0, 0], 
      state: 0
    }, 
    {
      pos: [0, 0, 1], 
      state: 1
    }, 
    {
      pos: [1, 0, 1], 
      state: 0
    }, 
    {
      pos: [2, 0, 1], 
      state: 0
    }, 
    {
      pos: [3, 0, 1], 
      state: 0
    }, 
    {
      pos: [4, 0, 1], 
      state: 0
    }, 
    {
      pos: [0, 0, 2], 
      state: 0
    }, 
    {
      pos: [1, 0, 2], 
      state: 1
    }, 
    {
      pos: [2, 0, 2], 
      state: 0
    }, 
    {
      pos: [3, 0, 2], 
      state: 0
    }, 
    {
      pos: [4, 0, 2], 
      state: 0
    }, 
    {
      pos: [5, 0, 2], 
      state: 0
    }, 
    {
      pos: [0, 0, 3], 
      state: 0
    }, 
    {
      pos: [1, 0, 3], 
      state: 0
    }, 
    {
      pos: [2, 0, 3], 
      state: 0
    }, 
    {
      pos: [3, 0, 3], 
      state: 0
    }, 
    {
      pos: [4, 0, 3], 
      state: 0
    }, 
    {
      pos: [5, 0, 3], 
      state: 0
    }, 
    {
      pos: [0, 0, 4], 
      state: 0
    }, 
    {
      pos: [1, 0, 4], 
      state: 0
    }, 
    {
      pos: [2, 0, 4], 
      state: 0
    }, 
    {
      pos: [4, 0, 4], 
      state: 0
    }, 
    {
      pos: [0, 0, 5], 
      state: 0
    }, 
    {
      pos: [1, 0, 5], 
      state: 0
    }, 
    {
      pos: [2, 0, 5], 
      state: 0
    }, 
    {
      pos: [3, 0, 5], 
      state: 0
    }, 
    {
      pos: [4, 0, 5], 
      state: 0
    }, 
    {
      pos: [2, 0, 6], 
      state: 0
    }, 
    {
      pos: [3, 0, 6], 
      state: 0
    }, 
    {
      nbt: {
        metadata: "chest", 
        mirror: "NONE", 
        ignoreEntities: 1b, 
        powered: 0b, 
        seed: 0L, 
        author: "LadyAgnes", 
        rotation: "NONE", 
        mode: "DATA", 
        posX: 0, 
        posY: 1, 
        sizeX: 0, 
        integrity: 1.0f, 
        posZ: 0, 
        showair: 0b, 
        name: "", 
        id: "minecraft:structure_block", 
        sizeY: 0, 
        showboundingbox: 1b, 
        sizeZ: 0
      }, 
      pos: [3, 0, 4], 
      state: 2
    }, 
    {
      pos: [4, 0, 0], 
      state: 3
    }, 
    {
      pos: [5, 0, 0], 
      state: 3
    }, 
    {
      pos: [5, 0, 1], 
      state: 3
    }, 
    {
      pos: [5, 0, 4], 
      state: 3
    }, 
    {
      pos: [5, 0, 5], 
      state: 3
    }, 
    {
      pos: [0, 0, 6], 
      state: 3
    }, 
    {
      pos: [1, 0, 6], 
      state: 3
    }, 
    {
      pos: [4, 0, 6], 
      state: 3
    }, 
    {
      pos: [5, 0, 6], 
      state: 3
    }, 
    {
      pos: [1, 1, 1], 
      state: 4
    }, 
    {
      pos: [3, 1, 1], 
      state: 4
    }, 
    {
      pos: [0, 1, 2], 
      state: 4
    }, 
    {
      pos: [4, 1, 2], 
      state: 4
    }, 
    {
      pos: [2, 1, 3], 
      state: 0
    }, 
    {
      pos: [3, 1, 3], 
      state: 0
    }, 
    {
      pos: [0, 1, 4], 
      state: 4
    }, 
    {
      pos: [1, 1, 4], 
      state: 0
    }, 
    {
      pos: [2, 1, 4], 
      state: 0
    }, 
    {
      pos: [3, 1, 4], 
      state: 0
    }, 
    {
      pos: [4, 1, 4], 
      state: 4
    }, 
    {
      pos: [1, 1, 5], 
      state: 4
    }, 
    {
      pos: [3, 1, 5], 
      state: 4
    }, 
    {
      nbt: {
        metadata: "drowned", 
        mirror: "NONE", 
        ignoreEntities: 1b, 
        powered: 0b, 
        seed: 0L, 
        author: "LadyAgnes", 
        rotation: "NONE", 
        mode: "DATA", 
        posX: 0, 
        posY: 1, 
        sizeX: 0, 
        integrity: 1.0f, 
        posZ: 0, 
        showair: 0b, 
        name: "", 
        id: "minecraft:structure_block", 
        sizeY: 0, 
        showboundingbox: 1b, 
        sizeZ: 0
      }, 
      pos: [3, 1, 2], 
      state: 2
    }, 
    {
      pos: [0, 1, 0], 
      state: 3
    }, 
    {
      pos: [1, 1, 0], 
      state: 3
    }, 
    {
      pos: [2, 1, 0], 
      state: 3
    }, 
    {
      pos: [3, 1, 0], 
      state: 3
    }, 
    {
      pos: [4, 1, 0], 
      state: 3
    }, 
    {
      pos: [5, 1, 0], 
      state: 3
    }, 
    {
      pos: [0, 1, 1], 
      state: 3
    }, 
    {
      pos: [2, 1, 1], 
      state: 3
    }, 
    {
      pos: [4, 1, 1], 
      state: 3
    }, 
    {
      pos: [5, 1, 1], 
      state: 3
    }, 
    {
      pos: [1, 1, 2], 
      state: 3
    }, 
    {
      pos: [2, 1, 2], 
      state: 3
    }, 
    {
      pos: [5, 1, 2], 
      state: 3
    }, 
    {
      pos: [0, 1, 3], 
      state: 3
    }, 
    {
      pos: [1, 1, 3], 
      state: 3
    }, 
    {
      pos: [4, 1, 3], 
      state: 3
    }, 
    {
      pos: [5, 1, 3], 
      state: 3
    }, 
    {
      pos: [5, 1, 4], 
      state: 3
    }, 
    {
      pos: [0, 1, 5], 
      state: 3
    }, 
    {
      pos: [2, 1, 5], 
      state: 3
    }, 
    {
      pos: [4, 1, 5], 
      state: 3
    }, 
    {
      pos: [5, 1, 5], 
      state: 3
    }, 
    {
      pos: [0, 1, 6], 
      state: 3
    }, 
    {
      pos: [1, 1, 6], 
      state: 3
    }, 
    {
      pos: [2, 1, 6], 
      state: 3
    }, 
    {
      pos: [3, 1, 6], 
      state: 3
    }, 
    {
      pos: [4, 1, 6], 
      state: 3
    }, 
    {
      pos: [5, 1, 6], 
      state: 3
    }, 
    {
      pos: [1, 2, 1], 
      state: 4
    }, 
    {
      pos: [3, 2, 1], 
      state: 4
    }, 
    {
      pos: [0, 2, 2], 
      state: 4
    }, 
    {
      pos: [4, 2, 2], 
      state: 4
    }, 
    {
      pos: [0, 2, 4], 
      state: 4
    }, 
    {
      pos: [3, 2, 4], 
      state: 0
    }, 
    {
      pos: [4, 2, 4], 
      state: 4
    }, 
    {
      pos: [1, 2, 5], 
      state: 4
    }, 
    {
      pos: [3, 2, 5], 
      state: 4
    }, 
    {
      pos: [0, 2, 0], 
      state: 3
    }, 
    {
      pos: [1, 2, 0], 
      state: 3
    }, 
    {
      pos: [2, 2, 0], 
      state: 3
    }, 
    {
      pos: [3, 2, 0], 
      state: 3
    }, 
    {
      pos: [4, 2, 0], 
      state: 3
    }, 
    {
      pos: [5, 2, 0], 
      state: 3
    }, 
    {
      pos: [0, 2, 1], 
      state: 3
    }, 
    {
      pos: [2, 2, 1], 
      state: 3
    }, 
    {
      pos: [4, 2, 1], 
      state: 3
    }, 
    {
      pos: [5, 2, 1], 
      state: 3
    }, 
    {
      pos: [1, 2, 2], 
      state: 3
    }, 
    {
      pos: [2, 2, 2], 
      state: 3
    }, 
    {
      pos: [3, 2, 2], 
      state: 3
    }, 
    {
      pos: [5, 2, 2], 
      state: 3
    }, 
    {
      pos: [0, 2, 3], 
      state: 3
    }, 
    {
      pos: [1, 2, 3], 
      state: 3
    }, 
    {
      pos: [2, 2, 3], 
      state: 3
    }, 
    {
      pos: [3, 2, 3], 
      state: 3
    }, 
    {
      pos: [4, 2, 3], 
      state: 3
    }, 
    {
      pos: [5, 2, 3], 
      state: 3
    }, 
    {
      pos: [1, 2, 4], 
      state: 3
    }, 
    {
      pos: [2, 2, 4], 
      state: 3
    }, 
    {
      pos: [5, 2, 4], 
      state: 3
    }, 
    {
      pos: [0, 2, 5], 
      state: 3
    }, 
    {
      pos: [2, 2, 5], 
      state: 3
    }, 
    {
      pos: [4, 2, 5], 
      state: 3
    }, 
    {
      pos: [5, 2, 5], 
      state: 3
    }, 
    {
      pos: [0, 2, 6], 
      state: 3
    }, 
    {
      pos: [1, 2, 6], 
      state: 3
    }, 
    {
      pos: [2, 2, 6], 
      state: 3
    }, 
    {
      pos: [3, 2, 6], 
      state: 3
    }, 
    {
      pos: [4, 2, 6], 
      state: 3
    }, 
    {
      pos: [5, 2, 6], 
      state: 3
    }, 
    {
      pos: [1, 3, 1], 
      state: 5
    }, 
    {
      pos: [2, 3, 1], 
      state: 4
    }, 
    {
      pos: [3, 3, 1], 
      state: 5
    }, 
    {
      pos: [0, 3, 2], 
      state: 5
    }, 
    {
      pos: [4, 3, 2], 
      state: 5
    }, 
    {
      pos: [0, 3, 3], 
      state: 4
    }, 
    {
      pos: [4, 3, 3], 
      state: 4
    }, 
    {
      pos: [0, 3, 4], 
      state: 5
    }, 
    {
      pos: [4, 3, 4], 
      state: 5
    }, 
    {
      pos: [1, 3, 5], 
      state: 5
    }, 
    {
      pos: [2, 3, 5], 
      state: 4
    }, 
    {
      pos: [3, 3, 5], 
      state: 5
    }, 
    {
      pos: [0, 3, 0], 
      state: 3
    }, 
    {
      pos: [1, 3, 0], 
      state: 3
    }, 
    {
      pos: [2, 3, 0], 
      state: 3
    }, 
    {
      pos: [3, 3, 0], 
      state: 3
    }, 
    {
      pos: [4, 3, 0], 
      state: 3
    }, 
    {
      pos: [5, 3, 0], 
      state: 3
    }, 
    {
      pos: [0, 3, 1], 
      state: 3
    }, 
    {
      pos: [4, 3, 1], 
      state: 3
    }, 
    {
      pos: [5, 3, 1], 
      state: 3
    }, 
    {
      pos: [1, 3, 2], 
      state: 3
    }, 
    {
      pos: [2, 3, 2], 
      state: 3
    }, 
    {
      pos: [3, 3, 2], 
      state: 3
    }, 
    {
      pos: [5, 3, 2], 
      state: 3
    }, 
    {
      pos: [1, 3, 3], 
      state: 3
    }, 
    {
      pos: [2, 3, 3], 
      state: 3
    }, 
    {
      pos: [3, 3, 3], 
      state: 3
    }, 
    {
      pos: [5, 3, 3], 
      state: 3
    }, 
    {
      pos: [1, 3, 4], 
      state: 3
    }, 
    {
      pos: [2, 3, 4], 
      state: 3
    }, 
    {
      pos: [3, 3, 4], 
      state: 3
    }, 
    {
      pos: [5, 3, 4], 
      state: 3
    }, 
    {
      pos: [0, 3, 5], 
      state: 3
    }, 
    {
      pos: [4, 3, 5], 
      state: 3
    }, 
    {
      pos: [5, 3, 5], 
      state: 3
    }, 
    {
      pos: [0, 3, 6], 
      state: 3
    }, 
    {
      pos: [1, 3, 6], 
      state: 3
    }, 
    {
      pos: [2, 3, 6], 
      state: 3
    }, 
    {
      pos: [3, 3, 6], 
      state: 3
    }, 
    {
      pos: [4, 3, 6], 
      state: 3
    }, 
    {
      pos: [5, 3, 6], 
      state: 3
    }, 
    {
      pos: [1, 4, 2], 
      state: 5
    }, 
    {
      pos: [2, 4, 2], 
      state: 4
    }, 
    {
      pos: [3, 4, 2], 
      state: 5
    }, 
    {
      pos: [1, 4, 3], 
      state: 4
    }, 
    {
      pos: [2, 4, 3], 
      state: 5
    }, 
    {
      pos: [3, 4, 3], 
      state: 4
    }, 
    {
      pos: [1, 4, 4], 
      state: 5
    }, 
    {
      pos: [2, 4, 4], 
      state: 4
    }, 
    {
      pos: [3, 4, 4], 
      state: 5
    }, 
    {
      pos: [0, 4, 0], 
      state: 3
    }, 
    {
      pos: [1, 4, 0], 
      state: 3
    }, 
    {
      pos: [2, 4, 0], 
      state: 3
    }, 
    {
      pos: [3, 4, 0], 
      state: 3
    }, 
    {
      pos: [4, 4, 0], 
      state: 3
    }, 
    {
      pos: [5, 4, 0], 
      state: 3
    }, 
    {
      pos: [0, 4, 1], 
      state: 3
    }, 
    {
      pos: [1, 4, 1], 
      state: 3
    }, 
    {
      pos: [2, 4, 1], 
      state: 3
    }, 
    {
      pos: [3, 4, 1], 
      state: 3
    }, 
    {
      pos: [4, 4, 1], 
      state: 3
    }, 
    {
      pos: [5, 4, 1], 
      state: 3
    }, 
    {
      pos: [0, 4, 2], 
      state: 3
    }, 
    {
      pos: [4, 4, 2], 
      state: 3
    }, 
    {
      pos: [5, 4, 2], 
      state: 3
    }, 
    {
      pos: [0, 4, 3], 
      state: 3
    }, 
    {
      pos: [4, 4, 3], 
      state: 3
    }, 
    {
      pos: [5, 4, 3], 
      state: 3
    }, 
    {
      pos: [0, 4, 4], 
      state: 3
    }, 
    {
      pos: [4, 4, 4], 
      state: 3
    }, 
    {
      pos: [5, 4, 4], 
      state: 3
    }, 
    {
      pos: [0, 4, 5], 
      state: 3
    }, 
    {
      pos: [1, 4, 5], 
      state: 3
    }, 
    {
      pos: [2, 4, 5], 
      state: 3
    }, 
    {
      pos: [3, 4, 5], 
      state: 3
    }, 
    {
      pos: [4, 4, 5], 
      state: 3
    }, 
    {
      pos: [5, 4, 5], 
      state: 3
    }, 
    {
      pos: [0, 4, 6], 
      state: 3
    }, 
    {
      pos: [1, 4, 6], 
      state: 3
    }, 
    {
      pos: [2, 4, 6], 
      state: 3
    }, 
    {
      pos: [3, 4, 6], 
      state: 3
    }, 
    {
      pos: [4, 4, 6], 
      state: 3
    }, 
    {
      pos: [5, 4, 6], 
      state: 3
    }, 
    {
      pos: [0, 5, 0], 
      state: 3
    }, 
    {
      pos: [1, 5, 0], 
      state: 3
    }, 
    {
      pos: [2, 5, 0], 
      state: 3
    }, 
    {
      pos: [3, 5, 0], 
      state: 3
    }, 
    {
      pos: [4, 5, 0], 
      state: 3
    }, 
    {
      pos: [5, 5, 0], 
      state: 3
    }, 
    {
      pos: [0, 5, 1], 
      state: 3
    }, 
    {
      pos: [1, 5, 1], 
      state: 3
    }, 
    {
      pos: [2, 5, 1], 
      state: 3
    }, 
    {
      pos: [3, 5, 1], 
      state: 3
    }, 
    {
      pos: [4, 5, 1], 
      state: 3
    }, 
    {
      pos: [5, 5, 1], 
      state: 3
    }, 
    {
      pos: [0, 5, 2], 
      state: 3
    }, 
    {
      pos: [1, 5, 2], 
      state: 3
    }, 
    {
      pos: [2, 5, 2], 
      state: 3
    }, 
    {
      pos: [3, 5, 2], 
      state: 3
    }, 
    {
      pos: [4, 5, 2], 
      state: 3
    }, 
    {
      pos: [5, 5, 2], 
      state: 3
    }, 
    {
      pos: [0, 5, 3], 
      state: 3
    }, 
    {
      pos: [1, 5, 3], 
      state: 3
    }, 
    {
      pos: [2, 5, 3], 
      state: 3
    }, 
    {
      pos: [3, 5, 3], 
      state: 3
    }, 
    {
      pos: [4, 5, 3], 
      state: 3
    }, 
    {
      pos: [5, 5, 3], 
      state: 3
    }, 
    {
      pos: [0, 5, 4], 
      state: 3
    }, 
    {
      pos: [1, 5, 4], 
      state: 3
    }, 
    {
      pos: [2, 5, 4], 
      state: 3
    }, 
    {
      pos: [3, 5, 4], 
      state: 3
    }, 
    {
      pos: [4, 5, 4], 
      state: 3
    }, 
    {
      pos: [5, 5, 4], 
      state: 3
    }, 
    {
      pos: [0, 5, 5], 
      state: 3
    }, 
    {
      pos: [1, 5, 5], 
      state: 3
    }, 
    {
      pos: [2, 5, 5], 
      state: 3
    }, 
    {
      pos: [3, 5, 5], 
      state: 3
    }, 
    {
      pos: [4, 5, 5], 
      state: 3
    }, 
    {
      pos: [5, 5, 5], 
      state: 3
    }, 
    {
      pos: [0, 5, 6], 
      state: 3
    }, 
    {
      pos: [1, 5, 6], 
      state: 3
    }, 
    {
      pos: [2, 5, 6], 
      state: 3
    }, 
    {
      pos: [3, 5, 6], 
      state: 3
    }, 
    {
      pos: [4, 5, 6], 
      state: 3
    }, 
    {
      pos: [5, 5, 6], 
      state: 3
    }, 
    {
      pos: [0, 6, 0], 
      state: 3
    }, 
    {
      pos: [1, 6, 0], 
      state: 3
    }, 
    {
      pos: [2, 6, 0], 
      state: 3
    }, 
    {
      pos: [3, 6, 0], 
      state: 3
    }, 
    {
      pos: [4, 6, 0], 
      state: 3
    }, 
    {
      pos: [5, 6, 0], 
      state: 3
    }, 
    {
      pos: [0, 6, 1], 
      state: 3
    }, 
    {
      pos: [1, 6, 1], 
      state: 3
    }, 
    {
      pos: [2, 6, 1], 
      state: 3
    }, 
    {
      pos: [3, 6, 1], 
      state: 3
    }, 
    {
      pos: [4, 6, 1], 
      state: 3
    }, 
    {
      pos: [5, 6, 1], 
      state: 3
    }, 
    {
      pos: [0, 6, 2], 
      state: 3
    }, 
    {
      pos: [1, 6, 2], 
      state: 3
    }, 
    {
      pos: [2, 6, 2], 
      state: 3
    }, 
    {
      pos: [3, 6, 2], 
      state: 3
    }, 
    {
      pos: [4, 6, 2], 
      state: 3
    }, 
    {
      pos: [5, 6, 2], 
      state: 3
    }, 
    {
      pos: [0, 6, 3], 
      state: 3
    }, 
    {
      pos: [1, 6, 3], 
      state: 3
    }, 
    {
      pos: [2, 6, 3], 
      state: 3
    }, 
    {
      pos: [3, 6, 3], 
      state: 3
    }, 
    {
      pos: [4, 6, 3], 
      state: 3
    }, 
    {
      pos: [5, 6, 3], 
      state: 3
    }, 
    {
      pos: [0, 6, 4], 
      state: 3
    }, 
    {
      pos: [1, 6, 4], 
      state: 3
    }, 
    {
      pos: [2, 6, 4], 
      state: 3
    }, 
    {
      pos: [3, 6, 4], 
      state: 3
    }, 
    {
      pos: [4, 6, 4], 
      state: 3
    }, 
    {
      pos: [5, 6, 4], 
      state: 3
    }, 
    {
      pos: [0, 6, 5], 
      state: 3
    }, 
    {
      pos: [1, 6, 5], 
      state: 3
    }, 
    {
      pos: [2, 6, 5], 
      state: 3
    }, 
    {
      pos: [3, 6, 5], 
      state: 3
    }, 
    {
      pos: [4, 6, 5], 
      state: 3
    }, 
    {
      pos: [5, 6, 5], 
      state: 3
    }, 
    {
      pos: [0, 6, 6], 
      state: 3
    }, 
    {
      pos: [1, 6, 6], 
      state: 3
    }, 
    {
      pos: [2, 6, 6], 
      state: 3
    }, 
    {
      pos: [3, 6, 6], 
      state: 3
    }, 
    {
      pos: [4, 6, 6], 
      state: 3
    }, 
    {
      pos: [5, 6, 6], 
      state: 3
    }
  ], 
  palette: [
    {
      Name: "minecraft:sand"
    }, 
    {
      Name: "minecraft:magma_block"
    }, 
    {
      Properties: {
        mode: "data"
      }, 
      Name: "minecraft:structure_block"
    }, 
    {
      Name: "minecraft:air"
    }, 
    {
      Name: "minecraft:cut_sandstone"
    }, 
    {
      Name: "minecraft:polished_granite"
    }
  ]
}
