{
  size: [3, 22, 3], 
  entities: [], 
  blocks: [
    {
      pos: [0, 0, 0], 
      state: 0
    }, 
    {
      pos: [0, 0, 1], 
      state: 0
    }, 
    {
      pos: [0, 0, 2], 
      state: 0
    }, 
    {
      pos: [1, 0, 0], 
      state: 0
    }, 
    {
      pos: [1, 0, 1], 
      state: 0
    }, 
    {
      pos: [1, 0, 2], 
      state: 0
    }, 
    {
      pos: [2, 0, 0], 
      state: 0
    }, 
    {
      pos: [2, 0, 1], 
      state: 0
    }, 
    {
      pos: [2, 0, 2], 
      state: 0
    }, 
    {
      pos: [0, 1, 0], 
      state: 0
    }, 
    {
      pos: [0, 1, 1], 
      state: 0
    }, 
    {
      pos: [0, 1, 2], 
      state: 0
    }, 
    {
      pos: [1, 1, 0], 
      state: 0
    }, 
    {
      pos: [1, 1, 1], 
      state: 0
    }, 
    {
      pos: [1, 1, 2], 
      state: 0
    }, 
    {
      pos: [2, 1, 0], 
      state: 0
    }, 
    {
      pos: [2, 1, 1], 
      state: 0
    }, 
    {
      pos: [2, 1, 2], 
      state: 0
    }, 
    {
      pos: [0, 2, 0], 
      state: 0
    }, 
    {
      pos: [0, 2, 1], 
      state: 0
    }, 
    {
      pos: [0, 2, 2], 
      state: 0
    }, 
    {
      pos: [1, 2, 0], 
      state: 0
    }, 
    {
      pos: [1, 2, 1], 
      state: 0
    }, 
    {
      pos: [1, 2, 2], 
      state: 0
    }, 
    {
      pos: [2, 2, 0], 
      state: 0
    }, 
    {
      pos: [2, 2, 1], 
      state: 0
    }, 
    {
      pos: [2, 2, 2], 
      state: 0
    }, 
    {
      pos: [0, 3, 0], 
      state: 0
    }, 
    {
      pos: [0, 3, 1], 
      state: 0
    }, 
    {
      pos: [0, 3, 2], 
      state: 0
    }, 
    {
      pos: [1, 3, 0], 
      state: 0
    }, 
    {
      pos: [1, 3, 1], 
      state: 0
    }, 
    {
      pos: [1, 3, 2], 
      state: 0
    }, 
    {
      pos: [2, 3, 0], 
      state: 0
    }, 
    {
      pos: [2, 3, 1], 
      state: 0
    }, 
    {
      pos: [2, 3, 2], 
      state: 0
    }, 
    {
      pos: [0, 4, 0], 
      state: 0
    }, 
    {
      pos: [0, 4, 1], 
      state: 0
    }, 
    {
      pos: [0, 4, 2], 
      state: 0
    }, 
    {
      pos: [1, 4, 0], 
      state: 0
    }, 
    {
      pos: [1, 4, 1], 
      state: 0
    }, 
    {
      pos: [1, 4, 2], 
      state: 0
    }, 
    {
      pos: [2, 4, 0], 
      state: 0
    }, 
    {
      pos: [2, 4, 1], 
      state: 0
    }, 
    {
      pos: [2, 4, 2], 
      state: 0
    }, 
    {
      pos: [0, 5, 0], 
      state: 0
    }, 
    {
      pos: [0, 5, 1], 
      state: 0
    }, 
    {
      pos: [0, 5, 2], 
      state: 0
    }, 
    {
      pos: [1, 5, 0], 
      state: 0
    }, 
    {
      pos: [1, 5, 1], 
      state: 0
    }, 
    {
      pos: [1, 5, 2], 
      state: 0
    }, 
    {
      pos: [2, 5, 0], 
      state: 0
    }, 
    {
      pos: [2, 5, 1], 
      state: 0
    }, 
    {
      pos: [2, 5, 2], 
      state: 0
    }, 
    {
      pos: [0, 6, 0], 
      state: 0
    }, 
    {
      pos: [0, 6, 1], 
      state: 0
    }, 
    {
      pos: [0, 6, 2], 
      state: 0
    }, 
    {
      pos: [1, 6, 0], 
      state: 0
    }, 
    {
      pos: [1, 6, 1], 
      state: 0
    }, 
    {
      pos: [1, 6, 2], 
      state: 0
    }, 
    {
      pos: [2, 6, 0], 
      state: 0
    }, 
    {
      pos: [2, 6, 1], 
      state: 0
    }, 
    {
      pos: [2, 6, 2], 
      state: 0
    }, 
    {
      pos: [0, 7, 0], 
      state: 0
    }, 
    {
      pos: [0, 7, 1], 
      state: 0
    }, 
    {
      pos: [0, 7, 2], 
      state: 0
    }, 
    {
      pos: [1, 7, 0], 
      state: 0
    }, 
    {
      pos: [1, 7, 1], 
      state: 0
    }, 
    {
      pos: [1, 7, 2], 
      state: 0
    }, 
    {
      pos: [2, 7, 0], 
      state: 0
    }, 
    {
      pos: [2, 7, 1], 
      state: 0
    }, 
    {
      pos: [2, 7, 2], 
      state: 0
    }, 
    {
      pos: [0, 8, 0], 
      state: 0
    }, 
    {
      pos: [0, 8, 1], 
      state: 0
    }, 
    {
      pos: [0, 8, 2], 
      state: 0
    }, 
    {
      pos: [1, 8, 0], 
      state: 0
    }, 
    {
      pos: [1, 8, 1], 
      state: 0
    }, 
    {
      pos: [1, 8, 2], 
      state: 0
    }, 
    {
      pos: [2, 8, 0], 
      state: 0
    }, 
    {
      pos: [2, 8, 2], 
      state: 1
    }, 
    {
      pos: [0, 9, 0], 
      state: 0
    }, 
    {
      pos: [0, 9, 1], 
      state: 0
    }, 
    {
      pos: [1, 9, 0], 
      state: 0
    }, 
    {
      pos: [1, 9, 1], 
      state: 0
    }, 
    {
      pos: [1, 9, 2], 
      state: 1
    }, 
    {
      pos: [2, 9, 0], 
      state: 1
    }, 
    {
      pos: [2, 9, 1], 
      state: 0
    }, 
    {
      pos: [0, 10, 0], 
      state: 0
    }, 
    {
      pos: [0, 10, 1], 
      state: 0
    }, 
    {
      pos: [0, 10, 2], 
      state: 0
    }, 
    {
      pos: [1, 10, 0], 
      state: 1
    }, 
    {
      pos: [1, 10, 1], 
      state: 1
    }, 
    {
      pos: [1, 10, 2], 
      state: 1
    }, 
    {
      pos: [2, 10, 0], 
      state: 1
    }, 
    {
      pos: [2, 10, 1], 
      state: 1
    }, 
    {
      pos: [2, 10, 2], 
      state: 1
    }, 
    {
      pos: [0, 11, 0], 
      state: 1
    }, 
    {
      pos: [0, 11, 1], 
      state: 0
    }, 
    {
      pos: [0, 11, 2], 
      state: 0
    }, 
    {
      pos: [1, 11, 0], 
      state: 1
    }, 
    {
      pos: [1, 11, 1], 
      state: 1
    }, 
    {
      pos: [1, 11, 2], 
      state: 1
    }, 
    {
      pos: [0, 12, 0], 
      state: 1
    }, 
    {
      pos: [0, 12, 1], 
      state: 1
    }, 
    {
      pos: [0, 12, 2], 
      state: 0
    }, 
    {
      pos: [1, 12, 0], 
      state: 1
    }, 
    {
      pos: [1, 12, 1], 
      state: 1
    }, 
    {
      pos: [1, 12, 2], 
      state: 1
    }, 
    {
      pos: [2, 12, 0], 
      state: 1
    }, 
    {
      pos: [2, 12, 1], 
      state: 1
    }, 
    {
      pos: [0, 13, 0], 
      state: 0
    }, 
    {
      pos: [0, 13, 1], 
      state: 1
    }, 
    {
      pos: [1, 13, 0], 
      state: 1
    }, 
    {
      pos: [1, 13, 1], 
      state: 1
    }, 
    {
      pos: [1, 13, 2], 
      state: 1
    }, 
    {
      pos: [2, 13, 0], 
      state: 1
    }, 
    {
      pos: [2, 13, 1], 
      state: 1
    }, 
    {
      pos: [0, 14, 0], 
      state: 0
    }, 
    {
      pos: [0, 14, 1], 
      state: 1
    }, 
    {
      pos: [0, 14, 2], 
      state: 1
    }, 
    {
      pos: [1, 14, 0], 
      state: 1
    }, 
    {
      pos: [1, 14, 1], 
      state: 1
    }, 
    {
      pos: [2, 14, 0], 
      state: 1
    }, 
    {
      pos: [0, 15, 0], 
      state: 0
    }, 
    {
      pos: [0, 15, 1], 
      state: 1
    }, 
    {
      pos: [0, 15, 2], 
      state: 1
    }, 
    {
      pos: [1, 15, 0], 
      state: 1
    }, 
    {
      pos: [1, 15, 1], 
      state: 1
    }, 
    {
      pos: [0, 16, 1], 
      state: 1
    }, 
    {
      pos: [1, 16, 1], 
      state: 1
    }, 
    {
      pos: [0, 17, 0], 
      state: 0
    }, 
    {
      pos: [0, 17, 1], 
      state: 1
    }, 
    {
      pos: [0, 18, 0], 
      state: 1
    }, 
    {
      pos: [0, 18, 1], 
      state: 1
    }, 
    {
      pos: [1, 18, 1], 
      state: 0
    }, 
    {
      pos: [0, 19, 1], 
      state: 0
    }, 
    {
      pos: [1, 19, 1], 
      state: 0
    }, 
    {
      pos: [2, 19, 1], 
      state: 0
    }, 
    {
      pos: [2, 19, 2], 
      state: 0
    }, 
    {
      pos: [0, 20, 0], 
      state: 0
    }, 
    {
      pos: [0, 20, 1], 
      state: 0
    }, 
    {
      pos: [0, 20, 2], 
      state: 0
    }, 
    {
      pos: [1, 20, 0], 
      state: 0
    }, 
    {
      pos: [1, 20, 1], 
      state: 0
    }, 
    {
      pos: [1, 20, 2], 
      state: 0
    }, 
    {
      pos: [2, 20, 1], 
      state: 0
    }, 
    {
      pos: [2, 20, 2], 
      state: 0
    }, 
    {
      pos: [0, 21, 0], 
      state: 0
    }, 
    {
      pos: [0, 21, 2], 
      state: 0
    }, 
    {
      pos: [1, 21, 0], 
      state: 0
    }, 
    {
      pos: [1, 21, 1], 
      state: 0
    }, 
    {
      pos: [1, 21, 2], 
      state: 0
    }, 
    {
      pos: [2, 21, 0], 
      state: 0
    }, 
    {
      pos: [2, 21, 1], 
      state: 0
    }, 
    {
      pos: [2, 21, 2], 
      state: 0
    }, 
    {
      nbt: {
        final_state: "minecraft:air", 
        name: "minecraft:leg_connector", 
        pool: "minecraft:empty", 
        joint: "aligned", 
        id: "minecraft:jigsaw", 
        target: "minecraft:empty"
      }, 
      pos: [0, 21, 1], 
      state: 2
    }
  ], 
  palette: [
    {
      Name: "minecraft:polished_blackstone_bricks"
    }, 
    {
      Name: "minecraft:blackstone"
    }, 
    {
      Properties: {
        orientation: "up_west"
      }, 
      Name: "minecraft:jigsaw"
    }
  ]
}
