{
  size: [5, 24, 32], 
  entities: [], 
  blocks: [
    {
      pos: [3, 0, 9], 
      state: 0
    }, 
    {
      pos: [4, 0, 9], 
      state: 0
    }, 
    {
      pos: [4, 0, 18], 
      state: 0
    }, 
    {
      pos: [4, 0, 19], 
      state: 0
    }, 
    {
      nbt: {
        joint: "rollable", 
        final_state: "minecraft:air", 
        name: "minecraft:entrance_face", 
        pool: "minecraft:empty", 
        id: "minecraft:jigsaw", 
        target: "minecraft:empty"
      }, 
      pos: [4, 0, 0], 
      state: 1
    }, 
    {
      pos: [4, 0, 10], 
      state: 2
    }, 
    {
      pos: [4, 0, 11], 
      state: 2
    }, 
    {
      pos: [3, 0, 12], 
      state: 2
    }, 
    {
      pos: [4, 0, 12], 
      state: 2
    }, 
    {
      pos: [3, 0, 13], 
      state: 2
    }, 
    {
      pos: [4, 0, 13], 
      state: 2
    }, 
    {
      pos: [2, 0, 14], 
      state: 2
    }, 
    {
      pos: [3, 0, 14], 
      state: 2
    }, 
    {
      pos: [4, 0, 14], 
      state: 2
    }, 
    {
      pos: [2, 0, 15], 
      state: 2
    }, 
    {
      pos: [3, 0, 15], 
      state: 2
    }, 
    {
      pos: [4, 0, 15], 
      state: 2
    }, 
    {
      pos: [2, 0, 16], 
      state: 2
    }, 
    {
      pos: [3, 0, 16], 
      state: 2
    }, 
    {
      pos: [4, 0, 16], 
      state: 2
    }, 
    {
      pos: [2, 0, 17], 
      state: 2
    }, 
    {
      pos: [3, 0, 17], 
      state: 2
    }, 
    {
      pos: [4, 0, 17], 
      state: 2
    }, 
    {
      pos: [2, 0, 18], 
      state: 2
    }, 
    {
      pos: [3, 0, 18], 
      state: 2
    }, 
    {
      pos: [2, 0, 19], 
      state: 2
    }, 
    {
      pos: [3, 0, 19], 
      state: 2
    }, 
    {
      pos: [2, 0, 20], 
      state: 2
    }, 
    {
      pos: [3, 0, 20], 
      state: 2
    }, 
    {
      pos: [4, 0, 20], 
      state: 2
    }, 
    {
      pos: [2, 0, 21], 
      state: 2
    }, 
    {
      pos: [3, 0, 21], 
      state: 2
    }, 
    {
      pos: [4, 0, 21], 
      state: 2
    }, 
    {
      pos: [3, 0, 22], 
      state: 2
    }, 
    {
      pos: [4, 0, 22], 
      state: 2
    }, 
    {
      pos: [3, 0, 23], 
      state: 2
    }, 
    {
      pos: [4, 0, 23], 
      state: 2
    }, 
    {
      pos: [3, 0, 24], 
      state: 2
    }, 
    {
      pos: [4, 0, 24], 
      state: 2
    }, 
    {
      pos: [3, 1, 9], 
      state: 0
    }, 
    {
      pos: [4, 1, 9], 
      state: 0
    }, 
    {
      pos: [2, 1, 11], 
      state: 0
    }, 
    {
      pos: [2, 1, 12], 
      state: 0
    }, 
    {
      pos: [4, 1, 12], 
      state: 0
    }, 
    {
      pos: [4, 1, 13], 
      state: 0
    }, 
    {
      pos: [4, 1, 18], 
      state: 0
    }, 
    {
      pos: [4, 1, 19], 
      state: 0
    }, 
    {
      pos: [3, 1, 10], 
      state: 2
    }, 
    {
      pos: [4, 1, 10], 
      state: 2
    }, 
    {
      pos: [3, 1, 11], 
      state: 2
    }, 
    {
      pos: [4, 1, 11], 
      state: 2
    }, 
    {
      pos: [4, 1, 14], 
      state: 2
    }, 
    {
      pos: [4, 1, 15], 
      state: 2
    }, 
    {
      pos: [4, 1, 16], 
      state: 2
    }, 
    {
      pos: [4, 1, 17], 
      state: 2
    }, 
    {
      pos: [4, 1, 20], 
      state: 2
    }, 
    {
      pos: [4, 1, 21], 
      state: 2
    }, 
    {
      pos: [0, 2, 8], 
      state: 3
    }, 
    {
      pos: [1, 2, 8], 
      state: 3
    }, 
    {
      pos: [2, 2, 8], 
      state: 3
    }, 
    {
      pos: [3, 2, 8], 
      state: 3
    }, 
    {
      pos: [4, 2, 8], 
      state: 3
    }, 
    {
      pos: [0, 2, 9], 
      state: 3
    }, 
    {
      pos: [1, 2, 9], 
      state: 3
    }, 
    {
      pos: [2, 2, 9], 
      state: 3
    }, 
    {
      pos: [3, 2, 9], 
      state: 3
    }, 
    {
      pos: [4, 2, 9], 
      state: 3
    }, 
    {
      pos: [0, 2, 10], 
      state: 3
    }, 
    {
      pos: [1, 2, 10], 
      state: 3
    }, 
    {
      pos: [2, 2, 10], 
      state: 3
    }, 
    {
      pos: [3, 2, 10], 
      state: 3
    }, 
    {
      pos: [4, 2, 10], 
      state: 3
    }, 
    {
      pos: [0, 2, 11], 
      state: 4
    }, 
    {
      pos: [1, 2, 11], 
      state: 3
    }, 
    {
      pos: [2, 2, 11], 
      state: 3
    }, 
    {
      pos: [3, 2, 11], 
      state: 3
    }, 
    {
      pos: [4, 2, 11], 
      state: 3
    }, 
    {
      pos: [0, 2, 12], 
      state: 3
    }, 
    {
      pos: [1, 2, 12], 
      state: 3
    }, 
    {
      pos: [2, 2, 12], 
      state: 3
    }, 
    {
      pos: [3, 2, 12], 
      state: 3
    }, 
    {
      pos: [4, 2, 12], 
      state: 3
    }, 
    {
      pos: [0, 2, 13], 
      state: 3
    }, 
    {
      pos: [1, 2, 13], 
      state: 3
    }, 
    {
      pos: [2, 2, 13], 
      state: 3
    }, 
    {
      pos: [3, 2, 13], 
      state: 3
    }, 
    {
      pos: [4, 2, 13], 
      state: 3
    }, 
    {
      pos: [0, 2, 14], 
      state: 3
    }, 
    {
      pos: [1, 2, 14], 
      state: 3
    }, 
    {
      pos: [2, 2, 14], 
      state: 3
    }, 
    {
      pos: [3, 2, 14], 
      state: 3
    }, 
    {
      pos: [4, 2, 14], 
      state: 3
    }, 
    {
      pos: [1, 2, 15], 
      state: 5
    }, 
    {
      pos: [2, 2, 15], 
      state: 3
    }, 
    {
      pos: [3, 2, 15], 
      state: 3
    }, 
    {
      pos: [4, 2, 15], 
      state: 3
    }, 
    {
      pos: [0, 2, 16], 
      state: 3
    }, 
    {
      pos: [1, 2, 16], 
      state: 3
    }, 
    {
      pos: [2, 2, 16], 
      state: 3
    }, 
    {
      pos: [3, 2, 16], 
      state: 3
    }, 
    {
      pos: [4, 2, 16], 
      state: 3
    }, 
    {
      pos: [0, 2, 17], 
      state: 3
    }, 
    {
      pos: [1, 2, 17], 
      state: 3
    }, 
    {
      pos: [2, 2, 17], 
      state: 3
    }, 
    {
      pos: [3, 2, 17], 
      state: 3
    }, 
    {
      pos: [4, 2, 17], 
      state: 3
    }, 
    {
      pos: [0, 2, 18], 
      state: 3
    }, 
    {
      pos: [1, 2, 18], 
      state: 3
    }, 
    {
      pos: [2, 2, 18], 
      state: 3
    }, 
    {
      pos: [3, 2, 18], 
      state: 3
    }, 
    {
      pos: [4, 2, 18], 
      state: 3
    }, 
    {
      pos: [0, 2, 19], 
      state: 3
    }, 
    {
      pos: [1, 2, 19], 
      state: 3
    }, 
    {
      pos: [2, 2, 19], 
      state: 3
    }, 
    {
      pos: [3, 2, 19], 
      state: 3
    }, 
    {
      pos: [4, 2, 19], 
      state: 3
    }, 
    {
      pos: [0, 2, 20], 
      state: 3
    }, 
    {
      pos: [1, 2, 20], 
      state: 3
    }, 
    {
      pos: [2, 2, 20], 
      state: 3
    }, 
    {
      pos: [3, 2, 20], 
      state: 3
    }, 
    {
      pos: [4, 2, 20], 
      state: 3
    }, 
    {
      pos: [1, 2, 21], 
      state: 3
    }, 
    {
      pos: [2, 2, 21], 
      state: 3
    }, 
    {
      pos: [3, 2, 21], 
      state: 3
    }, 
    {
      pos: [4, 2, 21], 
      state: 3
    }, 
    {
      pos: [3, 2, 22], 
      state: 3
    }, 
    {
      pos: [4, 2, 22], 
      state: 3
    }, 
    {
      pos: [2, 2, 23], 
      state: 3
    }, 
    {
      pos: [3, 2, 23], 
      state: 3
    }, 
    {
      pos: [4, 2, 23], 
      state: 3
    }, 
    {
      pos: [4, 3, 5], 
      state: 3
    }, 
    {
      pos: [0, 3, 8], 
      state: 3
    }, 
    {
      pos: [1, 3, 8], 
      state: 3
    }, 
    {
      pos: [2, 3, 8], 
      state: 3
    }, 
    {
      pos: [3, 3, 8], 
      state: 3
    }, 
    {
      pos: [4, 3, 8], 
      state: 3
    }, 
    {
      pos: [0, 3, 9], 
      state: 3
    }, 
    {
      pos: [1, 3, 9], 
      state: 3
    }, 
    {
      pos: [2, 3, 9], 
      state: 3
    }, 
    {
      pos: [3, 3, 9], 
      state: 3
    }, 
    {
      pos: [4, 3, 9], 
      state: 3
    }, 
    {
      pos: [0, 3, 10], 
      state: 3
    }, 
    {
      pos: [1, 3, 10], 
      state: 3
    }, 
    {
      pos: [2, 3, 10], 
      state: 3
    }, 
    {
      pos: [3, 3, 10], 
      state: 6
    }, 
    {
      pos: [4, 3, 10], 
      state: 3
    }, 
    {
      pos: [0, 3, 11], 
      state: 4
    }, 
    {
      pos: [1, 3, 11], 
      state: 4
    }, 
    {
      pos: [2, 3, 11], 
      state: 3
    }, 
    {
      pos: [3, 3, 11], 
      state: 6
    }, 
    {
      pos: [4, 3, 11], 
      state: 3
    }, 
    {
      pos: [0, 3, 12], 
      state: 3
    }, 
    {
      pos: [1, 3, 12], 
      state: 4
    }, 
    {
      pos: [2, 3, 12], 
      state: 4
    }, 
    {
      pos: [3, 3, 12], 
      state: 6
    }, 
    {
      pos: [4, 3, 12], 
      state: 3
    }, 
    {
      pos: [0, 3, 13], 
      state: 3
    }, 
    {
      pos: [1, 3, 13], 
      state: 4
    }, 
    {
      pos: [2, 3, 13], 
      state: 4
    }, 
    {
      pos: [3, 3, 13], 
      state: 6
    }, 
    {
      pos: [4, 3, 13], 
      state: 3
    }, 
    {
      pos: [0, 3, 14], 
      state: 5
    }, 
    {
      pos: [1, 3, 14], 
      state: 5
    }, 
    {
      pos: [2, 3, 14], 
      state: 5
    }, 
    {
      pos: [3, 3, 14], 
      state: 6
    }, 
    {
      pos: [4, 3, 14], 
      state: 3
    }, 
    {
      pos: [2, 3, 15], 
      state: 5
    }, 
    {
      pos: [4, 3, 15], 
      state: 3
    }, 
    {
      pos: [1, 3, 16], 
      state: 5
    }, 
    {
      pos: [2, 3, 16], 
      state: 3
    }, 
    {
      pos: [3, 3, 16], 
      state: 3
    }, 
    {
      pos: [4, 3, 16], 
      state: 3
    }, 
    {
      pos: [1, 3, 17], 
      state: 3
    }, 
    {
      pos: [2, 3, 17], 
      state: 3
    }, 
    {
      pos: [3, 3, 17], 
      state: 3
    }, 
    {
      pos: [4, 3, 17], 
      state: 3
    }, 
    {
      pos: [0, 3, 18], 
      state: 3
    }, 
    {
      pos: [1, 3, 18], 
      state: 4
    }, 
    {
      pos: [2, 3, 18], 
      state: 3
    }, 
    {
      pos: [3, 3, 18], 
      state: 3
    }, 
    {
      pos: [4, 3, 18], 
      state: 3
    }, 
    {
      pos: [0, 3, 19], 
      state: 4
    }, 
    {
      pos: [1, 3, 19], 
      state: 4
    }, 
    {
      pos: [2, 3, 19], 
      state: 3
    }, 
    {
      pos: [3, 3, 19], 
      state: 3
    }, 
    {
      pos: [4, 3, 19], 
      state: 3
    }, 
    {
      pos: [0, 3, 20], 
      state: 3
    }, 
    {
      pos: [1, 3, 20], 
      state: 3
    }, 
    {
      pos: [2, 3, 20], 
      state: 3
    }, 
    {
      pos: [3, 3, 20], 
      state: 3
    }, 
    {
      pos: [4, 3, 20], 
      state: 3
    }, 
    {
      pos: [0, 3, 21], 
      state: 3
    }, 
    {
      pos: [1, 3, 21], 
      state: 3
    }, 
    {
      pos: [2, 3, 21], 
      state: 3
    }, 
    {
      pos: [3, 3, 21], 
      state: 3
    }, 
    {
      pos: [4, 3, 21], 
      state: 3
    }, 
    {
      pos: [1, 3, 22], 
      state: 3
    }, 
    {
      pos: [2, 3, 22], 
      state: 3
    }, 
    {
      pos: [3, 3, 22], 
      state: 3
    }, 
    {
      pos: [4, 3, 22], 
      state: 3
    }, 
    {
      pos: [1, 3, 23], 
      state: 3
    }, 
    {
      pos: [2, 3, 23], 
      state: 3
    }, 
    {
      pos: [3, 3, 23], 
      state: 3
    }, 
    {
      pos: [4, 3, 23], 
      state: 3
    }, 
    {
      pos: [0, 4, 8], 
      state: 3
    }, 
    {
      pos: [1, 4, 8], 
      state: 3
    }, 
    {
      pos: [2, 4, 8], 
      state: 3
    }, 
    {
      pos: [3, 4, 8], 
      state: 3
    }, 
    {
      pos: [4, 4, 8], 
      state: 3
    }, 
    {
      pos: [0, 4, 9], 
      state: 3
    }, 
    {
      pos: [1, 4, 9], 
      state: 3
    }, 
    {
      pos: [2, 4, 9], 
      state: 3
    }, 
    {
      pos: [3, 4, 9], 
      state: 3
    }, 
    {
      pos: [4, 4, 9], 
      state: 3
    }, 
    {
      pos: [0, 4, 10], 
      state: 3
    }, 
    {
      pos: [1, 4, 10], 
      state: 3
    }, 
    {
      pos: [2, 4, 10], 
      state: 3
    }, 
    {
      pos: [3, 4, 10], 
      state: 6
    }, 
    {
      pos: [4, 4, 10], 
      state: 3
    }, 
    {
      pos: [1, 4, 11], 
      state: 4
    }, 
    {
      pos: [2, 4, 11], 
      state: 4
    }, 
    {
      pos: [3, 4, 11], 
      state: 4
    }, 
    {
      pos: [4, 4, 11], 
      state: 3
    }, 
    {
      pos: [0, 4, 12], 
      state: 4
    }, 
    {
      pos: [1, 4, 12], 
      state: 4
    }, 
    {
      pos: [2, 4, 12], 
      state: 4
    }, 
    {
      pos: [3, 4, 12], 
      state: 4
    }, 
    {
      pos: [4, 4, 12], 
      state: 3
    }, 
    {
      pos: [0, 4, 13], 
      state: 3
    }, 
    {
      pos: [1, 4, 13], 
      state: 4
    }, 
    {
      pos: [2, 4, 13], 
      state: 4
    }, 
    {
      pos: [3, 4, 13], 
      state: 4
    }, 
    {
      pos: [4, 4, 13], 
      state: 3
    }, 
    {
      pos: [0, 4, 14], 
      state: 5
    }, 
    {
      pos: [1, 4, 14], 
      state: 5
    }, 
    {
      pos: [2, 4, 14], 
      state: 3
    }, 
    {
      pos: [3, 4, 14], 
      state: 6
    }, 
    {
      pos: [4, 4, 14], 
      state: 3
    }, 
    {
      pos: [1, 4, 15], 
      state: 5
    }, 
    {
      pos: [2, 4, 15], 
      state: 3
    }, 
    {
      pos: [3, 4, 15], 
      state: 3
    }, 
    {
      pos: [4, 4, 15], 
      state: 3
    }, 
    {
      pos: [1, 4, 16], 
      state: 3
    }, 
    {
      pos: [2, 4, 16], 
      state: 3
    }, 
    {
      pos: [3, 4, 16], 
      state: 3
    }, 
    {
      pos: [4, 4, 16], 
      state: 3
    }, 
    {
      pos: [0, 4, 17], 
      state: 3
    }, 
    {
      pos: [1, 4, 17], 
      state: 3
    }, 
    {
      pos: [2, 4, 17], 
      state: 3
    }, 
    {
      pos: [3, 4, 17], 
      state: 3
    }, 
    {
      pos: [4, 4, 17], 
      state: 3
    }, 
    {
      pos: [0, 4, 18], 
      state: 4
    }, 
    {
      pos: [1, 4, 18], 
      state: 4
    }, 
    {
      pos: [2, 4, 18], 
      state: 4
    }, 
    {
      pos: [3, 4, 18], 
      state: 3
    }, 
    {
      pos: [4, 4, 18], 
      state: 3
    }, 
    {
      pos: [0, 4, 19], 
      state: 4
    }, 
    {
      pos: [1, 4, 19], 
      state: 4
    }, 
    {
      pos: [2, 4, 19], 
      state: 4
    }, 
    {
      pos: [3, 4, 19], 
      state: 3
    }, 
    {
      pos: [4, 4, 19], 
      state: 3
    }, 
    {
      pos: [0, 4, 20], 
      state: 4
    }, 
    {
      pos: [1, 4, 20], 
      state: 4
    }, 
    {
      pos: [2, 4, 20], 
      state: 3
    }, 
    {
      pos: [3, 4, 20], 
      state: 3
    }, 
    {
      pos: [4, 4, 20], 
      state: 3
    }, 
    {
      pos: [0, 4, 21], 
      state: 3
    }, 
    {
      pos: [1, 4, 21], 
      state: 3
    }, 
    {
      pos: [2, 4, 21], 
      state: 3
    }, 
    {
      pos: [3, 4, 21], 
      state: 3
    }, 
    {
      pos: [4, 4, 21], 
      state: 3
    }, 
    {
      pos: [0, 4, 22], 
      state: 3
    }, 
    {
      pos: [1, 4, 22], 
      state: 3
    }, 
    {
      pos: [2, 4, 22], 
      state: 3
    }, 
    {
      pos: [3, 4, 22], 
      state: 3
    }, 
    {
      pos: [4, 4, 22], 
      state: 3
    }, 
    {
      pos: [0, 4, 23], 
      state: 3
    }, 
    {
      pos: [1, 4, 23], 
      state: 3
    }, 
    {
      pos: [2, 4, 23], 
      state: 3
    }, 
    {
      pos: [3, 4, 23], 
      state: 3
    }, 
    {
      pos: [4, 4, 23], 
      state: 3
    }, 
    {
      pos: [0, 5, 8], 
      state: 3
    }, 
    {
      pos: [1, 5, 8], 
      state: 3
    }, 
    {
      pos: [2, 5, 8], 
      state: 3
    }, 
    {
      pos: [3, 5, 8], 
      state: 3
    }, 
    {
      pos: [4, 5, 8], 
      state: 3
    }, 
    {
      pos: [0, 5, 9], 
      state: 3
    }, 
    {
      pos: [1, 5, 9], 
      state: 3
    }, 
    {
      pos: [2, 5, 9], 
      state: 3
    }, 
    {
      pos: [3, 5, 9], 
      state: 3
    }, 
    {
      pos: [4, 5, 9], 
      state: 3
    }, 
    {
      pos: [1, 5, 10], 
      state: 3
    }, 
    {
      pos: [2, 5, 10], 
      state: 3
    }, 
    {
      pos: [3, 5, 10], 
      state: 3
    }, 
    {
      pos: [4, 5, 10], 
      state: 3
    }, 
    {
      pos: [1, 5, 11], 
      state: 4
    }, 
    {
      pos: [2, 5, 11], 
      state: 4
    }, 
    {
      pos: [3, 5, 11], 
      state: 3
    }, 
    {
      pos: [4, 5, 11], 
      state: 3
    }, 
    {
      pos: [1, 5, 12], 
      state: 4
    }, 
    {
      pos: [2, 5, 12], 
      state: 4
    }, 
    {
      pos: [3, 5, 12], 
      state: 3
    }, 
    {
      pos: [4, 5, 12], 
      state: 3
    }, 
    {
      pos: [0, 5, 13], 
      state: 4
    }, 
    {
      pos: [1, 5, 13], 
      state: 4
    }, 
    {
      pos: [2, 5, 13], 
      state: 4
    }, 
    {
      pos: [3, 5, 13], 
      state: 3
    }, 
    {
      pos: [4, 5, 13], 
      state: 3
    }, 
    {
      pos: [0, 5, 14], 
      state: 3
    }, 
    {
      pos: [1, 5, 14], 
      state: 3
    }, 
    {
      pos: [2, 5, 14], 
      state: 3
    }, 
    {
      pos: [3, 5, 14], 
      state: 3
    }, 
    {
      pos: [4, 5, 14], 
      state: 3
    }, 
    {
      pos: [0, 5, 15], 
      state: 3
    }, 
    {
      pos: [1, 5, 15], 
      state: 3
    }, 
    {
      pos: [2, 5, 15], 
      state: 3
    }, 
    {
      pos: [3, 5, 15], 
      state: 3
    }, 
    {
      pos: [4, 5, 15], 
      state: 3
    }, 
    {
      pos: [3, 5, 16], 
      state: 3
    }, 
    {
      pos: [4, 5, 16], 
      state: 3
    }, 
    {
      pos: [0, 5, 21], 
      state: 3
    }, 
    {
      pos: [1, 5, 21], 
      state: 3
    }, 
    {
      pos: [2, 5, 21], 
      state: 3
    }, 
    {
      pos: [4, 5, 21], 
      state: 3
    }, 
    {
      pos: [0, 5, 22], 
      state: 3
    }, 
    {
      pos: [1, 5, 22], 
      state: 3
    }, 
    {
      pos: [2, 5, 22], 
      state: 3
    }, 
    {
      pos: [3, 5, 22], 
      state: 3
    }, 
    {
      pos: [4, 5, 22], 
      state: 3
    }, 
    {
      pos: [0, 5, 23], 
      state: 3
    }, 
    {
      pos: [1, 5, 23], 
      state: 3
    }, 
    {
      pos: [2, 5, 23], 
      state: 3
    }, 
    {
      pos: [3, 5, 23], 
      state: 3
    }, 
    {
      pos: [4, 5, 23], 
      state: 3
    }, 
    {
      pos: [0, 6, 8], 
      state: 3
    }, 
    {
      pos: [1, 6, 8], 
      state: 3
    }, 
    {
      pos: [2, 6, 8], 
      state: 3
    }, 
    {
      pos: [3, 6, 8], 
      state: 3
    }, 
    {
      pos: [4, 6, 8], 
      state: 3
    }, 
    {
      pos: [0, 6, 9], 
      state: 3
    }, 
    {
      pos: [1, 6, 9], 
      state: 3
    }, 
    {
      pos: [2, 6, 9], 
      state: 3
    }, 
    {
      pos: [3, 6, 9], 
      state: 3
    }, 
    {
      pos: [4, 6, 9], 
      state: 3
    }, 
    {
      pos: [1, 6, 10], 
      state: 3
    }, 
    {
      pos: [2, 6, 10], 
      state: 3
    }, 
    {
      pos: [3, 6, 10], 
      state: 3
    }, 
    {
      pos: [4, 6, 10], 
      state: 3
    }, 
    {
      pos: [0, 6, 14], 
      state: 3
    }, 
    {
      pos: [1, 6, 14], 
      state: 3
    }, 
    {
      pos: [2, 6, 14], 
      state: 3
    }, 
    {
      pos: [3, 6, 14], 
      state: 3
    }, 
    {
      pos: [4, 6, 14], 
      state: 3
    }, 
    {
      pos: [0, 6, 15], 
      state: 3
    }, 
    {
      pos: [1, 6, 15], 
      state: 3
    }, 
    {
      pos: [2, 6, 15], 
      state: 3
    }, 
    {
      pos: [3, 6, 15], 
      state: 3
    }, 
    {
      pos: [4, 6, 15], 
      state: 3
    }, 
    {
      pos: [0, 6, 21], 
      state: 3
    }, 
    {
      pos: [1, 6, 21], 
      state: 3
    }, 
    {
      pos: [2, 6, 21], 
      state: 3
    }, 
    {
      pos: [4, 6, 21], 
      state: 3
    }, 
    {
      pos: [0, 6, 22], 
      state: 3
    }, 
    {
      pos: [1, 6, 22], 
      state: 3
    }, 
    {
      pos: [2, 6, 22], 
      state: 3
    }, 
    {
      pos: [3, 6, 22], 
      state: 3
    }, 
    {
      pos: [4, 6, 22], 
      state: 3
    }, 
    {
      pos: [0, 6, 23], 
      state: 3
    }, 
    {
      pos: [1, 6, 23], 
      state: 3
    }, 
    {
      pos: [2, 6, 23], 
      state: 3
    }, 
    {
      pos: [3, 6, 23], 
      state: 3
    }, 
    {
      pos: [4, 6, 23], 
      state: 3
    }, 
    {
      pos: [0, 7, 8], 
      state: 3
    }, 
    {
      pos: [1, 7, 8], 
      state: 4
    }, 
    {
      pos: [2, 7, 8], 
      state: 3
    }, 
    {
      pos: [3, 7, 8], 
      state: 3
    }, 
    {
      pos: [4, 7, 8], 
      state: 4
    }, 
    {
      pos: [0, 7, 9], 
      state: 3
    }, 
    {
      pos: [1, 7, 9], 
      state: 3
    }, 
    {
      pos: [2, 7, 9], 
      state: 3
    }, 
    {
      pos: [3, 7, 9], 
      state: 3
    }, 
    {
      pos: [4, 7, 9], 
      state: 3
    }, 
    {
      pos: [1, 7, 10], 
      state: 3
    }, 
    {
      pos: [2, 7, 10], 
      state: 3
    }, 
    {
      pos: [3, 7, 10], 
      state: 3
    }, 
    {
      pos: [4, 7, 10], 
      state: 3
    }, 
    {
      pos: [0, 7, 14], 
      state: 3
    }, 
    {
      pos: [1, 7, 14], 
      state: 3
    }, 
    {
      pos: [2, 7, 14], 
      state: 3
    }, 
    {
      pos: [3, 7, 14], 
      state: 3
    }, 
    {
      pos: [4, 7, 14], 
      state: 3
    }, 
    {
      pos: [0, 7, 15], 
      state: 3
    }, 
    {
      pos: [1, 7, 15], 
      state: 3
    }, 
    {
      pos: [2, 7, 15], 
      state: 3
    }, 
    {
      pos: [3, 7, 15], 
      state: 3
    }, 
    {
      pos: [4, 7, 15], 
      state: 3
    }, 
    {
      pos: [0, 7, 16], 
      state: 3
    }, 
    {
      pos: [1, 7, 16], 
      state: 3
    }, 
    {
      pos: [2, 7, 16], 
      state: 3
    }, 
    {
      pos: [3, 7, 16], 
      state: 3
    }, 
    {
      pos: [4, 7, 16], 
      state: 3
    }, 
    {
      pos: [0, 7, 21], 
      state: 3
    }, 
    {
      pos: [1, 7, 21], 
      state: 3
    }, 
    {
      pos: [2, 7, 21], 
      state: 3
    }, 
    {
      pos: [4, 7, 21], 
      state: 3
    }, 
    {
      pos: [0, 7, 22], 
      state: 3
    }, 
    {
      pos: [1, 7, 22], 
      state: 3
    }, 
    {
      pos: [2, 7, 22], 
      state: 3
    }, 
    {
      pos: [3, 7, 22], 
      state: 3
    }, 
    {
      pos: [4, 7, 22], 
      state: 3
    }, 
    {
      pos: [0, 7, 23], 
      state: 3
    }, 
    {
      pos: [1, 7, 23], 
      state: 3
    }, 
    {
      pos: [2, 7, 23], 
      state: 3
    }, 
    {
      pos: [2, 8, 8], 
      state: 3
    }, 
    {
      pos: [3, 8, 8], 
      state: 4
    }, 
    {
      pos: [4, 8, 8], 
      state: 4
    }, 
    {
      pos: [1, 8, 9], 
      state: 4
    }, 
    {
      pos: [2, 8, 9], 
      state: 3
    }, 
    {
      pos: [3, 8, 9], 
      state: 3
    }, 
    {
      pos: [4, 8, 9], 
      state: 3
    }, 
    {
      pos: [0, 8, 10], 
      state: 4
    }, 
    {
      pos: [1, 8, 10], 
      state: 3
    }, 
    {
      pos: [2, 8, 10], 
      state: 3
    }, 
    {
      pos: [3, 8, 10], 
      state: 3
    }, 
    {
      pos: [4, 8, 10], 
      state: 3
    }, 
    {
      pos: [0, 8, 14], 
      state: 4
    }, 
    {
      pos: [1, 8, 14], 
      state: 3
    }, 
    {
      pos: [2, 8, 14], 
      state: 3
    }, 
    {
      pos: [3, 8, 14], 
      state: 3
    }, 
    {
      pos: [4, 8, 14], 
      state: 3
    }, 
    {
      pos: [0, 8, 15], 
      state: 3
    }, 
    {
      pos: [1, 8, 15], 
      state: 3
    }, 
    {
      pos: [2, 8, 15], 
      state: 3
    }, 
    {
      pos: [3, 8, 15], 
      state: 3
    }, 
    {
      pos: [4, 8, 15], 
      state: 3
    }, 
    {
      pos: [0, 8, 16], 
      state: 3
    }, 
    {
      pos: [1, 8, 16], 
      state: 4
    }, 
    {
      pos: [2, 8, 16], 
      state: 3
    }, 
    {
      pos: [3, 8, 16], 
      state: 3
    }, 
    {
      pos: [4, 8, 16], 
      state: 3
    }, 
    {
      pos: [4, 8, 17], 
      state: 3
    }, 
    {
      pos: [0, 8, 20], 
      state: 3
    }, 
    {
      pos: [1, 8, 20], 
      state: 3
    }, 
    {
      pos: [2, 8, 20], 
      state: 3
    }, 
    {
      pos: [3, 8, 20], 
      state: 3
    }, 
    {
      pos: [4, 8, 20], 
      state: 3
    }, 
    {
      pos: [0, 8, 21], 
      state: 3
    }, 
    {
      pos: [2, 8, 21], 
      state: 3
    }, 
    {
      pos: [3, 8, 21], 
      state: 3
    }, 
    {
      pos: [4, 8, 21], 
      state: 3
    }, 
    {
      pos: [0, 8, 22], 
      state: 3
    }, 
    {
      pos: [3, 8, 22], 
      state: 3
    }, 
    {
      pos: [4, 8, 22], 
      state: 3
    }, 
    {
      pos: [0, 8, 23], 
      state: 4
    }, 
    {
      pos: [1, 8, 23], 
      state: 4
    }, 
    {
      pos: [2, 8, 23], 
      state: 3
    }, 
    {
      pos: [3, 9, 8], 
      state: 4
    }, 
    {
      pos: [4, 9, 8], 
      state: 4
    }, 
    {
      pos: [3, 9, 9], 
      state: 3
    }, 
    {
      pos: [4, 9, 9], 
      state: 3
    }, 
    {
      pos: [3, 9, 10], 
      state: 3
    }, 
    {
      pos: [4, 9, 10], 
      state: 3
    }, 
    {
      pos: [0, 9, 14], 
      state: 4
    }, 
    {
      pos: [1, 9, 14], 
      state: 3
    }, 
    {
      pos: [2, 9, 14], 
      state: 3
    }, 
    {
      pos: [3, 9, 14], 
      state: 3
    }, 
    {
      pos: [4, 9, 14], 
      state: 3
    }, 
    {
      pos: [0, 9, 15], 
      state: 4
    }, 
    {
      pos: [1, 9, 15], 
      state: 3
    }, 
    {
      pos: [2, 9, 15], 
      state: 3
    }, 
    {
      pos: [3, 9, 15], 
      state: 3
    }, 
    {
      pos: [4, 9, 15], 
      state: 3
    }, 
    {
      pos: [0, 9, 16], 
      state: 3
    }, 
    {
      pos: [1, 9, 16], 
      state: 4
    }, 
    {
      pos: [2, 9, 16], 
      state: 3
    }, 
    {
      pos: [3, 9, 16], 
      state: 3
    }, 
    {
      pos: [4, 9, 16], 
      state: 3
    }, 
    {
      pos: [0, 9, 17], 
      state: 4
    }, 
    {
      pos: [1, 9, 17], 
      state: 3
    }, 
    {
      pos: [2, 9, 17], 
      state: 3
    }, 
    {
      pos: [3, 9, 17], 
      state: 6
    }, 
    {
      pos: [4, 9, 17], 
      state: 3
    }, 
    {
      pos: [0, 9, 18], 
      state: 3
    }, 
    {
      pos: [1, 9, 18], 
      state: 3
    }, 
    {
      pos: [2, 9, 18], 
      state: 3
    }, 
    {
      pos: [3, 9, 18], 
      state: 3
    }, 
    {
      pos: [4, 9, 18], 
      state: 3
    }, 
    {
      pos: [0, 9, 19], 
      state: 3
    }, 
    {
      pos: [1, 9, 19], 
      state: 3
    }, 
    {
      pos: [2, 9, 19], 
      state: 3
    }, 
    {
      pos: [3, 9, 19], 
      state: 3
    }, 
    {
      pos: [4, 9, 19], 
      state: 3
    }, 
    {
      pos: [0, 9, 20], 
      state: 3
    }, 
    {
      pos: [1, 9, 20], 
      state: 3
    }, 
    {
      pos: [2, 9, 20], 
      state: 3
    }, 
    {
      pos: [3, 9, 20], 
      state: 3
    }, 
    {
      pos: [4, 9, 20], 
      state: 3
    }, 
    {
      pos: [2, 9, 21], 
      state: 3
    }, 
    {
      pos: [3, 9, 21], 
      state: 3
    }, 
    {
      pos: [4, 9, 21], 
      state: 3
    }, 
    {
      pos: [2, 9, 22], 
      state: 3
    }, 
    {
      pos: [3, 9, 22], 
      state: 3
    }, 
    {
      pos: [4, 9, 22], 
      state: 3
    }, 
    {
      pos: [1, 9, 23], 
      state: 4
    }, 
    {
      pos: [2, 9, 23], 
      state: 4
    }, 
    {
      pos: [3, 10, 8], 
      state: 4
    }, 
    {
      pos: [4, 10, 8], 
      state: 4
    }, 
    {
      pos: [4, 10, 9], 
      state: 3
    }, 
    {
      pos: [3, 10, 10], 
      state: 3
    }, 
    {
      pos: [4, 10, 10], 
      state: 3
    }, 
    {
      pos: [0, 10, 11], 
      state: 3
    }, 
    {
      pos: [1, 10, 11], 
      state: 3
    }, 
    {
      pos: [2, 10, 11], 
      state: 3
    }, 
    {
      pos: [3, 10, 11], 
      state: 3
    }, 
    {
      pos: [4, 10, 11], 
      state: 3
    }, 
    {
      pos: [0, 10, 12], 
      state: 3
    }, 
    {
      pos: [1, 10, 12], 
      state: 3
    }, 
    {
      pos: [2, 10, 12], 
      state: 3
    }, 
    {
      pos: [3, 10, 12], 
      state: 3
    }, 
    {
      pos: [4, 10, 12], 
      state: 3
    }, 
    {
      pos: [0, 10, 13], 
      state: 3
    }, 
    {
      pos: [1, 10, 13], 
      state: 3
    }, 
    {
      pos: [2, 10, 13], 
      state: 3
    }, 
    {
      pos: [4, 10, 13], 
      state: 3
    }, 
    {
      pos: [0, 10, 14], 
      state: 4
    }, 
    {
      pos: [1, 10, 14], 
      state: 3
    }, 
    {
      pos: [2, 10, 14], 
      state: 3
    }, 
    {
      pos: [3, 10, 14], 
      state: 3
    }, 
    {
      pos: [4, 10, 14], 
      state: 3
    }, 
    {
      pos: [0, 10, 15], 
      state: 4
    }, 
    {
      pos: [1, 10, 15], 
      state: 3
    }, 
    {
      pos: [2, 10, 15], 
      state: 3
    }, 
    {
      pos: [3, 10, 15], 
      state: 3
    }, 
    {
      pos: [4, 10, 15], 
      state: 3
    }, 
    {
      pos: [0, 10, 16], 
      state: 4
    }, 
    {
      pos: [1, 10, 16], 
      state: 4
    }, 
    {
      pos: [2, 10, 16], 
      state: 3
    }, 
    {
      pos: [3, 10, 16], 
      state: 3
    }, 
    {
      pos: [4, 10, 16], 
      state: 3
    }, 
    {
      pos: [0, 10, 17], 
      state: 4
    }, 
    {
      pos: [1, 10, 17], 
      state: 4
    }, 
    {
      pos: [2, 10, 17], 
      state: 3
    }, 
    {
      pos: [3, 10, 17], 
      state: 6
    }, 
    {
      pos: [4, 10, 17], 
      state: 3
    }, 
    {
      pos: [0, 10, 18], 
      state: 4
    }, 
    {
      pos: [1, 10, 18], 
      state: 4
    }, 
    {
      pos: [2, 10, 18], 
      state: 3
    }, 
    {
      pos: [3, 10, 18], 
      state: 6
    }, 
    {
      pos: [4, 10, 18], 
      state: 3
    }, 
    {
      pos: [0, 10, 19], 
      state: 4
    }, 
    {
      pos: [1, 10, 19], 
      state: 3
    }, 
    {
      pos: [2, 10, 19], 
      state: 3
    }, 
    {
      pos: [3, 10, 19], 
      state: 6
    }, 
    {
      pos: [4, 10, 19], 
      state: 3
    }, 
    {
      pos: [0, 10, 20], 
      state: 3
    }, 
    {
      pos: [1, 10, 20], 
      state: 3
    }, 
    {
      pos: [2, 10, 20], 
      state: 3
    }, 
    {
      pos: [3, 10, 20], 
      state: 6
    }, 
    {
      pos: [4, 10, 20], 
      state: 3
    }, 
    {
      pos: [1, 10, 21], 
      state: 4
    }, 
    {
      pos: [2, 10, 21], 
      state: 3
    }, 
    {
      pos: [3, 10, 21], 
      state: 3
    }, 
    {
      pos: [4, 10, 21], 
      state: 3
    }, 
    {
      pos: [2, 10, 22], 
      state: 3
    }, 
    {
      pos: [3, 10, 22], 
      state: 3
    }, 
    {
      pos: [4, 10, 22], 
      state: 3
    }, 
    {
      pos: [3, 11, 8], 
      state: 4
    }, 
    {
      pos: [4, 11, 8], 
      state: 4
    }, 
    {
      pos: [3, 11, 9], 
      state: 4
    }, 
    {
      pos: [4, 11, 9], 
      state: 4
    }, 
    {
      pos: [3, 11, 10], 
      state: 5
    }, 
    {
      pos: [4, 11, 10], 
      state: 4
    }, 
    {
      pos: [0, 11, 11], 
      state: 4
    }, 
    {
      pos: [1, 11, 11], 
      state: 5
    }, 
    {
      pos: [3, 11, 11], 
      state: 5
    }, 
    {
      pos: [4, 11, 11], 
      state: 5
    }, 
    {
      pos: [0, 11, 12], 
      state: 4
    }, 
    {
      pos: [1, 11, 12], 
      state: 5
    }, 
    {
      pos: [2, 11, 12], 
      state: 5
    }, 
    {
      pos: [3, 11, 12], 
      state: 3
    }, 
    {
      pos: [4, 11, 12], 
      state: 3
    }, 
    {
      pos: [0, 11, 13], 
      state: 4
    }, 
    {
      pos: [1, 11, 13], 
      state: 5
    }, 
    {
      pos: [2, 11, 13], 
      state: 3
    }, 
    {
      pos: [3, 11, 13], 
      state: 3
    }, 
    {
      pos: [4, 11, 13], 
      state: 3
    }, 
    {
      pos: [0, 11, 14], 
      state: 4
    }, 
    {
      pos: [1, 11, 14], 
      state: 5
    }, 
    {
      pos: [2, 11, 14], 
      state: 5
    }, 
    {
      pos: [3, 11, 14], 
      state: 5
    }, 
    {
      pos: [4, 11, 14], 
      state: 3
    }, 
    {
      pos: [0, 11, 15], 
      state: 4
    }, 
    {
      pos: [1, 11, 15], 
      state: 5
    }, 
    {
      pos: [2, 11, 15], 
      state: 5
    }, 
    {
      pos: [3, 11, 15], 
      state: 3
    }, 
    {
      pos: [4, 11, 15], 
      state: 3
    }, 
    {
      pos: [0, 11, 16], 
      state: 4
    }, 
    {
      pos: [1, 11, 16], 
      state: 4
    }, 
    {
      pos: [2, 11, 16], 
      state: 4
    }, 
    {
      pos: [3, 11, 16], 
      state: 3
    }, 
    {
      pos: [4, 11, 16], 
      state: 3
    }, 
    {
      pos: [0, 11, 17], 
      state: 4
    }, 
    {
      pos: [1, 11, 17], 
      state: 4
    }, 
    {
      pos: [2, 11, 17], 
      state: 4
    }, 
    {
      pos: [3, 11, 17], 
      state: 3
    }, 
    {
      pos: [4, 11, 17], 
      state: 3
    }, 
    {
      pos: [0, 11, 18], 
      state: 4
    }, 
    {
      pos: [1, 11, 18], 
      state: 4
    }, 
    {
      pos: [2, 11, 18], 
      state: 4
    }, 
    {
      pos: [3, 11, 18], 
      state: 5
    }, 
    {
      pos: [4, 11, 18], 
      state: 5
    }, 
    {
      pos: [1, 11, 19], 
      state: 4
    }, 
    {
      pos: [2, 11, 19], 
      state: 5
    }, 
    {
      pos: [3, 11, 19], 
      state: 5
    }, 
    {
      pos: [4, 11, 19], 
      state: 5
    }, 
    {
      pos: [2, 11, 20], 
      state: 4
    }, 
    {
      pos: [3, 11, 20], 
      state: 5
    }, 
    {
      pos: [4, 11, 20], 
      state: 3
    }, 
    {
      pos: [2, 11, 21], 
      state: 4
    }, 
    {
      pos: [3, 11, 21], 
      state: 4
    }, 
    {
      pos: [4, 11, 21], 
      state: 3
    }, 
    {
      pos: [2, 11, 22], 
      state: 4
    }, 
    {
      pos: [3, 11, 22], 
      state: 4
    }, 
    {
      pos: [4, 11, 22], 
      state: 3
    }, 
    {
      pos: [4, 12, 11], 
      state: 5
    }, 
    {
      pos: [4, 12, 14], 
      state: 3
    }, 
    {
      pos: [3, 12, 15], 
      state: 5
    }, 
    {
      pos: [4, 12, 15], 
      state: 3
    }, 
    {
      pos: [3, 12, 16], 
      state: 3
    }, 
    {
      pos: [4, 12, 16], 
      state: 3
    }, 
    {
      pos: [3, 12, 17], 
      state: 5
    }, 
    {
      pos: [4, 12, 17], 
      state: 5
    }, 
    {
      pos: [4, 13, 14], 
      state: 3
    }, 
    {
      pos: [3, 13, 15], 
      state: 3
    }, 
    {
      pos: [4, 13, 15], 
      state: 3
    }, 
    {
      pos: [3, 13, 16], 
      state: 5
    }, 
    {
      pos: [4, 13, 16], 
      state: 3
    }, 
    {
      pos: [3, 13, 17], 
      state: 5
    }, 
    {
      pos: [3, 14, 14], 
      state: 3
    }, 
    {
      pos: [3, 14, 15], 
      state: 3
    }, 
    {
      pos: [4, 14, 15], 
      state: 3
    }, 
    {
      pos: [3, 14, 16], 
      state: 3
    }, 
    {
      pos: [4, 14, 16], 
      state: 3
    }, 
    {
      pos: [3, 14, 17], 
      state: 3
    }, 
    {
      pos: [4, 14, 17], 
      state: 3
    }, 
    {
      pos: [3, 15, 14], 
      state: 3
    }, 
    {
      pos: [4, 15, 14], 
      state: 3
    }, 
    {
      pos: [3, 15, 15], 
      state: 3
    }, 
    {
      pos: [4, 15, 15], 
      state: 3
    }, 
    {
      pos: [3, 15, 16], 
      state: 5
    }, 
    {
      pos: [4, 15, 16], 
      state: 3
    }, 
    {
      pos: [3, 15, 17], 
      state: 5
    }, 
    {
      pos: [4, 15, 17], 
      state: 3
    }, 
    {
      pos: [3, 16, 14], 
      state: 4
    }, 
    {
      pos: [4, 16, 14], 
      state: 3
    }, 
    {
      pos: [3, 16, 15], 
      state: 3
    }, 
    {
      pos: [4, 16, 15], 
      state: 3
    }, 
    {
      pos: [3, 16, 16], 
      state: 5
    }, 
    {
      pos: [4, 16, 16], 
      state: 5
    }, 
    {
      pos: [3, 17, 14], 
      state: 4
    }, 
    {
      pos: [4, 17, 14], 
      state: 3
    }, 
    {
      pos: [3, 17, 15], 
      state: 3
    }, 
    {
      pos: [4, 17, 15], 
      state: 3
    }, 
    {
      pos: [3, 17, 16], 
      state: 3
    }, 
    {
      pos: [4, 17, 16], 
      state: 3
    }, 
    {
      pos: [4, 17, 17], 
      state: 5
    }, 
    {
      pos: [4, 18, 0], 
      state: 3
    }, 
    {
      pos: [4, 18, 1], 
      state: 3
    }, 
    {
      pos: [4, 18, 2], 
      state: 3
    }, 
    {
      pos: [4, 18, 9], 
      state: 3
    }, 
    {
      pos: [4, 18, 10], 
      state: 3
    }, 
    {
      pos: [4, 18, 11], 
      state: 3
    }, 
    {
      pos: [4, 18, 12], 
      state: 3
    }, 
    {
      pos: [4, 18, 13], 
      state: 3
    }, 
    {
      pos: [3, 18, 14], 
      state: 4
    }, 
    {
      pos: [4, 18, 14], 
      state: 3
    }, 
    {
      pos: [3, 18, 15], 
      state: 3
    }, 
    {
      pos: [4, 18, 15], 
      state: 3
    }, 
    {
      pos: [3, 18, 16], 
      state: 3
    }, 
    {
      pos: [4, 18, 16], 
      state: 3
    }, 
    {
      pos: [4, 18, 17], 
      state: 3
    }, 
    {
      pos: [4, 18, 18], 
      state: 3
    }, 
    {
      pos: [4, 18, 19], 
      state: 3
    }, 
    {
      pos: [4, 18, 20], 
      state: 3
    }, 
    {
      pos: [4, 18, 21], 
      state: 3
    }, 
    {
      pos: [4, 18, 22], 
      state: 3
    }, 
    {
      pos: [4, 18, 23], 
      state: 3
    }, 
    {
      pos: [4, 18, 24], 
      state: 3
    }, 
    {
      pos: [4, 18, 25], 
      state: 4
    }, 
    {
      pos: [4, 19, 0], 
      state: 5
    }, 
    {
      pos: [4, 19, 9], 
      state: 3
    }, 
    {
      pos: [4, 19, 10], 
      state: 3
    }, 
    {
      pos: [4, 19, 11], 
      state: 3
    }, 
    {
      pos: [4, 19, 12], 
      state: 4
    }, 
    {
      pos: [4, 19, 13], 
      state: 4
    }, 
    {
      pos: [3, 19, 14], 
      state: 4
    }, 
    {
      pos: [4, 19, 14], 
      state: 3
    }, 
    {
      pos: [3, 19, 15], 
      state: 3
    }, 
    {
      pos: [4, 19, 15], 
      state: 3
    }, 
    {
      pos: [3, 19, 16], 
      state: 3
    }, 
    {
      pos: [4, 19, 16], 
      state: 3
    }, 
    {
      pos: [3, 19, 17], 
      state: 3
    }, 
    {
      pos: [4, 19, 17], 
      state: 3
    }, 
    {
      pos: [4, 19, 18], 
      state: 3
    }, 
    {
      pos: [4, 19, 19], 
      state: 5
    }, 
    {
      pos: [4, 19, 21], 
      state: 5
    }, 
    {
      pos: [4, 19, 22], 
      state: 5
    }, 
    {
      pos: [4, 19, 23], 
      state: 4
    }, 
    {
      pos: [4, 19, 24], 
      state: 5
    }, 
    {
      pos: [4, 19, 25], 
      state: 4
    }, 
    {
      pos: [4, 20, 9], 
      state: 3
    }, 
    {
      pos: [4, 20, 10], 
      state: 4
    }, 
    {
      pos: [4, 20, 11], 
      state: 3
    }, 
    {
      pos: [4, 20, 12], 
      state: 4
    }, 
    {
      pos: [4, 20, 13], 
      state: 4
    }, 
    {
      pos: [3, 20, 14], 
      state: 4
    }, 
    {
      pos: [4, 20, 14], 
      state: 3
    }, 
    {
      pos: [3, 20, 15], 
      state: 3
    }, 
    {
      pos: [4, 20, 15], 
      state: 3
    }, 
    {
      pos: [3, 20, 16], 
      state: 4
    }, 
    {
      pos: [4, 20, 16], 
      state: 3
    }, 
    {
      pos: [3, 20, 17], 
      state: 3
    }, 
    {
      pos: [4, 20, 17], 
      state: 3
    }, 
    {
      pos: [4, 20, 18], 
      state: 5
    }, 
    {
      pos: [4, 20, 19], 
      state: 4
    }, 
    {
      pos: [4, 20, 20], 
      state: 5
    }, 
    {
      pos: [4, 20, 21], 
      state: 5
    }, 
    {
      pos: [4, 20, 22], 
      state: 4
    }, 
    {
      pos: [4, 20, 23], 
      state: 0
    }, 
    {
      pos: [4, 20, 24], 
      state: 4
    }, 
    {
      pos: [4, 20, 25], 
      state: 4
    }, 
    {
      pos: [4, 21, 8], 
      state: 4
    }, 
    {
      pos: [4, 21, 9], 
      state: 3
    }, 
    {
      pos: [4, 21, 10], 
      state: 4
    }, 
    {
      pos: [4, 21, 11], 
      state: 4
    }, 
    {
      pos: [4, 21, 12], 
      state: 4
    }, 
    {
      pos: [4, 21, 13], 
      state: 4
    }, 
    {
      pos: [3, 21, 14], 
      state: 4
    }, 
    {
      pos: [4, 21, 14], 
      state: 3
    }, 
    {
      pos: [3, 21, 15], 
      state: 3
    }, 
    {
      pos: [4, 21, 15], 
      state: 3
    }, 
    {
      pos: [3, 21, 16], 
      state: 4
    }, 
    {
      pos: [4, 21, 16], 
      state: 3
    }, 
    {
      pos: [3, 21, 17], 
      state: 4
    }, 
    {
      pos: [4, 21, 17], 
      state: 3
    }, 
    {
      pos: [4, 21, 18], 
      state: 4
    }, 
    {
      pos: [4, 21, 19], 
      state: 4
    }, 
    {
      pos: [4, 21, 20], 
      state: 4
    }, 
    {
      pos: [4, 21, 21], 
      state: 4
    }, 
    {
      pos: [4, 21, 22], 
      state: 4
    }, 
    {
      pos: [4, 21, 23], 
      state: 4
    }, 
    {
      pos: [4, 21, 24], 
      state: 4
    }, 
    {
      pos: [4, 22, 9], 
      state: 4
    }, 
    {
      pos: [4, 22, 10], 
      state: 4
    }, 
    {
      pos: [3, 22, 14], 
      state: 4
    }, 
    {
      pos: [4, 22, 14], 
      state: 4
    }, 
    {
      pos: [3, 22, 15], 
      state: 4
    }, 
    {
      pos: [4, 22, 15], 
      state: 3
    }, 
    {
      pos: [3, 22, 16], 
      state: 4
    }, 
    {
      pos: [4, 22, 16], 
      state: 3
    }, 
    {
      pos: [3, 22, 17], 
      state: 4
    }, 
    {
      pos: [4, 22, 17], 
      state: 3
    }, 
    {
      pos: [4, 22, 21], 
      state: 4
    }, 
    {
      pos: [4, 22, 22], 
      state: 4
    }, 
    {
      pos: [3, 23, 14], 
      state: 4
    }, 
    {
      pos: [4, 23, 14], 
      state: 4
    }, 
    {
      pos: [3, 23, 15], 
      state: 4
    }, 
    {
      pos: [4, 23, 15], 
      state: 5
    }, 
    {
      pos: [3, 23, 16], 
      state: 4
    }, 
    {
      pos: [4, 23, 16], 
      state: 5
    }, 
    {
      pos: [3, 23, 17], 
      state: 5
    }, 
    {
      pos: [4, 23, 17], 
      state: 3
    }
  ], 
  palette: [
    {
      Properties: {
        axis: "y"
      }, 
      Name: "minecraft:polished_basalt"
    }, 
    {
      Properties: {
        orientation: "east_up"
      }, 
      Name: "minecraft:jigsaw"
    }, 
    {
      Name: "minecraft:air"
    }, 
    {
      Name: "minecraft:polished_blackstone_bricks"
    }, 
    {
      Properties: {
        axis: "y"
      }, 
      Name: "minecraft:basalt"
    }, 
    {
      Name: "minecraft:blackstone"
    }, 
    {
      Name: "minecraft:netherrack"
    }
  ]
}
