{
  size: [15, 6, 15], 
  entities: [], 
  blocks: [
    {
      pos: [3, 0, 0], 
      state: 0
    }, 
    {
      pos: [4, 0, 0], 
      state: 1
    }, 
    {
      pos: [5, 0, 0], 
      state: 0
    }, 
    {
      pos: [6, 0, 0], 
      state: 0
    }, 
    {
      pos: [7, 0, 0], 
      state: 1
    }, 
    {
      pos: [8, 0, 0], 
      state: 0
    }, 
    {
      pos: [9, 0, 0], 
      state: 0
    }, 
    {
      pos: [1, 0, 1], 
      state: 0
    }, 
    {
      pos: [2, 0, 1], 
      state: 0
    }, 
    {
      pos: [3, 0, 1], 
      state: 0
    }, 
    {
      pos: [4, 0, 1], 
      state: 1
    }, 
    {
      pos: [5, 0, 1], 
      state: 1
    }, 
    {
      pos: [6, 0, 1], 
      state: 1
    }, 
    {
      pos: [7, 0, 1], 
      state: 1
    }, 
    {
      pos: [8, 0, 1], 
      state: 0
    }, 
    {
      pos: [9, 0, 1], 
      state: 0
    }, 
    {
      pos: [11, 0, 1], 
      state: 0
    }, 
    {
      pos: [1, 0, 2], 
      state: 0
    }, 
    {
      pos: [2, 0, 2], 
      state: 0
    }, 
    {
      pos: [3, 0, 2], 
      state: 0
    }, 
    {
      pos: [4, 0, 2], 
      state: 1
    }, 
    {
      pos: [5, 0, 2], 
      state: 0
    }, 
    {
      pos: [6, 0, 2], 
      state: 0
    }, 
    {
      pos: [7, 0, 2], 
      state: 1
    }, 
    {
      pos: [8, 0, 2], 
      state: 0
    }, 
    {
      pos: [9, 0, 2], 
      state: 0
    }, 
    {
      pos: [10, 0, 2], 
      state: 0
    }, 
    {
      pos: [11, 0, 2], 
      state: 0
    }, 
    {
      pos: [0, 0, 3], 
      state: 0
    }, 
    {
      pos: [1, 0, 3], 
      state: 0
    }, 
    {
      pos: [2, 0, 3], 
      state: 0
    }, 
    {
      pos: [3, 0, 3], 
      state: 0
    }, 
    {
      pos: [4, 0, 3], 
      state: 1
    }, 
    {
      pos: [5, 0, 3], 
      state: 1
    }, 
    {
      pos: [6, 0, 3], 
      state: 1
    }, 
    {
      pos: [7, 0, 3], 
      state: 1
    }, 
    {
      pos: [8, 0, 3], 
      state: 0
    }, 
    {
      pos: [9, 0, 3], 
      state: 0
    }, 
    {
      pos: [10, 0, 3], 
      state: 0
    }, 
    {
      pos: [11, 0, 3], 
      state: 0
    }, 
    {
      pos: [0, 0, 4], 
      state: 0
    }, 
    {
      pos: [1, 0, 4], 
      state: 1
    }, 
    {
      pos: [2, 0, 4], 
      state: 1
    }, 
    {
      pos: [3, 0, 4], 
      state: 1
    }, 
    {
      pos: [4, 0, 4], 
      state: 1
    }, 
    {
      pos: [5, 0, 4], 
      state: 1
    }, 
    {
      pos: [6, 0, 4], 
      state: 1
    }, 
    {
      pos: [7, 0, 4], 
      state: 1
    }, 
    {
      pos: [8, 0, 4], 
      state: 0
    }, 
    {
      pos: [9, 0, 4], 
      state: 0
    }, 
    {
      pos: [10, 0, 4], 
      state: 0
    }, 
    {
      pos: [11, 0, 4], 
      state: 0
    }, 
    {
      pos: [12, 0, 4], 
      state: 0
    }, 
    {
      pos: [13, 0, 4], 
      state: 0
    }, 
    {
      pos: [0, 0, 5], 
      state: 0
    }, 
    {
      pos: [1, 0, 5], 
      state: 1
    }, 
    {
      pos: [2, 0, 5], 
      state: 0
    }, 
    {
      pos: [3, 0, 5], 
      state: 0
    }, 
    {
      pos: [4, 0, 5], 
      state: 0
    }, 
    {
      pos: [5, 0, 5], 
      state: 0
    }, 
    {
      pos: [6, 0, 5], 
      state: 1
    }, 
    {
      pos: [7, 0, 5], 
      state: 0
    }, 
    {
      pos: [9, 0, 5], 
      state: 0
    }, 
    {
      pos: [10, 0, 5], 
      state: 0
    }, 
    {
      pos: [11, 0, 5], 
      state: 0
    }, 
    {
      pos: [12, 0, 5], 
      state: 0
    }, 
    {
      pos: [13, 0, 5], 
      state: 0
    }, 
    {
      pos: [0, 0, 6], 
      state: 1
    }, 
    {
      pos: [1, 0, 6], 
      state: 1
    }, 
    {
      pos: [2, 0, 6], 
      state: 0
    }, 
    {
      pos: [3, 0, 6], 
      state: 1
    }, 
    {
      pos: [4, 0, 6], 
      state: 1
    }, 
    {
      pos: [5, 0, 6], 
      state: 0
    }, 
    {
      pos: [6, 0, 6], 
      state: 1
    }, 
    {
      pos: [7, 0, 6], 
      state: 0
    }, 
    {
      pos: [8, 0, 6], 
      state: 0
    }, 
    {
      pos: [9, 0, 6], 
      state: 0
    }, 
    {
      pos: [10, 0, 6], 
      state: 0
    }, 
    {
      pos: [11, 0, 6], 
      state: 0
    }, 
    {
      pos: [12, 0, 6], 
      state: 0
    }, 
    {
      pos: [13, 0, 6], 
      state: 0
    }, 
    {
      pos: [0, 0, 7], 
      state: 0
    }, 
    {
      pos: [1, 0, 7], 
      state: 1
    }, 
    {
      pos: [2, 0, 7], 
      state: 0
    }, 
    {
      pos: [3, 0, 7], 
      state: 1
    }, 
    {
      pos: [4, 0, 7], 
      state: 1
    }, 
    {
      pos: [5, 0, 7], 
      state: 0
    }, 
    {
      pos: [6, 0, 7], 
      state: 1
    }, 
    {
      pos: [7, 0, 7], 
      state: 0
    }, 
    {
      pos: [8, 0, 7], 
      state: 0
    }, 
    {
      pos: [9, 0, 7], 
      state: 0
    }, 
    {
      pos: [10, 0, 7], 
      state: 0
    }, 
    {
      pos: [11, 0, 7], 
      state: 0
    }, 
    {
      pos: [12, 0, 7], 
      state: 0
    }, 
    {
      pos: [13, 0, 7], 
      state: 0
    }, 
    {
      pos: [14, 0, 7], 
      state: 0
    }, 
    {
      pos: [0, 0, 8], 
      state: 1
    }, 
    {
      pos: [1, 0, 8], 
      state: 1
    }, 
    {
      pos: [2, 0, 8], 
      state: 0
    }, 
    {
      pos: [3, 0, 8], 
      state: 0
    }, 
    {
      pos: [4, 0, 8], 
      state: 0
    }, 
    {
      pos: [5, 0, 8], 
      state: 0
    }, 
    {
      pos: [6, 0, 8], 
      state: 1
    }, 
    {
      pos: [7, 0, 8], 
      state: 0
    }, 
    {
      pos: [8, 0, 8], 
      state: 0
    }, 
    {
      pos: [9, 0, 8], 
      state: 0
    }, 
    {
      pos: [10, 0, 8], 
      state: 0
    }, 
    {
      pos: [11, 0, 8], 
      state: 0
    }, 
    {
      pos: [12, 0, 8], 
      state: 0
    }, 
    {
      pos: [13, 0, 8], 
      state: 0
    }, 
    {
      pos: [14, 0, 8], 
      state: 0
    }, 
    {
      pos: [0, 0, 9], 
      state: 0
    }, 
    {
      pos: [1, 0, 9], 
      state: 1
    }, 
    {
      pos: [2, 0, 9], 
      state: 1
    }, 
    {
      pos: [3, 0, 9], 
      state: 1
    }, 
    {
      pos: [4, 0, 9], 
      state: 1
    }, 
    {
      pos: [5, 0, 9], 
      state: 1
    }, 
    {
      pos: [6, 0, 9], 
      state: 1
    }, 
    {
      pos: [7, 0, 9], 
      state: 0
    }, 
    {
      pos: [8, 0, 9], 
      state: 0
    }, 
    {
      pos: [9, 0, 9], 
      state: 0
    }, 
    {
      pos: [10, 0, 9], 
      state: 0
    }, 
    {
      pos: [11, 0, 9], 
      state: 0
    }, 
    {
      pos: [12, 0, 9], 
      state: 0
    }, 
    {
      pos: [13, 0, 9], 
      state: 0
    }, 
    {
      pos: [14, 0, 9], 
      state: 0
    }, 
    {
      pos: [0, 0, 10], 
      state: 0
    }, 
    {
      pos: [1, 0, 10], 
      state: 0
    }, 
    {
      pos: [2, 0, 10], 
      state: 0
    }, 
    {
      pos: [4, 0, 10], 
      state: 0
    }, 
    {
      pos: [5, 0, 10], 
      state: 0
    }, 
    {
      pos: [7, 0, 10], 
      state: 0
    }, 
    {
      pos: [8, 0, 10], 
      state: 0
    }, 
    {
      pos: [9, 0, 10], 
      state: 0
    }, 
    {
      pos: [10, 0, 10], 
      state: 0
    }, 
    {
      pos: [11, 0, 10], 
      state: 0
    }, 
    {
      pos: [12, 0, 10], 
      state: 0
    }, 
    {
      pos: [13, 0, 10], 
      state: 0
    }, 
    {
      pos: [14, 0, 10], 
      state: 0
    }, 
    {
      pos: [0, 0, 11], 
      state: 0
    }, 
    {
      pos: [1, 0, 11], 
      state: 0
    }, 
    {
      pos: [2, 0, 11], 
      state: 0
    }, 
    {
      pos: [3, 0, 11], 
      state: 0
    }, 
    {
      pos: [5, 0, 11], 
      state: 0
    }, 
    {
      pos: [6, 0, 11], 
      state: 0
    }, 
    {
      pos: [7, 0, 11], 
      state: 0
    }, 
    {
      pos: [8, 0, 11], 
      state: 0
    }, 
    {
      pos: [9, 0, 11], 
      state: 0
    }, 
    {
      pos: [10, 0, 11], 
      state: 0
    }, 
    {
      pos: [11, 0, 11], 
      state: 0
    }, 
    {
      pos: [12, 0, 11], 
      state: 0
    }, 
    {
      pos: [14, 0, 11], 
      state: 0
    }, 
    {
      pos: [1, 0, 12], 
      state: 0
    }, 
    {
      pos: [3, 0, 12], 
      state: 0
    }, 
    {
      pos: [4, 0, 12], 
      state: 0
    }, 
    {
      pos: [5, 0, 12], 
      state: 0
    }, 
    {
      pos: [6, 0, 12], 
      state: 0
    }, 
    {
      pos: [7, 0, 12], 
      state: 0
    }, 
    {
      pos: [8, 0, 12], 
      state: 0
    }, 
    {
      pos: [9, 0, 12], 
      state: 0
    }, 
    {
      pos: [10, 0, 12], 
      state: 0
    }, 
    {
      pos: [11, 0, 12], 
      state: 0
    }, 
    {
      pos: [12, 0, 12], 
      state: 0
    }, 
    {
      pos: [13, 0, 12], 
      state: 0
    }, 
    {
      pos: [14, 0, 12], 
      state: 0
    }, 
    {
      pos: [2, 0, 13], 
      state: 0
    }, 
    {
      pos: [3, 0, 13], 
      state: 0
    }, 
    {
      pos: [4, 0, 13], 
      state: 0
    }, 
    {
      pos: [5, 0, 13], 
      state: 0
    }, 
    {
      pos: [6, 0, 13], 
      state: 0
    }, 
    {
      pos: [7, 0, 13], 
      state: 0
    }, 
    {
      pos: [8, 0, 13], 
      state: 0
    }, 
    {
      pos: [9, 0, 13], 
      state: 0
    }, 
    {
      pos: [10, 0, 13], 
      state: 0
    }, 
    {
      pos: [11, 0, 13], 
      state: 0
    }, 
    {
      pos: [5, 0, 14], 
      state: 0
    }, 
    {
      pos: [6, 0, 14], 
      state: 0
    }, 
    {
      pos: [7, 0, 14], 
      state: 0
    }, 
    {
      pos: [8, 0, 14], 
      state: 0
    }, 
    {
      pos: [9, 0, 14], 
      state: 0
    }, 
    {
      pos: [10, 0, 14], 
      state: 0
    }, 
    {
      pos: [12, 0, 14], 
      state: 0
    }, 
    {
      pos: [13, 0, 14], 
      state: 0
    }, 
    {
      nbt: {
        final_state: "minecraft:sand", 
        name: "minecraft:bottom", 
        pool: "minecraft:village/desert/decor", 
        id: "minecraft:jigsaw", 
        target: "minecraft:bottom"
      }, 
      pos: [1, 0, 0], 
      state: 2
    }, 
    {
      nbt: {
        final_state: "minecraft:sand", 
        name: "minecraft:bottom", 
        pool: "minecraft:village/desert/villagers", 
        id: "minecraft:jigsaw", 
        target: "minecraft:bottom"
      }, 
      pos: [8, 0, 5], 
      state: 2
    }, 
    {
      nbt: {
        final_state: "minecraft:sand", 
        name: "minecraft:bottom", 
        pool: "minecraft:village/desert/villagers", 
        id: "minecraft:jigsaw", 
        target: "minecraft:bottom"
      }, 
      pos: [3, 0, 10], 
      state: 2
    }, 
    {
      nbt: {
        final_state: "minecraft:sand", 
        name: "minecraft:bottom", 
        pool: "minecraft:village/desert/villagers", 
        id: "minecraft:jigsaw", 
        target: "minecraft:bottom"
      }, 
      pos: [6, 0, 10], 
      state: 2
    }, 
    {
      nbt: {
        final_state: "minecraft:sand", 
        name: "minecraft:bottom", 
        pool: "minecraft:village/common/iron_golem", 
        id: "minecraft:jigsaw", 
        target: "minecraft:bottom"
      }, 
      pos: [4, 0, 11], 
      state: 2
    }, 
    {
      nbt: {
        final_state: "minecraft:sand", 
        name: "minecraft:bottom", 
        pool: "minecraft:village/desert/decor", 
        id: "minecraft:jigsaw", 
        target: "minecraft:bottom"
      }, 
      pos: [13, 0, 11], 
      state: 2
    }, 
    {
      nbt: {
        final_state: "minecraft:sand", 
        name: "minecraft:bottom", 
        pool: "minecraft:village/desert/decor", 
        id: "minecraft:jigsaw", 
        target: "minecraft:bottom"
      }, 
      pos: [2, 0, 12], 
      state: 2
    }, 
    {
      pos: [5, 1, 0], 
      state: 3
    }, 
    {
      pos: [6, 1, 0], 
      state: 4
    }, 
    {
      pos: [9, 1, 0], 
      state: 5
    }, 
    {
      pos: [5, 1, 2], 
      state: 6
    }, 
    {
      pos: [6, 1, 2], 
      state: 7
    }, 
    {
      pos: [11, 1, 2], 
      state: 8
    }, 
    {
      pos: [0, 1, 3], 
      state: 9
    }, 
    {
      pos: [2, 1, 5], 
      state: 9
    }, 
    {
      pos: [3, 1, 5], 
      state: 1
    }, 
    {
      pos: [4, 1, 5], 
      state: 1
    }, 
    {
      pos: [5, 1, 5], 
      state: 9
    }, 
    {
      pos: [2, 1, 6], 
      state: 1
    }, 
    {
      pos: [5, 1, 6], 
      state: 1
    }, 
    {
      pos: [10, 1, 6], 
      state: 9
    }, 
    {
      pos: [11, 1, 6], 
      state: 9
    }, 
    {
      pos: [12, 1, 6], 
      state: 9
    }, 
    {
      pos: [2, 1, 7], 
      state: 1
    }, 
    {
      pos: [5, 1, 7], 
      state: 1
    }, 
    {
      pos: [2, 1, 8], 
      state: 9
    }, 
    {
      pos: [3, 1, 8], 
      state: 1
    }, 
    {
      pos: [4, 1, 8], 
      state: 1
    }, 
    {
      pos: [5, 1, 8], 
      state: 9
    }, 
    {
      pos: [8, 1, 12], 
      state: 3
    }, 
    {
      pos: [9, 1, 12], 
      state: 4
    }, 
    {
      pos: [8, 1, 13], 
      state: 6
    }, 
    {
      pos: [9, 1, 13], 
      state: 7
    }, 
    {
      nbt: {
        final_state: "minecraft:structure_void", 
        name: "minecraft:bottom", 
        pool: "minecraft:village/common/cats", 
        id: "minecraft:jigsaw", 
        target: "minecraft:bottom"
      }, 
      pos: [6, 1, 4], 
      state: 2
    }, 
    {
      nbt: {
        final_state: "minecraft:structure_void", 
        name: "minecraft:street", 
        pool: "minecraft:village/desert/streets", 
        id: "minecraft:jigsaw", 
        target: "minecraft:street"
      }, 
      pos: [0, 1, 7], 
      state: 10
    }, 
    {
      nbt: {
        final_state: "minecraft:structure_void", 
        name: "minecraft:street", 
        pool: "minecraft:village/desert/streets", 
        id: "minecraft:jigsaw", 
        target: "minecraft:street"
      }, 
      pos: [14, 1, 8], 
      state: 11
    }, 
    {
      nbt: {
        final_state: "minecraft:structure_void", 
        name: "minecraft:bottom", 
        pool: "minecraft:village/common/cats", 
        id: "minecraft:jigsaw", 
        target: "minecraft:bottom"
      }, 
      pos: [9, 1, 9], 
      state: 2
    }, 
    {
      nbt: {
        final_state: "minecraft:structure_void", 
        name: "minecraft:street", 
        pool: "minecraft:village/desert/streets", 
        id: "minecraft:jigsaw", 
        target: "minecraft:street"
      }, 
      pos: [12, 1, 14], 
      state: 12
    }, 
    {
      pos: [4, 1, 0], 
      state: 13
    }, 
    {
      pos: [7, 1, 0], 
      state: 14
    }, 
    {
      pos: [4, 1, 2], 
      state: 13
    }, 
    {
      pos: [7, 1, 2], 
      state: 14
    }, 
    {
      pos: [5, 1, 4], 
      state: 15
    }, 
    {
      pos: [13, 1, 4], 
      state: 16
    }, 
    {
      pos: [9, 1, 5], 
      state: 17
    }, 
    {
      pos: [10, 1, 5], 
      state: 16
    }, 
    {
      pos: [12, 1, 5], 
      state: 16
    }, 
    {
      pos: [13, 1, 5], 
      state: 17
    }, 
    {
      pos: [3, 1, 6], 
      state: 18
    }, 
    {
      pos: [4, 1, 6], 
      state: 18
    }, 
    {
      pos: [9, 1, 6], 
      state: 19
    }, 
    {
      pos: [13, 1, 6], 
      state: 20
    }, 
    {
      pos: [3, 1, 7], 
      state: 18
    }, 
    {
      pos: [4, 1, 7], 
      state: 18
    }, 
    {
      pos: [9, 1, 7], 
      state: 17
    }, 
    {
      pos: [11, 1, 7], 
      state: 21
    }, 
    {
      pos: [12, 1, 7], 
      state: 16
    }, 
    {
      pos: [13, 1, 7], 
      state: 17
    }, 
    {
      pos: [14, 1, 7], 
      state: 21
    }, 
    {
      pos: [6, 1, 8], 
      state: 15
    }, 
    {
      pos: [7, 1, 11], 
      state: 17
    }, 
    {
      pos: [10, 1, 11], 
      state: 17
    }, 
    {
      pos: [7, 1, 14], 
      state: 17
    }, 
    {
      pos: [10, 1, 14], 
      state: 17
    }, 
    {
      pos: [0, 2, 3], 
      state: 9
    }, 
    {
      pos: [4, 2, 0], 
      state: 17
    }, 
    {
      pos: [7, 2, 0], 
      state: 17
    }, 
    {
      pos: [4, 2, 2], 
      state: 17
    }, 
    {
      pos: [5, 2, 2], 
      state: 21
    }, 
    {
      pos: [7, 2, 2], 
      state: 17
    }, 
    {
      pos: [2, 2, 5], 
      state: 22
    }, 
    {
      pos: [5, 2, 5], 
      state: 22
    }, 
    {
      pos: [9, 2, 5], 
      state: 17
    }, 
    {
      pos: [13, 2, 5], 
      state: 17
    }, 
    {
      pos: [10, 2, 6], 
      state: 21
    }, 
    {
      pos: [11, 2, 6], 
      state: 16
    }, 
    {
      pos: [12, 2, 6], 
      state: 21
    }, 
    {
      pos: [1, 2, 7], 
      state: 15
    }, 
    {
      pos: [9, 2, 7], 
      state: 17
    }, 
    {
      pos: [13, 2, 7], 
      state: 17
    }, 
    {
      pos: [2, 2, 8], 
      state: 22
    }, 
    {
      pos: [5, 2, 8], 
      state: 22
    }, 
    {
      pos: [6, 2, 9], 
      state: 15
    }, 
    {
      pos: [3, 2, 11], 
      state: 15
    }, 
    {
      pos: [7, 2, 11], 
      state: 17
    }, 
    {
      pos: [10, 2, 11], 
      state: 17
    }, 
    {
      pos: [7, 2, 14], 
      state: 17
    }, 
    {
      pos: [10, 2, 14], 
      state: 17
    }, 
    {
      pos: [0, 3, 3], 
      state: 23
    }, 
    {
      nbt: {
        id: "minecraft:bell"
      }, 
      pos: [6, 3, 2], 
      state: 24
    }, 
    {
      pos: [4, 3, 0], 
      state: 17
    }, 
    {
      pos: [7, 3, 0], 
      state: 17
    }, 
    {
      pos: [4, 3, 2], 
      state: 17
    }, 
    {
      pos: [7, 3, 2], 
      state: 17
    }, 
    {
      pos: [9, 3, 5], 
      state: 17
    }, 
    {
      pos: [13, 3, 5], 
      state: 17
    }, 
    {
      pos: [9, 3, 7], 
      state: 17
    }, 
    {
      pos: [13, 3, 7], 
      state: 17
    }, 
    {
      pos: [7, 3, 11], 
      state: 17
    }, 
    {
      pos: [10, 3, 11], 
      state: 17
    }, 
    {
      pos: [7, 3, 14], 
      state: 17
    }, 
    {
      pos: [10, 3, 14], 
      state: 17
    }, 
    {
      pos: [4, 4, 0], 
      state: 25
    }, 
    {
      pos: [5, 4, 0], 
      state: 25
    }, 
    {
      pos: [6, 4, 0], 
      state: 25
    }, 
    {
      pos: [7, 4, 0], 
      state: 25
    }, 
    {
      pos: [4, 4, 1], 
      state: 25
    }, 
    {
      pos: [7, 4, 1], 
      state: 25
    }, 
    {
      pos: [4, 4, 2], 
      state: 25
    }, 
    {
      pos: [5, 4, 2], 
      state: 25
    }, 
    {
      pos: [6, 4, 2], 
      state: 25
    }, 
    {
      pos: [7, 4, 2], 
      state: 25
    }, 
    {
      pos: [0, 4, 3], 
      state: 26
    }, 
    {
      pos: [9, 4, 5], 
      state: 17
    }, 
    {
      pos: [13, 4, 5], 
      state: 17
    }, 
    {
      pos: [9, 4, 7], 
      state: 17
    }, 
    {
      pos: [13, 4, 7], 
      state: 17
    }, 
    {
      pos: [7, 4, 11], 
      state: 25
    }, 
    {
      pos: [8, 4, 11], 
      state: 25
    }, 
    {
      pos: [9, 4, 11], 
      state: 25
    }, 
    {
      pos: [10, 4, 11], 
      state: 25
    }, 
    {
      pos: [7, 4, 12], 
      state: 25
    }, 
    {
      pos: [10, 4, 12], 
      state: 25
    }, 
    {
      pos: [7, 4, 13], 
      state: 25
    }, 
    {
      pos: [10, 4, 13], 
      state: 25
    }, 
    {
      pos: [7, 4, 14], 
      state: 25
    }, 
    {
      pos: [8, 4, 14], 
      state: 25
    }, 
    {
      pos: [9, 4, 14], 
      state: 25
    }, 
    {
      pos: [10, 4, 14], 
      state: 25
    }, 
    {
      pos: [9, 5, 5], 
      state: 25
    }, 
    {
      pos: [10, 5, 5], 
      state: 25
    }, 
    {
      pos: [11, 5, 5], 
      state: 25
    }, 
    {
      pos: [12, 5, 5], 
      state: 25
    }, 
    {
      pos: [13, 5, 5], 
      state: 25
    }, 
    {
      pos: [9, 5, 6], 
      state: 25
    }, 
    {
      pos: [13, 5, 6], 
      state: 25
    }, 
    {
      pos: [9, 5, 7], 
      state: 25
    }, 
    {
      pos: [10, 5, 7], 
      state: 25
    }, 
    {
      pos: [11, 5, 7], 
      state: 25
    }, 
    {
      pos: [12, 5, 7], 
      state: 25
    }, 
    {
      pos: [13, 5, 7], 
      state: 25
    }
  ], 
  palette: [
    {
      Name: "minecraft:sand"
    }, 
    {
      Name: "minecraft:smooth_sandstone"
    }, 
    {
      Properties: {
        orientation: "up_north"
      }, 
      Name: "minecraft:jigsaw"
    }, 
    {
      Properties: {
        facing: "north"
      }, 
      Name: "minecraft:white_glazed_terracotta"
    }, 
    {
      Properties: {
        facing: "east"
      }, 
      Name: "minecraft:white_glazed_terracotta"
    }, 
    {
      Properties: {
        axis: "y"
      }, 
      Name: "minecraft:hay_block"
    }, 
    {
      Properties: {
        facing: "west"
      }, 
      Name: "minecraft:white_glazed_terracotta"
    }, 
    {
      Properties: {
        facing: "south"
      }, 
      Name: "minecraft:white_glazed_terracotta"
    }, 
    {
      Properties: {
        axis: "x"
      }, 
      Name: "minecraft:hay_block"
    }, 
    {
      Name: "minecraft:cut_sandstone"
    }, 
    {
      Properties: {
        orientation: "west_up"
      }, 
      Name: "minecraft:jigsaw"
    }, 
    {
      Properties: {
        orientation: "east_up"
      }, 
      Name: "minecraft:jigsaw"
    }, 
    {
      Properties: {
        orientation: "south_up"
      }, 
      Name: "minecraft:jigsaw"
    }, 
    {
      Properties: {
        east: "low", 
        waterlogged: "false", 
        south: "none", 
        north: "none", 
        west: "none", 
        up: "true"
      }, 
      Name: "minecraft:sandstone_wall"
    }, 
    {
      Properties: {
        east: "none", 
        waterlogged: "false", 
        south: "none", 
        north: "none", 
        west: "low", 
        up: "true"
      }, 
      Name: "minecraft:sandstone_wall"
    }, 
    {
      Name: "minecraft:air"
    }, 
    {
      Name: "minecraft:potted_dead_bush"
    }, 
    {
      Properties: {
        east: "none", 
        waterlogged: "false", 
        south: "none", 
        north: "none", 
        west: "none", 
        up: "true"
      }, 
      Name: "minecraft:sandstone_wall"
    }, 
    {
      Properties: {
        level: "0"
      }, 
      Name: "minecraft:water"
    }, 
    {
      Properties: {
        half: "bottom", 
        waterlogged: "false", 
        shape: "straight", 
        facing: "east"
      }, 
      Name: "minecraft:smooth_sandstone_stairs"
    }, 
    {
      Properties: {
        half: "bottom", 
        waterlogged: "false", 
        shape: "straight", 
        facing: "west"
      }, 
      Name: "minecraft:smooth_sandstone_stairs"
    }, 
    {
      Name: "minecraft:potted_cactus"
    }, 
    {
      Properties: {
        waterlogged: "false", 
        type: "bottom"
      }, 
      Name: "minecraft:sandstone_slab"
    }, 
    {
      Name: "minecraft:terracotta"
    }, 
    {
      Properties: {
        attachment: "ceiling", 
        powered: "false", 
        facing: "north"
      }, 
      Name: "minecraft:bell"
    }, 
    {
      Properties: {
        waterlogged: "false", 
        type: "bottom"
      }, 
      Name: "minecraft:smooth_sandstone_slab"
    }, 
    {
      Name: "minecraft:torch"
    }
  ]
}
