{
  size: [7, 7, 7], 
  entities: [], 
  blocks: [
    {
      pos: [1, 0, 2], 
      state: 0
    }, 
    {
      pos: [1, 0, 4], 
      state: 0
    }, 
    {
      pos: [2, 0, 1], 
      state: 1
    }, 
    {
      pos: [2, 0, 2], 
      state: 2
    }, 
    {
      pos: [2, 0, 3], 
      state: 2
    }, 
    {
      pos: [2, 0, 4], 
      state: 2
    }, 
    {
      pos: [2, 0, 5], 
      state: 1
    }, 
    {
      pos: [3, 0, 1], 
      state: 2
    }, 
    {
      pos: [3, 0, 2], 
      state: 2
    }, 
    {
      pos: [3, 0, 3], 
      state: 2
    }, 
    {
      pos: [3, 0, 5], 
      state: 2
    }, 
    {
      pos: [4, 0, 1], 
      state: 2
    }, 
    {
      pos: [4, 0, 2], 
      state: 2
    }, 
    {
      pos: [4, 0, 3], 
      state: 2
    }, 
    {
      pos: [4, 0, 4], 
      state: 2
    }, 
    {
      pos: [4, 0, 5], 
      state: 2
    }, 
    {
      pos: [5, 0, 1], 
      state: 1
    }, 
    {
      pos: [5, 0, 2], 
      state: 2
    }, 
    {
      pos: [5, 0, 3], 
      state: 2
    }, 
    {
      pos: [5, 0, 4], 
      state: 2
    }, 
    {
      pos: [5, 0, 5], 
      state: 1
    }, 
    {
      pos: [2, 1, 1], 
      state: 1
    }, 
    {
      pos: [2, 1, 2], 
      state: 3
    }, 
    {
      pos: [2, 1, 4], 
      state: 3
    }, 
    {
      pos: [2, 1, 5], 
      state: 1
    }, 
    {
      pos: [3, 1, 1], 
      state: 3
    }, 
    {
      pos: [3, 1, 5], 
      state: 3
    }, 
    {
      pos: [4, 1, 1], 
      state: 3
    }, 
    {
      pos: [4, 1, 2], 
      state: 3
    }, 
    {
      pos: [4, 1, 5], 
      state: 3
    }, 
    {
      pos: [5, 1, 1], 
      state: 1
    }, 
    {
      pos: [5, 1, 2], 
      state: 3
    }, 
    {
      pos: [5, 1, 3], 
      state: 3
    }, 
    {
      pos: [5, 1, 4], 
      state: 3
    }, 
    {
      pos: [5, 1, 5], 
      state: 1
    }, 
    {
      pos: [2, 2, 1], 
      state: 1
    }, 
    {
      pos: [2, 2, 2], 
      state: 3
    }, 
    {
      pos: [2, 2, 4], 
      state: 3
    }, 
    {
      pos: [2, 2, 5], 
      state: 1
    }, 
    {
      pos: [3, 2, 1], 
      state: 3
    }, 
    {
      pos: [3, 2, 5], 
      state: 3
    }, 
    {
      pos: [4, 2, 1], 
      state: 3
    }, 
    {
      pos: [4, 2, 5], 
      state: 3
    }, 
    {
      pos: [5, 2, 1], 
      state: 1
    }, 
    {
      pos: [5, 2, 2], 
      state: 3
    }, 
    {
      pos: [5, 2, 4], 
      state: 3
    }, 
    {
      pos: [5, 2, 5], 
      state: 1
    }, 
    {
      pos: [2, 3, 1], 
      state: 1
    }, 
    {
      pos: [2, 3, 2], 
      state: 3
    }, 
    {
      pos: [2, 3, 3], 
      state: 3
    }, 
    {
      pos: [2, 3, 4], 
      state: 3
    }, 
    {
      pos: [2, 3, 5], 
      state: 1
    }, 
    {
      pos: [3, 3, 1], 
      state: 3
    }, 
    {
      pos: [3, 3, 5], 
      state: 3
    }, 
    {
      pos: [4, 3, 1], 
      state: 3
    }, 
    {
      pos: [4, 3, 5], 
      state: 3
    }, 
    {
      pos: [5, 3, 1], 
      state: 1
    }, 
    {
      pos: [5, 3, 2], 
      state: 3
    }, 
    {
      pos: [5, 3, 3], 
      state: 3
    }, 
    {
      pos: [5, 3, 4], 
      state: 3
    }, 
    {
      pos: [5, 3, 5], 
      state: 1
    }, 
    {
      pos: [2, 4, 1], 
      state: 1
    }, 
    {
      pos: [2, 4, 2], 
      state: 4
    }, 
    {
      pos: [2, 4, 3], 
      state: 4
    }, 
    {
      pos: [2, 4, 4], 
      state: 4
    }, 
    {
      pos: [2, 4, 5], 
      state: 1
    }, 
    {
      pos: [3, 4, 1], 
      state: 5
    }, 
    {
      pos: [3, 4, 5], 
      state: 5
    }, 
    {
      pos: [4, 4, 1], 
      state: 5
    }, 
    {
      pos: [4, 4, 5], 
      state: 5
    }, 
    {
      pos: [5, 4, 1], 
      state: 1
    }, 
    {
      pos: [5, 4, 2], 
      state: 4
    }, 
    {
      pos: [5, 4, 3], 
      state: 4
    }, 
    {
      pos: [5, 4, 4], 
      state: 4
    }, 
    {
      pos: [5, 4, 5], 
      state: 1
    }, 
    {
      pos: [2, 5, 2], 
      state: 3
    }, 
    {
      pos: [2, 5, 3], 
      state: 3
    }, 
    {
      pos: [2, 5, 4], 
      state: 3
    }, 
    {
      pos: [5, 5, 2], 
      state: 3
    }, 
    {
      pos: [5, 5, 3], 
      state: 3
    }, 
    {
      pos: [5, 5, 4], 
      state: 3
    }, 
    {
      pos: [1, 6, 3], 
      state: 3
    }, 
    {
      pos: [2, 6, 3], 
      state: 3
    }, 
    {
      pos: [3, 6, 3], 
      state: 3
    }, 
    {
      pos: [4, 6, 3], 
      state: 3
    }, 
    {
      pos: [5, 6, 3], 
      state: 3
    }, 
    {
      pos: [6, 6, 3], 
      state: 3
    }, 
    {
      pos: [0, 0, 0], 
      state: 6
    }, 
    {
      pos: [0, 0, 1], 
      state: 6
    }, 
    {
      pos: [0, 0, 2], 
      state: 7
    }, 
    {
      pos: [0, 0, 4], 
      state: 7
    }, 
    {
      pos: [0, 0, 5], 
      state: 6
    }, 
    {
      pos: [0, 0, 6], 
      state: 6
    }, 
    {
      pos: [1, 0, 0], 
      state: 6
    }, 
    {
      pos: [1, 0, 1], 
      state: 8
    }, 
    {
      pos: [1, 0, 3], 
      state: 9
    }, 
    {
      pos: [1, 0, 5], 
      state: 10
    }, 
    {
      pos: [1, 0, 6], 
      state: 6
    }, 
    {
      pos: [2, 0, 0], 
      state: 6
    }, 
    {
      pos: [2, 0, 6], 
      state: 6
    }, 
    {
      pos: [3, 0, 0], 
      state: 6
    }, 
    {
      pos: [3, 0, 6], 
      state: 6
    }, 
    {
      pos: [4, 0, 0], 
      state: 6
    }, 
    {
      pos: [4, 0, 6], 
      state: 6
    }, 
    {
      pos: [5, 0, 0], 
      state: 6
    }, 
    {
      pos: [5, 0, 6], 
      state: 6
    }, 
    {
      pos: [6, 0, 0], 
      state: 6
    }, 
    {
      pos: [6, 0, 1], 
      state: 6
    }, 
    {
      pos: [6, 0, 2], 
      state: 6
    }, 
    {
      pos: [6, 0, 3], 
      state: 6
    }, 
    {
      pos: [6, 0, 4], 
      state: 6
    }, 
    {
      pos: [6, 0, 5], 
      state: 6
    }, 
    {
      pos: [6, 0, 6], 
      state: 6
    }, 
    {
      pos: [0, 1, 0], 
      state: 6
    }, 
    {
      pos: [0, 1, 1], 
      state: 6
    }, 
    {
      pos: [0, 1, 2], 
      state: 6
    }, 
    {
      pos: [0, 1, 3], 
      state: 6
    }, 
    {
      pos: [0, 1, 4], 
      state: 6
    }, 
    {
      pos: [0, 1, 5], 
      state: 6
    }, 
    {
      pos: [0, 1, 6], 
      state: 6
    }, 
    {
      pos: [1, 1, 0], 
      state: 6
    }, 
    {
      pos: [1, 1, 1], 
      state: 6
    }, 
    {
      pos: [1, 1, 2], 
      state: 11
    }, 
    {
      pos: [1, 1, 3], 
      state: 6
    }, 
    {
      pos: [1, 1, 4], 
      state: 11
    }, 
    {
      pos: [1, 1, 5], 
      state: 6
    }, 
    {
      pos: [1, 1, 6], 
      state: 6
    }, 
    {
      pos: [2, 1, 0], 
      state: 6
    }, 
    {
      pos: [2, 1, 3], 
      state: 12
    }, 
    {
      pos: [2, 1, 6], 
      state: 6
    }, 
    {
      pos: [3, 1, 0], 
      state: 6
    }, 
    {
      pos: [3, 1, 2], 
      state: 6
    }, 
    {
      pos: [3, 1, 3], 
      state: 6
    }, 
    {
      pos: [3, 1, 4], 
      state: 6
    }, 
    {
      pos: [3, 1, 6], 
      state: 6
    }, 
    {
      pos: [4, 1, 0], 
      state: 6
    }, 
    {
      pos: [4, 1, 3], 
      state: 13
    }, 
    {
      pos: [4, 1, 4], 
      state: 14
    }, 
    {
      pos: [4, 1, 6], 
      state: 6
    }, 
    {
      pos: [5, 1, 0], 
      state: 6
    }, 
    {
      pos: [5, 1, 6], 
      state: 6
    }, 
    {
      pos: [6, 1, 0], 
      state: 6
    }, 
    {
      pos: [6, 1, 1], 
      state: 6
    }, 
    {
      pos: [6, 1, 2], 
      state: 6
    }, 
    {
      pos: [6, 1, 3], 
      state: 6
    }, 
    {
      pos: [6, 1, 4], 
      state: 6
    }, 
    {
      pos: [6, 1, 5], 
      state: 6
    }, 
    {
      pos: [6, 1, 6], 
      state: 6
    }, 
    {
      pos: [0, 2, 0], 
      state: 6
    }, 
    {
      pos: [0, 2, 1], 
      state: 6
    }, 
    {
      pos: [0, 2, 2], 
      state: 6
    }, 
    {
      pos: [0, 2, 3], 
      state: 6
    }, 
    {
      pos: [0, 2, 4], 
      state: 6
    }, 
    {
      pos: [0, 2, 5], 
      state: 6
    }, 
    {
      pos: [0, 2, 6], 
      state: 6
    }, 
    {
      pos: [1, 2, 0], 
      state: 6
    }, 
    {
      pos: [1, 2, 1], 
      state: 6
    }, 
    {
      pos: [1, 2, 2], 
      state: 6
    }, 
    {
      pos: [1, 2, 3], 
      state: 6
    }, 
    {
      pos: [1, 2, 4], 
      state: 6
    }, 
    {
      pos: [1, 2, 5], 
      state: 6
    }, 
    {
      pos: [1, 2, 6], 
      state: 6
    }, 
    {
      pos: [2, 2, 0], 
      state: 6
    }, 
    {
      pos: [2, 2, 3], 
      state: 15
    }, 
    {
      pos: [2, 2, 6], 
      state: 6
    }, 
    {
      pos: [3, 2, 0], 
      state: 6
    }, 
    {
      pos: [3, 2, 2], 
      state: 6
    }, 
    {
      pos: [3, 2, 3], 
      state: 6
    }, 
    {
      pos: [3, 2, 4], 
      state: 6
    }, 
    {
      pos: [3, 2, 6], 
      state: 6
    }, 
    {
      pos: [4, 2, 0], 
      state: 6
    }, 
    {
      pos: [4, 2, 2], 
      state: 16
    }, 
    {
      pos: [4, 2, 3], 
      state: 6
    }, 
    {
      pos: [4, 2, 4], 
      state: 6
    }, 
    {
      pos: [4, 2, 6], 
      state: 6
    }, 
    {
      pos: [5, 2, 0], 
      state: 6
    }, 
    {
      pos: [5, 2, 3], 
      state: 17
    }, 
    {
      pos: [5, 2, 6], 
      state: 6
    }, 
    {
      pos: [6, 2, 0], 
      state: 6
    }, 
    {
      pos: [6, 2, 1], 
      state: 6
    }, 
    {
      pos: [6, 2, 2], 
      state: 6
    }, 
    {
      pos: [6, 2, 3], 
      state: 6
    }, 
    {
      pos: [6, 2, 4], 
      state: 6
    }, 
    {
      pos: [6, 2, 5], 
      state: 6
    }, 
    {
      pos: [6, 2, 6], 
      state: 6
    }, 
    {
      pos: [0, 3, 0], 
      state: 6
    }, 
    {
      pos: [0, 3, 1], 
      state: 6
    }, 
    {
      pos: [0, 3, 2], 
      state: 6
    }, 
    {
      pos: [0, 3, 3], 
      state: 6
    }, 
    {
      pos: [0, 3, 4], 
      state: 6
    }, 
    {
      pos: [0, 3, 5], 
      state: 6
    }, 
    {
      pos: [0, 3, 6], 
      state: 6
    }, 
    {
      pos: [1, 3, 0], 
      state: 6
    }, 
    {
      pos: [1, 3, 1], 
      state: 6
    }, 
    {
      pos: [1, 3, 2], 
      state: 6
    }, 
    {
      pos: [1, 3, 3], 
      state: 6
    }, 
    {
      pos: [1, 3, 4], 
      state: 6
    }, 
    {
      pos: [1, 3, 5], 
      state: 6
    }, 
    {
      pos: [1, 3, 6], 
      state: 6
    }, 
    {
      pos: [2, 3, 0], 
      state: 6
    }, 
    {
      pos: [2, 3, 6], 
      state: 6
    }, 
    {
      pos: [3, 3, 0], 
      state: 6
    }, 
    {
      pos: [3, 3, 2], 
      state: 6
    }, 
    {
      pos: [3, 3, 3], 
      state: 6
    }, 
    {
      pos: [3, 3, 4], 
      state: 6
    }, 
    {
      pos: [3, 3, 6], 
      state: 6
    }, 
    {
      pos: [4, 3, 0], 
      state: 6
    }, 
    {
      pos: [4, 3, 2], 
      state: 6
    }, 
    {
      pos: [4, 3, 3], 
      state: 6
    }, 
    {
      pos: [4, 3, 4], 
      state: 6
    }, 
    {
      pos: [4, 3, 6], 
      state: 6
    }, 
    {
      pos: [5, 3, 0], 
      state: 6
    }, 
    {
      pos: [5, 3, 6], 
      state: 6
    }, 
    {
      pos: [6, 3, 0], 
      state: 6
    }, 
    {
      pos: [6, 3, 1], 
      state: 6
    }, 
    {
      pos: [6, 3, 2], 
      state: 6
    }, 
    {
      pos: [6, 3, 3], 
      state: 6
    }, 
    {
      pos: [6, 3, 4], 
      state: 6
    }, 
    {
      pos: [6, 3, 5], 
      state: 6
    }, 
    {
      pos: [6, 3, 6], 
      state: 6
    }, 
    {
      pos: [0, 4, 0], 
      state: 6
    }, 
    {
      pos: [0, 4, 1], 
      state: 6
    }, 
    {
      pos: [0, 4, 2], 
      state: 6
    }, 
    {
      pos: [0, 4, 3], 
      state: 6
    }, 
    {
      pos: [0, 4, 4], 
      state: 6
    }, 
    {
      pos: [0, 4, 5], 
      state: 6
    }, 
    {
      pos: [0, 4, 6], 
      state: 6
    }, 
    {
      pos: [1, 4, 0], 
      state: 18
    }, 
    {
      pos: [1, 4, 1], 
      state: 19
    }, 
    {
      pos: [1, 4, 2], 
      state: 6
    }, 
    {
      pos: [1, 4, 3], 
      state: 6
    }, 
    {
      pos: [1, 4, 4], 
      state: 6
    }, 
    {
      pos: [1, 4, 5], 
      state: 20
    }, 
    {
      pos: [1, 4, 6], 
      state: 21
    }, 
    {
      pos: [2, 4, 0], 
      state: 18
    }, 
    {
      pos: [2, 4, 6], 
      state: 21
    }, 
    {
      pos: [3, 4, 0], 
      state: 18
    }, 
    {
      pos: [3, 4, 2], 
      state: 6
    }, 
    {
      pos: [3, 4, 3], 
      state: 6
    }, 
    {
      pos: [3, 4, 4], 
      state: 6
    }, 
    {
      pos: [3, 4, 6], 
      state: 21
    }, 
    {
      pos: [4, 4, 0], 
      state: 18
    }, 
    {
      pos: [4, 4, 2], 
      state: 6
    }, 
    {
      pos: [4, 4, 3], 
      state: 6
    }, 
    {
      pos: [4, 4, 4], 
      state: 6
    }, 
    {
      pos: [4, 4, 6], 
      state: 21
    }, 
    {
      pos: [5, 4, 0], 
      state: 18
    }, 
    {
      pos: [5, 4, 6], 
      state: 21
    }, 
    {
      pos: [6, 4, 0], 
      state: 18
    }, 
    {
      pos: [6, 4, 1], 
      state: 19
    }, 
    {
      pos: [6, 4, 2], 
      state: 6
    }, 
    {
      pos: [6, 4, 3], 
      state: 6
    }, 
    {
      pos: [6, 4, 4], 
      state: 6
    }, 
    {
      pos: [6, 4, 5], 
      state: 20
    }, 
    {
      pos: [6, 4, 6], 
      state: 21
    }, 
    {
      pos: [0, 5, 0], 
      state: 6
    }, 
    {
      pos: [0, 5, 1], 
      state: 6
    }, 
    {
      pos: [0, 5, 2], 
      state: 6
    }, 
    {
      pos: [0, 5, 3], 
      state: 6
    }, 
    {
      pos: [0, 5, 4], 
      state: 6
    }, 
    {
      pos: [0, 5, 5], 
      state: 6
    }, 
    {
      pos: [0, 5, 6], 
      state: 6
    }, 
    {
      pos: [1, 5, 0], 
      state: 6
    }, 
    {
      pos: [1, 5, 1], 
      state: 18
    }, 
    {
      pos: [1, 5, 2], 
      state: 19
    }, 
    {
      pos: [1, 5, 3], 
      state: 6
    }, 
    {
      pos: [1, 5, 4], 
      state: 20
    }, 
    {
      pos: [1, 5, 5], 
      state: 21
    }, 
    {
      pos: [1, 5, 6], 
      state: 6
    }, 
    {
      pos: [2, 5, 0], 
      state: 6
    }, 
    {
      pos: [2, 5, 1], 
      state: 18
    }, 
    {
      pos: [2, 5, 5], 
      state: 21
    }, 
    {
      pos: [2, 5, 6], 
      state: 6
    }, 
    {
      pos: [3, 5, 0], 
      state: 6
    }, 
    {
      pos: [3, 5, 1], 
      state: 18
    }, 
    {
      pos: [3, 5, 2], 
      state: 6
    }, 
    {
      pos: [3, 5, 3], 
      state: 6
    }, 
    {
      pos: [3, 5, 4], 
      state: 6
    }, 
    {
      pos: [3, 5, 5], 
      state: 21
    }, 
    {
      pos: [3, 5, 6], 
      state: 6
    }, 
    {
      pos: [4, 5, 0], 
      state: 6
    }, 
    {
      pos: [4, 5, 1], 
      state: 18
    }, 
    {
      pos: [4, 5, 2], 
      state: 6
    }, 
    {
      pos: [4, 5, 3], 
      state: 6
    }, 
    {
      pos: [4, 5, 4], 
      state: 6
    }, 
    {
      pos: [4, 5, 5], 
      state: 21
    }, 
    {
      pos: [4, 5, 6], 
      state: 6
    }, 
    {
      pos: [5, 5, 0], 
      state: 6
    }, 
    {
      pos: [5, 5, 1], 
      state: 18
    }, 
    {
      pos: [5, 5, 5], 
      state: 21
    }, 
    {
      pos: [5, 5, 6], 
      state: 6
    }, 
    {
      pos: [6, 5, 0], 
      state: 6
    }, 
    {
      pos: [6, 5, 1], 
      state: 18
    }, 
    {
      pos: [6, 5, 2], 
      state: 19
    }, 
    {
      pos: [6, 5, 3], 
      state: 6
    }, 
    {
      pos: [6, 5, 4], 
      state: 20
    }, 
    {
      pos: [6, 5, 5], 
      state: 21
    }, 
    {
      pos: [6, 5, 6], 
      state: 6
    }, 
    {
      pos: [0, 6, 0], 
      state: 6
    }, 
    {
      pos: [0, 6, 1], 
      state: 6
    }, 
    {
      pos: [0, 6, 2], 
      state: 6
    }, 
    {
      pos: [0, 6, 3], 
      state: 6
    }, 
    {
      pos: [0, 6, 4], 
      state: 6
    }, 
    {
      pos: [0, 6, 5], 
      state: 6
    }, 
    {
      pos: [0, 6, 6], 
      state: 6
    }, 
    {
      pos: [1, 6, 0], 
      state: 6
    }, 
    {
      pos: [1, 6, 1], 
      state: 6
    }, 
    {
      pos: [1, 6, 2], 
      state: 18
    }, 
    {
      pos: [1, 6, 4], 
      state: 21
    }, 
    {
      pos: [1, 6, 5], 
      state: 6
    }, 
    {
      pos: [1, 6, 6], 
      state: 6
    }, 
    {
      pos: [2, 6, 0], 
      state: 6
    }, 
    {
      pos: [2, 6, 1], 
      state: 6
    }, 
    {
      pos: [2, 6, 2], 
      state: 18
    }, 
    {
      pos: [2, 6, 4], 
      state: 21
    }, 
    {
      pos: [2, 6, 5], 
      state: 6
    }, 
    {
      pos: [2, 6, 6], 
      state: 6
    }, 
    {
      pos: [3, 6, 0], 
      state: 6
    }, 
    {
      pos: [3, 6, 1], 
      state: 6
    }, 
    {
      pos: [3, 6, 2], 
      state: 18
    }, 
    {
      pos: [3, 6, 4], 
      state: 21
    }, 
    {
      pos: [3, 6, 5], 
      state: 6
    }, 
    {
      pos: [3, 6, 6], 
      state: 6
    }, 
    {
      pos: [4, 6, 0], 
      state: 6
    }, 
    {
      pos: [4, 6, 1], 
      state: 6
    }, 
    {
      pos: [4, 6, 2], 
      state: 18
    }, 
    {
      pos: [4, 6, 4], 
      state: 21
    }, 
    {
      pos: [4, 6, 5], 
      state: 6
    }, 
    {
      pos: [4, 6, 6], 
      state: 6
    }, 
    {
      pos: [5, 6, 0], 
      state: 6
    }, 
    {
      pos: [5, 6, 1], 
      state: 6
    }, 
    {
      pos: [5, 6, 2], 
      state: 18
    }, 
    {
      pos: [5, 6, 4], 
      state: 21
    }, 
    {
      pos: [5, 6, 5], 
      state: 6
    }, 
    {
      pos: [5, 6, 6], 
      state: 6
    }, 
    {
      pos: [6, 6, 0], 
      state: 6
    }, 
    {
      pos: [6, 6, 1], 
      state: 6
    }, 
    {
      pos: [6, 6, 2], 
      state: 18
    }, 
    {
      pos: [6, 6, 4], 
      state: 21
    }, 
    {
      pos: [6, 6, 5], 
      state: 6
    }, 
    {
      pos: [6, 6, 6], 
      state: 6
    }, 
    {
      nbt: {
        joint: "aligned", 
        final_state: "minecraft:structure_void", 
        name: "minecraft:building_entrance", 
        pool: "minecraft:village/plains/zombie/streets", 
        id: "minecraft:jigsaw", 
        target: "minecraft:building_entrance"
      }, 
      pos: [0, 0, 3], 
      state: 22
    }, 
    {
      nbt: {
        joint: "rollable", 
        final_state: "minecraft:cobblestone", 
        name: "minecraft:bottom", 
        pool: "minecraft:village/plains/zombie/villagers", 
        id: "minecraft:jigsaw", 
        target: "minecraft:bottom"
      }, 
      pos: [3, 0, 4], 
      state: 23
    }
  ], 
  palette: [
    {
      id: "minecraft:grass_block", 
      properties: {
        snowy: "false"
      }
    }, 
    {
      id: "minecraft:oak_log", 
      properties: {
        axis: "y"
      }
    }, 
    {
      id: "minecraft:cobblestone"
    }, 
    {
      id: "minecraft:oak_planks"
    }, 
    {
      id: "minecraft:oak_log", 
      properties: {
        axis: "z"
      }
    }, 
    {
      id: "minecraft:oak_log", 
      properties: {
        axis: "x"
      }
    }, 
    {
      id: "minecraft:air"
    }, 
    {
      id: "minecraft:oak_trapdoor", 
      properties: {
        half: "top", 
        waterlogged: "false", 
        powered: "false", 
        facing: "west", 
        open: "true"
      }
    }, 
    {
      id: "minecraft:oak_trapdoor", 
      properties: {
        half: "top", 
        waterlogged: "false", 
        powered: "false", 
        facing: "north", 
        open: "true"
      }
    }, 
    {
      id: "minecraft:cobblestone_stairs", 
      properties: {
        half: "bottom", 
        waterlogged: "false", 
        shape: "straight", 
        facing: "east"
      }
    }, 
    {
      id: "minecraft:oak_trapdoor", 
      properties: {
        half: "top", 
        waterlogged: "false", 
        powered: "false", 
        facing: "south", 
        open: "true"
      }
    }, 
    {
      id: "minecraft:poppy"
    }, 
    {
      id: "minecraft:oak_door", 
      properties: {
        hinge: "left", 
        half: "lower", 
        powered: "false", 
        facing: "east", 
        open: "false"
      }
    }, 
    {
      id: "minecraft:white_bed", 
      properties: {
        part: "foot", 
        facing: "south", 
        occupied: "false"
      }
    }, 
    {
      id: "minecraft:white_bed", 
      properties: {
        part: "head", 
        facing: "south", 
        occupied: "false"
      }
    }, 
    {
      id: "minecraft:oak_door", 
      properties: {
        hinge: "left", 
        half: "upper", 
        powered: "false", 
        facing: "east", 
        open: "false"
      }
    }, 
    {
      id: "minecraft:torch"
    }, 
    {
      id: "minecraft:glass_pane", 
      properties: {
        east: "false", 
        waterlogged: "false", 
        south: "true", 
        north: "true", 
        west: "false"
      }
    }, 
    {
      id: "minecraft:oak_stairs", 
      properties: {
        half: "bottom", 
        waterlogged: "false", 
        shape: "straight", 
        facing: "south"
      }
    }, 
    {
      id: "minecraft:oak_stairs", 
      properties: {
        half: "top", 
        waterlogged: "false", 
        shape: "straight", 
        facing: "north"
      }
    }, 
    {
      id: "minecraft:oak_stairs", 
      properties: {
        half: "top", 
        waterlogged: "false", 
        shape: "straight", 
        facing: "south"
      }
    }, 
    {
      id: "minecraft:oak_stairs", 
      properties: {
        half: "bottom", 
        waterlogged: "false", 
        shape: "straight", 
        facing: "north"
      }
    }, 
    {
      id: "minecraft:jigsaw", 
      properties: {
        orientation: "west_up"
      }
    }, 
    {
      id: "minecraft:jigsaw", 
      properties: {
        orientation: "up_north"
      }
    }
  ]
}
