{
  size: [9, 9, 28], 
  entities: [], 
  author: "CascadianBacon", 
  blocks: [
    {
      pos: [4, 7, 2], 
      state: 0
    }, 
    {
      pos: [4, 5, 3], 
      state: 0
    }, 
    {
      pos: [4, 6, 3], 
      state: 0
    }, 
    {
      pos: [4, 4, 4], 
      state: 0
    }, 
    {
      pos: [3, 5, 4], 
      state: 1
    }, 
    {
      pos: [4, 5, 4], 
      state: 1
    }, 
    {
      pos: [5, 5, 4], 
      state: 1
    }, 
    {
      pos: [3, 6, 4], 
      state: 1
    }, 
    {
      pos: [5, 6, 4], 
      state: 1
    }, 
    {
      pos: [4, 3, 5], 
      state: 1
    }, 
    {
      pos: [3, 4, 5], 
      state: 1
    }, 
    {
      pos: [4, 4, 5], 
      state: 1
    }, 
    {
      pos: [5, 4, 5], 
      state: 1
    }, 
    {
      pos: [2, 5, 5], 
      state: 1
    }, 
    {
      pos: [3, 5, 5], 
      state: 0
    }, 
    {
      pos: [4, 5, 5], 
      state: 0
    }, 
    {
      pos: [5, 5, 5], 
      state: 0
    }, 
    {
      pos: [6, 5, 5], 
      state: 1
    }, 
    {
      pos: [2, 6, 5], 
      state: 1
    }, 
    {
      pos: [6, 6, 5], 
      state: 1
    }, 
    {
      pos: [4, 2, 6], 
      state: 0
    }, 
    {
      pos: [4, 3, 6], 
      state: 1
    }, 
    {
      pos: [3, 4, 6], 
      state: 1
    }, 
    {
      pos: [4, 4, 6], 
      state: 1
    }, 
    {
      pos: [5, 4, 6], 
      state: 1
    }, 
    {
      pos: [2, 5, 6], 
      state: 0
    }, 
    {
      pos: [3, 5, 6], 
      state: 0
    }, 
    {
      pos: [4, 5, 6], 
      state: 0
    }, 
    {
      pos: [5, 5, 6], 
      state: 0
    }, 
    {
      pos: [6, 5, 6], 
      state: 0
    }, 
    {
      pos: [1, 6, 6], 
      state: 1
    }, 
    {
      pos: [7, 6, 6], 
      state: 1
    }, 
    {
      pos: [4, 1, 7], 
      state: 0
    }, 
    {
      pos: [4, 2, 7], 
      state: 1
    }, 
    {
      pos: [3, 3, 7], 
      state: 1
    }, 
    {
      pos: [4, 3, 7], 
      state: 1
    }, 
    {
      pos: [5, 3, 7], 
      state: 1
    }, 
    {
      pos: [2, 4, 7], 
      state: 1
    }, 
    {
      pos: [3, 4, 7], 
      state: 1
    }, 
    {
      pos: [4, 4, 7], 
      state: 2
    }, 
    {
      pos: [5, 4, 7], 
      state: 1
    }, 
    {
      pos: [6, 4, 7], 
      state: 1
    }, 
    {
      pos: [1, 5, 7], 
      state: 1
    }, 
    {
      pos: [2, 5, 7], 
      state: 0
    }, 
    {
      pos: [4, 5, 7], 
      state: 2
    }, 
    {
      pos: [6, 5, 7], 
      state: 0
    }, 
    {
      pos: [7, 5, 7], 
      state: 1
    }, 
    {
      pos: [1, 6, 7], 
      state: 1
    }, 
    {
      pos: [7, 6, 7], 
      state: 1
    }, 
    {
      pos: [4, 1, 8], 
      state: 1
    }, 
    {
      pos: [3, 2, 8], 
      state: 1
    }, 
    {
      pos: [5, 2, 8], 
      state: 1
    }, 
    {
      pos: [2, 3, 8], 
      state: 1
    }, 
    {
      pos: [6, 3, 8], 
      state: 1
    }, 
    {
      pos: [1, 4, 8], 
      state: 1
    }, 
    {
      pos: [2, 4, 8], 
      state: 0
    }, 
    {
      pos: [3, 4, 8], 
      state: 0
    }, 
    {
      pos: [4, 4, 8], 
      state: 0
    }, 
    {
      pos: [5, 4, 8], 
      state: 0
    }, 
    {
      pos: [6, 4, 8], 
      state: 0
    }, 
    {
      pos: [7, 4, 8], 
      state: 1
    }, 
    {
      pos: [1, 5, 8], 
      state: 1
    }, 
    {
      pos: [7, 5, 8], 
      state: 1
    }, 
    {
      pos: [0, 6, 8], 
      state: 1
    }, 
    {
      pos: [8, 6, 8], 
      state: 1
    }, 
    {
      pos: [4, 0, 9], 
      state: 0
    }, 
    {
      pos: [3, 1, 9], 
      state: 1
    }, 
    {
      pos: [4, 1, 9], 
      state: 1
    }, 
    {
      pos: [5, 1, 9], 
      state: 1
    }, 
    {
      pos: [2, 2, 9], 
      state: 1
    }, 
    {
      pos: [6, 2, 9], 
      state: 1
    }, 
    {
      pos: [1, 3, 9], 
      state: 1
    }, 
    {
      pos: [2, 3, 9], 
      state: 1
    }, 
    {
      pos: [6, 3, 9], 
      state: 1
    }, 
    {
      pos: [7, 3, 9], 
      state: 1
    }, 
    {
      pos: [1, 4, 9], 
      state: 0
    }, 
    {
      pos: [2, 4, 9], 
      state: 0
    }, 
    {
      pos: [6, 4, 9], 
      state: 0
    }, 
    {
      pos: [7, 4, 9], 
      state: 0
    }, 
    {
      pos: [0, 5, 9], 
      state: 1
    }, 
    {
      pos: [8, 5, 9], 
      state: 1
    }, 
    {
      pos: [4, 0, 10], 
      state: 0
    }, 
    {
      pos: [3, 1, 10], 
      state: 1
    }, 
    {
      pos: [4, 1, 10], 
      state: 1
    }, 
    {
      pos: [5, 1, 10], 
      state: 1
    }, 
    {
      pos: [2, 2, 10], 
      state: 1
    }, 
    {
      pos: [6, 2, 10], 
      state: 1
    }, 
    {
      pos: [1, 3, 10], 
      state: 1
    }, 
    {
      pos: [2, 3, 10], 
      state: 1
    }, 
    {
      pos: [6, 3, 10], 
      state: 1
    }, 
    {
      pos: [7, 3, 10], 
      state: 1
    }, 
    {
      pos: [1, 4, 10], 
      state: 0
    }, 
    {
      pos: [2, 4, 10], 
      state: 0
    }, 
    {
      pos: [0, 5, 10], 
      state: 1
    }, 
    {
      pos: [8, 5, 10], 
      state: 1
    }, 
    {
      pos: [4, 0, 11], 
      state: 0
    }, 
    {
      pos: [3, 1, 11], 
      state: 1
    }, 
    {
      pos: [4, 1, 11], 
      state: 1
    }, 
    {
      pos: [5, 1, 11], 
      state: 1
    }, 
    {
      pos: [2, 2, 11], 
      state: 1
    }, 
    {
      pos: [4, 2, 11], 
      state: 2
    }, 
    {
      pos: [6, 2, 11], 
      state: 1
    }, 
    {
      pos: [1, 3, 11], 
      state: 1
    }, 
    {
      pos: [2, 3, 11], 
      state: 1
    }, 
    {
      pos: [4, 3, 11], 
      state: 2
    }, 
    {
      pos: [7, 3, 11], 
      state: 1
    }, 
    {
      pos: [1, 4, 11], 
      state: 0
    }, 
    {
      pos: [2, 4, 11], 
      state: 0
    }, 
    {
      pos: [3, 4, 11], 
      state: 0
    }, 
    {
      pos: [4, 4, 11], 
      state: 2
    }, 
    {
      pos: [5, 4, 11], 
      state: 0
    }, 
    {
      pos: [4, 5, 11], 
      state: 2
    }, 
    {
      pos: [4, 0, 12], 
      state: 0
    }, 
    {
      pos: [3, 1, 12], 
      state: 1
    }, 
    {
      pos: [4, 1, 12], 
      state: 1
    }, 
    {
      pos: [5, 1, 12], 
      state: 1
    }, 
    {
      pos: [4, 0, 13], 
      state: 0
    }, 
    {
      pos: [3, 1, 13], 
      state: 1
    }, 
    {
      pos: [4, 1, 13], 
      state: 1
    }, 
    {
      pos: [5, 1, 13], 
      state: 1
    }, 
    {
      pos: [6, 2, 13], 
      state: 1
    }, 
    {
      pos: [4, 0, 14], 
      state: 0
    }, 
    {
      pos: [3, 1, 14], 
      state: 1
    }, 
    {
      pos: [4, 1, 14], 
      state: 1
    }, 
    {
      pos: [5, 1, 14], 
      state: 1
    }, 
    {
      pos: [6, 2, 14], 
      state: 1
    }, 
    {
      pos: [6, 3, 14], 
      state: 1
    }, 
    {
      pos: [7, 3, 14], 
      state: 1
    }, 
    {
      pos: [4, 0, 15], 
      state: 0
    }, 
    {
      pos: [3, 1, 15], 
      state: 1
    }, 
    {
      pos: [4, 1, 15], 
      state: 1
    }, 
    {
      pos: [5, 1, 15], 
      state: 1
    }, 
    {
      pos: [1, 4, 15], 
      state: 0
    }, 
    {
      pos: [7, 4, 15], 
      state: 0
    }, 
    {
      pos: [4, 0, 16], 
      state: 0
    }, 
    {
      pos: [3, 1, 16], 
      state: 1
    }, 
    {
      pos: [4, 1, 16], 
      state: 1
    }, 
    {
      pos: [5, 1, 16], 
      state: 1
    }, 
    {
      pos: [2, 2, 16], 
      state: 1
    }, 
    {
      pos: [4, 2, 16], 
      state: 2
    }, 
    {
      pos: [5, 2, 16], 
      state: 1
    }, 
    {
      pos: [6, 2, 16], 
      state: 1
    }, 
    {
      pos: [1, 3, 16], 
      state: 1
    }, 
    {
      pos: [2, 3, 16], 
      state: 1
    }, 
    {
      pos: [4, 3, 16], 
      state: 2
    }, 
    {
      pos: [5, 3, 16], 
      state: 1
    }, 
    {
      pos: [6, 3, 16], 
      state: 1
    }, 
    {
      pos: [7, 3, 16], 
      state: 1
    }, 
    {
      pos: [1, 4, 16], 
      state: 0
    }, 
    {
      pos: [2, 4, 16], 
      state: 0
    }, 
    {
      pos: [3, 4, 16], 
      state: 0
    }, 
    {
      pos: [4, 4, 16], 
      state: 2
    }, 
    {
      pos: [5, 4, 16], 
      state: 0
    }, 
    {
      pos: [7, 4, 16], 
      state: 0
    }, 
    {
      pos: [4, 5, 16], 
      state: 2
    }, 
    {
      pos: [4, 0, 17], 
      state: 0
    }, 
    {
      pos: [3, 1, 17], 
      state: 1
    }, 
    {
      pos: [4, 1, 17], 
      state: 1
    }, 
    {
      pos: [5, 1, 17], 
      state: 1
    }, 
    {
      pos: [2, 2, 17], 
      state: 1
    }, 
    {
      pos: [6, 2, 17], 
      state: 1
    }, 
    {
      pos: [1, 3, 17], 
      state: 1
    }, 
    {
      pos: [2, 3, 17], 
      state: 1
    }, 
    {
      pos: [6, 3, 17], 
      state: 1
    }, 
    {
      pos: [7, 3, 17], 
      state: 1
    }, 
    {
      pos: [1, 4, 17], 
      state: 0
    }, 
    {
      pos: [2, 4, 17], 
      state: 0
    }, 
    {
      pos: [3, 4, 17], 
      state: 0
    }, 
    {
      pos: [4, 4, 17], 
      state: 0
    }, 
    {
      pos: [5, 4, 17], 
      state: 0
    }, 
    {
      pos: [6, 4, 17], 
      state: 0
    }, 
    {
      pos: [7, 4, 17], 
      state: 0
    }, 
    {
      pos: [4, 0, 18], 
      state: 0
    }, 
    {
      pos: [3, 1, 18], 
      state: 1
    }, 
    {
      pos: [4, 1, 18], 
      state: 1
    }, 
    {
      pos: [5, 1, 18], 
      state: 1
    }, 
    {
      pos: [1, 4, 18], 
      state: 1
    }, 
    {
      pos: [2, 4, 18], 
      state: 0
    }, 
    {
      pos: [3, 4, 18], 
      state: 0
    }, 
    {
      pos: [5, 4, 18], 
      state: 0
    }, 
    {
      pos: [6, 4, 18], 
      state: 0
    }, 
    {
      pos: [7, 4, 18], 
      state: 1
    }, 
    {
      pos: [0, 5, 18], 
      state: 1
    }, 
    {
      pos: [8, 5, 18], 
      state: 1
    }, 
    {
      pos: [4, 0, 19], 
      state: 0
    }, 
    {
      pos: [3, 1, 19], 
      state: 1
    }, 
    {
      pos: [4, 1, 19], 
      state: 1
    }, 
    {
      pos: [5, 1, 19], 
      state: 1
    }, 
    {
      pos: [2, 2, 19], 
      state: 1
    }, 
    {
      pos: [6, 2, 19], 
      state: 1
    }, 
    {
      pos: [1, 3, 19], 
      state: 1
    }, 
    {
      pos: [2, 3, 19], 
      state: 1
    }, 
    {
      pos: [6, 3, 19], 
      state: 1
    }, 
    {
      pos: [7, 3, 19], 
      state: 1
    }, 
    {
      pos: [1, 4, 19], 
      state: 1
    }, 
    {
      pos: [2, 4, 19], 
      state: 1
    }, 
    {
      pos: [3, 4, 19], 
      state: 1
    }, 
    {
      pos: [5, 4, 19], 
      state: 1
    }, 
    {
      pos: [6, 4, 19], 
      state: 1
    }, 
    {
      pos: [7, 4, 19], 
      state: 1
    }, 
    {
      pos: [0, 5, 19], 
      state: 1
    }, 
    {
      pos: [1, 5, 19], 
      state: 1
    }, 
    {
      pos: [2, 5, 19], 
      state: 1
    }, 
    {
      pos: [3, 5, 19], 
      state: 1
    }, 
    {
      pos: [5, 5, 19], 
      state: 1
    }, 
    {
      pos: [6, 5, 19], 
      state: 1
    }, 
    {
      pos: [7, 5, 19], 
      state: 1
    }, 
    {
      pos: [8, 5, 19], 
      state: 1
    }, 
    {
      pos: [0, 6, 19], 
      state: 1
    }, 
    {
      pos: [2, 6, 19], 
      state: 1
    }, 
    {
      pos: [3, 6, 19], 
      state: 1
    }, 
    {
      pos: [5, 6, 19], 
      state: 1
    }, 
    {
      pos: [6, 6, 19], 
      state: 1
    }, 
    {
      pos: [8, 6, 19], 
      state: 1
    }, 
    {
      pos: [4, 0, 20], 
      state: 0
    }, 
    {
      pos: [3, 1, 20], 
      state: 1
    }, 
    {
      pos: [4, 1, 20], 
      state: 1
    }, 
    {
      pos: [5, 1, 20], 
      state: 1
    }, 
    {
      pos: [2, 2, 20], 
      state: 1
    }, 
    {
      pos: [3, 2, 20], 
      state: 1
    }, 
    {
      pos: [4, 2, 20], 
      state: 1
    }, 
    {
      pos: [5, 2, 20], 
      state: 1
    }, 
    {
      pos: [6, 2, 20], 
      state: 1
    }, 
    {
      pos: [1, 3, 20], 
      state: 1
    }, 
    {
      pos: [2, 3, 20], 
      state: 1
    }, 
    {
      pos: [3, 3, 20], 
      state: 0
    }, 
    {
      pos: [4, 3, 20], 
      state: 0
    }, 
    {
      pos: [5, 3, 20], 
      state: 0
    }, 
    {
      pos: [6, 3, 20], 
      state: 1
    }, 
    {
      pos: [7, 3, 20], 
      state: 1
    }, 
    {
      pos: [1, 4, 20], 
      state: 1
    }, 
    {
      pos: [7, 4, 20], 
      state: 1
    }, 
    {
      pos: [0, 5, 20], 
      state: 1
    }, 
    {
      pos: [1, 5, 20], 
      state: 1
    }, 
    {
      pos: [7, 5, 20], 
      state: 1
    }, 
    {
      pos: [8, 5, 20], 
      state: 1
    }, 
    {
      pos: [0, 6, 20], 
      state: 1
    }, 
    {
      pos: [1, 6, 20], 
      state: 0
    }, 
    {
      pos: [7, 6, 20], 
      state: 0
    }, 
    {
      pos: [8, 6, 20], 
      state: 1
    }, 
    {
      pos: [4, 1, 21], 
      state: 1
    }, 
    {
      pos: [3, 2, 21], 
      state: 1
    }, 
    {
      pos: [4, 2, 21], 
      state: 1
    }, 
    {
      pos: [5, 2, 21], 
      state: 1
    }, 
    {
      pos: [2, 3, 21], 
      state: 0
    }, 
    {
      pos: [3, 3, 21], 
      state: 0
    }, 
    {
      pos: [4, 3, 21], 
      state: 0
    }, 
    {
      pos: [5, 3, 21], 
      state: 0
    }, 
    {
      pos: [6, 3, 21], 
      state: 0
    }, 
    {
      pos: [1, 4, 21], 
      state: 1
    }, 
    {
      pos: [7, 4, 21], 
      state: 1
    }, 
    {
      pos: [1, 5, 21], 
      state: 1
    }, 
    {
      pos: [7, 5, 21], 
      state: 1
    }, 
    {
      pos: [0, 6, 21], 
      state: 1
    }, 
    {
      pos: [8, 6, 21], 
      state: 1
    }, 
    {
      pos: [0, 7, 21], 
      state: 1
    }, 
    {
      pos: [1, 7, 21], 
      state: 1
    }, 
    {
      pos: [3, 7, 21], 
      state: 1
    }, 
    {
      pos: [4, 7, 21], 
      state: 1
    }, 
    {
      pos: [5, 7, 21], 
      state: 1
    }, 
    {
      pos: [7, 7, 21], 
      state: 1
    }, 
    {
      pos: [8, 7, 21], 
      state: 1
    }, 
    {
      pos: [1, 8, 21], 
      state: 1
    }, 
    {
      pos: [3, 8, 21], 
      state: 1
    }, 
    {
      pos: [4, 8, 21], 
      state: 1
    }, 
    {
      pos: [5, 8, 21], 
      state: 1
    }, 
    {
      pos: [7, 8, 21], 
      state: 1
    }, 
    {
      pos: [4, 1, 22], 
      state: 0
    }, 
    {
      pos: [3, 2, 22], 
      state: 1
    }, 
    {
      pos: [4, 2, 22], 
      state: 1
    }, 
    {
      pos: [5, 2, 22], 
      state: 1
    }, 
    {
      pos: [2, 3, 22], 
      state: 0
    }, 
    {
      pos: [3, 3, 22], 
      state: 0
    }, 
    {
      pos: [4, 3, 22], 
      state: 0
    }, 
    {
      pos: [5, 3, 22], 
      state: 0
    }, 
    {
      pos: [6, 3, 22], 
      state: 0
    }, 
    {
      pos: [1, 4, 22], 
      state: 1
    }, 
    {
      pos: [7, 4, 22], 
      state: 1
    }, 
    {
      pos: [0, 7, 22], 
      state: 1
    }, 
    {
      pos: [3, 7, 22], 
      state: 1
    }, 
    {
      pos: [4, 7, 22], 
      state: 1
    }, 
    {
      pos: [5, 7, 22], 
      state: 1
    }, 
    {
      pos: [8, 7, 22], 
      state: 1
    }, 
    {
      pos: [4, 1, 23], 
      state: 0
    }, 
    {
      pos: [3, 2, 23], 
      state: 1
    }, 
    {
      pos: [4, 2, 23], 
      state: 1
    }, 
    {
      pos: [5, 2, 23], 
      state: 1
    }, 
    {
      pos: [2, 3, 23], 
      state: 0
    }, 
    {
      pos: [3, 3, 23], 
      state: 0
    }, 
    {
      pos: [4, 3, 23], 
      state: 0
    }, 
    {
      pos: [5, 3, 23], 
      state: 0
    }, 
    {
      pos: [6, 3, 23], 
      state: 0
    }, 
    {
      pos: [1, 4, 23], 
      state: 1
    }, 
    {
      pos: [7, 4, 23], 
      state: 1
    }, 
    {
      pos: [1, 5, 23], 
      state: 1
    }, 
    {
      pos: [7, 5, 23], 
      state: 1
    }, 
    {
      pos: [0, 6, 23], 
      state: 1
    }, 
    {
      pos: [8, 6, 23], 
      state: 1
    }, 
    {
      pos: [0, 7, 23], 
      state: 1
    }, 
    {
      pos: [8, 7, 23], 
      state: 1
    }, 
    {
      pos: [4, 2, 24], 
      state: 0
    }, 
    {
      pos: [2, 3, 24], 
      state: 0
    }, 
    {
      pos: [3, 3, 24], 
      state: 0
    }, 
    {
      pos: [4, 3, 24], 
      state: 0
    }, 
    {
      pos: [5, 3, 24], 
      state: 0
    }, 
    {
      pos: [6, 3, 24], 
      state: 0
    }, 
    {
      pos: [1, 4, 24], 
      state: 1
    }, 
    {
      pos: [7, 4, 24], 
      state: 1
    }, 
    {
      pos: [1, 5, 24], 
      state: 1
    }, 
    {
      pos: [7, 5, 24], 
      state: 1
    }, 
    {
      pos: [1, 6, 24], 
      state: 1
    }, 
    {
      pos: [7, 6, 24], 
      state: 1
    }, 
    {
      pos: [1, 7, 24], 
      state: 1
    }, 
    {
      pos: [7, 7, 24], 
      state: 1
    }, 
    {
      pos: [4, 0, 25], 
      state: 1
    }, 
    {
      pos: [4, 1, 25], 
      state: 1
    }, 
    {
      pos: [2, 4, 25], 
      state: 1
    }, 
    {
      pos: [3, 4, 25], 
      state: 1
    }, 
    {
      pos: [4, 4, 25], 
      state: 1
    }, 
    {
      pos: [5, 4, 25], 
      state: 1
    }, 
    {
      pos: [6, 4, 25], 
      state: 1
    }, 
    {
      pos: [2, 5, 25], 
      state: 1
    }, 
    {
      pos: [6, 5, 25], 
      state: 1
    }, 
    {
      pos: [1, 6, 25], 
      state: 1
    }, 
    {
      pos: [7, 6, 25], 
      state: 1
    }, 
    {
      pos: [1, 7, 25], 
      state: 1
    }, 
    {
      pos: [7, 7, 25], 
      state: 1
    }, 
    {
      pos: [1, 8, 25], 
      state: 1
    }, 
    {
      pos: [7, 8, 25], 
      state: 1
    }, 
    {
      pos: [4, 0, 26], 
      state: 1
    }, 
    {
      pos: [4, 1, 26], 
      state: 1
    }, 
    {
      pos: [4, 2, 26], 
      state: 1
    }, 
    {
      pos: [4, 5, 26], 
      state: 1
    }, 
    {
      pos: [3, 6, 26], 
      state: 1
    }, 
    {
      pos: [5, 6, 26], 
      state: 1
    }, 
    {
      pos: [2, 7, 26], 
      state: 1
    }, 
    {
      pos: [3, 7, 26], 
      state: 1
    }, 
    {
      pos: [5, 7, 26], 
      state: 1
    }, 
    {
      pos: [6, 7, 26], 
      state: 1
    }, 
    {
      pos: [2, 8, 26], 
      state: 1
    }, 
    {
      pos: [6, 8, 26], 
      state: 1
    }, 
    {
      pos: [4, 7, 27], 
      state: 1
    }, 
    {
      nbt: {
        Items: [], 
        id: "minecraft:chest", 
        Lock: ""
      }, 
      pos: [4, 2, 8], 
      state: 3
    }, 
    {
      nbt: {
        metadata: "supply_chest", 
        mirror: "NONE", 
        ignoreEntities: 1b, 
        powered: 0b, 
        seed: 0L, 
        author: "CascadianBacon", 
        rotation: "NONE", 
        mode: "DATA", 
        posX: 0, 
        posY: 1, 
        sizeX: 0, 
        integrity: 1.0f, 
        posZ: 0, 
        showair: 0b, 
        name: "", 
        id: "minecraft:structure_block", 
        sizeY: 0, 
        showboundingbox: 1b, 
        sizeZ: 0
      }, 
      pos: [4, 3, 8], 
      state: 4
    }, 
    {
      nbt: {
        Items: [], 
        id: "minecraft:chest", 
        Lock: ""
      }, 
      pos: [5, 2, 18], 
      state: 5
    }, 
    {
      nbt: {
        metadata: "map_chest", 
        mirror: "NONE", 
        ignoreEntities: 1b, 
        powered: 0b, 
        seed: 0L, 
        author: "CascadianBacon", 
        rotation: "NONE", 
        mode: "DATA", 
        posX: 0, 
        posY: 1, 
        sizeX: 0, 
        integrity: 1.0f, 
        posZ: 0, 
        showair: 0b, 
        name: "", 
        id: "minecraft:structure_block", 
        sizeY: 0, 
        showboundingbox: 1b, 
        sizeZ: 0
      }, 
      pos: [5, 3, 18], 
      state: 4
    }, 
    {
      nbt: {
        Items: [], 
        id: "minecraft:chest", 
        Lock: ""
      }, 
      pos: [6, 4, 24], 
      state: 6
    }, 
    {
      nbt: {
        metadata: "treasure_chest", 
        mirror: "NONE", 
        ignoreEntities: 1b, 
        powered: 0b, 
        seed: 0L, 
        author: "CascadianBacon", 
        rotation: "NONE", 
        mode: "DATA", 
        posX: 0, 
        posY: 1, 
        sizeX: 0, 
        integrity: 1.0f, 
        posZ: 0, 
        showair: 0b, 
        name: "", 
        id: "minecraft:structure_block", 
        sizeY: 0, 
        showboundingbox: 1b, 
        sizeZ: 0
      }, 
      pos: [6, 5, 24], 
      state: 4
    }, 
    {
      pos: [4, 8, 0], 
      state: 7
    }, 
    {
      pos: [4, 7, 1], 
      state: 7
    }, 
    {
      pos: [4, 8, 1], 
      state: 8
    }, 
    {
      pos: [3, 6, 2], 
      state: 9
    }, 
    {
      pos: [4, 6, 2], 
      state: 7
    }, 
    {
      pos: [5, 6, 2], 
      state: 9
    }, 
    {
      pos: [3, 7, 2], 
      state: 9
    }, 
    {
      pos: [5, 7, 2], 
      state: 9
    }, 
    {
      pos: [4, 4, 3], 
      state: 7
    }, 
    {
      pos: [3, 5, 3], 
      state: 10
    }, 
    {
      pos: [5, 5, 3], 
      state: 10
    }, 
    {
      pos: [3, 6, 3], 
      state: 11
    }, 
    {
      pos: [5, 6, 3], 
      state: 11
    }, 
    {
      pos: [3, 7, 3], 
      state: 9
    }, 
    {
      pos: [4, 7, 3], 
      state: 8
    }, 
    {
      pos: [5, 7, 3], 
      state: 9
    }, 
    {
      pos: [4, 3, 4], 
      state: 7
    }, 
    {
      pos: [3, 4, 4], 
      state: 10
    }, 
    {
      pos: [5, 4, 4], 
      state: 10
    }, 
    {
      pos: [4, 6, 4], 
      state: 8
    }, 
    {
      pos: [3, 7, 4], 
      state: 9
    }, 
    {
      pos: [5, 7, 4], 
      state: 9
    }, 
    {
      pos: [4, 2, 5], 
      state: 7
    }, 
    {
      pos: [3, 3, 5], 
      state: 12
    }, 
    {
      pos: [5, 3, 5], 
      state: 13
    }, 
    {
      pos: [2, 4, 5], 
      state: 12
    }, 
    {
      pos: [6, 4, 5], 
      state: 13
    }, 
    {
      pos: [4, 1, 6], 
      state: 7
    }, 
    {
      pos: [3, 3, 6], 
      state: 12
    }, 
    {
      pos: [5, 3, 6], 
      state: 13
    }, 
    {
      pos: [2, 4, 6], 
      state: 12
    }, 
    {
      pos: [6, 4, 6], 
      state: 13
    }, 
    {
      pos: [1, 5, 6], 
      state: 12
    }, 
    {
      pos: [7, 5, 6], 
      state: 13
    }, 
    {
      pos: [3, 2, 7], 
      state: 12
    }, 
    {
      pos: [5, 2, 7], 
      state: 13
    }, 
    {
      pos: [2, 3, 7], 
      state: 12
    }, 
    {
      pos: [6, 3, 7], 
      state: 13
    }, 
    {
      pos: [1, 4, 7], 
      state: 12
    }, 
    {
      pos: [7, 4, 7], 
      state: 13
    }, 
    {
      pos: [3, 5, 7], 
      state: 8
    }, 
    {
      pos: [5, 5, 7], 
      state: 8
    }, 
    {
      pos: [4, 0, 8], 
      state: 7
    }, 
    {
      pos: [3, 1, 8], 
      state: 12
    }, 
    {
      pos: [5, 1, 8], 
      state: 13
    }, 
    {
      pos: [2, 2, 8], 
      state: 12
    }, 
    {
      pos: [6, 2, 8], 
      state: 13
    }, 
    {
      pos: [1, 3, 8], 
      state: 12
    }, 
    {
      pos: [7, 3, 8], 
      state: 13
    }, 
    {
      pos: [0, 5, 8], 
      state: 10
    }, 
    {
      pos: [8, 5, 8], 
      state: 10
    }, 
    {
      pos: [1, 6, 8], 
      state: 14
    }, 
    {
      pos: [7, 6, 8], 
      state: 14
    }, 
    {
      pos: [2, 1, 9], 
      state: 12
    }, 
    {
      pos: [6, 1, 9], 
      state: 13
    }, 
    {
      pos: [1, 2, 9], 
      state: 12
    }, 
    {
      pos: [7, 2, 9], 
      state: 13
    }, 
    {
      pos: [0, 4, 9], 
      state: 12
    }, 
    {
      pos: [3, 4, 9], 
      state: 15
    }, 
    {
      pos: [5, 4, 9], 
      state: 15
    }, 
    {
      pos: [8, 4, 9], 
      state: 13
    }, 
    {
      pos: [0, 6, 9], 
      state: 14
    }, 
    {
      pos: [8, 6, 9], 
      state: 14
    }, 
    {
      pos: [2, 1, 10], 
      state: 12
    }, 
    {
      pos: [6, 1, 10], 
      state: 13
    }, 
    {
      pos: [1, 2, 10], 
      state: 12
    }, 
    {
      pos: [7, 2, 10], 
      state: 13
    }, 
    {
      pos: [0, 4, 10], 
      state: 12
    }, 
    {
      pos: [3, 4, 10], 
      state: 16
    }, 
    {
      pos: [5, 4, 10], 
      state: 17
    }, 
    {
      pos: [8, 4, 10], 
      state: 13
    }, 
    {
      pos: [2, 1, 11], 
      state: 12
    }, 
    {
      pos: [6, 1, 11], 
      state: 13
    }, 
    {
      pos: [1, 2, 11], 
      state: 12
    }, 
    {
      pos: [7, 2, 11], 
      state: 13
    }, 
    {
      pos: [0, 4, 11], 
      state: 12
    }, 
    {
      pos: [8, 4, 11], 
      state: 13
    }, 
    {
      pos: [0, 5, 11], 
      state: 9
    }, 
    {
      pos: [8, 5, 11], 
      state: 9
    }, 
    {
      pos: [2, 1, 12], 
      state: 12
    }, 
    {
      pos: [6, 1, 12], 
      state: 13
    }, 
    {
      pos: [1, 2, 12], 
      state: 12
    }, 
    {
      pos: [2, 2, 12], 
      state: 18
    }, 
    {
      pos: [6, 2, 12], 
      state: 19
    }, 
    {
      pos: [7, 2, 12], 
      state: 13
    }, 
    {
      pos: [4, 4, 12], 
      state: 15
    }, 
    {
      pos: [5, 4, 12], 
      state: 15
    }, 
    {
      pos: [2, 1, 13], 
      state: 12
    }, 
    {
      pos: [6, 1, 13], 
      state: 13
    }, 
    {
      pos: [1, 2, 13], 
      state: 12
    }, 
    {
      pos: [7, 2, 13], 
      state: 13
    }, 
    {
      pos: [2, 1, 14], 
      state: 12
    }, 
    {
      pos: [6, 1, 14], 
      state: 13
    }, 
    {
      pos: [7, 2, 14], 
      state: 13
    }, 
    {
      pos: [2, 1, 15], 
      state: 12
    }, 
    {
      pos: [6, 1, 15], 
      state: 13
    }, 
    {
      pos: [1, 2, 15], 
      state: 12
    }, 
    {
      pos: [2, 2, 15], 
      state: 18
    }, 
    {
      pos: [6, 2, 15], 
      state: 19
    }, 
    {
      pos: [7, 2, 15], 
      state: 13
    }, 
    {
      pos: [0, 4, 15], 
      state: 12
    }, 
    {
      pos: [2, 4, 15], 
      state: 20
    }, 
    {
      pos: [3, 4, 15], 
      state: 16
    }, 
    {
      pos: [4, 4, 15], 
      state: 16
    }, 
    {
      pos: [5, 4, 15], 
      state: 16
    }, 
    {
      pos: [8, 4, 15], 
      state: 13
    }, 
    {
      pos: [0, 5, 15], 
      state: 9
    }, 
    {
      pos: [8, 5, 15], 
      state: 9
    }, 
    {
      pos: [2, 1, 16], 
      state: 12
    }, 
    {
      pos: [6, 1, 16], 
      state: 13
    }, 
    {
      pos: [1, 2, 16], 
      state: 12
    }, 
    {
      pos: [3, 2, 16], 
      state: 21
    }, 
    {
      pos: [7, 2, 16], 
      state: 13
    }, 
    {
      pos: [3, 3, 16], 
      state: 22
    }, 
    {
      pos: [0, 4, 16], 
      state: 12
    }, 
    {
      pos: [8, 4, 16], 
      state: 13
    }, 
    {
      pos: [0, 5, 16], 
      state: 9
    }, 
    {
      pos: [8, 5, 16], 
      state: 9
    }, 
    {
      pos: [2, 1, 17], 
      state: 12
    }, 
    {
      pos: [6, 1, 17], 
      state: 13
    }, 
    {
      pos: [1, 2, 17], 
      state: 12
    }, 
    {
      pos: [7, 2, 17], 
      state: 13
    }, 
    {
      pos: [0, 4, 17], 
      state: 12
    }, 
    {
      pos: [8, 4, 17], 
      state: 13
    }, 
    {
      pos: [0, 5, 17], 
      state: 9
    }, 
    {
      pos: [8, 5, 17], 
      state: 9
    }, 
    {
      pos: [2, 1, 18], 
      state: 12
    }, 
    {
      pos: [6, 1, 18], 
      state: 13
    }, 
    {
      pos: [1, 2, 18], 
      state: 12
    }, 
    {
      pos: [2, 2, 18], 
      state: 18
    }, 
    {
      pos: [6, 2, 18], 
      state: 19
    }, 
    {
      pos: [7, 2, 18], 
      state: 13
    }, 
    {
      pos: [0, 4, 18], 
      state: 12
    }, 
    {
      pos: [4, 4, 18], 
      state: 8
    }, 
    {
      pos: [8, 4, 18], 
      state: 13
    }, 
    {
      pos: [1, 5, 18], 
      state: 23
    }, 
    {
      pos: [7, 5, 18], 
      state: 23
    }, 
    {
      pos: [0, 6, 18], 
      state: 11
    }, 
    {
      pos: [8, 6, 18], 
      state: 11
    }, 
    {
      pos: [2, 1, 19], 
      state: 12
    }, 
    {
      pos: [6, 1, 19], 
      state: 13
    }, 
    {
      pos: [1, 2, 19], 
      state: 12
    }, 
    {
      pos: [7, 2, 19], 
      state: 13
    }, 
    {
      pos: [3, 3, 19], 
      state: 10
    }, 
    {
      pos: [4, 3, 19], 
      state: 10
    }, 
    {
      pos: [5, 3, 19], 
      state: 10
    }, 
    {
      pos: [0, 4, 19], 
      state: 12
    }, 
    {
      pos: [4, 4, 19], 
      state: 24
    }, 
    {
      pos: [8, 4, 19], 
      state: 13
    }, 
    {
      pos: [1, 6, 19], 
      state: 23
    }, 
    {
      pos: [7, 6, 19], 
      state: 23
    }, 
    {
      pos: [4, 7, 19], 
      state: 25
    }, 
    {
      pos: [2, 1, 20], 
      state: 12
    }, 
    {
      pos: [6, 1, 20], 
      state: 13
    }, 
    {
      pos: [1, 2, 20], 
      state: 12
    }, 
    {
      pos: [7, 2, 20], 
      state: 13
    }, 
    {
      pos: [0, 4, 20], 
      state: 12
    }, 
    {
      pos: [2, 4, 20], 
      state: 18
    }, 
    {
      pos: [6, 4, 20], 
      state: 19
    }, 
    {
      pos: [8, 4, 20], 
      state: 13
    }, 
    {
      pos: [2, 6, 20], 
      state: 26
    }, 
    {
      pos: [3, 6, 20], 
      state: 26
    }, 
    {
      pos: [4, 6, 20], 
      state: 26
    }, 
    {
      pos: [5, 6, 20], 
      state: 26
    }, 
    {
      pos: [6, 6, 20], 
      state: 26
    }, 
    {
      pos: [0, 7, 20], 
      state: 11
    }, 
    {
      pos: [4, 7, 20], 
      state: 11
    }, 
    {
      pos: [8, 7, 20], 
      state: 11
    }, 
    {
      pos: [4, 0, 21], 
      state: 27
    }, 
    {
      pos: [3, 1, 21], 
      state: 12
    }, 
    {
      pos: [5, 1, 21], 
      state: 13
    }, 
    {
      pos: [2, 2, 21], 
      state: 12
    }, 
    {
      pos: [6, 2, 21], 
      state: 13
    }, 
    {
      pos: [1, 3, 21], 
      state: 12
    }, 
    {
      pos: [7, 3, 21], 
      state: 13
    }, 
    {
      pos: [0, 5, 21], 
      state: 12
    }, 
    {
      pos: [8, 5, 21], 
      state: 13
    }, 
    {
      pos: [1, 6, 21], 
      state: 28
    }, 
    {
      pos: [3, 6, 21], 
      state: 26
    }, 
    {
      pos: [4, 6, 21], 
      state: 26
    }, 
    {
      pos: [5, 6, 21], 
      state: 26
    }, 
    {
      pos: [7, 6, 21], 
      state: 28
    }, 
    {
      pos: [2, 7, 21], 
      state: 23
    }, 
    {
      pos: [6, 7, 21], 
      state: 23
    }, 
    {
      pos: [0, 8, 21], 
      state: 19
    }, 
    {
      pos: [8, 8, 21], 
      state: 18
    }, 
    {
      pos: [3, 1, 22], 
      state: 12
    }, 
    {
      pos: [5, 1, 22], 
      state: 13
    }, 
    {
      pos: [2, 2, 22], 
      state: 12
    }, 
    {
      pos: [6, 2, 22], 
      state: 13
    }, 
    {
      pos: [1, 3, 22], 
      state: 12
    }, 
    {
      pos: [7, 3, 22], 
      state: 13
    }, 
    {
      pos: [0, 5, 22], 
      state: 12
    }, 
    {
      pos: [1, 5, 22], 
      state: 18
    }, 
    {
      pos: [7, 5, 22], 
      state: 19
    }, 
    {
      pos: [8, 5, 22], 
      state: 13
    }, 
    {
      pos: [1, 7, 22], 
      state: 26
    }, 
    {
      pos: [2, 7, 22], 
      state: 26
    }, 
    {
      pos: [6, 7, 22], 
      state: 26
    }, 
    {
      pos: [7, 7, 22], 
      state: 26
    }, 
    {
      pos: [0, 8, 22], 
      state: 19
    }, 
    {
      pos: [8, 8, 22], 
      state: 18
    }, 
    {
      pos: [3, 1, 23], 
      state: 12
    }, 
    {
      pos: [5, 1, 23], 
      state: 13
    }, 
    {
      pos: [2, 2, 23], 
      state: 12
    }, 
    {
      pos: [6, 2, 23], 
      state: 13
    }, 
    {
      pos: [1, 3, 23], 
      state: 12
    }, 
    {
      pos: [7, 3, 23], 
      state: 13
    }, 
    {
      pos: [3, 4, 23], 
      state: 13
    }, 
    {
      pos: [4, 4, 23], 
      state: 29
    }, 
    {
      pos: [5, 4, 23], 
      state: 12
    }, 
    {
      pos: [0, 5, 23], 
      state: 30
    }, 
    {
      pos: [8, 5, 23], 
      state: 30
    }, 
    {
      pos: [1, 6, 23], 
      state: 28
    }, 
    {
      pos: [7, 6, 23], 
      state: 28
    }, 
    {
      pos: [1, 7, 23], 
      state: 26
    }, 
    {
      pos: [2, 7, 23], 
      state: 26
    }, 
    {
      pos: [3, 7, 23], 
      state: 26
    }, 
    {
      pos: [4, 7, 23], 
      state: 26
    }, 
    {
      pos: [5, 7, 23], 
      state: 26
    }, 
    {
      pos: [6, 7, 23], 
      state: 26
    }, 
    {
      pos: [7, 7, 23], 
      state: 26
    }, 
    {
      pos: [0, 8, 23], 
      state: 19
    }, 
    {
      pos: [1, 8, 23], 
      state: 9
    }, 
    {
      pos: [7, 8, 23], 
      state: 9
    }, 
    {
      pos: [8, 8, 23], 
      state: 18
    }, 
    {
      pos: [4, 1, 24], 
      state: 27
    }, 
    {
      pos: [2, 2, 24], 
      state: 30
    }, 
    {
      pos: [3, 2, 24], 
      state: 30
    }, 
    {
      pos: [5, 2, 24], 
      state: 30
    }, 
    {
      pos: [6, 2, 24], 
      state: 13
    }, 
    {
      pos: [1, 3, 24], 
      state: 12
    }, 
    {
      pos: [7, 3, 24], 
      state: 13
    }, 
    {
      pos: [2, 7, 24], 
      state: 26
    }, 
    {
      pos: [3, 7, 24], 
      state: 26
    }, 
    {
      pos: [4, 7, 24], 
      state: 26
    }, 
    {
      pos: [5, 7, 24], 
      state: 26
    }, 
    {
      pos: [6, 7, 24], 
      state: 26
    }, 
    {
      pos: [1, 8, 24], 
      state: 9
    }, 
    {
      pos: [7, 8, 24], 
      state: 9
    }, 
    {
      pos: [4, 2, 25], 
      state: 9
    }, 
    {
      pos: [2, 3, 25], 
      state: 30
    }, 
    {
      pos: [3, 3, 25], 
      state: 30
    }, 
    {
      pos: [4, 3, 25], 
      state: 9
    }, 
    {
      pos: [5, 3, 25], 
      state: 30
    }, 
    {
      pos: [6, 3, 25], 
      state: 30
    }, 
    {
      pos: [1, 5, 25], 
      state: 30
    }, 
    {
      pos: [3, 5, 25], 
      state: 11
    }, 
    {
      pos: [4, 5, 25], 
      state: 11
    }, 
    {
      pos: [5, 5, 25], 
      state: 11
    }, 
    {
      pos: [7, 5, 25], 
      state: 30
    }, 
    {
      pos: [2, 6, 25], 
      state: 28
    }, 
    {
      pos: [6, 6, 25], 
      state: 28
    }, 
    {
      pos: [2, 7, 25], 
      state: 26
    }, 
    {
      pos: [3, 7, 25], 
      state: 26
    }, 
    {
      pos: [4, 7, 25], 
      state: 26
    }, 
    {
      pos: [5, 7, 25], 
      state: 26
    }, 
    {
      pos: [6, 7, 25], 
      state: 26
    }, 
    {
      pos: [4, 4, 26], 
      state: 30
    }, 
    {
      pos: [3, 5, 26], 
      state: 30
    }, 
    {
      pos: [5, 5, 26], 
      state: 30
    }, 
    {
      pos: [2, 6, 26], 
      state: 30
    }, 
    {
      pos: [6, 6, 26], 
      state: 30
    }, 
    {
      pos: [4, 7, 26], 
      state: 26
    }, 
    {
      pos: [3, 8, 26], 
      state: 9
    }, 
    {
      pos: [5, 8, 26], 
      state: 9
    }, 
    {
      pos: [3, 7, 27], 
      state: 30
    }, 
    {
      pos: [5, 7, 27], 
      state: 30
    }, 
    {
      pos: [3, 8, 27], 
      state: 9
    }, 
    {
      pos: [4, 8, 27], 
      state: 9
    }, 
    {
      pos: [5, 8, 27], 
      state: 9
    }
  ], 
  palettes: [
    [
      {
        Name: "minecraft:spruce_planks"
      }, 
      {
        Name: "minecraft:oak_planks"
      }, 
      {
        Properties: {
          axis: "y"
        }, 
        Name: "minecraft:oak_log"
      }, 
      {
        Properties: {
          facing: "south", 
          type: "single"
        }, 
        Name: "minecraft:chest"
      }, 
      {
        Properties: {
          mode: "data"
        }, 
        Name: "minecraft:structure_block"
      }, 
      {
        Properties: {
          facing: "west", 
          type: "single"
        }, 
        Name: "minecraft:chest"
      }, 
      {
        Properties: {
          facing: "north", 
          type: "single"
        }, 
        Name: "minecraft:chest"
      }, 
      {
        Properties: {
          half: "top", 
          shape: "outer_right", 
          facing: "south"
        }, 
        Name: "minecraft:spruce_stairs"
      }, 
      {
        Properties: {
          half: "bottom", 
          shape: "outer_right", 
          facing: "north"
        }, 
        Name: "minecraft:spruce_stairs"
      }, 
      {
        Properties: {
          east: "false", 
          south: "false", 
          north: "false", 
          west: "false"
        }, 
        Name: "minecraft:spruce_fence"
      }, 
      {
        Properties: {
          half: "top", 
          shape: "outer_right", 
          facing: "south"
        }, 
        Name: "minecraft:oak_stairs"
      }, 
      {
        Properties: {
          half: "bottom", 
          shape: "outer_right", 
          facing: "south"
        }, 
        Name: "minecraft:oak_stairs"
      }, 
      {
        Properties: {
          half: "top", 
          shape: "outer_right", 
          facing: "east"
        }, 
        Name: "minecraft:oak_stairs"
      }, 
      {
        Properties: {
          half: "top", 
          shape: "outer_right", 
          facing: "west"
        }, 
        Name: "minecraft:oak_stairs"
      }, 
      {
        Properties: {
          half: "bottom", 
          shape: "outer_right", 
          facing: "north"
        }, 
        Name: "minecraft:oak_stairs"
      }, 
      {
        Properties: {
          half: "top", 
          powered: "false", 
          facing: "south", 
          open: "false"
        }, 
        Name: "minecraft:oak_trapdoor"
      }, 
      {
        Properties: {
          half: "top", 
          powered: "false", 
          facing: "north", 
          open: "false"
        }, 
        Name: "minecraft:oak_trapdoor"
      }, 
      {
        Properties: {
          half: "top", 
          powered: "false", 
          facing: "west", 
          open: "false"
        }, 
        Name: "minecraft:oak_trapdoor"
      }, 
      {
        Properties: {
          half: "bottom", 
          shape: "outer_right", 
          facing: "west"
        }, 
        Name: "minecraft:oak_stairs"
      }, 
      {
        Properties: {
          half: "bottom", 
          shape: "outer_right", 
          facing: "east"
        }, 
        Name: "minecraft:oak_stairs"
      }, 
      {
        Properties: {
          half: "top", 
          shape: "outer_right", 
          facing: "west"
        }, 
        Name: "minecraft:spruce_stairs"
      }, 
      {
        Properties: {
          hinge: "right", 
          half: "lower", 
          powered: "false", 
          facing: "south", 
          open: "false"
        }, 
        Name: "minecraft:oak_door"
      }, 
      {
        Properties: {
          hinge: "left", 
          half: "upper", 
          powered: "false", 
          facing: "east", 
          open: "false"
        }, 
        Name: "minecraft:oak_door"
      }, 
      {
        Properties: {
          half: "bottom", 
          shape: "outer_right", 
          facing: "south"
        }, 
        Name: "minecraft:spruce_stairs"
      }, 
      {
        Properties: {
          half: "bottom"
        }, 
        Name: "minecraft:spruce_slab"
      }, 
      {
        Properties: {
          half: "bottom"
        }, 
        Name: "minecraft:oak_slab"
      }, 
      {
        Properties: {
          half: "top"
        }, 
        Name: "minecraft:spruce_slab"
      }, 
      {
        Properties: {
          half: "top", 
          shape: "outer_right", 
          facing: "north"
        }, 
        Name: "minecraft:spruce_stairs"
      }, 
      {
        Properties: {
          east: "false", 
          south: "false", 
          north: "false", 
          west: "false"
        }, 
        Name: "minecraft:oak_fence"
      }, 
      {
        Properties: {
          half: "top"
        }, 
        Name: "minecraft:oak_slab"
      }, 
      {
        Properties: {
          half: "top", 
          shape: "outer_right", 
          facing: "north"
        }, 
        Name: "minecraft:oak_stairs"
      }
    ], 
    [
      {
        Name: "minecraft:spruce_planks"
      }, 
      {
        Name: "minecraft:jungle_planks"
      }, 
      {
        Properties: {
          axis: "y"
        }, 
        Name: "minecraft:jungle_log"
      }, 
      {
        Properties: {
          facing: "south", 
          type: "single"
        }, 
        Name: "minecraft:chest"
      }, 
      {
        Properties: {
          mode: "data"
        }, 
        Name: "minecraft:structure_block"
      }, 
      {
        Properties: {
          facing: "west", 
          type: "single"
        }, 
        Name: "minecraft:chest"
      }, 
      {
        Properties: {
          facing: "north", 
          type: "single"
        }, 
        Name: "minecraft:chest"
      }, 
      {
        Properties: {
          half: "top", 
          shape: "outer_right", 
          facing: "south"
        }, 
        Name: "minecraft:spruce_stairs"
      }, 
      {
        Properties: {
          half: "bottom", 
          shape: "outer_right", 
          facing: "north"
        }, 
        Name: "minecraft:spruce_stairs"
      }, 
      {
        Properties: {
          east: "false", 
          south: "false", 
          north: "false", 
          west: "false"
        }, 
        Name: "minecraft:spruce_fence"
      }, 
      {
        Properties: {
          half: "top", 
          shape: "outer_right", 
          facing: "south"
        }, 
        Name: "minecraft:jungle_stairs"
      }, 
      {
        Properties: {
          half: "bottom", 
          shape: "outer_right", 
          facing: "south"
        }, 
        Name: "minecraft:jungle_stairs"
      }, 
      {
        Properties: {
          half: "top", 
          shape: "outer_right", 
          facing: "east"
        }, 
        Name: "minecraft:jungle_stairs"
      }, 
      {
        Properties: {
          half: "top", 
          shape: "outer_right", 
          facing: "west"
        }, 
        Name: "minecraft:jungle_stairs"
      }, 
      {
        Properties: {
          half: "bottom", 
          shape: "outer_right", 
          facing: "north"
        }, 
        Name: "minecraft:jungle_stairs"
      }, 
      {
        Properties: {
          half: "top", 
          powered: "false", 
          facing: "south", 
          open: "false"
        }, 
        Name: "minecraft:jungle_trapdoor"
      }, 
      {
        Properties: {
          half: "top", 
          powered: "false", 
          facing: "north", 
          open: "false"
        }, 
        Name: "minecraft:jungle_trapdoor"
      }, 
      {
        Properties: {
          half: "top", 
          powered: "false", 
          facing: "west", 
          open: "false"
        }, 
        Name: "minecraft:jungle_trapdoor"
      }, 
      {
        Properties: {
          half: "bottom", 
          shape: "outer_right", 
          facing: "west"
        }, 
        Name: "minecraft:jungle_stairs"
      }, 
      {
        Properties: {
          half: "bottom", 
          shape: "outer_right", 
          facing: "east"
        }, 
        Name: "minecraft:jungle_stairs"
      }, 
      {
        Properties: {
          half: "top", 
          shape: "outer_right", 
          facing: "west"
        }, 
        Name: "minecraft:spruce_stairs"
      }, 
      {
        Properties: {
          hinge: "right", 
          half: "lower", 
          powered: "false", 
          facing: "south", 
          open: "false"
        }, 
        Name: "minecraft:jungle_door"
      }, 
      {
        Properties: {
          hinge: "left", 
          half: "upper", 
          powered: "false", 
          facing: "east", 
          open: "false"
        }, 
        Name: "minecraft:jungle_door"
      }, 
      {
        Properties: {
          half: "bottom", 
          shape: "outer_right", 
          facing: "south"
        }, 
        Name: "minecraft:spruce_stairs"
      }, 
      {
        Properties: {
          half: "bottom"
        }, 
        Name: "minecraft:spruce_slab"
      }, 
      {
        Properties: {
          half: "bottom"
        }, 
        Name: "minecraft:jungle_slab"
      }, 
      {
        Properties: {
          half: "top"
        }, 
        Name: "minecraft:spruce_slab"
      }, 
      {
        Properties: {
          half: "top", 
          shape: "outer_right", 
          facing: "north"
        }, 
        Name: "minecraft:spruce_stairs"
      }, 
      {
        Properties: {
          east: "false", 
          south: "false", 
          north: "false", 
          west: "false"
        }, 
        Name: "minecraft:jungle_fence"
      }, 
      {
        Properties: {
          half: "top"
        }, 
        Name: "minecraft:jungle_slab"
      }, 
      {
        Properties: {
          half: "top", 
          shape: "outer_right", 
          facing: "north"
        }, 
        Name: "minecraft:jungle_stairs"
      }
    ], 
    [
      {
        Name: "minecraft:jungle_planks"
      }, 
      {
        Name: "minecraft:dark_oak_planks"
      }, 
      {
        Properties: {
          axis: "y"
        }, 
        Name: "minecraft:dark_oak_log"
      }, 
      {
        Properties: {
          facing: "south", 
          type: "single"
        }, 
        Name: "minecraft:chest"
      }, 
      {
        Properties: {
          mode: "data"
        }, 
        Name: "minecraft:structure_block"
      }, 
      {
        Properties: {
          facing: "west", 
          type: "single"
        }, 
        Name: "minecraft:chest"
      }, 
      {
        Properties: {
          facing: "north", 
          type: "single"
        }, 
        Name: "minecraft:chest"
      }, 
      {
        Properties: {
          half: "top", 
          shape: "outer_right", 
          facing: "south"
        }, 
        Name: "minecraft:jungle_stairs"
      }, 
      {
        Properties: {
          half: "bottom", 
          shape: "outer_right", 
          facing: "north"
        }, 
        Name: "minecraft:jungle_stairs"
      }, 
      {
        Properties: {
          east: "false", 
          south: "false", 
          north: "false", 
          west: "false"
        }, 
        Name: "minecraft:jungle_fence"
      }, 
      {
        Properties: {
          half: "top", 
          shape: "outer_right", 
          facing: "south"
        }, 
        Name: "minecraft:dark_oak_stairs"
      }, 
      {
        Properties: {
          half: "bottom", 
          shape: "outer_right", 
          facing: "south"
        }, 
        Name: "minecraft:dark_oak_stairs"
      }, 
      {
        Properties: {
          half: "top", 
          shape: "outer_right", 
          facing: "east"
        }, 
        Name: "minecraft:dark_oak_stairs"
      }, 
      {
        Properties: {
          half: "top", 
          shape: "outer_right", 
          facing: "west"
        }, 
        Name: "minecraft:dark_oak_stairs"
      }, 
      {
        Properties: {
          half: "bottom", 
          shape: "outer_right", 
          facing: "north"
        }, 
        Name: "minecraft:dark_oak_stairs"
      }, 
      {
        Properties: {
          half: "top", 
          powered: "false", 
          facing: "south", 
          open: "false"
        }, 
        Name: "minecraft:dark_oak_trapdoor"
      }, 
      {
        Properties: {
          half: "top", 
          powered: "false", 
          facing: "north", 
          open: "false"
        }, 
        Name: "minecraft:dark_oak_trapdoor"
      }, 
      {
        Properties: {
          half: "top", 
          powered: "false", 
          facing: "west", 
          open: "false"
        }, 
        Name: "minecraft:dark_oak_trapdoor"
      }, 
      {
        Properties: {
          half: "bottom", 
          shape: "outer_right", 
          facing: "west"
        }, 
        Name: "minecraft:dark_oak_stairs"
      }, 
      {
        Properties: {
          half: "bottom", 
          shape: "outer_right", 
          facing: "east"
        }, 
        Name: "minecraft:dark_oak_stairs"
      }, 
      {
        Properties: {
          half: "top", 
          shape: "outer_right", 
          facing: "west"
        }, 
        Name: "minecraft:jungle_stairs"
      }, 
      {
        Properties: {
          hinge: "right", 
          half: "lower", 
          powered: "false", 
          facing: "south", 
          open: "false"
        }, 
        Name: "minecraft:dark_oak_door"
      }, 
      {
        Properties: {
          hinge: "left", 
          half: "upper", 
          powered: "false", 
          facing: "east", 
          open: "false"
        }, 
        Name: "minecraft:dark_oak_door"
      }, 
      {
        Properties: {
          half: "bottom", 
          shape: "outer_right", 
          facing: "south"
        }, 
        Name: "minecraft:jungle_stairs"
      }, 
      {
        Properties: {
          half: "bottom"
        }, 
        Name: "minecraft:jungle_slab"
      }, 
      {
        Properties: {
          half: "bottom"
        }, 
        Name: "minecraft:dark_oak_slab"
      }, 
      {
        Properties: {
          half: "top"
        }, 
        Name: "minecraft:jungle_slab"
      }, 
      {
        Properties: {
          half: "top", 
          shape: "outer_right", 
          facing: "north"
        }, 
        Name: "minecraft:jungle_stairs"
      }, 
      {
        Properties: {
          east: "false", 
          south: "false", 
          north: "false", 
          west: "false"
        }, 
        Name: "minecraft:dark_oak_fence"
      }, 
      {
        Properties: {
          half: "top"
        }, 
        Name: "minecraft:dark_oak_slab"
      }, 
      {
        Properties: {
          half: "top", 
          shape: "outer_right", 
          facing: "north"
        }, 
        Name: "minecraft:dark_oak_stairs"
      }
    ], 
    [
      {
        Name: "minecraft:spruce_planks"
      }, 
      {
        Name: "minecraft:dark_oak_planks"
      }, 
      {
        Properties: {
          axis: "y"
        }, 
        Name: "minecraft:dark_oak_log"
      }, 
      {
        Properties: {
          facing: "south", 
          type: "single"
        }, 
        Name: "minecraft:chest"
      }, 
      {
        Properties: {
          mode: "data"
        }, 
        Name: "minecraft:structure_block"
      }, 
      {
        Properties: {
          facing: "west", 
          type: "single"
        }, 
        Name: "minecraft:chest"
      }, 
      {
        Properties: {
          facing: "north", 
          type: "single"
        }, 
        Name: "minecraft:chest"
      }, 
      {
        Properties: {
          half: "top", 
          shape: "outer_right", 
          facing: "south"
        }, 
        Name: "minecraft:spruce_stairs"
      }, 
      {
        Properties: {
          half: "bottom", 
          shape: "outer_right", 
          facing: "north"
        }, 
        Name: "minecraft:spruce_stairs"
      }, 
      {
        Properties: {
          east: "false", 
          south: "false", 
          north: "false", 
          west: "false"
        }, 
        Name: "minecraft:spruce_fence"
      }, 
      {
        Properties: {
          half: "top", 
          shape: "outer_right", 
          facing: "south"
        }, 
        Name: "minecraft:dark_oak_stairs"
      }, 
      {
        Properties: {
          half: "bottom", 
          shape: "outer_right", 
          facing: "south"
        }, 
        Name: "minecraft:dark_oak_stairs"
      }, 
      {
        Properties: {
          half: "top", 
          shape: "outer_right", 
          facing: "east"
        }, 
        Name: "minecraft:dark_oak_stairs"
      }, 
      {
        Properties: {
          half: "top", 
          shape: "outer_right", 
          facing: "west"
        }, 
        Name: "minecraft:dark_oak_stairs"
      }, 
      {
        Properties: {
          half: "bottom", 
          shape: "outer_right", 
          facing: "north"
        }, 
        Name: "minecraft:dark_oak_stairs"
      }, 
      {
        Properties: {
          half: "top", 
          powered: "false", 
          facing: "south", 
          open: "false"
        }, 
        Name: "minecraft:dark_oak_trapdoor"
      }, 
      {
        Properties: {
          half: "top", 
          powered: "false", 
          facing: "north", 
          open: "false"
        }, 
        Name: "minecraft:dark_oak_trapdoor"
      }, 
      {
        Properties: {
          half: "top", 
          powered: "false", 
          facing: "west", 
          open: "false"
        }, 
        Name: "minecraft:dark_oak_trapdoor"
      }, 
      {
        Properties: {
          half: "bottom", 
          shape: "outer_right", 
          facing: "west"
        }, 
        Name: "minecraft:dark_oak_stairs"
      }, 
      {
        Properties: {
          half: "bottom", 
          shape: "outer_right", 
          facing: "east"
        }, 
        Name: "minecraft:dark_oak_stairs"
      }, 
      {
        Properties: {
          half: "top", 
          shape: "outer_right", 
          facing: "west"
        }, 
        Name: "minecraft:spruce_stairs"
      }, 
      {
        Properties: {
          hinge: "right", 
          half: "lower", 
          powered: "false", 
          facing: "south", 
          open: "false"
        }, 
        Name: "minecraft:dark_oak_door"
      }, 
      {
        Properties: {
          hinge: "left", 
          half: "upper", 
          powered: "false", 
          facing: "east", 
          open: "false"
        }, 
        Name: "minecraft:dark_oak_door"
      }, 
      {
        Properties: {
          half: "bottom", 
          shape: "outer_right", 
          facing: "south"
        }, 
        Name: "minecraft:spruce_stairs"
      }, 
      {
        Properties: {
          half: "bottom"
        }, 
        Name: "minecraft:spruce_slab"
      }, 
      {
        Properties: {
          half: "bottom"
        }, 
        Name: "minecraft:dark_oak_slab"
      }, 
      {
        Properties: {
          half: "top"
        }, 
        Name: "minecraft:spruce_slab"
      }, 
      {
        Properties: {
          half: "top", 
          shape: "outer_right", 
          facing: "north"
        }, 
        Name: "minecraft:spruce_stairs"
      }, 
      {
        Properties: {
          east: "false", 
          south: "false", 
          north: "false", 
          west: "false"
        }, 
        Name: "minecraft:dark_oak_fence"
      }, 
      {
        Properties: {
          half: "top"
        }, 
        Name: "minecraft:dark_oak_slab"
      }, 
      {
        Properties: {
          half: "top", 
          shape: "outer_right", 
          facing: "north"
        }, 
        Name: "minecraft:dark_oak_stairs"
      }
    ], 
    [
      {
        Name: "minecraft:oak_planks"
      }, 
      {
        Name: "minecraft:spruce_planks"
      }, 
      {
        Properties: {
          axis: "y"
        }, 
        Name: "minecraft:spruce_log"
      }, 
      {
        Properties: {
          facing: "south", 
          type: "single"
        }, 
        Name: "minecraft:chest"
      }, 
      {
        Properties: {
          mode: "data"
        }, 
        Name: "minecraft:structure_block"
      }, 
      {
        Properties: {
          facing: "west", 
          type: "single"
        }, 
        Name: "minecraft:chest"
      }, 
      {
        Properties: {
          facing: "north", 
          type: "single"
        }, 
        Name: "minecraft:chest"
      }, 
      {
        Properties: {
          half: "top", 
          shape: "outer_right", 
          facing: "south"
        }, 
        Name: "minecraft:oak_stairs"
      }, 
      {
        Properties: {
          half: "bottom", 
          shape: "outer_right", 
          facing: "north"
        }, 
        Name: "minecraft:oak_stairs"
      }, 
      {
        Properties: {
          east: "false", 
          south: "false", 
          north: "false", 
          west: "false"
        }, 
        Name: "minecraft:oak_fence"
      }, 
      {
        Properties: {
          half: "top", 
          shape: "outer_right", 
          facing: "south"
        }, 
        Name: "minecraft:spruce_stairs"
      }, 
      {
        Properties: {
          half: "bottom", 
          shape: "outer_right", 
          facing: "south"
        }, 
        Name: "minecraft:spruce_stairs"
      }, 
      {
        Properties: {
          half: "top", 
          shape: "outer_right", 
          facing: "east"
        }, 
        Name: "minecraft:spruce_stairs"
      }, 
      {
        Properties: {
          half: "top", 
          shape: "outer_right", 
          facing: "west"
        }, 
        Name: "minecraft:spruce_stairs"
      }, 
      {
        Properties: {
          half: "bottom", 
          shape: "outer_right", 
          facing: "north"
        }, 
        Name: "minecraft:spruce_stairs"
      }, 
      {
        Properties: {
          half: "top", 
          powered: "false", 
          facing: "south", 
          open: "false"
        }, 
        Name: "minecraft:spruce_trapdoor"
      }, 
      {
        Properties: {
          half: "top", 
          powered: "false", 
          facing: "north", 
          open: "false"
        }, 
        Name: "minecraft:spruce_trapdoor"
      }, 
      {
        Properties: {
          half: "top", 
          powered: "false", 
          facing: "west", 
          open: "false"
        }, 
        Name: "minecraft:spruce_trapdoor"
      }, 
      {
        Properties: {
          half: "bottom", 
          shape: "outer_right", 
          facing: "west"
        }, 
        Name: "minecraft:spruce_stairs"
      }, 
      {
        Properties: {
          half: "bottom", 
          shape: "outer_right", 
          facing: "east"
        }, 
        Name: "minecraft:spruce_stairs"
      }, 
      {
        Properties: {
          half: "top", 
          shape: "outer_right", 
          facing: "west"
        }, 
        Name: "minecraft:oak_stairs"
      }, 
      {
        Properties: {
          hinge: "right", 
          half: "lower", 
          powered: "false", 
          facing: "south", 
          open: "false"
        }, 
        Name: "minecraft:spruce_door"
      }, 
      {
        Properties: {
          hinge: "left", 
          half: "upper", 
          powered: "false", 
          facing: "east", 
          open: "false"
        }, 
        Name: "minecraft:spruce_door"
      }, 
      {
        Properties: {
          half: "bottom", 
          shape: "outer_right", 
          facing: "south"
        }, 
        Name: "minecraft:oak_stairs"
      }, 
      {
        Properties: {
          half: "bottom"
        }, 
        Name: "minecraft:oak_slab"
      }, 
      {
        Properties: {
          half: "bottom"
        }, 
        Name: "minecraft:spruce_slab"
      }, 
      {
        Properties: {
          half: "top"
        }, 
        Name: "minecraft:oak_slab"
      }, 
      {
        Properties: {
          half: "top", 
          shape: "outer_right", 
          facing: "north"
        }, 
        Name: "minecraft:oak_stairs"
      }, 
      {
        Properties: {
          east: "false", 
          south: "false", 
          north: "false", 
          west: "false"
        }, 
        Name: "minecraft:spruce_fence"
      }, 
      {
        Properties: {
          half: "top"
        }, 
        Name: "minecraft:spruce_slab"
      }, 
      {
        Properties: {
          half: "top", 
          shape: "outer_right", 
          facing: "north"
        }, 
        Name: "minecraft:spruce_stairs"
      }
    ], 
    [
      {
        Name: "minecraft:jungle_planks"
      }, 
      {
        Name: "minecraft:spruce_planks"
      }, 
      {
        Properties: {
          axis: "y"
        }, 
        Name: "minecraft:spruce_log"
      }, 
      {
        Properties: {
          facing: "south", 
          type: "single"
        }, 
        Name: "minecraft:chest"
      }, 
      {
        Properties: {
          mode: "data"
        }, 
        Name: "minecraft:structure_block"
      }, 
      {
        Properties: {
          facing: "west", 
          type: "single"
        }, 
        Name: "minecraft:chest"
      }, 
      {
        Properties: {
          facing: "north", 
          type: "single"
        }, 
        Name: "minecraft:chest"
      }, 
      {
        Properties: {
          half: "top", 
          shape: "outer_right", 
          facing: "south"
        }, 
        Name: "minecraft:jungle_stairs"
      }, 
      {
        Properties: {
          half: "bottom", 
          shape: "outer_right", 
          facing: "north"
        }, 
        Name: "minecraft:jungle_stairs"
      }, 
      {
        Properties: {
          east: "false", 
          south: "false", 
          north: "false", 
          west: "false"
        }, 
        Name: "minecraft:jungle_fence"
      }, 
      {
        Properties: {
          half: "top", 
          shape: "outer_right", 
          facing: "south"
        }, 
        Name: "minecraft:spruce_stairs"
      }, 
      {
        Properties: {
          half: "bottom", 
          shape: "outer_right", 
          facing: "south"
        }, 
        Name: "minecraft:spruce_stairs"
      }, 
      {
        Properties: {
          half: "top", 
          shape: "outer_right", 
          facing: "east"
        }, 
        Name: "minecraft:spruce_stairs"
      }, 
      {
        Properties: {
          half: "top", 
          shape: "outer_right", 
          facing: "west"
        }, 
        Name: "minecraft:spruce_stairs"
      }, 
      {
        Properties: {
          half: "bottom", 
          shape: "outer_right", 
          facing: "north"
        }, 
        Name: "minecraft:spruce_stairs"
      }, 
      {
        Properties: {
          half: "top", 
          powered: "false", 
          facing: "south", 
          open: "false"
        }, 
        Name: "minecraft:spruce_trapdoor"
      }, 
      {
        Properties: {
          half: "top", 
          powered: "false", 
          facing: "north", 
          open: "false"
        }, 
        Name: "minecraft:spruce_trapdoor"
      }, 
      {
        Properties: {
          half: "top", 
          powered: "false", 
          facing: "west", 
          open: "false"
        }, 
        Name: "minecraft:spruce_trapdoor"
      }, 
      {
        Properties: {
          half: "bottom", 
          shape: "outer_right", 
          facing: "west"
        }, 
        Name: "minecraft:spruce_stairs"
      }, 
      {
        Properties: {
          half: "bottom", 
          shape: "outer_right", 
          facing: "east"
        }, 
        Name: "minecraft:spruce_stairs"
      }, 
      {
        Properties: {
          half: "top", 
          shape: "outer_right", 
          facing: "west"
        }, 
        Name: "minecraft:jungle_stairs"
      }, 
      {
        Properties: {
          hinge: "right", 
          half: "lower", 
          powered: "false", 
          facing: "south", 
          open: "false"
        }, 
        Name: "minecraft:spruce_door"
      }, 
      {
        Properties: {
          hinge: "left", 
          half: "upper", 
          powered: "false", 
          facing: "east", 
          open: "false"
        }, 
        Name: "minecraft:spruce_door"
      }, 
      {
        Properties: {
          half: "bottom", 
          shape: "outer_right", 
          facing: "south"
        }, 
        Name: "minecraft:jungle_stairs"
      }, 
      {
        Properties: {
          half: "bottom"
        }, 
        Name: "minecraft:jungle_slab"
      }, 
      {
        Properties: {
          half: "bottom"
        }, 
        Name: "minecraft:spruce_slab"
      }, 
      {
        Properties: {
          half: "top"
        }, 
        Name: "minecraft:jungle_slab"
      }, 
      {
        Properties: {
          half: "top", 
          shape: "outer_right", 
          facing: "north"
        }, 
        Name: "minecraft:jungle_stairs"
      }, 
      {
        Properties: {
          east: "false", 
          south: "false", 
          north: "false", 
          west: "false"
        }, 
        Name: "minecraft:spruce_fence"
      }, 
      {
        Properties: {
          half: "top"
        }, 
        Name: "minecraft:spruce_slab"
      }, 
      {
        Properties: {
          half: "top", 
          shape: "outer_right", 
          facing: "north"
        }, 
        Name: "minecraft:spruce_stairs"
      }
    ], 
    [
      {
        Name: "minecraft:dark_oak_planks"
      }, 
      {
        Name: "minecraft:spruce_planks"
      }, 
      {
        Properties: {
          axis: "y"
        }, 
        Name: "minecraft:spruce_log"
      }, 
      {
        Properties: {
          facing: "south", 
          type: "single"
        }, 
        Name: "minecraft:chest"
      }, 
      {
        Properties: {
          mode: "data"
        }, 
        Name: "minecraft:structure_block"
      }, 
      {
        Properties: {
          facing: "west", 
          type: "single"
        }, 
        Name: "minecraft:chest"
      }, 
      {
        Properties: {
          facing: "north", 
          type: "single"
        }, 
        Name: "minecraft:chest"
      }, 
      {
        Properties: {
          half: "top", 
          shape: "outer_right", 
          facing: "south"
        }, 
        Name: "minecraft:dark_oak_stairs"
      }, 
      {
        Properties: {
          half: "bottom", 
          shape: "outer_right", 
          facing: "north"
        }, 
        Name: "minecraft:dark_oak_stairs"
      }, 
      {
        Properties: {
          east: "false", 
          south: "false", 
          north: "false", 
          west: "false"
        }, 
        Name: "minecraft:dark_oak_fence"
      }, 
      {
        Properties: {
          half: "top", 
          shape: "outer_right", 
          facing: "south"
        }, 
        Name: "minecraft:spruce_stairs"
      }, 
      {
        Properties: {
          half: "bottom", 
          shape: "outer_right", 
          facing: "south"
        }, 
        Name: "minecraft:spruce_stairs"
      }, 
      {
        Properties: {
          half: "top", 
          shape: "outer_right", 
          facing: "east"
        }, 
        Name: "minecraft:spruce_stairs"
      }, 
      {
        Properties: {
          half: "top", 
          shape: "outer_right", 
          facing: "west"
        }, 
        Name: "minecraft:spruce_stairs"
      }, 
      {
        Properties: {
          half: "bottom", 
          shape: "outer_right", 
          facing: "north"
        }, 
        Name: "minecraft:spruce_stairs"
      }, 
      {
        Properties: {
          half: "top", 
          powered: "false", 
          facing: "south", 
          open: "false"
        }, 
        Name: "minecraft:spruce_trapdoor"
      }, 
      {
        Properties: {
          half: "top", 
          powered: "false", 
          facing: "north", 
          open: "false"
        }, 
        Name: "minecraft:spruce_trapdoor"
      }, 
      {
        Properties: {
          half: "top", 
          powered: "false", 
          facing: "west", 
          open: "false"
        }, 
        Name: "minecraft:spruce_trapdoor"
      }, 
      {
        Properties: {
          half: "bottom", 
          shape: "outer_right", 
          facing: "west"
        }, 
        Name: "minecraft:spruce_stairs"
      }, 
      {
        Properties: {
          half: "bottom", 
          shape: "outer_right", 
          facing: "east"
        }, 
        Name: "minecraft:spruce_stairs"
      }, 
      {
        Properties: {
          half: "top", 
          shape: "outer_right", 
          facing: "west"
        }, 
        Name: "minecraft:dark_oak_stairs"
      }, 
      {
        Properties: {
          hinge: "right", 
          half: "lower", 
          powered: "false", 
          facing: "south", 
          open: "false"
        }, 
        Name: "minecraft:spruce_door"
      }, 
      {
        Properties: {
          hinge: "left", 
          half: "upper", 
          powered: "false", 
          facing: "east", 
          open: "false"
        }, 
        Name: "minecraft:spruce_door"
      }, 
      {
        Properties: {
          half: "bottom", 
          shape: "outer_right", 
          facing: "south"
        }, 
        Name: "minecraft:dark_oak_stairs"
      }, 
      {
        Properties: {
          half: "bottom"
        }, 
        Name: "minecraft:dark_oak_slab"
      }, 
      {
        Properties: {
          half: "bottom"
        }, 
        Name: "minecraft:spruce_slab"
      }, 
      {
        Properties: {
          half: "top"
        }, 
        Name: "minecraft:dark_oak_slab"
      }, 
      {
        Properties: {
          half: "top", 
          shape: "outer_right", 
          facing: "north"
        }, 
        Name: "minecraft:dark_oak_stairs"
      }, 
      {
        Properties: {
          east: "false", 
          south: "false", 
          north: "false", 
          west: "false"
        }, 
        Name: "minecraft:spruce_fence"
      }, 
      {
        Properties: {
          half: "top"
        }, 
        Name: "minecraft:spruce_slab"
      }, 
      {
        Properties: {
          half: "top", 
          shape: "outer_right", 
          facing: "north"
        }, 
        Name: "minecraft:spruce_stairs"
      }
    ], 
    [
      {
        Name: "minecraft:birch_planks"
      }, 
      {
        Name: "minecraft:oak_planks"
      }, 
      {
        Properties: {
          axis: "y"
        }, 
        Name: "minecraft:oak_log"
      }, 
      {
        Properties: {
          facing: "south", 
          type: "single"
        }, 
        Name: "minecraft:chest"
      }, 
      {
        Properties: {
          mode: "data"
        }, 
        Name: "minecraft:structure_block"
      }, 
      {
        Properties: {
          facing: "west", 
          type: "single"
        }, 
        Name: "minecraft:chest"
      }, 
      {
        Properties: {
          facing: "north", 
          type: "single"
        }, 
        Name: "minecraft:chest"
      }, 
      {
        Properties: {
          half: "top", 
          shape: "outer_right", 
          facing: "south"
        }, 
        Name: "minecraft:birch_stairs"
      }, 
      {
        Properties: {
          half: "bottom", 
          shape: "outer_right", 
          facing: "north"
        }, 
        Name: "minecraft:birch_stairs"
      }, 
      {
        Properties: {
          east: "false", 
          south: "false", 
          north: "false", 
          west: "false"
        }, 
        Name: "minecraft:birch_fence"
      }, 
      {
        Properties: {
          half: "top", 
          shape: "outer_right", 
          facing: "south"
        }, 
        Name: "minecraft:oak_stairs"
      }, 
      {
        Properties: {
          half: "bottom", 
          shape: "outer_right", 
          facing: "south"
        }, 
        Name: "minecraft:oak_stairs"
      }, 
      {
        Properties: {
          half: "top", 
          shape: "outer_right", 
          facing: "east"
        }, 
        Name: "minecraft:oak_stairs"
      }, 
      {
        Properties: {
          half: "top", 
          shape: "outer_right", 
          facing: "west"
        }, 
        Name: "minecraft:oak_stairs"
      }, 
      {
        Properties: {
          half: "bottom", 
          shape: "outer_right", 
          facing: "north"
        }, 
        Name: "minecraft:oak_stairs"
      }, 
      {
        Properties: {
          half: "top", 
          powered: "false", 
          facing: "south", 
          open: "false"
        }, 
        Name: "minecraft:oak_trapdoor"
      }, 
      {
        Properties: {
          half: "top", 
          powered: "false", 
          facing: "north", 
          open: "false"
        }, 
        Name: "minecraft:oak_trapdoor"
      }, 
      {
        Properties: {
          half: "top", 
          powered: "false", 
          facing: "west", 
          open: "false"
        }, 
        Name: "minecraft:oak_trapdoor"
      }, 
      {
        Properties: {
          half: "bottom", 
          shape: "outer_right", 
          facing: "west"
        }, 
        Name: "minecraft:oak_stairs"
      }, 
      {
        Properties: {
          half: "bottom", 
          shape: "outer_right", 
          facing: "east"
        }, 
        Name: "minecraft:oak_stairs"
      }, 
      {
        Properties: {
          half: "top", 
          shape: "outer_right", 
          facing: "west"
        }, 
        Name: "minecraft:birch_stairs"
      }, 
      {
        Properties: {
          hinge: "right", 
          half: "lower", 
          powered: "false", 
          facing: "south", 
          open: "false"
        }, 
        Name: "minecraft:oak_door"
      }, 
      {
        Properties: {
          hinge: "left", 
          half: "upper", 
          powered: "false", 
          facing: "east", 
          open: "false"
        }, 
        Name: "minecraft:oak_door"
      }, 
      {
        Properties: {
          half: "bottom", 
          shape: "outer_right", 
          facing: "south"
        }, 
        Name: "minecraft:birch_stairs"
      }, 
      {
        Properties: {
          half: "bottom"
        }, 
        Name: "minecraft:birch_slab"
      }, 
      {
        Properties: {
          half: "bottom"
        }, 
        Name: "minecraft:oak_slab"
      }, 
      {
        Properties: {
          half: "top"
        }, 
        Name: "minecraft:birch_slab"
      }, 
      {
        Properties: {
          half: "top", 
          shape: "outer_right", 
          facing: "north"
        }, 
        Name: "minecraft:birch_stairs"
      }, 
      {
        Properties: {
          east: "false", 
          south: "false", 
          north: "false", 
          west: "false"
        }, 
        Name: "minecraft:oak_fence"
      }, 
      {
        Properties: {
          half: "top"
        }, 
        Name: "minecraft:oak_slab"
      }, 
      {
        Properties: {
          half: "top", 
          shape: "outer_right", 
          facing: "north"
        }, 
        Name: "minecraft:oak_stairs"
      }
    ]
  ]
}
