{
  size: [9, 9, 16], 
  entities: [], 
  author: "CascadianBacon", 
  blocks: [
    {
      pos: [4, 0, 0], 
      state: 0
    }, 
    {
      pos: [4, 0, 1], 
      state: 0
    }, 
    {
      pos: [3, 1, 1], 
      state: 1
    }, 
    {
      pos: [4, 1, 1], 
      state: 1
    }, 
    {
      pos: [6, 2, 1], 
      state: 1
    }, 
    {
      pos: [4, 0, 2], 
      state: 0
    }, 
    {
      pos: [3, 1, 2], 
      state: 1
    }, 
    {
      pos: [4, 1, 2], 
      state: 1
    }, 
    {
      pos: [5, 1, 2], 
      state: 1
    }, 
    {
      pos: [2, 2, 2], 
      state: 1
    }, 
    {
      pos: [6, 2, 2], 
      state: 1
    }, 
    {
      pos: [4, 0, 3], 
      state: 0
    }, 
    {
      pos: [3, 1, 3], 
      state: 1
    }, 
    {
      pos: [4, 1, 3], 
      state: 1
    }, 
    {
      pos: [5, 1, 3], 
      state: 1
    }, 
    {
      pos: [7, 4, 3], 
      state: 0
    }, 
    {
      pos: [4, 0, 4], 
      state: 0
    }, 
    {
      pos: [3, 1, 4], 
      state: 1
    }, 
    {
      pos: [4, 1, 4], 
      state: 1
    }, 
    {
      pos: [5, 1, 4], 
      state: 1
    }, 
    {
      pos: [2, 2, 4], 
      state: 1
    }, 
    {
      pos: [4, 2, 4], 
      state: 2
    }, 
    {
      pos: [5, 2, 4], 
      state: 1
    }, 
    {
      pos: [6, 2, 4], 
      state: 1
    }, 
    {
      pos: [1, 3, 4], 
      state: 1
    }, 
    {
      pos: [2, 3, 4], 
      state: 1
    }, 
    {
      pos: [4, 3, 4], 
      state: 2
    }, 
    {
      pos: [5, 3, 4], 
      state: 1
    }, 
    {
      pos: [6, 3, 4], 
      state: 1
    }, 
    {
      pos: [7, 3, 4], 
      state: 1
    }, 
    {
      pos: [3, 4, 4], 
      state: 0
    }, 
    {
      pos: [4, 4, 4], 
      state: 2
    }, 
    {
      pos: [6, 4, 4], 
      state: 0
    }, 
    {
      pos: [7, 4, 4], 
      state: 0
    }, 
    {
      pos: [4, 5, 4], 
      state: 2
    }, 
    {
      pos: [4, 0, 5], 
      state: 0
    }, 
    {
      pos: [3, 1, 5], 
      state: 1
    }, 
    {
      pos: [4, 1, 5], 
      state: 1
    }, 
    {
      pos: [5, 1, 5], 
      state: 1
    }, 
    {
      pos: [2, 2, 5], 
      state: 1
    }, 
    {
      pos: [6, 2, 5], 
      state: 1
    }, 
    {
      pos: [1, 3, 5], 
      state: 1
    }, 
    {
      pos: [2, 3, 5], 
      state: 1
    }, 
    {
      pos: [6, 3, 5], 
      state: 1
    }, 
    {
      pos: [7, 3, 5], 
      state: 1
    }, 
    {
      pos: [1, 4, 5], 
      state: 0
    }, 
    {
      pos: [3, 4, 5], 
      state: 0
    }, 
    {
      pos: [4, 4, 5], 
      state: 0
    }, 
    {
      pos: [5, 4, 5], 
      state: 0
    }, 
    {
      pos: [6, 4, 5], 
      state: 0
    }, 
    {
      pos: [7, 4, 5], 
      state: 0
    }, 
    {
      pos: [4, 0, 6], 
      state: 0
    }, 
    {
      pos: [3, 1, 6], 
      state: 1
    }, 
    {
      pos: [4, 1, 6], 
      state: 1
    }, 
    {
      pos: [5, 1, 6], 
      state: 1
    }, 
    {
      pos: [1, 4, 6], 
      state: 1
    }, 
    {
      pos: [2, 4, 6], 
      state: 0
    }, 
    {
      pos: [3, 4, 6], 
      state: 0
    }, 
    {
      pos: [5, 4, 6], 
      state: 0
    }, 
    {
      pos: [6, 4, 6], 
      state: 0
    }, 
    {
      pos: [7, 4, 6], 
      state: 1
    }, 
    {
      pos: [0, 5, 6], 
      state: 1
    }, 
    {
      pos: [8, 5, 6], 
      state: 1
    }, 
    {
      pos: [4, 0, 7], 
      state: 0
    }, 
    {
      pos: [3, 1, 7], 
      state: 1
    }, 
    {
      pos: [4, 1, 7], 
      state: 1
    }, 
    {
      pos: [5, 1, 7], 
      state: 1
    }, 
    {
      pos: [2, 2, 7], 
      state: 1
    }, 
    {
      pos: [6, 2, 7], 
      state: 1
    }, 
    {
      pos: [1, 3, 7], 
      state: 1
    }, 
    {
      pos: [2, 3, 7], 
      state: 1
    }, 
    {
      pos: [6, 3, 7], 
      state: 1
    }, 
    {
      pos: [7, 3, 7], 
      state: 1
    }, 
    {
      pos: [1, 4, 7], 
      state: 1
    }, 
    {
      pos: [2, 4, 7], 
      state: 1
    }, 
    {
      pos: [3, 4, 7], 
      state: 1
    }, 
    {
      pos: [5, 4, 7], 
      state: 1
    }, 
    {
      pos: [6, 4, 7], 
      state: 1
    }, 
    {
      pos: [7, 4, 7], 
      state: 1
    }, 
    {
      pos: [0, 5, 7], 
      state: 1
    }, 
    {
      pos: [1, 5, 7], 
      state: 1
    }, 
    {
      pos: [2, 5, 7], 
      state: 1
    }, 
    {
      pos: [3, 5, 7], 
      state: 1
    }, 
    {
      pos: [5, 5, 7], 
      state: 1
    }, 
    {
      pos: [6, 5, 7], 
      state: 1
    }, 
    {
      pos: [7, 5, 7], 
      state: 1
    }, 
    {
      pos: [8, 5, 7], 
      state: 1
    }, 
    {
      pos: [0, 6, 7], 
      state: 1
    }, 
    {
      pos: [2, 6, 7], 
      state: 1
    }, 
    {
      pos: [3, 6, 7], 
      state: 1
    }, 
    {
      pos: [5, 6, 7], 
      state: 1
    }, 
    {
      pos: [6, 6, 7], 
      state: 1
    }, 
    {
      pos: [8, 6, 7], 
      state: 1
    }, 
    {
      pos: [4, 0, 8], 
      state: 0
    }, 
    {
      pos: [3, 1, 8], 
      state: 1
    }, 
    {
      pos: [4, 1, 8], 
      state: 1
    }, 
    {
      pos: [5, 1, 8], 
      state: 1
    }, 
    {
      pos: [2, 2, 8], 
      state: 1
    }, 
    {
      pos: [3, 2, 8], 
      state: 1
    }, 
    {
      pos: [4, 2, 8], 
      state: 1
    }, 
    {
      pos: [5, 2, 8], 
      state: 1
    }, 
    {
      pos: [6, 2, 8], 
      state: 1
    }, 
    {
      pos: [1, 3, 8], 
      state: 1
    }, 
    {
      pos: [2, 3, 8], 
      state: 1
    }, 
    {
      pos: [3, 3, 8], 
      state: 0
    }, 
    {
      pos: [4, 3, 8], 
      state: 0
    }, 
    {
      pos: [5, 3, 8], 
      state: 0
    }, 
    {
      pos: [6, 3, 8], 
      state: 1
    }, 
    {
      pos: [7, 3, 8], 
      state: 1
    }, 
    {
      pos: [1, 4, 8], 
      state: 1
    }, 
    {
      pos: [7, 4, 8], 
      state: 1
    }, 
    {
      pos: [0, 5, 8], 
      state: 1
    }, 
    {
      pos: [1, 5, 8], 
      state: 1
    }, 
    {
      pos: [7, 5, 8], 
      state: 1
    }, 
    {
      pos: [8, 5, 8], 
      state: 1
    }, 
    {
      pos: [0, 6, 8], 
      state: 1
    }, 
    {
      pos: [7, 6, 8], 
      state: 0
    }, 
    {
      pos: [8, 6, 8], 
      state: 1
    }, 
    {
      pos: [4, 1, 9], 
      state: 1
    }, 
    {
      pos: [3, 2, 9], 
      state: 1
    }, 
    {
      pos: [4, 2, 9], 
      state: 1
    }, 
    {
      pos: [5, 2, 9], 
      state: 1
    }, 
    {
      pos: [2, 3, 9], 
      state: 0
    }, 
    {
      pos: [3, 3, 9], 
      state: 0
    }, 
    {
      pos: [4, 3, 9], 
      state: 0
    }, 
    {
      pos: [5, 3, 9], 
      state: 0
    }, 
    {
      pos: [6, 3, 9], 
      state: 0
    }, 
    {
      pos: [1, 4, 9], 
      state: 1
    }, 
    {
      pos: [7, 4, 9], 
      state: 1
    }, 
    {
      pos: [1, 5, 9], 
      state: 1
    }, 
    {
      pos: [7, 5, 9], 
      state: 1
    }, 
    {
      pos: [0, 6, 9], 
      state: 1
    }, 
    {
      pos: [8, 6, 9], 
      state: 1
    }, 
    {
      pos: [0, 7, 9], 
      state: 1
    }, 
    {
      pos: [4, 7, 9], 
      state: 1
    }, 
    {
      pos: [5, 7, 9], 
      state: 1
    }, 
    {
      pos: [7, 7, 9], 
      state: 1
    }, 
    {
      pos: [8, 7, 9], 
      state: 1
    }, 
    {
      pos: [7, 8, 9], 
      state: 1
    }, 
    {
      pos: [4, 1, 10], 
      state: 0
    }, 
    {
      pos: [3, 2, 10], 
      state: 1
    }, 
    {
      pos: [4, 2, 10], 
      state: 1
    }, 
    {
      pos: [5, 2, 10], 
      state: 1
    }, 
    {
      pos: [2, 3, 10], 
      state: 0
    }, 
    {
      pos: [3, 3, 10], 
      state: 0
    }, 
    {
      pos: [4, 3, 10], 
      state: 0
    }, 
    {
      pos: [5, 3, 10], 
      state: 0
    }, 
    {
      pos: [6, 3, 10], 
      state: 0
    }, 
    {
      pos: [1, 4, 10], 
      state: 1
    }, 
    {
      pos: [7, 4, 10], 
      state: 1
    }, 
    {
      pos: [0, 7, 10], 
      state: 1
    }, 
    {
      pos: [1, 7, 10], 
      state: 0
    }, 
    {
      pos: [4, 7, 10], 
      state: 0
    }, 
    {
      pos: [5, 7, 10], 
      state: 0
    }, 
    {
      pos: [6, 7, 10], 
      state: 0
    }, 
    {
      pos: [7, 7, 10], 
      state: 0
    }, 
    {
      pos: [8, 7, 10], 
      state: 1
    }, 
    {
      pos: [4, 1, 11], 
      state: 0
    }, 
    {
      pos: [3, 2, 11], 
      state: 1
    }, 
    {
      pos: [4, 2, 11], 
      state: 1
    }, 
    {
      pos: [5, 2, 11], 
      state: 1
    }, 
    {
      pos: [2, 3, 11], 
      state: 0
    }, 
    {
      pos: [3, 3, 11], 
      state: 0
    }, 
    {
      pos: [4, 3, 11], 
      state: 0
    }, 
    {
      pos: [5, 3, 11], 
      state: 0
    }, 
    {
      pos: [6, 3, 11], 
      state: 0
    }, 
    {
      pos: [1, 4, 11], 
      state: 1
    }, 
    {
      pos: [7, 4, 11], 
      state: 1
    }, 
    {
      pos: [1, 5, 11], 
      state: 1
    }, 
    {
      pos: [7, 5, 11], 
      state: 1
    }, 
    {
      pos: [0, 6, 11], 
      state: 1
    }, 
    {
      pos: [8, 6, 11], 
      state: 1
    }, 
    {
      pos: [0, 7, 11], 
      state: 1
    }, 
    {
      pos: [1, 7, 11], 
      state: 0
    }, 
    {
      pos: [7, 7, 11], 
      state: 0
    }, 
    {
      pos: [8, 7, 11], 
      state: 1
    }, 
    {
      pos: [4, 2, 12], 
      state: 0
    }, 
    {
      pos: [2, 3, 12], 
      state: 0
    }, 
    {
      pos: [3, 3, 12], 
      state: 0
    }, 
    {
      pos: [4, 3, 12], 
      state: 0
    }, 
    {
      pos: [5, 3, 12], 
      state: 0
    }, 
    {
      pos: [6, 3, 12], 
      state: 0
    }, 
    {
      pos: [1, 4, 12], 
      state: 1
    }, 
    {
      pos: [7, 4, 12], 
      state: 1
    }, 
    {
      pos: [1, 5, 12], 
      state: 1
    }, 
    {
      pos: [7, 5, 12], 
      state: 1
    }, 
    {
      pos: [1, 6, 12], 
      state: 1
    }, 
    {
      pos: [7, 6, 12], 
      state: 1
    }, 
    {
      pos: [1, 7, 12], 
      state: 1
    }, 
    {
      pos: [7, 7, 12], 
      state: 1
    }, 
    {
      pos: [4, 0, 13], 
      state: 1
    }, 
    {
      pos: [4, 1, 13], 
      state: 1
    }, 
    {
      pos: [2, 4, 13], 
      state: 1
    }, 
    {
      pos: [3, 4, 13], 
      state: 1
    }, 
    {
      pos: [4, 4, 13], 
      state: 1
    }, 
    {
      pos: [5, 4, 13], 
      state: 1
    }, 
    {
      pos: [6, 4, 13], 
      state: 1
    }, 
    {
      pos: [2, 5, 13], 
      state: 1
    }, 
    {
      pos: [6, 5, 13], 
      state: 1
    }, 
    {
      pos: [1, 6, 13], 
      state: 1
    }, 
    {
      pos: [7, 6, 13], 
      state: 1
    }, 
    {
      pos: [1, 7, 13], 
      state: 1
    }, 
    {
      pos: [2, 7, 13], 
      state: 0
    }, 
    {
      pos: [1, 8, 13], 
      state: 1
    }, 
    {
      pos: [4, 0, 14], 
      state: 1
    }, 
    {
      pos: [4, 1, 14], 
      state: 1
    }, 
    {
      pos: [4, 2, 14], 
      state: 1
    }, 
    {
      pos: [4, 5, 14], 
      state: 1
    }, 
    {
      pos: [3, 6, 14], 
      state: 1
    }, 
    {
      pos: [5, 6, 14], 
      state: 1
    }, 
    {
      pos: [2, 7, 14], 
      state: 1
    }, 
    {
      pos: [3, 7, 14], 
      state: 1
    }, 
    {
      pos: [4, 7, 14], 
      state: 0
    }, 
    {
      pos: [5, 7, 14], 
      state: 1
    }, 
    {
      pos: [2, 8, 14], 
      state: 1
    }, 
    {
      pos: [4, 7, 15], 
      state: 1
    }, 
    {
      nbt: {
        Items: [], 
        id: "minecraft:chest", 
        Lock: ""
      }, 
      pos: [5, 2, 6], 
      state: 3
    }, 
    {
      nbt: {
        metadata: "map_chest", 
        mirror: "NONE", 
        ignoreEntities: 1b, 
        powered: 0b, 
        seed: 0L, 
        author: "CascadianBacon", 
        rotation: "NONE", 
        mode: "DATA", 
        posX: 0, 
        posY: 1, 
        sizeX: 0, 
        integrity: 1.0f, 
        posZ: 0, 
        showair: 0b, 
        name: "", 
        id: "minecraft:structure_block", 
        sizeY: 0, 
        showboundingbox: 1b, 
        sizeZ: 0
      }, 
      pos: [5, 3, 6], 
      state: 4
    }, 
    {
      nbt: {
        Items: [], 
        id: "minecraft:chest", 
        Lock: ""
      }, 
      pos: [6, 4, 12], 
      state: 5
    }, 
    {
      nbt: {
        metadata: "treasure_chest", 
        mirror: "NONE", 
        ignoreEntities: 1b, 
        powered: 0b, 
        seed: 0L, 
        author: "CascadianBacon", 
        rotation: "NONE", 
        mode: "DATA", 
        posX: 0, 
        posY: 1, 
        sizeX: 0, 
        integrity: 1.0f, 
        posZ: 0, 
        showair: 0b, 
        name: "", 
        id: "minecraft:structure_block", 
        sizeY: 0, 
        showboundingbox: 1b, 
        sizeZ: 0
      }, 
      pos: [6, 5, 12], 
      state: 4
    }, 
    {
      pos: [2, 1, 0], 
      state: 6
    }, 
    {
      pos: [6, 1, 0], 
      state: 7
    }, 
    {
      pos: [2, 1, 1], 
      state: 6
    }, 
    {
      pos: [6, 1, 1], 
      state: 7
    }, 
    {
      pos: [2, 1, 2], 
      state: 6
    }, 
    {
      pos: [6, 1, 2], 
      state: 7
    }, 
    {
      pos: [1, 2, 2], 
      state: 6
    }, 
    {
      pos: [7, 2, 2], 
      state: 7
    }, 
    {
      pos: [2, 1, 3], 
      state: 6
    }, 
    {
      pos: [6, 1, 3], 
      state: 7
    }, 
    {
      pos: [1, 2, 3], 
      state: 6
    }, 
    {
      pos: [2, 2, 3], 
      state: 8
    }, 
    {
      pos: [6, 2, 3], 
      state: 9
    }, 
    {
      pos: [7, 2, 3], 
      state: 7
    }, 
    {
      pos: [3, 4, 3], 
      state: 10
    }, 
    {
      pos: [4, 4, 3], 
      state: 10
    }, 
    {
      pos: [2, 1, 4], 
      state: 6
    }, 
    {
      pos: [6, 1, 4], 
      state: 7
    }, 
    {
      pos: [1, 2, 4], 
      state: 6
    }, 
    {
      pos: [3, 2, 4], 
      state: 11
    }, 
    {
      pos: [7, 2, 4], 
      state: 7
    }, 
    {
      pos: [3, 3, 4], 
      state: 12
    }, 
    {
      pos: [8, 4, 4], 
      state: 7
    }, 
    {
      pos: [8, 5, 4], 
      state: 13
    }, 
    {
      pos: [2, 1, 5], 
      state: 6
    }, 
    {
      pos: [6, 1, 5], 
      state: 7
    }, 
    {
      pos: [1, 2, 5], 
      state: 6
    }, 
    {
      pos: [7, 2, 5], 
      state: 7
    }, 
    {
      pos: [0, 4, 5], 
      state: 6
    }, 
    {
      pos: [8, 4, 5], 
      state: 7
    }, 
    {
      pos: [0, 5, 5], 
      state: 13
    }, 
    {
      pos: [8, 5, 5], 
      state: 13
    }, 
    {
      pos: [2, 1, 6], 
      state: 6
    }, 
    {
      pos: [6, 1, 6], 
      state: 7
    }, 
    {
      pos: [1, 2, 6], 
      state: 6
    }, 
    {
      pos: [2, 2, 6], 
      state: 8
    }, 
    {
      pos: [6, 2, 6], 
      state: 9
    }, 
    {
      pos: [7, 2, 6], 
      state: 7
    }, 
    {
      pos: [0, 4, 6], 
      state: 6
    }, 
    {
      pos: [4, 4, 6], 
      state: 14
    }, 
    {
      pos: [8, 4, 6], 
      state: 7
    }, 
    {
      pos: [1, 5, 6], 
      state: 15
    }, 
    {
      pos: [7, 5, 6], 
      state: 15
    }, 
    {
      pos: [0, 6, 6], 
      state: 16
    }, 
    {
      pos: [8, 6, 6], 
      state: 16
    }, 
    {
      pos: [2, 1, 7], 
      state: 6
    }, 
    {
      pos: [6, 1, 7], 
      state: 7
    }, 
    {
      pos: [1, 2, 7], 
      state: 6
    }, 
    {
      pos: [7, 2, 7], 
      state: 7
    }, 
    {
      pos: [3, 3, 7], 
      state: 17
    }, 
    {
      pos: [4, 3, 7], 
      state: 17
    }, 
    {
      pos: [5, 3, 7], 
      state: 17
    }, 
    {
      pos: [0, 4, 7], 
      state: 6
    }, 
    {
      pos: [4, 4, 7], 
      state: 18
    }, 
    {
      pos: [8, 4, 7], 
      state: 7
    }, 
    {
      pos: [7, 6, 7], 
      state: 15
    }, 
    {
      pos: [4, 7, 7], 
      state: 19
    }, 
    {
      pos: [2, 1, 8], 
      state: 6
    }, 
    {
      pos: [6, 1, 8], 
      state: 7
    }, 
    {
      pos: [1, 2, 8], 
      state: 6
    }, 
    {
      pos: [7, 2, 8], 
      state: 7
    }, 
    {
      pos: [0, 4, 8], 
      state: 6
    }, 
    {
      pos: [2, 4, 8], 
      state: 8
    }, 
    {
      pos: [6, 4, 8], 
      state: 9
    }, 
    {
      pos: [8, 4, 8], 
      state: 7
    }, 
    {
      pos: [2, 6, 8], 
      state: 20
    }, 
    {
      pos: [3, 6, 8], 
      state: 20
    }, 
    {
      pos: [4, 6, 8], 
      state: 20
    }, 
    {
      pos: [5, 6, 8], 
      state: 20
    }, 
    {
      pos: [6, 6, 8], 
      state: 20
    }, 
    {
      pos: [4, 7, 8], 
      state: 16
    }, 
    {
      pos: [8, 7, 8], 
      state: 16
    }, 
    {
      pos: [4, 0, 9], 
      state: 21
    }, 
    {
      pos: [3, 1, 9], 
      state: 6
    }, 
    {
      pos: [5, 1, 9], 
      state: 7
    }, 
    {
      pos: [2, 2, 9], 
      state: 6
    }, 
    {
      pos: [6, 2, 9], 
      state: 7
    }, 
    {
      pos: [1, 3, 9], 
      state: 6
    }, 
    {
      pos: [7, 3, 9], 
      state: 7
    }, 
    {
      pos: [0, 5, 9], 
      state: 6
    }, 
    {
      pos: [8, 5, 9], 
      state: 7
    }, 
    {
      pos: [1, 6, 9], 
      state: 22
    }, 
    {
      pos: [3, 6, 9], 
      state: 20
    }, 
    {
      pos: [4, 6, 9], 
      state: 20
    }, 
    {
      pos: [5, 6, 9], 
      state: 20
    }, 
    {
      pos: [7, 6, 9], 
      state: 22
    }, 
    {
      pos: [6, 7, 9], 
      state: 15
    }, 
    {
      pos: [0, 8, 9], 
      state: 9
    }, 
    {
      pos: [8, 8, 9], 
      state: 8
    }, 
    {
      pos: [3, 1, 10], 
      state: 6
    }, 
    {
      pos: [5, 1, 10], 
      state: 7
    }, 
    {
      pos: [2, 2, 10], 
      state: 6
    }, 
    {
      pos: [6, 2, 10], 
      state: 7
    }, 
    {
      pos: [1, 3, 10], 
      state: 6
    }, 
    {
      pos: [7, 3, 10], 
      state: 7
    }, 
    {
      pos: [0, 5, 10], 
      state: 6
    }, 
    {
      pos: [1, 5, 10], 
      state: 8
    }, 
    {
      pos: [7, 5, 10], 
      state: 9
    }, 
    {
      pos: [8, 5, 10], 
      state: 7
    }, 
    {
      pos: [2, 7, 10], 
      state: 20
    }, 
    {
      pos: [0, 8, 10], 
      state: 9
    }, 
    {
      pos: [8, 8, 10], 
      state: 8
    }, 
    {
      pos: [3, 1, 11], 
      state: 6
    }, 
    {
      pos: [5, 1, 11], 
      state: 7
    }, 
    {
      pos: [2, 2, 11], 
      state: 6
    }, 
    {
      pos: [6, 2, 11], 
      state: 7
    }, 
    {
      pos: [1, 3, 11], 
      state: 6
    }, 
    {
      pos: [7, 3, 11], 
      state: 7
    }, 
    {
      pos: [3, 4, 11], 
      state: 7
    }, 
    {
      pos: [4, 4, 11], 
      state: 23
    }, 
    {
      pos: [5, 4, 11], 
      state: 6
    }, 
    {
      pos: [0, 5, 11], 
      state: 24
    }, 
    {
      pos: [8, 5, 11], 
      state: 24
    }, 
    {
      pos: [1, 6, 11], 
      state: 22
    }, 
    {
      pos: [7, 6, 11], 
      state: 22
    }, 
    {
      pos: [2, 7, 11], 
      state: 20
    }, 
    {
      pos: [3, 7, 11], 
      state: 20
    }, 
    {
      pos: [4, 7, 11], 
      state: 20
    }, 
    {
      pos: [5, 7, 11], 
      state: 20
    }, 
    {
      pos: [6, 7, 11], 
      state: 20
    }, 
    {
      pos: [0, 8, 11], 
      state: 9
    }, 
    {
      pos: [1, 8, 11], 
      state: 13
    }, 
    {
      pos: [7, 8, 11], 
      state: 13
    }, 
    {
      pos: [8, 8, 11], 
      state: 8
    }, 
    {
      pos: [4, 1, 12], 
      state: 21
    }, 
    {
      pos: [2, 2, 12], 
      state: 6
    }, 
    {
      pos: [3, 2, 12], 
      state: 24
    }, 
    {
      pos: [5, 2, 12], 
      state: 24
    }, 
    {
      pos: [6, 2, 12], 
      state: 7
    }, 
    {
      pos: [1, 3, 12], 
      state: 6
    }, 
    {
      pos: [7, 3, 12], 
      state: 7
    }, 
    {
      pos: [2, 7, 12], 
      state: 20
    }, 
    {
      pos: [3, 7, 12], 
      state: 20
    }, 
    {
      pos: [4, 7, 12], 
      state: 20
    }, 
    {
      pos: [5, 7, 12], 
      state: 20
    }, 
    {
      pos: [6, 7, 12], 
      state: 20
    }, 
    {
      pos: [1, 8, 12], 
      state: 13
    }, 
    {
      pos: [7, 8, 12], 
      state: 13
    }, 
    {
      pos: [4, 2, 13], 
      state: 13
    }, 
    {
      pos: [2, 3, 13], 
      state: 24
    }, 
    {
      pos: [3, 3, 13], 
      state: 24
    }, 
    {
      pos: [4, 3, 13], 
      state: 13
    }, 
    {
      pos: [5, 3, 13], 
      state: 24
    }, 
    {
      pos: [6, 3, 13], 
      state: 24
    }, 
    {
      pos: [1, 5, 13], 
      state: 24
    }, 
    {
      pos: [3, 5, 13], 
      state: 16
    }, 
    {
      pos: [4, 5, 13], 
      state: 16
    }, 
    {
      pos: [5, 5, 13], 
      state: 16
    }, 
    {
      pos: [7, 5, 13], 
      state: 24
    }, 
    {
      pos: [2, 6, 13], 
      state: 22
    }, 
    {
      pos: [6, 6, 13], 
      state: 22
    }, 
    {
      pos: [3, 7, 13], 
      state: 25
    }, 
    {
      pos: [4, 7, 13], 
      state: 25
    }, 
    {
      pos: [5, 7, 13], 
      state: 25
    }, 
    {
      pos: [4, 4, 14], 
      state: 24
    }, 
    {
      pos: [3, 5, 14], 
      state: 24
    }, 
    {
      pos: [5, 5, 14], 
      state: 24
    }, 
    {
      pos: [2, 6, 14], 
      state: 24
    }, 
    {
      pos: [3, 8, 14], 
      state: 13
    }, 
    {
      pos: [5, 8, 14], 
      state: 13
    }, 
    {
      pos: [3, 7, 15], 
      state: 24
    }, 
    {
      pos: [5, 7, 15], 
      state: 24
    }, 
    {
      pos: [3, 8, 15], 
      state: 13
    }, 
    {
      pos: [4, 8, 15], 
      state: 13
    }, 
    {
      pos: [5, 8, 15], 
      state: 13
    }
  ], 
  palettes: [
    [
      {
        Name: "minecraft:spruce_planks"
      }, 
      {
        Name: "minecraft:oak_planks"
      }, 
      {
        Properties: {
          axis: "y"
        }, 
        Name: "minecraft:oak_log"
      }, 
      {
        Properties: {
          facing: "west", 
          type: "single"
        }, 
        Name: "minecraft:chest"
      }, 
      {
        Properties: {
          mode: "data"
        }, 
        Name: "minecraft:structure_block"
      }, 
      {
        Properties: {
          facing: "north", 
          type: "single"
        }, 
        Name: "minecraft:chest"
      }, 
      {
        Properties: {
          half: "top", 
          shape: "outer_right", 
          facing: "east"
        }, 
        Name: "minecraft:oak_stairs"
      }, 
      {
        Properties: {
          half: "top", 
          shape: "outer_right", 
          facing: "west"
        }, 
        Name: "minecraft:oak_stairs"
      }, 
      {
        Properties: {
          half: "bottom", 
          shape: "outer_right", 
          facing: "west"
        }, 
        Name: "minecraft:oak_stairs"
      }, 
      {
        Properties: {
          half: "bottom", 
          shape: "outer_right", 
          facing: "east"
        }, 
        Name: "minecraft:oak_stairs"
      }, 
      {
        Properties: {
          half: "top", 
          powered: "false", 
          facing: "north", 
          open: "false"
        }, 
        Name: "minecraft:oak_trapdoor"
      }, 
      {
        Properties: {
          hinge: "right", 
          half: "lower", 
          powered: "false", 
          facing: "south", 
          open: "false"
        }, 
        Name: "minecraft:oak_door"
      }, 
      {
        Properties: {
          hinge: "left", 
          half: "upper", 
          powered: "false", 
          facing: "east", 
          open: "false"
        }, 
        Name: "minecraft:oak_door"
      }, 
      {
        Properties: {
          east: "false", 
          south: "false", 
          north: "false", 
          west: "false"
        }, 
        Name: "minecraft:spruce_fence"
      }, 
      {
        Properties: {
          half: "bottom", 
          shape: "outer_right", 
          facing: "north"
        }, 
        Name: "minecraft:spruce_stairs"
      }, 
      {
        Properties: {
          half: "bottom", 
          shape: "outer_right", 
          facing: "south"
        }, 
        Name: "minecraft:spruce_stairs"
      }, 
      {
        Properties: {
          half: "bottom", 
          shape: "outer_right", 
          facing: "south"
        }, 
        Name: "minecraft:oak_stairs"
      }, 
      {
        Properties: {
          half: "top", 
          shape: "outer_right", 
          facing: "south"
        }, 
        Name: "minecraft:oak_stairs"
      }, 
      {
        Properties: {
          half: "bottom"
        }, 
        Name: "minecraft:spruce_slab"
      }, 
      {
        Properties: {
          half: "bottom"
        }, 
        Name: "minecraft:oak_slab"
      }, 
      {
        Properties: {
          half: "top"
        }, 
        Name: "minecraft:spruce_slab"
      }, 
      {
        Properties: {
          half: "top", 
          shape: "outer_right", 
          facing: "north"
        }, 
        Name: "minecraft:spruce_stairs"
      }, 
      {
        Properties: {
          east: "false", 
          south: "false", 
          north: "false", 
          west: "false"
        }, 
        Name: "minecraft:oak_fence"
      }, 
      {
        Properties: {
          half: "top"
        }, 
        Name: "minecraft:oak_slab"
      }, 
      {
        Properties: {
          half: "top", 
          shape: "outer_right", 
          facing: "north"
        }, 
        Name: "minecraft:oak_stairs"
      }, 
      {
        Properties: {
          half: "top", 
          shape: "outer_right", 
          facing: "south"
        }, 
        Name: "minecraft:spruce_stairs"
      }
    ], 
    [
      {
        Name: "minecraft:spruce_planks"
      }, 
      {
        Name: "minecraft:jungle_planks"
      }, 
      {
        Properties: {
          axis: "y"
        }, 
        Name: "minecraft:jungle_log"
      }, 
      {
        Properties: {
          facing: "west", 
          type: "single"
        }, 
        Name: "minecraft:chest"
      }, 
      {
        Properties: {
          mode: "data"
        }, 
        Name: "minecraft:structure_block"
      }, 
      {
        Properties: {
          facing: "north", 
          type: "single"
        }, 
        Name: "minecraft:chest"
      }, 
      {
        Properties: {
          half: "top", 
          shape: "outer_right", 
          facing: "east"
        }, 
        Name: "minecraft:jungle_stairs"
      }, 
      {
        Properties: {
          half: "top", 
          shape: "outer_right", 
          facing: "west"
        }, 
        Name: "minecraft:jungle_stairs"
      }, 
      {
        Properties: {
          half: "bottom", 
          shape: "outer_right", 
          facing: "west"
        }, 
        Name: "minecraft:jungle_stairs"
      }, 
      {
        Properties: {
          half: "bottom", 
          shape: "outer_right", 
          facing: "east"
        }, 
        Name: "minecraft:jungle_stairs"
      }, 
      {
        Properties: {
          half: "top", 
          powered: "false", 
          facing: "north", 
          open: "false"
        }, 
        Name: "minecraft:jungle_trapdoor"
      }, 
      {
        Properties: {
          hinge: "right", 
          half: "lower", 
          powered: "false", 
          facing: "south", 
          open: "false"
        }, 
        Name: "minecraft:jungle_door"
      }, 
      {
        Properties: {
          hinge: "left", 
          half: "upper", 
          powered: "false", 
          facing: "east", 
          open: "false"
        }, 
        Name: "minecraft:jungle_door"
      }, 
      {
        Properties: {
          east: "false", 
          south: "false", 
          north: "false", 
          west: "false"
        }, 
        Name: "minecraft:spruce_fence"
      }, 
      {
        Properties: {
          half: "bottom", 
          shape: "outer_right", 
          facing: "north"
        }, 
        Name: "minecraft:spruce_stairs"
      }, 
      {
        Properties: {
          half: "bottom", 
          shape: "outer_right", 
          facing: "south"
        }, 
        Name: "minecraft:spruce_stairs"
      }, 
      {
        Properties: {
          half: "bottom", 
          shape: "outer_right", 
          facing: "south"
        }, 
        Name: "minecraft:jungle_stairs"
      }, 
      {
        Properties: {
          half: "top", 
          shape: "outer_right", 
          facing: "south"
        }, 
        Name: "minecraft:jungle_stairs"
      }, 
      {
        Properties: {
          half: "bottom"
        }, 
        Name: "minecraft:spruce_slab"
      }, 
      {
        Properties: {
          half: "bottom"
        }, 
        Name: "minecraft:jungle_slab"
      }, 
      {
        Properties: {
          half: "top"
        }, 
        Name: "minecraft:spruce_slab"
      }, 
      {
        Properties: {
          half: "top", 
          shape: "outer_right", 
          facing: "north"
        }, 
        Name: "minecraft:spruce_stairs"
      }, 
      {
        Properties: {
          east: "false", 
          south: "false", 
          north: "false", 
          west: "false"
        }, 
        Name: "minecraft:jungle_fence"
      }, 
      {
        Properties: {
          half: "top"
        }, 
        Name: "minecraft:jungle_slab"
      }, 
      {
        Properties: {
          half: "top", 
          shape: "outer_right", 
          facing: "north"
        }, 
        Name: "minecraft:jungle_stairs"
      }, 
      {
        Properties: {
          half: "top", 
          shape: "outer_right", 
          facing: "south"
        }, 
        Name: "minecraft:spruce_stairs"
      }
    ], 
    [
      {
        Name: "minecraft:jungle_planks"
      }, 
      {
        Name: "minecraft:dark_oak_planks"
      }, 
      {
        Properties: {
          axis: "y"
        }, 
        Name: "minecraft:dark_oak_log"
      }, 
      {
        Properties: {
          facing: "west", 
          type: "single"
        }, 
        Name: "minecraft:chest"
      }, 
      {
        Properties: {
          mode: "data"
        }, 
        Name: "minecraft:structure_block"
      }, 
      {
        Properties: {
          facing: "north", 
          type: "single"
        }, 
        Name: "minecraft:chest"
      }, 
      {
        Properties: {
          half: "top", 
          shape: "outer_right", 
          facing: "east"
        }, 
        Name: "minecraft:dark_oak_stairs"
      }, 
      {
        Properties: {
          half: "top", 
          shape: "outer_right", 
          facing: "west"
        }, 
        Name: "minecraft:dark_oak_stairs"
      }, 
      {
        Properties: {
          half: "bottom", 
          shape: "outer_right", 
          facing: "west"
        }, 
        Name: "minecraft:dark_oak_stairs"
      }, 
      {
        Properties: {
          half: "bottom", 
          shape: "outer_right", 
          facing: "east"
        }, 
        Name: "minecraft:dark_oak_stairs"
      }, 
      {
        Properties: {
          half: "top", 
          powered: "false", 
          facing: "north", 
          open: "false"
        }, 
        Name: "minecraft:dark_oak_trapdoor"
      }, 
      {
        Properties: {
          hinge: "right", 
          half: "lower", 
          powered: "false", 
          facing: "south", 
          open: "false"
        }, 
        Name: "minecraft:dark_oak_door"
      }, 
      {
        Properties: {
          hinge: "left", 
          half: "upper", 
          powered: "false", 
          facing: "east", 
          open: "false"
        }, 
        Name: "minecraft:dark_oak_door"
      }, 
      {
        Properties: {
          east: "false", 
          south: "false", 
          north: "false", 
          west: "false"
        }, 
        Name: "minecraft:jungle_fence"
      }, 
      {
        Properties: {
          half: "bottom", 
          shape: "outer_right", 
          facing: "north"
        }, 
        Name: "minecraft:jungle_stairs"
      }, 
      {
        Properties: {
          half: "bottom", 
          shape: "outer_right", 
          facing: "south"
        }, 
        Name: "minecraft:jungle_stairs"
      }, 
      {
        Properties: {
          half: "bottom", 
          shape: "outer_right", 
          facing: "south"
        }, 
        Name: "minecraft:dark_oak_stairs"
      }, 
      {
        Properties: {
          half: "top", 
          shape: "outer_right", 
          facing: "south"
        }, 
        Name: "minecraft:dark_oak_stairs"
      }, 
      {
        Properties: {
          half: "bottom"
        }, 
        Name: "minecraft:jungle_slab"
      }, 
      {
        Properties: {
          half: "bottom"
        }, 
        Name: "minecraft:dark_oak_slab"
      }, 
      {
        Properties: {
          half: "top"
        }, 
        Name: "minecraft:jungle_slab"
      }, 
      {
        Properties: {
          half: "top", 
          shape: "outer_right", 
          facing: "north"
        }, 
        Name: "minecraft:jungle_stairs"
      }, 
      {
        Properties: {
          east: "false", 
          south: "false", 
          north: "false", 
          west: "false"
        }, 
        Name: "minecraft:dark_oak_fence"
      }, 
      {
        Properties: {
          half: "top"
        }, 
        Name: "minecraft:dark_oak_slab"
      }, 
      {
        Properties: {
          half: "top", 
          shape: "outer_right", 
          facing: "north"
        }, 
        Name: "minecraft:dark_oak_stairs"
      }, 
      {
        Properties: {
          half: "top", 
          shape: "outer_right", 
          facing: "south"
        }, 
        Name: "minecraft:jungle_stairs"
      }
    ], 
    [
      {
        Name: "minecraft:spruce_planks"
      }, 
      {
        Name: "minecraft:dark_oak_planks"
      }, 
      {
        Properties: {
          axis: "y"
        }, 
        Name: "minecraft:dark_oak_log"
      }, 
      {
        Properties: {
          facing: "west", 
          type: "single"
        }, 
        Name: "minecraft:chest"
      }, 
      {
        Properties: {
          mode: "data"
        }, 
        Name: "minecraft:structure_block"
      }, 
      {
        Properties: {
          facing: "north", 
          type: "single"
        }, 
        Name: "minecraft:chest"
      }, 
      {
        Properties: {
          half: "top", 
          shape: "outer_right", 
          facing: "east"
        }, 
        Name: "minecraft:dark_oak_stairs"
      }, 
      {
        Properties: {
          half: "top", 
          shape: "outer_right", 
          facing: "west"
        }, 
        Name: "minecraft:dark_oak_stairs"
      }, 
      {
        Properties: {
          half: "bottom", 
          shape: "outer_right", 
          facing: "west"
        }, 
        Name: "minecraft:dark_oak_stairs"
      }, 
      {
        Properties: {
          half: "bottom", 
          shape: "outer_right", 
          facing: "east"
        }, 
        Name: "minecraft:dark_oak_stairs"
      }, 
      {
        Properties: {
          half: "top", 
          powered: "false", 
          facing: "north", 
          open: "false"
        }, 
        Name: "minecraft:dark_oak_trapdoor"
      }, 
      {
        Properties: {
          hinge: "right", 
          half: "lower", 
          powered: "false", 
          facing: "south", 
          open: "false"
        }, 
        Name: "minecraft:dark_oak_door"
      }, 
      {
        Properties: {
          hinge: "left", 
          half: "upper", 
          powered: "false", 
          facing: "east", 
          open: "false"
        }, 
        Name: "minecraft:dark_oak_door"
      }, 
      {
        Properties: {
          east: "false", 
          south: "false", 
          north: "false", 
          west: "false"
        }, 
        Name: "minecraft:spruce_fence"
      }, 
      {
        Properties: {
          half: "bottom", 
          shape: "outer_right", 
          facing: "north"
        }, 
        Name: "minecraft:spruce_stairs"
      }, 
      {
        Properties: {
          half: "bottom", 
          shape: "outer_right", 
          facing: "south"
        }, 
        Name: "minecraft:spruce_stairs"
      }, 
      {
        Properties: {
          half: "bottom", 
          shape: "outer_right", 
          facing: "south"
        }, 
        Name: "minecraft:dark_oak_stairs"
      }, 
      {
        Properties: {
          half: "top", 
          shape: "outer_right", 
          facing: "south"
        }, 
        Name: "minecraft:dark_oak_stairs"
      }, 
      {
        Properties: {
          half: "bottom"
        }, 
        Name: "minecraft:spruce_slab"
      }, 
      {
        Properties: {
          half: "bottom"
        }, 
        Name: "minecraft:dark_oak_slab"
      }, 
      {
        Properties: {
          half: "top"
        }, 
        Name: "minecraft:spruce_slab"
      }, 
      {
        Properties: {
          half: "top", 
          shape: "outer_right", 
          facing: "north"
        }, 
        Name: "minecraft:spruce_stairs"
      }, 
      {
        Properties: {
          east: "false", 
          south: "false", 
          north: "false", 
          west: "false"
        }, 
        Name: "minecraft:dark_oak_fence"
      }, 
      {
        Properties: {
          half: "top"
        }, 
        Name: "minecraft:dark_oak_slab"
      }, 
      {
        Properties: {
          half: "top", 
          shape: "outer_right", 
          facing: "north"
        }, 
        Name: "minecraft:dark_oak_stairs"
      }, 
      {
        Properties: {
          half: "top", 
          shape: "outer_right", 
          facing: "south"
        }, 
        Name: "minecraft:spruce_stairs"
      }
    ], 
    [
      {
        Name: "minecraft:oak_planks"
      }, 
      {
        Name: "minecraft:spruce_planks"
      }, 
      {
        Properties: {
          axis: "y"
        }, 
        Name: "minecraft:spruce_log"
      }, 
      {
        Properties: {
          facing: "west", 
          type: "single"
        }, 
        Name: "minecraft:chest"
      }, 
      {
        Properties: {
          mode: "data"
        }, 
        Name: "minecraft:structure_block"
      }, 
      {
        Properties: {
          facing: "north", 
          type: "single"
        }, 
        Name: "minecraft:chest"
      }, 
      {
        Properties: {
          half: "top", 
          shape: "outer_right", 
          facing: "east"
        }, 
        Name: "minecraft:spruce_stairs"
      }, 
      {
        Properties: {
          half: "top", 
          shape: "outer_right", 
          facing: "west"
        }, 
        Name: "minecraft:spruce_stairs"
      }, 
      {
        Properties: {
          half: "bottom", 
          shape: "outer_right", 
          facing: "west"
        }, 
        Name: "minecraft:spruce_stairs"
      }, 
      {
        Properties: {
          half: "bottom", 
          shape: "outer_right", 
          facing: "east"
        }, 
        Name: "minecraft:spruce_stairs"
      }, 
      {
        Properties: {
          half: "top", 
          powered: "false", 
          facing: "north", 
          open: "false"
        }, 
        Name: "minecraft:spruce_trapdoor"
      }, 
      {
        Properties: {
          hinge: "right", 
          half: "lower", 
          powered: "false", 
          facing: "south", 
          open: "false"
        }, 
        Name: "minecraft:spruce_door"
      }, 
      {
        Properties: {
          hinge: "left", 
          half: "upper", 
          powered: "false", 
          facing: "east", 
          open: "false"
        }, 
        Name: "minecraft:spruce_door"
      }, 
      {
        Properties: {
          east: "false", 
          south: "false", 
          north: "false", 
          west: "false"
        }, 
        Name: "minecraft:oak_fence"
      }, 
      {
        Properties: {
          half: "bottom", 
          shape: "outer_right", 
          facing: "north"
        }, 
        Name: "minecraft:oak_stairs"
      }, 
      {
        Properties: {
          half: "bottom", 
          shape: "outer_right", 
          facing: "south"
        }, 
        Name: "minecraft:oak_stairs"
      }, 
      {
        Properties: {
          half: "bottom", 
          shape: "outer_right", 
          facing: "south"
        }, 
        Name: "minecraft:spruce_stairs"
      }, 
      {
        Properties: {
          half: "top", 
          shape: "outer_right", 
          facing: "south"
        }, 
        Name: "minecraft:spruce_stairs"
      }, 
      {
        Properties: {
          half: "bottom"
        }, 
        Name: "minecraft:oak_slab"
      }, 
      {
        Properties: {
          half: "bottom"
        }, 
        Name: "minecraft:spruce_slab"
      }, 
      {
        Properties: {
          half: "top"
        }, 
        Name: "minecraft:oak_slab"
      }, 
      {
        Properties: {
          half: "top", 
          shape: "outer_right", 
          facing: "north"
        }, 
        Name: "minecraft:oak_stairs"
      }, 
      {
        Properties: {
          east: "false", 
          south: "false", 
          north: "false", 
          west: "false"
        }, 
        Name: "minecraft:spruce_fence"
      }, 
      {
        Properties: {
          half: "top"
        }, 
        Name: "minecraft:spruce_slab"
      }, 
      {
        Properties: {
          half: "top", 
          shape: "outer_right", 
          facing: "north"
        }, 
        Name: "minecraft:spruce_stairs"
      }, 
      {
        Properties: {
          half: "top", 
          shape: "outer_right", 
          facing: "south"
        }, 
        Name: "minecraft:oak_stairs"
      }
    ], 
    [
      {
        Name: "minecraft:jungle_planks"
      }, 
      {
        Name: "minecraft:spruce_planks"
      }, 
      {
        Properties: {
          axis: "y"
        }, 
        Name: "minecraft:spruce_log"
      }, 
      {
        Properties: {
          facing: "west", 
          type: "single"
        }, 
        Name: "minecraft:chest"
      }, 
      {
        Properties: {
          mode: "data"
        }, 
        Name: "minecraft:structure_block"
      }, 
      {
        Properties: {
          facing: "north", 
          type: "single"
        }, 
        Name: "minecraft:chest"
      }, 
      {
        Properties: {
          half: "top", 
          shape: "outer_right", 
          facing: "east"
        }, 
        Name: "minecraft:spruce_stairs"
      }, 
      {
        Properties: {
          half: "top", 
          shape: "outer_right", 
          facing: "west"
        }, 
        Name: "minecraft:spruce_stairs"
      }, 
      {
        Properties: {
          half: "bottom", 
          shape: "outer_right", 
          facing: "west"
        }, 
        Name: "minecraft:spruce_stairs"
      }, 
      {
        Properties: {
          half: "bottom", 
          shape: "outer_right", 
          facing: "east"
        }, 
        Name: "minecraft:spruce_stairs"
      }, 
      {
        Properties: {
          half: "top", 
          powered: "false", 
          facing: "north", 
          open: "false"
        }, 
        Name: "minecraft:spruce_trapdoor"
      }, 
      {
        Properties: {
          hinge: "right", 
          half: "lower", 
          powered: "false", 
          facing: "south", 
          open: "false"
        }, 
        Name: "minecraft:spruce_door"
      }, 
      {
        Properties: {
          hinge: "left", 
          half: "upper", 
          powered: "false", 
          facing: "east", 
          open: "false"
        }, 
        Name: "minecraft:spruce_door"
      }, 
      {
        Properties: {
          east: "false", 
          south: "false", 
          north: "false", 
          west: "false"
        }, 
        Name: "minecraft:jungle_fence"
      }, 
      {
        Properties: {
          half: "bottom", 
          shape: "outer_right", 
          facing: "north"
        }, 
        Name: "minecraft:jungle_stairs"
      }, 
      {
        Properties: {
          half: "bottom", 
          shape: "outer_right", 
          facing: "south"
        }, 
        Name: "minecraft:jungle_stairs"
      }, 
      {
        Properties: {
          half: "bottom", 
          shape: "outer_right", 
          facing: "south"
        }, 
        Name: "minecraft:spruce_stairs"
      }, 
      {
        Properties: {
          half: "top", 
          shape: "outer_right", 
          facing: "south"
        }, 
        Name: "minecraft:spruce_stairs"
      }, 
      {
        Properties: {
          half: "bottom"
        }, 
        Name: "minecraft:jungle_slab"
      }, 
      {
        Properties: {
          half: "bottom"
        }, 
        Name: "minecraft:spruce_slab"
      }, 
      {
        Properties: {
          half: "top"
        }, 
        Name: "minecraft:jungle_slab"
      }, 
      {
        Properties: {
          half: "top", 
          shape: "outer_right", 
          facing: "north"
        }, 
        Name: "minecraft:jungle_stairs"
      }, 
      {
        Properties: {
          east: "false", 
          south: "false", 
          north: "false", 
          west: "false"
        }, 
        Name: "minecraft:spruce_fence"
      }, 
      {
        Properties: {
          half: "top"
        }, 
        Name: "minecraft:spruce_slab"
      }, 
      {
        Properties: {
          half: "top", 
          shape: "outer_right", 
          facing: "north"
        }, 
        Name: "minecraft:spruce_stairs"
      }, 
      {
        Properties: {
          half: "top", 
          shape: "outer_right", 
          facing: "south"
        }, 
        Name: "minecraft:jungle_stairs"
      }
    ], 
    [
      {
        Name: "minecraft:dark_oak_planks"
      }, 
      {
        Name: "minecraft:spruce_planks"
      }, 
      {
        Properties: {
          axis: "y"
        }, 
        Name: "minecraft:spruce_log"
      }, 
      {
        Properties: {
          facing: "west", 
          type: "single"
        }, 
        Name: "minecraft:chest"
      }, 
      {
        Properties: {
          mode: "data"
        }, 
        Name: "minecraft:structure_block"
      }, 
      {
        Properties: {
          facing: "north", 
          type: "single"
        }, 
        Name: "minecraft:chest"
      }, 
      {
        Properties: {
          half: "top", 
          shape: "outer_right", 
          facing: "east"
        }, 
        Name: "minecraft:spruce_stairs"
      }, 
      {
        Properties: {
          half: "top", 
          shape: "outer_right", 
          facing: "west"
        }, 
        Name: "minecraft:spruce_stairs"
      }, 
      {
        Properties: {
          half: "bottom", 
          shape: "outer_right", 
          facing: "west"
        }, 
        Name: "minecraft:spruce_stairs"
      }, 
      {
        Properties: {
          half: "bottom", 
          shape: "outer_right", 
          facing: "east"
        }, 
        Name: "minecraft:spruce_stairs"
      }, 
      {
        Properties: {
          half: "top", 
          powered: "false", 
          facing: "north", 
          open: "false"
        }, 
        Name: "minecraft:spruce_trapdoor"
      }, 
      {
        Properties: {
          hinge: "right", 
          half: "lower", 
          powered: "false", 
          facing: "south", 
          open: "false"
        }, 
        Name: "minecraft:spruce_door"
      }, 
      {
        Properties: {
          hinge: "left", 
          half: "upper", 
          powered: "false", 
          facing: "east", 
          open: "false"
        }, 
        Name: "minecraft:spruce_door"
      }, 
      {
        Properties: {
          east: "false", 
          south: "false", 
          north: "false", 
          west: "false"
        }, 
        Name: "minecraft:dark_oak_fence"
      }, 
      {
        Properties: {
          half: "bottom", 
          shape: "outer_right", 
          facing: "north"
        }, 
        Name: "minecraft:dark_oak_stairs"
      }, 
      {
        Properties: {
          half: "bottom", 
          shape: "outer_right", 
          facing: "south"
        }, 
        Name: "minecraft:dark_oak_stairs"
      }, 
      {
        Properties: {
          half: "bottom", 
          shape: "outer_right", 
          facing: "south"
        }, 
        Name: "minecraft:spruce_stairs"
      }, 
      {
        Properties: {
          half: "top", 
          shape: "outer_right", 
          facing: "south"
        }, 
        Name: "minecraft:spruce_stairs"
      }, 
      {
        Properties: {
          half: "bottom"
        }, 
        Name: "minecraft:dark_oak_slab"
      }, 
      {
        Properties: {
          half: "bottom"
        }, 
        Name: "minecraft:spruce_slab"
      }, 
      {
        Properties: {
          half: "top"
        }, 
        Name: "minecraft:dark_oak_slab"
      }, 
      {
        Properties: {
          half: "top", 
          shape: "outer_right", 
          facing: "north"
        }, 
        Name: "minecraft:dark_oak_stairs"
      }, 
      {
        Properties: {
          east: "false", 
          south: "false", 
          north: "false", 
          west: "false"
        }, 
        Name: "minecraft:spruce_fence"
      }, 
      {
        Properties: {
          half: "top"
        }, 
        Name: "minecraft:spruce_slab"
      }, 
      {
        Properties: {
          half: "top", 
          shape: "outer_right", 
          facing: "north"
        }, 
        Name: "minecraft:spruce_stairs"
      }, 
      {
        Properties: {
          half: "top", 
          shape: "outer_right", 
          facing: "south"
        }, 
        Name: "minecraft:dark_oak_stairs"
      }
    ], 
    [
      {
        Name: "minecraft:birch_planks"
      }, 
      {
        Name: "minecraft:oak_planks"
      }, 
      {
        Properties: {
          axis: "y"
        }, 
        Name: "minecraft:oak_log"
      }, 
      {
        Properties: {
          facing: "west", 
          type: "single"
        }, 
        Name: "minecraft:chest"
      }, 
      {
        Properties: {
          mode: "data"
        }, 
        Name: "minecraft:structure_block"
      }, 
      {
        Properties: {
          facing: "north", 
          type: "single"
        }, 
        Name: "minecraft:chest"
      }, 
      {
        Properties: {
          half: "top", 
          shape: "outer_right", 
          facing: "east"
        }, 
        Name: "minecraft:oak_stairs"
      }, 
      {
        Properties: {
          half: "top", 
          shape: "outer_right", 
          facing: "west"
        }, 
        Name: "minecraft:oak_stairs"
      }, 
      {
        Properties: {
          half: "bottom", 
          shape: "outer_right", 
          facing: "west"
        }, 
        Name: "minecraft:oak_stairs"
      }, 
      {
        Properties: {
          half: "bottom", 
          shape: "outer_right", 
          facing: "east"
        }, 
        Name: "minecraft:oak_stairs"
      }, 
      {
        Properties: {
          half: "top", 
          powered: "false", 
          facing: "north", 
          open: "false"
        }, 
        Name: "minecraft:oak_trapdoor"
      }, 
      {
        Properties: {
          hinge: "right", 
          half: "lower", 
          powered: "false", 
          facing: "south", 
          open: "false"
        }, 
        Name: "minecraft:oak_door"
      }, 
      {
        Properties: {
          hinge: "left", 
          half: "upper", 
          powered: "false", 
          facing: "east", 
          open: "false"
        }, 
        Name: "minecraft:oak_door"
      }, 
      {
        Properties: {
          east: "false", 
          south: "false", 
          north: "false", 
          west: "false"
        }, 
        Name: "minecraft:birch_fence"
      }, 
      {
        Properties: {
          half: "bottom", 
          shape: "outer_right", 
          facing: "north"
        }, 
        Name: "minecraft:birch_stairs"
      }, 
      {
        Properties: {
          half: "bottom", 
          shape: "outer_right", 
          facing: "south"
        }, 
        Name: "minecraft:birch_stairs"
      }, 
      {
        Properties: {
          half: "bottom", 
          shape: "outer_right", 
          facing: "south"
        }, 
        Name: "minecraft:oak_stairs"
      }, 
      {
        Properties: {
          half: "top", 
          shape: "outer_right", 
          facing: "south"
        }, 
        Name: "minecraft:oak_stairs"
      }, 
      {
        Properties: {
          half: "bottom"
        }, 
        Name: "minecraft:birch_slab"
      }, 
      {
        Properties: {
          half: "bottom"
        }, 
        Name: "minecraft:oak_slab"
      }, 
      {
        Properties: {
          half: "top"
        }, 
        Name: "minecraft:birch_slab"
      }, 
      {
        Properties: {
          half: "top", 
          shape: "outer_right", 
          facing: "north"
        }, 
        Name: "minecraft:birch_stairs"
      }, 
      {
        Properties: {
          east: "false", 
          south: "false", 
          north: "false", 
          west: "false"
        }, 
        Name: "minecraft:oak_fence"
      }, 
      {
        Properties: {
          half: "top"
        }, 
        Name: "minecraft:oak_slab"
      }, 
      {
        Properties: {
          half: "top", 
          shape: "outer_right", 
          facing: "north"
        }, 
        Name: "minecraft:oak_stairs"
      }, 
      {
        Properties: {
          half: "top", 
          shape: "outer_right", 
          facing: "south"
        }, 
        Name: "minecraft:birch_stairs"
      }
    ]
  ]
}
