{
  size: [9, 9, 28], 
  entities: [], 
  author: "CascadianBacon", 
  blocks: [
    {
      pos: [1, 4, 2], 
      state: 0
    }, 
    {
      pos: [2, 4, 3], 
      state: 0
    }, 
    {
      pos: [3, 4, 3], 
      state: 0
    }, 
    {
      pos: [2, 3, 4], 
      state: 1
    }, 
    {
      pos: [3, 3, 4], 
      state: 1
    }, 
    {
      pos: [3, 4, 4], 
      state: 0
    }, 
    {
      pos: [4, 4, 4], 
      state: 0
    }, 
    {
      pos: [2, 5, 4], 
      state: 1
    }, 
    {
      pos: [3, 5, 4], 
      state: 1
    }, 
    {
      pos: [2, 2, 5], 
      state: 1
    }, 
    {
      pos: [3, 2, 5], 
      state: 1
    }, 
    {
      pos: [3, 3, 5], 
      state: 0
    }, 
    {
      pos: [4, 3, 5], 
      state: 1
    }, 
    {
      pos: [3, 4, 5], 
      state: 0
    }, 
    {
      pos: [4, 4, 5], 
      state: 1
    }, 
    {
      pos: [5, 4, 5], 
      state: 0
    }, 
    {
      pos: [3, 5, 5], 
      state: 0
    }, 
    {
      pos: [4, 5, 5], 
      state: 1
    }, 
    {
      pos: [2, 6, 5], 
      state: 1
    }, 
    {
      pos: [3, 6, 5], 
      state: 1
    }, 
    {
      pos: [2, 1, 6], 
      state: 1
    }, 
    {
      pos: [3, 2, 6], 
      state: 0
    }, 
    {
      pos: [3, 3, 6], 
      state: 0
    }, 
    {
      pos: [4, 3, 6], 
      state: 1
    }, 
    {
      pos: [3, 4, 6], 
      state: 0
    }, 
    {
      pos: [4, 4, 6], 
      state: 1
    }, 
    {
      pos: [5, 4, 6], 
      state: 1
    }, 
    {
      pos: [6, 4, 6], 
      state: 0
    }, 
    {
      pos: [3, 5, 6], 
      state: 0
    }, 
    {
      pos: [4, 5, 6], 
      state: 1
    }, 
    {
      pos: [3, 6, 6], 
      state: 0
    }, 
    {
      pos: [2, 7, 6], 
      state: 1
    }, 
    {
      pos: [2, 1, 7], 
      state: 1
    }, 
    {
      pos: [3, 1, 7], 
      state: 1
    }, 
    {
      pos: [3, 2, 7], 
      state: 0
    }, 
    {
      pos: [4, 2, 7], 
      state: 1
    }, 
    {
      pos: [4, 3, 7], 
      state: 0
    }, 
    {
      pos: [5, 3, 7], 
      state: 1
    }, 
    {
      pos: [3, 4, 7], 
      state: 2
    }, 
    {
      pos: [4, 4, 7], 
      state: 2
    }, 
    {
      pos: [5, 4, 7], 
      state: 1
    }, 
    {
      pos: [6, 4, 7], 
      state: 1
    }, 
    {
      pos: [7, 4, 7], 
      state: 0
    }, 
    {
      pos: [4, 5, 7], 
      state: 0
    }, 
    {
      pos: [5, 5, 7], 
      state: 1
    }, 
    {
      pos: [3, 6, 7], 
      state: 0
    }, 
    {
      pos: [4, 6, 7], 
      state: 1
    }, 
    {
      pos: [2, 7, 7], 
      state: 1
    }, 
    {
      pos: [3, 7, 7], 
      state: 1
    }, 
    {
      pos: [2, 0, 8], 
      state: 1
    }, 
    {
      pos: [3, 1, 8], 
      state: 1
    }, 
    {
      pos: [4, 1, 8], 
      state: 1
    }, 
    {
      pos: [4, 2, 8], 
      state: 0
    }, 
    {
      pos: [5, 2, 8], 
      state: 1
    }, 
    {
      pos: [4, 3, 8], 
      state: 0
    }, 
    {
      pos: [6, 3, 8], 
      state: 1
    }, 
    {
      pos: [4, 4, 8], 
      state: 0
    }, 
    {
      pos: [6, 4, 8], 
      state: 1
    }, 
    {
      pos: [7, 4, 8], 
      state: 0
    }, 
    {
      pos: [4, 5, 8], 
      state: 0
    }, 
    {
      pos: [6, 5, 8], 
      state: 1
    }, 
    {
      pos: [4, 6, 8], 
      state: 0
    }, 
    {
      pos: [5, 6, 8], 
      state: 1
    }, 
    {
      pos: [3, 7, 8], 
      state: 1
    }, 
    {
      pos: [4, 7, 8], 
      state: 1
    }, 
    {
      pos: [2, 8, 8], 
      state: 1
    }, 
    {
      pos: [3, 0, 9], 
      state: 1
    }, 
    {
      pos: [4, 1, 9], 
      state: 0
    }, 
    {
      pos: [5, 1, 9], 
      state: 1
    }, 
    {
      pos: [4, 2, 9], 
      state: 0
    }, 
    {
      pos: [5, 2, 9], 
      state: 1
    }, 
    {
      pos: [6, 2, 9], 
      state: 1
    }, 
    {
      pos: [7, 3, 9], 
      state: 1
    }, 
    {
      pos: [7, 4, 9], 
      state: 1
    }, 
    {
      pos: [8, 4, 9], 
      state: 0
    }, 
    {
      pos: [7, 5, 9], 
      state: 1
    }, 
    {
      pos: [4, 6, 9], 
      state: 0
    }, 
    {
      pos: [5, 6, 9], 
      state: 1
    }, 
    {
      pos: [6, 6, 9], 
      state: 1
    }, 
    {
      pos: [4, 7, 9], 
      state: 0
    }, 
    {
      pos: [5, 7, 9], 
      state: 1
    }, 
    {
      pos: [3, 8, 9], 
      state: 1
    }, 
    {
      pos: [3, 0, 10], 
      state: 1
    }, 
    {
      pos: [4, 1, 10], 
      state: 0
    }, 
    {
      pos: [5, 1, 10], 
      state: 1
    }, 
    {
      pos: [4, 2, 10], 
      state: 0
    }, 
    {
      pos: [5, 2, 10], 
      state: 1
    }, 
    {
      pos: [6, 2, 10], 
      state: 1
    }, 
    {
      pos: [7, 3, 10], 
      state: 1
    }, 
    {
      pos: [7, 4, 10], 
      state: 1
    }, 
    {
      pos: [8, 4, 10], 
      state: 0
    }, 
    {
      pos: [7, 5, 10], 
      state: 1
    }, 
    {
      pos: [4, 6, 10], 
      state: 0
    }, 
    {
      pos: [5, 6, 10], 
      state: 1
    }, 
    {
      pos: [6, 6, 10], 
      state: 1
    }, 
    {
      pos: [4, 7, 10], 
      state: 0
    }, 
    {
      pos: [5, 7, 10], 
      state: 1
    }, 
    {
      pos: [3, 8, 10], 
      state: 1
    }, 
    {
      pos: [4, 1, 11], 
      state: 0
    }, 
    {
      pos: [5, 1, 11], 
      state: 1
    }, 
    {
      pos: [4, 2, 11], 
      state: 0
    }, 
    {
      pos: [5, 2, 11], 
      state: 1
    }, 
    {
      pos: [6, 2, 11], 
      state: 1
    }, 
    {
      pos: [4, 3, 11], 
      state: 0
    }, 
    {
      pos: [7, 3, 11], 
      state: 1
    }, 
    {
      pos: [3, 4, 11], 
      state: 2
    }, 
    {
      pos: [4, 4, 11], 
      state: 2
    }, 
    {
      pos: [5, 4, 11], 
      state: 2
    }, 
    {
      pos: [6, 4, 11], 
      state: 2
    }, 
    {
      pos: [7, 4, 11], 
      state: 1
    }, 
    {
      pos: [8, 4, 11], 
      state: 0
    }, 
    {
      pos: [4, 5, 11], 
      state: 0
    }, 
    {
      pos: [7, 5, 11], 
      state: 1
    }, 
    {
      pos: [4, 6, 11], 
      state: 0
    }, 
    {
      pos: [5, 6, 11], 
      state: 1
    }, 
    {
      pos: [6, 6, 11], 
      state: 1
    }, 
    {
      pos: [4, 7, 11], 
      state: 0
    }, 
    {
      pos: [5, 7, 11], 
      state: 1
    }, 
    {
      pos: [4, 1, 12], 
      state: 0
    }, 
    {
      pos: [7, 3, 12], 
      state: 1
    }, 
    {
      pos: [7, 4, 12], 
      state: 1
    }, 
    {
      pos: [8, 4, 12], 
      state: 0
    }, 
    {
      pos: [7, 5, 12], 
      state: 1
    }, 
    {
      pos: [4, 7, 12], 
      state: 0
    }, 
    {
      pos: [4, 1, 13], 
      state: 0
    }, 
    {
      pos: [5, 1, 13], 
      state: 1
    }, 
    {
      pos: [4, 2, 13], 
      state: 0
    }, 
    {
      pos: [5, 2, 13], 
      state: 1
    }, 
    {
      pos: [6, 2, 13], 
      state: 1
    }, 
    {
      pos: [7, 3, 13], 
      state: 1
    }, 
    {
      pos: [7, 4, 13], 
      state: 1
    }, 
    {
      pos: [8, 4, 13], 
      state: 0
    }, 
    {
      pos: [4, 6, 13], 
      state: 0
    }, 
    {
      pos: [4, 1, 14], 
      state: 0
    }, 
    {
      pos: [5, 1, 14], 
      state: 1
    }, 
    {
      pos: [4, 2, 14], 
      state: 0
    }, 
    {
      pos: [5, 2, 14], 
      state: 1
    }, 
    {
      pos: [6, 2, 14], 
      state: 1
    }, 
    {
      pos: [7, 3, 14], 
      state: 1
    }, 
    {
      pos: [4, 1, 15], 
      state: 0
    }, 
    {
      pos: [7, 3, 15], 
      state: 1
    }, 
    {
      pos: [7, 4, 15], 
      state: 1
    }, 
    {
      pos: [4, 1, 16], 
      state: 0
    }, 
    {
      pos: [5, 1, 16], 
      state: 1
    }, 
    {
      pos: [4, 2, 16], 
      state: 0
    }, 
    {
      pos: [5, 2, 16], 
      state: 1
    }, 
    {
      pos: [6, 2, 16], 
      state: 1
    }, 
    {
      pos: [4, 3, 16], 
      state: 0
    }, 
    {
      pos: [7, 3, 16], 
      state: 1
    }, 
    {
      pos: [3, 4, 16], 
      state: 2
    }, 
    {
      pos: [4, 4, 16], 
      state: 2
    }, 
    {
      pos: [5, 4, 16], 
      state: 2
    }, 
    {
      pos: [6, 4, 16], 
      state: 2
    }, 
    {
      pos: [7, 4, 16], 
      state: 1
    }, 
    {
      pos: [8, 4, 16], 
      state: 0
    }, 
    {
      pos: [4, 5, 16], 
      state: 0
    }, 
    {
      pos: [5, 5, 16], 
      state: 1
    }, 
    {
      pos: [6, 5, 16], 
      state: 1
    }, 
    {
      pos: [4, 1, 17], 
      state: 0
    }, 
    {
      pos: [5, 1, 17], 
      state: 1
    }, 
    {
      pos: [4, 2, 17], 
      state: 0
    }, 
    {
      pos: [5, 2, 17], 
      state: 1
    }, 
    {
      pos: [6, 2, 17], 
      state: 1
    }, 
    {
      pos: [4, 3, 17], 
      state: 0
    }, 
    {
      pos: [7, 3, 17], 
      state: 1
    }, 
    {
      pos: [4, 4, 17], 
      state: 0
    }, 
    {
      pos: [7, 4, 17], 
      state: 1
    }, 
    {
      pos: [8, 4, 17], 
      state: 0
    }, 
    {
      pos: [4, 5, 17], 
      state: 0
    }, 
    {
      pos: [7, 5, 17], 
      state: 1
    }, 
    {
      pos: [4, 6, 17], 
      state: 0
    }, 
    {
      pos: [6, 6, 17], 
      state: 1
    }, 
    {
      pos: [3, 0, 18], 
      state: 1
    }, 
    {
      pos: [4, 1, 18], 
      state: 0
    }, 
    {
      pos: [4, 2, 18], 
      state: 0
    }, 
    {
      pos: [4, 3, 18], 
      state: 0
    }, 
    {
      pos: [7, 3, 18], 
      state: 1
    }, 
    {
      pos: [4, 4, 18], 
      state: 0
    }, 
    {
      pos: [7, 4, 18], 
      state: 1
    }, 
    {
      pos: [8, 4, 18], 
      state: 0
    }, 
    {
      pos: [4, 5, 18], 
      state: 0
    }, 
    {
      pos: [7, 5, 18], 
      state: 1
    }, 
    {
      pos: [4, 6, 18], 
      state: 0
    }, 
    {
      pos: [4, 7, 18], 
      state: 0
    }, 
    {
      pos: [2, 0, 19], 
      state: 1
    }, 
    {
      pos: [3, 0, 19], 
      state: 1
    }, 
    {
      pos: [3, 1, 19], 
      state: 0
    }, 
    {
      pos: [4, 1, 19], 
      state: 1
    }, 
    {
      pos: [5, 1, 19], 
      state: 1
    }, 
    {
      pos: [2, 2, 19], 
      state: 1
    }, 
    {
      pos: [3, 2, 19], 
      state: 1
    }, 
    {
      pos: [4, 2, 19], 
      state: 0
    }, 
    {
      pos: [5, 2, 19], 
      state: 1
    }, 
    {
      pos: [6, 2, 19], 
      state: 1
    }, 
    {
      pos: [3, 3, 19], 
      state: 1
    }, 
    {
      pos: [4, 3, 19], 
      state: 0
    }, 
    {
      pos: [7, 3, 19], 
      state: 1
    }, 
    {
      pos: [4, 4, 19], 
      state: 0
    }, 
    {
      pos: [7, 4, 19], 
      state: 1
    }, 
    {
      pos: [8, 4, 19], 
      state: 0
    }, 
    {
      pos: [3, 5, 19], 
      state: 1
    }, 
    {
      pos: [4, 5, 19], 
      state: 0
    }, 
    {
      pos: [7, 5, 19], 
      state: 1
    }, 
    {
      pos: [2, 6, 19], 
      state: 1
    }, 
    {
      pos: [3, 6, 19], 
      state: 1
    }, 
    {
      pos: [4, 6, 19], 
      state: 0
    }, 
    {
      pos: [5, 6, 19], 
      state: 1
    }, 
    {
      pos: [6, 6, 19], 
      state: 1
    }, 
    {
      pos: [3, 7, 19], 
      state: 0
    }, 
    {
      pos: [4, 7, 19], 
      state: 1
    }, 
    {
      pos: [5, 7, 19], 
      state: 1
    }, 
    {
      pos: [2, 8, 19], 
      state: 1
    }, 
    {
      pos: [3, 8, 19], 
      state: 1
    }, 
    {
      pos: [2, 0, 20], 
      state: 1
    }, 
    {
      pos: [3, 0, 20], 
      state: 1
    }, 
    {
      pos: [2, 1, 20], 
      state: 0
    }, 
    {
      pos: [3, 1, 20], 
      state: 1
    }, 
    {
      pos: [4, 1, 20], 
      state: 1
    }, 
    {
      pos: [5, 1, 20], 
      state: 1
    }, 
    {
      pos: [2, 2, 20], 
      state: 0
    }, 
    {
      pos: [5, 2, 20], 
      state: 1
    }, 
    {
      pos: [6, 2, 20], 
      state: 1
    }, 
    {
      pos: [2, 3, 20], 
      state: 0
    }, 
    {
      pos: [5, 3, 20], 
      state: 0
    }, 
    {
      pos: [6, 3, 20], 
      state: 0
    }, 
    {
      pos: [7, 3, 20], 
      state: 1
    }, 
    {
      pos: [5, 4, 20], 
      state: 0
    }, 
    {
      pos: [6, 4, 20], 
      state: 0
    }, 
    {
      pos: [7, 4, 20], 
      state: 1
    }, 
    {
      pos: [8, 4, 20], 
      state: 0
    }, 
    {
      pos: [2, 5, 20], 
      state: 0
    }, 
    {
      pos: [5, 5, 20], 
      state: 0
    }, 
    {
      pos: [6, 5, 20], 
      state: 0
    }, 
    {
      pos: [7, 5, 20], 
      state: 1
    }, 
    {
      pos: [2, 6, 20], 
      state: 0
    }, 
    {
      pos: [5, 6, 20], 
      state: 1
    }, 
    {
      pos: [6, 6, 20], 
      state: 1
    }, 
    {
      pos: [2, 7, 20], 
      state: 0
    }, 
    {
      pos: [3, 7, 20], 
      state: 1
    }, 
    {
      pos: [4, 7, 20], 
      state: 1
    }, 
    {
      pos: [5, 7, 20], 
      state: 1
    }, 
    {
      pos: [2, 8, 20], 
      state: 1
    }, 
    {
      pos: [3, 8, 20], 
      state: 1
    }, 
    {
      pos: [1, 0, 21], 
      state: 1
    }, 
    {
      pos: [2, 0, 21], 
      state: 1
    }, 
    {
      pos: [0, 1, 21], 
      state: 1
    }, 
    {
      pos: [1, 1, 21], 
      state: 1
    }, 
    {
      pos: [3, 1, 21], 
      state: 1
    }, 
    {
      pos: [4, 1, 21], 
      state: 1
    }, 
    {
      pos: [1, 2, 21], 
      state: 0
    }, 
    {
      pos: [5, 2, 21], 
      state: 0
    }, 
    {
      pos: [0, 3, 21], 
      state: 1
    }, 
    {
      pos: [1, 3, 21], 
      state: 0
    }, 
    {
      pos: [5, 3, 21], 
      state: 0
    }, 
    {
      pos: [6, 3, 21], 
      state: 1
    }, 
    {
      pos: [0, 4, 21], 
      state: 1
    }, 
    {
      pos: [1, 4, 21], 
      state: 0
    }, 
    {
      pos: [5, 4, 21], 
      state: 0
    }, 
    {
      pos: [6, 4, 21], 
      state: 1
    }, 
    {
      pos: [7, 4, 21], 
      state: 0
    }, 
    {
      pos: [0, 5, 21], 
      state: 1
    }, 
    {
      pos: [1, 5, 21], 
      state: 0
    }, 
    {
      pos: [5, 5, 21], 
      state: 0
    }, 
    {
      pos: [6, 5, 21], 
      state: 1
    }, 
    {
      pos: [1, 6, 21], 
      state: 0
    }, 
    {
      pos: [5, 6, 21], 
      state: 0
    }, 
    {
      pos: [0, 7, 21], 
      state: 1
    }, 
    {
      pos: [1, 7, 21], 
      state: 1
    }, 
    {
      pos: [3, 7, 21], 
      state: 1
    }, 
    {
      pos: [4, 7, 21], 
      state: 1
    }, 
    {
      pos: [1, 8, 21], 
      state: 1
    }, 
    {
      pos: [2, 8, 21], 
      state: 1
    }, 
    {
      pos: [1, 0, 22], 
      state: 1
    }, 
    {
      pos: [1, 1, 22], 
      state: 0
    }, 
    {
      pos: [4, 1, 22], 
      state: 1
    }, 
    {
      pos: [1, 2, 22], 
      state: 0
    }, 
    {
      pos: [5, 2, 22], 
      state: 0
    }, 
    {
      pos: [1, 3, 22], 
      state: 0
    }, 
    {
      pos: [5, 3, 22], 
      state: 0
    }, 
    {
      pos: [6, 3, 22], 
      state: 1
    }, 
    {
      pos: [1, 4, 22], 
      state: 0
    }, 
    {
      pos: [5, 4, 22], 
      state: 0
    }, 
    {
      pos: [6, 4, 22], 
      state: 1
    }, 
    {
      pos: [7, 4, 22], 
      state: 0
    }, 
    {
      pos: [1, 5, 22], 
      state: 0
    }, 
    {
      pos: [5, 5, 22], 
      state: 0
    }, 
    {
      pos: [6, 5, 22], 
      state: 1
    }, 
    {
      pos: [1, 6, 22], 
      state: 0
    }, 
    {
      pos: [5, 6, 22], 
      state: 0
    }, 
    {
      pos: [1, 7, 22], 
      state: 0
    }, 
    {
      pos: [4, 7, 22], 
      state: 1
    }, 
    {
      pos: [1, 8, 22], 
      state: 1
    }, 
    {
      pos: [1, 0, 23], 
      state: 1
    }, 
    {
      pos: [2, 0, 23], 
      state: 1
    }, 
    {
      pos: [1, 1, 23], 
      state: 0
    }, 
    {
      pos: [3, 1, 23], 
      state: 1
    }, 
    {
      pos: [4, 1, 23], 
      state: 1
    }, 
    {
      pos: [1, 2, 23], 
      state: 0
    }, 
    {
      pos: [5, 2, 23], 
      state: 0
    }, 
    {
      pos: [1, 3, 23], 
      state: 0
    }, 
    {
      pos: [5, 3, 23], 
      state: 0
    }, 
    {
      pos: [6, 3, 23], 
      state: 1
    }, 
    {
      pos: [1, 4, 23], 
      state: 0
    }, 
    {
      pos: [5, 4, 23], 
      state: 0
    }, 
    {
      pos: [6, 4, 23], 
      state: 1
    }, 
    {
      pos: [7, 4, 23], 
      state: 0
    }, 
    {
      pos: [1, 5, 23], 
      state: 0
    }, 
    {
      pos: [5, 5, 23], 
      state: 0
    }, 
    {
      pos: [6, 5, 23], 
      state: 1
    }, 
    {
      pos: [1, 6, 23], 
      state: 0
    }, 
    {
      pos: [5, 6, 23], 
      state: 0
    }, 
    {
      pos: [1, 7, 23], 
      state: 0
    }, 
    {
      pos: [3, 7, 23], 
      state: 1
    }, 
    {
      pos: [4, 7, 23], 
      state: 1
    }, 
    {
      pos: [1, 8, 23], 
      state: 1
    }, 
    {
      pos: [2, 8, 23], 
      state: 1
    }, 
    {
      pos: [1, 1, 24], 
      state: 1
    }, 
    {
      pos: [2, 1, 24], 
      state: 1
    }, 
    {
      pos: [3, 1, 24], 
      state: 1
    }, 
    {
      pos: [4, 1, 24], 
      state: 1
    }, 
    {
      pos: [1, 2, 24], 
      state: 0
    }, 
    {
      pos: [5, 2, 24], 
      state: 0
    }, 
    {
      pos: [1, 3, 24], 
      state: 0
    }, 
    {
      pos: [5, 3, 24], 
      state: 0
    }, 
    {
      pos: [6, 3, 24], 
      state: 1
    }, 
    {
      pos: [1, 4, 24], 
      state: 0
    }, 
    {
      pos: [5, 4, 24], 
      state: 0
    }, 
    {
      pos: [6, 4, 24], 
      state: 0
    }, 
    {
      pos: [1, 5, 24], 
      state: 0
    }, 
    {
      pos: [5, 5, 24], 
      state: 0
    }, 
    {
      pos: [6, 5, 24], 
      state: 1
    }, 
    {
      pos: [1, 6, 24], 
      state: 0
    }, 
    {
      pos: [5, 6, 24], 
      state: 0
    }, 
    {
      pos: [1, 7, 24], 
      state: 1
    }, 
    {
      pos: [2, 7, 24], 
      state: 1
    }, 
    {
      pos: [3, 7, 24], 
      state: 1
    }, 
    {
      pos: [4, 7, 24], 
      state: 1
    }, 
    {
      pos: [0, 1, 25], 
      state: 1
    }, 
    {
      pos: [1, 1, 25], 
      state: 1
    }, 
    {
      pos: [2, 1, 25], 
      state: 1
    }, 
    {
      pos: [1, 2, 25], 
      state: 0
    }, 
    {
      pos: [3, 2, 25], 
      state: 1
    }, 
    {
      pos: [1, 3, 25], 
      state: 0
    }, 
    {
      pos: [4, 3, 25], 
      state: 1
    }, 
    {
      pos: [5, 3, 25], 
      state: 1
    }, 
    {
      pos: [1, 4, 25], 
      state: 0
    }, 
    {
      pos: [4, 4, 25], 
      state: 1
    }, 
    {
      pos: [1, 5, 25], 
      state: 0
    }, 
    {
      pos: [4, 5, 25], 
      state: 1
    }, 
    {
      pos: [5, 5, 25], 
      state: 1
    }, 
    {
      pos: [1, 6, 25], 
      state: 0
    }, 
    {
      pos: [3, 6, 25], 
      state: 1
    }, 
    {
      pos: [0, 7, 25], 
      state: 1
    }, 
    {
      pos: [1, 7, 25], 
      state: 1
    }, 
    {
      pos: [2, 7, 25], 
      state: 1
    }, 
    {
      pos: [0, 2, 26], 
      state: 1
    }, 
    {
      pos: [1, 2, 26], 
      state: 1
    }, 
    {
      pos: [1, 3, 26], 
      state: 0
    }, 
    {
      pos: [2, 3, 26], 
      state: 1
    }, 
    {
      pos: [1, 4, 26], 
      state: 0
    }, 
    {
      pos: [3, 4, 26], 
      state: 1
    }, 
    {
      pos: [1, 5, 26], 
      state: 0
    }, 
    {
      pos: [2, 5, 26], 
      state: 1
    }, 
    {
      pos: [0, 6, 26], 
      state: 1
    }, 
    {
      pos: [1, 6, 26], 
      state: 1
    }, 
    {
      pos: [1, 4, 27], 
      state: 1
    }, 
    {
      nbt: {
        Items: [], 
        id: "minecraft:chest", 
        Lock: ""
      }, 
      pos: [5, 3, 8], 
      state: 3
    }, 
    {
      nbt: {
        metadata: "supply_chest", 
        mirror: "NONE", 
        ignoreEntities: 1b, 
        powered: 0b, 
        seed: 0L, 
        author: "CascadianBacon", 
        rotation: "NONE", 
        mode: "DATA", 
        posX: 0, 
        posY: 1, 
        sizeX: 0, 
        integrity: 1.0f, 
        posZ: 0, 
        showair: 0b, 
        name: "", 
        id: "minecraft:structure_block", 
        sizeY: 0, 
        showboundingbox: 1b, 
        sizeZ: 0
      }, 
      pos: [5, 4, 8], 
      state: 4
    }, 
    {
      nbt: {
        Items: [], 
        id: "minecraft:chest", 
        Lock: ""
      }, 
      pos: [6, 3, 19], 
      state: 5
    }, 
    {
      nbt: {
        metadata: "map_chest", 
        mirror: "NONE", 
        ignoreEntities: 1b, 
        powered: 0b, 
        seed: 0L, 
        author: "CascadianBacon", 
        rotation: "NONE", 
        mode: "DATA", 
        posX: 0, 
        posY: 1, 
        sizeX: 0, 
        integrity: 1.0f, 
        posZ: 0, 
        showair: 0b, 
        name: "", 
        id: "minecraft:structure_block", 
        sizeY: 0, 
        showboundingbox: 1b, 
        sizeZ: 0
      }, 
      pos: [6, 4, 19], 
      state: 4
    }, 
    {
      nbt: {
        Items: [], 
        id: "minecraft:chest", 
        Lock: ""
      }, 
      pos: [3, 2, 24], 
      state: 5
    }, 
    {
      nbt: {
        metadata: "treasure_chest", 
        mirror: "NONE", 
        ignoreEntities: 1b, 
        powered: 0b, 
        seed: 0L, 
        author: "CascadianBacon", 
        rotation: "NONE", 
        mode: "DATA", 
        posX: 0, 
        posY: 1, 
        sizeX: 0, 
        integrity: 1.0f, 
        posZ: 0, 
        showair: 0b, 
        name: "", 
        id: "minecraft:structure_block", 
        sizeY: 0, 
        showboundingbox: 1b, 
        sizeZ: 0
      }, 
      pos: [3, 3, 24], 
      state: 4
    }, 
    {
      pos: [0, 4, 0], 
      state: 6
    }, 
    {
      pos: [0, 4, 1], 
      state: 7
    }, 
    {
      pos: [1, 4, 1], 
      state: 6
    }, 
    {
      pos: [1, 3, 2], 
      state: 8
    }, 
    {
      pos: [2, 3, 2], 
      state: 8
    }, 
    {
      pos: [2, 4, 2], 
      state: 6
    }, 
    {
      pos: [1, 5, 2], 
      state: 8
    }, 
    {
      pos: [2, 5, 2], 
      state: 8
    }, 
    {
      pos: [1, 3, 3], 
      state: 8
    }, 
    {
      pos: [2, 3, 3], 
      state: 9
    }, 
    {
      pos: [3, 3, 3], 
      state: 10
    }, 
    {
      pos: [1, 4, 3], 
      state: 7
    }, 
    {
      pos: [4, 4, 3], 
      state: 6
    }, 
    {
      pos: [1, 5, 3], 
      state: 8
    }, 
    {
      pos: [2, 5, 3], 
      state: 9
    }, 
    {
      pos: [3, 5, 3], 
      state: 9
    }, 
    {
      pos: [1, 3, 4], 
      state: 8
    }, 
    {
      pos: [4, 3, 4], 
      state: 10
    }, 
    {
      pos: [2, 4, 4], 
      state: 7
    }, 
    {
      pos: [5, 4, 4], 
      state: 6
    }, 
    {
      pos: [1, 5, 4], 
      state: 8
    }, 
    {
      pos: [4, 5, 4], 
      state: 9
    }, 
    {
      pos: [4, 2, 5], 
      state: 11
    }, 
    {
      pos: [5, 3, 5], 
      state: 11
    }, 
    {
      pos: [6, 4, 5], 
      state: 6
    }, 
    {
      pos: [5, 5, 5], 
      state: 12
    }, 
    {
      pos: [4, 6, 5], 
      state: 12
    }, 
    {
      pos: [3, 1, 6], 
      state: 11
    }, 
    {
      pos: [4, 2, 6], 
      state: 11
    }, 
    {
      pos: [5, 3, 6], 
      state: 11
    }, 
    {
      pos: [7, 4, 6], 
      state: 6
    }, 
    {
      pos: [5, 5, 6], 
      state: 12
    }, 
    {
      pos: [4, 6, 6], 
      state: 12
    }, 
    {
      pos: [3, 7, 6], 
      state: 12
    }, 
    {
      pos: [4, 1, 7], 
      state: 11
    }, 
    {
      pos: [5, 2, 7], 
      state: 11
    }, 
    {
      pos: [3, 3, 7], 
      state: 7
    }, 
    {
      pos: [6, 3, 7], 
      state: 11
    }, 
    {
      pos: [3, 5, 7], 
      state: 13
    }, 
    {
      pos: [6, 5, 7], 
      state: 12
    }, 
    {
      pos: [5, 6, 7], 
      state: 12
    }, 
    {
      pos: [4, 7, 7], 
      state: 12
    }, 
    {
      pos: [3, 0, 8], 
      state: 10
    }, 
    {
      pos: [2, 1, 8], 
      state: 14
    }, 
    {
      pos: [5, 1, 8], 
      state: 11
    }, 
    {
      pos: [6, 2, 8], 
      state: 11
    }, 
    {
      pos: [7, 3, 8], 
      state: 11
    }, 
    {
      pos: [8, 4, 8], 
      state: 6
    }, 
    {
      pos: [7, 5, 8], 
      state: 12
    }, 
    {
      pos: [6, 6, 8], 
      state: 12
    }, 
    {
      pos: [2, 7, 8], 
      state: 15
    }, 
    {
      pos: [5, 7, 8], 
      state: 12
    }, 
    {
      pos: [3, 8, 8], 
      state: 9
    }, 
    {
      pos: [2, 0, 9], 
      state: 14
    }, 
    {
      pos: [4, 0, 9], 
      state: 11
    }, 
    {
      pos: [6, 1, 9], 
      state: 11
    }, 
    {
      pos: [7, 2, 9], 
      state: 11
    }, 
    {
      pos: [4, 3, 9], 
      state: 16
    }, 
    {
      pos: [4, 5, 9], 
      state: 17
    }, 
    {
      pos: [7, 6, 9], 
      state: 12
    }, 
    {
      pos: [6, 7, 9], 
      state: 12
    }, 
    {
      pos: [2, 8, 9], 
      state: 15
    }, 
    {
      pos: [4, 8, 9], 
      state: 12
    }, 
    {
      pos: [4, 0, 10], 
      state: 11
    }, 
    {
      pos: [6, 1, 10], 
      state: 11
    }, 
    {
      pos: [7, 2, 10], 
      state: 11
    }, 
    {
      pos: [4, 3, 10], 
      state: 16
    }, 
    {
      pos: [4, 5, 10], 
      state: 17
    }, 
    {
      pos: [7, 6, 10], 
      state: 12
    }, 
    {
      pos: [6, 7, 10], 
      state: 12
    }, 
    {
      pos: [4, 8, 10], 
      state: 12
    }, 
    {
      pos: [3, 0, 11], 
      state: 8
    }, 
    {
      pos: [4, 0, 11], 
      state: 11
    }, 
    {
      pos: [6, 1, 11], 
      state: 11
    }, 
    {
      pos: [7, 2, 11], 
      state: 11
    }, 
    {
      pos: [7, 6, 11], 
      state: 12
    }, 
    {
      pos: [6, 7, 11], 
      state: 12
    }, 
    {
      pos: [4, 8, 11], 
      state: 12
    }, 
    {
      pos: [3, 0, 12], 
      state: 8
    }, 
    {
      pos: [4, 0, 12], 
      state: 11
    }, 
    {
      pos: [6, 1, 12], 
      state: 11
    }, 
    {
      pos: [4, 2, 12], 
      state: 18
    }, 
    {
      pos: [6, 2, 12], 
      state: 19
    }, 
    {
      pos: [7, 2, 12], 
      state: 11
    }, 
    {
      pos: [4, 3, 12], 
      state: 16
    }, 
    {
      pos: [4, 4, 12], 
      state: 16
    }, 
    {
      pos: [4, 5, 12], 
      state: 17
    }, 
    {
      pos: [4, 6, 12], 
      state: 20
    }, 
    {
      pos: [6, 6, 12], 
      state: 21
    }, 
    {
      pos: [3, 0, 13], 
      state: 8
    }, 
    {
      pos: [4, 0, 13], 
      state: 11
    }, 
    {
      pos: [6, 1, 13], 
      state: 11
    }, 
    {
      pos: [7, 2, 13], 
      state: 11
    }, 
    {
      pos: [4, 3, 13], 
      state: 16
    }, 
    {
      pos: [4, 0, 14], 
      state: 11
    }, 
    {
      pos: [6, 1, 14], 
      state: 11
    }, 
    {
      pos: [7, 2, 14], 
      state: 11
    }, 
    {
      pos: [4, 3, 14], 
      state: 16
    }, 
    {
      pos: [3, 0, 15], 
      state: 8
    }, 
    {
      pos: [4, 0, 15], 
      state: 11
    }, 
    {
      pos: [6, 1, 15], 
      state: 11
    }, 
    {
      pos: [4, 2, 15], 
      state: 18
    }, 
    {
      pos: [6, 2, 15], 
      state: 19
    }, 
    {
      pos: [7, 2, 15], 
      state: 11
    }, 
    {
      pos: [4, 3, 15], 
      state: 16
    }, 
    {
      pos: [4, 4, 15], 
      state: 16
    }, 
    {
      pos: [3, 0, 16], 
      state: 8
    }, 
    {
      pos: [4, 0, 16], 
      state: 11
    }, 
    {
      pos: [6, 1, 16], 
      state: 11
    }, 
    {
      pos: [7, 2, 16], 
      state: 11
    }, 
    {
      pos: [3, 0, 17], 
      state: 8
    }, 
    {
      pos: [4, 0, 17], 
      state: 11
    }, 
    {
      pos: [6, 1, 17], 
      state: 11
    }, 
    {
      pos: [7, 2, 17], 
      state: 11
    }, 
    {
      pos: [2, 0, 18], 
      state: 9
    }, 
    {
      pos: [4, 0, 18], 
      state: 11
    }, 
    {
      pos: [3, 1, 18], 
      state: 22
    }, 
    {
      pos: [6, 1, 18], 
      state: 11
    }, 
    {
      pos: [6, 2, 18], 
      state: 19
    }, 
    {
      pos: [7, 2, 18], 
      state: 11
    }, 
    {
      pos: [6, 6, 18], 
      state: 21
    }, 
    {
      pos: [7, 6, 18], 
      state: 12
    }, 
    {
      pos: [3, 7, 18], 
      state: 6
    }, 
    {
      pos: [6, 7, 18], 
      state: 12
    }, 
    {
      pos: [4, 0, 19], 
      state: 11
    }, 
    {
      pos: [2, 1, 19], 
      state: 22
    }, 
    {
      pos: [6, 1, 19], 
      state: 11
    }, 
    {
      pos: [7, 2, 19], 
      state: 11
    }, 
    {
      pos: [7, 6, 19], 
      state: 12
    }, 
    {
      pos: [2, 7, 19], 
      state: 6
    }, 
    {
      pos: [6, 7, 19], 
      state: 12
    }, 
    {
      pos: [1, 0, 20], 
      state: 9
    }, 
    {
      pos: [4, 0, 20], 
      state: 11
    }, 
    {
      pos: [6, 1, 20], 
      state: 11
    }, 
    {
      pos: [4, 2, 20], 
      state: 19
    }, 
    {
      pos: [7, 2, 20], 
      state: 11
    }, 
    {
      pos: [4, 6, 20], 
      state: 21
    }, 
    {
      pos: [7, 6, 20], 
      state: 12
    }, 
    {
      pos: [6, 7, 20], 
      state: 12
    }, 
    {
      pos: [1, 8, 20], 
      state: 9
    }, 
    {
      pos: [4, 8, 20], 
      state: 12
    }, 
    {
      pos: [0, 0, 21], 
      state: 21
    }, 
    {
      pos: [3, 0, 21], 
      state: 11
    }, 
    {
      pos: [2, 1, 21], 
      state: 23
    }, 
    {
      pos: [5, 1, 21], 
      state: 11
    }, 
    {
      pos: [6, 2, 21], 
      state: 11
    }, 
    {
      pos: [7, 3, 21], 
      state: 11
    }, 
    {
      pos: [8, 4, 21], 
      state: 13
    }, 
    {
      pos: [7, 5, 21], 
      state: 12
    }, 
    {
      pos: [6, 6, 21], 
      state: 12
    }, 
    {
      pos: [2, 7, 21], 
      state: 23
    }, 
    {
      pos: [5, 7, 21], 
      state: 12
    }, 
    {
      pos: [0, 8, 21], 
      state: 19
    }, 
    {
      pos: [3, 8, 21], 
      state: 12
    }, 
    {
      pos: [0, 0, 22], 
      state: 21
    }, 
    {
      pos: [3, 0, 22], 
      state: 11
    }, 
    {
      pos: [3, 1, 22], 
      state: 19
    }, 
    {
      pos: [5, 1, 22], 
      state: 11
    }, 
    {
      pos: [6, 2, 22], 
      state: 11
    }, 
    {
      pos: [7, 3, 22], 
      state: 11
    }, 
    {
      pos: [7, 5, 22], 
      state: 12
    }, 
    {
      pos: [6, 6, 22], 
      state: 12
    }, 
    {
      pos: [3, 7, 22], 
      state: 21
    }, 
    {
      pos: [5, 7, 22], 
      state: 12
    }, 
    {
      pos: [0, 8, 22], 
      state: 19
    }, 
    {
      pos: [3, 8, 22], 
      state: 12
    }, 
    {
      pos: [0, 0, 23], 
      state: 21
    }, 
    {
      pos: [3, 0, 23], 
      state: 15
    }, 
    {
      pos: [0, 1, 23], 
      state: 8
    }, 
    {
      pos: [2, 1, 23], 
      state: 23
    }, 
    {
      pos: [5, 1, 23], 
      state: 11
    }, 
    {
      pos: [6, 2, 23], 
      state: 11
    }, 
    {
      pos: [7, 3, 23], 
      state: 11
    }, 
    {
      pos: [7, 5, 23], 
      state: 12
    }, 
    {
      pos: [6, 6, 23], 
      state: 12
    }, 
    {
      pos: [0, 7, 23], 
      state: 8
    }, 
    {
      pos: [2, 7, 23], 
      state: 23
    }, 
    {
      pos: [5, 7, 23], 
      state: 12
    }, 
    {
      pos: [0, 8, 23], 
      state: 19
    }, 
    {
      pos: [3, 8, 23], 
      state: 14
    }, 
    {
      pos: [0, 1, 24], 
      state: 8
    }, 
    {
      pos: [5, 1, 24], 
      state: 11
    }, 
    {
      pos: [4, 2, 24], 
      state: 9
    }, 
    {
      pos: [6, 2, 24], 
      state: 11
    }, 
    {
      pos: [4, 6, 24], 
      state: 10
    }, 
    {
      pos: [6, 6, 24], 
      state: 12
    }, 
    {
      pos: [0, 7, 24], 
      state: 8
    }, 
    {
      pos: [5, 7, 24], 
      state: 12
    }, 
    {
      pos: [3, 1, 25], 
      state: 15
    }, 
    {
      pos: [2, 2, 25], 
      state: 23
    }, 
    {
      pos: [4, 2, 25], 
      state: 15
    }, 
    {
      pos: [5, 2, 25], 
      state: 15
    }, 
    {
      pos: [3, 3, 25], 
      state: 9
    }, 
    {
      pos: [5, 4, 25], 
      state: 8
    }, 
    {
      pos: [3, 5, 25], 
      state: 10
    }, 
    {
      pos: [2, 6, 25], 
      state: 23
    }, 
    {
      pos: [4, 6, 25], 
      state: 14
    }, 
    {
      pos: [5, 6, 25], 
      state: 14
    }, 
    {
      pos: [3, 7, 25], 
      state: 14
    }, 
    {
      pos: [2, 2, 26], 
      state: 15
    }, 
    {
      pos: [0, 3, 26], 
      state: 8
    }, 
    {
      pos: [3, 3, 26], 
      state: 15
    }, 
    {
      pos: [4, 4, 26], 
      state: 15
    }, 
    {
      pos: [0, 5, 26], 
      state: 8
    }, 
    {
      pos: [3, 5, 26], 
      state: 14
    }, 
    {
      pos: [2, 6, 26], 
      state: 14
    }, 
    {
      pos: [0, 3, 27], 
      state: 8
    }, 
    {
      pos: [1, 3, 27], 
      state: 15
    }, 
    {
      pos: [0, 4, 27], 
      state: 8
    }, 
    {
      pos: [0, 5, 27], 
      state: 8
    }, 
    {
      pos: [1, 5, 27], 
      state: 14
    }
  ], 
  palettes: [
    [
      {
        Name: "minecraft:spruce_planks"
      }, 
      {
        Name: "minecraft:oak_planks"
      }, 
      {
        Properties: {
          axis: "x"
        }, 
        Name: "minecraft:oak_log"
      }, 
      {
        Properties: {
          facing: "south", 
          type: "single"
        }, 
        Name: "minecraft:chest"
      }, 
      {
        Properties: {
          mode: "data"
        }, 
        Name: "minecraft:structure_block"
      }, 
      {
        Properties: {
          facing: "north", 
          type: "single"
        }, 
        Name: "minecraft:chest"
      }, 
      {
        Properties: {
          half: "top", 
          shape: "outer_right", 
          facing: "south"
        }, 
        Name: "minecraft:spruce_stairs"
      }, 
      {
        Properties: {
          half: "bottom", 
          shape: "outer_right", 
          facing: "north"
        }, 
        Name: "minecraft:spruce_stairs"
      }, 
      {
        Properties: {
          east: "false", 
          south: "false", 
          north: "false", 
          west: "false"
        }, 
        Name: "minecraft:spruce_fence"
      }, 
      {
        Properties: {
          half: "bottom", 
          shape: "outer_right", 
          facing: "south"
        }, 
        Name: "minecraft:oak_stairs"
      }, 
      {
        Properties: {
          half: "top", 
          shape: "outer_right", 
          facing: "south"
        }, 
        Name: "minecraft:oak_stairs"
      }, 
      {
        Properties: {
          half: "top", 
          shape: "outer_right", 
          facing: "west"
        }, 
        Name: "minecraft:oak_stairs"
      }, 
      {
        Properties: {
          half: "bottom", 
          shape: "outer_right", 
          facing: "west"
        }, 
        Name: "minecraft:oak_stairs"
      }, 
      {
        Properties: {
          half: "top", 
          shape: "outer_right", 
          facing: "north"
        }, 
        Name: "minecraft:spruce_stairs"
      }, 
      {
        Properties: {
          half: "bottom", 
          shape: "outer_right", 
          facing: "north"
        }, 
        Name: "minecraft:oak_stairs"
      }, 
      {
        Properties: {
          half: "top", 
          shape: "outer_right", 
          facing: "north"
        }, 
        Name: "minecraft:oak_stairs"
      }, 
      {
        Properties: {
          half: "bottom", 
          powered: "false", 
          facing: "east", 
          open: "true"
        }, 
        Name: "minecraft:oak_trapdoor"
      }, 
      {
        Properties: {
          half: "top", 
          powered: "false", 
          facing: "east", 
          open: "true"
        }, 
        Name: "minecraft:oak_trapdoor"
      }, 
      {
        Properties: {
          half: "bottom", 
          shape: "outer_right", 
          facing: "west"
        }, 
        Name: "minecraft:spruce_stairs"
      }, 
      {
        Properties: {
          half: "bottom", 
          shape: "outer_right", 
          facing: "east"
        }, 
        Name: "minecraft:oak_stairs"
      }, 
      {
        Properties: {
          half: "top", 
          shape: "outer_right", 
          facing: "west"
        }, 
        Name: "minecraft:spruce_stairs"
      }, 
      {
        Properties: {
          half: "top", 
          shape: "outer_right", 
          facing: "east"
        }, 
        Name: "minecraft:oak_stairs"
      }, 
      {
        Properties: {
          half: "bottom", 
          shape: "outer_right", 
          facing: "south"
        }, 
        Name: "minecraft:spruce_stairs"
      }, 
      {
        Properties: {
          east: "false", 
          south: "false", 
          north: "false", 
          west: "false"
        }, 
        Name: "minecraft:oak_fence"
      }
    ], 
    [
      {
        Name: "minecraft:spruce_planks"
      }, 
      {
        Name: "minecraft:jungle_planks"
      }, 
      {
        Properties: {
          axis: "x"
        }, 
        Name: "minecraft:jungle_log"
      }, 
      {
        Properties: {
          facing: "south", 
          type: "single"
        }, 
        Name: "minecraft:chest"
      }, 
      {
        Properties: {
          mode: "data"
        }, 
        Name: "minecraft:structure_block"
      }, 
      {
        Properties: {
          facing: "north", 
          type: "single"
        }, 
        Name: "minecraft:chest"
      }, 
      {
        Properties: {
          half: "top", 
          shape: "outer_right", 
          facing: "south"
        }, 
        Name: "minecraft:spruce_stairs"
      }, 
      {
        Properties: {
          half: "bottom", 
          shape: "outer_right", 
          facing: "north"
        }, 
        Name: "minecraft:spruce_stairs"
      }, 
      {
        Properties: {
          east: "false", 
          south: "false", 
          north: "false", 
          west: "false"
        }, 
        Name: "minecraft:spruce_fence"
      }, 
      {
        Properties: {
          half: "bottom", 
          shape: "outer_right", 
          facing: "south"
        }, 
        Name: "minecraft:jungle_stairs"
      }, 
      {
        Properties: {
          half: "top", 
          shape: "outer_right", 
          facing: "south"
        }, 
        Name: "minecraft:jungle_stairs"
      }, 
      {
        Properties: {
          half: "top", 
          shape: "outer_right", 
          facing: "west"
        }, 
        Name: "minecraft:jungle_stairs"
      }, 
      {
        Properties: {
          half: "bottom", 
          shape: "outer_right", 
          facing: "west"
        }, 
        Name: "minecraft:jungle_stairs"
      }, 
      {
        Properties: {
          half: "top", 
          shape: "outer_right", 
          facing: "north"
        }, 
        Name: "minecraft:spruce_stairs"
      }, 
      {
        Properties: {
          half: "bottom", 
          shape: "outer_right", 
          facing: "north"
        }, 
        Name: "minecraft:jungle_stairs"
      }, 
      {
        Properties: {
          half: "top", 
          shape: "outer_right", 
          facing: "north"
        }, 
        Name: "minecraft:jungle_stairs"
      }, 
      {
        Properties: {
          half: "bottom", 
          powered: "false", 
          facing: "east", 
          open: "true"
        }, 
        Name: "minecraft:jungle_trapdoor"
      }, 
      {
        Properties: {
          half: "top", 
          powered: "false", 
          facing: "east", 
          open: "true"
        }, 
        Name: "minecraft:jungle_trapdoor"
      }, 
      {
        Properties: {
          half: "bottom", 
          shape: "outer_right", 
          facing: "west"
        }, 
        Name: "minecraft:spruce_stairs"
      }, 
      {
        Properties: {
          half: "bottom", 
          shape: "outer_right", 
          facing: "east"
        }, 
        Name: "minecraft:jungle_stairs"
      }, 
      {
        Properties: {
          half: "top", 
          shape: "outer_right", 
          facing: "west"
        }, 
        Name: "minecraft:spruce_stairs"
      }, 
      {
        Properties: {
          half: "top", 
          shape: "outer_right", 
          facing: "east"
        }, 
        Name: "minecraft:jungle_stairs"
      }, 
      {
        Properties: {
          half: "bottom", 
          shape: "outer_right", 
          facing: "south"
        }, 
        Name: "minecraft:spruce_stairs"
      }, 
      {
        Properties: {
          east: "false", 
          south: "false", 
          north: "false", 
          west: "false"
        }, 
        Name: "minecraft:jungle_fence"
      }
    ], 
    [
      {
        Name: "minecraft:jungle_planks"
      }, 
      {
        Name: "minecraft:dark_oak_planks"
      }, 
      {
        Properties: {
          axis: "x"
        }, 
        Name: "minecraft:dark_oak_log"
      }, 
      {
        Properties: {
          facing: "south", 
          type: "single"
        }, 
        Name: "minecraft:chest"
      }, 
      {
        Properties: {
          mode: "data"
        }, 
        Name: "minecraft:structure_block"
      }, 
      {
        Properties: {
          facing: "north", 
          type: "single"
        }, 
        Name: "minecraft:chest"
      }, 
      {
        Properties: {
          half: "top", 
          shape: "outer_right", 
          facing: "south"
        }, 
        Name: "minecraft:jungle_stairs"
      }, 
      {
        Properties: {
          half: "bottom", 
          shape: "outer_right", 
          facing: "north"
        }, 
        Name: "minecraft:jungle_stairs"
      }, 
      {
        Properties: {
          east: "false", 
          south: "false", 
          north: "false", 
          west: "false"
        }, 
        Name: "minecraft:jungle_fence"
      }, 
      {
        Properties: {
          half: "bottom", 
          shape: "outer_right", 
          facing: "south"
        }, 
        Name: "minecraft:dark_oak_stairs"
      }, 
      {
        Properties: {
          half: "top", 
          shape: "outer_right", 
          facing: "south"
        }, 
        Name: "minecraft:dark_oak_stairs"
      }, 
      {
        Properties: {
          half: "top", 
          shape: "outer_right", 
          facing: "west"
        }, 
        Name: "minecraft:dark_oak_stairs"
      }, 
      {
        Properties: {
          half: "bottom", 
          shape: "outer_right", 
          facing: "west"
        }, 
        Name: "minecraft:dark_oak_stairs"
      }, 
      {
        Properties: {
          half: "top", 
          shape: "outer_right", 
          facing: "north"
        }, 
        Name: "minecraft:jungle_stairs"
      }, 
      {
        Properties: {
          half: "bottom", 
          shape: "outer_right", 
          facing: "north"
        }, 
        Name: "minecraft:dark_oak_stairs"
      }, 
      {
        Properties: {
          half: "top", 
          shape: "outer_right", 
          facing: "north"
        }, 
        Name: "minecraft:dark_oak_stairs"
      }, 
      {
        Properties: {
          half: "bottom", 
          powered: "false", 
          facing: "east", 
          open: "true"
        }, 
        Name: "minecraft:dark_oak_trapdoor"
      }, 
      {
        Properties: {
          half: "top", 
          powered: "false", 
          facing: "east", 
          open: "true"
        }, 
        Name: "minecraft:dark_oak_trapdoor"
      }, 
      {
        Properties: {
          half: "bottom", 
          shape: "outer_right", 
          facing: "west"
        }, 
        Name: "minecraft:jungle_stairs"
      }, 
      {
        Properties: {
          half: "bottom", 
          shape: "outer_right", 
          facing: "east"
        }, 
        Name: "minecraft:dark_oak_stairs"
      }, 
      {
        Properties: {
          half: "top", 
          shape: "outer_right", 
          facing: "west"
        }, 
        Name: "minecraft:jungle_stairs"
      }, 
      {
        Properties: {
          half: "top", 
          shape: "outer_right", 
          facing: "east"
        }, 
        Name: "minecraft:dark_oak_stairs"
      }, 
      {
        Properties: {
          half: "bottom", 
          shape: "outer_right", 
          facing: "south"
        }, 
        Name: "minecraft:jungle_stairs"
      }, 
      {
        Properties: {
          east: "false", 
          south: "false", 
          north: "false", 
          west: "false"
        }, 
        Name: "minecraft:dark_oak_fence"
      }
    ], 
    [
      {
        Name: "minecraft:spruce_planks"
      }, 
      {
        Name: "minecraft:dark_oak_planks"
      }, 
      {
        Properties: {
          axis: "x"
        }, 
        Name: "minecraft:dark_oak_log"
      }, 
      {
        Properties: {
          facing: "south", 
          type: "single"
        }, 
        Name: "minecraft:chest"
      }, 
      {
        Properties: {
          mode: "data"
        }, 
        Name: "minecraft:structure_block"
      }, 
      {
        Properties: {
          facing: "north", 
          type: "single"
        }, 
        Name: "minecraft:chest"
      }, 
      {
        Properties: {
          half: "top", 
          shape: "outer_right", 
          facing: "south"
        }, 
        Name: "minecraft:spruce_stairs"
      }, 
      {
        Properties: {
          half: "bottom", 
          shape: "outer_right", 
          facing: "north"
        }, 
        Name: "minecraft:spruce_stairs"
      }, 
      {
        Properties: {
          east: "false", 
          south: "false", 
          north: "false", 
          west: "false"
        }, 
        Name: "minecraft:spruce_fence"
      }, 
      {
        Properties: {
          half: "bottom", 
          shape: "outer_right", 
          facing: "south"
        }, 
        Name: "minecraft:dark_oak_stairs"
      }, 
      {
        Properties: {
          half: "top", 
          shape: "outer_right", 
          facing: "south"
        }, 
        Name: "minecraft:dark_oak_stairs"
      }, 
      {
        Properties: {
          half: "top", 
          shape: "outer_right", 
          facing: "west"
        }, 
        Name: "minecraft:dark_oak_stairs"
      }, 
      {
        Properties: {
          half: "bottom", 
          shape: "outer_right", 
          facing: "west"
        }, 
        Name: "minecraft:dark_oak_stairs"
      }, 
      {
        Properties: {
          half: "top", 
          shape: "outer_right", 
          facing: "north"
        }, 
        Name: "minecraft:spruce_stairs"
      }, 
      {
        Properties: {
          half: "bottom", 
          shape: "outer_right", 
          facing: "north"
        }, 
        Name: "minecraft:dark_oak_stairs"
      }, 
      {
        Properties: {
          half: "top", 
          shape: "outer_right", 
          facing: "north"
        }, 
        Name: "minecraft:dark_oak_stairs"
      }, 
      {
        Properties: {
          half: "bottom", 
          powered: "false", 
          facing: "east", 
          open: "true"
        }, 
        Name: "minecraft:dark_oak_trapdoor"
      }, 
      {
        Properties: {
          half: "top", 
          powered: "false", 
          facing: "east", 
          open: "true"
        }, 
        Name: "minecraft:dark_oak_trapdoor"
      }, 
      {
        Properties: {
          half: "bottom", 
          shape: "outer_right", 
          facing: "west"
        }, 
        Name: "minecraft:spruce_stairs"
      }, 
      {
        Properties: {
          half: "bottom", 
          shape: "outer_right", 
          facing: "east"
        }, 
        Name: "minecraft:dark_oak_stairs"
      }, 
      {
        Properties: {
          half: "top", 
          shape: "outer_right", 
          facing: "west"
        }, 
        Name: "minecraft:spruce_stairs"
      }, 
      {
        Properties: {
          half: "top", 
          shape: "outer_right", 
          facing: "east"
        }, 
        Name: "minecraft:dark_oak_stairs"
      }, 
      {
        Properties: {
          half: "bottom", 
          shape: "outer_right", 
          facing: "south"
        }, 
        Name: "minecraft:spruce_stairs"
      }, 
      {
        Properties: {
          east: "false", 
          south: "false", 
          north: "false", 
          west: "false"
        }, 
        Name: "minecraft:dark_oak_fence"
      }
    ], 
    [
      {
        Name: "minecraft:oak_planks"
      }, 
      {
        Name: "minecraft:spruce_planks"
      }, 
      {
        Properties: {
          axis: "x"
        }, 
        Name: "minecraft:spruce_log"
      }, 
      {
        Properties: {
          facing: "south", 
          type: "single"
        }, 
        Name: "minecraft:chest"
      }, 
      {
        Properties: {
          mode: "data"
        }, 
        Name: "minecraft:structure_block"
      }, 
      {
        Properties: {
          facing: "north", 
          type: "single"
        }, 
        Name: "minecraft:chest"
      }, 
      {
        Properties: {
          half: "top", 
          shape: "outer_right", 
          facing: "south"
        }, 
        Name: "minecraft:oak_stairs"
      }, 
      {
        Properties: {
          half: "bottom", 
          shape: "outer_right", 
          facing: "north"
        }, 
        Name: "minecraft:oak_stairs"
      }, 
      {
        Properties: {
          east: "false", 
          south: "false", 
          north: "false", 
          west: "false"
        }, 
        Name: "minecraft:oak_fence"
      }, 
      {
        Properties: {
          half: "bottom", 
          shape: "outer_right", 
          facing: "south"
        }, 
        Name: "minecraft:spruce_stairs"
      }, 
      {
        Properties: {
          half: "top", 
          shape: "outer_right", 
          facing: "south"
        }, 
        Name: "minecraft:spruce_stairs"
      }, 
      {
        Properties: {
          half: "top", 
          shape: "outer_right", 
          facing: "west"
        }, 
        Name: "minecraft:spruce_stairs"
      }, 
      {
        Properties: {
          half: "bottom", 
          shape: "outer_right", 
          facing: "west"
        }, 
        Name: "minecraft:spruce_stairs"
      }, 
      {
        Properties: {
          half: "top", 
          shape: "outer_right", 
          facing: "north"
        }, 
        Name: "minecraft:oak_stairs"
      }, 
      {
        Properties: {
          half: "bottom", 
          shape: "outer_right", 
          facing: "north"
        }, 
        Name: "minecraft:spruce_stairs"
      }, 
      {
        Properties: {
          half: "top", 
          shape: "outer_right", 
          facing: "north"
        }, 
        Name: "minecraft:spruce_stairs"
      }, 
      {
        Properties: {
          half: "bottom", 
          powered: "false", 
          facing: "east", 
          open: "true"
        }, 
        Name: "minecraft:spruce_trapdoor"
      }, 
      {
        Properties: {
          half: "top", 
          powered: "false", 
          facing: "east", 
          open: "true"
        }, 
        Name: "minecraft:spruce_trapdoor"
      }, 
      {
        Properties: {
          half: "bottom", 
          shape: "outer_right", 
          facing: "west"
        }, 
        Name: "minecraft:oak_stairs"
      }, 
      {
        Properties: {
          half: "bottom", 
          shape: "outer_right", 
          facing: "east"
        }, 
        Name: "minecraft:spruce_stairs"
      }, 
      {
        Properties: {
          half: "top", 
          shape: "outer_right", 
          facing: "west"
        }, 
        Name: "minecraft:oak_stairs"
      }, 
      {
        Properties: {
          half: "top", 
          shape: "outer_right", 
          facing: "east"
        }, 
        Name: "minecraft:spruce_stairs"
      }, 
      {
        Properties: {
          half: "bottom", 
          shape: "outer_right", 
          facing: "south"
        }, 
        Name: "minecraft:oak_stairs"
      }, 
      {
        Properties: {
          east: "false", 
          south: "false", 
          north: "false", 
          west: "false"
        }, 
        Name: "minecraft:spruce_fence"
      }
    ], 
    [
      {
        Name: "minecraft:jungle_planks"
      }, 
      {
        Name: "minecraft:spruce_planks"
      }, 
      {
        Properties: {
          axis: "x"
        }, 
        Name: "minecraft:spruce_log"
      }, 
      {
        Properties: {
          facing: "south", 
          type: "single"
        }, 
        Name: "minecraft:chest"
      }, 
      {
        Properties: {
          mode: "data"
        }, 
        Name: "minecraft:structure_block"
      }, 
      {
        Properties: {
          facing: "north", 
          type: "single"
        }, 
        Name: "minecraft:chest"
      }, 
      {
        Properties: {
          half: "top", 
          shape: "outer_right", 
          facing: "south"
        }, 
        Name: "minecraft:jungle_stairs"
      }, 
      {
        Properties: {
          half: "bottom", 
          shape: "outer_right", 
          facing: "north"
        }, 
        Name: "minecraft:jungle_stairs"
      }, 
      {
        Properties: {
          east: "false", 
          south: "false", 
          north: "false", 
          west: "false"
        }, 
        Name: "minecraft:jungle_fence"
      }, 
      {
        Properties: {
          half: "bottom", 
          shape: "outer_right", 
          facing: "south"
        }, 
        Name: "minecraft:spruce_stairs"
      }, 
      {
        Properties: {
          half: "top", 
          shape: "outer_right", 
          facing: "south"
        }, 
        Name: "minecraft:spruce_stairs"
      }, 
      {
        Properties: {
          half: "top", 
          shape: "outer_right", 
          facing: "west"
        }, 
        Name: "minecraft:spruce_stairs"
      }, 
      {
        Properties: {
          half: "bottom", 
          shape: "outer_right", 
          facing: "west"
        }, 
        Name: "minecraft:spruce_stairs"
      }, 
      {
        Properties: {
          half: "top", 
          shape: "outer_right", 
          facing: "north"
        }, 
        Name: "minecraft:jungle_stairs"
      }, 
      {
        Properties: {
          half: "bottom", 
          shape: "outer_right", 
          facing: "north"
        }, 
        Name: "minecraft:spruce_stairs"
      }, 
      {
        Properties: {
          half: "top", 
          shape: "outer_right", 
          facing: "north"
        }, 
        Name: "minecraft:spruce_stairs"
      }, 
      {
        Properties: {
          half: "bottom", 
          powered: "false", 
          facing: "east", 
          open: "true"
        }, 
        Name: "minecraft:spruce_trapdoor"
      }, 
      {
        Properties: {
          half: "top", 
          powered: "false", 
          facing: "east", 
          open: "true"
        }, 
        Name: "minecraft:spruce_trapdoor"
      }, 
      {
        Properties: {
          half: "bottom", 
          shape: "outer_right", 
          facing: "west"
        }, 
        Name: "minecraft:jungle_stairs"
      }, 
      {
        Properties: {
          half: "bottom", 
          shape: "outer_right", 
          facing: "east"
        }, 
        Name: "minecraft:spruce_stairs"
      }, 
      {
        Properties: {
          half: "top", 
          shape: "outer_right", 
          facing: "west"
        }, 
        Name: "minecraft:jungle_stairs"
      }, 
      {
        Properties: {
          half: "top", 
          shape: "outer_right", 
          facing: "east"
        }, 
        Name: "minecraft:spruce_stairs"
      }, 
      {
        Properties: {
          half: "bottom", 
          shape: "outer_right", 
          facing: "south"
        }, 
        Name: "minecraft:jungle_stairs"
      }, 
      {
        Properties: {
          east: "false", 
          south: "false", 
          north: "false", 
          west: "false"
        }, 
        Name: "minecraft:spruce_fence"
      }
    ], 
    [
      {
        Name: "minecraft:dark_oak_planks"
      }, 
      {
        Name: "minecraft:spruce_planks"
      }, 
      {
        Properties: {
          axis: "x"
        }, 
        Name: "minecraft:spruce_log"
      }, 
      {
        Properties: {
          facing: "south", 
          type: "single"
        }, 
        Name: "minecraft:chest"
      }, 
      {
        Properties: {
          mode: "data"
        }, 
        Name: "minecraft:structure_block"
      }, 
      {
        Properties: {
          facing: "north", 
          type: "single"
        }, 
        Name: "minecraft:chest"
      }, 
      {
        Properties: {
          half: "top", 
          shape: "outer_right", 
          facing: "south"
        }, 
        Name: "minecraft:dark_oak_stairs"
      }, 
      {
        Properties: {
          half: "bottom", 
          shape: "outer_right", 
          facing: "north"
        }, 
        Name: "minecraft:dark_oak_stairs"
      }, 
      {
        Properties: {
          east: "false", 
          south: "false", 
          north: "false", 
          west: "false"
        }, 
        Name: "minecraft:dark_oak_fence"
      }, 
      {
        Properties: {
          half: "bottom", 
          shape: "outer_right", 
          facing: "south"
        }, 
        Name: "minecraft:spruce_stairs"
      }, 
      {
        Properties: {
          half: "top", 
          shape: "outer_right", 
          facing: "south"
        }, 
        Name: "minecraft:spruce_stairs"
      }, 
      {
        Properties: {
          half: "top", 
          shape: "outer_right", 
          facing: "west"
        }, 
        Name: "minecraft:spruce_stairs"
      }, 
      {
        Properties: {
          half: "bottom", 
          shape: "outer_right", 
          facing: "west"
        }, 
        Name: "minecraft:spruce_stairs"
      }, 
      {
        Properties: {
          half: "top", 
          shape: "outer_right", 
          facing: "north"
        }, 
        Name: "minecraft:dark_oak_stairs"
      }, 
      {
        Properties: {
          half: "bottom", 
          shape: "outer_right", 
          facing: "north"
        }, 
        Name: "minecraft:spruce_stairs"
      }, 
      {
        Properties: {
          half: "top", 
          shape: "outer_right", 
          facing: "north"
        }, 
        Name: "minecraft:spruce_stairs"
      }, 
      {
        Properties: {
          half: "bottom", 
          powered: "false", 
          facing: "east", 
          open: "true"
        }, 
        Name: "minecraft:spruce_trapdoor"
      }, 
      {
        Properties: {
          half: "top", 
          powered: "false", 
          facing: "east", 
          open: "true"
        }, 
        Name: "minecraft:spruce_trapdoor"
      }, 
      {
        Properties: {
          half: "bottom", 
          shape: "outer_right", 
          facing: "west"
        }, 
        Name: "minecraft:dark_oak_stairs"
      }, 
      {
        Properties: {
          half: "bottom", 
          shape: "outer_right", 
          facing: "east"
        }, 
        Name: "minecraft:spruce_stairs"
      }, 
      {
        Properties: {
          half: "top", 
          shape: "outer_right", 
          facing: "west"
        }, 
        Name: "minecraft:dark_oak_stairs"
      }, 
      {
        Properties: {
          half: "top", 
          shape: "outer_right", 
          facing: "east"
        }, 
        Name: "minecraft:spruce_stairs"
      }, 
      {
        Properties: {
          half: "bottom", 
          shape: "outer_right", 
          facing: "south"
        }, 
        Name: "minecraft:dark_oak_stairs"
      }, 
      {
        Properties: {
          east: "false", 
          south: "false", 
          north: "false", 
          west: "false"
        }, 
        Name: "minecraft:spruce_fence"
      }
    ], 
    [
      {
        Name: "minecraft:birch_planks"
      }, 
      {
        Name: "minecraft:oak_planks"
      }, 
      {
        Properties: {
          axis: "x"
        }, 
        Name: "minecraft:oak_log"
      }, 
      {
        Properties: {
          facing: "south", 
          type: "single"
        }, 
        Name: "minecraft:chest"
      }, 
      {
        Properties: {
          mode: "data"
        }, 
        Name: "minecraft:structure_block"
      }, 
      {
        Properties: {
          facing: "north", 
          type: "single"
        }, 
        Name: "minecraft:chest"
      }, 
      {
        Properties: {
          half: "top", 
          shape: "outer_right", 
          facing: "south"
        }, 
        Name: "minecraft:birch_stairs"
      }, 
      {
        Properties: {
          half: "bottom", 
          shape: "outer_right", 
          facing: "north"
        }, 
        Name: "minecraft:birch_stairs"
      }, 
      {
        Properties: {
          east: "false", 
          south: "false", 
          north: "false", 
          west: "false"
        }, 
        Name: "minecraft:birch_fence"
      }, 
      {
        Properties: {
          half: "bottom", 
          shape: "outer_right", 
          facing: "south"
        }, 
        Name: "minecraft:oak_stairs"
      }, 
      {
        Properties: {
          half: "top", 
          shape: "outer_right", 
          facing: "south"
        }, 
        Name: "minecraft:oak_stairs"
      }, 
      {
        Properties: {
          half: "top", 
          shape: "outer_right", 
          facing: "west"
        }, 
        Name: "minecraft:oak_stairs"
      }, 
      {
        Properties: {
          half: "bottom", 
          shape: "outer_right", 
          facing: "west"
        }, 
        Name: "minecraft:oak_stairs"
      }, 
      {
        Properties: {
          half: "top", 
          shape: "outer_right", 
          facing: "north"
        }, 
        Name: "minecraft:birch_stairs"
      }, 
      {
        Properties: {
          half: "bottom", 
          shape: "outer_right", 
          facing: "north"
        }, 
        Name: "minecraft:oak_stairs"
      }, 
      {
        Properties: {
          half: "top", 
          shape: "outer_right", 
          facing: "north"
        }, 
        Name: "minecraft:oak_stairs"
      }, 
      {
        Properties: {
          half: "bottom", 
          powered: "false", 
          facing: "east", 
          open: "true"
        }, 
        Name: "minecraft:oak_trapdoor"
      }, 
      {
        Properties: {
          half: "top", 
          powered: "false", 
          facing: "east", 
          open: "true"
        }, 
        Name: "minecraft:oak_trapdoor"
      }, 
      {
        Properties: {
          half: "bottom", 
          shape: "outer_right", 
          facing: "west"
        }, 
        Name: "minecraft:birch_stairs"
      }, 
      {
        Properties: {
          half: "bottom", 
          shape: "outer_right", 
          facing: "east"
        }, 
        Name: "minecraft:oak_stairs"
      }, 
      {
        Properties: {
          half: "top", 
          shape: "outer_right", 
          facing: "west"
        }, 
        Name: "minecraft:birch_stairs"
      }, 
      {
        Properties: {
          half: "top", 
          shape: "outer_right", 
          facing: "east"
        }, 
        Name: "minecraft:oak_stairs"
      }, 
      {
        Properties: {
          half: "bottom", 
          shape: "outer_right", 
          facing: "south"
        }, 
        Name: "minecraft:birch_stairs"
      }, 
      {
        Properties: {
          east: "false", 
          south: "false", 
          north: "false", 
          west: "false"
        }, 
        Name: "minecraft:oak_fence"
      }
    ]
  ]
}
