{
  size: [9, 9, 17], 
  entities: [], 
  blocks: [
    {
      pos: [3, 0, 7], 
      state: 0
    }, 
    {
      pos: [2, 0, 8], 
      state: 0
    }, 
    {
      pos: [3, 0, 8], 
      state: 0
    }, 
    {
      pos: [2, 0, 9], 
      state: 0
    }, 
    {
      pos: [3, 0, 9], 
      state: 0
    }, 
    {
      pos: [1, 0, 10], 
      state: 0
    }, 
    {
      pos: [2, 0, 10], 
      state: 0
    }, 
    {
      pos: [1, 0, 11], 
      state: 0
    }, 
    {
      pos: [1, 0, 12], 
      state: 0
    }, 
    {
      pos: [2, 0, 12], 
      state: 0
    }, 
    {
      pos: [4, 0, 0], 
      state: 1
    }, 
    {
      pos: [4, 0, 1], 
      state: 1
    }, 
    {
      pos: [4, 0, 2], 
      state: 1
    }, 
    {
      pos: [4, 0, 3], 
      state: 1
    }, 
    {
      pos: [4, 0, 4], 
      state: 1
    }, 
    {
      pos: [4, 0, 5], 
      state: 1
    }, 
    {
      pos: [4, 0, 6], 
      state: 1
    }, 
    {
      pos: [2, 0, 7], 
      state: 2
    }, 
    {
      pos: [4, 0, 7], 
      state: 1
    }, 
    {
      pos: [4, 0, 8], 
      state: 1
    }, 
    {
      pos: [1, 0, 9], 
      state: 2
    }, 
    {
      pos: [4, 0, 9], 
      state: 1
    }, 
    {
      pos: [0, 0, 10], 
      state: 3
    }, 
    {
      pos: [3, 0, 10], 
      state: 1
    }, 
    {
      pos: [0, 0, 11], 
      state: 3
    }, 
    {
      pos: [3, 0, 11], 
      state: 1
    }, 
    {
      pos: [0, 0, 12], 
      state: 3
    }, 
    {
      pos: [3, 0, 12], 
      state: 4
    }, 
    {
      pos: [4, 1, 2], 
      state: 5
    }, 
    {
      pos: [5, 1, 2], 
      state: 0
    }, 
    {
      pos: [4, 1, 3], 
      state: 5
    }, 
    {
      pos: [5, 1, 3], 
      state: 0
    }, 
    {
      pos: [4, 1, 4], 
      state: 5
    }, 
    {
      pos: [4, 1, 5], 
      state: 5
    }, 
    {
      pos: [5, 1, 5], 
      state: 0
    }, 
    {
      pos: [4, 1, 6], 
      state: 5
    }, 
    {
      pos: [5, 1, 6], 
      state: 0
    }, 
    {
      pos: [4, 1, 7], 
      state: 5
    }, 
    {
      pos: [3, 1, 8], 
      state: 5
    }, 
    {
      pos: [4, 1, 8], 
      state: 0
    }, 
    {
      pos: [5, 1, 8], 
      state: 0
    }, 
    {
      pos: [2, 1, 9], 
      state: 5
    }, 
    {
      pos: [3, 1, 9], 
      state: 0
    }, 
    {
      pos: [4, 1, 9], 
      state: 0
    }, 
    {
      pos: [5, 1, 9], 
      state: 0
    }, 
    {
      pos: [0, 1, 10], 
      state: 0
    }, 
    {
      pos: [1, 1, 10], 
      state: 0
    }, 
    {
      pos: [3, 1, 10], 
      state: 0
    }, 
    {
      pos: [4, 1, 10], 
      state: 0
    }, 
    {
      pos: [1, 1, 11], 
      state: 5
    }, 
    {
      pos: [4, 1, 11], 
      state: 0
    }, 
    {
      pos: [1, 1, 12], 
      state: 5
    }, 
    {
      pos: [3, 1, 12], 
      state: 0
    }, 
    {
      pos: [4, 1, 12], 
      state: 0
    }, 
    {
      pos: [1, 1, 13], 
      state: 0
    }, 
    {
      pos: [2, 1, 13], 
      state: 0
    }, 
    {
      pos: [3, 1, 13], 
      state: 0
    }, 
    {
      pos: [4, 1, 13], 
      state: 0
    }, 
    {
      pos: [0, 1, 14], 
      state: 0
    }, 
    {
      pos: [1, 1, 14], 
      state: 0
    }, 
    {
      pos: [2, 1, 14], 
      state: 0
    }, 
    {
      pos: [6, 1, 1], 
      state: 1
    }, 
    {
      pos: [6, 1, 2], 
      state: 1
    }, 
    {
      pos: [6, 1, 3], 
      state: 1
    }, 
    {
      pos: [6, 1, 4], 
      state: 1
    }, 
    {
      pos: [6, 1, 5], 
      state: 1
    }, 
    {
      pos: [6, 1, 6], 
      state: 1
    }, 
    {
      pos: [3, 1, 7], 
      state: 6
    }, 
    {
      pos: [6, 1, 7], 
      state: 1
    }, 
    {
      pos: [2, 1, 8], 
      state: 6
    }, 
    {
      pos: [6, 1, 8], 
      state: 1
    }, 
    {
      pos: [6, 1, 9], 
      state: 1
    }, 
    {
      pos: [2, 1, 10], 
      state: 7
    }, 
    {
      pos: [5, 1, 10], 
      state: 1
    }, 
    {
      pos: [3, 1, 11], 
      state: 8
    }, 
    {
      pos: [5, 1, 11], 
      state: 1
    }, 
    {
      pos: [0, 1, 12], 
      state: 9
    }, 
    {
      pos: [2, 1, 12], 
      state: 7
    }, 
    {
      pos: [5, 1, 12], 
      state: 1
    }, 
    {
      pos: [0, 1, 13], 
      state: 9
    }, 
    {
      pos: [5, 1, 13], 
      state: 1
    }, 
    {
      pos: [3, 1, 14], 
      state: 4
    }, 
    {
      pos: [6, 2, 2], 
      state: 0
    }, 
    {
      pos: [4, 2, 3], 
      state: 5
    }, 
    {
      pos: [6, 2, 3], 
      state: 0
    }, 
    {
      pos: [4, 2, 4], 
      state: 5
    }, 
    {
      pos: [4, 2, 5], 
      state: 5
    }, 
    {
      pos: [5, 2, 5], 
      state: 0
    }, 
    {
      pos: [6, 2, 5], 
      state: 0
    }, 
    {
      pos: [4, 2, 6], 
      state: 5
    }, 
    {
      pos: [5, 2, 6], 
      state: 0
    }, 
    {
      pos: [6, 2, 6], 
      state: 0
    }, 
    {
      pos: [4, 2, 7], 
      state: 5
    }, 
    {
      pos: [2, 2, 8], 
      state: 0
    }, 
    {
      pos: [3, 2, 8], 
      state: 0
    }, 
    {
      pos: [4, 2, 8], 
      state: 5
    }, 
    {
      pos: [5, 2, 8], 
      state: 0
    }, 
    {
      pos: [6, 2, 8], 
      state: 0
    }, 
    {
      pos: [2, 2, 9], 
      state: 5
    }, 
    {
      pos: [5, 2, 9], 
      state: 0
    }, 
    {
      pos: [6, 2, 9], 
      state: 0
    }, 
    {
      pos: [1, 2, 10], 
      state: 5
    }, 
    {
      pos: [5, 2, 10], 
      state: 5
    }, 
    {
      pos: [1, 2, 11], 
      state: 5
    }, 
    {
      pos: [5, 2, 11], 
      state: 5
    }, 
    {
      pos: [1, 2, 12], 
      state: 5
    }, 
    {
      pos: [5, 2, 12], 
      state: 5
    }, 
    {
      pos: [1, 2, 13], 
      state: 5
    }, 
    {
      pos: [5, 2, 13], 
      state: 5
    }, 
    {
      pos: [1, 2, 14], 
      state: 5
    }, 
    {
      pos: [3, 2, 14], 
      state: 0
    }, 
    {
      pos: [0, 2, 15], 
      state: 0
    }, 
    {
      pos: [1, 2, 15], 
      state: 0
    }, 
    {
      nbt: {
        Items: [], 
        id: "minecraft:chest", 
        Lock: ""
      }, 
      pos: [3, 2, 13], 
      state: 10
    }, 
    {
      pos: [7, 2, 0], 
      state: 1
    }, 
    {
      pos: [6, 2, 1], 
      state: 8
    }, 
    {
      pos: [7, 2, 1], 
      state: 1
    }, 
    {
      pos: [7, 2, 2], 
      state: 1
    }, 
    {
      pos: [7, 2, 3], 
      state: 1
    }, 
    {
      pos: [6, 2, 4], 
      state: 8
    }, 
    {
      pos: [7, 2, 4], 
      state: 1
    }, 
    {
      pos: [7, 2, 5], 
      state: 1
    }, 
    {
      pos: [7, 2, 6], 
      state: 1
    }, 
    {
      pos: [6, 2, 7], 
      state: 8
    }, 
    {
      pos: [7, 2, 7], 
      state: 1
    }, 
    {
      pos: [7, 2, 8], 
      state: 1
    }, 
    {
      pos: [4, 2, 9], 
      state: 8
    }, 
    {
      pos: [7, 2, 9], 
      state: 1
    }, 
    {
      pos: [6, 2, 10], 
      state: 1
    }, 
    {
      pos: [6, 2, 11], 
      state: 1
    }, 
    {
      pos: [6, 2, 12], 
      state: 1
    }, 
    {
      pos: [4, 2, 13], 
      state: 2
    }, 
    {
      pos: [6, 2, 13], 
      state: 1
    }, 
    {
      pos: [2, 2, 14], 
      state: 7
    }, 
    {
      pos: [4, 2, 14], 
      state: 4
    }, 
    {
      pos: [5, 2, 14], 
      state: 4
    }, 
    {
      pos: [2, 2, 15], 
      state: 4
    }, 
    {
      pos: [7, 3, 3], 
      state: 0
    }, 
    {
      pos: [7, 3, 4], 
      state: 0
    }, 
    {
      pos: [4, 3, 5], 
      state: 5
    }, 
    {
      pos: [7, 3, 5], 
      state: 0
    }, 
    {
      pos: [4, 3, 6], 
      state: 5
    }, 
    {
      pos: [7, 3, 6], 
      state: 0
    }, 
    {
      pos: [4, 3, 7], 
      state: 5
    }, 
    {
      pos: [7, 3, 7], 
      state: 0
    }, 
    {
      pos: [3, 3, 8], 
      state: 0
    }, 
    {
      pos: [4, 3, 8], 
      state: 5
    }, 
    {
      pos: [7, 3, 8], 
      state: 0
    }, 
    {
      pos: [2, 3, 9], 
      state: 0
    }, 
    {
      pos: [5, 3, 9], 
      state: 5
    }, 
    {
      pos: [6, 3, 9], 
      state: 0
    }, 
    {
      pos: [7, 3, 9], 
      state: 0
    }, 
    {
      pos: [0, 3, 10], 
      state: 0
    }, 
    {
      pos: [1, 3, 10], 
      state: 5
    }, 
    {
      pos: [5, 3, 10], 
      state: 5
    }, 
    {
      pos: [6, 3, 10], 
      state: 0
    }, 
    {
      pos: [1, 3, 11], 
      state: 5
    }, 
    {
      pos: [5, 3, 11], 
      state: 5
    }, 
    {
      pos: [6, 3, 11], 
      state: 0
    }, 
    {
      pos: [1, 3, 12], 
      state: 5
    }, 
    {
      pos: [5, 3, 12], 
      state: 5
    }, 
    {
      pos: [6, 3, 12], 
      state: 0
    }, 
    {
      pos: [1, 3, 13], 
      state: 5
    }, 
    {
      pos: [5, 3, 13], 
      state: 5
    }, 
    {
      pos: [6, 3, 13], 
      state: 0
    }, 
    {
      pos: [1, 3, 14], 
      state: 5
    }, 
    {
      pos: [4, 3, 14], 
      state: 0
    }, 
    {
      pos: [5, 3, 14], 
      state: 0
    }, 
    {
      pos: [1, 3, 15], 
      state: 5
    }, 
    {
      pos: [2, 3, 15], 
      state: 0
    }, 
    {
      nbt: {
        Items: [], 
        id: "minecraft:chest", 
        Lock: ""
      }, 
      pos: [6, 3, 8], 
      state: 10
    }, 
    {
      nbt: {
        metadata: "treasure_chest", 
        mirror: "NONE", 
        ignoreEntities: 1b, 
        powered: 0b, 
        seed: 0L, 
        author: "CascadianBacon", 
        rotation: "NONE", 
        mode: "DATA", 
        posX: 0, 
        posY: 1, 
        sizeX: 0, 
        integrity: 1.0f, 
        posZ: 0, 
        showair: 0b, 
        name: "", 
        id: "minecraft:structure_block", 
        sizeY: 0, 
        showboundingbox: 1b, 
        sizeZ: 0
      }, 
      pos: [3, 3, 13], 
      state: 11
    }, 
    {
      pos: [4, 3, 3], 
      state: 12
    }, 
    {
      pos: [4, 3, 4], 
      state: 12
    }, 
    {
      pos: [7, 3, 10], 
      state: 1
    }, 
    {
      pos: [7, 3, 11], 
      state: 1
    }, 
    {
      pos: [7, 3, 12], 
      state: 1
    }, 
    {
      pos: [3, 3, 14], 
      state: 2
    }, 
    {
      pos: [0, 3, 15], 
      state: 9
    }, 
    {
      pos: [3, 3, 15], 
      state: 4
    }, 
    {
      pos: [0, 3, 16], 
      state: 9
    }, 
    {
      pos: [1, 3, 16], 
      state: 4
    }, 
    {
      pos: [3, 4, 5], 
      state: 13
    }, 
    {
      pos: [4, 4, 5], 
      state: 13
    }, 
    {
      pos: [5, 4, 5], 
      state: 13
    }, 
    {
      pos: [6, 4, 5], 
      state: 13
    }, 
    {
      pos: [7, 4, 5], 
      state: 0
    }, 
    {
      pos: [4, 4, 6], 
      state: 5
    }, 
    {
      pos: [7, 4, 6], 
      state: 0
    }, 
    {
      pos: [8, 4, 6], 
      state: 5
    }, 
    {
      pos: [4, 4, 7], 
      state: 5
    }, 
    {
      pos: [7, 4, 7], 
      state: 0
    }, 
    {
      pos: [8, 4, 7], 
      state: 5
    }, 
    {
      pos: [4, 4, 8], 
      state: 5
    }, 
    {
      pos: [7, 4, 8], 
      state: 0
    }, 
    {
      pos: [8, 4, 8], 
      state: 5
    }, 
    {
      pos: [5, 4, 9], 
      state: 5
    }, 
    {
      pos: [6, 4, 9], 
      state: 0
    }, 
    {
      pos: [7, 4, 9], 
      state: 0
    }, 
    {
      pos: [8, 4, 9], 
      state: 5
    }, 
    {
      pos: [1, 4, 10], 
      state: 5
    }, 
    {
      pos: [5, 4, 10], 
      state: 5
    }, 
    {
      pos: [6, 4, 10], 
      state: 0
    }, 
    {
      pos: [7, 4, 10], 
      state: 5
    }, 
    {
      pos: [1, 4, 11], 
      state: 5
    }, 
    {
      pos: [5, 4, 11], 
      state: 5
    }, 
    {
      pos: [6, 4, 11], 
      state: 0
    }, 
    {
      pos: [7, 4, 11], 
      state: 5
    }, 
    {
      pos: [1, 4, 12], 
      state: 5
    }, 
    {
      pos: [5, 4, 12], 
      state: 5
    }, 
    {
      pos: [6, 4, 12], 
      state: 0
    }, 
    {
      pos: [7, 4, 12], 
      state: 5
    }, 
    {
      pos: [1, 4, 13], 
      state: 5
    }, 
    {
      pos: [5, 4, 13], 
      state: 5
    }, 
    {
      pos: [6, 4, 13], 
      state: 5
    }, 
    {
      pos: [1, 4, 14], 
      state: 5
    }, 
    {
      pos: [4, 4, 14], 
      state: 0
    }, 
    {
      pos: [1, 4, 15], 
      state: 5
    }, 
    {
      pos: [3, 4, 15], 
      state: 0
    }, 
    {
      pos: [1, 4, 16], 
      state: 0
    }, 
    {
      nbt: {
        metadata: "map_chest", 
        mirror: "NONE", 
        ignoreEntities: 1b, 
        powered: 0b, 
        seed: 0L, 
        author: "CascadianBacon", 
        rotation: "NONE", 
        mode: "DATA", 
        posX: 0, 
        posY: 1, 
        sizeX: 0, 
        integrity: 1.0f, 
        posZ: 0, 
        showair: 0b, 
        name: "", 
        id: "minecraft:structure_block", 
        sizeY: 0, 
        showboundingbox: 1b, 
        sizeZ: 0
      }, 
      pos: [6, 4, 8], 
      state: 11
    }, 
    {
      pos: [4, 4, 4], 
      state: 12
    }, 
    {
      pos: [8, 4, 10], 
      state: 14
    }, 
    {
      pos: [5, 4, 14], 
      state: 9
    }, 
    {
      pos: [4, 4, 15], 
      state: 4
    }, 
    {
      pos: [0, 4, 16], 
      state: 9
    }, 
    {
      pos: [5, 5, 5], 
      state: 0
    }, 
    {
      pos: [6, 5, 5], 
      state: 0
    }, 
    {
      pos: [4, 5, 6], 
      state: 5
    }, 
    {
      pos: [7, 5, 6], 
      state: 0
    }, 
    {
      pos: [4, 5, 7], 
      state: 5
    }, 
    {
      pos: [7, 5, 7], 
      state: 0
    }, 
    {
      pos: [3, 5, 8], 
      state: 0
    }, 
    {
      pos: [4, 5, 8], 
      state: 5
    }, 
    {
      pos: [7, 5, 8], 
      state: 0
    }, 
    {
      pos: [5, 5, 9], 
      state: 5
    }, 
    {
      pos: [6, 5, 9], 
      state: 0
    }, 
    {
      pos: [7, 5, 9], 
      state: 0
    }, 
    {
      pos: [5, 5, 10], 
      state: 5
    }, 
    {
      pos: [6, 5, 10], 
      state: 0
    }, 
    {
      pos: [1, 5, 11], 
      state: 5
    }, 
    {
      pos: [5, 5, 11], 
      state: 5
    }, 
    {
      pos: [6, 5, 11], 
      state: 0
    }, 
    {
      pos: [1, 5, 12], 
      state: 5
    }, 
    {
      pos: [5, 5, 12], 
      state: 5
    }, 
    {
      pos: [6, 5, 12], 
      state: 0
    }, 
    {
      pos: [1, 5, 13], 
      state: 5
    }, 
    {
      pos: [5, 5, 13], 
      state: 5
    }, 
    {
      pos: [6, 5, 13], 
      state: 0
    }, 
    {
      pos: [1, 5, 14], 
      state: 5
    }, 
    {
      pos: [4, 5, 14], 
      state: 0
    }, 
    {
      pos: [5, 5, 14], 
      state: 0
    }, 
    {
      pos: [1, 5, 15], 
      state: 5
    }, 
    {
      pos: [2, 5, 15], 
      state: 0
    }, 
    {
      pos: [7, 5, 10], 
      state: 15
    }, 
    {
      pos: [7, 5, 11], 
      state: 15
    }, 
    {
      pos: [7, 5, 12], 
      state: 15
    }, 
    {
      pos: [3, 5, 14], 
      state: 16
    }, 
    {
      pos: [0, 5, 15], 
      state: 9
    }, 
    {
      pos: [3, 5, 15], 
      state: 17
    }, 
    {
      pos: [0, 5, 16], 
      state: 9
    }, 
    {
      pos: [1, 5, 16], 
      state: 17
    }, 
    {
      pos: [5, 6, 6], 
      state: 0
    }, 
    {
      pos: [6, 6, 6], 
      state: 0
    }, 
    {
      pos: [4, 6, 7], 
      state: 5
    }, 
    {
      pos: [3, 6, 8], 
      state: 0
    }, 
    {
      pos: [4, 6, 8], 
      state: 5
    }, 
    {
      pos: [5, 6, 8], 
      state: 0
    }, 
    {
      pos: [6, 6, 8], 
      state: 0
    }, 
    {
      pos: [5, 6, 9], 
      state: 0
    }, 
    {
      pos: [6, 6, 9], 
      state: 0
    }, 
    {
      pos: [5, 6, 10], 
      state: 5
    }, 
    {
      pos: [1, 6, 11], 
      state: 5
    }, 
    {
      pos: [5, 6, 11], 
      state: 5
    }, 
    {
      pos: [1, 6, 12], 
      state: 5
    }, 
    {
      pos: [5, 6, 12], 
      state: 5
    }, 
    {
      pos: [1, 6, 13], 
      state: 5
    }, 
    {
      pos: [5, 6, 13], 
      state: 5
    }, 
    {
      pos: [1, 6, 14], 
      state: 5
    }, 
    {
      pos: [3, 6, 14], 
      state: 0
    }, 
    {
      pos: [0, 6, 15], 
      state: 0
    }, 
    {
      pos: [1, 6, 15], 
      state: 0
    }, 
    {
      pos: [7, 6, 6], 
      state: 15
    }, 
    {
      pos: [6, 6, 7], 
      state: 3
    }, 
    {
      pos: [7, 6, 7], 
      state: 15
    }, 
    {
      pos: [7, 6, 8], 
      state: 15
    }, 
    {
      pos: [4, 6, 9], 
      state: 3
    }, 
    {
      pos: [7, 6, 9], 
      state: 15
    }, 
    {
      pos: [6, 6, 10], 
      state: 15
    }, 
    {
      pos: [6, 6, 11], 
      state: 15
    }, 
    {
      pos: [6, 6, 12], 
      state: 15
    }, 
    {
      pos: [4, 6, 13], 
      state: 16
    }, 
    {
      pos: [6, 6, 13], 
      state: 15
    }, 
    {
      pos: [2, 6, 14], 
      state: 7
    }, 
    {
      pos: [4, 6, 14], 
      state: 17
    }, 
    {
      pos: [5, 6, 14], 
      state: 17
    }, 
    {
      pos: [2, 6, 15], 
      state: 17
    }, 
    {
      pos: [4, 7, 8], 
      state: 0
    }, 
    {
      pos: [5, 7, 8], 
      state: 0
    }, 
    {
      pos: [3, 7, 9], 
      state: 0
    }, 
    {
      pos: [4, 7, 9], 
      state: 0
    }, 
    {
      pos: [5, 7, 9], 
      state: 0
    }, 
    {
      pos: [3, 7, 10], 
      state: 0
    }, 
    {
      pos: [4, 7, 10], 
      state: 0
    }, 
    {
      pos: [1, 7, 11], 
      state: 5
    }, 
    {
      pos: [4, 7, 11], 
      state: 0
    }, 
    {
      pos: [1, 7, 12], 
      state: 5
    }, 
    {
      pos: [3, 7, 12], 
      state: 0
    }, 
    {
      pos: [4, 7, 12], 
      state: 0
    }, 
    {
      pos: [1, 7, 13], 
      state: 0
    }, 
    {
      pos: [2, 7, 13], 
      state: 0
    }, 
    {
      pos: [3, 7, 13], 
      state: 0
    }, 
    {
      pos: [4, 7, 13], 
      state: 0
    }, 
    {
      pos: [0, 7, 14], 
      state: 0
    }, 
    {
      pos: [1, 7, 14], 
      state: 0
    }, 
    {
      pos: [2, 7, 14], 
      state: 0
    }, 
    {
      pos: [6, 7, 6], 
      state: 15
    }, 
    {
      pos: [6, 7, 7], 
      state: 15
    }, 
    {
      pos: [6, 7, 8], 
      state: 15
    }, 
    {
      pos: [6, 7, 9], 
      state: 15
    }, 
    {
      pos: [2, 7, 10], 
      state: 7
    }, 
    {
      pos: [5, 7, 10], 
      state: 15
    }, 
    {
      pos: [3, 7, 11], 
      state: 3
    }, 
    {
      pos: [5, 7, 11], 
      state: 15
    }, 
    {
      pos: [0, 7, 12], 
      state: 9
    }, 
    {
      pos: [2, 7, 12], 
      state: 7
    }, 
    {
      pos: [5, 7, 12], 
      state: 15
    }, 
    {
      pos: [0, 7, 13], 
      state: 9
    }, 
    {
      pos: [5, 7, 13], 
      state: 15
    }, 
    {
      pos: [3, 7, 14], 
      state: 17
    }, 
    {
      pos: [3, 8, 9], 
      state: 0
    }, 
    {
      pos: [1, 8, 12], 
      state: 0
    }, 
    {
      pos: [2, 8, 12], 
      state: 0
    }, 
    {
      pos: [4, 8, 8], 
      state: 15
    }, 
    {
      pos: [4, 8, 9], 
      state: 15
    }, 
    {
      pos: [3, 8, 10], 
      state: 15
    }, 
    {
      pos: [0, 8, 11], 
      state: 8
    }, 
    {
      pos: [3, 8, 11], 
      state: 15
    }, 
    {
      pos: [0, 8, 12], 
      state: 8
    }, 
    {
      pos: [3, 8, 12], 
      state: 15
    }
  ], 
  palettes: [
    [
      {
        Name: "minecraft:oak_planks"
      }, 
      {
        Properties: {
          half: "top", 
          waterlogged: "false", 
          shape: "outer_right", 
          facing: "west"
        }, 
        Name: "minecraft:oak_stairs"
      }, 
      {
        Properties: {
          half: "bottom", 
          waterlogged: "false", 
          shape: "outer_right", 
          facing: "south"
        }, 
        Name: "minecraft:oak_stairs"
      }, 
      {
        Properties: {
          half: "top", 
          waterlogged: "false", 
          shape: "outer_right", 
          facing: "east"
        }, 
        Name: "minecraft:oak_stairs"
      }, 
      {
        Properties: {
          half: "top", 
          waterlogged: "false", 
          shape: "outer_right", 
          facing: "north"
        }, 
        Name: "minecraft:oak_stairs"
      }, 
      {
        Name: "minecraft:spruce_planks"
      }, 
      {
        Properties: {
          half: "bottom", 
          waterlogged: "false", 
          shape: "outer_right", 
          facing: "south"
        }, 
        Name: "minecraft:spruce_stairs"
      }, 
      {
        Properties: {
          east: "false", 
          waterlogged: "false", 
          south: "false", 
          north: "false", 
          west: "false"
        }, 
        Name: "minecraft:oak_fence"
      }, 
      {
        Properties: {
          half: "bottom", 
          waterlogged: "false", 
          shape: "outer_right", 
          facing: "east"
        }, 
        Name: "minecraft:oak_stairs"
      }, 
      {
        Properties: {
          east: "false", 
          waterlogged: "false", 
          south: "false", 
          north: "false", 
          west: "false"
        }, 
        Name: "minecraft:spruce_fence"
      }, 
      {
        Properties: {
          waterlogged: "false", 
          facing: "north", 
          type: "single"
        }, 
        Name: "minecraft:chest"
      }, 
      {
        Properties: {
          mode: "data"
        }, 
        Name: "minecraft:structure_block"
      }, 
      {
        Properties: {
          half: "bottom", 
          waterlogged: "false", 
          powered: "false", 
          facing: "east", 
          open: "true"
        }, 
        Name: "minecraft:oak_trapdoor"
      }, 
      {
        Properties: {
          axis: "x"
        }, 
        Name: "minecraft:oak_log"
      }, 
      {
        Properties: {
          half: "top", 
          waterlogged: "false", 
          shape: "outer_right", 
          facing: "north"
        }, 
        Name: "minecraft:spruce_stairs"
      }, 
      {
        Properties: {
          half: "bottom", 
          waterlogged: "false", 
          shape: "outer_right", 
          facing: "west"
        }, 
        Name: "minecraft:oak_stairs"
      }, 
      {
        Properties: {
          half: "top", 
          waterlogged: "false", 
          shape: "outer_right", 
          facing: "south"
        }, 
        Name: "minecraft:oak_stairs"
      }, 
      {
        Properties: {
          half: "bottom", 
          waterlogged: "false", 
          shape: "outer_right", 
          facing: "north"
        }, 
        Name: "minecraft:oak_stairs"
      }
    ], 
    [
      {
        Name: "minecraft:jungle_planks"
      }, 
      {
        Properties: {
          half: "top", 
          waterlogged: "false", 
          shape: "outer_right", 
          facing: "west"
        }, 
        Name: "minecraft:jungle_stairs"
      }, 
      {
        Properties: {
          half: "bottom", 
          waterlogged: "false", 
          shape: "outer_right", 
          facing: "south"
        }, 
        Name: "minecraft:jungle_stairs"
      }, 
      {
        Properties: {
          half: "top", 
          waterlogged: "false", 
          shape: "outer_right", 
          facing: "east"
        }, 
        Name: "minecraft:jungle_stairs"
      }, 
      {
        Properties: {
          half: "top", 
          waterlogged: "false", 
          shape: "outer_right", 
          facing: "north"
        }, 
        Name: "minecraft:jungle_stairs"
      }, 
      {
        Name: "minecraft:spruce_planks"
      }, 
      {
        Properties: {
          half: "bottom", 
          waterlogged: "false", 
          shape: "outer_right", 
          facing: "south"
        }, 
        Name: "minecraft:spruce_stairs"
      }, 
      {
        Properties: {
          east: "false", 
          waterlogged: "false", 
          south: "false", 
          north: "false", 
          west: "false"
        }, 
        Name: "minecraft:jungle_fence"
      }, 
      {
        Properties: {
          half: "bottom", 
          waterlogged: "false", 
          shape: "outer_right", 
          facing: "east"
        }, 
        Name: "minecraft:jungle_stairs"
      }, 
      {
        Properties: {
          east: "false", 
          waterlogged: "false", 
          south: "false", 
          north: "false", 
          west: "false"
        }, 
        Name: "minecraft:spruce_fence"
      }, 
      {
        Properties: {
          waterlogged: "false", 
          facing: "north", 
          type: "single"
        }, 
        Name: "minecraft:chest"
      }, 
      {
        Properties: {
          mode: "data"
        }, 
        Name: "minecraft:structure_block"
      }, 
      {
        Properties: {
          half: "bottom", 
          waterlogged: "false", 
          powered: "false", 
          facing: "east", 
          open: "true"
        }, 
        Name: "minecraft:jungle_trapdoor"
      }, 
      {
        Properties: {
          axis: "x"
        }, 
        Name: "minecraft:jungle_log"
      }, 
      {
        Properties: {
          half: "top", 
          waterlogged: "false", 
          shape: "outer_right", 
          facing: "north"
        }, 
        Name: "minecraft:spruce_stairs"
      }, 
      {
        Properties: {
          half: "bottom", 
          waterlogged: "false", 
          shape: "outer_right", 
          facing: "west"
        }, 
        Name: "minecraft:jungle_stairs"
      }, 
      {
        Properties: {
          half: "top", 
          waterlogged: "false", 
          shape: "outer_right", 
          facing: "south"
        }, 
        Name: "minecraft:jungle_stairs"
      }, 
      {
        Properties: {
          half: "bottom", 
          waterlogged: "false", 
          shape: "outer_right", 
          facing: "north"
        }, 
        Name: "minecraft:jungle_stairs"
      }
    ], 
    [
      {
        Name: "minecraft:dark_oak_planks"
      }, 
      {
        Properties: {
          half: "top", 
          waterlogged: "false", 
          shape: "outer_right", 
          facing: "west"
        }, 
        Name: "minecraft:dark_oak_stairs"
      }, 
      {
        Properties: {
          half: "bottom", 
          waterlogged: "false", 
          shape: "outer_right", 
          facing: "south"
        }, 
        Name: "minecraft:dark_oak_stairs"
      }, 
      {
        Properties: {
          half: "top", 
          waterlogged: "false", 
          shape: "outer_right", 
          facing: "east"
        }, 
        Name: "minecraft:dark_oak_stairs"
      }, 
      {
        Properties: {
          half: "top", 
          waterlogged: "false", 
          shape: "outer_right", 
          facing: "north"
        }, 
        Name: "minecraft:dark_oak_stairs"
      }, 
      {
        Name: "minecraft:jungle_planks"
      }, 
      {
        Properties: {
          half: "bottom", 
          waterlogged: "false", 
          shape: "outer_right", 
          facing: "south"
        }, 
        Name: "minecraft:jungle_stairs"
      }, 
      {
        Properties: {
          east: "false", 
          waterlogged: "false", 
          south: "false", 
          north: "false", 
          west: "false"
        }, 
        Name: "minecraft:dark_oak_fence"
      }, 
      {
        Properties: {
          half: "bottom", 
          waterlogged: "false", 
          shape: "outer_right", 
          facing: "east"
        }, 
        Name: "minecraft:dark_oak_stairs"
      }, 
      {
        Properties: {
          east: "false", 
          waterlogged: "false", 
          south: "false", 
          north: "false", 
          west: "false"
        }, 
        Name: "minecraft:jungle_fence"
      }, 
      {
        Properties: {
          waterlogged: "false", 
          facing: "north", 
          type: "single"
        }, 
        Name: "minecraft:chest"
      }, 
      {
        Properties: {
          mode: "data"
        }, 
        Name: "minecraft:structure_block"
      }, 
      {
        Properties: {
          half: "bottom", 
          waterlogged: "false", 
          powered: "false", 
          facing: "east", 
          open: "true"
        }, 
        Name: "minecraft:dark_oak_trapdoor"
      }, 
      {
        Properties: {
          axis: "x"
        }, 
        Name: "minecraft:dark_oak_log"
      }, 
      {
        Properties: {
          half: "top", 
          waterlogged: "false", 
          shape: "outer_right", 
          facing: "north"
        }, 
        Name: "minecraft:jungle_stairs"
      }, 
      {
        Properties: {
          half: "bottom", 
          waterlogged: "false", 
          shape: "outer_right", 
          facing: "west"
        }, 
        Name: "minecraft:dark_oak_stairs"
      }, 
      {
        Properties: {
          half: "top", 
          waterlogged: "false", 
          shape: "outer_right", 
          facing: "south"
        }, 
        Name: "minecraft:dark_oak_stairs"
      }, 
      {
        Properties: {
          half: "bottom", 
          waterlogged: "false", 
          shape: "outer_right", 
          facing: "north"
        }, 
        Name: "minecraft:dark_oak_stairs"
      }
    ], 
    [
      {
        Name: "minecraft:dark_oak_planks"
      }, 
      {
        Properties: {
          half: "top", 
          waterlogged: "false", 
          shape: "outer_right", 
          facing: "west"
        }, 
        Name: "minecraft:dark_oak_stairs"
      }, 
      {
        Properties: {
          half: "bottom", 
          waterlogged: "false", 
          shape: "outer_right", 
          facing: "south"
        }, 
        Name: "minecraft:dark_oak_stairs"
      }, 
      {
        Properties: {
          half: "top", 
          waterlogged: "false", 
          shape: "outer_right", 
          facing: "east"
        }, 
        Name: "minecraft:dark_oak_stairs"
      }, 
      {
        Properties: {
          half: "top", 
          waterlogged: "false", 
          shape: "outer_right", 
          facing: "north"
        }, 
        Name: "minecraft:dark_oak_stairs"
      }, 
      {
        Name: "minecraft:spruce_planks"
      }, 
      {
        Properties: {
          half: "bottom", 
          waterlogged: "false", 
          shape: "outer_right", 
          facing: "south"
        }, 
        Name: "minecraft:spruce_stairs"
      }, 
      {
        Properties: {
          east: "false", 
          waterlogged: "false", 
          south: "false", 
          north: "false", 
          west: "false"
        }, 
        Name: "minecraft:dark_oak_fence"
      }, 
      {
        Properties: {
          half: "bottom", 
          waterlogged: "false", 
          shape: "outer_right", 
          facing: "east"
        }, 
        Name: "minecraft:dark_oak_stairs"
      }, 
      {
        Properties: {
          east: "false", 
          waterlogged: "false", 
          south: "false", 
          north: "false", 
          west: "false"
        }, 
        Name: "minecraft:spruce_fence"
      }, 
      {
        Properties: {
          waterlogged: "false", 
          facing: "north", 
          type: "single"
        }, 
        Name: "minecraft:chest"
      }, 
      {
        Properties: {
          mode: "data"
        }, 
        Name: "minecraft:structure_block"
      }, 
      {
        Properties: {
          half: "bottom", 
          waterlogged: "false", 
          powered: "false", 
          facing: "east", 
          open: "true"
        }, 
        Name: "minecraft:dark_oak_trapdoor"
      }, 
      {
        Properties: {
          axis: "x"
        }, 
        Name: "minecraft:dark_oak_log"
      }, 
      {
        Properties: {
          half: "top", 
          waterlogged: "false", 
          shape: "outer_right", 
          facing: "north"
        }, 
        Name: "minecraft:spruce_stairs"
      }, 
      {
        Properties: {
          half: "bottom", 
          waterlogged: "false", 
          shape: "outer_right", 
          facing: "west"
        }, 
        Name: "minecraft:dark_oak_stairs"
      }, 
      {
        Properties: {
          half: "top", 
          waterlogged: "false", 
          shape: "outer_right", 
          facing: "south"
        }, 
        Name: "minecraft:dark_oak_stairs"
      }, 
      {
        Properties: {
          half: "bottom", 
          waterlogged: "false", 
          shape: "outer_right", 
          facing: "north"
        }, 
        Name: "minecraft:dark_oak_stairs"
      }
    ], 
    [
      {
        Name: "minecraft:spruce_planks"
      }, 
      {
        Properties: {
          half: "top", 
          waterlogged: "false", 
          shape: "outer_right", 
          facing: "west"
        }, 
        Name: "minecraft:spruce_stairs"
      }, 
      {
        Properties: {
          half: "bottom", 
          waterlogged: "false", 
          shape: "outer_right", 
          facing: "south"
        }, 
        Name: "minecraft:spruce_stairs"
      }, 
      {
        Properties: {
          half: "top", 
          waterlogged: "false", 
          shape: "outer_right", 
          facing: "east"
        }, 
        Name: "minecraft:spruce_stairs"
      }, 
      {
        Properties: {
          half: "top", 
          waterlogged: "false", 
          shape: "outer_right", 
          facing: "north"
        }, 
        Name: "minecraft:spruce_stairs"
      }, 
      {
        Name: "minecraft:oak_planks"
      }, 
      {
        Properties: {
          half: "bottom", 
          waterlogged: "false", 
          shape: "outer_right", 
          facing: "south"
        }, 
        Name: "minecraft:oak_stairs"
      }, 
      {
        Properties: {
          east: "false", 
          waterlogged: "false", 
          south: "false", 
          north: "false", 
          west: "false"
        }, 
        Name: "minecraft:spruce_fence"
      }, 
      {
        Properties: {
          half: "bottom", 
          waterlogged: "false", 
          shape: "outer_right", 
          facing: "east"
        }, 
        Name: "minecraft:spruce_stairs"
      }, 
      {
        Properties: {
          east: "false", 
          waterlogged: "false", 
          south: "false", 
          north: "false", 
          west: "false"
        }, 
        Name: "minecraft:oak_fence"
      }, 
      {
        Properties: {
          waterlogged: "false", 
          facing: "north", 
          type: "single"
        }, 
        Name: "minecraft:chest"
      }, 
      {
        Properties: {
          mode: "data"
        }, 
        Name: "minecraft:structure_block"
      }, 
      {
        Properties: {
          half: "bottom", 
          waterlogged: "false", 
          powered: "false", 
          facing: "east", 
          open: "true"
        }, 
        Name: "minecraft:spruce_trapdoor"
      }, 
      {
        Properties: {
          axis: "x"
        }, 
        Name: "minecraft:spruce_log"
      }, 
      {
        Properties: {
          half: "top", 
          waterlogged: "false", 
          shape: "outer_right", 
          facing: "north"
        }, 
        Name: "minecraft:oak_stairs"
      }, 
      {
        Properties: {
          half: "bottom", 
          waterlogged: "false", 
          shape: "outer_right", 
          facing: "west"
        }, 
        Name: "minecraft:spruce_stairs"
      }, 
      {
        Properties: {
          half: "top", 
          waterlogged: "false", 
          shape: "outer_right", 
          facing: "south"
        }, 
        Name: "minecraft:spruce_stairs"
      }, 
      {
        Properties: {
          half: "bottom", 
          waterlogged: "false", 
          shape: "outer_right", 
          facing: "north"
        }, 
        Name: "minecraft:spruce_stairs"
      }
    ], 
    [
      {
        Name: "minecraft:spruce_planks"
      }, 
      {
        Properties: {
          half: "top", 
          waterlogged: "false", 
          shape: "outer_right", 
          facing: "west"
        }, 
        Name: "minecraft:spruce_stairs"
      }, 
      {
        Properties: {
          half: "bottom", 
          waterlogged: "false", 
          shape: "outer_right", 
          facing: "south"
        }, 
        Name: "minecraft:spruce_stairs"
      }, 
      {
        Properties: {
          half: "top", 
          waterlogged: "false", 
          shape: "outer_right", 
          facing: "east"
        }, 
        Name: "minecraft:spruce_stairs"
      }, 
      {
        Properties: {
          half: "top", 
          waterlogged: "false", 
          shape: "outer_right", 
          facing: "north"
        }, 
        Name: "minecraft:spruce_stairs"
      }, 
      {
        Name: "minecraft:jungle_planks"
      }, 
      {
        Properties: {
          half: "bottom", 
          waterlogged: "false", 
          shape: "outer_right", 
          facing: "south"
        }, 
        Name: "minecraft:jungle_stairs"
      }, 
      {
        Properties: {
          east: "false", 
          waterlogged: "false", 
          south: "false", 
          north: "false", 
          west: "false"
        }, 
        Name: "minecraft:spruce_fence"
      }, 
      {
        Properties: {
          half: "bottom", 
          waterlogged: "false", 
          shape: "outer_right", 
          facing: "east"
        }, 
        Name: "minecraft:spruce_stairs"
      }, 
      {
        Properties: {
          east: "false", 
          waterlogged: "false", 
          south: "false", 
          north: "false", 
          west: "false"
        }, 
        Name: "minecraft:jungle_fence"
      }, 
      {
        Properties: {
          waterlogged: "false", 
          facing: "north", 
          type: "single"
        }, 
        Name: "minecraft:chest"
      }, 
      {
        Properties: {
          mode: "data"
        }, 
        Name: "minecraft:structure_block"
      }, 
      {
        Properties: {
          half: "bottom", 
          waterlogged: "false", 
          powered: "false", 
          facing: "east", 
          open: "true"
        }, 
        Name: "minecraft:spruce_trapdoor"
      }, 
      {
        Properties: {
          axis: "x"
        }, 
        Name: "minecraft:spruce_log"
      }, 
      {
        Properties: {
          half: "top", 
          waterlogged: "false", 
          shape: "outer_right", 
          facing: "north"
        }, 
        Name: "minecraft:jungle_stairs"
      }, 
      {
        Properties: {
          half: "bottom", 
          waterlogged: "false", 
          shape: "outer_right", 
          facing: "west"
        }, 
        Name: "minecraft:spruce_stairs"
      }, 
      {
        Properties: {
          half: "top", 
          waterlogged: "false", 
          shape: "outer_right", 
          facing: "south"
        }, 
        Name: "minecraft:spruce_stairs"
      }, 
      {
        Properties: {
          half: "bottom", 
          waterlogged: "false", 
          shape: "outer_right", 
          facing: "north"
        }, 
        Name: "minecraft:spruce_stairs"
      }
    ], 
    [
      {
        Name: "minecraft:spruce_planks"
      }, 
      {
        Properties: {
          half: "top", 
          waterlogged: "false", 
          shape: "outer_right", 
          facing: "west"
        }, 
        Name: "minecraft:spruce_stairs"
      }, 
      {
        Properties: {
          half: "bottom", 
          waterlogged: "false", 
          shape: "outer_right", 
          facing: "south"
        }, 
        Name: "minecraft:spruce_stairs"
      }, 
      {
        Properties: {
          half: "top", 
          waterlogged: "false", 
          shape: "outer_right", 
          facing: "east"
        }, 
        Name: "minecraft:spruce_stairs"
      }, 
      {
        Properties: {
          half: "top", 
          waterlogged: "false", 
          shape: "outer_right", 
          facing: "north"
        }, 
        Name: "minecraft:spruce_stairs"
      }, 
      {
        Name: "minecraft:dark_oak_planks"
      }, 
      {
        Properties: {
          half: "bottom", 
          waterlogged: "false", 
          shape: "outer_right", 
          facing: "south"
        }, 
        Name: "minecraft:dark_oak_stairs"
      }, 
      {
        Properties: {
          east: "false", 
          waterlogged: "false", 
          south: "false", 
          north: "false", 
          west: "false"
        }, 
        Name: "minecraft:spruce_fence"
      }, 
      {
        Properties: {
          half: "bottom", 
          waterlogged: "false", 
          shape: "outer_right", 
          facing: "east"
        }, 
        Name: "minecraft:spruce_stairs"
      }, 
      {
        Properties: {
          east: "false", 
          waterlogged: "false", 
          south: "false", 
          north: "false", 
          west: "false"
        }, 
        Name: "minecraft:dark_oak_fence"
      }, 
      {
        Properties: {
          waterlogged: "false", 
          facing: "north", 
          type: "single"
        }, 
        Name: "minecraft:chest"
      }, 
      {
        Properties: {
          mode: "data"
        }, 
        Name: "minecraft:structure_block"
      }, 
      {
        Properties: {
          half: "bottom", 
          waterlogged: "false", 
          powered: "false", 
          facing: "east", 
          open: "true"
        }, 
        Name: "minecraft:spruce_trapdoor"
      }, 
      {
        Properties: {
          axis: "x"
        }, 
        Name: "minecraft:spruce_log"
      }, 
      {
        Properties: {
          half: "top", 
          waterlogged: "false", 
          shape: "outer_right", 
          facing: "north"
        }, 
        Name: "minecraft:dark_oak_stairs"
      }, 
      {
        Properties: {
          half: "bottom", 
          waterlogged: "false", 
          shape: "outer_right", 
          facing: "west"
        }, 
        Name: "minecraft:spruce_stairs"
      }, 
      {
        Properties: {
          half: "top", 
          waterlogged: "false", 
          shape: "outer_right", 
          facing: "south"
        }, 
        Name: "minecraft:spruce_stairs"
      }, 
      {
        Properties: {
          half: "bottom", 
          waterlogged: "false", 
          shape: "outer_right", 
          facing: "north"
        }, 
        Name: "minecraft:spruce_stairs"
      }
    ], 
    [
      {
        Name: "minecraft:oak_planks"
      }, 
      {
        Properties: {
          half: "top", 
          waterlogged: "false", 
          shape: "outer_right", 
          facing: "west"
        }, 
        Name: "minecraft:oak_stairs"
      }, 
      {
        Properties: {
          half: "bottom", 
          waterlogged: "false", 
          shape: "outer_right", 
          facing: "south"
        }, 
        Name: "minecraft:oak_stairs"
      }, 
      {
        Properties: {
          half: "top", 
          waterlogged: "false", 
          shape: "outer_right", 
          facing: "east"
        }, 
        Name: "minecraft:oak_stairs"
      }, 
      {
        Properties: {
          half: "top", 
          waterlogged: "false", 
          shape: "outer_right", 
          facing: "north"
        }, 
        Name: "minecraft:oak_stairs"
      }, 
      {
        Name: "minecraft:birch_planks"
      }, 
      {
        Properties: {
          half: "bottom", 
          waterlogged: "false", 
          shape: "outer_right", 
          facing: "south"
        }, 
        Name: "minecraft:birch_stairs"
      }, 
      {
        Properties: {
          east: "false", 
          waterlogged: "false", 
          south: "false", 
          north: "false", 
          west: "false"
        }, 
        Name: "minecraft:oak_fence"
      }, 
      {
        Properties: {
          half: "bottom", 
          waterlogged: "false", 
          shape: "outer_right", 
          facing: "east"
        }, 
        Name: "minecraft:oak_stairs"
      }, 
      {
        Properties: {
          east: "false", 
          waterlogged: "false", 
          south: "false", 
          north: "false", 
          west: "false"
        }, 
        Name: "minecraft:birch_fence"
      }, 
      {
        Properties: {
          waterlogged: "false", 
          facing: "north", 
          type: "single"
        }, 
        Name: "minecraft:chest"
      }, 
      {
        Properties: {
          mode: "data"
        }, 
        Name: "minecraft:structure_block"
      }, 
      {
        Properties: {
          half: "bottom", 
          waterlogged: "false", 
          powered: "false", 
          facing: "east", 
          open: "true"
        }, 
        Name: "minecraft:oak_trapdoor"
      }, 
      {
        Properties: {
          axis: "x"
        }, 
        Name: "minecraft:oak_log"
      }, 
      {
        Properties: {
          half: "top", 
          waterlogged: "false", 
          shape: "outer_right", 
          facing: "north"
        }, 
        Name: "minecraft:birch_stairs"
      }, 
      {
        Properties: {
          half: "bottom", 
          waterlogged: "false", 
          shape: "outer_right", 
          facing: "west"
        }, 
        Name: "minecraft:oak_stairs"
      }, 
      {
        Properties: {
          half: "top", 
          waterlogged: "false", 
          shape: "outer_right", 
          facing: "south"
        }, 
        Name: "minecraft:oak_stairs"
      }, 
      {
        Properties: {
          half: "bottom", 
          waterlogged: "false", 
          shape: "outer_right", 
          facing: "north"
        }, 
        Name: "minecraft:oak_stairs"
      }
    ]
  ]
}
