{
  size: [9, 9, 24], 
  entities: [], 
  blocks: [
    {
      pos: [2, 0, 8], 
      state: 0
    }, 
    {
      pos: [3, 0, 9], 
      state: 0
    }, 
    {
      pos: [3, 0, 10], 
      state: 0
    }, 
    {
      pos: [3, 0, 18], 
      state: 0
    }, 
    {
      pos: [3, 0, 19], 
      state: 0
    }, 
    {
      pos: [3, 0, 20], 
      state: 0
    }, 
    {
      pos: [2, 0, 23], 
      state: 0
    }, 
    {
      pos: [3, 0, 8], 
      state: 1
    }, 
    {
      pos: [2, 0, 9], 
      state: 2
    }, 
    {
      pos: [4, 0, 9], 
      state: 3
    }, 
    {
      pos: [4, 0, 10], 
      state: 3
    }, 
    {
      pos: [4, 0, 11], 
      state: 3
    }, 
    {
      pos: [4, 0, 12], 
      state: 3
    }, 
    {
      pos: [4, 0, 13], 
      state: 3
    }, 
    {
      pos: [4, 0, 14], 
      state: 3
    }, 
    {
      pos: [4, 0, 15], 
      state: 3
    }, 
    {
      pos: [4, 0, 16], 
      state: 3
    }, 
    {
      pos: [4, 0, 17], 
      state: 3
    }, 
    {
      pos: [4, 0, 18], 
      state: 3
    }, 
    {
      pos: [4, 0, 19], 
      state: 3
    }, 
    {
      pos: [4, 0, 20], 
      state: 3
    }, 
    {
      pos: [3, 0, 21], 
      state: 3
    }, 
    {
      pos: [3, 0, 22], 
      state: 3
    }, 
    {
      pos: [3, 0, 23], 
      state: 4
    }, 
    {
      pos: [2, 1, 6], 
      state: 0
    }, 
    {
      pos: [2, 1, 7], 
      state: 0
    }, 
    {
      pos: [3, 1, 7], 
      state: 0
    }, 
    {
      pos: [3, 1, 8], 
      state: 0
    }, 
    {
      pos: [4, 1, 8], 
      state: 0
    }, 
    {
      pos: [4, 1, 9], 
      state: 5
    }, 
    {
      pos: [5, 1, 9], 
      state: 0
    }, 
    {
      pos: [4, 1, 10], 
      state: 5
    }, 
    {
      pos: [5, 1, 10], 
      state: 0
    }, 
    {
      pos: [4, 1, 11], 
      state: 5
    }, 
    {
      pos: [5, 1, 11], 
      state: 0
    }, 
    {
      pos: [4, 1, 12], 
      state: 5
    }, 
    {
      pos: [4, 1, 13], 
      state: 5
    }, 
    {
      pos: [5, 1, 13], 
      state: 0
    }, 
    {
      pos: [4, 1, 14], 
      state: 5
    }, 
    {
      pos: [5, 1, 14], 
      state: 0
    }, 
    {
      pos: [5, 1, 16], 
      state: 0
    }, 
    {
      pos: [5, 1, 17], 
      state: 0
    }, 
    {
      pos: [4, 1, 19], 
      state: 5
    }, 
    {
      pos: [5, 1, 19], 
      state: 0
    }, 
    {
      pos: [5, 1, 20], 
      state: 0
    }, 
    {
      pos: [4, 1, 22], 
      state: 0
    }, 
    {
      pos: [3, 1, 6], 
      state: 3
    }, 
    {
      pos: [4, 1, 7], 
      state: 3
    }, 
    {
      pos: [2, 1, 8], 
      state: 2
    }, 
    {
      pos: [5, 1, 8], 
      state: 3
    }, 
    {
      pos: [6, 1, 9], 
      state: 3
    }, 
    {
      pos: [6, 1, 10], 
      state: 3
    }, 
    {
      pos: [6, 1, 11], 
      state: 3
    }, 
    {
      pos: [6, 1, 12], 
      state: 3
    }, 
    {
      pos: [6, 1, 13], 
      state: 3
    }, 
    {
      pos: [6, 1, 14], 
      state: 3
    }, 
    {
      pos: [6, 1, 15], 
      state: 3
    }, 
    {
      pos: [6, 1, 16], 
      state: 3
    }, 
    {
      pos: [6, 1, 17], 
      state: 3
    }, 
    {
      pos: [6, 1, 18], 
      state: 3
    }, 
    {
      pos: [6, 1, 19], 
      state: 3
    }, 
    {
      pos: [6, 1, 20], 
      state: 3
    }, 
    {
      pos: [5, 1, 21], 
      state: 3
    }, 
    {
      pos: [5, 1, 22], 
      state: 3
    }, 
    {
      pos: [4, 1, 23], 
      state: 3
    }, 
    {
      pos: [2, 2, 5], 
      state: 0
    }, 
    {
      pos: [3, 2, 5], 
      state: 0
    }, 
    {
      pos: [3, 2, 6], 
      state: 5
    }, 
    {
      pos: [3, 2, 7], 
      state: 5
    }, 
    {
      pos: [4, 2, 7], 
      state: 0
    }, 
    {
      pos: [4, 2, 8], 
      state: 5
    }, 
    {
      pos: [5, 2, 8], 
      state: 0
    }, 
    {
      pos: [4, 2, 9], 
      state: 5
    }, 
    {
      pos: [5, 2, 9], 
      state: 0
    }, 
    {
      pos: [6, 2, 9], 
      state: 0
    }, 
    {
      pos: [4, 2, 10], 
      state: 5
    }, 
    {
      pos: [5, 2, 10], 
      state: 0
    }, 
    {
      pos: [6, 2, 10], 
      state: 0
    }, 
    {
      pos: [4, 2, 11], 
      state: 5
    }, 
    {
      pos: [5, 2, 11], 
      state: 0
    }, 
    {
      pos: [6, 2, 11], 
      state: 0
    }, 
    {
      pos: [4, 2, 12], 
      state: 5
    }, 
    {
      pos: [4, 2, 13], 
      state: 5
    }, 
    {
      pos: [5, 2, 13], 
      state: 0
    }, 
    {
      pos: [6, 2, 13], 
      state: 0
    }, 
    {
      pos: [6, 2, 14], 
      state: 0
    }, 
    {
      pos: [5, 2, 16], 
      state: 0
    }, 
    {
      pos: [6, 2, 16], 
      state: 0
    }, 
    {
      pos: [6, 2, 17], 
      state: 0
    }, 
    {
      pos: [6, 2, 19], 
      state: 0
    }, 
    {
      pos: [6, 2, 20], 
      state: 0
    }, 
    {
      pos: [5, 2, 21], 
      state: 0
    }, 
    {
      pos: [4, 2, 5], 
      state: 3
    }, 
    {
      pos: [4, 2, 6], 
      state: 3
    }, 
    {
      pos: [5, 2, 7], 
      state: 3
    }, 
    {
      pos: [6, 2, 8], 
      state: 3
    }, 
    {
      pos: [7, 2, 9], 
      state: 3
    }, 
    {
      pos: [7, 2, 10], 
      state: 3
    }, 
    {
      pos: [7, 2, 11], 
      state: 3
    }, 
    {
      pos: [6, 2, 12], 
      state: 6
    }, 
    {
      pos: [7, 2, 12], 
      state: 3
    }, 
    {
      pos: [7, 2, 13], 
      state: 3
    }, 
    {
      pos: [7, 2, 14], 
      state: 3
    }, 
    {
      pos: [6, 2, 15], 
      state: 6
    }, 
    {
      pos: [7, 2, 15], 
      state: 3
    }, 
    {
      pos: [7, 2, 16], 
      state: 3
    }, 
    {
      pos: [7, 2, 17], 
      state: 3
    }, 
    {
      pos: [6, 2, 18], 
      state: 6
    }, 
    {
      pos: [7, 2, 18], 
      state: 3
    }, 
    {
      pos: [7, 2, 19], 
      state: 3
    }, 
    {
      pos: [7, 2, 20], 
      state: 3
    }, 
    {
      pos: [6, 2, 21], 
      state: 3
    }, 
    {
      pos: [6, 2, 22], 
      state: 3
    }, 
    {
      pos: [2, 3, 4], 
      state: 0
    }, 
    {
      pos: [3, 3, 4], 
      state: 0
    }, 
    {
      pos: [3, 3, 5], 
      state: 5
    }, 
    {
      pos: [4, 3, 5], 
      state: 0
    }, 
    {
      pos: [3, 3, 6], 
      state: 5
    }, 
    {
      pos: [4, 3, 6], 
      state: 0
    }, 
    {
      pos: [4, 3, 7], 
      state: 5
    }, 
    {
      pos: [5, 3, 7], 
      state: 0
    }, 
    {
      pos: [4, 3, 8], 
      state: 5
    }, 
    {
      pos: [6, 3, 8], 
      state: 0
    }, 
    {
      pos: [7, 3, 9], 
      state: 0
    }, 
    {
      pos: [7, 3, 10], 
      state: 0
    }, 
    {
      pos: [4, 3, 11], 
      state: 5
    }, 
    {
      pos: [7, 3, 11], 
      state: 0
    }, 
    {
      pos: [7, 3, 12], 
      state: 0
    }, 
    {
      pos: [7, 3, 13], 
      state: 0
    }, 
    {
      pos: [7, 3, 14], 
      state: 0
    }, 
    {
      pos: [7, 3, 15], 
      state: 0
    }, 
    {
      pos: [7, 3, 16], 
      state: 0
    }, 
    {
      pos: [7, 3, 17], 
      state: 0
    }, 
    {
      pos: [7, 3, 18], 
      state: 0
    }, 
    {
      pos: [7, 3, 19], 
      state: 0
    }, 
    {
      pos: [7, 3, 20], 
      state: 0
    }, 
    {
      nbt: {
        Items: [], 
        id: "minecraft:chest", 
        Lock: ""
      }, 
      pos: [5, 3, 8], 
      state: 7
    }, 
    {
      pos: [1, 3, 2], 
      state: 8
    }, 
    {
      pos: [2, 3, 2], 
      state: 8
    }, 
    {
      pos: [1, 3, 3], 
      state: 8
    }, 
    {
      pos: [2, 3, 3], 
      state: 1
    }, 
    {
      pos: [3, 3, 3], 
      state: 1
    }, 
    {
      pos: [1, 3, 4], 
      state: 8
    }, 
    {
      pos: [4, 3, 4], 
      state: 1
    }, 
    {
      pos: [5, 3, 5], 
      state: 3
    }, 
    {
      pos: [5, 3, 6], 
      state: 3
    }, 
    {
      pos: [3, 3, 7], 
      state: 9
    }, 
    {
      pos: [6, 3, 7], 
      state: 3
    }, 
    {
      pos: [7, 3, 8], 
      state: 3
    }, 
    {
      pos: [4, 3, 9], 
      state: 10
    }, 
    {
      pos: [4, 3, 10], 
      state: 10
    }, 
    {
      pos: [4, 3, 12], 
      state: 10
    }, 
    {
      pos: [4, 3, 13], 
      state: 10
    }, 
    {
      pos: [7, 3, 21], 
      state: 3
    }, 
    {
      pos: [1, 4, 2], 
      state: 5
    }, 
    {
      pos: [2, 4, 3], 
      state: 5
    }, 
    {
      pos: [3, 4, 3], 
      state: 5
    }, 
    {
      pos: [3, 4, 4], 
      state: 5
    }, 
    {
      pos: [4, 4, 4], 
      state: 5
    }, 
    {
      pos: [3, 4, 5], 
      state: 5
    }, 
    {
      pos: [4, 4, 5], 
      state: 0
    }, 
    {
      pos: [5, 4, 5], 
      state: 5
    }, 
    {
      pos: [3, 4, 6], 
      state: 5
    }, 
    {
      pos: [4, 4, 6], 
      state: 0
    }, 
    {
      pos: [5, 4, 6], 
      state: 0
    }, 
    {
      pos: [6, 4, 6], 
      state: 5
    }, 
    {
      pos: [3, 4, 7], 
      state: 11
    }, 
    {
      pos: [4, 4, 7], 
      state: 11
    }, 
    {
      pos: [5, 4, 7], 
      state: 0
    }, 
    {
      pos: [6, 4, 7], 
      state: 0
    }, 
    {
      pos: [7, 4, 7], 
      state: 5
    }, 
    {
      pos: [4, 4, 8], 
      state: 5
    }, 
    {
      pos: [6, 4, 8], 
      state: 0
    }, 
    {
      pos: [7, 4, 8], 
      state: 5
    }, 
    {
      pos: [7, 4, 9], 
      state: 0
    }, 
    {
      pos: [8, 4, 9], 
      state: 5
    }, 
    {
      pos: [7, 4, 10], 
      state: 0
    }, 
    {
      pos: [8, 4, 10], 
      state: 5
    }, 
    {
      pos: [3, 4, 11], 
      state: 11
    }, 
    {
      pos: [4, 4, 11], 
      state: 11
    }, 
    {
      pos: [5, 4, 11], 
      state: 11
    }, 
    {
      pos: [6, 4, 11], 
      state: 11
    }, 
    {
      pos: [7, 4, 11], 
      state: 0
    }, 
    {
      pos: [8, 4, 11], 
      state: 5
    }, 
    {
      pos: [7, 4, 12], 
      state: 0
    }, 
    {
      pos: [8, 4, 12], 
      state: 5
    }, 
    {
      pos: [7, 4, 13], 
      state: 0
    }, 
    {
      pos: [8, 4, 13], 
      state: 5
    }, 
    {
      pos: [7, 4, 14], 
      state: 0
    }, 
    {
      pos: [8, 4, 14], 
      state: 5
    }, 
    {
      pos: [7, 4, 15], 
      state: 0
    }, 
    {
      pos: [8, 4, 15], 
      state: 5
    }, 
    {
      pos: [6, 4, 16], 
      state: 11
    }, 
    {
      pos: [7, 4, 16], 
      state: 0
    }, 
    {
      pos: [8, 4, 16], 
      state: 5
    }, 
    {
      pos: [7, 4, 17], 
      state: 0
    }, 
    {
      pos: [8, 4, 17], 
      state: 5
    }, 
    {
      pos: [7, 4, 18], 
      state: 0
    }, 
    {
      pos: [8, 4, 18], 
      state: 5
    }, 
    {
      pos: [7, 4, 19], 
      state: 0
    }, 
    {
      pos: [8, 4, 19], 
      state: 5
    }, 
    {
      pos: [8, 4, 20], 
      state: 5
    }, 
    {
      nbt: {
        metadata: "supply_chest", 
        mirror: "NONE", 
        ignoreEntities: 1b, 
        powered: 0b, 
        seed: 0L, 
        author: "CascadianBacon", 
        rotation: "NONE", 
        mode: "DATA", 
        posX: 0, 
        posY: 1, 
        sizeX: 0, 
        integrity: 1.0f, 
        posZ: 0, 
        showair: 0b, 
        name: "", 
        id: "minecraft:structure_block", 
        sizeY: 0, 
        showboundingbox: 1b, 
        sizeZ: 0
      }, 
      pos: [5, 4, 8], 
      state: 12
    }, 
    {
      pos: [0, 4, 0], 
      state: 13
    }, 
    {
      pos: [0, 4, 1], 
      state: 9
    }, 
    {
      pos: [1, 4, 1], 
      state: 13
    }, 
    {
      pos: [2, 4, 2], 
      state: 13
    }, 
    {
      pos: [1, 4, 3], 
      state: 9
    }, 
    {
      pos: [4, 4, 3], 
      state: 13
    }, 
    {
      pos: [2, 4, 4], 
      state: 9
    }, 
    {
      pos: [5, 4, 4], 
      state: 13
    }, 
    {
      pos: [6, 4, 5], 
      state: 13
    }, 
    {
      pos: [7, 4, 6], 
      state: 13
    }, 
    {
      pos: [8, 4, 8], 
      state: 13
    }, 
    {
      pos: [4, 4, 12], 
      state: 10
    }, 
    {
      pos: [2, 5, 4], 
      state: 0
    }, 
    {
      pos: [3, 5, 4], 
      state: 0
    }, 
    {
      pos: [3, 5, 5], 
      state: 5
    }, 
    {
      pos: [4, 5, 5], 
      state: 0
    }, 
    {
      pos: [3, 5, 6], 
      state: 5
    }, 
    {
      pos: [4, 5, 6], 
      state: 0
    }, 
    {
      pos: [4, 5, 7], 
      state: 5
    }, 
    {
      pos: [5, 5, 7], 
      state: 0
    }, 
    {
      pos: [4, 5, 8], 
      state: 5
    }, 
    {
      pos: [6, 5, 8], 
      state: 0
    }, 
    {
      pos: [7, 5, 9], 
      state: 0
    }, 
    {
      pos: [7, 5, 10], 
      state: 0
    }, 
    {
      pos: [4, 5, 11], 
      state: 5
    }, 
    {
      pos: [7, 5, 11], 
      state: 0
    }, 
    {
      pos: [7, 5, 12], 
      state: 0
    }, 
    {
      pos: [7, 5, 13], 
      state: 0
    }, 
    {
      pos: [7, 5, 14], 
      state: 0
    }, 
    {
      pos: [7, 5, 15], 
      state: 0
    }, 
    {
      pos: [6, 5, 16], 
      state: 0
    }, 
    {
      pos: [7, 5, 16], 
      state: 0
    }, 
    {
      pos: [1, 5, 2], 
      state: 8
    }, 
    {
      pos: [2, 5, 2], 
      state: 8
    }, 
    {
      pos: [1, 5, 3], 
      state: 8
    }, 
    {
      pos: [2, 5, 3], 
      state: 14
    }, 
    {
      pos: [3, 5, 3], 
      state: 14
    }, 
    {
      pos: [1, 5, 4], 
      state: 8
    }, 
    {
      pos: [4, 5, 4], 
      state: 14
    }, 
    {
      pos: [5, 5, 5], 
      state: 15
    }, 
    {
      pos: [5, 5, 6], 
      state: 15
    }, 
    {
      pos: [3, 5, 7], 
      state: 16
    }, 
    {
      pos: [6, 5, 7], 
      state: 15
    }, 
    {
      pos: [7, 5, 8], 
      state: 15
    }, 
    {
      pos: [4, 5, 9], 
      state: 17
    }, 
    {
      pos: [4, 5, 10], 
      state: 17
    }, 
    {
      pos: [2, 6, 5], 
      state: 0
    }, 
    {
      pos: [3, 6, 5], 
      state: 0
    }, 
    {
      pos: [3, 6, 6], 
      state: 5
    }, 
    {
      pos: [3, 6, 7], 
      state: 5
    }, 
    {
      pos: [4, 6, 7], 
      state: 0
    }, 
    {
      pos: [4, 6, 8], 
      state: 5
    }, 
    {
      pos: [5, 6, 8], 
      state: 0
    }, 
    {
      pos: [4, 6, 9], 
      state: 5
    }, 
    {
      pos: [5, 6, 9], 
      state: 0
    }, 
    {
      pos: [6, 6, 9], 
      state: 0
    }, 
    {
      pos: [4, 6, 10], 
      state: 5
    }, 
    {
      pos: [5, 6, 10], 
      state: 0
    }, 
    {
      pos: [6, 6, 10], 
      state: 0
    }, 
    {
      pos: [4, 6, 11], 
      state: 5
    }, 
    {
      pos: [5, 6, 11], 
      state: 0
    }, 
    {
      pos: [6, 6, 11], 
      state: 0
    }, 
    {
      pos: [5, 6, 13], 
      state: 0
    }, 
    {
      pos: [6, 6, 13], 
      state: 0
    }, 
    {
      pos: [6, 6, 14], 
      state: 0
    }, 
    {
      pos: [4, 6, 5], 
      state: 15
    }, 
    {
      pos: [4, 6, 6], 
      state: 15
    }, 
    {
      pos: [5, 6, 7], 
      state: 15
    }, 
    {
      pos: [6, 6, 8], 
      state: 15
    }, 
    {
      pos: [7, 6, 9], 
      state: 15
    }, 
    {
      pos: [7, 6, 10], 
      state: 15
    }, 
    {
      pos: [7, 6, 11], 
      state: 15
    }, 
    {
      pos: [6, 6, 12], 
      state: 18
    }, 
    {
      pos: [7, 6, 12], 
      state: 15
    }, 
    {
      pos: [7, 6, 13], 
      state: 15
    }, 
    {
      pos: [7, 6, 14], 
      state: 15
    }, 
    {
      pos: [6, 6, 15], 
      state: 18
    }, 
    {
      pos: [7, 6, 15], 
      state: 15
    }, 
    {
      pos: [7, 6, 16], 
      state: 15
    }, 
    {
      pos: [2, 7, 6], 
      state: 0
    }, 
    {
      pos: [2, 7, 7], 
      state: 0
    }, 
    {
      pos: [3, 7, 7], 
      state: 0
    }, 
    {
      pos: [3, 7, 8], 
      state: 0
    }, 
    {
      pos: [4, 7, 8], 
      state: 0
    }, 
    {
      pos: [4, 7, 9], 
      state: 5
    }, 
    {
      pos: [5, 7, 9], 
      state: 0
    }, 
    {
      pos: [4, 7, 10], 
      state: 5
    }, 
    {
      pos: [5, 7, 10], 
      state: 0
    }, 
    {
      pos: [4, 7, 11], 
      state: 5
    }, 
    {
      pos: [5, 7, 11], 
      state: 0
    }, 
    {
      pos: [4, 7, 12], 
      state: 5
    }, 
    {
      pos: [4, 7, 13], 
      state: 5
    }, 
    {
      pos: [5, 7, 13], 
      state: 0
    }, 
    {
      pos: [5, 7, 14], 
      state: 0
    }, 
    {
      pos: [3, 7, 6], 
      state: 15
    }, 
    {
      pos: [4, 7, 7], 
      state: 15
    }, 
    {
      pos: [2, 7, 8], 
      state: 4
    }, 
    {
      pos: [5, 7, 8], 
      state: 15
    }, 
    {
      pos: [6, 7, 9], 
      state: 15
    }, 
    {
      pos: [6, 7, 10], 
      state: 15
    }, 
    {
      pos: [6, 7, 11], 
      state: 15
    }, 
    {
      pos: [6, 7, 12], 
      state: 15
    }, 
    {
      pos: [6, 7, 13], 
      state: 15
    }, 
    {
      pos: [6, 7, 14], 
      state: 15
    }, 
    {
      pos: [6, 7, 15], 
      state: 15
    }, 
    {
      pos: [2, 8, 8], 
      state: 0
    }, 
    {
      pos: [3, 8, 9], 
      state: 0
    }, 
    {
      pos: [3, 8, 10], 
      state: 0
    }, 
    {
      pos: [3, 8, 8], 
      state: 14
    }, 
    {
      pos: [2, 8, 9], 
      state: 4
    }, 
    {
      pos: [4, 8, 9], 
      state: 15
    }, 
    {
      pos: [4, 8, 10], 
      state: 15
    }, 
    {
      pos: [3, 8, 11], 
      state: 8
    }, 
    {
      pos: [4, 8, 11], 
      state: 15
    }, 
    {
      pos: [3, 8, 12], 
      state: 8
    }, 
    {
      pos: [4, 8, 12], 
      state: 15
    }, 
    {
      pos: [3, 8, 13], 
      state: 8
    }, 
    {
      pos: [4, 8, 13], 
      state: 15
    }
  ], 
  palettes: [
    [
      {
        Name: "minecraft:oak_planks"
      }, 
      {
        Properties: {
          half: "top", 
          waterlogged: "false", 
          shape: "outer_right", 
          facing: "south"
        }, 
        Name: "minecraft:oak_stairs"
      }, 
      {
        Properties: {
          half: "bottom", 
          waterlogged: "false", 
          shape: "outer_right", 
          facing: "north"
        }, 
        Name: "minecraft:oak_stairs"
      }, 
      {
        Properties: {
          half: "top", 
          waterlogged: "false", 
          shape: "outer_right", 
          facing: "west"
        }, 
        Name: "minecraft:oak_stairs"
      }, 
      {
        Properties: {
          half: "top", 
          waterlogged: "false", 
          shape: "outer_right", 
          facing: "north"
        }, 
        Name: "minecraft:oak_stairs"
      }, 
      {
        Name: "minecraft:spruce_planks"
      }, 
      {
        Properties: {
          half: "bottom", 
          waterlogged: "false", 
          shape: "outer_right", 
          facing: "east"
        }, 
        Name: "minecraft:oak_stairs"
      }, 
      {
        Properties: {
          waterlogged: "false", 
          facing: "south", 
          type: "single"
        }, 
        Name: "minecraft:chest"
      }, 
      {
        Properties: {
          east: "false", 
          waterlogged: "false", 
          south: "false", 
          north: "false", 
          west: "false"
        }, 
        Name: "minecraft:spruce_fence"
      }, 
      {
        Properties: {
          half: "bottom", 
          waterlogged: "false", 
          shape: "outer_right", 
          facing: "north"
        }, 
        Name: "minecraft:spruce_stairs"
      }, 
      {
        Properties: {
          half: "bottom", 
          waterlogged: "false", 
          powered: "false", 
          facing: "east", 
          open: "true"
        }, 
        Name: "minecraft:oak_trapdoor"
      }, 
      {
        Properties: {
          axis: "x"
        }, 
        Name: "minecraft:oak_log"
      }, 
      {
        Properties: {
          mode: "data"
        }, 
        Name: "minecraft:structure_block"
      }, 
      {
        Properties: {
          half: "top", 
          waterlogged: "false", 
          shape: "outer_right", 
          facing: "south"
        }, 
        Name: "minecraft:spruce_stairs"
      }, 
      {
        Properties: {
          half: "bottom", 
          waterlogged: "false", 
          shape: "outer_right", 
          facing: "south"
        }, 
        Name: "minecraft:oak_stairs"
      }, 
      {
        Properties: {
          half: "bottom", 
          waterlogged: "false", 
          shape: "outer_right", 
          facing: "west"
        }, 
        Name: "minecraft:oak_stairs"
      }, 
      {
        Properties: {
          half: "top", 
          waterlogged: "false", 
          shape: "outer_right", 
          facing: "north"
        }, 
        Name: "minecraft:spruce_stairs"
      }, 
      {
        Properties: {
          half: "top", 
          waterlogged: "false", 
          powered: "false", 
          facing: "east", 
          open: "true"
        }, 
        Name: "minecraft:oak_trapdoor"
      }, 
      {
        Properties: {
          half: "top", 
          waterlogged: "false", 
          shape: "outer_right", 
          facing: "east"
        }, 
        Name: "minecraft:oak_stairs"
      }
    ], 
    [
      {
        Name: "minecraft:jungle_planks"
      }, 
      {
        Properties: {
          half: "top", 
          waterlogged: "false", 
          shape: "outer_right", 
          facing: "south"
        }, 
        Name: "minecraft:jungle_stairs"
      }, 
      {
        Properties: {
          half: "bottom", 
          waterlogged: "false", 
          shape: "outer_right", 
          facing: "north"
        }, 
        Name: "minecraft:jungle_stairs"
      }, 
      {
        Properties: {
          half: "top", 
          waterlogged: "false", 
          shape: "outer_right", 
          facing: "west"
        }, 
        Name: "minecraft:jungle_stairs"
      }, 
      {
        Properties: {
          half: "top", 
          waterlogged: "false", 
          shape: "outer_right", 
          facing: "north"
        }, 
        Name: "minecraft:jungle_stairs"
      }, 
      {
        Name: "minecraft:spruce_planks"
      }, 
      {
        Properties: {
          half: "bottom", 
          waterlogged: "false", 
          shape: "outer_right", 
          facing: "east"
        }, 
        Name: "minecraft:jungle_stairs"
      }, 
      {
        Properties: {
          waterlogged: "false", 
          facing: "south", 
          type: "single"
        }, 
        Name: "minecraft:chest"
      }, 
      {
        Properties: {
          east: "false", 
          waterlogged: "false", 
          south: "false", 
          north: "false", 
          west: "false"
        }, 
        Name: "minecraft:spruce_fence"
      }, 
      {
        Properties: {
          half: "bottom", 
          waterlogged: "false", 
          shape: "outer_right", 
          facing: "north"
        }, 
        Name: "minecraft:spruce_stairs"
      }, 
      {
        Properties: {
          half: "bottom", 
          waterlogged: "false", 
          powered: "false", 
          facing: "east", 
          open: "true"
        }, 
        Name: "minecraft:jungle_trapdoor"
      }, 
      {
        Properties: {
          axis: "x"
        }, 
        Name: "minecraft:jungle_log"
      }, 
      {
        Properties: {
          mode: "data"
        }, 
        Name: "minecraft:structure_block"
      }, 
      {
        Properties: {
          half: "top", 
          waterlogged: "false", 
          shape: "outer_right", 
          facing: "south"
        }, 
        Name: "minecraft:spruce_stairs"
      }, 
      {
        Properties: {
          half: "bottom", 
          waterlogged: "false", 
          shape: "outer_right", 
          facing: "south"
        }, 
        Name: "minecraft:jungle_stairs"
      }, 
      {
        Properties: {
          half: "bottom", 
          waterlogged: "false", 
          shape: "outer_right", 
          facing: "west"
        }, 
        Name: "minecraft:jungle_stairs"
      }, 
      {
        Properties: {
          half: "top", 
          waterlogged: "false", 
          shape: "outer_right", 
          facing: "north"
        }, 
        Name: "minecraft:spruce_stairs"
      }, 
      {
        Properties: {
          half: "top", 
          waterlogged: "false", 
          powered: "false", 
          facing: "east", 
          open: "true"
        }, 
        Name: "minecraft:jungle_trapdoor"
      }, 
      {
        Properties: {
          half: "top", 
          waterlogged: "false", 
          shape: "outer_right", 
          facing: "east"
        }, 
        Name: "minecraft:jungle_stairs"
      }
    ], 
    [
      {
        Name: "minecraft:dark_oak_planks"
      }, 
      {
        Properties: {
          half: "top", 
          waterlogged: "false", 
          shape: "outer_right", 
          facing: "south"
        }, 
        Name: "minecraft:dark_oak_stairs"
      }, 
      {
        Properties: {
          half: "bottom", 
          waterlogged: "false", 
          shape: "outer_right", 
          facing: "north"
        }, 
        Name: "minecraft:dark_oak_stairs"
      }, 
      {
        Properties: {
          half: "top", 
          waterlogged: "false", 
          shape: "outer_right", 
          facing: "west"
        }, 
        Name: "minecraft:dark_oak_stairs"
      }, 
      {
        Properties: {
          half: "top", 
          waterlogged: "false", 
          shape: "outer_right", 
          facing: "north"
        }, 
        Name: "minecraft:dark_oak_stairs"
      }, 
      {
        Name: "minecraft:jungle_planks"
      }, 
      {
        Properties: {
          half: "bottom", 
          waterlogged: "false", 
          shape: "outer_right", 
          facing: "east"
        }, 
        Name: "minecraft:dark_oak_stairs"
      }, 
      {
        Properties: {
          waterlogged: "false", 
          facing: "south", 
          type: "single"
        }, 
        Name: "minecraft:chest"
      }, 
      {
        Properties: {
          east: "false", 
          waterlogged: "false", 
          south: "false", 
          north: "false", 
          west: "false"
        }, 
        Name: "minecraft:jungle_fence"
      }, 
      {
        Properties: {
          half: "bottom", 
          waterlogged: "false", 
          shape: "outer_right", 
          facing: "north"
        }, 
        Name: "minecraft:jungle_stairs"
      }, 
      {
        Properties: {
          half: "bottom", 
          waterlogged: "false", 
          powered: "false", 
          facing: "east", 
          open: "true"
        }, 
        Name: "minecraft:dark_oak_trapdoor"
      }, 
      {
        Properties: {
          axis: "x"
        }, 
        Name: "minecraft:dark_oak_log"
      }, 
      {
        Properties: {
          mode: "data"
        }, 
        Name: "minecraft:structure_block"
      }, 
      {
        Properties: {
          half: "top", 
          waterlogged: "false", 
          shape: "outer_right", 
          facing: "south"
        }, 
        Name: "minecraft:jungle_stairs"
      }, 
      {
        Properties: {
          half: "bottom", 
          waterlogged: "false", 
          shape: "outer_right", 
          facing: "south"
        }, 
        Name: "minecraft:dark_oak_stairs"
      }, 
      {
        Properties: {
          half: "bottom", 
          waterlogged: "false", 
          shape: "outer_right", 
          facing: "west"
        }, 
        Name: "minecraft:dark_oak_stairs"
      }, 
      {
        Properties: {
          half: "top", 
          waterlogged: "false", 
          shape: "outer_right", 
          facing: "north"
        }, 
        Name: "minecraft:jungle_stairs"
      }, 
      {
        Properties: {
          half: "top", 
          waterlogged: "false", 
          powered: "false", 
          facing: "east", 
          open: "true"
        }, 
        Name: "minecraft:dark_oak_trapdoor"
      }, 
      {
        Properties: {
          half: "top", 
          waterlogged: "false", 
          shape: "outer_right", 
          facing: "east"
        }, 
        Name: "minecraft:dark_oak_stairs"
      }
    ], 
    [
      {
        Name: "minecraft:dark_oak_planks"
      }, 
      {
        Properties: {
          half: "top", 
          waterlogged: "false", 
          shape: "outer_right", 
          facing: "south"
        }, 
        Name: "minecraft:dark_oak_stairs"
      }, 
      {
        Properties: {
          half: "bottom", 
          waterlogged: "false", 
          shape: "outer_right", 
          facing: "north"
        }, 
        Name: "minecraft:dark_oak_stairs"
      }, 
      {
        Properties: {
          half: "top", 
          waterlogged: "false", 
          shape: "outer_right", 
          facing: "west"
        }, 
        Name: "minecraft:dark_oak_stairs"
      }, 
      {
        Properties: {
          half: "top", 
          waterlogged: "false", 
          shape: "outer_right", 
          facing: "north"
        }, 
        Name: "minecraft:dark_oak_stairs"
      }, 
      {
        Name: "minecraft:spruce_planks"
      }, 
      {
        Properties: {
          half: "bottom", 
          waterlogged: "false", 
          shape: "outer_right", 
          facing: "east"
        }, 
        Name: "minecraft:dark_oak_stairs"
      }, 
      {
        Properties: {
          waterlogged: "false", 
          facing: "south", 
          type: "single"
        }, 
        Name: "minecraft:chest"
      }, 
      {
        Properties: {
          east: "false", 
          waterlogged: "false", 
          south: "false", 
          north: "false", 
          west: "false"
        }, 
        Name: "minecraft:spruce_fence"
      }, 
      {
        Properties: {
          half: "bottom", 
          waterlogged: "false", 
          shape: "outer_right", 
          facing: "north"
        }, 
        Name: "minecraft:spruce_stairs"
      }, 
      {
        Properties: {
          half: "bottom", 
          waterlogged: "false", 
          powered: "false", 
          facing: "east", 
          open: "true"
        }, 
        Name: "minecraft:dark_oak_trapdoor"
      }, 
      {
        Properties: {
          axis: "x"
        }, 
        Name: "minecraft:dark_oak_log"
      }, 
      {
        Properties: {
          mode: "data"
        }, 
        Name: "minecraft:structure_block"
      }, 
      {
        Properties: {
          half: "top", 
          waterlogged: "false", 
          shape: "outer_right", 
          facing: "south"
        }, 
        Name: "minecraft:spruce_stairs"
      }, 
      {
        Properties: {
          half: "bottom", 
          waterlogged: "false", 
          shape: "outer_right", 
          facing: "south"
        }, 
        Name: "minecraft:dark_oak_stairs"
      }, 
      {
        Properties: {
          half: "bottom", 
          waterlogged: "false", 
          shape: "outer_right", 
          facing: "west"
        }, 
        Name: "minecraft:dark_oak_stairs"
      }, 
      {
        Properties: {
          half: "top", 
          waterlogged: "false", 
          shape: "outer_right", 
          facing: "north"
        }, 
        Name: "minecraft:spruce_stairs"
      }, 
      {
        Properties: {
          half: "top", 
          waterlogged: "false", 
          powered: "false", 
          facing: "east", 
          open: "true"
        }, 
        Name: "minecraft:dark_oak_trapdoor"
      }, 
      {
        Properties: {
          half: "top", 
          waterlogged: "false", 
          shape: "outer_right", 
          facing: "east"
        }, 
        Name: "minecraft:dark_oak_stairs"
      }
    ], 
    [
      {
        Name: "minecraft:spruce_planks"
      }, 
      {
        Properties: {
          half: "top", 
          waterlogged: "false", 
          shape: "outer_right", 
          facing: "south"
        }, 
        Name: "minecraft:spruce_stairs"
      }, 
      {
        Properties: {
          half: "bottom", 
          waterlogged: "false", 
          shape: "outer_right", 
          facing: "north"
        }, 
        Name: "minecraft:spruce_stairs"
      }, 
      {
        Properties: {
          half: "top", 
          waterlogged: "false", 
          shape: "outer_right", 
          facing: "west"
        }, 
        Name: "minecraft:spruce_stairs"
      }, 
      {
        Properties: {
          half: "top", 
          waterlogged: "false", 
          shape: "outer_right", 
          facing: "north"
        }, 
        Name: "minecraft:spruce_stairs"
      }, 
      {
        Name: "minecraft:oak_planks"
      }, 
      {
        Properties: {
          half: "bottom", 
          waterlogged: "false", 
          shape: "outer_right", 
          facing: "east"
        }, 
        Name: "minecraft:spruce_stairs"
      }, 
      {
        Properties: {
          waterlogged: "false", 
          facing: "south", 
          type: "single"
        }, 
        Name: "minecraft:chest"
      }, 
      {
        Properties: {
          east: "false", 
          waterlogged: "false", 
          south: "false", 
          north: "false", 
          west: "false"
        }, 
        Name: "minecraft:oak_fence"
      }, 
      {
        Properties: {
          half: "bottom", 
          waterlogged: "false", 
          shape: "outer_right", 
          facing: "north"
        }, 
        Name: "minecraft:oak_stairs"
      }, 
      {
        Properties: {
          half: "bottom", 
          waterlogged: "false", 
          powered: "false", 
          facing: "east", 
          open: "true"
        }, 
        Name: "minecraft:spruce_trapdoor"
      }, 
      {
        Properties: {
          axis: "x"
        }, 
        Name: "minecraft:spruce_log"
      }, 
      {
        Properties: {
          mode: "data"
        }, 
        Name: "minecraft:structure_block"
      }, 
      {
        Properties: {
          half: "top", 
          waterlogged: "false", 
          shape: "outer_right", 
          facing: "south"
        }, 
        Name: "minecraft:oak_stairs"
      }, 
      {
        Properties: {
          half: "bottom", 
          waterlogged: "false", 
          shape: "outer_right", 
          facing: "south"
        }, 
        Name: "minecraft:spruce_stairs"
      }, 
      {
        Properties: {
          half: "bottom", 
          waterlogged: "false", 
          shape: "outer_right", 
          facing: "west"
        }, 
        Name: "minecraft:spruce_stairs"
      }, 
      {
        Properties: {
          half: "top", 
          waterlogged: "false", 
          shape: "outer_right", 
          facing: "north"
        }, 
        Name: "minecraft:oak_stairs"
      }, 
      {
        Properties: {
          half: "top", 
          waterlogged: "false", 
          powered: "false", 
          facing: "east", 
          open: "true"
        }, 
        Name: "minecraft:spruce_trapdoor"
      }, 
      {
        Properties: {
          half: "top", 
          waterlogged: "false", 
          shape: "outer_right", 
          facing: "east"
        }, 
        Name: "minecraft:spruce_stairs"
      }
    ], 
    [
      {
        Name: "minecraft:spruce_planks"
      }, 
      {
        Properties: {
          half: "top", 
          waterlogged: "false", 
          shape: "outer_right", 
          facing: "south"
        }, 
        Name: "minecraft:spruce_stairs"
      }, 
      {
        Properties: {
          half: "bottom", 
          waterlogged: "false", 
          shape: "outer_right", 
          facing: "north"
        }, 
        Name: "minecraft:spruce_stairs"
      }, 
      {
        Properties: {
          half: "top", 
          waterlogged: "false", 
          shape: "outer_right", 
          facing: "west"
        }, 
        Name: "minecraft:spruce_stairs"
      }, 
      {
        Properties: {
          half: "top", 
          waterlogged: "false", 
          shape: "outer_right", 
          facing: "north"
        }, 
        Name: "minecraft:spruce_stairs"
      }, 
      {
        Name: "minecraft:jungle_planks"
      }, 
      {
        Properties: {
          half: "bottom", 
          waterlogged: "false", 
          shape: "outer_right", 
          facing: "east"
        }, 
        Name: "minecraft:spruce_stairs"
      }, 
      {
        Properties: {
          waterlogged: "false", 
          facing: "south", 
          type: "single"
        }, 
        Name: "minecraft:chest"
      }, 
      {
        Properties: {
          east: "false", 
          waterlogged: "false", 
          south: "false", 
          north: "false", 
          west: "false"
        }, 
        Name: "minecraft:jungle_fence"
      }, 
      {
        Properties: {
          half: "bottom", 
          waterlogged: "false", 
          shape: "outer_right", 
          facing: "north"
        }, 
        Name: "minecraft:jungle_stairs"
      }, 
      {
        Properties: {
          half: "bottom", 
          waterlogged: "false", 
          powered: "false", 
          facing: "east", 
          open: "true"
        }, 
        Name: "minecraft:spruce_trapdoor"
      }, 
      {
        Properties: {
          axis: "x"
        }, 
        Name: "minecraft:spruce_log"
      }, 
      {
        Properties: {
          mode: "data"
        }, 
        Name: "minecraft:structure_block"
      }, 
      {
        Properties: {
          half: "top", 
          waterlogged: "false", 
          shape: "outer_right", 
          facing: "south"
        }, 
        Name: "minecraft:jungle_stairs"
      }, 
      {
        Properties: {
          half: "bottom", 
          waterlogged: "false", 
          shape: "outer_right", 
          facing: "south"
        }, 
        Name: "minecraft:spruce_stairs"
      }, 
      {
        Properties: {
          half: "bottom", 
          waterlogged: "false", 
          shape: "outer_right", 
          facing: "west"
        }, 
        Name: "minecraft:spruce_stairs"
      }, 
      {
        Properties: {
          half: "top", 
          waterlogged: "false", 
          shape: "outer_right", 
          facing: "north"
        }, 
        Name: "minecraft:jungle_stairs"
      }, 
      {
        Properties: {
          half: "top", 
          waterlogged: "false", 
          powered: "false", 
          facing: "east", 
          open: "true"
        }, 
        Name: "minecraft:spruce_trapdoor"
      }, 
      {
        Properties: {
          half: "top", 
          waterlogged: "false", 
          shape: "outer_right", 
          facing: "east"
        }, 
        Name: "minecraft:spruce_stairs"
      }
    ], 
    [
      {
        Name: "minecraft:spruce_planks"
      }, 
      {
        Properties: {
          half: "top", 
          waterlogged: "false", 
          shape: "outer_right", 
          facing: "south"
        }, 
        Name: "minecraft:spruce_stairs"
      }, 
      {
        Properties: {
          half: "bottom", 
          waterlogged: "false", 
          shape: "outer_right", 
          facing: "north"
        }, 
        Name: "minecraft:spruce_stairs"
      }, 
      {
        Properties: {
          half: "top", 
          waterlogged: "false", 
          shape: "outer_right", 
          facing: "west"
        }, 
        Name: "minecraft:spruce_stairs"
      }, 
      {
        Properties: {
          half: "top", 
          waterlogged: "false", 
          shape: "outer_right", 
          facing: "north"
        }, 
        Name: "minecraft:spruce_stairs"
      }, 
      {
        Name: "minecraft:dark_oak_planks"
      }, 
      {
        Properties: {
          half: "bottom", 
          waterlogged: "false", 
          shape: "outer_right", 
          facing: "east"
        }, 
        Name: "minecraft:spruce_stairs"
      }, 
      {
        Properties: {
          waterlogged: "false", 
          facing: "south", 
          type: "single"
        }, 
        Name: "minecraft:chest"
      }, 
      {
        Properties: {
          east: "false", 
          waterlogged: "false", 
          south: "false", 
          north: "false", 
          west: "false"
        }, 
        Name: "minecraft:dark_oak_fence"
      }, 
      {
        Properties: {
          half: "bottom", 
          waterlogged: "false", 
          shape: "outer_right", 
          facing: "north"
        }, 
        Name: "minecraft:dark_oak_stairs"
      }, 
      {
        Properties: {
          half: "bottom", 
          waterlogged: "false", 
          powered: "false", 
          facing: "east", 
          open: "true"
        }, 
        Name: "minecraft:spruce_trapdoor"
      }, 
      {
        Properties: {
          axis: "x"
        }, 
        Name: "minecraft:spruce_log"
      }, 
      {
        Properties: {
          mode: "data"
        }, 
        Name: "minecraft:structure_block"
      }, 
      {
        Properties: {
          half: "top", 
          waterlogged: "false", 
          shape: "outer_right", 
          facing: "south"
        }, 
        Name: "minecraft:dark_oak_stairs"
      }, 
      {
        Properties: {
          half: "bottom", 
          waterlogged: "false", 
          shape: "outer_right", 
          facing: "south"
        }, 
        Name: "minecraft:spruce_stairs"
      }, 
      {
        Properties: {
          half: "bottom", 
          waterlogged: "false", 
          shape: "outer_right", 
          facing: "west"
        }, 
        Name: "minecraft:spruce_stairs"
      }, 
      {
        Properties: {
          half: "top", 
          waterlogged: "false", 
          shape: "outer_right", 
          facing: "north"
        }, 
        Name: "minecraft:dark_oak_stairs"
      }, 
      {
        Properties: {
          half: "top", 
          waterlogged: "false", 
          powered: "false", 
          facing: "east", 
          open: "true"
        }, 
        Name: "minecraft:spruce_trapdoor"
      }, 
      {
        Properties: {
          half: "top", 
          waterlogged: "false", 
          shape: "outer_right", 
          facing: "east"
        }, 
        Name: "minecraft:spruce_stairs"
      }
    ], 
    [
      {
        Name: "minecraft:oak_planks"
      }, 
      {
        Properties: {
          half: "top", 
          waterlogged: "false", 
          shape: "outer_right", 
          facing: "south"
        }, 
        Name: "minecraft:oak_stairs"
      }, 
      {
        Properties: {
          half: "bottom", 
          waterlogged: "false", 
          shape: "outer_right", 
          facing: "north"
        }, 
        Name: "minecraft:oak_stairs"
      }, 
      {
        Properties: {
          half: "top", 
          waterlogged: "false", 
          shape: "outer_right", 
          facing: "west"
        }, 
        Name: "minecraft:oak_stairs"
      }, 
      {
        Properties: {
          half: "top", 
          waterlogged: "false", 
          shape: "outer_right", 
          facing: "north"
        }, 
        Name: "minecraft:oak_stairs"
      }, 
      {
        Name: "minecraft:birch_planks"
      }, 
      {
        Properties: {
          half: "bottom", 
          waterlogged: "false", 
          shape: "outer_right", 
          facing: "east"
        }, 
        Name: "minecraft:oak_stairs"
      }, 
      {
        Properties: {
          waterlogged: "false", 
          facing: "south", 
          type: "single"
        }, 
        Name: "minecraft:chest"
      }, 
      {
        Properties: {
          east: "false", 
          waterlogged: "false", 
          south: "false", 
          north: "false", 
          west: "false"
        }, 
        Name: "minecraft:birch_fence"
      }, 
      {
        Properties: {
          half: "bottom", 
          waterlogged: "false", 
          shape: "outer_right", 
          facing: "north"
        }, 
        Name: "minecraft:birch_stairs"
      }, 
      {
        Properties: {
          half: "bottom", 
          waterlogged: "false", 
          powered: "false", 
          facing: "east", 
          open: "true"
        }, 
        Name: "minecraft:oak_trapdoor"
      }, 
      {
        Properties: {
          axis: "x"
        }, 
        Name: "minecraft:oak_log"
      }, 
      {
        Properties: {
          mode: "data"
        }, 
        Name: "minecraft:structure_block"
      }, 
      {
        Properties: {
          half: "top", 
          waterlogged: "false", 
          shape: "outer_right", 
          facing: "south"
        }, 
        Name: "minecraft:birch_stairs"
      }, 
      {
        Properties: {
          half: "bottom", 
          waterlogged: "false", 
          shape: "outer_right", 
          facing: "south"
        }, 
        Name: "minecraft:oak_stairs"
      }, 
      {
        Properties: {
          half: "bottom", 
          waterlogged: "false", 
          shape: "outer_right", 
          facing: "west"
        }, 
        Name: "minecraft:oak_stairs"
      }, 
      {
        Properties: {
          half: "top", 
          waterlogged: "false", 
          shape: "outer_right", 
          facing: "north"
        }, 
        Name: "minecraft:birch_stairs"
      }, 
      {
        Properties: {
          half: "top", 
          waterlogged: "false", 
          powered: "false", 
          facing: "east", 
          open: "true"
        }, 
        Name: "minecraft:oak_trapdoor"
      }, 
      {
        Properties: {
          half: "top", 
          waterlogged: "false", 
          shape: "outer_right", 
          facing: "east"
        }, 
        Name: "minecraft:oak_stairs"
      }
    ]
  ]
}
