{
  size: [9, 9, 22], 
  entities: [], 
  author: "CascadianBacon", 
  blocks: [
    {
      pos: [4, 1, 2], 
      state: 0
    }, 
    {
      pos: [4, 2, 3], 
      state: 0
    }, 
    {
      pos: [4, 3, 3], 
      state: 0
    }, 
    {
      pos: [3, 2, 4], 
      state: 1
    }, 
    {
      pos: [5, 2, 4], 
      state: 1
    }, 
    {
      pos: [3, 3, 4], 
      state: 1
    }, 
    {
      pos: [4, 3, 4], 
      state: 1
    }, 
    {
      pos: [5, 3, 4], 
      state: 1
    }, 
    {
      pos: [4, 4, 4], 
      state: 0
    }, 
    {
      pos: [2, 2, 5], 
      state: 1
    }, 
    {
      pos: [6, 2, 5], 
      state: 1
    }, 
    {
      pos: [2, 3, 5], 
      state: 1
    }, 
    {
      pos: [3, 3, 5], 
      state: 0
    }, 
    {
      pos: [4, 3, 5], 
      state: 0
    }, 
    {
      pos: [5, 3, 5], 
      state: 0
    }, 
    {
      pos: [6, 3, 5], 
      state: 1
    }, 
    {
      pos: [3, 4, 5], 
      state: 1
    }, 
    {
      pos: [4, 4, 5], 
      state: 1
    }, 
    {
      pos: [5, 4, 5], 
      state: 1
    }, 
    {
      pos: [4, 5, 5], 
      state: 1
    }, 
    {
      pos: [1, 2, 6], 
      state: 1
    }, 
    {
      pos: [7, 2, 6], 
      state: 1
    }, 
    {
      pos: [2, 3, 6], 
      state: 0
    }, 
    {
      pos: [3, 3, 6], 
      state: 0
    }, 
    {
      pos: [4, 3, 6], 
      state: 0
    }, 
    {
      pos: [5, 3, 6], 
      state: 0
    }, 
    {
      pos: [6, 3, 6], 
      state: 0
    }, 
    {
      pos: [3, 4, 6], 
      state: 1
    }, 
    {
      pos: [4, 4, 6], 
      state: 1
    }, 
    {
      pos: [5, 4, 6], 
      state: 1
    }, 
    {
      pos: [4, 5, 6], 
      state: 1
    }, 
    {
      pos: [4, 6, 6], 
      state: 0
    }, 
    {
      pos: [1, 2, 7], 
      state: 1
    }, 
    {
      pos: [7, 2, 7], 
      state: 1
    }, 
    {
      pos: [1, 3, 7], 
      state: 1
    }, 
    {
      pos: [2, 3, 7], 
      state: 0
    }, 
    {
      pos: [4, 3, 7], 
      state: 2
    }, 
    {
      pos: [6, 3, 7], 
      state: 0
    }, 
    {
      pos: [7, 3, 7], 
      state: 1
    }, 
    {
      pos: [2, 4, 7], 
      state: 1
    }, 
    {
      pos: [3, 4, 7], 
      state: 1
    }, 
    {
      pos: [4, 4, 7], 
      state: 2
    }, 
    {
      pos: [5, 4, 7], 
      state: 1
    }, 
    {
      pos: [6, 4, 7], 
      state: 1
    }, 
    {
      pos: [3, 5, 7], 
      state: 1
    }, 
    {
      pos: [4, 5, 7], 
      state: 1
    }, 
    {
      pos: [5, 5, 7], 
      state: 1
    }, 
    {
      pos: [4, 6, 7], 
      state: 1
    }, 
    {
      pos: [4, 7, 7], 
      state: 0
    }, 
    {
      pos: [0, 2, 8], 
      state: 1
    }, 
    {
      pos: [8, 2, 8], 
      state: 1
    }, 
    {
      pos: [1, 3, 8], 
      state: 1
    }, 
    {
      pos: [7, 3, 8], 
      state: 1
    }, 
    {
      pos: [1, 4, 8], 
      state: 1
    }, 
    {
      pos: [2, 4, 8], 
      state: 0
    }, 
    {
      pos: [4, 4, 8], 
      state: 0
    }, 
    {
      pos: [6, 4, 8], 
      state: 0
    }, 
    {
      pos: [7, 4, 8], 
      state: 1
    }, 
    {
      pos: [2, 5, 8], 
      state: 1
    }, 
    {
      pos: [6, 5, 8], 
      state: 1
    }, 
    {
      pos: [3, 6, 8], 
      state: 1
    }, 
    {
      pos: [5, 6, 8], 
      state: 1
    }, 
    {
      pos: [4, 7, 8], 
      state: 1
    }, 
    {
      pos: [0, 3, 9], 
      state: 1
    }, 
    {
      pos: [8, 3, 9], 
      state: 1
    }, 
    {
      pos: [1, 4, 9], 
      state: 0
    }, 
    {
      pos: [2, 4, 9], 
      state: 0
    }, 
    {
      pos: [6, 4, 9], 
      state: 0
    }, 
    {
      pos: [7, 4, 9], 
      state: 0
    }, 
    {
      pos: [1, 5, 9], 
      state: 1
    }, 
    {
      pos: [2, 5, 9], 
      state: 1
    }, 
    {
      pos: [6, 5, 9], 
      state: 1
    }, 
    {
      pos: [7, 5, 9], 
      state: 1
    }, 
    {
      pos: [2, 6, 9], 
      state: 1
    }, 
    {
      pos: [6, 6, 9], 
      state: 1
    }, 
    {
      pos: [3, 7, 9], 
      state: 1
    }, 
    {
      pos: [4, 7, 9], 
      state: 1
    }, 
    {
      pos: [5, 7, 9], 
      state: 1
    }, 
    {
      pos: [4, 8, 9], 
      state: 0
    }, 
    {
      pos: [0, 3, 10], 
      state: 1
    }, 
    {
      pos: [8, 3, 10], 
      state: 1
    }, 
    {
      pos: [1, 4, 10], 
      state: 0
    }, 
    {
      pos: [2, 4, 10], 
      state: 0
    }, 
    {
      pos: [6, 4, 10], 
      state: 0
    }, 
    {
      pos: [7, 4, 10], 
      state: 0
    }, 
    {
      pos: [1, 5, 10], 
      state: 1
    }, 
    {
      pos: [2, 5, 10], 
      state: 1
    }, 
    {
      pos: [6, 5, 10], 
      state: 1
    }, 
    {
      pos: [7, 5, 10], 
      state: 1
    }, 
    {
      pos: [2, 6, 10], 
      state: 1
    }, 
    {
      pos: [6, 6, 10], 
      state: 1
    }, 
    {
      pos: [3, 7, 10], 
      state: 1
    }, 
    {
      pos: [4, 7, 10], 
      state: 1
    }, 
    {
      pos: [5, 7, 10], 
      state: 1
    }, 
    {
      pos: [4, 8, 10], 
      state: 0
    }, 
    {
      pos: [4, 3, 11], 
      state: 2
    }, 
    {
      pos: [1, 4, 11], 
      state: 0
    }, 
    {
      pos: [2, 4, 11], 
      state: 0
    }, 
    {
      pos: [3, 4, 11], 
      state: 0
    }, 
    {
      pos: [4, 4, 11], 
      state: 2
    }, 
    {
      pos: [5, 4, 11], 
      state: 0
    }, 
    {
      pos: [6, 4, 11], 
      state: 0
    }, 
    {
      pos: [7, 4, 11], 
      state: 0
    }, 
    {
      pos: [1, 5, 11], 
      state: 1
    }, 
    {
      pos: [2, 5, 11], 
      state: 1
    }, 
    {
      pos: [4, 5, 11], 
      state: 2
    }, 
    {
      pos: [6, 5, 11], 
      state: 1
    }, 
    {
      pos: [7, 5, 11], 
      state: 1
    }, 
    {
      pos: [2, 6, 11], 
      state: 1
    }, 
    {
      pos: [4, 6, 11], 
      state: 2
    }, 
    {
      pos: [6, 6, 11], 
      state: 1
    }, 
    {
      pos: [3, 7, 11], 
      state: 1
    }, 
    {
      pos: [4, 7, 11], 
      state: 1
    }, 
    {
      pos: [5, 7, 11], 
      state: 1
    }, 
    {
      pos: [1, 4, 12], 
      state: 0
    }, 
    {
      pos: [7, 4, 12], 
      state: 0
    }, 
    {
      pos: [5, 7, 12], 
      state: 1
    }, 
    {
      pos: [1, 4, 13], 
      state: 0
    }, 
    {
      pos: [6, 4, 13], 
      state: 0
    }, 
    {
      pos: [7, 4, 13], 
      state: 0
    }, 
    {
      pos: [6, 5, 13], 
      state: 1
    }, 
    {
      pos: [7, 5, 13], 
      state: 1
    }, 
    {
      pos: [6, 6, 13], 
      state: 1
    }, 
    {
      pos: [4, 7, 13], 
      state: 1
    }, 
    {
      pos: [5, 7, 13], 
      state: 1
    }, 
    {
      pos: [4, 8, 13], 
      state: 0
    }, 
    {
      pos: [6, 4, 14], 
      state: 0
    }, 
    {
      pos: [7, 4, 14], 
      state: 0
    }, 
    {
      pos: [6, 5, 14], 
      state: 1
    }, 
    {
      pos: [7, 5, 14], 
      state: 1
    }, 
    {
      pos: [6, 6, 14], 
      state: 1
    }, 
    {
      pos: [3, 7, 14], 
      state: 1
    }, 
    {
      pos: [4, 7, 14], 
      state: 1
    }, 
    {
      pos: [5, 7, 14], 
      state: 1
    }, 
    {
      pos: [4, 8, 14], 
      state: 0
    }, 
    {
      pos: [7, 4, 15], 
      state: 0
    }, 
    {
      pos: [3, 7, 15], 
      state: 1
    }, 
    {
      pos: [4, 7, 15], 
      state: 1
    }, 
    {
      pos: [5, 7, 15], 
      state: 1
    }, 
    {
      pos: [4, 8, 15], 
      state: 0
    }, 
    {
      pos: [4, 4, 16], 
      state: 2
    }, 
    {
      pos: [5, 4, 16], 
      state: 0
    }, 
    {
      pos: [3, 5, 16], 
      state: 1
    }, 
    {
      pos: [4, 5, 16], 
      state: 2
    }, 
    {
      pos: [6, 5, 16], 
      state: 1
    }, 
    {
      pos: [7, 5, 16], 
      state: 1
    }, 
    {
      pos: [2, 6, 16], 
      state: 1
    }, 
    {
      pos: [3, 6, 16], 
      state: 1
    }, 
    {
      pos: [4, 6, 16], 
      state: 2
    }, 
    {
      pos: [6, 6, 16], 
      state: 1
    }, 
    {
      pos: [3, 7, 16], 
      state: 1
    }, 
    {
      pos: [4, 7, 16], 
      state: 1
    }, 
    {
      pos: [5, 7, 16], 
      state: 1
    }, 
    {
      pos: [4, 8, 16], 
      state: 0
    }, 
    {
      pos: [3, 4, 17], 
      state: 0
    }, 
    {
      pos: [4, 4, 17], 
      state: 0
    }, 
    {
      pos: [2, 5, 17], 
      state: 1
    }, 
    {
      pos: [6, 5, 17], 
      state: 1
    }, 
    {
      pos: [7, 5, 17], 
      state: 1
    }, 
    {
      pos: [2, 6, 17], 
      state: 1
    }, 
    {
      pos: [6, 6, 17], 
      state: 1
    }, 
    {
      pos: [3, 7, 17], 
      state: 1
    }, 
    {
      pos: [4, 7, 17], 
      state: 1
    }, 
    {
      pos: [5, 7, 17], 
      state: 1
    }, 
    {
      pos: [4, 8, 17], 
      state: 0
    }, 
    {
      pos: [3, 7, 18], 
      state: 1
    }, 
    {
      pos: [4, 7, 18], 
      state: 1
    }, 
    {
      pos: [5, 7, 18], 
      state: 1
    }, 
    {
      pos: [4, 8, 18], 
      state: 0
    }, 
    {
      pos: [3, 7, 19], 
      state: 1
    }, 
    {
      pos: [4, 7, 19], 
      state: 1
    }, 
    {
      pos: [5, 7, 19], 
      state: 1
    }, 
    {
      pos: [4, 8, 19], 
      state: 0
    }, 
    {
      pos: [5, 7, 20], 
      state: 1
    }, 
    {
      pos: [4, 8, 20], 
      state: 0
    }, 
    {
      nbt: {
        Items: [], 
        id: "minecraft:chest", 
        Lock: ""
      }, 
      pos: [4, 5, 8], 
      state: 3
    }, 
    {
      nbt: {
        metadata: "supply_chest", 
        mirror: "NONE", 
        ignoreEntities: 1b, 
        powered: 0b, 
        seed: 0L, 
        author: "CascadianBacon", 
        rotation: "NONE", 
        mode: "DATA", 
        posX: 0, 
        posY: 1, 
        sizeX: 0, 
        integrity: 1.0f, 
        posZ: 0, 
        showair: 0b, 
        name: "", 
        id: "minecraft:structure_block", 
        sizeY: 0, 
        showboundingbox: 1b, 
        sizeZ: 0
      }, 
      pos: [4, 6, 8], 
      state: 4
    }, 
    {
      nbt: {
        Items: [], 
        id: "minecraft:chest", 
        Lock: ""
      }, 
      pos: [3, 5, 17], 
      state: 5
    }, 
    {
      nbt: {
        metadata: "map_chest", 
        mirror: "NONE", 
        ignoreEntities: 1b, 
        powered: 0b, 
        seed: 0L, 
        author: "CascadianBacon", 
        rotation: "NONE", 
        mode: "DATA", 
        posX: 0, 
        posY: 1, 
        sizeX: 0, 
        integrity: 1.0f, 
        posZ: 0, 
        showair: 0b, 
        name: "", 
        id: "minecraft:structure_block", 
        sizeY: 0, 
        showboundingbox: 1b, 
        sizeZ: 0
      }, 
      pos: [3, 6, 17], 
      state: 4
    }, 
    {
      pos: [4, 0, 0], 
      state: 6
    }, 
    {
      pos: [4, 0, 1], 
      state: 7
    }, 
    {
      pos: [4, 1, 1], 
      state: 6
    }, 
    {
      pos: [3, 1, 2], 
      state: 8
    }, 
    {
      pos: [5, 1, 2], 
      state: 8
    }, 
    {
      pos: [3, 2, 2], 
      state: 8
    }, 
    {
      pos: [4, 2, 2], 
      state: 6
    }, 
    {
      pos: [5, 2, 2], 
      state: 8
    }, 
    {
      pos: [3, 1, 3], 
      state: 8
    }, 
    {
      pos: [4, 1, 3], 
      state: 7
    }, 
    {
      pos: [5, 1, 3], 
      state: 8
    }, 
    {
      pos: [3, 2, 3], 
      state: 9
    }, 
    {
      pos: [5, 2, 3], 
      state: 9
    }, 
    {
      pos: [4, 4, 3], 
      state: 6
    }, 
    {
      pos: [3, 1, 4], 
      state: 8
    }, 
    {
      pos: [5, 1, 4], 
      state: 8
    }, 
    {
      pos: [4, 2, 4], 
      state: 7
    }, 
    {
      pos: [3, 4, 4], 
      state: 9
    }, 
    {
      pos: [5, 4, 4], 
      state: 9
    }, 
    {
      pos: [4, 5, 4], 
      state: 6
    }, 
    {
      pos: [2, 4, 5], 
      state: 10
    }, 
    {
      pos: [6, 4, 5], 
      state: 11
    }, 
    {
      pos: [3, 5, 5], 
      state: 10
    }, 
    {
      pos: [5, 5, 5], 
      state: 11
    }, 
    {
      pos: [4, 6, 5], 
      state: 6
    }, 
    {
      pos: [1, 3, 6], 
      state: 10
    }, 
    {
      pos: [7, 3, 6], 
      state: 11
    }, 
    {
      pos: [2, 4, 6], 
      state: 10
    }, 
    {
      pos: [6, 4, 6], 
      state: 11
    }, 
    {
      pos: [3, 5, 6], 
      state: 10
    }, 
    {
      pos: [5, 5, 6], 
      state: 11
    }, 
    {
      pos: [4, 7, 6], 
      state: 6
    }, 
    {
      pos: [3, 3, 7], 
      state: 7
    }, 
    {
      pos: [5, 3, 7], 
      state: 7
    }, 
    {
      pos: [1, 4, 7], 
      state: 10
    }, 
    {
      pos: [7, 4, 7], 
      state: 11
    }, 
    {
      pos: [2, 5, 7], 
      state: 10
    }, 
    {
      pos: [6, 5, 7], 
      state: 11
    }, 
    {
      pos: [3, 6, 7], 
      state: 10
    }, 
    {
      pos: [5, 6, 7], 
      state: 11
    }, 
    {
      pos: [1, 2, 8], 
      state: 12
    }, 
    {
      pos: [7, 2, 8], 
      state: 12
    }, 
    {
      pos: [0, 3, 8], 
      state: 9
    }, 
    {
      pos: [8, 3, 8], 
      state: 9
    }, 
    {
      pos: [3, 4, 8], 
      state: 13
    }, 
    {
      pos: [5, 4, 8], 
      state: 13
    }, 
    {
      pos: [1, 5, 8], 
      state: 10
    }, 
    {
      pos: [7, 5, 8], 
      state: 11
    }, 
    {
      pos: [2, 6, 8], 
      state: 10
    }, 
    {
      pos: [6, 6, 8], 
      state: 11
    }, 
    {
      pos: [3, 7, 8], 
      state: 10
    }, 
    {
      pos: [5, 7, 8], 
      state: 11
    }, 
    {
      pos: [4, 8, 8], 
      state: 6
    }, 
    {
      pos: [0, 2, 9], 
      state: 12
    }, 
    {
      pos: [8, 2, 9], 
      state: 12
    }, 
    {
      pos: [0, 4, 9], 
      state: 10
    }, 
    {
      pos: [3, 4, 9], 
      state: 14
    }, 
    {
      pos: [5, 4, 9], 
      state: 15
    }, 
    {
      pos: [8, 4, 9], 
      state: 11
    }, 
    {
      pos: [1, 6, 9], 
      state: 10
    }, 
    {
      pos: [7, 6, 9], 
      state: 11
    }, 
    {
      pos: [2, 7, 9], 
      state: 10
    }, 
    {
      pos: [6, 7, 9], 
      state: 11
    }, 
    {
      pos: [0, 4, 10], 
      state: 10
    }, 
    {
      pos: [3, 4, 10], 
      state: 14
    }, 
    {
      pos: [5, 4, 10], 
      state: 15
    }, 
    {
      pos: [8, 4, 10], 
      state: 11
    }, 
    {
      pos: [1, 6, 10], 
      state: 10
    }, 
    {
      pos: [7, 6, 10], 
      state: 11
    }, 
    {
      pos: [2, 7, 10], 
      state: 10
    }, 
    {
      pos: [6, 7, 10], 
      state: 11
    }, 
    {
      pos: [0, 4, 11], 
      state: 10
    }, 
    {
      pos: [8, 4, 11], 
      state: 11
    }, 
    {
      pos: [1, 6, 11], 
      state: 10
    }, 
    {
      pos: [7, 6, 11], 
      state: 11
    }, 
    {
      pos: [2, 7, 11], 
      state: 10
    }, 
    {
      pos: [6, 7, 11], 
      state: 11
    }, 
    {
      pos: [0, 4, 12], 
      state: 10
    }, 
    {
      pos: [2, 4, 12], 
      state: 16
    }, 
    {
      pos: [3, 4, 12], 
      state: 17
    }, 
    {
      pos: [4, 4, 12], 
      state: 17
    }, 
    {
      pos: [5, 4, 12], 
      state: 17
    }, 
    {
      pos: [6, 4, 12], 
      state: 18
    }, 
    {
      pos: [8, 4, 12], 
      state: 11
    }, 
    {
      pos: [2, 6, 12], 
      state: 19
    }, 
    {
      pos: [6, 6, 12], 
      state: 20
    }, 
    {
      pos: [7, 6, 12], 
      state: 11
    }, 
    {
      pos: [2, 7, 12], 
      state: 10
    }, 
    {
      pos: [6, 7, 12], 
      state: 11
    }, 
    {
      pos: [0, 4, 13], 
      state: 10
    }, 
    {
      pos: [5, 4, 13], 
      state: 15
    }, 
    {
      pos: [8, 4, 13], 
      state: 11
    }, 
    {
      pos: [7, 6, 13], 
      state: 11
    }, 
    {
      pos: [6, 7, 13], 
      state: 11
    }, 
    {
      pos: [5, 4, 14], 
      state: 15
    }, 
    {
      pos: [8, 4, 14], 
      state: 11
    }, 
    {
      pos: [7, 6, 14], 
      state: 11
    }, 
    {
      pos: [6, 7, 14], 
      state: 11
    }, 
    {
      pos: [4, 4, 15], 
      state: 21
    }, 
    {
      pos: [5, 4, 15], 
      state: 21
    }, 
    {
      pos: [6, 4, 15], 
      state: 18
    }, 
    {
      pos: [8, 4, 15], 
      state: 11
    }, 
    {
      pos: [6, 6, 15], 
      state: 20
    }, 
    {
      pos: [7, 6, 15], 
      state: 11
    }, 
    {
      pos: [2, 7, 15], 
      state: 10
    }, 
    {
      pos: [6, 7, 15], 
      state: 11
    }, 
    {
      pos: [7, 6, 16], 
      state: 11
    }, 
    {
      pos: [2, 7, 16], 
      state: 10
    }, 
    {
      pos: [6, 7, 16], 
      state: 11
    }, 
    {
      pos: [7, 6, 17], 
      state: 11
    }, 
    {
      pos: [2, 7, 17], 
      state: 10
    }, 
    {
      pos: [6, 7, 17], 
      state: 11
    }, 
    {
      pos: [4, 4, 18], 
      state: 7
    }, 
    {
      pos: [6, 6, 18], 
      state: 20
    }, 
    {
      pos: [7, 6, 18], 
      state: 11
    }, 
    {
      pos: [2, 7, 18], 
      state: 10
    }, 
    {
      pos: [6, 7, 18], 
      state: 11
    }, 
    {
      pos: [7, 6, 19], 
      state: 11
    }, 
    {
      pos: [6, 7, 19], 
      state: 11
    }, 
    {
      pos: [7, 6, 20], 
      state: 11
    }, 
    {
      pos: [4, 8, 21], 
      state: 13
    }
  ], 
  palettes: [
    [
      {
        Name: "minecraft:spruce_planks"
      }, 
      {
        Name: "minecraft:oak_planks"
      }, 
      {
        Properties: {
          axis: "y"
        }, 
        Name: "minecraft:oak_log"
      }, 
      {
        Properties: {
          facing: "south", 
          type: "single"
        }, 
        Name: "minecraft:chest"
      }, 
      {
        Properties: {
          mode: "data"
        }, 
        Name: "minecraft:structure_block"
      }, 
      {
        Properties: {
          facing: "east", 
          type: "single"
        }, 
        Name: "minecraft:chest"
      }, 
      {
        Properties: {
          half: "bottom", 
          shape: "outer_right", 
          facing: "south"
        }, 
        Name: "minecraft:spruce_stairs"
      }, 
      {
        Properties: {
          half: "top", 
          shape: "outer_right", 
          facing: "north"
        }, 
        Name: "minecraft:spruce_stairs"
      }, 
      {
        Properties: {
          east: "false", 
          south: "false", 
          north: "false", 
          west: "false"
        }, 
        Name: "minecraft:spruce_fence"
      }, 
      {
        Properties: {
          half: "bottom", 
          shape: "outer_right", 
          facing: "south"
        }, 
        Name: "minecraft:oak_stairs"
      }, 
      {
        Properties: {
          half: "bottom", 
          shape: "outer_right", 
          facing: "east"
        }, 
        Name: "minecraft:oak_stairs"
      }, 
      {
        Properties: {
          half: "bottom", 
          shape: "outer_right", 
          facing: "west"
        }, 
        Name: "minecraft:oak_stairs"
      }, 
      {
        Properties: {
          half: "top", 
          shape: "outer_right", 
          facing: "north"
        }, 
        Name: "minecraft:oak_stairs"
      }, 
      {
        Properties: {
          half: "bottom", 
          shape: "outer_right", 
          facing: "north"
        }, 
        Name: "minecraft:spruce_stairs"
      }, 
      {
        Properties: {
          half: "bottom", 
          powered: "false", 
          facing: "east", 
          open: "false"
        }, 
        Name: "minecraft:oak_trapdoor"
      }, 
      {
        Properties: {
          half: "bottom", 
          powered: "false", 
          facing: "west", 
          open: "false"
        }, 
        Name: "minecraft:oak_trapdoor"
      }, 
      {
        Properties: {
          half: "bottom", 
          shape: "outer_right", 
          facing: "west"
        }, 
        Name: "minecraft:spruce_stairs"
      }, 
      {
        Properties: {
          half: "bottom", 
          powered: "false", 
          facing: "south", 
          open: "false"
        }, 
        Name: "minecraft:oak_trapdoor"
      }, 
      {
        Properties: {
          half: "bottom", 
          shape: "outer_right", 
          facing: "east"
        }, 
        Name: "minecraft:spruce_stairs"
      }, 
      {
        Properties: {
          half: "top", 
          shape: "outer_right", 
          facing: "west"
        }, 
        Name: "minecraft:oak_stairs"
      }, 
      {
        Properties: {
          half: "top", 
          shape: "outer_right", 
          facing: "east"
        }, 
        Name: "minecraft:oak_stairs"
      }, 
      {
        Properties: {
          half: "bottom", 
          powered: "false", 
          facing: "north", 
          open: "false"
        }, 
        Name: "minecraft:oak_trapdoor"
      }
    ], 
    [
      {
        Name: "minecraft:spruce_planks"
      }, 
      {
        Name: "minecraft:jungle_planks"
      }, 
      {
        Properties: {
          axis: "y"
        }, 
        Name: "minecraft:jungle_log"
      }, 
      {
        Properties: {
          facing: "south", 
          type: "single"
        }, 
        Name: "minecraft:chest"
      }, 
      {
        Properties: {
          mode: "data"
        }, 
        Name: "minecraft:structure_block"
      }, 
      {
        Properties: {
          facing: "east", 
          type: "single"
        }, 
        Name: "minecraft:chest"
      }, 
      {
        Properties: {
          half: "bottom", 
          shape: "outer_right", 
          facing: "south"
        }, 
        Name: "minecraft:spruce_stairs"
      }, 
      {
        Properties: {
          half: "top", 
          shape: "outer_right", 
          facing: "north"
        }, 
        Name: "minecraft:spruce_stairs"
      }, 
      {
        Properties: {
          east: "false", 
          south: "false", 
          north: "false", 
          west: "false"
        }, 
        Name: "minecraft:spruce_fence"
      }, 
      {
        Properties: {
          half: "bottom", 
          shape: "outer_right", 
          facing: "south"
        }, 
        Name: "minecraft:jungle_stairs"
      }, 
      {
        Properties: {
          half: "bottom", 
          shape: "outer_right", 
          facing: "east"
        }, 
        Name: "minecraft:jungle_stairs"
      }, 
      {
        Properties: {
          half: "bottom", 
          shape: "outer_right", 
          facing: "west"
        }, 
        Name: "minecraft:jungle_stairs"
      }, 
      {
        Properties: {
          half: "top", 
          shape: "outer_right", 
          facing: "north"
        }, 
        Name: "minecraft:jungle_stairs"
      }, 
      {
        Properties: {
          half: "bottom", 
          shape: "outer_right", 
          facing: "north"
        }, 
        Name: "minecraft:spruce_stairs"
      }, 
      {
        Properties: {
          half: "bottom", 
          powered: "false", 
          facing: "east", 
          open: "false"
        }, 
        Name: "minecraft:jungle_trapdoor"
      }, 
      {
        Properties: {
          half: "bottom", 
          powered: "false", 
          facing: "west", 
          open: "false"
        }, 
        Name: "minecraft:jungle_trapdoor"
      }, 
      {
        Properties: {
          half: "bottom", 
          shape: "outer_right", 
          facing: "west"
        }, 
        Name: "minecraft:spruce_stairs"
      }, 
      {
        Properties: {
          half: "bottom", 
          powered: "false", 
          facing: "south", 
          open: "false"
        }, 
        Name: "minecraft:jungle_trapdoor"
      }, 
      {
        Properties: {
          half: "bottom", 
          shape: "outer_right", 
          facing: "east"
        }, 
        Name: "minecraft:spruce_stairs"
      }, 
      {
        Properties: {
          half: "top", 
          shape: "outer_right", 
          facing: "west"
        }, 
        Name: "minecraft:jungle_stairs"
      }, 
      {
        Properties: {
          half: "top", 
          shape: "outer_right", 
          facing: "east"
        }, 
        Name: "minecraft:jungle_stairs"
      }, 
      {
        Properties: {
          half: "bottom", 
          powered: "false", 
          facing: "north", 
          open: "false"
        }, 
        Name: "minecraft:jungle_trapdoor"
      }
    ], 
    [
      {
        Name: "minecraft:jungle_planks"
      }, 
      {
        Name: "minecraft:dark_oak_planks"
      }, 
      {
        Properties: {
          axis: "y"
        }, 
        Name: "minecraft:dark_oak_log"
      }, 
      {
        Properties: {
          facing: "south", 
          type: "single"
        }, 
        Name: "minecraft:chest"
      }, 
      {
        Properties: {
          mode: "data"
        }, 
        Name: "minecraft:structure_block"
      }, 
      {
        Properties: {
          facing: "east", 
          type: "single"
        }, 
        Name: "minecraft:chest"
      }, 
      {
        Properties: {
          half: "bottom", 
          shape: "outer_right", 
          facing: "south"
        }, 
        Name: "minecraft:jungle_stairs"
      }, 
      {
        Properties: {
          half: "top", 
          shape: "outer_right", 
          facing: "north"
        }, 
        Name: "minecraft:jungle_stairs"
      }, 
      {
        Properties: {
          east: "false", 
          south: "false", 
          north: "false", 
          west: "false"
        }, 
        Name: "minecraft:jungle_fence"
      }, 
      {
        Properties: {
          half: "bottom", 
          shape: "outer_right", 
          facing: "south"
        }, 
        Name: "minecraft:dark_oak_stairs"
      }, 
      {
        Properties: {
          half: "bottom", 
          shape: "outer_right", 
          facing: "east"
        }, 
        Name: "minecraft:dark_oak_stairs"
      }, 
      {
        Properties: {
          half: "bottom", 
          shape: "outer_right", 
          facing: "west"
        }, 
        Name: "minecraft:dark_oak_stairs"
      }, 
      {
        Properties: {
          half: "top", 
          shape: "outer_right", 
          facing: "north"
        }, 
        Name: "minecraft:dark_oak_stairs"
      }, 
      {
        Properties: {
          half: "bottom", 
          shape: "outer_right", 
          facing: "north"
        }, 
        Name: "minecraft:jungle_stairs"
      }, 
      {
        Properties: {
          half: "bottom", 
          powered: "false", 
          facing: "east", 
          open: "false"
        }, 
        Name: "minecraft:dark_oak_trapdoor"
      }, 
      {
        Properties: {
          half: "bottom", 
          powered: "false", 
          facing: "west", 
          open: "false"
        }, 
        Name: "minecraft:dark_oak_trapdoor"
      }, 
      {
        Properties: {
          half: "bottom", 
          shape: "outer_right", 
          facing: "west"
        }, 
        Name: "minecraft:jungle_stairs"
      }, 
      {
        Properties: {
          half: "bottom", 
          powered: "false", 
          facing: "south", 
          open: "false"
        }, 
        Name: "minecraft:dark_oak_trapdoor"
      }, 
      {
        Properties: {
          half: "bottom", 
          shape: "outer_right", 
          facing: "east"
        }, 
        Name: "minecraft:jungle_stairs"
      }, 
      {
        Properties: {
          half: "top", 
          shape: "outer_right", 
          facing: "west"
        }, 
        Name: "minecraft:dark_oak_stairs"
      }, 
      {
        Properties: {
          half: "top", 
          shape: "outer_right", 
          facing: "east"
        }, 
        Name: "minecraft:dark_oak_stairs"
      }, 
      {
        Properties: {
          half: "bottom", 
          powered: "false", 
          facing: "north", 
          open: "false"
        }, 
        Name: "minecraft:dark_oak_trapdoor"
      }
    ], 
    [
      {
        Name: "minecraft:spruce_planks"
      }, 
      {
        Name: "minecraft:dark_oak_planks"
      }, 
      {
        Properties: {
          axis: "y"
        }, 
        Name: "minecraft:dark_oak_log"
      }, 
      {
        Properties: {
          facing: "south", 
          type: "single"
        }, 
        Name: "minecraft:chest"
      }, 
      {
        Properties: {
          mode: "data"
        }, 
        Name: "minecraft:structure_block"
      }, 
      {
        Properties: {
          facing: "east", 
          type: "single"
        }, 
        Name: "minecraft:chest"
      }, 
      {
        Properties: {
          half: "bottom", 
          shape: "outer_right", 
          facing: "south"
        }, 
        Name: "minecraft:spruce_stairs"
      }, 
      {
        Properties: {
          half: "top", 
          shape: "outer_right", 
          facing: "north"
        }, 
        Name: "minecraft:spruce_stairs"
      }, 
      {
        Properties: {
          east: "false", 
          south: "false", 
          north: "false", 
          west: "false"
        }, 
        Name: "minecraft:spruce_fence"
      }, 
      {
        Properties: {
          half: "bottom", 
          shape: "outer_right", 
          facing: "south"
        }, 
        Name: "minecraft:dark_oak_stairs"
      }, 
      {
        Properties: {
          half: "bottom", 
          shape: "outer_right", 
          facing: "east"
        }, 
        Name: "minecraft:dark_oak_stairs"
      }, 
      {
        Properties: {
          half: "bottom", 
          shape: "outer_right", 
          facing: "west"
        }, 
        Name: "minecraft:dark_oak_stairs"
      }, 
      {
        Properties: {
          half: "top", 
          shape: "outer_right", 
          facing: "north"
        }, 
        Name: "minecraft:dark_oak_stairs"
      }, 
      {
        Properties: {
          half: "bottom", 
          shape: "outer_right", 
          facing: "north"
        }, 
        Name: "minecraft:spruce_stairs"
      }, 
      {
        Properties: {
          half: "bottom", 
          powered: "false", 
          facing: "east", 
          open: "false"
        }, 
        Name: "minecraft:dark_oak_trapdoor"
      }, 
      {
        Properties: {
          half: "bottom", 
          powered: "false", 
          facing: "west", 
          open: "false"
        }, 
        Name: "minecraft:dark_oak_trapdoor"
      }, 
      {
        Properties: {
          half: "bottom", 
          shape: "outer_right", 
          facing: "west"
        }, 
        Name: "minecraft:spruce_stairs"
      }, 
      {
        Properties: {
          half: "bottom", 
          powered: "false", 
          facing: "south", 
          open: "false"
        }, 
        Name: "minecraft:dark_oak_trapdoor"
      }, 
      {
        Properties: {
          half: "bottom", 
          shape: "outer_right", 
          facing: "east"
        }, 
        Name: "minecraft:spruce_stairs"
      }, 
      {
        Properties: {
          half: "top", 
          shape: "outer_right", 
          facing: "west"
        }, 
        Name: "minecraft:dark_oak_stairs"
      }, 
      {
        Properties: {
          half: "top", 
          shape: "outer_right", 
          facing: "east"
        }, 
        Name: "minecraft:dark_oak_stairs"
      }, 
      {
        Properties: {
          half: "bottom", 
          powered: "false", 
          facing: "north", 
          open: "false"
        }, 
        Name: "minecraft:dark_oak_trapdoor"
      }
    ], 
    [
      {
        Name: "minecraft:oak_planks"
      }, 
      {
        Name: "minecraft:spruce_planks"
      }, 
      {
        Properties: {
          axis: "y"
        }, 
        Name: "minecraft:spruce_log"
      }, 
      {
        Properties: {
          facing: "south", 
          type: "single"
        }, 
        Name: "minecraft:chest"
      }, 
      {
        Properties: {
          mode: "data"
        }, 
        Name: "minecraft:structure_block"
      }, 
      {
        Properties: {
          facing: "east", 
          type: "single"
        }, 
        Name: "minecraft:chest"
      }, 
      {
        Properties: {
          half: "bottom", 
          shape: "outer_right", 
          facing: "south"
        }, 
        Name: "minecraft:oak_stairs"
      }, 
      {
        Properties: {
          half: "top", 
          shape: "outer_right", 
          facing: "north"
        }, 
        Name: "minecraft:oak_stairs"
      }, 
      {
        Properties: {
          east: "false", 
          south: "false", 
          north: "false", 
          west: "false"
        }, 
        Name: "minecraft:oak_fence"
      }, 
      {
        Properties: {
          half: "bottom", 
          shape: "outer_right", 
          facing: "south"
        }, 
        Name: "minecraft:spruce_stairs"
      }, 
      {
        Properties: {
          half: "bottom", 
          shape: "outer_right", 
          facing: "east"
        }, 
        Name: "minecraft:spruce_stairs"
      }, 
      {
        Properties: {
          half: "bottom", 
          shape: "outer_right", 
          facing: "west"
        }, 
        Name: "minecraft:spruce_stairs"
      }, 
      {
        Properties: {
          half: "top", 
          shape: "outer_right", 
          facing: "north"
        }, 
        Name: "minecraft:spruce_stairs"
      }, 
      {
        Properties: {
          half: "bottom", 
          shape: "outer_right", 
          facing: "north"
        }, 
        Name: "minecraft:oak_stairs"
      }, 
      {
        Properties: {
          half: "bottom", 
          powered: "false", 
          facing: "east", 
          open: "false"
        }, 
        Name: "minecraft:spruce_trapdoor"
      }, 
      {
        Properties: {
          half: "bottom", 
          powered: "false", 
          facing: "west", 
          open: "false"
        }, 
        Name: "minecraft:spruce_trapdoor"
      }, 
      {
        Properties: {
          half: "bottom", 
          shape: "outer_right", 
          facing: "west"
        }, 
        Name: "minecraft:oak_stairs"
      }, 
      {
        Properties: {
          half: "bottom", 
          powered: "false", 
          facing: "south", 
          open: "false"
        }, 
        Name: "minecraft:spruce_trapdoor"
      }, 
      {
        Properties: {
          half: "bottom", 
          shape: "outer_right", 
          facing: "east"
        }, 
        Name: "minecraft:oak_stairs"
      }, 
      {
        Properties: {
          half: "top", 
          shape: "outer_right", 
          facing: "west"
        }, 
        Name: "minecraft:spruce_stairs"
      }, 
      {
        Properties: {
          half: "top", 
          shape: "outer_right", 
          facing: "east"
        }, 
        Name: "minecraft:spruce_stairs"
      }, 
      {
        Properties: {
          half: "bottom", 
          powered: "false", 
          facing: "north", 
          open: "false"
        }, 
        Name: "minecraft:spruce_trapdoor"
      }
    ], 
    [
      {
        Name: "minecraft:jungle_planks"
      }, 
      {
        Name: "minecraft:spruce_planks"
      }, 
      {
        Properties: {
          axis: "y"
        }, 
        Name: "minecraft:spruce_log"
      }, 
      {
        Properties: {
          facing: "south", 
          type: "single"
        }, 
        Name: "minecraft:chest"
      }, 
      {
        Properties: {
          mode: "data"
        }, 
        Name: "minecraft:structure_block"
      }, 
      {
        Properties: {
          facing: "east", 
          type: "single"
        }, 
        Name: "minecraft:chest"
      }, 
      {
        Properties: {
          half: "bottom", 
          shape: "outer_right", 
          facing: "south"
        }, 
        Name: "minecraft:jungle_stairs"
      }, 
      {
        Properties: {
          half: "top", 
          shape: "outer_right", 
          facing: "north"
        }, 
        Name: "minecraft:jungle_stairs"
      }, 
      {
        Properties: {
          east: "false", 
          south: "false", 
          north: "false", 
          west: "false"
        }, 
        Name: "minecraft:jungle_fence"
      }, 
      {
        Properties: {
          half: "bottom", 
          shape: "outer_right", 
          facing: "south"
        }, 
        Name: "minecraft:spruce_stairs"
      }, 
      {
        Properties: {
          half: "bottom", 
          shape: "outer_right", 
          facing: "east"
        }, 
        Name: "minecraft:spruce_stairs"
      }, 
      {
        Properties: {
          half: "bottom", 
          shape: "outer_right", 
          facing: "west"
        }, 
        Name: "minecraft:spruce_stairs"
      }, 
      {
        Properties: {
          half: "top", 
          shape: "outer_right", 
          facing: "north"
        }, 
        Name: "minecraft:spruce_stairs"
      }, 
      {
        Properties: {
          half: "bottom", 
          shape: "outer_right", 
          facing: "north"
        }, 
        Name: "minecraft:jungle_stairs"
      }, 
      {
        Properties: {
          half: "bottom", 
          powered: "false", 
          facing: "east", 
          open: "false"
        }, 
        Name: "minecraft:spruce_trapdoor"
      }, 
      {
        Properties: {
          half: "bottom", 
          powered: "false", 
          facing: "west", 
          open: "false"
        }, 
        Name: "minecraft:spruce_trapdoor"
      }, 
      {
        Properties: {
          half: "bottom", 
          shape: "outer_right", 
          facing: "west"
        }, 
        Name: "minecraft:jungle_stairs"
      }, 
      {
        Properties: {
          half: "bottom", 
          powered: "false", 
          facing: "south", 
          open: "false"
        }, 
        Name: "minecraft:spruce_trapdoor"
      }, 
      {
        Properties: {
          half: "bottom", 
          shape: "outer_right", 
          facing: "east"
        }, 
        Name: "minecraft:jungle_stairs"
      }, 
      {
        Properties: {
          half: "top", 
          shape: "outer_right", 
          facing: "west"
        }, 
        Name: "minecraft:spruce_stairs"
      }, 
      {
        Properties: {
          half: "top", 
          shape: "outer_right", 
          facing: "east"
        }, 
        Name: "minecraft:spruce_stairs"
      }, 
      {
        Properties: {
          half: "bottom", 
          powered: "false", 
          facing: "north", 
          open: "false"
        }, 
        Name: "minecraft:spruce_trapdoor"
      }
    ], 
    [
      {
        Name: "minecraft:dark_oak_planks"
      }, 
      {
        Name: "minecraft:spruce_planks"
      }, 
      {
        Properties: {
          axis: "y"
        }, 
        Name: "minecraft:spruce_log"
      }, 
      {
        Properties: {
          facing: "south", 
          type: "single"
        }, 
        Name: "minecraft:chest"
      }, 
      {
        Properties: {
          mode: "data"
        }, 
        Name: "minecraft:structure_block"
      }, 
      {
        Properties: {
          facing: "east", 
          type: "single"
        }, 
        Name: "minecraft:chest"
      }, 
      {
        Properties: {
          half: "bottom", 
          shape: "outer_right", 
          facing: "south"
        }, 
        Name: "minecraft:dark_oak_stairs"
      }, 
      {
        Properties: {
          half: "top", 
          shape: "outer_right", 
          facing: "north"
        }, 
        Name: "minecraft:dark_oak_stairs"
      }, 
      {
        Properties: {
          east: "false", 
          south: "false", 
          north: "false", 
          west: "false"
        }, 
        Name: "minecraft:dark_oak_fence"
      }, 
      {
        Properties: {
          half: "bottom", 
          shape: "outer_right", 
          facing: "south"
        }, 
        Name: "minecraft:spruce_stairs"
      }, 
      {
        Properties: {
          half: "bottom", 
          shape: "outer_right", 
          facing: "east"
        }, 
        Name: "minecraft:spruce_stairs"
      }, 
      {
        Properties: {
          half: "bottom", 
          shape: "outer_right", 
          facing: "west"
        }, 
        Name: "minecraft:spruce_stairs"
      }, 
      {
        Properties: {
          half: "top", 
          shape: "outer_right", 
          facing: "north"
        }, 
        Name: "minecraft:spruce_stairs"
      }, 
      {
        Properties: {
          half: "bottom", 
          shape: "outer_right", 
          facing: "north"
        }, 
        Name: "minecraft:dark_oak_stairs"
      }, 
      {
        Properties: {
          half: "bottom", 
          powered: "false", 
          facing: "east", 
          open: "false"
        }, 
        Name: "minecraft:spruce_trapdoor"
      }, 
      {
        Properties: {
          half: "bottom", 
          powered: "false", 
          facing: "west", 
          open: "false"
        }, 
        Name: "minecraft:spruce_trapdoor"
      }, 
      {
        Properties: {
          half: "bottom", 
          shape: "outer_right", 
          facing: "west"
        }, 
        Name: "minecraft:dark_oak_stairs"
      }, 
      {
        Properties: {
          half: "bottom", 
          powered: "false", 
          facing: "south", 
          open: "false"
        }, 
        Name: "minecraft:spruce_trapdoor"
      }, 
      {
        Properties: {
          half: "bottom", 
          shape: "outer_right", 
          facing: "east"
        }, 
        Name: "minecraft:dark_oak_stairs"
      }, 
      {
        Properties: {
          half: "top", 
          shape: "outer_right", 
          facing: "west"
        }, 
        Name: "minecraft:spruce_stairs"
      }, 
      {
        Properties: {
          half: "top", 
          shape: "outer_right", 
          facing: "east"
        }, 
        Name: "minecraft:spruce_stairs"
      }, 
      {
        Properties: {
          half: "bottom", 
          powered: "false", 
          facing: "north", 
          open: "false"
        }, 
        Name: "minecraft:spruce_trapdoor"
      }
    ], 
    [
      {
        Name: "minecraft:birch_planks"
      }, 
      {
        Name: "minecraft:oak_planks"
      }, 
      {
        Properties: {
          axis: "y"
        }, 
        Name: "minecraft:oak_log"
      }, 
      {
        Properties: {
          facing: "south", 
          type: "single"
        }, 
        Name: "minecraft:chest"
      }, 
      {
        Properties: {
          mode: "data"
        }, 
        Name: "minecraft:structure_block"
      }, 
      {
        Properties: {
          facing: "east", 
          type: "single"
        }, 
        Name: "minecraft:chest"
      }, 
      {
        Properties: {
          half: "bottom", 
          shape: "outer_right", 
          facing: "south"
        }, 
        Name: "minecraft:birch_stairs"
      }, 
      {
        Properties: {
          half: "top", 
          shape: "outer_right", 
          facing: "north"
        }, 
        Name: "minecraft:birch_stairs"
      }, 
      {
        Properties: {
          east: "false", 
          south: "false", 
          north: "false", 
          west: "false"
        }, 
        Name: "minecraft:birch_fence"
      }, 
      {
        Properties: {
          half: "bottom", 
          shape: "outer_right", 
          facing: "south"
        }, 
        Name: "minecraft:oak_stairs"
      }, 
      {
        Properties: {
          half: "bottom", 
          shape: "outer_right", 
          facing: "east"
        }, 
        Name: "minecraft:oak_stairs"
      }, 
      {
        Properties: {
          half: "bottom", 
          shape: "outer_right", 
          facing: "west"
        }, 
        Name: "minecraft:oak_stairs"
      }, 
      {
        Properties: {
          half: "top", 
          shape: "outer_right", 
          facing: "north"
        }, 
        Name: "minecraft:oak_stairs"
      }, 
      {
        Properties: {
          half: "bottom", 
          shape: "outer_right", 
          facing: "north"
        }, 
        Name: "minecraft:birch_stairs"
      }, 
      {
        Properties: {
          half: "bottom", 
          powered: "false", 
          facing: "east", 
          open: "false"
        }, 
        Name: "minecraft:oak_trapdoor"
      }, 
      {
        Properties: {
          half: "bottom", 
          powered: "false", 
          facing: "west", 
          open: "false"
        }, 
        Name: "minecraft:oak_trapdoor"
      }, 
      {
        Properties: {
          half: "bottom", 
          shape: "outer_right", 
          facing: "west"
        }, 
        Name: "minecraft:birch_stairs"
      }, 
      {
        Properties: {
          half: "bottom", 
          powered: "false", 
          facing: "south", 
          open: "false"
        }, 
        Name: "minecraft:oak_trapdoor"
      }, 
      {
        Properties: {
          half: "bottom", 
          shape: "outer_right", 
          facing: "east"
        }, 
        Name: "minecraft:birch_stairs"
      }, 
      {
        Properties: {
          half: "top", 
          shape: "outer_right", 
          facing: "west"
        }, 
        Name: "minecraft:oak_stairs"
      }, 
      {
        Properties: {
          half: "top", 
          shape: "outer_right", 
          facing: "east"
        }, 
        Name: "minecraft:oak_stairs"
      }, 
      {
        Properties: {
          half: "bottom", 
          powered: "false", 
          facing: "north", 
          open: "false"
        }, 
        Name: "minecraft:oak_trapdoor"
      }
    ]
  ]
}
