{
  size: [9, 9, 28], 
  entities: [], 
  author: "CascadianBacon", 
  blocks: [
    {
      pos: [4, 1, 2], 
      state: 0
    }, 
    {
      pos: [4, 2, 3], 
      state: 0
    }, 
    {
      pos: [4, 3, 3], 
      state: 0
    }, 
    {
      pos: [3, 2, 4], 
      state: 1
    }, 
    {
      pos: [5, 2, 4], 
      state: 1
    }, 
    {
      pos: [3, 3, 4], 
      state: 1
    }, 
    {
      pos: [4, 3, 4], 
      state: 1
    }, 
    {
      pos: [5, 3, 4], 
      state: 1
    }, 
    {
      pos: [4, 4, 4], 
      state: 0
    }, 
    {
      pos: [2, 2, 5], 
      state: 1
    }, 
    {
      pos: [2, 3, 5], 
      state: 1
    }, 
    {
      pos: [3, 3, 5], 
      state: 0
    }, 
    {
      pos: [4, 3, 5], 
      state: 0
    }, 
    {
      pos: [5, 3, 5], 
      state: 0
    }, 
    {
      pos: [6, 3, 5], 
      state: 1
    }, 
    {
      pos: [3, 4, 5], 
      state: 1
    }, 
    {
      pos: [4, 4, 5], 
      state: 1
    }, 
    {
      pos: [5, 4, 5], 
      state: 1
    }, 
    {
      pos: [4, 5, 5], 
      state: 1
    }, 
    {
      pos: [1, 2, 6], 
      state: 1
    }, 
    {
      pos: [2, 3, 6], 
      state: 0
    }, 
    {
      pos: [3, 3, 6], 
      state: 0
    }, 
    {
      pos: [4, 3, 6], 
      state: 0
    }, 
    {
      pos: [5, 3, 6], 
      state: 0
    }, 
    {
      pos: [3, 4, 6], 
      state: 1
    }, 
    {
      pos: [4, 4, 6], 
      state: 1
    }, 
    {
      pos: [5, 4, 6], 
      state: 1
    }, 
    {
      pos: [4, 5, 6], 
      state: 1
    }, 
    {
      pos: [4, 6, 6], 
      state: 0
    }, 
    {
      pos: [1, 2, 7], 
      state: 1
    }, 
    {
      pos: [1, 3, 7], 
      state: 1
    }, 
    {
      pos: [2, 3, 7], 
      state: 0
    }, 
    {
      pos: [4, 3, 7], 
      state: 2
    }, 
    {
      pos: [2, 4, 7], 
      state: 1
    }, 
    {
      pos: [3, 4, 7], 
      state: 1
    }, 
    {
      pos: [4, 4, 7], 
      state: 2
    }, 
    {
      pos: [5, 4, 7], 
      state: 1
    }, 
    {
      pos: [6, 4, 7], 
      state: 1
    }, 
    {
      pos: [3, 5, 7], 
      state: 1
    }, 
    {
      pos: [4, 5, 7], 
      state: 1
    }, 
    {
      pos: [5, 5, 7], 
      state: 1
    }, 
    {
      pos: [4, 6, 7], 
      state: 1
    }, 
    {
      pos: [4, 7, 7], 
      state: 0
    }, 
    {
      pos: [0, 2, 8], 
      state: 1
    }, 
    {
      pos: [1, 3, 8], 
      state: 1
    }, 
    {
      pos: [1, 4, 8], 
      state: 1
    }, 
    {
      pos: [2, 4, 8], 
      state: 0
    }, 
    {
      pos: [3, 4, 8], 
      state: 0
    }, 
    {
      pos: [4, 4, 8], 
      state: 0
    }, 
    {
      pos: [5, 4, 8], 
      state: 0
    }, 
    {
      pos: [6, 4, 8], 
      state: 0
    }, 
    {
      pos: [7, 4, 8], 
      state: 1
    }, 
    {
      pos: [2, 5, 8], 
      state: 1
    }, 
    {
      pos: [6, 5, 8], 
      state: 1
    }, 
    {
      pos: [3, 6, 8], 
      state: 1
    }, 
    {
      pos: [5, 6, 8], 
      state: 1
    }, 
    {
      pos: [4, 7, 8], 
      state: 1
    }, 
    {
      pos: [0, 3, 9], 
      state: 1
    }, 
    {
      pos: [1, 4, 9], 
      state: 0
    }, 
    {
      pos: [2, 4, 9], 
      state: 0
    }, 
    {
      pos: [6, 4, 9], 
      state: 0
    }, 
    {
      pos: [1, 5, 9], 
      state: 1
    }, 
    {
      pos: [2, 5, 9], 
      state: 1
    }, 
    {
      pos: [6, 5, 9], 
      state: 1
    }, 
    {
      pos: [2, 6, 9], 
      state: 1
    }, 
    {
      pos: [6, 6, 9], 
      state: 1
    }, 
    {
      pos: [3, 7, 9], 
      state: 1
    }, 
    {
      pos: [4, 7, 9], 
      state: 1
    }, 
    {
      pos: [5, 7, 9], 
      state: 1
    }, 
    {
      pos: [4, 8, 9], 
      state: 0
    }, 
    {
      pos: [0, 3, 10], 
      state: 1
    }, 
    {
      pos: [1, 4, 10], 
      state: 0
    }, 
    {
      pos: [2, 4, 10], 
      state: 0
    }, 
    {
      pos: [6, 4, 10], 
      state: 0
    }, 
    {
      pos: [1, 5, 10], 
      state: 1
    }, 
    {
      pos: [2, 5, 10], 
      state: 1
    }, 
    {
      pos: [6, 5, 10], 
      state: 1
    }, 
    {
      pos: [7, 5, 10], 
      state: 1
    }, 
    {
      pos: [2, 6, 10], 
      state: 1
    }, 
    {
      pos: [6, 6, 10], 
      state: 1
    }, 
    {
      pos: [3, 7, 10], 
      state: 1
    }, 
    {
      pos: [4, 7, 10], 
      state: 1
    }, 
    {
      pos: [5, 7, 10], 
      state: 1
    }, 
    {
      pos: [4, 8, 10], 
      state: 0
    }, 
    {
      pos: [4, 3, 11], 
      state: 2
    }, 
    {
      pos: [1, 4, 11], 
      state: 0
    }, 
    {
      pos: [2, 4, 11], 
      state: 0
    }, 
    {
      pos: [3, 4, 11], 
      state: 0
    }, 
    {
      pos: [4, 4, 11], 
      state: 2
    }, 
    {
      pos: [5, 4, 11], 
      state: 0
    }, 
    {
      pos: [6, 4, 11], 
      state: 0
    }, 
    {
      pos: [7, 4, 11], 
      state: 0
    }, 
    {
      pos: [1, 5, 11], 
      state: 1
    }, 
    {
      pos: [2, 5, 11], 
      state: 1
    }, 
    {
      pos: [4, 5, 11], 
      state: 2
    }, 
    {
      pos: [6, 5, 11], 
      state: 1
    }, 
    {
      pos: [7, 5, 11], 
      state: 1
    }, 
    {
      pos: [2, 6, 11], 
      state: 1
    }, 
    {
      pos: [4, 6, 11], 
      state: 2
    }, 
    {
      pos: [6, 6, 11], 
      state: 1
    }, 
    {
      pos: [3, 7, 11], 
      state: 1
    }, 
    {
      pos: [4, 7, 11], 
      state: 1
    }, 
    {
      pos: [5, 7, 11], 
      state: 1
    }, 
    {
      pos: [4, 8, 11], 
      state: 0
    }, 
    {
      pos: [1, 4, 12], 
      state: 0
    }, 
    {
      pos: [7, 4, 12], 
      state: 0
    }, 
    {
      pos: [3, 7, 12], 
      state: 1
    }, 
    {
      pos: [5, 7, 12], 
      state: 1
    }, 
    {
      pos: [1, 4, 13], 
      state: 0
    }, 
    {
      pos: [2, 4, 13], 
      state: 0
    }, 
    {
      pos: [6, 4, 13], 
      state: 0
    }, 
    {
      pos: [7, 4, 13], 
      state: 0
    }, 
    {
      pos: [1, 5, 13], 
      state: 1
    }, 
    {
      pos: [2, 5, 13], 
      state: 1
    }, 
    {
      pos: [1, 4, 14], 
      state: 0
    }, 
    {
      pos: [2, 4, 14], 
      state: 0
    }, 
    {
      pos: [6, 4, 14], 
      state: 0
    }, 
    {
      pos: [7, 4, 14], 
      state: 0
    }, 
    {
      pos: [1, 5, 14], 
      state: 1
    }, 
    {
      pos: [6, 5, 14], 
      state: 1
    }, 
    {
      pos: [7, 5, 14], 
      state: 1
    }, 
    {
      pos: [1, 4, 15], 
      state: 0
    }, 
    {
      pos: [7, 4, 15], 
      state: 0
    }, 
    {
      pos: [4, 3, 16], 
      state: 2
    }, 
    {
      pos: [1, 4, 16], 
      state: 0
    }, 
    {
      pos: [2, 4, 16], 
      state: 0
    }, 
    {
      pos: [3, 4, 16], 
      state: 0
    }, 
    {
      pos: [4, 4, 16], 
      state: 2
    }, 
    {
      pos: [5, 4, 16], 
      state: 0
    }, 
    {
      pos: [6, 4, 16], 
      state: 0
    }, 
    {
      pos: [7, 4, 16], 
      state: 0
    }, 
    {
      pos: [2, 5, 16], 
      state: 1
    }, 
    {
      pos: [3, 5, 16], 
      state: 1
    }, 
    {
      pos: [4, 5, 16], 
      state: 2
    }, 
    {
      pos: [6, 5, 16], 
      state: 1
    }, 
    {
      pos: [7, 5, 16], 
      state: 1
    }, 
    {
      pos: [4, 6, 16], 
      state: 2
    }, 
    {
      pos: [1, 4, 17], 
      state: 0
    }, 
    {
      pos: [2, 4, 17], 
      state: 0
    }, 
    {
      pos: [3, 4, 17], 
      state: 0
    }, 
    {
      pos: [4, 4, 17], 
      state: 0
    }, 
    {
      pos: [5, 4, 17], 
      state: 0
    }, 
    {
      pos: [6, 4, 17], 
      state: 0
    }, 
    {
      pos: [7, 4, 17], 
      state: 0
    }, 
    {
      pos: [1, 5, 17], 
      state: 1
    }, 
    {
      pos: [2, 5, 17], 
      state: 1
    }, 
    {
      pos: [6, 5, 17], 
      state: 1
    }, 
    {
      pos: [7, 5, 17], 
      state: 1
    }, 
    {
      pos: [2, 6, 17], 
      state: 1
    }, 
    {
      pos: [0, 3, 18], 
      state: 1
    }, 
    {
      pos: [8, 3, 18], 
      state: 1
    }, 
    {
      pos: [1, 4, 18], 
      state: 0
    }, 
    {
      pos: [2, 4, 18], 
      state: 0
    }, 
    {
      pos: [3, 4, 18], 
      state: 0
    }, 
    {
      pos: [5, 4, 18], 
      state: 0
    }, 
    {
      pos: [6, 4, 18], 
      state: 0
    }, 
    {
      pos: [7, 4, 18], 
      state: 0
    }, 
    {
      pos: [0, 2, 19], 
      state: 1
    }, 
    {
      pos: [2, 2, 19], 
      state: 1
    }, 
    {
      pos: [3, 2, 19], 
      state: 1
    }, 
    {
      pos: [5, 2, 19], 
      state: 1
    }, 
    {
      pos: [6, 2, 19], 
      state: 1
    }, 
    {
      pos: [8, 2, 19], 
      state: 1
    }, 
    {
      pos: [0, 3, 19], 
      state: 1
    }, 
    {
      pos: [1, 3, 19], 
      state: 1
    }, 
    {
      pos: [2, 3, 19], 
      state: 1
    }, 
    {
      pos: [3, 3, 19], 
      state: 1
    }, 
    {
      pos: [5, 3, 19], 
      state: 1
    }, 
    {
      pos: [6, 3, 19], 
      state: 1
    }, 
    {
      pos: [7, 3, 19], 
      state: 1
    }, 
    {
      pos: [8, 3, 19], 
      state: 1
    }, 
    {
      pos: [1, 4, 19], 
      state: 1
    }, 
    {
      pos: [2, 4, 19], 
      state: 1
    }, 
    {
      pos: [3, 4, 19], 
      state: 1
    }, 
    {
      pos: [5, 4, 19], 
      state: 1
    }, 
    {
      pos: [6, 4, 19], 
      state: 1
    }, 
    {
      pos: [7, 4, 19], 
      state: 1
    }, 
    {
      pos: [1, 5, 19], 
      state: 1
    }, 
    {
      pos: [2, 5, 19], 
      state: 1
    }, 
    {
      pos: [7, 5, 19], 
      state: 1
    }, 
    {
      pos: [2, 6, 19], 
      state: 1
    }, 
    {
      pos: [3, 7, 19], 
      state: 1
    }, 
    {
      pos: [4, 7, 19], 
      state: 1
    }, 
    {
      pos: [0, 2, 20], 
      state: 1
    }, 
    {
      pos: [1, 2, 20], 
      state: 0
    }, 
    {
      pos: [2, 2, 20], 
      state: 0
    }, 
    {
      pos: [6, 2, 20], 
      state: 0
    }, 
    {
      pos: [7, 2, 20], 
      state: 0
    }, 
    {
      pos: [8, 2, 20], 
      state: 1
    }, 
    {
      pos: [0, 3, 20], 
      state: 1
    }, 
    {
      pos: [1, 3, 20], 
      state: 1
    }, 
    {
      pos: [7, 3, 20], 
      state: 1
    }, 
    {
      pos: [8, 3, 20], 
      state: 1
    }, 
    {
      pos: [1, 4, 20], 
      state: 1
    }, 
    {
      pos: [7, 4, 20], 
      state: 1
    }, 
    {
      pos: [1, 5, 20], 
      state: 1
    }, 
    {
      pos: [2, 5, 20], 
      state: 1
    }, 
    {
      pos: [3, 5, 20], 
      state: 1
    }, 
    {
      pos: [4, 5, 20], 
      state: 1
    }, 
    {
      pos: [5, 5, 20], 
      state: 1
    }, 
    {
      pos: [2, 6, 20], 
      state: 1
    }, 
    {
      pos: [3, 6, 20], 
      state: 1
    }, 
    {
      pos: [4, 6, 20], 
      state: 1
    }, 
    {
      pos: [3, 7, 20], 
      state: 1
    }, 
    {
      pos: [4, 7, 20], 
      state: 1
    }, 
    {
      pos: [4, 8, 20], 
      state: 0
    }, 
    {
      pos: [1, 0, 21], 
      state: 1
    }, 
    {
      pos: [3, 0, 21], 
      state: 1
    }, 
    {
      pos: [4, 0, 21], 
      state: 1
    }, 
    {
      pos: [5, 0, 21], 
      state: 1
    }, 
    {
      pos: [7, 0, 21], 
      state: 1
    }, 
    {
      pos: [0, 1, 21], 
      state: 1
    }, 
    {
      pos: [1, 1, 21], 
      state: 1
    }, 
    {
      pos: [3, 1, 21], 
      state: 1
    }, 
    {
      pos: [4, 1, 21], 
      state: 1
    }, 
    {
      pos: [5, 1, 21], 
      state: 1
    }, 
    {
      pos: [7, 1, 21], 
      state: 1
    }, 
    {
      pos: [8, 1, 21], 
      state: 1
    }, 
    {
      pos: [0, 2, 21], 
      state: 1
    }, 
    {
      pos: [1, 2, 21], 
      state: 1
    }, 
    {
      pos: [7, 2, 21], 
      state: 1
    }, 
    {
      pos: [8, 2, 21], 
      state: 1
    }, 
    {
      pos: [1, 3, 21], 
      state: 1
    }, 
    {
      pos: [7, 3, 21], 
      state: 1
    }, 
    {
      pos: [1, 4, 21], 
      state: 1
    }, 
    {
      pos: [7, 4, 21], 
      state: 1
    }, 
    {
      pos: [2, 5, 21], 
      state: 0
    }, 
    {
      pos: [3, 5, 21], 
      state: 0
    }, 
    {
      pos: [4, 5, 21], 
      state: 0
    }, 
    {
      pos: [3, 6, 21], 
      state: 1
    }, 
    {
      pos: [4, 6, 21], 
      state: 1
    }, 
    {
      pos: [4, 7, 21], 
      state: 1
    }, 
    {
      pos: [0, 1, 22], 
      state: 1
    }, 
    {
      pos: [1, 1, 22], 
      state: 0
    }, 
    {
      pos: [2, 1, 22], 
      state: 0
    }, 
    {
      pos: [3, 1, 22], 
      state: 0
    }, 
    {
      pos: [4, 1, 22], 
      state: 0
    }, 
    {
      pos: [5, 1, 22], 
      state: 0
    }, 
    {
      pos: [6, 1, 22], 
      state: 0
    }, 
    {
      pos: [7, 1, 22], 
      state: 0
    }, 
    {
      pos: [8, 1, 22], 
      state: 1
    }, 
    {
      pos: [1, 4, 22], 
      state: 1
    }, 
    {
      pos: [7, 4, 22], 
      state: 1
    }, 
    {
      pos: [2, 5, 22], 
      state: 0
    }, 
    {
      pos: [3, 5, 22], 
      state: 0
    }, 
    {
      pos: [4, 5, 22], 
      state: 0
    }, 
    {
      pos: [5, 5, 22], 
      state: 0
    }, 
    {
      pos: [3, 6, 22], 
      state: 1
    }, 
    {
      pos: [4, 7, 22], 
      state: 0
    }, 
    {
      pos: [0, 1, 23], 
      state: 1
    }, 
    {
      pos: [1, 1, 23], 
      state: 0
    }, 
    {
      pos: [2, 1, 23], 
      state: 0
    }, 
    {
      pos: [3, 1, 23], 
      state: 0
    }, 
    {
      pos: [4, 1, 23], 
      state: 0
    }, 
    {
      pos: [5, 1, 23], 
      state: 0
    }, 
    {
      pos: [6, 1, 23], 
      state: 0
    }, 
    {
      pos: [7, 1, 23], 
      state: 0
    }, 
    {
      pos: [8, 1, 23], 
      state: 1
    }, 
    {
      pos: [0, 2, 23], 
      state: 1
    }, 
    {
      pos: [8, 2, 23], 
      state: 1
    }, 
    {
      pos: [1, 3, 23], 
      state: 1
    }, 
    {
      pos: [7, 3, 23], 
      state: 1
    }, 
    {
      pos: [2, 5, 23], 
      state: 1
    }, 
    {
      pos: [3, 5, 23], 
      state: 0
    }, 
    {
      pos: [4, 5, 23], 
      state: 0
    }, 
    {
      pos: [5, 5, 23], 
      state: 0
    }, 
    {
      pos: [6, 5, 23], 
      state: 1
    }, 
    {
      pos: [3, 6, 23], 
      state: 1
    }, 
    {
      pos: [4, 6, 23], 
      state: 1
    }, 
    {
      pos: [5, 6, 23], 
      state: 1
    }, 
    {
      pos: [4, 7, 23], 
      state: 0
    }, 
    {
      pos: [1, 1, 24], 
      state: 1
    }, 
    {
      pos: [2, 1, 24], 
      state: 0
    }, 
    {
      pos: [3, 1, 24], 
      state: 0
    }, 
    {
      pos: [4, 1, 24], 
      state: 0
    }, 
    {
      pos: [5, 1, 24], 
      state: 0
    }, 
    {
      pos: [6, 1, 24], 
      state: 0
    }, 
    {
      pos: [7, 1, 24], 
      state: 1
    }, 
    {
      pos: [1, 2, 24], 
      state: 1
    }, 
    {
      pos: [7, 2, 24], 
      state: 1
    }, 
    {
      pos: [1, 3, 24], 
      state: 1
    }, 
    {
      pos: [7, 3, 24], 
      state: 1
    }, 
    {
      pos: [3, 5, 24], 
      state: 1
    }, 
    {
      pos: [4, 5, 24], 
      state: 0
    }, 
    {
      pos: [5, 5, 24], 
      state: 1
    }, 
    {
      pos: [4, 6, 24], 
      state: 0
    }, 
    {
      pos: [1, 0, 25], 
      state: 1
    }, 
    {
      pos: [7, 0, 25], 
      state: 1
    }, 
    {
      pos: [1, 1, 25], 
      state: 1
    }, 
    {
      pos: [2, 1, 25], 
      state: 0
    }, 
    {
      pos: [3, 1, 25], 
      state: 0
    }, 
    {
      pos: [4, 1, 25], 
      state: 0
    }, 
    {
      pos: [5, 1, 25], 
      state: 0
    }, 
    {
      pos: [6, 1, 25], 
      state: 0
    }, 
    {
      pos: [7, 1, 25], 
      state: 1
    }, 
    {
      pos: [1, 2, 25], 
      state: 1
    }, 
    {
      pos: [7, 2, 25], 
      state: 1
    }, 
    {
      pos: [2, 3, 25], 
      state: 1
    }, 
    {
      pos: [6, 3, 25], 
      state: 1
    }, 
    {
      pos: [3, 4, 25], 
      state: 1
    }, 
    {
      pos: [4, 4, 25], 
      state: 1
    }, 
    {
      pos: [5, 4, 25], 
      state: 1
    }, 
    {
      pos: [2, 0, 26], 
      state: 1
    }, 
    {
      pos: [6, 0, 26], 
      state: 1
    }, 
    {
      pos: [2, 1, 26], 
      state: 1
    }, 
    {
      pos: [3, 1, 26], 
      state: 1
    }, 
    {
      pos: [4, 1, 26], 
      state: 0
    }, 
    {
      pos: [5, 1, 26], 
      state: 1
    }, 
    {
      pos: [6, 1, 26], 
      state: 1
    }, 
    {
      pos: [3, 2, 26], 
      state: 1
    }, 
    {
      pos: [5, 2, 26], 
      state: 1
    }, 
    {
      pos: [4, 3, 26], 
      state: 1
    }, 
    {
      pos: [4, 1, 27], 
      state: 1
    }, 
    {
      nbt: {
        Items: [], 
        id: "minecraft:chest", 
        Lock: ""
      }, 
      pos: [4, 5, 8], 
      state: 3
    }, 
    {
      nbt: {
        metadata: "supply_chest", 
        mirror: "NONE", 
        ignoreEntities: 1b, 
        powered: 0b, 
        seed: 0L, 
        author: "CascadianBacon", 
        rotation: "NONE", 
        mode: "DATA", 
        posX: 0, 
        posY: 1, 
        sizeX: 0, 
        integrity: 1.0f, 
        posZ: 0, 
        showair: 0b, 
        name: "", 
        id: "minecraft:structure_block", 
        sizeY: 0, 
        showboundingbox: 1b, 
        sizeZ: 0
      }, 
      pos: [4, 6, 8], 
      state: 4
    }, 
    {
      nbt: {
        Items: [], 
        id: "minecraft:chest", 
        Lock: ""
      }, 
      pos: [3, 5, 17], 
      state: 5
    }, 
    {
      nbt: {
        metadata: "map_chest", 
        mirror: "NONE", 
        ignoreEntities: 1b, 
        powered: 0b, 
        seed: 0L, 
        author: "CascadianBacon", 
        rotation: "NONE", 
        mode: "DATA", 
        posX: 0, 
        posY: 1, 
        sizeX: 0, 
        integrity: 1.0f, 
        posZ: 0, 
        showair: 0b, 
        name: "", 
        id: "minecraft:structure_block", 
        sizeY: 0, 
        showboundingbox: 1b, 
        sizeZ: 0
      }, 
      pos: [3, 6, 17], 
      state: 4
    }, 
    {
      nbt: {
        Items: [], 
        id: "minecraft:chest", 
        Lock: ""
      }, 
      pos: [2, 2, 24], 
      state: 6
    }, 
    {
      nbt: {
        metadata: "treasure_chest", 
        mirror: "NONE", 
        ignoreEntities: 1b, 
        powered: 0b, 
        seed: 0L, 
        author: "CascadianBacon", 
        rotation: "NONE", 
        mode: "DATA", 
        posX: 0, 
        posY: 1, 
        sizeX: 0, 
        integrity: 1.0f, 
        posZ: 0, 
        showair: 0b, 
        name: "", 
        id: "minecraft:structure_block", 
        sizeY: 0, 
        showboundingbox: 1b, 
        sizeZ: 0
      }, 
      pos: [2, 3, 24], 
      state: 4
    }, 
    {
      pos: [4, 0, 0], 
      state: 7
    }, 
    {
      pos: [4, 0, 1], 
      state: 8
    }, 
    {
      pos: [4, 1, 1], 
      state: 7
    }, 
    {
      pos: [3, 1, 2], 
      state: 9
    }, 
    {
      pos: [5, 1, 2], 
      state: 9
    }, 
    {
      pos: [3, 2, 2], 
      state: 9
    }, 
    {
      pos: [4, 2, 2], 
      state: 7
    }, 
    {
      pos: [5, 2, 2], 
      state: 9
    }, 
    {
      pos: [3, 1, 3], 
      state: 9
    }, 
    {
      pos: [4, 1, 3], 
      state: 8
    }, 
    {
      pos: [5, 1, 3], 
      state: 9
    }, 
    {
      pos: [3, 2, 3], 
      state: 10
    }, 
    {
      pos: [5, 2, 3], 
      state: 10
    }, 
    {
      pos: [4, 4, 3], 
      state: 7
    }, 
    {
      pos: [3, 1, 4], 
      state: 9
    }, 
    {
      pos: [5, 1, 4], 
      state: 9
    }, 
    {
      pos: [4, 2, 4], 
      state: 8
    }, 
    {
      pos: [3, 4, 4], 
      state: 10
    }, 
    {
      pos: [5, 4, 4], 
      state: 10
    }, 
    {
      pos: [4, 5, 4], 
      state: 7
    }, 
    {
      pos: [2, 4, 5], 
      state: 11
    }, 
    {
      pos: [6, 4, 5], 
      state: 12
    }, 
    {
      pos: [3, 5, 5], 
      state: 11
    }, 
    {
      pos: [5, 5, 5], 
      state: 12
    }, 
    {
      pos: [4, 6, 5], 
      state: 7
    }, 
    {
      pos: [1, 3, 6], 
      state: 11
    }, 
    {
      pos: [7, 3, 6], 
      state: 12
    }, 
    {
      pos: [2, 4, 6], 
      state: 11
    }, 
    {
      pos: [6, 4, 6], 
      state: 12
    }, 
    {
      pos: [3, 5, 6], 
      state: 11
    }, 
    {
      pos: [5, 5, 6], 
      state: 12
    }, 
    {
      pos: [4, 7, 6], 
      state: 7
    }, 
    {
      pos: [3, 3, 7], 
      state: 8
    }, 
    {
      pos: [5, 3, 7], 
      state: 8
    }, 
    {
      pos: [1, 4, 7], 
      state: 11
    }, 
    {
      pos: [2, 5, 7], 
      state: 11
    }, 
    {
      pos: [6, 5, 7], 
      state: 12
    }, 
    {
      pos: [3, 6, 7], 
      state: 11
    }, 
    {
      pos: [5, 6, 7], 
      state: 12
    }, 
    {
      pos: [1, 2, 8], 
      state: 13
    }, 
    {
      pos: [0, 3, 8], 
      state: 10
    }, 
    {
      pos: [1, 5, 8], 
      state: 11
    }, 
    {
      pos: [2, 6, 8], 
      state: 11
    }, 
    {
      pos: [6, 6, 8], 
      state: 12
    }, 
    {
      pos: [3, 7, 8], 
      state: 11
    }, 
    {
      pos: [5, 7, 8], 
      state: 12
    }, 
    {
      pos: [4, 8, 8], 
      state: 7
    }, 
    {
      pos: [0, 2, 9], 
      state: 13
    }, 
    {
      pos: [0, 4, 9], 
      state: 11
    }, 
    {
      pos: [3, 4, 9], 
      state: 14
    }, 
    {
      pos: [5, 4, 9], 
      state: 15
    }, 
    {
      pos: [1, 6, 9], 
      state: 11
    }, 
    {
      pos: [7, 6, 9], 
      state: 12
    }, 
    {
      pos: [2, 7, 9], 
      state: 11
    }, 
    {
      pos: [6, 7, 9], 
      state: 12
    }, 
    {
      pos: [0, 4, 10], 
      state: 11
    }, 
    {
      pos: [3, 4, 10], 
      state: 14
    }, 
    {
      pos: [5, 4, 10], 
      state: 15
    }, 
    {
      pos: [1, 6, 10], 
      state: 11
    }, 
    {
      pos: [7, 6, 10], 
      state: 12
    }, 
    {
      pos: [2, 7, 10], 
      state: 11
    }, 
    {
      pos: [6, 7, 10], 
      state: 12
    }, 
    {
      pos: [0, 3, 11], 
      state: 9
    }, 
    {
      pos: [0, 4, 11], 
      state: 11
    }, 
    {
      pos: [8, 4, 11], 
      state: 12
    }, 
    {
      pos: [1, 6, 11], 
      state: 11
    }, 
    {
      pos: [7, 6, 11], 
      state: 12
    }, 
    {
      pos: [2, 7, 11], 
      state: 11
    }, 
    {
      pos: [6, 7, 11], 
      state: 12
    }, 
    {
      pos: [0, 3, 12], 
      state: 9
    }, 
    {
      pos: [0, 4, 12], 
      state: 11
    }, 
    {
      pos: [2, 4, 12], 
      state: 16
    }, 
    {
      pos: [3, 4, 12], 
      state: 17
    }, 
    {
      pos: [4, 4, 12], 
      state: 17
    }, 
    {
      pos: [5, 4, 12], 
      state: 17
    }, 
    {
      pos: [6, 4, 12], 
      state: 18
    }, 
    {
      pos: [8, 4, 12], 
      state: 12
    }, 
    {
      pos: [1, 6, 12], 
      state: 11
    }, 
    {
      pos: [2, 6, 12], 
      state: 19
    }, 
    {
      pos: [2, 7, 12], 
      state: 11
    }, 
    {
      pos: [6, 7, 12], 
      state: 12
    }, 
    {
      pos: [0, 3, 13], 
      state: 9
    }, 
    {
      pos: [0, 4, 13], 
      state: 11
    }, 
    {
      pos: [3, 4, 13], 
      state: 14
    }, 
    {
      pos: [5, 4, 13], 
      state: 15
    }, 
    {
      pos: [8, 4, 13], 
      state: 12
    }, 
    {
      pos: [1, 6, 13], 
      state: 11
    }, 
    {
      pos: [0, 4, 14], 
      state: 11
    }, 
    {
      pos: [3, 4, 14], 
      state: 14
    }, 
    {
      pos: [5, 4, 14], 
      state: 15
    }, 
    {
      pos: [8, 4, 14], 
      state: 12
    }, 
    {
      pos: [0, 3, 15], 
      state: 9
    }, 
    {
      pos: [8, 3, 15], 
      state: 9
    }, 
    {
      pos: [0, 4, 15], 
      state: 11
    }, 
    {
      pos: [2, 4, 15], 
      state: 16
    }, 
    {
      pos: [3, 4, 15], 
      state: 20
    }, 
    {
      pos: [4, 4, 15], 
      state: 20
    }, 
    {
      pos: [5, 4, 15], 
      state: 20
    }, 
    {
      pos: [6, 4, 15], 
      state: 18
    }, 
    {
      pos: [8, 4, 15], 
      state: 12
    }, 
    {
      pos: [6, 6, 15], 
      state: 21
    }, 
    {
      pos: [7, 6, 15], 
      state: 12
    }, 
    {
      pos: [0, 3, 16], 
      state: 9
    }, 
    {
      pos: [8, 3, 16], 
      state: 9
    }, 
    {
      pos: [0, 4, 16], 
      state: 11
    }, 
    {
      pos: [8, 4, 16], 
      state: 12
    }, 
    {
      pos: [7, 6, 16], 
      state: 12
    }, 
    {
      pos: [0, 3, 17], 
      state: 9
    }, 
    {
      pos: [8, 3, 17], 
      state: 9
    }, 
    {
      pos: [0, 4, 17], 
      state: 11
    }, 
    {
      pos: [8, 4, 17], 
      state: 12
    }, 
    {
      pos: [1, 6, 17], 
      state: 11
    }, 
    {
      pos: [7, 6, 17], 
      state: 12
    }, 
    {
      pos: [0, 2, 18], 
      state: 22
    }, 
    {
      pos: [8, 2, 18], 
      state: 22
    }, 
    {
      pos: [1, 3, 18], 
      state: 23
    }, 
    {
      pos: [7, 3, 18], 
      state: 23
    }, 
    {
      pos: [0, 4, 18], 
      state: 11
    }, 
    {
      pos: [4, 4, 18], 
      state: 8
    }, 
    {
      pos: [8, 4, 18], 
      state: 12
    }, 
    {
      pos: [1, 6, 18], 
      state: 11
    }, 
    {
      pos: [2, 6, 18], 
      state: 19
    }, 
    {
      pos: [2, 7, 18], 
      state: 11
    }, 
    {
      pos: [1, 2, 19], 
      state: 23
    }, 
    {
      pos: [7, 2, 19], 
      state: 23
    }, 
    {
      pos: [0, 4, 19], 
      state: 11
    }, 
    {
      pos: [4, 4, 19], 
      state: 24
    }, 
    {
      pos: [8, 4, 19], 
      state: 12
    }, 
    {
      pos: [3, 5, 19], 
      state: 25
    }, 
    {
      pos: [5, 5, 19], 
      state: 25
    }, 
    {
      pos: [1, 6, 19], 
      state: 11
    }, 
    {
      pos: [2, 7, 19], 
      state: 11
    }, 
    {
      pos: [0, 1, 20], 
      state: 22
    }, 
    {
      pos: [3, 1, 20], 
      state: 26
    }, 
    {
      pos: [4, 1, 20], 
      state: 10
    }, 
    {
      pos: [5, 1, 20], 
      state: 26
    }, 
    {
      pos: [8, 1, 20], 
      state: 22
    }, 
    {
      pos: [3, 2, 20], 
      state: 25
    }, 
    {
      pos: [5, 2, 20], 
      state: 25
    }, 
    {
      pos: [0, 4, 20], 
      state: 11
    }, 
    {
      pos: [2, 4, 20], 
      state: 27
    }, 
    {
      pos: [3, 4, 20], 
      state: 24
    }, 
    {
      pos: [4, 4, 20], 
      state: 24
    }, 
    {
      pos: [5, 4, 20], 
      state: 24
    }, 
    {
      pos: [6, 4, 20], 
      state: 28
    }, 
    {
      pos: [8, 4, 20], 
      state: 12
    }, 
    {
      pos: [1, 6, 20], 
      state: 11
    }, 
    {
      pos: [2, 7, 20], 
      state: 11
    }, 
    {
      pos: [0, 0, 21], 
      state: 21
    }, 
    {
      pos: [8, 0, 21], 
      state: 19
    }, 
    {
      pos: [2, 1, 21], 
      state: 23
    }, 
    {
      pos: [6, 1, 21], 
      state: 23
    }, 
    {
      pos: [2, 2, 21], 
      state: 25
    }, 
    {
      pos: [3, 2, 21], 
      state: 25
    }, 
    {
      pos: [4, 2, 21], 
      state: 25
    }, 
    {
      pos: [5, 2, 21], 
      state: 25
    }, 
    {
      pos: [6, 2, 21], 
      state: 25
    }, 
    {
      pos: [0, 3, 21], 
      state: 11
    }, 
    {
      pos: [8, 3, 21], 
      state: 12
    }, 
    {
      pos: [1, 5, 21], 
      state: 11
    }, 
    {
      pos: [2, 6, 21], 
      state: 11
    }, 
    {
      pos: [3, 7, 21], 
      state: 11
    }, 
    {
      pos: [5, 7, 21], 
      state: 12
    }, 
    {
      pos: [4, 8, 21], 
      state: 29
    }, 
    {
      pos: [0, 0, 22], 
      state: 21
    }, 
    {
      pos: [8, 0, 22], 
      state: 19
    }, 
    {
      pos: [0, 3, 22], 
      state: 11
    }, 
    {
      pos: [1, 3, 22], 
      state: 19
    }, 
    {
      pos: [7, 3, 22], 
      state: 21
    }, 
    {
      pos: [8, 3, 22], 
      state: 12
    }, 
    {
      pos: [1, 5, 22], 
      state: 11
    }, 
    {
      pos: [7, 5, 22], 
      state: 12
    }, 
    {
      pos: [2, 6, 22], 
      state: 11
    }, 
    {
      pos: [3, 7, 22], 
      state: 11
    }, 
    {
      pos: [0, 0, 23], 
      state: 21
    }, 
    {
      pos: [1, 0, 23], 
      state: 9
    }, 
    {
      pos: [7, 0, 23], 
      state: 9
    }, 
    {
      pos: [8, 0, 23], 
      state: 19
    }, 
    {
      pos: [1, 2, 23], 
      state: 30
    }, 
    {
      pos: [7, 2, 23], 
      state: 30
    }, 
    {
      pos: [0, 3, 23], 
      state: 31
    }, 
    {
      pos: [8, 3, 23], 
      state: 31
    }, 
    {
      pos: [1, 4, 23], 
      state: 11
    }, 
    {
      pos: [2, 4, 23], 
      state: 24
    }, 
    {
      pos: [6, 4, 23], 
      state: 24
    }, 
    {
      pos: [7, 4, 23], 
      state: 12
    }, 
    {
      pos: [2, 6, 23], 
      state: 31
    }, 
    {
      pos: [6, 6, 23], 
      state: 31
    }, 
    {
      pos: [3, 7, 23], 
      state: 11
    }, 
    {
      pos: [5, 7, 23], 
      state: 12
    }, 
    {
      pos: [1, 0, 24], 
      state: 9
    }, 
    {
      pos: [7, 0, 24], 
      state: 9
    }, 
    {
      pos: [1, 4, 24], 
      state: 11
    }, 
    {
      pos: [2, 4, 24], 
      state: 24
    }, 
    {
      pos: [3, 4, 24], 
      state: 24
    }, 
    {
      pos: [5, 4, 24], 
      state: 24
    }, 
    {
      pos: [6, 4, 24], 
      state: 24
    }, 
    {
      pos: [7, 4, 24], 
      state: 12
    }, 
    {
      pos: [2, 5, 24], 
      state: 31
    }, 
    {
      pos: [6, 5, 24], 
      state: 31
    }, 
    {
      pos: [3, 6, 24], 
      state: 31
    }, 
    {
      pos: [5, 6, 24], 
      state: 31
    }, 
    {
      pos: [4, 7, 24], 
      state: 29
    }, 
    {
      pos: [2, 2, 25], 
      state: 30
    }, 
    {
      pos: [6, 2, 25], 
      state: 30
    }, 
    {
      pos: [1, 3, 25], 
      state: 31
    }, 
    {
      pos: [3, 3, 25], 
      state: 22
    }, 
    {
      pos: [4, 3, 25], 
      state: 22
    }, 
    {
      pos: [5, 3, 25], 
      state: 22
    }, 
    {
      pos: [7, 3, 25], 
      state: 31
    }, 
    {
      pos: [2, 4, 25], 
      state: 31
    }, 
    {
      pos: [6, 4, 25], 
      state: 31
    }, 
    {
      pos: [3, 5, 25], 
      state: 31
    }, 
    {
      pos: [4, 5, 25], 
      state: 9
    }, 
    {
      pos: [5, 5, 25], 
      state: 31
    }, 
    {
      pos: [3, 0, 26], 
      state: 9
    }, 
    {
      pos: [5, 0, 26], 
      state: 9
    }, 
    {
      pos: [2, 2, 26], 
      state: 31
    }, 
    {
      pos: [6, 2, 26], 
      state: 31
    }, 
    {
      pos: [3, 3, 26], 
      state: 31
    }, 
    {
      pos: [5, 3, 26], 
      state: 31
    }, 
    {
      pos: [4, 4, 26], 
      state: 31
    }, 
    {
      pos: [3, 0, 27], 
      state: 9
    }, 
    {
      pos: [4, 0, 27], 
      state: 9
    }, 
    {
      pos: [5, 0, 27], 
      state: 9
    }, 
    {
      pos: [3, 1, 27], 
      state: 31
    }, 
    {
      pos: [5, 1, 27], 
      state: 31
    }
  ], 
  palettes: [
    [
      {
        Name: "minecraft:spruce_planks"
      }, 
      {
        Name: "minecraft:oak_planks"
      }, 
      {
        Properties: {
          axis: "y"
        }, 
        Name: "minecraft:oak_log"
      }, 
      {
        Properties: {
          facing: "south", 
          type: "single"
        }, 
        Name: "minecraft:chest"
      }, 
      {
        Properties: {
          mode: "data"
        }, 
        Name: "minecraft:structure_block"
      }, 
      {
        Properties: {
          facing: "east", 
          type: "single"
        }, 
        Name: "minecraft:chest"
      }, 
      {
        Properties: {
          facing: "north", 
          type: "single"
        }, 
        Name: "minecraft:chest"
      }, 
      {
        Properties: {
          half: "bottom", 
          shape: "outer_right", 
          facing: "south"
        }, 
        Name: "minecraft:spruce_stairs"
      }, 
      {
        Properties: {
          half: "top", 
          shape: "outer_right", 
          facing: "north"
        }, 
        Name: "minecraft:spruce_stairs"
      }, 
      {
        Properties: {
          east: "false", 
          south: "false", 
          north: "false", 
          west: "false"
        }, 
        Name: "minecraft:spruce_fence"
      }, 
      {
        Properties: {
          half: "bottom", 
          shape: "outer_right", 
          facing: "south"
        }, 
        Name: "minecraft:oak_stairs"
      }, 
      {
        Properties: {
          half: "bottom", 
          shape: "outer_right", 
          facing: "east"
        }, 
        Name: "minecraft:oak_stairs"
      }, 
      {
        Properties: {
          half: "bottom", 
          shape: "outer_right", 
          facing: "west"
        }, 
        Name: "minecraft:oak_stairs"
      }, 
      {
        Properties: {
          half: "top", 
          shape: "outer_right", 
          facing: "north"
        }, 
        Name: "minecraft:oak_stairs"
      }, 
      {
        Properties: {
          half: "bottom", 
          powered: "false", 
          facing: "east", 
          open: "false"
        }, 
        Name: "minecraft:oak_trapdoor"
      }, 
      {
        Properties: {
          half: "bottom", 
          powered: "false", 
          facing: "west", 
          open: "false"
        }, 
        Name: "minecraft:oak_trapdoor"
      }, 
      {
        Properties: {
          half: "bottom", 
          shape: "outer_right", 
          facing: "west"
        }, 
        Name: "minecraft:spruce_stairs"
      }, 
      {
        Properties: {
          half: "bottom", 
          powered: "false", 
          facing: "south", 
          open: "false"
        }, 
        Name: "minecraft:oak_trapdoor"
      }, 
      {
        Properties: {
          half: "bottom", 
          shape: "outer_right", 
          facing: "east"
        }, 
        Name: "minecraft:spruce_stairs"
      }, 
      {
        Properties: {
          half: "top", 
          shape: "outer_right", 
          facing: "west"
        }, 
        Name: "minecraft:oak_stairs"
      }, 
      {
        Properties: {
          half: "bottom", 
          powered: "false", 
          facing: "north", 
          open: "false"
        }, 
        Name: "minecraft:oak_trapdoor"
      }, 
      {
        Properties: {
          half: "top", 
          shape: "outer_right", 
          facing: "east"
        }, 
        Name: "minecraft:oak_stairs"
      }, 
      {
        Properties: {
          half: "top", 
          shape: "outer_right", 
          facing: "south"
        }, 
        Name: "minecraft:oak_stairs"
      }, 
      {
        Properties: {
          half: "top", 
          shape: "outer_right", 
          facing: "south"
        }, 
        Name: "minecraft:spruce_stairs"
      }, 
      {
        Properties: {
          half: "top"
        }, 
        Name: "minecraft:spruce_slab"
      }, 
      {
        Properties: {
          half: "bottom"
        }, 
        Name: "minecraft:spruce_slab"
      }, 
      {
        Properties: {
          half: "top"
        }, 
        Name: "minecraft:oak_slab"
      }, 
      {
        Properties: {
          half: "top", 
          shape: "outer_right", 
          facing: "west"
        }, 
        Name: "minecraft:spruce_stairs"
      }, 
      {
        Properties: {
          half: "top", 
          shape: "outer_right", 
          facing: "east"
        }, 
        Name: "minecraft:spruce_stairs"
      }, 
      {
        Properties: {
          half: "bottom", 
          shape: "outer_right", 
          facing: "north"
        }, 
        Name: "minecraft:spruce_stairs"
      }, 
      {
        Properties: {
          east: "false", 
          south: "false", 
          north: "false", 
          west: "false"
        }, 
        Name: "minecraft:oak_fence"
      }, 
      {
        Properties: {
          half: "bottom", 
          shape: "outer_right", 
          facing: "north"
        }, 
        Name: "minecraft:oak_stairs"
      }
    ], 
    [
      {
        Name: "minecraft:spruce_planks"
      }, 
      {
        Name: "minecraft:jungle_planks"
      }, 
      {
        Properties: {
          axis: "y"
        }, 
        Name: "minecraft:jungle_log"
      }, 
      {
        Properties: {
          facing: "south", 
          type: "single"
        }, 
        Name: "minecraft:chest"
      }, 
      {
        Properties: {
          mode: "data"
        }, 
        Name: "minecraft:structure_block"
      }, 
      {
        Properties: {
          facing: "east", 
          type: "single"
        }, 
        Name: "minecraft:chest"
      }, 
      {
        Properties: {
          facing: "north", 
          type: "single"
        }, 
        Name: "minecraft:chest"
      }, 
      {
        Properties: {
          half: "bottom", 
          shape: "outer_right", 
          facing: "south"
        }, 
        Name: "minecraft:spruce_stairs"
      }, 
      {
        Properties: {
          half: "top", 
          shape: "outer_right", 
          facing: "north"
        }, 
        Name: "minecraft:spruce_stairs"
      }, 
      {
        Properties: {
          east: "false", 
          south: "false", 
          north: "false", 
          west: "false"
        }, 
        Name: "minecraft:spruce_fence"
      }, 
      {
        Properties: {
          half: "bottom", 
          shape: "outer_right", 
          facing: "south"
        }, 
        Name: "minecraft:jungle_stairs"
      }, 
      {
        Properties: {
          half: "bottom", 
          shape: "outer_right", 
          facing: "east"
        }, 
        Name: "minecraft:jungle_stairs"
      }, 
      {
        Properties: {
          half: "bottom", 
          shape: "outer_right", 
          facing: "west"
        }, 
        Name: "minecraft:jungle_stairs"
      }, 
      {
        Properties: {
          half: "top", 
          shape: "outer_right", 
          facing: "north"
        }, 
        Name: "minecraft:jungle_stairs"
      }, 
      {
        Properties: {
          half: "bottom", 
          powered: "false", 
          facing: "east", 
          open: "false"
        }, 
        Name: "minecraft:jungle_trapdoor"
      }, 
      {
        Properties: {
          half: "bottom", 
          powered: "false", 
          facing: "west", 
          open: "false"
        }, 
        Name: "minecraft:jungle_trapdoor"
      }, 
      {
        Properties: {
          half: "bottom", 
          shape: "outer_right", 
          facing: "west"
        }, 
        Name: "minecraft:spruce_stairs"
      }, 
      {
        Properties: {
          half: "bottom", 
          powered: "false", 
          facing: "south", 
          open: "false"
        }, 
        Name: "minecraft:jungle_trapdoor"
      }, 
      {
        Properties: {
          half: "bottom", 
          shape: "outer_right", 
          facing: "east"
        }, 
        Name: "minecraft:spruce_stairs"
      }, 
      {
        Properties: {
          half: "top", 
          shape: "outer_right", 
          facing: "west"
        }, 
        Name: "minecraft:jungle_stairs"
      }, 
      {
        Properties: {
          half: "bottom", 
          powered: "false", 
          facing: "north", 
          open: "false"
        }, 
        Name: "minecraft:jungle_trapdoor"
      }, 
      {
        Properties: {
          half: "top", 
          shape: "outer_right", 
          facing: "east"
        }, 
        Name: "minecraft:jungle_stairs"
      }, 
      {
        Properties: {
          half: "top", 
          shape: "outer_right", 
          facing: "south"
        }, 
        Name: "minecraft:jungle_stairs"
      }, 
      {
        Properties: {
          half: "top", 
          shape: "outer_right", 
          facing: "south"
        }, 
        Name: "minecraft:spruce_stairs"
      }, 
      {
        Properties: {
          half: "top"
        }, 
        Name: "minecraft:spruce_slab"
      }, 
      {
        Properties: {
          half: "bottom"
        }, 
        Name: "minecraft:spruce_slab"
      }, 
      {
        Properties: {
          half: "top"
        }, 
        Name: "minecraft:jungle_slab"
      }, 
      {
        Properties: {
          half: "top", 
          shape: "outer_right", 
          facing: "west"
        }, 
        Name: "minecraft:spruce_stairs"
      }, 
      {
        Properties: {
          half: "top", 
          shape: "outer_right", 
          facing: "east"
        }, 
        Name: "minecraft:spruce_stairs"
      }, 
      {
        Properties: {
          half: "bottom", 
          shape: "outer_right", 
          facing: "north"
        }, 
        Name: "minecraft:spruce_stairs"
      }, 
      {
        Properties: {
          east: "false", 
          south: "false", 
          north: "false", 
          west: "false"
        }, 
        Name: "minecraft:jungle_fence"
      }, 
      {
        Properties: {
          half: "bottom", 
          shape: "outer_right", 
          facing: "north"
        }, 
        Name: "minecraft:jungle_stairs"
      }
    ], 
    [
      {
        Name: "minecraft:jungle_planks"
      }, 
      {
        Name: "minecraft:dark_oak_planks"
      }, 
      {
        Properties: {
          axis: "y"
        }, 
        Name: "minecraft:dark_oak_log"
      }, 
      {
        Properties: {
          facing: "south", 
          type: "single"
        }, 
        Name: "minecraft:chest"
      }, 
      {
        Properties: {
          mode: "data"
        }, 
        Name: "minecraft:structure_block"
      }, 
      {
        Properties: {
          facing: "east", 
          type: "single"
        }, 
        Name: "minecraft:chest"
      }, 
      {
        Properties: {
          facing: "north", 
          type: "single"
        }, 
        Name: "minecraft:chest"
      }, 
      {
        Properties: {
          half: "bottom", 
          shape: "outer_right", 
          facing: "south"
        }, 
        Name: "minecraft:jungle_stairs"
      }, 
      {
        Properties: {
          half: "top", 
          shape: "outer_right", 
          facing: "north"
        }, 
        Name: "minecraft:jungle_stairs"
      }, 
      {
        Properties: {
          east: "false", 
          south: "false", 
          north: "false", 
          west: "false"
        }, 
        Name: "minecraft:jungle_fence"
      }, 
      {
        Properties: {
          half: "bottom", 
          shape: "outer_right", 
          facing: "south"
        }, 
        Name: "minecraft:dark_oak_stairs"
      }, 
      {
        Properties: {
          half: "bottom", 
          shape: "outer_right", 
          facing: "east"
        }, 
        Name: "minecraft:dark_oak_stairs"
      }, 
      {
        Properties: {
          half: "bottom", 
          shape: "outer_right", 
          facing: "west"
        }, 
        Name: "minecraft:dark_oak_stairs"
      }, 
      {
        Properties: {
          half: "top", 
          shape: "outer_right", 
          facing: "north"
        }, 
        Name: "minecraft:dark_oak_stairs"
      }, 
      {
        Properties: {
          half: "bottom", 
          powered: "false", 
          facing: "east", 
          open: "false"
        }, 
        Name: "minecraft:dark_oak_trapdoor"
      }, 
      {
        Properties: {
          half: "bottom", 
          powered: "false", 
          facing: "west", 
          open: "false"
        }, 
        Name: "minecraft:dark_oak_trapdoor"
      }, 
      {
        Properties: {
          half: "bottom", 
          shape: "outer_right", 
          facing: "west"
        }, 
        Name: "minecraft:jungle_stairs"
      }, 
      {
        Properties: {
          half: "bottom", 
          powered: "false", 
          facing: "south", 
          open: "false"
        }, 
        Name: "minecraft:dark_oak_trapdoor"
      }, 
      {
        Properties: {
          half: "bottom", 
          shape: "outer_right", 
          facing: "east"
        }, 
        Name: "minecraft:jungle_stairs"
      }, 
      {
        Properties: {
          half: "top", 
          shape: "outer_right", 
          facing: "west"
        }, 
        Name: "minecraft:dark_oak_stairs"
      }, 
      {
        Properties: {
          half: "bottom", 
          powered: "false", 
          facing: "north", 
          open: "false"
        }, 
        Name: "minecraft:dark_oak_trapdoor"
      }, 
      {
        Properties: {
          half: "top", 
          shape: "outer_right", 
          facing: "east"
        }, 
        Name: "minecraft:dark_oak_stairs"
      }, 
      {
        Properties: {
          half: "top", 
          shape: "outer_right", 
          facing: "south"
        }, 
        Name: "minecraft:dark_oak_stairs"
      }, 
      {
        Properties: {
          half: "top", 
          shape: "outer_right", 
          facing: "south"
        }, 
        Name: "minecraft:jungle_stairs"
      }, 
      {
        Properties: {
          half: "top"
        }, 
        Name: "minecraft:jungle_slab"
      }, 
      {
        Properties: {
          half: "bottom"
        }, 
        Name: "minecraft:jungle_slab"
      }, 
      {
        Properties: {
          half: "top"
        }, 
        Name: "minecraft:dark_oak_slab"
      }, 
      {
        Properties: {
          half: "top", 
          shape: "outer_right", 
          facing: "west"
        }, 
        Name: "minecraft:jungle_stairs"
      }, 
      {
        Properties: {
          half: "top", 
          shape: "outer_right", 
          facing: "east"
        }, 
        Name: "minecraft:jungle_stairs"
      }, 
      {
        Properties: {
          half: "bottom", 
          shape: "outer_right", 
          facing: "north"
        }, 
        Name: "minecraft:jungle_stairs"
      }, 
      {
        Properties: {
          east: "false", 
          south: "false", 
          north: "false", 
          west: "false"
        }, 
        Name: "minecraft:dark_oak_fence"
      }, 
      {
        Properties: {
          half: "bottom", 
          shape: "outer_right", 
          facing: "north"
        }, 
        Name: "minecraft:dark_oak_stairs"
      }
    ], 
    [
      {
        Name: "minecraft:spruce_planks"
      }, 
      {
        Name: "minecraft:dark_oak_planks"
      }, 
      {
        Properties: {
          axis: "y"
        }, 
        Name: "minecraft:dark_oak_log"
      }, 
      {
        Properties: {
          facing: "south", 
          type: "single"
        }, 
        Name: "minecraft:chest"
      }, 
      {
        Properties: {
          mode: "data"
        }, 
        Name: "minecraft:structure_block"
      }, 
      {
        Properties: {
          facing: "east", 
          type: "single"
        }, 
        Name: "minecraft:chest"
      }, 
      {
        Properties: {
          facing: "north", 
          type: "single"
        }, 
        Name: "minecraft:chest"
      }, 
      {
        Properties: {
          half: "bottom", 
          shape: "outer_right", 
          facing: "south"
        }, 
        Name: "minecraft:spruce_stairs"
      }, 
      {
        Properties: {
          half: "top", 
          shape: "outer_right", 
          facing: "north"
        }, 
        Name: "minecraft:spruce_stairs"
      }, 
      {
        Properties: {
          east: "false", 
          south: "false", 
          north: "false", 
          west: "false"
        }, 
        Name: "minecraft:spruce_fence"
      }, 
      {
        Properties: {
          half: "bottom", 
          shape: "outer_right", 
          facing: "south"
        }, 
        Name: "minecraft:dark_oak_stairs"
      }, 
      {
        Properties: {
          half: "bottom", 
          shape: "outer_right", 
          facing: "east"
        }, 
        Name: "minecraft:dark_oak_stairs"
      }, 
      {
        Properties: {
          half: "bottom", 
          shape: "outer_right", 
          facing: "west"
        }, 
        Name: "minecraft:dark_oak_stairs"
      }, 
      {
        Properties: {
          half: "top", 
          shape: "outer_right", 
          facing: "north"
        }, 
        Name: "minecraft:dark_oak_stairs"
      }, 
      {
        Properties: {
          half: "bottom", 
          powered: "false", 
          facing: "east", 
          open: "false"
        }, 
        Name: "minecraft:dark_oak_trapdoor"
      }, 
      {
        Properties: {
          half: "bottom", 
          powered: "false", 
          facing: "west", 
          open: "false"
        }, 
        Name: "minecraft:dark_oak_trapdoor"
      }, 
      {
        Properties: {
          half: "bottom", 
          shape: "outer_right", 
          facing: "west"
        }, 
        Name: "minecraft:spruce_stairs"
      }, 
      {
        Properties: {
          half: "bottom", 
          powered: "false", 
          facing: "south", 
          open: "false"
        }, 
        Name: "minecraft:dark_oak_trapdoor"
      }, 
      {
        Properties: {
          half: "bottom", 
          shape: "outer_right", 
          facing: "east"
        }, 
        Name: "minecraft:spruce_stairs"
      }, 
      {
        Properties: {
          half: "top", 
          shape: "outer_right", 
          facing: "west"
        }, 
        Name: "minecraft:dark_oak_stairs"
      }, 
      {
        Properties: {
          half: "bottom", 
          powered: "false", 
          facing: "north", 
          open: "false"
        }, 
        Name: "minecraft:dark_oak_trapdoor"
      }, 
      {
        Properties: {
          half: "top", 
          shape: "outer_right", 
          facing: "east"
        }, 
        Name: "minecraft:dark_oak_stairs"
      }, 
      {
        Properties: {
          half: "top", 
          shape: "outer_right", 
          facing: "south"
        }, 
        Name: "minecraft:dark_oak_stairs"
      }, 
      {
        Properties: {
          half: "top", 
          shape: "outer_right", 
          facing: "south"
        }, 
        Name: "minecraft:spruce_stairs"
      }, 
      {
        Properties: {
          half: "top"
        }, 
        Name: "minecraft:spruce_slab"
      }, 
      {
        Properties: {
          half: "bottom"
        }, 
        Name: "minecraft:spruce_slab"
      }, 
      {
        Properties: {
          half: "top"
        }, 
        Name: "minecraft:dark_oak_slab"
      }, 
      {
        Properties: {
          half: "top", 
          shape: "outer_right", 
          facing: "west"
        }, 
        Name: "minecraft:spruce_stairs"
      }, 
      {
        Properties: {
          half: "top", 
          shape: "outer_right", 
          facing: "east"
        }, 
        Name: "minecraft:spruce_stairs"
      }, 
      {
        Properties: {
          half: "bottom", 
          shape: "outer_right", 
          facing: "north"
        }, 
        Name: "minecraft:spruce_stairs"
      }, 
      {
        Properties: {
          east: "false", 
          south: "false", 
          north: "false", 
          west: "false"
        }, 
        Name: "minecraft:dark_oak_fence"
      }, 
      {
        Properties: {
          half: "bottom", 
          shape: "outer_right", 
          facing: "north"
        }, 
        Name: "minecraft:dark_oak_stairs"
      }
    ], 
    [
      {
        Name: "minecraft:oak_planks"
      }, 
      {
        Name: "minecraft:spruce_planks"
      }, 
      {
        Properties: {
          axis: "y"
        }, 
        Name: "minecraft:spruce_log"
      }, 
      {
        Properties: {
          facing: "south", 
          type: "single"
        }, 
        Name: "minecraft:chest"
      }, 
      {
        Properties: {
          mode: "data"
        }, 
        Name: "minecraft:structure_block"
      }, 
      {
        Properties: {
          facing: "east", 
          type: "single"
        }, 
        Name: "minecraft:chest"
      }, 
      {
        Properties: {
          facing: "north", 
          type: "single"
        }, 
        Name: "minecraft:chest"
      }, 
      {
        Properties: {
          half: "bottom", 
          shape: "outer_right", 
          facing: "south"
        }, 
        Name: "minecraft:oak_stairs"
      }, 
      {
        Properties: {
          half: "top", 
          shape: "outer_right", 
          facing: "north"
        }, 
        Name: "minecraft:oak_stairs"
      }, 
      {
        Properties: {
          east: "false", 
          south: "false", 
          north: "false", 
          west: "false"
        }, 
        Name: "minecraft:oak_fence"
      }, 
      {
        Properties: {
          half: "bottom", 
          shape: "outer_right", 
          facing: "south"
        }, 
        Name: "minecraft:spruce_stairs"
      }, 
      {
        Properties: {
          half: "bottom", 
          shape: "outer_right", 
          facing: "east"
        }, 
        Name: "minecraft:spruce_stairs"
      }, 
      {
        Properties: {
          half: "bottom", 
          shape: "outer_right", 
          facing: "west"
        }, 
        Name: "minecraft:spruce_stairs"
      }, 
      {
        Properties: {
          half: "top", 
          shape: "outer_right", 
          facing: "north"
        }, 
        Name: "minecraft:spruce_stairs"
      }, 
      {
        Properties: {
          half: "bottom", 
          powered: "false", 
          facing: "east", 
          open: "false"
        }, 
        Name: "minecraft:spruce_trapdoor"
      }, 
      {
        Properties: {
          half: "bottom", 
          powered: "false", 
          facing: "west", 
          open: "false"
        }, 
        Name: "minecraft:spruce_trapdoor"
      }, 
      {
        Properties: {
          half: "bottom", 
          shape: "outer_right", 
          facing: "west"
        }, 
        Name: "minecraft:oak_stairs"
      }, 
      {
        Properties: {
          half: "bottom", 
          powered: "false", 
          facing: "south", 
          open: "false"
        }, 
        Name: "minecraft:spruce_trapdoor"
      }, 
      {
        Properties: {
          half: "bottom", 
          shape: "outer_right", 
          facing: "east"
        }, 
        Name: "minecraft:oak_stairs"
      }, 
      {
        Properties: {
          half: "top", 
          shape: "outer_right", 
          facing: "west"
        }, 
        Name: "minecraft:spruce_stairs"
      }, 
      {
        Properties: {
          half: "bottom", 
          powered: "false", 
          facing: "north", 
          open: "false"
        }, 
        Name: "minecraft:spruce_trapdoor"
      }, 
      {
        Properties: {
          half: "top", 
          shape: "outer_right", 
          facing: "east"
        }, 
        Name: "minecraft:spruce_stairs"
      }, 
      {
        Properties: {
          half: "top", 
          shape: "outer_right", 
          facing: "south"
        }, 
        Name: "minecraft:spruce_stairs"
      }, 
      {
        Properties: {
          half: "top", 
          shape: "outer_right", 
          facing: "south"
        }, 
        Name: "minecraft:oak_stairs"
      }, 
      {
        Properties: {
          half: "top"
        }, 
        Name: "minecraft:oak_slab"
      }, 
      {
        Properties: {
          half: "bottom"
        }, 
        Name: "minecraft:oak_slab"
      }, 
      {
        Properties: {
          half: "top"
        }, 
        Name: "minecraft:spruce_slab"
      }, 
      {
        Properties: {
          half: "top", 
          shape: "outer_right", 
          facing: "west"
        }, 
        Name: "minecraft:oak_stairs"
      }, 
      {
        Properties: {
          half: "top", 
          shape: "outer_right", 
          facing: "east"
        }, 
        Name: "minecraft:oak_stairs"
      }, 
      {
        Properties: {
          half: "bottom", 
          shape: "outer_right", 
          facing: "north"
        }, 
        Name: "minecraft:oak_stairs"
      }, 
      {
        Properties: {
          east: "false", 
          south: "false", 
          north: "false", 
          west: "false"
        }, 
        Name: "minecraft:spruce_fence"
      }, 
      {
        Properties: {
          half: "bottom", 
          shape: "outer_right", 
          facing: "north"
        }, 
        Name: "minecraft:spruce_stairs"
      }
    ], 
    [
      {
        Name: "minecraft:jungle_planks"
      }, 
      {
        Name: "minecraft:spruce_planks"
      }, 
      {
        Properties: {
          axis: "y"
        }, 
        Name: "minecraft:spruce_log"
      }, 
      {
        Properties: {
          facing: "south", 
          type: "single"
        }, 
        Name: "minecraft:chest"
      }, 
      {
        Properties: {
          mode: "data"
        }, 
        Name: "minecraft:structure_block"
      }, 
      {
        Properties: {
          facing: "east", 
          type: "single"
        }, 
        Name: "minecraft:chest"
      }, 
      {
        Properties: {
          facing: "north", 
          type: "single"
        }, 
        Name: "minecraft:chest"
      }, 
      {
        Properties: {
          half: "bottom", 
          shape: "outer_right", 
          facing: "south"
        }, 
        Name: "minecraft:jungle_stairs"
      }, 
      {
        Properties: {
          half: "top", 
          shape: "outer_right", 
          facing: "north"
        }, 
        Name: "minecraft:jungle_stairs"
      }, 
      {
        Properties: {
          east: "false", 
          south: "false", 
          north: "false", 
          west: "false"
        }, 
        Name: "minecraft:jungle_fence"
      }, 
      {
        Properties: {
          half: "bottom", 
          shape: "outer_right", 
          facing: "south"
        }, 
        Name: "minecraft:spruce_stairs"
      }, 
      {
        Properties: {
          half: "bottom", 
          shape: "outer_right", 
          facing: "east"
        }, 
        Name: "minecraft:spruce_stairs"
      }, 
      {
        Properties: {
          half: "bottom", 
          shape: "outer_right", 
          facing: "west"
        }, 
        Name: "minecraft:spruce_stairs"
      }, 
      {
        Properties: {
          half: "top", 
          shape: "outer_right", 
          facing: "north"
        }, 
        Name: "minecraft:spruce_stairs"
      }, 
      {
        Properties: {
          half: "bottom", 
          powered: "false", 
          facing: "east", 
          open: "false"
        }, 
        Name: "minecraft:spruce_trapdoor"
      }, 
      {
        Properties: {
          half: "bottom", 
          powered: "false", 
          facing: "west", 
          open: "false"
        }, 
        Name: "minecraft:spruce_trapdoor"
      }, 
      {
        Properties: {
          half: "bottom", 
          shape: "outer_right", 
          facing: "west"
        }, 
        Name: "minecraft:jungle_stairs"
      }, 
      {
        Properties: {
          half: "bottom", 
          powered: "false", 
          facing: "south", 
          open: "false"
        }, 
        Name: "minecraft:spruce_trapdoor"
      }, 
      {
        Properties: {
          half: "bottom", 
          shape: "outer_right", 
          facing: "east"
        }, 
        Name: "minecraft:jungle_stairs"
      }, 
      {
        Properties: {
          half: "top", 
          shape: "outer_right", 
          facing: "west"
        }, 
        Name: "minecraft:spruce_stairs"
      }, 
      {
        Properties: {
          half: "bottom", 
          powered: "false", 
          facing: "north", 
          open: "false"
        }, 
        Name: "minecraft:spruce_trapdoor"
      }, 
      {
        Properties: {
          half: "top", 
          shape: "outer_right", 
          facing: "east"
        }, 
        Name: "minecraft:spruce_stairs"
      }, 
      {
        Properties: {
          half: "top", 
          shape: "outer_right", 
          facing: "south"
        }, 
        Name: "minecraft:spruce_stairs"
      }, 
      {
        Properties: {
          half: "top", 
          shape: "outer_right", 
          facing: "south"
        }, 
        Name: "minecraft:jungle_stairs"
      }, 
      {
        Properties: {
          half: "top"
        }, 
        Name: "minecraft:jungle_slab"
      }, 
      {
        Properties: {
          half: "bottom"
        }, 
        Name: "minecraft:jungle_slab"
      }, 
      {
        Properties: {
          half: "top"
        }, 
        Name: "minecraft:spruce_slab"
      }, 
      {
        Properties: {
          half: "top", 
          shape: "outer_right", 
          facing: "west"
        }, 
        Name: "minecraft:jungle_stairs"
      }, 
      {
        Properties: {
          half: "top", 
          shape: "outer_right", 
          facing: "east"
        }, 
        Name: "minecraft:jungle_stairs"
      }, 
      {
        Properties: {
          half: "bottom", 
          shape: "outer_right", 
          facing: "north"
        }, 
        Name: "minecraft:jungle_stairs"
      }, 
      {
        Properties: {
          east: "false", 
          south: "false", 
          north: "false", 
          west: "false"
        }, 
        Name: "minecraft:spruce_fence"
      }, 
      {
        Properties: {
          half: "bottom", 
          shape: "outer_right", 
          facing: "north"
        }, 
        Name: "minecraft:spruce_stairs"
      }
    ], 
    [
      {
        Name: "minecraft:dark_oak_planks"
      }, 
      {
        Name: "minecraft:spruce_planks"
      }, 
      {
        Properties: {
          axis: "y"
        }, 
        Name: "minecraft:spruce_log"
      }, 
      {
        Properties: {
          facing: "south", 
          type: "single"
        }, 
        Name: "minecraft:chest"
      }, 
      {
        Properties: {
          mode: "data"
        }, 
        Name: "minecraft:structure_block"
      }, 
      {
        Properties: {
          facing: "east", 
          type: "single"
        }, 
        Name: "minecraft:chest"
      }, 
      {
        Properties: {
          facing: "north", 
          type: "single"
        }, 
        Name: "minecraft:chest"
      }, 
      {
        Properties: {
          half: "bottom", 
          shape: "outer_right", 
          facing: "south"
        }, 
        Name: "minecraft:dark_oak_stairs"
      }, 
      {
        Properties: {
          half: "top", 
          shape: "outer_right", 
          facing: "north"
        }, 
        Name: "minecraft:dark_oak_stairs"
      }, 
      {
        Properties: {
          east: "false", 
          south: "false", 
          north: "false", 
          west: "false"
        }, 
        Name: "minecraft:dark_oak_fence"
      }, 
      {
        Properties: {
          half: "bottom", 
          shape: "outer_right", 
          facing: "south"
        }, 
        Name: "minecraft:spruce_stairs"
      }, 
      {
        Properties: {
          half: "bottom", 
          shape: "outer_right", 
          facing: "east"
        }, 
        Name: "minecraft:spruce_stairs"
      }, 
      {
        Properties: {
          half: "bottom", 
          shape: "outer_right", 
          facing: "west"
        }, 
        Name: "minecraft:spruce_stairs"
      }, 
      {
        Properties: {
          half: "top", 
          shape: "outer_right", 
          facing: "north"
        }, 
        Name: "minecraft:spruce_stairs"
      }, 
      {
        Properties: {
          half: "bottom", 
          powered: "false", 
          facing: "east", 
          open: "false"
        }, 
        Name: "minecraft:spruce_trapdoor"
      }, 
      {
        Properties: {
          half: "bottom", 
          powered: "false", 
          facing: "west", 
          open: "false"
        }, 
        Name: "minecraft:spruce_trapdoor"
      }, 
      {
        Properties: {
          half: "bottom", 
          shape: "outer_right", 
          facing: "west"
        }, 
        Name: "minecraft:dark_oak_stairs"
      }, 
      {
        Properties: {
          half: "bottom", 
          powered: "false", 
          facing: "south", 
          open: "false"
        }, 
        Name: "minecraft:spruce_trapdoor"
      }, 
      {
        Properties: {
          half: "bottom", 
          shape: "outer_right", 
          facing: "east"
        }, 
        Name: "minecraft:dark_oak_stairs"
      }, 
      {
        Properties: {
          half: "top", 
          shape: "outer_right", 
          facing: "west"
        }, 
        Name: "minecraft:spruce_stairs"
      }, 
      {
        Properties: {
          half: "bottom", 
          powered: "false", 
          facing: "north", 
          open: "false"
        }, 
        Name: "minecraft:spruce_trapdoor"
      }, 
      {
        Properties: {
          half: "top", 
          shape: "outer_right", 
          facing: "east"
        }, 
        Name: "minecraft:spruce_stairs"
      }, 
      {
        Properties: {
          half: "top", 
          shape: "outer_right", 
          facing: "south"
        }, 
        Name: "minecraft:spruce_stairs"
      }, 
      {
        Properties: {
          half: "top", 
          shape: "outer_right", 
          facing: "south"
        }, 
        Name: "minecraft:dark_oak_stairs"
      }, 
      {
        Properties: {
          half: "top"
        }, 
        Name: "minecraft:dark_oak_slab"
      }, 
      {
        Properties: {
          half: "bottom"
        }, 
        Name: "minecraft:dark_oak_slab"
      }, 
      {
        Properties: {
          half: "top"
        }, 
        Name: "minecraft:spruce_slab"
      }, 
      {
        Properties: {
          half: "top", 
          shape: "outer_right", 
          facing: "west"
        }, 
        Name: "minecraft:dark_oak_stairs"
      }, 
      {
        Properties: {
          half: "top", 
          shape: "outer_right", 
          facing: "east"
        }, 
        Name: "minecraft:dark_oak_stairs"
      }, 
      {
        Properties: {
          half: "bottom", 
          shape: "outer_right", 
          facing: "north"
        }, 
        Name: "minecraft:dark_oak_stairs"
      }, 
      {
        Properties: {
          east: "false", 
          south: "false", 
          north: "false", 
          west: "false"
        }, 
        Name: "minecraft:spruce_fence"
      }, 
      {
        Properties: {
          half: "bottom", 
          shape: "outer_right", 
          facing: "north"
        }, 
        Name: "minecraft:spruce_stairs"
      }
    ], 
    [
      {
        Name: "minecraft:birch_planks"
      }, 
      {
        Name: "minecraft:oak_planks"
      }, 
      {
        Properties: {
          axis: "y"
        }, 
        Name: "minecraft:oak_log"
      }, 
      {
        Properties: {
          facing: "south", 
          type: "single"
        }, 
        Name: "minecraft:chest"
      }, 
      {
        Properties: {
          mode: "data"
        }, 
        Name: "minecraft:structure_block"
      }, 
      {
        Properties: {
          facing: "east", 
          type: "single"
        }, 
        Name: "minecraft:chest"
      }, 
      {
        Properties: {
          facing: "north", 
          type: "single"
        }, 
        Name: "minecraft:chest"
      }, 
      {
        Properties: {
          half: "bottom", 
          shape: "outer_right", 
          facing: "south"
        }, 
        Name: "minecraft:birch_stairs"
      }, 
      {
        Properties: {
          half: "top", 
          shape: "outer_right", 
          facing: "north"
        }, 
        Name: "minecraft:birch_stairs"
      }, 
      {
        Properties: {
          east: "false", 
          south: "false", 
          north: "false", 
          west: "false"
        }, 
        Name: "minecraft:birch_fence"
      }, 
      {
        Properties: {
          half: "bottom", 
          shape: "outer_right", 
          facing: "south"
        }, 
        Name: "minecraft:oak_stairs"
      }, 
      {
        Properties: {
          half: "bottom", 
          shape: "outer_right", 
          facing: "east"
        }, 
        Name: "minecraft:oak_stairs"
      }, 
      {
        Properties: {
          half: "bottom", 
          shape: "outer_right", 
          facing: "west"
        }, 
        Name: "minecraft:oak_stairs"
      }, 
      {
        Properties: {
          half: "top", 
          shape: "outer_right", 
          facing: "north"
        }, 
        Name: "minecraft:oak_stairs"
      }, 
      {
        Properties: {
          half: "bottom", 
          powered: "false", 
          facing: "east", 
          open: "false"
        }, 
        Name: "minecraft:oak_trapdoor"
      }, 
      {
        Properties: {
          half: "bottom", 
          powered: "false", 
          facing: "west", 
          open: "false"
        }, 
        Name: "minecraft:oak_trapdoor"
      }, 
      {
        Properties: {
          half: "bottom", 
          shape: "outer_right", 
          facing: "west"
        }, 
        Name: "minecraft:birch_stairs"
      }, 
      {
        Properties: {
          half: "bottom", 
          powered: "false", 
          facing: "south", 
          open: "false"
        }, 
        Name: "minecraft:oak_trapdoor"
      }, 
      {
        Properties: {
          half: "bottom", 
          shape: "outer_right", 
          facing: "east"
        }, 
        Name: "minecraft:birch_stairs"
      }, 
      {
        Properties: {
          half: "top", 
          shape: "outer_right", 
          facing: "west"
        }, 
        Name: "minecraft:oak_stairs"
      }, 
      {
        Properties: {
          half: "bottom", 
          powered: "false", 
          facing: "north", 
          open: "false"
        }, 
        Name: "minecraft:oak_trapdoor"
      }, 
      {
        Properties: {
          half: "top", 
          shape: "outer_right", 
          facing: "east"
        }, 
        Name: "minecraft:oak_stairs"
      }, 
      {
        Properties: {
          half: "top", 
          shape: "outer_right", 
          facing: "south"
        }, 
        Name: "minecraft:oak_stairs"
      }, 
      {
        Properties: {
          half: "top", 
          shape: "outer_right", 
          facing: "south"
        }, 
        Name: "minecraft:birch_stairs"
      }, 
      {
        Properties: {
          half: "top"
        }, 
        Name: "minecraft:birch_slab"
      }, 
      {
        Properties: {
          half: "bottom"
        }, 
        Name: "minecraft:birch_slab"
      }, 
      {
        Properties: {
          half: "top"
        }, 
        Name: "minecraft:oak_slab"
      }, 
      {
        Properties: {
          half: "top", 
          shape: "outer_right", 
          facing: "west"
        }, 
        Name: "minecraft:birch_stairs"
      }, 
      {
        Properties: {
          half: "top", 
          shape: "outer_right", 
          facing: "east"
        }, 
        Name: "minecraft:birch_stairs"
      }, 
      {
        Properties: {
          half: "bottom", 
          shape: "outer_right", 
          facing: "north"
        }, 
        Name: "minecraft:birch_stairs"
      }, 
      {
        Properties: {
          east: "false", 
          south: "false", 
          north: "false", 
          west: "false"
        }, 
        Name: "minecraft:oak_fence"
      }, 
      {
        Properties: {
          half: "bottom", 
          shape: "outer_right", 
          facing: "north"
        }, 
        Name: "minecraft:oak_stairs"
      }
    ]
  ]
}
