{
  size: [3, 4, 3], 
  entities: [], 
  blocks: [
    {
      pos: [0, 0, 0], 
      state: 0
    }, 
    {
      pos: [0, 0, 1], 
      state: 0
    }, 
    {
      pos: [0, 0, 2], 
      state: 0
    }, 
    {
      pos: [1, 0, 0], 
      state: 1
    }, 
    {
      pos: [1, 0, 2], 
      state: 1
    }, 
    {
      pos: [2, 0, 0], 
      state: 0
    }, 
    {
      pos: [2, 0, 1], 
      state: 1
    }, 
    {
      pos: [2, 0, 2], 
      state: 0
    }, 
    {
      pos: [0, 1, 0], 
      state: 0
    }, 
    {
      pos: [0, 1, 1], 
      state: 0
    }, 
    {
      pos: [0, 1, 2], 
      state: 0
    }, 
    {
      pos: [1, 1, 0], 
      state: 0
    }, 
    {
      pos: [1, 1, 1], 
      state: 2
    }, 
    {
      pos: [1, 1, 2], 
      state: 0
    }, 
    {
      pos: [2, 1, 0], 
      state: 0
    }, 
    {
      pos: [2, 1, 1], 
      state: 0
    }, 
    {
      pos: [2, 1, 2], 
      state: 0
    }, 
    {
      pos: [0, 2, 0], 
      state: 0
    }, 
    {
      pos: [0, 2, 1], 
      state: 3
    }, 
    {
      pos: [0, 2, 2], 
      state: 0
    }, 
    {
      pos: [1, 2, 0], 
      state: 3
    }, 
    {
      pos: [1, 2, 1], 
      state: 2
    }, 
    {
      pos: [1, 2, 2], 
      state: 3
    }, 
    {
      pos: [2, 2, 0], 
      state: 0
    }, 
    {
      pos: [2, 2, 1], 
      state: 3
    }, 
    {
      pos: [2, 2, 2], 
      state: 0
    }, 
    {
      pos: [0, 3, 0], 
      state: 0
    }, 
    {
      pos: [0, 3, 1], 
      state: 4
    }, 
    {
      pos: [0, 3, 2], 
      state: 0
    }, 
    {
      pos: [1, 3, 0], 
      state: 5
    }, 
    {
      pos: [1, 3, 1], 
      state: 6
    }, 
    {
      pos: [1, 3, 2], 
      state: 7
    }, 
    {
      pos: [2, 3, 0], 
      state: 0
    }, 
    {
      pos: [2, 3, 1], 
      state: 8
    }, 
    {
      pos: [2, 3, 2], 
      state: 0
    }, 
    {
      nbt: {
        joint: "rollable", 
        final_state: "minecraft:spruce_fence", 
        name: "minecraft:bottom", 
        pool: "minecraft:empty", 
        id: "minecraft:jigsaw", 
        target: "minecraft:bottom"
      }, 
      pos: [1, 0, 1], 
      state: 9
    }
  ], 
  palette: [
    {
      id: "minecraft:air"
    }, 
    {
      id: "minecraft:snow", 
      properties: {
        layers: "1"
      }
    }, 
    {
      id: "minecraft:spruce_fence", 
      properties: {
        east: "false", 
        waterlogged: "false", 
        south: "false", 
        north: "false", 
        west: "false"
      }
    }, 
    {
      id: "minecraft:lantern", 
      properties: {
        waterlogged: "false", 
        hanging: "true"
      }
    }, 
    {
      id: "minecraft:spruce_fence", 
      properties: {
        east: "true", 
        waterlogged: "false", 
        south: "false", 
        north: "false", 
        west: "false"
      }
    }, 
    {
      id: "minecraft:spruce_fence", 
      properties: {
        east: "false", 
        waterlogged: "false", 
        south: "true", 
        north: "false", 
        west: "false"
      }
    }, 
    {
      id: "minecraft:spruce_fence", 
      properties: {
        east: "true", 
        waterlogged: "false", 
        south: "true", 
        north: "true", 
        west: "true"
      }
    }, 
    {
      id: "minecraft:spruce_fence", 
      properties: {
        east: "false", 
        waterlogged: "false", 
        south: "false", 
        north: "true", 
        west: "false"
      }
    }, 
    {
      id: "minecraft:spruce_fence", 
      properties: {
        east: "false", 
        waterlogged: "false", 
        south: "false", 
        north: "false", 
        west: "true"
      }
    }, 
    {
      id: "minecraft:jigsaw", 
      properties: {
        orientation: "down_south"
      }
    }
  ]
}
