{
  size: [5, 7, 4], 
  entities: [], 
  blocks: [
    {
      pos: [0, 0, 0], 
      state: 0
    }, 
    {
      pos: [0, 0, 1], 
      state: 0
    }, 
    {
      pos: [0, 0, 2], 
      state: 0
    }, 
    {
      pos: [0, 0, 3], 
      state: 0
    }, 
    {
      pos: [1, 0, 0], 
      state: 0
    }, 
    {
      pos: [1, 0, 1], 
      state: 0
    }, 
    {
      pos: [1, 0, 2], 
      state: 0
    }, 
    {
      pos: [1, 0, 3], 
      state: 0
    }, 
    {
      pos: [2, 0, 0], 
      state: 0
    }, 
    {
      pos: [2, 0, 1], 
      state: 0
    }, 
    {
      pos: [2, 0, 2], 
      state: 0
    }, 
    {
      pos: [2, 0, 3], 
      state: 0
    }, 
    {
      pos: [3, 0, 0], 
      state: 0
    }, 
    {
      pos: [3, 0, 1], 
      state: 0
    }, 
    {
      pos: [3, 0, 2], 
      state: 0
    }, 
    {
      pos: [3, 0, 3], 
      state: 0
    }, 
    {
      pos: [4, 0, 0], 
      state: 0
    }, 
    {
      pos: [4, 0, 1], 
      state: 0
    }, 
    {
      pos: [4, 0, 2], 
      state: 0
    }, 
    {
      pos: [4, 0, 3], 
      state: 0
    }, 
    {
      pos: [0, 1, 0], 
      state: 0
    }, 
    {
      pos: [0, 1, 1], 
      state: 0
    }, 
    {
      pos: [0, 1, 2], 
      state: 0
    }, 
    {
      pos: [0, 1, 3], 
      state: 0
    }, 
    {
      pos: [1, 1, 0], 
      state: 1
    }, 
    {
      pos: [1, 1, 1], 
      state: 1
    }, 
    {
      pos: [1, 1, 2], 
      state: 1
    }, 
    {
      pos: [1, 1, 3], 
      state: 1
    }, 
    {
      pos: [2, 1, 0], 
      state: 1
    }, 
    {
      pos: [2, 1, 1], 
      state: 1
    }, 
    {
      pos: [2, 1, 2], 
      state: 1
    }, 
    {
      pos: [2, 1, 3], 
      state: 1
    }, 
    {
      pos: [3, 1, 0], 
      state: 1
    }, 
    {
      pos: [3, 1, 1], 
      state: 1
    }, 
    {
      pos: [3, 1, 2], 
      state: 1
    }, 
    {
      pos: [3, 1, 3], 
      state: 1
    }, 
    {
      pos: [4, 1, 0], 
      state: 0
    }, 
    {
      pos: [4, 1, 1], 
      state: 0
    }, 
    {
      pos: [4, 1, 2], 
      state: 0
    }, 
    {
      pos: [4, 1, 3], 
      state: 0
    }, 
    {
      pos: [0, 2, 0], 
      state: 2
    }, 
    {
      pos: [0, 2, 1], 
      state: 2
    }, 
    {
      pos: [0, 2, 2], 
      state: 2
    }, 
    {
      pos: [0, 2, 3], 
      state: 2
    }, 
    {
      pos: [1, 2, 1], 
      state: 3
    }, 
    {
      pos: [1, 2, 2], 
      state: 4
    }, 
    {
      pos: [1, 2, 3], 
      state: 4
    }, 
    {
      pos: [2, 2, 1], 
      state: 3
    }, 
    {
      pos: [2, 2, 2], 
      state: 4
    }, 
    {
      pos: [2, 2, 3], 
      state: 4
    }, 
    {
      pos: [3, 2, 1], 
      state: 3
    }, 
    {
      pos: [3, 2, 3], 
      state: 4
    }, 
    {
      pos: [4, 2, 0], 
      state: 2
    }, 
    {
      pos: [4, 2, 1], 
      state: 2
    }, 
    {
      pos: [4, 2, 2], 
      state: 2
    }, 
    {
      pos: [4, 2, 3], 
      state: 2
    }, 
    {
      pos: [0, 3, 0], 
      state: 0
    }, 
    {
      pos: [0, 3, 1], 
      state: 0
    }, 
    {
      pos: [0, 3, 2], 
      state: 5
    }, 
    {
      pos: [0, 3, 3], 
      state: 2
    }, 
    {
      pos: [1, 3, 1], 
      state: 3
    }, 
    {
      pos: [1, 3, 2], 
      state: 4
    }, 
    {
      pos: [1, 3, 3], 
      state: 4
    }, 
    {
      pos: [2, 3, 1], 
      state: 3
    }, 
    {
      pos: [2, 3, 3], 
      state: 4
    }, 
    {
      pos: [3, 3, 1], 
      state: 3
    }, 
    {
      pos: [3, 3, 3], 
      state: 4
    }, 
    {
      pos: [4, 3, 0], 
      state: 0
    }, 
    {
      pos: [4, 3, 1], 
      state: 0
    }, 
    {
      pos: [4, 3, 2], 
      state: 5
    }, 
    {
      pos: [4, 3, 3], 
      state: 0
    }, 
    {
      pos: [0, 4, 0], 
      state: 6
    }, 
    {
      pos: [0, 4, 1], 
      state: 6
    }, 
    {
      pos: [0, 4, 2], 
      state: 6
    }, 
    {
      pos: [0, 4, 3], 
      state: 6
    }, 
    {
      pos: [1, 4, 1], 
      state: 3
    }, 
    {
      pos: [1, 4, 3], 
      state: 4
    }, 
    {
      pos: [2, 4, 1], 
      state: 3
    }, 
    {
      pos: [2, 4, 3], 
      state: 4
    }, 
    {
      pos: [3, 4, 1], 
      state: 3
    }, 
    {
      pos: [3, 4, 3], 
      state: 4
    }, 
    {
      pos: [4, 4, 0], 
      state: 6
    }, 
    {
      pos: [4, 4, 1], 
      state: 6
    }, 
    {
      pos: [4, 4, 2], 
      state: 6
    }, 
    {
      pos: [4, 4, 3], 
      state: 6
    }, 
    {
      pos: [0, 5, 0], 
      state: 0
    }, 
    {
      pos: [0, 5, 1], 
      state: 0
    }, 
    {
      pos: [0, 5, 2], 
      state: 0
    }, 
    {
      pos: [0, 5, 3], 
      state: 0
    }, 
    {
      pos: [1, 5, 0], 
      state: 7
    }, 
    {
      pos: [1, 5, 1], 
      state: 7
    }, 
    {
      pos: [1, 5, 2], 
      state: 7
    }, 
    {
      pos: [1, 5, 3], 
      state: 7
    }, 
    {
      pos: [2, 5, 0], 
      state: 7
    }, 
    {
      pos: [2, 5, 1], 
      state: 7
    }, 
    {
      pos: [2, 5, 2], 
      state: 7
    }, 
    {
      pos: [2, 5, 3], 
      state: 7
    }, 
    {
      pos: [3, 5, 0], 
      state: 7
    }, 
    {
      pos: [3, 5, 1], 
      state: 7
    }, 
    {
      pos: [3, 5, 2], 
      state: 7
    }, 
    {
      pos: [3, 5, 3], 
      state: 7
    }, 
    {
      pos: [4, 5, 0], 
      state: 0
    }, 
    {
      pos: [4, 5, 1], 
      state: 0
    }, 
    {
      pos: [4, 5, 2], 
      state: 0
    }, 
    {
      pos: [4, 5, 3], 
      state: 0
    }, 
    {
      pos: [0, 6, 0], 
      state: 0
    }, 
    {
      pos: [0, 6, 1], 
      state: 0
    }, 
    {
      pos: [0, 6, 2], 
      state: 0
    }, 
    {
      pos: [0, 6, 3], 
      state: 0
    }, 
    {
      pos: [1, 6, 0], 
      state: 0
    }, 
    {
      pos: [1, 6, 1], 
      state: 0
    }, 
    {
      pos: [1, 6, 2], 
      state: 0
    }, 
    {
      pos: [1, 6, 3], 
      state: 0
    }, 
    {
      pos: [2, 6, 0], 
      state: 0
    }, 
    {
      pos: [2, 6, 1], 
      state: 0
    }, 
    {
      pos: [2, 6, 2], 
      state: 0
    }, 
    {
      pos: [2, 6, 3], 
      state: 0
    }, 
    {
      pos: [3, 6, 0], 
      state: 0
    }, 
    {
      pos: [3, 6, 1], 
      state: 0
    }, 
    {
      pos: [3, 6, 2], 
      state: 0
    }, 
    {
      pos: [3, 6, 3], 
      state: 0
    }, 
    {
      pos: [4, 6, 0], 
      state: 0
    }, 
    {
      pos: [4, 6, 1], 
      state: 0
    }, 
    {
      pos: [4, 6, 2], 
      state: 0
    }, 
    {
      pos: [4, 6, 3], 
      state: 0
    }, 
    {
      pos: [1, 2, 0], 
      state: 8
    }, 
    {
      pos: [3, 2, 0], 
      state: 8
    }, 
    {
      pos: [3, 2, 2], 
      state: 8
    }, 
    {
      pos: [1, 3, 0], 
      state: 8
    }, 
    {
      pos: [2, 3, 2], 
      state: 8
    }, 
    {
      pos: [3, 3, 0], 
      state: 8
    }, 
    {
      pos: [3, 3, 2], 
      state: 8
    }, 
    {
      pos: [1, 4, 0], 
      state: 8
    }, 
    {
      pos: [1, 4, 2], 
      state: 8
    }, 
    {
      pos: [2, 4, 0], 
      state: 8
    }, 
    {
      pos: [2, 4, 2], 
      state: 8
    }, 
    {
      pos: [3, 4, 0], 
      state: 8
    }, 
    {
      pos: [3, 4, 2], 
      state: 8
    }, 
    {
      nbt: {
        LootTable: "minecraft:chests/trial_chambers/reward", 
        id: "minecraft:chest"
      }, 
      pos: [2, 2, 0], 
      state: 9
    }, 
    {
      nbt: {
        joint: "rollable", 
        final_state: "minecraft:air", 
        name: "minecraft:chamber", 
        placement_priority: 0, 
        pool: "minecraft:empty", 
        selection_priority: 0, 
        id: "minecraft:jigsaw", 
        target: "minecraft:empty"
      }, 
      pos: [2, 3, 0], 
      state: 10
    }
  ], 
  palette: [
    {
      Name: "minecraft:tuff_bricks"
    }, 
    {
      Name: "minecraft:waxed_oxidized_copper"
    }, 
    {
      Name: "minecraft:waxed_copper_block"
    }, 
    {
      Properties: {
        waterlogged: "false"
      }, 
      Name: "minecraft:waxed_oxidized_copper_grate"
    }, 
    {
      Name: "minecraft:cobbled_deepslate"
    }, 
    {
      Properties: {
        powered: "false", 
        lit: "false"
      }, 
      Name: "minecraft:waxed_copper_bulb"
    }, 
    {
      Name: "minecraft:chiseled_tuff_bricks"
    }, 
    {
      Name: "minecraft:polished_tuff"
    }, 
    {
      Name: "minecraft:air"
    }, 
    {
      Properties: {
        waterlogged: "false", 
        facing: "north", 
        type: "single"
      }, 
      Name: "minecraft:chest"
    }, 
    {
      Properties: {
        orientation: "north_up"
      }, 
      Name: "minecraft:jigsaw"
    }
  ]
}
