{
  size: [8, 11, 19], 
  entities: [], 
  blocks: [
    {
      pos: [0, 0, 4], 
      state: 0
    }, 
    {
      pos: [0, 0, 5], 
      state: 0
    }, 
    {
      pos: [0, 0, 6], 
      state: 0
    }, 
    {
      pos: [0, 0, 7], 
      state: 0
    }, 
    {
      pos: [0, 0, 8], 
      state: 0
    }, 
    {
      pos: [0, 0, 9], 
      state: 0
    }, 
    {
      pos: [0, 0, 10], 
      state: 0
    }, 
    {
      pos: [0, 0, 11], 
      state: 0
    }, 
    {
      pos: [0, 0, 12], 
      state: 0
    }, 
    {
      pos: [1, 0, 3], 
      state: 0
    }, 
    {
      pos: [1, 0, 4], 
      state: 0
    }, 
    {
      pos: [1, 0, 5], 
      state: 0
    }, 
    {
      pos: [1, 0, 6], 
      state: 0
    }, 
    {
      pos: [1, 0, 7], 
      state: 0
    }, 
    {
      pos: [1, 0, 8], 
      state: 0
    }, 
    {
      pos: [1, 0, 9], 
      state: 0
    }, 
    {
      pos: [1, 0, 11], 
      state: 0
    }, 
    {
      pos: [1, 0, 12], 
      state: 0
    }, 
    {
      pos: [2, 0, 3], 
      state: 0
    }, 
    {
      pos: [2, 0, 4], 
      state: 0
    }, 
    {
      pos: [2, 0, 5], 
      state: 0
    }, 
    {
      pos: [2, 0, 6], 
      state: 1
    }, 
    {
      pos: [2, 0, 7], 
      state: 1
    }, 
    {
      pos: [2, 0, 9], 
      state: 0
    }, 
    {
      pos: [2, 0, 11], 
      state: 0
    }, 
    {
      pos: [2, 0, 12], 
      state: 0
    }, 
    {
      pos: [3, 0, 5], 
      state: 1
    }, 
    {
      pos: [3, 0, 6], 
      state: 1
    }, 
    {
      pos: [3, 0, 9], 
      state: 1
    }, 
    {
      pos: [3, 0, 12], 
      state: 1
    }, 
    {
      pos: [4, 0, 9], 
      state: 1
    }, 
    {
      pos: [4, 0, 12], 
      state: 1
    }, 
    {
      pos: [0, 1, 3], 
      state: 0
    }, 
    {
      pos: [0, 1, 4], 
      state: 0
    }, 
    {
      pos: [0, 1, 5], 
      state: 0
    }, 
    {
      pos: [0, 1, 6], 
      state: 0
    }, 
    {
      pos: [0, 1, 7], 
      state: 0
    }, 
    {
      pos: [0, 1, 8], 
      state: 0
    }, 
    {
      pos: [0, 1, 9], 
      state: 0
    }, 
    {
      pos: [0, 1, 10], 
      state: 0
    }, 
    {
      pos: [0, 1, 11], 
      state: 0
    }, 
    {
      pos: [0, 1, 12], 
      state: 0
    }, 
    {
      pos: [1, 1, 3], 
      state: 0
    }, 
    {
      pos: [1, 1, 4], 
      state: 0
    }, 
    {
      pos: [1, 1, 5], 
      state: 0
    }, 
    {
      pos: [1, 1, 6], 
      state: 0
    }, 
    {
      pos: [1, 1, 7], 
      state: 1
    }, 
    {
      pos: [1, 1, 8], 
      state: 0
    }, 
    {
      pos: [1, 1, 10], 
      state: 0
    }, 
    {
      pos: [1, 1, 11], 
      state: 1
    }, 
    {
      pos: [1, 1, 12], 
      state: 0
    }, 
    {
      pos: [2, 1, 4], 
      state: 0
    }, 
    {
      pos: [2, 1, 6], 
      state: 1
    }, 
    {
      pos: [2, 1, 7], 
      state: 1
    }, 
    {
      pos: [2, 1, 10], 
      state: 0
    }, 
    {
      pos: [2, 1, 11], 
      state: 1
    }, 
    {
      pos: [2, 1, 12], 
      state: 1
    }, 
    {
      pos: [3, 1, 6], 
      state: 1
    }, 
    {
      pos: [3, 1, 11], 
      state: 1
    }, 
    {
      pos: [4, 1, 11], 
      state: 1
    }, 
    {
      pos: [5, 1, 11], 
      state: 1
    }, 
    {
      pos: [0, 2, 3], 
      state: 1
    }, 
    {
      pos: [0, 2, 5], 
      state: 1
    }, 
    {
      pos: [0, 2, 6], 
      state: 1
    }, 
    {
      pos: [0, 2, 7], 
      state: 1
    }, 
    {
      pos: [0, 2, 8], 
      state: 1
    }, 
    {
      pos: [0, 2, 9], 
      state: 0
    }, 
    {
      pos: [0, 2, 10], 
      state: 1
    }, 
    {
      pos: [0, 2, 11], 
      state: 1
    }, 
    {
      pos: [0, 2, 12], 
      state: 0
    }, 
    {
      pos: [1, 2, 4], 
      state: 1
    }, 
    {
      pos: [1, 2, 5], 
      state: 1
    }, 
    {
      pos: [1, 2, 7], 
      state: 1
    }, 
    {
      pos: [1, 2, 8], 
      state: 1
    }, 
    {
      pos: [1, 2, 10], 
      state: 1
    }, 
    {
      pos: [1, 2, 11], 
      state: 1
    }, 
    {
      pos: [1, 2, 12], 
      state: 1
    }, 
    {
      pos: [2, 2, 5], 
      state: 1
    }, 
    {
      pos: [2, 2, 10], 
      state: 0
    }, 
    {
      pos: [2, 2, 11], 
      state: 0
    }, 
    {
      pos: [2, 2, 12], 
      state: 1
    }, 
    {
      pos: [3, 2, 12], 
      state: 1
    }, 
    {
      pos: [4, 2, 12], 
      state: 1
    }, 
    {
      pos: [0, 3, 6], 
      state: 1
    }, 
    {
      pos: [0, 3, 8], 
      state: 1
    }, 
    {
      pos: [1, 3, 5], 
      state: 1
    }, 
    {
      pos: [1, 3, 8], 
      state: 1
    }, 
    {
      pos: [0, 0, 1], 
      state: 2
    }, 
    {
      pos: [0, 0, 14], 
      state: 2
    }, 
    {
      pos: [0, 0, 15], 
      state: 2
    }, 
    {
      pos: [0, 0, 16], 
      state: 2
    }, 
    {
      pos: [0, 0, 17], 
      state: 2
    }, 
    {
      pos: [0, 0, 18], 
      state: 2
    }, 
    {
      pos: [1, 0, 16], 
      state: 2
    }, 
    {
      pos: [1, 0, 17], 
      state: 2
    }, 
    {
      pos: [2, 0, 8], 
      state: 2
    }, 
    {
      pos: [3, 0, 7], 
      state: 2
    }, 
    {
      pos: [3, 0, 8], 
      state: 2
    }, 
    {
      pos: [3, 0, 10], 
      state: 2
    }, 
    {
      pos: [3, 0, 14], 
      state: 2
    }, 
    {
      pos: [4, 0, 8], 
      state: 2
    }, 
    {
      pos: [4, 0, 10], 
      state: 2
    }, 
    {
      pos: [0, 1, 2], 
      state: 2
    }, 
    {
      pos: [0, 1, 14], 
      state: 2
    }, 
    {
      pos: [0, 1, 15], 
      state: 2
    }, 
    {
      pos: [0, 1, 16], 
      state: 2
    }, 
    {
      pos: [0, 1, 17], 
      state: 2
    }, 
    {
      pos: [1, 1, 16], 
      state: 2
    }, 
    {
      pos: [1, 1, 17], 
      state: 2
    }, 
    {
      pos: [2, 1, 8], 
      state: 2
    }, 
    {
      pos: [3, 1, 7], 
      state: 2
    }, 
    {
      pos: [3, 1, 8], 
      state: 2
    }, 
    {
      pos: [3, 1, 10], 
      state: 2
    }, 
    {
      pos: [4, 1, 7], 
      state: 2
    }, 
    {
      pos: [4, 1, 8], 
      state: 2
    }, 
    {
      pos: [4, 1, 9], 
      state: 2
    }, 
    {
      pos: [4, 1, 10], 
      state: 2
    }, 
    {
      pos: [0, 2, 13], 
      state: 2
    }, 
    {
      pos: [0, 2, 14], 
      state: 2
    }, 
    {
      pos: [0, 2, 15], 
      state: 2
    }, 
    {
      pos: [0, 2, 16], 
      state: 2
    }, 
    {
      pos: [0, 2, 17], 
      state: 2
    }, 
    {
      pos: [1, 2, 6], 
      state: 2
    }, 
    {
      pos: [1, 2, 9], 
      state: 2
    }, 
    {
      pos: [1, 2, 16], 
      state: 2
    }, 
    {
      pos: [1, 2, 17], 
      state: 2
    }, 
    {
      pos: [2, 2, 4], 
      state: 2
    }, 
    {
      pos: [2, 2, 6], 
      state: 2
    }, 
    {
      pos: [2, 2, 7], 
      state: 2
    }, 
    {
      pos: [2, 2, 8], 
      state: 2
    }, 
    {
      pos: [2, 2, 9], 
      state: 2
    }, 
    {
      pos: [3, 2, 7], 
      state: 2
    }, 
    {
      pos: [3, 2, 8], 
      state: 2
    }, 
    {
      pos: [3, 2, 9], 
      state: 2
    }, 
    {
      pos: [3, 2, 10], 
      state: 2
    }, 
    {
      pos: [3, 2, 11], 
      state: 2
    }, 
    {
      pos: [3, 2, 14], 
      state: 2
    }, 
    {
      pos: [4, 2, 8], 
      state: 2
    }, 
    {
      pos: [4, 2, 9], 
      state: 2
    }, 
    {
      pos: [4, 2, 10], 
      state: 2
    }, 
    {
      pos: [4, 2, 11], 
      state: 2
    }, 
    {
      pos: [5, 2, 8], 
      state: 2
    }, 
    {
      pos: [5, 2, 11], 
      state: 2
    }, 
    {
      pos: [0, 3, 3], 
      state: 2
    }, 
    {
      pos: [0, 3, 4], 
      state: 2
    }, 
    {
      pos: [0, 3, 5], 
      state: 2
    }, 
    {
      pos: [0, 3, 7], 
      state: 2
    }, 
    {
      pos: [0, 3, 9], 
      state: 2
    }, 
    {
      pos: [0, 3, 10], 
      state: 2
    }, 
    {
      pos: [0, 3, 11], 
      state: 2
    }, 
    {
      pos: [0, 3, 12], 
      state: 2
    }, 
    {
      pos: [0, 3, 14], 
      state: 2
    }, 
    {
      pos: [0, 3, 15], 
      state: 2
    }, 
    {
      pos: [0, 3, 16], 
      state: 2
    }, 
    {
      pos: [0, 3, 17], 
      state: 2
    }, 
    {
      pos: [1, 3, 4], 
      state: 2
    }, 
    {
      pos: [1, 3, 6], 
      state: 2
    }, 
    {
      pos: [1, 3, 7], 
      state: 2
    }, 
    {
      pos: [1, 3, 9], 
      state: 2
    }, 
    {
      pos: [1, 3, 10], 
      state: 2
    }, 
    {
      pos: [1, 3, 11], 
      state: 2
    }, 
    {
      pos: [1, 3, 12], 
      state: 2
    }, 
    {
      pos: [1, 3, 13], 
      state: 2
    }, 
    {
      pos: [1, 3, 14], 
      state: 2
    }, 
    {
      pos: [1, 3, 15], 
      state: 2
    }, 
    {
      pos: [1, 3, 16], 
      state: 2
    }, 
    {
      pos: [1, 3, 17], 
      state: 2
    }, 
    {
      pos: [2, 3, 5], 
      state: 2
    }, 
    {
      pos: [2, 3, 6], 
      state: 2
    }, 
    {
      pos: [2, 3, 7], 
      state: 2
    }, 
    {
      pos: [2, 3, 8], 
      state: 2
    }, 
    {
      pos: [2, 3, 9], 
      state: 2
    }, 
    {
      pos: [2, 3, 10], 
      state: 2
    }, 
    {
      pos: [2, 3, 11], 
      state: 2
    }, 
    {
      pos: [2, 3, 12], 
      state: 2
    }, 
    {
      pos: [2, 3, 13], 
      state: 2
    }, 
    {
      pos: [2, 3, 14], 
      state: 2
    }, 
    {
      pos: [3, 3, 6], 
      state: 2
    }, 
    {
      pos: [3, 3, 7], 
      state: 2
    }, 
    {
      pos: [3, 3, 8], 
      state: 2
    }, 
    {
      pos: [3, 3, 9], 
      state: 2
    }, 
    {
      pos: [3, 3, 10], 
      state: 2
    }, 
    {
      pos: [3, 3, 11], 
      state: 2
    }, 
    {
      pos: [3, 3, 12], 
      state: 2
    }, 
    {
      pos: [3, 3, 13], 
      state: 2
    }, 
    {
      pos: [4, 3, 8], 
      state: 2
    }, 
    {
      pos: [4, 3, 10], 
      state: 2
    }, 
    {
      pos: [4, 3, 11], 
      state: 2
    }, 
    {
      pos: [0, 4, 3], 
      state: 2
    }, 
    {
      pos: [0, 4, 4], 
      state: 2
    }, 
    {
      pos: [0, 4, 5], 
      state: 2
    }, 
    {
      pos: [0, 4, 6], 
      state: 2
    }, 
    {
      pos: [0, 4, 7], 
      state: 2
    }, 
    {
      pos: [0, 4, 8], 
      state: 2
    }, 
    {
      pos: [0, 4, 9], 
      state: 2
    }, 
    {
      pos: [0, 4, 10], 
      state: 2
    }, 
    {
      pos: [0, 4, 11], 
      state: 2
    }, 
    {
      pos: [0, 4, 12], 
      state: 2
    }, 
    {
      pos: [0, 4, 13], 
      state: 2
    }, 
    {
      pos: [0, 4, 14], 
      state: 2
    }, 
    {
      pos: [0, 4, 15], 
      state: 2
    }, 
    {
      pos: [0, 4, 16], 
      state: 2
    }, 
    {
      pos: [1, 4, 3], 
      state: 2
    }, 
    {
      pos: [1, 4, 4], 
      state: 2
    }, 
    {
      pos: [1, 4, 5], 
      state: 2
    }, 
    {
      pos: [1, 4, 6], 
      state: 2
    }, 
    {
      pos: [1, 4, 7], 
      state: 2
    }, 
    {
      pos: [1, 4, 8], 
      state: 2
    }, 
    {
      pos: [1, 4, 9], 
      state: 2
    }, 
    {
      pos: [1, 4, 10], 
      state: 2
    }, 
    {
      pos: [1, 4, 11], 
      state: 2
    }, 
    {
      pos: [1, 4, 12], 
      state: 2
    }, 
    {
      pos: [1, 4, 13], 
      state: 2
    }, 
    {
      pos: [1, 4, 14], 
      state: 2
    }, 
    {
      pos: [1, 4, 15], 
      state: 2
    }, 
    {
      pos: [1, 4, 16], 
      state: 2
    }, 
    {
      pos: [1, 4, 17], 
      state: 2
    }, 
    {
      pos: [2, 4, 5], 
      state: 2
    }, 
    {
      pos: [2, 4, 6], 
      state: 2
    }, 
    {
      pos: [2, 4, 7], 
      state: 2
    }, 
    {
      pos: [2, 4, 8], 
      state: 2
    }, 
    {
      pos: [2, 4, 9], 
      state: 2
    }, 
    {
      pos: [2, 4, 10], 
      state: 2
    }, 
    {
      pos: [2, 4, 11], 
      state: 2
    }, 
    {
      pos: [2, 4, 12], 
      state: 2
    }, 
    {
      pos: [2, 4, 13], 
      state: 2
    }, 
    {
      pos: [2, 4, 14], 
      state: 2
    }, 
    {
      pos: [3, 4, 5], 
      state: 2
    }, 
    {
      pos: [3, 4, 6], 
      state: 2
    }, 
    {
      pos: [3, 4, 7], 
      state: 2
    }, 
    {
      pos: [3, 4, 8], 
      state: 2
    }, 
    {
      pos: [3, 4, 9], 
      state: 2
    }, 
    {
      pos: [3, 4, 10], 
      state: 2
    }, 
    {
      pos: [3, 4, 11], 
      state: 2
    }, 
    {
      pos: [4, 4, 8], 
      state: 2
    }, 
    {
      pos: [4, 4, 10], 
      state: 2
    }, 
    {
      pos: [4, 4, 11], 
      state: 2
    }, 
    {
      pos: [0, 5, 3], 
      state: 2
    }, 
    {
      pos: [0, 5, 4], 
      state: 2
    }, 
    {
      pos: [0, 5, 5], 
      state: 2
    }, 
    {
      pos: [0, 5, 6], 
      state: 2
    }, 
    {
      pos: [0, 5, 7], 
      state: 2
    }, 
    {
      pos: [0, 5, 8], 
      state: 2
    }, 
    {
      pos: [0, 5, 9], 
      state: 2
    }, 
    {
      pos: [0, 5, 10], 
      state: 2
    }, 
    {
      pos: [0, 5, 11], 
      state: 2
    }, 
    {
      pos: [0, 5, 12], 
      state: 2
    }, 
    {
      pos: [0, 5, 13], 
      state: 2
    }, 
    {
      pos: [0, 5, 14], 
      state: 2
    }, 
    {
      pos: [0, 5, 15], 
      state: 2
    }, 
    {
      pos: [0, 5, 16], 
      state: 2
    }, 
    {
      pos: [1, 5, 3], 
      state: 2
    }, 
    {
      pos: [1, 5, 4], 
      state: 2
    }, 
    {
      pos: [1, 5, 5], 
      state: 2
    }, 
    {
      pos: [1, 5, 6], 
      state: 2
    }, 
    {
      pos: [1, 5, 7], 
      state: 2
    }, 
    {
      pos: [1, 5, 8], 
      state: 2
    }, 
    {
      pos: [1, 5, 9], 
      state: 2
    }, 
    {
      pos: [1, 5, 10], 
      state: 2
    }, 
    {
      pos: [1, 5, 11], 
      state: 2
    }, 
    {
      pos: [1, 5, 12], 
      state: 2
    }, 
    {
      pos: [2, 5, 0], 
      state: 2
    }, 
    {
      pos: [2, 5, 5], 
      state: 2
    }, 
    {
      pos: [2, 5, 6], 
      state: 2
    }, 
    {
      pos: [2, 5, 7], 
      state: 2
    }, 
    {
      pos: [2, 5, 8], 
      state: 2
    }, 
    {
      pos: [2, 5, 9], 
      state: 2
    }, 
    {
      pos: [2, 5, 10], 
      state: 2
    }, 
    {
      pos: [2, 5, 11], 
      state: 2
    }, 
    {
      pos: [2, 5, 12], 
      state: 2
    }, 
    {
      pos: [2, 5, 13], 
      state: 2
    }, 
    {
      pos: [3, 5, 6], 
      state: 2
    }, 
    {
      pos: [3, 5, 7], 
      state: 2
    }, 
    {
      pos: [3, 5, 8], 
      state: 2
    }, 
    {
      pos: [3, 5, 9], 
      state: 2
    }, 
    {
      pos: [3, 5, 10], 
      state: 2
    }, 
    {
      pos: [3, 5, 11], 
      state: 2
    }, 
    {
      pos: [3, 5, 12], 
      state: 2
    }, 
    {
      pos: [4, 5, 10], 
      state: 2
    }, 
    {
      pos: [4, 5, 11], 
      state: 2
    }, 
    {
      pos: [4, 5, 12], 
      state: 2
    }, 
    {
      pos: [0, 6, 1], 
      state: 2
    }, 
    {
      pos: [0, 6, 3], 
      state: 2
    }, 
    {
      pos: [0, 6, 4], 
      state: 2
    }, 
    {
      pos: [0, 6, 5], 
      state: 2
    }, 
    {
      pos: [0, 6, 6], 
      state: 2
    }, 
    {
      pos: [0, 6, 7], 
      state: 2
    }, 
    {
      pos: [0, 6, 8], 
      state: 2
    }, 
    {
      pos: [0, 6, 9], 
      state: 2
    }, 
    {
      pos: [0, 6, 10], 
      state: 2
    }, 
    {
      pos: [0, 6, 11], 
      state: 2
    }, 
    {
      pos: [0, 6, 12], 
      state: 2
    }, 
    {
      pos: [0, 6, 13], 
      state: 2
    }, 
    {
      pos: [0, 6, 14], 
      state: 2
    }, 
    {
      pos: [0, 6, 15], 
      state: 2
    }, 
    {
      pos: [0, 6, 16], 
      state: 2
    }, 
    {
      pos: [1, 6, 0], 
      state: 2
    }, 
    {
      pos: [1, 6, 3], 
      state: 2
    }, 
    {
      pos: [1, 6, 4], 
      state: 2
    }, 
    {
      pos: [1, 6, 5], 
      state: 2
    }, 
    {
      pos: [1, 6, 6], 
      state: 2
    }, 
    {
      pos: [1, 6, 7], 
      state: 2
    }, 
    {
      pos: [1, 6, 8], 
      state: 2
    }, 
    {
      pos: [1, 6, 9], 
      state: 2
    }, 
    {
      pos: [1, 6, 10], 
      state: 2
    }, 
    {
      pos: [1, 6, 11], 
      state: 2
    }, 
    {
      pos: [1, 6, 12], 
      state: 2
    }, 
    {
      pos: [2, 6, 6], 
      state: 2
    }, 
    {
      pos: [2, 6, 7], 
      state: 2
    }, 
    {
      pos: [2, 6, 8], 
      state: 2
    }, 
    {
      pos: [2, 6, 9], 
      state: 2
    }, 
    {
      pos: [2, 6, 10], 
      state: 2
    }, 
    {
      pos: [2, 6, 11], 
      state: 2
    }, 
    {
      pos: [2, 6, 12], 
      state: 2
    }, 
    {
      pos: [3, 6, 8], 
      state: 2
    }, 
    {
      pos: [3, 6, 10], 
      state: 2
    }, 
    {
      pos: [3, 6, 11], 
      state: 2
    }, 
    {
      pos: [3, 6, 12], 
      state: 2
    }, 
    {
      pos: [4, 6, 10], 
      state: 2
    }, 
    {
      pos: [4, 6, 11], 
      state: 2
    }, 
    {
      pos: [0, 7, 4], 
      state: 2
    }, 
    {
      pos: [0, 7, 5], 
      state: 2
    }, 
    {
      pos: [0, 7, 6], 
      state: 2
    }, 
    {
      pos: [0, 7, 7], 
      state: 2
    }, 
    {
      pos: [0, 7, 8], 
      state: 2
    }, 
    {
      pos: [0, 7, 9], 
      state: 2
    }, 
    {
      pos: [0, 7, 10], 
      state: 2
    }, 
    {
      pos: [0, 7, 11], 
      state: 2
    }, 
    {
      pos: [0, 7, 12], 
      state: 2
    }, 
    {
      pos: [0, 7, 13], 
      state: 2
    }, 
    {
      pos: [0, 7, 14], 
      state: 2
    }, 
    {
      pos: [0, 7, 15], 
      state: 2
    }, 
    {
      pos: [1, 7, 6], 
      state: 2
    }, 
    {
      pos: [1, 7, 7], 
      state: 2
    }, 
    {
      pos: [1, 7, 8], 
      state: 2
    }, 
    {
      pos: [1, 7, 9], 
      state: 2
    }, 
    {
      pos: [1, 7, 10], 
      state: 2
    }, 
    {
      pos: [1, 7, 11], 
      state: 2
    }, 
    {
      pos: [1, 7, 12], 
      state: 2
    }, 
    {
      pos: [1, 7, 13], 
      state: 2
    }, 
    {
      pos: [2, 7, 8], 
      state: 2
    }, 
    {
      pos: [2, 7, 9], 
      state: 2
    }, 
    {
      pos: [2, 7, 10], 
      state: 2
    }, 
    {
      pos: [4, 7, 11], 
      state: 2
    }, 
    {
      pos: [0, 8, 8], 
      state: 2
    }, 
    {
      pos: [0, 8, 9], 
      state: 2
    }, 
    {
      pos: [0, 8, 10], 
      state: 2
    }, 
    {
      pos: [0, 8, 11], 
      state: 2
    }, 
    {
      pos: [0, 8, 12], 
      state: 2
    }, 
    {
      pos: [1, 8, 8], 
      state: 2
    }, 
    {
      pos: [1, 8, 9], 
      state: 2
    }, 
    {
      pos: [0, 9, 9], 
      state: 2
    }, 
    {
      pos: [0, 9, 10], 
      state: 2
    }, 
    {
      pos: [0, 9, 11], 
      state: 2
    }, 
    {
      pos: [1, 9, 9], 
      state: 2
    }, 
    {
      pos: [1, 9, 10], 
      state: 2
    }, 
    {
      pos: [1, 9, 11], 
      state: 2
    }, 
    {
      nbt: {
        joint: "rollable", 
        final_state: "minecraft:polished_blackstone_bricks", 
        name: "minecraft:back_bridge_connector_top", 
        pool: "minecraft:empty", 
        id: "minecraft:jigsaw", 
        target: "minecraft:empty"
      }, 
      pos: [0, 0, 3], 
      state: 3
    }
  ], 
  palette: [
    {
      Name: "minecraft:polished_blackstone_bricks"
    }, 
    {
      Name: "minecraft:blackstone"
    }, 
    {
      Name: "minecraft:air"
    }, 
    {
      Properties: {
        orientation: "west_up"
      }, 
      Name: "minecraft:jigsaw"
    }
  ]
}
