{
  size: [11, 9, 11], 
  entities: [], 
  blocks: [
    {
      pos: [0, 0, 0], 
      state: 0
    }, 
    {
      pos: [1, 0, 0], 
      state: 0
    }, 
    {
      pos: [2, 0, 0], 
      state: 0
    }, 
    {
      pos: [3, 0, 0], 
      state: 0
    }, 
    {
      pos: [6, 0, 0], 
      state: 0
    }, 
    {
      pos: [10, 0, 0], 
      state: 0
    }, 
    {
      pos: [1, 0, 1], 
      state: 0
    }, 
    {
      pos: [3, 0, 1], 
      state: 1
    }, 
    {
      pos: [4, 0, 1], 
      state: 0
    }, 
    {
      pos: [5, 0, 1], 
      state: 1
    }, 
    {
      pos: [6, 0, 1], 
      state: 0
    }, 
    {
      pos: [7, 0, 1], 
      state: 0
    }, 
    {
      pos: [8, 0, 1], 
      state: 1
    }, 
    {
      pos: [10, 0, 1], 
      state: 1
    }, 
    {
      pos: [0, 0, 2], 
      state: 0
    }, 
    {
      pos: [2, 0, 2], 
      state: 1
    }, 
    {
      pos: [3, 0, 2], 
      state: 0
    }, 
    {
      pos: [4, 0, 2], 
      state: 1
    }, 
    {
      pos: [5, 0, 2], 
      state: 1
    }, 
    {
      pos: [6, 0, 2], 
      state: 0
    }, 
    {
      pos: [9, 0, 2], 
      state: 0
    }, 
    {
      pos: [0, 0, 3], 
      state: 0
    }, 
    {
      pos: [2, 0, 3], 
      state: 0
    }, 
    {
      pos: [4, 0, 3], 
      state: 1
    }, 
    {
      pos: [6, 0, 3], 
      state: 1
    }, 
    {
      pos: [7, 0, 3], 
      state: 1
    }, 
    {
      pos: [8, 0, 3], 
      state: 0
    }, 
    {
      pos: [10, 0, 3], 
      state: 0
    }, 
    {
      pos: [1, 0, 4], 
      state: 0
    }, 
    {
      pos: [4, 0, 4], 
      state: 0
    }, 
    {
      pos: [5, 0, 4], 
      state: 0
    }, 
    {
      pos: [6, 0, 4], 
      state: 0
    }, 
    {
      pos: [7, 0, 4], 
      state: 0
    }, 
    {
      pos: [8, 0, 4], 
      state: 1
    }, 
    {
      pos: [10, 0, 4], 
      state: 1
    }, 
    {
      pos: [2, 0, 5], 
      state: 0
    }, 
    {
      pos: [3, 0, 5], 
      state: 1
    }, 
    {
      pos: [4, 0, 5], 
      state: 0
    }, 
    {
      pos: [6, 0, 5], 
      state: 0
    }, 
    {
      pos: [8, 0, 5], 
      state: 1
    }, 
    {
      pos: [9, 0, 5], 
      state: 1
    }, 
    {
      pos: [0, 0, 6], 
      state: 0
    }, 
    {
      pos: [1, 0, 6], 
      state: 1
    }, 
    {
      pos: [4, 0, 6], 
      state: 0
    }, 
    {
      pos: [5, 0, 6], 
      state: 0
    }, 
    {
      pos: [6, 0, 6], 
      state: 0
    }, 
    {
      pos: [7, 0, 6], 
      state: 1
    }, 
    {
      pos: [9, 0, 6], 
      state: 0
    }, 
    {
      pos: [10, 0, 6], 
      state: 0
    }, 
    {
      pos: [0, 0, 7], 
      state: 1
    }, 
    {
      pos: [1, 0, 7], 
      state: 0
    }, 
    {
      pos: [2, 0, 7], 
      state: 0
    }, 
    {
      pos: [4, 0, 7], 
      state: 0
    }, 
    {
      pos: [7, 0, 7], 
      state: 0
    }, 
    {
      pos: [8, 0, 7], 
      state: 1
    }, 
    {
      pos: [10, 0, 7], 
      state: 0
    }, 
    {
      pos: [0, 0, 8], 
      state: 0
    }, 
    {
      pos: [2, 0, 8], 
      state: 0
    }, 
    {
      pos: [3, 0, 8], 
      state: 1
    }, 
    {
      pos: [4, 0, 8], 
      state: 0
    }, 
    {
      pos: [6, 0, 8], 
      state: 1
    }, 
    {
      pos: [9, 0, 8], 
      state: 1
    }, 
    {
      pos: [0, 0, 9], 
      state: 0
    }, 
    {
      pos: [1, 0, 9], 
      state: 1
    }, 
    {
      pos: [3, 0, 9], 
      state: 0
    }, 
    {
      pos: [4, 0, 9], 
      state: 1
    }, 
    {
      pos: [6, 0, 9], 
      state: 0
    }, 
    {
      pos: [7, 0, 9], 
      state: 1
    }, 
    {
      pos: [9, 0, 9], 
      state: 0
    }, 
    {
      pos: [0, 0, 10], 
      state: 0
    }, 
    {
      pos: [1, 0, 10], 
      state: 0
    }, 
    {
      pos: [2, 0, 10], 
      state: 0
    }, 
    {
      pos: [4, 0, 10], 
      state: 0
    }, 
    {
      pos: [5, 0, 10], 
      state: 1
    }, 
    {
      pos: [7, 0, 10], 
      state: 0
    }, 
    {
      pos: [8, 0, 10], 
      state: 1
    }, 
    {
      pos: [9, 0, 10], 
      state: 0
    }, 
    {
      pos: [10, 0, 10], 
      state: 0
    }, 
    {
      nbt: {
        final_state: "minecraft:cobblestone", 
        name: "minecraft:bottom", 
        pool: "minecraft:village/common/cats", 
        id: "minecraft:jigsaw", 
        target: "minecraft:bottom"
      }, 
      pos: [3, 0, 3], 
      state: 2
    }, 
    {
      nbt: {
        final_state: "minecraft:cobblestone", 
        name: "minecraft:bottom", 
        pool: "minecraft:village/common/cats", 
        id: "minecraft:jigsaw", 
        target: "minecraft:bottom"
      }, 
      pos: [2, 0, 4], 
      state: 2
    }, 
    {
      pos: [4, 0, 0], 
      state: 3
    }, 
    {
      pos: [5, 0, 0], 
      state: 3
    }, 
    {
      pos: [7, 0, 0], 
      state: 3
    }, 
    {
      pos: [8, 0, 0], 
      state: 3
    }, 
    {
      pos: [9, 0, 0], 
      state: 3
    }, 
    {
      pos: [0, 0, 1], 
      state: 3
    }, 
    {
      pos: [2, 0, 1], 
      state: 3
    }, 
    {
      pos: [9, 0, 1], 
      state: 3
    }, 
    {
      pos: [1, 0, 2], 
      state: 3
    }, 
    {
      pos: [7, 0, 2], 
      state: 3
    }, 
    {
      pos: [8, 0, 2], 
      state: 3
    }, 
    {
      pos: [10, 0, 2], 
      state: 3
    }, 
    {
      pos: [1, 0, 3], 
      state: 3
    }, 
    {
      pos: [5, 0, 3], 
      state: 3
    }, 
    {
      pos: [9, 0, 3], 
      state: 3
    }, 
    {
      pos: [0, 0, 4], 
      state: 3
    }, 
    {
      pos: [3, 0, 4], 
      state: 3
    }, 
    {
      pos: [9, 0, 4], 
      state: 3
    }, 
    {
      pos: [0, 0, 5], 
      state: 3
    }, 
    {
      pos: [1, 0, 5], 
      state: 3
    }, 
    {
      pos: [5, 0, 5], 
      state: 3
    }, 
    {
      pos: [7, 0, 5], 
      state: 3
    }, 
    {
      pos: [10, 0, 5], 
      state: 3
    }, 
    {
      pos: [2, 0, 6], 
      state: 3
    }, 
    {
      pos: [3, 0, 6], 
      state: 3
    }, 
    {
      pos: [8, 0, 6], 
      state: 3
    }, 
    {
      pos: [3, 0, 7], 
      state: 3
    }, 
    {
      pos: [5, 0, 7], 
      state: 3
    }, 
    {
      pos: [6, 0, 7], 
      state: 3
    }, 
    {
      pos: [9, 0, 7], 
      state: 3
    }, 
    {
      pos: [1, 0, 8], 
      state: 3
    }, 
    {
      pos: [5, 0, 8], 
      state: 3
    }, 
    {
      pos: [7, 0, 8], 
      state: 3
    }, 
    {
      pos: [8, 0, 8], 
      state: 3
    }, 
    {
      pos: [10, 0, 8], 
      state: 3
    }, 
    {
      pos: [2, 0, 9], 
      state: 3
    }, 
    {
      pos: [5, 0, 9], 
      state: 3
    }, 
    {
      pos: [8, 0, 9], 
      state: 3
    }, 
    {
      pos: [10, 0, 9], 
      state: 3
    }, 
    {
      pos: [3, 0, 10], 
      state: 3
    }, 
    {
      pos: [6, 0, 10], 
      state: 3
    }, 
    {
      pos: [5, 1, 5], 
      state: 4
    }, 
    {
      nbt: {
        final_state: "minecraft:structure_void", 
        name: "minecraft:street", 
        pool: "minecraft:village/plains/zombie/streets", 
        id: "minecraft:jigsaw", 
        target: "minecraft:street"
      }, 
      pos: [0, 1, 5], 
      state: 5
    }, 
    {
      nbt: {
        final_state: "minecraft:structure_void", 
        name: "minecraft:street", 
        pool: "minecraft:village/plains/zombie/streets", 
        id: "minecraft:jigsaw", 
        target: "minecraft:street"
      }, 
      pos: [10, 1, 5], 
      state: 6
    }, 
    {
      nbt: {
        final_state: "minecraft:structure_void", 
        name: "minecraft:street", 
        pool: "minecraft:village/plains/zombie/streets", 
        id: "minecraft:jigsaw", 
        target: "minecraft:street"
      }, 
      pos: [5, 1, 10], 
      state: 7
    }, 
    {
      pos: [0, 1, 0], 
      state: 8
    }, 
    {
      pos: [2, 1, 0], 
      state: 8
    }, 
    {
      pos: [3, 1, 0], 
      state: 8
    }, 
    {
      pos: [4, 1, 1], 
      state: 9
    }, 
    {
      pos: [6, 1, 1], 
      state: 9
    }, 
    {
      pos: [7, 1, 1], 
      state: 10
    }, 
    {
      pos: [6, 1, 2], 
      state: 8
    }, 
    {
      pos: [9, 1, 2], 
      state: 8
    }, 
    {
      pos: [0, 1, 3], 
      state: 8
    }, 
    {
      pos: [10, 1, 3], 
      state: 8
    }, 
    {
      pos: [4, 1, 4], 
      state: 11
    }, 
    {
      pos: [5, 1, 4], 
      state: 12
    }, 
    {
      pos: [6, 1, 4], 
      state: 13
    }, 
    {
      pos: [7, 1, 4], 
      state: 8
    }, 
    {
      pos: [2, 1, 5], 
      state: 8
    }, 
    {
      pos: [4, 1, 5], 
      state: 14
    }, 
    {
      pos: [6, 1, 5], 
      state: 15
    }, 
    {
      pos: [4, 1, 6], 
      state: 16
    }, 
    {
      pos: [5, 1, 6], 
      state: 17
    }, 
    {
      pos: [6, 1, 6], 
      state: 18
    }, 
    {
      pos: [9, 1, 6], 
      state: 8
    }, 
    {
      pos: [4, 1, 7], 
      state: 8
    }, 
    {
      pos: [2, 1, 8], 
      state: 8
    }, 
    {
      pos: [4, 1, 8], 
      state: 8
    }, 
    {
      pos: [4, 1, 9], 
      state: 9
    }, 
    {
      pos: [6, 1, 9], 
      state: 9
    }, 
    {
      pos: [7, 1, 10], 
      state: 8
    }, 
    {
      pos: [5, 2, 5], 
      state: 4
    }, 
    {
      pos: [4, 2, 1], 
      state: 9
    }, 
    {
      pos: [6, 2, 1], 
      state: 9
    }, 
    {
      pos: [4, 2, 9], 
      state: 9
    }, 
    {
      pos: [6, 2, 9], 
      state: 9
    }, 
    {
      pos: [5, 3, 5], 
      state: 4
    }, 
    {
      nbt: {
        id: "minecraft:bell"
      }, 
      pos: [5, 3, 1], 
      state: 19
    }, 
    {
      nbt: {
        id: "minecraft:bell"
      }, 
      pos: [5, 3, 9], 
      state: 20
    }, 
    {
      pos: [4, 3, 1], 
      state: 9
    }, 
    {
      pos: [6, 3, 1], 
      state: 9
    }, 
    {
      pos: [5, 3, 4], 
      state: 21
    }, 
    {
      pos: [4, 3, 5], 
      state: 22
    }, 
    {
      pos: [6, 3, 5], 
      state: 23
    }, 
    {
      pos: [5, 3, 6], 
      state: 24
    }, 
    {
      pos: [4, 3, 9], 
      state: 9
    }, 
    {
      pos: [6, 3, 9], 
      state: 9
    }, 
    {
      pos: [5, 4, 1], 
      state: 1
    }, 
    {
      pos: [5, 4, 5], 
      state: 4
    }, 
    {
      pos: [5, 4, 9], 
      state: 1
    }, 
    {
      pos: [4, 4, 1], 
      state: 25
    }, 
    {
      pos: [6, 4, 1], 
      state: 26
    }, 
    {
      pos: [4, 4, 9], 
      state: 25
    }, 
    {
      pos: [6, 4, 9], 
      state: 26
    }, 
    {
      pos: [4, 5, 3], 
      state: 27
    }, 
    {
      pos: [5, 5, 3], 
      state: 28
    }, 
    {
      pos: [3, 5, 4], 
      state: 27
    }, 
    {
      pos: [4, 5, 4], 
      state: 28
    }, 
    {
      pos: [5, 5, 4], 
      state: 29
    }, 
    {
      pos: [6, 5, 4], 
      state: 28
    }, 
    {
      pos: [7, 5, 4], 
      state: 27
    }, 
    {
      pos: [3, 5, 5], 
      state: 28
    }, 
    {
      pos: [4, 5, 5], 
      state: 29
    }, 
    {
      pos: [5, 5, 5], 
      state: 4
    }, 
    {
      pos: [6, 5, 5], 
      state: 29
    }, 
    {
      pos: [7, 5, 5], 
      state: 28
    }, 
    {
      pos: [3, 5, 6], 
      state: 27
    }, 
    {
      pos: [4, 5, 6], 
      state: 28
    }, 
    {
      pos: [5, 5, 6], 
      state: 29
    }, 
    {
      pos: [6, 5, 6], 
      state: 28
    }, 
    {
      pos: [7, 5, 6], 
      state: 27
    }, 
    {
      pos: [5, 5, 7], 
      state: 28
    }, 
    {
      pos: [4, 6, 3], 
      state: 27
    }, 
    {
      pos: [5, 6, 3], 
      state: 28
    }, 
    {
      pos: [6, 6, 3], 
      state: 27
    }, 
    {
      pos: [3, 6, 4], 
      state: 27
    }, 
    {
      pos: [4, 6, 4], 
      state: 28
    }, 
    {
      pos: [5, 6, 4], 
      state: 29
    }, 
    {
      pos: [6, 6, 4], 
      state: 28
    }, 
    {
      pos: [7, 6, 4], 
      state: 27
    }, 
    {
      pos: [3, 6, 5], 
      state: 28
    }, 
    {
      pos: [4, 6, 5], 
      state: 29
    }, 
    {
      pos: [5, 6, 5], 
      state: 4
    }, 
    {
      pos: [6, 6, 5], 
      state: 29
    }, 
    {
      pos: [7, 6, 5], 
      state: 28
    }, 
    {
      pos: [3, 6, 6], 
      state: 27
    }, 
    {
      pos: [4, 6, 6], 
      state: 28
    }, 
    {
      pos: [5, 6, 6], 
      state: 29
    }, 
    {
      pos: [6, 6, 6], 
      state: 28
    }, 
    {
      pos: [7, 6, 6], 
      state: 27
    }, 
    {
      pos: [4, 6, 7], 
      state: 27
    }, 
    {
      pos: [6, 6, 7], 
      state: 27
    }, 
    {
      pos: [4, 7, 4], 
      state: 28
    }, 
    {
      pos: [5, 7, 4], 
      state: 29
    }, 
    {
      pos: [6, 7, 4], 
      state: 28
    }, 
    {
      pos: [4, 7, 5], 
      state: 29
    }, 
    {
      pos: [5, 7, 5], 
      state: 4
    }, 
    {
      pos: [6, 7, 5], 
      state: 29
    }, 
    {
      pos: [4, 7, 6], 
      state: 28
    }, 
    {
      pos: [5, 7, 6], 
      state: 29
    }, 
    {
      pos: [6, 7, 6], 
      state: 28
    }, 
    {
      pos: [5, 8, 4], 
      state: 28
    }, 
    {
      pos: [4, 8, 5], 
      state: 28
    }, 
    {
      pos: [5, 8, 5], 
      state: 29
    }, 
    {
      pos: [6, 8, 5], 
      state: 28
    }, 
    {
      pos: [5, 8, 6], 
      state: 28
    }
  ], 
  palette: [
    {
      Properties: {
        snowy: "false"
      }, 
      Name: "minecraft:grass_block"
    }, 
    {
      Name: "minecraft:cobblestone"
    }, 
    {
      Properties: {
        orientation: "up_north"
      }, 
      Name: "minecraft:jigsaw"
    }, 
    {
      Name: "minecraft:grass_path"
    }, 
    {
      Properties: {
        axis: "y"
      }, 
      Name: "minecraft:oak_log"
    }, 
    {
      Properties: {
        orientation: "west_up"
      }, 
      Name: "minecraft:jigsaw"
    }, 
    {
      Properties: {
        orientation: "east_up"
      }, 
      Name: "minecraft:jigsaw"
    }, 
    {
      Properties: {
        orientation: "south_up"
      }, 
      Name: "minecraft:jigsaw"
    }, 
    {
      Name: "minecraft:grass"
    }, 
    {
      Properties: {
        east: "false", 
        waterlogged: "false", 
        south: "false", 
        north: "false", 
        west: "false"
      }, 
      Name: "minecraft:oak_fence"
    }, 
    {
      Name: "minecraft:dandelion"
    }, 
    {
      Properties: {
        half: "bottom", 
        waterlogged: "false", 
        shape: "outer_left", 
        facing: "south"
      }, 
      Name: "minecraft:cobblestone_stairs"
    }, 
    {
      Properties: {
        half: "bottom", 
        waterlogged: "false", 
        shape: "straight", 
        facing: "south"
      }, 
      Name: "minecraft:cobblestone_stairs"
    }, 
    {
      Properties: {
        half: "bottom", 
        waterlogged: "false", 
        shape: "outer_right", 
        facing: "south"
      }, 
      Name: "minecraft:cobblestone_stairs"
    }, 
    {
      Properties: {
        half: "bottom", 
        waterlogged: "false", 
        shape: "straight", 
        facing: "east"
      }, 
      Name: "minecraft:cobblestone_stairs"
    }, 
    {
      Properties: {
        half: "bottom", 
        waterlogged: "false", 
        shape: "straight", 
        facing: "west"
      }, 
      Name: "minecraft:cobblestone_stairs"
    }, 
    {
      Properties: {
        half: "bottom", 
        waterlogged: "false", 
        shape: "outer_right", 
        facing: "north"
      }, 
      Name: "minecraft:cobblestone_stairs"
    }, 
    {
      Properties: {
        half: "bottom", 
        waterlogged: "false", 
        shape: "straight", 
        facing: "north"
      }, 
      Name: "minecraft:cobblestone_stairs"
    }, 
    {
      Properties: {
        half: "bottom", 
        waterlogged: "false", 
        shape: "outer_right", 
        facing: "west"
      }, 
      Name: "minecraft:cobblestone_stairs"
    }, 
    {
      Properties: {
        attachment: "ceiling", 
        powered: "false", 
        facing: "south"
      }, 
      Name: "minecraft:bell"
    }, 
    {
      Properties: {
        attachment: "ceiling", 
        powered: "false", 
        facing: "north"
      }, 
      Name: "minecraft:bell"
    }, 
    {
      Properties: {
        facing: "north"
      }, 
      Name: "minecraft:wall_torch"
    }, 
    {
      Properties: {
        facing: "west"
      }, 
      Name: "minecraft:wall_torch"
    }, 
    {
      Properties: {
        facing: "east"
      }, 
      Name: "minecraft:wall_torch"
    }, 
    {
      Properties: {
        facing: "south"
      }, 
      Name: "minecraft:wall_torch"
    }, 
    {
      Properties: {
        east: "true", 
        waterlogged: "false", 
        south: "false", 
        north: "false", 
        west: "false"
      }, 
      Name: "minecraft:oak_fence"
    }, 
    {
      Properties: {
        east: "false", 
        waterlogged: "false", 
        south: "false", 
        north: "false", 
        west: "true"
      }, 
      Name: "minecraft:oak_fence"
    }, 
    {
      Properties: {
        distance: "3", 
        persistent: "false"
      }, 
      Name: "minecraft:oak_leaves"
    }, 
    {
      Properties: {
        distance: "2", 
        persistent: "false"
      }, 
      Name: "minecraft:oak_leaves"
    }, 
    {
      Properties: {
        distance: "1", 
        persistent: "false"
      }, 
      Name: "minecraft:oak_leaves"
    }
  ]
}
