{
  size: [5, 4, 3], 
  entities: [], 
  blocks: [
    {
      pos: [0, 0, 1], 
      state: 0
    }, 
    {
      pos: [0, 0, 2], 
      state: 0
    }, 
    {
      pos: [1, 0, 0], 
      state: 1
    }, 
    {
      pos: [1, 0, 1], 
      state: 1
    }, 
    {
      pos: [1, 0, 2], 
      state: 1
    }, 
    {
      pos: [2, 0, 0], 
      state: 1
    }, 
    {
      pos: [2, 0, 1], 
      state: 1
    }, 
    {
      pos: [2, 0, 2], 
      state: 1
    }, 
    {
      pos: [3, 0, 0], 
      state: 1
    }, 
    {
      pos: [3, 0, 1], 
      state: 1
    }, 
    {
      pos: [3, 0, 2], 
      state: 1
    }, 
    {
      pos: [4, 0, 0], 
      state: 0
    }, 
    {
      pos: [4, 0, 1], 
      state: 0
    }, 
    {
      pos: [4, 0, 2], 
      state: 0
    }, 
    {
      pos: [0, 1, 0], 
      state: 2
    }, 
    {
      pos: [0, 1, 1], 
      state: 3
    }, 
    {
      pos: [0, 1, 2], 
      state: 2
    }, 
    {
      pos: [1, 1, 0], 
      state: 3
    }, 
    {
      pos: [1, 1, 1], 
      state: 3
    }, 
    {
      pos: [1, 1, 2], 
      state: 3
    }, 
    {
      pos: [2, 1, 0], 
      state: 3
    }, 
    {
      pos: [2, 1, 1], 
      state: 3
    }, 
    {
      pos: [2, 1, 2], 
      state: 3
    }, 
    {
      pos: [3, 1, 0], 
      state: 3
    }, 
    {
      pos: [3, 1, 1], 
      state: 3
    }, 
    {
      pos: [3, 1, 2], 
      state: 3
    }, 
    {
      pos: [4, 1, 0], 
      state: 2
    }, 
    {
      pos: [4, 1, 1], 
      state: 3
    }, 
    {
      pos: [4, 1, 2], 
      state: 2
    }, 
    {
      pos: [0, 2, 0], 
      state: 2
    }, 
    {
      pos: [0, 2, 1], 
      state: 3
    }, 
    {
      pos: [0, 2, 2], 
      state: 2
    }, 
    {
      pos: [1, 2, 0], 
      state: 3
    }, 
    {
      pos: [1, 2, 1], 
      state: 3
    }, 
    {
      pos: [1, 2, 2], 
      state: 3
    }, 
    {
      pos: [2, 2, 0], 
      state: 3
    }, 
    {
      pos: [2, 2, 2], 
      state: 3
    }, 
    {
      pos: [3, 2, 0], 
      state: 3
    }, 
    {
      pos: [3, 2, 1], 
      state: 3
    }, 
    {
      pos: [3, 2, 2], 
      state: 3
    }, 
    {
      pos: [4, 2, 0], 
      state: 2
    }, 
    {
      pos: [4, 2, 1], 
      state: 3
    }, 
    {
      pos: [4, 2, 2], 
      state: 2
    }, 
    {
      pos: [0, 3, 0], 
      state: 2
    }, 
    {
      pos: [0, 3, 1], 
      state: 3
    }, 
    {
      pos: [0, 3, 2], 
      state: 2
    }, 
    {
      pos: [1, 3, 0], 
      state: 3
    }, 
    {
      pos: [1, 3, 1], 
      state: 3
    }, 
    {
      pos: [1, 3, 2], 
      state: 3
    }, 
    {
      pos: [2, 3, 0], 
      state: 3
    }, 
    {
      pos: [2, 3, 1], 
      state: 3
    }, 
    {
      pos: [2, 3, 2], 
      state: 3
    }, 
    {
      pos: [3, 3, 0], 
      state: 3
    }, 
    {
      pos: [3, 3, 1], 
      state: 3
    }, 
    {
      pos: [3, 3, 2], 
      state: 3
    }, 
    {
      pos: [4, 3, 0], 
      state: 2
    }, 
    {
      pos: [4, 3, 1], 
      state: 3
    }, 
    {
      pos: [4, 3, 2], 
      state: 2
    }, 
    {
      nbt: {
        joint: "aligned", 
        final_state: "minecraft:waxed_copper_block", 
        name: "minecraft:addon_upper", 
        placement_priority: 0, 
        pool: "minecraft:empty", 
        selection_priority: 0, 
        id: "minecraft:jigsaw", 
        target: "minecraft:empty"
      }, 
      pos: [0, 0, 0], 
      state: 4
    }, 
    {
      nbt: {
        joint: "aligned", 
        final_state: "minecraft:air", 
        name: "minecraft:empty", 
        placement_priority: 0, 
        pool: "minecraft:trial_chambers/spawner/all", 
        selection_priority: 0, 
        id: "minecraft:jigsaw", 
        target: "minecraft:spawner_connector"
      }, 
      pos: [2, 2, 1], 
      state: 5
    }
  ], 
  palette: [
    {
      Name: "minecraft:waxed_copper_block"
    }, 
    {
      Properties: {
        waterlogged: "false"
      }, 
      Name: "minecraft:waxed_copper_grate"
    }, 
    {
      Properties: {
        waterlogged: "false", 
        axis: "y"
      }, 
      Name: "minecraft:chain"
    }, 
    {
      Name: "minecraft:air"
    }, 
    {
      Properties: {
        orientation: "down_north"
      }, 
      Name: "minecraft:jigsaw"
    }, 
    {
      Properties: {
        orientation: "east_up"
      }, 
      Name: "minecraft:jigsaw"
    }
  ]
}
