{
  size: [7, 6, 8], 
  entities: [], 
  blocks: [
    {
      pos: [1, 0, 1], 
      state: 0
    }, 
    {
      pos: [1, 0, 2], 
      state: 0
    }, 
    {
      pos: [1, 0, 3], 
      state: 0
    }, 
    {
      pos: [1, 0, 4], 
      state: 0
    }, 
    {
      pos: [2, 0, 1], 
      state: 0
    }, 
    {
      pos: [2, 0, 2], 
      state: 1
    }, 
    {
      pos: [2, 0, 4], 
      state: 0
    }, 
    {
      pos: [2, 0, 5], 
      state: 0
    }, 
    {
      pos: [2, 0, 6], 
      state: 0
    }, 
    {
      pos: [3, 0, 1], 
      state: 0
    }, 
    {
      pos: [3, 0, 2], 
      state: 1
    }, 
    {
      pos: [3, 0, 3], 
      state: 1
    }, 
    {
      pos: [3, 0, 4], 
      state: 1
    }, 
    {
      pos: [3, 0, 5], 
      state: 2
    }, 
    {
      pos: [3, 0, 6], 
      state: 2
    }, 
    {
      pos: [4, 0, 1], 
      state: 0
    }, 
    {
      pos: [4, 0, 2], 
      state: 1
    }, 
    {
      pos: [4, 0, 3], 
      state: 1
    }, 
    {
      pos: [4, 0, 4], 
      state: 0
    }, 
    {
      pos: [4, 0, 5], 
      state: 0
    }, 
    {
      pos: [4, 0, 6], 
      state: 0
    }, 
    {
      pos: [5, 0, 1], 
      state: 0
    }, 
    {
      pos: [5, 0, 2], 
      state: 0
    }, 
    {
      pos: [5, 0, 3], 
      state: 0
    }, 
    {
      pos: [5, 0, 4], 
      state: 0
    }, 
    {
      pos: [1, 1, 1], 
      state: 1
    }, 
    {
      pos: [1, 1, 2], 
      state: 1
    }, 
    {
      pos: [1, 1, 3], 
      state: 1
    }, 
    {
      pos: [1, 1, 4], 
      state: 1
    }, 
    {
      pos: [2, 1, 1], 
      state: 1
    }, 
    {
      pos: [2, 1, 2], 
      state: 3
    }, 
    {
      pos: [2, 1, 4], 
      state: 1
    }, 
    {
      pos: [2, 1, 5], 
      state: 2
    }, 
    {
      pos: [2, 1, 6], 
      state: 2
    }, 
    {
      pos: [3, 1, 1], 
      state: 1
    }, 
    {
      pos: [4, 1, 1], 
      state: 1
    }, 
    {
      pos: [4, 1, 4], 
      state: 1
    }, 
    {
      pos: [4, 1, 5], 
      state: 2
    }, 
    {
      pos: [4, 1, 6], 
      state: 2
    }, 
    {
      pos: [5, 1, 1], 
      state: 1
    }, 
    {
      pos: [5, 1, 2], 
      state: 1
    }, 
    {
      pos: [5, 1, 3], 
      state: 1
    }, 
    {
      pos: [5, 1, 4], 
      state: 1
    }, 
    {
      pos: [1, 2, 1], 
      state: 1
    }, 
    {
      pos: [1, 2, 2], 
      state: 1
    }, 
    {
      pos: [1, 2, 3], 
      state: 1
    }, 
    {
      pos: [1, 2, 4], 
      state: 1
    }, 
    {
      pos: [2, 2, 4], 
      state: 1
    }, 
    {
      pos: [2, 2, 5], 
      state: 2
    }, 
    {
      pos: [2, 2, 6], 
      state: 2
    }, 
    {
      pos: [3, 2, 1], 
      state: 1
    }, 
    {
      pos: [4, 2, 4], 
      state: 1
    }, 
    {
      pos: [4, 2, 5], 
      state: 2
    }, 
    {
      pos: [4, 2, 6], 
      state: 2
    }, 
    {
      pos: [5, 2, 1], 
      state: 1
    }, 
    {
      pos: [5, 2, 2], 
      state: 1
    }, 
    {
      pos: [5, 2, 3], 
      state: 1
    }, 
    {
      pos: [5, 2, 4], 
      state: 1
    }, 
    {
      pos: [0, 3, 0], 
      state: 4
    }, 
    {
      pos: [0, 3, 5], 
      state: 4
    }, 
    {
      pos: [1, 3, 0], 
      state: 4
    }, 
    {
      pos: [1, 3, 1], 
      state: 1
    }, 
    {
      pos: [1, 3, 2], 
      state: 1
    }, 
    {
      pos: [1, 3, 3], 
      state: 1
    }, 
    {
      pos: [1, 3, 4], 
      state: 1
    }, 
    {
      pos: [1, 3, 5], 
      state: 5
    }, 
    {
      pos: [1, 3, 6], 
      state: 5
    }, 
    {
      pos: [1, 3, 7], 
      state: 5
    }, 
    {
      pos: [2, 3, 0], 
      state: 4
    }, 
    {
      pos: [2, 3, 1], 
      state: 1
    }, 
    {
      pos: [2, 3, 4], 
      state: 1
    }, 
    {
      pos: [2, 3, 5], 
      state: 2
    }, 
    {
      pos: [2, 3, 6], 
      state: 2
    }, 
    {
      pos: [3, 3, 0], 
      state: 4
    }, 
    {
      pos: [3, 3, 1], 
      state: 1
    }, 
    {
      pos: [3, 3, 4], 
      state: 1
    }, 
    {
      pos: [3, 3, 5], 
      state: 2
    }, 
    {
      pos: [3, 3, 6], 
      state: 2
    }, 
    {
      pos: [4, 3, 0], 
      state: 4
    }, 
    {
      pos: [4, 3, 1], 
      state: 1
    }, 
    {
      pos: [4, 3, 4], 
      state: 1
    }, 
    {
      pos: [4, 3, 5], 
      state: 2
    }, 
    {
      pos: [4, 3, 6], 
      state: 2
    }, 
    {
      pos: [5, 3, 0], 
      state: 4
    }, 
    {
      pos: [5, 3, 1], 
      state: 1
    }, 
    {
      pos: [5, 3, 2], 
      state: 1
    }, 
    {
      pos: [5, 3, 3], 
      state: 1
    }, 
    {
      pos: [5, 3, 4], 
      state: 1
    }, 
    {
      pos: [5, 3, 5], 
      state: 5
    }, 
    {
      pos: [5, 3, 6], 
      state: 5
    }, 
    {
      pos: [5, 3, 7], 
      state: 5
    }, 
    {
      pos: [6, 3, 0], 
      state: 4
    }, 
    {
      pos: [6, 3, 5], 
      state: 4
    }, 
    {
      pos: [0, 4, 1], 
      state: 4
    }, 
    {
      pos: [0, 4, 4], 
      state: 4
    }, 
    {
      pos: [1, 4, 1], 
      state: 4
    }, 
    {
      pos: [1, 4, 2], 
      state: 1
    }, 
    {
      pos: [1, 4, 3], 
      state: 1
    }, 
    {
      pos: [1, 4, 4], 
      state: 4
    }, 
    {
      pos: [2, 4, 1], 
      state: 4
    }, 
    {
      pos: [2, 4, 4], 
      state: 4
    }, 
    {
      pos: [2, 4, 5], 
      state: 5
    }, 
    {
      pos: [2, 4, 6], 
      state: 5
    }, 
    {
      pos: [2, 4, 7], 
      state: 5
    }, 
    {
      pos: [3, 4, 1], 
      state: 4
    }, 
    {
      pos: [3, 4, 4], 
      state: 5
    }, 
    {
      pos: [3, 4, 5], 
      state: 2
    }, 
    {
      pos: [3, 4, 6], 
      state: 2
    }, 
    {
      pos: [4, 4, 1], 
      state: 4
    }, 
    {
      pos: [4, 4, 4], 
      state: 4
    }, 
    {
      pos: [4, 4, 5], 
      state: 5
    }, 
    {
      pos: [4, 4, 6], 
      state: 5
    }, 
    {
      pos: [4, 4, 7], 
      state: 5
    }, 
    {
      pos: [5, 4, 1], 
      state: 4
    }, 
    {
      pos: [5, 4, 2], 
      state: 1
    }, 
    {
      pos: [5, 4, 3], 
      state: 1
    }, 
    {
      pos: [5, 4, 4], 
      state: 4
    }, 
    {
      pos: [6, 4, 1], 
      state: 4
    }, 
    {
      pos: [6, 4, 4], 
      state: 4
    }, 
    {
      pos: [0, 5, 2], 
      state: 4
    }, 
    {
      pos: [0, 5, 3], 
      state: 4
    }, 
    {
      pos: [1, 5, 2], 
      state: 4
    }, 
    {
      pos: [1, 5, 3], 
      state: 4
    }, 
    {
      pos: [2, 5, 2], 
      state: 4
    }, 
    {
      pos: [2, 5, 3], 
      state: 4
    }, 
    {
      pos: [3, 5, 2], 
      state: 4
    }, 
    {
      pos: [3, 5, 3], 
      state: 4
    }, 
    {
      pos: [3, 5, 4], 
      state: 5
    }, 
    {
      pos: [3, 5, 5], 
      state: 5
    }, 
    {
      pos: [3, 5, 6], 
      state: 5
    }, 
    {
      pos: [3, 5, 7], 
      state: 5
    }, 
    {
      pos: [4, 5, 2], 
      state: 4
    }, 
    {
      pos: [4, 5, 3], 
      state: 4
    }, 
    {
      pos: [5, 5, 2], 
      state: 4
    }, 
    {
      pos: [5, 5, 3], 
      state: 4
    }, 
    {
      pos: [6, 5, 2], 
      state: 4
    }, 
    {
      pos: [6, 5, 3], 
      state: 4
    }, 
    {
      pos: [0, 0, 0], 
      state: 6
    }, 
    {
      pos: [3, 0, 7], 
      state: 7
    }, 
    {
      pos: [0, 1, 0], 
      state: 6
    }, 
    {
      pos: [0, 1, 1], 
      state: 6
    }, 
    {
      pos: [0, 1, 2], 
      state: 6
    }, 
    {
      pos: [0, 1, 3], 
      state: 6
    }, 
    {
      pos: [0, 1, 4], 
      state: 6
    }, 
    {
      pos: [0, 1, 5], 
      state: 6
    }, 
    {
      pos: [0, 1, 6], 
      state: 6
    }, 
    {
      pos: [0, 1, 7], 
      state: 6
    }, 
    {
      pos: [1, 1, 0], 
      state: 6
    }, 
    {
      pos: [1, 1, 5], 
      state: 6
    }, 
    {
      pos: [1, 1, 6], 
      state: 6
    }, 
    {
      pos: [1, 1, 7], 
      state: 6
    }, 
    {
      pos: [2, 1, 3], 
      state: 6
    }, 
    {
      pos: [2, 1, 7], 
      state: 6
    }, 
    {
      pos: [3, 1, 0], 
      state: 6
    }, 
    {
      pos: [3, 1, 2], 
      state: 6
    }, 
    {
      pos: [3, 1, 3], 
      state: 6
    }, 
    {
      pos: [3, 1, 4], 
      state: 8
    }, 
    {
      pos: [3, 1, 5], 
      state: 6
    }, 
    {
      pos: [3, 1, 6], 
      state: 8
    }, 
    {
      pos: [4, 1, 0], 
      state: 6
    }, 
    {
      pos: [4, 1, 7], 
      state: 6
    }, 
    {
      pos: [5, 1, 0], 
      state: 6
    }, 
    {
      pos: [5, 1, 5], 
      state: 6
    }, 
    {
      pos: [5, 1, 6], 
      state: 6
    }, 
    {
      pos: [5, 1, 7], 
      state: 6
    }, 
    {
      pos: [6, 1, 0], 
      state: 6
    }, 
    {
      pos: [6, 1, 1], 
      state: 6
    }, 
    {
      pos: [6, 1, 2], 
      state: 6
    }, 
    {
      pos: [6, 1, 3], 
      state: 6
    }, 
    {
      pos: [6, 1, 4], 
      state: 6
    }, 
    {
      pos: [6, 1, 5], 
      state: 6
    }, 
    {
      pos: [6, 1, 6], 
      state: 6
    }, 
    {
      pos: [6, 1, 7], 
      state: 6
    }, 
    {
      pos: [0, 2, 0], 
      state: 6
    }, 
    {
      pos: [0, 2, 1], 
      state: 6
    }, 
    {
      pos: [0, 2, 2], 
      state: 6
    }, 
    {
      pos: [0, 2, 3], 
      state: 6
    }, 
    {
      pos: [0, 2, 4], 
      state: 6
    }, 
    {
      pos: [0, 2, 5], 
      state: 6
    }, 
    {
      pos: [0, 2, 6], 
      state: 6
    }, 
    {
      pos: [0, 2, 7], 
      state: 6
    }, 
    {
      pos: [1, 2, 0], 
      state: 9
    }, 
    {
      pos: [1, 2, 5], 
      state: 6
    }, 
    {
      pos: [1, 2, 6], 
      state: 6
    }, 
    {
      pos: [1, 2, 7], 
      state: 6
    }, 
    {
      pos: [2, 2, 0], 
      state: 6
    }, 
    {
      pos: [2, 2, 1], 
      state: 10
    }, 
    {
      pos: [2, 2, 2], 
      state: 6
    }, 
    {
      pos: [2, 2, 3], 
      state: 6
    }, 
    {
      pos: [2, 2, 7], 
      state: 6
    }, 
    {
      pos: [3, 2, 0], 
      state: 9
    }, 
    {
      pos: [3, 2, 2], 
      state: 6
    }, 
    {
      pos: [3, 2, 3], 
      state: 6
    }, 
    {
      pos: [3, 2, 4], 
      state: 11
    }, 
    {
      pos: [3, 2, 5], 
      state: 6
    }, 
    {
      pos: [3, 2, 6], 
      state: 11
    }, 
    {
      pos: [3, 2, 7], 
      state: 6
    }, 
    {
      pos: [4, 2, 0], 
      state: 6
    }, 
    {
      pos: [4, 2, 1], 
      state: 10
    }, 
    {
      pos: [4, 2, 2], 
      state: 6
    }, 
    {
      pos: [4, 2, 3], 
      state: 6
    }, 
    {
      pos: [4, 2, 7], 
      state: 6
    }, 
    {
      pos: [5, 2, 0], 
      state: 9
    }, 
    {
      pos: [5, 2, 5], 
      state: 6
    }, 
    {
      pos: [5, 2, 6], 
      state: 6
    }, 
    {
      pos: [5, 2, 7], 
      state: 6
    }, 
    {
      pos: [6, 2, 0], 
      state: 6
    }, 
    {
      pos: [6, 2, 1], 
      state: 6
    }, 
    {
      pos: [6, 2, 2], 
      state: 6
    }, 
    {
      pos: [6, 2, 3], 
      state: 6
    }, 
    {
      pos: [6, 2, 4], 
      state: 6
    }, 
    {
      pos: [6, 2, 5], 
      state: 6
    }, 
    {
      pos: [6, 2, 6], 
      state: 6
    }, 
    {
      pos: [6, 2, 7], 
      state: 6
    }, 
    {
      pos: [0, 3, 1], 
      state: 6
    }, 
    {
      pos: [0, 3, 2], 
      state: 6
    }, 
    {
      pos: [0, 3, 3], 
      state: 6
    }, 
    {
      pos: [0, 3, 4], 
      state: 6
    }, 
    {
      pos: [0, 3, 6], 
      state: 6
    }, 
    {
      pos: [0, 3, 7], 
      state: 6
    }, 
    {
      pos: [2, 3, 2], 
      state: 6
    }, 
    {
      pos: [2, 3, 3], 
      state: 6
    }, 
    {
      pos: [2, 3, 7], 
      state: 6
    }, 
    {
      pos: [3, 3, 2], 
      state: 6
    }, 
    {
      pos: [3, 3, 3], 
      state: 6
    }, 
    {
      pos: [3, 3, 7], 
      state: 12
    }, 
    {
      pos: [4, 3, 2], 
      state: 6
    }, 
    {
      pos: [4, 3, 3], 
      state: 6
    }, 
    {
      pos: [4, 3, 7], 
      state: 6
    }, 
    {
      pos: [6, 3, 1], 
      state: 6
    }, 
    {
      pos: [6, 3, 2], 
      state: 6
    }, 
    {
      pos: [6, 3, 3], 
      state: 6
    }, 
    {
      pos: [6, 3, 4], 
      state: 6
    }, 
    {
      pos: [6, 3, 6], 
      state: 6
    }, 
    {
      pos: [6, 3, 7], 
      state: 6
    }, 
    {
      pos: [0, 4, 0], 
      state: 6
    }, 
    {
      pos: [0, 4, 2], 
      state: 6
    }, 
    {
      pos: [0, 4, 3], 
      state: 6
    }, 
    {
      pos: [0, 4, 5], 
      state: 6
    }, 
    {
      pos: [0, 4, 6], 
      state: 6
    }, 
    {
      pos: [0, 4, 7], 
      state: 6
    }, 
    {
      pos: [1, 4, 0], 
      state: 6
    }, 
    {
      pos: [1, 4, 5], 
      state: 6
    }, 
    {
      pos: [1, 4, 6], 
      state: 6
    }, 
    {
      pos: [1, 4, 7], 
      state: 6
    }, 
    {
      pos: [2, 4, 0], 
      state: 6
    }, 
    {
      pos: [2, 4, 2], 
      state: 6
    }, 
    {
      pos: [2, 4, 3], 
      state: 6
    }, 
    {
      pos: [3, 4, 0], 
      state: 6
    }, 
    {
      pos: [3, 4, 2], 
      state: 12
    }, 
    {
      pos: [3, 4, 3], 
      state: 13
    }, 
    {
      pos: [3, 4, 7], 
      state: 6
    }, 
    {
      pos: [4, 4, 0], 
      state: 6
    }, 
    {
      pos: [4, 4, 2], 
      state: 6
    }, 
    {
      pos: [4, 4, 3], 
      state: 6
    }, 
    {
      pos: [5, 4, 0], 
      state: 6
    }, 
    {
      pos: [5, 4, 5], 
      state: 6
    }, 
    {
      pos: [5, 4, 6], 
      state: 6
    }, 
    {
      pos: [5, 4, 7], 
      state: 6
    }, 
    {
      pos: [6, 4, 0], 
      state: 6
    }, 
    {
      pos: [6, 4, 2], 
      state: 6
    }, 
    {
      pos: [6, 4, 3], 
      state: 6
    }, 
    {
      pos: [6, 4, 5], 
      state: 6
    }, 
    {
      pos: [6, 4, 6], 
      state: 6
    }, 
    {
      pos: [6, 4, 7], 
      state: 6
    }, 
    {
      pos: [0, 5, 0], 
      state: 6
    }, 
    {
      pos: [0, 5, 1], 
      state: 6
    }, 
    {
      pos: [0, 5, 4], 
      state: 6
    }, 
    {
      pos: [0, 5, 5], 
      state: 6
    }, 
    {
      pos: [0, 5, 6], 
      state: 6
    }, 
    {
      pos: [0, 5, 7], 
      state: 6
    }, 
    {
      pos: [1, 5, 0], 
      state: 6
    }, 
    {
      pos: [1, 5, 1], 
      state: 6
    }, 
    {
      pos: [1, 5, 4], 
      state: 6
    }, 
    {
      pos: [1, 5, 5], 
      state: 6
    }, 
    {
      pos: [1, 5, 6], 
      state: 6
    }, 
    {
      pos: [1, 5, 7], 
      state: 6
    }, 
    {
      pos: [2, 5, 0], 
      state: 6
    }, 
    {
      pos: [2, 5, 1], 
      state: 6
    }, 
    {
      pos: [2, 5, 4], 
      state: 6
    }, 
    {
      pos: [2, 5, 5], 
      state: 6
    }, 
    {
      pos: [2, 5, 6], 
      state: 6
    }, 
    {
      pos: [2, 5, 7], 
      state: 6
    }, 
    {
      pos: [3, 5, 0], 
      state: 6
    }, 
    {
      pos: [3, 5, 1], 
      state: 6
    }, 
    {
      pos: [4, 5, 0], 
      state: 6
    }, 
    {
      pos: [4, 5, 1], 
      state: 6
    }, 
    {
      pos: [4, 5, 4], 
      state: 6
    }, 
    {
      pos: [4, 5, 5], 
      state: 6
    }, 
    {
      pos: [4, 5, 6], 
      state: 6
    }, 
    {
      pos: [4, 5, 7], 
      state: 6
    }, 
    {
      pos: [5, 5, 0], 
      state: 6
    }, 
    {
      pos: [5, 5, 1], 
      state: 6
    }, 
    {
      pos: [5, 5, 4], 
      state: 6
    }, 
    {
      pos: [5, 5, 5], 
      state: 6
    }, 
    {
      pos: [5, 5, 6], 
      state: 6
    }, 
    {
      pos: [5, 5, 7], 
      state: 6
    }, 
    {
      pos: [6, 5, 0], 
      state: 6
    }, 
    {
      pos: [6, 5, 1], 
      state: 6
    }, 
    {
      pos: [6, 5, 4], 
      state: 6
    }, 
    {
      pos: [6, 5, 5], 
      state: 6
    }, 
    {
      pos: [6, 5, 6], 
      state: 6
    }, 
    {
      pos: [6, 5, 7], 
      state: 6
    }, 
    {
      nbt: {
        final_state: "minecraft:grass_block", 
        name: "minecraft:bottom", 
        pool: "minecraft:village/taiga/zombie/decor", 
        joint: "rollable", 
        id: "minecraft:jigsaw", 
        target: "minecraft:bottom"
      }, 
      pos: [0, 0, 6], 
      state: 14
    }, 
    {
      nbt: {
        final_state: "minecraft:cobblestone", 
        name: "minecraft:bottom", 
        pool: "minecraft:village/taiga/zombie/villagers", 
        joint: "rollable", 
        id: "minecraft:jigsaw", 
        target: "minecraft:bottom"
      }, 
      pos: [2, 0, 3], 
      state: 14
    }, 
    {
      nbt: {
        final_state: "minecraft:structure_void", 
        name: "minecraft:building_entrance", 
        pool: "minecraft:empty", 
        joint: "aligned", 
        id: "minecraft:jigsaw", 
        target: "minecraft:building_entrance"
      }, 
      pos: [3, 1, 7], 
      state: 15
    }, 
    {
      nbt: {
        id: "minecraft:bed"
      }, 
      pos: [4, 1, 2], 
      state: 16
    }, 
    {
      nbt: {
        id: "minecraft:bed"
      }, 
      pos: [4, 1, 3], 
      state: 17
    }
  ], 
  palette: [
    {
      Name: "minecraft:dirt"
    }, 
    {
      Name: "minecraft:cobblestone"
    }, 
    {
      Name: "minecraft:spruce_planks"
    }, 
    {
      Name: "minecraft:crafting_table"
    }, 
    {
      Properties: {
        axis: "x"
      }, 
      Name: "minecraft:spruce_log"
    }, 
    {
      Properties: {
        axis: "z"
      }, 
      Name: "minecraft:spruce_log"
    }, 
    {
      Name: "minecraft:air"
    }, 
    {
      Name: "minecraft:dirt_path"
    }, 
    {
      Properties: {
        hinge: "right", 
        half: "lower", 
        powered: "false", 
        facing: "north", 
        open: "false"
      }, 
      Name: "minecraft:spruce_door"
    }, 
    {
      Properties: {
        half: "top", 
        waterlogged: "false", 
        powered: "false", 
        facing: "north", 
        open: "true"
      }, 
      Name: "minecraft:spruce_trapdoor"
    }, 
    {
      Properties: {
        east: "true", 
        waterlogged: "false", 
        south: "false", 
        north: "false", 
        west: "true"
      }, 
      Name: "minecraft:glass_pane"
    }, 
    {
      Properties: {
        hinge: "right", 
        half: "upper", 
        powered: "false", 
        facing: "north", 
        open: "false"
      }, 
      Name: "minecraft:spruce_door"
    }, 
    {
      Properties: {
        facing: "south"
      }, 
      Name: "minecraft:wall_torch"
    }, 
    {
      Properties: {
        facing: "north"
      }, 
      Name: "minecraft:wall_torch"
    }, 
    {
      Properties: {
        orientation: "up_north"
      }, 
      Name: "minecraft:jigsaw"
    }, 
    {
      Properties: {
        orientation: "south_up"
      }, 
      Name: "minecraft:jigsaw"
    }, 
    {
      Properties: {
        part: "head", 
        facing: "north", 
        occupied: "false"
      }, 
      Name: "minecraft:blue_bed"
    }, 
    {
      Properties: {
        part: "foot", 
        facing: "north", 
        occupied: "false"
      }, 
      Name: "minecraft:blue_bed"
    }
  ]
}
