{
  size: [11, 16, 16], 
  entities: [], 
  blocks: [
    {
      pos: [2, 0, 0], 
      state: 0
    }, 
    {
      pos: [3, 0, 0], 
      state: 0
    }, 
    {
      pos: [4, 0, 0], 
      state: 0
    }, 
    {
      pos: [5, 0, 0], 
      state: 0
    }, 
    {
      pos: [6, 0, 0], 
      state: 0
    }, 
    {
      pos: [7, 0, 0], 
      state: 0
    }, 
    {
      pos: [8, 0, 0], 
      state: 0
    }, 
    {
      pos: [9, 0, 0], 
      state: 0
    }, 
    {
      pos: [1, 0, 1], 
      state: 0
    }, 
    {
      pos: [2, 0, 1], 
      state: 0
    }, 
    {
      pos: [3, 0, 1], 
      state: 0
    }, 
    {
      pos: [4, 0, 1], 
      state: 0
    }, 
    {
      pos: [5, 0, 1], 
      state: 0
    }, 
    {
      pos: [6, 0, 1], 
      state: 0
    }, 
    {
      pos: [7, 0, 1], 
      state: 0
    }, 
    {
      pos: [8, 0, 1], 
      state: 0
    }, 
    {
      pos: [9, 0, 1], 
      state: 0
    }, 
    {
      pos: [10, 0, 1], 
      state: 0
    }, 
    {
      pos: [0, 0, 2], 
      state: 0
    }, 
    {
      pos: [1, 0, 2], 
      state: 0
    }, 
    {
      pos: [2, 0, 2], 
      state: 0
    }, 
    {
      pos: [3, 0, 2], 
      state: 0
    }, 
    {
      pos: [4, 0, 2], 
      state: 0
    }, 
    {
      pos: [5, 0, 2], 
      state: 0
    }, 
    {
      pos: [6, 0, 2], 
      state: 0
    }, 
    {
      pos: [7, 0, 2], 
      state: 0
    }, 
    {
      pos: [8, 0, 2], 
      state: 0
    }, 
    {
      pos: [9, 0, 2], 
      state: 0
    }, 
    {
      pos: [10, 0, 2], 
      state: 0
    }, 
    {
      pos: [0, 0, 3], 
      state: 0
    }, 
    {
      pos: [1, 0, 3], 
      state: 0
    }, 
    {
      pos: [2, 0, 3], 
      state: 0
    }, 
    {
      pos: [3, 0, 3], 
      state: 0
    }, 
    {
      pos: [4, 0, 3], 
      state: 0
    }, 
    {
      pos: [5, 0, 3], 
      state: 0
    }, 
    {
      pos: [6, 0, 3], 
      state: 0
    }, 
    {
      pos: [7, 0, 3], 
      state: 0
    }, 
    {
      pos: [8, 0, 3], 
      state: 0
    }, 
    {
      pos: [9, 0, 3], 
      state: 0
    }, 
    {
      pos: [10, 0, 3], 
      state: 0
    }, 
    {
      pos: [0, 0, 4], 
      state: 0
    }, 
    {
      pos: [1, 0, 4], 
      state: 0
    }, 
    {
      pos: [2, 0, 4], 
      state: 0
    }, 
    {
      pos: [3, 0, 4], 
      state: 0
    }, 
    {
      pos: [4, 0, 4], 
      state: 0
    }, 
    {
      pos: [5, 0, 4], 
      state: 0
    }, 
    {
      pos: [6, 0, 4], 
      state: 0
    }, 
    {
      pos: [7, 0, 4], 
      state: 0
    }, 
    {
      pos: [8, 0, 4], 
      state: 0
    }, 
    {
      pos: [9, 0, 4], 
      state: 0
    }, 
    {
      pos: [10, 0, 4], 
      state: 0
    }, 
    {
      pos: [0, 0, 5], 
      state: 0
    }, 
    {
      pos: [1, 0, 5], 
      state: 0
    }, 
    {
      pos: [2, 0, 5], 
      state: 0
    }, 
    {
      pos: [3, 0, 5], 
      state: 0
    }, 
    {
      pos: [4, 0, 5], 
      state: 0
    }, 
    {
      pos: [5, 0, 5], 
      state: 0
    }, 
    {
      pos: [6, 0, 5], 
      state: 0
    }, 
    {
      pos: [7, 0, 5], 
      state: 0
    }, 
    {
      pos: [8, 0, 5], 
      state: 0
    }, 
    {
      pos: [9, 0, 5], 
      state: 0
    }, 
    {
      pos: [10, 0, 5], 
      state: 0
    }, 
    {
      pos: [0, 0, 6], 
      state: 0
    }, 
    {
      pos: [1, 0, 6], 
      state: 0
    }, 
    {
      pos: [2, 0, 6], 
      state: 0
    }, 
    {
      pos: [3, 0, 6], 
      state: 0
    }, 
    {
      pos: [4, 0, 6], 
      state: 0
    }, 
    {
      pos: [5, 0, 6], 
      state: 0
    }, 
    {
      pos: [6, 0, 6], 
      state: 0
    }, 
    {
      pos: [7, 0, 6], 
      state: 0
    }, 
    {
      pos: [8, 0, 6], 
      state: 0
    }, 
    {
      pos: [9, 0, 6], 
      state: 0
    }, 
    {
      pos: [10, 0, 6], 
      state: 0
    }, 
    {
      pos: [0, 0, 7], 
      state: 0
    }, 
    {
      pos: [1, 0, 7], 
      state: 0
    }, 
    {
      pos: [2, 0, 7], 
      state: 0
    }, 
    {
      pos: [3, 0, 7], 
      state: 0
    }, 
    {
      pos: [4, 0, 7], 
      state: 0
    }, 
    {
      pos: [5, 0, 7], 
      state: 0
    }, 
    {
      pos: [6, 0, 7], 
      state: 0
    }, 
    {
      pos: [7, 0, 7], 
      state: 0
    }, 
    {
      pos: [8, 0, 7], 
      state: 0
    }, 
    {
      pos: [9, 0, 7], 
      state: 0
    }, 
    {
      pos: [1, 0, 8], 
      state: 0
    }, 
    {
      pos: [2, 0, 8], 
      state: 0
    }, 
    {
      pos: [3, 0, 8], 
      state: 0
    }, 
    {
      pos: [4, 0, 8], 
      state: 0
    }, 
    {
      pos: [5, 0, 8], 
      state: 0
    }, 
    {
      pos: [6, 0, 8], 
      state: 0
    }, 
    {
      pos: [7, 0, 8], 
      state: 0
    }, 
    {
      pos: [8, 0, 8], 
      state: 0
    }, 
    {
      pos: [9, 0, 8], 
      state: 0
    }, 
    {
      pos: [10, 0, 8], 
      state: 0
    }, 
    {
      pos: [1, 0, 9], 
      state: 0
    }, 
    {
      pos: [2, 0, 9], 
      state: 0
    }, 
    {
      pos: [3, 0, 9], 
      state: 0
    }, 
    {
      pos: [4, 0, 9], 
      state: 0
    }, 
    {
      pos: [5, 0, 9], 
      state: 0
    }, 
    {
      pos: [6, 0, 9], 
      state: 0
    }, 
    {
      pos: [7, 0, 9], 
      state: 0
    }, 
    {
      pos: [8, 0, 9], 
      state: 0
    }, 
    {
      pos: [9, 0, 9], 
      state: 0
    }, 
    {
      pos: [10, 0, 9], 
      state: 0
    }, 
    {
      pos: [0, 0, 10], 
      state: 0
    }, 
    {
      pos: [1, 0, 10], 
      state: 0
    }, 
    {
      pos: [2, 0, 10], 
      state: 0
    }, 
    {
      pos: [3, 0, 10], 
      state: 0
    }, 
    {
      pos: [4, 0, 10], 
      state: 0
    }, 
    {
      pos: [5, 0, 10], 
      state: 0
    }, 
    {
      pos: [6, 0, 10], 
      state: 0
    }, 
    {
      pos: [7, 0, 10], 
      state: 0
    }, 
    {
      pos: [8, 0, 10], 
      state: 0
    }, 
    {
      pos: [9, 0, 10], 
      state: 0
    }, 
    {
      pos: [10, 0, 10], 
      state: 0
    }, 
    {
      pos: [0, 0, 11], 
      state: 0
    }, 
    {
      pos: [1, 0, 11], 
      state: 0
    }, 
    {
      pos: [2, 0, 11], 
      state: 0
    }, 
    {
      pos: [3, 0, 11], 
      state: 0
    }, 
    {
      pos: [4, 0, 11], 
      state: 0
    }, 
    {
      pos: [5, 0, 11], 
      state: 0
    }, 
    {
      pos: [6, 0, 11], 
      state: 0
    }, 
    {
      pos: [7, 0, 11], 
      state: 0
    }, 
    {
      pos: [8, 0, 11], 
      state: 0
    }, 
    {
      pos: [9, 0, 11], 
      state: 0
    }, 
    {
      pos: [10, 0, 11], 
      state: 0
    }, 
    {
      pos: [0, 0, 12], 
      state: 0
    }, 
    {
      pos: [1, 0, 12], 
      state: 0
    }, 
    {
      pos: [2, 0, 12], 
      state: 0
    }, 
    {
      pos: [3, 0, 12], 
      state: 0
    }, 
    {
      pos: [4, 0, 12], 
      state: 0
    }, 
    {
      pos: [5, 0, 12], 
      state: 0
    }, 
    {
      pos: [6, 0, 12], 
      state: 0
    }, 
    {
      pos: [7, 0, 12], 
      state: 0
    }, 
    {
      pos: [8, 0, 12], 
      state: 0
    }, 
    {
      pos: [9, 0, 12], 
      state: 0
    }, 
    {
      pos: [0, 0, 13], 
      state: 0
    }, 
    {
      pos: [1, 0, 13], 
      state: 0
    }, 
    {
      pos: [2, 0, 13], 
      state: 0
    }, 
    {
      pos: [3, 0, 13], 
      state: 0
    }, 
    {
      pos: [4, 0, 13], 
      state: 0
    }, 
    {
      pos: [5, 0, 13], 
      state: 0
    }, 
    {
      pos: [6, 0, 13], 
      state: 0
    }, 
    {
      pos: [7, 0, 13], 
      state: 0
    }, 
    {
      pos: [8, 0, 13], 
      state: 0
    }, 
    {
      pos: [1, 0, 14], 
      state: 0
    }, 
    {
      pos: [2, 0, 14], 
      state: 0
    }, 
    {
      pos: [3, 0, 14], 
      state: 0
    }, 
    {
      pos: [4, 0, 14], 
      state: 0
    }, 
    {
      pos: [5, 0, 14], 
      state: 0
    }, 
    {
      pos: [6, 0, 14], 
      state: 0
    }, 
    {
      pos: [7, 0, 14], 
      state: 0
    }, 
    {
      pos: [8, 0, 14], 
      state: 0
    }, 
    {
      pos: [3, 0, 15], 
      state: 0
    }, 
    {
      pos: [4, 0, 15], 
      state: 0
    }, 
    {
      pos: [5, 0, 15], 
      state: 0
    }, 
    {
      pos: [3, 1, 1], 
      state: 1
    }, 
    {
      pos: [4, 1, 1], 
      state: 1
    }, 
    {
      pos: [5, 1, 1], 
      state: 0
    }, 
    {
      pos: [6, 1, 1], 
      state: 0
    }, 
    {
      pos: [7, 1, 1], 
      state: 0
    }, 
    {
      pos: [8, 1, 1], 
      state: 0
    }, 
    {
      pos: [3, 1, 2], 
      state: 0
    }, 
    {
      pos: [4, 1, 2], 
      state: 0
    }, 
    {
      pos: [5, 1, 2], 
      state: 0
    }, 
    {
      pos: [6, 1, 2], 
      state: 0
    }, 
    {
      pos: [7, 1, 2], 
      state: 0
    }, 
    {
      pos: [9, 1, 2], 
      state: 0
    }, 
    {
      pos: [2, 1, 3], 
      state: 0
    }, 
    {
      pos: [3, 1, 3], 
      state: 0
    }, 
    {
      pos: [4, 1, 3], 
      state: 0
    }, 
    {
      pos: [5, 1, 3], 
      state: 0
    }, 
    {
      pos: [6, 1, 3], 
      state: 0
    }, 
    {
      pos: [7, 1, 3], 
      state: 0
    }, 
    {
      pos: [8, 1, 3], 
      state: 0
    }, 
    {
      pos: [9, 1, 3], 
      state: 0
    }, 
    {
      pos: [1, 1, 4], 
      state: 0
    }, 
    {
      pos: [3, 1, 4], 
      state: 0
    }, 
    {
      pos: [4, 1, 4], 
      state: 0
    }, 
    {
      pos: [8, 1, 4], 
      state: 0
    }, 
    {
      pos: [9, 1, 4], 
      state: 0
    }, 
    {
      pos: [1, 1, 5], 
      state: 0
    }, 
    {
      pos: [2, 1, 5], 
      state: 0
    }, 
    {
      pos: [3, 1, 5], 
      state: 0
    }, 
    {
      pos: [4, 1, 5], 
      state: 0
    }, 
    {
      pos: [8, 1, 5], 
      state: 0
    }, 
    {
      pos: [9, 1, 5], 
      state: 0
    }, 
    {
      pos: [1, 1, 6], 
      state: 0
    }, 
    {
      pos: [2, 1, 6], 
      state: 0
    }, 
    {
      pos: [3, 1, 6], 
      state: 0
    }, 
    {
      pos: [4, 1, 6], 
      state: 0
    }, 
    {
      pos: [8, 1, 6], 
      state: 0
    }, 
    {
      pos: [9, 1, 6], 
      state: 0
    }, 
    {
      pos: [1, 1, 7], 
      state: 0
    }, 
    {
      pos: [3, 1, 7], 
      state: 0
    }, 
    {
      pos: [4, 1, 7], 
      state: 0
    }, 
    {
      pos: [8, 1, 7], 
      state: 0
    }, 
    {
      pos: [9, 1, 7], 
      state: 0
    }, 
    {
      pos: [1, 1, 8], 
      state: 0
    }, 
    {
      pos: [2, 1, 8], 
      state: 0
    }, 
    {
      pos: [3, 1, 8], 
      state: 0
    }, 
    {
      pos: [4, 1, 8], 
      state: 0
    }, 
    {
      pos: [5, 1, 8], 
      state: 1
    }, 
    {
      pos: [8, 1, 8], 
      state: 0
    }, 
    {
      pos: [9, 1, 8], 
      state: 0
    }, 
    {
      pos: [1, 1, 9], 
      state: 0
    }, 
    {
      pos: [2, 1, 9], 
      state: 0
    }, 
    {
      pos: [3, 1, 9], 
      state: 0
    }, 
    {
      pos: [4, 1, 9], 
      state: 0
    }, 
    {
      pos: [5, 1, 9], 
      state: 0
    }, 
    {
      pos: [6, 1, 9], 
      state: 0
    }, 
    {
      pos: [7, 1, 9], 
      state: 0
    }, 
    {
      pos: [8, 1, 9], 
      state: 0
    }, 
    {
      pos: [1, 1, 10], 
      state: 0
    }, 
    {
      pos: [3, 1, 10], 
      state: 0
    }, 
    {
      pos: [4, 1, 10], 
      state: 0
    }, 
    {
      pos: [5, 1, 10], 
      state: 0
    }, 
    {
      pos: [6, 1, 10], 
      state: 0
    }, 
    {
      pos: [7, 1, 10], 
      state: 0
    }, 
    {
      pos: [8, 1, 10], 
      state: 0
    }, 
    {
      pos: [1, 1, 11], 
      state: 0
    }, 
    {
      pos: [3, 1, 11], 
      state: 0
    }, 
    {
      pos: [4, 1, 11], 
      state: 0
    }, 
    {
      pos: [5, 1, 11], 
      state: 0
    }, 
    {
      pos: [6, 1, 11], 
      state: 0
    }, 
    {
      pos: [7, 1, 11], 
      state: 0
    }, 
    {
      pos: [1, 1, 12], 
      state: 0
    }, 
    {
      pos: [2, 1, 12], 
      state: 0
    }, 
    {
      pos: [3, 1, 12], 
      state: 0
    }, 
    {
      pos: [4, 1, 12], 
      state: 0
    }, 
    {
      pos: [5, 1, 12], 
      state: 0
    }, 
    {
      pos: [6, 1, 12], 
      state: 0
    }, 
    {
      pos: [7, 1, 12], 
      state: 0
    }, 
    {
      pos: [2, 1, 13], 
      state: 0
    }, 
    {
      pos: [3, 1, 13], 
      state: 0
    }, 
    {
      pos: [4, 1, 13], 
      state: 0
    }, 
    {
      pos: [5, 1, 13], 
      state: 0
    }, 
    {
      pos: [6, 1, 13], 
      state: 0
    }, 
    {
      pos: [7, 1, 13], 
      state: 1
    }, 
    {
      pos: [3, 1, 14], 
      state: 0
    }, 
    {
      pos: [4, 1, 14], 
      state: 0
    }, 
    {
      pos: [5, 1, 14], 
      state: 0
    }, 
    {
      nbt: {
        LootTable: "minecraft:chests/ruined_portal", 
        id: "minecraft:chest"
      }, 
      pos: [9, 1, 9], 
      state: 2
    }, 
    {
      pos: [1, 1, 0], 
      state: 3
    }, 
    {
      pos: [2, 1, 0], 
      state: 3
    }, 
    {
      pos: [3, 1, 0], 
      state: 3
    }, 
    {
      pos: [4, 1, 0], 
      state: 3
    }, 
    {
      pos: [5, 1, 0], 
      state: 3
    }, 
    {
      pos: [6, 1, 0], 
      state: 3
    }, 
    {
      pos: [7, 1, 0], 
      state: 3
    }, 
    {
      pos: [8, 1, 0], 
      state: 3
    }, 
    {
      pos: [9, 1, 0], 
      state: 3
    }, 
    {
      pos: [10, 1, 0], 
      state: 3
    }, 
    {
      pos: [9, 1, 1], 
      state: 3
    }, 
    {
      pos: [10, 1, 1], 
      state: 3
    }, 
    {
      pos: [0, 1, 2], 
      state: 3
    }, 
    {
      pos: [8, 1, 2], 
      state: 4
    }, 
    {
      pos: [10, 1, 2], 
      state: 3
    }, 
    {
      pos: [0, 1, 3], 
      state: 3
    }, 
    {
      pos: [1, 1, 3], 
      state: 3
    }, 
    {
      pos: [10, 1, 3], 
      state: 3
    }, 
    {
      pos: [0, 1, 4], 
      state: 3
    }, 
    {
      pos: [2, 1, 4], 
      state: 4
    }, 
    {
      pos: [5, 1, 4], 
      state: 4
    }, 
    {
      pos: [6, 1, 4], 
      state: 4
    }, 
    {
      pos: [7, 1, 4], 
      state: 4
    }, 
    {
      pos: [10, 1, 4], 
      state: 3
    }, 
    {
      pos: [0, 1, 5], 
      state: 3
    }, 
    {
      pos: [5, 1, 5], 
      state: 4
    }, 
    {
      pos: [6, 1, 5], 
      state: 4
    }, 
    {
      pos: [7, 1, 5], 
      state: 4
    }, 
    {
      pos: [10, 1, 5], 
      state: 3
    }, 
    {
      pos: [0, 1, 6], 
      state: 3
    }, 
    {
      pos: [5, 1, 6], 
      state: 4
    }, 
    {
      pos: [6, 1, 6], 
      state: 4
    }, 
    {
      pos: [7, 1, 6], 
      state: 4
    }, 
    {
      pos: [10, 1, 6], 
      state: 3
    }, 
    {
      pos: [0, 1, 7], 
      state: 3
    }, 
    {
      pos: [2, 1, 7], 
      state: 4
    }, 
    {
      pos: [5, 1, 7], 
      state: 4
    }, 
    {
      pos: [6, 1, 7], 
      state: 4
    }, 
    {
      pos: [7, 1, 7], 
      state: 4
    }, 
    {
      pos: [10, 1, 7], 
      state: 3
    }, 
    {
      pos: [0, 1, 8], 
      state: 3
    }, 
    {
      pos: [6, 1, 8], 
      state: 4
    }, 
    {
      pos: [7, 1, 8], 
      state: 4
    }, 
    {
      pos: [10, 1, 8], 
      state: 3
    }, 
    {
      pos: [0, 1, 9], 
      state: 3
    }, 
    {
      pos: [10, 1, 9], 
      state: 3
    }, 
    {
      pos: [0, 1, 10], 
      state: 3
    }, 
    {
      pos: [2, 1, 10], 
      state: 4
    }, 
    {
      pos: [9, 1, 10], 
      state: 3
    }, 
    {
      pos: [10, 1, 10], 
      state: 3
    }, 
    {
      pos: [0, 1, 11], 
      state: 3
    }, 
    {
      pos: [2, 1, 11], 
      state: 4
    }, 
    {
      pos: [8, 1, 11], 
      state: 5
    }, 
    {
      pos: [9, 1, 11], 
      state: 3
    }, 
    {
      pos: [10, 1, 11], 
      state: 3
    }, 
    {
      pos: [0, 1, 12], 
      state: 3
    }, 
    {
      pos: [8, 1, 12], 
      state: 3
    }, 
    {
      pos: [0, 1, 13], 
      state: 3
    }, 
    {
      pos: [8, 1, 13], 
      state: 3
    }, 
    {
      pos: [2, 1, 14], 
      state: 3
    }, 
    {
      pos: [6, 1, 14], 
      state: 3
    }, 
    {
      pos: [2, 1, 15], 
      state: 3
    }, 
    {
      pos: [3, 1, 15], 
      state: 3
    }, 
    {
      pos: [4, 1, 15], 
      state: 3
    }, 
    {
      pos: [5, 1, 15], 
      state: 3
    }, 
    {
      pos: [6, 1, 15], 
      state: 3
    }, 
    {
      pos: [7, 1, 15], 
      state: 3
    }, 
    {
      pos: [8, 1, 15], 
      state: 3
    }, 
    {
      pos: [10, 1, 15], 
      state: 3
    }, 
    {
      pos: [7, 2, 1], 
      state: 6
    }, 
    {
      pos: [8, 2, 1], 
      state: 6
    }, 
    {
      pos: [4, 2, 2], 
      state: 6
    }, 
    {
      pos: [4, 2, 3], 
      state: 1
    }, 
    {
      pos: [5, 2, 3], 
      state: 1
    }, 
    {
      pos: [6, 2, 3], 
      state: 1
    }, 
    {
      pos: [4, 2, 4], 
      state: 1
    }, 
    {
      pos: [3, 2, 5], 
      state: 6
    }, 
    {
      pos: [4, 2, 5], 
      state: 1
    }, 
    {
      pos: [4, 2, 6], 
      state: 1
    }, 
    {
      pos: [4, 2, 7], 
      state: 1
    }, 
    {
      pos: [4, 2, 8], 
      state: 1
    }, 
    {
      pos: [4, 2, 9], 
      state: 1
    }, 
    {
      pos: [5, 2, 9], 
      state: 1
    }, 
    {
      pos: [6, 2, 9], 
      state: 1
    }, 
    {
      pos: [4, 2, 10], 
      state: 1
    }, 
    {
      pos: [5, 2, 10], 
      state: 1
    }, 
    {
      pos: [6, 2, 10], 
      state: 1
    }, 
    {
      pos: [4, 2, 11], 
      state: 1
    }, 
    {
      pos: [5, 2, 11], 
      state: 1
    }, 
    {
      pos: [6, 2, 11], 
      state: 1
    }, 
    {
      pos: [4, 2, 12], 
      state: 1
    }, 
    {
      pos: [5, 2, 12], 
      state: 1
    }, 
    {
      pos: [6, 2, 12], 
      state: 1
    }, 
    {
      pos: [5, 2, 13], 
      state: 7
    }, 
    {
      pos: [2, 2, 0], 
      state: 3
    }, 
    {
      pos: [3, 2, 1], 
      state: 3
    }, 
    {
      pos: [4, 2, 1], 
      state: 3
    }, 
    {
      pos: [5, 2, 1], 
      state: 3
    }, 
    {
      pos: [6, 2, 1], 
      state: 3
    }, 
    {
      pos: [2, 2, 2], 
      state: 3
    }, 
    {
      pos: [3, 2, 2], 
      state: 3
    }, 
    {
      pos: [5, 2, 2], 
      state: 5
    }, 
    {
      pos: [6, 2, 2], 
      state: 8
    }, 
    {
      pos: [7, 2, 2], 
      state: 9
    }, 
    {
      pos: [8, 2, 2], 
      state: 3
    }, 
    {
      pos: [2, 2, 3], 
      state: 3
    }, 
    {
      pos: [3, 2, 3], 
      state: 5
    }, 
    {
      pos: [7, 2, 3], 
      state: 10
    }, 
    {
      pos: [8, 2, 3], 
      state: 11
    }, 
    {
      pos: [1, 2, 4], 
      state: 3
    }, 
    {
      pos: [2, 2, 4], 
      state: 3
    }, 
    {
      pos: [3, 2, 4], 
      state: 5
    }, 
    {
      pos: [5, 2, 4], 
      state: 3
    }, 
    {
      pos: [6, 2, 4], 
      state: 3
    }, 
    {
      pos: [7, 2, 4], 
      state: 3
    }, 
    {
      pos: [8, 2, 4], 
      state: 12
    }, 
    {
      pos: [9, 2, 4], 
      state: 3
    }, 
    {
      pos: [10, 2, 4], 
      state: 3
    }, 
    {
      pos: [1, 2, 5], 
      state: 3
    }, 
    {
      pos: [2, 2, 5], 
      state: 5
    }, 
    {
      pos: [5, 2, 5], 
      state: 3
    }, 
    {
      pos: [6, 2, 5], 
      state: 3
    }, 
    {
      pos: [7, 2, 5], 
      state: 3
    }, 
    {
      pos: [8, 2, 5], 
      state: 12
    }, 
    {
      pos: [9, 2, 5], 
      state: 5
    }, 
    {
      pos: [10, 2, 5], 
      state: 3
    }, 
    {
      pos: [1, 2, 6], 
      state: 3
    }, 
    {
      pos: [2, 2, 6], 
      state: 5
    }, 
    {
      pos: [3, 2, 6], 
      state: 13
    }, 
    {
      pos: [5, 2, 6], 
      state: 3
    }, 
    {
      pos: [6, 2, 6], 
      state: 3
    }, 
    {
      pos: [7, 2, 6], 
      state: 3
    }, 
    {
      pos: [8, 2, 6], 
      state: 12
    }, 
    {
      pos: [9, 2, 6], 
      state: 5
    }, 
    {
      pos: [10, 2, 6], 
      state: 3
    }, 
    {
      pos: [1, 2, 7], 
      state: 3
    }, 
    {
      pos: [2, 2, 7], 
      state: 3
    }, 
    {
      pos: [3, 2, 7], 
      state: 13
    }, 
    {
      pos: [5, 2, 7], 
      state: 3
    }, 
    {
      pos: [6, 2, 7], 
      state: 3
    }, 
    {
      pos: [7, 2, 7], 
      state: 3
    }, 
    {
      pos: [8, 2, 7], 
      state: 14
    }, 
    {
      pos: [9, 2, 7], 
      state: 3
    }, 
    {
      pos: [0, 2, 8], 
      state: 3
    }, 
    {
      pos: [1, 2, 8], 
      state: 3
    }, 
    {
      pos: [2, 2, 8], 
      state: 5
    }, 
    {
      pos: [3, 2, 8], 
      state: 13
    }, 
    {
      pos: [5, 2, 8], 
      state: 3
    }, 
    {
      pos: [6, 2, 8], 
      state: 3
    }, 
    {
      pos: [7, 2, 8], 
      state: 3
    }, 
    {
      pos: [8, 2, 8], 
      state: 5
    }, 
    {
      pos: [9, 2, 8], 
      state: 3
    }, 
    {
      pos: [0, 2, 9], 
      state: 3
    }, 
    {
      pos: [1, 2, 9], 
      state: 3
    }, 
    {
      pos: [2, 2, 9], 
      state: 5
    }, 
    {
      pos: [3, 2, 9], 
      state: 13
    }, 
    {
      pos: [7, 2, 9], 
      state: 5
    }, 
    {
      pos: [8, 2, 9], 
      state: 3
    }, 
    {
      pos: [9, 2, 9], 
      state: 3
    }, 
    {
      pos: [10, 2, 9], 
      state: 3
    }, 
    {
      pos: [0, 2, 10], 
      state: 3
    }, 
    {
      pos: [1, 2, 10], 
      state: 3
    }, 
    {
      pos: [2, 2, 10], 
      state: 3
    }, 
    {
      pos: [3, 2, 10], 
      state: 13
    }, 
    {
      pos: [7, 2, 10], 
      state: 12
    }, 
    {
      pos: [8, 2, 10], 
      state: 3
    }, 
    {
      pos: [9, 2, 10], 
      state: 3
    }, 
    {
      pos: [10, 2, 10], 
      state: 3
    }, 
    {
      pos: [1, 2, 11], 
      state: 3
    }, 
    {
      pos: [2, 2, 11], 
      state: 3
    }, 
    {
      pos: [3, 2, 11], 
      state: 13
    }, 
    {
      pos: [7, 2, 11], 
      state: 12
    }, 
    {
      pos: [8, 2, 11], 
      state: 3
    }, 
    {
      pos: [9, 2, 11], 
      state: 3
    }, 
    {
      pos: [10, 2, 11], 
      state: 3
    }, 
    {
      pos: [1, 2, 12], 
      state: 3
    }, 
    {
      pos: [2, 2, 12], 
      state: 5
    }, 
    {
      pos: [3, 2, 12], 
      state: 5
    }, 
    {
      pos: [7, 2, 12], 
      state: 12
    }, 
    {
      pos: [8, 2, 12], 
      state: 3
    }, 
    {
      pos: [9, 2, 12], 
      state: 3
    }, 
    {
      pos: [1, 2, 13], 
      state: 3
    }, 
    {
      pos: [2, 2, 13], 
      state: 3
    }, 
    {
      pos: [3, 2, 13], 
      state: 5
    }, 
    {
      pos: [4, 2, 13], 
      state: 5
    }, 
    {
      pos: [6, 2, 13], 
      state: 5
    }, 
    {
      pos: [7, 2, 13], 
      state: 3
    }, 
    {
      pos: [8, 2, 13], 
      state: 3
    }, 
    {
      pos: [1, 2, 14], 
      state: 3
    }, 
    {
      pos: [3, 2, 14], 
      state: 3
    }, 
    {
      pos: [4, 2, 14], 
      state: 3
    }, 
    {
      pos: [5, 2, 14], 
      state: 3
    }, 
    {
      pos: [6, 2, 14], 
      state: 3
    }, 
    {
      pos: [7, 2, 14], 
      state: 3
    }, 
    {
      pos: [6, 2, 15], 
      state: 3
    }, 
    {
      pos: [5, 3, 2], 
      state: 1
    }, 
    {
      pos: [5, 3, 3], 
      state: 1
    }, 
    {
      pos: [5, 3, 4], 
      state: 6
    }, 
    {
      pos: [3, 3, 5], 
      state: 6
    }, 
    {
      pos: [5, 3, 5], 
      state: 6
    }, 
    {
      pos: [5, 3, 6], 
      state: 6
    }, 
    {
      pos: [5, 3, 7], 
      state: 6
    }, 
    {
      pos: [5, 3, 8], 
      state: 6
    }, 
    {
      pos: [5, 3, 9], 
      state: 6
    }, 
    {
      pos: [5, 3, 10], 
      state: 6
    }, 
    {
      pos: [5, 3, 11], 
      state: 6
    }, 
    {
      pos: [5, 3, 12], 
      state: 15
    }, 
    {
      pos: [5, 3, 13], 
      state: 1
    }, 
    {
      pos: [6, 3, 0], 
      state: 3
    }, 
    {
      pos: [2, 3, 1], 
      state: 3
    }, 
    {
      pos: [3, 3, 1], 
      state: 3
    }, 
    {
      pos: [4, 3, 1], 
      state: 3
    }, 
    {
      pos: [5, 3, 1], 
      state: 3
    }, 
    {
      pos: [6, 3, 1], 
      state: 3
    }, 
    {
      pos: [7, 3, 1], 
      state: 3
    }, 
    {
      pos: [8, 3, 1], 
      state: 3
    }, 
    {
      pos: [2, 3, 2], 
      state: 3
    }, 
    {
      pos: [3, 3, 2], 
      state: 3
    }, 
    {
      pos: [4, 3, 2], 
      state: 3
    }, 
    {
      pos: [6, 3, 2], 
      state: 3
    }, 
    {
      pos: [7, 3, 2], 
      state: 3
    }, 
    {
      pos: [8, 3, 2], 
      state: 3
    }, 
    {
      pos: [1, 3, 3], 
      state: 3
    }, 
    {
      pos: [2, 3, 3], 
      state: 3
    }, 
    {
      pos: [3, 3, 3], 
      state: 3
    }, 
    {
      pos: [4, 3, 3], 
      state: 3
    }, 
    {
      pos: [6, 3, 3], 
      state: 3
    }, 
    {
      pos: [7, 3, 3], 
      state: 3
    }, 
    {
      pos: [8, 3, 3], 
      state: 3
    }, 
    {
      pos: [9, 3, 3], 
      state: 3
    }, 
    {
      pos: [0, 3, 4], 
      state: 3
    }, 
    {
      pos: [1, 3, 4], 
      state: 3
    }, 
    {
      pos: [2, 3, 4], 
      state: 3
    }, 
    {
      pos: [3, 3, 4], 
      state: 3
    }, 
    {
      pos: [4, 3, 4], 
      state: 5
    }, 
    {
      pos: [6, 3, 4], 
      state: 3
    }, 
    {
      pos: [7, 3, 4], 
      state: 3
    }, 
    {
      pos: [8, 3, 4], 
      state: 3
    }, 
    {
      pos: [9, 3, 4], 
      state: 3
    }, 
    {
      pos: [10, 3, 4], 
      state: 3
    }, 
    {
      pos: [1, 3, 5], 
      state: 3
    }, 
    {
      pos: [2, 3, 5], 
      state: 3
    }, 
    {
      pos: [4, 3, 5], 
      state: 5
    }, 
    {
      pos: [6, 3, 5], 
      state: 3
    }, 
    {
      pos: [7, 3, 5], 
      state: 3
    }, 
    {
      pos: [8, 3, 5], 
      state: 3
    }, 
    {
      pos: [9, 3, 5], 
      state: 3
    }, 
    {
      pos: [10, 3, 5], 
      state: 3
    }, 
    {
      pos: [1, 3, 6], 
      state: 3
    }, 
    {
      pos: [2, 3, 6], 
      state: 3
    }, 
    {
      pos: [3, 3, 6], 
      state: 3
    }, 
    {
      pos: [4, 3, 6], 
      state: 5
    }, 
    {
      pos: [6, 3, 6], 
      state: 3
    }, 
    {
      pos: [7, 3, 6], 
      state: 3
    }, 
    {
      pos: [8, 3, 6], 
      state: 3
    }, 
    {
      pos: [9, 3, 6], 
      state: 3
    }, 
    {
      pos: [0, 3, 7], 
      state: 3
    }, 
    {
      pos: [1, 3, 7], 
      state: 3
    }, 
    {
      pos: [2, 3, 7], 
      state: 3
    }, 
    {
      pos: [3, 3, 7], 
      state: 3
    }, 
    {
      pos: [4, 3, 7], 
      state: 5
    }, 
    {
      pos: [6, 3, 7], 
      state: 3
    }, 
    {
      pos: [7, 3, 7], 
      state: 3
    }, 
    {
      pos: [8, 3, 7], 
      state: 3
    }, 
    {
      pos: [9, 3, 7], 
      state: 3
    }, 
    {
      pos: [0, 3, 8], 
      state: 3
    }, 
    {
      pos: [1, 3, 8], 
      state: 3
    }, 
    {
      pos: [2, 3, 8], 
      state: 3
    }, 
    {
      pos: [3, 3, 8], 
      state: 3
    }, 
    {
      pos: [4, 3, 8], 
      state: 5
    }, 
    {
      pos: [6, 3, 8], 
      state: 3
    }, 
    {
      pos: [7, 3, 8], 
      state: 3
    }, 
    {
      pos: [8, 3, 8], 
      state: 3
    }, 
    {
      pos: [9, 3, 8], 
      state: 3
    }, 
    {
      pos: [0, 3, 9], 
      state: 3
    }, 
    {
      pos: [1, 3, 9], 
      state: 3
    }, 
    {
      pos: [2, 3, 9], 
      state: 3
    }, 
    {
      pos: [3, 3, 9], 
      state: 3
    }, 
    {
      pos: [4, 3, 9], 
      state: 5
    }, 
    {
      pos: [6, 3, 9], 
      state: 3
    }, 
    {
      pos: [7, 3, 9], 
      state: 3
    }, 
    {
      pos: [8, 3, 9], 
      state: 3
    }, 
    {
      pos: [9, 3, 9], 
      state: 3
    }, 
    {
      pos: [10, 3, 9], 
      state: 3
    }, 
    {
      pos: [0, 3, 10], 
      state: 3
    }, 
    {
      pos: [1, 3, 10], 
      state: 3
    }, 
    {
      pos: [2, 3, 10], 
      state: 3
    }, 
    {
      pos: [3, 3, 10], 
      state: 3
    }, 
    {
      pos: [4, 3, 10], 
      state: 5
    }, 
    {
      pos: [6, 3, 10], 
      state: 5
    }, 
    {
      pos: [7, 3, 10], 
      state: 3
    }, 
    {
      pos: [8, 3, 10], 
      state: 3
    }, 
    {
      pos: [9, 3, 10], 
      state: 3
    }, 
    {
      pos: [10, 3, 10], 
      state: 3
    }, 
    {
      pos: [0, 3, 11], 
      state: 3
    }, 
    {
      pos: [1, 3, 11], 
      state: 3
    }, 
    {
      pos: [2, 3, 11], 
      state: 3
    }, 
    {
      pos: [3, 3, 11], 
      state: 3
    }, 
    {
      pos: [4, 3, 11], 
      state: 5
    }, 
    {
      pos: [6, 3, 11], 
      state: 5
    }, 
    {
      pos: [7, 3, 11], 
      state: 3
    }, 
    {
      pos: [8, 3, 11], 
      state: 3
    }, 
    {
      pos: [9, 3, 11], 
      state: 3
    }, 
    {
      pos: [10, 3, 11], 
      state: 3
    }, 
    {
      pos: [1, 3, 12], 
      state: 3
    }, 
    {
      pos: [2, 3, 12], 
      state: 3
    }, 
    {
      pos: [3, 3, 12], 
      state: 3
    }, 
    {
      pos: [4, 3, 12], 
      state: 3
    }, 
    {
      pos: [6, 3, 12], 
      state: 3
    }, 
    {
      pos: [7, 3, 12], 
      state: 3
    }, 
    {
      pos: [8, 3, 12], 
      state: 3
    }, 
    {
      pos: [9, 3, 12], 
      state: 3
    }, 
    {
      pos: [10, 3, 12], 
      state: 3
    }, 
    {
      pos: [2, 3, 13], 
      state: 3
    }, 
    {
      pos: [3, 3, 13], 
      state: 3
    }, 
    {
      pos: [4, 3, 13], 
      state: 3
    }, 
    {
      pos: [6, 3, 13], 
      state: 3
    }, 
    {
      pos: [7, 3, 13], 
      state: 3
    }, 
    {
      pos: [8, 3, 13], 
      state: 3
    }, 
    {
      pos: [9, 3, 13], 
      state: 3
    }, 
    {
      pos: [2, 3, 14], 
      state: 3
    }, 
    {
      pos: [3, 3, 14], 
      state: 3
    }, 
    {
      pos: [4, 3, 14], 
      state: 3
    }, 
    {
      pos: [5, 3, 14], 
      state: 3
    }, 
    {
      pos: [6, 3, 14], 
      state: 3
    }, 
    {
      pos: [7, 3, 14], 
      state: 3
    }, 
    {
      pos: [3, 3, 15], 
      state: 3
    }, 
    {
      pos: [8, 3, 15], 
      state: 3
    }, 
    {
      pos: [10, 3, 15], 
      state: 3
    }, 
    {
      pos: [5, 4, 4], 
      state: 6
    }, 
    {
      pos: [3, 4, 5], 
      state: 6
    }, 
    {
      pos: [5, 4, 11], 
      state: 6
    }, 
    {
      pos: [5, 4, 13], 
      state: 1
    }, 
    {
      pos: [5, 4, 0], 
      state: 3
    }, 
    {
      pos: [6, 4, 0], 
      state: 3
    }, 
    {
      pos: [7, 4, 0], 
      state: 3
    }, 
    {
      pos: [2, 4, 1], 
      state: 3
    }, 
    {
      pos: [3, 4, 1], 
      state: 3
    }, 
    {
      pos: [4, 4, 1], 
      state: 3
    }, 
    {
      pos: [5, 4, 1], 
      state: 3
    }, 
    {
      pos: [6, 4, 1], 
      state: 3
    }, 
    {
      pos: [7, 4, 1], 
      state: 3
    }, 
    {
      pos: [8, 4, 1], 
      state: 3
    }, 
    {
      pos: [1, 4, 2], 
      state: 3
    }, 
    {
      pos: [2, 4, 2], 
      state: 3
    }, 
    {
      pos: [3, 4, 2], 
      state: 3
    }, 
    {
      pos: [4, 4, 2], 
      state: 3
    }, 
    {
      pos: [5, 4, 2], 
      state: 3
    }, 
    {
      pos: [6, 4, 2], 
      state: 3
    }, 
    {
      pos: [7, 4, 2], 
      state: 3
    }, 
    {
      pos: [8, 4, 2], 
      state: 3
    }, 
    {
      pos: [0, 4, 3], 
      state: 3
    }, 
    {
      pos: [1, 4, 3], 
      state: 3
    }, 
    {
      pos: [2, 4, 3], 
      state: 3
    }, 
    {
      pos: [3, 4, 3], 
      state: 3
    }, 
    {
      pos: [4, 4, 3], 
      state: 3
    }, 
    {
      pos: [5, 4, 3], 
      state: 16
    }, 
    {
      pos: [6, 4, 3], 
      state: 3
    }, 
    {
      pos: [7, 4, 3], 
      state: 3
    }, 
    {
      pos: [8, 4, 3], 
      state: 3
    }, 
    {
      pos: [9, 4, 3], 
      state: 3
    }, 
    {
      pos: [10, 4, 3], 
      state: 3
    }, 
    {
      pos: [0, 4, 4], 
      state: 3
    }, 
    {
      pos: [1, 4, 4], 
      state: 3
    }, 
    {
      pos: [2, 4, 4], 
      state: 3
    }, 
    {
      pos: [3, 4, 4], 
      state: 3
    }, 
    {
      pos: [4, 4, 4], 
      state: 3
    }, 
    {
      pos: [6, 4, 4], 
      state: 3
    }, 
    {
      pos: [7, 4, 4], 
      state: 3
    }, 
    {
      pos: [8, 4, 4], 
      state: 3
    }, 
    {
      pos: [9, 4, 4], 
      state: 3
    }, 
    {
      pos: [10, 4, 4], 
      state: 3
    }, 
    {
      pos: [0, 4, 5], 
      state: 3
    }, 
    {
      pos: [1, 4, 5], 
      state: 3
    }, 
    {
      pos: [2, 4, 5], 
      state: 3
    }, 
    {
      pos: [4, 4, 5], 
      state: 3
    }, 
    {
      pos: [5, 4, 5], 
      state: 3
    }, 
    {
      pos: [6, 4, 5], 
      state: 3
    }, 
    {
      pos: [7, 4, 5], 
      state: 3
    }, 
    {
      pos: [8, 4, 5], 
      state: 3
    }, 
    {
      pos: [9, 4, 5], 
      state: 3
    }, 
    {
      pos: [10, 4, 5], 
      state: 3
    }, 
    {
      pos: [1, 4, 6], 
      state: 3
    }, 
    {
      pos: [2, 4, 6], 
      state: 3
    }, 
    {
      pos: [3, 4, 6], 
      state: 3
    }, 
    {
      pos: [4, 4, 6], 
      state: 3
    }, 
    {
      pos: [5, 4, 6], 
      state: 3
    }, 
    {
      pos: [6, 4, 6], 
      state: 3
    }, 
    {
      pos: [7, 4, 6], 
      state: 3
    }, 
    {
      pos: [8, 4, 6], 
      state: 3
    }, 
    {
      pos: [9, 4, 6], 
      state: 3
    }, 
    {
      pos: [10, 4, 6], 
      state: 3
    }, 
    {
      pos: [1, 4, 7], 
      state: 3
    }, 
    {
      pos: [2, 4, 7], 
      state: 3
    }, 
    {
      pos: [3, 4, 7], 
      state: 3
    }, 
    {
      pos: [4, 4, 7], 
      state: 3
    }, 
    {
      pos: [5, 4, 7], 
      state: 3
    }, 
    {
      pos: [6, 4, 7], 
      state: 3
    }, 
    {
      pos: [7, 4, 7], 
      state: 3
    }, 
    {
      pos: [8, 4, 7], 
      state: 3
    }, 
    {
      pos: [9, 4, 7], 
      state: 3
    }, 
    {
      pos: [1, 4, 8], 
      state: 3
    }, 
    {
      pos: [2, 4, 8], 
      state: 3
    }, 
    {
      pos: [3, 4, 8], 
      state: 3
    }, 
    {
      pos: [4, 4, 8], 
      state: 3
    }, 
    {
      pos: [5, 4, 8], 
      state: 3
    }, 
    {
      pos: [6, 4, 8], 
      state: 3
    }, 
    {
      pos: [7, 4, 8], 
      state: 3
    }, 
    {
      pos: [8, 4, 8], 
      state: 3
    }, 
    {
      pos: [9, 4, 8], 
      state: 3
    }, 
    {
      pos: [0, 4, 9], 
      state: 3
    }, 
    {
      pos: [1, 4, 9], 
      state: 3
    }, 
    {
      pos: [2, 4, 9], 
      state: 3
    }, 
    {
      pos: [3, 4, 9], 
      state: 3
    }, 
    {
      pos: [4, 4, 9], 
      state: 3
    }, 
    {
      pos: [5, 4, 9], 
      state: 3
    }, 
    {
      pos: [6, 4, 9], 
      state: 3
    }, 
    {
      pos: [7, 4, 9], 
      state: 3
    }, 
    {
      pos: [8, 4, 9], 
      state: 3
    }, 
    {
      pos: [9, 4, 9], 
      state: 3
    }, 
    {
      pos: [10, 4, 9], 
      state: 3
    }, 
    {
      pos: [0, 4, 10], 
      state: 3
    }, 
    {
      pos: [1, 4, 10], 
      state: 3
    }, 
    {
      pos: [2, 4, 10], 
      state: 3
    }, 
    {
      pos: [3, 4, 10], 
      state: 3
    }, 
    {
      pos: [4, 4, 10], 
      state: 3
    }, 
    {
      pos: [5, 4, 10], 
      state: 3
    }, 
    {
      pos: [6, 4, 10], 
      state: 3
    }, 
    {
      pos: [7, 4, 10], 
      state: 3
    }, 
    {
      pos: [8, 4, 10], 
      state: 3
    }, 
    {
      pos: [9, 4, 10], 
      state: 3
    }, 
    {
      pos: [10, 4, 10], 
      state: 3
    }, 
    {
      pos: [0, 4, 11], 
      state: 3
    }, 
    {
      pos: [1, 4, 11], 
      state: 3
    }, 
    {
      pos: [2, 4, 11], 
      state: 3
    }, 
    {
      pos: [3, 4, 11], 
      state: 3
    }, 
    {
      pos: [4, 4, 11], 
      state: 3
    }, 
    {
      pos: [6, 4, 11], 
      state: 3
    }, 
    {
      pos: [7, 4, 11], 
      state: 3
    }, 
    {
      pos: [8, 4, 11], 
      state: 3
    }, 
    {
      pos: [9, 4, 11], 
      state: 3
    }, 
    {
      pos: [10, 4, 11], 
      state: 3
    }, 
    {
      pos: [0, 4, 12], 
      state: 3
    }, 
    {
      pos: [1, 4, 12], 
      state: 3
    }, 
    {
      pos: [2, 4, 12], 
      state: 3
    }, 
    {
      pos: [3, 4, 12], 
      state: 3
    }, 
    {
      pos: [4, 4, 12], 
      state: 3
    }, 
    {
      pos: [5, 4, 12], 
      state: 17
    }, 
    {
      pos: [6, 4, 12], 
      state: 3
    }, 
    {
      pos: [7, 4, 12], 
      state: 3
    }, 
    {
      pos: [8, 4, 12], 
      state: 3
    }, 
    {
      pos: [9, 4, 12], 
      state: 3
    }, 
    {
      pos: [10, 4, 12], 
      state: 3
    }, 
    {
      pos: [0, 4, 13], 
      state: 3
    }, 
    {
      pos: [1, 4, 13], 
      state: 3
    }, 
    {
      pos: [2, 4, 13], 
      state: 3
    }, 
    {
      pos: [3, 4, 13], 
      state: 3
    }, 
    {
      pos: [4, 4, 13], 
      state: 3
    }, 
    {
      pos: [6, 4, 13], 
      state: 3
    }, 
    {
      pos: [7, 4, 13], 
      state: 3
    }, 
    {
      pos: [8, 4, 13], 
      state: 3
    }, 
    {
      pos: [9, 4, 13], 
      state: 3
    }, 
    {
      pos: [10, 4, 13], 
      state: 3
    }, 
    {
      pos: [1, 4, 14], 
      state: 3
    }, 
    {
      pos: [2, 4, 14], 
      state: 3
    }, 
    {
      pos: [3, 4, 14], 
      state: 3
    }, 
    {
      pos: [4, 4, 14], 
      state: 3
    }, 
    {
      pos: [5, 4, 14], 
      state: 3
    }, 
    {
      pos: [6, 4, 14], 
      state: 3
    }, 
    {
      pos: [7, 4, 14], 
      state: 3
    }, 
    {
      pos: [8, 4, 14], 
      state: 3
    }, 
    {
      pos: [9, 4, 14], 
      state: 3
    }, 
    {
      pos: [2, 4, 15], 
      state: 3
    }, 
    {
      pos: [3, 4, 15], 
      state: 3
    }, 
    {
      pos: [4, 4, 15], 
      state: 3
    }, 
    {
      pos: [8, 4, 15], 
      state: 3
    }, 
    {
      pos: [5, 5, 11], 
      state: 6
    }, 
    {
      pos: [5, 5, 13], 
      state: 1
    }, 
    {
      pos: [3, 5, 0], 
      state: 3
    }, 
    {
      pos: [4, 5, 0], 
      state: 3
    }, 
    {
      pos: [5, 5, 0], 
      state: 3
    }, 
    {
      pos: [6, 5, 0], 
      state: 3
    }, 
    {
      pos: [7, 5, 0], 
      state: 3
    }, 
    {
      pos: [8, 5, 0], 
      state: 3
    }, 
    {
      pos: [1, 5, 1], 
      state: 3
    }, 
    {
      pos: [2, 5, 1], 
      state: 3
    }, 
    {
      pos: [3, 5, 1], 
      state: 3
    }, 
    {
      pos: [4, 5, 1], 
      state: 3
    }, 
    {
      pos: [5, 5, 1], 
      state: 3
    }, 
    {
      pos: [6, 5, 1], 
      state: 3
    }, 
    {
      pos: [7, 5, 1], 
      state: 3
    }, 
    {
      pos: [8, 5, 1], 
      state: 3
    }, 
    {
      pos: [9, 5, 1], 
      state: 3
    }, 
    {
      pos: [0, 5, 2], 
      state: 3
    }, 
    {
      pos: [1, 5, 2], 
      state: 3
    }, 
    {
      pos: [2, 5, 2], 
      state: 3
    }, 
    {
      pos: [3, 5, 2], 
      state: 3
    }, 
    {
      pos: [4, 5, 2], 
      state: 3
    }, 
    {
      pos: [5, 5, 2], 
      state: 3
    }, 
    {
      pos: [6, 5, 2], 
      state: 3
    }, 
    {
      pos: [7, 5, 2], 
      state: 3
    }, 
    {
      pos: [8, 5, 2], 
      state: 3
    }, 
    {
      pos: [9, 5, 2], 
      state: 3
    }, 
    {
      pos: [10, 5, 2], 
      state: 3
    }, 
    {
      pos: [0, 5, 3], 
      state: 3
    }, 
    {
      pos: [1, 5, 3], 
      state: 3
    }, 
    {
      pos: [2, 5, 3], 
      state: 3
    }, 
    {
      pos: [3, 5, 3], 
      state: 3
    }, 
    {
      pos: [4, 5, 3], 
      state: 3
    }, 
    {
      pos: [5, 5, 3], 
      state: 18
    }, 
    {
      pos: [6, 5, 3], 
      state: 3
    }, 
    {
      pos: [7, 5, 3], 
      state: 3
    }, 
    {
      pos: [8, 5, 3], 
      state: 3
    }, 
    {
      pos: [9, 5, 3], 
      state: 3
    }, 
    {
      pos: [10, 5, 3], 
      state: 3
    }, 
    {
      pos: [0, 5, 4], 
      state: 3
    }, 
    {
      pos: [1, 5, 4], 
      state: 3
    }, 
    {
      pos: [2, 5, 4], 
      state: 3
    }, 
    {
      pos: [3, 5, 4], 
      state: 3
    }, 
    {
      pos: [4, 5, 4], 
      state: 3
    }, 
    {
      pos: [5, 5, 4], 
      state: 3
    }, 
    {
      pos: [6, 5, 4], 
      state: 3
    }, 
    {
      pos: [7, 5, 4], 
      state: 3
    }, 
    {
      pos: [8, 5, 4], 
      state: 3
    }, 
    {
      pos: [9, 5, 4], 
      state: 3
    }, 
    {
      pos: [10, 5, 4], 
      state: 3
    }, 
    {
      pos: [1, 5, 5], 
      state: 3
    }, 
    {
      pos: [2, 5, 5], 
      state: 3
    }, 
    {
      pos: [3, 5, 5], 
      state: 3
    }, 
    {
      pos: [4, 5, 5], 
      state: 3
    }, 
    {
      pos: [5, 5, 5], 
      state: 3
    }, 
    {
      pos: [6, 5, 5], 
      state: 3
    }, 
    {
      pos: [7, 5, 5], 
      state: 3
    }, 
    {
      pos: [8, 5, 5], 
      state: 3
    }, 
    {
      pos: [9, 5, 5], 
      state: 3
    }, 
    {
      pos: [10, 5, 5], 
      state: 3
    }, 
    {
      pos: [1, 5, 6], 
      state: 3
    }, 
    {
      pos: [2, 5, 6], 
      state: 3
    }, 
    {
      pos: [3, 5, 6], 
      state: 3
    }, 
    {
      pos: [4, 5, 6], 
      state: 3
    }, 
    {
      pos: [5, 5, 6], 
      state: 3
    }, 
    {
      pos: [6, 5, 6], 
      state: 3
    }, 
    {
      pos: [7, 5, 6], 
      state: 3
    }, 
    {
      pos: [8, 5, 6], 
      state: 3
    }, 
    {
      pos: [9, 5, 6], 
      state: 3
    }, 
    {
      pos: [10, 5, 6], 
      state: 3
    }, 
    {
      pos: [1, 5, 7], 
      state: 3
    }, 
    {
      pos: [2, 5, 7], 
      state: 3
    }, 
    {
      pos: [3, 5, 7], 
      state: 3
    }, 
    {
      pos: [4, 5, 7], 
      state: 3
    }, 
    {
      pos: [5, 5, 7], 
      state: 3
    }, 
    {
      pos: [6, 5, 7], 
      state: 3
    }, 
    {
      pos: [7, 5, 7], 
      state: 3
    }, 
    {
      pos: [8, 5, 7], 
      state: 3
    }, 
    {
      pos: [9, 5, 7], 
      state: 3
    }, 
    {
      pos: [10, 5, 7], 
      state: 3
    }, 
    {
      pos: [1, 5, 8], 
      state: 3
    }, 
    {
      pos: [2, 5, 8], 
      state: 3
    }, 
    {
      pos: [3, 5, 8], 
      state: 3
    }, 
    {
      pos: [4, 5, 8], 
      state: 3
    }, 
    {
      pos: [5, 5, 8], 
      state: 3
    }, 
    {
      pos: [6, 5, 8], 
      state: 3
    }, 
    {
      pos: [7, 5, 8], 
      state: 3
    }, 
    {
      pos: [8, 5, 8], 
      state: 3
    }, 
    {
      pos: [9, 5, 8], 
      state: 3
    }, 
    {
      pos: [10, 5, 8], 
      state: 3
    }, 
    {
      pos: [1, 5, 9], 
      state: 3
    }, 
    {
      pos: [2, 5, 9], 
      state: 3
    }, 
    {
      pos: [3, 5, 9], 
      state: 3
    }, 
    {
      pos: [4, 5, 9], 
      state: 3
    }, 
    {
      pos: [5, 5, 9], 
      state: 3
    }, 
    {
      pos: [6, 5, 9], 
      state: 3
    }, 
    {
      pos: [7, 5, 9], 
      state: 3
    }, 
    {
      pos: [8, 5, 9], 
      state: 3
    }, 
    {
      pos: [9, 5, 9], 
      state: 3
    }, 
    {
      pos: [10, 5, 9], 
      state: 3
    }, 
    {
      pos: [1, 5, 10], 
      state: 3
    }, 
    {
      pos: [2, 5, 10], 
      state: 3
    }, 
    {
      pos: [3, 5, 10], 
      state: 3
    }, 
    {
      pos: [4, 5, 10], 
      state: 3
    }, 
    {
      pos: [5, 5, 10], 
      state: 3
    }, 
    {
      pos: [6, 5, 10], 
      state: 3
    }, 
    {
      pos: [7, 5, 10], 
      state: 3
    }, 
    {
      pos: [8, 5, 10], 
      state: 3
    }, 
    {
      pos: [9, 5, 10], 
      state: 3
    }, 
    {
      pos: [10, 5, 10], 
      state: 3
    }, 
    {
      pos: [0, 5, 11], 
      state: 3
    }, 
    {
      pos: [1, 5, 11], 
      state: 3
    }, 
    {
      pos: [2, 5, 11], 
      state: 3
    }, 
    {
      pos: [3, 5, 11], 
      state: 3
    }, 
    {
      pos: [4, 5, 11], 
      state: 3
    }, 
    {
      pos: [6, 5, 11], 
      state: 3
    }, 
    {
      pos: [7, 5, 11], 
      state: 3
    }, 
    {
      pos: [8, 5, 11], 
      state: 3
    }, 
    {
      pos: [9, 5, 11], 
      state: 3
    }, 
    {
      pos: [10, 5, 11], 
      state: 3
    }, 
    {
      pos: [0, 5, 12], 
      state: 3
    }, 
    {
      pos: [1, 5, 12], 
      state: 3
    }, 
    {
      pos: [2, 5, 12], 
      state: 3
    }, 
    {
      pos: [3, 5, 12], 
      state: 3
    }, 
    {
      pos: [4, 5, 12], 
      state: 3
    }, 
    {
      pos: [5, 5, 12], 
      state: 17
    }, 
    {
      pos: [6, 5, 12], 
      state: 3
    }, 
    {
      pos: [7, 5, 12], 
      state: 3
    }, 
    {
      pos: [8, 5, 12], 
      state: 3
    }, 
    {
      pos: [9, 5, 12], 
      state: 3
    }, 
    {
      pos: [10, 5, 12], 
      state: 3
    }, 
    {
      pos: [0, 5, 13], 
      state: 3
    }, 
    {
      pos: [1, 5, 13], 
      state: 3
    }, 
    {
      pos: [2, 5, 13], 
      state: 3
    }, 
    {
      pos: [3, 5, 13], 
      state: 3
    }, 
    {
      pos: [4, 5, 13], 
      state: 3
    }, 
    {
      pos: [6, 5, 13], 
      state: 3
    }, 
    {
      pos: [7, 5, 13], 
      state: 3
    }, 
    {
      pos: [8, 5, 13], 
      state: 3
    }, 
    {
      pos: [9, 5, 13], 
      state: 3
    }, 
    {
      pos: [10, 5, 13], 
      state: 3
    }, 
    {
      pos: [1, 5, 14], 
      state: 3
    }, 
    {
      pos: [2, 5, 14], 
      state: 3
    }, 
    {
      pos: [3, 5, 14], 
      state: 3
    }, 
    {
      pos: [4, 5, 14], 
      state: 3
    }, 
    {
      pos: [5, 5, 14], 
      state: 3
    }, 
    {
      pos: [6, 5, 14], 
      state: 3
    }, 
    {
      pos: [7, 5, 14], 
      state: 3
    }, 
    {
      pos: [8, 5, 14], 
      state: 3
    }, 
    {
      pos: [9, 5, 14], 
      state: 3
    }, 
    {
      pos: [1, 5, 15], 
      state: 3
    }, 
    {
      pos: [2, 5, 15], 
      state: 3
    }, 
    {
      pos: [3, 5, 15], 
      state: 3
    }, 
    {
      pos: [4, 5, 15], 
      state: 3
    }, 
    {
      pos: [7, 5, 15], 
      state: 3
    }, 
    {
      pos: [8, 5, 15], 
      state: 3
    }, 
    {
      pos: [9, 5, 15], 
      state: 3
    }, 
    {
      pos: [5, 6, 11], 
      state: 6
    }, 
    {
      pos: [5, 6, 12], 
      state: 15
    }, 
    {
      pos: [5, 6, 13], 
      state: 1
    }, 
    {
      pos: [2, 6, 0], 
      state: 3
    }, 
    {
      pos: [3, 6, 0], 
      state: 3
    }, 
    {
      pos: [4, 6, 0], 
      state: 3
    }, 
    {
      pos: [5, 6, 0], 
      state: 3
    }, 
    {
      pos: [6, 6, 0], 
      state: 3
    }, 
    {
      pos: [7, 6, 0], 
      state: 3
    }, 
    {
      pos: [8, 6, 0], 
      state: 3
    }, 
    {
      pos: [9, 6, 0], 
      state: 3
    }, 
    {
      pos: [0, 6, 1], 
      state: 3
    }, 
    {
      pos: [1, 6, 1], 
      state: 3
    }, 
    {
      pos: [2, 6, 1], 
      state: 3
    }, 
    {
      pos: [3, 6, 1], 
      state: 3
    }, 
    {
      pos: [4, 6, 1], 
      state: 3
    }, 
    {
      pos: [5, 6, 1], 
      state: 3
    }, 
    {
      pos: [6, 6, 1], 
      state: 3
    }, 
    {
      pos: [7, 6, 1], 
      state: 3
    }, 
    {
      pos: [8, 6, 1], 
      state: 3
    }, 
    {
      pos: [9, 6, 1], 
      state: 3
    }, 
    {
      pos: [10, 6, 1], 
      state: 3
    }, 
    {
      pos: [0, 6, 2], 
      state: 3
    }, 
    {
      pos: [1, 6, 2], 
      state: 3
    }, 
    {
      pos: [2, 6, 2], 
      state: 3
    }, 
    {
      pos: [3, 6, 2], 
      state: 3
    }, 
    {
      pos: [4, 6, 2], 
      state: 3
    }, 
    {
      pos: [5, 6, 2], 
      state: 3
    }, 
    {
      pos: [6, 6, 2], 
      state: 3
    }, 
    {
      pos: [7, 6, 2], 
      state: 3
    }, 
    {
      pos: [8, 6, 2], 
      state: 3
    }, 
    {
      pos: [9, 6, 2], 
      state: 3
    }, 
    {
      pos: [10, 6, 2], 
      state: 3
    }, 
    {
      pos: [0, 6, 3], 
      state: 3
    }, 
    {
      pos: [1, 6, 3], 
      state: 3
    }, 
    {
      pos: [2, 6, 3], 
      state: 3
    }, 
    {
      pos: [3, 6, 3], 
      state: 3
    }, 
    {
      pos: [4, 6, 3], 
      state: 3
    }, 
    {
      pos: [5, 6, 3], 
      state: 3
    }, 
    {
      pos: [6, 6, 3], 
      state: 3
    }, 
    {
      pos: [7, 6, 3], 
      state: 3
    }, 
    {
      pos: [8, 6, 3], 
      state: 3
    }, 
    {
      pos: [9, 6, 3], 
      state: 3
    }, 
    {
      pos: [10, 6, 3], 
      state: 3
    }, 
    {
      pos: [1, 6, 4], 
      state: 3
    }, 
    {
      pos: [2, 6, 4], 
      state: 3
    }, 
    {
      pos: [3, 6, 4], 
      state: 3
    }, 
    {
      pos: [4, 6, 4], 
      state: 3
    }, 
    {
      pos: [5, 6, 4], 
      state: 3
    }, 
    {
      pos: [6, 6, 4], 
      state: 3
    }, 
    {
      pos: [7, 6, 4], 
      state: 3
    }, 
    {
      pos: [8, 6, 4], 
      state: 3
    }, 
    {
      pos: [9, 6, 4], 
      state: 3
    }, 
    {
      pos: [10, 6, 4], 
      state: 3
    }, 
    {
      pos: [2, 6, 5], 
      state: 3
    }, 
    {
      pos: [3, 6, 5], 
      state: 3
    }, 
    {
      pos: [4, 6, 5], 
      state: 3
    }, 
    {
      pos: [5, 6, 5], 
      state: 3
    }, 
    {
      pos: [6, 6, 5], 
      state: 3
    }, 
    {
      pos: [7, 6, 5], 
      state: 3
    }, 
    {
      pos: [8, 6, 5], 
      state: 3
    }, 
    {
      pos: [9, 6, 5], 
      state: 3
    }, 
    {
      pos: [10, 6, 5], 
      state: 3
    }, 
    {
      pos: [2, 6, 6], 
      state: 3
    }, 
    {
      pos: [3, 6, 6], 
      state: 3
    }, 
    {
      pos: [4, 6, 6], 
      state: 3
    }, 
    {
      pos: [5, 6, 6], 
      state: 3
    }, 
    {
      pos: [6, 6, 6], 
      state: 3
    }, 
    {
      pos: [7, 6, 6], 
      state: 3
    }, 
    {
      pos: [8, 6, 6], 
      state: 3
    }, 
    {
      pos: [9, 6, 6], 
      state: 3
    }, 
    {
      pos: [10, 6, 6], 
      state: 3
    }, 
    {
      pos: [2, 6, 7], 
      state: 3
    }, 
    {
      pos: [3, 6, 7], 
      state: 3
    }, 
    {
      pos: [4, 6, 7], 
      state: 3
    }, 
    {
      pos: [5, 6, 7], 
      state: 3
    }, 
    {
      pos: [6, 6, 7], 
      state: 3
    }, 
    {
      pos: [7, 6, 7], 
      state: 3
    }, 
    {
      pos: [8, 6, 7], 
      state: 3
    }, 
    {
      pos: [9, 6, 7], 
      state: 3
    }, 
    {
      pos: [10, 6, 7], 
      state: 3
    }, 
    {
      pos: [2, 6, 8], 
      state: 3
    }, 
    {
      pos: [3, 6, 8], 
      state: 3
    }, 
    {
      pos: [4, 6, 8], 
      state: 3
    }, 
    {
      pos: [5, 6, 8], 
      state: 3
    }, 
    {
      pos: [6, 6, 8], 
      state: 3
    }, 
    {
      pos: [7, 6, 8], 
      state: 3
    }, 
    {
      pos: [8, 6, 8], 
      state: 3
    }, 
    {
      pos: [9, 6, 8], 
      state: 3
    }, 
    {
      pos: [10, 6, 8], 
      state: 3
    }, 
    {
      pos: [1, 6, 9], 
      state: 3
    }, 
    {
      pos: [2, 6, 9], 
      state: 3
    }, 
    {
      pos: [3, 6, 9], 
      state: 3
    }, 
    {
      pos: [4, 6, 9], 
      state: 3
    }, 
    {
      pos: [5, 6, 9], 
      state: 3
    }, 
    {
      pos: [6, 6, 9], 
      state: 3
    }, 
    {
      pos: [7, 6, 9], 
      state: 3
    }, 
    {
      pos: [8, 6, 9], 
      state: 3
    }, 
    {
      pos: [9, 6, 9], 
      state: 3
    }, 
    {
      pos: [10, 6, 9], 
      state: 3
    }, 
    {
      pos: [1, 6, 10], 
      state: 3
    }, 
    {
      pos: [2, 6, 10], 
      state: 3
    }, 
    {
      pos: [3, 6, 10], 
      state: 3
    }, 
    {
      pos: [4, 6, 10], 
      state: 3
    }, 
    {
      pos: [5, 6, 10], 
      state: 3
    }, 
    {
      pos: [6, 6, 10], 
      state: 3
    }, 
    {
      pos: [7, 6, 10], 
      state: 3
    }, 
    {
      pos: [8, 6, 10], 
      state: 3
    }, 
    {
      pos: [9, 6, 10], 
      state: 3
    }, 
    {
      pos: [10, 6, 10], 
      state: 3
    }, 
    {
      pos: [0, 6, 11], 
      state: 3
    }, 
    {
      pos: [1, 6, 11], 
      state: 3
    }, 
    {
      pos: [2, 6, 11], 
      state: 3
    }, 
    {
      pos: [3, 6, 11], 
      state: 3
    }, 
    {
      pos: [4, 6, 11], 
      state: 3
    }, 
    {
      pos: [6, 6, 11], 
      state: 3
    }, 
    {
      pos: [7, 6, 11], 
      state: 3
    }, 
    {
      pos: [8, 6, 11], 
      state: 3
    }, 
    {
      pos: [9, 6, 11], 
      state: 3
    }, 
    {
      pos: [10, 6, 11], 
      state: 3
    }, 
    {
      pos: [0, 6, 12], 
      state: 3
    }, 
    {
      pos: [1, 6, 12], 
      state: 3
    }, 
    {
      pos: [2, 6, 12], 
      state: 3
    }, 
    {
      pos: [3, 6, 12], 
      state: 3
    }, 
    {
      pos: [4, 6, 12], 
      state: 3
    }, 
    {
      pos: [6, 6, 12], 
      state: 3
    }, 
    {
      pos: [7, 6, 12], 
      state: 3
    }, 
    {
      pos: [8, 6, 12], 
      state: 3
    }, 
    {
      pos: [9, 6, 12], 
      state: 3
    }, 
    {
      pos: [10, 6, 12], 
      state: 3
    }, 
    {
      pos: [0, 6, 13], 
      state: 3
    }, 
    {
      pos: [1, 6, 13], 
      state: 3
    }, 
    {
      pos: [2, 6, 13], 
      state: 3
    }, 
    {
      pos: [3, 6, 13], 
      state: 3
    }, 
    {
      pos: [4, 6, 13], 
      state: 3
    }, 
    {
      pos: [6, 6, 13], 
      state: 3
    }, 
    {
      pos: [7, 6, 13], 
      state: 3
    }, 
    {
      pos: [8, 6, 13], 
      state: 3
    }, 
    {
      pos: [9, 6, 13], 
      state: 3
    }, 
    {
      pos: [10, 6, 13], 
      state: 3
    }, 
    {
      pos: [1, 6, 14], 
      state: 3
    }, 
    {
      pos: [2, 6, 14], 
      state: 3
    }, 
    {
      pos: [3, 6, 14], 
      state: 3
    }, 
    {
      pos: [4, 6, 14], 
      state: 3
    }, 
    {
      pos: [5, 6, 14], 
      state: 3
    }, 
    {
      pos: [6, 6, 14], 
      state: 3
    }, 
    {
      pos: [7, 6, 14], 
      state: 3
    }, 
    {
      pos: [8, 6, 14], 
      state: 3
    }, 
    {
      pos: [9, 6, 14], 
      state: 3
    }, 
    {
      pos: [10, 6, 14], 
      state: 3
    }, 
    {
      pos: [1, 6, 15], 
      state: 3
    }, 
    {
      pos: [2, 6, 15], 
      state: 3
    }, 
    {
      pos: [3, 6, 15], 
      state: 3
    }, 
    {
      pos: [4, 6, 15], 
      state: 3
    }, 
    {
      pos: [7, 6, 15], 
      state: 3
    }, 
    {
      pos: [8, 6, 15], 
      state: 3
    }, 
    {
      pos: [9, 6, 15], 
      state: 3
    }, 
    {
      pos: [5, 7, 11], 
      state: 6
    }, 
    {
      pos: [5, 7, 13], 
      state: 1
    }, 
    {
      pos: [2, 7, 0], 
      state: 3
    }, 
    {
      pos: [3, 7, 0], 
      state: 3
    }, 
    {
      pos: [4, 7, 0], 
      state: 3
    }, 
    {
      pos: [5, 7, 0], 
      state: 3
    }, 
    {
      pos: [6, 7, 0], 
      state: 3
    }, 
    {
      pos: [7, 7, 0], 
      state: 3
    }, 
    {
      pos: [8, 7, 0], 
      state: 3
    }, 
    {
      pos: [1, 7, 1], 
      state: 3
    }, 
    {
      pos: [2, 7, 1], 
      state: 3
    }, 
    {
      pos: [3, 7, 1], 
      state: 3
    }, 
    {
      pos: [4, 7, 1], 
      state: 3
    }, 
    {
      pos: [5, 7, 1], 
      state: 3
    }, 
    {
      pos: [6, 7, 1], 
      state: 3
    }, 
    {
      pos: [7, 7, 1], 
      state: 3
    }, 
    {
      pos: [8, 7, 1], 
      state: 3
    }, 
    {
      pos: [9, 7, 1], 
      state: 3
    }, 
    {
      pos: [10, 7, 1], 
      state: 3
    }, 
    {
      pos: [0, 7, 2], 
      state: 3
    }, 
    {
      pos: [1, 7, 2], 
      state: 3
    }, 
    {
      pos: [2, 7, 2], 
      state: 3
    }, 
    {
      pos: [3, 7, 2], 
      state: 3
    }, 
    {
      pos: [4, 7, 2], 
      state: 3
    }, 
    {
      pos: [5, 7, 2], 
      state: 3
    }, 
    {
      pos: [6, 7, 2], 
      state: 3
    }, 
    {
      pos: [7, 7, 2], 
      state: 3
    }, 
    {
      pos: [8, 7, 2], 
      state: 3
    }, 
    {
      pos: [9, 7, 2], 
      state: 3
    }, 
    {
      pos: [10, 7, 2], 
      state: 3
    }, 
    {
      pos: [0, 7, 3], 
      state: 3
    }, 
    {
      pos: [1, 7, 3], 
      state: 3
    }, 
    {
      pos: [2, 7, 3], 
      state: 3
    }, 
    {
      pos: [3, 7, 3], 
      state: 3
    }, 
    {
      pos: [4, 7, 3], 
      state: 3
    }, 
    {
      pos: [5, 7, 3], 
      state: 3
    }, 
    {
      pos: [6, 7, 3], 
      state: 3
    }, 
    {
      pos: [7, 7, 3], 
      state: 3
    }, 
    {
      pos: [8, 7, 3], 
      state: 3
    }, 
    {
      pos: [9, 7, 3], 
      state: 3
    }, 
    {
      pos: [10, 7, 3], 
      state: 3
    }, 
    {
      pos: [1, 7, 4], 
      state: 3
    }, 
    {
      pos: [2, 7, 4], 
      state: 3
    }, 
    {
      pos: [3, 7, 4], 
      state: 3
    }, 
    {
      pos: [4, 7, 4], 
      state: 3
    }, 
    {
      pos: [5, 7, 4], 
      state: 3
    }, 
    {
      pos: [6, 7, 4], 
      state: 3
    }, 
    {
      pos: [7, 7, 4], 
      state: 3
    }, 
    {
      pos: [8, 7, 4], 
      state: 3
    }, 
    {
      pos: [9, 7, 4], 
      state: 3
    }, 
    {
      pos: [10, 7, 4], 
      state: 3
    }, 
    {
      pos: [1, 7, 5], 
      state: 3
    }, 
    {
      pos: [2, 7, 5], 
      state: 3
    }, 
    {
      pos: [3, 7, 5], 
      state: 3
    }, 
    {
      pos: [4, 7, 5], 
      state: 3
    }, 
    {
      pos: [5, 7, 5], 
      state: 3
    }, 
    {
      pos: [6, 7, 5], 
      state: 3
    }, 
    {
      pos: [7, 7, 5], 
      state: 3
    }, 
    {
      pos: [8, 7, 5], 
      state: 3
    }, 
    {
      pos: [9, 7, 5], 
      state: 3
    }, 
    {
      pos: [2, 7, 6], 
      state: 3
    }, 
    {
      pos: [3, 7, 6], 
      state: 3
    }, 
    {
      pos: [4, 7, 6], 
      state: 3
    }, 
    {
      pos: [5, 7, 6], 
      state: 3
    }, 
    {
      pos: [6, 7, 6], 
      state: 3
    }, 
    {
      pos: [7, 7, 6], 
      state: 3
    }, 
    {
      pos: [8, 7, 6], 
      state: 3
    }, 
    {
      pos: [9, 7, 6], 
      state: 3
    }, 
    {
      pos: [2, 7, 7], 
      state: 3
    }, 
    {
      pos: [3, 7, 7], 
      state: 3
    }, 
    {
      pos: [4, 7, 7], 
      state: 3
    }, 
    {
      pos: [5, 7, 7], 
      state: 3
    }, 
    {
      pos: [6, 7, 7], 
      state: 3
    }, 
    {
      pos: [7, 7, 7], 
      state: 3
    }, 
    {
      pos: [8, 7, 7], 
      state: 3
    }, 
    {
      pos: [9, 7, 7], 
      state: 3
    }, 
    {
      pos: [2, 7, 8], 
      state: 3
    }, 
    {
      pos: [3, 7, 8], 
      state: 3
    }, 
    {
      pos: [4, 7, 8], 
      state: 3
    }, 
    {
      pos: [5, 7, 8], 
      state: 3
    }, 
    {
      pos: [6, 7, 8], 
      state: 3
    }, 
    {
      pos: [7, 7, 8], 
      state: 3
    }, 
    {
      pos: [8, 7, 8], 
      state: 3
    }, 
    {
      pos: [9, 7, 8], 
      state: 3
    }, 
    {
      pos: [10, 7, 8], 
      state: 3
    }, 
    {
      pos: [2, 7, 9], 
      state: 3
    }, 
    {
      pos: [3, 7, 9], 
      state: 3
    }, 
    {
      pos: [4, 7, 9], 
      state: 3
    }, 
    {
      pos: [5, 7, 9], 
      state: 3
    }, 
    {
      pos: [6, 7, 9], 
      state: 3
    }, 
    {
      pos: [7, 7, 9], 
      state: 3
    }, 
    {
      pos: [8, 7, 9], 
      state: 3
    }, 
    {
      pos: [9, 7, 9], 
      state: 3
    }, 
    {
      pos: [10, 7, 9], 
      state: 3
    }, 
    {
      pos: [1, 7, 10], 
      state: 3
    }, 
    {
      pos: [2, 7, 10], 
      state: 3
    }, 
    {
      pos: [3, 7, 10], 
      state: 3
    }, 
    {
      pos: [4, 7, 10], 
      state: 3
    }, 
    {
      pos: [5, 7, 10], 
      state: 3
    }, 
    {
      pos: [6, 7, 10], 
      state: 3
    }, 
    {
      pos: [7, 7, 10], 
      state: 3
    }, 
    {
      pos: [8, 7, 10], 
      state: 3
    }, 
    {
      pos: [9, 7, 10], 
      state: 3
    }, 
    {
      pos: [10, 7, 10], 
      state: 3
    }, 
    {
      pos: [1, 7, 11], 
      state: 3
    }, 
    {
      pos: [2, 7, 11], 
      state: 3
    }, 
    {
      pos: [3, 7, 11], 
      state: 3
    }, 
    {
      pos: [4, 7, 11], 
      state: 3
    }, 
    {
      pos: [6, 7, 11], 
      state: 3
    }, 
    {
      pos: [7, 7, 11], 
      state: 3
    }, 
    {
      pos: [8, 7, 11], 
      state: 3
    }, 
    {
      pos: [9, 7, 11], 
      state: 3
    }, 
    {
      pos: [10, 7, 11], 
      state: 3
    }, 
    {
      pos: [0, 7, 12], 
      state: 3
    }, 
    {
      pos: [1, 7, 12], 
      state: 3
    }, 
    {
      pos: [2, 7, 12], 
      state: 3
    }, 
    {
      pos: [3, 7, 12], 
      state: 3
    }, 
    {
      pos: [4, 7, 12], 
      state: 3
    }, 
    {
      pos: [5, 7, 12], 
      state: 17
    }, 
    {
      pos: [6, 7, 12], 
      state: 3
    }, 
    {
      pos: [7, 7, 12], 
      state: 3
    }, 
    {
      pos: [8, 7, 12], 
      state: 3
    }, 
    {
      pos: [9, 7, 12], 
      state: 3
    }, 
    {
      pos: [10, 7, 12], 
      state: 3
    }, 
    {
      pos: [1, 7, 13], 
      state: 3
    }, 
    {
      pos: [2, 7, 13], 
      state: 3
    }, 
    {
      pos: [3, 7, 13], 
      state: 3
    }, 
    {
      pos: [4, 7, 13], 
      state: 3
    }, 
    {
      pos: [6, 7, 13], 
      state: 3
    }, 
    {
      pos: [7, 7, 13], 
      state: 3
    }, 
    {
      pos: [8, 7, 13], 
      state: 3
    }, 
    {
      pos: [9, 7, 13], 
      state: 3
    }, 
    {
      pos: [10, 7, 13], 
      state: 3
    }, 
    {
      pos: [1, 7, 14], 
      state: 3
    }, 
    {
      pos: [2, 7, 14], 
      state: 3
    }, 
    {
      pos: [3, 7, 14], 
      state: 3
    }, 
    {
      pos: [4, 7, 14], 
      state: 3
    }, 
    {
      pos: [5, 7, 14], 
      state: 3
    }, 
    {
      pos: [6, 7, 14], 
      state: 3
    }, 
    {
      pos: [7, 7, 14], 
      state: 3
    }, 
    {
      pos: [8, 7, 14], 
      state: 3
    }, 
    {
      pos: [9, 7, 14], 
      state: 3
    }, 
    {
      pos: [10, 7, 14], 
      state: 3
    }, 
    {
      pos: [1, 7, 15], 
      state: 3
    }, 
    {
      pos: [2, 7, 15], 
      state: 3
    }, 
    {
      pos: [3, 7, 15], 
      state: 3
    }, 
    {
      pos: [4, 7, 15], 
      state: 3
    }, 
    {
      pos: [6, 7, 15], 
      state: 3
    }, 
    {
      pos: [7, 7, 15], 
      state: 3
    }, 
    {
      pos: [8, 7, 15], 
      state: 3
    }, 
    {
      pos: [9, 7, 15], 
      state: 3
    }, 
    {
      pos: [5, 8, 11], 
      state: 6
    }, 
    {
      pos: [5, 8, 13], 
      state: 1
    }, 
    {
      pos: [1, 8, 0], 
      state: 3
    }, 
    {
      pos: [2, 8, 0], 
      state: 3
    }, 
    {
      pos: [7, 8, 0], 
      state: 3
    }, 
    {
      pos: [1, 8, 1], 
      state: 3
    }, 
    {
      pos: [2, 8, 1], 
      state: 3
    }, 
    {
      pos: [3, 8, 1], 
      state: 3
    }, 
    {
      pos: [4, 8, 1], 
      state: 3
    }, 
    {
      pos: [5, 8, 1], 
      state: 3
    }, 
    {
      pos: [6, 8, 1], 
      state: 3
    }, 
    {
      pos: [7, 8, 1], 
      state: 3
    }, 
    {
      pos: [8, 8, 1], 
      state: 3
    }, 
    {
      pos: [9, 8, 1], 
      state: 3
    }, 
    {
      pos: [10, 8, 1], 
      state: 3
    }, 
    {
      pos: [1, 8, 2], 
      state: 3
    }, 
    {
      pos: [2, 8, 2], 
      state: 3
    }, 
    {
      pos: [3, 8, 2], 
      state: 3
    }, 
    {
      pos: [4, 8, 2], 
      state: 3
    }, 
    {
      pos: [5, 8, 2], 
      state: 3
    }, 
    {
      pos: [6, 8, 2], 
      state: 3
    }, 
    {
      pos: [7, 8, 2], 
      state: 3
    }, 
    {
      pos: [8, 8, 2], 
      state: 3
    }, 
    {
      pos: [9, 8, 2], 
      state: 3
    }, 
    {
      pos: [10, 8, 2], 
      state: 3
    }, 
    {
      pos: [0, 8, 3], 
      state: 3
    }, 
    {
      pos: [1, 8, 3], 
      state: 3
    }, 
    {
      pos: [2, 8, 3], 
      state: 3
    }, 
    {
      pos: [3, 8, 3], 
      state: 3
    }, 
    {
      pos: [4, 8, 3], 
      state: 3
    }, 
    {
      pos: [5, 8, 3], 
      state: 3
    }, 
    {
      pos: [6, 8, 3], 
      state: 3
    }, 
    {
      pos: [7, 8, 3], 
      state: 3
    }, 
    {
      pos: [8, 8, 3], 
      state: 3
    }, 
    {
      pos: [9, 8, 3], 
      state: 3
    }, 
    {
      pos: [10, 8, 3], 
      state: 3
    }, 
    {
      pos: [0, 8, 4], 
      state: 3
    }, 
    {
      pos: [1, 8, 4], 
      state: 3
    }, 
    {
      pos: [2, 8, 4], 
      state: 3
    }, 
    {
      pos: [3, 8, 4], 
      state: 3
    }, 
    {
      pos: [4, 8, 4], 
      state: 3
    }, 
    {
      pos: [5, 8, 4], 
      state: 3
    }, 
    {
      pos: [6, 8, 4], 
      state: 3
    }, 
    {
      pos: [7, 8, 4], 
      state: 3
    }, 
    {
      pos: [8, 8, 4], 
      state: 3
    }, 
    {
      pos: [9, 8, 4], 
      state: 3
    }, 
    {
      pos: [1, 8, 5], 
      state: 3
    }, 
    {
      pos: [2, 8, 5], 
      state: 3
    }, 
    {
      pos: [3, 8, 5], 
      state: 3
    }, 
    {
      pos: [4, 8, 5], 
      state: 3
    }, 
    {
      pos: [5, 8, 5], 
      state: 3
    }, 
    {
      pos: [6, 8, 5], 
      state: 3
    }, 
    {
      pos: [7, 8, 5], 
      state: 3
    }, 
    {
      pos: [8, 8, 5], 
      state: 3
    }, 
    {
      pos: [2, 8, 6], 
      state: 3
    }, 
    {
      pos: [3, 8, 6], 
      state: 3
    }, 
    {
      pos: [4, 8, 6], 
      state: 3
    }, 
    {
      pos: [5, 8, 6], 
      state: 3
    }, 
    {
      pos: [6, 8, 6], 
      state: 3
    }, 
    {
      pos: [7, 8, 6], 
      state: 3
    }, 
    {
      pos: [8, 8, 6], 
      state: 3
    }, 
    {
      pos: [2, 8, 7], 
      state: 3
    }, 
    {
      pos: [3, 8, 7], 
      state: 3
    }, 
    {
      pos: [4, 8, 7], 
      state: 3
    }, 
    {
      pos: [5, 8, 7], 
      state: 3
    }, 
    {
      pos: [6, 8, 7], 
      state: 3
    }, 
    {
      pos: [7, 8, 7], 
      state: 3
    }, 
    {
      pos: [8, 8, 7], 
      state: 3
    }, 
    {
      pos: [2, 8, 8], 
      state: 3
    }, 
    {
      pos: [3, 8, 8], 
      state: 3
    }, 
    {
      pos: [4, 8, 8], 
      state: 3
    }, 
    {
      pos: [5, 8, 8], 
      state: 3
    }, 
    {
      pos: [6, 8, 8], 
      state: 3
    }, 
    {
      pos: [7, 8, 8], 
      state: 3
    }, 
    {
      pos: [8, 8, 8], 
      state: 3
    }, 
    {
      pos: [9, 8, 8], 
      state: 3
    }, 
    {
      pos: [1, 8, 9], 
      state: 3
    }, 
    {
      pos: [2, 8, 9], 
      state: 3
    }, 
    {
      pos: [3, 8, 9], 
      state: 3
    }, 
    {
      pos: [4, 8, 9], 
      state: 3
    }, 
    {
      pos: [5, 8, 9], 
      state: 3
    }, 
    {
      pos: [6, 8, 9], 
      state: 3
    }, 
    {
      pos: [7, 8, 9], 
      state: 3
    }, 
    {
      pos: [8, 8, 9], 
      state: 3
    }, 
    {
      pos: [9, 8, 9], 
      state: 3
    }, 
    {
      pos: [1, 8, 10], 
      state: 3
    }, 
    {
      pos: [2, 8, 10], 
      state: 3
    }, 
    {
      pos: [3, 8, 10], 
      state: 3
    }, 
    {
      pos: [4, 8, 10], 
      state: 3
    }, 
    {
      pos: [5, 8, 10], 
      state: 3
    }, 
    {
      pos: [6, 8, 10], 
      state: 3
    }, 
    {
      pos: [7, 8, 10], 
      state: 3
    }, 
    {
      pos: [8, 8, 10], 
      state: 3
    }, 
    {
      pos: [9, 8, 10], 
      state: 3
    }, 
    {
      pos: [0, 8, 11], 
      state: 3
    }, 
    {
      pos: [1, 8, 11], 
      state: 3
    }, 
    {
      pos: [2, 8, 11], 
      state: 3
    }, 
    {
      pos: [3, 8, 11], 
      state: 3
    }, 
    {
      pos: [4, 8, 11], 
      state: 3
    }, 
    {
      pos: [6, 8, 11], 
      state: 3
    }, 
    {
      pos: [7, 8, 11], 
      state: 3
    }, 
    {
      pos: [8, 8, 11], 
      state: 3
    }, 
    {
      pos: [9, 8, 11], 
      state: 3
    }, 
    {
      pos: [10, 8, 11], 
      state: 3
    }, 
    {
      pos: [0, 8, 12], 
      state: 3
    }, 
    {
      pos: [1, 8, 12], 
      state: 3
    }, 
    {
      pos: [2, 8, 12], 
      state: 3
    }, 
    {
      pos: [3, 8, 12], 
      state: 3
    }, 
    {
      pos: [4, 8, 12], 
      state: 3
    }, 
    {
      pos: [5, 8, 12], 
      state: 17
    }, 
    {
      pos: [6, 8, 12], 
      state: 3
    }, 
    {
      pos: [7, 8, 12], 
      state: 3
    }, 
    {
      pos: [8, 8, 12], 
      state: 3
    }, 
    {
      pos: [9, 8, 12], 
      state: 3
    }, 
    {
      pos: [10, 8, 12], 
      state: 3
    }, 
    {
      pos: [0, 8, 13], 
      state: 3
    }, 
    {
      pos: [1, 8, 13], 
      state: 3
    }, 
    {
      pos: [2, 8, 13], 
      state: 3
    }, 
    {
      pos: [3, 8, 13], 
      state: 3
    }, 
    {
      pos: [4, 8, 13], 
      state: 3
    }, 
    {
      pos: [6, 8, 13], 
      state: 3
    }, 
    {
      pos: [7, 8, 13], 
      state: 3
    }, 
    {
      pos: [8, 8, 13], 
      state: 3
    }, 
    {
      pos: [9, 8, 13], 
      state: 3
    }, 
    {
      pos: [10, 8, 13], 
      state: 3
    }, 
    {
      pos: [1, 8, 14], 
      state: 3
    }, 
    {
      pos: [2, 8, 14], 
      state: 3
    }, 
    {
      pos: [3, 8, 14], 
      state: 3
    }, 
    {
      pos: [4, 8, 14], 
      state: 3
    }, 
    {
      pos: [5, 8, 14], 
      state: 3
    }, 
    {
      pos: [6, 8, 14], 
      state: 3
    }, 
    {
      pos: [7, 8, 14], 
      state: 3
    }, 
    {
      pos: [8, 8, 14], 
      state: 3
    }, 
    {
      pos: [9, 8, 14], 
      state: 3
    }, 
    {
      pos: [10, 8, 14], 
      state: 3
    }, 
    {
      pos: [1, 8, 15], 
      state: 3
    }, 
    {
      pos: [2, 8, 15], 
      state: 3
    }, 
    {
      pos: [3, 8, 15], 
      state: 3
    }, 
    {
      pos: [4, 8, 15], 
      state: 3
    }, 
    {
      pos: [5, 8, 15], 
      state: 3
    }, 
    {
      pos: [6, 8, 15], 
      state: 3
    }, 
    {
      pos: [7, 8, 15], 
      state: 3
    }, 
    {
      pos: [8, 8, 15], 
      state: 3
    }, 
    {
      pos: [9, 8, 15], 
      state: 3
    }, 
    {
      pos: [5, 9, 2], 
      state: 1
    }, 
    {
      pos: [5, 9, 3], 
      state: 15
    }, 
    {
      pos: [5, 9, 11], 
      state: 6
    }, 
    {
      pos: [5, 9, 12], 
      state: 15
    }, 
    {
      pos: [5, 9, 13], 
      state: 1
    }, 
    {
      pos: [1, 9, 0], 
      state: 3
    }, 
    {
      pos: [2, 9, 0], 
      state: 3
    }, 
    {
      pos: [8, 9, 0], 
      state: 3
    }, 
    {
      pos: [1, 9, 1], 
      state: 3
    }, 
    {
      pos: [2, 9, 1], 
      state: 3
    }, 
    {
      pos: [7, 9, 1], 
      state: 3
    }, 
    {
      pos: [8, 9, 1], 
      state: 3
    }, 
    {
      pos: [9, 9, 1], 
      state: 3
    }, 
    {
      pos: [10, 9, 1], 
      state: 3
    }, 
    {
      pos: [1, 9, 2], 
      state: 3
    }, 
    {
      pos: [2, 9, 2], 
      state: 3
    }, 
    {
      pos: [3, 9, 2], 
      state: 3
    }, 
    {
      pos: [4, 9, 2], 
      state: 3
    }, 
    {
      pos: [6, 9, 2], 
      state: 3
    }, 
    {
      pos: [7, 9, 2], 
      state: 3
    }, 
    {
      pos: [8, 9, 2], 
      state: 3
    }, 
    {
      pos: [9, 9, 2], 
      state: 3
    }, 
    {
      pos: [10, 9, 2], 
      state: 3
    }, 
    {
      pos: [0, 9, 3], 
      state: 3
    }, 
    {
      pos: [1, 9, 3], 
      state: 3
    }, 
    {
      pos: [2, 9, 3], 
      state: 3
    }, 
    {
      pos: [3, 9, 3], 
      state: 3
    }, 
    {
      pos: [4, 9, 3], 
      state: 3
    }, 
    {
      pos: [6, 9, 3], 
      state: 3
    }, 
    {
      pos: [7, 9, 3], 
      state: 3
    }, 
    {
      pos: [8, 9, 3], 
      state: 3
    }, 
    {
      pos: [9, 9, 3], 
      state: 3
    }, 
    {
      pos: [10, 9, 3], 
      state: 3
    }, 
    {
      pos: [0, 9, 4], 
      state: 3
    }, 
    {
      pos: [1, 9, 4], 
      state: 3
    }, 
    {
      pos: [2, 9, 4], 
      state: 3
    }, 
    {
      pos: [3, 9, 4], 
      state: 3
    }, 
    {
      pos: [4, 9, 4], 
      state: 3
    }, 
    {
      pos: [5, 9, 4], 
      state: 3
    }, 
    {
      pos: [6, 9, 4], 
      state: 3
    }, 
    {
      pos: [7, 9, 4], 
      state: 3
    }, 
    {
      pos: [8, 9, 4], 
      state: 3
    }, 
    {
      pos: [9, 9, 4], 
      state: 3
    }, 
    {
      pos: [1, 9, 5], 
      state: 3
    }, 
    {
      pos: [2, 9, 5], 
      state: 3
    }, 
    {
      pos: [3, 9, 5], 
      state: 3
    }, 
    {
      pos: [4, 9, 5], 
      state: 3
    }, 
    {
      pos: [5, 9, 5], 
      state: 3
    }, 
    {
      pos: [6, 9, 5], 
      state: 3
    }, 
    {
      pos: [7, 9, 5], 
      state: 3
    }, 
    {
      pos: [8, 9, 5], 
      state: 3
    }, 
    {
      pos: [9, 9, 5], 
      state: 3
    }, 
    {
      pos: [1, 9, 6], 
      state: 3
    }, 
    {
      pos: [2, 9, 6], 
      state: 3
    }, 
    {
      pos: [3, 9, 6], 
      state: 3
    }, 
    {
      pos: [4, 9, 6], 
      state: 3
    }, 
    {
      pos: [5, 9, 6], 
      state: 3
    }, 
    {
      pos: [6, 9, 6], 
      state: 3
    }, 
    {
      pos: [7, 9, 6], 
      state: 3
    }, 
    {
      pos: [8, 9, 6], 
      state: 3
    }, 
    {
      pos: [2, 9, 7], 
      state: 3
    }, 
    {
      pos: [3, 9, 7], 
      state: 3
    }, 
    {
      pos: [4, 9, 7], 
      state: 3
    }, 
    {
      pos: [5, 9, 7], 
      state: 3
    }, 
    {
      pos: [6, 9, 7], 
      state: 3
    }, 
    {
      pos: [7, 9, 7], 
      state: 3
    }, 
    {
      pos: [8, 9, 7], 
      state: 3
    }, 
    {
      pos: [1, 9, 8], 
      state: 3
    }, 
    {
      pos: [2, 9, 8], 
      state: 3
    }, 
    {
      pos: [3, 9, 8], 
      state: 3
    }, 
    {
      pos: [4, 9, 8], 
      state: 3
    }, 
    {
      pos: [5, 9, 8], 
      state: 3
    }, 
    {
      pos: [6, 9, 8], 
      state: 3
    }, 
    {
      pos: [7, 9, 8], 
      state: 3
    }, 
    {
      pos: [8, 9, 8], 
      state: 3
    }, 
    {
      pos: [0, 9, 9], 
      state: 3
    }, 
    {
      pos: [1, 9, 9], 
      state: 3
    }, 
    {
      pos: [2, 9, 9], 
      state: 3
    }, 
    {
      pos: [3, 9, 9], 
      state: 3
    }, 
    {
      pos: [4, 9, 9], 
      state: 3
    }, 
    {
      pos: [5, 9, 9], 
      state: 3
    }, 
    {
      pos: [6, 9, 9], 
      state: 3
    }, 
    {
      pos: [7, 9, 9], 
      state: 3
    }, 
    {
      pos: [8, 9, 9], 
      state: 3
    }, 
    {
      pos: [0, 9, 10], 
      state: 3
    }, 
    {
      pos: [1, 9, 10], 
      state: 3
    }, 
    {
      pos: [2, 9, 10], 
      state: 3
    }, 
    {
      pos: [3, 9, 10], 
      state: 3
    }, 
    {
      pos: [4, 9, 10], 
      state: 3
    }, 
    {
      pos: [5, 9, 10], 
      state: 3
    }, 
    {
      pos: [6, 9, 10], 
      state: 3
    }, 
    {
      pos: [7, 9, 10], 
      state: 3
    }, 
    {
      pos: [8, 9, 10], 
      state: 3
    }, 
    {
      pos: [9, 9, 10], 
      state: 3
    }, 
    {
      pos: [0, 9, 11], 
      state: 3
    }, 
    {
      pos: [1, 9, 11], 
      state: 3
    }, 
    {
      pos: [2, 9, 11], 
      state: 3
    }, 
    {
      pos: [3, 9, 11], 
      state: 3
    }, 
    {
      pos: [4, 9, 11], 
      state: 3
    }, 
    {
      pos: [6, 9, 11], 
      state: 3
    }, 
    {
      pos: [7, 9, 11], 
      state: 3
    }, 
    {
      pos: [8, 9, 11], 
      state: 3
    }, 
    {
      pos: [9, 9, 11], 
      state: 3
    }, 
    {
      pos: [0, 9, 12], 
      state: 3
    }, 
    {
      pos: [1, 9, 12], 
      state: 3
    }, 
    {
      pos: [2, 9, 12], 
      state: 3
    }, 
    {
      pos: [3, 9, 12], 
      state: 3
    }, 
    {
      pos: [4, 9, 12], 
      state: 3
    }, 
    {
      pos: [6, 9, 12], 
      state: 3
    }, 
    {
      pos: [7, 9, 12], 
      state: 3
    }, 
    {
      pos: [8, 9, 12], 
      state: 3
    }, 
    {
      pos: [9, 9, 12], 
      state: 3
    }, 
    {
      pos: [10, 9, 12], 
      state: 3
    }, 
    {
      pos: [0, 9, 13], 
      state: 3
    }, 
    {
      pos: [1, 9, 13], 
      state: 3
    }, 
    {
      pos: [2, 9, 13], 
      state: 3
    }, 
    {
      pos: [3, 9, 13], 
      state: 3
    }, 
    {
      pos: [4, 9, 13], 
      state: 3
    }, 
    {
      pos: [6, 9, 13], 
      state: 3
    }, 
    {
      pos: [7, 9, 13], 
      state: 3
    }, 
    {
      pos: [8, 9, 13], 
      state: 3
    }, 
    {
      pos: [9, 9, 13], 
      state: 3
    }, 
    {
      pos: [10, 9, 13], 
      state: 3
    }, 
    {
      pos: [0, 9, 14], 
      state: 3
    }, 
    {
      pos: [1, 9, 14], 
      state: 3
    }, 
    {
      pos: [2, 9, 14], 
      state: 3
    }, 
    {
      pos: [3, 9, 14], 
      state: 3
    }, 
    {
      pos: [4, 9, 14], 
      state: 3
    }, 
    {
      pos: [5, 9, 14], 
      state: 3
    }, 
    {
      pos: [6, 9, 14], 
      state: 3
    }, 
    {
      pos: [7, 9, 14], 
      state: 3
    }, 
    {
      pos: [8, 9, 14], 
      state: 3
    }, 
    {
      pos: [9, 9, 14], 
      state: 3
    }, 
    {
      pos: [10, 9, 14], 
      state: 3
    }, 
    {
      pos: [1, 9, 15], 
      state: 3
    }, 
    {
      pos: [3, 9, 15], 
      state: 3
    }, 
    {
      pos: [4, 9, 15], 
      state: 3
    }, 
    {
      pos: [5, 9, 15], 
      state: 3
    }, 
    {
      pos: [6, 9, 15], 
      state: 3
    }, 
    {
      pos: [7, 9, 15], 
      state: 3
    }, 
    {
      pos: [8, 9, 15], 
      state: 3
    }, 
    {
      pos: [9, 9, 15], 
      state: 3
    }, 
    {
      pos: [5, 10, 2], 
      state: 1
    }, 
    {
      pos: [5, 10, 4], 
      state: 6
    }, 
    {
      pos: [5, 10, 11], 
      state: 6
    }, 
    {
      pos: [5, 10, 13], 
      state: 1
    }, 
    {
      pos: [1, 10, 0], 
      state: 3
    }, 
    {
      pos: [2, 10, 0], 
      state: 3
    }, 
    {
      pos: [3, 10, 0], 
      state: 3
    }, 
    {
      pos: [9, 10, 0], 
      state: 3
    }, 
    {
      pos: [0, 10, 1], 
      state: 3
    }, 
    {
      pos: [1, 10, 1], 
      state: 3
    }, 
    {
      pos: [2, 10, 1], 
      state: 3
    }, 
    {
      pos: [3, 10, 1], 
      state: 3
    }, 
    {
      pos: [8, 10, 1], 
      state: 3
    }, 
    {
      pos: [9, 10, 1], 
      state: 3
    }, 
    {
      pos: [10, 10, 1], 
      state: 3
    }, 
    {
      pos: [0, 10, 2], 
      state: 3
    }, 
    {
      pos: [1, 10, 2], 
      state: 3
    }, 
    {
      pos: [2, 10, 2], 
      state: 3
    }, 
    {
      pos: [3, 10, 2], 
      state: 3
    }, 
    {
      pos: [4, 10, 2], 
      state: 3
    }, 
    {
      pos: [6, 10, 2], 
      state: 3
    }, 
    {
      pos: [7, 10, 2], 
      state: 3
    }, 
    {
      pos: [8, 10, 2], 
      state: 3
    }, 
    {
      pos: [9, 10, 2], 
      state: 3
    }, 
    {
      pos: [10, 10, 2], 
      state: 3
    }, 
    {
      pos: [0, 10, 3], 
      state: 3
    }, 
    {
      pos: [1, 10, 3], 
      state: 3
    }, 
    {
      pos: [2, 10, 3], 
      state: 3
    }, 
    {
      pos: [3, 10, 3], 
      state: 3
    }, 
    {
      pos: [4, 10, 3], 
      state: 3
    }, 
    {
      pos: [5, 10, 3], 
      state: 17
    }, 
    {
      pos: [6, 10, 3], 
      state: 3
    }, 
    {
      pos: [7, 10, 3], 
      state: 3
    }, 
    {
      pos: [8, 10, 3], 
      state: 3
    }, 
    {
      pos: [9, 10, 3], 
      state: 3
    }, 
    {
      pos: [10, 10, 3], 
      state: 3
    }, 
    {
      pos: [0, 10, 4], 
      state: 3
    }, 
    {
      pos: [1, 10, 4], 
      state: 3
    }, 
    {
      pos: [2, 10, 4], 
      state: 3
    }, 
    {
      pos: [3, 10, 4], 
      state: 3
    }, 
    {
      pos: [4, 10, 4], 
      state: 3
    }, 
    {
      pos: [6, 10, 4], 
      state: 3
    }, 
    {
      pos: [7, 10, 4], 
      state: 3
    }, 
    {
      pos: [8, 10, 4], 
      state: 3
    }, 
    {
      pos: [9, 10, 4], 
      state: 3
    }, 
    {
      pos: [10, 10, 4], 
      state: 3
    }, 
    {
      pos: [0, 10, 5], 
      state: 3
    }, 
    {
      pos: [1, 10, 5], 
      state: 3
    }, 
    {
      pos: [2, 10, 5], 
      state: 3
    }, 
    {
      pos: [3, 10, 5], 
      state: 3
    }, 
    {
      pos: [4, 10, 5], 
      state: 3
    }, 
    {
      pos: [5, 10, 5], 
      state: 3
    }, 
    {
      pos: [6, 10, 5], 
      state: 3
    }, 
    {
      pos: [7, 10, 5], 
      state: 3
    }, 
    {
      pos: [8, 10, 5], 
      state: 3
    }, 
    {
      pos: [9, 10, 5], 
      state: 3
    }, 
    {
      pos: [1, 10, 6], 
      state: 3
    }, 
    {
      pos: [2, 10, 6], 
      state: 3
    }, 
    {
      pos: [3, 10, 6], 
      state: 3
    }, 
    {
      pos: [4, 10, 6], 
      state: 3
    }, 
    {
      pos: [5, 10, 6], 
      state: 3
    }, 
    {
      pos: [6, 10, 6], 
      state: 3
    }, 
    {
      pos: [7, 10, 6], 
      state: 3
    }, 
    {
      pos: [8, 10, 6], 
      state: 3
    }, 
    {
      pos: [9, 10, 6], 
      state: 3
    }, 
    {
      pos: [1, 10, 7], 
      state: 3
    }, 
    {
      pos: [2, 10, 7], 
      state: 3
    }, 
    {
      pos: [3, 10, 7], 
      state: 3
    }, 
    {
      pos: [4, 10, 7], 
      state: 3
    }, 
    {
      pos: [5, 10, 7], 
      state: 3
    }, 
    {
      pos: [6, 10, 7], 
      state: 3
    }, 
    {
      pos: [7, 10, 7], 
      state: 3
    }, 
    {
      pos: [8, 10, 7], 
      state: 3
    }, 
    {
      pos: [1, 10, 8], 
      state: 3
    }, 
    {
      pos: [2, 10, 8], 
      state: 3
    }, 
    {
      pos: [3, 10, 8], 
      state: 3
    }, 
    {
      pos: [4, 10, 8], 
      state: 3
    }, 
    {
      pos: [5, 10, 8], 
      state: 3
    }, 
    {
      pos: [6, 10, 8], 
      state: 3
    }, 
    {
      pos: [7, 10, 8], 
      state: 3
    }, 
    {
      pos: [8, 10, 8], 
      state: 3
    }, 
    {
      pos: [0, 10, 9], 
      state: 3
    }, 
    {
      pos: [1, 10, 9], 
      state: 3
    }, 
    {
      pos: [2, 10, 9], 
      state: 3
    }, 
    {
      pos: [3, 10, 9], 
      state: 3
    }, 
    {
      pos: [4, 10, 9], 
      state: 3
    }, 
    {
      pos: [5, 10, 9], 
      state: 3
    }, 
    {
      pos: [6, 10, 9], 
      state: 3
    }, 
    {
      pos: [7, 10, 9], 
      state: 3
    }, 
    {
      pos: [8, 10, 9], 
      state: 3
    }, 
    {
      pos: [0, 10, 10], 
      state: 3
    }, 
    {
      pos: [1, 10, 10], 
      state: 3
    }, 
    {
      pos: [2, 10, 10], 
      state: 3
    }, 
    {
      pos: [3, 10, 10], 
      state: 3
    }, 
    {
      pos: [4, 10, 10], 
      state: 3
    }, 
    {
      pos: [5, 10, 10], 
      state: 3
    }, 
    {
      pos: [6, 10, 10], 
      state: 3
    }, 
    {
      pos: [7, 10, 10], 
      state: 3
    }, 
    {
      pos: [8, 10, 10], 
      state: 3
    }, 
    {
      pos: [9, 10, 10], 
      state: 3
    }, 
    {
      pos: [0, 10, 11], 
      state: 3
    }, 
    {
      pos: [1, 10, 11], 
      state: 3
    }, 
    {
      pos: [2, 10, 11], 
      state: 3
    }, 
    {
      pos: [3, 10, 11], 
      state: 3
    }, 
    {
      pos: [4, 10, 11], 
      state: 3
    }, 
    {
      pos: [6, 10, 11], 
      state: 3
    }, 
    {
      pos: [7, 10, 11], 
      state: 3
    }, 
    {
      pos: [8, 10, 11], 
      state: 3
    }, 
    {
      pos: [9, 10, 11], 
      state: 3
    }, 
    {
      pos: [10, 10, 11], 
      state: 3
    }, 
    {
      pos: [0, 10, 12], 
      state: 3
    }, 
    {
      pos: [1, 10, 12], 
      state: 3
    }, 
    {
      pos: [2, 10, 12], 
      state: 3
    }, 
    {
      pos: [3, 10, 12], 
      state: 3
    }, 
    {
      pos: [4, 10, 12], 
      state: 3
    }, 
    {
      pos: [5, 10, 12], 
      state: 17
    }, 
    {
      pos: [6, 10, 12], 
      state: 3
    }, 
    {
      pos: [7, 10, 12], 
      state: 3
    }, 
    {
      pos: [8, 10, 12], 
      state: 3
    }, 
    {
      pos: [9, 10, 12], 
      state: 3
    }, 
    {
      pos: [10, 10, 12], 
      state: 3
    }, 
    {
      pos: [0, 10, 13], 
      state: 3
    }, 
    {
      pos: [1, 10, 13], 
      state: 3
    }, 
    {
      pos: [2, 10, 13], 
      state: 3
    }, 
    {
      pos: [3, 10, 13], 
      state: 3
    }, 
    {
      pos: [4, 10, 13], 
      state: 3
    }, 
    {
      pos: [6, 10, 13], 
      state: 3
    }, 
    {
      pos: [7, 10, 13], 
      state: 3
    }, 
    {
      pos: [8, 10, 13], 
      state: 3
    }, 
    {
      pos: [9, 10, 13], 
      state: 3
    }, 
    {
      pos: [10, 10, 13], 
      state: 3
    }, 
    {
      pos: [0, 10, 14], 
      state: 3
    }, 
    {
      pos: [1, 10, 14], 
      state: 3
    }, 
    {
      pos: [2, 10, 14], 
      state: 3
    }, 
    {
      pos: [3, 10, 14], 
      state: 3
    }, 
    {
      pos: [4, 10, 14], 
      state: 3
    }, 
    {
      pos: [5, 10, 14], 
      state: 3
    }, 
    {
      pos: [6, 10, 14], 
      state: 3
    }, 
    {
      pos: [7, 10, 14], 
      state: 3
    }, 
    {
      pos: [8, 10, 14], 
      state: 3
    }, 
    {
      pos: [9, 10, 14], 
      state: 3
    }, 
    {
      pos: [10, 10, 14], 
      state: 3
    }, 
    {
      pos: [1, 10, 15], 
      state: 3
    }, 
    {
      pos: [3, 10, 15], 
      state: 3
    }, 
    {
      pos: [4, 10, 15], 
      state: 3
    }, 
    {
      pos: [5, 10, 15], 
      state: 3
    }, 
    {
      pos: [6, 10, 15], 
      state: 3
    }, 
    {
      pos: [7, 10, 15], 
      state: 3
    }, 
    {
      pos: [8, 10, 15], 
      state: 3
    }, 
    {
      pos: [9, 10, 15], 
      state: 3
    }, 
    {
      pos: [5, 11, 2], 
      state: 1
    }, 
    {
      pos: [5, 11, 4], 
      state: 6
    }, 
    {
      pos: [5, 11, 11], 
      state: 6
    }, 
    {
      pos: [5, 11, 13], 
      state: 1
    }, 
    {
      pos: [2, 11, 0], 
      state: 3
    }, 
    {
      pos: [3, 11, 0], 
      state: 3
    }, 
    {
      pos: [4, 11, 0], 
      state: 3
    }, 
    {
      pos: [8, 11, 0], 
      state: 3
    }, 
    {
      pos: [9, 11, 0], 
      state: 3
    }, 
    {
      pos: [1, 11, 1], 
      state: 3
    }, 
    {
      pos: [2, 11, 1], 
      state: 3
    }, 
    {
      pos: [3, 11, 1], 
      state: 3
    }, 
    {
      pos: [4, 11, 1], 
      state: 3
    }, 
    {
      pos: [5, 11, 1], 
      state: 3
    }, 
    {
      pos: [6, 11, 1], 
      state: 3
    }, 
    {
      pos: [7, 11, 1], 
      state: 3
    }, 
    {
      pos: [8, 11, 1], 
      state: 3
    }, 
    {
      pos: [9, 11, 1], 
      state: 3
    }, 
    {
      pos: [0, 11, 2], 
      state: 3
    }, 
    {
      pos: [1, 11, 2], 
      state: 3
    }, 
    {
      pos: [2, 11, 2], 
      state: 3
    }, 
    {
      pos: [3, 11, 2], 
      state: 3
    }, 
    {
      pos: [4, 11, 2], 
      state: 3
    }, 
    {
      pos: [6, 11, 2], 
      state: 3
    }, 
    {
      pos: [7, 11, 2], 
      state: 3
    }, 
    {
      pos: [8, 11, 2], 
      state: 3
    }, 
    {
      pos: [9, 11, 2], 
      state: 3
    }, 
    {
      pos: [10, 11, 2], 
      state: 3
    }, 
    {
      pos: [0, 11, 3], 
      state: 3
    }, 
    {
      pos: [1, 11, 3], 
      state: 3
    }, 
    {
      pos: [2, 11, 3], 
      state: 3
    }, 
    {
      pos: [3, 11, 3], 
      state: 3
    }, 
    {
      pos: [4, 11, 3], 
      state: 3
    }, 
    {
      pos: [5, 11, 3], 
      state: 17
    }, 
    {
      pos: [6, 11, 3], 
      state: 3
    }, 
    {
      pos: [7, 11, 3], 
      state: 3
    }, 
    {
      pos: [8, 11, 3], 
      state: 3
    }, 
    {
      pos: [9, 11, 3], 
      state: 3
    }, 
    {
      pos: [10, 11, 3], 
      state: 3
    }, 
    {
      pos: [0, 11, 4], 
      state: 3
    }, 
    {
      pos: [1, 11, 4], 
      state: 3
    }, 
    {
      pos: [2, 11, 4], 
      state: 3
    }, 
    {
      pos: [3, 11, 4], 
      state: 3
    }, 
    {
      pos: [4, 11, 4], 
      state: 3
    }, 
    {
      pos: [6, 11, 4], 
      state: 3
    }, 
    {
      pos: [7, 11, 4], 
      state: 3
    }, 
    {
      pos: [8, 11, 4], 
      state: 3
    }, 
    {
      pos: [9, 11, 4], 
      state: 3
    }, 
    {
      pos: [10, 11, 4], 
      state: 3
    }, 
    {
      pos: [0, 11, 5], 
      state: 3
    }, 
    {
      pos: [1, 11, 5], 
      state: 3
    }, 
    {
      pos: [2, 11, 5], 
      state: 3
    }, 
    {
      pos: [3, 11, 5], 
      state: 3
    }, 
    {
      pos: [4, 11, 5], 
      state: 3
    }, 
    {
      pos: [5, 11, 5], 
      state: 3
    }, 
    {
      pos: [6, 11, 5], 
      state: 3
    }, 
    {
      pos: [7, 11, 5], 
      state: 3
    }, 
    {
      pos: [8, 11, 5], 
      state: 3
    }, 
    {
      pos: [9, 11, 5], 
      state: 3
    }, 
    {
      pos: [10, 11, 5], 
      state: 3
    }, 
    {
      pos: [0, 11, 6], 
      state: 3
    }, 
    {
      pos: [1, 11, 6], 
      state: 3
    }, 
    {
      pos: [2, 11, 6], 
      state: 3
    }, 
    {
      pos: [3, 11, 6], 
      state: 3
    }, 
    {
      pos: [4, 11, 6], 
      state: 3
    }, 
    {
      pos: [5, 11, 6], 
      state: 3
    }, 
    {
      pos: [6, 11, 6], 
      state: 3
    }, 
    {
      pos: [7, 11, 6], 
      state: 3
    }, 
    {
      pos: [8, 11, 6], 
      state: 3
    }, 
    {
      pos: [9, 11, 6], 
      state: 3
    }, 
    {
      pos: [10, 11, 6], 
      state: 3
    }, 
    {
      pos: [0, 11, 7], 
      state: 3
    }, 
    {
      pos: [1, 11, 7], 
      state: 3
    }, 
    {
      pos: [2, 11, 7], 
      state: 3
    }, 
    {
      pos: [3, 11, 7], 
      state: 3
    }, 
    {
      pos: [4, 11, 7], 
      state: 3
    }, 
    {
      pos: [5, 11, 7], 
      state: 3
    }, 
    {
      pos: [6, 11, 7], 
      state: 3
    }, 
    {
      pos: [7, 11, 7], 
      state: 3
    }, 
    {
      pos: [8, 11, 7], 
      state: 3
    }, 
    {
      pos: [9, 11, 7], 
      state: 3
    }, 
    {
      pos: [0, 11, 8], 
      state: 3
    }, 
    {
      pos: [1, 11, 8], 
      state: 3
    }, 
    {
      pos: [2, 11, 8], 
      state: 3
    }, 
    {
      pos: [3, 11, 8], 
      state: 3
    }, 
    {
      pos: [4, 11, 8], 
      state: 3
    }, 
    {
      pos: [5, 11, 8], 
      state: 3
    }, 
    {
      pos: [6, 11, 8], 
      state: 3
    }, 
    {
      pos: [7, 11, 8], 
      state: 3
    }, 
    {
      pos: [8, 11, 8], 
      state: 3
    }, 
    {
      pos: [9, 11, 8], 
      state: 3
    }, 
    {
      pos: [0, 11, 9], 
      state: 3
    }, 
    {
      pos: [1, 11, 9], 
      state: 3
    }, 
    {
      pos: [2, 11, 9], 
      state: 3
    }, 
    {
      pos: [3, 11, 9], 
      state: 3
    }, 
    {
      pos: [4, 11, 9], 
      state: 3
    }, 
    {
      pos: [5, 11, 9], 
      state: 3
    }, 
    {
      pos: [6, 11, 9], 
      state: 3
    }, 
    {
      pos: [7, 11, 9], 
      state: 3
    }, 
    {
      pos: [8, 11, 9], 
      state: 3
    }, 
    {
      pos: [9, 11, 9], 
      state: 3
    }, 
    {
      pos: [0, 11, 10], 
      state: 3
    }, 
    {
      pos: [1, 11, 10], 
      state: 3
    }, 
    {
      pos: [2, 11, 10], 
      state: 3
    }, 
    {
      pos: [3, 11, 10], 
      state: 3
    }, 
    {
      pos: [4, 11, 10], 
      state: 3
    }, 
    {
      pos: [5, 11, 10], 
      state: 3
    }, 
    {
      pos: [6, 11, 10], 
      state: 3
    }, 
    {
      pos: [7, 11, 10], 
      state: 3
    }, 
    {
      pos: [8, 11, 10], 
      state: 3
    }, 
    {
      pos: [9, 11, 10], 
      state: 3
    }, 
    {
      pos: [0, 11, 11], 
      state: 3
    }, 
    {
      pos: [1, 11, 11], 
      state: 3
    }, 
    {
      pos: [2, 11, 11], 
      state: 3
    }, 
    {
      pos: [3, 11, 11], 
      state: 3
    }, 
    {
      pos: [4, 11, 11], 
      state: 3
    }, 
    {
      pos: [6, 11, 11], 
      state: 3
    }, 
    {
      pos: [7, 11, 11], 
      state: 3
    }, 
    {
      pos: [8, 11, 11], 
      state: 3
    }, 
    {
      pos: [9, 11, 11], 
      state: 3
    }, 
    {
      pos: [10, 11, 11], 
      state: 3
    }, 
    {
      pos: [0, 11, 12], 
      state: 3
    }, 
    {
      pos: [1, 11, 12], 
      state: 3
    }, 
    {
      pos: [2, 11, 12], 
      state: 3
    }, 
    {
      pos: [3, 11, 12], 
      state: 3
    }, 
    {
      pos: [4, 11, 12], 
      state: 3
    }, 
    {
      pos: [5, 11, 12], 
      state: 17
    }, 
    {
      pos: [6, 11, 12], 
      state: 3
    }, 
    {
      pos: [7, 11, 12], 
      state: 3
    }, 
    {
      pos: [8, 11, 12], 
      state: 3
    }, 
    {
      pos: [9, 11, 12], 
      state: 3
    }, 
    {
      pos: [10, 11, 12], 
      state: 3
    }, 
    {
      pos: [0, 11, 13], 
      state: 3
    }, 
    {
      pos: [1, 11, 13], 
      state: 3
    }, 
    {
      pos: [2, 11, 13], 
      state: 3
    }, 
    {
      pos: [3, 11, 13], 
      state: 3
    }, 
    {
      pos: [4, 11, 13], 
      state: 3
    }, 
    {
      pos: [6, 11, 13], 
      state: 3
    }, 
    {
      pos: [7, 11, 13], 
      state: 3
    }, 
    {
      pos: [8, 11, 13], 
      state: 3
    }, 
    {
      pos: [9, 11, 13], 
      state: 3
    }, 
    {
      pos: [10, 11, 13], 
      state: 3
    }, 
    {
      pos: [1, 11, 14], 
      state: 3
    }, 
    {
      pos: [2, 11, 14], 
      state: 3
    }, 
    {
      pos: [3, 11, 14], 
      state: 3
    }, 
    {
      pos: [4, 11, 14], 
      state: 3
    }, 
    {
      pos: [5, 11, 14], 
      state: 3
    }, 
    {
      pos: [6, 11, 14], 
      state: 3
    }, 
    {
      pos: [7, 11, 14], 
      state: 3
    }, 
    {
      pos: [8, 11, 14], 
      state: 3
    }, 
    {
      pos: [9, 11, 14], 
      state: 3
    }, 
    {
      pos: [4, 11, 15], 
      state: 3
    }, 
    {
      pos: [5, 11, 15], 
      state: 3
    }, 
    {
      pos: [7, 11, 15], 
      state: 3
    }, 
    {
      pos: [8, 11, 15], 
      state: 3
    }, 
    {
      pos: [5, 12, 2], 
      state: 1
    }, 
    {
      pos: [5, 12, 3], 
      state: 15
    }, 
    {
      pos: [5, 12, 4], 
      state: 6
    }, 
    {
      pos: [5, 12, 7], 
      state: 6
    }, 
    {
      pos: [5, 12, 8], 
      state: 6
    }, 
    {
      pos: [5, 12, 11], 
      state: 6
    }, 
    {
      pos: [5, 12, 12], 
      state: 15
    }, 
    {
      pos: [5, 12, 13], 
      state: 1
    }, 
    {
      pos: [3, 12, 0], 
      state: 3
    }, 
    {
      pos: [4, 12, 0], 
      state: 3
    }, 
    {
      pos: [5, 12, 0], 
      state: 3
    }, 
    {
      pos: [6, 12, 0], 
      state: 3
    }, 
    {
      pos: [7, 12, 0], 
      state: 3
    }, 
    {
      pos: [8, 12, 0], 
      state: 3
    }, 
    {
      pos: [2, 12, 1], 
      state: 3
    }, 
    {
      pos: [3, 12, 1], 
      state: 3
    }, 
    {
      pos: [4, 12, 1], 
      state: 3
    }, 
    {
      pos: [5, 12, 1], 
      state: 3
    }, 
    {
      pos: [6, 12, 1], 
      state: 3
    }, 
    {
      pos: [7, 12, 1], 
      state: 3
    }, 
    {
      pos: [8, 12, 1], 
      state: 3
    }, 
    {
      pos: [1, 12, 2], 
      state: 3
    }, 
    {
      pos: [2, 12, 2], 
      state: 3
    }, 
    {
      pos: [3, 12, 2], 
      state: 3
    }, 
    {
      pos: [4, 12, 2], 
      state: 3
    }, 
    {
      pos: [6, 12, 2], 
      state: 3
    }, 
    {
      pos: [7, 12, 2], 
      state: 3
    }, 
    {
      pos: [8, 12, 2], 
      state: 3
    }, 
    {
      pos: [9, 12, 2], 
      state: 3
    }, 
    {
      pos: [10, 12, 2], 
      state: 3
    }, 
    {
      pos: [0, 12, 3], 
      state: 3
    }, 
    {
      pos: [1, 12, 3], 
      state: 3
    }, 
    {
      pos: [2, 12, 3], 
      state: 3
    }, 
    {
      pos: [3, 12, 3], 
      state: 3
    }, 
    {
      pos: [4, 12, 3], 
      state: 3
    }, 
    {
      pos: [6, 12, 3], 
      state: 3
    }, 
    {
      pos: [7, 12, 3], 
      state: 3
    }, 
    {
      pos: [8, 12, 3], 
      state: 3
    }, 
    {
      pos: [9, 12, 3], 
      state: 3
    }, 
    {
      pos: [10, 12, 3], 
      state: 3
    }, 
    {
      pos: [0, 12, 4], 
      state: 3
    }, 
    {
      pos: [1, 12, 4], 
      state: 3
    }, 
    {
      pos: [2, 12, 4], 
      state: 3
    }, 
    {
      pos: [3, 12, 4], 
      state: 3
    }, 
    {
      pos: [4, 12, 4], 
      state: 3
    }, 
    {
      pos: [6, 12, 4], 
      state: 3
    }, 
    {
      pos: [7, 12, 4], 
      state: 3
    }, 
    {
      pos: [8, 12, 4], 
      state: 3
    }, 
    {
      pos: [9, 12, 4], 
      state: 3
    }, 
    {
      pos: [10, 12, 4], 
      state: 3
    }, 
    {
      pos: [0, 12, 5], 
      state: 3
    }, 
    {
      pos: [1, 12, 5], 
      state: 3
    }, 
    {
      pos: [2, 12, 5], 
      state: 3
    }, 
    {
      pos: [3, 12, 5], 
      state: 3
    }, 
    {
      pos: [4, 12, 5], 
      state: 3
    }, 
    {
      pos: [5, 12, 5], 
      state: 3
    }, 
    {
      pos: [6, 12, 5], 
      state: 3
    }, 
    {
      pos: [7, 12, 5], 
      state: 3
    }, 
    {
      pos: [8, 12, 5], 
      state: 3
    }, 
    {
      pos: [9, 12, 5], 
      state: 3
    }, 
    {
      pos: [0, 12, 6], 
      state: 3
    }, 
    {
      pos: [1, 12, 6], 
      state: 3
    }, 
    {
      pos: [2, 12, 6], 
      state: 3
    }, 
    {
      pos: [3, 12, 6], 
      state: 3
    }, 
    {
      pos: [4, 12, 6], 
      state: 3
    }, 
    {
      pos: [5, 12, 6], 
      state: 3
    }, 
    {
      pos: [6, 12, 6], 
      state: 3
    }, 
    {
      pos: [7, 12, 6], 
      state: 3
    }, 
    {
      pos: [8, 12, 6], 
      state: 3
    }, 
    {
      pos: [9, 12, 6], 
      state: 3
    }, 
    {
      pos: [10, 12, 6], 
      state: 3
    }, 
    {
      pos: [0, 12, 7], 
      state: 3
    }, 
    {
      pos: [1, 12, 7], 
      state: 3
    }, 
    {
      pos: [2, 12, 7], 
      state: 3
    }, 
    {
      pos: [3, 12, 7], 
      state: 3
    }, 
    {
      pos: [4, 12, 7], 
      state: 3
    }, 
    {
      pos: [6, 12, 7], 
      state: 3
    }, 
    {
      pos: [7, 12, 7], 
      state: 3
    }, 
    {
      pos: [8, 12, 7], 
      state: 3
    }, 
    {
      pos: [9, 12, 7], 
      state: 3
    }, 
    {
      pos: [10, 12, 7], 
      state: 3
    }, 
    {
      pos: [0, 12, 8], 
      state: 3
    }, 
    {
      pos: [1, 12, 8], 
      state: 3
    }, 
    {
      pos: [2, 12, 8], 
      state: 3
    }, 
    {
      pos: [3, 12, 8], 
      state: 3
    }, 
    {
      pos: [4, 12, 8], 
      state: 3
    }, 
    {
      pos: [6, 12, 8], 
      state: 3
    }, 
    {
      pos: [7, 12, 8], 
      state: 3
    }, 
    {
      pos: [8, 12, 8], 
      state: 3
    }, 
    {
      pos: [9, 12, 8], 
      state: 3
    }, 
    {
      pos: [10, 12, 8], 
      state: 3
    }, 
    {
      pos: [0, 12, 9], 
      state: 3
    }, 
    {
      pos: [1, 12, 9], 
      state: 3
    }, 
    {
      pos: [2, 12, 9], 
      state: 3
    }, 
    {
      pos: [3, 12, 9], 
      state: 3
    }, 
    {
      pos: [4, 12, 9], 
      state: 3
    }, 
    {
      pos: [5, 12, 9], 
      state: 3
    }, 
    {
      pos: [6, 12, 9], 
      state: 3
    }, 
    {
      pos: [7, 12, 9], 
      state: 3
    }, 
    {
      pos: [8, 12, 9], 
      state: 3
    }, 
    {
      pos: [9, 12, 9], 
      state: 3
    }, 
    {
      pos: [10, 12, 9], 
      state: 3
    }, 
    {
      pos: [0, 12, 10], 
      state: 3
    }, 
    {
      pos: [1, 12, 10], 
      state: 3
    }, 
    {
      pos: [2, 12, 10], 
      state: 3
    }, 
    {
      pos: [3, 12, 10], 
      state: 3
    }, 
    {
      pos: [4, 12, 10], 
      state: 3
    }, 
    {
      pos: [5, 12, 10], 
      state: 3
    }, 
    {
      pos: [6, 12, 10], 
      state: 3
    }, 
    {
      pos: [7, 12, 10], 
      state: 3
    }, 
    {
      pos: [8, 12, 10], 
      state: 3
    }, 
    {
      pos: [9, 12, 10], 
      state: 3
    }, 
    {
      pos: [10, 12, 10], 
      state: 3
    }, 
    {
      pos: [0, 12, 11], 
      state: 3
    }, 
    {
      pos: [1, 12, 11], 
      state: 3
    }, 
    {
      pos: [2, 12, 11], 
      state: 3
    }, 
    {
      pos: [3, 12, 11], 
      state: 3
    }, 
    {
      pos: [4, 12, 11], 
      state: 3
    }, 
    {
      pos: [6, 12, 11], 
      state: 3
    }, 
    {
      pos: [7, 12, 11], 
      state: 3
    }, 
    {
      pos: [8, 12, 11], 
      state: 3
    }, 
    {
