{
  size: [18, 15, 21], 
  entities: [], 
  blocks: [
    {
      pos: [0, 0, 7], 
      state: 0
    }, 
    {
      pos: [0, 0, 8], 
      state: 1
    }, 
    {
      pos: [0, 0, 9], 
      state: 1
    }, 
    {
      pos: [0, 0, 11], 
      state: 1
    }, 
    {
      pos: [0, 0, 12], 
      state: 1
    }, 
    {
      pos: [0, 0, 13], 
      state: 0
    }, 
    {
      pos: [1, 0, 7], 
      state: 0
    }, 
    {
      pos: [1, 0, 8], 
      state: 1
    }, 
    {
      pos: [1, 0, 9], 
      state: 1
    }, 
    {
      pos: [1, 0, 10], 
      state: 0
    }, 
    {
      pos: [1, 0, 11], 
      state: 1
    }, 
    {
      pos: [1, 0, 12], 
      state: 1
    }, 
    {
      pos: [1, 0, 13], 
      state: 0
    }, 
    {
      pos: [1, 0, 14], 
      state: 2
    }, 
    {
      pos: [2, 0, 7], 
      state: 0
    }, 
    {
      pos: [2, 0, 8], 
      state: 1
    }, 
    {
      pos: [2, 0, 9], 
      state: 1
    }, 
    {
      pos: [2, 0, 10], 
      state: 3
    }, 
    {
      pos: [2, 0, 11], 
      state: 1
    }, 
    {
      pos: [2, 0, 12], 
      state: 1
    }, 
    {
      pos: [2, 0, 13], 
      state: 0
    }, 
    {
      pos: [2, 0, 15], 
      state: 2
    }, 
    {
      pos: [3, 0, 7], 
      state: 0
    }, 
    {
      pos: [3, 0, 8], 
      state: 1
    }, 
    {
      pos: [3, 0, 9], 
      state: 1
    }, 
    {
      pos: [3, 0, 10], 
      state: 0
    }, 
    {
      pos: [3, 0, 11], 
      state: 1
    }, 
    {
      pos: [3, 0, 12], 
      state: 1
    }, 
    {
      pos: [3, 0, 13], 
      state: 0
    }, 
    {
      pos: [4, 0, 7], 
      state: 0
    }, 
    {
      pos: [4, 0, 8], 
      state: 1
    }, 
    {
      pos: [4, 0, 9], 
      state: 1
    }, 
    {
      pos: [4, 0, 10], 
      state: 0
    }, 
    {
      pos: [4, 0, 11], 
      state: 1
    }, 
    {
      pos: [4, 0, 12], 
      state: 1
    }, 
    {
      pos: [4, 0, 13], 
      state: 0
    }, 
    {
      pos: [5, 0, 7], 
      state: 0
    }, 
    {
      pos: [5, 0, 8], 
      state: 1
    }, 
    {
      pos: [5, 0, 9], 
      state: 1
    }, 
    {
      pos: [5, 0, 10], 
      state: 0
    }, 
    {
      pos: [5, 0, 11], 
      state: 1
    }, 
    {
      pos: [5, 0, 12], 
      state: 1
    }, 
    {
      pos: [5, 0, 13], 
      state: 0
    }, 
    {
      pos: [6, 0, 7], 
      state: 0
    }, 
    {
      pos: [6, 0, 9], 
      state: 1
    }, 
    {
      pos: [6, 0, 10], 
      state: 3
    }, 
    {
      pos: [6, 0, 11], 
      state: 1
    }, 
    {
      pos: [7, 0, 7], 
      state: 0
    }, 
    {
      pos: [7, 0, 8], 
      state: 1
    }, 
    {
      pos: [10, 0, 12], 
      state: 1
    }, 
    {
      pos: [10, 0, 13], 
      state: 0
    }, 
    {
      pos: [11, 0, 10], 
      state: 0
    }, 
    {
      pos: [11, 0, 12], 
      state: 1
    }, 
    {
      pos: [11, 0, 13], 
      state: 0
    }, 
    {
      pos: [11, 0, 14], 
      state: 0
    }, 
    {
      pos: [12, 0, 7], 
      state: 3
    }, 
    {
      pos: [12, 0, 8], 
      state: 1
    }, 
    {
      pos: [12, 0, 9], 
      state: 1
    }, 
    {
      pos: [12, 0, 10], 
      state: 1
    }, 
    {
      pos: [12, 0, 11], 
      state: 1
    }, 
    {
      pos: [12, 0, 12], 
      state: 1
    }, 
    {
      pos: [12, 0, 13], 
      state: 0
    }, 
    {
      pos: [13, 0, 7], 
      state: 0
    }, 
    {
      pos: [13, 0, 8], 
      state: 1
    }, 
    {
      pos: [13, 0, 9], 
      state: 1
    }, 
    {
      pos: [13, 0, 10], 
      state: 0
    }, 
    {
      pos: [13, 0, 11], 
      state: 1
    }, 
    {
      pos: [13, 0, 12], 
      state: 1
    }, 
    {
      pos: [13, 0, 13], 
      state: 0
    }, 
    {
      pos: [14, 0, 7], 
      state: 0
    }, 
    {
      pos: [14, 0, 8], 
      state: 1
    }, 
    {
      pos: [14, 0, 9], 
      state: 1
    }, 
    {
      pos: [14, 0, 10], 
      state: 0
    }, 
    {
      pos: [14, 0, 11], 
      state: 1
    }, 
    {
      pos: [14, 0, 12], 
      state: 1
    }, 
    {
      pos: [14, 0, 13], 
      state: 0
    }, 
    {
      pos: [15, 0, 7], 
      state: 0
    }, 
    {
      pos: [15, 0, 8], 
      state: 1
    }, 
    {
      pos: [15, 0, 9], 
      state: 1
    }, 
    {
      pos: [15, 0, 10], 
      state: 0
    }, 
    {
      pos: [15, 0, 11], 
      state: 1
    }, 
    {
      pos: [15, 0, 12], 
      state: 1
    }, 
    {
      pos: [15, 0, 13], 
      state: 0
    }, 
    {
      pos: [15, 0, 14], 
      state: 2
    }, 
    {
      pos: [16, 0, 7], 
      state: 0
    }, 
    {
      pos: [16, 0, 8], 
      state: 1
    }, 
    {
      pos: [16, 0, 9], 
      state: 1
    }, 
    {
      pos: [16, 0, 10], 
      state: 0
    }, 
    {
      pos: [16, 0, 11], 
      state: 1
    }, 
    {
      pos: [16, 0, 12], 
      state: 1
    }, 
    {
      pos: [16, 0, 13], 
      state: 0
    }, 
    {
      pos: [16, 0, 14], 
      state: 2
    }, 
    {
      pos: [17, 0, 7], 
      state: 0
    }, 
    {
      pos: [17, 0, 8], 
      state: 1
    }, 
    {
      pos: [17, 0, 9], 
      state: 1
    }, 
    {
      pos: [17, 0, 11], 
      state: 1
    }, 
    {
      pos: [17, 0, 12], 
      state: 1
    }, 
    {
      pos: [17, 0, 13], 
      state: 0
    }, 
    {
      pos: [0, 1, 7], 
      state: 2
    }, 
    {
      pos: [0, 1, 8], 
      state: 1
    }, 
    {
      pos: [0, 1, 9], 
      state: 1
    }, 
    {
      pos: [0, 1, 10], 
      state: 2
    }, 
    {
      pos: [0, 1, 11], 
      state: 1
    }, 
    {
      pos: [0, 1, 12], 
      state: 1
    }, 
    {
      pos: [0, 1, 13], 
      state: 2
    }, 
    {
      pos: [1, 1, 7], 
      state: 2
    }, 
    {
      pos: [1, 1, 8], 
      state: 1
    }, 
    {
      pos: [1, 1, 9], 
      state: 1
    }, 
    {
      pos: [1, 1, 10], 
      state: 2
    }, 
    {
      pos: [1, 1, 11], 
      state: 1
    }, 
    {
      pos: [1, 1, 12], 
      state: 1
    }, 
    {
      pos: [1, 1, 13], 
      state: 2
    }, 
    {
      pos: [2, 1, 7], 
      state: 2
    }, 
    {
      pos: [2, 1, 8], 
      state: 1
    }, 
    {
      pos: [2, 1, 9], 
      state: 1
    }, 
    {
      pos: [2, 1, 10], 
      state: 2
    }, 
    {
      pos: [2, 1, 11], 
      state: 1
    }, 
    {
      pos: [2, 1, 13], 
      state: 2
    }, 
    {
      pos: [3, 1, 7], 
      state: 2
    }, 
    {
      pos: [3, 1, 8], 
      state: 1
    }, 
    {
      pos: [3, 1, 9], 
      state: 1
    }, 
    {
      pos: [4, 1, 7], 
      state: 3
    }, 
    {
      pos: [4, 1, 8], 
      state: 1
    }, 
    {
      pos: [5, 1, 7], 
      state: 2
    }, 
    {
      pos: [5, 1, 8], 
      state: 1
    }, 
    {
      pos: [7, 1, 7], 
      state: 2
    }, 
    {
      pos: [11, 1, 11], 
      state: 1
    }, 
    {
      pos: [11, 1, 12], 
      state: 1
    }, 
    {
      pos: [11, 1, 13], 
      state: 2
    }, 
    {
      pos: [12, 1, 9], 
      state: 1
    }, 
    {
      pos: [12, 1, 10], 
      state: 1
    }, 
    {
      pos: [12, 1, 11], 
      state: 1
    }, 
    {
      pos: [12, 1, 12], 
      state: 1
    }, 
    {
      pos: [12, 1, 13], 
      state: 2
    }, 
    {
      pos: [13, 1, 7], 
      state: 2
    }, 
    {
      pos: [13, 1, 8], 
      state: 1
    }, 
    {
      pos: [13, 1, 9], 
      state: 1
    }, 
    {
      pos: [13, 1, 10], 
      state: 2
    }, 
    {
      pos: [13, 1, 11], 
      state: 1
    }, 
    {
      pos: [13, 1, 12], 
      state: 1
    }, 
    {
      pos: [13, 1, 13], 
      state: 2
    }, 
    {
      pos: [14, 1, 7], 
      state: 2
    }, 
    {
      pos: [14, 1, 8], 
      state: 1
    }, 
    {
      pos: [14, 1, 9], 
      state: 1
    }, 
    {
      pos: [14, 1, 10], 
      state: 2
    }, 
    {
      pos: [14, 1, 11], 
      state: 1
    }, 
    {
      pos: [14, 1, 12], 
      state: 1
    }, 
    {
      pos: [14, 1, 13], 
      state: 2
    }, 
    {
      pos: [15, 1, 7], 
      state: 2
    }, 
    {
      pos: [15, 1, 8], 
      state: 1
    }, 
    {
      pos: [15, 1, 9], 
      state: 1
    }, 
    {
      pos: [15, 1, 10], 
      state: 2
    }, 
    {
      pos: [15, 1, 11], 
      state: 1
    }, 
    {
      pos: [15, 1, 12], 
      state: 1
    }, 
    {
      pos: [15, 1, 13], 
      state: 2
    }, 
    {
      pos: [16, 1, 7], 
      state: 2
    }, 
    {
      pos: [16, 1, 8], 
      state: 1
    }, 
    {
      pos: [16, 1, 9], 
      state: 1
    }, 
    {
      pos: [16, 1, 10], 
      state: 2
    }, 
    {
      pos: [16, 1, 11], 
      state: 1
    }, 
    {
      pos: [16, 1, 12], 
      state: 1
    }, 
    {
      pos: [16, 1, 13], 
      state: 2
    }, 
    {
      pos: [17, 1, 7], 
      state: 2
    }, 
    {
      pos: [17, 1, 8], 
      state: 1
    }, 
    {
      pos: [17, 1, 9], 
      state: 1
    }, 
    {
      pos: [17, 1, 10], 
      state: 2
    }, 
    {
      pos: [17, 1, 11], 
      state: 1
    }, 
    {
      pos: [17, 1, 12], 
      state: 1
    }, 
    {
      pos: [17, 1, 13], 
      state: 2
    }, 
    {
      pos: [0, 2, 10], 
      state: 0
    }, 
    {
      pos: [1, 2, 7], 
      state: 4
    }, 
    {
      pos: [1, 2, 10], 
      state: 0
    }, 
    {
      pos: [1, 2, 13], 
      state: 4
    }, 
    {
      pos: [2, 2, 10], 
      state: 0
    }, 
    {
      pos: [3, 2, 10], 
      state: 3
    }, 
    {
      pos: [5, 2, 7], 
      state: 2
    }, 
    {
      pos: [7, 2, 7], 
      state: 4
    }, 
    {
      pos: [13, 2, 7], 
      state: 4
    }, 
    {
      pos: [13, 2, 10], 
      state: 0
    }, 
    {
      pos: [14, 2, 10], 
      state: 0
    }, 
    {
      pos: [15, 2, 7], 
      state: 2
    }, 
    {
      pos: [15, 2, 10], 
      state: 3
    }, 
    {
      pos: [15, 2, 13], 
      state: 2
    }, 
    {
      pos: [16, 2, 10], 
      state: 0
    }, 
    {
      pos: [17, 2, 7], 
      state: 2
    }, 
    {
      pos: [17, 2, 10], 
      state: 3
    }, 
    {
      pos: [17, 2, 13], 
      state: 2
    }, 
    {
      pos: [0, 3, 10], 
      state: 2
    }, 
    {
      pos: [1, 3, 7], 
      state: 4
    }, 
    {
      pos: [1, 3, 10], 
      state: 2
    }, 
    {
      pos: [2, 3, 10], 
      state: 2
    }, 
    {
      pos: [3, 3, 10], 
      state: 0
    }, 
    {
      pos: [7, 3, 7], 
      state: 4
    }, 
    {
      pos: [13, 3, 7], 
      state: 4
    }, 
    {
      pos: [15, 3, 10], 
      state: 0
    }, 
    {
      pos: [16, 3, 10], 
      state: 4
    }, 
    {
      pos: [17, 3, 10], 
      state: 0
    }, 
    {
      pos: [0, 4, 10], 
      state: 0
    }, 
    {
      pos: [1, 4, 7], 
      state: 4
    }, 
    {
      pos: [1, 4, 10], 
      state: 0
    }, 
    {
      pos: [7, 4, 7], 
      state: 4
    }, 
    {
      pos: [13, 4, 7], 
      state: 4
    }, 
    {
      pos: [16, 4, 10], 
      state: 0
    }, 
    {
      pos: [17, 4, 10], 
      state: 3
    }, 
    {
      pos: [0, 5, 7], 
      state: 2
    }, 
    {
      pos: [0, 5, 8], 
      state: 1
    }, 
    {
      pos: [0, 5, 9], 
      state: 1
    }, 
    {
      pos: [0, 5, 10], 
      state: 2
    }, 
    {
      pos: [1, 5, 7], 
      state: 2
    }, 
    {
      pos: [1, 5, 8], 
      state: 1
    }, 
    {
      pos: [1, 5, 9], 
      state: 1
    }, 
    {
      pos: [1, 5, 10], 
      state: 2
    }, 
    {
      pos: [2, 5, 9], 
      state: 5
    }, 
    {
      pos: [3, 5, 9], 
      state: 5
    }, 
    {
      pos: [4, 5, 9], 
      state: 5
    }, 
    {
      pos: [5, 5, 9], 
      state: 5
    }, 
    {
      pos: [6, 5, 7], 
      state: 2
    }, 
    {
      pos: [7, 5, 7], 
      state: 2
    }, 
    {
      pos: [10, 5, 9], 
      state: 5
    }, 
    {
      pos: [11, 5, 9], 
      state: 5
    }, 
    {
      pos: [12, 5, 6], 
      state: 2
    }, 
    {
      pos: [12, 5, 7], 
      state: 2
    }, 
    {
      pos: [12, 5, 9], 
      state: 5
    }, 
    {
      pos: [13, 5, 6], 
      state: 2
    }, 
    {
      pos: [13, 5, 7], 
      state: 2
    }, 
    {
      pos: [13, 5, 9], 
      state: 5
    }, 
    {
      pos: [14, 5, 6], 
      state: 2
    }, 
    {
      pos: [14, 5, 7], 
      state: 2
    }, 
    {
      pos: [14, 5, 9], 
      state: 5
    }, 
    {
      pos: [15, 5, 9], 
      state: 5
    }, 
    {
      pos: [16, 5, 9], 
      state: 1
    }, 
    {
      pos: [17, 5, 6], 
      state: 2
    }, 
    {
      pos: [17, 5, 7], 
      state: 2
    }, 
    {
      pos: [17, 5, 8], 
      state: 1
    }, 
    {
      pos: [17, 5, 9], 
      state: 1
    }, 
    {
      pos: [17, 5, 10], 
      state: 2
    }, 
    {
      pos: [0, 6, 10], 
      state: 3
    }, 
    {
      pos: [1, 6, 7], 
      state: 2
    }, 
    {
      pos: [7, 6, 7], 
      state: 2
    }, 
    {
      pos: [13, 6, 7], 
      state: 2
    }, 
    {
      pos: [17, 6, 7], 
      state: 2
    }, 
    {
      pos: [4, 0, 14], 
      state: 6
    }, 
    {
      pos: [5, 0, 14], 
      state: 6
    }, 
    {
      pos: [11, 0, 15], 
      state: 7
    }, 
    {
      pos: [12, 0, 14], 
      state: 6
    }, 
    {
      pos: [12, 1, 7], 
      state: 8
    }, 
    {
      pos: [4, 2, 7], 
      state: 8
    }, 
    {
      pos: [2, 6, 9], 
      state: 9
    }, 
    {
      pos: [3, 6, 9], 
      state: 9
    }, 
    {
      pos: [4, 6, 9], 
      state: 9
    }, 
    {
      pos: [5, 6, 9], 
      state: 9
    }, 
    {
      pos: [10, 6, 9], 
      state: 9
    }, 
    {
      pos: [11, 6, 9], 
      state: 9
    }, 
    {
      pos: [12, 6, 9], 
      state: 9
    }, 
    {
      pos: [13, 6, 9], 
      state: 9
    }, 
    {
      pos: [14, 6, 9], 
      state: 9
    }, 
    {
      pos: [15, 6, 9], 
      state: 9
    }, 
    {
      pos: [0, 7, 10], 
      state: 8
    }, 
    {
      nbt: {
        final_state: "minecraft:deepslate_tiles", 
        name: "minecraft:connect_wall", 
        pool: "minecraft:ancient_city/walls", 
        joint: "rollable", 
        id: "minecraft:jigsaw", 
        target: "minecraft:connect_wall"
      }, 
      pos: [0, 0, 10], 
      state: 10
    }, 
    {
      nbt: {
        final_state: "minecraft:structure_void", 
        name: "minecraft:empty", 
        pool: "minecraft:ancient_city/structures", 
        joint: "rollable", 
        id: "minecraft:jigsaw", 
        target: "minecraft:connect_structure"
      }, 
      pos: [6, 0, 20], 
      state: 11
    }, 
    {
      nbt: {
        final_state: "minecraft:structure_void", 
        name: "minecraft:empty", 
        pool: "minecraft:ancient_city/structures", 
        joint: "rollable", 
        id: "minecraft:jigsaw", 
        target: "minecraft:connect_structure"
      }, 
      pos: [9, 0, 0], 
      state: 12
    }, 
    {
      nbt: {
        final_state: "minecraft:structure_void", 
        name: "minecraft:empty", 
        pool: "minecraft:ancient_city/structures", 
        joint: "rollable", 
        id: "minecraft:jigsaw", 
        target: "minecraft:connect_structure"
      }, 
      pos: [9, 0, 20], 
      state: 11
    }, 
    {
      nbt: {
        final_state: "minecraft:deepslate_tiles", 
        name: "minecraft:connect_wall", 
        pool: "minecraft:ancient_city/walls", 
        joint: "rollable", 
        id: "minecraft:jigsaw", 
        target: "minecraft:connect_wall"
      }, 
      pos: [17, 0, 10], 
      state: 13
    }
  ], 
  palette: [
    {
      Name: "minecraft:deepslate_tiles"
    }, 
    {
      Name: "minecraft:gray_wool"
    }, 
    {
      Name: "minecraft:deepslate_bricks"
    }, 
    {
      Name: "minecraft:chiseled_deepslate"
    }, 
    {
      Name: "minecraft:polished_deepslate"
    }, 
    {
      Name: "minecraft:dark_oak_planks"
    }, 
    {
      Properties: {
        waterlogged: "false", 
        type: "bottom"
      }, 
      Name: "minecraft:deepslate_tile_slab"
    }, 
    {
      Properties: {
        half: "bottom", 
        waterlogged: "false", 
        shape: "straight", 
        facing: "north"
      }, 
      Name: "minecraft:deepslate_tile_stairs"
    }, 
    {
      Properties: {
        waterlogged: "false", 
        hanging: "false"
      }, 
      Name: "minecraft:soul_lantern"
    }, 
    {
      Name: "minecraft:cyan_carpet"
    }, 
    {
      Properties: {
        orientation: "west_up"
      }, 
      Name: "minecraft:jigsaw"
    }, 
    {
      Properties: {
        orientation: "south_up"
      }, 
      Name: "minecraft:jigsaw"
    }, 
    {
      Properties: {
        orientation: "north_up"
      }, 
      Name: "minecraft:jigsaw"
    }, 
    {
      Properties: {
        orientation: "east_up"
      }, 
      Name: "minecraft:jigsaw"
    }
  ]
}
