{
  size: [18, 15, 21], 
  entities: [], 
  blocks: [
    {
      pos: [0, 0, 7], 
      state: 0
    }, 
    {
      pos: [0, 0, 8], 
      state: 1
    }, 
    {
      pos: [0, 0, 9], 
      state: 1
    }, 
    {
      pos: [0, 0, 11], 
      state: 1
    }, 
    {
      pos: [0, 0, 12], 
      state: 1
    }, 
    {
      pos: [0, 0, 13], 
      state: 0
    }, 
    {
      pos: [1, 0, 7], 
      state: 0
    }, 
    {
      pos: [1, 0, 8], 
      state: 1
    }, 
    {
      pos: [1, 0, 9], 
      state: 1
    }, 
    {
      pos: [1, 0, 10], 
      state: 0
    }, 
    {
      pos: [1, 0, 11], 
      state: 1
    }, 
    {
      pos: [1, 0, 12], 
      state: 1
    }, 
    {
      pos: [1, 0, 13], 
      state: 0
    }, 
    {
      pos: [1, 0, 15], 
      state: 2
    }, 
    {
      pos: [1, 0, 16], 
      state: 2
    }, 
    {
      pos: [2, 0, 7], 
      state: 0
    }, 
    {
      pos: [2, 0, 8], 
      state: 1
    }, 
    {
      pos: [2, 0, 9], 
      state: 1
    }, 
    {
      pos: [2, 0, 10], 
      state: 3
    }, 
    {
      pos: [2, 0, 11], 
      state: 1
    }, 
    {
      pos: [2, 0, 12], 
      state: 1
    }, 
    {
      pos: [2, 0, 13], 
      state: 0
    }, 
    {
      pos: [3, 0, 4], 
      state: 2
    }, 
    {
      pos: [3, 0, 5], 
      state: 2
    }, 
    {
      pos: [3, 0, 7], 
      state: 0
    }, 
    {
      pos: [3, 0, 10], 
      state: 0
    }, 
    {
      pos: [3, 0, 11], 
      state: 1
    }, 
    {
      pos: [3, 0, 12], 
      state: 1
    }, 
    {
      pos: [3, 0, 13], 
      state: 0
    }, 
    {
      pos: [3, 0, 15], 
      state: 2
    }, 
    {
      pos: [3, 0, 16], 
      state: 2
    }, 
    {
      pos: [4, 0, 10], 
      state: 0
    }, 
    {
      pos: [4, 0, 13], 
      state: 0
    }, 
    {
      pos: [5, 0, 5], 
      state: 2
    }, 
    {
      pos: [5, 0, 13], 
      state: 0
    }, 
    {
      pos: [5, 0, 15], 
      state: 2
    }, 
    {
      pos: [5, 0, 16], 
      state: 2
    }, 
    {
      pos: [6, 0, 13], 
      state: 0
    }, 
    {
      pos: [7, 0, 13], 
      state: 0
    }, 
    {
      pos: [7, 0, 15], 
      state: 2
    }, 
    {
      pos: [7, 0, 16], 
      state: 2
    }, 
    {
      pos: [9, 0, 14], 
      state: 0
    }, 
    {
      pos: [13, 0, 4], 
      state: 2
    }, 
    {
      pos: [13, 0, 5], 
      state: 2
    }, 
    {
      pos: [13, 0, 16], 
      state: 2
    }, 
    {
      pos: [15, 0, 4], 
      state: 2
    }, 
    {
      pos: [15, 0, 5], 
      state: 2
    }, 
    {
      pos: [15, 0, 15], 
      state: 2
    }, 
    {
      pos: [15, 0, 16], 
      state: 2
    }, 
    {
      pos: [16, 0, 13], 
      state: 0
    }, 
    {
      pos: [17, 0, 7], 
      state: 0
    }, 
    {
      pos: [17, 0, 13], 
      state: 0
    }, 
    {
      pos: [0, 1, 7], 
      state: 2
    }, 
    {
      pos: [0, 1, 8], 
      state: 1
    }, 
    {
      pos: [0, 1, 9], 
      state: 1
    }, 
    {
      pos: [0, 1, 10], 
      state: 2
    }, 
    {
      pos: [0, 1, 11], 
      state: 1
    }, 
    {
      pos: [0, 1, 12], 
      state: 1
    }, 
    {
      pos: [0, 1, 13], 
      state: 2
    }, 
    {
      pos: [1, 1, 7], 
      state: 2
    }, 
    {
      pos: [1, 1, 8], 
      state: 1
    }, 
    {
      pos: [1, 1, 9], 
      state: 1
    }, 
    {
      pos: [1, 1, 10], 
      state: 2
    }, 
    {
      pos: [1, 1, 11], 
      state: 1
    }, 
    {
      pos: [1, 1, 12], 
      state: 1
    }, 
    {
      pos: [1, 1, 13], 
      state: 2
    }, 
    {
      pos: [2, 1, 7], 
      state: 2
    }, 
    {
      pos: [2, 1, 8], 
      state: 1
    }, 
    {
      pos: [2, 1, 10], 
      state: 2
    }, 
    {
      pos: [2, 1, 11], 
      state: 1
    }, 
    {
      pos: [2, 1, 12], 
      state: 1
    }, 
    {
      pos: [2, 1, 13], 
      state: 2
    }, 
    {
      pos: [3, 1, 7], 
      state: 2
    }, 
    {
      pos: [3, 1, 10], 
      state: 2
    }, 
    {
      pos: [3, 1, 11], 
      state: 1
    }, 
    {
      pos: [3, 1, 13], 
      state: 2
    }, 
    {
      pos: [4, 1, 13], 
      state: 2
    }, 
    {
      pos: [5, 1, 13], 
      state: 2
    }, 
    {
      pos: [16, 1, 13], 
      state: 2
    }, 
    {
      pos: [17, 1, 7], 
      state: 2
    }, 
    {
      pos: [17, 1, 13], 
      state: 2
    }, 
    {
      pos: [0, 2, 10], 
      state: 0
    }, 
    {
      pos: [1, 2, 7], 
      state: 4
    }, 
    {
      pos: [1, 2, 10], 
      state: 0
    }, 
    {
      pos: [1, 2, 13], 
      state: 4
    }, 
    {
      pos: [2, 2, 10], 
      state: 0
    }, 
    {
      pos: [3, 2, 10], 
      state: 3
    }, 
    {
      pos: [3, 2, 13], 
      state: 2
    }, 
    {
      pos: [5, 2, 13], 
      state: 2
    }, 
    {
      pos: [17, 2, 13], 
      state: 2
    }, 
    {
      pos: [0, 3, 10], 
      state: 2
    }, 
    {
      pos: [1, 3, 7], 
      state: 4
    }, 
    {
      pos: [1, 3, 10], 
      state: 2
    }, 
    {
      pos: [1, 3, 13], 
      state: 4
    }, 
    {
      pos: [2, 3, 10], 
      state: 2
    }, 
    {
      pos: [3, 3, 10], 
      state: 0
    }, 
    {
      pos: [0, 4, 10], 
      state: 0
    }, 
    {
      pos: [1, 4, 7], 
      state: 4
    }, 
    {
      pos: [1, 4, 10], 
      state: 0
    }, 
    {
      pos: [1, 4, 13], 
      state: 4
    }, 
    {
      pos: [2, 4, 10], 
      state: 0
    }, 
    {
      pos: [0, 5, 6], 
      state: 2
    }, 
    {
      pos: [0, 5, 7], 
      state: 2
    }, 
    {
      pos: [0, 5, 8], 
      state: 1
    }, 
    {
      pos: [0, 5, 9], 
      state: 1
    }, 
    {
      pos: [0, 5, 10], 
      state: 2
    }, 
    {
      pos: [0, 5, 13], 
      state: 2
    }, 
    {
      pos: [0, 5, 14], 
      state: 2
    }, 
    {
      pos: [1, 5, 6], 
      state: 2
    }, 
    {
      pos: [1, 5, 7], 
      state: 2
    }, 
    {
      pos: [1, 5, 8], 
      state: 1
    }, 
    {
      pos: [1, 5, 9], 
      state: 1
    }, 
    {
      pos: [1, 5, 13], 
      state: 2
    }, 
    {
      pos: [1, 5, 14], 
      state: 2
    }, 
    {
      pos: [2, 5, 6], 
      state: 2
    }, 
    {
      pos: [2, 5, 7], 
      state: 2
    }, 
    {
      pos: [2, 5, 14], 
      state: 2
    }, 
    {
      pos: [3, 5, 6], 
      state: 2
    }, 
    {
      pos: [3, 5, 7], 
      state: 2
    }, 
    {
      pos: [3, 5, 14], 
      state: 2
    }, 
    {
      pos: [4, 5, 6], 
      state: 2
    }, 
    {
      pos: [4, 5, 7], 
      state: 2
    }, 
    {
      pos: [5, 5, 6], 
      state: 2
    }, 
    {
      pos: [1, 6, 7], 
      state: 2
    }, 
    {
      pos: [3, 6, 7], 
      state: 2
    }, 
    {
      pos: [0, 0, 3], 
      state: 5
    }, 
    {
      pos: [0, 0, 4], 
      state: 5
    }, 
    {
      pos: [0, 0, 5], 
      state: 5
    }, 
    {
      pos: [0, 0, 6], 
      state: 5
    }, 
    {
      pos: [0, 0, 14], 
      state: 5
    }, 
    {
      pos: [0, 0, 15], 
      state: 5
    }, 
    {
      pos: [0, 0, 16], 
      state: 5
    }, 
    {
      pos: [0, 0, 17], 
      state: 5
    }, 
    {
      pos: [1, 0, 2], 
      state: 5
    }, 
    {
      pos: [1, 0, 3], 
      state: 5
    }, 
    {
      pos: [1, 0, 4], 
      state: 5
    }, 
    {
      pos: [1, 0, 5], 
      state: 5
    }, 
    {
      pos: [1, 0, 6], 
      state: 5
    }, 
    {
      pos: [1, 0, 14], 
      state: 5
    }, 
    {
      pos: [1, 0, 17], 
      state: 5
    }, 
    {
      pos: [1, 0, 18], 
      state: 5
    }, 
    {
      pos: [2, 0, 2], 
      state: 5
    }, 
    {
      pos: [2, 0, 3], 
      state: 5
    }, 
    {
      pos: [2, 0, 4], 
      state: 5
    }, 
    {
      pos: [2, 0, 5], 
      state: 5
    }, 
    {
      pos: [2, 0, 6], 
      state: 5
    }, 
    {
      pos: [2, 0, 14], 
      state: 5
    }, 
    {
      pos: [2, 0, 15], 
      state: 5
    }, 
    {
      pos: [2, 0, 16], 
      state: 5
    }, 
    {
      pos: [2, 0, 17], 
      state: 5
    }, 
    {
      pos: [2, 0, 18], 
      state: 5
    }, 
    {
      pos: [3, 0, 2], 
      state: 5
    }, 
    {
      pos: [3, 0, 3], 
      state: 5
    }, 
    {
      pos: [3, 0, 6], 
      state: 5
    }, 
    {
      pos: [3, 0, 14], 
      state: 5
    }, 
    {
      pos: [3, 0, 17], 
      state: 5
    }, 
    {
      pos: [3, 0, 18], 
      state: 5
    }, 
    {
      pos: [4, 0, 2], 
      state: 5
    }, 
    {
      pos: [4, 0, 3], 
      state: 5
    }, 
    {
      pos: [4, 0, 4], 
      state: 5
    }, 
    {
      pos: [4, 0, 5], 
      state: 5
    }, 
    {
      pos: [4, 0, 6], 
      state: 5
    }, 
    {
      pos: [4, 0, 14], 
      state: 5
    }, 
    {
      pos: [4, 0, 15], 
      state: 5
    }, 
    {
      pos: [4, 0, 16], 
      state: 5
    }, 
    {
      pos: [4, 0, 17], 
      state: 5
    }, 
    {
      pos: [4, 0, 18], 
      state: 5
    }, 
    {
      pos: [5, 0, 2], 
      state: 5
    }, 
    {
      pos: [5, 0, 6], 
      state: 5
    }, 
    {
      pos: [5, 0, 14], 
      state: 5
    }, 
    {
      pos: [5, 0, 17], 
      state: 5
    }, 
    {
      pos: [5, 0, 18], 
      state: 5
    }, 
    {
      pos: [6, 0, 14], 
      state: 5
    }, 
    {
      pos: [6, 0, 15], 
      state: 5
    }, 
    {
      pos: [6, 0, 16], 
      state: 5
    }, 
    {
      pos: [6, 0, 17], 
      state: 5
    }, 
    {
      pos: [6, 0, 18], 
      state: 5
    }, 
    {
      pos: [7, 0, 14], 
      state: 5
    }, 
    {
      pos: [7, 0, 17], 
      state: 5
    }, 
    {
      pos: [7, 0, 18], 
      state: 5
    }, 
    {
      pos: [8, 0, 14], 
      state: 5
    }, 
    {
      pos: [8, 0, 15], 
      state: 5
    }, 
    {
      pos: [8, 0, 16], 
      state: 5
    }, 
    {
      pos: [8, 0, 17], 
      state: 5
    }, 
    {
      pos: [8, 0, 18], 
      state: 5
    }, 
    {
      pos: [9, 0, 2], 
      state: 5
    }, 
    {
      pos: [9, 0, 3], 
      state: 6
    }, 
    {
      pos: [9, 0, 4], 
      state: 6
    }, 
    {
      pos: [9, 0, 5], 
      state: 6
    }, 
    {
      pos: [9, 0, 6], 
      state: 7
    }, 
    {
      pos: [9, 0, 15], 
      state: 8
    }, 
    {
      pos: [9, 0, 16], 
      state: 6
    }, 
    {
      pos: [9, 0, 17], 
      state: 6
    }, 
    {
      pos: [9, 0, 18], 
      state: 5
    }, 
    {
      pos: [10, 0, 2], 
      state: 5
    }, 
    {
      pos: [10, 0, 3], 
      state: 6
    }, 
    {
      pos: [10, 0, 4], 
      state: 6
    }, 
    {
      pos: [10, 0, 5], 
      state: 6
    }, 
    {
      pos: [10, 0, 15], 
      state: 8
    }, 
    {
      pos: [10, 0, 16], 
      state: 6
    }, 
    {
      pos: [10, 0, 17], 
      state: 6
    }, 
    {
      pos: [10, 0, 18], 
      state: 5
    }, 
    {
      pos: [11, 0, 2], 
      state: 5
    }, 
    {
      pos: [11, 0, 3], 
      state: 6
    }, 
    {
      pos: [11, 0, 4], 
      state: 6
    }, 
    {
      pos: [11, 0, 5], 
      state: 6
    }, 
    {
      pos: [11, 0, 6], 
      state: 7
    }, 
    {
      pos: [11, 0, 15], 
      state: 8
    }, 
    {
      pos: [11, 0, 16], 
      state: 6
    }, 
    {
      pos: [11, 0, 17], 
      state: 6
    }, 
    {
      pos: [11, 0, 18], 
      state: 5
    }, 
    {
      pos: [12, 0, 2], 
      state: 5
    }, 
    {
      pos: [12, 0, 3], 
      state: 5
    }, 
    {
      pos: [12, 0, 4], 
      state: 5
    }, 
    {
      pos: [12, 0, 5], 
      state: 5
    }, 
    {
      pos: [12, 0, 6], 
      state: 5
    }, 
    {
      pos: [12, 0, 15], 
      state: 5
    }, 
    {
      pos: [12, 0, 16], 
      state: 5
    }, 
    {
      pos: [12, 0, 17], 
      state: 5
    }, 
    {
      pos: [12, 0, 18], 
      state: 5
    }, 
    {
      pos: [13, 0, 2], 
      state: 5
    }, 
    {
      pos: [13, 0, 3], 
      state: 5
    }, 
    {
      pos: [13, 0, 6], 
      state: 5
    }, 
    {
      pos: [13, 0, 17], 
      state: 5
    }, 
    {
      pos: [13, 0, 18], 
      state: 5
    }, 
    {
      pos: [14, 0, 2], 
      state: 5
    }, 
    {
      pos: [14, 0, 3], 
      state: 5
    }, 
    {
      pos: [14, 0, 4], 
      state: 5
    }, 
    {
      pos: [14, 0, 5], 
      state: 5
    }, 
    {
      pos: [14, 0, 15], 
      state: 5
    }, 
    {
      pos: [14, 0, 16], 
      state: 5
    }, 
    {
      pos: [14, 0, 17], 
      state: 5
    }, 
    {
      pos: [14, 0, 18], 
      state: 5
    }, 
    {
      pos: [15, 0, 2], 
      state: 5
    }, 
    {
      pos: [15, 0, 3], 
      state: 5
    }, 
    {
      pos: [15, 0, 14], 
      state: 5
    }, 
    {
      pos: [15, 0, 17], 
      state: 5
    }, 
    {
      pos: [15, 0, 18], 
      state: 5
    }, 
    {
      pos: [16, 0, 2], 
      state: 5
    }, 
    {
      pos: [16, 0, 3], 
      state: 5
    }, 
    {
      pos: [16, 0, 4], 
      state: 5
    }, 
    {
      pos: [16, 0, 5], 
      state: 5
    }, 
    {
      pos: [16, 0, 6], 
      state: 5
    }, 
    {
      pos: [16, 0, 14], 
      state: 5
    }, 
    {
      pos: [16, 0, 15], 
      state: 5
    }, 
    {
      pos: [16, 0, 16], 
      state: 5
    }, 
    {
      pos: [16, 0, 17], 
      state: 5
    }, 
    {
      pos: [16, 0, 18], 
      state: 5
    }, 
    {
      pos: [17, 0, 3], 
      state: 5
    }, 
    {
      pos: [17, 0, 4], 
      state: 5
    }, 
    {
      pos: [17, 0, 5], 
      state: 5
    }, 
    {
      pos: [17, 0, 6], 
      state: 5
    }, 
    {
      pos: [17, 0, 14], 
      state: 5
    }, 
    {
      pos: [17, 0, 15], 
      state: 5
    }, 
    {
      pos: [17, 0, 16], 
      state: 5
    }, 
    {
      pos: [17, 0, 17], 
      state: 5
    }, 
    {
      pos: [9, 1, 14], 
      state: 8
    }, 
    {
      nbt: {
        joint: "rollable", 
        final_state: "minecraft:deepslate_tiles", 
        name: "minecraft:connect_wall", 
        pool: "minecraft:ancient_city/walls", 
        id: "minecraft:jigsaw", 
        target: "minecraft:connect_wall"
      }, 
      pos: [0, 0, 10], 
      state: 9
    }, 
    {
      nbt: {
        joint: "rollable", 
        final_state: "minecraft:structure_void", 
        name: "minecraft:empty", 
        pool: "minecraft:ancient_city/structures", 
        id: "minecraft:jigsaw", 
        target: "minecraft:connect_structure"
      }, 
      pos: [9, 0, 0], 
      state: 10
    }, 
    {
      nbt: {
        joint: "rollable", 
        final_state: "minecraft:deepslate_tile_slab", 
        name: "minecraft:empty", 
        pool: "minecraft:ancient_city/structures", 
        id: "minecraft:jigsaw", 
        target: "minecraft:connect_structure"
      }, 
      pos: [9, 0, 20], 
      state: 11
    }, 
    {
      nbt: {
        joint: "rollable", 
        final_state: "minecraft:deepslate_tiles", 
        name: "minecraft:connect_wall", 
        pool: "minecraft:ancient_city/walls", 
        id: "minecraft:jigsaw", 
        target: "minecraft:connect_wall"
      }, 
      pos: [17, 0, 10], 
      state: 12
    }
  ], 
  palette: [
    {
      Name: "minecraft:deepslate_tiles"
    }, 
    {
      Name: "minecraft:gray_wool"
    }, 
    {
      Name: "minecraft:deepslate_bricks"
    }, 
    {
      Name: "minecraft:chiseled_deepslate"
    }, 
    {
      Name: "minecraft:polished_deepslate"
    }, 
    {
      Properties: {
        waterlogged: "false", 
        type: "bottom"
      }, 
      Name: "minecraft:deepslate_tile_slab"
    }, 
    {
      Properties: {
        waterlogged: "false", 
        type: "bottom"
      }, 
      Name: "minecraft:deepslate_brick_slab"
    }, 
    {
      Properties: {
        half: "bottom", 
        waterlogged: "false", 
        shape: "straight", 
        facing: "south"
      }, 
      Name: "minecraft:deepslate_brick_stairs"
    }, 
    {
      Properties: {
        half: "bottom", 
        waterlogged: "false", 
        shape: "straight", 
        facing: "north"
      }, 
      Name: "minecraft:deepslate_brick_stairs"
    }, 
    {
      Properties: {
        orientation: "west_up"
      }, 
      Name: "minecraft:jigsaw"
    }, 
    {
      Properties: {
        orientation: "north_up"
      }, 
      Name: "minecraft:jigsaw"
    }, 
    {
      Properties: {
        orientation: "south_up"
      }, 
      Name: "minecraft:jigsaw"
    }, 
    {
      Properties: {
        orientation: "east_up"
      }, 
      Name: "minecraft:jigsaw"
    }
  ]
}
