{
  size: [10, 6, 12], 
  entities: [], 
  blocks: [
    {
      pos: [0, 0, 0], 
      state: 0
    }, 
    {
      pos: [1, 0, 0], 
      state: 0
    }, 
    {
      pos: [2, 0, 0], 
      state: 0
    }, 
    {
      pos: [3, 0, 0], 
      state: 0
    }, 
    {
      pos: [4, 0, 0], 
      state: 0
    }, 
    {
      pos: [5, 0, 0], 
      state: 0
    }, 
    {
      pos: [6, 0, 0], 
      state: 0
    }, 
    {
      pos: [7, 0, 0], 
      state: 0
    }, 
    {
      pos: [8, 0, 0], 
      state: 0
    }, 
    {
      pos: [9, 0, 0], 
      state: 0
    }, 
    {
      pos: [1, 1, 0], 
      state: 1
    }, 
    {
      pos: [2, 1, 0], 
      state: 1
    }, 
    {
      pos: [3, 1, 0], 
      state: 1
    }, 
    {
      pos: [4, 1, 0], 
      state: 1
    }, 
    {
      pos: [5, 1, 0], 
      state: 1
    }, 
    {
      pos: [1, 2, 0], 
      state: 1
    }, 
    {
      pos: [2, 2, 0], 
      state: 1
    }, 
    {
      pos: [4, 2, 0], 
      state: 1
    }, 
    {
      pos: [5, 2, 0], 
      state: 1
    }, 
    {
      pos: [1, 3, 0], 
      state: 1
    }, 
    {
      pos: [2, 3, 0], 
      state: 1
    }, 
    {
      pos: [4, 3, 0], 
      state: 1
    }, 
    {
      pos: [5, 3, 0], 
      state: 1
    }, 
    {
      pos: [1, 4, 0], 
      state: 1
    }, 
    {
      pos: [0, 0, 1], 
      state: 0
    }, 
    {
      pos: [1, 0, 1], 
      state: 0
    }, 
    {
      pos: [2, 0, 1], 
      state: 1
    }, 
    {
      pos: [3, 0, 1], 
      state: 1
    }, 
    {
      pos: [4, 0, 1], 
      state: 1
    }, 
    {
      pos: [5, 0, 1], 
      state: 0
    }, 
    {
      pos: [6, 0, 1], 
      state: 0
    }, 
    {
      pos: [7, 0, 1], 
      state: 0
    }, 
    {
      pos: [8, 0, 1], 
      state: 0
    }, 
    {
      pos: [9, 0, 1], 
      state: 0
    }, 
    {
      pos: [5, 1, 1], 
      state: 1
    }, 
    {
      pos: [1, 4, 1], 
      state: 1
    }, 
    {
      pos: [2, 4, 1], 
      state: 1
    }, 
    {
      pos: [3, 4, 1], 
      state: 1
    }, 
    {
      pos: [4, 4, 1], 
      state: 1
    }, 
    {
      pos: [0, 0, 2], 
      state: 0
    }, 
    {
      pos: [1, 0, 2], 
      state: 0
    }, 
    {
      pos: [2, 0, 2], 
      state: 1
    }, 
    {
      pos: [3, 0, 2], 
      state: 1
    }, 
    {
      pos: [4, 0, 2], 
      state: 1
    }, 
    {
      pos: [5, 0, 2], 
      state: 0
    }, 
    {
      pos: [6, 0, 2], 
      state: 0
    }, 
    {
      pos: [7, 0, 2], 
      state: 0
    }, 
    {
      pos: [8, 0, 2], 
      state: 0
    }, 
    {
      pos: [9, 0, 2], 
      state: 0
    }, 
    {
      pos: [1, 1, 2], 
      state: 1
    }, 
    {
      pos: [5, 1, 2], 
      state: 1
    }, 
    {
      pos: [1, 2, 2], 
      state: 1
    }, 
    {
      pos: [5, 2, 2], 
      state: 1
    }, 
    {
      pos: [1, 3, 2], 
      state: 1
    }, 
    {
      pos: [5, 3, 2], 
      state: 1
    }, 
    {
      pos: [1, 4, 2], 
      state: 1
    }, 
    {
      pos: [2, 4, 2], 
      state: 1
    }, 
    {
      pos: [3, 4, 2], 
      state: 1
    }, 
    {
      pos: [4, 4, 2], 
      state: 1
    }, 
    {
      pos: [0, 0, 3], 
      state: 0
    }, 
    {
      pos: [1, 0, 3], 
      state: 0
    }, 
    {
      pos: [2, 0, 3], 
      state: 1
    }, 
    {
      pos: [3, 0, 3], 
      state: 1
    }, 
    {
      pos: [4, 0, 3], 
      state: 1
    }, 
    {
      pos: [5, 0, 3], 
      state: 0
    }, 
    {
      pos: [6, 0, 3], 
      state: 0
    }, 
    {
      pos: [7, 0, 3], 
      state: 0
    }, 
    {
      pos: [8, 0, 3], 
      state: 0
    }, 
    {
      pos: [9, 0, 3], 
      state: 0
    }, 
    {
      pos: [5, 1, 3], 
      state: 1
    }, 
    {
      pos: [6, 1, 3], 
      state: 1
    }, 
    {
      pos: [7, 1, 3], 
      state: 1
    }, 
    {
      pos: [5, 2, 3], 
      state: 1
    }, 
    {
      pos: [7, 2, 3], 
      state: 1
    }, 
    {
      pos: [5, 3, 3], 
      state: 1
    }, 
    {
      pos: [7, 3, 3], 
      state: 1
    }, 
    {
      pos: [1, 4, 3], 
      state: 1
    }, 
    {
      pos: [2, 4, 3], 
      state: 1
    }, 
    {
      pos: [3, 4, 3], 
      state: 1
    }, 
    {
      pos: [4, 4, 3], 
      state: 1
    }, 
    {
      pos: [5, 4, 3], 
      state: 1
    }, 
    {
      pos: [6, 4, 3], 
      state: 1
    }, 
    {
      pos: [7, 4, 3], 
      state: 1
    }, 
    {
      pos: [0, 0, 4], 
      state: 0
    }, 
    {
      pos: [1, 0, 4], 
      state: 0
    }, 
    {
      pos: [2, 0, 4], 
      state: 1
    }, 
    {
      pos: [3, 0, 4], 
      state: 1
    }, 
    {
      pos: [4, 0, 4], 
      state: 1
    }, 
    {
      pos: [5, 0, 4], 
      state: 0
    }, 
    {
      pos: [6, 0, 4], 
      state: 1
    }, 
    {
      pos: [7, 0, 4], 
      state: 1
    }, 
    {
      pos: [8, 0, 4], 
      state: 0
    }, 
    {
      pos: [9, 0, 4], 
      state: 0
    }, 
    {
      pos: [1, 1, 4], 
      state: 1
    }, 
    {
      pos: [8, 1, 4], 
      state: 1
    }, 
    {
      pos: [1, 2, 4], 
      state: 1
    }, 
    {
      pos: [8, 2, 4], 
      state: 1
    }, 
    {
      pos: [1, 3, 4], 
      state: 1
    }, 
    {
      pos: [5, 3, 4], 
      state: 1
    }, 
    {
      pos: [8, 3, 4], 
      state: 1
    }, 
    {
      pos: [1, 4, 4], 
      state: 1
    }, 
    {
      pos: [2, 4, 4], 
      state: 1
    }, 
    {
      pos: [3, 4, 4], 
      state: 1
    }, 
    {
      pos: [4, 4, 4], 
      state: 1
    }, 
    {
      pos: [5, 4, 4], 
      state: 1
    }, 
    {
      pos: [8, 4, 4], 
      state: 1
    }, 
    {
      pos: [0, 0, 5], 
      state: 0
    }, 
    {
      pos: [1, 0, 5], 
      state: 0
    }, 
    {
      pos: [2, 0, 5], 
      state: 1
    }, 
    {
      pos: [3, 0, 5], 
      state: 1
    }, 
    {
      pos: [4, 0, 5], 
      state: 1
    }, 
    {
      pos: [5, 0, 5], 
      state: 1
    }, 
    {
      pos: [6, 0, 5], 
      state: 2
    }, 
    {
      pos: [7, 0, 5], 
      state: 3
    }, 
    {
      pos: [8, 0, 5], 
      state: 1
    }, 
    {
      pos: [9, 0, 5], 
      state: 0
    }, 
    {
      pos: [9, 1, 5], 
      state: 1
    }, 
    {
      pos: [9, 2, 5], 
      state: 1
    }, 
    {
      pos: [9, 3, 5], 
      state: 1
    }, 
    {
      pos: [4, 4, 5], 
      state: 4
    }, 
    {
      pos: [9, 4, 5], 
      state: 1
    }, 
    {
      pos: [6, 5, 5], 
      state: 4
    }, 
    {
      pos: [0, 0, 6], 
      state: 0
    }, 
    {
      pos: [1, 0, 6], 
      state: 0
    }, 
    {
      pos: [2, 0, 6], 
      state: 1
    }, 
    {
      pos: [3, 0, 6], 
      state: 1
    }, 
    {
      pos: [4, 0, 6], 
      state: 1
    }, 
    {
      pos: [5, 0, 6], 
      state: 1
    }, 
    {
      pos: [6, 0, 6], 
      state: 5
    }, 
    {
      pos: [7, 0, 6], 
      state: 6
    }, 
    {
      pos: [8, 0, 6], 
      state: 1
    }, 
    {
      pos: [9, 0, 6], 
      state: 0
    }, 
    {
      pos: [9, 1, 6], 
      state: 1
    }, 
    {
      pos: [9, 2, 6], 
      state: 1
    }, 
    {
      pos: [9, 3, 6], 
      state: 1
    }, 
    {
      pos: [4, 4, 6], 
      state: 4
    }, 
    {
      pos: [9, 4, 6], 
      state: 1
    }, 
    {
      pos: [6, 5, 6], 
      state: 4
    }, 
    {
      pos: [0, 0, 7], 
      state: 0
    }, 
    {
      pos: [1, 0, 7], 
      state: 0
    }, 
    {
      pos: [2, 0, 7], 
      state: 1
    }, 
    {
      pos: [3, 0, 7], 
      state: 1
    }, 
    {
      pos: [4, 0, 7], 
      state: 1
    }, 
    {
      pos: [5, 0, 7], 
      state: 0
    }, 
    {
      pos: [6, 0, 7], 
      state: 1
    }, 
    {
      pos: [7, 0, 7], 
      state: 1
    }, 
    {
      pos: [8, 0, 7], 
      state: 0
    }, 
    {
      pos: [9, 0, 7], 
      state: 0
    }, 
    {
      pos: [1, 1, 7], 
      state: 1
    }, 
    {
      pos: [8, 1, 7], 
      state: 1
    }, 
    {
      pos: [1, 2, 7], 
      state: 1
    }, 
    {
      pos: [8, 2, 7], 
      state: 1
    }, 
    {
      pos: [1, 3, 7], 
      state: 1
    }, 
    {
      pos: [5, 3, 7], 
      state: 1
    }, 
    {
      pos: [8, 3, 7], 
      state: 1
    }, 
    {
      pos: [1, 4, 7], 
      state: 1
    }, 
    {
      pos: [2, 4, 7], 
      state: 1
    }, 
    {
      pos: [3, 4, 7], 
      state: 1
    }, 
    {
      pos: [4, 4, 7], 
      state: 1
    }, 
    {
      pos: [5, 4, 7], 
      state: 1
    }, 
    {
      pos: [8, 4, 7], 
      state: 1
    }, 
    {
      pos: [0, 0, 8], 
      state: 0
    }, 
    {
      pos: [1, 0, 8], 
      state: 0
    }, 
    {
      pos: [2, 0, 8], 
      state: 1
    }, 
    {
      pos: [3, 0, 8], 
      state: 1
    }, 
    {
      pos: [4, 0, 8], 
      state: 1
    }, 
    {
      pos: [5, 0, 8], 
      state: 0
    }, 
    {
      pos: [6, 0, 8], 
      state: 0
    }, 
    {
      pos: [7, 0, 8], 
      state: 0
    }, 
    {
      pos: [8, 0, 8], 
      state: 0
    }, 
    {
      pos: [9, 0, 8], 
      state: 0
    }, 
    {
      pos: [5, 1, 8], 
      state: 1
    }, 
    {
      pos: [6, 1, 8], 
      state: 1
    }, 
    {
      pos: [7, 1, 8], 
      state: 1
    }, 
    {
      pos: [5, 2, 8], 
      state: 1
    }, 
    {
      pos: [7, 2, 8], 
      state: 1
    }, 
    {
      pos: [5, 3, 8], 
      state: 1
    }, 
    {
      pos: [7, 3, 8], 
      state: 1
    }, 
    {
      pos: [1, 4, 8], 
      state: 1
    }, 
    {
      pos: [2, 4, 8], 
      state: 1
    }, 
    {
      pos: [3, 4, 8], 
      state: 1
    }, 
    {
      pos: [4, 4, 8], 
      state: 1
    }, 
    {
      pos: [5, 4, 8], 
      state: 1
    }, 
    {
      pos: [6, 4, 8], 
      state: 1
    }, 
    {
      pos: [7, 4, 8], 
      state: 1
    }, 
    {
      pos: [0, 0, 9], 
      state: 0
    }, 
    {
      pos: [1, 0, 9], 
      state: 0
    }, 
    {
      pos: [2, 0, 9], 
      state: 1
    }, 
    {
      pos: [3, 0, 9], 
      state: 1
    }, 
    {
      pos: [4, 0, 9], 
      state: 1
    }, 
    {
      pos: [5, 0, 9], 
      state: 0
    }, 
    {
      pos: [6, 0, 9], 
      state: 0
    }, 
    {
      pos: [7, 0, 9], 
      state: 0
    }, 
    {
      pos: [8, 0, 9], 
      state: 0
    }, 
    {
      pos: [9, 0, 9], 
      state: 0
    }, 
    {
      pos: [1, 1, 9], 
      state: 1
    }, 
    {
      pos: [5, 1, 9], 
      state: 1
    }, 
    {
      pos: [1, 2, 9], 
      state: 1
    }, 
    {
      pos: [5, 2, 9], 
      state: 1
    }, 
    {
      pos: [1, 3, 9], 
      state: 1
    }, 
    {
      pos: [5, 3, 9], 
      state: 1
    }, 
    {
      pos: [1, 4, 9], 
      state: 1
    }, 
    {
      pos: [2, 4, 9], 
      state: 1
    }, 
    {
      pos: [3, 4, 9], 
      state: 1
    }, 
    {
      pos: [4, 4, 9], 
      state: 1
    }, 
    {
      pos: [0, 0, 10], 
      state: 0
    }, 
    {
      pos: [1, 0, 10], 
      state: 0
    }, 
    {
      pos: [2, 0, 10], 
      state: 1
    }, 
    {
      pos: [3, 0, 10], 
      state: 1
    }, 
    {
      pos: [4, 0, 10], 
      state: 1
    }, 
    {
      pos: [5, 0, 10], 
      state: 0
    }, 
    {
      pos: [6, 0, 10], 
      state: 0
    }, 
    {
      pos: [7, 0, 10], 
      state: 0
    }, 
    {
      pos: [8, 0, 10], 
      state: 0
    }, 
    {
      pos: [9, 0, 10], 
      state: 0
    }, 
    {
      pos: [5, 1, 10], 
      state: 1
    }, 
    {
      pos: [1, 4, 10], 
      state: 1
    }, 
    {
      pos: [2, 4, 10], 
      state: 1
    }, 
    {
      pos: [3, 4, 10], 
      state: 1
    }, 
    {
      pos: [4, 4, 10], 
      state: 1
    }, 
    {
      pos: [0, 0, 11], 
      state: 0
    }, 
    {
      pos: [1, 0, 11], 
      state: 0
    }, 
    {
      pos: [2, 0, 11], 
      state: 0
    }, 
    {
      pos: [3, 0, 11], 
      state: 0
    }, 
    {
      pos: [4, 0, 11], 
      state: 0
    }, 
    {
      pos: [5, 0, 11], 
      state: 0
    }, 
    {
      pos: [6, 0, 11], 
      state: 0
    }, 
    {
      pos: [7, 0, 11], 
      state: 0
    }, 
    {
      pos: [8, 0, 11], 
      state: 0
    }, 
    {
      pos: [9, 0, 11], 
      state: 0
    }, 
    {
      pos: [1, 1, 11], 
      state: 1
    }, 
    {
      pos: [2, 1, 11], 
      state: 1
    }, 
    {
      pos: [3, 1, 11], 
      state: 1
    }, 
    {
      pos: [4, 1, 11], 
      state: 1
    }, 
    {
      pos: [5, 1, 11], 
      state: 1
    }, 
    {
      pos: [1, 2, 11], 
      state: 1
    }, 
    {
      pos: [2, 2, 11], 
      state: 1
    }, 
    {
      pos: [4, 2, 11], 
      state: 1
    }, 
    {
      pos: [5, 2, 11], 
      state: 1
    }, 
    {
      pos: [1, 3, 11], 
      state: 1
    }, 
    {
      pos: [2, 3, 11], 
      state: 1
    }, 
    {
      pos: [4, 3, 11], 
      state: 1
    }, 
    {
      pos: [5, 3, 11], 
      state: 1
    }, 
    {
      pos: [1, 4, 11], 
      state: 1
    }, 
    {
      nbt: {
        Fuel: 0b, 
        Items: [], 
        id: "minecraft:brewing_stand", 
        BrewTime: 0s, 
        Lock: ""
      }, 
      pos: [4, 1, 1], 
      state: 7
    }, 
    {
      nbt: {
        target_pool: "minecraft:empty", 
        final_state: "minecraft:structure_void", 
        id: "minecraft:jigsaw", 
        attachement_type: "minecraft:building_entrance"
      }, 
      pos: [0, 1, 5], 
      state: 8
    }, 
    {
      pos: [0, 1, 0], 
      state: 9
    }, 
    {
      pos: [6, 1, 0], 
      state: 10
    }, 
    {
      pos: [7, 1, 0], 
      state: 10
    }, 
    {
      pos: [8, 1, 0], 
      state: 10
    }, 
    {
      pos: [9, 1, 0], 
      state: 10
    }, 
    {
      pos: [0, 2, 0], 
      state: 10
    }, 
    {
      pos: [3, 2, 0], 
      state: 11
    }, 
    {
      pos: [6, 2, 0], 
      state: 10
    }, 
    {
      pos: [7, 2, 0], 
      state: 10
    }, 
    {
      pos: [8, 2, 0], 
      state: 10
    }, 
    {
      pos: [9, 2, 0], 
      state: 10
    }, 
    {
      pos: [0, 3, 0], 
      state: 10
    }, 
    {
      pos: [3, 3, 0], 
      state: 12
    }, 
    {
      pos: [6, 3, 0], 
      state: 10
    }, 
    {
      pos: [7, 3, 0], 
      state: 10
    }, 
    {
      pos: [8, 3, 0], 
      state: 10
    }, 
    {
      pos: [9, 3, 0], 
      state: 10
    }, 
    {
      pos: [0, 4, 0], 
      state: 10
    }, 
    {
      pos: [2, 4, 0], 
      state: 13
    }, 
    {
      pos: [3, 4, 0], 
      state: 13
    }, 
    {
      pos: [4, 4, 0], 
      state: 13
    }, 
    {
      pos: [5, 4, 0], 
      state: 10
    }, 
    {
      pos: [6, 4, 0], 
      state: 10
    }, 
    {
      pos: [7, 4, 0], 
      state: 10
    }, 
    {
      pos: [8, 4, 0], 
      state: 10
    }, 
    {
      pos: [9, 4, 0], 
      state: 10
    }, 
    {
      pos: [0, 5, 0], 
      state: 10
    }, 
    {
      pos: [1, 5, 0], 
      state: 14
    }, 
    {
      pos: [2, 5, 0], 
      state: 10
    }, 
    {
      pos: [3, 5, 0], 
      state: 10
    }, 
    {
      pos: [4, 5, 0], 
      state: 10
    }, 
    {
      pos: [5, 5, 0], 
      state: 10
    }, 
    {
      pos: [6, 5, 0], 
      state: 10
    }, 
    {
      pos: [7, 5, 0], 
      state: 10
    }, 
    {
      pos: [8, 5, 0], 
      state: 10
    }, 
    {
      pos: [9, 5, 0], 
      state: 10
    }, 
    {
      pos: [0, 1, 1], 
      state: 10
    }, 
    {
      pos: [1, 1, 1], 
      state: 10
    }, 
    {
      pos: [2, 1, 1], 
      state: 10
    }, 
    {
      pos: [3, 1, 1], 
      state: 10
    }, 
    {
      pos: [6, 1, 1], 
      state: 10
    }, 
    {
      pos: [7, 1, 1], 
      state: 10
    }, 
    {
      pos: [8, 1, 1], 
      state: 10
    }, 
    {
      pos: [9, 1, 1], 
      state: 10
    }, 
    {
      pos: [0, 2, 1], 
      state: 10
    }, 
    {
      pos: [1, 2, 1], 
      state: 10
    }, 
    {
      pos: [2, 2, 1], 
      state: 10
    }, 
    {
      pos: [3, 2, 1], 
      state: 10
    }, 
    {
      pos: [4, 2, 1], 
      state: 10
    }, 
    {
      pos: [5, 2, 1], 
      state: 11
    }, 
    {
      pos: [6, 2, 1], 
      state: 10
    }, 
    {
      pos: [7, 2, 1], 
      state: 10
    }, 
    {
      pos: [8, 2, 1], 
      state: 10
    }, 
    {
      pos: [9, 2, 1], 
      state: 10
    }, 
    {
      pos: [0, 3, 1], 
      state: 10
    }, 
    {
      pos: [1, 3, 1], 
      state: 15
    }, 
    {
      pos: [2, 3, 1], 
      state: 10
    }, 
    {
      pos: [3, 3, 1], 
      state: 10
    }, 
    {
      pos: [4, 3, 1], 
      state: 10
    }, 
    {
      pos: [5, 3, 1], 
      state: 12
    }, 
    {
      pos: [6, 3, 1], 
      state: 10
    }, 
    {
      pos: [7, 3, 1], 
      state: 10
    }, 
    {
      pos: [8, 3, 1], 
      state: 10
    }, 
    {
      pos: [9, 3, 1], 
      state: 10
    }, 
    {
      pos: [0, 4, 1], 
      state: 10
    }, 
    {
      pos: [5, 4, 1], 
      state: 13
    }, 
    {
      pos: [6, 4, 1], 
      state: 10
    }, 
    {
      pos: [7, 4, 1], 
      state: 10
    }, 
    {
      pos: [8, 4, 1], 
      state: 10
    }, 
    {
      pos: [9, 4, 1], 
      state: 10
    }, 
    {
      pos: [0, 5, 1], 
      state: 10
    }, 
    {
      pos: [1, 5, 1], 
      state: 16
    }, 
    {
      pos: [2, 5, 1], 
      state: 10
    }, 
    {
      pos: [3, 5, 1], 
      state: 10
    }, 
    {
      pos: [4, 5, 1], 
      state: 10
    }, 
    {
      pos: [5, 5, 1], 
      state: 10
    }, 
    {
      pos: [6, 5, 1], 
      state: 10
    }, 
    {
      pos: [7, 5, 1], 
      state: 10
    }, 
    {
      pos: [8, 5, 1], 
      state: 10
    }, 
    {
      pos: [9, 5, 1], 
      state: 10
    }, 
    {
      pos: [0, 1, 2], 
      state: 17
    }, 
    {
      pos: [2, 1, 2], 
      state: 10
    }, 
    {
      pos: [3, 1, 2], 
      state: 10
    }, 
    {
      pos: [4, 1, 2], 
      state: 10
    }, 
    {
      pos: [6, 1, 2], 
      state: 10
    }, 
    {
      pos: [7, 1, 2], 
      state: 10
    }, 
    {
      pos: [8, 1, 2], 
      state: 10
    }, 
    {
      pos: [9, 1, 2], 
      state: 10
    }, 
    {
      pos: [0, 2, 2], 
      state: 10
    }, 
    {
      pos: [2, 2, 2], 
      state: 10
    }, 
    {
      pos: [3, 2, 2], 
      state: 10
    }, 
    {
      pos: [4, 2, 2], 
      state: 10
    }, 
    {
      pos: [6, 2, 2], 
      state: 10
    }, 
    {
      pos: [7, 2, 2], 
      state: 10
    }, 
    {
      pos: [8, 2, 2], 
      state: 10
    }, 
    {
      pos: [9, 2, 2], 
      state: 10
    }, 
    {
      pos: [0, 3, 2], 
      state: 10
    }, 
    {
      pos: [2, 3, 2], 
      state: 10
    }, 
    {
      pos: [3, 3, 2], 
      state: 10
    }, 
    {
      pos: [4, 3, 2], 
      state: 10
    }, 
    {
      pos: [6, 3, 2], 
      state: 10
    }, 
    {
      pos: [7, 3, 2], 
      state: 10
    }, 
    {
      pos: [8, 3, 2], 
      state: 10
    }, 
    {
      pos: [9, 3, 2], 
      state: 10
    }, 
    {
      pos: [0, 4, 2], 
      state: 10
    }, 
    {
      pos: [5, 4, 2], 
      state: 13
    }, 
    {
      pos: [6, 4, 2], 
      state: 10
    }, 
    {
      pos: [7, 4, 2], 
      state: 10
    }, 
    {
      pos: [8, 4, 2], 
      state: 10
    }, 
    {
      pos: [9, 4, 2], 
      state: 10
    }, 
    {
      pos: [0, 5, 2], 
      state: 10
    }, 
    {
      pos: [1, 5, 2], 
      state: 10
    }, 
    {
      pos: [2, 5, 2], 
      state: 10
    }, 
    {
      pos: [3, 5, 2], 
      state: 10
    }, 
    {
      pos: [4, 5, 2], 
      state: 10
    }, 
    {
      pos: [5, 5, 2], 
      state: 10
    }, 
    {
      pos: [6, 5, 2], 
      state: 10
    }, 
    {
      pos: [7, 5, 2], 
      state: 10
    }, 
    {
      pos: [8, 5, 2], 
      state: 10
    }, 
    {
      pos: [9, 5, 2], 
      state: 10
    }, 
    {
      pos: [0, 1, 3], 
      state: 10
    }, 
    {
      pos: [1, 1, 3], 
      state: 10
    }, 
    {
      pos: [2, 1, 3], 
      state: 10
    }, 
    {
      pos: [3, 1, 3], 
      state: 10
    }, 
    {
      pos: [4, 1, 3], 
      state: 13
    }, 
    {
      pos: [8, 1, 3], 
      state: 10
    }, 
    {
      pos: [9, 1, 3], 
      state: 10
    }, 
    {
      pos: [0, 2, 3], 
      state: 10
    }, 
    {
      pos: [1, 2, 3], 
      state: 10
    }, 
    {
      pos: [2, 2, 3], 
      state: 10
    }, 
    {
      pos: [3, 2, 3], 
      state: 10
    }, 
    {
      pos: [4, 2, 3], 
      state: 10
    }, 
    {
      pos: [6, 2, 3], 
      state: 11
    }, 
    {
      pos: [8, 2, 3], 
      state: 10
    }, 
    {
      pos: [9, 2, 3], 
      state: 10
    }, 
    {
      pos: [0, 3, 3], 
      state: 10
    }, 
    {
      pos: [1, 3, 3], 
      state: 10
    }, 
    {
      pos: [2, 3, 3], 
      state: 10
    }, 
    {
      pos: [3, 3, 3], 
      state: 10
    }, 
    {
      pos: [4, 3, 3], 
      state: 18
    }, 
    {
      pos: [6, 3, 3], 
      state: 12
    }, 
    {
      pos: [8, 3, 3], 
      state: 10
    }, 
    {
      pos: [9, 3, 3], 
      state: 10
    }, 
    {
      pos: [0, 4, 3], 
      state: 10
    }, 
    {
      pos: [8, 4, 3], 
      state: 10
    }, 
    {
      pos: [9, 4, 3], 
      state: 10
    }, 
    {
      pos: [0, 5, 3], 
      state: 10
    }, 
    {
      pos: [1, 5, 3], 
      state: 14
    }, 
    {
      pos: [2, 5, 3], 
      state: 10
    }, 
    {
      pos: [3, 5, 3], 
      state: 10
    }, 
    {
      pos: [4, 5, 3], 
      state: 10
    }, 
    {
      pos: [5, 5, 3], 
      state: 10
    }, 
    {
      pos: [6, 5, 3], 
      state: 10
    }, 
    {
      pos: [7, 5, 3], 
      state: 10
    }, 
    {
      pos: [8, 5, 3], 
      state: 10
    }, 
    {
      pos: [9, 5, 3], 
      state: 10
    }, 
    {
      pos: [0, 1, 4], 
      state: 9
    }, 
    {
      pos: [2, 1, 4], 
      state: 10
    }, 
    {
      pos: [3, 1, 4], 
      state: 10
    }, 
    {
      pos: [4, 1, 4], 
      state: 13
    }, 
    {
      pos: [5, 1, 4], 
      state: 10
    }, 
    {
      pos: [6, 1, 4], 
      state: 10
    }, 
    {
      pos: [7, 1, 4], 
      state: 10
    }, 
    {
      pos: [9, 1, 4], 
      state: 10
    }, 
    {
      pos: [0, 2, 4], 
      state: 10
    }, 
    {
      pos: [2, 2, 4], 
      state: 10
    }, 
    {
      pos: [3, 2, 4], 
      state: 10
    }, 
    {
      pos: [4, 2, 4], 
      state: 10
    }, 
    {
      pos: [5, 2, 4], 
      state: 19
    }, 
    {
      pos: [6, 2, 4], 
      state: 10
    }, 
    {
      pos: [7, 2, 4], 
      state: 10
    }, 
    {
      pos: [9, 2, 4], 
      state: 10
    }, 
    {
      pos: [0, 3, 4], 
      state: 18
    }, 
    {
      pos: [2, 3, 4], 
      state: 10
    }, 
    {
      pos: [3, 3, 4], 
      state: 10
    }, 
    {
      pos: [4, 3, 4], 
      state: 10
    }, 
    {
      pos: [6, 3, 4], 
      state: 10
    }, 
    {
      pos: [7, 3, 4], 
      state: 10
    }, 
    {
      pos: [9, 3, 4], 
      state: 10
    }, 
    {
      pos: [0, 4, 4], 
      state: 10
    }, 
    {
      pos: [6, 4, 4], 
      state: 10
    }, 
    {
      pos: [7, 4, 4], 
      state: 10
    }, 
    {
      pos: [9, 4, 4], 
      state: 10
    }, 
    {
      pos: [0, 5, 4], 
      state: 10
    }, 
    {
      pos: [1, 5, 4], 
      state: 16
    }, 
    {
      pos: [2, 5, 4], 
      state: 10
    }, 
    {
      pos: [3, 5, 4], 
      state: 10
    }, 
    {
      pos: [4, 5, 4], 
      state: 10
    }, 
    {
      pos: [5, 5, 4], 
      state: 10
    }, 
    {
      pos: [6, 5, 4], 
      state: 13
    }, 
    {
      pos: [7, 5, 4], 
      state: 13
    }, 
    {
      pos: [8, 5, 4], 
      state: 10
    }, 
    {
      pos: [9, 5, 4], 
      state: 10
    }, 
    {
      pos: [1, 1, 5], 
      state: 10
    }, 
    {
      pos: [2, 1, 5], 
      state: 10
    }, 
    {
      pos: [3, 1, 5], 
      state: 10
    }, 
    {
      pos: [4, 1, 5], 
      state: 10
    }, 
    {
      pos: [5, 1, 5], 
      state: 10
    }, 
    {
      pos: [6, 1, 5], 
      state: 10
    }, 
    {
      pos: [7, 1, 5], 
      state: 10
    }, 
    {
      pos: [8, 1, 5], 
      state: 10
    }, 
    {
      pos: [0, 2, 5], 
      state: 10
    }, 
    {
      pos: [1, 2, 5], 
      state: 10
    }, 
    {
      pos: [2, 2, 5], 
      state: 10
    }, 
    {
      pos: [3, 2, 5], 
      state: 10
    }, 
    {
      pos: [4, 2, 5], 
      state: 10
    }, 
    {
      pos: [5, 2, 5], 
      state: 10
    }, 
    {
      pos: [6, 2, 5], 
      state: 10
    }, 
    {
      pos: [7, 2, 5], 
      state: 10
    }, 
    {
      pos: [8, 2, 5], 
      state: 10
    }, 
    {
      pos: [0, 3, 5], 
      state: 10
    }, 
    {
      pos: [1, 3, 5], 
      state: 19
    }, 
    {
      pos: [2, 3, 5], 
      state: 10
    }, 
    {
      pos: [3, 3, 5], 
      state: 10
    }, 
    {
      pos: [4, 3, 5], 
      state: 10
    }, 
    {
      pos: [5, 3, 5], 
      state: 19
    }, 
    {
      pos: [6, 3, 5], 
      state: 10
    }, 
    {
      pos: [7, 3, 5], 
      state: 10
    }, 
    {
      pos: [8, 3, 5], 
      state: 20
    }, 
    {
      pos: [0, 4, 5], 
      state: 10
    }, 
    {
      pos: [1, 4, 5], 
      state: 16
    }, 
    {
      pos: [2, 4, 5], 
      state: 13
    }, 
    {
      pos: [3, 4, 5], 
      state: 13
    }, 
    {
      pos: [5, 4, 5], 
      state: 10
    }, 
    {
      pos: [6, 4, 5], 
      state: 10
    }, 
    {
      pos: [7, 4, 5], 
      state: 10
    }, 
    {
      pos: [8, 4, 5], 
      state: 10
    }, 
    {
      pos: [0, 5, 5], 
      state: 10
    }, 
    {
      pos: [1, 5, 5], 
      state: 10
    }, 
    {
      pos: [2, 5, 5], 
      state: 10
    }, 
    {
      pos: [3, 5, 5], 
      state: 10
    }, 
    {
      pos: [4, 5, 5], 
      state: 10
    }, 
    {
      pos: [5, 5, 5], 
      state: 13
    }, 
    {
      pos: [7, 5, 5], 
      state: 15
    }, 
    {
      pos: [8, 5, 5], 
      state: 13
    }, 
    {
      pos: [9, 5, 5], 
      state: 10
    }, 
    {
      pos: [0, 1, 6], 
      state: 10
    }, 
    {
      pos: [1, 1, 6], 
      state: 10
    }, 
    {
      pos: [2, 1, 6], 
      state: 10
    }, 
    {
      pos: [3, 1, 6], 
      state: 10
    }, 
    {
      pos: [4, 1, 6], 
      state: 10
    }, 
    {
      pos: [5, 1, 6], 
      state: 10
    }, 
    {
      pos: [6, 1, 6], 
      state: 10
    }, 
    {
      pos: [7, 1, 6], 
      state: 10
    }, 
    {
      pos: [8, 1, 6], 
      state: 10
    }, 
    {
      pos: [0, 2, 6], 
      state: 10
    }, 
    {
      pos: [1, 2, 6], 
      state: 10
    }, 
    {
      pos: [2, 2, 6], 
      state: 10
    }, 
    {
      pos: [3, 2, 6], 
      state: 10
    }, 
    {
      pos: [4, 2, 6], 
      state: 10
    }, 
    {
      pos: [5, 2, 6], 
      state: 10
    }, 
    {
      pos: [6, 2, 6], 
      state: 10
    }, 
    {
      pos: [7, 2, 6], 
      state: 10
    }, 
    {
      pos: [8, 2, 6], 
      state: 10
    }, 
    {
      pos: [0, 3, 6], 
      state: 10
    }, 
    {
      pos: [1, 3, 6], 
      state: 21
    }, 
    {
      pos: [2, 3, 6], 
      state: 10
    }, 
    {
      pos: [3, 3, 6], 
      state: 10
    }, 
    {
      pos: [4, 3, 6], 
      state: 10
    }, 
    {
      pos: [5, 3, 6], 
      state: 21
    }, 
    {
      pos: [6, 3, 6], 
      state: 10
    }, 
    {
      pos: [7, 3, 6], 
      state: 10
    }, 
    {
      pos: [8, 3, 6], 
      state: 22
    }, 
    {
      pos: [0, 4, 6], 
      state: 10
    }, 
    {
      pos: [1, 4, 6], 
      state: 14
    }, 
    {
      pos: [2, 4, 6], 
      state: 13
    }, 
    {
      pos: [3, 4, 6], 
      state: 13
    }, 
    {
      pos: [5, 4, 6], 
      state: 10
    }, 
    {
      pos: [6, 4, 6], 
      state: 10
    }, 
    {
      pos: [7, 4, 6], 
      state: 10
    }, 
    {
      pos: [8, 4, 6], 
      state: 10
    }, 
    {
      pos: [0, 5, 6], 
      state: 10
    }, 
    {
      pos: [1, 5, 6], 
      state: 10
    }, 
    {
      pos: [2, 5, 6], 
      state: 10
    }, 
    {
      pos: [3, 5, 6], 
      state: 10
    }, 
    {
      pos: [4, 5, 6], 
      state: 10
    }, 
    {
      pos: [5, 5, 6], 
      state: 13
    }, 
    {
      pos: [7, 5, 6], 
      state: 15
    }, 
    {
      pos: [8, 5, 6], 
      state: 13
    }, 
    {
      pos: [9, 5, 6], 
      state: 10
    }, 
    {
      pos: [0, 1, 7], 
      state: 9
    }, 
    {
      pos: [2, 1, 7], 
      state: 10
    }, 
    {
      pos: [3, 1, 7], 
      state: 10
    }, 
    {
      pos: [4, 1, 7], 
      state: 13
    }, 
    {
      pos: [5, 1, 7], 
      state: 10
    }, 
    {
      pos: [6, 1, 7], 
      state: 10
    }, 
    {
      pos: [7, 1, 7], 
      state: 10
    }, 
    {
      pos: [9, 1, 7], 
      state: 10
    }, 
    {
      pos: [0, 2, 7], 
      state: 10
    }, 
    {
      pos: [2, 2, 7], 
      state: 10
    }, 
    {
      pos: [3, 2, 7], 
      state: 10
    }, 
    {
      pos: [4, 2, 7], 
      state: 10
    }, 
    {
      pos: [5, 2, 7], 
      state: 21
    }, 
    {
      pos: [6, 2, 7], 
      state: 10
    }, 
    {
      pos: [7, 2, 7], 
      state: 10
    }, 
    {
      pos: [9, 2, 7], 
      state: 10
    }, 
    {
      pos: [0, 3, 7], 
      state: 18
    }, 
    {
      pos: [2, 3, 7], 
      state: 10
    }, 
    {
      pos: [3, 3, 7], 
      state: 10
    }, 
    {
      pos: [4, 3, 7], 
      state: 10
    }, 
    {
      pos: [6, 3, 7], 
      state: 10
    }, 
    {
      pos: [7, 3, 7], 
      state: 10
    }, 
    {
      pos: [9, 3, 7], 
      state: 10
    }, 
    {
      pos: [0, 4, 7], 
      state: 10
    }, 
    {
      pos: [6, 4, 7], 
      state: 10
    }, 
    {
      pos: [7, 4, 7], 
      state: 10
    }, 
    {
      pos: [9, 4, 7], 
      state: 10
    }, 
    {
      pos: [0, 5, 7], 
      state: 10
    }, 
    {
      pos: [1, 5, 7], 
      state: 14
    }, 
    {
      pos: [2, 5, 7], 
      state: 10
    }, 
    {
      pos: [3, 5, 7], 
      state: 10
    }, 
    {
      pos: [4, 5, 7], 
      state: 10
    }, 
    {
      pos: [5, 5, 7], 
      state: 10
    }, 
    {
      pos: [6, 5, 7], 
      state: 13
    }, 
    {
      pos: [7, 5, 7], 
      state: 13
    }, 
    {
      pos: [8, 5, 7], 
      state: 10
    }, 
    {
      pos: [9, 5, 7], 
      state: 10
    }, 
    {
      pos: [0, 1, 8], 
      state: 10
    }, 
    {
      pos: [1, 1, 8], 
      state: 10
    }, 
    {
      pos: [2, 1, 8], 
      state: 10
    }, 
    {
      pos: [3, 1, 8], 
      state: 10
    }, 
    {
      pos: [4, 1, 8], 
      state: 13
    }, 
    {
      pos: [8, 1, 8], 
      state: 10
    }, 
    {
      pos: [9, 1, 8], 
      state: 10
    }, 
    {
      pos: [0, 2, 8], 
      state: 10
    }, 
    {
      pos: [1, 2, 8], 
      state: 10
    }, 
    {
      pos: [2, 2, 8], 
      state: 10
    }, 
    {
      pos: [3, 2, 8], 
      state: 10
    }, 
    {
      pos: [4, 2, 8], 
      state: 10
    }, 
    {
      pos: [6, 2, 8], 
      state: 11
    }, 
    {
      pos: [8, 2, 8], 
      state: 10
    }, 
    {
      pos: [9, 2, 8], 
      state: 10
    }, 
    {
      pos: [0, 3, 8], 
      state: 10
    }, 
    {
      pos: [1, 3, 8], 
      state: 10
    }, 
    {
      pos: [2, 3, 8], 
      state: 10
    }, 
    {
      pos: [3, 3, 8], 
      state: 10
    }, 
    {
      pos: [4, 3, 8], 
      state: 18
    }, 
    {
      pos: [6, 3, 8], 
      state: 12
    }, 
    {
      pos: [8, 3, 8], 
      state: 10
    }, 
    {
      pos: [9, 3, 8], 
      state: 10
    }, 
    {
      pos: [0, 4, 8], 
      state: 10
    }, 
    {
      pos: [8, 4, 8], 
      state: 10
    }, 
    {
      pos: [9, 4, 8], 
      state: 10
    }, 
    {
      pos: [0, 5, 8], 
      state: 10
    }, 
    {
      pos: [1, 5, 8], 
      state: 16
    }, 
    {
      pos: [2, 5, 8], 
      state: 10
    }, 
    {
      pos: [3, 5, 8], 
      state: 10
    }, 
    {
      pos: [4, 5, 8], 
      state: 10
    }, 
    {
      pos: [5, 5, 8], 
      state: 10
    }, 
    {
      pos: [6, 5, 8], 
      state: 10
    }, 
    {
      pos: [7, 5, 8], 
      state: 10
    }, 
    {
      pos: [8, 5, 8], 
      state: 10
    }, 
    {
      pos: [9, 5, 8], 
      state: 10
    }, 
    {
      pos: [0, 1, 9], 
      state: 17
    }, 
    {
      pos: [2, 1, 9], 
      state: 10
    }, 
    {
      pos: [3, 1, 9], 
      state: 10
    }, 
    {
      pos: [4, 1, 9], 
      state: 10
    }, 
    {
      pos: [6, 1, 9], 
      state: 10
    }, 
    {
      pos: [7, 1, 9], 
      state: 10
    }, 
    {
      pos: [8, 1, 9], 
      state: 10
    }, 
    {
      pos: [9, 1, 9], 
      state: 10
    }, 
    {
      pos: [0, 2, 9], 
      state: 10
    }, 
    {
      pos: [2, 2, 9], 
      state: 10
    }, 
    {
      pos: [3, 2, 9], 
      state: 10
    }, 
    {
      pos: [4, 2, 9], 
      state: 10
    }, 
    {
      pos: [6, 2, 9], 
      state: 10
    }, 
    {
      pos: [7, 2, 9], 
      state: 10
    }, 
    {
      pos: [8, 2, 9], 
      state: 10
    }, 
    {
      pos: [9, 2, 9], 
      state: 10
    }, 
    {
      pos: [0, 3, 9], 
      state: 10
    }, 
    {
      pos: [2, 3, 9], 
      state: 10
    }, 
    {
      pos: [3, 3, 9], 
      state: 10
    }, 
    {
      pos: [4, 3, 9], 
      state: 10
    }, 
    {
      pos: [6, 3, 9], 
      state: 10
    }, 
    {
      pos: [7, 3, 9], 
      state: 10
    }, 
    {
      pos: [8, 3, 9], 
      state: 10
    }, 
    {
      pos: [9, 3, 9], 
      state: 10
    }, 
    {
      pos: [0, 4, 9], 
      state: 10
    }, 
    {
      pos: [5, 4, 9], 
      state: 13
    }, 
    {
      pos: [6, 4, 9], 
      state: 10
    }, 
    {
      pos: [7, 4, 9], 
      state: 10
    }, 
    {
      pos: [8, 4, 9], 
      state: 10
    }, 
    {
      pos: [9, 4, 9], 
      state: 10
    }, 
    {
      pos: [0, 5, 9], 
      state: 10
    }, 
    {
      pos: [1, 5, 9], 
      state: 10
    }, 
    {
      pos: [2, 5, 9], 
      state: 10
    }, 
    {
      pos: [3, 5, 9], 
      state: 10
    }, 
    {
      pos: [4, 5, 9], 
      state: 10
    }, 
    {
      pos: [5, 5, 9], 
      state: 10
    }, 
    {
      pos: [6, 5, 9], 
      state: 10
    }, 
    {
      pos: [7, 5, 9], 
      state: 10
    }, 
    {
      pos: [8, 5, 9], 
      state: 10
    }, 
    {
      pos: [9, 5, 9], 
      state: 10
    }, 
    {
      pos: [0, 1, 10], 
      state: 10
    }, 
    {
      pos: [1, 1, 10], 
      state: 10
    }, 
    {
      pos: [2, 1, 10], 
      state: 10
    }, 
    {
      pos: [3, 1, 10], 
      state: 13
    }, 
    {
      pos: [4, 1, 10], 
      state: 13
    }, 
    {
      pos: [6, 1, 10], 
      state: 10
    }, 
    {
      pos: [7, 1, 10], 
      state: 10
    }, 
    {
      pos: [8, 1, 10], 
      state: 10
    }, 
    {
      pos: [9, 1, 10], 
      state: 10
    }, 
    {
      pos: [0, 2, 10], 
      state: 10
    }, 
    {
      pos: [1, 2, 10], 
      state: 10
    }, 
    {
      pos: [2, 2, 10], 
      state: 10
    }, 
    {
      pos: [3, 2, 10], 
      state: 10
    }, 
    {
      pos: [4, 2, 10], 
      state: 10
    }, 
    {
      pos: [5, 2, 10], 
      state: 11
    }, 
    {
      pos: [6, 2, 10], 
      state: 10
    }, 
    {
      pos: [7, 2, 10], 
      state: 10
    }, 
    {
      pos: [8, 2, 10], 
      state: 10
    }, 
    {
      pos: [9, 2, 10], 
      state: 10
    }, 
    {
      pos: [0, 3, 10], 
      state: 10
    }, 
    {
      pos: [1, 3, 10], 
      state: 15
    }, 
    {
      pos: [2, 3, 10], 
      state: 10
    }, 
    {
      pos: [3, 3, 10], 
      state: 10
    }, 
    {
      pos: [4, 3, 10], 
      state: 10
    }, 
    {
      pos: [5, 3, 10], 
      state: 12
    }, 
    {
      pos: [6, 3, 10], 
      state: 10
    }, 
    {
      pos: [7, 3, 10], 
      state: 10
    }, 
    {
      pos: [8, 3, 10], 
      state: 10
    }, 
    {
      pos: [9, 3, 10], 
      state: 10
    }, 
    {
      pos: [0, 4, 10], 
      state: 10
    }, 
    {
      pos: [5, 4, 10], 
      state: 13
    }, 
    {
      pos: [6, 4, 10], 
      state: 10
    }, 
    {
      pos: [7, 4, 10], 
      state: 10
    }, 
    {
      pos: [8, 4, 10], 
      state: 10
    }, 
    {
      pos: [9, 4, 10], 
      state: 10
    }, 
    {
      pos: [0, 5, 10], 
      state: 10
    }, 
    {
      pos: [1, 5, 10], 
      state: 14
    }, 
    {
      pos: [2, 5, 10], 
      state: 10
    }, 
    {
      pos: [3, 5, 10], 
      state: 10
    }, 
    {
      pos: [4, 5, 10], 
      state: 10
    }, 
    {
      pos: [5, 5, 10], 
      state: 10
    }, 
    {
      pos: [6, 5, 10], 
      state: 10
    }, 
    {
      pos: [7, 5, 10], 
      state: 10
    }, 
    {
      pos: [8, 5, 10], 
      state: 10
    }, 
    {
      pos: [9, 5, 10], 
      state: 10
    }, 
    {
      pos: [0, 1, 11], 
      state: 9
    }, 
    {
      pos: [6, 1, 11], 
      state: 10
    }, 
    {
      pos: [7, 1, 11], 
      state: 10
    }, 
    {
      pos: [8, 1, 11], 
      state: 10
    }, 
    {
      pos: [9, 1, 11], 
      state: 10
    }, 
    {
      pos: [0, 2, 11], 
      state: 10
    }, 
    {
      pos: [3, 2, 11], 
      state: 11
    }, 
    {
      pos: [6, 2, 11], 
      state: 10
    }, 
    {
      pos: [7, 2, 11], 
      state: 10
    }, 
    {
      pos: [8, 2, 11], 
      state: 10
    }, 
    {
      pos: [9, 2, 11], 
      state: 10
    }, 
    {
      pos: [0, 3, 11], 
      state: 10
    }, 
    {
      pos: [3, 3, 11], 
      state: 12
    }, 
    {
      pos: [6, 3, 11], 
      state: 10
    }, 
    {
      pos: [7, 3, 11], 
      state: 10
    }, 
    {
      pos: [8, 3, 11], 
      state: 10
    }, 
    {
      pos: [9, 3, 11], 
      state: 10
    }, 
    {
      pos: [0, 4, 11], 
      state: 10
    }, 
    {
      pos: [2, 4, 11], 
      state: 13
    }, 
    {
      pos: [3, 4, 11], 
      state: 13
    }, 
    {
      pos: [4, 4, 11], 
      state: 13
    }, 
    {
      pos: [5, 4, 11], 
      state: 10
    }, 
    {
      pos: [6, 4, 11], 
      state: 10
    }, 
    {
      pos: [7, 4, 11], 
      state: 10
    }, 
    {
      pos: [8, 4, 11], 
      state: 10
    }, 
    {
      pos: [9, 4, 11], 
      state: 10
    }, 
    {
      pos: [0, 5, 11], 
      state: 10
    }, 
    {
      pos: [1, 5, 11], 
      state: 16
    }, 
    {
      pos: [2, 5, 11], 
      state: 10
    }, 
    {
      pos: [3, 5, 11], 
      state: 10
    }, 
    {
      pos: [4, 5, 11], 
      state: 10
    }, 
    {
      pos: [5, 5, 11], 
      state: 10
    }, 
    {
      pos: [6, 5, 11], 
      state: 10
    }, 
    {
      pos: [7, 5, 11], 
      state: 10
    }, 
    {
      pos: [8, 5, 11], 
      state: 10
    }, 
    {
      pos: [9, 5, 11], 
      state: 10
    }
  ], 
  palette: [
    {
      Name: "minecraft:sand"
    }, 
    {
      Name: "minecraft:smooth_sandstone"
    }, 
    {
      Properties: {
        facing: "north"
      }, 
      Name: "minecraft:lime_glazed_terracotta"
    }, 
    {
      Properties: {
        facing: "east"
      }, 
      Name: "minecraft:lime_glazed_terracotta"
    }, 
    {
      Properties: {
        waterlogged: "false", 
        type: "double"
      }, 
      Name: "minecraft:smooth_sandstone_slab"
    }, 
    {
      Properties: {
        facing: "west"
      }, 
      Name: "minecraft:lime_glazed_terracotta"
    }, 
    {
      Properties: {
        facing: "south"
      }, 
      Name: "minecraft:lime_glazed_terracotta"
    }, 
    {
      Properties: {
        has_bottle_0: "false", 
        has_bottle_1: "false", 
        has_bottle_2: "false"
      }, 
      Name: "minecraft:brewing_stand"
    }, 
    {
      Properties: {
        facing: "west"
      }, 
      Name: "minecraft:jigsaw"
    }, 
    {
      Properties: {
        half: "bottom", 
        waterlogged: "false", 
        shape: "straight", 
        facing: "east"
      }, 
      Name: "minecraft:smooth_sandstone_stairs"
    }, 
    {
      Name: "minecraft:air"
    }, 
    {
      Properties: {
        waterlogged: "false", 
        type: "bottom"
      }, 
      Name: "minecraft:sandstone_slab"
    }, 
    {
      Properties: {
        waterlogged: "false", 
        type: "top"
      }, 
      Name: "minecraft:sandstone_slab"
    }, 
    {
      Properties: {
        waterlogged: "false", 
        type: "bottom"
      }, 
      Name: "minecraft:smooth_sandstone_slab"
    }, 
    {
      Properties: {
        half: "bottom", 
        waterlogged: "false", 
        shape: "straight", 
        facing: "south"
      }, 
      Name: "minecraft:smooth_sandstone_stairs"
    }, 
    {
      Properties: {
        waterlogged: "false", 
        type: "top"
      }, 
      Name: "minecraft:smooth_sandstone_slab"
    }, 
    {
      Properties: {
        half: "bottom", 
        waterlogged: "false", 
        shape: "straight", 
        facing: "north"
      }, 
      Name: "minecraft:smooth_sandstone_stairs"
    }, 
    {
      Name: "minecraft:potted_cactus"
    }, 
    {
      Properties: {
        facing: "west"
      }, 
      Name: "minecraft:wall_torch"
    }, 
    {
      Properties: {
        half: "top", 
        waterlogged: "false", 
        shape: "straight", 
        facing: "north"
      }, 
      Name: "minecraft:smooth_sandstone_stairs"
    }, 
    {
      Properties: {
        facing: "south"
      }, 
      Name: "minecraft:wall_torch"
    }, 
    {
      Properties: {
        half: "top", 
        waterlogged: "false", 
        shape: "straight", 
        facing: "south"
      }, 
      Name: "minecraft:smooth_sandstone_stairs"
    }, 
    {
      Properties: {
        facing: "north"
      }, 
      Name: "minecraft:wall_torch"
    }
  ]
}
