{
  size: [6, 12, 12], 
  entities: [], 
  blocks: [
    {
      pos: [1, 0, 0], 
      state: 0
    }, 
    {
      pos: [2, 0, 0], 
      state: 0
    }, 
    {
      pos: [3, 0, 0], 
      state: 0
    }, 
    {
      pos: [4, 0, 0], 
      state: 0
    }, 
    {
      pos: [5, 0, 0], 
      state: 0
    }, 
    {
      pos: [1, 0, 1], 
      state: 0
    }, 
    {
      pos: [2, 0, 1], 
      state: 1
    }, 
    {
      pos: [3, 0, 1], 
      state: 1
    }, 
    {
      pos: [4, 0, 1], 
      state: 1
    }, 
    {
      pos: [5, 0, 1], 
      state: 0
    }, 
    {
      pos: [1, 0, 2], 
      state: 0
    }, 
    {
      pos: [2, 0, 2], 
      state: 1
    }, 
    {
      pos: [3, 0, 2], 
      state: 1
    }, 
    {
      pos: [4, 0, 2], 
      state: 1
    }, 
    {
      pos: [5, 0, 2], 
      state: 0
    }, 
    {
      pos: [0, 0, 3], 
      state: 1
    }, 
    {
      pos: [1, 0, 3], 
      state: 1
    }, 
    {
      pos: [2, 0, 3], 
      state: 1
    }, 
    {
      pos: [3, 0, 3], 
      state: 1
    }, 
    {
      pos: [4, 0, 3], 
      state: 1
    }, 
    {
      pos: [5, 0, 3], 
      state: 0
    }, 
    {
      pos: [1, 0, 4], 
      state: 0
    }, 
    {
      pos: [2, 0, 4], 
      state: 1
    }, 
    {
      pos: [3, 0, 4], 
      state: 1
    }, 
    {
      pos: [4, 0, 4], 
      state: 1
    }, 
    {
      pos: [5, 0, 4], 
      state: 0
    }, 
    {
      pos: [1, 0, 5], 
      state: 0
    }, 
    {
      pos: [2, 0, 5], 
      state: 1
    }, 
    {
      pos: [3, 0, 5], 
      state: 1
    }, 
    {
      pos: [4, 0, 5], 
      state: 1
    }, 
    {
      pos: [5, 0, 5], 
      state: 0
    }, 
    {
      pos: [1, 0, 6], 
      state: 0
    }, 
    {
      pos: [2, 0, 6], 
      state: 1
    }, 
    {
      pos: [3, 0, 6], 
      state: 1
    }, 
    {
      pos: [4, 0, 6], 
      state: 1
    }, 
    {
      pos: [5, 0, 6], 
      state: 0
    }, 
    {
      pos: [1, 0, 7], 
      state: 0
    }, 
    {
      pos: [2, 0, 7], 
      state: 1
    }, 
    {
      pos: [3, 0, 7], 
      state: 1
    }, 
    {
      pos: [4, 0, 7], 
      state: 1
    }, 
    {
      pos: [5, 0, 7], 
      state: 0
    }, 
    {
      pos: [1, 0, 8], 
      state: 0
    }, 
    {
      pos: [2, 0, 8], 
      state: 1
    }, 
    {
      pos: [3, 0, 8], 
      state: 1
    }, 
    {
      pos: [4, 0, 8], 
      state: 1
    }, 
    {
      pos: [5, 0, 8], 
      state: 0
    }, 
    {
      pos: [2, 0, 9], 
      state: 0
    }, 
    {
      pos: [3, 0, 9], 
      state: 1
    }, 
    {
      pos: [4, 0, 9], 
      state: 0
    }, 
    {
      pos: [2, 0, 10], 
      state: 0
    }, 
    {
      pos: [3, 0, 10], 
      state: 1
    }, 
    {
      pos: [4, 0, 10], 
      state: 0
    }, 
    {
      pos: [2, 0, 11], 
      state: 0
    }, 
    {
      pos: [3, 0, 11], 
      state: 0
    }, 
    {
      pos: [4, 0, 11], 
      state: 0
    }, 
    {
      pos: [1, 1, 0], 
      state: 2
    }, 
    {
      pos: [2, 1, 0], 
      state: 1
    }, 
    {
      pos: [3, 1, 0], 
      state: 1
    }, 
    {
      pos: [4, 1, 0], 
      state: 1
    }, 
    {
      pos: [5, 1, 0], 
      state: 2
    }, 
    {
      pos: [1, 1, 1], 
      state: 1
    }, 
    {
      pos: [2, 1, 1], 
      state: 1
    }, 
    {
      pos: [3, 1, 1], 
      state: 3
    }, 
    {
      pos: [4, 1, 1], 
      state: 1
    }, 
    {
      pos: [5, 1, 1], 
      state: 1
    }, 
    {
      pos: [1, 1, 2], 
      state: 1
    }, 
    {
      pos: [5, 1, 2], 
      state: 1
    }, 
    {
      pos: [5, 1, 3], 
      state: 1
    }, 
    {
      pos: [1, 1, 4], 
      state: 1
    }, 
    {
      pos: [5, 1, 4], 
      state: 1
    }, 
    {
      pos: [1, 1, 5], 
      state: 1
    }, 
    {
      pos: [5, 1, 5], 
      state: 1
    }, 
    {
      pos: [1, 1, 6], 
      state: 1
    }, 
    {
      pos: [5, 1, 6], 
      state: 1
    }, 
    {
      pos: [1, 1, 7], 
      state: 1
    }, 
    {
      pos: [5, 1, 7], 
      state: 1
    }, 
    {
      pos: [1, 1, 8], 
      state: 2
    }, 
    {
      pos: [5, 1, 8], 
      state: 2
    }, 
    {
      pos: [2, 1, 9], 
      state: 2
    }, 
    {
      pos: [4, 1, 9], 
      state: 2
    }, 
    {
      pos: [2, 1, 10], 
      state: 1
    }, 
    {
      pos: [4, 1, 10], 
      state: 1
    }, 
    {
      pos: [2, 1, 11], 
      state: 2
    }, 
    {
      pos: [3, 1, 11], 
      state: 1
    }, 
    {
      pos: [4, 1, 11], 
      state: 2
    }, 
    {
      nbt: {
        target_pool: "minecraft:empty", 
        final_state: "minecraft:structure_void", 
        id: "minecraft:jigsaw", 
        attachement_type: "minecraft:building_entrance"
      }, 
      pos: [0, 1, 4], 
      state: 4
    }, 
    {
      pos: [0, 1, 0], 
      state: 5
    }, 
    {
      pos: [0, 1, 1], 
      state: 5
    }, 
    {
      pos: [0, 1, 2], 
      state: 5
    }, 
    {
      pos: [2, 1, 2], 
      state: 5
    }, 
    {
      pos: [3, 1, 2], 
      state: 5
    }, 
    {
      pos: [4, 1, 2], 
      state: 5
    }, 
    {
      pos: [0, 1, 3], 
      state: 5
    }, 
    {
      pos: [1, 1, 3], 
      state: 6
    }, 
    {
      pos: [2, 1, 3], 
      state: 5
    }, 
    {
      pos: [3, 1, 3], 
      state: 5
    }, 
    {
      pos: [4, 1, 3], 
      state: 5
    }, 
    {
      pos: [2, 1, 4], 
      state: 5
    }, 
    {
      pos: [3, 1, 4], 
      state: 5
    }, 
    {
      pos: [4, 1, 4], 
      state: 5
    }, 
    {
      pos: [0, 1, 5], 
      state: 5
    }, 
    {
      pos: [2, 1, 5], 
      state: 5
    }, 
    {
      pos: [3, 1, 5], 
      state: 5
    }, 
    {
      pos: [4, 1, 5], 
      state: 5
    }, 
    {
      pos: [0, 1, 6], 
      state: 5
    }, 
    {
      pos: [2, 1, 6], 
      state: 5
    }, 
    {
      pos: [3, 1, 6], 
      state: 5
    }, 
    {
      pos: [4, 1, 6], 
      state: 5
    }, 
    {
      pos: [0, 1, 7], 
      state: 5
    }, 
    {
      pos: [2, 1, 7], 
      state: 5
    }, 
    {
      pos: [3, 1, 7], 
      state: 5
    }, 
    {
      pos: [4, 1, 7], 
      state: 5
    }, 
    {
      pos: [0, 1, 8], 
      state: 5
    }, 
    {
      pos: [2, 1, 8], 
      state: 7
    }, 
    {
      pos: [3, 1, 8], 
      state: 5
    }, 
    {
      pos: [4, 1, 8], 
      state: 7
    }, 
    {
      pos: [0, 1, 9], 
      state: 5
    }, 
    {
      pos: [1, 1, 9], 
      state: 5
    }, 
    {
      pos: [3, 1, 9], 
      state: 8
    }, 
    {
      pos: [5, 1, 9], 
      state: 5
    }, 
    {
      pos: [0, 1, 10], 
      state: 5
    }, 
    {
      pos: [1, 1, 10], 
      state: 5
    }, 
    {
      pos: [3, 1, 10], 
      state: 5
    }, 
    {
      pos: [5, 1, 10], 
      state: 5
    }, 
    {
      pos: [0, 1, 11], 
      state: 5
    }, 
    {
      pos: [1, 1, 11], 
      state: 5
    }, 
    {
      pos: [5, 1, 11], 
      state: 5
    }, 
    {
      pos: [1, 2, 0], 
      state: 2
    }, 
    {
      pos: [2, 2, 0], 
      state: 1
    }, 
    {
      pos: [4, 2, 0], 
      state: 1
    }, 
    {
      pos: [5, 2, 0], 
      state: 2
    }, 
    {
      pos: [1, 2, 1], 
      state: 1
    }, 
    {
      pos: [5, 2, 1], 
      state: 1
    }, 
    {
      pos: [1, 2, 2], 
      state: 1
    }, 
    {
      pos: [5, 2, 2], 
      state: 1
    }, 
    {
      pos: [5, 2, 3], 
      state: 1
    }, 
    {
      pos: [1, 2, 4], 
      state: 1
    }, 
    {
      pos: [1, 2, 5], 
      state: 1
    }, 
    {
      pos: [5, 2, 5], 
      state: 1
    }, 
    {
      pos: [5, 2, 6], 
      state: 1
    }, 
    {
      pos: [1, 2, 7], 
      state: 1
    }, 
    {
      pos: [5, 2, 7], 
      state: 1
    }, 
    {
      pos: [1, 2, 8], 
      state: 2
    }, 
    {
      pos: [5, 2, 8], 
      state: 2
    }, 
    {
      pos: [2, 2, 9], 
      state: 2
    }, 
    {
      pos: [4, 2, 9], 
      state: 2
    }, 
    {
      pos: [2, 2, 10], 
      state: 1
    }, 
    {
      pos: [4, 2, 10], 
      state: 1
    }, 
    {
      pos: [2, 2, 11], 
      state: 2
    }, 
    {
      pos: [3, 2, 11], 
      state: 1
    }, 
    {
      pos: [4, 2, 11], 
      state: 2
    }, 
    {
      pos: [0, 2, 0], 
      state: 5
    }, 
    {
      pos: [3, 2, 0], 
      state: 9
    }, 
    {
      pos: [0, 2, 1], 
      state: 5
    }, 
    {
      pos: [2, 2, 1], 
      state: 5
    }, 
    {
      pos: [3, 2, 1], 
      state: 5
    }, 
    {
      pos: [4, 2, 1], 
      state: 5
    }, 
    {
      pos: [0, 2, 2], 
      state: 10
    }, 
    {
      pos: [2, 2, 2], 
      state: 5
    }, 
    {
      pos: [3, 2, 2], 
      state: 5
    }, 
    {
      pos: [4, 2, 2], 
      state: 10
    }, 
    {
      pos: [0, 2, 3], 
      state: 5
    }, 
    {
      pos: [1, 2, 3], 
      state: 11
    }, 
    {
      pos: [2, 2, 3], 
      state: 5
    }, 
    {
      pos: [3, 2, 3], 
      state: 5
    }, 
    {
      pos: [4, 2, 3], 
      state: 5
    }, 
    {
      pos: [0, 2, 4], 
      state: 5
    }, 
    {
      pos: [2, 2, 4], 
      state: 5
    }, 
    {
      pos: [3, 2, 4], 
      state: 5
    }, 
    {
      pos: [4, 2, 4], 
      state: 5
    }, 
    {
      pos: [5, 2, 4], 
      state: 9
    }, 
    {
      pos: [0, 2, 5], 
      state: 5
    }, 
    {
      pos: [2, 2, 5], 
      state: 5
    }, 
    {
      pos: [3, 2, 5], 
      state: 5
    }, 
    {
      pos: [4, 2, 5], 
      state: 5
    }, 
    {
      pos: [0, 2, 6], 
      state: 5
    }, 
    {
      pos: [1, 2, 6], 
      state: 9
    }, 
    {
      pos: [2, 2, 6], 
      state: 5
    }, 
    {
      pos: [3, 2, 6], 
      state: 5
    }, 
    {
      pos: [4, 2, 6], 
      state: 10
    }, 
    {
      pos: [0, 2, 7], 
      state: 5
    }, 
    {
      pos: [2, 2, 7], 
      state: 5
    }, 
    {
      pos: [3, 2, 7], 
      state: 5
    }, 
    {
      pos: [4, 2, 7], 
      state: 5
    }, 
    {
      pos: [0, 2, 8], 
      state: 5
    }, 
    {
      pos: [2, 2, 8], 
      state: 5
    }, 
    {
      pos: [3, 2, 8], 
      state: 5
    }, 
    {
      pos: [4, 2, 8], 
      state: 5
    }, 
    {
      pos: [0, 2, 9], 
      state: 5
    }, 
    {
      pos: [1, 2, 9], 
      state: 5
    }, 
    {
      pos: [3, 2, 9], 
      state: 12
    }, 
    {
      pos: [5, 2, 9], 
      state: 5
    }, 
    {
      pos: [0, 2, 10], 
      state: 5
    }, 
    {
      pos: [1, 2, 10], 
      state: 5
    }, 
    {
      pos: [3, 2, 10], 
      state: 13
    }, 
    {
      pos: [5, 2, 10], 
      state: 5
    }, 
    {
      pos: [0, 2, 11], 
      state: 5
    }, 
    {
      pos: [1, 2, 11], 
      state: 5
    }, 
    {
      pos: [5, 2, 11], 
      state: 5
    }, 
    {
      pos: [1, 3, 0], 
      state: 2
    }, 
    {
      pos: [2, 3, 0], 
      state: 1
    }, 
    {
      pos: [4, 3, 0], 
      state: 1
    }, 
    {
      pos: [5, 3, 0], 
      state: 2
    }, 
    {
      pos: [1, 3, 1], 
      state: 1
    }, 
    {
      pos: [5, 3, 1], 
      state: 1
    }, 
    {
      pos: [1, 3, 2], 
      state: 1
    }, 
    {
      pos: [5, 3, 2], 
      state: 1
    }, 
    {
      pos: [1, 3, 3], 
      state: 1
    }, 
    {
      pos: [5, 3, 3], 
      state: 1
    }, 
    {
      pos: [1, 3, 4], 
      state: 1
    }, 
    {
      pos: [1, 3, 5], 
      state: 1
    }, 
    {
      pos: [5, 3, 5], 
      state: 1
    }, 
    {
      pos: [5, 3, 6], 
      state: 1
    }, 
    {
      pos: [1, 3, 7], 
      state: 1
    }, 
    {
      pos: [5, 3, 7], 
      state: 1
    }, 
    {
      pos: [1, 3, 8], 
      state: 2
    }, 
    {
      pos: [5, 3, 8], 
      state: 2
    }, 
    {
      pos: [2, 3, 9], 
      state: 2
    }, 
    {
      pos: [3, 3, 9], 
      state: 1
    }, 
    {
      pos: [4, 3, 9], 
      state: 2
    }, 
    {
      pos: [2, 3, 10], 
      state: 1
    }, 
    {
      pos: [4, 3, 10], 
      state: 1
    }, 
    {
      pos: [2, 3, 11], 
      state: 2
    }, 
    {
      pos: [3, 3, 11], 
      state: 1
    }, 
    {
      pos: [4, 3, 11], 
      state: 2
    }, 
    {
      pos: [0, 3, 0], 
      state: 5
    }, 
    {
      pos: [3, 3, 0], 
      state: 14
    }, 
    {
      pos: [0, 3, 1], 
      state: 5
    }, 
    {
      pos: [2, 3, 1], 
      state: 14
    }, 
    {
      pos: [3, 3, 1], 
      state: 14
    }, 
    {
      pos: [4, 3, 1], 
      state: 14
    }, 
    {
      pos: [0, 3, 2], 
      state: 5
    }, 
    {
      pos: [2, 3, 2], 
      state: 14
    }, 
    {
      pos: [3, 3, 2], 
      state: 14
    }, 
    {
      pos: [4, 3, 2], 
      state: 14
    }, 
    {
      pos: [0, 3, 3], 
      state: 5
    }, 
    {
      pos: [2, 3, 3], 
      state: 14
    }, 
    {
      pos: [3, 3, 3], 
      state: 14
    }, 
    {
      pos: [4, 3, 3], 
      state: 14
    }, 
    {
      pos: [0, 3, 4], 
      state: 5
    }, 
    {
      pos: [2, 3, 4], 
      state: 14
    }, 
    {
      pos: [3, 3, 4], 
      state: 14
    }, 
    {
      pos: [4, 3, 4], 
      state: 14
    }, 
    {
      pos: [5, 3, 4], 
      state: 14
    }, 
    {
      pos: [0, 3, 5], 
      state: 5
    }, 
    {
      pos: [2, 3, 5], 
      state: 14
    }, 
    {
      pos: [3, 3, 5], 
      state: 14
    }, 
    {
      pos: [4, 3, 5], 
      state: 14
    }, 
    {
      pos: [0, 3, 6], 
      state: 5
    }, 
    {
      pos: [1, 3, 6], 
      state: 14
    }, 
    {
      pos: [2, 3, 6], 
      state: 14
    }, 
    {
      pos: [3, 3, 6], 
      state: 14
    }, 
    {
      pos: [4, 3, 6], 
      state: 14
    }, 
    {
      pos: [0, 3, 7], 
      state: 5
    }, 
    {
      pos: [2, 3, 7], 
      state: 14
    }, 
    {
      pos: [3, 3, 7], 
      state: 14
    }, 
    {
      pos: [4, 3, 7], 
      state: 14
    }, 
    {
      pos: [0, 3, 8], 
      state: 5
    }, 
    {
      pos: [2, 3, 8], 
      state: 14
    }, 
    {
      pos: [3, 3, 8], 
      state: 14
    }, 
    {
      pos: [4, 3, 8], 
      state: 14
    }, 
    {
      pos: [0, 3, 9], 
      state: 5
    }, 
    {
      pos: [1, 3, 9], 
      state: 5
    }, 
    {
      pos: [5, 3, 9], 
      state: 5
    }, 
    {
      pos: [0, 3, 10], 
      state: 5
    }, 
    {
      pos: [1, 3, 10], 
      state: 5
    }, 
    {
      pos: [3, 3, 10], 
      state: 13
    }, 
    {
      pos: [5, 3, 10], 
      state: 5
    }, 
    {
      pos: [0, 3, 11], 
      state: 5
    }, 
    {
      pos: [1, 3, 11], 
      state: 5
    }, 
    {
      pos: [5, 3, 11], 
      state: 5
    }, 
    {
      pos: [1, 4, 0], 
      state: 2
    }, 
    {
      pos: [5, 4, 0], 
      state: 2
    }, 
    {
      pos: [1, 4, 8], 
      state: 2
    }, 
    {
      pos: [5, 4, 8], 
      state: 2
    }, 
    {
      pos: [2, 4, 9], 
      state: 2
    }, 
    {
      pos: [3, 4, 9], 
      state: 1
    }, 
    {
      pos: [4, 4, 9], 
      state: 2
    }, 
    {
      pos: [2, 4, 10], 
      state: 1
    }, 
    {
      pos: [4, 4, 10], 
      state: 1
    }, 
    {
      pos: [2, 4, 11], 
      state: 2
    }, 
    {
      pos: [3, 4, 11], 
      state: 1
    }, 
    {
      pos: [4, 4, 11], 
      state: 2
    }, 
    {
      pos: [0, 4, 0], 
      state: 5
    }, 
    {
      pos: [2, 4, 0], 
      state: 5
    }, 
    {
      pos: [3, 4, 0], 
      state: 15
    }, 
    {
      pos: [4, 4, 0], 
      state: 5
    }, 
    {
      pos: [0, 4, 1], 
      state: 5
    }, 
    {
      pos: [1, 4, 1], 
      state: 5
    }, 
    {
      pos: [2, 4, 1], 
      state: 5
    }, 
    {
      pos: [3, 4, 1], 
      state: 5
    }, 
    {
      pos: [4, 4, 1], 
      state: 5
    }, 
    {
      pos: [5, 4, 1], 
      state: 5
    }, 
    {
      pos: [0, 4, 2], 
      state: 5
    }, 
    {
      pos: [1, 4, 2], 
      state: 15
    }, 
    {
      pos: [2, 4, 2], 
      state: 5
    }, 
    {
      pos: [3, 4, 2], 
      state: 5
    }, 
    {
      pos: [4, 4, 2], 
      state: 5
    }, 
    {
      pos: [5, 4, 2], 
      state: 15
    }, 
    {
      pos: [0, 4, 3], 
      state: 5
    }, 
    {
      pos: [1, 4, 3], 
      state: 5
    }, 
    {
      pos: [2, 4, 3], 
      state: 5
    }, 
    {
      pos: [3, 4, 3], 
      state: 5
    }, 
    {
      pos: [4, 4, 3], 
      state: 5
    }, 
    {
      pos: [5, 4, 3], 
      state: 5
    }, 
    {
      pos: [0, 4, 4], 
      state: 5
    }, 
    {
      pos: [1, 4, 4], 
      state: 15
    }, 
    {
      pos: [2, 4, 4], 
      state: 5
    }, 
    {
      pos: [3, 4, 4], 
      state: 5
    }, 
    {
      pos: [4, 4, 4], 
      state: 5
    }, 
    {
      pos: [5, 4, 4], 
      state: 15
    }, 
    {
      pos: [0, 4, 5], 
      state: 5
    }, 
    {
      pos: [1, 4, 5], 
      state: 5
    }, 
    {
      pos: [2, 4, 5], 
      state: 5
    }, 
    {
      pos: [3, 4, 5], 
      state: 5
    }, 
    {
      pos: [4, 4, 5], 
      state: 5
    }, 
    {
      pos: [5, 4, 5], 
      state: 5
    }, 
    {
      pos: [0, 4, 6], 
      state: 5
    }, 
    {
      pos: [1, 4, 6], 
      state: 15
    }, 
    {
      pos: [2, 4, 6], 
      state: 5
    }, 
    {
      pos: [3, 4, 6], 
      state: 5
    }, 
    {
      pos: [4, 4, 6], 
      state: 5
    }, 
    {
      pos: [5, 4, 6], 
      state: 15
    }, 
    {
      pos: [0, 4, 7], 
      state: 5
    }, 
    {
      pos: [1, 4, 7], 
      state: 5
    }, 
    {
      pos: [2, 4, 7], 
      state: 5
    }, 
    {
      pos: [3, 4, 7], 
      state: 5
    }, 
    {
      pos: [4, 4, 7], 
      state: 5
    }, 
    {
      pos: [5, 4, 7], 
      state: 5
    }, 
    {
      pos: [0, 4, 8], 
      state: 5
    }, 
    {
      pos: [2, 4, 8], 
      state: 5
    }, 
    {
      pos: [3, 4, 8], 
      state: 5
    }, 
    {
      pos: [4, 4, 8], 
      state: 5
    }, 
    {
      pos: [0, 4, 9], 
      state: 5
    }, 
    {
      pos: [1, 4, 9], 
      state: 5
    }, 
    {
      pos: [5, 4, 9], 
      state: 5
    }, 
    {
      pos: [0, 4, 10], 
      state: 5
    }, 
    {
      pos: [1, 4, 10], 
      state: 5
    }, 
    {
      pos: [3, 4, 10], 
      state: 13
    }, 
    {
      pos: [5, 4, 10], 
      state: 5
    }, 
    {
      pos: [0, 4, 11], 
      state: 5
    }, 
    {
      pos: [1, 4, 11], 
      state: 5
    }, 
    {
      pos: [5, 4, 11], 
      state: 5
    }, 
    {
      pos: [2, 5, 9], 
      state: 2
    }, 
    {
      pos: [3, 5, 9], 
      state: 1
    }, 
    {
      pos: [4, 5, 9], 
      state: 2
    }, 
    {
      pos: [2, 5, 10], 
      state: 1
    }, 
    {
      pos: [4, 5, 10], 
      state: 1
    }, 
    {
      pos: [2, 5, 11], 
      state: 2
    }, 
    {
      pos: [3, 5, 11], 
      state: 1
    }, 
    {
      pos: [4, 5, 11], 
      state: 2
    }, 
    {
      pos: [0, 5, 0], 
      state: 5
    }, 
    {
      pos: [1, 5, 0], 
      state: 5
    }, 
    {
      pos: [2, 5, 0], 
      state: 5
    }, 
    {
      pos: [3, 5, 0], 
      state: 5
    }, 
    {
      pos: [4, 5, 0], 
      state: 5
    }, 
    {
      pos: [5, 5, 0], 
      state: 5
    }, 
    {
      pos: [0, 5, 1], 
      state: 5
    }, 
    {
      pos: [1, 5, 1], 
      state: 5
    }, 
    {
      pos: [2, 5, 1], 
      state: 5
    }, 
    {
      pos: [3, 5, 1], 
      state: 5
    }, 
    {
      pos: [4, 5, 1], 
      state: 5
    }, 
    {
      pos: [5, 5, 1], 
      state: 5
    }, 
    {
      pos: [0, 5, 2], 
      state: 5
    }, 
    {
      pos: [1, 5, 2], 
      state: 5
    }, 
    {
      pos: [2, 5, 2], 
      state: 5
    }, 
    {
      pos: [3, 5, 2], 
      state: 5
    }, 
    {
      pos: [4, 5, 2], 
      state: 5
    }, 
    {
      pos: [5, 5, 2], 
      state: 5
    }, 
    {
      pos: [0, 5, 3], 
      state: 5
    }, 
    {
      pos: [1, 5, 3], 
      state: 5
    }, 
    {
      pos: [2, 5, 3], 
      state: 5
    }, 
    {
      pos: [3, 5, 3], 
      state: 5
    }, 
    {
      pos: [4, 5, 3], 
      state: 5
    }, 
    {
      pos: [5, 5, 3], 
      state: 5
    }, 
    {
      pos: [0, 5, 4], 
      state: 5
    }, 
    {
      pos: [1, 5, 4], 
      state: 5
    }, 
    {
      pos: [2, 5, 4], 
      state: 5
    }, 
    {
      pos: [3, 5, 4], 
      state: 5
    }, 
    {
      pos: [4, 5, 4], 
      state: 5
    }, 
    {
      pos: [5, 5, 4], 
      state: 5
    }, 
    {
      pos: [0, 5, 5], 
      state: 5
    }, 
    {
      pos: [1, 5, 5], 
      state: 5
    }, 
    {
      pos: [2, 5, 5], 
      state: 5
    }, 
    {
      pos: [3, 5, 5], 
      state: 5
    }, 
    {
      pos: [4, 5, 5], 
      state: 5
    }, 
    {
      pos: [5, 5, 5], 
      state: 5
    }, 
    {
      pos: [0, 5, 6], 
      state: 5
    }, 
    {
      pos: [1, 5, 6], 
      state: 5
    }, 
    {
      pos: [2, 5, 6], 
      state: 5
    }, 
    {
      pos: [3, 5, 6], 
      state: 5
    }, 
    {
      pos: [4, 5, 6], 
      state: 5
    }, 
    {
      pos: [5, 5, 6], 
      state: 5
    }, 
    {
      pos: [0, 5, 7], 
      state: 5
    }, 
    {
      pos: [1, 5, 7], 
      state: 5
    }, 
    {
      pos: [2, 5, 7], 
      state: 5
    }, 
    {
      pos: [3, 5, 7], 
      state: 5
    }, 
    {
      pos: [4, 5, 7], 
      state: 5
    }, 
    {
      pos: [5, 5, 7], 
      state: 5
    }, 
    {
      pos: [0, 5, 8], 
      state: 5
    }, 
    {
      pos: [1, 5, 8], 
      state: 5
    }, 
    {
      pos: [2, 5, 8], 
      state: 5
    }, 
    {
      pos: [3, 5, 8], 
      state: 5
    }, 
    {
      pos: [4, 5, 8], 
      state: 5
    }, 
    {
      pos: [5, 5, 8], 
      state: 5
    }, 
    {
      pos: [0, 5, 9], 
      state: 5
    }, 
    {
      pos: [1, 5, 9], 
      state: 5
    }, 
    {
      pos: [5, 5, 9], 
      state: 5
    }, 
    {
      pos: [0, 5, 10], 
      state: 5
    }, 
    {
      pos: [1, 5, 10], 
      state: 5
    }, 
    {
      pos: [3, 5, 10], 
      state: 13
    }, 
    {
      pos: [5, 5, 10], 
      state: 5
    }, 
    {
      pos: [0, 5, 11], 
      state: 5
    }, 
    {
      pos: [1, 5, 11], 
      state: 5
    }, 
    {
      pos: [5, 5, 11], 
      state: 5
    }, 
    {
      pos: [2, 6, 9], 
      state: 2
    }, 
    {
      pos: [3, 6, 9], 
      state: 1
    }, 
    {
      pos: [4, 6, 9], 
      state: 2
    }, 
    {
      pos: [2, 6, 10], 
      state: 1
    }, 
    {
      pos: [4, 6, 10], 
      state: 1
    }, 
    {
      pos: [2, 6, 11], 
      state: 2
    }, 
    {
      pos: [3, 6, 11], 
      state: 1
    }, 
    {
      pos: [4, 6, 11], 
      state: 2
    }, 
    {
      pos: [0, 6, 0], 
      state: 5
    }, 
    {
      pos: [1, 6, 0], 
      state: 5
    }, 
    {
      pos: [2, 6, 0], 
      state: 5
    }, 
    {
      pos: [3, 6, 0], 
      state: 5
    }, 
    {
      pos: [4, 6, 0], 
      state: 5
    }, 
    {
      pos: [5, 6, 0], 
      state: 5
    }, 
    {
      pos: [0, 6, 1], 
      state: 5
    }, 
    {
      pos: [1, 6, 1], 
      state: 5
    }, 
    {
      pos: [2, 6, 1], 
      state: 5
    }, 
    {
      pos: [3, 6, 1], 
      state: 5
    }, 
    {
      pos: [4, 6, 1], 
      state: 5
    }, 
    {
      pos: [5, 6, 1], 
      state: 5
    }, 
    {
      pos: [0, 6, 2], 
      state: 5
    }, 
    {
      pos: [1, 6, 2], 
      state: 5
    }, 
    {
      pos: [2, 6, 2], 
      state: 5
    }, 
    {
      pos: [3, 6, 2], 
      state: 5
    }, 
    {
      pos: [4, 6, 2], 
      state: 5
    }, 
    {
      pos: [5, 6, 2], 
      state: 5
    }, 
    {
      pos: [0, 6, 3], 
      state: 5
    }, 
    {
      pos: [1, 6, 3], 
      state: 5
    }, 
    {
      pos: [2, 6, 3], 
      state: 5
    }, 
    {
      pos: [3, 6, 3], 
      state: 5
    }, 
    {
      pos: [4, 6, 3], 
      state: 5
    }, 
    {
      pos: [5, 6, 3], 
      state: 5
    }, 
    {
      pos: [0, 6, 4], 
      state: 5
    }, 
    {
      pos: [1, 6, 4], 
      state: 5
    }, 
    {
      pos: [2, 6, 4], 
      state: 5
    }, 
    {
      pos: [3, 6, 4], 
      state: 5
    }, 
    {
      pos: [4, 6, 4], 
      state: 5
    }, 
    {
      pos: [5, 6, 4], 
      state: 5
    }, 
    {
      pos: [0, 6, 5], 
      state: 5
    }, 
    {
      pos: [1, 6, 5], 
      state: 5
    }, 
    {
      pos: [2, 6, 5], 
      state: 5
    }, 
    {
      pos: [3, 6, 5], 
      state: 5
    }, 
    {
      pos: [4, 6, 5], 
      state: 5
    }, 
    {
      pos: [5, 6, 5], 
      state: 5
    }, 
    {
      pos: [0, 6, 6], 
      state: 5
    }, 
    {
      pos: [1, 6, 6], 
      state: 5
    }, 
    {
      pos: [2, 6, 6], 
      state: 5
    }, 
    {
      pos: [3, 6, 6], 
      state: 5
    }, 
    {
      pos: [4, 6, 6], 
      state: 5
    }, 
    {
      pos: [5, 6, 6], 
      state: 5
    }, 
    {
      pos: [0, 6, 7], 
      state: 5
    }, 
    {
      pos: [1, 6, 7], 
      state: 5
    }, 
    {
      pos: [2, 6, 7], 
      state: 5
    }, 
    {
      pos: [3, 6, 7], 
      state: 5
    }, 
    {
      pos: [4, 6, 7], 
      state: 5
    }, 
    {
      pos: [5, 6, 7], 
      state: 5
    }, 
    {
      pos: [0, 6, 8], 
      state: 5
    }, 
    {
      pos: [1, 6, 8], 
      state: 5
    }, 
    {
      pos: [2, 6, 8], 
      state: 5
    }, 
    {
      pos: [3, 6, 8], 
      state: 5
    }, 
    {
      pos: [4, 6, 8], 
      state: 5
    }, 
    {
      pos: [5, 6, 8], 
      state: 5
    }, 
    {
      pos: [0, 6, 9], 
      state: 5
    }, 
    {
      pos: [1, 6, 9], 
      state: 5
    }, 
    {
      pos: [5, 6, 9], 
      state: 5
    }, 
    {
      pos: [0, 6, 10], 
      state: 5
    }, 
    {
      pos: [1, 6, 10], 
      state: 5
    }, 
    {
      pos: [3, 6, 10], 
      state: 13
    }, 
    {
      pos: [5, 6, 10], 
      state: 5
    }, 
    {
      pos: [0, 6, 11], 
      state: 5
    }, 
    {
      pos: [1, 6, 11], 
      state: 5
    }, 
    {
      pos: [5, 6, 11], 
      state: 5
    }, 
    {
      pos: [2, 7, 9], 
      state: 2
    }, 
    {
      pos: [3, 7, 9], 
      state: 1
    }, 
    {
      pos: [4, 7, 9], 
      state: 2
    }, 
    {
      pos: [2, 7, 10], 
      state: 1
    }, 
    {
      pos: [4, 7, 10], 
      state: 1
    }, 
    {
      pos: [2, 7, 11], 
      state: 2
    }, 
    {
      pos: [3, 7, 11], 
      state: 1
    }, 
    {
      pos: [4, 7, 11], 
      state: 2
    }, 
    {
      pos: [0, 7, 0], 
      state: 5
    }, 
    {
      pos: [1, 7, 0], 
      state: 5
    }, 
    {
      pos: [2, 7, 0], 
      state: 5
    }, 
    {
      pos: [3, 7, 0], 
      state: 5
    }, 
    {
      pos: [4, 7, 0], 
      state: 5
    }, 
    {
      pos: [5, 7, 0], 
      state: 5
    }, 
    {
      pos: [0, 7, 1], 
      state: 5
    }, 
    {
      pos: [1, 7, 1], 
      state: 5
    }, 
    {
      pos: [2, 7, 1], 
      state: 5
    }, 
    {
      pos: [3, 7, 1], 
      state: 5
    }, 
    {
      pos: [4, 7, 1], 
      state: 5
    }, 
    {
      pos: [5, 7, 1], 
      state: 5
    }, 
    {
      pos: [0, 7, 2], 
      state: 5
    }, 
    {
      pos: [1, 7, 2], 
      state: 5
    }, 
    {
      pos: [2, 7, 2], 
      state: 5
    }, 
    {
      pos: [3, 7, 2], 
      state: 5
    }, 
    {
      pos: [4, 7, 2], 
      state: 5
    }, 
    {
      pos: [5, 7, 2], 
      state: 5
    }, 
    {
      pos: [0, 7, 3], 
      state: 5
    }, 
    {
      pos: [1, 7, 3], 
      state: 5
    }, 
    {
      pos: [2, 7, 3], 
      state: 5
    }, 
    {
      pos: [3, 7, 3], 
      state: 5
    }, 
    {
      pos: [4, 7, 3], 
      state: 5
    }, 
    {
      pos: [5, 7, 3], 
      state: 5
    }, 
    {
      pos: [0, 7, 4], 
      state: 5
    }, 
    {
      pos: [1, 7, 4], 
      state: 5
    }, 
    {
      pos: [2, 7, 4], 
      state: 5
    }, 
    {
      pos: [3, 7, 4], 
      state: 5
    }, 
    {
      pos: [4, 7, 4], 
      state: 5
    }, 
    {
      pos: [5, 7, 4], 
      state: 5
    }, 
    {
      pos: [0, 7, 5], 
      state: 5
    }, 
    {
      pos: [1, 7, 5], 
      state: 5
    }, 
    {
      pos: [2, 7, 5], 
      state: 5
    }, 
    {
      pos: [3, 7, 5], 
      state: 5
    }, 
    {
      pos: [4, 7, 5], 
      state: 5
    }, 
    {
      pos: [5, 7, 5], 
      state: 5
    }, 
    {
      pos: [0, 7, 6], 
      state: 5
    }, 
    {
      pos: [1, 7, 6], 
      state: 5
    }, 
    {
      pos: [2, 7, 6], 
      state: 5
    }, 
    {
      pos: [3, 7, 6], 
      state: 5
    }, 
    {
      pos: [4, 7, 6], 
      state: 5
    }, 
    {
      pos: [5, 7, 6], 
      state: 5
    }, 
    {
      pos: [0, 7, 7], 
      state: 5
    }, 
    {
      pos: [1, 7, 7], 
      state: 5
    }, 
    {
      pos: [2, 7, 7], 
      state: 5
    }, 
    {
      pos: [3, 7, 7], 
      state: 5
    }, 
    {
      pos: [4, 7, 7], 
      state: 5
    }, 
    {
      pos: [5, 7, 7], 
      state: 5
    }, 
    {
      pos: [0, 7, 8], 
      state: 5
    }, 
    {
      pos: [1, 7, 8], 
      state: 5
    }, 
    {
      pos: [2, 7, 8], 
      state: 5
    }, 
    {
      pos: [3, 7, 8], 
      state: 5
    }, 
    {
      pos: [4, 7, 8], 
      state: 5
    }, 
    {
      pos: [5, 7, 8], 
      state: 5
    }, 
    {
      pos: [0, 7, 9], 
      state: 5
    }, 
    {
      pos: [1, 7, 9], 
      state: 5
    }, 
    {
      pos: [5, 7, 9], 
      state: 5
    }, 
    {
      pos: [0, 7, 10], 
      state: 5
    }, 
    {
      pos: [1, 7, 10], 
      state: 5
    }, 
    {
      pos: [3, 7, 10], 
      state: 16
    }, 
    {
      pos: [5, 7, 10], 
      state: 5
    }, 
    {
      pos: [0, 7, 11], 
      state: 5
    }, 
    {
      pos: [1, 7, 11], 
      state: 5
    }, 
    {
      pos: [5, 7, 11], 
      state: 5
    }, 
    {
      pos: [2, 8, 9], 
      state: 2
    }, 
    {
      pos: [3, 8, 9], 
      state: 1
    }, 
    {
      pos: [4, 8, 9], 
      state: 2
    }, 
    {
      pos: [2, 8, 10], 
      state: 1
    }, 
    {
      pos: [4, 8, 10], 
      state: 1
    }, 
    {
      pos: [2, 8, 11], 
      state: 2
    }, 
    {
      pos: [3, 8, 11], 
      state: 1
    }, 
    {
      pos: [4, 8, 11], 
      state: 2
    }, 
    {
      pos: [0, 8, 0], 
      state: 5
    }, 
    {
      pos: [1, 8, 0], 
      state: 5
    }, 
    {
      pos: [2, 8, 0], 
      state: 5
    }, 
    {
      pos: [3, 8, 0], 
      state: 5
    }, 
    {
      pos: [4, 8, 0], 
      state: 5
    }, 
    {
      pos: [5, 8, 0], 
      state: 5
    }, 
    {
      pos: [0, 8, 1], 
      state: 5
    }, 
    {
      pos: [1, 8, 1], 
      state: 5
    }, 
    {
      pos: [2, 8, 1], 
      state: 5
    }, 
    {
      pos: [3, 8, 1], 
      state: 5
    }, 
    {
      pos: [4, 8, 1], 
      state: 5
    }, 
    {
      pos: [5, 8, 1], 
      state: 5
    }, 
    {
      pos: [0, 8, 2], 
      state: 5
    }, 
    {
      pos: [1, 8, 2], 
      state: 5
    }, 
    {
      pos: [2, 8, 2], 
      state: 5
    }, 
    {
      pos: [3, 8, 2], 
      state: 5
    }, 
    {
      pos: [4, 8, 2], 
      state: 5
    }, 
    {
      pos: [5, 8, 2], 
      state: 5
    }, 
    {
      pos: [0, 8, 3], 
      state: 5
    }, 
    {
      pos: [1, 8, 3], 
      state: 5
    }, 
    {
      pos: [2, 8, 3], 
      state: 5
    }, 
    {
      pos: [3, 8, 3], 
      state: 5
    }, 
    {
      pos: [4, 8, 3], 
      state: 5
    }, 
    {
      pos: [5, 8, 3], 
      state: 5
    }, 
    {
      pos: [0, 8, 4], 
      state: 5
    }, 
    {
      pos: [1, 8, 4], 
      state: 5
    }, 
    {
      pos: [2, 8, 4], 
      state: 5
    }, 
    {
      pos: [3, 8, 4], 
      state: 5
    }, 
    {
      pos: [4, 8, 4], 
      state: 5
    }, 
    {
      pos: [5, 8, 4], 
      state: 5
    }, 
    {
      pos: [0, 8, 5], 
      state: 5
    }, 
    {
      pos: [1, 8, 5], 
      state: 5
    }, 
    {
      pos: [2, 8, 5], 
      state: 5
    }, 
    {
      pos: [3, 8, 5], 
      state: 5
    }, 
    {
      pos: [4, 8, 5], 
      state: 5
    }, 
    {
      pos: [5, 8, 5], 
      state: 5
    }, 
    {
      pos: [0, 8, 6], 
      state: 5
    }, 
    {
      pos: [1, 8, 6], 
      state: 5
    }, 
    {
      pos: [2, 8, 6], 
      state: 5
    }, 
    {
      pos: [3, 8, 6], 
      state: 5
    }, 
    {
      pos: [4, 8, 6], 
      state: 5
    }, 
    {
      pos: [5, 8, 6], 
      state: 5
    }, 
    {
      pos: [0, 8, 7], 
      state: 5
    }, 
    {
      pos: [1, 8, 7], 
      state: 5
    }, 
    {
      pos: [2, 8, 7], 
      state: 5
    }, 
    {
      pos: [3, 8, 7], 
      state: 5
    }, 
    {
      pos: [4, 8, 7], 
      state: 5
    }, 
    {
      pos: [5, 8, 7], 
      state: 5
    }, 
    {
      pos: [0, 8, 8], 
      state: 5
    }, 
    {
      pos: [1, 8, 8], 
      state: 5
    }, 
    {
      pos: [2, 8, 8], 
      state: 5
    }, 
    {
      pos: [3, 8, 8], 
      state: 5
    }, 
    {
      pos: [4, 8, 8], 
      state: 5
    }, 
    {
      pos: [5, 8, 8], 
      state: 5
    }, 
    {
      pos: [0, 8, 9], 
      state: 5
    }, 
    {
      pos: [1, 8, 9], 
      state: 5
    }, 
    {
      pos: [5, 8, 9], 
      state: 5
    }, 
    {
      pos: [0, 8, 10], 
      state: 5
    }, 
    {
      pos: [1, 8, 10], 
      state: 5
    }, 
    {
      pos: [3, 8, 10], 
      state: 5
    }, 
    {
      pos: [5, 8, 10], 
      state: 5
    }, 
    {
      pos: [0, 8, 11], 
      state: 5
    }, 
    {
      pos: [1, 8, 11], 
      state: 5
    }, 
    {
      pos: [5, 8, 11], 
      state: 5
    }, 
    {
      pos: [2, 9, 9], 
      state: 2
    }, 
    {
      pos: [4, 9, 9], 
      state: 2
    }, 
    {
      pos: [3, 9, 10], 
      state: 17
    }, 
    {
      pos: [2, 9, 11], 
      state: 2
    }, 
    {
      pos: [4, 9, 11], 
      state: 2
    }, 
    {
      pos: [0, 9, 0], 
      state: 5
    }, 
    {
      pos: [1, 9, 0], 
      state: 5
    }, 
    {
      pos: [2, 9, 0], 
      state: 5
    }, 
    {
      pos: [3, 9, 0], 
      state: 5
    }, 
    {
      pos: [4, 9, 0], 
      state: 5
    }, 
    {
      pos: [5, 9, 0], 
      state: 5
    }, 
    {
      pos: [0, 9, 1], 
      state: 5
    }, 
    {
      pos: [1, 9, 1], 
      state: 5
    }, 
    {
      pos: [2, 9, 1], 
      state: 5
    }, 
    {
      pos: [3, 9, 1], 
      state: 5
    }, 
    {
      pos: [4, 9, 1], 
      state: 5
    }, 
    {
      pos: [5, 9, 1], 
      state: 5
    }, 
    {
      pos: [0, 9, 2], 
      state: 5
    }, 
    {
      pos: [1, 9, 2], 
      state: 5
    }, 
    {
      pos: [2, 9, 2], 
      state: 5
    }, 
    {
      pos: [3, 9, 2], 
      state: 5
    }, 
    {
      pos: [4, 9, 2], 
      state: 5
    }, 
    {
      pos: [5, 9, 2], 
      state: 5
    }, 
    {
      pos: [0, 9, 3], 
      state: 5
    }, 
    {
      pos: [1, 9, 3], 
      state: 5
    }, 
    {
      pos: [2, 9, 3], 
      state: 5
    }, 
    {
      pos: [3, 9, 3], 
      state: 5
    }, 
    {
      pos: [4, 9, 3], 
      state: 5
    }, 
    {
      pos: [5, 9, 3], 
      state: 5
    }, 
    {
      pos: [0, 9, 4], 
      state: 5
    }, 
    {
      pos: [1, 9, 4], 
      state: 5
    }, 
    {
      pos: [2, 9, 4], 
      state: 5
    }, 
    {
      pos: [3, 9, 4], 
      state: 5
    }, 
    {
      pos: [4, 9, 4], 
      state: 5
    }, 
    {
      pos: [5, 9, 4], 
      state: 5
    }, 
    {
      pos: [0, 9, 5], 
      state: 5
    }, 
    {
      pos: [1, 9, 5], 
      state: 5
    }, 
    {
      pos: [2, 9, 5], 
      state: 5
    }, 
    {
      pos: [3, 9, 5], 
      state: 5
    }, 
    {
      pos: [4, 9, 5], 
      state: 5
    }, 
    {
      pos: [5, 9, 5], 
      state: 5
    }, 
    {
      pos: [0, 9, 6], 
      state: 5
    }, 
    {
      pos: [1, 9, 6], 
      state: 5
    }, 
    {
      pos: [2, 9, 6], 
      state: 5
    }, 
    {
      pos: [3, 9, 6], 
      state: 5
    }, 
    {
      pos: [4, 9, 6], 
      state: 5
    }, 
    {
      pos: [5, 9, 6], 
      state: 5
    }, 
    {
      pos: [0, 9, 7], 
      state: 5
    }, 
    {
      pos: [1, 9, 7], 
      state: 5
    }, 
    {
      pos: [2, 9, 7], 
      state: 5
    }, 
    {
      pos: [3, 9, 7], 
      state: 5
    }, 
    {
      pos: [4, 9, 7], 
      state: 5
    }, 
    {
      pos: [5, 9, 7], 
      state: 5
    }, 
    {
      pos: [0, 9, 8], 
      state: 5
    }, 
    {
      pos: [1, 9, 8], 
      state: 5
    }, 
    {
      pos: [2, 9, 8], 
      state: 5
    }, 
    {
      pos: [3, 9, 8], 
      state: 5
    }, 
    {
      pos: [4, 9, 8], 
      state: 5
    }, 
    {
      pos: [5, 9, 8], 
      state: 5
    }, 
    {
      pos: [0, 9, 9], 
      state: 5
    }, 
    {
      pos: [1, 9, 9], 
      state: 5
    }, 
    {
      pos: [3, 9, 9], 
      state: 15
    }, 
    {
      pos: [5, 9, 9], 
      state: 5
    }, 
    {
      pos: [0, 9, 10], 
      state: 5
    }, 
    {
      pos: [1, 9, 10], 
      state: 5
    }, 
    {
      pos: [2, 9, 10], 
      state: 15
    }, 
    {
      pos: [4, 9, 10], 
      state: 15
    }, 
    {
      pos: [5, 9, 10], 
      state: 5
    }, 
    {
      pos: [0, 9, 11], 
      state: 5
    }, 
    {
      pos: [1, 9, 11], 
      state: 5
    }, 
    {
      pos: [3, 9, 11], 
      state: 15
    }, 
    {
      pos: [5, 9, 11], 
      state: 5
    }, 
    {
      pos: [0, 10, 0], 
      state: 5
    }, 
    {
      pos: [1, 10, 0], 
      state: 5
    }, 
    {
      pos: [2, 10, 0], 
      state: 5
    }, 
    {
      pos: [3, 10, 0], 
      state: 5
    }, 
    {
      pos: [4, 10, 0], 
      state: 5
    }, 
    {
      pos: [5, 10, 0], 
      state: 5
    }, 
    {
      pos: [0, 10, 1], 
      state: 5
    }, 
    {
      pos: [1, 10, 1], 
      state: 5
    }, 
    {
      pos: [2, 10, 1], 
      state: 5
    }, 
    {
      pos: [3, 10, 1], 
      state: 5
    }, 
    {
      pos: [4, 10, 1], 
      state: 5
    }, 
    {
      pos: [5, 10, 1], 
      state: 5
    }, 
    {
      pos: [0, 10, 2], 
      state: 5
    }, 
    {
      pos: [1, 10, 2], 
      state: 5
    }, 
    {
      pos: [2, 10, 2], 
      state: 5
    }, 
    {
      pos: [3, 10, 2], 
      state: 5
    }, 
    {
      pos: [4, 10, 2], 
      state: 5
    }, 
    {
      pos: [5, 10, 2], 
      state: 5
    }, 
    {
      pos: [0, 10, 3], 
      state: 5
    }, 
    {
      pos: [1, 10, 3], 
      state: 5
    }, 
    {
      pos: [2, 10, 3], 
      state: 5
    }, 
    {
      pos: [3, 10, 3], 
      state: 5
    }, 
    {
      pos: [4, 10, 3], 
      state: 5
    }, 
    {
      pos: [5, 10, 3], 
      state: 5
    }, 
    {
      pos: [0, 10, 4], 
      state: 5
    }, 
    {
      pos: [1, 10, 4], 
      state: 5
    }, 
    {
      pos: [2, 10, 4], 
      state: 5
    }, 
    {
      pos: [3, 10, 4], 
      state: 5
    }, 
    {
      pos: [4, 10, 4], 
      state: 5
    }, 
    {
      pos: [5, 10, 4], 
      state: 5
    }, 
    {
      pos: [0, 10, 5], 
      state: 5
    }, 
    {
      pos: [1, 10, 5], 
      state: 5
    }, 
    {
      pos: [2, 10, 5], 
      state: 5
    }, 
    {
      pos: [3, 10, 5], 
      state: 5
    }, 
    {
      pos: [4, 10, 5], 
      state: 5
    }, 
    {
      pos: [5, 10, 5], 
      state: 5
    }, 
    {
      pos: [0, 10, 6], 
      state: 5
    }, 
    {
      pos: [1, 10, 6], 
      state: 5
    }, 
    {
      pos: [2, 10, 6], 
      state: 5
    }, 
    {
      pos: [3, 10, 6], 
      state: 5
    }, 
    {
      pos: [4, 10, 6], 
      state: 5
    }, 
    {
      pos: [5, 10, 6], 
      state: 5
    }, 
    {
      pos: [0, 10, 7], 
      state: 5
    }, 
    {
      pos: [1, 10, 7], 
      state: 5
    }, 
    {
      pos: [2, 10, 7], 
      state: 5
    }, 
    {
      pos: [3, 10, 7], 
      state: 5
    }, 
    {
      pos: [4, 10, 7], 
      state: 5
    }, 
    {
      pos: [5, 10, 7], 
      state: 5
    }, 
    {
      pos: [0, 10, 8], 
      state: 5
    }, 
    {
      pos: [1, 10, 8], 
      state: 5
    }, 
    {
      pos: [2, 10, 8], 
      state: 5
    }, 
    {
      pos: [3, 10, 8], 
      state: 5
    }, 
    {
      pos: [4, 10, 8], 
      state: 5
    }, 
    {
      pos: [5, 10, 8], 
      state: 5
    }, 
    {
      pos: [0, 10, 9], 
      state: 5
    }, 
    {
      pos: [1, 10, 9], 
      state: 5
    }, 
    {
      pos: [2, 10, 9], 
      state: 5
    }, 
    {
      pos: [3, 10, 9], 
      state: 5
    }, 
    {
      pos: [4, 10, 9], 
      state: 5
    }, 
    {
      pos: [5, 10, 9], 
      state: 5
    }, 
    {
      pos: [0, 10, 10], 
      state: 5
    }, 
    {
      pos: [1, 10, 10], 
      state: 5
    }, 
    {
      pos: [2, 10, 10], 
      state: 5
    }, 
    {
      pos: [3, 10, 10], 
      state: 18
    }, 
    {
      pos: [4, 10, 10], 
      state: 5
    }, 
    {
      pos: [5, 10, 10], 
      state: 5
    }, 
    {
      pos: [0, 10, 11], 
      state: 5
    }, 
    {
      pos: [1, 10, 11], 
      state: 5
    }, 
    {
      pos: [2, 10, 11], 
      state: 5
    }, 
    {
      pos: [3, 10, 11], 
      state: 5
    }, 
    {
      pos: [4, 10, 11], 
      state: 5
    }, 
    {
      pos: [5, 10, 11], 
      state: 5
    }, 
    {
      pos: [0, 11, 0], 
      state: 5
    }, 
    {
      pos: [1, 11, 0], 
      state: 5
    }, 
    {
      pos: [2, 11, 0], 
      state: 5
    }, 
    {
      pos: [3, 11, 0], 
      state: 5
    }, 
    {
      pos: [4, 11, 0], 
      state: 5
    }, 
    {
      pos: [5, 11, 0], 
      state: 5
    }, 
    {
      pos: [0, 11, 1], 
      state: 5
    }, 
    {
      pos: [1, 11, 1], 
      state: 5
    }, 
    {
      pos: [2, 11, 1], 
      state: 5
    }, 
    {
      pos: [3, 11, 1], 
      state: 5
    }, 
    {
      pos: [4, 11, 1], 
      state: 5
    }, 
    {
      pos: [5, 11, 1], 
      state: 5
    }, 
    {
      pos: [0, 11, 2], 
      state: 5
    }, 
    {
      pos: [1, 11, 2], 
      state: 5
    }, 
    {
      pos: [2, 11, 2], 
      state: 5
    }, 
    {
      pos: [3, 11, 2], 
      state: 5
    }, 
    {
      pos: [4, 11, 2], 
      state: 5
    }, 
    {
      pos: [5, 11, 2], 
      state: 5
    }, 
    {
      pos: [0, 11, 3], 
      state: 5
    }, 
    {
      pos: [1, 11, 3], 
      state: 5
    }, 
    {
      pos: [2, 11, 3], 
      state: 5
    }, 
    {
      pos: [3, 11, 3], 
      state: 5
    }, 
    {
      pos: [4, 11, 3], 
      state: 5
    }, 
    {
      pos: [5, 11, 3], 
      state: 5
    }, 
    {
      pos: [0, 11, 4], 
      state: 5
    }, 
    {
      pos: [1, 11, 4], 
      state: 5
    }, 
    {
      pos: [2, 11, 4], 
      state: 5
    }, 
    {
      pos: [3, 11, 4], 
      state: 5
    }, 
    {
      pos: [4, 11, 4], 
      state: 5
    }, 
    {
      pos: [5, 11, 4], 
      state: 5
    }, 
    {
      pos: [0, 11, 5], 
      state: 5
    }, 
    {
      pos: [1, 11, 5], 
      state: 5
    }, 
    {
      pos: [2, 11, 5], 
      state: 5
    }, 
    {
      pos: [3, 11, 5], 
      state: 5
    }, 
    {
      pos: [4, 11, 5], 
      state: 5
    }, 
    {
      pos: [5, 11, 5], 
      state: 5
    }, 
    {
      pos: [0, 11, 6], 
      state: 5
    }, 
    {
      pos: [1, 11, 6], 
      state: 5
    }, 
    {
      pos: [2, 11, 6], 
      state: 5
    }, 
    {
      pos: [3, 11, 6], 
      state: 5
    }, 
    {
      pos: [4, 11, 6], 
      state: 5
    }, 
    {
      pos: [5, 11, 6], 
      state: 5
    }, 
    {
      pos: [0, 11, 7], 
      state: 5
    }, 
    {
      pos: [1, 11, 7], 
      state: 5
    }, 
    {
      pos: [2, 11, 7], 
      state: 5
    }, 
    {
      pos: [3, 11, 7], 
      state: 5
    }, 
    {
      pos: [4, 11, 7], 
      state: 5
    }, 
    {
      pos: [5, 11, 7], 
      state: 5
    }, 
    {
      pos: [0, 11, 8], 
      state: 5
    }, 
    {
      pos: [1, 11, 8], 
      state: 5
    }, 
    {
      pos: [2, 11, 8], 
      state: 5
    }, 
    {
      pos: [3, 11, 8], 
      state: 5
    }, 
    {
      pos: [4, 11, 8], 
      state: 5
    }, 
    {
      pos: [5, 11, 8], 
      state: 5
    }, 
    {
      pos: [0, 11, 9], 
      state: 5
    }, 
    {
      pos: [1, 11, 9], 
      state: 5
    }, 
    {
      pos: [2, 11, 9], 
      state: 5
    }, 
    {
      pos: [3, 11, 9], 
      state: 5
    }, 
    {
      pos: [4, 11, 9], 
      state: 5
    }, 
    {
      pos: [5, 11, 9], 
      state: 5
    }, 
    {
      pos: [0, 11, 10], 
      state: 5
    }, 
    {
      pos: [1, 11, 10], 
      state: 5
    }, 
    {
      pos: [2, 11, 10], 
      state: 5
    }, 
    {
      pos: [3, 11, 10], 
      state: 19
    }, 
    {
      pos: [4, 11, 10], 
      state: 5
    }, 
    {
      pos: [5, 11, 10], 
      state: 5
    }, 
    {
      pos: [0, 11, 11], 
      state: 5
    }, 
    {
      pos: [1, 11, 11], 
      state: 5
    }, 
    {
      pos: [2, 11, 11], 
      state: 5
    }, 
    {
      pos: [3, 11, 11], 
      state: 5
    }, 
    {
      pos: [4, 11, 11], 
      state: 5
    }, 
    {
      pos: [5, 11, 11], 
      state: 5
    }
  ], 
  palette: [
    {
      Name: "minecraft:sand"
    }, 
    {
      Name: "minecraft:smooth_sandstone"
    }, 
    {
      Name: "minecraft:cut_sandstone"
    }, 
    {
      Name: "minecraft:fletching_table"
    }, 
    {
      Properties: {
        facing: "west"
      }, 
      Name: "minecraft:jigsaw"
    }, 
    {
      Name: "minecraft:air"
    }, 
    {
      Properties: {
        hinge: "right", 
        half: "lower", 
        powered: "false", 
        facing: "west", 
        open: "false"
      }, 
      Name: "minecraft:jungle_door"
    }, 
    {
      Properties: {
        half: "bottom", 
        waterlogged: "false", 
        shape: "straight", 
        facing: "south"
      }, 
      Name: "minecraft:smooth_sandstone_stairs"
    }, 
    {
      Properties: {
        hinge: "right", 
        half: "lower", 
        powered: "false", 
        facing: "south", 
        open: "false"
      }, 
      Name: "minecraft:jungle_door"
    }, 
    {
      Name: "minecraft:potted_cactus"
    }, 
    {
      Properties: {
        facing: "west"
      }, 
      Name: "minecraft:wall_torch"
    }, 
    {
      Properties: {
        hinge: "right", 
        half: "upper", 
        powered: "false", 
        facing: "west", 
        open: "false"
      }, 
      Name: "minecraft:jungle_door"
    }, 
    {
      Properties: {
        hinge: "right", 
        half: "upper", 
        powered: "false", 
        facing: "south", 
        open: "false"
      }, 
      Name: "minecraft:jungle_door"
    }, 
    {
      Properties: {
        waterlogged: "false", 
        facing: "north"
      }, 
      Name: "minecraft:ladder"
    }, 
    {
      Properties: {
        waterlogged: "false", 
        type: "top"
      }, 
      Name: "minecraft:smooth_sandstone_slab"
    }, 
    {
      Properties: {
        waterlogged: "false", 
        type: "bottom"
      }, 
      Name: "minecraft:smooth_sandstone_slab"
    }, 
    {
      Properties: {
        facing: "north"
      }, 
      Name: "minecraft:wall_torch"
    }, 
    {
      Properties: {
        waterlogged: "false", 
        type: "double"
      }, 
      Name: "minecraft:smooth_sandstone_slab"
    }, 
    {
      Properties: {
        east: "false", 
        waterlogged: "false", 
        south: "false", 
        north: "false", 
        west: "false", 
        up: "true"
      }, 
      Name: "minecraft:sandstone_wall"
    }, 
    {
      Name: "minecraft:torch"
    }
  ]
}
