{
  size: [10, 10, 10], 
  entities: [
    {
      nbt: {
        Motion: [0.0d, 0.0d, 0.0d], 
        color: "gray", 
        block_pos: [I; -86, -61, 660], 
        Invulnerable: 0b, 
        Air: 300s, 
        OnGround: 0b, 
        fall_distance: 0.0d, 
        PortalCooldown: 0, 
        Rotation: [90.0f, 0.0f], 
        Pos: [-85.5d, -60.0625d, 660.5d], 
        Fire: 0s, 
        id: "minecraft:cushion", 
        UUID: [I; 1197559094, 1767063921, -1680016986, 1675023202]
      }, 
      blockPos: [8, 0, 3], 
      pos: [8.5d, 0.9375d, 3.5d]
    }
  ], 
  blocks: [
    {
      pos: [2, 0, 3], 
      state: 0
    }, 
    {
      pos: [2, 0, 4], 
      state: 1
    }, 
    {
      pos: [2, 0, 5], 
      state: 0
    }, 
    {
      pos: [2, 0, 7], 
      state: 0
    }, 
    {
      pos: [3, 0, 2], 
      state: 0
    }, 
    {
      pos: [3, 0, 3], 
      state: 1
    }, 
    {
      pos: [3, 0, 4], 
      state: 1
    }, 
    {
      pos: [3, 0, 5], 
      state: 1
    }, 
    {
      pos: [3, 0, 6], 
      state: 1
    }, 
    {
      pos: [3, 0, 7], 
      state: 0
    }, 
    {
      pos: [4, 0, 2], 
      state: 0
    }, 
    {
      pos: [4, 0, 3], 
      state: 1
    }, 
    {
      pos: [4, 0, 4], 
      state: 1
    }, 
    {
      pos: [4, 0, 5], 
      state: 1
    }, 
    {
      pos: [4, 0, 6], 
      state: 1
    }, 
    {
      pos: [4, 0, 7], 
      state: 1
    }, 
    {
      pos: [4, 0, 8], 
      state: 0
    }, 
    {
      pos: [5, 0, 0], 
      state: 2
    }, 
    {
      pos: [5, 0, 2], 
      state: 1
    }, 
    {
      pos: [5, 0, 3], 
      state: 1
    }, 
    {
      pos: [5, 0, 4], 
      state: 1
    }, 
    {
      pos: [5, 0, 5], 
      state: 1
    }, 
    {
      pos: [5, 0, 6], 
      state: 1
    }, 
    {
      pos: [5, 0, 7], 
      state: 1
    }, 
    {
      pos: [5, 0, 8], 
      state: 0
    }, 
    {
      pos: [6, 0, 2], 
      state: 2
    }, 
    {
      pos: [6, 0, 3], 
      state: 1
    }, 
    {
      pos: [6, 0, 4], 
      state: 1
    }, 
    {
      pos: [6, 0, 5], 
      state: 0
    }, 
    {
      pos: [6, 0, 6], 
      state: 1
    }, 
    {
      pos: [6, 0, 7], 
      state: 1
    }, 
    {
      pos: [7, 0, 6], 
      state: 1
    }, 
    {
      pos: [7, 0, 7], 
      state: 1
    }, 
    {
      pos: [8, 0, 4], 
      state: 1
    }, 
    {
      pos: [8, 0, 7], 
      state: 2
    }, 
    {
      pos: [2, 1, 4], 
      state: 0
    }, 
    {
      pos: [3, 1, 3], 
      state: 2
    }, 
    {
      pos: [3, 1, 4], 
      state: 0
    }, 
    {
      pos: [3, 1, 5], 
      state: 0
    }, 
    {
      pos: [3, 1, 6], 
      state: 2
    }, 
    {
      pos: [4, 1, 3], 
      state: 0
    }, 
    {
      pos: [4, 1, 4], 
      state: 1
    }, 
    {
      pos: [4, 1, 5], 
      state: 1
    }, 
    {
      pos: [4, 1, 6], 
      state: 2
    }, 
    {
      pos: [4, 1, 7], 
      state: 2
    }, 
    {
      pos: [5, 1, 2], 
      state: 0
    }, 
    {
      pos: [5, 1, 3], 
      state: 2
    }, 
    {
      pos: [5, 1, 4], 
      state: 1
    }, 
    {
      pos: [5, 1, 5], 
      state: 1
    }, 
    {
      pos: [5, 1, 6], 
      state: 0
    }, 
    {
      pos: [5, 1, 7], 
      state: 2
    }, 
    {
      pos: [6, 1, 3], 
      state: 2
    }, 
    {
      pos: [6, 1, 6], 
      state: 2
    }, 
    {
      pos: [6, 1, 7], 
      state: 0
    }, 
    {
      pos: [7, 1, 6], 
      state: 3
    }, 
    {
      pos: [7, 1, 7], 
      state: 2
    }, 
    {
      pos: [4, 2, 4], 
      state: 4
    }, 
    {
      pos: [4, 2, 5], 
      state: 4
    }, 
    {
      pos: [4, 2, 6], 
      state: 2
    }, 
    {
      pos: [5, 2, 4], 
      state: 4
    }, 
    {
      pos: [5, 2, 5], 
      state: 4
    }, 
    {
      pos: [6, 2, 6], 
      state: 3
    }, 
    {
      pos: [7, 2, 7], 
      state: 3
    }, 
    {
      pos: [4, 3, 4], 
      state: 4
    }, 
    {
      pos: [4, 3, 5], 
      state: 4
    }, 
    {
      pos: [5, 3, 4], 
      state: 4
    }, 
    {
      pos: [5, 3, 5], 
      state: 4
    }, 
    {
      pos: [4, 4, 4], 
      state: 4
    }, 
    {
      pos: [5, 4, 3], 
      state: 4
    }, 
    {
      pos: [5, 4, 4], 
      state: 4
    }, 
    {
      pos: [5, 4, 5], 
      state: 4
    }, 
    {
      pos: [4, 5, 4], 
      state: 4
    }, 
    {
      pos: [4, 5, 5], 
      state: 4
    }, 
    {
      pos: [5, 5, 3], 
      state: 4
    }, 
    {
      pos: [5, 5, 4], 
      state: 4
    }, 
    {
      pos: [5, 5, 5], 
      state: 4
    }, 
    {
      pos: [4, 6, 4], 
      state: 4
    }, 
    {
      pos: [4, 6, 5], 
      state: 4
    }, 
    {
      pos: [5, 6, 3], 
      state: 4
    }, 
    {
      pos: [5, 6, 4], 
      state: 4
    }, 
    {
      pos: [5, 6, 5], 
      state: 4
    }, 
    {
      pos: [2, 7, 2], 
      state: 5
    }, 
    {
      pos: [2, 7, 3], 
      state: 6
    }, 
    {
      pos: [2, 7, 4], 
      state: 7
    }, 
    {
      pos: [2, 7, 5], 
      state: 7
    }, 
    {
      pos: [2, 7, 6], 
      state: 6
    }, 
    {
      pos: [2, 7, 7], 
      state: 5
    }, 
    {
      pos: [3, 7, 2], 
      state: 6
    }, 
    {
      pos: [3, 7, 3], 
      state: 7
    }, 
    {
      pos: [3, 7, 4], 
      state: 8
    }, 
    {
      pos: [3, 7, 5], 
      state: 8
    }, 
    {
      pos: [3, 7, 6], 
      state: 7
    }, 
    {
      pos: [3, 7, 7], 
      state: 6
    }, 
    {
      pos: [4, 7, 1], 
      state: 6
    }, 
    {
      pos: [4, 7, 2], 
      state: 7
    }, 
    {
      pos: [4, 7, 3], 
      state: 8
    }, 
    {
      pos: [4, 7, 4], 
      state: 4
    }, 
    {
      pos: [4, 7, 5], 
      state: 4
    }, 
    {
      pos: [4, 7, 6], 
      state: 8
    }, 
    {
      pos: [4, 7, 7], 
      state: 7
    }, 
    {
      pos: [5, 7, 1], 
      state: 7
    }, 
    {
      pos: [5, 7, 2], 
      state: 8
    }, 
    {
      pos: [5, 7, 3], 
      state: 4
    }, 
    {
      pos: [5, 7, 4], 
      state: 4
    }, 
    {
      pos: [5, 7, 5], 
      state: 4
    }, 
    {
      pos: [5, 7, 6], 
      state: 8
    }, 
    {
      pos: [5, 7, 7], 
      state: 7
    }, 
    {
      pos: [6, 7, 1], 
      state: 6
    }, 
    {
      pos: [6, 7, 2], 
      state: 7
    }, 
    {
      pos: [6, 7, 3], 
      state: 8
    }, 
    {
      pos: [6, 7, 4], 
      state: 8
    }, 
    {
      pos: [6, 7, 5], 
      state: 8
    }, 
    {
      pos: [6, 7, 6], 
      state: 7
    }, 
    {
      pos: [6, 7, 7], 
      state: 6
    }, 
    {
      pos: [7, 7, 2], 
      state: 6
    }, 
    {
      pos: [7, 7, 3], 
      state: 7
    }, 
    {
      pos: [7, 7, 4], 
      state: 7
    }, 
    {
      pos: [7, 7, 5], 
      state: 7
    }, 
    {
      pos: [7, 7, 6], 
      state: 6
    }, 
    {
      pos: [7, 7, 7], 
      state: 5
    }, 
    {
      pos: [1, 8, 2], 
      state: 9
    }, 
    {
      pos: [1, 8, 3], 
      state: 5
    }, 
    {
      pos: [1, 8, 4], 
      state: 6
    }, 
    {
      pos: [1, 8, 5], 
      state: 6
    }, 
    {
      pos: [1, 8, 6], 
      state: 5
    }, 
    {
      pos: [2, 8, 1], 
      state: 9
    }, 
    {
      pos: [2, 8, 2], 
      state: 5
    }, 
    {
      pos: [2, 8, 3], 
      state: 6
    }, 
    {
      pos: [2, 8, 4], 
      state: 7
    }, 
    {
      pos: [2, 8, 5], 
      state: 7
    }, 
    {
      pos: [2, 8, 6], 
      state: 6
    }, 
    {
      pos: [2, 8, 7], 
      state: 5
    }, 
    {
      pos: [2, 8, 8], 
      state: 9
    }, 
    {
      pos: [3, 8, 1], 
      state: 5
    }, 
    {
      pos: [3, 8, 2], 
      state: 6
    }, 
    {
      pos: [3, 8, 3], 
      state: 7
    }, 
    {
      pos: [3, 8, 4], 
      state: 8
    }, 
    {
      pos: [3, 8, 5], 
      state: 8
    }, 
    {
      pos: [3, 8, 6], 
      state: 7
    }, 
    {
      pos: [3, 8, 7], 
      state: 6
    }, 
    {
      pos: [3, 8, 8], 
      state: 5
    }, 
    {
      pos: [4, 8, 1], 
      state: 6
    }, 
    {
      pos: [4, 8, 2], 
      state: 7
    }, 
    {
      pos: [4, 8, 3], 
      state: 8
    }, 
    {
      pos: [4, 8, 4], 
      state: 4
    }, 
    {
      pos: [4, 8, 5], 
      state: 4
    }, 
    {
      pos: [4, 8, 6], 
      state: 8
    }, 
    {
      pos: [4, 8, 7], 
      state: 7
    }, 
    {
      pos: [4, 8, 8], 
      state: 6
    }, 
    {
      pos: [5, 8, 1], 
      state: 6
    }, 
    {
      pos: [5, 8, 2], 
      state: 7
    }, 
    {
      pos: [5, 8, 3], 
      state: 8
    }, 
    {
      pos: [5, 8, 4], 
      state: 4
    }, 
    {
      pos: [5, 8, 5], 
      state: 4
    }, 
    {
      pos: [5, 8, 6], 
      state: 8
    }, 
    {
      pos: [5, 8, 7], 
      state: 7
    }, 
    {
      pos: [5, 8, 8], 
      state: 6
    }, 
    {
      pos: [6, 8, 1], 
      state: 5
    }, 
    {
      pos: [6, 8, 2], 
      state: 6
    }, 
    {
      pos: [6, 8, 3], 
      state: 7
    }, 
    {
      pos: [6, 8, 4], 
      state: 8
    }, 
    {
      pos: [6, 8, 5], 
      state: 8
    }, 
    {
      pos: [6, 8, 6], 
      state: 7
    }, 
    {
      pos: [6, 8, 7], 
      state: 6
    }, 
    {
      pos: [6, 8, 8], 
      state: 5
    }, 
    {
      pos: [7, 8, 2], 
      state: 5
    }, 
    {
      pos: [7, 8, 3], 
      state: 6
    }, 
    {
      pos: [7, 8, 4], 
      state: 7
    }, 
    {
      pos: [7, 8, 5], 
      state: 7
    }, 
    {
      pos: [7, 8, 6], 
      state: 6
    }, 
    {
      pos: [8, 8, 2], 
      state: 9
    }, 
    {
      pos: [8, 8, 3], 
      state: 5
    }, 
    {
      pos: [8, 8, 4], 
      state: 6
    }, 
    {
      pos: [8, 8, 5], 
      state: 6
    }, 
    {
      pos: [8, 8, 6], 
      state: 5
    }, 
    {
      pos: [2, 9, 4], 
      state: 6
    }, 
    {
      pos: [2, 9, 5], 
      state: 6
    }, 
    {
      pos: [3, 9, 3], 
      state: 6
    }, 
    {
      pos: [3, 9, 4], 
      state: 7
    }, 
    {
      pos: [3, 9, 5], 
      state: 7
    }, 
    {
      pos: [3, 9, 6], 
      state: 6
    }, 
    {
      pos: [4, 9, 2], 
      state: 6
    }, 
    {
      pos: [4, 9, 3], 
      state: 7
    }, 
    {
      pos: [4, 9, 4], 
      state: 8
    }, 
    {
      pos: [4, 9, 5], 
      state: 8
    }, 
    {
      pos: [4, 9, 6], 
      state: 7
    }, 
    {
      pos: [4, 9, 7], 
      state: 6
    }, 
    {
      pos: [5, 9, 2], 
      state: 6
    }, 
    {
      pos: [5, 9, 3], 
      state: 7
    }, 
    {
      pos: [5, 9, 4], 
      state: 8
    }, 
    {
      pos: [5, 9, 5], 
      state: 8
    }, 
    {
      pos: [5, 9, 6], 
      state: 7
    }, 
    {
      pos: [5, 9, 7], 
      state: 6
    }, 
    {
      pos: [6, 9, 3], 
      state: 6
    }, 
    {
      pos: [6, 9, 4], 
      state: 7
    }, 
    {
      pos: [6, 9, 5], 
      state: 7
    }, 
    {
      pos: [6, 9, 6], 
      state: 6
    }, 
    {
      pos: [7, 9, 4], 
      state: 6
    }, 
    {
      pos: [7, 9, 5], 
      state: 6
    }, 
    {
      pos: [7, 0, 3], 
      state: 10
    }, 
    {
      pos: [7, 0, 4], 
      state: 10
    }, 
    {
      pos: [7, 0, 5], 
      state: 10
    }, 
    {
      pos: [8, 0, 2], 
      state: 10
    }, 
    {
      pos: [8, 0, 3], 
      state: 10
    }, 
    {
      pos: [8, 0, 5], 
      state: 10
    }, 
    {
      pos: [8, 0, 6], 
      state: 10
    }, 
    {
      pos: [9, 0, 2], 
      state: 10
    }, 
    {
      pos: [9, 0, 3], 
      state: 10
    }, 
    {
      pos: [9, 0, 5], 
      state: 10
    }, 
    {
      pos: [9, 0, 6], 
      state: 10
    }, 
    {
      pos: [2, 1, 3], 
      state: 11
    }, 
    {
      pos: [2, 1, 5], 
      state: 12
    }, 
    {
      pos: [2, 1, 7], 
      state: 13
    }, 
    {
      pos: [3, 1, 2], 
      state: 14
    }, 
    {
      pos: [3, 1, 7], 
      state: 12
    }, 
    {
      pos: [4, 1, 2], 
      state: 11
    }, 
    {
      pos: [4, 1, 8], 
      state: 15
    }, 
    {
      pos: [5, 1, 8], 
      state: 15
    }, 
    {
      pos: [6, 1, 2], 
      state: 16
    }, 
    {
      pos: [8, 1, 7], 
      state: 17
    }, 
    {
      pos: [3, 2, 3], 
      state: 13
    }, 
    {
      pos: [3, 2, 6], 
      state: 18
    }, 
    {
      pos: [4, 2, 3], 
      state: 19
    }, 
    {
      pos: [5, 2, 2], 
      state: 17
    }, 
    {
      pos: [5, 2, 3], 
      state: 14
    }, 
    {
      pos: [5, 2, 6], 
      state: 20
    }, 
    {
      pos: [6, 2, 3], 
      state: 13
    }, 
    {
      pos: [6, 2, 7], 
      state: 17
    }, 
    {
      pos: [8, 2, 7], 
      state: 21
    }, 
    {
      pos: [4, 3, 1], 
      state: 22
    }, 
    {
      pos: [4, 3, 3], 
      state: 23
    }, 
    {
      pos: [5, 3, 2], 
      state: 21
    }, 
    {
      pos: [5, 3, 6], 
      state: 24
    }, 
    {
      pos: [6, 3, 7], 
      state: 21
    }, 
    {
      pos: [7, 3, 2], 
      state: 22
    }, 
    {
      pos: [7, 3, 5], 
      state: 22
    }, 
    {
      pos: [2, 4, 6], 
      state: 22
    }, 
    {
      pos: [4, 4, 1], 
      state: 25
    }, 
    {
      pos: [4, 4, 7], 
      state: 22
    }, 
    {
      pos: [5, 4, 1], 
      state: 22
    }, 
    {
      pos: [7, 4, 2], 
      state: 25
    }, 
    {
      pos: [7, 4, 4], 
      state: 22
    }, 
    {
      pos: [7, 4, 5], 
      state: 25
    }, 
    {
      pos: [7, 4, 7], 
      state: 22
    }, 
    {
      pos: [2, 5, 6], 
      state: 25
    }, 
    {
      pos: [4, 5, 1], 
      state: 25
    }, 
    {
      pos: [4, 5, 7], 
      state: 25
    }, 
    {
      pos: [5, 5, 1], 
      state: 25
    }, 
    {
      pos: [5, 5, 6], 
      state: 22
    }, 
    {
      pos: [7, 5, 2], 
      state: 25
    }, 
    {
      pos: [7, 5, 4], 
      state: 25
    }, 
    {
      pos: [7, 5, 5], 
      state: 25
    }, 
    {
      pos: [7, 5, 7], 
      state: 25
    }, 
    {
      pos: [2, 6, 4], 
      state: 22
    }, 
    {
      pos: [2, 6, 5], 
      state: 22
    }, 
    {
      pos: [2, 6, 6], 
      state: 25
    }, 
    {
      pos: [2, 6, 7], 
      state: 22
    }, 
    {
      pos: [3, 6, 5], 
      state: 22
    }, 
    {
      pos: [4, 6, 1], 
      state: 25
    }, 
    {
      pos: [4, 6, 3], 
      state: 22
    }, 
    {
      pos: [4, 6, 7], 
      state: 25
    }, 
    {
      pos: [5, 6, 1], 
      state: 25
    }, 
    {
      pos: [5, 6, 2], 
      state: 22
    }, 
    {
      pos: [5, 6, 6], 
      state: 25
    }, 
    {
      pos: [6, 6, 3], 
      state: 22
    }, 
    {
      pos: [7, 6, 2], 
      state: 25
    }, 
    {
      pos: [7, 6, 4], 
      state: 25
    }, 
    {
      pos: [7, 6, 5], 
      state: 25
    }, 
    {
      pos: [7, 6, 6], 
      state: 22
    }, 
    {
      pos: [7, 6, 7], 
      state: 25
    }, 
    {
      nbt: {
        components: {}, 
        joint: "rollable", 
        final_state: "minecraft:dirt_path", 
        name: "minecraft:end_connector", 
        placement_priority: 0, 
        pool: "minecraft:empty", 
        selection_priority: 0, 
        id: "minecraft:jigsaw", 
        target: "minecraft:connector"
      }, 
      pos: [9, 0, 4], 
      state: 26
    }, 
    {
      nbt: {
        LootTable: "minecraft:barrels/abandoned_camp_barrel", 
        components: {}, 
        id: "minecraft:barrel"
      }, 
      pos: [6, 1, 4], 
      state: 27
    }, 
    {
      nbt: {
        LootTable: "minecraft:chests/abandoned_camp_common_chest", 
        components: {}, 
        id: "minecraft:chest"
      }, 
      pos: [6, 1, 5], 
      state: 28
    }, 
    {
      nbt: {
        components: {}, 
        Items: [], 
        CookingTimes: [I; 0, 0, 0, 0], 
        CookingTotalTimes: [I; 0, 0, 0, 0], 
        id: "minecraft:campfire"
      }, 
      pos: [8, 1, 4], 
      state: 29
    }, 
    {
      nbt: {
        components: {}, 
        id: "minecraft:creaking_heart"
      }, 
      pos: [4, 4, 5], 
      state: 30
    }
  ], 
  palette: [
    {
      Properties: {
        snowy: "false"
      }, 
      Name: "minecraft:grass_block"
    }, 
    {
      Name: "minecraft:dirt"
    }, 
    {
      Name: "minecraft:pale_moss_block"
    }, 
    {
      Name: "minecraft:resin_block"
    }, 
    {
      Properties: {
        axis: "y"
      }, 
      Name: "minecraft:pale_oak_log"
    }, 
    {
      Properties: {
        waterlogged: "false", 
        distance: "4", 
        persistent: "false"
      }, 
      Name: "minecraft:pale_oak_leaves"
    }, 
    {
      Properties: {
        waterlogged: "false", 
        distance: "3", 
        persistent: "false"
      }, 
      Name: "minecraft:pale_oak_leaves"
    }, 
    {
      Properties: {
        waterlogged: "false", 
        distance: "2", 
        persistent: "false"
      }, 
      Name: "minecraft:pale_oak_leaves"
    }, 
    {
      Properties: {
        waterlogged: "false", 
        distance: "1", 
        persistent: "false"
      }, 
      Name: "minecraft:pale_oak_leaves"
    }, 
    {
      Properties: {
        waterlogged: "false", 
        distance: "5", 
        persistent: "false"
      }, 
      Name: "minecraft:pale_oak_leaves"
    }, 
    {
      Name: "minecraft:dirt_path"
    }, 
    {
      Properties: {
        east: "low", 
        south: "low", 
        bottom: "true", 
        north: "none", 
        west: "none"
      }, 
      Name: "minecraft:pale_moss_carpet"
    }, 
    {
      Properties: {
        east: "low", 
        south: "none", 
        bottom: "true", 
        north: "low", 
        west: "none"
      }, 
      Name: "minecraft:pale_moss_carpet"
    }, 
    {
      Properties: {
        east: "none", 
        south: "none", 
        bottom: "true", 
        north: "none", 
        west: "none"
      }, 
      Name: "minecraft:pale_moss_carpet"
    }, 
    {
      Properties: {
        east: "none", 
        south: "low", 
        bottom: "true", 
        north: "none", 
        west: "none"
      }, 
      Name: "minecraft:pale_moss_carpet"
    }, 
    {
      Properties: {
        east: "none", 
        south: "none", 
        bottom: "true", 
        north: "low", 
        west: "none"
      }, 
      Name: "minecraft:pale_moss_carpet"
    }, 
    {
      Properties: {
        east: "none", 
        south: "low", 
        bottom: "true", 
        north: "none", 
        west: "low"
      }, 
      Name: "minecraft:pale_moss_carpet"
    }, 
    {
      Properties: {
        half: "lower"
      }, 
      Name: "minecraft:tall_grass"
    }, 
    {
      Properties: {
        east: "low", 
        south: "none", 
        bottom: "true", 
        north: "none", 
        west: "none"
      }, 
      Name: "minecraft:pale_moss_carpet"
    }, 
    {
      Properties: {
        east: "none", 
        south: "tall", 
        bottom: "true", 
        north: "none", 
        west: "none"
      }, 
      Name: "minecraft:pale_moss_carpet"
    }, 
    {
      Properties: {
        east: "low", 
        south: "none", 
        bottom: "true", 
        north: "tall", 
        west: "low"
      }, 
      Name: "minecraft:pale_moss_carpet"
    }, 
    {
      Properties: {
        half: "upper"
      }, 
      Name: "minecraft:tall_grass"
    }, 
    {
      Properties: {
        tip: "true"
      }, 
      Name: "minecraft:pale_hanging_moss"
    }, 
    {
      Properties: {
        east: "none", 
        south: "low", 
        bottom: "false", 
        north: "none", 
        west: "none"
      }, 
      Name: "minecraft:pale_moss_carpet"
    }, 
    {
      Properties: {
        east: "none", 
        south: "none", 
        bottom: "false", 
        north: "low", 
        west: "none"
      }, 
      Name: "minecraft:pale_moss_carpet"
    }, 
    {
      Properties: {
        tip: "false"
      }, 
      Name: "minecraft:pale_hanging_moss"
    }, 
    {
      Properties: {
        orientation: "east_up"
      }, 
      Name: "minecraft:jigsaw"
    }, 
    {
      Properties: {
        facing: "east", 
        open: "false"
      }, 
      Name: "minecraft:barrel"
    }, 
    {
      Properties: {
        waterlogged: "false", 
        facing: "east", 
        type: "single"
      }, 
      Name: "minecraft:chest"
    }, 
    {
      Properties: {
        waterlogged: "false", 
        signal_fire: "false", 
        lit: "false", 
        facing: "west"
      }, 
      Name: "minecraft:campfire"
    }, 
    {
      Properties: {
        natural: "false", 
        axis: "y", 
        creaking_heart_state: "dormant"
      }, 
      Name: "minecraft:creaking_heart"
    }
  ]
}
