{
  size: [3, 4, 3], 
  entities: [], 
  blocks: [
    {
      pos: [0, 0, 0], 
      state: 0
    }, 
    {
      pos: [0, 0, 1], 
      state: 0
    }, 
    {
      pos: [0, 0, 2], 
      state: 1
    }, 
    {
      pos: [1, 0, 0], 
      state: 0
    }, 
    {
      pos: [1, 0, 1], 
      state: 0
    }, 
    {
      pos: [1, 0, 2], 
      state: 1
    }, 
    {
      pos: [2, 0, 0], 
      state: 0
    }, 
    {
      pos: [2, 0, 1], 
      state: 0
    }, 
    {
      pos: [2, 0, 2], 
      state: 1
    }, 
    {
      pos: [0, 1, 1], 
      state: 1
    }, 
    {
      pos: [0, 1, 2], 
      state: 2
    }, 
    {
      pos: [1, 1, 2], 
      state: 3
    }, 
    {
      pos: [2, 1, 1], 
      state: 1
    }, 
    {
      pos: [2, 1, 2], 
      state: 2
    }, 
    {
      pos: [0, 2, 2], 
      state: 4
    }, 
    {
      pos: [1, 2, 2], 
      state: 5
    }, 
    {
      pos: [2, 2, 2], 
      state: 4
    }, 
    {
      pos: [0, 3, 1], 
      state: 1
    }, 
    {
      pos: [0, 3, 2], 
      state: 2
    }, 
    {
      pos: [1, 3, 1], 
      state: 3
    }, 
    {
      pos: [1, 3, 2], 
      state: 2
    }, 
    {
      pos: [2, 3, 1], 
      state: 1
    }, 
    {
      pos: [2, 3, 2], 
      state: 2
    }, 
    {
      pos: [0, 1, 0], 
      state: 6
    }, 
    {
      pos: [2, 1, 0], 
      state: 7
    }, 
    {
      pos: [0, 2, 0], 
      state: 8
    }, 
    {
      pos: [0, 2, 1], 
      state: 9
    }, 
    {
      pos: [1, 2, 0], 
      state: 8
    }, 
    {
      pos: [1, 2, 1], 
      state: 8
    }, 
    {
      pos: [2, 2, 0], 
      state: 8
    }, 
    {
      pos: [2, 2, 1], 
      state: 9
    }, 
    {
      pos: [0, 3, 0], 
      state: 8
    }, 
    {
      pos: [1, 3, 0], 
      state: 8
    }, 
    {
      pos: [2, 3, 0], 
      state: 8
    }, 
    {
      nbt: {
        joint: "rollable", 
        final_state: "minecraft:air", 
        name: "minecraft:ominous_vault", 
        placement_priority: 0, 
        pool: "minecraft:empty", 
        selection_priority: 0, 
        id: "minecraft:jigsaw", 
        target: "minecraft:empty"
      }, 
      pos: [1, 1, 0], 
      state: 10
    }, 
    {
      nbt: {
        id: "minecraft:vault", 
        config: {
          key_item: {
            count: 1, 
            id: "minecraft:ominous_trial_key"
          }, 
          loot_table: "minecraft:chests/trial_chambers/reward_ominous"
        }
      }, 
      pos: [1, 1, 1], 
      state: 11
    }
  ], 
  palette: [
    {
      id: "minecraft:waxed_oxidized_copper_grate", 
      properties: {
        waterlogged: "false"
      }
    }, 
    {
      id: "minecraft:polished_tuff"
    }, 
    {
      id: "minecraft:tuff_bricks"
    }, 
    {
      id: "minecraft:waxed_copper_bulb", 
      properties: {
        powered: "false", 
        lit: "true"
      }
    }, 
    {
      id: "minecraft:red_glazed_terracotta", 
      properties: {
        facing: "west"
      }
    }, 
    {
      id: "minecraft:chiseled_tuff"
    }, 
    {
      id: "minecraft:red_candle", 
      properties: {
        waterlogged: "false", 
        lit: "true", 
        candles: "3"
      }
    }, 
    {
      id: "minecraft:red_candle", 
      properties: {
        waterlogged: "false", 
        lit: "true", 
        candles: "4"
      }
    }, 
    {
      id: "minecraft:air"
    }, 
    {
      id: "minecraft:polished_tuff_slab", 
      properties: {
        waterlogged: "false", 
        type: "top"
      }
    }, 
    {
      id: "minecraft:jigsaw", 
      properties: {
        orientation: "north_up"
      }
    }, 
    {
      id: "minecraft:vault", 
      properties: {
        ominous: "true", 
        facing: "north", 
        vault_state: "inactive"
      }
    }
  ]
}
