{
  size: [5, 6, 5], 
  entities: [], 
  blocks: [
    {
      pos: [0, 0, 1], 
      state: 0
    }, 
    {
      pos: [0, 0, 2], 
      state: 0
    }, 
    {
      pos: [0, 0, 3], 
      state: 0
    }, 
    {
      pos: [0, 0, 4], 
      state: 0
    }, 
    {
      pos: [1, 0, 0], 
      state: 0
    }, 
    {
      pos: [1, 0, 1], 
      state: 0
    }, 
    {
      pos: [1, 0, 2], 
      state: 0
    }, 
    {
      pos: [1, 0, 3], 
      state: 0
    }, 
    {
      pos: [1, 0, 4], 
      state: 0
    }, 
    {
      pos: [2, 0, 0], 
      state: 0
    }, 
    {
      pos: [2, 0, 1], 
      state: 0
    }, 
    {
      pos: [2, 0, 2], 
      state: 0
    }, 
    {
      pos: [2, 0, 3], 
      state: 0
    }, 
    {
      pos: [2, 0, 4], 
      state: 0
    }, 
    {
      pos: [3, 0, 0], 
      state: 0
    }, 
    {
      pos: [3, 0, 1], 
      state: 0
    }, 
    {
      pos: [3, 0, 2], 
      state: 0
    }, 
    {
      pos: [3, 0, 3], 
      state: 0
    }, 
    {
      pos: [3, 0, 4], 
      state: 0
    }, 
    {
      pos: [4, 0, 0], 
      state: 0
    }, 
    {
      pos: [4, 0, 1], 
      state: 0
    }, 
    {
      pos: [4, 0, 2], 
      state: 0
    }, 
    {
      pos: [4, 0, 3], 
      state: 0
    }, 
    {
      pos: [4, 0, 4], 
      state: 0
    }, 
    {
      pos: [1, 1, 1], 
      state: 1
    }, 
    {
      pos: [1, 1, 2], 
      state: 2
    }, 
    {
      pos: [1, 1, 3], 
      state: 1
    }, 
    {
      pos: [2, 1, 1], 
      state: 2
    }, 
    {
      pos: [2, 1, 3], 
      state: 2
    }, 
    {
      pos: [3, 1, 1], 
      state: 2
    }, 
    {
      pos: [3, 1, 2], 
      state: 3
    }, 
    {
      pos: [3, 1, 3], 
      state: 2
    }, 
    {
      pos: [4, 1, 1], 
      state: 1
    }, 
    {
      pos: [4, 1, 2], 
      state: 2
    }, 
    {
      pos: [4, 1, 3], 
      state: 1
    }, 
    {
      pos: [3, 2, 2], 
      state: 4
    }, 
    {
      pos: [1, 3, 1], 
      state: 5
    }, 
    {
      pos: [1, 3, 2], 
      state: 6
    }, 
    {
      pos: [1, 3, 3], 
      state: 5
    }, 
    {
      pos: [2, 3, 0], 
      state: 5
    }, 
    {
      pos: [2, 3, 1], 
      state: 6
    }, 
    {
      pos: [2, 3, 2], 
      state: 7
    }, 
    {
      pos: [2, 3, 3], 
      state: 6
    }, 
    {
      pos: [2, 3, 4], 
      state: 5
    }, 
    {
      pos: [3, 3, 0], 
      state: 6
    }, 
    {
      pos: [3, 3, 1], 
      state: 7
    }, 
    {
      pos: [3, 3, 2], 
      state: 4
    }, 
    {
      pos: [3, 3, 3], 
      state: 7
    }, 
    {
      pos: [3, 3, 4], 
      state: 6
    }, 
    {
      pos: [4, 3, 0], 
      state: 5
    }, 
    {
      pos: [4, 3, 1], 
      state: 6
    }, 
    {
      pos: [4, 3, 2], 
      state: 7
    }, 
    {
      pos: [4, 3, 3], 
      state: 6
    }, 
    {
      pos: [4, 3, 4], 
      state: 5
    }, 
    {
      pos: [2, 4, 1], 
      state: 6
    }, 
    {
      pos: [2, 4, 2], 
      state: 7
    }, 
    {
      pos: [3, 4, 1], 
      state: 7
    }, 
    {
      pos: [3, 4, 2], 
      state: 4
    }, 
    {
      pos: [3, 4, 3], 
      state: 7
    }, 
    {
      pos: [4, 4, 1], 
      state: 6
    }, 
    {
      pos: [4, 4, 2], 
      state: 7
    }, 
    {
      pos: [4, 4, 3], 
      state: 6
    }, 
    {
      pos: [3, 5, 2], 
      state: 7
    }, 
    {
      pos: [0, 1, 0], 
      state: 8
    }, 
    {
      pos: [0, 1, 1], 
      state: 8
    }, 
    {
      pos: [0, 1, 2], 
      state: 8
    }, 
    {
      pos: [0, 1, 3], 
      state: 8
    }, 
    {
      pos: [0, 1, 4], 
      state: 8
    }, 
    {
      pos: [1, 1, 0], 
      state: 8
    }, 
    {
      pos: [1, 1, 4], 
      state: 8
    }, 
    {
      pos: [2, 1, 0], 
      state: 8
    }, 
    {
      pos: [2, 1, 2], 
      state: 9
    }, 
    {
      pos: [2, 1, 4], 
      state: 8
    }, 
    {
      pos: [3, 1, 0], 
      state: 8
    }, 
    {
      pos: [3, 1, 4], 
      state: 8
    }, 
    {
      pos: [4, 1, 0], 
      state: 8
    }, 
    {
      pos: [4, 1, 4], 
      state: 8
    }, 
    {
      pos: [0, 2, 0], 
      state: 8
    }, 
    {
      pos: [0, 2, 1], 
      state: 8
    }, 
    {
      pos: [0, 2, 2], 
      state: 8
    }, 
    {
      pos: [0, 2, 3], 
      state: 8
    }, 
    {
      pos: [0, 2, 4], 
      state: 8
    }, 
    {
      pos: [1, 2, 0], 
      state: 8
    }, 
    {
      pos: [1, 2, 1], 
      state: 8
    }, 
    {
      pos: [1, 2, 2], 
      state: 8
    }, 
    {
      pos: [1, 2, 3], 
      state: 8
    }, 
    {
      pos: [1, 2, 4], 
      state: 8
    }, 
    {
      pos: [2, 2, 0], 
      state: 8
    }, 
    {
      pos: [2, 2, 1], 
      state: 8
    }, 
    {
      pos: [2, 2, 2], 
      state: 8
    }, 
    {
      pos: [2, 2, 3], 
      state: 8
    }, 
    {
      pos: [2, 2, 4], 
      state: 8
    }, 
    {
      pos: [3, 2, 0], 
      state: 8
    }, 
    {
      pos: [3, 2, 1], 
      state: 8
    }, 
    {
      pos: [3, 2, 3], 
      state: 8
    }, 
    {
      pos: [3, 2, 4], 
      state: 8
    }, 
    {
      pos: [4, 2, 0], 
      state: 8
    }, 
    {
      pos: [4, 2, 1], 
      state: 8
    }, 
    {
      pos: [4, 2, 2], 
      state: 8
    }, 
    {
      pos: [4, 2, 3], 
      state: 8
    }, 
    {
      pos: [4, 2, 4], 
      state: 8
    }, 
    {
      pos: [0, 3, 0], 
      state: 8
    }, 
    {
      pos: [0, 3, 1], 
      state: 8
    }, 
    {
      pos: [0, 3, 2], 
      state: 8
    }, 
    {
      pos: [0, 3, 3], 
      state: 8
    }, 
    {
      pos: [0, 3, 4], 
      state: 8
    }, 
    {
      pos: [1, 3, 0], 
      state: 8
    }, 
    {
      pos: [1, 3, 4], 
      state: 8
    }, 
    {
      pos: [0, 4, 0], 
      state: 8
    }, 
    {
      pos: [0, 4, 1], 
      state: 8
    }, 
    {
      pos: [0, 4, 2], 
      state: 8
    }, 
    {
      pos: [0, 4, 3], 
      state: 8
    }, 
    {
      pos: [0, 4, 4], 
      state: 8
    }, 
    {
      pos: [1, 4, 0], 
      state: 8
    }, 
    {
      pos: [1, 4, 1], 
      state: 8
    }, 
    {
      pos: [1, 4, 2], 
      state: 8
    }, 
    {
      pos: [1, 4, 3], 
      state: 8
    }, 
    {
      pos: [1, 4, 4], 
      state: 8
    }, 
    {
      pos: [2, 4, 0], 
      state: 8
    }, 
    {
      pos: [2, 4, 3], 
      state: 8
    }, 
    {
      pos: [2, 4, 4], 
      state: 8
    }, 
    {
      pos: [3, 4, 0], 
      state: 8
    }, 
    {
      pos: [3, 4, 4], 
      state: 8
    }, 
    {
      pos: [4, 4, 0], 
      state: 8
    }, 
    {
      pos: [4, 4, 4], 
      state: 8
    }, 
    {
      pos: [0, 5, 0], 
      state: 8
    }, 
    {
      pos: [0, 5, 1], 
      state: 8
    }, 
    {
      pos: [0, 5, 2], 
      state: 8
    }, 
    {
      pos: [0, 5, 3], 
      state: 8
    }, 
    {
      pos: [0, 5, 4], 
      state: 8
    }, 
    {
      pos: [1, 5, 0], 
      state: 8
    }, 
    {
      pos: [1, 5, 1], 
      state: 8
    }, 
    {
      pos: [1, 5, 2], 
      state: 8
    }, 
    {
      pos: [1, 5, 3], 
      state: 8
    }, 
    {
      pos: [1, 5, 4], 
      state: 8
    }, 
    {
      pos: [2, 5, 0], 
      state: 8
    }, 
    {
      pos: [2, 5, 1], 
      state: 8
    }, 
    {
      pos: [2, 5, 2], 
      state: 8
    }, 
    {
      pos: [2, 5, 3], 
      state: 8
    }, 
    {
      pos: [2, 5, 4], 
      state: 8
    }, 
    {
      pos: [3, 5, 0], 
      state: 8
    }, 
    {
      pos: [3, 5, 1], 
      state: 8
    }, 
    {
      pos: [3, 5, 3], 
      state: 8
    }, 
    {
      pos: [3, 5, 4], 
      state: 8
    }, 
    {
      pos: [4, 5, 0], 
      state: 8
    }, 
    {
      pos: [4, 5, 1], 
      state: 8
    }, 
    {
      pos: [4, 5, 2], 
      state: 8
    }, 
    {
      pos: [4, 5, 3], 
      state: 8
    }, 
    {
      pos: [4, 5, 4], 
      state: 8
    }, 
    {
      nbt: {
        joint: "rollable", 
        final_state: "minecraft:waxed_oxidized_copper", 
        name: "minecraft:display", 
        placement_priority: 0, 
        pool: "minecraft:empty", 
        selection_priority: 0, 
        id: "minecraft:jigsaw", 
        target: "minecraft:empty"
      }, 
      pos: [0, 0, 0], 
      state: 10
    }
  ], 
  palette: [
    {
      Name: "minecraft:waxed_oxidized_cut_copper"
    }, 
    {
      Name: "minecraft:waxed_chiseled_copper"
    }, 
    {
      Name: "minecraft:waxed_copper_block"
    }, 
    {
      Name: "minecraft:dirt"
    }, 
    {
      Properties: {
        axis: "y"
      }, 
      Name: "minecraft:oak_log"
    }, 
    {
      Properties: {
        waterlogged: "false", 
        distance: "3", 
        persistent: "true"
      }, 
      Name: "minecraft:oak_leaves"
    }, 
    {
      Properties: {
        waterlogged: "false", 
        distance: "2", 
        persistent: "true"
      }, 
      Name: "minecraft:oak_leaves"
    }, 
    {
      Properties: {
        waterlogged: "false", 
        distance: "1", 
        persistent: "true"
      }, 
      Name: "minecraft:oak_leaves"
    }, 
    {
      Name: "minecraft:air"
    }, 
    {
      Properties: {
        level: "0"
      }, 
      Name: "minecraft:water"
    }, 
    {
      Properties: {
        orientation: "east_up"
      }, 
      Name: "minecraft:jigsaw"
    }
  ]
}
