{
  size: [3, 8, 3], 
  entities: [], 
  blocks: [
    {
      pos: [1, 0, 0], 
      state: 0
    }, 
    {
      pos: [1, 0, 1], 
      state: 1
    }, 
    {
      pos: [1, 0, 2], 
      state: 0
    }, 
    {
      pos: [2, 0, 0], 
      state: 2
    }, 
    {
      pos: [2, 0, 1], 
      state: 2
    }, 
    {
      pos: [2, 0, 2], 
      state: 2
    }, 
    {
      pos: [1, 1, 0], 
      state: 1
    }, 
    {
      pos: [1, 1, 1], 
      state: 3
    }, 
    {
      pos: [1, 1, 2], 
      state: 1
    }, 
    {
      pos: [2, 1, 0], 
      state: 4
    }, 
    {
      pos: [2, 1, 1], 
      state: 4
    }, 
    {
      pos: [2, 1, 2], 
      state: 4
    }, 
    {
      pos: [1, 2, 0], 
      state: 0
    }, 
    {
      pos: [1, 2, 1], 
      state: 1
    }, 
    {
      pos: [1, 2, 2], 
      state: 0
    }, 
    {
      pos: [1, 3, 0], 
      state: 2
    }, 
    {
      pos: [1, 3, 1], 
      state: 5
    }, 
    {
      pos: [1, 3, 2], 
      state: 2
    }, 
    {
      pos: [1, 4, 0], 
      state: 6
    }, 
    {
      pos: [1, 4, 1], 
      state: 1
    }, 
    {
      pos: [1, 4, 2], 
      state: 6
    }, 
    {
      pos: [0, 5, 0], 
      state: 7
    }, 
    {
      pos: [0, 5, 2], 
      state: 7
    }, 
    {
      pos: [1, 5, 0], 
      state: 7
    }, 
    {
      pos: [1, 5, 1], 
      state: 1
    }, 
    {
      pos: [1, 5, 2], 
      state: 7
    }, 
    {
      pos: [2, 5, 0], 
      state: 7
    }, 
    {
      pos: [2, 5, 2], 
      state: 7
    }, 
    {
      pos: [0, 6, 0], 
      state: 1
    }, 
    {
      pos: [0, 6, 1], 
      state: 1
    }, 
    {
      pos: [0, 6, 2], 
      state: 1
    }, 
    {
      pos: [1, 6, 0], 
      state: 4
    }, 
    {
      pos: [1, 6, 1], 
      state: 1
    }, 
    {
      pos: [1, 6, 2], 
      state: 4
    }, 
    {
      pos: [2, 6, 0], 
      state: 4
    }, 
    {
      pos: [2, 6, 2], 
      state: 4
    }, 
    {
      pos: [1, 7, 1], 
      state: 3
    }, 
    {
      pos: [0, 0, 1], 
      state: 8
    }, 
    {
      pos: [0, 0, 2], 
      state: 8
    }, 
    {
      pos: [0, 1, 0], 
      state: 8
    }, 
    {
      pos: [0, 1, 1], 
      state: 8
    }, 
    {
      pos: [0, 1, 2], 
      state: 8
    }, 
    {
      pos: [0, 2, 0], 
      state: 8
    }, 
    {
      pos: [0, 2, 1], 
      state: 8
    }, 
    {
      pos: [0, 2, 2], 
      state: 8
    }, 
    {
      pos: [2, 2, 0], 
      state: 8
    }, 
    {
      pos: [2, 2, 1], 
      state: 9
    }, 
    {
      pos: [2, 2, 2], 
      state: 8
    }, 
    {
      pos: [0, 3, 0], 
      state: 8
    }, 
    {
      pos: [0, 3, 1], 
      state: 8
    }, 
    {
      pos: [0, 3, 2], 
      state: 8
    }, 
    {
      pos: [2, 3, 0], 
      state: 8
    }, 
    {
      pos: [2, 3, 1], 
      state: 9
    }, 
    {
      pos: [2, 3, 2], 
      state: 8
    }, 
    {
      pos: [0, 4, 0], 
      state: 8
    }, 
    {
      pos: [0, 4, 1], 
      state: 8
    }, 
    {
      pos: [0, 4, 2], 
      state: 8
    }, 
    {
      pos: [2, 4, 0], 
      state: 8
    }, 
    {
      pos: [2, 4, 1], 
      state: 9
    }, 
    {
      pos: [2, 4, 2], 
      state: 8
    }, 
    {
      pos: [0, 5, 1], 
      state: 8
    }, 
    {
      pos: [2, 5, 1], 
      state: 9
    }, 
    {
      pos: [2, 6, 1], 
      state: 9
    }, 
    {
      pos: [0, 7, 0], 
      state: 8
    }, 
    {
      pos: [0, 7, 1], 
      state: 8
    }, 
    {
      pos: [0, 7, 2], 
      state: 8
    }, 
    {
      pos: [1, 7, 0], 
      state: 8
    }, 
    {
      pos: [1, 7, 2], 
      state: 8
    }, 
    {
      pos: [2, 7, 0], 
      state: 8
    }, 
    {
      pos: [2, 7, 1], 
      state: 9
    }, 
    {
      pos: [2, 7, 2], 
      state: 8
    }, 
    {
      nbt: {
        joint: "aligned", 
        final_state: "minecraft:air", 
        name: "minecraft:addon", 
        placement_priority: 0, 
        pool: "minecraft:empty", 
        selection_priority: 0, 
        id: "minecraft:jigsaw", 
        target: "minecraft:empty"
      }, 
      pos: [0, 0, 0], 
      state: 10
    }
  ], 
  palette: [
    {
      Name: "minecraft:chiseled_tuff_bricks"
    }, 
    {
      Name: "minecraft:waxed_copper_block"
    }, 
    {
      Name: "minecraft:tuff_bricks"
    }, 
    {
      Name: "minecraft:waxed_chiseled_copper"
    }, 
    {
      Name: "minecraft:waxed_oxidized_cut_copper"
    }, 
    {
      Properties: {
        powered: "false", 
        lit: "true"
      }, 
      Name: "minecraft:waxed_copper_bulb"
    }, 
    {
      Name: "minecraft:chiseled_tuff"
    }, 
    {
      Name: "minecraft:polished_tuff"
    }, 
    {
      Name: "minecraft:air"
    }, 
    {
      Properties: {
        waterlogged: "false", 
        facing: "east"
      }, 
      Name: "minecraft:ladder"
    }, 
    {
      Properties: {
        orientation: "down_west"
      }, 
      Name: "minecraft:jigsaw"
    }
  ]
}
