{
  size: [11, 10, 11], 
  entities: [
    {
      nbt: {
        Motion: [0.0d, 0.0d, 0.0d], 
        color: "light_gray", 
        block_pos: [I; -87, -61, 452], 
        Invulnerable: 0b, 
        Air: 300s, 
        OnGround: 0b, 
        fall_distance: 0.0d, 
        PortalCooldown: 0, 
        Rotation: [90.0f, 0.0f], 
        Pos: [-86.5d, -60.0625d, 452.5d], 
        Fire: 0s, 
        id: "minecraft:cushion", 
        UUID: [I; 1500831039, -1086502731, -2037009256, -335002563]
      }, 
      blockPos: [8, 1, 6], 
      pos: [8.5d, 1.9375d, 6.5d]
    }, 
    {
      nbt: {
        Motion: [0.0d, 0.0d, 0.0d], 
        color: "gray", 
        block_pos: [I; -86, -61, 450], 
        Invulnerable: 0b, 
        Air: 300s, 
        OnGround: 0b, 
        fall_distance: 0.0d, 
        PortalCooldown: 0, 
        Rotation: [90.0f, 0.0f], 
        Pos: [-85.5d, -60.0625d, 450.5d], 
        Fire: 0s, 
        id: "minecraft:cushion", 
        UUID: [I; -1290572159, -1161278295, -1522885746, 1871737353]
      }, 
      blockPos: [9, 1, 4], 
      pos: [9.5d, 1.9375d, 4.5d]
    }
  ], 
  blocks: [
    {
      pos: [0, 0, 0], 
      state: 0
    }, 
    {
      pos: [0, 0, 1], 
      state: 0
    }, 
    {
      pos: [0, 0, 2], 
      state: 0
    }, 
    {
      pos: [0, 0, 3], 
      state: 0
    }, 
    {
      pos: [0, 0, 4], 
      state: 0
    }, 
    {
      pos: [0, 0, 5], 
      state: 0
    }, 
    {
      pos: [0, 0, 6], 
      state: 0
    }, 
    {
      pos: [0, 0, 7], 
      state: 0
    }, 
    {
      pos: [0, 0, 8], 
      state: 0
    }, 
    {
      pos: [0, 0, 9], 
      state: 0
    }, 
    {
      pos: [0, 0, 10], 
      state: 0
    }, 
    {
      pos: [1, 0, 0], 
      state: 0
    }, 
    {
      pos: [1, 0, 1], 
      state: 0
    }, 
    {
      pos: [1, 0, 2], 
      state: 0
    }, 
    {
      pos: [1, 0, 3], 
      state: 1
    }, 
    {
      pos: [1, 0, 4], 
      state: 0
    }, 
    {
      pos: [1, 0, 5], 
      state: 0
    }, 
    {
      pos: [1, 0, 6], 
      state: 1
    }, 
    {
      pos: [1, 0, 7], 
      state: 1
    }, 
    {
      pos: [1, 0, 8], 
      state: 1
    }, 
    {
      pos: [1, 0, 9], 
      state: 1
    }, 
    {
      pos: [1, 0, 10], 
      state: 1
    }, 
    {
      pos: [2, 0, 0], 
      state: 0
    }, 
    {
      pos: [2, 0, 1], 
      state: 1
    }, 
    {
      pos: [2, 0, 2], 
      state: 1
    }, 
    {
      pos: [2, 0, 3], 
      state: 1
    }, 
    {
      pos: [2, 0, 4], 
      state: 0
    }, 
    {
      pos: [2, 0, 5], 
      state: 1
    }, 
    {
      pos: [2, 0, 6], 
      state: 2
    }, 
    {
      pos: [2, 0, 7], 
      state: 2
    }, 
    {
      pos: [2, 0, 8], 
      state: 2
    }, 
    {
      pos: [2, 0, 9], 
      state: 2
    }, 
    {
      pos: [2, 0, 10], 
      state: 1
    }, 
    {
      pos: [3, 0, 0], 
      state: 0
    }, 
    {
      pos: [3, 0, 1], 
      state: 0
    }, 
    {
      pos: [3, 0, 2], 
      state: 1
    }, 
    {
      pos: [3, 0, 3], 
      state: 1
    }, 
    {
      pos: [3, 0, 4], 
      state: 1
    }, 
    {
      pos: [3, 0, 5], 
      state: 1
    }, 
    {
      pos: [3, 0, 6], 
      state: 2
    }, 
    {
      pos: [3, 0, 7], 
      state: 2
    }, 
    {
      pos: [3, 0, 8], 
      state: 2
    }, 
    {
      pos: [3, 0, 9], 
      state: 2
    }, 
    {
      pos: [3, 0, 10], 
      state: 0
    }, 
    {
      pos: [4, 0, 0], 
      state: 0
    }, 
    {
      pos: [4, 0, 1], 
      state: 0
    }, 
    {
      pos: [4, 0, 2], 
      state: 0
    }, 
    {
      pos: [4, 0, 3], 
      state: 1
    }, 
    {
      pos: [4, 0, 4], 
      state: 1
    }, 
    {
      pos: [4, 0, 5], 
      state: 1
    }, 
    {
      pos: [4, 0, 6], 
      state: 1
    }, 
    {
      pos: [4, 0, 7], 
      state: 2
    }, 
    {
      pos: [4, 0, 8], 
      state: 2
    }, 
    {
      pos: [4, 0, 9], 
      state: 2
    }, 
    {
      pos: [4, 0, 10], 
      state: 1
    }, 
    {
      pos: [5, 0, 0], 
      state: 0
    }, 
    {
      pos: [5, 0, 1], 
      state: 0
    }, 
    {
      pos: [5, 0, 2], 
      state: 0
    }, 
    {
      pos: [5, 0, 3], 
      state: 1
    }, 
    {
      pos: [5, 0, 4], 
      state: 1
    }, 
    {
      pos: [5, 0, 5], 
      state: 0
    }, 
    {
      pos: [5, 0, 6], 
      state: 1
    }, 
    {
      pos: [5, 0, 7], 
      state: 1
    }, 
    {
      pos: [5, 0, 8], 
      state: 1
    }, 
    {
      pos: [5, 0, 9], 
      state: 1
    }, 
    {
      pos: [5, 0, 10], 
      state: 0
    }, 
    {
      pos: [6, 0, 0], 
      state: 0
    }, 
    {
      pos: [6, 0, 1], 
      state: 0
    }, 
    {
      pos: [6, 0, 2], 
      state: 0
    }, 
    {
      pos: [6, 0, 3], 
      state: 0
    }, 
    {
      pos: [6, 0, 4], 
      state: 0
    }, 
    {
      pos: [6, 0, 5], 
      state: 1
    }, 
    {
      pos: [6, 0, 6], 
      state: 0
    }, 
    {
      pos: [6, 0, 7], 
      state: 0
    }, 
    {
      pos: [6, 0, 8], 
      state: 1
    }, 
    {
      pos: [6, 0, 9], 
      state: 0
    }, 
    {
      pos: [6, 0, 10], 
      state: 0
    }, 
    {
      pos: [7, 0, 0], 
      state: 0
    }, 
    {
      pos: [7, 0, 1], 
      state: 0
    }, 
    {
      pos: [7, 0, 2], 
      state: 0
    }, 
    {
      pos: [7, 0, 3], 
      state: 0
    }, 
    {
      pos: [7, 0, 4], 
      state: 1
    }, 
    {
      pos: [7, 0, 5], 
      state: 1
    }, 
    {
      pos: [7, 0, 6], 
      state: 1
    }, 
    {
      pos: [7, 0, 7], 
      state: 0
    }, 
    {
      pos: [7, 0, 8], 
      state: 1
    }, 
    {
      pos: [7, 0, 9], 
      state: 1
    }, 
    {
      pos: [7, 0, 10], 
      state: 0
    }, 
    {
      pos: [8, 0, 0], 
      state: 0
    }, 
    {
      pos: [8, 0, 1], 
      state: 0
    }, 
    {
      pos: [8, 0, 2], 
      state: 0
    }, 
    {
      pos: [8, 0, 3], 
      state: 0
    }, 
    {
      pos: [8, 0, 4], 
      state: 0
    }, 
    {
      pos: [8, 0, 5], 
      state: 1
    }, 
    {
      pos: [8, 0, 6], 
      state: 1
    }, 
    {
      pos: [8, 0, 7], 
      state: 1
    }, 
    {
      pos: [8, 0, 8], 
      state: 1
    }, 
    {
      pos: [8, 0, 9], 
      state: 1
    }, 
    {
      pos: [8, 0, 10], 
      state: 0
    }, 
    {
      pos: [9, 0, 0], 
      state: 0
    }, 
    {
      pos: [9, 0, 1], 
      state: 0
    }, 
    {
      pos: [9, 0, 2], 
      state: 0
    }, 
    {
      pos: [9, 0, 3], 
      state: 1
    }, 
    {
      pos: [9, 0, 4], 
      state: 1
    }, 
    {
      pos: [9, 0, 5], 
      state: 1
    }, 
    {
      pos: [9, 0, 6], 
      state: 1
    }, 
    {
      pos: [9, 0, 7], 
      state: 1
    }, 
    {
      pos: [9, 0, 8], 
      state: 1
    }, 
    {
      pos: [9, 0, 9], 
      state: 0
    }, 
    {
      pos: [9, 0, 10], 
      state: 0
    }, 
    {
      pos: [10, 0, 0], 
      state: 0
    }, 
    {
      pos: [10, 0, 1], 
      state: 0
    }, 
    {
      pos: [10, 0, 2], 
      state: 0
    }, 
    {
      pos: [10, 0, 3], 
      state: 1
    }, 
    {
      pos: [10, 0, 4], 
      state: 1
    }, 
    {
      pos: [10, 0, 5], 
      state: 1
    }, 
    {
      pos: [10, 0, 6], 
      state: 1
    }, 
    {
      pos: [10, 0, 7], 
      state: 1
    }, 
    {
      pos: [10, 0, 8], 
      state: 1
    }, 
    {
      pos: [10, 0, 9], 
      state: 0
    }, 
    {
      pos: [10, 0, 10], 
      state: 0
    }, 
    {
      pos: [1, 1, 3], 
      state: 1
    }, 
    {
      pos: [1, 1, 6], 
      state: 2
    }, 
    {
      pos: [1, 1, 7], 
      state: 2
    }, 
    {
      pos: [1, 1, 8], 
      state: 0
    }, 
    {
      pos: [1, 1, 9], 
      state: 2
    }, 
    {
      pos: [1, 1, 10], 
      state: 2
    }, 
    {
      pos: [2, 1, 1], 
      state: 1
    }, 
    {
      pos: [2, 1, 2], 
      state: 1
    }, 
    {
      pos: [2, 1, 3], 
      state: 1
    }, 
    {
      pos: [2, 1, 5], 
      state: 2
    }, 
    {
      pos: [2, 1, 10], 
      state: 0
    }, 
    {
      pos: [3, 1, 2], 
      state: 1
    }, 
    {
      pos: [3, 1, 3], 
      state: 1
    }, 
    {
      pos: [3, 1, 4], 
      state: 1
    }, 
    {
      pos: [3, 1, 5], 
      state: 2
    }, 
    {
      pos: [3, 1, 9], 
      state: 2
    }, 
    {
      pos: [4, 1, 3], 
      state: 1
    }, 
    {
      pos: [4, 1, 4], 
      state: 1
    }, 
    {
      pos: [4, 1, 5], 
      state: 2
    }, 
    {
      pos: [4, 1, 6], 
      state: 2
    }, 
    {
      pos: [4, 1, 10], 
      state: 2
    }, 
    {
      pos: [5, 1, 3], 
      state: 1
    }, 
    {
      pos: [5, 1, 4], 
      state: 0
    }, 
    {
      pos: [5, 1, 5], 
      state: 2
    }, 
    {
      pos: [5, 1, 6], 
      state: 2
    }, 
    {
      pos: [5, 1, 7], 
      state: 2
    }, 
    {
      pos: [5, 1, 8], 
      state: 0
    }, 
    {
      pos: [5, 1, 9], 
      state: 2
    }, 
    {
      pos: [6, 1, 8], 
      state: 0
    }, 
    {
      pos: [7, 1, 8], 
      state: 0
    }, 
    {
      pos: [7, 1, 9], 
      state: 0
    }, 
    {
      pos: [8, 1, 8], 
      state: 0
    }, 
    {
      pos: [8, 1, 9], 
      state: 0
    }, 
    {
      pos: [9, 1, 5], 
      state: 0
    }, 
    {
      pos: [1, 2, 3], 
      state: 0
    }, 
    {
      pos: [2, 2, 1], 
      state: 0
    }, 
    {
      pos: [2, 2, 2], 
      state: 0
    }, 
    {
      pos: [2, 2, 3], 
      state: 0
    }, 
    {
      pos: [3, 2, 2], 
      state: 0
    }, 
    {
      pos: [3, 2, 3], 
      state: 1
    }, 
    {
      pos: [3, 2, 4], 
      state: 0
    }, 
    {
      pos: [4, 2, 3], 
      state: 0
    }, 
    {
      pos: [4, 2, 4], 
      state: 0
    }, 
    {
      pos: [5, 2, 3], 
      state: 0
    }, 
    {
      pos: [3, 3, 3], 
      state: 3
    }, 
    {
      pos: [3, 4, 3], 
      state: 3
    }, 
    {
      pos: [3, 5, 3], 
      state: 3
    }, 
    {
      pos: [0, 6, 0], 
      state: 4
    }, 
    {
      pos: [0, 6, 1], 
      state: 5
    }, 
    {
      pos: [0, 6, 2], 
      state: 6
    }, 
    {
      pos: [0, 6, 3], 
      state: 7
    }, 
    {
      pos: [0, 6, 4], 
      state: 6
    }, 
    {
      pos: [0, 6, 5], 
      state: 5
    }, 
    {
      pos: [0, 6, 6], 
      state: 4
    }, 
    {
      pos: [1, 6, 0], 
      state: 5
    }, 
    {
      pos: [1, 6, 1], 
      state: 6
    }, 
    {
      pos: [1, 6, 2], 
      state: 7
    }, 
    {
      pos: [1, 6, 3], 
      state: 8
    }, 
    {
      pos: [1, 6, 4], 
      state: 7
    }, 
    {
      pos: [1, 6, 5], 
      state: 6
    }, 
    {
      pos: [1, 6, 6], 
      state: 5
    }, 
    {
      pos: [2, 6, 0], 
      state: 6
    }, 
    {
      pos: [2, 6, 1], 
      state: 7
    }, 
    {
      pos: [2, 6, 2], 
      state: 8
    }, 
    {
      pos: [2, 6, 3], 
      state: 9
    }, 
    {
      pos: [2, 6, 4], 
      state: 8
    }, 
    {
      pos: [2, 6, 5], 
      state: 7
    }, 
    {
      pos: [2, 6, 6], 
      state: 6
    }, 
    {
      pos: [3, 6, 0], 
      state: 7
    }, 
    {
      pos: [3, 6, 1], 
      state: 8
    }, 
    {
      pos: [3, 6, 2], 
      state: 9
    }, 
    {
      pos: [3, 6, 3], 
      state: 3
    }, 
    {
      pos: [3, 6, 4], 
      state: 9
    }, 
    {
      pos: [3, 6, 5], 
      state: 8
    }, 
    {
      pos: [3, 6, 6], 
      state: 7
    }, 
    {
      pos: [4, 6, 0], 
      state: 6
    }, 
    {
      pos: [4, 6, 1], 
      state: 7
    }, 
    {
      pos: [4, 6, 2], 
      state: 8
    }, 
    {
      pos: [4, 6, 3], 
      state: 9
    }, 
    {
      pos: [4, 6, 4], 
      state: 8
    }, 
    {
      pos: [4, 6, 5], 
      state: 7
    }, 
    {
      pos: [4, 6, 6], 
      state: 6
    }, 
    {
      pos: [5, 6, 0], 
      state: 5
    }, 
    {
      pos: [5, 6, 1], 
      state: 6
    }, 
    {
      pos: [5, 6, 2], 
      state: 7
    }, 
    {
      pos: [5, 6, 3], 
      state: 8
    }, 
    {
      pos: [5, 6, 4], 
      state: 7
    }, 
    {
      pos: [5, 6, 5], 
      state: 6
    }, 
    {
      pos: [5, 6, 6], 
      state: 5
    }, 
    {
      pos: [6, 6, 0], 
      state: 4
    }, 
    {
      pos: [6, 6, 1], 
      state: 5
    }, 
    {
      pos: [6, 6, 2], 
      state: 6
    }, 
    {
      pos: [6, 6, 3], 
      state: 7
    }, 
    {
      pos: [6, 6, 4], 
      state: 6
    }, 
    {
      pos: [6, 6, 5], 
      state: 5
    }, 
    {
      pos: [6, 6, 6], 
      state: 4
    }, 
    {
      pos: [1, 7, 1], 
      state: 6
    }, 
    {
      pos: [1, 7, 2], 
      state: 7
    }, 
    {
      pos: [1, 7, 3], 
      state: 8
    }, 
    {
      pos: [1, 7, 4], 
      state: 7
    }, 
    {
      pos: [1, 7, 5], 
      state: 6
    }, 
    {
      pos: [2, 7, 1], 
      state: 7
    }, 
    {
      pos: [2, 7, 2], 
      state: 8
    }, 
    {
      pos: [2, 7, 3], 
      state: 9
    }, 
    {
      pos: [2, 7, 4], 
      state: 8
    }, 
    {
      pos: [2, 7, 5], 
      state: 7
    }, 
    {
      pos: [3, 7, 1], 
      state: 8
    }, 
    {
      pos: [3, 7, 2], 
      state: 9
    }, 
    {
      pos: [3, 7, 3], 
      state: 3
    }, 
    {
      pos: [3, 7, 4], 
      state: 9
    }, 
    {
      pos: [3, 7, 5], 
      state: 8
    }, 
    {
      pos: [4, 7, 1], 
      state: 7
    }, 
    {
      pos: [4, 7, 2], 
      state: 8
    }, 
    {
      pos: [4, 7, 3], 
      state: 9
    }, 
    {
      pos: [4, 7, 4], 
      state: 8
    }, 
    {
      pos: [4, 7, 5], 
      state: 7
    }, 
    {
      pos: [5, 7, 1], 
      state: 6
    }, 
    {
      pos: [5, 7, 2], 
      state: 7
    }, 
    {
      pos: [5, 7, 3], 
      state: 8
    }, 
    {
      pos: [5, 7, 4], 
      state: 7
    }, 
    {
      pos: [5, 7, 5], 
      state: 6
    }, 
    {
      pos: [1, 8, 2], 
      state: 6
    }, 
    {
      pos: [1, 8, 3], 
      state: 7
    }, 
    {
      pos: [1, 8, 4], 
      state: 6
    }, 
    {
      pos: [2, 8, 1], 
      state: 6
    }, 
    {
      pos: [2, 8, 2], 
      state: 7
    }, 
    {
      pos: [2, 8, 3], 
      state: 8
    }, 
    {
      pos: [2, 8, 4], 
      state: 7
    }, 
    {
      pos: [2, 8, 5], 
      state: 6
    }, 
    {
      pos: [3, 8, 1], 
      state: 7
    }, 
    {
      pos: [3, 8, 2], 
      state: 8
    }, 
    {
      pos: [3, 8, 3], 
      state: 9
    }, 
    {
      pos: [3, 8, 4], 
      state: 8
    }, 
    {
      pos: [3, 8, 5], 
      state: 7
    }, 
    {
      pos: [4, 8, 1], 
      state: 6
    }, 
    {
      pos: [4, 8, 2], 
      state: 7
    }, 
    {
      pos: [4, 8, 3], 
      state: 8
    }, 
    {
      pos: [4, 8, 4], 
      state: 7
    }, 
    {
      pos: [4, 8, 5], 
      state: 6
    }, 
    {
      pos: [5, 8, 2], 
      state: 6
    }, 
    {
      pos: [5, 8, 3], 
      state: 7
    }, 
    {
      pos: [5, 8, 4], 
      state: 6
    }, 
    {
      pos: [2, 1, 6], 
      state: 10
    }, 
    {
      pos: [2, 1, 7], 
      state: 10
    }, 
    {
      pos: [2, 1, 8], 
      state: 11
    }, 
    {
      pos: [2, 1, 9], 
      state: 11
    }, 
    {
      pos: [3, 1, 6], 
      state: 10
    }, 
    {
      pos: [3, 1, 7], 
      state: 11
    }, 
    {
      pos: [3, 1, 8], 
      state: 10
    }, 
    {
      pos: [4, 1, 7], 
      state: 11
    }, 
    {
      pos: [4, 1, 8], 
      state: 11
    }, 
    {
      pos: [4, 1, 9], 
      state: 11
    }, 
    {
      pos: [6, 1, 5], 
      state: 12
    }, 
    {
      pos: [7, 1, 4], 
      state: 12
    }, 
    {
      pos: [7, 1, 5], 
      state: 12
    }, 
    {
      pos: [7, 1, 6], 
      state: 12
    }, 
    {
      pos: [8, 1, 5], 
      state: 12
    }, 
    {
      pos: [8, 1, 6], 
      state: 12
    }, 
    {
      pos: [8, 1, 7], 
      state: 12
    }, 
    {
      pos: [9, 1, 3], 
      state: 12
    }, 
    {
      pos: [9, 1, 4], 
      state: 12
    }, 
    {
      pos: [9, 1, 6], 
      state: 12
    }, 
    {
      pos: [9, 1, 7], 
      state: 12
    }, 
    {
      pos: [9, 1, 8], 
      state: 12
    }, 
    {
      pos: [10, 1, 3], 
      state: 12
    }, 
    {
      pos: [10, 1, 4], 
      state: 12
    }, 
    {
      pos: [10, 1, 6], 
      state: 12
    }, 
    {
      pos: [10, 1, 7], 
      state: 12
    }, 
    {
      pos: [10, 1, 8], 
      state: 12
    }, 
    {
      pos: [2, 2, 4], 
      state: 13
    }, 
    {
      pos: [2, 2, 9], 
      state: 14
    }, 
    {
      pos: [2, 2, 10], 
      state: 15
    }, 
    {
      pos: [4, 2, 2], 
      state: 13
    }, 
    {
      pos: [4, 2, 8], 
      state: 14
    }, 
    {
      pos: [5, 2, 4], 
      state: 16
    }, 
    {
      pos: [5, 2, 8], 
      state: 15
    }, 
    {
      pos: [6, 2, 6], 
      state: 13
    }, 
    {
      pos: [6, 2, 8], 
      state: 16
    }, 
    {
      pos: [7, 2, 8], 
      state: 16
    }, 
    {
      pos: [7, 2, 9], 
      state: 16
    }, 
    {
      pos: [8, 2, 2], 
      state: 13
    }, 
    {
      pos: [8, 2, 9], 
      state: 16
    }, 
    {
      pos: [1, 3, 3], 
      state: 16
    }, 
    {
      pos: [2, 3, 3], 
      state: 17
    }, 
    {
      pos: [3, 3, 2], 
      state: 16
    }, 
    {
      pos: [3, 3, 4], 
      state: 16
    }, 
    {
      pos: [4, 3, 3], 
      state: 18
    }, 
    {
      pos: [4, 3, 4], 
      state: 19
    }, 
    {
      pos: [5, 3, 3], 
      state: 16
    }, 
    {
      pos: [7, 3, 0], 
      state: 18
    }, 
    {
      pos: [2, 4, 3], 
      state: 17
    }, 
    {
      pos: [3, 4, 2], 
      state: 20
    }, 
    {
      pos: [3, 4, 4], 
      state: 21
    }, 
    {
      pos: [3, 4, 7], 
      state: 21
    }, 
    {
      pos: [4, 4, 3], 
      state: 18
    }, 
    {
      pos: [6, 4, 7], 
      state: 21
    }, 
    {
      pos: [7, 4, 0], 
      state: 18
    }, 
    {
      pos: [7, 4, 6], 
      state: 18
    }, 
    {
      pos: [1, 5, 7], 
      state: 21
    }, 
    {
      pos: [3, 5, 2], 
      state: 22
    }, 
    {
      pos: [3, 5, 4], 
      state: 23
    }, 
    {
      pos: [3, 5, 7], 
      state: 21
    }, 
    {
      pos: [4, 5, 3], 
      state: 13
    }, 
    {
      pos: [4, 5, 7], 
      state: 21
    }, 
    {
      pos: [6, 5, 3], 
      state: 24
    }, 
    {
      pos: [6, 5, 7], 
      state: 21
    }, 
    {
      pos: [7, 5, 0], 
      state: 18
    }, 
    {
      pos: [7, 5, 3], 
      state: 18
    }, 
    {
      pos: [7, 5, 4], 
      state: 18
    }, 
    {
      pos: [7, 5, 6], 
      state: 18
    }, 
    {
      pos: [1, 6, 7], 
      state: 21
    }, 
    {
      pos: [3, 6, 7], 
      state: 21
    }, 
    {
      pos: [4, 6, 7], 
      state: 21
    }, 
    {
      pos: [6, 6, 7], 
      state: 21
    }, 
    {
      pos: [7, 6, 0], 
      state: 18
    }, 
    {
      pos: [7, 6, 3], 
      state: 18
    }, 
    {
      pos: [7, 6, 4], 
      state: 18
    }, 
    {
      pos: [7, 6, 6], 
      state: 18
    }, 
    {
      nbt: {
        components: {}, 
        joint: "rollable", 
        final_state: "minecraft:dirt_path", 
        name: "minecraft:end_connector", 
        placement_priority: 0, 
        pool: "minecraft:empty", 
        selection_priority: 0, 
        id: "minecraft:jigsaw", 
        target: "minecraft:connector"
      }, 
      pos: [10, 1, 5], 
      state: 25
    }, 
    {
      nbt: {
        LootTable: "minecraft:chests/abandoned_camp_common_chest", 
        components: {}, 
        id: "minecraft:chest"
      }, 
      pos: [8, 2, 8], 
      state: 26
    }, 
    {
      nbt: {
        components: {}, 
        Items: [], 
        CookingTimes: [I; 0, 0, 0, 0], 
        CookingTotalTimes: [I; 0, 0, 0, 0], 
        id: "minecraft:campfire"
      }, 
      pos: [9, 2, 5], 
      state: 27
    }
  ], 
  palette: [
    {
      id: "minecraft:grass_block", 
      properties: {
        snowy: "false"
      }
    }, 
    {
      id: "minecraft:dirt"
    }, 
    {
      id: "minecraft:clay"
    }, 
    {
      id: "minecraft:oak_log", 
      properties: {
        axis: "y"
      }
    }, 
    {
      id: "minecraft:oak_leaves", 
      properties: {
        waterlogged: "false", 
        distance: "6", 
        persistent: "true"
      }
    }, 
    {
      id: "minecraft:oak_leaves", 
      properties: {
        waterlogged: "false", 
        distance: "5", 
        persistent: "true"
      }
    }, 
    {
      id: "minecraft:oak_leaves", 
      properties: {
        waterlogged: "false", 
        distance: "4", 
        persistent: "true"
      }
    }, 
    {
      id: "minecraft:oak_leaves", 
      properties: {
        waterlogged: "false", 
        distance: "3", 
        persistent: "true"
      }
    }, 
    {
      id: "minecraft:oak_leaves", 
      properties: {
        waterlogged: "false", 
        distance: "2", 
        persistent: "true"
      }
    }, 
    {
      id: "minecraft:oak_leaves", 
      properties: {
        waterlogged: "false", 
        distance: "1", 
        persistent: "true"
      }
    }, 
    {
      id: "minecraft:seagrass"
    }, 
    {
      id: "minecraft:water", 
      properties: {
        level: "0"
      }
    }, 
    {
      id: "minecraft:dirt_path"
    }, 
    {
      id: "minecraft:cobweb"
    }, 
    {
      id: "minecraft:lily_pad"
    }, 
    {
      id: "minecraft:firefly_bush"
    }, 
    {
      id: "minecraft:short_grass"
    }, 
    {
      id: "minecraft:vine", 
      properties: {
        east: "true", 
        south: "false", 
        north: "false", 
        west: "false", 
        up: "false"
      }
    }, 
    {
      id: "minecraft:vine", 
      properties: {
        east: "false", 
        south: "false", 
        north: "false", 
        west: "true", 
        up: "false"
      }
    }, 
    {
      id: "minecraft:red_mushroom"
    }, 
    {
      id: "minecraft:vine", 
      properties: {
        east: "false", 
        south: "true", 
        north: "false", 
        west: "false", 
        up: "false"
      }
    }, 
    {
      id: "minecraft:vine", 
      properties: {
        east: "false", 
        south: "false", 
        north: "true", 
        west: "false", 
        up: "false"
      }
    }, 
    {
      id: "minecraft:vine", 
      properties: {
        east: "false", 
        south: "true", 
        north: "false", 
        west: "false", 
        up: "true"
      }
    }, 
    {
      id: "minecraft:vine", 
      properties: {
        east: "false", 
        south: "false", 
        north: "true", 
        west: "false", 
        up: "true"
      }
    }, 
    {
      id: "minecraft:vine", 
      properties: {
        east: "false", 
        south: "false", 
        north: "false", 
        west: "false", 
        up: "true"
      }
    }, 
    {
      id: "minecraft:jigsaw", 
      properties: {
        orientation: "east_up"
      }
    }, 
    {
      id: "minecraft:chest", 
      properties: {
        waterlogged: "false", 
        facing: "east", 
        type: "single"
      }
    }, 
    {
      id: "minecraft:campfire", 
      properties: {
        waterlogged: "false", 
        signal_fire: "false", 
        lit: "false", 
        facing: "west"
      }
    }
  ]
}
