{
  size: [11, 10, 10], 
  entities: [
    {
      nbt: {
        Motion: [0.0d, 0.0d, 0.0d], 
        color: "green", 
        block_pos: [I; -86, -61, 467], 
        Invulnerable: 0b, 
        Air: 300s, 
        OnGround: 0b, 
        fall_distance: 0.0d, 
        PortalCooldown: 0, 
        Rotation: [90.0f, 0.0f], 
        Pos: [-85.5d, -60.0625d, 467.5d], 
        Fire: 0s, 
        id: "minecraft:cushion", 
        UUID: [I; 250658999, 1395018639, -1810121144, 43777593]
      }, 
      blockPos: [8, 1, 5], 
      pos: [8.5d, 1.9375d, 5.5d]
    }, 
    {
      nbt: {
        Motion: [0.0d, 0.0d, 0.0d], 
        color: "green", 
        block_pos: [I; -86, -61, 467], 
        Invulnerable: 0b, 
        Air: 300s, 
        OnGround: 0b, 
        fall_distance: 0.0d, 
        PortalCooldown: 0, 
        Rotation: [90.0f, 0.0f], 
        Pos: [-85.5d, -60.0625d, 467.5d], 
        Fire: 0s, 
        id: "minecraft:cushion", 
        UUID: [I; -901118095, 312623735, -2018381717, 1015185138]
      }, 
      blockPos: [8, 1, 5], 
      pos: [8.5d, 1.9375d, 5.5d]
    }, 
    {
      nbt: {
        Motion: [0.0d, 0.0d, 0.0d], 
        color: "green", 
        block_pos: [I; -86, -61, 467], 
        Invulnerable: 0b, 
        Air: 300s, 
        OnGround: 0b, 
        fall_distance: 0.0d, 
        PortalCooldown: 0, 
        Rotation: [90.0f, 0.0f], 
        Pos: [-85.5d, -60.0625d, 467.5d], 
        Fire: 0s, 
        id: "minecraft:cushion", 
        UUID: [I; 2103887284, -138195838, -1505434825, -1215860960]
      }, 
      blockPos: [8, 1, 5], 
      pos: [8.5d, 1.9375d, 5.5d]
    }, 
    {
      nbt: {
        Motion: [0.0d, 0.0d, 0.0d], 
        color: "green", 
        block_pos: [I; -86, -61, 467], 
        Invulnerable: 0b, 
        Air: 300s, 
        OnGround: 0b, 
        fall_distance: 0.0d, 
        PortalCooldown: 0, 
        Rotation: [90.0f, 0.0f], 
        Pos: [-85.5d, -60.0625d, 467.5d], 
        Fire: 0s, 
        id: "minecraft:cushion", 
        UUID: [I; -1321386935, 281165862, -1805217744, 714807086]
      }, 
      blockPos: [8, 1, 5], 
      pos: [8.5d, 1.9375d, 5.5d]
    }, 
    {
      nbt: {
        Motion: [0.0d, 0.0d, 0.0d], 
        color: "green", 
        block_pos: [I; -86, -61, 467], 
        Invulnerable: 0b, 
        Air: 300s, 
        OnGround: 0b, 
        fall_distance: 0.0d, 
        PortalCooldown: 0, 
        Rotation: [90.0f, 0.0f], 
        Pos: [-85.5d, -60.0625d, 467.5d], 
        Fire: 0s, 
        id: "minecraft:cushion", 
        UUID: [I; -477267560, -514307753, -1428369283, 748848206]
      }, 
      blockPos: [8, 1, 5], 
      pos: [8.5d, 1.9375d, 5.5d]
    }, 
    {
      nbt: {
        Motion: [0.0d, 0.0d, 0.0d], 
        color: "green", 
        block_pos: [I; -86, -61, 467], 
        Invulnerable: 0b, 
        Air: 300s, 
        OnGround: 0b, 
        fall_distance: 0.0d, 
        PortalCooldown: 0, 
        Rotation: [90.0f, 0.0f], 
        Pos: [-85.5d, -60.0625d, 467.5d], 
        Fire: 0s, 
        id: "minecraft:cushion", 
        UUID: [I; 1565295832, 468274716, -1646104292, -192354055]
      }, 
      blockPos: [8, 1, 5], 
      pos: [8.5d, 1.9375d, 5.5d]
    }
  ], 
  blocks: [
    {
      pos: [0, 0, 0], 
      state: 0
    }, 
    {
      pos: [0, 0, 1], 
      state: 0
    }, 
    {
      pos: [0, 0, 2], 
      state: 0
    }, 
    {
      pos: [0, 0, 3], 
      state: 0
    }, 
    {
      pos: [0, 0, 4], 
      state: 0
    }, 
    {
      pos: [0, 0, 5], 
      state: 0
    }, 
    {
      pos: [0, 0, 6], 
      state: 0
    }, 
    {
      pos: [0, 0, 7], 
      state: 0
    }, 
    {
      pos: [0, 0, 8], 
      state: 0
    }, 
    {
      pos: [0, 0, 9], 
      state: 0
    }, 
    {
      pos: [1, 0, 0], 
      state: 0
    }, 
    {
      pos: [1, 0, 1], 
      state: 0
    }, 
    {
      pos: [1, 0, 2], 
      state: 0
    }, 
    {
      pos: [1, 0, 3], 
      state: 1
    }, 
    {
      pos: [1, 0, 4], 
      state: 1
    }, 
    {
      pos: [1, 0, 5], 
      state: 1
    }, 
    {
      pos: [1, 0, 6], 
      state: 1
    }, 
    {
      pos: [1, 0, 7], 
      state: 1
    }, 
    {
      pos: [1, 0, 8], 
      state: 1
    }, 
    {
      pos: [1, 0, 9], 
      state: 1
    }, 
    {
      pos: [2, 0, 0], 
      state: 0
    }, 
    {
      pos: [2, 0, 1], 
      state: 1
    }, 
    {
      pos: [2, 0, 2], 
      state: 1
    }, 
    {
      pos: [2, 0, 3], 
      state: 0
    }, 
    {
      pos: [2, 0, 4], 
      state: 1
    }, 
    {
      pos: [2, 0, 5], 
      state: 1
    }, 
    {
      pos: [2, 0, 6], 
      state: 1
    }, 
    {
      pos: [2, 0, 7], 
      state: 1
    }, 
    {
      pos: [2, 0, 8], 
      state: 1
    }, 
    {
      pos: [2, 0, 9], 
      state: 1
    }, 
    {
      pos: [3, 0, 0], 
      state: 0
    }, 
    {
      pos: [3, 0, 1], 
      state: 0
    }, 
    {
      pos: [3, 0, 2], 
      state: 0
    }, 
    {
      pos: [3, 0, 3], 
      state: 1
    }, 
    {
      pos: [3, 0, 4], 
      state: 1
    }, 
    {
      pos: [3, 0, 5], 
      state: 1
    }, 
    {
      pos: [3, 0, 6], 
      state: 2
    }, 
    {
      pos: [3, 0, 7], 
      state: 2
    }, 
    {
      pos: [3, 0, 8], 
      state: 1
    }, 
    {
      pos: [3, 0, 9], 
      state: 1
    }, 
    {
      pos: [4, 0, 0], 
      state: 0
    }, 
    {
      pos: [4, 0, 1], 
      state: 0
    }, 
    {
      pos: [4, 0, 2], 
      state: 1
    }, 
    {
      pos: [4, 0, 3], 
      state: 1
    }, 
    {
      pos: [4, 0, 4], 
      state: 1
    }, 
    {
      pos: [4, 0, 5], 
      state: 2
    }, 
    {
      pos: [4, 0, 6], 
      state: 1
    }, 
    {
      pos: [4, 0, 7], 
      state: 1
    }, 
    {
      pos: [4, 0, 8], 
      state: 1
    }, 
    {
      pos: [4, 0, 9], 
      state: 1
    }, 
    {
      pos: [5, 0, 0], 
      state: 0
    }, 
    {
      pos: [5, 0, 1], 
      state: 0
    }, 
    {
      pos: [5, 0, 2], 
      state: 0
    }, 
    {
      pos: [5, 0, 3], 
      state: 0
    }, 
    {
      pos: [5, 0, 4], 
      state: 1
    }, 
    {
      pos: [5, 0, 5], 
      state: 1
    }, 
    {
      pos: [5, 0, 6], 
      state: 1
    }, 
    {
      pos: [5, 0, 7], 
      state: 1
    }, 
    {
      pos: [5, 0, 8], 
      state: 1
    }, 
    {
      pos: [5, 0, 9], 
      state: 0
    }, 
    {
      pos: [6, 0, 0], 
      state: 0
    }, 
    {
      pos: [6, 0, 1], 
      state: 0
    }, 
    {
      pos: [6, 0, 2], 
      state: 0
    }, 
    {
      pos: [6, 0, 3], 
      state: 0
    }, 
    {
      pos: [6, 0, 4], 
      state: 1
    }, 
    {
      pos: [6, 0, 5], 
      state: 1
    }, 
    {
      pos: [6, 0, 6], 
      state: 1
    }, 
    {
      pos: [6, 0, 7], 
      state: 1
    }, 
    {
      pos: [6, 0, 8], 
      state: 0
    }, 
    {
      pos: [6, 0, 9], 
      state: 0
    }, 
    {
      pos: [7, 0, 0], 
      state: 0
    }, 
    {
      pos: [7, 0, 1], 
      state: 0
    }, 
    {
      pos: [7, 0, 2], 
      state: 0
    }, 
    {
      pos: [7, 0, 3], 
      state: 1
    }, 
    {
      pos: [7, 0, 4], 
      state: 1
    }, 
    {
      pos: [7, 0, 5], 
      state: 1
    }, 
    {
      pos: [7, 0, 6], 
      state: 1
    }, 
    {
      pos: [7, 0, 7], 
      state: 1
    }, 
    {
      pos: [7, 0, 8], 
      state: 0
    }, 
    {
      pos: [7, 0, 9], 
      state: 0
    }, 
    {
      pos: [8, 0, 0], 
      state: 0
    }, 
    {
      pos: [8, 0, 1], 
      state: 0
    }, 
    {
      pos: [8, 0, 2], 
      state: 1
    }, 
    {
      pos: [8, 0, 3], 
      state: 1
    }, 
    {
      pos: [8, 0, 4], 
      state: 1
    }, 
    {
      pos: [8, 0, 5], 
      state: 1
    }, 
    {
      pos: [8, 0, 6], 
      state: 1
    }, 
    {
      pos: [8, 0, 7], 
      state: 0
    }, 
    {
      pos: [8, 0, 8], 
      state: 1
    }, 
    {
      pos: [8, 0, 9], 
      state: 0
    }, 
    {
      pos: [9, 0, 0], 
      state: 0
    }, 
    {
      pos: [9, 0, 1], 
      state: 0
    }, 
    {
      pos: [9, 0, 2], 
      state: 1
    }, 
    {
      pos: [9, 0, 3], 
      state: 1
    }, 
    {
      pos: [9, 0, 4], 
      state: 1
    }, 
    {
      pos: [9, 0, 5], 
      state: 1
    }, 
    {
      pos: [9, 0, 6], 
      state: 1
    }, 
    {
      pos: [9, 0, 7], 
      state: 1
    }, 
    {
      pos: [9, 0, 8], 
      state: 0
    }, 
    {
      pos: [9, 0, 9], 
      state: 0
    }, 
    {
      pos: [10, 0, 0], 
      state: 0
    }, 
    {
      pos: [10, 0, 1], 
      state: 0
    }, 
    {
      pos: [10, 0, 2], 
      state: 0
    }, 
    {
      pos: [10, 0, 3], 
      state: 1
    }, 
    {
      pos: [10, 0, 4], 
      state: 1
    }, 
    {
      pos: [10, 0, 5], 
      state: 1
    }, 
    {
      pos: [10, 0, 6], 
      state: 0
    }, 
    {
      pos: [10, 0, 7], 
      state: 0
    }, 
    {
      pos: [10, 0, 8], 
      state: 0
    }, 
    {
      pos: [10, 0, 9], 
      state: 0
    }, 
    {
      pos: [1, 1, 3], 
      state: 0
    }, 
    {
      pos: [1, 1, 4], 
      state: 2
    }, 
    {
      pos: [1, 1, 5], 
      state: 2
    }, 
    {
      pos: [1, 1, 6], 
      state: 2
    }, 
    {
      pos: [1, 1, 7], 
      state: 2
    }, 
    {
      pos: [1, 1, 8], 
      state: 2
    }, 
    {
      pos: [1, 1, 9], 
      state: 2
    }, 
    {
      pos: [2, 1, 1], 
      state: 0
    }, 
    {
      pos: [2, 1, 2], 
      state: 0
    }, 
    {
      pos: [2, 1, 4], 
      state: 2
    }, 
    {
      pos: [2, 1, 9], 
      state: 2
    }, 
    {
      pos: [3, 1, 3], 
      state: 0
    }, 
    {
      pos: [3, 1, 4], 
      state: 2
    }, 
    {
      pos: [3, 1, 9], 
      state: 2
    }, 
    {
      pos: [4, 1, 2], 
      state: 1
    }, 
    {
      pos: [4, 1, 3], 
      state: 0
    }, 
    {
      pos: [4, 1, 4], 
      state: 2
    }, 
    {
      pos: [4, 1, 9], 
      state: 2
    }, 
    {
      pos: [5, 1, 4], 
      state: 0
    }, 
    {
      pos: [5, 1, 5], 
      state: 2
    }, 
    {
      pos: [5, 1, 8], 
      state: 2
    }, 
    {
      pos: [6, 1, 6], 
      state: 2
    }, 
    {
      pos: [6, 1, 7], 
      state: 2
    }, 
    {
      pos: [7, 1, 4], 
      state: 0
    }, 
    {
      pos: [7, 1, 7], 
      state: 2
    }, 
    {
      pos: [8, 1, 3], 
      state: 0
    }, 
    {
      pos: [8, 1, 6], 
      state: 1
    }, 
    {
      pos: [8, 1, 8], 
      state: 3
    }, 
    {
      pos: [9, 1, 3], 
      state: 0
    }, 
    {
      pos: [4, 2, 2], 
      state: 4
    }, 
    {
      pos: [8, 2, 7], 
      state: 4
    }, 
    {
      pos: [4, 3, 2], 
      state: 5
    }, 
    {
      pos: [8, 3, 7], 
      state: 5
    }, 
    {
      pos: [4, 4, 2], 
      state: 5
    }, 
    {
      pos: [8, 4, 7], 
      state: 5
    }, 
    {
      pos: [2, 5, 1], 
      state: 6
    }, 
    {
      pos: [2, 5, 2], 
      state: 7
    }, 
    {
      pos: [2, 5, 3], 
      state: 8
    }, 
    {
      pos: [3, 5, 0], 
      state: 6
    }, 
    {
      pos: [3, 5, 4], 
      state: 8
    }, 
    {
      pos: [4, 5, 0], 
      state: 9
    }, 
    {
      pos: [4, 5, 2], 
      state: 5
    }, 
    {
      pos: [4, 5, 4], 
      state: 10
    }, 
    {
      pos: [5, 5, 0], 
      state: 11
    }, 
    {
      pos: [5, 5, 4], 
      state: 12
    }, 
    {
      pos: [6, 5, 1], 
      state: 11
    }, 
    {
      pos: [6, 5, 2], 
      state: 13
    }, 
    {
      pos: [6, 5, 3], 
      state: 12
    }, 
    {
      pos: [8, 5, 7], 
      state: 14
    }, 
    {
      pos: [2, 6, 1], 
      state: 6
    }, 
    {
      pos: [2, 6, 2], 
      state: 7
    }, 
    {
      pos: [2, 6, 3], 
      state: 8
    }, 
    {
      pos: [3, 6, 0], 
      state: 6
    }, 
    {
      pos: [3, 6, 4], 
      state: 8
    }, 
    {
      pos: [4, 6, 0], 
      state: 9
    }, 
    {
      pos: [4, 6, 2], 
      state: 5
    }, 
    {
      pos: [4, 6, 4], 
      state: 10
    }, 
    {
      pos: [5, 6, 0], 
      state: 11
    }, 
    {
      pos: [5, 6, 4], 
      state: 12
    }, 
    {
      pos: [6, 6, 1], 
      state: 11
    }, 
    {
      pos: [6, 6, 2], 
      state: 13
    }, 
    {
      pos: [6, 6, 3], 
      state: 12
    }, 
    {
      pos: [6, 6, 6], 
      state: 15
    }, 
    {
      pos: [6, 6, 7], 
      state: 16
    }, 
    {
      pos: [6, 6, 8], 
      state: 17
    }, 
    {
      pos: [7, 6, 5], 
      state: 15
    }, 
    {
      pos: [7, 6, 6], 
      state: 18
    }, 
    {
      pos: [7, 6, 7], 
      state: 18
    }, 
    {
      pos: [7, 6, 8], 
      state: 18
    }, 
    {
      pos: [7, 6, 9], 
      state: 17
    }, 
    {
      pos: [8, 6, 5], 
      state: 19
    }, 
    {
      pos: [8, 6, 6], 
      state: 18
    }, 
    {
      pos: [8, 6, 7], 
      state: 18
    }, 
    {
      pos: [8, 6, 8], 
      state: 18
    }, 
    {
      pos: [8, 6, 9], 
      state: 20
    }, 
    {
      pos: [9, 6, 5], 
      state: 21
    }, 
    {
      pos: [9, 6, 6], 
      state: 18
    }, 
    {
      pos: [9, 6, 7], 
      state: 18
    }, 
    {
      pos: [9, 6, 8], 
      state: 18
    }, 
    {
      pos: [9, 6, 9], 
      state: 22
    }, 
    {
      pos: [10, 6, 6], 
      state: 21
    }, 
    {
      pos: [10, 6, 7], 
      state: 23
    }, 
    {
      pos: [10, 6, 8], 
      state: 22
    }, 
    {
      pos: [2, 7, 1], 
      state: 24
    }, 
    {
      pos: [2, 7, 2], 
      state: 25
    }, 
    {
      pos: [2, 7, 3], 
      state: 26
    }, 
    {
      pos: [3, 7, 0], 
      state: 24
    }, 
    {
      pos: [3, 7, 4], 
      state: 26
    }, 
    {
      pos: [4, 7, 0], 
      state: 27
    }, 
    {
      pos: [4, 7, 2], 
      state: 14
    }, 
    {
      pos: [4, 7, 4], 
      state: 28
    }, 
    {
      pos: [5, 7, 0], 
      state: 29
    }, 
    {
      pos: [5, 7, 4], 
      state: 30
    }, 
    {
      pos: [6, 7, 1], 
      state: 29
    }, 
    {
      pos: [6, 7, 2], 
      state: 31
    }, 
    {
      pos: [6, 7, 3], 
      state: 30
    }, 
    {
      pos: [3, 8, 1], 
      state: 24
    }, 
    {
      pos: [3, 8, 2], 
      state: 25
    }, 
    {
      pos: [3, 8, 3], 
      state: 26
    }, 
    {
      pos: [4, 8, 1], 
      state: 27
    }, 
    {
      pos: [4, 8, 2], 
      state: 32
    }, 
    {
      pos: [4, 8, 3], 
      state: 28
    }, 
    {
      pos: [5, 8, 1], 
      state: 29
    }, 
    {
      pos: [5, 8, 2], 
      state: 31
    }, 
    {
      pos: [5, 8, 3], 
      state: 30
    }, 
    {
      pos: [2, 1, 5], 
      state: 33
    }, 
    {
      pos: [2, 1, 6], 
      state: 34
    }, 
    {
      pos: [2, 1, 7], 
      state: 33
    }, 
    {
      pos: [2, 1, 8], 
      state: 34
    }, 
    {
      pos: [3, 1, 5], 
      state: 34
    }, 
    {
      pos: [3, 1, 6], 
      state: 33
    }, 
    {
      pos: [3, 1, 7], 
      state: 34
    }, 
    {
      pos: [3, 1, 8], 
      state: 33
    }, 
    {
      pos: [4, 1, 5], 
      state: 34
    }, 
    {
      pos: [4, 1, 6], 
      state: 33
    }, 
    {
      pos: [4, 1, 7], 
      state: 33
    }, 
    {
      pos: [4, 1, 8], 
      state: 34
    }, 
    {
      pos: [5, 1, 6], 
      state: 33
    }, 
    {
      pos: [5, 1, 7], 
      state: 34
    }, 
    {
      pos: [6, 1, 4], 
      state: 35
    }, 
    {
      pos: [6, 1, 5], 
      state: 35
    }, 
    {
      pos: [7, 1, 3], 
      state: 35
    }, 
    {
      pos: [7, 1, 5], 
      state: 35
    }, 
    {
      pos: [7, 1, 6], 
      state: 35
    }, 
    {
      pos: [8, 1, 2], 
      state: 35
    }, 
    {
      pos: [8, 1, 4], 
      state: 35
    }, 
    {
      pos: [8, 1, 5], 
      state: 35
    }, 
    {
      pos: [9, 1, 2], 
      state: 35
    }, 
    {
      pos: [9, 1, 4], 
      state: 35
    }, 
    {
      pos: [9, 1, 5], 
      state: 35
    }, 
    {
      pos: [9, 1, 6], 
      state: 35
    }, 
    {
      pos: [9, 1, 7], 
      state: 35
    }, 
    {
      pos: [10, 1, 3], 
      state: 35
    }, 
    {
      pos: [10, 1, 5], 
      state: 35
    }, 
    {
      pos: [1, 2, 3], 
      state: 36
    }, 
    {
      pos: [2, 2, 1], 
      state: 36
    }, 
    {
      pos: [2, 2, 2], 
      state: 36
    }, 
    {
      pos: [2, 2, 6], 
      state: 37
    }, 
    {
      pos: [3, 2, 3], 
      state: 36
    }, 
    {
      pos: [3, 2, 5], 
      state: 37
    }, 
    {
      pos: [3, 2, 7], 
      state: 37
    }, 
    {
      pos: [5, 2, 2], 
      state: 38
    }, 
    {
      pos: [5, 2, 4], 
      state: 36
    }, 
    {
      pos: [5, 2, 6], 
      state: 37
    }, 
    {
      pos: [7, 2, 7], 
      state: 38
    }, 
    {
      pos: [8, 2, 8], 
      state: 39
    }, 
    {
      pos: [9, 2, 3], 
      state: 38
    }, 
    {
      pos: [4, 3, 1], 
      state: 38
    }, 
    {
      pos: [5, 3, 2], 
      state: 38
    }, 
    {
      pos: [7, 3, 7], 
      state: 38
    }, 
    {
      pos: [5, 4, 2], 
      state: 38
    }, 
    {
      pos: [7, 4, 7], 
      state: 38
    }, 
    {
      pos: [8, 4, 6], 
      state: 38
    }, 
    {
      pos: [8, 5, 6], 
      state: 38
    }, 
    {
      nbt: {
        LootTable: "minecraft:chests/abandoned_camp_secret_chest", 
        components: {}, 
        id: "minecraft:chest"
      }, 
      pos: [8, 1, 7], 
      state: 40
    }, 
    {
      nbt: {
        components: {}, 
        joint: "rollable", 
        final_state: "minecraft:dirt_path", 
        name: "minecraft:end_connector", 
        placement_priority: 0, 
        pool: "minecraft:empty", 
        selection_priority: 0, 
        id: "minecraft:jigsaw", 
        target: "minecraft:connector"
      }, 
      pos: [10, 1, 4], 
      state: 41
    }, 
    {
      nbt: {
        components: {}, 
        Items: [], 
        CookingTimes: [I; 0, 0, 0, 0], 
        CookingTotalTimes: [I; 0, 0, 0, 0], 
        id: "minecraft:campfire"
      }, 
      pos: [7, 2, 4], 
      state: 42
    }, 
    {
      nbt: {
        LootTable: "minecraft:barrels/abandoned_camp_barrel", 
        components: {}, 
        id: "minecraft:barrel"
      }, 
      pos: [8, 2, 6], 
      state: 43
    }
  ], 
  palette: [
    {
      Properties: {
        snowy: "false"
      }, 
      Name: "minecraft:grass_block"
    }, 
    {
      Name: "minecraft:dirt"
    }, 
    {
      Name: "minecraft:clay"
    }, 
    {
      Properties: {
        snowy: "false"
      }, 
      Name: "minecraft:mycelium"
    }, 
    {
      Properties: {
        east: "true", 
        south: "true", 
        north: "true", 
        west: "true", 
        up: "false", 
        down: "true"
      }, 
      Name: "minecraft:mushroom_stem"
    }, 
    {
      Properties: {
        east: "true", 
        south: "true", 
        north: "true", 
        west: "true", 
        up: "false", 
        down: "false"
      }, 
      Name: "minecraft:mushroom_stem"
    }, 
    {
      Properties: {
        east: "false", 
        south: "false", 
        north: "true", 
        west: "true", 
        up: "false", 
        down: "false"
      }, 
      Name: "minecraft:red_mushroom_block"
    }, 
    {
      Properties: {
        east: "false", 
        south: "false", 
        north: "false", 
        west: "true", 
        up: "false", 
        down: "false"
      }, 
      Name: "minecraft:red_mushroom_block"
    }, 
    {
      Properties: {
        east: "false", 
        south: "true", 
        north: "false", 
        west: "true", 
        up: "false", 
        down: "false"
      }, 
      Name: "minecraft:red_mushroom_block"
    }, 
    {
      Properties: {
        east: "false", 
        south: "false", 
        north: "true", 
        west: "false", 
        up: "false", 
        down: "false"
      }, 
      Name: "minecraft:red_mushroom_block"
    }, 
    {
      Properties: {
        east: "false", 
        south: "true", 
        north: "false", 
        west: "false", 
        up: "false", 
        down: "false"
      }, 
      Name: "minecraft:red_mushroom_block"
    }, 
    {
      Properties: {
        east: "true", 
        south: "false", 
        north: "true", 
        west: "false", 
        up: "false", 
        down: "false"
      }, 
      Name: "minecraft:red_mushroom_block"
    }, 
    {
      Properties: {
        east: "true", 
        south: "true", 
        north: "false", 
        west: "false", 
        up: "false", 
        down: "false"
      }, 
      Name: "minecraft:red_mushroom_block"
    }, 
    {
      Properties: {
        east: "true", 
        south: "false", 
        north: "false", 
        west: "false", 
        up: "false", 
        down: "false"
      }, 
      Name: "minecraft:red_mushroom_block"
    }, 
    {
      Properties: {
        east: "true", 
        south: "true", 
        north: "true", 
        west: "true", 
        up: "true", 
        down: "false"
      }, 
      Name: "minecraft:mushroom_stem"
    }, 
    {
      Properties: {
        east: "false", 
        south: "false", 
        north: "true", 
        west: "true", 
        up: "true", 
        down: "true"
      }, 
      Name: "minecraft:brown_mushroom_block"
    }, 
    {
      Properties: {
        east: "false", 
        south: "false", 
        north: "false", 
        west: "true", 
        up: "true", 
        down: "true"
      }, 
      Name: "minecraft:brown_mushroom_block"
    }, 
    {
      Properties: {
        east: "false", 
        south: "true", 
        north: "false", 
        west: "true", 
        up: "true", 
        down: "true"
      }, 
      Name: "minecraft:brown_mushroom_block"
    }, 
    {
      Properties: {
        east: "false", 
        south: "false", 
        north: "false", 
        west: "false", 
        up: "true", 
        down: "true"
      }, 
      Name: "minecraft:brown_mushroom_block"
    }, 
    {
      Properties: {
        east: "false", 
        south: "false", 
        north: "true", 
        west: "false", 
        up: "true", 
        down: "true"
      }, 
      Name: "minecraft:brown_mushroom_block"
    }, 
    {
      Properties: {
        east: "false", 
        south: "true", 
        north: "false", 
        west: "false", 
        up: "true", 
        down: "true"
      }, 
      Name: "minecraft:brown_mushroom_block"
    }, 
    {
      Properties: {
        east: "true", 
        south: "false", 
        north: "true", 
        west: "false", 
        up: "true", 
        down: "true"
      }, 
      Name: "minecraft:brown_mushroom_block"
    }, 
    {
      Properties: {
        east: "true", 
        south: "true", 
        north: "false", 
        west: "false", 
        up: "true", 
        down: "true"
      }, 
      Name: "minecraft:brown_mushroom_block"
    }, 
    {
      Properties: {
        east: "true", 
        south: "false", 
        north: "false", 
        west: "false", 
        up: "true", 
        down: "true"
      }, 
      Name: "minecraft:brown_mushroom_block"
    }, 
    {
      Properties: {
        east: "false", 
        south: "false", 
        north: "true", 
        west: "true", 
        up: "true", 
        down: "false"
      }, 
      Name: "minecraft:red_mushroom_block"
    }, 
    {
      Properties: {
        east: "false", 
        south: "false", 
        north: "false", 
        west: "true", 
        up: "true", 
        down: "false"
      }, 
      Name: "minecraft:red_mushroom_block"
    }, 
    {
      Properties: {
        east: "false", 
        south: "true", 
        north: "false", 
        west: "true", 
        up: "true", 
        down: "false"
      }, 
      Name: "minecraft:red_mushroom_block"
    }, 
    {
      Properties: {
        east: "false", 
        south: "false", 
        north: "true", 
        west: "false", 
        up: "true", 
        down: "false"
      }, 
      Name: "minecraft:red_mushroom_block"
    }, 
    {
      Properties: {
        east: "false", 
        south: "true", 
        north: "false", 
        west: "false", 
        up: "true", 
        down: "false"
      }, 
      Name: "minecraft:red_mushroom_block"
    }, 
    {
      Properties: {
        east: "true", 
        south: "false", 
        north: "true", 
        west: "false", 
        up: "true", 
        down: "false"
      }, 
      Name: "minecraft:red_mushroom_block"
    }, 
    {
      Properties: {
        east: "true", 
        south: "true", 
        north: "false", 
        west: "false", 
        up: "true", 
        down: "false"
      }, 
      Name: "minecraft:red_mushroom_block"
    }, 
    {
      Properties: {
        east: "true", 
        south: "false", 
        north: "false", 
        west: "false", 
        up: "true", 
        down: "false"
      }, 
      Name: "minecraft:red_mushroom_block"
    }, 
    {
      Properties: {
        east: "false", 
        south: "false", 
        north: "false", 
        west: "false", 
        up: "true", 
        down: "true"
      }, 
      Name: "minecraft:red_mushroom_block"
    }, 
    {
      Name: "minecraft:seagrass"
    }, 
    {
      Properties: {
        level: "0"
      }, 
      Name: "minecraft:water"
    }, 
    {
      Name: "minecraft:dirt_path"
    }, 
    {
      Name: "minecraft:short_grass"
    }, 
    {
      Name: "minecraft:lily_pad"
    }, 
    {
      Name: "minecraft:cobweb"
    }, 
    {
      Name: "minecraft:brown_mushroom"
    }, 
    {
      Properties: {
        waterlogged: "false", 
        facing: "east", 
        type: "single"
      }, 
      Name: "minecraft:oxidized_copper_chest"
    }, 
    {
      Properties: {
        orientation: "east_up"
      }, 
      Name: "minecraft:jigsaw"
    }, 
    {
      Properties: {
        waterlogged: "false", 
        signal_fire: "false", 
        lit: "false", 
        facing: "west"
      }, 
      Name: "minecraft:campfire"
    }, 
    {
      Properties: {
        facing: "up", 
        open: "false"
      }, 
      Name: "minecraft:barrel"
    }
  ]
}
