{
  size: [12, 10, 10], 
  entities: [
    {
      nbt: {
        Motion: [0.0d, 0.0d, 0.0d], 
        color: "black", 
        block_pos: [I; -88, -61, 480], 
        Invulnerable: 0b, 
        Air: 300s, 
        OnGround: 0b, 
        fall_distance: 0.0d, 
        PortalCooldown: 0, 
        Rotation: [90.0f, 0.0f], 
        Pos: [-87.5d, -60.0625d, 480.5d], 
        Fire: 0s, 
        id: "minecraft:cushion", 
        UUID: [I; -1937218603, -1107999103, -2030115128, -2100916108]
      }, 
      blockPos: [8, 1, 3], 
      pos: [8.5d, 1.9375d, 3.5d]
    }, 
    {
      nbt: {
        Motion: [0.0d, 0.0d, 0.0d], 
        color: "black", 
        block_pos: [I; -86, -61, 482], 
        Invulnerable: 0b, 
        Air: 300s, 
        OnGround: 0b, 
        fall_distance: 0.0d, 
        PortalCooldown: 0, 
        Rotation: [90.0f, 0.0f], 
        Pos: [-85.5d, -60.0625d, 482.5d], 
        Fire: 0s, 
        id: "minecraft:cushion", 
        UUID: [I; -412476361, -574011874, -1802980412, 400786165]
      }, 
      blockPos: [10, 1, 5], 
      pos: [10.5d, 1.9375d, 5.5d]
    }
  ], 
  blocks: [
    {
      pos: [0, 0, 0], 
      state: 0
    }, 
    {
      pos: [0, 0, 1], 
      state: 0
    }, 
    {
      pos: [0, 0, 2], 
      state: 0
    }, 
    {
      pos: [0, 0, 3], 
      state: 0
    }, 
    {
      pos: [0, 0, 4], 
      state: 0
    }, 
    {
      pos: [0, 0, 5], 
      state: 0
    }, 
    {
      pos: [0, 0, 6], 
      state: 0
    }, 
    {
      pos: [0, 0, 7], 
      state: 0
    }, 
    {
      pos: [0, 0, 8], 
      state: 0
    }, 
    {
      pos: [0, 0, 9], 
      state: 0
    }, 
    {
      pos: [1, 0, 0], 
      state: 0
    }, 
    {
      pos: [1, 0, 1], 
      state: 0
    }, 
    {
      pos: [1, 0, 2], 
      state: 0
    }, 
    {
      pos: [1, 0, 3], 
      state: 0
    }, 
    {
      pos: [1, 0, 4], 
      state: 0
    }, 
    {
      pos: [1, 0, 5], 
      state: 0
    }, 
    {
      pos: [1, 0, 6], 
      state: 0
    }, 
    {
      pos: [1, 0, 7], 
      state: 1
    }, 
    {
      pos: [1, 0, 8], 
      state: 0
    }, 
    {
      pos: [1, 0, 9], 
      state: 0
    }, 
    {
      pos: [2, 0, 0], 
      state: 1
    }, 
    {
      pos: [2, 0, 1], 
      state: 1
    }, 
    {
      pos: [2, 0, 2], 
      state: 1
    }, 
    {
      pos: [2, 0, 3], 
      state: 1
    }, 
    {
      pos: [2, 0, 4], 
      state: 1
    }, 
    {
      pos: [2, 0, 5], 
      state: 1
    }, 
    {
      pos: [2, 0, 6], 
      state: 0
    }, 
    {
      pos: [2, 0, 7], 
      state: 0
    }, 
    {
      pos: [2, 0, 8], 
      state: 0
    }, 
    {
      pos: [2, 0, 9], 
      state: 0
    }, 
    {
      pos: [3, 0, 0], 
      state: 1
    }, 
    {
      pos: [3, 0, 1], 
      state: 1
    }, 
    {
      pos: [3, 0, 2], 
      state: 2
    }, 
    {
      pos: [3, 0, 3], 
      state: 1
    }, 
    {
      pos: [3, 0, 4], 
      state: 1
    }, 
    {
      pos: [3, 0, 5], 
      state: 1
    }, 
    {
      pos: [3, 0, 6], 
      state: 1
    }, 
    {
      pos: [3, 0, 7], 
      state: 1
    }, 
    {
      pos: [3, 0, 8], 
      state: 1
    }, 
    {
      pos: [3, 0, 9], 
      state: 0
    }, 
    {
      pos: [4, 0, 0], 
      state: 2
    }, 
    {
      pos: [4, 0, 1], 
      state: 1
    }, 
    {
      pos: [4, 0, 2], 
      state: 2
    }, 
    {
      pos: [4, 0, 3], 
      state: 1
    }, 
    {
      pos: [4, 0, 4], 
      state: 1
    }, 
    {
      pos: [4, 0, 5], 
      state: 1
    }, 
    {
      pos: [4, 0, 6], 
      state: 1
    }, 
    {
      pos: [4, 0, 7], 
      state: 1
    }, 
    {
      pos: [4, 0, 8], 
      state: 1
    }, 
    {
      pos: [4, 0, 9], 
      state: 2
    }, 
    {
      pos: [5, 0, 0], 
      state: 1
    }, 
    {
      pos: [5, 0, 1], 
      state: 2
    }, 
    {
      pos: [5, 0, 2], 
      state: 1
    }, 
    {
      pos: [5, 0, 3], 
      state: 1
    }, 
    {
      pos: [5, 0, 4], 
      state: 1
    }, 
    {
      pos: [5, 0, 5], 
      state: 1
    }, 
    {
      pos: [5, 0, 6], 
      state: 1
    }, 
    {
      pos: [5, 0, 7], 
      state: 2
    }, 
    {
      pos: [5, 0, 8], 
      state: 1
    }, 
    {
      pos: [5, 0, 9], 
      state: 1
    }, 
    {
      pos: [6, 0, 0], 
      state: 0
    }, 
    {
      pos: [6, 0, 1], 
      state: 1
    }, 
    {
      pos: [6, 0, 2], 
      state: 1
    }, 
    {
      pos: [6, 0, 3], 
      state: 1
    }, 
    {
      pos: [6, 0, 4], 
      state: 0
    }, 
    {
      pos: [6, 0, 5], 
      state: 1
    }, 
    {
      pos: [6, 0, 6], 
      state: 2
    }, 
    {
      pos: [6, 0, 7], 
      state: 2
    }, 
    {
      pos: [6, 0, 8], 
      state: 1
    }, 
    {
      pos: [6, 0, 9], 
      state: 0
    }, 
    {
      pos: [7, 0, 0], 
      state: 0
    }, 
    {
      pos: [7, 0, 1], 
      state: 0
    }, 
    {
      pos: [7, 0, 2], 
      state: 0
    }, 
    {
      pos: [7, 0, 3], 
      state: 1
    }, 
    {
      pos: [7, 0, 4], 
      state: 1
    }, 
    {
      pos: [7, 0, 5], 
      state: 0
    }, 
    {
      pos: [7, 0, 6], 
      state: 1
    }, 
    {
      pos: [7, 0, 7], 
      state: 1
    }, 
    {
      pos: [7, 0, 8], 
      state: 1
    }, 
    {
      pos: [7, 0, 9], 
      state: 0
    }, 
    {
      pos: [8, 0, 0], 
      state: 0
    }, 
    {
      pos: [8, 0, 1], 
      state: 0
    }, 
    {
      pos: [8, 0, 2], 
      state: 0
    }, 
    {
      pos: [8, 0, 3], 
      state: 1
    }, 
    {
      pos: [8, 0, 4], 
      state: 1
    }, 
    {
      pos: [8, 0, 5], 
      state: 0
    }, 
    {
      pos: [8, 0, 6], 
      state: 0
    }, 
    {
      pos: [8, 0, 7], 
      state: 1
    }, 
    {
      pos: [8, 0, 8], 
      state: 0
    }, 
    {
      pos: [8, 0, 9], 
      state: 0
    }, 
    {
      pos: [9, 0, 0], 
      state: 0
    }, 
    {
      pos: [9, 0, 1], 
      state: 0
    }, 
    {
      pos: [9, 0, 2], 
      state: 0
    }, 
    {
      pos: [9, 0, 3], 
      state: 1
    }, 
    {
      pos: [9, 0, 4], 
      state: 1
    }, 
    {
      pos: [9, 0, 5], 
      state: 0
    }, 
    {
      pos: [9, 0, 6], 
      state: 1
    }, 
    {
      pos: [9, 0, 7], 
      state: 1
    }, 
    {
      pos: [9, 0, 8], 
      state: 0
    }, 
    {
      pos: [9, 0, 9], 
      state: 0
    }, 
    {
      pos: [10, 0, 0], 
      state: 0
    }, 
    {
      pos: [10, 0, 1], 
      state: 0
    }, 
    {
      pos: [10, 0, 2], 
      state: 1
    }, 
    {
      pos: [10, 0, 3], 
      state: 1
    }, 
    {
      pos: [10, 0, 4], 
      state: 1
    }, 
    {
      pos: [10, 0, 5], 
      state: 1
    }, 
    {
      pos: [10, 0, 6], 
      state: 1
    }, 
    {
      pos: [10, 0, 7], 
      state: 0
    }, 
    {
      pos: [10, 0, 8], 
      state: 0
    }, 
    {
      pos: [10, 0, 9], 
      state: 0
    }, 
    {
      pos: [11, 0, 0], 
      state: 0
    }, 
    {
      pos: [11, 0, 1], 
      state: 0
    }, 
    {
      pos: [11, 0, 2], 
      state: 0
    }, 
    {
      pos: [11, 0, 3], 
      state: 1
    }, 
    {
      pos: [11, 0, 4], 
      state: 1
    }, 
    {
      pos: [11, 0, 5], 
      state: 1
    }, 
    {
      pos: [11, 0, 6], 
      state: 1
    }, 
    {
      pos: [11, 0, 7], 
      state: 0
    }, 
    {
      pos: [11, 0, 8], 
      state: 0
    }, 
    {
      pos: [11, 0, 9], 
      state: 0
    }, 
    {
      pos: [1, 1, 7], 
      state: 0
    }, 
    {
      pos: [2, 1, 0], 
      state: 0
    }, 
    {
      pos: [2, 1, 1], 
      state: 2
    }, 
    {
      pos: [2, 1, 2], 
      state: 2
    }, 
    {
      pos: [2, 1, 3], 
      state: 2
    }, 
    {
      pos: [2, 1, 4], 
      state: 1
    }, 
    {
      pos: [2, 1, 5], 
      state: 1
    }, 
    {
      pos: [3, 1, 0], 
      state: 2
    }, 
    {
      pos: [3, 1, 3], 
      state: 2
    }, 
    {
      pos: [3, 1, 4], 
      state: 1
    }, 
    {
      pos: [3, 1, 5], 
      state: 1
    }, 
    {
      pos: [3, 1, 6], 
      state: 1
    }, 
    {
      pos: [3, 1, 7], 
      state: 2
    }, 
    {
      pos: [3, 1, 8], 
      state: 0
    }, 
    {
      pos: [4, 1, 0], 
      state: 2
    }, 
    {
      pos: [4, 1, 4], 
      state: 0
    }, 
    {
      pos: [4, 1, 5], 
      state: 1
    }, 
    {
      pos: [4, 1, 6], 
      state: 2
    }, 
    {
      pos: [4, 1, 9], 
      state: 2
    }, 
    {
      pos: [5, 1, 0], 
      state: 2
    }, 
    {
      pos: [5, 1, 3], 
      state: 2
    }, 
    {
      pos: [5, 1, 4], 
      state: 1
    }, 
    {
      pos: [5, 1, 5], 
      state: 0
    }, 
    {
      pos: [5, 1, 9], 
      state: 2
    }, 
    {
      pos: [6, 1, 1], 
      state: 2
    }, 
    {
      pos: [6, 1, 2], 
      state: 2
    }, 
    {
      pos: [6, 1, 3], 
      state: 0
    }, 
    {
      pos: [6, 1, 5], 
      state: 2
    }, 
    {
      pos: [6, 1, 8], 
      state: 2
    }, 
    {
      pos: [7, 1, 4], 
      state: 0
    }, 
    {
      pos: [7, 1, 6], 
      state: 2
    }, 
    {
      pos: [7, 1, 8], 
      state: 2
    }, 
    {
      pos: [8, 1, 7], 
      state: 2
    }, 
    {
      pos: [9, 1, 4], 
      state: 0
    }, 
    {
      pos: [9, 1, 6], 
      state: 1
    }, 
    {
      pos: [9, 1, 7], 
      state: 0
    }, 
    {
      pos: [2, 2, 4], 
      state: 0
    }, 
    {
      pos: [2, 2, 5], 
      state: 0
    }, 
    {
      pos: [3, 2, 4], 
      state: 0
    }, 
    {
      pos: [3, 2, 5], 
      state: 0
    }, 
    {
      pos: [3, 2, 6], 
      state: 0
    }, 
    {
      pos: [4, 2, 5], 
      state: 1
    }, 
    {
      pos: [5, 2, 4], 
      state: 0
    }, 
    {
      pos: [4, 3, 5], 
      state: 3
    }, 
    {
      pos: [4, 4, 5], 
      state: 3
    }, 
    {
      pos: [4, 5, 5], 
      state: 3
    }, 
    {
      pos: [1, 6, 2], 
      state: 4
    }, 
    {
      pos: [1, 6, 3], 
      state: 5
    }, 
    {
      pos: [1, 6, 4], 
      state: 6
    }, 
    {
      pos: [1, 6, 5], 
      state: 7
    }, 
    {
      pos: [1, 6, 6], 
      state: 6
    }, 
    {
      pos: [1, 6, 7], 
      state: 5
    }, 
    {
      pos: [1, 6, 8], 
      state: 4
    }, 
    {
      pos: [2, 6, 2], 
      state: 5
    }, 
    {
      pos: [2, 6, 3], 
      state: 6
    }, 
    {
      pos: [2, 6, 4], 
      state: 7
    }, 
    {
      pos: [2, 6, 5], 
      state: 8
    }, 
    {
      pos: [2, 6, 6], 
      state: 7
    }, 
    {
      pos: [2, 6, 7], 
      state: 6
    }, 
    {
      pos: [2, 6, 8], 
      state: 5
    }, 
    {
      pos: [3, 6, 2], 
      state: 6
    }, 
    {
      pos: [3, 6, 3], 
      state: 7
    }, 
    {
      pos: [3, 6, 4], 
      state: 8
    }, 
    {
      pos: [3, 6, 5], 
      state: 9
    }, 
    {
      pos: [3, 6, 6], 
      state: 8
    }, 
    {
      pos: [3, 6, 7], 
      state: 7
    }, 
    {
      pos: [3, 6, 8], 
      state: 6
    }, 
    {
      pos: [4, 6, 2], 
      state: 7
    }, 
    {
      pos: [4, 6, 3], 
      state: 8
    }, 
    {
      pos: [4, 6, 4], 
      state: 9
    }, 
    {
      pos: [4, 6, 5], 
      state: 3
    }, 
    {
      pos: [4, 6, 6], 
      state: 9
    }, 
    {
      pos: [4, 6, 7], 
      state: 8
    }, 
    {
      pos: [4, 6, 8], 
      state: 7
    }, 
    {
      pos: [5, 6, 2], 
      state: 6
    }, 
    {
      pos: [5, 6, 3], 
      state: 7
    }, 
    {
      pos: [5, 6, 4], 
      state: 8
    }, 
    {
      pos: [5, 6, 5], 
      state: 9
    }, 
    {
      pos: [5, 6, 6], 
      state: 8
    }, 
    {
      pos: [5, 6, 7], 
      state: 7
    }, 
    {
      pos: [5, 6, 8], 
      state: 6
    }, 
    {
      pos: [6, 6, 2], 
      state: 5
    }, 
    {
      pos: [6, 6, 3], 
      state: 6
    }, 
    {
      pos: [6, 6, 4], 
      state: 7
    }, 
    {
      pos: [6, 6, 5], 
      state: 8
    }, 
    {
      pos: [6, 6, 6], 
      state: 7
    }, 
    {
      pos: [6, 6, 7], 
      state: 6
    }, 
    {
      pos: [6, 6, 8], 
      state: 5
    }, 
    {
      pos: [7, 6, 2], 
      state: 4
    }, 
    {
      pos: [7, 6, 3], 
      state: 5
    }, 
    {
      pos: [7, 6, 4], 
      state: 6
    }, 
    {
      pos: [7, 6, 5], 
      state: 7
    }, 
    {
      pos: [7, 6, 6], 
      state: 6
    }, 
    {
      pos: [7, 6, 7], 
      state: 5
    }, 
    {
      pos: [7, 6, 8], 
      state: 4
    }, 
    {
      pos: [2, 7, 3], 
      state: 6
    }, 
    {
      pos: [2, 7, 4], 
      state: 7
    }, 
    {
      pos: [2, 7, 5], 
      state: 8
    }, 
    {
      pos: [2, 7, 6], 
      state: 7
    }, 
    {
      pos: [2, 7, 7], 
      state: 6
    }, 
    {
      pos: [3, 7, 3], 
      state: 7
    }, 
    {
      pos: [3, 7, 4], 
      state: 8
    }, 
    {
      pos: [3, 7, 5], 
      state: 9
    }, 
    {
      pos: [3, 7, 6], 
      state: 8
    }, 
    {
      pos: [3, 7, 7], 
      state: 7
    }, 
    {
      pos: [4, 7, 3], 
      state: 8
    }, 
    {
      pos: [4, 7, 4], 
      state: 9
    }, 
    {
      pos: [4, 7, 5], 
      state: 3
    }, 
    {
      pos: [4, 7, 6], 
      state: 9
    }, 
    {
      pos: [4, 7, 7], 
      state: 8
    }, 
    {
      pos: [5, 7, 3], 
      state: 7
    }, 
    {
      pos: [5, 7, 4], 
      state: 8
    }, 
    {
      pos: [5, 7, 5], 
      state: 9
    }, 
    {
      pos: [5, 7, 6], 
      state: 8
    }, 
    {
      pos: [5, 7, 7], 
      state: 7
    }, 
    {
      pos: [6, 7, 3], 
      state: 6
    }, 
    {
      pos: [6, 7, 4], 
      state: 7
    }, 
    {
      pos: [6, 7, 5], 
      state: 8
    }, 
    {
      pos: [6, 7, 6], 
      state: 7
    }, 
    {
      pos: [6, 7, 7], 
      state: 6
    }, 
    {
      pos: [2, 8, 4], 
      state: 6
    }, 
    {
      pos: [2, 8, 5], 
      state: 7
    }, 
    {
      pos: [2, 8, 6], 
      state: 6
    }, 
    {
      pos: [3, 8, 3], 
      state: 6
    }, 
    {
      pos: [3, 8, 4], 
      state: 7
    }, 
    {
      pos: [3, 8, 5], 
      state: 8
    }, 
    {
      pos: [3, 8, 6], 
      state: 7
    }, 
    {
      pos: [3, 8, 7], 
      state: 6
    }, 
    {
      pos: [4, 8, 3], 
      state: 7
    }, 
    {
      pos: [4, 8, 4], 
      state: 8
    }, 
    {
      pos: [4, 8, 5], 
      state: 9
    }, 
    {
      pos: [4, 8, 6], 
      state: 8
    }, 
    {
      pos: [4, 8, 7], 
      state: 7
    }, 
    {
      pos: [5, 8, 3], 
      state: 6
    }, 
    {
      pos: [5, 8, 4], 
      state: 7
    }, 
    {
      pos: [5, 8, 5], 
      state: 8
    }, 
    {
      pos: [5, 8, 6], 
      state: 7
    }, 
    {
      pos: [5, 8, 7], 
      state: 6
    }, 
    {
      pos: [6, 8, 4], 
      state: 6
    }, 
    {
      pos: [6, 8, 5], 
      state: 7
    }, 
    {
      pos: [6, 8, 6], 
      state: 6
    }, 
    {
      pos: [0, 1, 3], 
      state: 10
    }, 
    {
      pos: [0, 1, 5], 
      state: 10
    }, 
    {
      pos: [0, 1, 6], 
      state: 10
    }, 
    {
      pos: [1, 1, 1], 
      state: 11
    }, 
    {
      pos: [3, 1, 1], 
      state: 12
    }, 
    {
      pos: [3, 1, 2], 
      state: 13
    }, 
    {
      pos: [4, 1, 1], 
      state: 13
    }, 
    {
      pos: [4, 1, 2], 
      state: 13
    }, 
    {
      pos: [4, 1, 3], 
      state: 12
    }, 
    {
      pos: [4, 1, 7], 
      state: 12
    }, 
    {
      pos: [4, 1, 8], 
      state: 13
    }, 
    {
      pos: [5, 1, 1], 
      state: 12
    }, 
    {
      pos: [5, 1, 2], 
      state: 13
    }, 
    {
      pos: [5, 1, 6], 
      state: 13
    }, 
    {
      pos: [5, 1, 7], 
      state: 12
    }, 
    {
      pos: [5, 1, 8], 
      state: 13
    }, 
    {
      pos: [6, 1, 6], 
      state: 13
    }, 
    {
      pos: [6, 1, 7], 
      state: 12
    }, 
    {
      pos: [7, 1, 3], 
      state: 14
    }, 
    {
      pos: [7, 1, 7], 
      state: 13
    }, 
    {
      pos: [8, 1, 2], 
      state: 15
    }, 
    {
      pos: [8, 1, 3], 
      state: 14
    }, 
    {
      pos: [8, 1, 4], 
      state: 14
    }, 
    {
      pos: [8, 1, 5], 
      state: 15
    }, 
    {
      pos: [8, 1, 8], 
      state: 15
    }, 
    {
      pos: [9, 1, 3], 
      state: 14
    }, 
    {
      pos: [10, 1, 2], 
      state: 14
    }, 
    {
      pos: [10, 1, 3], 
      state: 14
    }, 
    {
      pos: [10, 1, 4], 
      state: 14
    }, 
    {
      pos: [10, 1, 5], 
      state: 14
    }, 
    {
      pos: [10, 1, 6], 
      state: 14
    }, 
    {
      pos: [11, 1, 3], 
      state: 14
    }, 
    {
      pos: [11, 1, 5], 
      state: 14
    }, 
    {
      pos: [11, 1, 6], 
      state: 14
    }, 
    {
      pos: [0, 2, 3], 
      state: 10
    }, 
    {
      pos: [0, 2, 5], 
      state: 10
    }, 
    {
      pos: [0, 2, 6], 
      state: 10
    }, 
    {
      pos: [1, 2, 1], 
      state: 11
    }, 
    {
      pos: [1, 2, 7], 
      state: 16
    }, 
    {
      pos: [2, 2, 0], 
      state: 17
    }, 
    {
      pos: [2, 2, 1], 
      state: 11
    }, 
    {
      pos: [3, 2, 1], 
      state: 18
    }, 
    {
      pos: [3, 2, 8], 
      state: 17
    }, 
    {
      pos: [4, 2, 2], 
      state: 18
    }, 
    {
      pos: [4, 2, 4], 
      state: 16
    }, 
    {
      pos: [4, 2, 6], 
      state: 19
    }, 
    {
      pos: [4, 2, 8], 
      state: 18
    }, 
    {
      pos: [5, 2, 1], 
      state: 11
    }, 
    {
      pos: [5, 2, 5], 
      state: 16
    }, 
    {
      pos: [6, 2, 1], 
      state: 11
    }, 
    {
      pos: [6, 2, 3], 
      state: 17
    }, 
    {
      pos: [6, 2, 7], 
      state: 18
    }, 
    {
      pos: [8, 2, 2], 
      state: 15
    }, 
    {
      pos: [8, 2, 4], 
      state: 15
    }, 
    {
      pos: [8, 2, 5], 
      state: 15
    }, 
    {
      pos: [8, 2, 7], 
      state: 15
    }, 
    {
      pos: [8, 2, 8], 
      state: 15
    }, 
    {
      pos: [9, 2, 7], 
      state: 17
    }, 
    {
      pos: [0, 3, 3], 
      state: 10
    }, 
    {
      pos: [0, 3, 5], 
      state: 10
    }, 
    {
      pos: [0, 3, 6], 
      state: 10
    }, 
    {
      pos: [1, 3, 1], 
      state: 11
    }, 
    {
      pos: [2, 3, 1], 
      state: 11
    }, 
    {
      pos: [2, 3, 4], 
      state: 16
    }, 
    {
      pos: [3, 3, 5], 
      state: 10
    }, 
    {
      pos: [3, 3, 6], 
      state: 17
    }, 
    {
      pos: [4, 3, 4], 
      state: 11
    }, 
    {
      pos: [4, 3, 6], 
      state: 19
    }, 
    {
      pos: [5, 3, 1], 
      state: 11
    }, 
    {
      pos: [5, 3, 4], 
      state: 17
    }, 
    {
      pos: [5, 3, 5], 
      state: 15
    }, 
    {
      pos: [6, 3, 1], 
      state: 11
    }, 
    {
      pos: [8, 3, 2], 
      state: 15
    }, 
    {
      pos: [8, 3, 4], 
      state: 15
    }, 
    {
      pos: [8, 3, 5], 
      state: 15
    }, 
    {
      pos: [8, 3, 7], 
      state: 15
    }, 
    {
      pos: [8, 3, 8], 
      state: 15
    }, 
    {
      pos: [0, 4, 3], 
      state: 10
    }, 
    {
      pos: [0, 4, 5], 
      state: 10
    }, 
    {
      pos: [0, 4, 6], 
      state: 10
    }, 
    {
      pos: [1, 4, 1], 
      state: 11
    }, 
    {
      pos: [2, 4, 1], 
      state: 11
    }, 
    {
      pos: [3, 4, 5], 
      state: 10
    }, 
    {
      pos: [4, 4, 4], 
      state: 11
    }, 
    {
      pos: [4, 4, 6], 
      state: 19
    }, 
    {
      pos: [5, 4, 1], 
      state: 11
    }, 
    {
      pos: [5, 4, 5], 
      state: 15
    }, 
    {
      pos: [6, 4, 1], 
      state: 11
    }, 
    {
      pos: [8, 4, 2], 
      state: 15
    }, 
    {
      pos: [8, 4, 4], 
      state: 15
    }, 
    {
      pos: [8, 4, 5], 
      state: 15
    }, 
    {
      pos: [8, 4, 7], 
      state: 15
    }, 
    {
      pos: [8, 4, 8], 
      state: 15
    }, 
    {
      pos: [0, 5, 3], 
      state: 10
    }, 
    {
      pos: [0, 5, 5], 
      state: 10
    }, 
    {
      pos: [0, 5, 6], 
      state: 10
    }, 
    {
      pos: [1, 5, 1], 
      state: 11
    }, 
    {
      pos: [2, 5, 1], 
      state: 11
    }, 
    {
      pos: [3, 5, 5], 
      state: 20
    }, 
    {
      pos: [4, 5, 4], 
      state: 21
    }, 
    {
      pos: [4, 5, 6], 
      state: 22
    }, 
    {
      pos: [5, 5, 1], 
      state: 11
    }, 
    {
      pos: [5, 5, 5], 
      state: 23
    }, 
    {
      pos: [6, 5, 1], 
      state: 11
    }, 
    {
      pos: [8, 5, 2], 
      state: 15
    }, 
    {
      pos: [8, 5, 4], 
      state: 15
    }, 
    {
      pos: [8, 5, 5], 
      state: 15
    }, 
    {
      pos: [8, 5, 7], 
      state: 15
    }, 
    {
      pos: [8, 5, 8], 
      state: 15
    }, 
    {
      pos: [0, 6, 3], 
      state: 10
    }, 
    {
      pos: [0, 6, 5], 
      state: 10
    }, 
    {
      pos: [0, 6, 6], 
      state: 10
    }, 
    {
      pos: [1, 6, 1], 
      state: 11
    }, 
    {
      pos: [2, 6, 1], 
      state: 11
    }, 
    {
      pos: [5, 6, 1], 
      state: 11
    }, 
    {
      pos: [6, 6, 1], 
      state: 11
    }, 
    {
      pos: [8, 6, 2], 
      state: 15
    }, 
    {
      pos: [8, 6, 4], 
      state: 15
    }, 
    {
      pos: [8, 6, 5], 
      state: 15
    }, 
    {
      pos: [8, 6, 7], 
      state: 15
    }, 
    {
      pos: [8, 6, 8], 
      state: 15
    }, 
    {
      nbt: {
        components: {}, 
        joint: "rollable", 
        final_state: "minecraft:dirt_path", 
        name: "minecraft:end_connector", 
        placement_priority: 0, 
        pool: "minecraft:empty", 
        selection_priority: 0, 
        id: "minecraft:jigsaw", 
        target: "minecraft:connector"
      }, 
      pos: [11, 1, 4], 
      state: 24
    }, 
    {
      nbt: {
        LootTable: "minecraft:chests/abandoned_camp_common_chest", 
        components: {}, 
        Items: [], 
        id: "minecraft:chest"
      }, 
      pos: [7, 2, 4], 
      state: 25
    }, 
    {
      nbt: {
        components: {}, 
        Items: [], 
        CookingTimes: [I; 0, 0, 0, 0], 
        CookingTotalTimes: [I; 0, 0, 0, 0], 
        id: "minecraft:campfire"
      }, 
      pos: [9, 2, 4], 
      state: 26
    }, 
    {
      nbt: {
        LootTable: "minecraft:barrels/abandoned_camp_barrel", 
        components: {}, 
        Items: [], 
        id: "minecraft:barrel"
      }, 
      pos: [9, 2, 6], 
      state: 27
    }
  ], 
  palette: [
    {
      Properties: {
        snowy: "false"
      }, 
      Name: "minecraft:grass_block"
    }, 
    {
      Name: "minecraft:dirt"
    }, 
    {
      Name: "minecraft:clay"
    }, 
    {
      Properties: {
        axis: "y"
      }, 
      Name: "minecraft:oak_log"
    }, 
    {
      Properties: {
        waterlogged: "false", 
        distance: "6", 
        persistent: "true"
      }, 
      Name: "minecraft:oak_leaves"
    }, 
    {
      Properties: {
        waterlogged: "false", 
        distance: "5", 
        persistent: "true"
      }, 
      Name: "minecraft:oak_leaves"
    }, 
    {
      Properties: {
        waterlogged: "false", 
        distance: "4", 
        persistent: "true"
      }, 
      Name: "minecraft:oak_leaves"
    }, 
    {
      Properties: {
        waterlogged: "false", 
        distance: "3", 
        persistent: "true"
      }, 
      Name: "minecraft:oak_leaves"
    }, 
    {
      Properties: {
        waterlogged: "false", 
        distance: "2", 
        persistent: "true"
      }, 
      Name: "minecraft:oak_leaves"
    }, 
    {
      Properties: {
        waterlogged: "false", 
        distance: "1", 
        persistent: "true"
      }, 
      Name: "minecraft:oak_leaves"
    }, 
    {
      Properties: {
        east: "true", 
        south: "false", 
        north: "false", 
        west: "false", 
        up: "false"
      }, 
      Name: "minecraft:vine"
    }, 
    {
      Properties: {
        east: "false", 
        south: "true", 
        north: "false", 
        west: "false", 
        up: "false"
      }, 
      Name: "minecraft:vine"
    }, 
    {
      Properties: {
        level: "0"
      }, 
      Name: "minecraft:water"
    }, 
    {
      Name: "minecraft:seagrass"
    }, 
    {
      Name: "minecraft:dirt_path"
    }, 
    {
      Properties: {
        east: "false", 
        south: "false", 
        north: "false", 
        west: "true", 
        up: "false"
      }, 
      Name: "minecraft:vine"
    }, 
    {
      Name: "minecraft:short_grass"
    }, 
    {
      Name: "minecraft:blue_orchid"
    }, 
    {
      Name: "minecraft:lily_pad"
    }, 
    {
      Properties: {
        east: "false", 
        south: "false", 
        north: "true", 
        west: "false", 
        up: "false"
      }, 
      Name: "minecraft:vine"
    }, 
    {
      Properties: {
        east: "true", 
        south: "false", 
        north: "false", 
        west: "false", 
        up: "true"
      }, 
      Name: "minecraft:vine"
    }, 
    {
      Properties: {
        east: "false", 
        south: "true", 
        north: "false", 
        west: "false", 
        up: "true"
      }, 
      Name: "minecraft:vine"
    }, 
    {
      Properties: {
        east: "false", 
        south: "false", 
        north: "true", 
        west: "false", 
        up: "true"
      }, 
      Name: "minecraft:vine"
    }, 
    {
      Properties: {
        east: "false", 
        south: "false", 
        north: "false", 
        west: "true", 
        up: "true"
      }, 
      Name: "minecraft:vine"
    }, 
    {
      Properties: {
        orientation: "east_up"
      }, 
      Name: "minecraft:jigsaw"
    }, 
    {
      Properties: {
        waterlogged: "false", 
        facing: "east", 
        type: "single"
      }, 
      Name: "minecraft:chest"
    }, 
    {
      Properties: {
        waterlogged: "false", 
        signal_fire: "false", 
        lit: "false", 
        facing: "west"
      }, 
      Name: "minecraft:campfire"
    }, 
    {
      Properties: {
        facing: "up", 
        open: "false"
      }, 
      Name: "minecraft:barrel"
    }
  ]
}
