{
  size: [6, 3, 7], 
  entities: [], 
  blocks: [
    {
      pos: [3, 0, 0], 
      state: 0
    }, 
    {
      pos: [2, 0, 1], 
      state: 0
    }, 
    {
      pos: [3, 0, 1], 
      state: 0
    }, 
    {
      pos: [4, 0, 1], 
      state: 0
    }, 
    {
      pos: [2, 0, 2], 
      state: 0
    }, 
    {
      pos: [3, 0, 2], 
      state: 0
    }, 
    {
      pos: [4, 0, 2], 
      state: 0
    }, 
    {
      pos: [2, 0, 3], 
      state: 0
    }, 
    {
      pos: [3, 0, 3], 
      state: 0
    }, 
    {
      pos: [4, 0, 3], 
      state: 0
    }, 
    {
      pos: [2, 0, 4], 
      state: 0
    }, 
    {
      pos: [3, 0, 4], 
      state: 0
    }, 
    {
      pos: [4, 0, 4], 
      state: 0
    }, 
    {
      pos: [3, 0, 5], 
      state: 0
    }, 
    {
      pos: [4, 0, 5], 
      state: 0
    }, 
    {
      pos: [4, 0, 6], 
      state: 0
    }, 
    {
      nbt: {
        final_state: "minecraft:air", 
        name: "minecraft:feature", 
        pool: "minecraft:empty", 
        id: "minecraft:jigsaw", 
        target: "minecraft:feature"
      }, 
      pos: [0, 0, 0], 
      state: 1
    }, 
    {
      nbt: {
        final_state: "minecraft:air", 
        name: "minecraft:feature", 
        pool: "minecraft:empty", 
        id: "minecraft:jigsaw", 
        target: "minecraft:feature"
      }, 
      pos: [5, 0, 0], 
      state: 1
    }, 
    {
      nbt: {
        final_state: "minecraft:air", 
        name: "minecraft:feature", 
        pool: "minecraft:empty", 
        id: "minecraft:jigsaw", 
        target: "minecraft:feature"
      }, 
      pos: [0, 0, 6], 
      state: 1
    }, 
    {
      nbt: {
        final_state: "minecraft:air", 
        name: "minecraft:feature", 
        pool: "minecraft:empty", 
        id: "minecraft:jigsaw", 
        target: "minecraft:feature"
      }, 
      pos: [5, 0, 6], 
      state: 1
    }, 
    {
      pos: [1, 0, 0], 
      state: 2
    }, 
    {
      pos: [2, 0, 0], 
      state: 2
    }, 
    {
      pos: [4, 0, 0], 
      state: 2
    }, 
    {
      pos: [0, 0, 1], 
      state: 2
    }, 
    {
      pos: [1, 0, 1], 
      state: 2
    }, 
    {
      pos: [5, 0, 1], 
      state: 2
    }, 
    {
      pos: [0, 0, 2], 
      state: 2
    }, 
    {
      pos: [1, 0, 2], 
      state: 2
    }, 
    {
      pos: [5, 0, 2], 
      state: 2
    }, 
    {
      pos: [0, 0, 3], 
      state: 2
    }, 
    {
      pos: [1, 0, 3], 
      state: 2
    }, 
    {
      pos: [5, 0, 3], 
      state: 2
    }, 
    {
      pos: [0, 0, 4], 
      state: 2
    }, 
    {
      pos: [1, 0, 4], 
      state: 2
    }, 
    {
      pos: [5, 0, 4], 
      state: 2
    }, 
    {
      pos: [0, 0, 5], 
      state: 2
    }, 
    {
      pos: [1, 0, 5], 
      state: 2
    }, 
    {
      pos: [2, 0, 5], 
      state: 2
    }, 
    {
      pos: [5, 0, 5], 
      state: 2
    }, 
    {
      pos: [1, 0, 6], 
      state: 2
    }, 
    {
      pos: [2, 0, 6], 
      state: 2
    }, 
    {
      pos: [3, 0, 6], 
      state: 2
    }, 
    {
      pos: [3, 1, 1], 
      state: 0
    }, 
    {
      pos: [3, 1, 2], 
      state: 0
    }, 
    {
      pos: [3, 1, 3], 
      state: 0
    }, 
    {
      pos: [3, 1, 4], 
      state: 0
    }, 
    {
      pos: [3, 1, 5], 
      state: 0
    }, 
    {
      pos: [0, 1, 0], 
      state: 2
    }, 
    {
      pos: [1, 1, 0], 
      state: 2
    }, 
    {
      pos: [2, 1, 0], 
      state: 2
    }, 
    {
      pos: [3, 1, 0], 
      state: 2
    }, 
    {
      pos: [4, 1, 0], 
      state: 2
    }, 
    {
      pos: [5, 1, 0], 
      state: 2
    }, 
    {
      pos: [0, 1, 1], 
      state: 2
    }, 
    {
      pos: [1, 1, 1], 
      state: 2
    }, 
    {
      pos: [2, 1, 1], 
      state: 2
    }, 
    {
      pos: [4, 1, 1], 
      state: 2
    }, 
    {
      pos: [5, 1, 1], 
      state: 2
    }, 
    {
      pos: [0, 1, 2], 
      state: 2
    }, 
    {
      pos: [1, 1, 2], 
      state: 2
    }, 
    {
      pos: [2, 1, 2], 
      state: 2
    }, 
    {
      pos: [4, 1, 2], 
      state: 2
    }, 
    {
      pos: [5, 1, 2], 
      state: 2
    }, 
    {
      pos: [0, 1, 3], 
      state: 2
    }, 
    {
      pos: [1, 1, 3], 
      state: 2
    }, 
    {
      pos: [2, 1, 3], 
      state: 2
    }, 
    {
      pos: [4, 1, 3], 
      state: 2
    }, 
    {
      pos: [5, 1, 3], 
      state: 2
    }, 
    {
      pos: [0, 1, 4], 
      state: 2
    }, 
    {
      pos: [1, 1, 4], 
      state: 2
    }, 
    {
      pos: [2, 1, 4], 
      state: 2
    }, 
    {
      pos: [4, 1, 4], 
      state: 2
    }, 
    {
      pos: [5, 1, 4], 
      state: 2
    }, 
    {
      pos: [0, 1, 5], 
      state: 2
    }, 
    {
      pos: [1, 1, 5], 
      state: 2
    }, 
    {
      pos: [2, 1, 5], 
      state: 2
    }, 
    {
      pos: [4, 1, 5], 
      state: 2
    }, 
    {
      pos: [5, 1, 5], 
      state: 2
    }, 
    {
      pos: [0, 1, 6], 
      state: 2
    }, 
    {
      pos: [1, 1, 6], 
      state: 2
    }, 
    {
      pos: [2, 1, 6], 
      state: 2
    }, 
    {
      pos: [3, 1, 6], 
      state: 2
    }, 
    {
      pos: [4, 1, 6], 
      state: 2
    }, 
    {
      pos: [5, 1, 6], 
      state: 2
    }, 
    {
      pos: [0, 2, 0], 
      state: 2
    }, 
    {
      pos: [1, 2, 0], 
      state: 2
    }, 
    {
      pos: [2, 2, 0], 
      state: 2
    }, 
    {
      pos: [3, 2, 0], 
      state: 2
    }, 
    {
      pos: [4, 2, 0], 
      state: 2
    }, 
    {
      pos: [5, 2, 0], 
      state: 2
    }, 
    {
      pos: [0, 2, 1], 
      state: 2
    }, 
    {
      pos: [1, 2, 1], 
      state: 2
    }, 
    {
      pos: [2, 2, 1], 
      state: 2
    }, 
    {
      pos: [3, 2, 1], 
      state: 2
    }, 
    {
      pos: [4, 2, 1], 
      state: 2
    }, 
    {
      pos: [5, 2, 1], 
      state: 2
    }, 
    {
      pos: [0, 2, 2], 
      state: 2
    }, 
    {
      pos: [1, 2, 2], 
      state: 2
    }, 
    {
      pos: [2, 2, 2], 
      state: 2
    }, 
    {
      pos: [3, 2, 2], 
      state: 2
    }, 
    {
      pos: [4, 2, 2], 
      state: 2
    }, 
    {
      pos: [5, 2, 2], 
      state: 2
    }, 
    {
      pos: [0, 2, 3], 
      state: 2
    }, 
    {
      pos: [1, 2, 3], 
      state: 2
    }, 
    {
      pos: [2, 2, 3], 
      state: 2
    }, 
    {
      pos: [3, 2, 3], 
      state: 2
    }, 
    {
      pos: [4, 2, 3], 
      state: 2
    }, 
    {
      pos: [5, 2, 3], 
      state: 2
    }, 
    {
      pos: [0, 2, 4], 
      state: 2
    }, 
    {
      pos: [1, 2, 4], 
      state: 2
    }, 
    {
      pos: [2, 2, 4], 
      state: 2
    }, 
    {
      pos: [3, 2, 4], 
      state: 2
    }, 
    {
      pos: [4, 2, 4], 
      state: 2
    }, 
    {
      pos: [5, 2, 4], 
      state: 2
    }, 
    {
      pos: [0, 2, 5], 
      state: 2
    }, 
    {
      pos: [1, 2, 5], 
      state: 2
    }, 
    {
      pos: [2, 2, 5], 
      state: 2
    }, 
    {
      pos: [3, 2, 5], 
      state: 2
    }, 
    {
      pos: [4, 2, 5], 
      state: 2
    }, 
    {
      pos: [5, 2, 5], 
      state: 2
    }, 
    {
      pos: [0, 2, 6], 
      state: 2
    }, 
    {
      pos: [1, 2, 6], 
      state: 2
    }, 
    {
      pos: [2, 2, 6], 
      state: 2
    }, 
    {
      pos: [3, 2, 6], 
      state: 2
    }, 
    {
      pos: [4, 2, 6], 
      state: 2
    }, 
    {
      pos: [5, 2, 6], 
      state: 2
    }
  ], 
  palette: [
    {
      Properties: {
        axis: "z"
      }, 
      Name: "minecraft:dark_oak_log"
    }, 
    {
      Properties: {
        orientation: "down_south"
      }, 
      Name: "minecraft:jigsaw"
    }, 
    {
      Name: "minecraft:air"
    }
  ]
}
