{
  size: [9, 15, 9], 
  entities: [
    {
      nbt: {
        Brain: {
          memories: {}
        }, 
        HurtByTimestamp: 0, 
        Crouching: 0b, 
        Sitting: 1b, 
        FallFlying: 0b, 
        ForcedAge: 0, 
        Invulnerable: 0b, 
        AbsorptionAmount: 0.0f, 
        PortalCooldown: 0, 
        InLove: 0, 
        DeathTime: 0s, 
        PersistenceRequired: 0b, 
        id: "minecraft:fox", 
        UUID: [I; 1412451506, 382881029, -1896449644, 143355727], 
        Age: 0, 
        Motion: [0.0d, -0.0784000015258789d, 0.0d], 
        Health: 10.0f, 
        LeftHanded: 0b, 
        Air: 300s, 
        OnGround: 1b, 
        fall_distance: 0.0d, 
        Rotation: [162.52682495117188f, 0.0f], 
        Trusted: [], 
        Type: "snow", 
        Sleeping: 0b, 
        Pos: [45.668486413836d, -48.0d, -44.278568648570904d], 
        Fire: 0s, 
        CanPickUpLoot: 0b, 
        attributes: [
          {
            id: "minecraft:movement_speed", 
            base: 0.30000001192092896d
          }
        ], 
        HurtTime: 0s
      }, 
      blockPos: [6, 5, 5], 
      pos: [6.668486413836d, 5.0d, 5.721431351429096d]
    }
  ], 
  blocks: [
    {
      pos: [4, 0, 6], 
      state: 0
    }, 
    {
      pos: [5, 0, 3], 
      state: 1
    }, 
    {
      pos: [5, 0, 4], 
      state: 2
    }, 
    {
      pos: [5, 0, 5], 
      state: 1
    }, 
    {
      pos: [5, 0, 6], 
      state: 0
    }, 
    {
      pos: [6, 0, 4], 
      state: 2
    }, 
    {
      pos: [4, 1, 4], 
      state: 3
    }, 
    {
      pos: [4, 1, 5], 
      state: 2
    }, 
    {
      pos: [4, 1, 6], 
      state: 0
    }, 
    {
      pos: [5, 1, 3], 
      state: 3
    }, 
    {
      pos: [5, 1, 4], 
      state: 3
    }, 
    {
      pos: [5, 1, 5], 
      state: 3
    }, 
    {
      pos: [5, 1, 6], 
      state: 3
    }, 
    {
      pos: [6, 1, 3], 
      state: 1
    }, 
    {
      pos: [6, 1, 4], 
      state: 3
    }, 
    {
      pos: [6, 1, 5], 
      state: 2
    }, 
    {
      pos: [6, 1, 6], 
      state: 3
    }, 
    {
      pos: [6, 1, 7], 
      state: 1
    }, 
    {
      pos: [7, 1, 4], 
      state: 2
    }, 
    {
      pos: [4, 2, 3], 
      state: 3
    }, 
    {
      pos: [4, 2, 4], 
      state: 3
    }, 
    {
      pos: [4, 2, 5], 
      state: 0
    }, 
    {
      pos: [4, 2, 6], 
      state: 3
    }, 
    {
      pos: [4, 2, 7], 
      state: 2
    }, 
    {
      pos: [5, 2, 3], 
      state: 2
    }, 
    {
      pos: [5, 2, 4], 
      state: 3
    }, 
    {
      pos: [5, 2, 5], 
      state: 3
    }, 
    {
      pos: [5, 2, 6], 
      state: 2
    }, 
    {
      pos: [5, 2, 7], 
      state: 2
    }, 
    {
      pos: [6, 2, 3], 
      state: 0
    }, 
    {
      pos: [6, 2, 4], 
      state: 3
    }, 
    {
      pos: [6, 2, 5], 
      state: 2
    }, 
    {
      pos: [6, 2, 6], 
      state: 3
    }, 
    {
      pos: [6, 2, 7], 
      state: 3
    }, 
    {
      pos: [7, 2, 3], 
      state: 3
    }, 
    {
      pos: [7, 2, 4], 
      state: 0
    }, 
    {
      pos: [7, 2, 5], 
      state: 3
    }, 
    {
      pos: [7, 2, 6], 
      state: 0
    }, 
    {
      pos: [7, 2, 7], 
      state: 4
    }, 
    {
      pos: [5, 3, 4], 
      state: 3
    }, 
    {
      pos: [5, 3, 5], 
      state: 3
    }, 
    {
      pos: [6, 3, 4], 
      state: 3
    }, 
    {
      pos: [6, 3, 5], 
      state: 3
    }, 
    {
      pos: [6, 3, 6], 
      state: 3
    }, 
    {
      pos: [5, 4, 4], 
      state: 1
    }, 
    {
      pos: [5, 4, 5], 
      state: 3
    }, 
    {
      pos: [6, 4, 4], 
      state: 3
    }, 
    {
      pos: [6, 4, 5], 
      state: 3
    }, 
    {
      pos: [5, 5, 4], 
      state: 5
    }, 
    {
      pos: [3, 6, 3], 
      state: 6
    }, 
    {
      pos: [3, 6, 4], 
      state: 7
    }, 
    {
      pos: [3, 6, 5], 
      state: 6
    }, 
    {
      pos: [4, 6, 2], 
      state: 6
    }, 
    {
      pos: [4, 6, 3], 
      state: 7
    }, 
    {
      pos: [4, 6, 4], 
      state: 8
    }, 
    {
      pos: [4, 6, 5], 
      state: 7
    }, 
    {
      pos: [4, 6, 6], 
      state: 6
    }, 
    {
      pos: [5, 6, 2], 
      state: 7
    }, 
    {
      pos: [5, 6, 3], 
      state: 8
    }, 
    {
      pos: [5, 6, 4], 
      state: 5
    }, 
    {
      pos: [5, 6, 5], 
      state: 8
    }, 
    {
      pos: [5, 6, 6], 
      state: 7
    }, 
    {
      pos: [6, 6, 2], 
      state: 6
    }, 
    {
      pos: [6, 6, 3], 
      state: 7
    }, 
    {
      pos: [6, 6, 4], 
      state: 8
    }, 
    {
      pos: [6, 6, 5], 
      state: 7
    }, 
    {
      pos: [6, 6, 6], 
      state: 6
    }, 
    {
      pos: [7, 6, 3], 
      state: 6
    }, 
    {
      pos: [7, 6, 4], 
      state: 7
    }, 
    {
      pos: [7, 6, 5], 
      state: 6
    }, 
    {
      pos: [4, 7, 4], 
      state: 8
    }, 
    {
      pos: [5, 7, 3], 
      state: 8
    }, 
    {
      pos: [5, 7, 4], 
      state: 5
    }, 
    {
      pos: [5, 7, 5], 
      state: 8
    }, 
    {
      pos: [6, 7, 4], 
      state: 8
    }, 
    {
      pos: [2, 8, 2], 
      state: 9
    }, 
    {
      pos: [2, 8, 3], 
      state: 10
    }, 
    {
      pos: [2, 8, 4], 
      state: 11
    }, 
    {
      pos: [2, 8, 5], 
      state: 10
    }, 
    {
      pos: [2, 8, 6], 
      state: 9
    }, 
    {
      pos: [3, 8, 1], 
      state: 9
    }, 
    {
      pos: [3, 8, 2], 
      state: 10
    }, 
    {
      pos: [3, 8, 3], 
      state: 11
    }, 
    {
      pos: [3, 8, 4], 
      state: 6
    }, 
    {
      pos: [3, 8, 5], 
      state: 11
    }, 
    {
      pos: [3, 8, 6], 
      state: 10
    }, 
    {
      pos: [3, 8, 7], 
      state: 9
    }, 
    {
      pos: [4, 8, 1], 
      state: 10
    }, 
    {
      pos: [4, 8, 2], 
      state: 11
    }, 
    {
      pos: [4, 8, 3], 
      state: 6
    }, 
    {
      pos: [4, 8, 4], 
      state: 7
    }, 
    {
      pos: [4, 8, 5], 
      state: 6
    }, 
    {
      pos: [4, 8, 6], 
      state: 11
    }, 
    {
      pos: [4, 8, 7], 
      state: 10
    }, 
    {
      pos: [5, 8, 1], 
      state: 11
    }, 
    {
      pos: [5, 8, 2], 
      state: 6
    }, 
    {
      pos: [5, 8, 3], 
      state: 7
    }, 
    {
      pos: [5, 8, 4], 
      state: 5
    }, 
    {
      pos: [5, 8, 5], 
      state: 7
    }, 
    {
      pos: [5, 8, 6], 
      state: 6
    }, 
    {
      pos: [5, 8, 7], 
      state: 11
    }, 
    {
      pos: [6, 8, 1], 
      state: 10
    }, 
    {
      pos: [6, 8, 2], 
      state: 11
    }, 
    {
      pos: [6, 8, 3], 
      state: 6
    }, 
    {
      pos: [6, 8, 4], 
      state: 7
    }, 
    {
      pos: [6, 8, 5], 
      state: 6
    }, 
    {
      pos: [6, 8, 6], 
      state: 11
    }, 
    {
      pos: [6, 8, 7], 
      state: 10
    }, 
    {
      pos: [7, 8, 1], 
      state: 9
    }, 
    {
      pos: [7, 8, 2], 
      state: 10
    }, 
    {
      pos: [7, 8, 3], 
      state: 11
    }, 
    {
      pos: [7, 8, 4], 
      state: 6
    }, 
    {
      pos: [7, 8, 5], 
      state: 11
    }, 
    {
      pos: [7, 8, 6], 
      state: 10
    }, 
    {
      pos: [7, 8, 7], 
      state: 9
    }, 
    {
      pos: [8, 8, 2], 
      state: 9
    }, 
    {
      pos: [8, 8, 3], 
      state: 10
    }, 
    {
      pos: [8, 8, 4], 
      state: 11
    }, 
    {
      pos: [8, 8, 5], 
      state: 10
    }, 
    {
      pos: [8, 8, 6], 
      state: 9
    }, 
    {
      pos: [3, 9, 3], 
      state: 6
    }, 
    {
      pos: [3, 9, 4], 
      state: 7
    }, 
    {
      pos: [3, 9, 5], 
      state: 6
    }, 
    {
      pos: [4, 9, 2], 
      state: 6
    }, 
    {
      pos: [4, 9, 3], 
      state: 7
    }, 
    {
      pos: [4, 9, 4], 
      state: 8
    }, 
    {
      pos: [4, 9, 5], 
      state: 7
    }, 
    {
      pos: [4, 9, 6], 
      state: 6
    }, 
    {
      pos: [5, 9, 2], 
      state: 7
    }, 
    {
      pos: [5, 9, 3], 
      state: 8
    }, 
    {
      pos: [5, 9, 4], 
      state: 5
    }, 
    {
      pos: [5, 9, 5], 
      state: 8
    }, 
    {
      pos: [5, 9, 6], 
      state: 7
    }, 
    {
      pos: [6, 9, 2], 
      state: 6
    }, 
    {
      pos: [6, 9, 3], 
      state: 7
    }, 
    {
      pos: [6, 9, 4], 
      state: 8
    }, 
    {
      pos: [6, 9, 5], 
      state: 7
    }, 
    {
      pos: [6, 9, 6], 
      state: 6
    }, 
    {
      pos: [7, 9, 3], 
      state: 6
    }, 
    {
      pos: [7, 9, 4], 
      state: 7
    }, 
    {
      pos: [7, 9, 5], 
      state: 6
    }, 
    {
      pos: [4, 10, 4], 
      state: 8
    }, 
    {
      pos: [5, 10, 3], 
      state: 8
    }, 
    {
      pos: [5, 10, 4], 
      state: 5
    }, 
    {
      pos: [5, 10, 5], 
      state: 8
    }, 
    {
      pos: [6, 10, 4], 
      state: 8
    }, 
    {
      pos: [3, 11, 3], 
      state: 6
    }, 
    {
      pos: [3, 11, 4], 
      state: 7
    }, 
    {
      pos: [3, 11, 5], 
      state: 6
    }, 
    {
      pos: [4, 11, 2], 
      state: 6
    }, 
    {
      pos: [4, 11, 3], 
      state: 7
    }, 
    {
      pos: [4, 11, 4], 
      state: 8
    }, 
    {
      pos: [4, 11, 5], 
      state: 7
    }, 
    {
      pos: [4, 11, 6], 
      state: 6
    }, 
    {
      pos: [5, 11, 2], 
      state: 7
    }, 
    {
      pos: [5, 11, 3], 
      state: 8
    }, 
    {
      pos: [5, 11, 4], 
      state: 5
    }, 
    {
      pos: [5, 11, 5], 
      state: 8
    }, 
    {
      pos: [5, 11, 6], 
      state: 7
    }, 
    {
      pos: [6, 11, 2], 
      state: 6
    }, 
    {
      pos: [6, 11, 3], 
      state: 7
    }, 
    {
      pos: [6, 11, 4], 
      state: 8
    }, 
    {
      pos: [6, 11, 5], 
      state: 7
    }, 
    {
      pos: [6, 11, 6], 
      state: 6
    }, 
    {
      pos: [7, 11, 3], 
      state: 6
    }, 
    {
      pos: [7, 11, 4], 
      state: 7
    }, 
    {
      pos: [7, 11, 5], 
      state: 6
    }, 
    {
      pos: [4, 12, 4], 
      state: 8
    }, 
    {
      pos: [5, 12, 3], 
      state: 8
    }, 
    {
      pos: [5, 12, 4], 
      state: 5
    }, 
    {
      pos: [5, 12, 5], 
      state: 8
    }, 
    {
      pos: [6, 12, 4], 
      state: 8
    }, 
    {
      pos: [5, 13, 4], 
      state: 8
    }, 
    {
      pos: [4, 14, 4], 
      state: 6
    }, 
    {
      pos: [5, 14, 3], 
      state: 6
    }, 
    {
      pos: [5, 14, 4], 
      state: 7
    }, 
    {
      pos: [5, 14, 5], 
      state: 6
    }, 
    {
      pos: [6, 14, 4], 
      state: 6
    }, 
    {
      pos: [0, 0, 0], 
      state: 12
    }, 
    {
      pos: [0, 0, 1], 
      state: 12
    }, 
    {
      pos: [0, 0, 2], 
      state: 12
    }, 
    {
      pos: [0, 0, 3], 
      state: 12
    }, 
    {
      pos: [0, 0, 4], 
      state: 12
    }, 
    {
      pos: [0, 0, 5], 
      state: 12
    }, 
    {
      pos: [0, 0, 6], 
      state: 12
    }, 
    {
      pos: [0, 0, 7], 
      state: 12
    }, 
    {
      pos: [0, 0, 8], 
      state: 12
    }, 
    {
      pos: [1, 0, 0], 
      state: 12
    }, 
    {
      pos: [1, 0, 1], 
      state: 12
    }, 
    {
      pos: [1, 0, 2], 
      state: 12
    }, 
    {
      pos: [1, 0, 3], 
      state: 12
    }, 
    {
      pos: [1, 0, 4], 
      state: 12
    }, 
    {
      pos: [1, 0, 5], 
      state: 12
    }, 
    {
      pos: [1, 0, 6], 
      state: 12
    }, 
    {
      pos: [1, 0, 7], 
      state: 12
    }, 
    {
      pos: [1, 0, 8], 
      state: 12
    }, 
    {
      pos: [2, 0, 0], 
      state: 12
    }, 
    {
      pos: [2, 0, 1], 
      state: 12
    }, 
    {
      pos: [2, 0, 2], 
      state: 12
    }, 
    {
      pos: [2, 0, 3], 
      state: 12
    }, 
    {
      pos: [2, 0, 4], 
      state: 12
    }, 
    {
      pos: [2, 0, 5], 
      state: 12
    }, 
    {
      pos: [2, 0, 6], 
      state: 12
    }, 
    {
      pos: [2, 0, 7], 
      state: 12
    }, 
    {
      pos: [2, 0, 8], 
      state: 12
    }, 
    {
      pos: [3, 0, 0], 
      state: 12
    }, 
    {
      pos: [3, 0, 1], 
      state: 12
    }, 
    {
      pos: [3, 0, 2], 
      state: 12
    }, 
    {
      pos: [3, 0, 3], 
      state: 12
    }, 
    {
      pos: [3, 0, 4], 
      state: 12
    }, 
    {
      pos: [3, 0, 5], 
      state: 12
    }, 
    {
      pos: [3, 0, 6], 
      state: 12
    }, 
    {
      pos: [3, 0, 7], 
      state: 12
    }, 
    {
      pos: [3, 0, 8], 
      state: 12
    }, 
    {
      pos: [4, 0, 0], 
      state: 12
    }, 
    {
      pos: [4, 0, 1], 
      state: 12
    }, 
    {
      pos: [4, 0, 2], 
      state: 12
    }, 
    {
      pos: [4, 0, 3], 
      state: 12
    }, 
    {
      pos: [4, 0, 4], 
      state: 12
    }, 
    {
      pos: [4, 0, 5], 
      state: 12
    }, 
    {
      pos: [4, 0, 7], 
      state: 12
    }, 
    {
      pos: [4, 0, 8], 
      state: 12
    }, 
    {
      pos: [5, 0, 0], 
      state: 12
    }, 
    {
      pos: [5, 0, 1], 
      state: 12
    }, 
    {
      pos: [5, 0, 2], 
      state: 12
    }, 
    {
      pos: [5, 0, 7], 
      state: 12
    }, 
    {
      pos: [5, 0, 8], 
      state: 12
    }, 
    {
      pos: [6, 0, 0], 
      state: 12
    }, 
    {
      pos: [6, 0, 1], 
      state: 12
    }, 
    {
      pos: [6, 0, 2], 
      state: 12
    }, 
    {
      pos: [6, 0, 3], 
      state: 12
    }, 
    {
      pos: [6, 0, 5], 
      state: 12
    }, 
    {
      pos: [6, 0, 6], 
      state: 12
    }, 
    {
      pos: [6, 0, 7], 
      state: 12
    }, 
    {
      pos: [6, 0, 8], 
      state: 12
    }, 
    {
      pos: [7, 0, 0], 
      state: 12
    }, 
    {
      pos: [7, 0, 1], 
      state: 12
    }, 
    {
      pos: [7, 0, 2], 
      state: 12
    }, 
    {
      pos: [7, 0, 3], 
      state: 12
    }, 
    {
      pos: [7, 0, 4], 
      state: 12
    }, 
    {
      pos: [7, 0, 5], 
      state: 12
    }, 
    {
      pos: [7, 0, 6], 
      state: 12
    }, 
    {
      pos: [7, 0, 7], 
      state: 12
    }, 
    {
      pos: [7, 0, 8], 
      state: 12
    }, 
    {
      pos: [8, 0, 0], 
      state: 12
    }, 
    {
      pos: [8, 0, 1], 
      state: 12
    }, 
    {
      pos: [8, 0, 2], 
      state: 12
    }, 
    {
      pos: [8, 0, 3], 
      state: 12
    }, 
    {
      pos: [8, 0, 4], 
      state: 12
    }, 
    {
      pos: [8, 0, 5], 
      state: 12
    }, 
    {
      pos: [8, 0, 6], 
      state: 12
    }, 
    {
      pos: [8, 0, 7], 
      state: 12
    }, 
    {
      pos: [8, 0, 8], 
      state: 12
    }, 
    {
      pos: [0, 1, 0], 
      state: 12
    }, 
    {
      pos: [0, 1, 1], 
      state: 12
    }, 
    {
      pos: [0, 1, 2], 
      state: 12
    }, 
    {
      pos: [0, 1, 3], 
      state: 12
    }, 
    {
      pos: [0, 1, 4], 
      state: 12
    }, 
    {
      pos: [0, 1, 5], 
      state: 12
    }, 
    {
      pos: [0, 1, 6], 
      state: 12
    }, 
    {
      pos: [0, 1, 7], 
      state: 12
    }, 
    {
      pos: [0, 1, 8], 
      state: 12
    }, 
    {
      pos: [1, 1, 0], 
      state: 12
    }, 
    {
      pos: [1, 1, 1], 
      state: 12
    }, 
    {
      pos: [1, 1, 2], 
      state: 12
    }, 
    {
      pos: [1, 1, 3], 
      state: 12
    }, 
    {
      pos: [1, 1, 4], 
      state: 12
    }, 
    {
      pos: [1, 1, 5], 
      state: 12
    }, 
    {
      pos: [1, 1, 6], 
      state: 12
    }, 
    {
      pos: [1, 1, 7], 
      state: 12
    }, 
    {
      pos: [1, 1, 8], 
      state: 12
    }, 
    {
      pos: [2, 1, 0], 
      state: 12
    }, 
    {
      pos: [2, 1, 1], 
      state: 12
    }, 
    {
      pos: [2, 1, 2], 
      state: 12
    }, 
    {
      pos: [2, 1, 3], 
      state: 12
    }, 
    {
      pos: [2, 1, 4], 
      state: 12
    }, 
    {
      pos: [2, 1, 5], 
      state: 12
    }, 
    {
      pos: [2, 1, 6], 
      state: 12
    }, 
    {
      pos: [2, 1, 7], 
      state: 12
    }, 
    {
      pos: [2, 1, 8], 
      state: 12
    }, 
    {
      pos: [3, 1, 0], 
      state: 12
    }, 
    {
      pos: [3, 1, 1], 
      state: 12
    }, 
    {
      pos: [3, 1, 2], 
      state: 12
    }, 
    {
      pos: [3, 1, 3], 
      state: 12
    }, 
    {
      pos: [3, 1, 4], 
      state: 12
    }, 
    {
      pos: [3, 1, 5], 
      state: 12
    }, 
    {
      pos: [3, 1, 6], 
      state: 12
    }, 
    {
      pos: [3, 1, 7], 
      state: 12
    }, 
    {
      pos: [3, 1, 8], 
      state: 12
    }, 
    {
      pos: [4, 1, 0], 
      state: 12
    }, 
    {
      pos: [4, 1, 1], 
      state: 12
    }, 
    {
      pos: [4, 1, 2], 
      state: 12
    }, 
    {
      pos: [4, 1, 3], 
      state: 12
    }, 
    {
      pos: [4, 1, 7], 
      state: 12
    }, 
    {
      pos: [4, 1, 8], 
      state: 12
    }, 
    {
      pos: [5, 1, 0], 
      state: 12
    }, 
    {
      pos: [5, 1, 1], 
      state: 12
    }, 
    {
      pos: [5, 1, 2], 
      state: 12
    }, 
    {
      pos: [5, 1, 7], 
      state: 12
    }, 
    {
      pos: [5, 1, 8], 
      state: 12
    }, 
    {
      pos: [6, 1, 0], 
      state: 12
    }, 
    {
      pos: [6, 1, 1], 
      state: 12
    }, 
    {
      pos: [6, 1, 2], 
      state: 12
    }, 
    {
      pos: [6, 1, 8], 
      state: 12
    }, 
    {
      pos: [7, 1, 0], 
      state: 12
    }, 
    {
      pos: [7, 1, 1], 
      state: 12
    }, 
    {
      pos: [7, 1, 2], 
      state: 12
    }, 
    {
      pos: [7, 1, 3], 
      state: 12
    }, 
    {
      pos: [7, 1, 5], 
      state: 12
    }, 
    {
      pos: [7, 1, 6], 
      state: 12
    }, 
    {
      pos: [7, 1, 7], 
      state: 12
    }, 
    {
      pos: [7, 1, 8], 
      state: 12
    }, 
    {
      pos: [8, 1, 0], 
      state: 12
    }, 
    {
      pos: [8, 1, 1], 
      state: 12
    }, 
    {
      pos: [8, 1, 2], 
      state: 12
    }, 
    {
      pos: [8, 1, 3], 
      state: 12
    }, 
    {
      pos: [8, 1, 4], 
      state: 12
    }, 
    {
      pos: [8, 1, 5], 
      state: 12
    }, 
    {
      pos: [8, 1, 6], 
      state: 12
    }, 
    {
      pos: [8, 1, 7], 
      state: 12
    }, 
    {
      pos: [8, 1, 8], 
      state: 12
    }, 
    {
      pos: [0, 2, 0], 
      state: 12
    }, 
    {
      pos: [0, 2, 1], 
      state: 12
    }, 
    {
      pos: [0, 2, 2], 
      state: 12
    }, 
    {
      pos: [0, 2, 3], 
      state: 12
    }, 
    {
      pos: [0, 2, 4], 
      state: 12
    }, 
    {
      pos: [0, 2, 5], 
      state: 12
    }, 
    {
      pos: [0, 2, 6], 
      state: 12
    }, 
    {
      pos: [0, 2, 7], 
      state: 12
    }, 
    {
      pos: [0, 2, 8], 
      state: 12
    }, 
    {
      pos: [1, 2, 0], 
      state: 12
    }, 
    {
      pos: [1, 2, 1], 
      state: 12
    }, 
    {
      pos: [1, 2, 2], 
      state: 12
    }, 
    {
      pos: [1, 2, 3], 
      state: 12
    }, 
    {
      pos: [1, 2, 4], 
      state: 12
    }, 
    {
      pos: [1, 2, 5], 
      state: 12
    }, 
    {
      pos: [1, 2, 6], 
      state: 12
    }, 
    {
      pos: [1, 2, 7], 
      state: 12
    }, 
    {
      pos: [1, 2, 8], 
      state: 12
    }, 
    {
      pos: [2, 2, 0], 
      state: 12
    }, 
    {
      pos: [2, 2, 1], 
      state: 12
    }, 
    {
      pos: [2, 2, 2], 
      state: 12
    }, 
    {
      pos: [2, 2, 3], 
      state: 12
    }, 
    {
      pos: [2, 2, 4], 
      state: 12
    }, 
    {
      pos: [2, 2, 5], 
      state: 12
    }, 
    {
      pos: [2, 2, 6], 
      state: 12
    }, 
    {
      pos: [2, 2, 7], 
      state: 12
    }, 
    {
      pos: [2, 2, 8], 
      state: 12
    }, 
    {
      pos: [3, 2, 0], 
      state: 12
    }, 
    {
      pos: [3, 2, 1], 
      state: 12
    }, 
    {
      pos: [3, 2, 2], 
      state: 12
    }, 
    {
      pos: [3, 2, 3], 
      state: 12
    }, 
    {
      pos: [3, 2, 4], 
      state: 12
    }, 
    {
      pos: [3, 2, 5], 
      state: 12
    }, 
    {
      pos: [3, 2, 6], 
      state: 12
    }, 
    {
      pos: [3, 2, 7], 
      state: 12
    }, 
    {
      pos: [3, 2, 8], 
      state: 12
    }, 
    {
      pos: [4, 2, 0], 
      state: 12
    }, 
    {
      pos: [4, 2, 1], 
      state: 12
    }, 
    {
      pos: [4, 2, 2], 
      state: 12
    }, 
    {
      pos: [4, 2, 8], 
      state: 12
    }, 
    {
      pos: [5, 2, 0], 
      state: 12
    }, 
    {
      pos: [5, 2, 1], 
      state: 12
    }, 
    {
      pos: [5, 2, 2], 
      state: 12
    }, 
    {
      pos: [5, 2, 8], 
      state: 12
    }, 
    {
      pos: [6, 2, 0], 
      state: 12
    }, 
    {
      pos: [6, 2, 1], 
      state: 12
    }, 
    {
      pos: [6, 2, 2], 
      state: 12
    }, 
    {
      pos: [6, 2, 8], 
      state: 12
    }, 
    {
      pos: [7, 2, 0], 
      state: 12
    }, 
    {
      pos: [7, 2, 1], 
      state: 12
    }, 
    {
      pos: [7, 2, 2], 
      state: 12
    }, 
    {
      pos: [7, 2, 8], 
      state: 12
    }, 
    {
      pos: [8, 2, 0], 
      state: 12
    }, 
    {
      pos: [8, 2, 1], 
      state: 12
    }, 
    {
      pos: [8, 2, 2], 
      state: 12
    }, 
    {
      pos: [8, 2, 3], 
      state: 12
    }, 
    {
      pos: [8, 2, 4], 
      state: 12
    }, 
    {
      pos: [8, 2, 5], 
      state: 12
    }, 
    {
      pos: [8, 2, 6], 
      state: 12
    }, 
    {
      pos: [8, 2, 7], 
      state: 12
    }, 
    {
      pos: [8, 2, 8], 
      state: 12
    }, 
    {
      pos: [0, 3, 0], 
      state: 12
    }, 
    {
      pos: [0, 3, 1], 
      state: 12
    }, 
    {
      pos: [0, 3, 2], 
      state: 12
    }, 
    {
      pos: [0, 3, 3], 
      state: 12
    }, 
    {
      pos: [0, 3, 4], 
      state: 12
    }, 
    {
      pos: [0, 3, 5], 
      state: 12
    }, 
    {
      pos: [0, 3, 6], 
      state: 12
    }, 
    {
      pos: [0, 3, 7], 
      state: 12
    }, 
    {
      pos: [0, 3, 8], 
      state: 12
    }, 
    {
      pos: [1, 3, 0], 
      state: 12
    }, 
    {
      pos: [1, 3, 1], 
      state: 12
    }, 
    {
      pos: [1, 3, 2], 
      state: 12
    }, 
    {
      pos: [1, 3, 3], 
      state: 12
    }, 
    {
      pos: [1, 3, 4], 
      state: 12
    }, 
    {
      pos: [1, 3, 5], 
      state: 12
    }, 
    {
      pos: [1, 3, 6], 
      state: 12
    }, 
    {
      pos: [1, 3, 7], 
      state: 12
    }, 
    {
      pos: [1, 3, 8], 
      state: 12
    }, 
    {
      pos: [2, 3, 0], 
      state: 12
    }, 
    {
      pos: [2, 3, 1], 
      state: 12
    }, 
    {
      pos: [2, 3, 2], 
      state: 12
    }, 
    {
      pos: [2, 3, 3], 
      state: 12
    }, 
    {
      pos: [2, 3, 4], 
      state: 12
    }, 
    {
      pos: [2, 3, 5], 
      state: 12
    }, 
    {
      pos: [2, 3, 6], 
      state: 12
    }, 
    {
      pos: [2, 3, 7], 
      state: 12
    }, 
    {
      pos: [2, 3, 8], 
      state: 12
    }, 
    {
      pos: [3, 3, 0], 
      state: 12
    }, 
    {
      pos: [3, 3, 1], 
      state: 12
    }, 
    {
      pos: [3, 3, 2], 
      state: 12
    }, 
    {
      pos: [3, 3, 3], 
      state: 12
    }, 
    {
      pos: [3, 3, 4], 
      state: 12
    }, 
    {
      pos: [3, 3, 5], 
      state: 12
    }, 
    {
      pos: [3, 3, 6], 
      state: 12
    }, 
    {
      pos: [3, 3, 7], 
      state: 12
    }, 
    {
      pos: [3, 3, 8], 
      state: 12
    }, 
    {
      pos: [4, 3, 0], 
      state: 12
    }, 
    {
      pos: [4, 3, 1], 
      state: 12
    }, 
    {
      pos: [4, 3, 2], 
      state: 12
    }, 
    {
      pos: [4, 3, 3], 
      state: 12
    }, 
    {
      pos: [4, 3, 4], 
      state: 12
    }, 
    {
      pos: [4, 3, 5], 
      state: 12
    }, 
    {
      pos: [4, 3, 6], 
      state: 12
    }, 
    {
      pos: [4, 3, 7], 
      state: 12
    }, 
    {
      pos: [4, 3, 8], 
      state: 12
    }, 
    {
      pos: [5, 3, 0], 
      state: 12
    }, 
    {
      pos: [5, 3, 1], 
      state: 12
    }, 
    {
      pos: [5, 3, 2], 
      state: 12
    }, 
    {
      pos: [5, 3, 3], 
      state: 12
    }, 
    {
      pos: [5, 3, 6], 
      state: 12
    }, 
    {
      pos: [5, 3, 7], 
      state: 12
    }, 
    {
      pos: [5, 3, 8], 
      state: 12
    }, 
    {
      pos: [6, 3, 0], 
      state: 12
    }, 
    {
      pos: [6, 3, 1], 
      state: 12
    }, 
    {
      pos: [6, 3, 2], 
      state: 12
    }, 
    {
      pos: [6, 3, 3], 
      state: 12
    }, 
    {
      pos: [6, 3, 7], 
      state: 12
    }, 
    {
      pos: [6, 3, 8], 
      state: 12
    }, 
    {
      pos: [7, 3, 0], 
      state: 12
    }, 
    {
      pos: [7, 3, 1], 
      state: 12
    }, 
    {
      pos: [7, 3, 2], 
      state: 12
    }, 
    {
      pos: [7, 3, 3], 
      state: 12
    }, 
    {
      pos: [7, 3, 4], 
      state: 12
    }, 
    {
      pos: [7, 3, 5], 
      state: 12
    }, 
    {
      pos: [7, 3, 6], 
      state: 12
    }, 
    {
      pos: [7, 3, 7], 
      state: 12
    }, 
    {
      pos: [7, 3, 8], 
      state: 12
    }, 
    {
      pos: [8, 3, 0], 
      state: 12
    }, 
    {
      pos: [8, 3, 1], 
      state: 12
    }, 
    {
      pos: [8, 3, 2], 
      state: 12
    }, 
    {
      pos: [8, 3, 3], 
      state: 12
    }, 
    {
      pos: [8, 3, 4], 
      state: 12
    }, 
    {
      pos: [8, 3, 5], 
      state: 12
    }, 
    {
      pos: [8, 3, 6], 
      state: 12
    }, 
    {
      pos: [8, 3, 7], 
      state: 12
    }, 
    {
      pos: [8, 3, 8], 
      state: 12
    }, 
    {
      pos: [0, 4, 0], 
      state: 12
    }, 
    {
      pos: [0, 4, 1], 
      state: 12
    }, 
    {
      pos: [0, 4, 2], 
      state: 12
    }, 
    {
      pos: [0, 4, 3], 
      state: 12
    }, 
    {
      pos: [0, 4, 4], 
      state: 12
    }, 
    {
      pos: [0, 4, 5], 
      state: 12
    }, 
    {
      pos: [0, 4, 6], 
      state: 12
    }, 
    {
      pos: [0, 4, 7], 
      state: 12
    }, 
    {
      pos: [0, 4, 8], 
      state: 12
    }, 
    {
      pos: [1, 4, 0], 
      state: 12
    }, 
    {
      pos: [1, 4, 1], 
      state: 12
    }, 
    {
      pos: [1, 4, 2], 
      state: 12
    }, 
    {
      pos: [1, 4, 3], 
      state: 12
    }, 
    {
      pos: [1, 4, 4], 
      state: 12
    }, 
    {
      pos: [1, 4, 5], 
      state: 12
    }, 
    {
      pos: [1, 4, 6], 
      state: 12
    }, 
    {
      pos: [1, 4, 7], 
      state: 12
    }, 
    {
      pos: [1, 4, 8], 
      state: 12
    }, 
    {
      pos: [2, 4, 0], 
      state: 12
    }, 
    {
      pos: [2, 4, 1], 
      state: 12
    }, 
    {
      pos: [2, 4, 2], 
      state: 12
    }, 
    {
      pos: [2, 4, 3], 
      state: 12
    }, 
    {
      pos: [2, 4, 4], 
      state: 12
    }, 
    {
      pos: [2, 4, 5], 
      state: 12
    }, 
    {
      pos: [2, 4, 6], 
      state: 12
    }, 
    {
      pos: [2, 4, 7], 
      state: 12
    }, 
    {
      pos: [2, 4, 8], 
      state: 12
    }, 
    {
      pos: [3, 4, 0], 
      state: 12
    }, 
    {
      pos: [3, 4, 1], 
      state: 12
    }, 
    {
      pos: [3, 4, 2], 
      state: 12
    }, 
    {
      pos: [3, 4, 3], 
      state: 12
    }, 
    {
      pos: [3, 4, 4], 
      state: 12
    }, 
    {
      pos: [3, 4, 5], 
      state: 12
    }, 
    {
      pos: [3, 4, 6], 
      state: 12
    }, 
    {
      pos: [3, 4, 7], 
      state: 12
    }, 
    {
      pos: [3, 4, 8], 
      state: 12
    }, 
    {
      pos: [4, 4, 0], 
      state: 12
    }, 
    {
      pos: [4, 4, 1], 
      state: 12
    }, 
    {
      pos: [4, 4, 2], 
      state: 12
    }, 
    {
      pos: [4, 4, 3], 
      state: 12
    }, 
    {
      pos: [4, 4, 4], 
      state: 12
    }, 
    {
      pos: [4, 4, 5], 
      state: 12
    }, 
    {
      pos: [4, 4, 6], 
      state: 12
    }, 
    {
      pos: [4, 4, 7], 
      state: 12
    }, 
    {
      pos: [4, 4, 8], 
      state: 12
    }, 
    {
      pos: [5, 4, 0], 
      state: 12
    }, 
    {
      pos: [5, 4, 1], 
      state: 12
    }, 
    {
      pos: [5, 4, 2], 
      state: 12
    }, 
    {
      pos: [5, 4, 3], 
      state: 12
    }, 
    {
      pos: [5, 4, 6], 
      state: 12
    }, 
    {
      pos: [5, 4, 7], 
      state: 12
    }, 
    {
      pos: [5, 4, 8], 
      state: 12
    }, 
    {
      pos: [6, 4, 0], 
      state: 12
    }, 
    {
      pos: [6, 4, 1], 
      state: 12
    }, 
    {
      pos: [6, 4, 2], 
      state: 12
    }, 
    {
      pos: [6, 4, 3], 
      state: 12
    }, 
    {
      pos: [6, 4, 6], 
      state: 12
    }, 
    {
      pos: [6, 4, 7], 
      state: 12
    }, 
    {
      pos: [6, 4, 8], 
      state: 12
    }, 
    {
      pos: [7, 4, 0], 
      state: 12
    }, 
    {
      pos: [7, 4, 1], 
      state: 12
    }, 
    {
      pos: [7, 4, 2], 
      state: 12
    }, 
    {
      pos: [7, 4, 3], 
      state: 12
    }, 
    {
      pos: [7, 4, 4], 
      state: 12
    }, 
    {
      pos: [7, 4, 5], 
      state: 12
    }, 
    {
      pos: [7, 4, 6], 
      state: 12
    }, 
    {
      pos: [7, 4, 7], 
      state: 12
    }, 
    {
      pos: [7, 4, 8], 
      state: 12
    }, 
    {
      pos: [8, 4, 0], 
      state: 12
    }, 
    {
      pos: [8, 4, 1], 
      state: 12
    }, 
    {
      pos: [8, 4, 2], 
      state: 12
    }, 
    {
      pos: [8, 4, 3], 
      state: 12
    }, 
    {
      pos: [8, 4, 4], 
      state: 12
    }, 
    {
      pos: [8, 4, 5], 
      state: 12
    }, 
    {
      pos: [8, 4, 6], 
      state: 12
    }, 
    {
      pos: [8, 4, 7], 
      state: 12
    }, 
    {
      pos: [8, 4, 8], 
      state: 12
    }, 
    {
      pos: [0, 5, 0], 
      state: 12
    }, 
    {
      pos: [0, 5, 1], 
      state: 12
    }, 
    {
      pos: [0, 5, 2], 
      state: 12
    }, 
    {
      pos: [0, 5, 3], 
      state: 12
    }, 
    {
      pos: [0, 5, 4], 
      state: 12
    }, 
    {
      pos: [0, 5, 5], 
      state: 12
    }, 
    {
      pos: [0, 5, 6], 
      state: 12
    }, 
    {
      pos: [0, 5, 7], 
      state: 12
    }, 
    {
      pos: [0, 5, 8], 
      state: 12
    }, 
    {
      pos: [1, 5, 0], 
      state: 12
    }, 
    {
      pos: [1, 5, 1], 
      state: 12
    }, 
    {
      pos: [1, 5, 2], 
      state: 12
    }, 
    {
      pos: [1, 5, 3], 
      state: 12
    }, 
    {
      pos: [1, 5, 4], 
      state: 12
    }, 
    {
      pos: [1, 5, 5], 
      state: 12
    }, 
    {
      pos: [1, 5, 6], 
      state: 12
    }, 
    {
      pos: [1, 5, 7], 
      state: 12
    }, 
    {
      pos: [1, 5, 8], 
      state: 12
    }, 
    {
      pos: [2, 5, 0], 
      state: 12
    }, 
    {
      pos: [2, 5, 1], 
      state: 12
    }, 
    {
      pos: [2, 5, 2], 
      state: 12
    }, 
    {
      pos: [2, 5, 3], 
      state: 12
    }, 
    {
      pos: [2, 5, 4], 
      state: 12
    }, 
    {
      pos: [2, 5, 5], 
      state: 12
    }, 
    {
      pos: [2, 5, 6], 
      state: 12
    }, 
    {
      pos: [2, 5, 7], 
      state: 12
    }, 
    {
      pos: [2, 5, 8], 
      state: 12
    }, 
    {
      pos: [3, 5, 0], 
      state: 12
    }, 
    {
      pos: [3, 5, 1], 
      state: 12
    }, 
    {
      pos: [3, 5, 2], 
      state: 12
    }, 
    {
      pos: [3, 5, 3], 
      state: 12
    }, 
    {
      pos: [3, 5, 4], 
      state: 12
    }, 
    {
      pos: [3, 5, 5], 
      state: 12
    }, 
    {
      pos: [3, 5, 6], 
      state: 12
    }, 
    {
      pos: [3, 5, 7], 
      state: 12
    }, 
    {
      pos: [3, 5, 8], 
      state: 12
    }, 
    {
      pos: [4, 5, 0], 
      state: 12
    }, 
    {
      pos: [4, 5, 1], 
      state: 12
    }, 
    {
      pos: [4, 5, 2], 
      state: 12
    }, 
    {
      pos: [4, 5, 3], 
      state: 12
    }, 
    {
      pos: [4, 5, 4], 
      state: 12
    }, 
    {
      pos: [4, 5, 5], 
      state: 12
    }, 
    {
      pos: [4, 5, 6], 
      state: 12
    }, 
    {
      pos: [4, 5, 7], 
      state: 12
    }, 
    {
      pos: [4, 5, 8], 
      state: 12
    }, 
    {
      pos: [5, 5, 0], 
      state: 12
    }, 
    {
      pos: [5, 5, 1], 
      state: 12
    }, 
    {
      pos: [5, 5, 2], 
      state: 12
    }, 
    {
      pos: [5, 5, 3], 
      state: 12
    }, 
    {
      pos: [5, 5, 5], 
      state: 12
    }, 
    {
      pos: [5, 5, 6], 
      state: 12
    }, 
    {
      pos: [5, 5, 7], 
      state: 12
    }, 
    {
      pos: [5, 5, 8], 
      state: 12
    }, 
    {
      pos: [6, 5, 0], 
      state: 12
    }, 
    {
      pos: [6, 5, 1], 
      state: 12
    }, 
    {
      pos: [6, 5, 2], 
      state: 12
    }, 
    {
      pos: [6, 5, 3], 
      state: 12
    }, 
    {
      pos: [6, 5, 4], 
      state: 12
    }, 
    {
      pos: [6, 5, 5], 
      state: 12
    }, 
    {
      pos: [6, 5, 6], 
      state: 12
    }, 
    {
      pos: [6, 5, 7], 
      state: 12
    }, 
    {
      pos: [6, 5, 8], 
      state: 12
    }, 
    {
      pos: [7, 5, 0], 
      state: 12
    }, 
    {
      pos: [7, 5, 1], 
      state: 12
    }, 
    {
      pos: [7, 5, 2], 
      state: 12
    }, 
    {
      pos: [7, 5, 3], 
      state: 12
    }, 
    {
      pos: [7, 5, 4], 
      state: 12
    }, 
    {
      pos: [7, 5, 5], 
      state: 12
    }, 
    {
      pos: [7, 5, 6], 
      state: 12
    }, 
    {
      pos: [7, 5, 7], 
      state: 12
    }, 
    {
      pos: [7, 5, 8], 
      state: 12
    }, 
    {
      pos: [8, 5, 0], 
      state: 12
    }, 
    {
      pos: [8, 5, 1], 
      state: 12
    }, 
    {
      pos: [8, 5, 2], 
      state: 12
    }, 
    {
      pos: [8, 5, 3], 
      state: 12
    }, 
    {
      pos: [8, 5, 4], 
      state: 12
    }, 
    {
      pos: [8, 5, 5], 
      state: 12
    }, 
    {
      pos: [8, 5, 6], 
      state: 12
    }, 
    {
      pos: [8, 5, 7], 
      state: 12
    }, 
    {
      pos: [8, 5, 8], 
      state: 12
    }, 
    {
      pos: [0, 6, 0], 
      state: 12
    }, 
    {
      pos: [0, 6, 1], 
      state: 12
    }, 
    {
      pos: [0, 6, 2], 
      state: 12
    }, 
    {
      pos: [0, 6, 3], 
      state: 12
    }, 
    {
      pos: [0, 6, 4], 
      state: 12
    }, 
    {
      pos: [0, 6, 5], 
      state: 12
    }, 
    {
      pos: [0, 6, 6], 
      state: 12
    }, 
    {
      pos: [0, 6, 7], 
      state: 12
    }, 
    {
      pos: [0, 6, 8], 
      state: 12
    }, 
    {
      pos: [1, 6, 0], 
      state: 12
    }, 
    {
      pos: [1, 6, 1], 
      state: 12
    }, 
    {
      pos: [1, 6, 2], 
      state: 12
    }, 
    {
      pos: [1, 6, 3], 
      state: 12
    }, 
    {
      pos: [1, 6, 4], 
      state: 12
    }, 
    {
      pos: [1, 6, 5], 
      state: 12
    }, 
    {
      pos: [1, 6, 6], 
      state: 12
    }, 
    {
      pos: [1, 6, 7], 
      state: 12
    }, 
    {
      pos: [1, 6, 8], 
      state: 12
    }, 
    {
      pos: [2, 6, 0], 
      state: 12
    }, 
    {
      pos: [2, 6, 1], 
      state: 12
    }, 
    {
      pos: [2, 6, 2], 
      state: 12
    }, 
    {
      pos: [2, 6, 3], 
      state: 12
    }, 
    {
      pos: [2, 6, 4], 
      state: 12
    }, 
    {
      pos: [2, 6, 5], 
      state: 12
    }, 
    {
      pos: [2, 6, 6], 
      state: 12
    }, 
    {
      pos: [2, 6, 7], 
      state: 12
    }, 
    {
      pos: [2, 6, 8], 
      state: 12
    }, 
    {
      pos: [3, 6, 0], 
      state: 12
    }, 
    {
      pos: [3, 6, 1], 
      state: 12
    }, 
    {
      pos: [3, 6, 2], 
      state: 12
    }, 
    {
      pos: [3, 6, 6], 
      state: 12
    }, 
    {
      pos: [3, 6, 7], 
      state: 12
    }, 
    {
      pos: [3, 6, 8], 
      state: 12
    }, 
    {
      pos: [4, 6, 0], 
      state: 12
    }, 
    {
      pos: [4, 6, 1], 
      state: 12
    }, 
    {
      pos: [4, 6, 7], 
      state: 12
    }, 
    {
      pos: [4, 6, 8], 
      state: 12
    }, 
    {
      pos: [5, 6, 0], 
      state: 12
    }, 
    {
      pos: [5, 6, 1], 
      state: 12
    }, 
    {
      pos: [5, 6, 7], 
      state: 12
    }, 
    {
      pos: [5, 6, 8], 
      state: 12
    }, 
    {
      pos: [6, 6, 0], 
      state: 12
    }, 
    {
      pos: [6, 6, 1], 
      state: 12
    }, 
    {
      pos: [6, 6, 7], 
      state: 12
    }, 
    {
      pos: [6, 6, 8], 
      state: 12
    }, 
    {
      pos: [7, 6, 0], 
      state: 12
    }, 
    {
      pos: [7, 6, 1], 
      state: 12
    }, 
    {
      pos: [7, 6, 2], 
      state: 12
    }, 
    {
      pos: [7, 6, 6], 
      state: 12
    }, 
    {
      pos: [7, 6, 7], 
      state: 12
    }, 
    {
      pos: [7, 6, 8], 
      state: 12
    }, 
    {
      pos: [8, 6, 0], 
      state: 12
    }, 
    {
      pos: [8, 6, 1], 
      state: 12
    }, 
    {
      pos: [8, 6, 2], 
      state: 12
    }, 
    {
      pos: [8, 6, 3], 
      state: 12
    }, 
    {
      pos: [8, 6, 4], 
      state: 12
    }, 
    {
      pos: [8, 6, 5], 
      state: 12
    }, 
    {
      pos: [8, 6, 6], 
      state: 12
    }, 
    {
      pos: [8, 6, 7], 
      state: 12
    }, 
    {
      pos: [8, 6, 8], 
      state: 12
    }, 
    {
      pos: [0, 7, 0], 
      state: 12
    }, 
    {
      pos: [0, 7, 1], 
      state: 12
    }, 
    {
      pos: [0, 7, 2], 
      state: 12
    }, 
    {
      pos: [0, 7, 3], 
      state: 12
    }, 
    {
      pos: [0, 7, 4], 
      state: 12
    }, 
    {
      pos: [0, 7, 5], 
      state: 12
    }, 
    {
      pos: [0, 7, 6], 
      state: 12
    }, 
    {
      pos: [0, 7, 7], 
      state: 12
    }, 
    {
      pos: [0, 7, 8], 
      state: 12
    }, 
    {
      pos: [1, 7, 0], 
      state: 12
    }, 
    {
      pos: [1, 7, 1], 
      state: 12
    }, 
    {
      pos: [1, 7, 2], 
      state: 12
    }, 
    {
      pos: [1, 7, 3], 
      state: 12
    }, 
    {
      pos: [1, 7, 4], 
      state: 12
    }, 
    {
      pos: [1, 7, 5], 
      state: 12
    }, 
    {
      pos: [1, 7, 6], 
      state: 12
    }, 
    {
      pos: [1, 7, 7], 
      state: 12
    }, 
    {
      pos: [1, 7, 8], 
      state: 12
    }, 
    {
      pos: [2, 7, 0], 
      state: 12
    }, 
    {
      pos: [2, 7, 1], 
      state: 12
    }, 
    {
      pos: [2, 7, 2], 
      state: 12
    }, 
    {
      pos: [2, 7, 3], 
      state: 12
    }, 
    {
      pos: [2, 7, 4], 
      state: 12
    }, 
    {
      pos: [2, 7, 5], 
      state: 12
    }, 
    {
      pos: [2, 7, 6], 
      state: 12
    }, 
    {
      pos: [2, 7, 7], 
      state: 12
    }, 
    {
      pos: [2, 7, 8], 
      state: 12
    }, 
    {
      pos: [3, 7, 0], 
      state: 12
    }, 
    {
      pos: [3, 7, 1], 
      state: 12
    }, 
    {
      pos: [3, 7, 2], 
      state: 12
    }, 
    {
      pos: [3, 7, 3], 
      state: 12
    }, 
    {
      pos: [3, 7, 4], 
      state: 12
    }, 
    {
      pos: [3, 7, 5], 
      state: 12
    }, 
    {
      pos: [3, 7, 6], 
      state: 12
    }, 
    {
      pos: [3, 7, 7], 
      state: 12
    }, 
    {
      pos: [3, 7, 8], 
      state: 12
    }, 
    {
      pos: [4, 7, 0], 
      state: 12
    }, 
    {
      pos: [4, 7, 1], 
      state: 12
    }, 
    {
      pos: [4, 7, 2], 
      state: 12
    }, 
    {
      pos: [4, 7, 3], 
      state: 12
    }, 
    {
      pos: [4, 7, 5], 
      state: 12
    }, 
    {
      pos: [4, 7, 6], 
      state: 12
    }, 
    {
      pos: [4, 7, 7], 
      state: 12
    }, 
    {
      pos: [4, 7, 8], 
      state: 12
    }, 
    {
      pos: [5, 7, 0], 
      state: 12
    }, 
    {
      pos: [5, 7, 1], 
      state: 12
    }, 
    {
      pos: [5, 7, 2], 
      state: 12
    }, 
    {
      pos: [5, 7, 6], 
      state: 12
    }, 
    {
      pos: [5, 7, 7], 
      state: 12
    }, 
    {
      pos: [5, 7, 8], 
      state: 12
    }, 
    {
      pos: [6, 7, 0], 
      state: 12
    }, 
    {
      pos: [6, 7, 1], 
      state: 12
    }, 
    {
      pos: [6, 7, 2], 
      state: 12
    }, 
    {
      pos: [6, 7, 3], 
      state: 12
    }, 
    {
      pos: [6, 7, 5], 
      state: 12
    }, 
    {
      pos: [6, 7, 6], 
      state: 12
    }, 
    {
      pos: [6, 7, 7], 
      state: 12
    }, 
    {
      pos: [6, 7, 8], 
      state: 12
    }, 
    {
      pos: [7, 7, 0], 
      state: 12
    }, 
    {
      pos: [7, 7, 1], 
      state: 12
    }, 
    {
      pos: [7, 7, 2], 
      state: 12
    }, 
    {
      pos: [7, 7, 3], 
      state: 12
    }, 
    {
      pos: [7, 7, 4], 
      state: 12
    }, 
    {
      pos: [7, 7, 5], 
      state: 12
    }, 
    {
      pos: [7, 7, 6], 
      state: 12
    }, 
    {
      pos: [7, 7, 7], 
      state: 12
    }, 
    {
      pos: [7, 7, 8], 
      state: 12
    }, 
    {
      pos: [8, 7, 0], 
      state: 12
    }, 
    {
      pos: [8, 7, 1], 
      state: 12
    }, 
    {
      pos: [8, 7, 2], 
      state: 12
    }, 
    {
      pos: [8, 7, 3], 
      state: 12
    }, 
    {
      pos: [8, 7, 4], 
      state: 12
    }, 
    {
      pos: [8, 7, 5], 
      state: 12
    }, 
    {
      pos: [8, 7, 6], 
      state: 12
    }, 
    {
      pos: [8, 7, 7], 
      state: 12
    }, 
    {
      pos: [8, 7, 8], 
      state: 12
    }, 
    {
      pos: [0, 8, 0], 
      state: 12
    }, 
    {
      pos: [0, 8, 1], 
      state: 12
    }, 
    {
      pos: [0, 8, 2], 
      state: 12
    }, 
    {
      pos: [0, 8, 3], 
      state: 12
    }, 
    {
      pos: [0, 8, 4], 
      state: 12
    }, 
    {
      pos: [0, 8, 5], 
      state: 12
    }, 
    {
      pos: [0, 8, 6], 
      state: 12
    }, 
    {
      pos: [0, 8, 7], 
      state: 12
    }, 
    {
      pos: [0, 8, 8], 
      state: 12
    }, 
    {
      pos: [1, 8, 0], 
      state: 12
    }, 
    {
      pos: [1, 8, 1], 
      state: 12
    }, 
    {
      pos: [1, 8, 2], 
      state: 12
    }, 
    {
      pos: [1, 8, 3], 
      state: 12
    }, 
    {
      pos: [1, 8, 4], 
      state: 12
    }, 
    {
      pos: [1, 8, 5], 
      state: 12
    }, 
    {
      pos: [1, 8, 6], 
      state: 12
    }, 
    {
      pos: [1, 8, 7], 
      state: 12
    }, 
    {
      pos: [1, 8, 8], 
      state: 12
    }, 
    {
      pos: [2, 8, 0], 
      state: 12
    }, 
    {
      pos: [2, 8, 1], 
      state: 12
    }, 
    {
      pos: [2, 8, 7], 
      state: 12
    }, 
    {
      pos: [2, 8, 8], 
      state: 12
    }, 
    {
      pos: [3, 8, 0], 
      state: 12
    }, 
    {
      pos: [3, 8, 8], 
      state: 12
    }, 
    {
      pos: [4, 8, 0], 
      state: 12
    }, 
    {
      pos: [4, 8, 8], 
      state: 12
    }, 
    {
      pos: [5, 8, 0], 
      state: 12
    }, 
    {
      pos: [5, 8, 8], 
      state: 12
    }, 
    {
      pos: [6, 8, 0], 
      state: 12
    }, 
    {
      pos: [6, 8, 8], 
      state: 12
    }, 
    {
      pos: [7, 8, 0], 
      state: 12
    }, 
    {
      pos: [7, 8, 8], 
      state: 12
    }, 
    {
      pos: [8, 8, 0], 
      state: 12
    }, 
    {
      pos: [8, 8, 1], 
      state: 12
    }, 
    {
      pos: [8, 8, 7], 
      state: 12
    }, 
    {
      pos: [8, 8, 8], 
      state: 12
    }, 
    {
      pos: [0, 9, 0], 
      state: 12
    }, 
    {
      pos: [0, 9, 1], 
      state: 12
    }, 
    {
      pos: [0, 9, 2], 
      state: 12
    }, 
    {
      pos: [0, 9, 3], 
      state: 12
    }, 
    {
      pos: [0, 9, 4], 
      state: 12
    }, 
    {
      pos: [0, 9, 5], 
      state: 12
    }, 
    {
      pos: [0, 9, 6], 
      state: 12
    }, 
    {
      pos: [0, 9, 7], 
      state: 12
    }, 
    {
      pos: [0, 9, 8], 
      state: 12
    }, 
    {
      pos: [1, 9, 0], 
      state: 12
    }, 
    {
      pos: [1, 9, 1], 
      state: 12
    }, 
    {
      pos: [1, 9, 2], 
      state: 12
    }, 
    {
      pos: [1, 9, 3], 
      state: 12
    }, 
    {
      pos: [1, 9, 4], 
      state: 12
    }, 
    {
      pos: [1, 9, 5], 
      state: 12
    }, 
    {
      pos: [1, 9, 6], 
      state: 12
    }, 
    {
      pos: [1, 9, 7], 
      state: 12
    }, 
    {
      pos: [1, 9, 8], 
      state: 12
    }, 
    {
      pos: [2, 9, 0], 
      state: 12
    }, 
    {
      pos: [2, 9, 1], 
      state: 12
    }, 
    {
      pos: [2, 9, 2], 
      state: 12
    }, 
    {
      pos: [2, 9, 3], 
      state: 12
    }, 
    {
      pos: [2, 9, 4], 
      state: 12
    }, 
    {
      pos: [2, 9, 5], 
      state: 12
    }, 
    {
      pos: [2, 9, 6], 
      state: 12
    }, 
    {
      pos: [2, 9, 7], 
      state: 12
    }, 
    {
      pos: [2, 9, 8], 
      state: 12
    }, 
    {
      pos: [3, 9, 0], 
      state: 12
    }, 
    {
      pos: [3, 9, 1], 
      state: 12
    }, 
    {
      pos: [3, 9, 2], 
      state: 12
    }, 
    {
      pos: [3, 9, 6], 
      state: 12
    }, 
    {
      pos: [3, 9, 7], 
      state: 12
    }, 
    {
      pos: [3, 9, 8], 
      state: 12
    }, 
    {
      pos: [4, 9, 0], 
      state: 12
    }, 
    {
      pos: [4, 9, 1], 
      state: 12
    }, 
    {
      pos: [4, 9, 7], 
      state: 12
    }, 
    {
      pos: [4, 9, 8], 
      state: 12
    }, 
    {
      pos: [5, 9, 0], 
      state: 12
    }, 
    {
      pos: [5, 9, 1], 
      state: 12
    }, 
    {
      pos: [5, 9, 7], 
      state: 12
    }, 
    {
      pos: [5, 9, 8], 
      state: 12
    }, 
    {
      pos: [6, 9, 0], 
      state: 12
    }, 
    {
      pos: [6, 9, 1], 
      state: 12
    }, 
    {
      pos: [6, 9, 7], 
      state: 12
    }, 
    {
      pos: [6, 9, 8], 
      state: 12
    }, 
    {
      pos: [7, 9, 0], 
      state: 12
    }, 
    {
      pos: [7, 9, 1], 
      state: 12
    }, 
    {
      pos: [7, 9, 2], 
      state: 12
    }, 
    {
      pos: [7, 9, 6], 
      state: 12
    }, 
    {
      pos: [7, 9, 7], 
      state: 12
    }, 
    {
      pos: [7, 9, 8], 
      state: 12
    }, 
    {
      pos: [8, 9, 0], 
      state: 12
    }, 
    {
      pos: [8, 9, 1], 
      state: 12
    }, 
    {
      pos: [8, 9, 2], 
      state: 12
    }, 
    {
      pos: [8, 9, 3], 
      state: 12
    }, 
    {
      pos: [8, 9, 4], 
      state: 12
    }, 
    {
      pos: [8, 9, 5], 
      state: 12
    }, 
    {
      pos: [8, 9, 6], 
      state: 12
    }, 
    {
      pos: [8, 9, 7], 
      state: 12
    }, 
    {
      pos: [8, 9, 8], 
      state: 12
    }, 
    {
      pos: [0, 10, 0], 
      state: 12
    }, 
    {
      pos: [0, 10, 1], 
      state: 12
    }, 
    {
      pos: [0, 10, 2], 
      state: 12
    }, 
    {
      pos: [0, 10, 3], 
      state: 12
    }, 
    {
      pos: [0, 10, 4], 
      state: 12
    }, 
    {
      pos: [0, 10, 5], 
      state: 12
    }, 
    {
      pos: [0, 10, 6], 
      state: 12
    }, 
    {
      pos: [0, 10, 7], 
      state: 12
    }, 
    {
      pos: [0, 10, 8], 
      state: 12
    }, 
    {
      pos: [1, 10, 0], 
      state: 12
    }, 
    {
      pos: [1, 10, 1], 
      state: 12
    }, 
    {
      pos: [1, 10, 2], 
      state: 12
    }, 
    {
      pos: [1, 10, 3], 
      state: 12
    }, 
    {
      pos: [1, 10, 4], 
      state: 12
    }, 
    {
      pos: [1, 10, 5], 
      state: 12
    }, 
    {
      pos: [1, 10, 6], 
      state: 12
    }, 
    {
      pos: [1, 10, 7], 
      state: 12
    }, 
    {
      pos: [1, 10, 8], 
      state: 12
    }, 
    {
      pos: [2, 10, 0], 
      state: 12
    }, 
    {
      pos: [2, 10, 1], 
      state: 12
    }, 
    {
      pos: [2, 10, 2], 
      state: 12
    }, 
    {
      pos: [2, 10, 3], 
      state: 12
    }, 
    {
      pos: [2, 10, 4], 
      state: 12
    }, 
    {
      pos: [2, 10, 5], 
      state: 12
    }, 
    {
      pos: [2, 10, 6], 
      state: 12
    }, 
    {
      pos: [2, 10, 7], 
      state: 12
    }, 
    {
      pos: [2, 10, 8], 
      state: 12
    }, 
    {
      pos: [3, 10, 0], 
      state: 12
    }, 
    {
      pos: [3, 10, 1], 
      state: 12
    }, 
    {
      pos: [3, 10, 2], 
      state: 12
    }, 
    {
      pos: [3, 10, 3], 
      state: 12
    }, 
    {
      pos: [3, 10, 4], 
      state: 12
    }, 
    {
      pos: [3, 10, 5], 
      state: 12
    }, 
    {
      pos: [3, 10, 6], 
      state: 12
    }, 
    {
      pos: [3, 10, 7], 
      state: 12
    }, 
    {
      pos: [3, 10, 8], 
      state: 12
    }, 
    {
      pos: [4, 10, 0], 
      state: 12
    }, 
    {
      pos: [4, 10, 1], 
      state: 12
    }, 
    {
      pos: [4, 10, 2], 
      state: 12
    }, 
    {
      pos: [4, 10, 3], 
      state: 12
    }, 
    {
      pos: [4, 10, 5], 
      state: 12
    }, 
    {
      pos: [4, 10, 6], 
      state: 12
    }, 
    {
      pos: [4, 10, 7], 
      state: 12
    }, 
    {
      pos: [4, 10, 8], 
      state: 12
    }, 
    {
      pos: [5, 10, 0], 
      state: 12
    }, 
    {
      pos: [5, 10, 1], 
      state: 12
    }, 
    {
      pos: [5, 10, 2], 
      state: 12
    }, 
    {
      pos: [5, 10, 6], 
      state: 12
    }, 
    {
      pos: [5, 10, 7], 
      state: 12
    }, 
    {
      pos: [5, 10, 8], 
      state: 12
    }, 
    {
      pos: [6, 10, 0], 
      state: 12
    }, 
    {
      pos: [6, 10, 1], 
      state: 12
    }, 
    {
      pos: [6, 10, 2], 
      state: 12
    }, 
    {
      pos: [6, 10, 3], 
      state: 12
    }, 
    {
      pos: [6, 10, 5], 
      state: 12
    }, 
    {
      pos: [6, 10, 6], 
      state: 12
    }, 
    {
      pos: [6, 10, 7], 
      state: 12
    }, 
    {
      pos: [6, 10, 8], 
      state: 12
    }, 
    {
      pos: [7, 10, 0], 
      state: 12
    }, 
    {
      pos: [7, 10, 1], 
      state: 12
    }, 
    {
      pos: [7, 10, 2], 
      state: 12
    }, 
    {
      pos: [7, 10, 3], 
      state: 12
    }, 
    {
      pos: [7, 10, 4], 
      state: 12
    }, 
    {
      pos: [7, 10, 5], 
      state: 12
    }, 
    {
      pos: [7, 10, 6], 
      state: 12
    }, 
    {
      pos: [7, 10, 7], 
      state: 12
    }, 
    {
      pos: [7, 10, 8], 
      state: 12
    }, 
    {
      pos: [8, 10, 0], 
      state: 12
    }, 
    {
      pos: [8, 10, 1], 
      state: 12
    }, 
    {
      pos: [8, 10, 2], 
      state: 12
    }, 
    {
      pos: [8, 10, 3], 
      state: 12
    }, 
    {
      pos: [8, 10, 4], 
      state: 12
    }, 
    {
      pos: [8, 10, 5], 
      state: 12
    }, 
    {
      pos: [8, 10, 6], 
      state: 12
    }, 
    {
      pos: [8, 10, 7], 
      state: 12
    }, 
    {
      pos: [8, 10, 8], 
      state: 12
    }, 
    {
      pos: [0, 11, 0], 
      state: 12
    }, 
    {
      pos: [0, 11, 1], 
      state: 12
    }, 
    {
      pos: [0, 11, 2], 
      state: 12
    }, 
    {
      pos: [0, 11, 3], 
      state: 12
    }, 
    {
      pos: [0, 11, 4], 
      state: 12
    }, 
    {
      pos: [0, 11, 5], 
      state: 12
    }, 
    {
      pos: [0, 11, 6], 
      state: 12
    }, 
    {
      pos: [0, 11, 7], 
      state: 12
    }, 
    {
      pos: [0, 11, 8], 
      state: 12
    }, 
    {
      pos: [1, 11, 0], 
      state: 12
    }, 
    {
      pos: [1, 11, 1], 
      state: 12
    }, 
    {
      pos: [1, 11, 2], 
      state: 12
    }, 
    {
      pos: [1, 11, 3], 
      state: 12
    }, 
    {
      pos: [1, 11, 4], 
      state: 12
    }, 
    {
      pos: [1, 11, 5], 
      state: 12
    }, 
    {
      pos: [1, 11, 6], 
      state: 12
    }, 
    {
      pos: [1, 11, 7], 
      state: 12
    }, 
    {
      pos: [1, 11, 8], 
      state: 12
    }, 
    {
      pos: [2, 11, 0], 
      state: 12
    }, 
    {
      pos: [2, 11, 1], 
      state: 12
    }, 
    {
      pos: [2, 11, 2], 
      state: 12
    }, 
    {
      pos: [2, 11, 3], 
      state: 12
    }, 
    {
      pos: [2, 11, 4], 
      state: 12
    }, 
    {
      pos: [2, 11, 5], 
      state: 12
    }, 
    {
      pos: [2, 11, 6], 
      state: 12
    }, 
    {
      pos: [2, 11, 7], 
      state: 12
    }, 
    {
      pos: [2, 11, 8], 
      state: 12
    }, 
    {
      pos: [3, 11, 0], 
      state: 12
    }, 
    {
      pos: [3, 11, 1], 
      state: 12
    }, 
    {
      pos: [3, 11, 2], 
      state: 12
    }, 
    {
      pos: [3, 11, 6], 
      state: 12
    }, 
    {
      pos: [3, 11, 7], 
      state: 12
    }, 
    {
      pos: [3, 11, 8], 
      state: 12
    }, 
    {
      pos: [4, 11, 0], 
      state: 12
    }, 
    {
      pos: [4, 11, 1], 
      state: 12
    }, 
    {
      pos: [4, 11, 7], 
      state: 12
    }, 
    {
      pos: [4, 11, 8], 
      state: 12
    }, 
    {
      pos: [5, 11, 0], 
      state: 12
    }, 
    {
      pos: [5, 11, 1], 
      state: 12
    }, 
    {
      pos: [5, 11, 7], 
      state: 12
    }, 
    {
      pos: [5, 11, 8], 
      state: 12
    }, 
    {
      pos: [6, 11, 0], 
      state: 12
    }, 
    {
      pos: [6, 11, 1], 
      state: 12
    }, 
    {
      pos: [6, 11, 7], 
      state: 12
    }, 
    {
      pos: [6, 11, 8], 
      state: 12
    }, 
    {
      pos: [7, 11, 0], 
      state: 12
    }, 
    {
      pos: [7, 11, 1], 
      state: 12
    }, 
    {
      pos: [7, 11, 2], 
      state: 12
    }, 
    {
      pos: [7, 11, 6], 
      state: 12
    }, 
    {
      pos: [7, 11, 7], 
      state: 12
    }, 
    {
      pos: [7, 11, 8], 
      state: 12
    }, 
    {
      pos: [8, 11, 0], 
      state: 12
    }, 
    {
      pos: [8, 11, 1], 
      state: 12
    }, 
    {
      pos: [8, 11, 2], 
      state: 12
    }, 
    {
      pos: [8, 11, 3], 
      state: 12
    }, 
    {
      pos: [8, 11, 4], 
      state: 12
    }, 
    {
      pos: [8, 11, 5], 
      state: 12
    }, 
    {
      pos: [8, 11, 6], 
      state: 12
    }, 
    {
      pos: [8, 11, 7], 
      state: 12
    }, 
    {
      pos: [8, 11, 8], 
      state: 12
    }, 
    {
      pos: [0, 12, 0], 
      state: 12
    }, 
    {
      pos: [0, 12, 1], 
      state: 12
    }, 
    {
      pos: [0, 12, 2], 
      state: 12
    }, 
    {
      pos: [0, 12, 3], 
      state: 12
    }, 
    {
      pos: [0, 12, 4], 
      state: 12
    }, 
    {
      pos: [0, 12, 5], 
      state: 12
    }, 
    {
      pos: [0, 12, 6], 
      state: 12
    }, 
    {
      pos: [0, 12, 7], 
      state: 12
    }, 
    {
      pos: [0, 12, 8], 
      state: 12
    }, 
    {
      pos: [1, 12, 0], 
      state: 12
    }, 
    {
      pos: [1, 12, 1], 
      state: 12
    }, 
    {
      pos: [1, 12, 2], 
      state: 12
    }, 
    {
      pos: [1, 12, 3], 
      state: 12
    }, 
    {
      pos: [1, 12, 4], 
      state: 12
    }, 
    {
      pos: [1, 12, 5], 
      state: 12
    }, 
    {
      pos: [1, 12, 6], 
      state: 12
    }, 
    {
      pos: [1, 12, 7], 
      state: 12
    }, 
    {
      pos: [1, 12, 8], 
      state: 12
    }, 
    {
      pos: [2, 12, 0], 
      state: 12
    }, 
    {
      pos: [2, 12, 1], 
      state: 12
    }, 
    {
      pos: [2, 12, 2], 
      state: 12
    }, 
    {
      pos: [2, 12, 3], 
      state: 12
    }, 
    {
      pos: [2, 12, 4], 
      state: 12
    }, 
    {
      pos: [2, 12, 5], 
      state: 12
    }, 
    {
      pos: [2, 12, 6], 
      state: 12
    }, 
    {
      pos: [2, 12, 7], 
      state: 12
    }, 
    {
      pos: [2, 12, 8], 
      state: 12
    }, 
    {
      pos: [3, 12, 0], 
      state: 12
    }, 
    {
      pos: [3, 12, 1], 
      state: 12
    }, 
    {
      pos: [3, 12, 2], 
      state: 12
    }, 
    {
      pos: [3, 12, 3], 
      state: 12
    }, 
    {
      pos: [3, 12, 4], 
      state: 12
    }, 
    {
      pos: [3, 12, 5], 
      state: 12
    }, 
    {
      pos: [3, 12, 6], 
      state: 12
    }, 
    {
      pos: [3, 12, 7], 
      state: 12
    }, 
    {
      pos: [3, 12, 8], 
      state: 12
    }, 
    {
      pos: [4, 12, 0], 
      state: 12
    }, 
    {
      pos: [4, 12, 1], 
      state: 12
    }, 
    {
      pos: [4, 12, 2], 
      state: 12
    }, 
    {
      pos: [4, 12, 3], 
      state: 12
    }, 
    {
      pos: [4, 12, 5], 
      state: 12
    }, 
    {
      pos: [4, 12, 6], 
      state: 12
    }, 
    {
      pos: [4, 12, 7], 
      state: 12
    }, 
    {
      pos: [4, 12, 8], 
      state: 12
    }, 
    {
      pos: [5, 12, 0], 
      state: 12
    }, 
    {
      pos: [5, 12, 1], 
      state: 12
    }, 
    {
      pos: [5, 12, 2], 
      state: 12
    }, 
    {
      pos: [5, 12, 6], 
      state: 12
    }, 
    {
      pos: [5, 12, 7], 
      state: 12
    }, 
    {
      pos: [5, 12, 8], 
      state: 12
    }, 
    {
      pos: [6, 12, 0], 
      state: 12
    }, 
    {
      pos: [6, 12, 1], 
      state: 12
    }, 
    {
      pos: [6, 12, 2], 
      state: 12
    }, 
    {
      pos: [6, 12, 3], 
      state: 12
    }, 
    {
      pos: [6, 12, 5], 
      state: 12
    }, 
    {
      pos: [6, 12, 6], 
      state: 12
    }, 
    {
      pos: [6, 12, 7], 
      state: 12
    }, 
    {
      pos: [6, 12, 8], 
      state: 12
    }, 
    {
      pos: [7, 12, 0], 
      state: 12
    }, 
    {
      pos: [7, 12, 1], 
      state: 12
    }, 
    {
      pos: [7, 12, 2], 
      state: 12
    }, 
    {
      pos: [7, 12, 3], 
      state: 12
    }, 
    {
      pos: [7, 12, 4], 
      state: 12
    }, 
    {
      pos: [7, 12, 5], 
      state: 12
    }, 
    {
      pos: [7, 12, 6], 
      state: 12
    }, 
    {
      pos: [7, 12, 7], 
      state: 12
    }, 
    {
      pos: [7, 12, 8], 
      state: 12
    }, 
    {
      pos: [8, 12, 0], 
      state: 12
    }, 
    {
      pos: [8, 12, 1], 
      state: 12
    }, 
    {
      pos: [8, 12, 2], 
      state: 12
    }, 
    {
      pos: [8, 12, 3], 
      state: 12
    }, 
    {
      pos: [8, 12, 4], 
      state: 12
    }, 
    {
      pos: [8, 12, 5], 
      state: 12
    }, 
    {
      pos: [8, 12, 6], 
      state: 12
    }, 
    {
      pos: [8, 12, 7], 
      state: 12
    }, 
    {
      pos: [8, 12, 8], 
      state: 12
    }, 
    {
      pos: [0, 13, 0], 
      state: 12
    }, 
    {
      pos: [0, 13, 1], 
      state: 12
    }, 
    {
      pos: [0, 13, 2], 
      state: 12
    }, 
    {
      pos: [0, 13, 3], 
      state: 12
    }, 
    {
      pos: [0, 13, 4], 
      state: 12
    }, 
    {
      pos: [0, 13, 5], 
      state: 12
    }, 
    {
      pos: [0, 13, 6], 
      state: 12
    }, 
    {
      pos: [0, 13, 7], 
      state: 12
    }, 
    {
      pos: [0, 13, 8], 
      state: 12
    }, 
    {
      pos: [1, 13, 0], 
      state: 12
    }, 
    {
      pos: [1, 13, 1], 
      state: 12
    }, 
    {
      pos: [1, 13, 2], 
      state: 12
    }, 
    {
      pos: [1, 13, 3], 
      state: 12
    }, 
    {
      pos: [1, 13, 4], 
      state: 12
    }, 
    {
      pos: [1, 13, 5], 
      state: 12
    }, 
    {
      pos: [1, 13, 6], 
      state: 12
    }, 
    {
      pos: [1, 13, 7], 
      state: 12
    }, 
    {
      pos: [1, 13, 8], 
      state: 12
    }, 
    {
      pos: [2, 13, 0], 
      state: 12
    }, 
    {
      pos: [2, 13, 1], 
      state: 12
    }, 
    {
      pos: [2, 13, 2], 
      state: 12
    }, 
    {
      pos: [2, 13, 3], 
      state: 12
    }, 
    {
      pos: [2, 13, 4], 
      state: 12
    }, 
    {
      pos: [2, 13, 5], 
      state: 12
    }, 
    {
      pos: [2, 13, 6], 
      state: 12
    }, 
    {
      pos: [2, 13, 7], 
      state: 12
    }, 
    {
      pos: [2, 13, 8], 
      state: 12
    }, 
    {
      pos: [3, 13, 0], 
      state: 12
    }, 
    {
      pos: [3, 13, 1], 
      state: 12
    }, 
    {
      pos: [3, 13, 2], 
      state: 12
    }, 
    {
      pos: [3, 13, 3], 
      state: 12
    }, 
    {
      pos: [3, 13, 4], 
      state: 12
    }, 
    {
      pos: [3, 13, 5], 
      state: 12
    }, 
    {
      pos: [3, 13, 6], 
      state: 12
    }, 
    {
      pos: [3, 13, 7], 
      state: 12
    }, 
    {
      pos: [3, 13, 8], 
      state: 12
    }, 
    {
      pos: [4, 13, 0], 
      state: 12
    }, 
    {
      pos: [4, 13, 1], 
      state: 12
    }, 
    {
      pos: [4, 13, 2], 
      state: 12
    }, 
    {
      pos: [4, 13, 3], 
      state: 12
    }, 
    {
      pos: [4, 13, 4], 
      state: 12
    }, 
    {
      pos: [4, 13, 5], 
      state: 12
    }, 
    {
      pos: [4, 13, 6], 
      state: 12
    }, 
    {
      pos: [4, 13, 7], 
      state: 12
    }, 
    {
      pos: [4, 13, 8], 
      state: 12
    }, 
    {
      pos: [5, 13, 0], 
      state: 12
    }, 
    {
      pos: [5, 13, 1], 
      state: 12
    }, 
    {
      pos: [5, 13, 2], 
      state: 12
    }, 
    {
      pos: [5, 13, 3], 
      state: 12
    }, 
    {
      pos: [5, 13, 5], 
      state: 12
    }, 
    {
      pos: [5, 13, 6], 
      state: 12
    }, 
    {
      pos: [5, 13, 7], 
      state: 12
    }, 
    {
      pos: [5, 13, 8], 
      state: 12
    }, 
    {
      pos: [6, 13, 0], 
      state: 12
    }, 
    {
      pos: [6, 13, 1], 
      state: 12
    }, 
    {
      pos: [6, 13, 2], 
      state: 12
    }, 
    {
      pos: [6, 13, 3], 
      state: 12
    }, 
    {
      pos: [6, 13, 4], 
      state: 12
    }, 
    {
      pos: [6, 13, 5], 
      state: 12
    }, 
    {
      pos: [6, 13, 6], 
      state: 12
    }, 
    {
      pos: [6, 13, 7], 
      state: 12
    }, 
    {
      pos: [6, 13, 8], 
      state: 12
    }, 
    {
      pos: [7, 13, 0], 
      state: 12
    }, 
    {
      pos: [7, 13, 1], 
      state: 12
    }, 
    {
      pos: [7, 13, 2], 
      state: 12
    }, 
    {
      pos: [7, 13, 3], 
      state: 12
    }, 
    {
      pos: [7, 13, 4], 
      state: 12
    }, 
    {
      pos: [7, 13, 5], 
      state: 12
    }, 
    {
      pos: [7, 13, 6], 
      state: 12
    }, 
    {
      pos: [7, 13, 7], 
      state: 12
    }, 
    {
      pos: [7, 13, 8], 
      state: 12
    }, 
    {
      pos: [8, 13, 0], 
      state: 12
    }, 
    {
      pos: [8, 13, 1], 
      state: 12
    }, 
    {
      pos: [8, 13, 2], 
      state: 12
    }, 
    {
      pos: [8, 13, 3], 
      state: 12
    }, 
    {
      pos: [8, 13, 4], 
      state: 12
    }, 
    {
      pos: [8, 13, 5], 
      state: 12
    }, 
    {
      pos: [8, 13, 6], 
      state: 12
    }, 
    {
      pos: [8, 13, 7], 
      state: 12
    }, 
    {
      pos: [8, 13, 8], 
      state: 12
    }, 
    {
      pos: [0, 14, 0], 
      state: 12
    }, 
    {
      pos: [0, 14, 1], 
      state: 12
    }, 
    {
      pos: [0, 14, 2], 
      state: 12
    }, 
    {
      pos: [0, 14, 3], 
      state: 12
    }, 
    {
      pos: [0, 14, 4], 
      state: 12
    }, 
    {
      pos: [0, 14, 5], 
      state: 12
    }, 
    {
      pos: [0, 14, 6], 
      state: 12
    }, 
    {
      pos: [0, 14, 7], 
      state: 12
    }, 
    {
      pos: [0, 14, 8], 
      state: 12
    }, 
    {
      pos: [1, 14, 0], 
      state: 12
    }, 
    {
      pos: [1, 14, 1], 
      state: 12
    }, 
    {
      pos: [1, 14, 2], 
      state: 12
    }, 
    {
      pos: [1, 14, 3], 
      state: 12
    }, 
    {
      pos: [1, 14, 4], 
      state: 12
    }, 
    {
      pos: [1, 14, 5], 
      state: 12
    }, 
    {
      pos: [1, 14, 6], 
      state: 12
    }, 
    {
      pos: [1, 14, 7], 
      state: 12
    }, 
    {
      pos: [1, 14, 8], 
      state: 12
    }, 
    {
      pos: [2, 14, 0], 
      state: 12
    }, 
    {
      pos: [2, 14, 1], 
      state: 12
    }, 
    {
      pos: [2, 14, 2], 
      state: 12
    }, 
    {
      pos: [2, 14, 3], 
      state: 12
    }, 
    {
      pos: [2, 14, 4], 
      state: 12
    }, 
    {
      pos: [2, 14, 5], 
      state: 12
    }, 
    {
      pos: [2, 14, 6], 
      state: 12
    }, 
    {
      pos: [2, 14, 7], 
      state: 12
    }, 
    {
      pos: [2, 14, 8], 
      state: 12
    }, 
    {
      pos: [3, 14, 0], 
      state: 12
    }, 
    {
      pos: [3, 14, 1], 
      state: 12
    }, 
    {
      pos: [3, 14, 2], 
      state: 12
    }, 
    {
      pos: [3, 14, 3], 
      state: 12
    }, 
    {
      pos: [3, 14, 4], 
      state: 12
    }, 
    {
      pos: [3, 14, 5], 
      state: 12
    }, 
    {
      pos: [3, 14, 6], 
      state: 12
    }, 
    {
      pos: [3, 14, 7], 
      state: 12
    }, 
    {
      pos: [3, 14, 8], 
      state: 12
    }, 
    {
      pos: [4, 14, 0], 
      state: 12
    }, 
    {
      pos: [4, 14, 1], 
      state: 12
    }, 
    {
      pos: [4, 14, 2], 
      state: 12
    }, 
    {
      pos: [4, 14, 3], 
      state: 12
    }, 
    {
      pos: [4, 14, 5], 
      state: 12
    }, 
    {
      pos: [4, 14, 6], 
      state: 12
    }, 
    {
      pos: [4, 14, 7], 
      state: 12
    }, 
    {
      pos: [4, 14, 8], 
      state: 12
    }, 
    {
      pos: [5, 14, 0], 
      state: 12
    }, 
    {
      pos: [5, 14, 1], 
      state: 12
    }, 
    {
      pos: [5, 14, 2], 
      state: 12
    }, 
    {
      pos: [5, 14, 6], 
      state: 12
    }, 
    {
      pos: [5, 14, 7], 
      state: 12
    }, 
    {
      pos: [5, 14, 8], 
      state: 12
    }, 
    {
      pos: [6, 14, 0], 
      state: 12
    }, 
    {
      pos: [6, 14, 1], 
      state: 12
    }, 
    {
      pos: [6, 14, 2], 
      state: 12
    }, 
    {
      pos: [6, 14, 3], 
      state: 12
    }, 
    {
      pos: [6, 14, 5], 
      state: 12
    }, 
    {
      pos: [6, 14, 6], 
      state: 12
    }, 
    {
      pos: [6, 14, 7], 
      state: 12
    }, 
    {
      pos: [6, 14, 8], 
      state: 12
    }, 
    {
      pos: [7, 14, 0], 
      state: 12
    }, 
    {
      pos: [7, 14, 1], 
      state: 12
    }, 
    {
      pos: [7, 14, 2], 
      state: 12
    }, 
    {
      pos: [7, 14, 3], 
      state: 12
    }, 
    {
      pos: [7, 14, 4], 
      state: 12
    }, 
    {
      pos: [7, 14, 5], 
      state: 12
    }, 
    {
      pos: [7, 14, 6], 
      state: 12
    }, 
    {
      pos: [7, 14, 7], 
      state: 12
    }, 
    {
      pos: [7, 14, 8], 
      state: 12
    }, 
    {
      pos: [8, 14, 0], 
      state: 12
    }, 
    {
      pos: [8, 14, 1], 
      state: 12
    }, 
    {
      pos: [8, 14, 2], 
      state: 12
    }, 
    {
      pos: [8, 14, 3], 
      state: 12
    }, 
    {
      pos: [8, 14, 4], 
      state: 12
    }, 
    {
      pos: [8, 14, 5], 
      state: 12
    }, 
    {
      pos: [8, 14, 6], 
      state: 12
    }, 
    {
      pos: [8, 14, 7], 
      state: 12
    }, 
    {
      pos: [8, 14, 8], 
      state: 12
    }
  ], 
  palette: [
    {
      Name: "minecraft:ice"
    }, 
    {
      Name: "minecraft:coarse_dirt"
    }, 
    {
      Name: "minecraft:blue_ice"
    }, 
    {
      Name: "minecraft:snow_block"
    }, 
    {
      Name: "minecraft:packed_ice"
    }, 
    {
      Properties: {
        axis: "y"
      }, 
      Name: "minecraft:spruce_log"
    }, 
    {
      Properties: {
        waterlogged: "false", 
        distance: "3", 
        persistent: "false"
      }, 
      Name: "minecraft:spruce_leaves"
    }, 
    {
      Properties: {
        waterlogged: "false", 
        distance: "2", 
        persistent: "false"
      }, 
      Name: "minecraft:spruce_leaves"
    }, 
    {
      Properties: {
        waterlogged: "false", 
        distance: "1", 
        persistent: "false"
      }, 
      Name: "minecraft:spruce_leaves"
    }, 
    {
      Properties: {
        waterlogged: "false", 
        distance: "6", 
        persistent: "false"
      }, 
      Name: "minecraft:spruce_leaves"
    }, 
    {
      Properties: {
        waterlogged: "false", 
        distance: "5", 
        persistent: "false"
      }, 
      Name: "minecraft:spruce_leaves"
    }, 
    {
      Properties: {
        waterlogged: "false", 
        distance: "4", 
        persistent: "false"
      }, 
      Name: "minecraft:spruce_leaves"
    }, 
    {
      Name: "minecraft:air"
    }
  ]
}
