{
  size: [5, 9, 5], 
  entities: [], 
  blocks: [
    {
      pos: [0, 0, 0], 
      state: 0
    }, 
    {
      pos: [0, 0, 1], 
      state: 0
    }, 
    {
      pos: [0, 0, 2], 
      state: 0
    }, 
    {
      pos: [0, 0, 3], 
      state: 0
    }, 
    {
      pos: [0, 0, 4], 
      state: 0
    }, 
    {
      pos: [1, 0, 0], 
      state: 0
    }, 
    {
      pos: [1, 0, 1], 
      state: 0
    }, 
    {
      pos: [1, 0, 2], 
      state: 0
    }, 
    {
      pos: [1, 0, 3], 
      state: 0
    }, 
    {
      pos: [1, 0, 4], 
      state: 0
    }, 
    {
      pos: [2, 0, 0], 
      state: 0
    }, 
    {
      pos: [2, 0, 1], 
      state: 0
    }, 
    {
      pos: [2, 0, 2], 
      state: 0
    }, 
    {
      pos: [2, 0, 3], 
      state: 0
    }, 
    {
      pos: [2, 0, 4], 
      state: 0
    }, 
    {
      pos: [3, 0, 0], 
      state: 0
    }, 
    {
      pos: [3, 0, 1], 
      state: 0
    }, 
    {
      pos: [3, 0, 2], 
      state: 0
    }, 
    {
      pos: [3, 0, 3], 
      state: 0
    }, 
    {
      pos: [3, 0, 4], 
      state: 0
    }, 
    {
      pos: [4, 0, 0], 
      state: 0
    }, 
    {
      pos: [4, 0, 1], 
      state: 0
    }, 
    {
      pos: [4, 0, 2], 
      state: 0
    }, 
    {
      pos: [4, 0, 3], 
      state: 0
    }, 
    {
      pos: [4, 0, 4], 
      state: 0
    }, 
    {
      pos: [0, 1, 0], 
      state: 0
    }, 
    {
      pos: [0, 1, 1], 
      state: 0
    }, 
    {
      pos: [0, 1, 2], 
      state: 0
    }, 
    {
      pos: [0, 1, 3], 
      state: 0
    }, 
    {
      pos: [0, 1, 4], 
      state: 0
    }, 
    {
      pos: [1, 1, 0], 
      state: 1
    }, 
    {
      pos: [1, 1, 1], 
      state: 2
    }, 
    {
      pos: [1, 1, 2], 
      state: 0
    }, 
    {
      pos: [1, 1, 3], 
      state: 0
    }, 
    {
      pos: [1, 1, 4], 
      state: 0
    }, 
    {
      pos: [2, 1, 0], 
      state: 1
    }, 
    {
      pos: [2, 1, 1], 
      state: 1
    }, 
    {
      pos: [2, 1, 2], 
      state: 0
    }, 
    {
      pos: [2, 1, 3], 
      state: 0
    }, 
    {
      pos: [2, 1, 4], 
      state: 0
    }, 
    {
      pos: [3, 1, 0], 
      state: 1
    }, 
    {
      pos: [3, 1, 1], 
      state: 2
    }, 
    {
      pos: [3, 1, 2], 
      state: 0
    }, 
    {
      pos: [3, 1, 3], 
      state: 0
    }, 
    {
      pos: [3, 1, 4], 
      state: 0
    }, 
    {
      pos: [4, 1, 0], 
      state: 0
    }, 
    {
      pos: [4, 1, 1], 
      state: 0
    }, 
    {
      pos: [4, 1, 2], 
      state: 0
    }, 
    {
      pos: [4, 1, 3], 
      state: 0
    }, 
    {
      pos: [4, 1, 4], 
      state: 0
    }, 
    {
      pos: [0, 2, 0], 
      state: 3
    }, 
    {
      pos: [0, 2, 1], 
      state: 0
    }, 
    {
      pos: [0, 2, 2], 
      state: 0
    }, 
    {
      pos: [0, 2, 3], 
      state: 0
    }, 
    {
      pos: [0, 2, 4], 
      state: 0
    }, 
    {
      pos: [1, 2, 2], 
      state: 0
    }, 
    {
      pos: [1, 2, 3], 
      state: 0
    }, 
    {
      pos: [1, 2, 4], 
      state: 0
    }, 
    {
      pos: [2, 2, 2], 
      state: 0
    }, 
    {
      pos: [2, 2, 3], 
      state: 0
    }, 
    {
      pos: [2, 2, 4], 
      state: 0
    }, 
    {
      pos: [3, 2, 2], 
      state: 0
    }, 
    {
      pos: [3, 2, 3], 
      state: 0
    }, 
    {
      pos: [3, 2, 4], 
      state: 0
    }, 
    {
      pos: [4, 2, 0], 
      state: 3
    }, 
    {
      pos: [4, 2, 1], 
      state: 0
    }, 
    {
      pos: [4, 2, 2], 
      state: 0
    }, 
    {
      pos: [4, 2, 3], 
      state: 0
    }, 
    {
      pos: [4, 2, 4], 
      state: 0
    }, 
    {
      pos: [0, 3, 0], 
      state: 4
    }, 
    {
      pos: [0, 3, 1], 
      state: 3
    }, 
    {
      pos: [0, 3, 2], 
      state: 0
    }, 
    {
      pos: [0, 3, 3], 
      state: 0
    }, 
    {
      pos: [0, 3, 4], 
      state: 0
    }, 
    {
      pos: [1, 3, 3], 
      state: 0
    }, 
    {
      pos: [1, 3, 4], 
      state: 0
    }, 
    {
      pos: [2, 3, 3], 
      state: 0
    }, 
    {
      pos: [2, 3, 4], 
      state: 0
    }, 
    {
      pos: [3, 3, 3], 
      state: 0
    }, 
    {
      pos: [3, 3, 4], 
      state: 0
    }, 
    {
      pos: [4, 3, 0], 
      state: 4
    }, 
    {
      pos: [4, 3, 1], 
      state: 3
    }, 
    {
      pos: [4, 3, 2], 
      state: 0
    }, 
    {
      pos: [4, 3, 3], 
      state: 0
    }, 
    {
      pos: [4, 3, 4], 
      state: 0
    }, 
    {
      pos: [0, 4, 0], 
      state: 0
    }, 
    {
      pos: [0, 4, 1], 
      state: 3
    }, 
    {
      pos: [0, 4, 2], 
      state: 3
    }, 
    {
      pos: [0, 4, 3], 
      state: 0
    }, 
    {
      pos: [0, 4, 4], 
      state: 0
    }, 
    {
      pos: [1, 4, 4], 
      state: 1
    }, 
    {
      pos: [2, 4, 4], 
      state: 1
    }, 
    {
      pos: [3, 4, 4], 
      state: 1
    }, 
    {
      pos: [4, 4, 0], 
      state: 0
    }, 
    {
      pos: [4, 4, 1], 
      state: 3
    }, 
    {
      pos: [4, 4, 2], 
      state: 3
    }, 
    {
      pos: [4, 4, 3], 
      state: 5
    }, 
    {
      pos: [4, 4, 4], 
      state: 0
    }, 
    {
      pos: [0, 5, 0], 
      state: 0
    }, 
    {
      pos: [0, 5, 1], 
      state: 0
    }, 
    {
      pos: [0, 5, 2], 
      state: 3
    }, 
    {
      pos: [0, 5, 3], 
      state: 3
    }, 
    {
      pos: [0, 5, 4], 
      state: 3
    }, 
    {
      pos: [1, 5, 0], 
      state: 6
    }, 
    {
      pos: [2, 5, 0], 
      state: 6
    }, 
    {
      pos: [3, 5, 0], 
      state: 6
    }, 
    {
      pos: [4, 5, 0], 
      state: 0
    }, 
    {
      pos: [4, 5, 1], 
      state: 0
    }, 
    {
      pos: [4, 5, 2], 
      state: 3
    }, 
    {
      pos: [4, 5, 3], 
      state: 3
    }, 
    {
      pos: [4, 5, 4], 
      state: 3
    }, 
    {
      pos: [0, 6, 0], 
      state: 0
    }, 
    {
      pos: [0, 6, 1], 
      state: 0
    }, 
    {
      pos: [0, 6, 2], 
      state: 0
    }, 
    {
      pos: [0, 6, 3], 
      state: 7
    }, 
    {
      pos: [0, 6, 4], 
      state: 0
    }, 
    {
      pos: [1, 6, 0], 
      state: 0
    }, 
    {
      pos: [2, 6, 0], 
      state: 0
    }, 
    {
      pos: [3, 6, 0], 
      state: 0
    }, 
    {
      pos: [4, 6, 0], 
      state: 0
    }, 
    {
      pos: [4, 6, 1], 
      state: 0
    }, 
    {
      pos: [4, 6, 2], 
      state: 0
    }, 
    {
      pos: [4, 6, 3], 
      state: 7
    }, 
    {
      pos: [4, 6, 4], 
      state: 0
    }, 
    {
      pos: [0, 7, 0], 
      state: 5
    }, 
    {
      pos: [0, 7, 1], 
      state: 5
    }, 
    {
      pos: [0, 7, 2], 
      state: 5
    }, 
    {
      pos: [0, 7, 3], 
      state: 5
    }, 
    {
      pos: [0, 7, 4], 
      state: 5
    }, 
    {
      pos: [1, 7, 0], 
      state: 5
    }, 
    {
      pos: [2, 7, 0], 
      state: 5
    }, 
    {
      pos: [3, 7, 0], 
      state: 5
    }, 
    {
      pos: [4, 7, 0], 
      state: 5
    }, 
    {
      pos: [4, 7, 1], 
      state: 5
    }, 
    {
      pos: [4, 7, 2], 
      state: 5
    }, 
    {
      pos: [4, 7, 3], 
      state: 5
    }, 
    {
      pos: [4, 7, 4], 
      state: 5
    }, 
    {
      pos: [0, 8, 0], 
      state: 0
    }, 
    {
      pos: [0, 8, 1], 
      state: 0
    }, 
    {
      pos: [0, 8, 2], 
      state: 0
    }, 
    {
      pos: [0, 8, 3], 
      state: 0
    }, 
    {
      pos: [0, 8, 4], 
      state: 0
    }, 
    {
      pos: [1, 8, 0], 
      state: 0
    }, 
    {
      pos: [1, 8, 1], 
      state: 6
    }, 
    {
      pos: [1, 8, 2], 
      state: 6
    }, 
    {
      pos: [1, 8, 3], 
      state: 6
    }, 
    {
      pos: [1, 8, 4], 
      state: 6
    }, 
    {
      pos: [2, 8, 0], 
      state: 0
    }, 
    {
      pos: [2, 8, 1], 
      state: 6
    }, 
    {
      pos: [2, 8, 2], 
      state: 6
    }, 
    {
      pos: [2, 8, 3], 
      state: 6
    }, 
    {
      pos: [2, 8, 4], 
      state: 6
    }, 
    {
      pos: [3, 8, 0], 
      state: 0
    }, 
    {
      pos: [3, 8, 1], 
      state: 6
    }, 
    {
      pos: [3, 8, 2], 
      state: 6
    }, 
    {
      pos: [3, 8, 3], 
      state: 6
    }, 
    {
      pos: [3, 8, 4], 
      state: 6
    }, 
    {
      pos: [4, 8, 0], 
      state: 0
    }, 
    {
      pos: [4, 8, 1], 
      state: 0
    }, 
    {
      pos: [4, 8, 2], 
      state: 0
    }, 
    {
      pos: [4, 8, 3], 
      state: 0
    }, 
    {
      pos: [4, 8, 4], 
      state: 0
    }, 
    {
      pos: [1, 2, 0], 
      state: 8
    }, 
    {
      pos: [1, 2, 1], 
      state: 9
    }, 
    {
      pos: [2, 2, 0], 
      state: 8
    }, 
    {
      pos: [2, 2, 1], 
      state: 9
    }, 
    {
      pos: [3, 2, 0], 
      state: 8
    }, 
    {
      pos: [3, 2, 1], 
      state: 9
    }, 
    {
      pos: [1, 3, 0], 
      state: 8
    }, 
    {
      pos: [1, 3, 1], 
      state: 8
    }, 
    {
      pos: [1, 3, 2], 
      state: 9
    }, 
    {
      pos: [2, 3, 1], 
      state: 8
    }, 
    {
      pos: [2, 3, 2], 
      state: 9
    }, 
    {
      pos: [3, 3, 0], 
      state: 8
    }, 
    {
      pos: [3, 3, 1], 
      state: 8
    }, 
    {
      pos: [3, 3, 2], 
      state: 9
    }, 
    {
      pos: [1, 4, 0], 
      state: 8
    }, 
    {
      pos: [1, 4, 1], 
      state: 8
    }, 
    {
      pos: [1, 4, 2], 
      state: 8
    }, 
    {
      pos: [1, 4, 3], 
      state: 9
    }, 
    {
      pos: [2, 4, 0], 
      state: 8
    }, 
    {
      pos: [2, 4, 1], 
      state: 8
    }, 
    {
      pos: [2, 4, 2], 
      state: 8
    }, 
    {
      pos: [2, 4, 3], 
      state: 9
    }, 
    {
      pos: [3, 4, 0], 
      state: 8
    }, 
    {
      pos: [3, 4, 1], 
      state: 8
    }, 
    {
      pos: [3, 4, 2], 
      state: 8
    }, 
    {
      pos: [3, 4, 3], 
      state: 9
    }, 
    {
      pos: [1, 5, 1], 
      state: 8
    }, 
    {
      pos: [1, 5, 2], 
      state: 8
    }, 
    {
      pos: [1, 5, 3], 
      state: 8
    }, 
    {
      pos: [1, 5, 4], 
      state: 8
    }, 
    {
      pos: [2, 5, 1], 
      state: 8
    }, 
    {
      pos: [2, 5, 2], 
      state: 8
    }, 
    {
      pos: [2, 5, 3], 
      state: 8
    }, 
    {
      pos: [2, 5, 4], 
      state: 8
    }, 
    {
      pos: [3, 5, 1], 
      state: 8
    }, 
    {
      pos: [3, 5, 2], 
      state: 8
    }, 
    {
      pos: [3, 5, 3], 
      state: 8
    }, 
    {
      pos: [3, 5, 4], 
      state: 8
    }, 
    {
      pos: [1, 6, 1], 
      state: 8
    }, 
    {
      pos: [1, 6, 2], 
      state: 8
    }, 
    {
      pos: [1, 6, 3], 
      state: 8
    }, 
    {
      pos: [1, 6, 4], 
      state: 8
    }, 
    {
      pos: [2, 6, 1], 
      state: 8
    }, 
    {
      pos: [2, 6, 2], 
      state: 8
    }, 
    {
      pos: [2, 6, 3], 
      state: 8
    }, 
    {
      pos: [3, 6, 1], 
      state: 8
    }, 
    {
      pos: [3, 6, 2], 
      state: 8
    }, 
    {
      pos: [3, 6, 3], 
      state: 8
    }, 
    {
      pos: [3, 6, 4], 
      state: 8
    }, 
    {
      pos: [1, 7, 1], 
      state: 8
    }, 
    {
      pos: [1, 7, 2], 
      state: 8
    }, 
    {
      pos: [1, 7, 3], 
      state: 8
    }, 
    {
      pos: [1, 7, 4], 
      state: 8
    }, 
    {
      pos: [2, 7, 1], 
      state: 8
    }, 
    {
      pos: [2, 7, 2], 
      state: 8
    }, 
    {
      pos: [2, 7, 3], 
      state: 8
    }, 
    {
      pos: [2, 7, 4], 
      state: 8
    }, 
    {
      pos: [3, 7, 1], 
      state: 8
    }, 
    {
      pos: [3, 7, 2], 
      state: 8
    }, 
    {
      pos: [3, 7, 3], 
      state: 8
    }, 
    {
      pos: [3, 7, 4], 
      state: 8
    }, 
    {
      nbt: {
        joint: "rollable", 
        final_state: "minecraft:air", 
        name: "minecraft:in_connector", 
        placement_priority: 0, 
        pool: "minecraft:empty", 
        selection_priority: 0, 
        id: "minecraft:jigsaw", 
        target: "minecraft:empty"
      }, 
      pos: [2, 3, 0], 
      state: 10
    }, 
    {
      nbt: {
        joint: "rollable", 
        final_state: "minecraft:air", 
        name: "minecraft:empty", 
        placement_priority: 0, 
        pool: "minecraft:trial_chambers/hallway", 
        selection_priority: 0, 
        id: "minecraft:jigsaw", 
        target: "minecraft:in_connector"
      }, 
      pos: [2, 6, 4], 
      state: 11
    }
  ], 
  palette: [
    {
      Name: "minecraft:tuff_bricks"
    }, 
    {
      Name: "minecraft:waxed_oxidized_copper"
    }, 
    {
      Name: "minecraft:waxed_oxidized_cut_copper"
    }, 
    {
      Name: "minecraft:waxed_copper_block"
    }, 
    {
      Name: "minecraft:waxed_chiseled_copper"
    }, 
    {
      Name: "minecraft:chiseled_tuff_bricks"
    }, 
    {
      Name: "minecraft:polished_tuff"
    }, 
    {
      Properties: {
        powered: "false", 
        lit: "true"
      }, 
      Name: "minecraft:waxed_copper_bulb"
    }, 
    {
      Name: "minecraft:air"
    }, 
    {
      Properties: {
        half: "bottom", 
        waterlogged: "false", 
        shape: "straight", 
        facing: "south"
      }, 
      Name: "minecraft:waxed_oxidized_cut_copper_stairs"
    }, 
    {
      Properties: {
        orientation: "north_up"
      }, 
      Name: "minecraft:jigsaw"
    }, 
    {
      Properties: {
        orientation: "south_up"
      }, 
      Name: "minecraft:jigsaw"
    }
  ]
}
