{
  size: [9, 6, 13], 
  entities: [], 
  blocks: [
    {
      pos: [3, 4, 0], 
      state: 0
    }, 
    {
      pos: [4, 4, 0], 
      state: 0
    }, 
    {
      pos: [2, 0, 1], 
      state: 1
    }, 
    {
      pos: [3, 0, 1], 
      state: 1
    }, 
    {
      pos: [4, 0, 1], 
      state: 1
    }, 
    {
      pos: [5, 0, 1], 
      state: 1
    }, 
    {
      pos: [2, 1, 1], 
      state: 2
    }, 
    {
      pos: [3, 1, 1], 
      state: 0
    }, 
    {
      pos: [4, 1, 1], 
      state: 0
    }, 
    {
      pos: [5, 1, 1], 
      state: 2
    }, 
    {
      pos: [2, 2, 1], 
      state: 2
    }, 
    {
      pos: [3, 2, 1], 
      state: 0
    }, 
    {
      pos: [4, 2, 1], 
      state: 0
    }, 
    {
      pos: [5, 2, 1], 
      state: 2
    }, 
    {
      pos: [2, 3, 1], 
      state: 2
    }, 
    {
      pos: [3, 3, 1], 
      state: 0
    }, 
    {
      pos: [4, 3, 1], 
      state: 0
    }, 
    {
      pos: [5, 3, 1], 
      state: 2
    }, 
    {
      pos: [3, 4, 1], 
      state: 0
    }, 
    {
      pos: [4, 4, 1], 
      state: 0
    }, 
    {
      pos: [2, 0, 2], 
      state: 1
    }, 
    {
      pos: [3, 0, 2], 
      state: 0
    }, 
    {
      pos: [4, 0, 2], 
      state: 0
    }, 
    {
      pos: [5, 0, 2], 
      state: 1
    }, 
    {
      pos: [2, 1, 2], 
      state: 0
    }, 
    {
      pos: [3, 1, 2], 
      state: 3
    }, 
    {
      pos: [4, 1, 2], 
      state: 3
    }, 
    {
      pos: [5, 1, 2], 
      state: 0
    }, 
    {
      pos: [2, 2, 2], 
      state: 4
    }, 
    {
      pos: [5, 2, 2], 
      state: 4
    }, 
    {
      pos: [2, 3, 2], 
      state: 0
    }, 
    {
      pos: [5, 3, 2], 
      state: 0
    }, 
    {
      pos: [3, 4, 2], 
      state: 0
    }, 
    {
      pos: [4, 4, 2], 
      state: 0
    }, 
    {
      pos: [2, 0, 3], 
      state: 1
    }, 
    {
      pos: [3, 0, 3], 
      state: 5
    }, 
    {
      pos: [4, 0, 3], 
      state: 6
    }, 
    {
      pos: [5, 0, 3], 
      state: 1
    }, 
    {
      pos: [6, 0, 3], 
      state: 7
    }, 
    {
      pos: [7, 0, 3], 
      state: 7
    }, 
    {
      pos: [8, 0, 3], 
      state: 7
    }, 
    {
      pos: [2, 1, 3], 
      state: 0
    }, 
    {
      pos: [5, 1, 3], 
      state: 0
    }, 
    {
      pos: [2, 3, 3], 
      state: 0
    }, 
    {
      pos: [5, 3, 3], 
      state: 0
    }, 
    {
      pos: [3, 4, 3], 
      state: 0
    }, 
    {
      pos: [4, 4, 3], 
      state: 0
    }, 
    {
      pos: [0, 0, 4], 
      state: 1
    }, 
    {
      pos: [2, 0, 4], 
      state: 1
    }, 
    {
      pos: [3, 0, 4], 
      state: 6
    }, 
    {
      pos: [4, 0, 4], 
      state: 5
    }, 
    {
      pos: [5, 0, 4], 
      state: 1
    }, 
    {
      pos: [6, 0, 4], 
      state: 7
    }, 
    {
      pos: [7, 0, 4], 
      state: 7
    }, 
    {
      pos: [8, 0, 4], 
      state: 7
    }, 
    {
      pos: [2, 1, 4], 
      state: 0
    }, 
    {
      pos: [5, 1, 4], 
      state: 0
    }, 
    {
      pos: [2, 2, 4], 
      state: 4
    }, 
    {
      pos: [5, 2, 4], 
      state: 4
    }, 
    {
      pos: [2, 3, 4], 
      state: 0
    }, 
    {
      pos: [5, 3, 4], 
      state: 0
    }, 
    {
      pos: [3, 4, 4], 
      state: 0
    }, 
    {
      pos: [4, 4, 4], 
      state: 0
    }, 
    {
      pos: [0, 0, 5], 
      state: 7
    }, 
    {
      pos: [2, 0, 5], 
      state: 1
    }, 
    {
      pos: [3, 0, 5], 
      state: 5
    }, 
    {
      pos: [4, 0, 5], 
      state: 6
    }, 
    {
      pos: [5, 0, 5], 
      state: 1
    }, 
    {
      pos: [6, 0, 5], 
      state: 7
    }, 
    {
      pos: [8, 0, 5], 
      state: 7
    }, 
    {
      pos: [2, 1, 5], 
      state: 0
    }, 
    {
      pos: [5, 1, 5], 
      state: 0
    }, 
    {
      pos: [2, 2, 5], 
      state: 0
    }, 
    {
      pos: [5, 2, 5], 
      state: 4
    }, 
    {
      pos: [2, 3, 5], 
      state: 0
    }, 
    {
      pos: [5, 3, 5], 
      state: 0
    }, 
    {
      pos: [2, 4, 5], 
      state: 0
    }, 
    {
      pos: [5, 4, 5], 
      state: 0
    }, 
    {
      pos: [2, 0, 6], 
      state: 0
    }, 
    {
      pos: [3, 0, 6], 
      state: 0
    }, 
    {
      pos: [4, 0, 6], 
      state: 0
    }, 
    {
      pos: [5, 0, 6], 
      state: 0
    }, 
    {
      pos: [6, 0, 6], 
      state: 7
    }, 
    {
      pos: [7, 0, 6], 
      state: 7
    }, 
    {
      pos: [8, 0, 6], 
      state: 7
    }, 
    {
      pos: [2, 3, 6], 
      state: 0
    }, 
    {
      pos: [5, 3, 6], 
      state: 0
    }, 
    {
      pos: [0, 4, 6], 
      state: 6
    }, 
    {
      pos: [1, 4, 6], 
      state: 5
    }, 
    {
      pos: [2, 4, 6], 
      state: 0
    }, 
    {
      pos: [5, 4, 6], 
      state: 0
    }, 
    {
      pos: [2, 5, 6], 
      state: 0
    }, 
    {
      pos: [3, 5, 6], 
      state: 0
    }, 
    {
      pos: [4, 5, 6], 
      state: 0
    }, 
    {
      pos: [5, 5, 6], 
      state: 0
    }, 
    {
      pos: [6, 5, 6], 
      state: 0
    }, 
    {
      pos: [0, 0, 7], 
      state: 7
    }, 
    {
      pos: [2, 0, 7], 
      state: 1
    }, 
    {
      pos: [3, 0, 7], 
      state: 6
    }, 
    {
      pos: [4, 0, 7], 
      state: 5
    }, 
    {
      pos: [5, 0, 7], 
      state: 1
    }, 
    {
      pos: [6, 0, 7], 
      state: 7
    }, 
    {
      pos: [7, 0, 7], 
      state: 7
    }, 
    {
      pos: [8, 0, 7], 
      state: 7
    }, 
    {
      pos: [2, 1, 7], 
      state: 0
    }, 
    {
      pos: [5, 1, 7], 
      state: 0
    }, 
    {
      pos: [2, 2, 7], 
      state: 0
    }, 
    {
      pos: [5, 2, 7], 
      state: 4
    }, 
    {
      pos: [2, 3, 7], 
      state: 0
    }, 
    {
      pos: [5, 3, 7], 
      state: 0
    }, 
    {
      pos: [2, 4, 7], 
      state: 0
    }, 
    {
      pos: [5, 4, 7], 
      state: 0
    }, 
    {
      pos: [2, 0, 8], 
      state: 1
    }, 
    {
      pos: [3, 0, 8], 
      state: 5
    }, 
    {
      pos: [4, 0, 8], 
      state: 6
    }, 
    {
      pos: [5, 0, 8], 
      state: 1
    }, 
    {
      pos: [6, 0, 8], 
      state: 7
    }, 
    {
      pos: [7, 0, 8], 
      state: 7
    }, 
    {
      pos: [8, 0, 8], 
      state: 7
    }, 
    {
      pos: [2, 1, 8], 
      state: 0
    }, 
    {
      pos: [5, 1, 8], 
      state: 0
    }, 
    {
      pos: [2, 2, 8], 
      state: 4
    }, 
    {
      pos: [5, 2, 8], 
      state: 4
    }, 
    {
      pos: [2, 3, 8], 
      state: 0
    }, 
    {
      pos: [5, 3, 8], 
      state: 0
    }, 
    {
      pos: [3, 4, 8], 
      state: 0
    }, 
    {
      pos: [4, 4, 8], 
      state: 0
    }, 
    {
      pos: [2, 0, 9], 
      state: 1
    }, 
    {
      pos: [3, 0, 9], 
      state: 6
    }, 
    {
      pos: [4, 0, 9], 
      state: 5
    }, 
    {
      pos: [5, 0, 9], 
      state: 1
    }, 
    {
      pos: [6, 0, 9], 
      state: 7
    }, 
    {
      pos: [7, 0, 9], 
      state: 7
    }, 
    {
      pos: [8, 0, 9], 
      state: 7
    }, 
    {
      pos: [2, 1, 9], 
      state: 0
    }, 
    {
      pos: [5, 1, 9], 
      state: 0
    }, 
    {
      pos: [2, 3, 9], 
      state: 0
    }, 
    {
      pos: [5, 3, 9], 
      state: 0
    }, 
    {
      pos: [3, 4, 9], 
      state: 0
    }, 
    {
      pos: [4, 4, 9], 
      state: 0
    }, 
    {
      pos: [2, 0, 10], 
      state: 1
    }, 
    {
      pos: [3, 0, 10], 
      state: 0
    }, 
    {
      pos: [4, 0, 10], 
      state: 0
    }, 
    {
      pos: [5, 0, 10], 
      state: 1
    }, 
    {
      pos: [2, 1, 10], 
      state: 0
    }, 
    {
      pos: [5, 1, 10], 
      state: 0
    }, 
    {
      pos: [2, 2, 10], 
      state: 4
    }, 
    {
      pos: [5, 2, 10], 
      state: 4
    }, 
    {
      pos: [2, 3, 10], 
      state: 0
    }, 
    {
      pos: [5, 3, 10], 
      state: 0
    }, 
    {
      pos: [3, 4, 10], 
      state: 0
    }, 
    {
      pos: [4, 4, 10], 
      state: 0
    }, 
    {
      pos: [2, 0, 11], 
      state: 1
    }, 
    {
      pos: [3, 0, 11], 
      state: 1
    }, 
    {
      pos: [4, 0, 11], 
      state: 1
    }, 
    {
      pos: [5, 0, 11], 
      state: 1
    }, 
    {
      pos: [2, 1, 11], 
      state: 2
    }, 
    {
      pos: [3, 1, 11], 
      state: 0
    }, 
    {
      pos: [4, 1, 11], 
      state: 0
    }, 
    {
      pos: [5, 1, 11], 
      state: 2
    }, 
    {
      pos: [2, 2, 11], 
      state: 2
    }, 
    {
      pos: [3, 2, 11], 
      state: 0
    }, 
    {
      pos: [4, 2, 11], 
      state: 0
    }, 
    {
      pos: [5, 2, 11], 
      state: 2
    }, 
    {
      pos: [2, 3, 11], 
      state: 2
    }, 
    {
      pos: [3, 3, 11], 
      state: 0
    }, 
    {
      pos: [4, 3, 11], 
      state: 0
    }, 
    {
      pos: [5, 3, 11], 
      state: 2
    }, 
    {
      pos: [3, 4, 11], 
      state: 0
    }, 
    {
      pos: [4, 4, 11], 
      state: 0
    }, 
    {
      pos: [3, 4, 12], 
      state: 0
    }, 
    {
      pos: [4, 4, 12], 
      state: 0
    }, 
    {
      nbt: {
        target_pool: "minecraft:village/plains/zombie/decor", 
        final_state: "minecraft:dirt", 
        id: "minecraft:jigsaw", 
        attachement_type: "minecraft:bottom"
      }, 
      pos: [0, 0, 0], 
      state: 8
    }, 
    {
      nbt: {
        target_pool: "minecraft:village/plains/zombie/decor", 
        final_state: "minecraft:dirt", 
        id: "minecraft:jigsaw", 
        attachement_type: "minecraft:bottom"
      }, 
      pos: [8, 0, 1], 
      state: 8
    }, 
    {
      nbt: {
        target_pool: "minecraft:empty", 
        final_state: "minecraft:structure_void", 
        id: "minecraft:jigsaw", 
        attachement_type: "minecraft:building_entrance"
      }, 
      pos: [0, 1, 4], 
      state: 9
    }, 
    {
      nbt: {
        target_pool: "minecraft:village/common/sheep", 
        final_state: "minecraft:dirt", 
        id: "minecraft:jigsaw", 
        attachement_type: "minecraft:bottom"
      }, 
      pos: [7, 0, 5], 
      state: 8
    }, 
    {
      pos: [0, 1, 0], 
      state: 10
    }, 
    {
      pos: [1, 1, 0], 
      state: 10
    }, 
    {
      pos: [2, 1, 0], 
      state: 10
    }, 
    {
      pos: [3, 1, 0], 
      state: 10
    }, 
    {
      pos: [4, 1, 0], 
      state: 10
    }, 
    {
      pos: [5, 1, 0], 
      state: 10
    }, 
    {
      pos: [6, 1, 0], 
      state: 10
    }, 
    {
      pos: [7, 1, 0], 
      state: 10
    }, 
    {
      pos: [8, 1, 0], 
      state: 10
    }, 
    {
      pos: [0, 2, 0], 
      state: 10
    }, 
    {
      pos: [1, 2, 0], 
      state: 10
    }, 
    {
      pos: [2, 2, 0], 
      state: 10
    }, 
    {
      pos: [3, 2, 0], 
      state: 10
    }, 
    {
      pos: [4, 2, 0], 
      state: 10
    }, 
    {
      pos: [5, 2, 0], 
      state: 10
    }, 
    {
      pos: [6, 2, 0], 
      state: 10
    }, 
    {
      pos: [7, 2, 0], 
      state: 10
    }, 
    {
      pos: [8, 2, 0], 
      state: 10
    }, 
    {
      pos: [0, 3, 0], 
      state: 10
    }, 
    {
      pos: [1, 3, 0], 
      state: 11
    }, 
    {
      pos: [2, 3, 0], 
      state: 12
    }, 
    {
      pos: [3, 3, 0], 
      state: 10
    }, 
    {
      pos: [4, 3, 0], 
      state: 10
    }, 
    {
      pos: [5, 3, 0], 
      state: 13
    }, 
    {
      pos: [6, 3, 0], 
      state: 14
    }, 
    {
      pos: [7, 3, 0], 
      state: 10
    }, 
    {
      pos: [8, 3, 0], 
      state: 10
    }, 
    {
      pos: [0, 4, 0], 
      state: 10
    }, 
    {
      pos: [1, 4, 0], 
      state: 10
    }, 
    {
      pos: [2, 4, 0], 
      state: 11
    }, 
    {
      pos: [5, 4, 0], 
      state: 14
    }, 
    {
      pos: [6, 4, 0], 
      state: 10
    }, 
    {
      pos: [7, 4, 0], 
      state: 10
    }, 
    {
      pos: [8, 4, 0], 
      state: 10
    }, 
    {
      pos: [0, 5, 0], 
      state: 10
    }, 
    {
      pos: [1, 5, 0], 
      state: 10
    }, 
    {
      pos: [2, 5, 0], 
      state: 10
    }, 
    {
      pos: [3, 5, 0], 
      state: 10
    }, 
    {
      pos: [4, 5, 0], 
      state: 10
    }, 
    {
      pos: [5, 5, 0], 
      state: 10
    }, 
    {
      pos: [6, 5, 0], 
      state: 10
    }, 
    {
      pos: [7, 5, 0], 
      state: 10
    }, 
    {
      pos: [8, 5, 0], 
      state: 10
    }, 
    {
      pos: [0, 1, 1], 
      state: 10
    }, 
    {
      pos: [1, 1, 1], 
      state: 10
    }, 
    {
      pos: [6, 1, 1], 
      state: 10
    }, 
    {
      pos: [7, 1, 1], 
      state: 10
    }, 
    {
      pos: [8, 1, 1], 
      state: 10
    }, 
    {
      pos: [0, 2, 1], 
      state: 10
    }, 
    {
      pos: [1, 2, 1], 
      state: 10
    }, 
    {
      pos: [6, 2, 1], 
      state: 10
    }, 
    {
      pos: [7, 2, 1], 
      state: 10
    }, 
    {
      pos: [8, 2, 1], 
      state: 10
    }, 
    {
      pos: [0, 3, 1], 
      state: 10
    }, 
    {
      pos: [1, 3, 1], 
      state: 11
    }, 
    {
      pos: [6, 3, 1], 
      state: 14
    }, 
    {
      pos: [7, 3, 1], 
      state: 10
    }, 
    {
      pos: [8, 3, 1], 
      state: 10
    }, 
    {
      pos: [0, 4, 1], 
      state: 10
    }, 
    {
      pos: [1, 4, 1], 
      state: 10
    }, 
    {
      pos: [2, 4, 1], 
      state: 11
    }, 
    {
      pos: [5, 4, 1], 
      state: 14
    }, 
    {
      pos: [6, 4, 1], 
      state: 10
    }, 
    {
      pos: [7, 4, 1], 
      state: 10
    }, 
    {
      pos: [8, 4, 1], 
      state: 10
    }, 
    {
      pos: [0, 5, 1], 
      state: 10
    }, 
    {
      pos: [1, 5, 1], 
      state: 10
    }, 
    {
      pos: [2, 5, 1], 
      state: 10
    }, 
    {
      pos: [3, 5, 1], 
      state: 10
    }, 
    {
      pos: [4, 5, 1], 
      state: 10
    }, 
    {
      pos: [5, 5, 1], 
      state: 10
    }, 
    {
      pos: [6, 5, 1], 
      state: 10
    }, 
    {
      pos: [7, 5, 1], 
      state: 10
    }, 
    {
      pos: [8, 5, 1], 
      state: 10
    }, 
    {
      pos: [0, 1, 2], 
      state: 10
    }, 
    {
      pos: [1, 1, 2], 
      state: 10
    }, 
    {
      pos: [6, 1, 2], 
      state: 10
    }, 
    {
      pos: [7, 1, 2], 
      state: 10
    }, 
    {
      pos: [8, 1, 2], 
      state: 10
    }, 
    {
      pos: [0, 2, 2], 
      state: 10
    }, 
    {
      pos: [1, 2, 2], 
      state: 10
    }, 
    {
      pos: [3, 2, 2], 
      state: 10
    }, 
    {
      pos: [4, 2, 2], 
      state: 10
    }, 
    {
      pos: [6, 2, 2], 
      state: 10
    }, 
    {
      pos: [7, 2, 2], 
      state: 10
    }, 
    {
      pos: [8, 2, 2], 
      state: 10
    }, 
    {
      pos: [0, 3, 2], 
      state: 10
    }, 
    {
      pos: [1, 3, 2], 
      state: 11
    }, 
    {
      pos: [3, 3, 2], 
      state: 15
    }, 
    {
      pos: [4, 3, 2], 
      state: 15
    }, 
    {
      pos: [6, 3, 2], 
      state: 14
    }, 
    {
      pos: [7, 3, 2], 
      state: 10
    }, 
    {
      pos: [8, 3, 2], 
      state: 10
    }, 
    {
      pos: [0, 4, 2], 
      state: 10
    }, 
    {
      pos: [1, 4, 2], 
      state: 10
    }, 
    {
      pos: [2, 4, 2], 
      state: 11
    }, 
    {
      pos: [5, 4, 2], 
      state: 14
    }, 
    {
      pos: [6, 4, 2], 
      state: 10
    }, 
    {
      pos: [7, 4, 2], 
      state: 10
    }, 
    {
      pos: [8, 4, 2], 
      state: 10
    }, 
    {
      pos: [0, 5, 2], 
      state: 10
    }, 
    {
      pos: [1, 5, 2], 
      state: 10
    }, 
    {
      pos: [2, 5, 2], 
      state: 10
    }, 
    {
      pos: [3, 5, 2], 
      state: 10
    }, 
    {
      pos: [4, 5, 2], 
      state: 10
    }, 
    {
      pos: [5, 5, 2], 
      state: 10
    }, 
    {
      pos: [6, 5, 2], 
      state: 10
    }, 
    {
      pos: [7, 5, 2], 
      state: 10
    }, 
    {
      pos: [8, 5, 2], 
      state: 10
    }, 
    {
      pos: [0, 1, 3], 
      state: 10
    }, 
    {
      pos: [1, 1, 3], 
      state: 10
    }, 
    {
      pos: [3, 1, 3], 
      state: 10
    }, 
    {
      pos: [4, 1, 3], 
      state: 10
    }, 
    {
      pos: [6, 1, 3], 
      state: 16
    }, 
    {
      pos: [7, 1, 3], 
      state: 16
    }, 
    {
      pos: [8, 1, 3], 
      state: 17
    }, 
    {
      pos: [0, 2, 3], 
      state: 10
    }, 
    {
      pos: [1, 2, 3], 
      state: 10
    }, 
    {
      pos: [2, 2, 3], 
      state: 18
    }, 
    {
      pos: [3, 2, 3], 
      state: 10
    }, 
    {
      pos: [4, 2, 3], 
      state: 10
    }, 
    {
      pos: [5, 2, 3], 
      state: 18
    }, 
    {
      pos: [6, 2, 3], 
      state: 10
    }, 
    {
      pos: [7, 2, 3], 
      state: 10
    }, 
    {
      pos: [8, 2, 3], 
      state: 10
    }, 
    {
      pos: [0, 3, 3], 
      state: 10
    }, 
    {
      pos: [1, 3, 3], 
      state: 11
    }, 
    {
      pos: [3, 3, 3], 
      state: 10
    }, 
    {
      pos: [4, 3, 3], 
      state: 10
    }, 
    {
      pos: [6, 3, 3], 
      state: 14
    }, 
    {
      pos: [7, 3, 3], 
      state: 10
    }, 
    {
      pos: [8, 3, 3], 
      state: 10
    }, 
    {
      pos: [0, 4, 3], 
      state: 10
    }, 
    {
      pos: [1, 4, 3], 
      state: 10
    }, 
    {
      pos: [2, 4, 3], 
      state: 11
    }, 
    {
      pos: [5, 4, 3], 
      state: 14
    }, 
    {
      pos: [6, 4, 3], 
      state: 10
    }, 
    {
      pos: [7, 4, 3], 
      state: 10
    }, 
    {
      pos: [8, 4, 3], 
      state: 10
    }, 
    {
      pos: [0, 5, 3], 
      state: 10
    }, 
    {
      pos: [1, 5, 3], 
      state: 10
    }, 
    {
      pos: [2, 5, 3], 
      state: 10
    }, 
    {
      pos: [3, 5, 3], 
      state: 10
    }, 
    {
      pos: [4, 5, 3], 
      state: 10
    }, 
    {
      pos: [5, 5, 3], 
      state: 10
    }, 
    {
      pos: [6, 5, 3], 
      state: 10
    }, 
    {
      pos: [7, 5, 3], 
      state: 10
    }, 
    {
      pos: [8, 5, 3], 
      state: 10
    }, 
    {
      pos: [1, 1, 4], 
      state: 10
    }, 
    {
      pos: [3, 1, 4], 
      state: 10
    }, 
    {
      pos: [4, 1, 4], 
      state: 10
    }, 
    {
      pos: [6, 1, 4], 
      state: 10
    }, 
    {
      pos: [7, 1, 4], 
      state: 10
    }, 
    {
      pos: [8, 1, 4], 
      state: 19
    }, 
    {
      pos: [0, 2, 4], 
      state: 10
    }, 
    {
      pos: [1, 2, 4], 
      state: 10
    }, 
    {
      pos: [3, 2, 4], 
      state: 10
    }, 
    {
      pos: [4, 2, 4], 
      state: 10
    }, 
    {
      pos: [6, 2, 4], 
      state: 10
    }, 
    {
      pos: [7, 2, 4], 
      state: 10
    }, 
    {
      pos: [8, 2, 4], 
      state: 10
    }, 
    {
      pos: [0, 3, 4], 
      state: 10
    }, 
    {
      pos: [1, 3, 4], 
      state: 20
    }, 
    {
      pos: [3, 3, 4], 
      state: 10
    }, 
    {
      pos: [4, 3, 4], 
      state: 10
    }, 
    {
      pos: [6, 3, 4], 
      state: 21
    }, 
    {
      pos: [7, 3, 4], 
      state: 10
    }, 
    {
      pos: [8, 3, 4], 
      state: 10
    }, 
    {
      pos: [0, 4, 4], 
      state: 10
    }, 
    {
      pos: [1, 4, 4], 
      state: 10
    }, 
    {
      pos: [2, 4, 4], 
      state: 22
    }, 
    {
      pos: [5, 4, 4], 
      state: 23
    }, 
    {
      pos: [6, 4, 4], 
      state: 24
    }, 
    {
      pos: [7, 4, 4], 
      state: 10
    }, 
    {
      pos: [8, 4, 4], 
      state: 10
    }, 
    {
      pos: [0, 5, 4], 
      state: 10
    }, 
    {
      pos: [1, 5, 4], 
      state: 10
    }, 
    {
      pos: [2, 5, 4], 
      state: 10
    }, 
    {
      pos: [3, 5, 4], 
      state: 10
    }, 
    {
      pos: [4, 5, 4], 
      state: 10
    }, 
    {
      pos: [5, 5, 4], 
      state: 10
    }, 
    {
      pos: [6, 5, 4], 
      state: 10
    }, 
    {
      pos: [7, 5, 4], 
      state: 10
    }, 
    {
      pos: [8, 5, 4], 
      state: 10
    }, 
    {
      pos: [0, 1, 5], 
      state: 25
    }, 
    {
      pos: [1, 1, 5], 
      state: 10
    }, 
    {
      pos: [3, 1, 5], 
      state: 10
    }, 
    {
      pos: [4, 1, 5], 
      state: 10
    }, 
    {
      pos: [6, 1, 5], 
      state: 10
    }, 
    {
      pos: [7, 1, 5], 
      state: 10
    }, 
    {
      pos: [8, 1, 5], 
      state: 19
    }, 
    {
      pos: [0, 2, 5], 
      state: 26
    }, 
    {
      pos: [1, 2, 5], 
      state: 27
    }, 
    {
      pos: [3, 2, 5], 
      state: 10
    }, 
    {
      pos: [4, 2, 5], 
      state: 10
    }, 
    {
      pos: [6, 2, 5], 
      state: 10
    }, 
    {
      pos: [7, 2, 5], 
      state: 10
    }, 
    {
      pos: [8, 2, 5], 
      state: 10
    }, 
    {
      pos: [0, 3, 5], 
      state: 26
    }, 
    {
      pos: [1, 3, 5], 
      state: 10
    }, 
    {
      pos: [3, 3, 5], 
      state: 10
    }, 
    {
      pos: [4, 3, 5], 
      state: 10
    }, 
    {
      pos: [6, 3, 5], 
      state: 10
    }, 
    {
      pos: [7, 3, 5], 
      state: 10
    }, 
    {
      pos: [8, 3, 5], 
      state: 10
    }, 
    {
      pos: [0, 4, 5], 
      state: 28
    }, 
    {
      pos: [1, 4, 5], 
      state: 28
    }, 
    {
      pos: [3, 4, 5], 
      state: 10
    }, 
    {
      pos: [4, 4, 5], 
      state: 10
    }, 
    {
      pos: [6, 4, 5], 
      state: 21
    }, 
    {
      pos: [7, 4, 5], 
      state: 10
    }, 
    {
      pos: [8, 4, 5], 
      state: 10
    }, 
    {
      pos: [0, 5, 5], 
      state: 10
    }, 
    {
      pos: [1, 5, 5], 
      state: 10
    }, 
    {
      pos: [2, 5, 5], 
      state: 24
    }, 
    {
      pos: [3, 5, 5], 
      state: 24
    }, 
    {
      pos: [4, 5, 5], 
      state: 24
    }, 
    {
      pos: [5, 5, 5], 
      state: 24
    }, 
    {
      pos: [6, 5, 5], 
      state: 24
    }, 
    {
      pos: [7, 5, 5], 
      state: 10
    }, 
    {
      pos: [8, 5, 5], 
      state: 10
    }, 
    {
      pos: [0, 0, 6], 
      state: 29
    }, 
    {
      pos: [1, 0, 6], 
      state: 29
    }, 
    {
      pos: [0, 1, 6], 
      state: 10
    }, 
    {
      pos: [1, 1, 6], 
      state: 10
    }, 
    {
      pos: [2, 1, 6], 
      state: 30
    }, 
    {
      pos: [3, 1, 6], 
      state: 10
    }, 
    {
      pos: [4, 1, 6], 
      state: 10
    }, 
    {
      pos: [5, 1, 6], 
      state: 31
    }, 
    {
      pos: [6, 1, 6], 
      state: 10
    }, 
    {
      pos: [7, 1, 6], 
      state: 10
    }, 
    {
      pos: [8, 1, 6], 
      state: 19
    }, 
    {
      pos: [0, 2, 6], 
      state: 10
    }, 
    {
      pos: [1, 2, 6], 
      state: 10
    }, 
    {
      pos: [2, 2, 6], 
      state: 32
    }, 
    {
      pos: [3, 2, 6], 
      state: 10
    }, 
    {
      pos: [4, 2, 6], 
      state: 10
    }, 
    {
      pos: [5, 2, 6], 
      state: 33
    }, 
    {
      pos: [6, 2, 6], 
      state: 10
    }, 
    {
      pos: [7, 2, 6], 
      state: 10
    }, 
    {
      pos: [8, 2, 6], 
      state: 10
    }, 
    {
      pos: [0, 3, 6], 
      state: 10
    }, 
    {
      pos: [1, 3, 6], 
      state: 10
    }, 
    {
      pos: [3, 3, 6], 
      state: 10
    }, 
    {
      pos: [4, 3, 6], 
      state: 10
    }, 
    {
      pos: [6, 3, 6], 
      state: 34
    }, 
    {
      pos: [7, 3, 6], 
      state: 10
    }, 
    {
      pos: [8, 3, 6], 
      state: 10
    }, 
    {
      pos: [3, 4, 6], 
      state: 10
    }, 
    {
      pos: [4, 4, 6], 
      state: 10
    }, 
    {
      pos: [6, 4, 6], 
      state: 10
    }, 
    {
      pos: [7, 4, 6], 
      state: 10
    }, 
    {
      pos: [8, 4, 6], 
      state: 10
    }, 
    {
      pos: [0, 5, 6], 
      state: 10
    }, 
    {
      pos: [1, 5, 6], 
      state: 10
    }, 
    {
      pos: [7, 5, 6], 
      state: 10
    }, 
    {
      pos: [8, 5, 6], 
      state: 10
    }, 
    {
      pos: [0, 1, 7], 
      state: 26
    }, 
    {
      pos: [1, 1, 7], 
      state: 10
    }, 
    {
      pos: [3, 1, 7], 
      state: 10
    }, 
    {
      pos: [4, 1, 7], 
      state: 10
    }, 
    {
      pos: [6, 1, 7], 
      state: 10
    }, 
    {
      pos: [7, 1, 7], 
      state: 10
    }, 
    {
      pos: [8, 1, 7], 
      state: 19
    }, 
    {
      pos: [0, 2, 7], 
      state: 26
    }, 
    {
      pos: [1, 2, 7], 
      state: 27
    }, 
    {
      pos: [3, 2, 7], 
      state: 10
    }, 
    {
      pos: [4, 2, 7], 
      state: 10
    }, 
    {
      pos: [6, 2, 7], 
      state: 10
    }, 
    {
      pos: [7, 2, 7], 
      state: 10
    }, 
    {
      pos: [8, 2, 7], 
      state: 10
    }, 
    {
      pos: [0, 3, 7], 
      state: 26
    }, 
    {
      pos: [1, 3, 7], 
      state: 10
    }, 
    {
      pos: [3, 3, 7], 
      state: 10
    }, 
    {
      pos: [4, 3, 7], 
      state: 10
    }, 
    {
      pos: [6, 3, 7], 
      state: 10
    }, 
    {
      pos: [7, 3, 7], 
      state: 10
    }, 
    {
      pos: [8, 3, 7], 
      state: 10
    }, 
    {
      pos: [0, 4, 7], 
      state: 28
    }, 
    {
      pos: [1, 4, 7], 
      state: 28
    }, 
    {
      pos: [3, 4, 7], 
      state: 10
    }, 
    {
      pos: [4, 4, 7], 
      state: 10
    }, 
    {
      pos: [6, 4, 7], 
      state: 35
    }, 
    {
      pos: [7, 4, 7], 
      state: 10
    }, 
    {
      pos: [8, 4, 7], 
      state: 10
    }, 
    {
      pos: [0, 5, 7], 
      state: 10
    }, 
    {
      pos: [1, 5, 7], 
      state: 10
    }, 
    {
      pos: [2, 5, 7], 
      state: 36
    }, 
    {
      pos: [3, 5, 7], 
      state: 36
    }, 
    {
      pos: [4, 5, 7], 
      state: 36
    }, 
    {
      pos: [5, 5, 7], 
      state: 36
    }, 
    {
      pos: [6, 5, 7], 
      state: 36
    }, 
    {
      pos: [7, 5, 7], 
      state: 10
    }, 
    {
      pos: [8, 5, 7], 
      state: 10
    }, 
    {
      pos: [0, 1, 8], 
      state: 10
    }, 
    {
      pos: [1, 1, 8], 
      state: 10
    }, 
    {
      pos: [3, 1, 8], 
      state: 10
    }, 
    {
      pos: [4, 1, 8], 
      state: 10
    }, 
    {
      pos: [6, 1, 8], 
      state: 10
    }, 
    {
      pos: [7, 1, 8], 
      state: 10
    }, 
    {
      pos: [8, 1, 8], 
      state: 19
    }, 
    {
      pos: [0, 2, 8], 
      state: 10
    }, 
    {
      pos: [1, 2, 8], 
      state: 10
    }, 
    {
      pos: [3, 2, 8], 
      state: 10
    }, 
    {
      pos: [4, 2, 8], 
      state: 10
    }, 
    {
      pos: [6, 2, 8], 
      state: 10
    }, 
    {
      pos: [7, 2, 8], 
      state: 10
    }, 
    {
      pos: [8, 2, 8], 
      state: 10
    }, 
    {
      pos: [0, 3, 8], 
      state: 10
    }, 
    {
      pos: [1, 3, 8], 
      state: 37
    }, 
    {
      pos: [3, 3, 8], 
      state: 10
    }, 
    {
      pos: [4, 3, 8], 
      state: 10
    }, 
    {
      pos: [6, 3, 8], 
      state: 35
    }, 
    {
      pos: [7, 3, 8], 
      state: 10
    }, 
    {
      pos: [8, 3, 8], 
      state: 10
    }, 
    {
      pos: [0, 4, 8], 
      state: 10
    }, 
    {
      pos: [1, 4, 8], 
      state: 10
    }, 
    {
      pos: [2, 4, 8], 
      state: 38
    }, 
    {
      pos: [5, 4, 8], 
      state: 39
    }, 
    {
      pos: [6, 4, 8], 
      state: 36
    }, 
    {
      pos: [7, 4, 8], 
      state: 10
    }, 
    {
      pos: [8, 4, 8], 
      state: 10
    }, 
    {
      pos: [0, 5, 8], 
      state: 10
    }, 
    {
      pos: [1, 5, 8], 
      state: 10
    }, 
    {
      pos: [2, 5, 8], 
      state: 10
    }, 
    {
      pos: [3, 5, 8], 
      state: 10
    }, 
    {
      pos: [4, 5, 8], 
      state: 10
    }, 
    {
      pos: [5, 5, 8], 
      state: 10
    }, 
    {
      pos: [6, 5, 8], 
      state: 10
    }, 
    {
      pos: [7, 5, 8], 
      state: 10
    }, 
    {
      pos: [8, 5, 8], 
      state: 10
    }, 
    {
      pos: [0, 1, 9], 
      state: 10
    }, 
    {
      pos: [1, 1, 9], 
      state: 10
    }, 
    {
      pos: [3, 1, 9], 
      state: 10
    }, 
    {
      pos: [4, 1, 9], 
      state: 10
    }, 
    {
      pos: [6, 1, 9], 
      state: 16
    }, 
    {
      pos: [7, 1, 9], 
      state: 16
    }, 
    {
      pos: [8, 1, 9], 
      state: 40
    }, 
    {
      pos: [0, 2, 9], 
      state: 10
    }, 
    {
      pos: [1, 2, 9], 
      state: 10
    }, 
    {
      pos: [2, 2, 9], 
      state: 18
    }, 
    {
      pos: [3, 2, 9], 
      state: 10
    }, 
    {
      pos: [4, 2, 9], 
      state: 10
    }, 
    {
      pos: [5, 2, 9], 
      state: 18
    }, 
    {
      pos: [6, 2, 9], 
      state: 10
    }, 
    {
      pos: [7, 2, 9], 
      state: 10
    }, 
    {
      pos: [8, 2, 9], 
      state: 10
    }, 
    {
      pos: [0, 3, 9], 
      state: 10
    }, 
    {
      pos: [1, 3, 9], 
      state: 11
    }, 
    {
      pos: [3, 3, 9], 
      state: 10
    }, 
    {
      pos: [4, 3, 9], 
      state: 10
    }, 
    {
      pos: [6, 3, 9], 
      state: 14
    }, 
    {
      pos: [7, 3, 9], 
      state: 10
    }, 
    {
      pos: [8, 3, 9], 
      state: 10
    }, 
    {
      pos: [0, 4, 9], 
      state: 10
    }, 
    {
      pos: [1, 4, 9], 
      state: 10
    }, 
    {
      pos: [2, 4, 9], 
      state: 11
    }, 
    {
      pos: [5, 4, 9], 
      state: 14
    }, 
    {
      pos: [6, 4, 9], 
      state: 10
    }, 
    {
      pos: [7, 4, 9], 
      state: 10
    }, 
    {
      pos: [8, 4, 9], 
      state: 10
    }, 
    {
      pos: [0, 5, 9], 
      state: 10
    }, 
    {
      pos: [1, 5, 9], 
      state: 10
    }, 
    {
      pos: [2, 5, 9], 
      state: 10
    }, 
    {
      pos: [3, 5, 9], 
      state: 10
    }, 
    {
      pos: [4, 5, 9], 
      state: 10
    }, 
    {
      pos: [5, 5, 9], 
      state: 10
    }, 
    {
      pos: [6, 5, 9], 
      state: 10
    }, 
    {
      pos: [7, 5, 9], 
      state: 10
    }, 
    {
      pos: [8, 5, 9], 
      state: 10
    }, 
    {
      pos: [0, 1, 10], 
      state: 10
    }, 
    {
      pos: [1, 1, 10], 
      state: 10
    }, 
    {
      pos: [3, 1, 10], 
      state: 24
    }, 
    {
      pos: [4, 1, 10], 
      state: 24
    }, 
    {
      pos: [6, 1, 10], 
      state: 10
    }, 
    {
      pos: [7, 1, 10], 
      state: 10
    }, 
    {
      pos: [8, 1, 10], 
      state: 10
    }, 
    {
      pos: [0, 2, 10], 
      state: 10
    }, 
    {
      pos: [1, 2, 10], 
      state: 10
    }, 
    {
      pos: [3, 2, 10], 
      state: 10
    }, 
    {
      pos: [4, 2, 10], 
      state: 10
    }, 
    {
      pos: [6, 2, 10], 
      state: 10
    }, 
    {
      pos: [7, 2, 10], 
      state: 10
    }, 
    {
      pos: [8, 2, 10], 
      state: 10
    }, 
    {
      pos: [0, 3, 10], 
      state: 10
    }, 
    {
      pos: [1, 3, 10], 
      state: 11
    }, 
    {
      pos: [3, 3, 10], 
      state: 41
    }, 
    {
      pos: [4, 3, 10], 
      state: 41
    }, 
    {
      pos: [6, 3, 10], 
      state: 14
    }, 
    {
      pos: [7, 3, 10], 
      state: 10
    }, 
    {
      pos: [8, 3, 10], 
      state: 10
    }, 
    {
      pos: [0, 4, 10], 
      state: 10
    }, 
    {
      pos: [1, 4, 10], 
      state: 10
    }, 
    {
      pos: [2, 4, 10], 
      state: 11
    }, 
    {
      pos: [5, 4, 10], 
      state: 14
    }, 
    {
      pos: [6, 4, 10], 
      state: 10
    }, 
    {
      pos: [7, 4, 10], 
      state: 10
    }, 
    {
      pos: [8, 4, 10], 
      state: 10
    }, 
    {
      pos: [0, 5, 10], 
      state: 10
    }, 
    {
      pos: [1, 5, 10], 
      state: 10
    }, 
    {
      pos: [2, 5, 10], 
      state: 10
    }, 
    {
      pos: [3, 5, 10], 
      state: 10
    }, 
    {
      pos: [4, 5, 10], 
      state: 10
    }, 
    {
      pos: [5, 5, 10], 
      state: 10
    }, 
    {
      pos: [6, 5, 10], 
      state: 10
    }, 
    {
      pos: [7, 5, 10], 
      state: 10
    }, 
    {
      pos: [8, 5, 10], 
      state: 10
    }, 
    {
      pos: [0, 1, 11], 
      state: 10
    }, 
    {
      pos: [1, 1, 11], 
      state: 10
    }, 
    {
      pos: [6, 1, 11], 
      state: 10
    }, 
    {
      pos: [7, 1, 11], 
      state: 10
    }, 
    {
      pos: [8, 1, 11], 
      state: 10
    }, 
    {
      pos: [0, 2, 11], 
      state: 10
    }, 
    {
      pos: [1, 2, 11], 
      state: 10
    }, 
    {
      pos: [6, 2, 11], 
      state: 10
    }, 
    {
      pos: [7, 2, 11], 
      state: 10
    }, 
    {
      pos: [8, 2, 11], 
      state: 10
    }, 
    {
      pos: [0, 3, 11], 
      state: 10
    }, 
    {
      pos: [1, 3, 11], 
      state: 11
    }, 
    {
      pos: [6, 3, 11], 
      state: 14
    }, 
    {
      pos: [7, 3, 11], 
      state: 10
    }, 
    {
      pos: [8, 3, 11], 
      state: 10
    }, 
    {
      pos: [0, 4, 11], 
      state: 10
    }, 
    {
      pos: [1, 4, 11], 
      state: 10
    }, 
    {
      pos: [2, 4, 11], 
      state: 11
    }, 
    {
      pos: [5, 4, 11], 
      state: 14
    }, 
    {
      pos: [6, 4, 11], 
      state: 10
    }, 
    {
      pos: [7, 4, 11], 
      state: 10
    }, 
    {
      pos: [8, 4, 11], 
      state: 10
    }, 
    {
      pos: [0, 5, 11], 
      state: 10
    }, 
    {
      pos: [1, 5, 11], 
      state: 10
    }, 
    {
      pos: [2, 5, 11], 
      state: 10
    }, 
    {
      pos: [3, 5, 11], 
      state: 10
    }, 
    {
      pos: [4, 5, 11], 
      state: 10
    }, 
    {
      pos: [5, 5, 11], 
      state: 10
    }, 
    {
      pos: [6, 5, 11], 
      state: 10
    }, 
    {
      pos: [7, 5, 11], 
      state: 10
    }, 
    {
      pos: [8, 5, 11], 
      state: 10
    }, 
    {
      pos: [0, 1, 12], 
      state: 10
    }, 
    {
      pos: [1, 1, 12], 
      state: 10
    }, 
    {
      pos: [2, 1, 12], 
      state: 10
    }, 
    {
      pos: [4, 1, 12], 
      state: 10
    }, 
    {
      pos: [5, 1, 12], 
      state: 10
    }, 
    {
      pos: [6, 1, 12], 
      state: 10
    }, 
    {
      pos: [7, 1, 12], 
      state: 10
    }, 
    {
      pos: [8, 1, 12], 
      state: 10
    }, 
    {
      pos: [0, 2, 12], 
      state: 10
    }, 
    {
      pos: [1, 2, 12], 
      state: 10
    }, 
    {
      pos: [2, 2, 12], 
      state: 10
    }, 
    {
      pos: [3, 2, 12], 
      state: 10
    }, 
    {
      pos: [4, 2, 12], 
      state: 10
    }, 
    {
      pos: [5, 2, 12], 
      state: 10
    }, 
    {
      pos: [6, 2, 12], 
      state: 10
    }, 
    {
      pos: [7, 2, 12], 
      state: 10
    }, 
    {
      pos: [8, 2, 12], 
      state: 10
    }, 
    {
      pos: [0, 3, 12], 
      state: 10
    }, 
    {
      pos: [1, 3, 12], 
      state: 11
    }, 
    {
      pos: [2, 3, 12], 
      state: 12
    }, 
    {
      pos: [3, 3, 12], 
      state: 10
    }, 
    {
      pos: [4, 3, 12], 
      state: 10
    }, 
    {
      pos: [5, 3, 12], 
      state: 13
    }, 
    {
      pos: [6, 3, 12], 
      state: 14
    }, 
    {
      pos: [7, 3, 12], 
      state: 10
    }, 
    {
      pos: [8, 3, 12], 
      state: 10
    }, 
    {
      pos: [0, 4, 12], 
      state: 10
    }, 
    {
      pos: [1, 4, 12], 
      state: 10
    }, 
    {
      pos: [2, 4, 12], 
      state: 11
    }, 
    {
      pos: [5, 4, 12], 
      state: 14
    }, 
    {
      pos: [6, 4, 12], 
      state: 10
    }, 
    {
      pos: [7, 4, 12], 
      state: 10
    }, 
    {
      pos: [8, 4, 12], 
      state: 10
    }, 
    {
      pos: [0, 5, 12], 
      state: 10
    }, 
    {
      pos: [1, 5, 12], 
      state: 10
    }, 
    {
      pos: [2, 5, 12], 
      state: 10
    }, 
    {
      pos: [3, 5, 12], 
      state: 10
    }, 
    {
      pos: [4, 5, 12], 
      state: 10
    }, 
    {
      pos: [5, 5, 12], 
      state: 10
    }, 
    {
      pos: [6, 5, 12], 
      state: 10
    }, 
    {
      pos: [7, 5, 12], 
      state: 10
    }, 
    {
      pos: [8, 5, 12], 
      state: 10
    }
  ], 
  palette: [
    {
      Name: "minecraft:oak_planks"
    }, 
    {
      Name: "minecraft:dirt"
    }, 
    {
      Properties: {
        axis: "y"
      }, 
      Name: "minecraft:oak_log"
    }, 
    {
      Properties: {
        facing: "south"
      }, 
      Name: "minecraft:loom"
    }, 
    {
      Properties: {
        axis: "z"
      }, 
      Name: "minecraft:oak_log"
    }, 
    {
      Name: "minecraft:yellow_wool"
    }, 
    {
      Name: "minecraft:white_wool"
    }, 
    {
      Properties: {
        snowy: "false"
      }, 
      Name: "minecraft:grass_block"
    }, 
    {
      Properties: {
        facing: "up"
      }, 
      Name: "minecraft:jigsaw"
    }, 
    {
      Properties: {
        facing: "west"
      }, 
      Name: "minecraft:jigsaw"
    }, 
    {
      Name: "minecraft:air"
    }, 
    {
      Properties: {
        half: "bottom", 
        waterlogged: "false", 
        shape: "straight", 
        facing: "east"
      }, 
      Name: "minecraft:oak_stairs"
    }, 
    {
      Properties: {
        half: "top", 
        waterlogged: "false", 
        shape: "straight", 
        facing: "west"
      }, 
      Name: "minecraft:oak_stairs"
    }, 
    {
      Properties: {
        half: "top", 
        waterlogged: "false", 
        shape: "straight", 
        facing: "east"
      }, 
      Name: "minecraft:oak_stairs"
    }, 
    {
      Properties: {
        half: "bottom", 
        waterlogged: "false", 
        shape: "straight", 
        facing: "west"
      }, 
      Name: "minecraft:oak_stairs"
    }, 
    {
      Properties: {
        facing: "south"
      }, 
      Name: "minecraft:wall_torch"
    }, 
    {
      Properties: {
        east: "true", 
        waterlogged: "false", 
        south: "false", 
        north: "false", 
        west: "true"
      }, 
      Name: "minecraft:oak_fence"
    }, 
    {
      Properties: {
        east: "false", 
        waterlogged: "false", 
        south: "true", 
        north: "false", 
        west: "true"
      }, 
      Name: "minecraft:oak_fence"
    }, 
    {
      Properties: {
        east: "false", 
        waterlogged: "false", 
        south: "true", 
        north: "true", 
        west: "false"
      }, 
      Name: "minecraft:glass_pane"
    }, 
    {
      Properties: {
        east: "false", 
        waterlogged: "false", 
        south: "true", 
        north: "true", 
        west: "false"
      }, 
      Name: "minecraft:oak_fence"
    }, 
    {
      Properties: {
        half: "bottom", 
        waterlogged: "false", 
        shape: "outer_right", 
        facing: "north"
      }, 
      Name: "minecraft:oak_stairs"
    }, 
    {
      Properties: {
        half: "top", 
        waterlogged: "false", 
        shape: "straight", 
        facing: "north"
      }, 
      Name: "minecraft:oak_stairs"
    }, 
    {
      Properties: {
        half: "bottom", 
        waterlogged: "false", 
        shape: "inner_left", 
        facing: "south"
      }, 
      Name: "minecraft:oak_stairs"
    }, 
    {
      Properties: {
        half: "bottom", 
        waterlogged: "false", 
        shape: "inner_left", 
        facing: "west"
      }, 
      Name: "minecraft:oak_stairs"
    }, 
    {
      Properties: {
        half: "bottom", 
        waterlogged: "false", 
        shape: "straight", 
        facing: "south"
      }, 
      Name: "minecraft:oak_stairs"
    }, 
    {
      Properties: {
        east: "false", 
        waterlogged: "false", 
        south: "false", 
        north: "true", 
        west: "false"
      }, 
      Name: "minecraft:oak_fence"
    }, 
    {
      Properties: {
        east: "false", 
        waterlogged: "false", 
        south: "false", 
        north: "false", 
        west: "false"
      }, 
      Name: "minecraft:oak_fence"
    }, 
    {
      Properties: {
        facing: "west"
      }, 
      Name: "minecraft:wall_torch"
    }, 
    {
      Properties: {
        waterlogged: "false", 
        type: "bottom"
      }, 
      Name: "minecraft:oak_slab"
    }, 
    {
      Name: "minecraft:grass_path"
    }, 
    {
      Properties: {
        hinge: "right", 
        half: "lower", 
        powered: "false", 
        facing: "east", 
        open: "false"
      }, 
      Name: "minecraft:oak_door"
    }, 
    {
      Properties: {
        hinge: "left", 
        half: "lower", 
        powered: "false", 
        facing: "west", 
        open: "false"
      }, 
      Name: "minecraft:oak_door"
    }, 
    {
      Properties: {
        hinge: "right", 
        half: "upper", 
        powered: "false", 
        facing: "east", 
        open: "false"
      }, 
      Name: "minecraft:oak_door"
    }, 
    {
      Properties: {
        hinge: "left", 
        half: "upper", 
        powered: "false", 
        facing: "west", 
        open: "false"
      }, 
      Name: "minecraft:oak_door"
    }, 
    {
      Properties: {
        facing: "east"
      }, 
      Name: "minecraft:wall_torch"
    }, 
    {
      Properties: {
        half: "top", 
        waterlogged: "false", 
        shape: "straight", 
        facing: "south"
      }, 
      Name: "minecraft:oak_stairs"
    }, 
    {
      Properties: {
        half: "bottom", 
        waterlogged: "false", 
        shape: "straight", 
        facing: "north"
      }, 
      Name: "minecraft:oak_stairs"
    }, 
    {
      Properties: {
        half: "bottom", 
        waterlogged: "false", 
        shape: "outer_left", 
        facing: "south"
      }, 
      Name: "minecraft:oak_stairs"
    }, 
    {
      Properties: {
        half: "bottom", 
        waterlogged: "false", 
        shape: "inner_right", 
        facing: "north"
      }, 
      Name: "minecraft:oak_stairs"
    }, 
    {
      Properties: {
        half: "bottom", 
        waterlogged: "false", 
        shape: "inner_right", 
        facing: "west"
      }, 
      Name: "minecraft:oak_stairs"
    }, 
    {
      Properties: {
        east: "false", 
        waterlogged: "false", 
        south: "false", 
        north: "true", 
        west: "true"
      }, 
      Name: "minecraft:oak_fence"
    }, 
    {
      Properties: {
        facing: "north"
      }, 
      Name: "minecraft:wall_torch"
    }
  ]
}
