{
  size: [7, 6, 13], 
  entities: [], 
  blocks: [
    {
      pos: [1, 0, 1], 
      state: 0
    }, 
    {
      pos: [2, 0, 1], 
      state: 1
    }, 
    {
      pos: [3, 0, 1], 
      state: 1
    }, 
    {
      pos: [4, 0, 1], 
      state: 1
    }, 
    {
      pos: [5, 0, 1], 
      state: 0
    }, 
    {
      pos: [1, 1, 1], 
      state: 0
    }, 
    {
      pos: [2, 1, 1], 
      state: 1
    }, 
    {
      pos: [3, 1, 1], 
      state: 1
    }, 
    {
      pos: [4, 1, 1], 
      state: 1
    }, 
    {
      pos: [5, 1, 1], 
      state: 0
    }, 
    {
      pos: [1, 2, 1], 
      state: 0
    }, 
    {
      pos: [2, 2, 1], 
      state: 1
    }, 
    {
      pos: [4, 2, 1], 
      state: 1
    }, 
    {
      pos: [5, 2, 1], 
      state: 0
    }, 
    {
      pos: [1, 3, 1], 
      state: 0
    }, 
    {
      pos: [2, 3, 1], 
      state: 1
    }, 
    {
      pos: [3, 3, 1], 
      state: 1
    }, 
    {
      pos: [4, 3, 1], 
      state: 1
    }, 
    {
      pos: [5, 3, 1], 
      state: 0
    }, 
    {
      pos: [1, 0, 2], 
      state: 1
    }, 
    {
      pos: [2, 0, 2], 
      state: 2
    }, 
    {
      pos: [3, 0, 2], 
      state: 2
    }, 
    {
      pos: [4, 0, 2], 
      state: 2
    }, 
    {
      pos: [5, 0, 2], 
      state: 1
    }, 
    {
      pos: [1, 1, 2], 
      state: 1
    }, 
    {
      pos: [5, 1, 2], 
      state: 1
    }, 
    {
      pos: [1, 2, 2], 
      state: 1
    }, 
    {
      pos: [5, 2, 2], 
      state: 1
    }, 
    {
      pos: [1, 3, 2], 
      state: 1
    }, 
    {
      pos: [5, 3, 2], 
      state: 1
    }, 
    {
      pos: [1, 4, 2], 
      state: 3
    }, 
    {
      pos: [5, 4, 2], 
      state: 3
    }, 
    {
      pos: [1, 0, 3], 
      state: 1
    }, 
    {
      pos: [2, 0, 3], 
      state: 2
    }, 
    {
      pos: [3, 0, 3], 
      state: 1
    }, 
    {
      pos: [4, 0, 3], 
      state: 2
    }, 
    {
      pos: [5, 0, 3], 
      state: 1
    }, 
    {
      pos: [1, 1, 3], 
      state: 1
    }, 
    {
      pos: [5, 1, 3], 
      state: 1
    }, 
    {
      pos: [1, 3, 3], 
      state: 1
    }, 
    {
      pos: [5, 3, 3], 
      state: 1
    }, 
    {
      pos: [1, 4, 3], 
      state: 3
    }, 
    {
      pos: [5, 4, 3], 
      state: 3
    }, 
    {
      pos: [0, 5, 3], 
      state: 2
    }, 
    {
      pos: [1, 5, 3], 
      state: 2
    }, 
    {
      pos: [2, 5, 3], 
      state: 2
    }, 
    {
      pos: [3, 5, 3], 
      state: 2
    }, 
    {
      pos: [4, 5, 3], 
      state: 2
    }, 
    {
      pos: [5, 5, 3], 
      state: 2
    }, 
    {
      pos: [6, 5, 3], 
      state: 2
    }, 
    {
      pos: [1, 0, 4], 
      state: 1
    }, 
    {
      pos: [2, 0, 4], 
      state: 2
    }, 
    {
      pos: [4, 0, 4], 
      state: 2
    }, 
    {
      pos: [5, 0, 4], 
      state: 1
    }, 
    {
      pos: [1, 1, 4], 
      state: 1
    }, 
    {
      pos: [5, 1, 4], 
      state: 1
    }, 
    {
      pos: [1, 2, 4], 
      state: 1
    }, 
    {
      pos: [5, 2, 4], 
      state: 1
    }, 
    {
      pos: [1, 3, 4], 
      state: 1
    }, 
    {
      pos: [5, 3, 4], 
      state: 1
    }, 
    {
      pos: [1, 4, 4], 
      state: 3
    }, 
    {
      pos: [5, 4, 4], 
      state: 3
    }, 
    {
      pos: [1, 0, 5], 
      state: 0
    }, 
    {
      pos: [2, 0, 5], 
      state: 2
    }, 
    {
      pos: [3, 0, 5], 
      state: 2
    }, 
    {
      pos: [4, 0, 5], 
      state: 2
    }, 
    {
      pos: [5, 0, 5], 
      state: 0
    }, 
    {
      pos: [1, 1, 5], 
      state: 0
    }, 
    {
      pos: [5, 1, 5], 
      state: 0
    }, 
    {
      pos: [1, 2, 5], 
      state: 0
    }, 
    {
      pos: [5, 2, 5], 
      state: 0
    }, 
    {
      pos: [1, 3, 5], 
      state: 0
    }, 
    {
      pos: [5, 3, 5], 
      state: 0
    }, 
    {
      pos: [1, 0, 6], 
      state: 1
    }, 
    {
      pos: [2, 0, 6], 
      state: 1
    }, 
    {
      pos: [3, 0, 6], 
      state: 1
    }, 
    {
      pos: [4, 0, 6], 
      state: 1
    }, 
    {
      pos: [5, 0, 6], 
      state: 1
    }, 
    {
      pos: [5, 1, 6], 
      state: 1
    }, 
    {
      pos: [5, 2, 6], 
      state: 1
    }, 
    {
      pos: [1, 3, 6], 
      state: 1
    }, 
    {
      pos: [5, 3, 6], 
      state: 1
    }, 
    {
      pos: [0, 4, 6], 
      state: 4
    }, 
    {
      pos: [1, 4, 6], 
      state: 4
    }, 
    {
      pos: [2, 4, 6], 
      state: 4
    }, 
    {
      pos: [3, 4, 6], 
      state: 4
    }, 
    {
      pos: [4, 4, 6], 
      state: 4
    }, 
    {
      pos: [5, 4, 6], 
      state: 4
    }, 
    {
      pos: [6, 4, 6], 
      state: 4
    }, 
    {
      pos: [1, 0, 7], 
      state: 0
    }, 
    {
      pos: [2, 0, 7], 
      state: 2
    }, 
    {
      pos: [3, 0, 7], 
      state: 2
    }, 
    {
      pos: [4, 0, 7], 
      state: 2
    }, 
    {
      pos: [5, 0, 7], 
      state: 0
    }, 
    {
      pos: [1, 1, 7], 
      state: 0
    }, 
    {
      pos: [5, 1, 7], 
      state: 0
    }, 
    {
      pos: [1, 2, 7], 
      state: 0
    }, 
    {
      pos: [5, 2, 7], 
      state: 0
    }, 
    {
      pos: [1, 3, 7], 
      state: 0
    }, 
    {
      pos: [5, 3, 7], 
      state: 0
    }, 
    {
      pos: [1, 0, 8], 
      state: 1
    }, 
    {
      pos: [2, 0, 8], 
      state: 2
    }, 
    {
      pos: [4, 0, 8], 
      state: 2
    }, 
    {
      pos: [5, 0, 8], 
      state: 1
    }, 
    {
      pos: [1, 1, 8], 
      state: 1
    }, 
    {
      pos: [5, 1, 8], 
      state: 1
    }, 
    {
      pos: [1, 2, 8], 
      state: 1
    }, 
    {
      pos: [5, 2, 8], 
      state: 1
    }, 
    {
      pos: [1, 3, 8], 
      state: 1
    }, 
    {
      pos: [5, 3, 8], 
      state: 1
    }, 
    {
      pos: [1, 4, 8], 
      state: 3
    }, 
    {
      pos: [5, 4, 8], 
      state: 3
    }, 
    {
      pos: [1, 0, 9], 
      state: 1
    }, 
    {
      pos: [2, 0, 9], 
      state: 2
    }, 
    {
      pos: [3, 0, 9], 
      state: 1
    }, 
    {
      pos: [4, 0, 9], 
      state: 2
    }, 
    {
      pos: [5, 0, 9], 
      state: 1
    }, 
    {
      pos: [1, 1, 9], 
      state: 1
    }, 
    {
      pos: [5, 1, 9], 
      state: 1
    }, 
    {
      pos: [1, 3, 9], 
      state: 1
    }, 
    {
      pos: [5, 3, 9], 
      state: 1
    }, 
    {
      pos: [1, 4, 9], 
      state: 3
    }, 
    {
      pos: [5, 4, 9], 
      state: 3
    }, 
    {
      pos: [0, 5, 9], 
      state: 2
    }, 
    {
      pos: [1, 5, 9], 
      state: 2
    }, 
    {
      pos: [2, 5, 9], 
      state: 2
    }, 
    {
      pos: [3, 5, 9], 
      state: 2
    }, 
    {
      pos: [4, 5, 9], 
      state: 2
    }, 
    {
      pos: [5, 5, 9], 
      state: 2
    }, 
    {
      pos: [6, 5, 9], 
      state: 2
    }, 
    {
      pos: [1, 0, 10], 
      state: 1
    }, 
    {
      pos: [2, 0, 10], 
      state: 2
    }, 
    {
      pos: [3, 0, 10], 
      state: 2
    }, 
    {
      pos: [4, 0, 10], 
      state: 2
    }, 
    {
      pos: [5, 0, 10], 
      state: 1
    }, 
    {
      pos: [1, 1, 10], 
      state: 1
    }, 
    {
      pos: [5, 1, 10], 
      state: 1
    }, 
    {
      pos: [1, 2, 10], 
      state: 1
    }, 
    {
      pos: [5, 2, 10], 
      state: 1
    }, 
    {
      pos: [1, 3, 10], 
      state: 1
    }, 
    {
      pos: [5, 3, 10], 
      state: 1
    }, 
    {
      pos: [1, 4, 10], 
      state: 3
    }, 
    {
      pos: [5, 4, 10], 
      state: 3
    }, 
    {
      pos: [1, 0, 11], 
      state: 0
    }, 
    {
      pos: [2, 0, 11], 
      state: 1
    }, 
    {
      pos: [3, 0, 11], 
      state: 1
    }, 
    {
      pos: [4, 0, 11], 
      state: 1
    }, 
    {
      pos: [5, 0, 11], 
      state: 0
    }, 
    {
      pos: [1, 1, 11], 
      state: 0
    }, 
    {
      pos: [2, 1, 11], 
      state: 1
    }, 
    {
      pos: [3, 1, 11], 
      state: 1
    }, 
    {
      pos: [4, 1, 11], 
      state: 1
    }, 
    {
      pos: [5, 1, 11], 
      state: 0
    }, 
    {
      pos: [1, 2, 11], 
      state: 0
    }, 
    {
      pos: [2, 2, 11], 
      state: 1
    }, 
    {
      pos: [4, 2, 11], 
      state: 1
    }, 
    {
      pos: [5, 2, 11], 
      state: 0
    }, 
    {
      pos: [1, 3, 11], 
      state: 0
    }, 
    {
      pos: [2, 3, 11], 
      state: 1
    }, 
    {
      pos: [3, 3, 11], 
      state: 1
    }, 
    {
      pos: [4, 3, 11], 
      state: 1
    }, 
    {
      pos: [5, 3, 11], 
      state: 0
    }, 
    {
      nbt: {
        id: "minecraft:bed"
      }, 
      pos: [2, 1, 2], 
      state: 5
    }, 
    {
      nbt: {
        id: "minecraft:bed"
      }, 
      pos: [2, 1, 3], 
      state: 6
    }, 
    {
      nbt: {
        target_pool: "minecraft:village/plains/zombie/villagers", 
        final_state: "minecraft:cobblestone", 
        id: "minecraft:jigsaw", 
        attachement_type: "minecraft:bottom"
      }, 
      pos: [3, 0, 4], 
      state: 7
    }, 
    {
      nbt: {
        target_pool: "minecraft:village/plains/zombie/streets", 
        final_state: "minecraft:cobblestone_stairs[facing=east,half=bottom,shape=straight,waterlogged=false]", 
        id: "minecraft:jigsaw", 
        attachement_type: "minecraft:building_entrance"
      }, 
      pos: [0, 0, 6], 
      state: 8
    }, 
    {
      nbt: {
        target_pool: "minecraft:village/plains/zombie/villagers", 
        final_state: "minecraft:cobblestone", 
        id: "minecraft:jigsaw", 
        attachement_type: "minecraft:bottom"
      }, 
      pos: [3, 0, 8], 
      state: 7
    }, 
    {
      nbt: {
        id: "minecraft:bed"
      }, 
      pos: [4, 1, 9], 
      state: 9
    }, 
    {
      nbt: {
        LootTable: "minecraft:chests/village/village_plains_house", 
        id: "minecraft:chest", 
        Lock: "", 
        LootTableSeed: 0L
      }, 
      pos: [2, 1, 10], 
      state: 10
    }, 
    {
      nbt: {
        id: "minecraft:bed"
      }, 
      pos: [4, 1, 10], 
      state: 11
    }, 
    {
      pos: [0, 0, 0], 
      state: 12
    }, 
    {
      pos: [1, 0, 0], 
      state: 12
    }, 
    {
      pos: [2, 0, 0], 
      state: 12
    }, 
    {
      pos: [3, 0, 0], 
      state: 12
    }, 
    {
      pos: [4, 0, 0], 
      state: 12
    }, 
    {
      pos: [5, 0, 0], 
      state: 12
    }, 
    {
      pos: [6, 0, 0], 
      state: 12
    }, 
    {
      pos: [0, 1, 0], 
      state: 12
    }, 
    {
      pos: [1, 1, 0], 
      state: 12
    }, 
    {
      pos: [2, 1, 0], 
      state: 12
    }, 
    {
      pos: [3, 1, 0], 
      state: 12
    }, 
    {
      pos: [4, 1, 0], 
      state: 12
    }, 
    {
      pos: [5, 1, 0], 
      state: 12
    }, 
    {
      pos: [6, 1, 0], 
      state: 12
    }, 
    {
      pos: [0, 2, 0], 
      state: 12
    }, 
    {
      pos: [1, 2, 0], 
      state: 12
    }, 
    {
      pos: [2, 2, 0], 
      state: 12
    }, 
    {
      pos: [3, 2, 0], 
      state: 12
    }, 
    {
      pos: [4, 2, 0], 
      state: 12
    }, 
    {
      pos: [5, 2, 0], 
      state: 12
    }, 
    {
      pos: [6, 2, 0], 
      state: 12
    }, 
    {
      pos: [0, 3, 0], 
      state: 13
    }, 
    {
      pos: [1, 3, 0], 
      state: 13
    }, 
    {
      pos: [2, 3, 0], 
      state: 13
    }, 
    {
      pos: [3, 3, 0], 
      state: 13
    }, 
    {
      pos: [4, 3, 0], 
      state: 13
    }, 
    {
      pos: [5, 3, 0], 
      state: 13
    }, 
    {
      pos: [6, 3, 0], 
      state: 13
    }, 
    {
      pos: [0, 4, 0], 
      state: 12
    }, 
    {
      pos: [1, 4, 0], 
      state: 12
    }, 
    {
      pos: [2, 4, 0], 
      state: 12
    }, 
    {
      pos: [3, 4, 0], 
      state: 12
    }, 
    {
      pos: [4, 4, 0], 
      state: 12
    }, 
    {
      pos: [5, 4, 0], 
      state: 12
    }, 
    {
      pos: [6, 4, 0], 
      state: 12
    }, 
    {
      pos: [0, 5, 0], 
      state: 12
    }, 
    {
      pos: [1, 5, 0], 
      state: 12
    }, 
    {
      pos: [2, 5, 0], 
      state: 12
    }, 
    {
      pos: [3, 5, 0], 
      state: 12
    }, 
    {
      pos: [4, 5, 0], 
      state: 12
    }, 
    {
      pos: [5, 5, 0], 
      state: 12
    }, 
    {
      pos: [6, 5, 0], 
      state: 12
    }, 
    {
      pos: [0, 0, 1], 
      state: 12
    }, 
    {
      pos: [6, 0, 1], 
      state: 12
    }, 
    {
      pos: [0, 1, 1], 
      state: 12
    }, 
    {
      pos: [6, 1, 1], 
      state: 12
    }, 
    {
      pos: [0, 2, 1], 
      state: 12
    }, 
    {
      pos: [3, 2, 1], 
      state: 14
    }, 
    {
      pos: [6, 2, 1], 
      state: 12
    }, 
    {
      pos: [0, 3, 1], 
      state: 15
    }, 
    {
      pos: [6, 3, 1], 
      state: 15
    }, 
    {
      pos: [0, 4, 1], 
      state: 13
    }, 
    {
      pos: [1, 4, 1], 
      state: 13
    }, 
    {
      pos: [2, 4, 1], 
      state: 13
    }, 
    {
      pos: [3, 4, 1], 
      state: 13
    }, 
    {
      pos: [4, 4, 1], 
      state: 13
    }, 
    {
      pos: [5, 4, 1], 
      state: 13
    }, 
    {
      pos: [6, 4, 1], 
      state: 13
    }, 
    {
      pos: [0, 5, 1], 
      state: 12
    }, 
    {
      pos: [1, 5, 1], 
      state: 12
    }, 
    {
      pos: [2, 5, 1], 
      state: 12
    }, 
    {
      pos: [3, 5, 1], 
      state: 12
    }, 
    {
      pos: [4, 5, 1], 
      state: 12
    }, 
    {
      pos: [5, 5, 1], 
      state: 12
    }, 
    {
      pos: [6, 5, 1], 
      state: 12
    }, 
    {
      pos: [0, 0, 2], 
      state: 12
    }, 
    {
      pos: [6, 0, 2], 
      state: 12
    }, 
    {
      pos: [0, 1, 2], 
      state: 12
    }, 
    {
      pos: [3, 1, 2], 
      state: 12
    }, 
    {
      pos: [4, 1, 2], 
      state: 16
    }, 
    {
      pos: [6, 1, 2], 
      state: 12
    }, 
    {
      pos: [0, 2, 2], 
      state: 12
    }, 
    {
      pos: [2, 2, 2], 
      state: 12
    }, 
    {
      pos: [3, 2, 2], 
      state: 12
    }, 
    {
      pos: [4, 2, 2], 
      state: 12
    }, 
    {
      pos: [6, 2, 2], 
      state: 12
    }, 
    {
      pos: [0, 3, 2], 
      state: 12
    }, 
    {
      pos: [2, 3, 2], 
      state: 12
    }, 
    {
      pos: [3, 3, 2], 
      state: 12
    }, 
    {
      pos: [4, 3, 2], 
      state: 12
    }, 
    {
      pos: [6, 3, 2], 
      state: 12
    }, 
    {
      pos: [0, 4, 2], 
      state: 15
    }, 
    {
      pos: [2, 4, 2], 
      state: 12
    }, 
    {
      pos: [3, 4, 2], 
      state: 12
    }, 
    {
      pos: [4, 4, 2], 
      state: 12
    }, 
    {
      pos: [6, 4, 2], 
      state: 15
    }, 
    {
      pos: [0, 5, 2], 
      state: 13
    }, 
    {
      pos: [1, 5, 2], 
      state: 13
    }, 
    {
      pos: [2, 5, 2], 
      state: 13
    }, 
    {
      pos: [3, 5, 2], 
      state: 13
    }, 
    {
      pos: [4, 5, 2], 
      state: 13
    }, 
    {
      pos: [5, 5, 2], 
      state: 13
    }, 
    {
      pos: [6, 5, 2], 
      state: 13
    }, 
    {
      pos: [0, 0, 3], 
      state: 12
    }, 
    {
      pos: [6, 0, 3], 
      state: 12
    }, 
    {
      pos: [0, 1, 3], 
      state: 12
    }, 
    {
      pos: [3, 1, 3], 
      state: 12
    }, 
    {
      pos: [4, 1, 3], 
      state: 17
    }, 
    {
      pos: [6, 1, 3], 
      state: 12
    }, 
    {
      pos: [0, 2, 3], 
      state: 12
    }, 
    {
      pos: [1, 2, 3], 
      state: 18
    }, 
    {
      pos: [2, 2, 3], 
      state: 12
    }, 
    {
      pos: [3, 2, 3], 
      state: 12
    }, 
    {
      pos: [4, 2, 3], 
      state: 19
    }, 
    {
      pos: [5, 2, 3], 
      state: 18
    }, 
    {
      pos: [6, 2, 3], 
      state: 12
    }, 
    {
      pos: [0, 3, 3], 
      state: 12
    }, 
    {
      pos: [2, 3, 3], 
      state: 12
    }, 
    {
      pos: [3, 3, 3], 
      state: 12
    }, 
    {
      pos: [4, 3, 3], 
      state: 12
    }, 
    {
      pos: [6, 3, 3], 
      state: 12
    }, 
    {
      pos: [0, 4, 3], 
      state: 12
    }, 
    {
      pos: [2, 4, 3], 
      state: 12
    }, 
    {
      pos: [3, 4, 3], 
      state: 12
    }, 
    {
      pos: [4, 4, 3], 
      state: 12
    }, 
    {
      pos: [6, 4, 3], 
      state: 12
    }, 
    {
      pos: [0, 0, 4], 
      state: 12
    }, 
    {
      pos: [6, 0, 4], 
      state: 12
    }, 
    {
      pos: [0, 1, 4], 
      state: 12
    }, 
    {
      pos: [2, 1, 4], 
      state: 12
    }, 
    {
      pos: [3, 1, 4], 
      state: 12
    }, 
    {
      pos: [4, 1, 4], 
      state: 12
    }, 
    {
      pos: [6, 1, 4], 
      state: 12
    }, 
    {
      pos: [0, 2, 4], 
      state: 12
    }, 
    {
      pos: [2, 2, 4], 
      state: 12
    }, 
    {
      pos: [3, 2, 4], 
      state: 12
    }, 
    {
      pos: [4, 2, 4], 
      state: 12
    }, 
    {
      pos: [6, 2, 4], 
      state: 12
    }, 
    {
      pos: [0, 3, 4], 
      state: 12
    }, 
    {
      pos: [2, 3, 4], 
      state: 12
    }, 
    {
      pos: [3, 3, 4], 
      state: 12
    }, 
    {
      pos: [4, 3, 4], 
      state: 12
    }, 
    {
      pos: [6, 3, 4], 
      state: 12
    }, 
    {
      pos: [0, 4, 4], 
      state: 20
    }, 
    {
      pos: [2, 4, 4], 
      state: 12
    }, 
    {
      pos: [3, 4, 4], 
      state: 12
    }, 
    {
      pos: [4, 4, 4], 
      state: 12
    }, 
    {
      pos: [6, 4, 4], 
      state: 20
    }, 
    {
      pos: [0, 5, 4], 
      state: 16
    }, 
    {
      pos: [1, 5, 4], 
      state: 16
    }, 
    {
      pos: [2, 5, 4], 
      state: 16
    }, 
    {
      pos: [3, 5, 4], 
      state: 16
    }, 
    {
      pos: [4, 5, 4], 
      state: 16
    }, 
    {
      pos: [5, 5, 4], 
      state: 16
    }, 
    {
      pos: [6, 5, 4], 
      state: 16
    }, 
    {
      pos: [0, 0, 5], 
      state: 12
    }, 
    {
      pos: [6, 0, 5], 
      state: 12
    }, 
    {
      pos: [0, 1, 5], 
      state: 12
    }, 
    {
      pos: [2, 1, 5], 
      state: 12
    }, 
    {
      pos: [3, 1, 5], 
      state: 12
    }, 
    {
      pos: [4, 1, 5], 
      state: 12
    }, 
    {
      pos: [6, 1, 5], 
      state: 12
    }, 
    {
      pos: [0, 2, 5], 
      state: 12
    }, 
    {
      pos: [2, 2, 5], 
      state: 12
    }, 
    {
      pos: [3, 2, 5], 
      state: 12
    }, 
    {
      pos: [4, 2, 5], 
      state: 21
    }, 
    {
      pos: [6, 2, 5], 
      state: 12
    }, 
    {
      pos: [0, 3, 5], 
      state: 12
    }, 
    {
      pos: [2, 3, 5], 
      state: 12
    }, 
    {
      pos: [3, 3, 5], 
      state: 12
    }, 
    {
      pos: [4, 3, 5], 
      state: 12
    }, 
    {
      pos: [6, 3, 5], 
      state: 12
    }, 
    {
      pos: [0, 4, 5], 
      state: 16
    }, 
    {
      pos: [1, 4, 5], 
      state: 16
    }, 
    {
      pos: [2, 4, 5], 
      state: 16
    }, 
    {
      pos: [3, 4, 5], 
      state: 16
    }, 
    {
      pos: [4, 4, 5], 
      state: 16
    }, 
    {
      pos: [5, 4, 5], 
      state: 16
    }, 
    {
      pos: [6, 4, 5], 
      state: 16
    }, 
    {
      pos: [0, 5, 5], 
      state: 12
    }, 
    {
      pos: [1, 5, 5], 
      state: 12
    }, 
    {
      pos: [2, 5, 5], 
      state: 12
    }, 
    {
      pos: [3, 5, 5], 
      state: 12
    }, 
    {
      pos: [4, 5, 5], 
      state: 12
    }, 
    {
      pos: [5, 5, 5], 
      state: 12
    }, 
    {
      pos: [6, 5, 5], 
      state: 12
    }, 
    {
      pos: [6, 0, 6], 
      state: 12
    }, 
    {
      pos: [0, 1, 6], 
      state: 12
    }, 
    {
      pos: [1, 1, 6], 
      state: 22
    }, 
    {
      pos: [2, 1, 6], 
      state: 12
    }, 
    {
      pos: [3, 1, 6], 
      state: 12
    }, 
    {
      pos: [4, 1, 6], 
      state: 12
    }, 
    {
      pos: [6, 1, 6], 
      state: 12
    }, 
    {
      pos: [0, 2, 6], 
      state: 12
    }, 
    {
      pos: [1, 2, 6], 
      state: 23
    }, 
    {
      pos: [2, 2, 6], 
      state: 12
    }, 
    {
      pos: [3, 2, 6], 
      state: 12
    }, 
    {
      pos: [4, 2, 6], 
      state: 12
    }, 
    {
      pos: [6, 2, 6], 
      state: 12
    }, 
    {
      pos: [0, 3, 6], 
      state: 24
    }, 
    {
      pos: [2, 3, 6], 
      state: 12
    }, 
    {
      pos: [3, 3, 6], 
      state: 12
    }, 
    {
      pos: [4, 3, 6], 
      state: 12
    }, 
    {
      pos: [6, 3, 6], 
      state: 24
    }, 
    {
      pos: [0, 5, 6], 
      state: 12
    }, 
    {
      pos: [1, 5, 6], 
      state: 12
    }, 
    {
      pos: [2, 5, 6], 
      state: 12
    }, 
    {
      pos: [3, 5, 6], 
      state: 12
    }, 
    {
      pos: [4, 5, 6], 
      state: 12
    }, 
    {
      pos: [5, 5, 6], 
      state: 12
    }, 
    {
      pos: [6, 5, 6], 
      state: 12
    }, 
    {
      pos: [0, 0, 7], 
      state: 12
    }, 
    {
      pos: [6, 0, 7], 
      state: 12
    }, 
    {
      pos: [0, 1, 7], 
      state: 12
    }, 
    {
      pos: [2, 1, 7], 
      state: 12
    }, 
    {
      pos: [3, 1, 7], 
      state: 12
    }, 
    {
      pos: [4, 1, 7], 
      state: 12
    }, 
    {
      pos: [6, 1, 7], 
      state: 12
    }, 
    {
      pos: [0, 2, 7], 
      state: 12
    }, 
    {
      pos: [2, 2, 7], 
      state: 12
    }, 
    {
      pos: [3, 2, 7], 
      state: 12
    }, 
    {
      pos: [4, 2, 7], 
      state: 21
    }, 
    {
      pos: [6, 2, 7], 
      state: 12
    }, 
    {
      pos: [0, 3, 7], 
      state: 12
    }, 
    {
      pos: [2, 3, 7], 
      state: 12
    }, 
    {
      pos: [3, 3, 7], 
      state: 12
    }, 
    {
      pos: [4, 3, 7], 
      state: 12
    }, 
    {
      pos: [6, 3, 7], 
      state: 12
    }, 
    {
      pos: [0, 4, 7], 
      state: 13
    }, 
    {
      pos: [1, 4, 7], 
      state: 13
    }, 
    {
      pos: [2, 4, 7], 
      state: 13
    }, 
    {
      pos: [3, 4, 7], 
      state: 13
    }, 
    {
      pos: [4, 4, 7], 
      state: 13
    }, 
    {
      pos: [5, 4, 7], 
      state: 13
    }, 
    {
      pos: [6, 4, 7], 
      state: 13
    }, 
    {
      pos: [0, 5, 7], 
      state: 12
    }, 
    {
      pos: [1, 5, 7], 
      state: 12
    }, 
    {
      pos: [2, 5, 7], 
      state: 12
    }, 
    {
      pos: [3, 5, 7], 
      state: 12
    }, 
    {
      pos: [4, 5, 7], 
      state: 12
    }, 
    {
      pos: [5, 5, 7], 
      state: 12
    }, 
    {
      pos: [6, 5, 7], 
      state: 12
    }, 
    {
      pos: [0, 0, 8], 
      state: 12
    }, 
    {
      pos: [6, 0, 8], 
      state: 12
    }, 
    {
      pos: [0, 1, 8], 
      state: 12
    }, 
    {
      pos: [2, 1, 8], 
      state: 12
    }, 
    {
      pos: [3, 1, 8], 
      state: 12
    }, 
    {
      pos: [4, 1, 8], 
      state: 12
    }, 
    {
      pos: [6, 1, 8], 
      state: 12
    }, 
    {
      pos: [0, 2, 8], 
      state: 12
    }, 
    {
      pos: [2, 2, 8], 
      state: 12
    }, 
    {
      pos: [3, 2, 8], 
      state: 12
    }, 
    {
      pos: [4, 2, 8], 
      state: 12
    }, 
    {
      pos: [6, 2, 8], 
      state: 12
    }, 
    {
      pos: [0, 3, 8], 
      state: 12
    }, 
    {
      pos: [2, 3, 8], 
      state: 12
    }, 
    {
      pos: [3, 3, 8], 
      state: 12
    }, 
    {
      pos: [4, 3, 8], 
      state: 12
    }, 
    {
      pos: [6, 3, 8], 
      state: 12
    }, 
    {
      pos: [0, 4, 8], 
      state: 15
    }, 
    {
      pos: [2, 4, 8], 
      state: 12
    }, 
    {
      pos: [3, 4, 8], 
      state: 12
    }, 
    {
      pos: [4, 4, 8], 
      state: 12
    }, 
    {
      pos: [6, 4, 8], 
      state: 15
    }, 
    {
      pos: [0, 5, 8], 
      state: 13
    }, 
    {
      pos: [1, 5, 8], 
      state: 13
    }, 
    {
      pos: [2, 5, 8], 
      state: 13
    }, 
    {
      pos: [3, 5, 8], 
      state: 13
    }, 
    {
      pos: [4, 5, 8], 
      state: 13
    }, 
    {
      pos: [5, 5, 8], 
      state: 13
    }, 
    {
      pos: [6, 5, 8], 
      state: 13
    }, 
    {
      pos: [0, 0, 9], 
      state: 12
    }, 
    {
      pos: [6, 0, 9], 
      state: 12
    }, 
    {
      pos: [0, 1, 9], 
      state: 12
    }, 
    {
      pos: [2, 1, 9], 
      state: 12
    }, 
    {
      pos: [3, 1, 9], 
      state: 12
    }, 
    {
      pos: [6, 1, 9], 
      state: 12
    }, 
    {
      pos: [0, 2, 9], 
      state: 12
    }, 
    {
      pos: [1, 2, 9], 
      state: 18
    }, 
    {
      pos: [2, 2, 9], 
      state: 12
    }, 
    {
      pos: [3, 2, 9], 
      state: 12
    }, 
    {
      pos: [4, 2, 9], 
      state: 12
    }, 
    {
      pos: [5, 2, 9], 
      state: 18
    }, 
    {
      pos: [6, 2, 9], 
      state: 12
    }, 
    {
      pos: [0, 3, 9], 
      state: 12
    }, 
    {
      pos: [2, 3, 9], 
      state: 12
    }, 
    {
      pos: [3, 3, 9], 
      state: 12
    }, 
    {
      pos: [4, 3, 9], 
      state: 12
    }, 
    {
      pos: [6, 3, 9], 
      state: 12
    }, 
    {
      pos: [0, 4, 9], 
      state: 12
    }, 
    {
      pos: [2, 4, 9], 
      state: 12
    }, 
    {
      pos: [3, 4, 9], 
      state: 12
    }, 
    {
      pos: [4, 4, 9], 
      state: 12
    }, 
    {
      pos: [6, 4, 9], 
      state: 12
    }, 
    {
      pos: [0, 0, 10], 
      state: 12
    }, 
    {
      pos: [6, 0, 10], 
      state: 12
    }, 
    {
      pos: [0, 1, 10], 
      state: 12
    }, 
    {
      pos: [3, 1, 10], 
      state: 12
    }, 
    {
      pos: [6, 1, 10], 
      state: 12
    }, 
    {
      pos: [0, 2, 10], 
      state: 12
    }, 
    {
      pos: [2, 2, 10], 
      state: 12
    }, 
    {
      pos: [3, 2, 10], 
      state: 12
    }, 
    {
      pos: [4, 2, 10], 
      state: 12
    }, 
    {
      pos: [6, 2, 10], 
      state: 12
    }, 
    {
      pos: [0, 3, 10], 
      state: 12
    }, 
    {
      pos: [2, 3, 10], 
      state: 12
    }, 
    {
      pos: [3, 3, 10], 
      state: 12
    }, 
    {
      pos: [4, 3, 10], 
      state: 12
    }, 
    {
      pos: [6, 3, 10], 
      state: 12
    }, 
    {
      pos: [0, 4, 10], 
      state: 20
    }, 
    {
      pos: [2, 4, 10], 
      state: 12
    }, 
    {
      pos: [3, 4, 10], 
      state: 12
    }, 
    {
      pos: [4, 4, 10], 
      state: 12
    }, 
    {
      pos: [6, 4, 10], 
      state: 20
    }, 
    {
      pos: [0, 5, 10], 
      state: 16
    }, 
    {
      pos: [1, 5, 10], 
      state: 16
    }, 
    {
      pos: [2, 5, 10], 
      state: 16
    }, 
    {
      pos: [3, 5, 10], 
      state: 16
    }, 
    {
      pos: [4, 5, 10], 
      state: 16
    }, 
    {
      pos: [5, 5, 10], 
      state: 16
    }, 
    {
      pos: [6, 5, 10], 
      state: 16
    }, 
    {
      pos: [0, 0, 11], 
      state: 12
    }, 
    {
      pos: [6, 0, 11], 
      state: 12
    }, 
    {
      pos: [0, 1, 11], 
      state: 12
    }, 
    {
      pos: [6, 1, 11], 
      state: 12
    }, 
    {
      pos: [0, 2, 11], 
      state: 12
    }, 
    {
      pos: [3, 2, 11], 
      state: 14
    }, 
    {
      pos: [6, 2, 11], 
      state: 12
    }, 
    {
      pos: [0, 3, 11], 
      state: 20
    }, 
    {
      pos: [6, 3, 11], 
      state: 20
    }, 
    {
      pos: [0, 4, 11], 
      state: 16
    }, 
    {
      pos: [1, 4, 11], 
      state: 16
    }, 
    {
      pos: [2, 4, 11], 
      state: 16
    }, 
    {
      pos: [3, 4, 11], 
      state: 16
    }, 
    {
      pos: [4, 4, 11], 
      state: 16
    }, 
    {
      pos: [5, 4, 11], 
      state: 16
    }, 
    {
      pos: [6, 4, 11], 
      state: 16
    }, 
    {
      pos: [0, 5, 11], 
      state: 12
    }, 
    {
      pos: [1, 5, 11], 
      state: 12
    }, 
    {
      pos: [2, 5, 11], 
      state: 12
    }, 
    {
      pos: [3, 5, 11], 
      state: 12
    }, 
    {
      pos: [4, 5, 11], 
      state: 12
    }, 
    {
      pos: [5, 5, 11], 
      state: 12
    }, 
    {
      pos: [6, 5, 11], 
      state: 12
    }, 
    {
      pos: [0, 0, 12], 
      state: 12
    }, 
    {
      pos: [1, 0, 12], 
      state: 12
    }, 
    {
      pos: [2, 0, 12], 
      state: 12
    }, 
    {
      pos: [3, 0, 12], 
      state: 12
    }, 
    {
      pos: [4, 0, 12], 
      state: 12
    }, 
    {
      pos: [5, 0, 12], 
      state: 12
    }, 
    {
      pos: [6, 0, 12], 
      state: 12
    }, 
    {
      pos: [0, 1, 12], 
      state: 12
    }, 
    {
      pos: [1, 1, 12], 
      state: 12
    }, 
    {
      pos: [2, 1, 12], 
      state: 12
    }, 
    {
      pos: [3, 1, 12], 
      state: 12
    }, 
    {
      pos: [4, 1, 12], 
      state: 12
    }, 
    {
      pos: [5, 1, 12], 
      state: 12
    }, 
    {
      pos: [6, 1, 12], 
      state: 12
    }, 
    {
      pos: [0, 2, 12], 
      state: 12
    }, 
    {
      pos: [1, 2, 12], 
      state: 12
    }, 
    {
      pos: [2, 2, 12], 
      state: 12
    }, 
    {
      pos: [3, 2, 12], 
      state: 12
    }, 
    {
      pos: [4, 2, 12], 
      state: 12
    }, 
    {
      pos: [5, 2, 12], 
      state: 12
    }, 
    {
      pos: [6, 2, 12], 
      state: 12
    }, 
    {
      pos: [0, 3, 12], 
      state: 16
    }, 
    {
      pos: [1, 3, 12], 
      state: 16
    }, 
    {
      pos: [2, 3, 12], 
      state: 16
    }, 
    {
      pos: [3, 3, 12], 
      state: 16
    }, 
    {
      pos: [4, 3, 12], 
      state: 16
    }, 
    {
      pos: [5, 3, 12], 
      state: 16
    }, 
    {
      pos: [6, 3, 12], 
      state: 16
    }, 
    {
      pos: [0, 4, 12], 
      state: 12
    }, 
    {
      pos: [1, 4, 12], 
      state: 12
    }, 
    {
      pos: [2, 4, 12], 
      state: 12
    }, 
    {
      pos: [3, 4, 12], 
      state: 12
    }, 
    {
      pos: [4, 4, 12], 
      state: 12
    }, 
    {
      pos: [5, 4, 12], 
      state: 12
    }, 
    {
      pos: [6, 4, 12], 
      state: 12
    }, 
    {
      pos: [0, 5, 12], 
      state: 12
    }, 
    {
      pos: [1, 5, 12], 
      state: 12
    }, 
    {
      pos: [2, 5, 12], 
      state: 12
    }, 
    {
      pos: [3, 5, 12], 
      state: 12
    }, 
    {
      pos: [4, 5, 12], 
      state: 12
    }, 
    {
      pos: [5, 5, 12], 
      state: 12
    }, 
    {
      pos: [6, 5, 12], 
      state: 12
    }
  ], 
  palette: [
    {
      Properties: {
        axis: "y"
      }, 
      Name: "minecraft:oak_log"
    }, 
    {
      Name: "minecraft:cobblestone"
    }, 
    {
      Name: "minecraft:oak_planks"
    }, 
    {
      Properties: {
        axis: "z"
      }, 
      Name: "minecraft:oak_log"
    }, 
    {
      Properties: {
        waterlogged: "false", 
        type: "double"
      }, 
      Name: "minecraft:oak_slab"
    }, 
    {
      Properties: {
        part: "head", 
        facing: "north", 
        occupied: "false"
      }, 
      Name: "minecraft:yellow_bed"
    }, 
    {
      Properties: {
        part: "foot", 
        facing: "north", 
        occupied: "false"
      }, 
      Name: "minecraft:yellow_bed"
    }, 
    {
      Properties: {
        facing: "up"
      }, 
      Name: "minecraft:jigsaw"
    }, 
    {
      Properties: {
        facing: "west"
      }, 
      Name: "minecraft:jigsaw"
    }, 
    {
      Properties: {
        part: "foot", 
        facing: "south", 
        occupied: "false"
      }, 
      Name: "minecraft:yellow_bed"
    }, 
    {
      Properties: {
        waterlogged: "false", 
        facing: "north", 
        type: "single"
      }, 
      Name: "minecraft:chest"
    }, 
    {
      Properties: {
        part: "head", 
        facing: "south", 
        occupied: "false"
      }, 
      Name: "minecraft:yellow_bed"
    }, 
    {
      Name: "minecraft:air"
    }, 
    {
      Properties: {
        half: "bottom", 
        waterlogged: "false", 
        shape: "straight", 
        facing: "south"
      }, 
      Name: "minecraft:oak_stairs"
    }, 
    {
      Properties: {
        east: "true", 
        waterlogged: "false", 
        south: "false", 
        north: "false", 
        west: "true"
      }, 
      Name: "minecraft:glass_pane"
    }, 
    {
      Properties: {
        half: "top", 
        waterlogged: "false", 
        shape: "straight", 
        facing: "north"
      }, 
      Name: "minecraft:oak_stairs"
    }, 
    {
      Properties: {
        half: "bottom", 
        waterlogged: "false", 
        shape: "straight", 
        facing: "north"
      }, 
      Name: "minecraft:oak_stairs"
    }, 
    {
      Properties: {
        east: "true", 
        waterlogged: "false", 
        south: "false", 
        north: "false", 
        west: "false"
      }, 
      Name: "minecraft:oak_fence"
    }, 
    {
      Properties: {
        east: "false", 
        waterlogged: "false", 
        south: "true", 
        north: "true", 
        west: "false"
      }, 
      Name: "minecraft:glass_pane"
    }, 
    {
      Properties: {
        powered: "false"
      }, 
      Name: "minecraft:oak_pressure_plate"
    }, 
    {
      Properties: {
        half: "top", 
        waterlogged: "false", 
        shape: "straight", 
        facing: "south"
      }, 
      Name: "minecraft:oak_stairs"
    }, 
    {
      Properties: {
        facing: "west"
      }, 
      Name: "minecraft:wall_torch"
    }, 
    {
      Properties: {
        hinge: "right", 
        half: "lower", 
        powered: "false", 
        facing: "east", 
        open: "false"
      }, 
      Name: "minecraft:oak_door"
    }, 
    {
      Properties: {
        hinge: "right", 
        half: "upper", 
        powered: "false", 
        facing: "east", 
        open: "false"
      }, 
      Name: "minecraft:oak_door"
    }, 
    {
      Properties: {
        waterlogged: "false", 
        type: "top"
      }, 
      Name: "minecraft:oak_slab"
    }
  ]
}
