{
  size: [11, 6, 11], 
  entities: [], 
  blocks: [
    {
      pos: [7, 0, 0], 
      state: 0
    }, 
    {
      pos: [8, 0, 0], 
      state: 0
    }, 
    {
      pos: [9, 0, 0], 
      state: 0
    }, 
    {
      pos: [10, 0, 0], 
      state: 0
    }, 
    {
      pos: [1, 0, 1], 
      state: 1
    }, 
    {
      pos: [7, 0, 1], 
      state: 0
    }, 
    {
      pos: [8, 0, 1], 
      state: 0
    }, 
    {
      pos: [9, 0, 1], 
      state: 1
    }, 
    {
      pos: [10, 0, 1], 
      state: 0
    }, 
    {
      pos: [1, 1, 1], 
      state: 2
    }, 
    {
      pos: [9, 1, 1], 
      state: 2
    }, 
    {
      pos: [8, 0, 2], 
      state: 0
    }, 
    {
      pos: [9, 0, 2], 
      state: 0
    }, 
    {
      pos: [10, 0, 2], 
      state: 0
    }, 
    {
      pos: [4, 0, 3], 
      state: 1
    }, 
    {
      pos: [5, 0, 3], 
      state: 1
    }, 
    {
      pos: [6, 0, 3], 
      state: 1
    }, 
    {
      pos: [9, 0, 3], 
      state: 0
    }, 
    {
      pos: [10, 0, 3], 
      state: 0
    }, 
    {
      pos: [4, 1, 3], 
      state: 3
    }, 
    {
      pos: [5, 1, 3], 
      state: 2
    }, 
    {
      pos: [6, 1, 3], 
      state: 3
    }, 
    {
      pos: [3, 0, 4], 
      state: 1
    }, 
    {
      pos: [4, 0, 4], 
      state: 0
    }, 
    {
      pos: [5, 0, 4], 
      state: 0
    }, 
    {
      pos: [6, 0, 4], 
      state: 0
    }, 
    {
      pos: [7, 0, 4], 
      state: 1
    }, 
    {
      pos: [3, 1, 4], 
      state: 3
    }, 
    {
      pos: [7, 1, 4], 
      state: 3
    }, 
    {
      pos: [3, 0, 5], 
      state: 1
    }, 
    {
      pos: [4, 0, 5], 
      state: 0
    }, 
    {
      pos: [5, 0, 5], 
      state: 1
    }, 
    {
      pos: [6, 0, 5], 
      state: 0
    }, 
    {
      pos: [7, 0, 5], 
      state: 1
    }, 
    {
      pos: [3, 1, 5], 
      state: 2
    }, 
    {
      pos: [5, 1, 5], 
      state: 2
    }, 
    {
      pos: [7, 1, 5], 
      state: 2
    }, 
    {
      pos: [5, 2, 5], 
      state: 2
    }, 
    {
      pos: [5, 3, 5], 
      state: 2
    }, 
    {
      pos: [5, 4, 5], 
      state: 3
    }, 
    {
      pos: [5, 5, 5], 
      state: 2
    }, 
    {
      pos: [3, 0, 6], 
      state: 1
    }, 
    {
      pos: [4, 0, 6], 
      state: 0
    }, 
    {
      pos: [5, 0, 6], 
      state: 0
    }, 
    {
      pos: [6, 0, 6], 
      state: 0
    }, 
    {
      pos: [7, 0, 6], 
      state: 1
    }, 
    {
      pos: [3, 1, 6], 
      state: 3
    }, 
    {
      pos: [7, 1, 6], 
      state: 3
    }, 
    {
      pos: [0, 0, 7], 
      state: 0
    }, 
    {
      pos: [1, 0, 7], 
      state: 0
    }, 
    {
      pos: [4, 0, 7], 
      state: 1
    }, 
    {
      pos: [5, 0, 7], 
      state: 1
    }, 
    {
      pos: [6, 0, 7], 
      state: 1
    }, 
    {
      pos: [9, 0, 7], 
      state: 0
    }, 
    {
      pos: [10, 0, 7], 
      state: 0
    }, 
    {
      pos: [4, 1, 7], 
      state: 3
    }, 
    {
      pos: [5, 1, 7], 
      state: 2
    }, 
    {
      pos: [6, 1, 7], 
      state: 3
    }, 
    {
      pos: [0, 0, 8], 
      state: 0
    }, 
    {
      pos: [2, 0, 8], 
      state: 0
    }, 
    {
      pos: [8, 0, 8], 
      state: 0
    }, 
    {
      pos: [9, 0, 8], 
      state: 0
    }, 
    {
      pos: [10, 0, 8], 
      state: 0
    }, 
    {
      pos: [0, 0, 9], 
      state: 0
    }, 
    {
      pos: [1, 0, 9], 
      state: 1
    }, 
    {
      pos: [2, 0, 9], 
      state: 0
    }, 
    {
      pos: [3, 0, 9], 
      state: 0
    }, 
    {
      pos: [7, 0, 9], 
      state: 0
    }, 
    {
      pos: [8, 0, 9], 
      state: 0
    }, 
    {
      pos: [9, 0, 9], 
      state: 1
    }, 
    {
      pos: [10, 0, 9], 
      state: 0
    }, 
    {
      pos: [1, 1, 9], 
      state: 2
    }, 
    {
      pos: [9, 1, 9], 
      state: 2
    }, 
    {
      pos: [0, 0, 10], 
      state: 0
    }, 
    {
      pos: [1, 0, 10], 
      state: 0
    }, 
    {
      pos: [2, 0, 10], 
      state: 0
    }, 
    {
      pos: [3, 0, 10], 
      state: 0
    }, 
    {
      pos: [7, 0, 10], 
      state: 0
    }, 
    {
      pos: [8, 0, 10], 
      state: 0
    }, 
    {
      pos: [9, 0, 10], 
      state: 0
    }, 
    {
      pos: [10, 0, 10], 
      state: 0
    }, 
    {
      nbt: {
        target_pool: "minecraft:village/savanna/zombie/streets", 
        final_state: "minecraft:structure_void", 
        id: "minecraft:jigsaw", 
        attachement_type: "minecraft:street"
      }, 
      pos: [5, 1, 0], 
      state: 4
    }, 
    {
      nbt: {
        id: "minecraft:bell"
      }, 
      pos: [1, 2, 1], 
      state: 5
    }, 
    {
      nbt: {
        target_pool: "minecraft:village/common/cats", 
        final_state: "minecraft:grass_block", 
        id: "minecraft:jigsaw", 
        attachement_type: "minecraft:bottom"
      }, 
      pos: [1, 0, 3], 
      state: 6
    }, 
    {
      nbt: {
        id: "minecraft:banner", 
        Patterns: []
      }, 
      pos: [5, 4, 4], 
      state: 7
    }, 
    {
      nbt: {
        target_pool: "minecraft:village/savanna/zombie/streets", 
        final_state: "minecraft:structure_void", 
        id: "minecraft:jigsaw", 
        attachement_type: "minecraft:street"
      }, 
      pos: [0, 1, 5], 
      state: 8
    }, 
    {
      nbt: {
        target_pool: "minecraft:village/savanna/zombie/streets", 
        final_state: "minecraft:structure_void", 
        id: "minecraft:jigsaw", 
        attachement_type: "minecraft:street"
      }, 
      pos: [10, 1, 5], 
      state: 9
    }, 
    {
      nbt: {
        id: "minecraft:banner", 
        Patterns: []
      }, 
      pos: [4, 4, 5], 
      state: 10
    }, 
    {
      nbt: {
        id: "minecraft:banner", 
        Patterns: []
      }, 
      pos: [6, 4, 5], 
      state: 11
    }, 
    {
      nbt: {
        id: "minecraft:banner", 
        Patterns: []
      }, 
      pos: [5, 4, 6], 
      state: 12
    }, 
    {
      nbt: {
        target_pool: "minecraft:village/common/cats", 
        final_state: "minecraft:grass_block", 
        id: "minecraft:jigsaw", 
        attachement_type: "minecraft:bottom"
      }, 
      pos: [1, 0, 8], 
      state: 6
    }, 
    {
      nbt: {
        id: "minecraft:bell"
      }, 
      pos: [9, 2, 9], 
      state: 13
    }, 
    {
      nbt: {
        target_pool: "minecraft:village/savanna/zombie/streets", 
        final_state: "minecraft:structure_void", 
        id: "minecraft:jigsaw", 
        attachement_type: "minecraft:street"
      }, 
      pos: [5, 1, 10], 
      state: 14
    }, 
    {
      pos: [4, 0, 0], 
      state: 15
    }, 
    {
      pos: [5, 0, 0], 
      state: 15
    }, 
    {
      pos: [6, 0, 0], 
      state: 15
    }, 
    {
      pos: [0, 1, 0], 
      state: 16
    }, 
    {
      pos: [1, 1, 0], 
      state: 16
    }, 
    {
      pos: [2, 1, 0], 
      state: 16
    }, 
    {
      pos: [3, 1, 0], 
      state: 16
    }, 
    {
      pos: [4, 1, 0], 
      state: 16
    }, 
    {
      pos: [6, 1, 0], 
      state: 16
    }, 
    {
      pos: [7, 1, 0], 
      state: 16
    }, 
    {
      pos: [8, 1, 0], 
      state: 16
    }, 
    {
      pos: [9, 1, 0], 
      state: 16
    }, 
    {
      pos: [10, 1, 0], 
      state: 16
    }, 
    {
      pos: [0, 2, 0], 
      state: 16
    }, 
    {
      pos: [1, 2, 0], 
      state: 16
    }, 
    {
      pos: [2, 2, 0], 
      state: 16
    }, 
    {
      pos: [3, 2, 0], 
      state: 16
    }, 
    {
      pos: [4, 2, 0], 
      state: 16
    }, 
    {
      pos: [5, 2, 0], 
      state: 16
    }, 
    {
      pos: [6, 2, 0], 
      state: 16
    }, 
    {
      pos: [7, 2, 0], 
      state: 16
    }, 
    {
      pos: [8, 2, 0], 
      state: 16
    }, 
    {
      pos: [9, 2, 0], 
      state: 16
    }, 
    {
      pos: [10, 2, 0], 
      state: 16
    }, 
    {
      pos: [0, 3, 0], 
      state: 16
    }, 
    {
      pos: [1, 3, 0], 
      state: 16
    }, 
    {
      pos: [2, 3, 0], 
      state: 16
    }, 
    {
      pos: [3, 3, 0], 
      state: 16
    }, 
    {
      pos: [4, 3, 0], 
      state: 16
    }, 
    {
      pos: [5, 3, 0], 
      state: 16
    }, 
    {
      pos: [6, 3, 0], 
      state: 16
    }, 
    {
      pos: [7, 3, 0], 
      state: 16
    }, 
    {
      pos: [8, 3, 0], 
      state: 16
    }, 
    {
      pos: [9, 3, 0], 
      state: 16
    }, 
    {
      pos: [10, 3, 0], 
      state: 16
    }, 
    {
      pos: [0, 4, 0], 
      state: 16
    }, 
    {
      pos: [1, 4, 0], 
      state: 16
    }, 
    {
      pos: [2, 4, 0], 
      state: 16
    }, 
    {
      pos: [3, 4, 0], 
      state: 16
    }, 
    {
      pos: [4, 4, 0], 
      state: 16
    }, 
    {
      pos: [5, 4, 0], 
      state: 16
    }, 
    {
      pos: [6, 4, 0], 
      state: 16
    }, 
    {
      pos: [7, 4, 0], 
      state: 16
    }, 
    {
      pos: [8, 4, 0], 
      state: 16
    }, 
    {
      pos: [9, 4, 0], 
      state: 16
    }, 
    {
      pos: [10, 4, 0], 
      state: 16
    }, 
    {
      pos: [0, 5, 0], 
      state: 16
    }, 
    {
      pos: [1, 5, 0], 
      state: 16
    }, 
    {
      pos: [2, 5, 0], 
      state: 16
    }, 
    {
      pos: [3, 5, 0], 
      state: 16
    }, 
    {
      pos: [4, 5, 0], 
      state: 16
    }, 
    {
      pos: [5, 5, 0], 
      state: 16
    }, 
    {
      pos: [6, 5, 0], 
      state: 16
    }, 
    {
      pos: [7, 5, 0], 
      state: 16
    }, 
    {
      pos: [8, 5, 0], 
      state: 16
    }, 
    {
      pos: [9, 5, 0], 
      state: 16
    }, 
    {
      pos: [10, 5, 0], 
      state: 16
    }, 
    {
      pos: [4, 0, 1], 
      state: 15
    }, 
    {
      pos: [5, 0, 1], 
      state: 15
    }, 
    {
      pos: [6, 0, 1], 
      state: 15
    }, 
    {
      pos: [0, 1, 1], 
      state: 16
    }, 
    {
      pos: [2, 1, 1], 
      state: 16
    }, 
    {
      pos: [3, 1, 1], 
      state: 16
    }, 
    {
      pos: [4, 1, 1], 
      state: 16
    }, 
    {
      pos: [5, 1, 1], 
      state: 16
    }, 
    {
      pos: [6, 1, 1], 
      state: 16
    }, 
    {
      pos: [7, 1, 1], 
      state: 16
    }, 
    {
      pos: [8, 1, 1], 
      state: 16
    }, 
    {
      pos: [10, 1, 1], 
      state: 17
    }, 
    {
      pos: [0, 2, 1], 
      state: 16
    }, 
    {
      pos: [2, 2, 1], 
      state: 16
    }, 
    {
      pos: [3, 2, 1], 
      state: 16
    }, 
    {
      pos: [4, 2, 1], 
      state: 16
    }, 
    {
      pos: [5, 2, 1], 
      state: 16
    }, 
    {
      pos: [6, 2, 1], 
      state: 16
    }, 
    {
      pos: [7, 2, 1], 
      state: 16
    }, 
    {
      pos: [8, 2, 1], 
      state: 16
    }, 
    {
      pos: [9, 2, 1], 
      state: 18
    }, 
    {
      pos: [10, 2, 1], 
      state: 16
    }, 
    {
      pos: [0, 3, 1], 
      state: 16
    }, 
    {
      pos: [1, 3, 1], 
      state: 16
    }, 
    {
      pos: [2, 3, 1], 
      state: 16
    }, 
    {
      pos: [3, 3, 1], 
      state: 16
    }, 
    {
      pos: [4, 3, 1], 
      state: 16
    }, 
    {
      pos: [5, 3, 1], 
      state: 16
    }, 
    {
      pos: [6, 3, 1], 
      state: 16
    }, 
    {
      pos: [7, 3, 1], 
      state: 16
    }, 
    {
      pos: [8, 3, 1], 
      state: 16
    }, 
    {
      pos: [9, 3, 1], 
      state: 16
    }, 
    {
      pos: [10, 3, 1], 
      state: 16
    }, 
    {
      pos: [0, 4, 1], 
      state: 16
    }, 
    {
      pos: [1, 4, 1], 
      state: 16
    }, 
    {
      pos: [2, 4, 1], 
      state: 16
    }, 
    {
      pos: [3, 4, 1], 
      state: 16
    }, 
    {
      pos: [4, 4, 1], 
      state: 16
    }, 
    {
      pos: [5, 4, 1], 
      state: 16
    }, 
    {
      pos: [6, 4, 1], 
      state: 16
    }, 
    {
      pos: [7, 4, 1], 
      state: 16
    }, 
    {
      pos: [8, 4, 1], 
      state: 16
    }, 
    {
      pos: [9, 4, 1], 
      state: 16
    }, 
    {
      pos: [10, 4, 1], 
      state: 16
    }, 
    {
      pos: [0, 5, 1], 
      state: 16
    }, 
    {
      pos: [1, 5, 1], 
      state: 16
    }, 
    {
      pos: [2, 5, 1], 
      state: 16
    }, 
    {
      pos: [3, 5, 1], 
      state: 16
    }, 
    {
      pos: [4, 5, 1], 
      state: 16
    }, 
    {
      pos: [5, 5, 1], 
      state: 16
    }, 
    {
      pos: [6, 5, 1], 
      state: 16
    }, 
    {
      pos: [7, 5, 1], 
      state: 16
    }, 
    {
      pos: [8, 5, 1], 
      state: 16
    }, 
    {
      pos: [9, 5, 1], 
      state: 16
    }, 
    {
      pos: [10, 5, 1], 
      state: 16
    }, 
    {
      pos: [3, 0, 2], 
      state: 15
    }, 
    {
      pos: [4, 0, 2], 
      state: 15
    }, 
    {
      pos: [5, 0, 2], 
      state: 15
    }, 
    {
      pos: [6, 0, 2], 
      state: 15
    }, 
    {
      pos: [7, 0, 2], 
      state: 15
    }, 
    {
      pos: [0, 1, 2], 
      state: 16
    }, 
    {
      pos: [1, 1, 2], 
      state: 16
    }, 
    {
      pos: [2, 1, 2], 
      state: 16
    }, 
    {
      pos: [3, 1, 2], 
      state: 16
    }, 
    {
      pos: [4, 1, 2], 
      state: 16
    }, 
    {
      pos: [5, 1, 2], 
      state: 16
    }, 
    {
      pos: [6, 1, 2], 
      state: 16
    }, 
    {
      pos: [7, 1, 2], 
      state: 16
    }, 
    {
      pos: [8, 1, 2], 
      state: 16
    }, 
    {
      pos: [9, 1, 2], 
      state: 16
    }, 
    {
      pos: [10, 1, 2], 
      state: 16
    }, 
    {
      pos: [0, 2, 2], 
      state: 16
    }, 
    {
      pos: [1, 2, 2], 
      state: 16
    }, 
    {
      pos: [2, 2, 2], 
      state: 16
    }, 
    {
      pos: [3, 2, 2], 
      state: 16
    }, 
    {
      pos: [4, 2, 2], 
      state: 16
    }, 
    {
      pos: [5, 2, 2], 
      state: 16
    }, 
    {
      pos: [6, 2, 2], 
      state: 16
    }, 
    {
      pos: [7, 2, 2], 
      state: 16
    }, 
    {
      pos: [8, 2, 2], 
      state: 16
    }, 
    {
      pos: [9, 2, 2], 
      state: 16
    }, 
    {
      pos: [10, 2, 2], 
      state: 16
    }, 
    {
      pos: [0, 3, 2], 
      state: 16
    }, 
    {
      pos: [1, 3, 2], 
      state: 16
    }, 
    {
      pos: [2, 3, 2], 
      state: 16
    }, 
    {
      pos: [3, 3, 2], 
      state: 16
    }, 
    {
      pos: [4, 3, 2], 
      state: 16
    }, 
    {
      pos: [5, 3, 2], 
      state: 16
    }, 
    {
      pos: [6, 3, 2], 
      state: 16
    }, 
    {
      pos: [7, 3, 2], 
      state: 16
    }, 
    {
      pos: [8, 3, 2], 
      state: 16
    }, 
    {
      pos: [9, 3, 2], 
      state: 16
    }, 
    {
      pos: [10, 3, 2], 
      state: 16
    }, 
    {
      pos: [0, 4, 2], 
      state: 16
    }, 
    {
      pos: [1, 4, 2], 
      state: 16
    }, 
    {
      pos: [2, 4, 2], 
      state: 16
    }, 
    {
      pos: [3, 4, 2], 
      state: 16
    }, 
    {
      pos: [4, 4, 2], 
      state: 16
    }, 
    {
      pos: [5, 4, 2], 
      state: 16
    }, 
    {
      pos: [6, 4, 2], 
      state: 16
    }, 
    {
      pos: [7, 4, 2], 
      state: 16
    }, 
    {
      pos: [8, 4, 2], 
      state: 16
    }, 
    {
      pos: [9, 4, 2], 
      state: 16
    }, 
    {
      pos: [10, 4, 2], 
      state: 16
    }, 
    {
      pos: [0, 5, 2], 
      state: 16
    }, 
    {
      pos: [1, 5, 2], 
      state: 16
    }, 
    {
      pos: [2, 5, 2], 
      state: 16
    }, 
    {
      pos: [3, 5, 2], 
      state: 16
    }, 
    {
      pos: [4, 5, 2], 
      state: 16
    }, 
    {
      pos: [5, 5, 2], 
      state: 16
    }, 
    {
      pos: [6, 5, 2], 
      state: 16
    }, 
    {
      pos: [7, 5, 2], 
      state: 16
    }, 
    {
      pos: [8, 5, 2], 
      state: 16
    }, 
    {
      pos: [9, 5, 2], 
      state: 16
    }, 
    {
      pos: [10, 5, 2], 
      state: 16
    }, 
    {
      pos: [2, 0, 3], 
      state: 15
    }, 
    {
      pos: [3, 0, 3], 
      state: 15
    }, 
    {
      pos: [7, 0, 3], 
      state: 15
    }, 
    {
      pos: [8, 0, 3], 
      state: 15
    }, 
    {
      pos: [0, 1, 3], 
      state: 16
    }, 
    {
      pos: [1, 1, 3], 
      state: 16
    }, 
    {
      pos: [2, 1, 3], 
      state: 16
    }, 
    {
      pos: [3, 1, 3], 
      state: 16
    }, 
    {
      pos: [7, 1, 3], 
      state: 16
    }, 
    {
      pos: [8, 1, 3], 
      state: 16
    }, 
    {
      pos: [9, 1, 3], 
      state: 16
    }, 
    {
      pos: [10, 1, 3], 
      state: 16
    }, 
    {
      pos: [0, 2, 3], 
      state: 16
    }, 
    {
      pos: [1, 2, 3], 
      state: 16
    }, 
    {
      pos: [2, 2, 3], 
      state: 16
    }, 
    {
      pos: [3, 2, 3], 
      state: 16
    }, 
    {
      pos: [4, 2, 3], 
      state: 16
    }, 
    {
      pos: [5, 2, 3], 
      state: 16
    }, 
    {
      pos: [6, 2, 3], 
      state: 16
    }, 
    {
      pos: [7, 2, 3], 
      state: 16
    }, 
    {
      pos: [8, 2, 3], 
      state: 16
    }, 
    {
      pos: [9, 2, 3], 
      state: 16
    }, 
    {
      pos: [10, 2, 3], 
      state: 16
    }, 
    {
      pos: [0, 3, 3], 
      state: 16
    }, 
    {
      pos: [1, 3, 3], 
      state: 16
    }, 
    {
      pos: [2, 3, 3], 
      state: 16
    }, 
    {
      pos: [3, 3, 3], 
      state: 16
    }, 
    {
      pos: [4, 3, 3], 
      state: 16
    }, 
    {
      pos: [5, 3, 3], 
      state: 16
    }, 
    {
      pos: [6, 3, 3], 
      state: 16
    }, 
    {
      pos: [7, 3, 3], 
      state: 16
    }, 
    {
      pos: [8, 3, 3], 
      state: 16
    }, 
    {
      pos: [9, 3, 3], 
      state: 16
    }, 
    {
      pos: [10, 3, 3], 
      state: 16
    }, 
    {
      pos: [0, 4, 3], 
      state: 16
    }, 
    {
      pos: [1, 4, 3], 
      state: 16
    }, 
    {
      pos: [2, 4, 3], 
      state: 16
    }, 
    {
      pos: [3, 4, 3], 
      state: 16
    }, 
    {
      pos: [4, 4, 3], 
      state: 16
    }, 
    {
      pos: [5, 4, 3], 
      state: 16
    }, 
    {
      pos: [6, 4, 3], 
      state: 16
    }, 
    {
      pos: [7, 4, 3], 
      state: 16
    }, 
    {
      pos: [8, 4, 3], 
      state: 16
    }, 
    {
      pos: [9, 4, 3], 
      state: 16
    }, 
    {
      pos: [10, 4, 3], 
      state: 16
    }, 
    {
      pos: [0, 5, 3], 
      state: 16
    }, 
    {
      pos: [1, 5, 3], 
      state: 16
    }, 
    {
      pos: [2, 5, 3], 
      state: 16
    }, 
    {
      pos: [3, 5, 3], 
      state: 16
    }, 
    {
      pos: [4, 5, 3], 
      state: 16
    }, 
    {
      pos: [5, 5, 3], 
      state: 16
    }, 
    {
      pos: [6, 5, 3], 
      state: 16
    }, 
    {
      pos: [7, 5, 3], 
      state: 16
    }, 
    {
      pos: [8, 5, 3], 
      state: 16
    }, 
    {
      pos: [9, 5, 3], 
      state: 16
    }, 
    {
      pos: [10, 5, 3], 
      state: 16
    }, 
    {
      pos: [0, 0, 4], 
      state: 15
    }, 
    {
      pos: [1, 0, 4], 
      state: 15
    }, 
    {
      pos: [2, 0, 4], 
      state: 15
    }, 
    {
      pos: [8, 0, 4], 
      state: 15
    }, 
    {
      pos: [9, 0, 4], 
      state: 15
    }, 
    {
      pos: [10, 0, 4], 
      state: 15
    }, 
    {
      pos: [0, 1, 4], 
      state: 16
    }, 
    {
      pos: [1, 1, 4], 
      state: 16
    }, 
    {
      pos: [2, 1, 4], 
      state: 16
    }, 
    {
      pos: [4, 1, 4], 
      state: 19
    }, 
    {
      pos: [5, 1, 4], 
      state: 19
    }, 
    {
      pos: [6, 1, 4], 
      state: 19
    }, 
    {
      pos: [8, 1, 4], 
      state: 16
    }, 
    {
      pos: [9, 1, 4], 
      state: 16
    }, 
    {
      pos: [10, 1, 4], 
      state: 16
    }, 
    {
      pos: [0, 2, 4], 
      state: 16
    }, 
    {
      pos: [1, 2, 4], 
      state: 16
    }, 
    {
      pos: [2, 2, 4], 
      state: 16
    }, 
    {
      pos: [3, 2, 4], 
      state: 16
    }, 
    {
      pos: [4, 2, 4], 
      state: 16
    }, 
    {
      pos: [5, 2, 4], 
      state: 16
    }, 
    {
      pos: [6, 2, 4], 
      state: 16
    }, 
    {
      pos: [7, 2, 4], 
      state: 16
    }, 
    {
      pos: [8, 2, 4], 
      state: 16
    }, 
    {
      pos: [9, 2, 4], 
      state: 16
    }, 
    {
      pos: [10, 2, 4], 
      state: 16
    }, 
    {
      pos: [0, 3, 4], 
      state: 16
    }, 
    {
      pos: [1, 3, 4], 
      state: 16
    }, 
    {
      pos: [2, 3, 4], 
      state: 16
    }, 
    {
      pos: [3, 3, 4], 
      state: 16
    }, 
    {
      pos: [4, 3, 4], 
      state: 16
    }, 
    {
      pos: [5, 3, 4], 
      state: 16
    }, 
    {
      pos: [6, 3, 4], 
      state: 16
    }, 
    {
      pos: [7, 3, 4], 
      state: 16
    }, 
    {
      pos: [8, 3, 4], 
      state: 16
    }, 
    {
      pos: [9, 3, 4], 
      state: 16
    }, 
    {
      pos: [10, 3, 4], 
      state: 16
    }, 
    {
      pos: [0, 4, 4], 
      state: 16
    }, 
    {
      pos: [1, 4, 4], 
      state: 16
    }, 
    {
      pos: [2, 4, 4], 
      state: 16
    }, 
    {
      pos: [3, 4, 4], 
      state: 16
    }, 
    {
      pos: [4, 4, 4], 
      state: 16
    }, 
    {
      pos: [6, 4, 4], 
      state: 16
    }, 
    {
      pos: [7, 4, 4], 
      state: 16
    }, 
    {
      pos: [8, 4, 4], 
      state: 16
    }, 
    {
      pos: [9, 4, 4], 
      state: 16
    }, 
    {
      pos: [10, 4, 4], 
      state: 16
    }, 
    {
      pos: [0, 5, 4], 
      state: 16
    }, 
    {
      pos: [1, 5, 4], 
      state: 16
    }, 
    {
      pos: [2, 5, 4], 
      state: 16
    }, 
    {
      pos: [3, 5, 4], 
      state: 16
    }, 
    {
      pos: [4, 5, 4], 
      state: 16
    }, 
    {
      pos: [5, 5, 4], 
      state: 16
    }, 
    {
      pos: [6, 5, 4], 
      state: 16
    }, 
    {
      pos: [7, 5, 4], 
      state: 16
    }, 
    {
      pos: [8, 5, 4], 
      state: 16
    }, 
    {
      pos: [9, 5, 4], 
      state: 16
    }, 
    {
      pos: [10, 5, 4], 
      state: 16
    }, 
    {
      pos: [0, 0, 5], 
      state: 15
    }, 
    {
      pos: [1, 0, 5], 
      state: 15
    }, 
    {
      pos: [2, 0, 5], 
      state: 15
    }, 
    {
      pos: [8, 0, 5], 
      state: 15
    }, 
    {
      pos: [9, 0, 5], 
      state: 15
    }, 
    {
      pos: [10, 0, 5], 
      state: 15
    }, 
    {
      pos: [1, 1, 5], 
      state: 16
    }, 
    {
      pos: [2, 1, 5], 
      state: 16
    }, 
    {
      pos: [4, 1, 5], 
      state: 19
    }, 
    {
      pos: [6, 1, 5], 
      state: 19
    }, 
    {
      pos: [8, 1, 5], 
      state: 16
    }, 
    {
      pos: [9, 1, 5], 
      state: 16
    }, 
    {
      pos: [0, 2, 5], 
      state: 16
    }, 
    {
      pos: [1, 2, 5], 
      state: 16
    }, 
    {
      pos: [2, 2, 5], 
      state: 16
    }, 
    {
      pos: [3, 2, 5], 
      state: 16
    }, 
    {
      pos: [4, 2, 5], 
      state: 16
    }, 
    {
      pos: [6, 2, 5], 
      state: 16
    }, 
    {
      pos: [7, 2, 5], 
      state: 16
    }, 
    {
      pos: [8, 2, 5], 
      state: 16
    }, 
    {
      pos: [9, 2, 5], 
      state: 16
    }, 
    {
      pos: [10, 2, 5], 
      state: 16
    }, 
    {
      pos: [0, 3, 5], 
      state: 16
    }, 
    {
      pos: [1, 3, 5], 
      state: 16
    }, 
    {
      pos: [2, 3, 5], 
      state: 16
    }, 
    {
      pos: [3, 3, 5], 
      state: 16
    }, 
    {
      pos: [4, 3, 5], 
      state: 16
    }, 
    {
      pos: [6, 3, 5], 
      state: 16
    }, 
    {
      pos: [7, 3, 5], 
      state: 16
    }, 
    {
      pos: [8, 3, 5], 
      state: 16
    }, 
    {
      pos: [9, 3, 5], 
      state: 16
    }, 
    {
      pos: [10, 3, 5], 
      state: 16
    }, 
    {
      pos: [0, 4, 5], 
      state: 16
    }, 
    {
      pos: [1, 4, 5], 
      state: 16
    }, 
    {
      pos: [2, 4, 5], 
      state: 16
    }, 
    {
      pos: [3, 4, 5], 
      state: 16
    }, 
    {
      pos: [7, 4, 5], 
      state: 16
    }, 
    {
      pos: [8, 4, 5], 
      state: 16
    }, 
    {
      pos: [9, 4, 5], 
      state: 16
    }, 
    {
      pos: [10, 4, 5], 
      state: 16
    }, 
    {
      pos: [0, 5, 5], 
      state: 16
    }, 
    {
      pos: [1, 5, 5], 
      state: 16
    }, 
    {
      pos: [2, 5, 5], 
      state: 16
    }, 
    {
      pos: [3, 5, 5], 
      state: 16
    }, 
    {
      pos: [4, 5, 5], 
      state: 16
    }, 
    {
      pos: [6, 5, 5], 
      state: 16
    }, 
    {
      pos: [7, 5, 5], 
      state: 16
    }, 
    {
      pos: [8, 5, 5], 
      state: 16
    }, 
    {
      pos: [9, 5, 5], 
      state: 16
    }, 
    {
      pos: [10, 5, 5], 
      state: 16
    }, 
    {
      pos: [0, 0, 6], 
      state: 15
    }, 
    {
      pos: [1, 0, 6], 
      state: 15
    }, 
    {
      pos: [2, 0, 6], 
      state: 15
    }, 
    {
      pos: [8, 0, 6], 
      state: 15
    }, 
    {
      pos: [9, 0, 6], 
      state: 15
    }, 
    {
      pos: [10, 0, 6], 
      state: 15
    }, 
    {
      pos: [0, 1, 6], 
      state: 16
    }, 
    {
      pos: [1, 1, 6], 
      state: 16
    }, 
    {
      pos: [2, 1, 6], 
      state: 16
    }, 
    {
      pos: [4, 1, 6], 
      state: 19
    }, 
    {
      pos: [5, 1, 6], 
      state: 19
    }, 
    {
      pos: [6, 1, 6], 
      state: 19
    }, 
    {
      pos: [8, 1, 6], 
      state: 16
    }, 
    {
      pos: [9, 1, 6], 
      state: 16
    }, 
    {
      pos: [10, 1, 6], 
      state: 16
    }, 
    {
      pos: [0, 2, 6], 
      state: 16
    }, 
    {
      pos: [1, 2, 6], 
      state: 16
    }, 
    {
      pos: [2, 2, 6], 
      state: 16
    }, 
    {
      pos: [3, 2, 6], 
      state: 16
    }, 
    {
      pos: [4, 2, 6], 
      state: 16
    }, 
    {
      pos: [5, 2, 6], 
      state: 16
    }, 
    {
      pos: [6, 2, 6], 
      state: 16
    }, 
    {
      pos: [7, 2, 6], 
      state: 16
    }, 
    {
      pos: [8, 2, 6], 
      state: 16
    }, 
    {
      pos: [9, 2, 6], 
      state: 16
    }, 
    {
      pos: [10, 2, 6], 
      state: 16
    }, 
    {
      pos: [0, 3, 6], 
      state: 16
    }, 
    {
      pos: [1, 3, 6], 
      state: 16
    }, 
    {
      pos: [2, 3, 6], 
      state: 16
    }, 
    {
      pos: [3, 3, 6], 
      state: 16
    }, 
    {
      pos: [4, 3, 6], 
      state: 16
    }, 
    {
      pos: [5, 3, 6], 
      state: 16
    }, 
    {
      pos: [6, 3, 6], 
      state: 16
    }, 
    {
      pos: [7, 3, 6], 
      state: 16
    }, 
    {
      pos: [8, 3, 6], 
      state: 16
    }, 
    {
      pos: [9, 3, 6], 
      state: 16
    }, 
    {
      pos: [10, 3, 6], 
      state: 16
    }, 
    {
      pos: [0, 4, 6], 
      state: 16
    }, 
    {
      pos: [1, 4, 6], 
      state: 16
    }, 
    {
      pos: [2, 4, 6], 
      state: 16
    }, 
    {
      pos: [3, 4, 6], 
      state: 16
    }, 
    {
      pos: [4, 4, 6], 
      state: 16
    }, 
    {
      pos: [6, 4, 6], 
      state: 16
    }, 
    {
      pos: [7, 4, 6], 
      state: 16
    }, 
    {
      pos: [8, 4, 6], 
      state: 16
    }, 
    {
      pos: [9, 4, 6], 
      state: 16
    }, 
    {
      pos: [10, 4, 6], 
      state: 16
    }, 
    {
      pos: [0, 5, 6], 
      state: 16
    }, 
    {
      pos: [1, 5, 6], 
      state: 16
    }, 
    {
      pos: [2, 5, 6], 
      state: 16
    }, 
    {
      pos: [3, 5, 6], 
      state: 16
    }, 
    {
      pos: [4, 5, 6], 
      state: 16
    }, 
    {
      pos: [5, 5, 6], 
      state: 16
    }, 
    {
      pos: [6, 5, 6], 
      state: 16
    }, 
    {
      pos: [7, 5, 6], 
      state: 16
    }, 
    {
      pos: [8, 5, 6], 
      state: 16
    }, 
    {
      pos: [9, 5, 6], 
      state: 16
    }, 
    {
      pos: [10, 5, 6], 
      state: 16
    }, 
    {
      pos: [2, 0, 7], 
      state: 15
    }, 
    {
      pos: [3, 0, 7], 
      state: 15
    }, 
    {
      pos: [7, 0, 7], 
      state: 15
    }, 
    {
      pos: [8, 0, 7], 
      state: 15
    }, 
    {
      pos: [0, 1, 7], 
      state: 17
    }, 
    {
      pos: [1, 1, 7], 
      state: 17
    }, 
    {
      pos: [2, 1, 7], 
      state: 16
    }, 
    {
      pos: [3, 1, 7], 
      state: 16
    }, 
    {
      pos: [7, 1, 7], 
      state: 16
    }, 
    {
      pos: [8, 1, 7], 
      state: 16
    }, 
    {
      pos: [9, 1, 7], 
      state: 16
    }, 
    {
      pos: [10, 1, 7], 
      state: 16
    }, 
    {
      pos: [0, 2, 7], 
      state: 16
    }, 
    {
      pos: [1, 2, 7], 
      state: 16
    }, 
    {
      pos: [2, 2, 7], 
      state: 16
    }, 
    {
      pos: [3, 2, 7], 
      state: 16
    }, 
    {
      pos: [4, 2, 7], 
      state: 16
    }, 
    {
      pos: [5, 2, 7], 
      state: 16
    }, 
    {
      pos: [6, 2, 7], 
      state: 16
    }, 
    {
      pos: [7, 2, 7], 
      state: 16
    }, 
    {
      pos: [8, 2, 7], 
      state: 16
    }, 
    {
      pos: [9, 2, 7], 
      state: 16
    }, 
    {
      pos: [10, 2, 7], 
      state: 16
    }, 
    {
      pos: [0, 3, 7], 
      state: 16
    }, 
    {
      pos: [1, 3, 7], 
      state: 16
    }, 
    {
      pos: [2, 3, 7], 
      state: 16
    }, 
    {
      pos: [3, 3, 7], 
      state: 16
    }, 
    {
      pos: [4, 3, 7], 
      state: 16
    }, 
    {
      pos: [5, 3, 7], 
      state: 16
    }, 
    {
      pos: [6, 3, 7], 
      state: 16
    }, 
    {
      pos: [7, 3, 7], 
      state: 16
    }, 
    {
      pos: [8, 3, 7], 
      state: 16
    }, 
    {
      pos: [9, 3, 7], 
      state: 16
    }, 
    {
      pos: [10, 3, 7], 
      state: 16
    }, 
    {
      pos: [0, 4, 7], 
      state: 16
    }, 
    {
      pos: [1, 4, 7], 
      state: 16
    }, 
    {
      pos: [2, 4, 7], 
      state: 16
    }, 
    {
      pos: [3, 4, 7], 
      state: 16
    }, 
    {
      pos: [4, 4, 7], 
      state: 16
    }, 
    {
      pos: [5, 4, 7], 
      state: 16
    }, 
    {
      pos: [6, 4, 7], 
      state: 16
    }, 
    {
      pos: [7, 4, 7], 
      state: 16
    }, 
    {
      pos: [8, 4, 7], 
      state: 16
    }, 
    {
      pos: [9, 4, 7], 
      state: 16
    }, 
    {
      pos: [10, 4, 7], 
      state: 16
    }, 
    {
      pos: [0, 5, 7], 
      state: 16
    }, 
    {
      pos: [1, 5, 7], 
      state: 16
    }, 
    {
      pos: [2, 5, 7], 
      state: 16
    }, 
    {
      pos: [3, 5, 7], 
      state: 16
    }, 
    {
      pos: [4, 5, 7], 
      state: 16
    }, 
    {
      pos: [5, 5, 7], 
      state: 16
    }, 
    {
      pos: [6, 5, 7], 
      state: 16
    }, 
    {
      pos: [7, 5, 7], 
      state: 16
    }, 
    {
      pos: [8, 5, 7], 
      state: 16
    }, 
    {
      pos: [9, 5, 7], 
      state: 16
    }, 
    {
      pos: [10, 5, 7], 
      state: 16
    }, 
    {
      pos: [3, 0, 8], 
      state: 15
    }, 
    {
      pos: [4, 0, 8], 
      state: 15
    }, 
    {
      pos: [5, 0, 8], 
      state: 15
    }, 
    {
      pos: [6, 0, 8], 
      state: 15
    }, 
    {
      pos: [7, 0, 8], 
      state: 15
    }, 
    {
      pos: [0, 1, 8], 
      state: 17
    }, 
    {
      pos: [1, 1, 8], 
      state: 16
    }, 
    {
      pos: [2, 1, 8], 
      state: 17
    }, 
    {
      pos: [3, 1, 8], 
      state: 16
    }, 
    {
      pos: [4, 1, 8], 
      state: 16
    }, 
    {
      pos: [5, 1, 8], 
      state: 16
    }, 
    {
      pos: [6, 1, 8], 
      state: 16
    }, 
    {
      pos: [7, 1, 8], 
      state: 16
    }, 
    {
      pos: [8, 1, 8], 
      state: 16
    }, 
    {
      pos: [9, 1, 8], 
      state: 16
    }, 
    {
      pos: [10, 1, 8], 
      state: 16
    }, 
    {
      pos: [0, 2, 8], 
      state: 16
    }, 
    {
      pos: [1, 2, 8], 
      state: 16
    }, 
    {
      pos: [2, 2, 8], 
      state: 16
    }, 
    {
      pos: [3, 2, 8], 
      state: 16
    }, 
    {
      pos: [4, 2, 8], 
      state: 16
    }, 
    {
      pos: [5, 2, 8], 
      state: 16
    }, 
    {
      pos: [6, 2, 8], 
      state: 16
    }, 
    {
      pos: [7, 2, 8], 
      state: 16
    }, 
    {
      pos: [8, 2, 8], 
      state: 16
    }, 
    {
      pos: [9, 2, 8], 
      state: 16
    }, 
    {
      pos: [10, 2, 8], 
      state: 16
    }, 
    {
      pos: [0, 3, 8], 
      state: 16
    }, 
    {
      pos: [1, 3, 8], 
      state: 16
    }, 
    {
      pos: [2, 3, 8], 
      state: 16
    }, 
    {
      pos: [3, 3, 8], 
      state: 16
    }, 
    {
      pos: [4, 3, 8], 
      state: 16
    }, 
    {
      pos: [5, 3, 8], 
      state: 16
    }, 
    {
      pos: [6, 3, 8], 
      state: 16
    }, 
    {
      pos: [7, 3, 8], 
      state: 16
    }, 
    {
      pos: [8, 3, 8], 
      state: 16
    }, 
    {
      pos: [9, 3, 8], 
      state: 16
    }, 
    {
      pos: [10, 3, 8], 
      state: 16
    }, 
    {
      pos: [0, 4, 8], 
      state: 16
    }, 
    {
      pos: [1, 4, 8], 
      state: 16
    }, 
    {
      pos: [2, 4, 8], 
      state: 16
    }, 
    {
      pos: [3, 4, 8], 
      state: 16
    }, 
    {
      pos: [4, 4, 8], 
      state: 16
    }, 
    {
      pos: [5, 4, 8], 
      state: 16
    }, 
    {
      pos: [6, 4, 8], 
      state: 16
    }, 
    {
      pos: [7, 4, 8], 
      state: 16
    }, 
    {
      pos: [8, 4, 8], 
      state: 16
    }, 
    {
      pos: [9, 4, 8], 
      state: 16
    }, 
    {
      pos: [10, 4, 8], 
      state: 16
    }, 
    {
      pos: [0, 5, 8], 
      state: 16
    }, 
    {
      pos: [1, 5, 8], 
      state: 16
    }, 
    {
      pos: [2, 5, 8], 
      state: 16
    }, 
    {
      pos: [3, 5, 8], 
      state: 16
    }, 
    {
      pos: [4, 5, 8], 
      state: 16
    }, 
    {
      pos: [5, 5, 8], 
      state: 16
    }, 
    {
      pos: [6, 5, 8], 
      state: 16
    }, 
    {
      pos: [7, 5, 8], 
      state: 16
    }, 
    {
      pos: [8, 5, 8], 
      state: 16
    }, 
    {
      pos: [9, 5, 8], 
      state: 16
    }, 
    {
      pos: [10, 5, 8], 
      state: 16
    }, 
    {
      pos: [4, 0, 9], 
      state: 15
    }, 
    {
      pos: [5, 0, 9], 
      state: 15
    }, 
    {
      pos: [6, 0, 9], 
      state: 15
    }, 
    {
      pos: [0, 1, 9], 
      state: 17
    }, 
    {
      pos: [2, 1, 9], 
      state: 17
    }, 
    {
      pos: [3, 1, 9], 
      state: 16
    }, 
    {
      pos: [4, 1, 9], 
      state: 16
    }, 
    {
      pos: [5, 1, 9], 
      state: 16
    }, 
    {
      pos: [6, 1, 9], 
      state: 16
    }, 
    {
      pos: [7, 1, 9], 
      state: 16
    }, 
    {
      pos: [8, 1, 9], 
      state: 16
    }, 
    {
      pos: [10, 1, 9], 
      state: 16
    }, 
    {
      pos: [0, 2, 9], 
      state: 16
    }, 
    {
      pos: [1, 2, 9], 
      state: 18
    }, 
    {
      pos: [2, 2, 9], 
      state: 16
    }, 
    {
      pos: [3, 2, 9], 
      state: 16
    }, 
    {
      pos: [4, 2, 9], 
      state: 16
    }, 
    {
      pos: [5, 2, 9], 
      state: 16
    }, 
    {
      pos: [6, 2, 9], 
      state: 16
    }, 
    {
      pos: [7, 2, 9], 
      state: 16
    }, 
    {
      pos: [8, 2, 9], 
      state: 16
    }, 
    {
      pos: [10, 2, 9], 
      state: 16
    }, 
    {
      pos: [0, 3, 9], 
      state: 16
    }, 
    {
      pos: [1, 3, 9], 
      state: 16
    }, 
    {
      pos: [2, 3, 9], 
      state: 16
    }, 
    {
      pos: [3, 3, 9], 
      state: 16
    }, 
    {
      pos: [4, 3, 9], 
      state: 16
    }, 
    {
      pos: [5, 3, 9], 
      state: 16
    }, 
    {
      pos: [6, 3, 9], 
      state: 16
    }, 
    {
      pos: [7, 3, 9], 
      state: 16
    }, 
    {
      pos: [8, 3, 9], 
      state: 16
    }, 
    {
      pos: [9, 3, 9], 
      state: 16
    }, 
    {
      pos: [10, 3, 9], 
      state: 16
    }, 
    {
      pos: [0, 4, 9], 
      state: 16
    }, 
    {
      pos: [1, 4, 9], 
      state: 16
    }, 
    {
      pos: [2, 4, 9], 
      state: 16
    }, 
    {
      pos: [3, 4, 9], 
      state: 16
    }, 
    {
      pos: [4, 4, 9], 
      state: 16
    }, 
    {
      pos: [5, 4, 9], 
      state: 16
    }, 
    {
      pos: [6, 4, 9], 
      state: 16
    }, 
    {
      pos: [7, 4, 9], 
      state: 16
    }, 
    {
      pos: [8, 4, 9], 
      state: 16
    }, 
    {
      pos: [9, 4, 9], 
      state: 16
    }, 
    {
      pos: [10, 4, 9], 
      state: 16
    }, 
    {
      pos: [0, 5, 9], 
      state: 16
    }, 
    {
      pos: [1, 5, 9], 
      state: 16
    }, 
    {
      pos: [2, 5, 9], 
      state: 16
    }, 
    {
      pos: [3, 5, 9], 
      state: 16
    }, 
    {
      pos: [4, 5, 9], 
      state: 16
    }, 
    {
      pos: [5, 5, 9], 
      state: 16
    }, 
    {
      pos: [6, 5, 9], 
      state: 16
    }, 
    {
      pos: [7, 5, 9], 
      state: 16
    }, 
    {
      pos: [8, 5, 9], 
      state: 16
    }, 
    {
      pos: [9, 5, 9], 
      state: 16
    }, 
    {
      pos: [10, 5, 9], 
      state: 16
    }, 
    {
      pos: [4, 0, 10], 
      state: 15
    }, 
    {
      pos: [5, 0, 10], 
      state: 15
    }, 
    {
      pos: [6, 0, 10], 
      state: 15
    }, 
    {
      pos: [0, 1, 10], 
      state: 16
    }, 
    {
      pos: [1, 1, 10], 
      state: 16
    }, 
    {
      pos: [2, 1, 10], 
      state: 16
    }, 
    {
      pos: [3, 1, 10], 
      state: 17
    }, 
    {
      pos: [4, 1, 10], 
      state: 16
    }, 
    {
      pos: [6, 1, 10], 
      state: 16
    }, 
    {
      pos: [7, 1, 10], 
      state: 16
    }, 
    {
      pos: [8, 1, 10], 
      state: 16
    }, 
    {
      pos: [9, 1, 10], 
      state: 16
    }, 
    {
      pos: [10, 1, 10], 
      state: 16
    }, 
    {
      pos: [0, 2, 10], 
      state: 16
    }, 
    {
      pos: [1, 2, 10], 
      state: 16
    }, 
    {
      pos: [2, 2, 10], 
      state: 16
    }, 
    {
      pos: [3, 2, 10], 
      state: 16
    }, 
    {
      pos: [4, 2, 10], 
      state: 16
    }, 
    {
      pos: [5, 2, 10], 
      state: 16
    }, 
    {
      pos: [6, 2, 10], 
      state: 16
    }, 
    {
      pos: [7, 2, 10], 
      state: 16
    }, 
    {
      pos: [8, 2, 10], 
      state: 16
    }, 
    {
      pos: [9, 2, 10], 
      state: 16
    }, 
    {
      pos: [10, 2, 10], 
      state: 16
    }, 
    {
      pos: [0, 3, 10], 
      state: 16
    }, 
    {
      pos: [1, 3, 10], 
      state: 16
    }, 
    {
      pos: [2, 3, 10], 
      state: 16
    }, 
    {
      pos: [3, 3, 10], 
      state: 16
    }, 
    {
      pos: [4, 3, 10], 
      state: 16
    }, 
    {
      pos: [5, 3, 10], 
      state: 16
    }, 
    {
      pos: [6, 3, 10], 
      state: 16
    }, 
    {
      pos: [7, 3, 10], 
      state: 16
    }, 
    {
      pos: [8, 3, 10], 
      state: 16
    }, 
    {
      pos: [9, 3, 10], 
      state: 16
    }, 
    {
      pos: [10, 3, 10], 
      state: 16
    }, 
    {
      pos: [0, 4, 10], 
      state: 16
    }, 
    {
      pos: [1, 4, 10], 
      state: 16
    }, 
    {
      pos: [2, 4, 10], 
      state: 16
    }, 
    {
      pos: [3, 4, 10], 
      state: 16
    }, 
    {
      pos: [4, 4, 10], 
      state: 16
    }, 
    {
      pos: [5, 4, 10], 
      state: 16
    }, 
    {
      pos: [6, 4, 10], 
      state: 16
    }, 
    {
      pos: [7, 4, 10], 
      state: 16
    }, 
    {
      pos: [8, 4, 10], 
      state: 16
    }, 
    {
      pos: [9, 4, 10], 
      state: 16
    }, 
    {
      pos: [10, 4, 10], 
      state: 16
    }, 
    {
      pos: [0, 5, 10], 
      state: 16
    }, 
    {
      pos: [1, 5, 10], 
      state: 16
    }, 
    {
      pos: [2, 5, 10], 
      state: 16
    }, 
    {
      pos: [3, 5, 10], 
      state: 16
    }, 
    {
      pos: [4, 5, 10], 
      state: 16
    }, 
    {
      pos: [5, 5, 10], 
      state: 16
    }, 
    {
      pos: [6, 5, 10], 
      state: 16
    }, 
    {
      pos: [7, 5, 10], 
      state: 16
    }, 
    {
      pos: [8, 5, 10], 
      state: 16
    }, 
    {
      pos: [9, 5, 10], 
      state: 16
    }, 
    {
      pos: [10, 5, 10], 
      state: 16
    }
  ], 
  palette: [
    {
      Properties: {
        snowy: "false"
      }, 
      Name: "minecraft:grass_block"
    }, 
    {
      Name: "minecraft:dirt"
    }, 
    {
      Name: "minecraft:yellow_terracotta"
    }, 
    {
      Name: "minecraft:orange_terracotta"
    }, 
    {
      Properties: {
        facing: "north"
      }, 
      Name: "minecraft:jigsaw"
    }, 
    {
      Properties: {
        face: "floor", 
        facing: "east"
      }, 
      Name: "minecraft:bell"
    }, 
    {
      Properties: {
        facing: "up"
      }, 
      Name: "minecraft:jigsaw"
    }, 
    {
      Properties: {
        facing: "north"
      }, 
      Name: "minecraft:brown_wall_banner"
    }, 
    {
      Properties: {
        facing: "west"
      }, 
      Name: "minecraft:jigsaw"
    }, 
    {
      Properties: {
        facing: "east"
      }, 
      Name: "minecraft:jigsaw"
    }, 
    {
      Properties: {
        facing: "west"
      }, 
      Name: "minecraft:brown_wall_banner"
    }, 
    {
      Properties: {
        facing: "east"
      }, 
      Name: "minecraft:brown_wall_banner"
    }, 
    {
      Properties: {
        facing: "south"
      }, 
      Name: "minecraft:brown_wall_banner"
    }, 
    {
      Properties: {
        face: "floor", 
        facing: "west"
      }, 
      Name: "minecraft:bell"
    }, 
    {
      Properties: {
        facing: "south"
      }, 
      Name: "minecraft:jigsaw"
    }, 
    {
      Name: "minecraft:grass_path"
    }, 
    {
      Name: "minecraft:air"
    }, 
    {
      Name: "minecraft:grass"
    }, 
    {
      Name: "minecraft:torch"
    }, 
    {
      Properties: {
        level: "0"
      }, 
      Name: "minecraft:water"
    }
  ]
}
