{
  size: [9, 7, 9], 
  entities: [], 
  blocks: [
    {
      pos: [0, 0, 0], 
      state: 0
    }, 
    {
      pos: [3, 0, 0], 
      state: 1
    }, 
    {
      pos: [4, 0, 0], 
      state: 1
    }, 
    {
      pos: [5, 0, 0], 
      state: 1
    }, 
    {
      pos: [1, 0, 1], 
      state: 1
    }, 
    {
      pos: [2, 0, 1], 
      state: 1
    }, 
    {
      pos: [3, 0, 1], 
      state: 1
    }, 
    {
      pos: [4, 0, 1], 
      state: 1
    }, 
    {
      pos: [5, 0, 1], 
      state: 1
    }, 
    {
      pos: [6, 0, 1], 
      state: 1
    }, 
    {
      pos: [7, 0, 1], 
      state: 1
    }, 
    {
      pos: [1, 0, 2], 
      state: 1
    }, 
    {
      pos: [2, 0, 2], 
      state: 0
    }, 
    {
      pos: [3, 0, 2], 
      state: 0
    }, 
    {
      pos: [4, 0, 2], 
      state: 0
    }, 
    {
      pos: [5, 0, 2], 
      state: 0
    }, 
    {
      pos: [6, 0, 2], 
      state: 0
    }, 
    {
      pos: [7, 0, 2], 
      state: 1
    }, 
    {
      pos: [2, 1, 2], 
      state: 2
    }, 
    {
      pos: [3, 1, 2], 
      state: 2
    }, 
    {
      pos: [4, 1, 2], 
      state: 2
    }, 
    {
      pos: [5, 1, 2], 
      state: 3
    }, 
    {
      pos: [6, 1, 2], 
      state: 2
    }, 
    {
      pos: [2, 2, 2], 
      state: 2
    }, 
    {
      pos: [3, 2, 2], 
      state: 2
    }, 
    {
      pos: [4, 2, 2], 
      state: 2
    }, 
    {
      pos: [5, 2, 2], 
      state: 2
    }, 
    {
      pos: [6, 2, 2], 
      state: 2
    }, 
    {
      pos: [2, 5, 2], 
      state: 4
    }, 
    {
      pos: [6, 5, 2], 
      state: 4
    }, 
    {
      pos: [3, 6, 2], 
      state: 4
    }, 
    {
      pos: [4, 6, 2], 
      state: 4
    }, 
    {
      pos: [5, 6, 2], 
      state: 4
    }, 
    {
      pos: [0, 0, 3], 
      state: 1
    }, 
    {
      pos: [1, 0, 3], 
      state: 1
    }, 
    {
      pos: [2, 0, 3], 
      state: 0
    }, 
    {
      pos: [3, 0, 3], 
      state: 3
    }, 
    {
      pos: [4, 0, 3], 
      state: 3
    }, 
    {
      pos: [5, 0, 3], 
      state: 2
    }, 
    {
      pos: [6, 0, 3], 
      state: 0
    }, 
    {
      pos: [7, 0, 3], 
      state: 1
    }, 
    {
      pos: [8, 0, 3], 
      state: 1
    }, 
    {
      pos: [2, 1, 3], 
      state: 2
    }, 
    {
      pos: [6, 1, 3], 
      state: 2
    }, 
    {
      pos: [2, 2, 3], 
      state: 2
    }, 
    {
      pos: [6, 2, 3], 
      state: 2
    }, 
    {
      pos: [2, 5, 3], 
      state: 4
    }, 
    {
      pos: [6, 5, 3], 
      state: 4
    }, 
    {
      pos: [3, 6, 3], 
      state: 4
    }, 
    {
      pos: [4, 6, 3], 
      state: 4
    }, 
    {
      pos: [5, 6, 3], 
      state: 4
    }, 
    {
      pos: [0, 0, 4], 
      state: 1
    }, 
    {
      pos: [1, 0, 4], 
      state: 1
    }, 
    {
      pos: [2, 0, 4], 
      state: 0
    }, 
    {
      pos: [3, 0, 4], 
      state: 3
    }, 
    {
      pos: [4, 0, 4], 
      state: 3
    }, 
    {
      pos: [5, 0, 4], 
      state: 3
    }, 
    {
      pos: [6, 0, 4], 
      state: 0
    }, 
    {
      pos: [7, 0, 4], 
      state: 1
    }, 
    {
      pos: [8, 0, 4], 
      state: 1
    }, 
    {
      pos: [2, 1, 4], 
      state: 2
    }, 
    {
      pos: [6, 1, 4], 
      state: 3
    }, 
    {
      pos: [2, 2, 4], 
      state: 2
    }, 
    {
      pos: [6, 2, 4], 
      state: 2
    }, 
    {
      pos: [2, 5, 4], 
      state: 4
    }, 
    {
      pos: [6, 5, 4], 
      state: 4
    }, 
    {
      pos: [3, 6, 4], 
      state: 4
    }, 
    {
      pos: [4, 6, 4], 
      state: 4
    }, 
    {
      pos: [5, 6, 4], 
      state: 4
    }, 
    {
      pos: [0, 0, 5], 
      state: 1
    }, 
    {
      pos: [1, 0, 5], 
      state: 0
    }, 
    {
      pos: [2, 0, 5], 
      state: 0
    }, 
    {
      pos: [3, 0, 5], 
      state: 3
    }, 
    {
      pos: [4, 0, 5], 
      state: 3
    }, 
    {
      pos: [5, 0, 5], 
      state: 3
    }, 
    {
      pos: [6, 0, 5], 
      state: 0
    }, 
    {
      pos: [7, 0, 5], 
      state: 1
    }, 
    {
      pos: [8, 0, 5], 
      state: 1
    }, 
    {
      pos: [2, 1, 5], 
      state: 2
    }, 
    {
      pos: [6, 1, 5], 
      state: 2
    }, 
    {
      pos: [2, 2, 5], 
      state: 2
    }, 
    {
      pos: [6, 2, 5], 
      state: 2
    }, 
    {
      pos: [2, 5, 5], 
      state: 4
    }, 
    {
      pos: [6, 5, 5], 
      state: 4
    }, 
    {
      pos: [3, 6, 5], 
      state: 4
    }, 
    {
      pos: [4, 6, 5], 
      state: 4
    }, 
    {
      pos: [5, 6, 5], 
      state: 4
    }, 
    {
      pos: [1, 0, 6], 
      state: 1
    }, 
    {
      pos: [2, 0, 6], 
      state: 0
    }, 
    {
      pos: [3, 0, 6], 
      state: 0
    }, 
    {
      pos: [4, 0, 6], 
      state: 0
    }, 
    {
      pos: [5, 0, 6], 
      state: 0
    }, 
    {
      pos: [6, 0, 6], 
      state: 0
    }, 
    {
      pos: [7, 0, 6], 
      state: 1
    }, 
    {
      pos: [2, 1, 6], 
      state: 2
    }, 
    {
      pos: [3, 1, 6], 
      state: 2
    }, 
    {
      pos: [4, 1, 6], 
      state: 2
    }, 
    {
      pos: [5, 1, 6], 
      state: 2
    }, 
    {
      pos: [6, 1, 6], 
      state: 2
    }, 
    {
      pos: [2, 2, 6], 
      state: 2
    }, 
    {
      pos: [3, 2, 6], 
      state: 2
    }, 
    {
      pos: [4, 2, 6], 
      state: 2
    }, 
    {
      pos: [5, 2, 6], 
      state: 2
    }, 
    {
      pos: [6, 2, 6], 
      state: 2
    }, 
    {
      pos: [2, 5, 6], 
      state: 6
    }, 
    {
      pos: [6, 5, 6], 
      state: 4
    }, 
    {
      pos: [3, 6, 6], 
      state: 4
    }, 
    {
      pos: [4, 6, 6], 
      state: 4
    }, 
    {
      pos: [5, 6, 6], 
      state: 4
    }, 
    {
      pos: [1, 0, 7], 
      state: 1
    }, 
    {
      pos: [2, 0, 7], 
      state: 1
    }, 
    {
      pos: [3, 0, 7], 
      state: 0
    }, 
    {
      pos: [5, 0, 7], 
      state: 1
    }, 
    {
      pos: [6, 0, 7], 
      state: 1
    }, 
    {
      pos: [7, 0, 7], 
      state: 1
    }, 
    {
      pos: [8, 0, 7], 
      state: 0
    }, 
    {
      pos: [3, 0, 8], 
      state: 1
    }, 
    {
      pos: [4, 0, 8], 
      state: 1
    }, 
    {
      nbt: {
        target_pool: "minecraft:village/taiga/zombie/decor", 
        final_state: "minecraft:grass_block", 
        id: "minecraft:jigsaw", 
        attachement_type: "minecraft:bottom"
      }, 
      pos: [0, 1, 0], 
      state: 7
    }, 
    {
      nbt: {
        target_pool: "minecraft:village/common/cats", 
        final_state: "minecraft:grass_block", 
        id: "minecraft:jigsaw", 
        attachement_type: "minecraft:bottom"
      }, 
      pos: [2, 1, 0], 
      state: 7
    }, 
    {
      nbt: {
        target_pool: "minecraft:village/taiga/zombie/streets", 
        final_state: "minecraft:structure_void", 
        id: "minecraft:jigsaw", 
        attachement_type: "minecraft:street"
      }, 
      pos: [4, 2, 0], 
      state: 8
    }, 
    {
      nbt: {
        target_pool: "minecraft:village/taiga/zombie/streets", 
        final_state: "minecraft:structure_void", 
        id: "minecraft:jigsaw", 
        attachement_type: "minecraft:street"
      }, 
      pos: [0, 2, 4], 
      state: 9
    }, 
    {
      nbt: {
        target_pool: "minecraft:village/taiga/zombie/streets", 
        final_state: "minecraft:structure_void", 
        id: "minecraft:jigsaw", 
        attachement_type: "minecraft:street"
      }, 
      pos: [8, 2, 4], 
      state: 10
    }, 
    {
      nbt: {
        id: "minecraft:bell"
      }, 
      pos: [4, 5, 4], 
      state: 11
    }, 
    {
      nbt: {
        target_pool: "minecraft:village/common/cats", 
        final_state: "minecraft:grass_block", 
        id: "minecraft:jigsaw", 
        attachement_type: "minecraft:bottom"
      }, 
      pos: [0, 1, 6], 
      state: 7
    }, 
    {
      nbt: {
        target_pool: "minecraft:village/taiga/zombie/decor", 
        final_state: "minecraft:grass_block", 
        id: "minecraft:jigsaw", 
        attachement_type: "minecraft:bottom"
      }, 
      pos: [8, 1, 7], 
      state: 7
    }, 
    {
      nbt: {
        target_pool: "minecraft:village/taiga/zombie/streets", 
        final_state: "minecraft:structure_void", 
        id: "minecraft:jigsaw", 
        attachement_type: "minecraft:street"
      }, 
      pos: [4, 2, 8], 
      state: 12
    }, 
    {
      pos: [3, 1, 0], 
      state: 13
    }, 
    {
      pos: [4, 1, 0], 
      state: 13
    }, 
    {
      pos: [5, 1, 0], 
      state: 13
    }, 
    {
      pos: [0, 2, 0], 
      state: 14
    }, 
    {
      pos: [1, 2, 0], 
      state: 14
    }, 
    {
      pos: [2, 2, 0], 
      state: 14
    }, 
    {
      pos: [3, 2, 0], 
      state: 14
    }, 
    {
      pos: [5, 2, 0], 
      state: 14
    }, 
    {
      pos: [6, 2, 0], 
      state: 14
    }, 
    {
      pos: [7, 2, 0], 
      state: 14
    }, 
    {
      pos: [8, 2, 0], 
      state: 14
    }, 
    {
      pos: [0, 3, 0], 
      state: 14
    }, 
    {
      pos: [1, 3, 0], 
      state: 14
    }, 
    {
      pos: [2, 3, 0], 
      state: 14
    }, 
    {
      pos: [3, 3, 0], 
      state: 14
    }, 
    {
      pos: [4, 3, 0], 
      state: 14
    }, 
    {
      pos: [5, 3, 0], 
      state: 14
    }, 
    {
      pos: [6, 3, 0], 
      state: 14
    }, 
    {
      pos: [7, 3, 0], 
      state: 14
    }, 
    {
      pos: [8, 3, 0], 
      state: 14
    }, 
    {
      pos: [0, 4, 0], 
      state: 14
    }, 
    {
      pos: [1, 4, 0], 
      state: 14
    }, 
    {
      pos: [2, 4, 0], 
      state: 14
    }, 
    {
      pos: [3, 4, 0], 
      state: 14
    }, 
    {
      pos: [4, 4, 0], 
      state: 14
    }, 
    {
      pos: [5, 4, 0], 
      state: 14
    }, 
    {
      pos: [6, 4, 0], 
      state: 14
    }, 
    {
      pos: [7, 4, 0], 
      state: 14
    }, 
    {
      pos: [8, 4, 0], 
      state: 14
    }, 
    {
      pos: [0, 5, 0], 
      state: 14
    }, 
    {
      pos: [1, 5, 0], 
      state: 14
    }, 
    {
      pos: [2, 5, 0], 
      state: 14
    }, 
    {
      pos: [3, 5, 0], 
      state: 14
    }, 
    {
      pos: [4, 5, 0], 
      state: 14
    }, 
    {
      pos: [5, 5, 0], 
      state: 14
    }, 
    {
      pos: [6, 5, 0], 
      state: 14
    }, 
    {
      pos: [7, 5, 0], 
      state: 14
    }, 
    {
      pos: [8, 5, 0], 
      state: 14
    }, 
    {
      pos: [0, 6, 0], 
      state: 14
    }, 
    {
      pos: [1, 6, 0], 
      state: 14
    }, 
    {
      pos: [2, 6, 0], 
      state: 14
    }, 
    {
      pos: [3, 6, 0], 
      state: 14
    }, 
    {
      pos: [4, 6, 0], 
      state: 14
    }, 
    {
      pos: [5, 6, 0], 
      state: 14
    }, 
    {
      pos: [6, 6, 0], 
      state: 14
    }, 
    {
      pos: [7, 6, 0], 
      state: 14
    }, 
    {
      pos: [8, 6, 0], 
      state: 14
    }, 
    {
      pos: [1, 1, 1], 
      state: 13
    }, 
    {
      pos: [2, 1, 1], 
      state: 13
    }, 
    {
      pos: [3, 1, 1], 
      state: 13
    }, 
    {
      pos: [4, 1, 1], 
      state: 13
    }, 
    {
      pos: [5, 1, 1], 
      state: 13
    }, 
    {
      pos: [6, 1, 1], 
      state: 13
    }, 
    {
      pos: [7, 1, 1], 
      state: 13
    }, 
    {
      pos: [0, 2, 1], 
      state: 14
    }, 
    {
      pos: [1, 2, 1], 
      state: 14
    }, 
    {
      pos: [2, 2, 1], 
      state: 14
    }, 
    {
      pos: [3, 2, 1], 
      state: 14
    }, 
    {
      pos: [4, 2, 1], 
      state: 14
    }, 
    {
      pos: [5, 2, 1], 
      state: 14
    }, 
    {
      pos: [6, 2, 1], 
      state: 14
    }, 
    {
      pos: [7, 2, 1], 
      state: 14
    }, 
    {
      pos: [8, 2, 1], 
      state: 14
    }, 
    {
      pos: [0, 3, 1], 
      state: 14
    }, 
    {
      pos: [1, 3, 1], 
      state: 14
    }, 
    {
      pos: [2, 3, 1], 
      state: 14
    }, 
    {
      pos: [3, 3, 1], 
      state: 14
    }, 
    {
      pos: [4, 3, 1], 
      state: 14
    }, 
    {
      pos: [5, 3, 1], 
      state: 14
    }, 
    {
      pos: [6, 3, 1], 
      state: 14
    }, 
    {
      pos: [7, 3, 1], 
      state: 14
    }, 
    {
      pos: [8, 3, 1], 
      state: 14
    }, 
    {
      pos: [0, 4, 1], 
      state: 14
    }, 
    {
      pos: [1, 4, 1], 
      state: 14
    }, 
    {
      pos: [2, 4, 1], 
      state: 14
    }, 
    {
      pos: [3, 4, 1], 
      state: 14
    }, 
    {
      pos: [4, 4, 1], 
      state: 14
    }, 
    {
      pos: [5, 4, 1], 
      state: 14
    }, 
    {
      pos: [6, 4, 1], 
      state: 14
    }, 
    {
      pos: [7, 4, 1], 
      state: 14
    }, 
    {
      pos: [8, 4, 1], 
      state: 14
    }, 
    {
      pos: [0, 5, 1], 
      state: 14
    }, 
    {
      pos: [1, 5, 1], 
      state: 14
    }, 
    {
      pos: [2, 5, 1], 
      state: 14
    }, 
    {
      pos: [3, 5, 1], 
      state: 14
    }, 
    {
      pos: [4, 5, 1], 
      state: 14
    }, 
    {
      pos: [5, 5, 1], 
      state: 14
    }, 
    {
      pos: [6, 5, 1], 
      state: 14
    }, 
    {
      pos: [7, 5, 1], 
      state: 14
    }, 
    {
      pos: [8, 5, 1], 
      state: 14
    }, 
    {
      pos: [0, 6, 1], 
      state: 14
    }, 
    {
      pos: [1, 6, 1], 
      state: 14
    }, 
    {
      pos: [2, 6, 1], 
      state: 14
    }, 
    {
      pos: [3, 6, 1], 
      state: 14
    }, 
    {
      pos: [4, 6, 1], 
      state: 14
    }, 
    {
      pos: [5, 6, 1], 
      state: 14
    }, 
    {
      pos: [6, 6, 1], 
      state: 14
    }, 
    {
      pos: [7, 6, 1], 
      state: 14
    }, 
    {
      pos: [8, 6, 1], 
      state: 14
    }, 
    {
      pos: [1, 1, 2], 
      state: 13
    }, 
    {
      pos: [7, 1, 2], 
      state: 13
    }, 
    {
      pos: [0, 2, 2], 
      state: 14
    }, 
    {
      pos: [1, 2, 2], 
      state: 14
    }, 
    {
      pos: [7, 2, 2], 
      state: 14
    }, 
    {
      pos: [8, 2, 2], 
      state: 14
    }, 
    {
      pos: [0, 3, 2], 
      state: 14
    }, 
    {
      pos: [1, 3, 2], 
      state: 14
    }, 
    {
      pos: [2, 3, 2], 
      state: 15
    }, 
    {
      pos: [3, 3, 2], 
      state: 14
    }, 
    {
      pos: [4, 3, 2], 
      state: 14
    }, 
    {
      pos: [5, 3, 2], 
      state: 14
    }, 
    {
      pos: [6, 3, 2], 
      state: 15
    }, 
    {
      pos: [7, 3, 2], 
      state: 14
    }, 
    {
      pos: [8, 3, 2], 
      state: 14
    }, 
    {
      pos: [0, 4, 2], 
      state: 14
    }, 
    {
      pos: [1, 4, 2], 
      state: 14
    }, 
    {
      pos: [2, 4, 2], 
      state: 15
    }, 
    {
      pos: [3, 4, 2], 
      state: 14
    }, 
    {
      pos: [4, 4, 2], 
      state: 14
    }, 
    {
      pos: [5, 4, 2], 
      state: 14
    }, 
    {
      pos: [6, 4, 2], 
      state: 15
    }, 
    {
      pos: [7, 4, 2], 
      state: 14
    }, 
    {
      pos: [8, 4, 2], 
      state: 14
    }, 
    {
      pos: [0, 5, 2], 
      state: 14
    }, 
    {
      pos: [1, 5, 2], 
      state: 14
    }, 
    {
      pos: [3, 5, 2], 
      state: 16
    }, 
    {
      pos: [4, 5, 2], 
      state: 16
    }, 
    {
      pos: [5, 5, 2], 
      state: 16
    }, 
    {
      pos: [7, 5, 2], 
      state: 14
    }, 
    {
      pos: [8, 5, 2], 
      state: 14
    }, 
    {
      pos: [0, 6, 2], 
      state: 14
    }, 
    {
      pos: [1, 6, 2], 
      state: 14
    }, 
    {
      pos: [2, 6, 2], 
      state: 14
    }, 
    {
      pos: [6, 6, 2], 
      state: 14
    }, 
    {
      pos: [7, 6, 2], 
      state: 14
    }, 
    {
      pos: [8, 6, 2], 
      state: 14
    }, 
    {
      pos: [0, 1, 3], 
      state: 13
    }, 
    {
      pos: [1, 1, 3], 
      state: 13
    }, 
    {
      pos: [3, 1, 3], 
      state: 17
    }, 
    {
      pos: [4, 1, 3], 
      state: 18
    }, 
    {
      pos: [5, 1, 3], 
      state: 18
    }, 
    {
      pos: [7, 1, 3], 
      state: 13
    }, 
    {
      pos: [8, 1, 3], 
      state: 13
    }, 
    {
      pos: [0, 2, 3], 
      state: 14
    }, 
    {
      pos: [1, 2, 3], 
      state: 14
    }, 
    {
      pos: [3, 2, 3], 
      state: 18
    }, 
    {
      pos: [4, 2, 3], 
      state: 18
    }, 
    {
      pos: [5, 2, 3], 
      state: 18
    }, 
    {
      pos: [7, 2, 3], 
      state: 14
    }, 
    {
      pos: [8, 2, 3], 
      state: 14
    }, 
    {
      pos: [0, 3, 3], 
      state: 14
    }, 
    {
      pos: [1, 3, 3], 
      state: 14
    }, 
    {
      pos: [2, 3, 3], 
      state: 14
    }, 
    {
      pos: [3, 3, 3], 
      state: 14
    }, 
    {
      pos: [4, 3, 3], 
      state: 14
    }, 
    {
      pos: [5, 3, 3], 
      state: 14
    }, 
    {
      pos: [6, 3, 3], 
      state: 14
    }, 
    {
      pos: [7, 3, 3], 
      state: 14
    }, 
    {
      pos: [8, 3, 3], 
      state: 14
    }, 
    {
      pos: [0, 4, 3], 
      state: 14
    }, 
    {
      pos: [1, 4, 3], 
      state: 14
    }, 
    {
      pos: [2, 4, 3], 
      state: 14
    }, 
    {
      pos: [3, 4, 3], 
      state: 14
    }, 
    {
      pos: [4, 4, 3], 
      state: 14
    }, 
    {
      pos: [5, 4, 3], 
      state: 14
    }, 
    {
      pos: [6, 4, 3], 
      state: 14
    }, 
    {
      pos: [7, 4, 3], 
      state: 14
    }, 
    {
      pos: [8, 4, 3], 
      state: 14
    }, 
    {
      pos: [0, 5, 3], 
      state: 14
    }, 
    {
      pos: [1, 5, 3], 
      state: 14
    }, 
    {
      pos: [3, 5, 3], 
      state: 14
    }, 
    {
      pos: [4, 5, 3], 
      state: 14
    }, 
    {
      pos: [5, 5, 3], 
      state: 14
    }, 
    {
      pos: [7, 5, 3], 
      state: 14
    }, 
    {
      pos: [8, 5, 3], 
      state: 14
    }, 
    {
      pos: [0, 6, 3], 
      state: 14
    }, 
    {
      pos: [1, 6, 3], 
      state: 14
    }, 
    {
      pos: [2, 6, 3], 
      state: 14
    }, 
    {
      pos: [6, 6, 3], 
      state: 14
    }, 
    {
      pos: [7, 6, 3], 
      state: 14
    }, 
    {
      pos: [8, 6, 3], 
      state: 14
    }, 
    {
      pos: [0, 1, 4], 
      state: 13
    }, 
    {
      pos: [1, 1, 4], 
      state: 13
    }, 
    {
      pos: [3, 1, 4], 
      state: 17
    }, 
    {
      pos: [4, 1, 4], 
      state: 18
    }, 
    {
      pos: [5, 1, 4], 
      state: 18
    }, 
    {
      pos: [7, 1, 4], 
      state: 13
    }, 
    {
      pos: [8, 1, 4], 
      state: 13
    }, 
    {
      pos: [1, 2, 4], 
      state: 14
    }, 
    {
      pos: [3, 2, 4], 
      state: 18
    }, 
    {
      pos: [4, 2, 4], 
      state: 18
    }, 
    {
      pos: [5, 2, 4], 
      state: 18
    }, 
    {
      pos: [7, 2, 4], 
      state: 14
    }, 
    {
      pos: [0, 3, 4], 
      state: 14
    }, 
    {
      pos: [1, 3, 4], 
      state: 14
    }, 
    {
      pos: [2, 3, 4], 
      state: 14
    }, 
    {
      pos: [3, 3, 4], 
      state: 14
    }, 
    {
      pos: [4, 3, 4], 
      state: 14
    }, 
    {
      pos: [5, 3, 4], 
      state: 14
    }, 
    {
      pos: [6, 3, 4], 
      state: 14
    }, 
    {
      pos: [7, 3, 4], 
      state: 14
    }, 
    {
      pos: [8, 3, 4], 
      state: 14
    }, 
    {
      pos: [0, 4, 4], 
      state: 14
    }, 
    {
      pos: [1, 4, 4], 
      state: 14
    }, 
    {
      pos: [2, 4, 4], 
      state: 14
    }, 
    {
      pos: [3, 4, 4], 
      state: 14
    }, 
    {
      pos: [4, 4, 4], 
      state: 14
    }, 
    {
      pos: [5, 4, 4], 
      state: 14
    }, 
    {
      pos: [6, 4, 4], 
      state: 14
    }, 
    {
      pos: [7, 4, 4], 
      state: 14
    }, 
    {
      pos: [8, 4, 4], 
      state: 14
    }, 
    {
      pos: [0, 5, 4], 
      state: 14
    }, 
    {
      pos: [1, 5, 4], 
      state: 14
    }, 
    {
      pos: [3, 5, 4], 
      state: 14
    }, 
    {
      pos: [5, 5, 4], 
      state: 14
    }, 
    {
      pos: [7, 5, 4], 
      state: 14
    }, 
    {
      pos: [8, 5, 4], 
      state: 14
    }, 
    {
      pos: [0, 6, 4], 
      state: 14
    }, 
    {
      pos: [1, 6, 4], 
      state: 14
    }, 
    {
      pos: [2, 6, 4], 
      state: 14
    }, 
    {
      pos: [6, 6, 4], 
      state: 14
    }, 
    {
      pos: [7, 6, 4], 
      state: 14
    }, 
    {
      pos: [8, 6, 4], 
      state: 14
    }, 
    {
      pos: [0, 1, 5], 
      state: 13
    }, 
    {
      pos: [1, 1, 5], 
      state: 13
    }, 
    {
      pos: [3, 1, 5], 
      state: 17
    }, 
    {
      pos: [4, 1, 5], 
      state: 17
    }, 
    {
      pos: [5, 1, 5], 
      state: 17
    }, 
    {
      pos: [7, 1, 5], 
      state: 13
    }, 
    {
      pos: [8, 1, 5], 
      state: 13
    }, 
    {
      pos: [0, 2, 5], 
      state: 14
    }, 
    {
      pos: [1, 2, 5], 
      state: 14
    }, 
    {
      pos: [3, 2, 5], 
      state: 18
    }, 
    {
      pos: [4, 2, 5], 
      state: 18
    }, 
    {
      pos: [5, 2, 5], 
      state: 18
    }, 
    {
      pos: [7, 2, 5], 
      state: 14
    }, 
    {
      pos: [8, 2, 5], 
      state: 14
    }, 
    {
      pos: [0, 3, 5], 
      state: 14
    }, 
    {
      pos: [1, 3, 5], 
      state: 14
    }, 
    {
      pos: [2, 3, 5], 
      state: 14
    }, 
    {
      pos: [3, 3, 5], 
      state: 14
    }, 
    {
      pos: [4, 3, 5], 
      state: 14
    }, 
    {
      pos: [5, 3, 5], 
      state: 14
    }, 
    {
      pos: [6, 3, 5], 
      state: 14
    }, 
    {
      pos: [7, 3, 5], 
      state: 14
    }, 
    {
      pos: [8, 3, 5], 
      state: 14
    }, 
    {
      pos: [0, 4, 5], 
      state: 14
    }, 
    {
      pos: [1, 4, 5], 
      state: 14
    }, 
    {
      pos: [2, 4, 5], 
      state: 14
    }, 
    {
      pos: [3, 4, 5], 
      state: 14
    }, 
    {
      pos: [4, 4, 5], 
      state: 14
    }, 
    {
      pos: [5, 4, 5], 
      state: 14
    }, 
    {
      pos: [6, 4, 5], 
      state: 14
    }, 
    {
      pos: [7, 4, 5], 
      state: 14
    }, 
    {
      pos: [8, 4, 5], 
      state: 14
    }, 
    {
      pos: [0, 5, 5], 
      state: 14
    }, 
    {
      pos: [1, 5, 5], 
      state: 14
    }, 
    {
      pos: [3, 5, 5], 
      state: 14
    }, 
    {
      pos: [4, 5, 5], 
      state: 14
    }, 
    {
      pos: [5, 5, 5], 
      state: 14
    }, 
    {
      pos: [7, 5, 5], 
      state: 14
    }, 
    {
      pos: [8, 5, 5], 
      state: 14
    }, 
    {
      pos: [0, 6, 5], 
      state: 14
    }, 
    {
      pos: [1, 6, 5], 
      state: 14
    }, 
    {
      pos: [2, 6, 5], 
      state: 14
    }, 
    {
      pos: [6, 6, 5], 
      state: 14
    }, 
    {
      pos: [7, 6, 5], 
      state: 14
    }, 
    {
      pos: [8, 6, 5], 
      state: 14
    }, 
    {
      pos: [1, 1, 6], 
      state: 13
    }, 
    {
      pos: [7, 1, 6], 
      state: 13
    }, 
    {
      pos: [0, 2, 6], 
      state: 14
    }, 
    {
      pos: [1, 2, 6], 
      state: 14
    }, 
    {
      pos: [7, 2, 6], 
      state: 14
    }, 
    {
      pos: [8, 2, 6], 
      state: 14
    }, 
    {
      pos: [0, 3, 6], 
      state: 14
    }, 
    {
      pos: [1, 3, 6], 
      state: 14
    }, 
    {
      pos: [2, 3, 6], 
      state: 15
    }, 
    {
      pos: [3, 3, 6], 
      state: 14
    }, 
    {
      pos: [4, 3, 6], 
      state: 14
    }, 
    {
      pos: [5, 3, 6], 
      state: 14
    }, 
    {
      pos: [6, 3, 6], 
      state: 15
    }, 
    {
      pos: [7, 3, 6], 
      state: 14
    }, 
    {
      pos: [8, 3, 6], 
      state: 14
    }, 
    {
      pos: [0, 4, 6], 
      state: 14
    }, 
    {
      pos: [1, 4, 6], 
      state: 14
    }, 
    {
      pos: [2, 4, 6], 
      state: 15
    }, 
    {
      pos: [3, 4, 6], 
      state: 14
    }, 
    {
      pos: [4, 4, 6], 
      state: 14
    }, 
    {
      pos: [5, 4, 6], 
      state: 14
    }, 
    {
      pos: [6, 4, 6], 
      state: 15
    }, 
    {
      pos: [7, 4, 6], 
      state: 14
    }, 
    {
      pos: [8, 4, 6], 
      state: 14
    }, 
    {
      pos: [0, 5, 6], 
      state: 14
    }, 
    {
      pos: [1, 5, 6], 
      state: 14
    }, 
    {
      pos: [3, 5, 6], 
      state: 16
    }, 
    {
      pos: [4, 5, 6], 
      state: 16
    }, 
    {
      pos: [5, 5, 6], 
      state: 16
    }, 
    {
      pos: [7, 5, 6], 
      state: 14
    }, 
    {
      pos: [8, 5, 6], 
      state: 14
    }, 
    {
      pos: [0, 6, 6], 
      state: 14
    }, 
    {
      pos: [1, 6, 6], 
      state: 14
    }, 
    {
      pos: [2, 6, 6], 
      state: 14
    }, 
    {
      pos: [6, 6, 6], 
      state: 14
    }, 
    {
      pos: [7, 6, 6], 
      state: 14
    }, 
    {
      pos: [8, 6, 6], 
      state: 14
    }, 
    {
      pos: [4, 0, 7], 
      state: 18
    }, 
    {
      pos: [1, 1, 7], 
      state: 13
    }, 
    {
      pos: [2, 1, 7], 
      state: 13
    }, 
    {
      pos: [3, 1, 7], 
      state: 13
    }, 
    {
      pos: [4, 1, 7], 
      state: 13
    }, 
    {
      pos: [5, 1, 7], 
      state: 13
    }, 
    {
      pos: [6, 1, 7], 
      state: 13
    }, 
    {
      pos: [7, 1, 7], 
      state: 13
    }, 
    {
      pos: [0, 2, 7], 
      state: 14
    }, 
    {
      pos: [1, 2, 7], 
      state: 14
    }, 
    {
      pos: [2, 2, 7], 
      state: 14
    }, 
    {
      pos: [3, 2, 7], 
      state: 14
    }, 
    {
      pos: [4, 2, 7], 
      state: 14
    }, 
    {
      pos: [5, 2, 7], 
      state: 14
    }, 
    {
      pos: [6, 2, 7], 
      state: 14
    }, 
    {
      pos: [7, 2, 7], 
      state: 14
    }, 
    {
      pos: [8, 2, 7], 
      state: 14
    }, 
    {
      pos: [0, 3, 7], 
      state: 14
    }, 
    {
      pos: [1, 3, 7], 
      state: 14
    }, 
    {
      pos: [2, 3, 7], 
      state: 14
    }, 
    {
      pos: [3, 3, 7], 
      state: 14
    }, 
    {
      pos: [4, 3, 7], 
      state: 14
    }, 
    {
      pos: [5, 3, 7], 
      state: 14
    }, 
    {
      pos: [6, 3, 7], 
      state: 14
    }, 
    {
      pos: [7, 3, 7], 
      state: 14
    }, 
    {
      pos: [8, 3, 7], 
      state: 14
    }, 
    {
      pos: [0, 4, 7], 
      state: 14
    }, 
    {
      pos: [1, 4, 7], 
      state: 14
    }, 
    {
      pos: [2, 4, 7], 
      state: 14
    }, 
    {
      pos: [3, 4, 7], 
      state: 14
    }, 
    {
      pos: [4, 4, 7], 
      state: 14
    }, 
    {
      pos: [5, 4, 7], 
      state: 14
    }, 
    {
      pos: [6, 4, 7], 
      state: 14
    }, 
    {
      pos: [7, 4, 7], 
      state: 14
    }, 
    {
      pos: [8, 4, 7], 
      state: 14
    }, 
    {
      pos: [0, 5, 7], 
      state: 14
    }, 
    {
      pos: [1, 5, 7], 
      state: 14
    }, 
    {
      pos: [2, 5, 7], 
      state: 14
    }, 
    {
      pos: [3, 5, 7], 
      state: 14
    }, 
    {
      pos: [4, 5, 7], 
      state: 14
    }, 
    {
      pos: [5, 5, 7], 
      state: 14
    }, 
    {
      pos: [6, 5, 7], 
      state: 14
    }, 
    {
      pos: [7, 5, 7], 
      state: 14
    }, 
    {
      pos: [8, 5, 7], 
      state: 14
    }, 
    {
      pos: [0, 6, 7], 
      state: 14
    }, 
    {
      pos: [1, 6, 7], 
      state: 14
    }, 
    {
      pos: [2, 6, 7], 
      state: 14
    }, 
    {
      pos: [3, 6, 7], 
      state: 14
    }, 
    {
      pos: [4, 6, 7], 
      state: 14
    }, 
    {
      pos: [5, 6, 7], 
      state: 14
    }, 
    {
      pos: [6, 6, 7], 
      state: 14
    }, 
    {
      pos: [7, 6, 7], 
      state: 14
    }, 
    {
      pos: [8, 6, 7], 
      state: 14
    }, 
    {
      pos: [0, 1, 8], 
      state: 14
    }, 
    {
      pos: [3, 1, 8], 
      state: 13
    }, 
    {
      pos: [4, 1, 8], 
      state: 13
    }, 
    {
      pos: [5, 1, 8], 
      state: 13
    }, 
    {
      pos: [6, 1, 8], 
      state: 14
    }, 
    {
      pos: [0, 2, 8], 
      state: 14
    }, 
    {
      pos: [1, 2, 8], 
      state: 14
    }, 
    {
      pos: [2, 2, 8], 
      state: 14
    }, 
    {
      pos: [3, 2, 8], 
      state: 14
    }, 
    {
      pos: [5, 2, 8], 
      state: 14
    }, 
    {
      pos: [6, 2, 8], 
      state: 14
    }, 
    {
      pos: [7, 2, 8], 
      state: 14
    }, 
    {
      pos: [8, 2, 8], 
      state: 14
    }, 
    {
      pos: [0, 3, 8], 
      state: 14
    }, 
    {
      pos: [1, 3, 8], 
      state: 14
    }, 
    {
      pos: [2, 3, 8], 
      state: 14
    }, 
    {
      pos: [3, 3, 8], 
      state: 14
    }, 
    {
      pos: [4, 3, 8], 
      state: 14
    }, 
    {
      pos: [5, 3, 8], 
      state: 14
    }, 
    {
      pos: [6, 3, 8], 
      state: 14
    }, 
    {
      pos: [7, 3, 8], 
      state: 14
    }, 
    {
      pos: [8, 3, 8], 
      state: 14
    }, 
    {
      pos: [0, 4, 8], 
      state: 14
    }, 
    {
      pos: [1, 4, 8], 
      state: 14
    }, 
    {
      pos: [2, 4, 8], 
      state: 14
    }, 
    {
      pos: [3, 4, 8], 
      state: 14
    }, 
    {
      pos: [4, 4, 8], 
      state: 14
    }, 
    {
      pos: [5, 4, 8], 
      state: 14
    }, 
    {
      pos: [6, 4, 8], 
      state: 14
    }, 
    {
      pos: [7, 4, 8], 
      state: 14
    }, 
    {
      pos: [8, 4, 8], 
      state: 14
    }, 
    {
      pos: [0, 5, 8], 
      state: 14
    }, 
    {
      pos: [1, 5, 8], 
      state: 14
    }, 
    {
      pos: [2, 5, 8], 
      state: 14
    }, 
    {
      pos: [3, 5, 8], 
      state: 14
    }, 
    {
      pos: [4, 5, 8], 
      state: 14
    }, 
    {
      pos: [5, 5, 8], 
      state: 14
    }, 
    {
      pos: [6, 5, 8], 
      state: 14
    }, 
    {
      pos: [7, 5, 8], 
      state: 14
    }, 
    {
      pos: [8, 5, 8], 
      state: 14
    }, 
    {
      pos: [0, 6, 8], 
      state: 14
    }, 
    {
      pos: [1, 6, 8], 
      state: 14
    }, 
    {
      pos: [2, 6, 8], 
      state: 14
    }, 
    {
      pos: [3, 6, 8], 
      state: 14
    }, 
    {
      pos: [4, 6, 8], 
      state: 14
    }, 
    {
      pos: [5, 6, 8], 
      state: 14
    }, 
    {
      pos: [6, 6, 8], 
      state: 14
    }, 
    {
      pos: [7, 6, 8], 
      state: 14
    }, 
    {
      pos: [8, 6, 8], 
      state: 14
    }
  ], 
  palette: [
    {
      Name: "minecraft:dirt"
    }, 
    {
      Properties: {
        snowy: "false"
      }, 
      Name: "minecraft:grass_block"
    }, 
    {
      Name: "minecraft:cobblestone"
    }, 
    {
      Name: "minecraft:mossy_cobblestone"
    }, 
    {
      Properties: {
        axis: "z"
      }, 
      Name: "minecraft:spruce_log"
    }, 
    {
      Properties: {
        axis: "x"
      }, 
      Name: "minecraft:spruce_log"
    }, 
    {
      Properties: {
        axis: "y"
      }, 
      Name: "minecraft:spruce_log"
    }, 
    {
      Properties: {
        facing: "up"
      }, 
      Name: "minecraft:jigsaw"
    }, 
    {
      Properties: {
        facing: "north"
      }, 
      Name: "minecraft:jigsaw"
    }, 
    {
      Properties: {
        facing: "west"
      }, 
      Name: "minecraft:jigsaw"
    }, 
    {
      Properties: {
        facing: "east"
      }, 
      Name: "minecraft:jigsaw"
    }, 
    {
      Properties: {
        face: "ceiling", 
        facing: "east"
      }, 
      Name: "minecraft:bell"
    }, 
    {
      Properties: {
        facing: "south"
      }, 
      Name: "minecraft:jigsaw"
    }, 
    {
      Name: "minecraft:grass_path"
    }, 
    {
      Name: "minecraft:air"
    }, 
    {
      Properties: {
        east: "false", 
        waterlogged: "false", 
        south: "false", 
        north: "false", 
        west: "false"
      }, 
      Name: "minecraft:spruce_fence"
    }, 
    {
      Properties: {
        east: "true", 
        waterlogged: "false", 
        south: "false", 
        north: "false", 
        west: "true"
      }, 
      Name: "minecraft:spruce_fence"
    }, 
    {
      Properties: {
        level: "8"
      }, 
      Name: "minecraft:water"
    }, 
    {
      Properties: {
        level: "0"
      }, 
      Name: "minecraft:water"
    }
  ]
}
