{
  size: [6, 4, 5], 
  entities: [], 
  blocks: [
    {
      pos: [0, 0, 3], 
      state: 0
    }, 
    {
      pos: [1, 0, 0], 
      state: 0
    }, 
    {
      pos: [1, 0, 4], 
      state: 0
    }, 
    {
      pos: [2, 0, 0], 
      state: 0
    }, 
    {
      pos: [2, 0, 1], 
      state: 1
    }, 
    {
      pos: [2, 0, 4], 
      state: 0
    }, 
    {
      pos: [3, 0, 0], 
      state: 0
    }, 
    {
      pos: [3, 0, 4], 
      state: 0
    }, 
    {
      pos: [4, 0, 1], 
      state: 0
    }, 
    {
      pos: [4, 0, 2], 
      state: 0
    }, 
    {
      pos: [4, 0, 3], 
      state: 0
    }, 
    {
      pos: [5, 0, 2], 
      state: 0
    }, 
    {
      pos: [0, 1, 1], 
      state: 0
    }, 
    {
      pos: [0, 1, 3], 
      state: 0
    }, 
    {
      pos: [1, 1, 0], 
      state: 0
    }, 
    {
      pos: [1, 1, 4], 
      state: 0
    }, 
    {
      pos: [2, 1, 0], 
      state: 0
    }, 
    {
      pos: [2, 1, 4], 
      state: 0
    }, 
    {
      pos: [3, 1, 0], 
      state: 0
    }, 
    {
      pos: [3, 1, 4], 
      state: 0
    }, 
    {
      pos: [4, 1, 1], 
      state: 0
    }, 
    {
      pos: [4, 1, 2], 
      state: 0
    }, 
    {
      pos: [4, 1, 3], 
      state: 0
    }, 
    {
      pos: [5, 1, 2], 
      state: 0
    }, 
    {
      pos: [0, 2, 1], 
      state: 0
    }, 
    {
      pos: [0, 2, 2], 
      state: 0
    }, 
    {
      pos: [0, 2, 3], 
      state: 0
    }, 
    {
      pos: [1, 2, 1], 
      state: 0
    }, 
    {
      pos: [1, 2, 2], 
      state: 0
    }, 
    {
      pos: [1, 2, 3], 
      state: 0
    }, 
    {
      pos: [2, 2, 1], 
      state: 0
    }, 
    {
      pos: [2, 2, 2], 
      state: 0
    }, 
    {
      pos: [2, 2, 3], 
      state: 0
    }, 
    {
      pos: [3, 2, 1], 
      state: 0
    }, 
    {
      pos: [3, 2, 2], 
      state: 0
    }, 
    {
      pos: [3, 2, 3], 
      state: 0
    }, 
    {
      pos: [4, 2, 1], 
      state: 0
    }, 
    {
      pos: [4, 2, 2], 
      state: 0
    }, 
    {
      pos: [4, 2, 3], 
      state: 0
    }, 
    {
      pos: [1, 3, 2], 
      state: 0
    }, 
    {
      pos: [2, 3, 2], 
      state: 0
    }, 
    {
      pos: [3, 3, 2], 
      state: 0
    }, 
    {
      pos: [0, 0, 0], 
      state: 2
    }, 
    {
      pos: [0, 0, 2], 
      state: 3
    }, 
    {
      pos: [0, 0, 4], 
      state: 2
    }, 
    {
      pos: [1, 0, 1], 
      state: 4
    }, 
    {
      pos: [1, 0, 2], 
      state: 5
    }, 
    {
      pos: [1, 0, 3], 
      state: 5
    }, 
    {
      pos: [2, 0, 2], 
      state: 5
    }, 
    {
      pos: [3, 0, 1], 
      state: 6
    }, 
    {
      pos: [3, 0, 2], 
      state: 5
    }, 
    {
      pos: [4, 0, 0], 
      state: 2
    }, 
    {
      pos: [4, 0, 4], 
      state: 2
    }, 
    {
      pos: [5, 0, 0], 
      state: 2
    }, 
    {
      pos: [5, 0, 1], 
      state: 2
    }, 
    {
      pos: [5, 0, 3], 
      state: 2
    }, 
    {
      pos: [5, 0, 4], 
      state: 2
    }, 
    {
      pos: [0, 1, 0], 
      state: 5
    }, 
    {
      pos: [0, 1, 2], 
      state: 7
    }, 
    {
      pos: [0, 1, 4], 
      state: 5
    }, 
    {
      pos: [1, 1, 1], 
      state: 5
    }, 
    {
      pos: [1, 1, 2], 
      state: 5
    }, 
    {
      pos: [1, 1, 3], 
      state: 5
    }, 
    {
      pos: [2, 1, 1], 
      state: 8
    }, 
    {
      pos: [2, 1, 2], 
      state: 5
    }, 
    {
      pos: [2, 1, 3], 
      state: 5
    }, 
    {
      pos: [3, 1, 1], 
      state: 5
    }, 
    {
      pos: [3, 1, 2], 
      state: 5
    }, 
    {
      pos: [3, 1, 3], 
      state: 5
    }, 
    {
      pos: [4, 1, 0], 
      state: 5
    }, 
    {
      pos: [4, 1, 4], 
      state: 5
    }, 
    {
      pos: [5, 1, 0], 
      state: 5
    }, 
    {
      pos: [5, 1, 1], 
      state: 5
    }, 
    {
      pos: [5, 1, 3], 
      state: 5
    }, 
    {
      pos: [5, 1, 4], 
      state: 5
    }, 
    {
      pos: [0, 2, 0], 
      state: 5
    }, 
    {
      pos: [0, 2, 4], 
      state: 5
    }, 
    {
      pos: [1, 2, 0], 
      state: 5
    }, 
    {
      pos: [1, 2, 4], 
      state: 5
    }, 
    {
      pos: [2, 2, 0], 
      state: 5
    }, 
    {
      pos: [2, 2, 4], 
      state: 5
    }, 
    {
      pos: [3, 2, 0], 
      state: 5
    }, 
    {
      pos: [3, 2, 4], 
      state: 5
    }, 
    {
      pos: [4, 2, 0], 
      state: 5
    }, 
    {
      pos: [4, 2, 4], 
      state: 5
    }, 
    {
      pos: [5, 2, 0], 
      state: 5
    }, 
    {
      pos: [5, 2, 1], 
      state: 5
    }, 
    {
      pos: [5, 2, 2], 
      state: 5
    }, 
    {
      pos: [5, 2, 3], 
      state: 5
    }, 
    {
      pos: [5, 2, 4], 
      state: 5
    }, 
    {
      pos: [0, 3, 0], 
      state: 5
    }, 
    {
      pos: [0, 3, 1], 
      state: 5
    }, 
    {
      pos: [0, 3, 2], 
      state: 5
    }, 
    {
      pos: [0, 3, 3], 
      state: 5
    }, 
    {
      pos: [0, 3, 4], 
      state: 5
    }, 
    {
      pos: [1, 3, 0], 
      state: 5
    }, 
    {
      pos: [1, 3, 1], 
      state: 5
    }, 
    {
      pos: [1, 3, 3], 
      state: 5
    }, 
    {
      pos: [1, 3, 4], 
      state: 5
    }, 
    {
      pos: [2, 3, 0], 
      state: 5
    }, 
    {
      pos: [2, 3, 1], 
      state: 5
    }, 
    {
      pos: [2, 3, 3], 
      state: 5
    }, 
    {
      pos: [2, 3, 4], 
      state: 5
    }, 
    {
      pos: [3, 3, 0], 
      state: 5
    }, 
    {
      pos: [3, 3, 1], 
      state: 5
    }, 
    {
      pos: [3, 3, 3], 
      state: 5
    }, 
    {
      pos: [3, 3, 4], 
      state: 5
    }, 
    {
      pos: [4, 3, 0], 
      state: 5
    }, 
    {
      pos: [4, 3, 1], 
      state: 5
    }, 
    {
      pos: [4, 3, 2], 
      state: 5
    }, 
    {
      pos: [4, 3, 3], 
      state: 5
    }, 
    {
      pos: [4, 3, 4], 
      state: 5
    }, 
    {
      pos: [5, 3, 0], 
      state: 5
    }, 
    {
      pos: [5, 3, 1], 
      state: 5
    }, 
    {
      pos: [5, 3, 2], 
      state: 5
    }, 
    {
      pos: [5, 3, 3], 
      state: 5
    }, 
    {
      pos: [5, 3, 4], 
      state: 5
    }, 
    {
      nbt: {
        final_state: "minecraft:snow_block", 
        name: "minecraft:building_entrance", 
        pool: "minecraft:empty", 
        joint: "aligned", 
        id: "minecraft:jigsaw", 
        target: "minecraft:building_entrance"
      }, 
      pos: [0, 0, 1], 
      state: 9
    }, 
    {
      nbt: {
        id: "minecraft:bed"
      }, 
      pos: [2, 0, 3], 
      state: 10
    }, 
    {
      nbt: {
        id: "minecraft:bed"
      }, 
      pos: [3, 0, 3], 
      state: 11
    }
  ], 
  palette: [
    {
      Name: "minecraft:snow_block"
    }, 
    {
      Properties: {
        axis: "y"
      }, 
      Name: "minecraft:stripped_spruce_log"
    }, 
    {
      Properties: {
        layers: "1"
      }, 
      Name: "minecraft:snow"
    }, 
    {
      Properties: {
        hinge: "left", 
        half: "lower", 
        powered: "false", 
        facing: "west", 
        open: "false"
      }, 
      Name: "minecraft:spruce_door"
    }, 
    {
      Properties: {
        half: "bottom", 
        waterlogged: "false", 
        shape: "straight", 
        facing: "west"
      }, 
      Name: "minecraft:spruce_stairs"
    }, 
    {
      Name: "minecraft:air"
    }, 
    {
      Properties: {
        half: "bottom", 
        waterlogged: "false", 
        shape: "straight", 
        facing: "east"
      }, 
      Name: "minecraft:spruce_stairs"
    }, 
    {
      Properties: {
        hinge: "left", 
        half: "upper", 
        powered: "false", 
        facing: "west", 
        open: "false"
      }, 
      Name: "minecraft:spruce_door"
    }, 
    {
      Name: "minecraft:torch"
    }, 
    {
      Properties: {
        orientation: "west_up"
      }, 
      Name: "minecraft:jigsaw"
    }, 
    {
      Properties: {
        part: "foot", 
        facing: "east", 
        occupied: "false"
      }, 
      Name: "minecraft:white_bed"
    }, 
    {
      Properties: {
        part: "head", 
        facing: "east", 
        occupied: "false"
      }, 
      Name: "minecraft:white_bed"
    }
  ]
}
