{
  size: [5, 5, 7], 
  entities: [], 
  blocks: [
    {
      pos: [0, 0, 0], 
      state: 0
    }, 
    {
      pos: [0, 0, 1], 
      state: 1
    }, 
    {
      pos: [0, 0, 2], 
      state: 1
    }, 
    {
      pos: [0, 0, 3], 
      state: 2
    }, 
    {
      pos: [0, 0, 4], 
      state: 1
    }, 
    {
      pos: [0, 0, 5], 
      state: 1
    }, 
    {
      pos: [0, 0, 6], 
      state: 0
    }, 
    {
      pos: [1, 0, 0], 
      state: 1
    }, 
    {
      pos: [1, 0, 1], 
      state: 2
    }, 
    {
      pos: [1, 0, 2], 
      state: 2
    }, 
    {
      pos: [1, 0, 3], 
      state: 2
    }, 
    {
      pos: [1, 0, 4], 
      state: 2
    }, 
    {
      pos: [1, 0, 5], 
      state: 2
    }, 
    {
      pos: [1, 0, 6], 
      state: 1
    }, 
    {
      pos: [2, 0, 0], 
      state: 1
    }, 
    {
      pos: [2, 0, 1], 
      state: 2
    }, 
    {
      pos: [2, 0, 3], 
      state: 2
    }, 
    {
      pos: [2, 0, 5], 
      state: 2
    }, 
    {
      pos: [2, 0, 6], 
      state: 1
    }, 
    {
      pos: [3, 0, 0], 
      state: 1
    }, 
    {
      pos: [3, 0, 1], 
      state: 2
    }, 
    {
      pos: [3, 0, 2], 
      state: 2
    }, 
    {
      pos: [3, 0, 3], 
      state: 1
    }, 
    {
      pos: [3, 0, 4], 
      state: 2
    }, 
    {
      pos: [3, 0, 5], 
      state: 2
    }, 
    {
      pos: [3, 0, 6], 
      state: 1
    }, 
    {
      pos: [4, 0, 0], 
      state: 0
    }, 
    {
      pos: [4, 0, 1], 
      state: 1
    }, 
    {
      pos: [4, 0, 2], 
      state: 1
    }, 
    {
      pos: [4, 0, 3], 
      state: 1
    }, 
    {
      pos: [4, 0, 4], 
      state: 1
    }, 
    {
      pos: [4, 0, 5], 
      state: 1
    }, 
    {
      pos: [4, 0, 6], 
      state: 0
    }, 
    {
      pos: [0, 1, 1], 
      state: 3
    }, 
    {
      pos: [0, 1, 4], 
      state: 4
    }, 
    {
      pos: [0, 1, 5], 
      state: 3
    }, 
    {
      pos: [1, 1, 0], 
      state: 3
    }, 
    {
      pos: [1, 1, 6], 
      state: 3
    }, 
    {
      pos: [2, 1, 0], 
      state: 4
    }, 
    {
      pos: [2, 1, 6], 
      state: 4
    }, 
    {
      pos: [3, 1, 0], 
      state: 3
    }, 
    {
      pos: [3, 1, 6], 
      state: 3
    }, 
    {
      pos: [4, 1, 1], 
      state: 3
    }, 
    {
      pos: [4, 1, 2], 
      state: 4
    }, 
    {
      pos: [4, 1, 3], 
      state: 4
    }, 
    {
      pos: [4, 1, 4], 
      state: 4
    }, 
    {
      pos: [4, 1, 5], 
      state: 3
    }, 
    {
      pos: [0, 2, 1], 
      state: 3
    }, 
    {
      pos: [0, 2, 2], 
      state: 4
    }, 
    {
      pos: [0, 2, 4], 
      state: 4
    }, 
    {
      pos: [0, 2, 5], 
      state: 3
    }, 
    {
      pos: [1, 2, 0], 
      state: 3
    }, 
    {
      pos: [1, 2, 6], 
      state: 3
    }, 
    {
      pos: [2, 2, 0], 
      state: 4
    }, 
    {
      pos: [2, 2, 6], 
      state: 4
    }, 
    {
      pos: [3, 2, 0], 
      state: 3
    }, 
    {
      pos: [3, 2, 6], 
      state: 3
    }, 
    {
      pos: [4, 2, 1], 
      state: 3
    }, 
    {
      pos: [4, 2, 2], 
      state: 4
    }, 
    {
      pos: [4, 2, 3], 
      state: 4
    }, 
    {
      pos: [4, 2, 4], 
      state: 4
    }, 
    {
      pos: [4, 2, 5], 
      state: 3
    }, 
    {
      pos: [0, 3, 2], 
      state: 4
    }, 
    {
      pos: [0, 3, 3], 
      state: 4
    }, 
    {
      pos: [0, 3, 4], 
      state: 4
    }, 
    {
      pos: [1, 3, 1], 
      state: 3
    }, 
    {
      pos: [1, 3, 2], 
      state: 4
    }, 
    {
      pos: [1, 3, 4], 
      state: 4
    }, 
    {
      pos: [1, 3, 5], 
      state: 3
    }, 
    {
      pos: [2, 3, 0], 
      state: 4
    }, 
    {
      pos: [2, 3, 1], 
      state: 4
    }, 
    {
      pos: [2, 3, 2], 
      state: 4
    }, 
    {
      pos: [2, 3, 4], 
      state: 4
    }, 
    {
      pos: [2, 3, 5], 
      state: 4
    }, 
    {
      pos: [2, 3, 6], 
      state: 4
    }, 
    {
      pos: [3, 3, 1], 
      state: 3
    }, 
    {
      pos: [3, 3, 2], 
      state: 4
    }, 
    {
      pos: [3, 3, 4], 
      state: 4
    }, 
    {
      pos: [3, 3, 5], 
      state: 3
    }, 
    {
      pos: [4, 3, 2], 
      state: 4
    }, 
    {
      pos: [4, 3, 3], 
      state: 4
    }, 
    {
      pos: [4, 3, 4], 
      state: 4
    }, 
    {
      pos: [1, 4, 3], 
      state: 3
    }, 
    {
      pos: [2, 4, 2], 
      state: 3
    }, 
    {
      pos: [2, 4, 3], 
      state: 4
    }, 
    {
      pos: [2, 4, 4], 
      state: 3
    }, 
    {
      pos: [3, 4, 3], 
      state: 3
    }, 
    {
      pos: [0, 1, 0], 
      state: 5
    }, 
    {
      pos: [0, 1, 3], 
      state: 6
    }, 
    {
      pos: [0, 1, 6], 
      state: 5
    }, 
    {
      pos: [1, 1, 1], 
      state: 7
    }, 
    {
      pos: [1, 1, 2], 
      state: 7
    }, 
    {
      pos: [1, 1, 3], 
      state: 7
    }, 
    {
      pos: [1, 1, 4], 
      state: 7
    }, 
    {
      pos: [1, 1, 5], 
      state: 7
    }, 
    {
      pos: [2, 1, 1], 
      state: 8
    }, 
    {
      pos: [2, 1, 2], 
      state: 7
    }, 
    {
      pos: [2, 1, 3], 
      state: 7
    }, 
    {
      pos: [2, 1, 4], 
      state: 7
    }, 
    {
      pos: [2, 1, 5], 
      state: 8
    }, 
    {
      pos: [3, 1, 1], 
      state: 9
    }, 
    {
      pos: [3, 1, 2], 
      state: 7
    }, 
    {
      pos: [3, 1, 4], 
      state: 7
    }, 
    {
      pos: [3, 1, 5], 
      state: 9
    }, 
    {
      pos: [4, 1, 0], 
      state: 5
    }, 
    {
      pos: [4, 1, 6], 
      state: 5
    }, 
    {
      pos: [0, 2, 0], 
      state: 7
    }, 
    {
      pos: [0, 2, 3], 
      state: 10
    }, 
    {
      pos: [0, 2, 6], 
      state: 7
    }, 
    {
      pos: [1, 2, 1], 
      state: 7
    }, 
    {
      pos: [1, 2, 2], 
      state: 7
    }, 
    {
      pos: [1, 2, 3], 
      state: 7
    }, 
    {
      pos: [1, 2, 4], 
      state: 7
    }, 
    {
      pos: [1, 2, 5], 
      state: 7
    }, 
    {
      pos: [2, 2, 1], 
      state: 11
    }, 
    {
      pos: [2, 2, 2], 
      state: 7
    }, 
    {
      pos: [2, 2, 3], 
      state: 7
    }, 
    {
      pos: [2, 2, 4], 
      state: 7
    }, 
    {
      pos: [2, 2, 5], 
      state: 12
    }, 
    {
      pos: [3, 2, 1], 
      state: 7
    }, 
    {
      pos: [3, 2, 2], 
      state: 7
    }, 
    {
      pos: [3, 2, 3], 
      state: 7
    }, 
    {
      pos: [3, 2, 4], 
      state: 7
    }, 
    {
      pos: [3, 2, 5], 
      state: 7
    }, 
    {
      pos: [4, 2, 0], 
      state: 7
    }, 
    {
      pos: [4, 2, 6], 
      state: 7
    }, 
    {
      pos: [0, 3, 0], 
      state: 7
    }, 
    {
      pos: [0, 3, 1], 
      state: 7
    }, 
    {
      pos: [0, 3, 5], 
      state: 7
    }, 
    {
      pos: [0, 3, 6], 
      state: 7
    }, 
    {
      pos: [1, 3, 0], 
      state: 7
    }, 
    {
      pos: [1, 3, 3], 
      state: 7
    }, 
    {
      pos: [1, 3, 6], 
      state: 7
    }, 
    {
      pos: [2, 3, 3], 
      state: 7
    }, 
    {
      pos: [3, 3, 0], 
      state: 7
    }, 
    {
      pos: [3, 3, 3], 
      state: 7
    }, 
    {
      pos: [3, 3, 6], 
      state: 7
    }, 
    {
      pos: [4, 3, 0], 
      state: 7
    }, 
    {
      pos: [4, 3, 1], 
      state: 7
    }, 
    {
      pos: [4, 3, 5], 
      state: 7
    }, 
    {
      pos: [4, 3, 6], 
      state: 7
    }, 
    {
      pos: [0, 4, 0], 
      state: 7
    }, 
    {
      pos: [0, 4, 1], 
      state: 7
    }, 
    {
      pos: [0, 4, 2], 
      state: 7
    }, 
    {
      pos: [0, 4, 3], 
      state: 7
    }, 
    {
      pos: [0, 4, 4], 
      state: 7
    }, 
    {
      pos: [0, 4, 5], 
      state: 7
    }, 
    {
      pos: [0, 4, 6], 
      state: 7
    }, 
    {
      pos: [1, 4, 0], 
      state: 7
    }, 
    {
      pos: [1, 4, 1], 
      state: 7
    }, 
    {
      pos: [1, 4, 2], 
      state: 7
    }, 
    {
      pos: [1, 4, 4], 
      state: 7
    }, 
    {
      pos: [1, 4, 5], 
      state: 7
    }, 
    {
      pos: [1, 4, 6], 
      state: 7
    }, 
    {
      pos: [2, 4, 0], 
      state: 7
    }, 
    {
      pos: [2, 4, 1], 
      state: 7
    }, 
    {
      pos: [2, 4, 5], 
      state: 7
    }, 
    {
      pos: [2, 4, 6], 
      state: 7
    }, 
    {
      pos: [3, 4, 0], 
      state: 7
    }, 
    {
      pos: [3, 4, 1], 
      state: 7
    }, 
    {
      pos: [3, 4, 2], 
      state: 7
    }, 
    {
      pos: [3, 4, 4], 
      state: 7
    }, 
    {
      pos: [3, 4, 5], 
      state: 7
    }, 
    {
      pos: [3, 4, 6], 
      state: 7
    }, 
    {
      pos: [4, 4, 0], 
      state: 7
    }, 
    {
      pos: [4, 4, 1], 
      state: 7
    }, 
    {
      pos: [4, 4, 2], 
      state: 7
    }, 
    {
      pos: [4, 4, 3], 
      state: 7
    }, 
    {
      pos: [4, 4, 4], 
      state: 7
    }, 
    {
      pos: [4, 4, 5], 
      state: 7
    }, 
    {
      pos: [4, 4, 6], 
      state: 7
    }, 
    {
      nbt: {
        joint: "rollable", 
        final_state: "minecraft:grass_block", 
        name: "minecraft:bottom", 
        pool: "minecraft:village/snowy/zombie/villagers", 
        id: "minecraft:jigsaw", 
        target: "minecraft:bottom"
      }, 
      pos: [2, 0, 2], 
      state: 13
    }, 
    {
      nbt: {
        joint: "rollable", 
        final_state: "minecraft:grass_block", 
        name: "minecraft:bottom", 
        pool: "minecraft:village/snowy/zombie/villagers", 
        id: "minecraft:jigsaw", 
        target: "minecraft:bottom"
      }, 
      pos: [2, 0, 4], 
      state: 13
    }, 
    {
      nbt: {
        joint: "aligned", 
        final_state: "minecraft:packed_ice", 
        name: "minecraft:building_entrance", 
        pool: "minecraft:empty", 
        id: "minecraft:jigsaw", 
        target: "minecraft:building_entrance"
      }, 
      pos: [0, 1, 2], 
      state: 14
    }, 
    {
      nbt: {
        lit_total_time: 0s, 
        cooking_time_spent: 0s, 
        Items: [], 
        cooking_total_time: 0s, 
        id: "minecraft:furnace", 
        lit_time_remaining: 0s, 
        RecipesUsed: {}
      }, 
      pos: [3, 1, 3], 
      state: 15
    }
  ], 
  palette: [
    {
      Properties: {
        snowy: "true"
      }, 
      Name: "minecraft:grass_block"
    }, 
    {
      Name: "minecraft:dirt"
    }, 
    {
      Properties: {
        snowy: "false"
      }, 
      Name: "minecraft:grass_block"
    }, 
    {
      Name: "minecraft:blue_ice"
    }, 
    {
      Name: "minecraft:packed_ice"
    }, 
    {
      Properties: {
        layers: "1"
      }, 
      Name: "minecraft:snow"
    }, 
    {
      Properties: {
        hinge: "right", 
        half: "lower", 
        powered: "false", 
        facing: "west", 
        open: "false"
      }, 
      Name: "minecraft:spruce_door"
    }, 
    {
      Name: "minecraft:air"
    }, 
    {
      Properties: {
        part: "foot", 
        facing: "east", 
        occupied: "false"
      }, 
      Name: "minecraft:blue_bed"
    }, 
    {
      Properties: {
        part: "head", 
        facing: "east", 
        occupied: "false"
      }, 
      Name: "minecraft:blue_bed"
    }, 
    {
      Properties: {
        hinge: "right", 
        half: "upper", 
        powered: "false", 
        facing: "west", 
        open: "false"
      }, 
      Name: "minecraft:spruce_door"
    }, 
    {
      Properties: {
        facing: "south"
      }, 
      Name: "minecraft:wall_torch"
    }, 
    {
      Properties: {
        facing: "north"
      }, 
      Name: "minecraft:wall_torch"
    }, 
    {
      Properties: {
        orientation: "up_north"
      }, 
      Name: "minecraft:jigsaw"
    }, 
    {
      Properties: {
        orientation: "west_up"
      }, 
      Name: "minecraft:jigsaw"
    }, 
    {
      Properties: {
        lit: "false", 
        facing: "west"
      }, 
      Name: "minecraft:furnace"
    }
  ]
}
