{
  size: [10, 10, 10], 
  entities: [
    {
      nbt: {
        Motion: [0.0d, 0.0d, 0.0d], 
        color: "red", 
        block_pos: [I; -108, -59, -44], 
        Invulnerable: 0b, 
        Air: 300s, 
        OnGround: 0b, 
        fall_distance: 0.0d, 
        PortalCooldown: 0, 
        Rotation: [90.0f, 0.0f], 
        Pos: [-107.5d, -58.0625d, -43.5d], 
        Fire: 0s, 
        id: "minecraft:cushion", 
        UUID: [I; -1242408236, 1047940829, -1396311312, -1764504774]
      }, 
      blockPos: [3, 2, 4], 
      pos: [3.5d, 2.9375d, 4.5d]
    }, 
    {
      nbt: {
        Motion: [0.0d, 0.0d, 0.0d], 
        color: "red", 
        block_pos: [I; -106, -59, -44], 
        Invulnerable: 0b, 
        Air: 300s, 
        OnGround: 0b, 
        fall_distance: 0.0d, 
        PortalCooldown: 0, 
        Rotation: [180.0f, 0.0f], 
        Pos: [-105.5d, -58.0625d, -43.5d], 
        Fire: 0s, 
        id: "minecraft:cushion", 
        UUID: [I; 1113026416, -1930934017, -2027335839, -199362108]
      }, 
      blockPos: [5, 2, 4], 
      pos: [5.5d, 2.9375d, 4.5d]
    }
  ], 
  blocks: [
    {
      pos: [1, 0, 2], 
      state: 0
    }, 
    {
      pos: [1, 0, 3], 
      state: 0
    }, 
    {
      pos: [1, 0, 4], 
      state: 0
    }, 
    {
      pos: [1, 0, 5], 
      state: 0
    }, 
    {
      pos: [2, 0, 2], 
      state: 0
    }, 
    {
      pos: [2, 0, 3], 
      state: 0
    }, 
    {
      pos: [2, 0, 4], 
      state: 0
    }, 
    {
      pos: [2, 0, 5], 
      state: 0
    }, 
    {
      pos: [2, 0, 6], 
      state: 0
    }, 
    {
      pos: [2, 0, 7], 
      state: 0
    }, 
    {
      pos: [3, 0, 2], 
      state: 0
    }, 
    {
      pos: [3, 0, 3], 
      state: 0
    }, 
    {
      pos: [3, 0, 4], 
      state: 0
    }, 
    {
      pos: [3, 0, 5], 
      state: 0
    }, 
    {
      pos: [3, 0, 6], 
      state: 0
    }, 
    {
      pos: [3, 0, 7], 
      state: 0
    }, 
    {
      pos: [3, 0, 8], 
      state: 0
    }, 
    {
      pos: [4, 0, 2], 
      state: 0
    }, 
    {
      pos: [4, 0, 3], 
      state: 0
    }, 
    {
      pos: [4, 0, 4], 
      state: 0
    }, 
    {
      pos: [4, 0, 5], 
      state: 0
    }, 
    {
      pos: [4, 0, 6], 
      state: 0
    }, 
    {
      pos: [4, 0, 7], 
      state: 0
    }, 
    {
      pos: [5, 0, 2], 
      state: 0
    }, 
    {
      pos: [5, 0, 3], 
      state: 0
    }, 
    {
      pos: [5, 0, 4], 
      state: 0
    }, 
    {
      pos: [5, 0, 5], 
      state: 0
    }, 
    {
      pos: [5, 0, 6], 
      state: 0
    }, 
    {
      pos: [5, 0, 7], 
      state: 0
    }, 
    {
      pos: [5, 0, 8], 
      state: 0
    }, 
    {
      pos: [6, 0, 2], 
      state: 0
    }, 
    {
      pos: [6, 0, 3], 
      state: 0
    }, 
    {
      pos: [6, 0, 4], 
      state: 0
    }, 
    {
      pos: [6, 0, 5], 
      state: 0
    }, 
    {
      pos: [6, 0, 6], 
      state: 0
    }, 
    {
      pos: [6, 0, 7], 
      state: 0
    }, 
    {
      pos: [6, 0, 8], 
      state: 0
    }, 
    {
      pos: [7, 0, 5], 
      state: 0
    }, 
    {
      pos: [7, 0, 6], 
      state: 0
    }, 
    {
      pos: [7, 0, 7], 
      state: 0
    }, 
    {
      pos: [7, 0, 8], 
      state: 0
    }, 
    {
      pos: [1, 1, 2], 
      state: 1
    }, 
    {
      pos: [1, 1, 3], 
      state: 2
    }, 
    {
      pos: [1, 1, 4], 
      state: 2
    }, 
    {
      pos: [1, 1, 5], 
      state: 2
    }, 
    {
      pos: [2, 1, 2], 
      state: 0
    }, 
    {
      pos: [2, 1, 3], 
      state: 2
    }, 
    {
      pos: [2, 1, 4], 
      state: 2
    }, 
    {
      pos: [2, 1, 5], 
      state: 2
    }, 
    {
      pos: [2, 1, 6], 
      state: 0
    }, 
    {
      pos: [2, 1, 7], 
      state: 1
    }, 
    {
      pos: [3, 1, 2], 
      state: 2
    }, 
    {
      pos: [3, 1, 3], 
      state: 2
    }, 
    {
      pos: [3, 1, 4], 
      state: 0
    }, 
    {
      pos: [3, 1, 5], 
      state: 2
    }, 
    {
      pos: [3, 1, 6], 
      state: 2
    }, 
    {
      pos: [3, 1, 7], 
      state: 2
    }, 
    {
      pos: [3, 1, 8], 
      state: 1
    }, 
    {
      pos: [4, 1, 2], 
      state: 2
    }, 
    {
      pos: [4, 1, 3], 
      state: 2
    }, 
    {
      pos: [4, 1, 4], 
      state: 2
    }, 
    {
      pos: [4, 1, 5], 
      state: 2
    }, 
    {
      pos: [4, 1, 6], 
      state: 2
    }, 
    {
      pos: [4, 1, 7], 
      state: 2
    }, 
    {
      pos: [5, 1, 2], 
      state: 1
    }, 
    {
      pos: [5, 1, 3], 
      state: 2
    }, 
    {
      pos: [5, 1, 4], 
      state: 2
    }, 
    {
      pos: [5, 1, 5], 
      state: 2
    }, 
    {
      pos: [5, 1, 6], 
      state: 2
    }, 
    {
      pos: [5, 1, 7], 
      state: 2
    }, 
    {
      pos: [5, 1, 8], 
      state: 1
    }, 
    {
      pos: [6, 1, 2], 
      state: 1
    }, 
    {
      pos: [6, 1, 3], 
      state: 1
    }, 
    {
      pos: [6, 1, 4], 
      state: 2
    }, 
    {
      pos: [6, 1, 5], 
      state: 2
    }, 
    {
      pos: [6, 1, 6], 
      state: 2
    }, 
    {
      pos: [6, 1, 7], 
      state: 2
    }, 
    {
      pos: [6, 1, 8], 
      state: 2
    }, 
    {
      pos: [7, 1, 8], 
      state: 1
    }, 
    {
      pos: [1, 2, 3], 
      state: 1
    }, 
    {
      pos: [1, 2, 4], 
      state: 1
    }, 
    {
      pos: [2, 2, 2], 
      state: 1
    }, 
    {
      pos: [2, 2, 4], 
      state: 1
    }, 
    {
      pos: [2, 2, 5], 
      state: 1
    }, 
    {
      pos: [2, 2, 6], 
      state: 1
    }, 
    {
      pos: [3, 2, 3], 
      state: 1
    }, 
    {
      pos: [3, 2, 7], 
      state: 1
    }, 
    {
      pos: [4, 2, 3], 
      state: 1
    }, 
    {
      pos: [4, 2, 5], 
      state: 0
    }, 
    {
      pos: [4, 2, 7], 
      state: 1
    }, 
    {
      pos: [5, 2, 3], 
      state: 1
    }, 
    {
      pos: [6, 2, 4], 
      state: 1
    }, 
    {
      pos: [6, 2, 5], 
      state: 1
    }, 
    {
      pos: [6, 2, 6], 
      state: 1
    }, 
    {
      pos: [7, 0, 3], 
      state: 3
    }, 
    {
      pos: [7, 0, 4], 
      state: 3
    }, 
    {
      pos: [8, 0, 3], 
      state: 3
    }, 
    {
      pos: [8, 0, 4], 
      state: 3
    }, 
    {
      pos: [7, 1, 5], 
      state: 4
    }, 
    {
      pos: [7, 1, 6], 
      state: 3
    }, 
    {
      pos: [7, 1, 7], 
      state: 3
    }, 
    {
      pos: [2, 2, 7], 
      state: 5
    }, 
    {
      pos: [3, 2, 4], 
      state: 3
    }, 
    {
      pos: [3, 2, 5], 
      state: 3
    }, 
    {
      pos: [3, 2, 8], 
      state: 6
    }, 
    {
      pos: [4, 2, 4], 
      state: 3
    }, 
    {
      pos: [4, 2, 6], 
      state: 3
    }, 
    {
      pos: [5, 2, 2], 
      state: 7
    }, 
    {
      pos: [5, 2, 4], 
      state: 3
    }, 
    {
      pos: [5, 2, 5], 
      state: 3
    }, 
    {
      pos: [5, 2, 6], 
      state: 3
    }, 
    {
      pos: [5, 2, 7], 
      state: 3
    }, 
    {
      pos: [5, 2, 8], 
      state: 8
    }, 
    {
      pos: [6, 2, 2], 
      state: 9
    }, 
    {
      pos: [6, 2, 3], 
      state: 10
    }, 
    {
      pos: [6, 2, 7], 
      state: 11
    }, 
    {
      pos: [7, 2, 8], 
      state: 8
    }, 
    {
      pos: [1, 3, 3], 
      state: 12
    }, 
    {
      pos: [1, 3, 4], 
      state: 5
    }, 
    {
      pos: [2, 3, 2], 
      state: 5
    }, 
    {
      pos: [2, 3, 4], 
      state: 6
    }, 
    {
      pos: [2, 3, 5], 
      state: 13
    }, 
    {
      pos: [3, 3, 7], 
      state: 14
    }, 
    {
      pos: [4, 3, 3], 
      state: 15
    }, 
    {
      pos: [6, 3, 5], 
      state: 10
    }, 
    {
      nbt: {
        components: {}, 
        joint: "rollable", 
        final_state: "minecraft:dirt_path", 
        name: "minecraft:end_connector", 
        placement_priority: 0, 
        pool: "minecraft:empty", 
        selection_priority: 0, 
        id: "minecraft:jigsaw", 
        target: "minecraft:connector"
      }, 
      pos: [9, 0, 4], 
      state: 16
    }, 
    {
      nbt: {
        components: {}, 
        joint: "rollable", 
        final_state: "minecraft:dirt", 
        name: "minecraft:bottom", 
        placement_priority: 0, 
        pool: "minecraft:abandoned_camp/trees/birch_bees", 
        selection_priority: 0, 
        id: "minecraft:jigsaw", 
        target: "minecraft:bottom"
      }, 
      pos: [2, 2, 3], 
      state: 17
    }, 
    {
      nbt: {
        LootTable: "minecraft:chests/abandoned_camp_secret_chest", 
        components: {}, 
        Items: [], 
        id: "minecraft:chest"
      }, 
      pos: [3, 2, 6], 
      state: 18
    }, 
    {
      nbt: {
        LootTable: "minecraft:barrels/abandoned_camp_barrel", 
        components: {}, 
        Items: [], 
        id: "minecraft:barrel"
      }, 
      pos: [3, 3, 6], 
      state: 19
    }, 
    {
      nbt: {
        components: {}, 
        Items: [], 
        CookingTimes: [I; 0, 0, 0, 0], 
        CookingTotalTimes: [I; 0, 0, 0, 0], 
        id: "minecraft:campfire"
      }, 
      pos: [4, 3, 5], 
      state: 20
    }
  ], 
  palette: [
    {
      id: "minecraft:dirt"
    }, 
    {
      id: "minecraft:grass_block", 
      properties: {
        snowy: "false"
      }
    }, 
    {
      id: "minecraft:stone"
    }, 
    {
      id: "minecraft:dirt_path"
    }, 
    {
      id: "minecraft:oak_stairs", 
      properties: {
        half: "bottom", 
        waterlogged: "false", 
        shape: "straight", 
        facing: "south"
      }
    }, 
    {
      id: "minecraft:wildflowers", 
      properties: {
        facing: "south", 
        flower_amount: "3"
      }
    }, 
    {
      id: "minecraft:dandelion"
    }, 
    {
      id: "minecraft:wildflowers", 
      properties: {
        facing: "north", 
        flower_amount: "4"
      }
    }, 
    {
      id: "minecraft:wildflowers", 
      properties: {
        facing: "east", 
        flower_amount: "3"
      }
    }, 
    {
      id: "minecraft:wildflowers", 
      properties: {
        facing: "north", 
        flower_amount: "1"
      }
    }, 
    {
      id: "minecraft:poppy"
    }, 
    {
      id: "minecraft:oak_stairs", 
      properties: {
        half: "bottom", 
        waterlogged: "false", 
        shape: "straight", 
        facing: "west"
      }
    }, 
    {
      id: "minecraft:wildflowers", 
      properties: {
        facing: "south", 
        flower_amount: "4"
      }
    }, 
    {
      id: "minecraft:wildflowers", 
      properties: {
        facing: "south", 
        flower_amount: "2"
      }
    }, 
    {
      id: "minecraft:wildflowers", 
      properties: {
        facing: "west", 
        flower_amount: "2"
      }
    }, 
    {
      id: "minecraft:wildflowers", 
      properties: {
        facing: "west", 
        flower_amount: "4"
      }
    }, 
    {
      id: "minecraft:jigsaw", 
      properties: {
        orientation: "east_up"
      }
    }, 
    {
      id: "minecraft:jigsaw", 
      properties: {
        orientation: "up_west"
      }
    }, 
    {
      id: "minecraft:oxidized_copper_chest", 
      properties: {
        waterlogged: "false", 
        facing: "north", 
        type: "single"
      }
    }, 
    {
      id: "minecraft:barrel", 
      properties: {
        facing: "east", 
        open: "false"
      }
    }, 
    {
      id: "minecraft:campfire", 
      properties: {
        waterlogged: "false", 
        signal_fire: "false", 
        lit: "false", 
        facing: "west"
      }
    }
  ]
}
