{
  size: [7, 5, 6], 
  entities: [], 
  blocks: [
    {
      pos: [0, 0, 0], 
      state: 0
    }, 
    {
      pos: [1, 0, 0], 
      state: 0
    }, 
    {
      pos: [2, 0, 0], 
      state: 1
    }, 
    {
      pos: [3, 0, 0], 
      state: 1
    }, 
    {
      pos: [4, 0, 0], 
      state: 1
    }, 
    {
      pos: [5, 0, 0], 
      state: 0
    }, 
    {
      pos: [6, 0, 0], 
      state: 0
    }, 
    {
      pos: [0, 0, 1], 
      state: 0
    }, 
    {
      pos: [1, 0, 1], 
      state: 1
    }, 
    {
      pos: [2, 0, 1], 
      state: 1
    }, 
    {
      pos: [3, 0, 1], 
      state: 2
    }, 
    {
      pos: [4, 0, 1], 
      state: 2
    }, 
    {
      pos: [5, 0, 1], 
      state: 1
    }, 
    {
      pos: [6, 0, 1], 
      state: 0
    }, 
    {
      pos: [0, 0, 2], 
      state: 0
    }, 
    {
      pos: [1, 0, 2], 
      state: 1
    }, 
    {
      pos: [2, 0, 2], 
      state: 2
    }, 
    {
      pos: [4, 0, 2], 
      state: 2
    }, 
    {
      pos: [5, 0, 2], 
      state: 1
    }, 
    {
      pos: [6, 0, 2], 
      state: 0
    }, 
    {
      pos: [0, 0, 3], 
      state: 0
    }, 
    {
      pos: [1, 0, 3], 
      state: 1
    }, 
    {
      pos: [2, 0, 3], 
      state: 2
    }, 
    {
      pos: [3, 0, 3], 
      state: 2
    }, 
    {
      pos: [4, 0, 3], 
      state: 2
    }, 
    {
      pos: [5, 0, 3], 
      state: 1
    }, 
    {
      pos: [6, 0, 3], 
      state: 0
    }, 
    {
      pos: [0, 0, 4], 
      state: 0
    }, 
    {
      pos: [1, 0, 4], 
      state: 0
    }, 
    {
      pos: [2, 0, 4], 
      state: 1
    }, 
    {
      pos: [3, 0, 4], 
      state: 2
    }, 
    {
      pos: [4, 0, 4], 
      state: 1
    }, 
    {
      pos: [5, 0, 4], 
      state: 1
    }, 
    {
      pos: [6, 0, 4], 
      state: 0
    }, 
    {
      pos: [0, 0, 5], 
      state: 2
    }, 
    {
      pos: [1, 0, 5], 
      state: 0
    }, 
    {
      pos: [2, 0, 5], 
      state: 0
    }, 
    {
      pos: [3, 0, 5], 
      state: 2
    }, 
    {
      pos: [4, 0, 5], 
      state: 0
    }, 
    {
      pos: [5, 0, 5], 
      state: 0
    }, 
    {
      pos: [6, 0, 5], 
      state: 0
    }, 
    {
      nbt: {
        final_state: "minecraft:grass_block", 
        name: "minecraft:bottom", 
        pool: "minecraft:village/snowy/zombie/villagers", 
        id: "minecraft:jigsaw", 
        target: "minecraft:bottom"
      }, 
      pos: [3, 0, 2], 
      state: 3
    }, 
    {
      pos: [2, 1, 0], 
      state: 4
    }, 
    {
      pos: [3, 1, 0], 
      state: 4
    }, 
    {
      pos: [4, 1, 0], 
      state: 4
    }, 
    {
      pos: [1, 1, 1], 
      state: 4
    }, 
    {
      pos: [2, 1, 1], 
      state: 5
    }, 
    {
      pos: [5, 1, 1], 
      state: 4
    }, 
    {
      pos: [1, 1, 2], 
      state: 4
    }, 
    {
      pos: [5, 1, 2], 
      state: 4
    }, 
    {
      pos: [1, 1, 3], 
      state: 4
    }, 
    {
      pos: [5, 1, 3], 
      state: 4
    }, 
    {
      pos: [2, 1, 4], 
      state: 4
    }, 
    {
      pos: [4, 1, 4], 
      state: 4
    }, 
    {
      pos: [5, 1, 4], 
      state: 6
    }, 
    {
      nbt: {
        id: "minecraft:bed"
      }, 
      pos: [3, 1, 1], 
      state: 7
    }, 
    {
      nbt: {
        id: "minecraft:bed"
      }, 
      pos: [4, 1, 1], 
      state: 8
    }, 
    {
      nbt: {
        final_state: "minecraft:structure_void", 
        name: "minecraft:building_entrance", 
        pool: "minecraft:empty", 
        id: "minecraft:jigsaw", 
        target: "minecraft:building_entrance"
      }, 
      pos: [3, 1, 5], 
      state: 9
    }, 
    {
      pos: [0, 1, 0], 
      state: 10
    }, 
    {
      pos: [1, 1, 0], 
      state: 10
    }, 
    {
      pos: [5, 1, 0], 
      state: 10
    }, 
    {
      pos: [6, 1, 0], 
      state: 10
    }, 
    {
      pos: [0, 1, 1], 
      state: 10
    }, 
    {
      pos: [6, 1, 1], 
      state: 10
    }, 
    {
      pos: [0, 1, 2], 
      state: 10
    }, 
    {
      pos: [2, 1, 2], 
      state: 11
    }, 
    {
      pos: [3, 1, 2], 
      state: 11
    }, 
    {
      pos: [4, 1, 2], 
      state: 11
    }, 
    {
      pos: [6, 1, 2], 
      state: 10
    }, 
    {
      pos: [0, 1, 3], 
      state: 12
    }, 
    {
      pos: [2, 1, 3], 
      state: 11
    }, 
    {
      pos: [3, 1, 3], 
      state: 11
    }, 
    {
      pos: [4, 1, 3], 
      state: 11
    }, 
    {
      pos: [6, 1, 3], 
      state: 10
    }, 
    {
      pos: [0, 1, 4], 
      state: 13
    }, 
    {
      pos: [1, 1, 4], 
      state: 12
    }, 
    {
      pos: [3, 1, 4], 
      state: 14
    }, 
    {
      pos: [6, 1, 4], 
      state: 12
    }, 
    {
      pos: [0, 1, 5], 
      state: 15
    }, 
    {
      pos: [1, 1, 5], 
      state: 10
    }, 
    {
      pos: [2, 1, 5], 
      state: 16
    }, 
    {
      pos: [4, 1, 5], 
      state: 17
    }, 
    {
      pos: [5, 1, 5], 
      state: 13
    }, 
    {
      pos: [6, 1, 5], 
      state: 10
    }, 
    {
      pos: [2, 2, 0], 
      state: 4
    }, 
    {
      pos: [3, 2, 0], 
      state: 4
    }, 
    {
      pos: [4, 2, 0], 
      state: 4
    }, 
    {
      pos: [1, 2, 1], 
      state: 4
    }, 
    {
      pos: [5, 2, 1], 
      state: 4
    }, 
    {
      pos: [1, 2, 3], 
      state: 4
    }, 
    {
      pos: [5, 2, 3], 
      state: 4
    }, 
    {
      pos: [2, 2, 4], 
      state: 4
    }, 
    {
      pos: [4, 2, 4], 
      state: 4
    }, 
    {
      pos: [0, 2, 0], 
      state: 11
    }, 
    {
      pos: [1, 2, 0], 
      state: 11
    }, 
    {
      pos: [5, 2, 0], 
      state: 11
    }, 
    {
      pos: [6, 2, 0], 
      state: 11
    }, 
    {
      pos: [0, 2, 1], 
      state: 11
    }, 
    {
      pos: [2, 2, 1], 
      state: 18
    }, 
    {
      pos: [3, 2, 1], 
      state: 11
    }, 
    {
      pos: [4, 2, 1], 
      state: 11
    }, 
    {
      pos: [6, 2, 1], 
      state: 11
    }, 
    {
      pos: [0, 2, 2], 
      state: 11
    }, 
    {
      pos: [1, 2, 2], 
      state: 19
    }, 
    {
      pos: [2, 2, 2], 
      state: 11
    }, 
    {
      pos: [3, 2, 2], 
      state: 11
    }, 
    {
      pos: [4, 2, 2], 
      state: 11
    }, 
    {
      pos: [5, 2, 2], 
      state: 19
    }, 
    {
      pos: [6, 2, 2], 
      state: 11
    }, 
    {
      pos: [0, 2, 3], 
      state: 11
    }, 
    {
      pos: [2, 2, 3], 
      state: 11
    }, 
    {
      pos: [3, 2, 3], 
      state: 11
    }, 
    {
      pos: [4, 2, 3], 
      state: 11
    }, 
    {
      pos: [6, 2, 3], 
      state: 11
    }, 
    {
      pos: [0, 2, 4], 
      state: 11
    }, 
    {
      pos: [1, 2, 4], 
      state: 11
    }, 
    {
      pos: [3, 2, 4], 
      state: 20
    }, 
    {
      pos: [5, 2, 4], 
      state: 16
    }, 
    {
      pos: [6, 2, 4], 
      state: 11
    }, 
    {
      pos: [0, 2, 5], 
      state: 11
    }, 
    {
      pos: [1, 2, 5], 
      state: 11
    }, 
    {
      pos: [2, 2, 5], 
      state: 11
    }, 
    {
      pos: [3, 2, 5], 
      state: 11
    }, 
    {
      pos: [4, 2, 5], 
      state: 11
    }, 
    {
      pos: [5, 2, 5], 
      state: 11
    }, 
    {
      pos: [6, 2, 5], 
      state: 11
    }, 
    {
      pos: [2, 3, 0], 
      state: 4
    }, 
    {
      pos: [3, 3, 0], 
      state: 4
    }, 
    {
      pos: [4, 3, 0], 
      state: 4
    }, 
    {
      pos: [1, 3, 1], 
      state: 4
    }, 
    {
      pos: [5, 3, 1], 
      state: 4
    }, 
    {
      pos: [1, 3, 2], 
      state: 4
    }, 
    {
      pos: [5, 3, 2], 
      state: 4
    }, 
    {
      pos: [1, 3, 3], 
      state: 4
    }, 
    {
      pos: [5, 3, 3], 
      state: 4
    }, 
    {
      pos: [2, 3, 4], 
      state: 4
    }, 
    {
      pos: [3, 3, 4], 
      state: 4
    }, 
    {
      pos: [4, 3, 4], 
      state: 4
    }, 
    {
      pos: [0, 3, 0], 
      state: 11
    }, 
    {
      pos: [1, 3, 0], 
      state: 11
    }, 
    {
      pos: [5, 3, 0], 
      state: 11
    }, 
    {
      pos: [6, 3, 0], 
      state: 11
    }, 
    {
      pos: [0, 3, 1], 
      state: 11
    }, 
    {
      pos: [2, 3, 1], 
      state: 11
    }, 
    {
      pos: [3, 3, 1], 
      state: 11
    }, 
    {
      pos: [4, 3, 1], 
      state: 11
    }, 
    {
      pos: [6, 3, 1], 
      state: 11
    }, 
    {
      pos: [0, 3, 2], 
      state: 11
    }, 
    {
      pos: [2, 3, 2], 
      state: 11
    }, 
    {
      pos: [3, 3, 2], 
      state: 11
    }, 
    {
      pos: [4, 3, 2], 
      state: 11
    }, 
    {
      pos: [6, 3, 2], 
      state: 11
    }, 
    {
      pos: [0, 3, 3], 
      state: 11
    }, 
    {
      pos: [2, 3, 3], 
      state: 11
    }, 
    {
      pos: [3, 3, 3], 
      state: 11
    }, 
    {
      pos: [4, 3, 3], 
      state: 11
    }, 
    {
      pos: [6, 3, 3], 
      state: 11
    }, 
    {
      pos: [0, 3, 4], 
      state: 11
    }, 
    {
      pos: [1, 3, 4], 
      state: 11
    }, 
    {
      pos: [5, 3, 4], 
      state: 11
    }, 
    {
      pos: [6, 3, 4], 
      state: 11
    }, 
    {
      pos: [0, 3, 5], 
      state: 11
    }, 
    {
      pos: [1, 3, 5], 
      state: 11
    }, 
    {
      pos: [2, 3, 5], 
      state: 11
    }, 
    {
      pos: [3, 3, 5], 
      state: 11
    }, 
    {
      pos: [4, 3, 5], 
      state: 11
    }, 
    {
      pos: [5, 3, 5], 
      state: 11
    }, 
    {
      pos: [6, 3, 5], 
      state: 11
    }, 
    {
      pos: [2, 4, 1], 
      state: 4
    }, 
    {
      pos: [3, 4, 1], 
      state: 4
    }, 
    {
      pos: [4, 4, 1], 
      state: 4
    }, 
    {
      pos: [2, 4, 2], 
      state: 4
    }, 
    {
      pos: [3, 4, 2], 
      state: 4
    }, 
    {
      pos: [4, 4, 2], 
      state: 4
    }, 
    {
      pos: [2, 4, 3], 
      state: 4
    }, 
    {
      pos: [3, 4, 3], 
      state: 4
    }, 
    {
      pos: [4, 4, 3], 
      state: 4
    }, 
    {
      pos: [0, 4, 0], 
      state: 11
    }, 
    {
      pos: [1, 4, 0], 
      state: 11
    }, 
    {
      pos: [2, 4, 0], 
      state: 11
    }, 
    {
      pos: [3, 4, 0], 
      state: 11
    }, 
    {
      pos: [4, 4, 0], 
      state: 11
    }, 
    {
      pos: [5, 4, 0], 
      state: 11
    }, 
    {
      pos: [6, 4, 0], 
      state: 11
    }, 
    {
      pos: [0, 4, 1], 
      state: 11
    }, 
    {
      pos: [1, 4, 1], 
      state: 11
    }, 
    {
      pos: [5, 4, 1], 
      state: 11
    }, 
    {
      pos: [6, 4, 1], 
      state: 11
    }, 
    {
      pos: [0, 4, 2], 
      state: 11
    }, 
    {
      pos: [1, 4, 2], 
      state: 11
    }, 
    {
      pos: [5, 4, 2], 
      state: 11
    }, 
    {
      pos: [6, 4, 2], 
      state: 11
    }, 
    {
      pos: [0, 4, 3], 
      state: 11
    }, 
    {
      pos: [1, 4, 3], 
      state: 11
    }, 
    {
      pos: [5, 4, 3], 
      state: 11
    }, 
    {
      pos: [6, 4, 3], 
      state: 11
    }, 
    {
      pos: [0, 4, 4], 
      state: 11
    }, 
    {
      pos: [1, 4, 4], 
      state: 11
    }, 
    {
      pos: [2, 4, 4], 
      state: 11
    }, 
    {
      pos: [3, 4, 4], 
      state: 11
    }, 
    {
      pos: [4, 4, 4], 
      state: 11
    }, 
    {
      pos: [5, 4, 4], 
      state: 11
    }, 
    {
      pos: [6, 4, 4], 
      state: 11
    }, 
    {
      pos: [0, 4, 5], 
      state: 11
    }, 
    {
      pos: [1, 4, 5], 
      state: 11
    }, 
    {
      pos: [2, 4, 5], 
      state: 11
    }, 
    {
      pos: [3, 4, 5], 
      state: 11
    }, 
    {
      pos: [4, 4, 5], 
      state: 11
    }, 
    {
      pos: [5, 4, 5], 
      state: 11
    }, 
    {
      pos: [6, 4, 5], 
      state: 11
    }
  ], 
  palette: [
    {
      Properties: {
        snowy: "true"
      }, 
      Name: "minecraft:grass_block"
    }, 
    {
      Name: "minecraft:dirt"
    }, 
    {
      Properties: {
        snowy: "false"
      }, 
      Name: "minecraft:grass_block"
    }, 
    {
      Properties: {
        orientation: "up_north"
      }, 
      Name: "minecraft:jigsaw"
    }, 
    {
      Name: "minecraft:packed_ice"
    }, 
    {
      Properties: {
        axis: "y"
      }, 
      Name: "minecraft:stripped_spruce_log"
    }, 
    {
      Name: "minecraft:snow_block"
    }, 
    {
      Properties: {
        part: "head", 
        facing: "west", 
        occupied: "false"
      }, 
      Name: "minecraft:blue_bed"
    }, 
    {
      Properties: {
        part: "foot", 
        facing: "west", 
        occupied: "false"
      }, 
      Name: "minecraft:blue_bed"
    }, 
    {
      Properties: {
        orientation: "south_up"
      }, 
      Name: "minecraft:jigsaw"
    }, 
    {
      Properties: {
        layers: "1"
      }, 
      Name: "minecraft:snow"
    }, 
    {
      Name: "minecraft:air"
    }, 
    {
      Properties: {
        layers: "5"
      }, 
      Name: "minecraft:snow"
    }, 
    {
      Properties: {
        layers: "3"
      }, 
      Name: "minecraft:snow"
    }, 
    {
      Properties: {
        hinge: "left", 
        half: "lower", 
        powered: "false", 
        facing: "south", 
        open: "false"
      }, 
      Name: "minecraft:spruce_door"
    }, 
    {
      Name: "minecraft:grass"
    }, 
    {
      Properties: {
        layers: "2"
      }, 
      Name: "minecraft:snow"
    }, 
    {
      Properties: {
        layers: "6"
      }, 
      Name: "minecraft:snow"
    }, 
    {
      Name: "minecraft:torch"
    }, 
    {
      Properties: {
        east: "false", 
        waterlogged: "false", 
        south: "true", 
        north: "true", 
        west: "false"
      }, 
      Name: "minecraft:glass_pane"
    }, 
    {
      Properties: {
        hinge: "left", 
        half: "upper", 
        powered: "false", 
        facing: "south", 
        open: "false"
      }, 
      Name: "minecraft:spruce_door"
    }
  ]
}
