{
  size: [9, 6, 8], 
  entities: [], 
  blocks: [
    {
      pos: [0, 0, 2], 
      state: 0
    }, 
    {
      pos: [0, 0, 3], 
      state: 0
    }, 
    {
      pos: [0, 0, 4], 
      state: 0
    }, 
    {
      pos: [0, 0, 5], 
      state: 0
    }, 
    {
      pos: [0, 0, 6], 
      state: 0
    }, 
    {
      pos: [0, 0, 7], 
      state: 0
    }, 
    {
      pos: [1, 0, 2], 
      state: 0
    }, 
    {
      pos: [1, 0, 3], 
      state: 0
    }, 
    {
      pos: [1, 0, 4], 
      state: 1
    }, 
    {
      pos: [1, 0, 5], 
      state: 1
    }, 
    {
      pos: [1, 0, 6], 
      state: 1
    }, 
    {
      pos: [1, 0, 7], 
      state: 0
    }, 
    {
      pos: [2, 0, 2], 
      state: 0
    }, 
    {
      pos: [2, 0, 3], 
      state: 1
    }, 
    {
      pos: [2, 0, 5], 
      state: 1
    }, 
    {
      pos: [2, 0, 6], 
      state: 1
    }, 
    {
      pos: [2, 0, 7], 
      state: 0
    }, 
    {
      pos: [3, 0, 2], 
      state: 0
    }, 
    {
      pos: [3, 0, 3], 
      state: 1
    }, 
    {
      pos: [3, 0, 4], 
      state: 1
    }, 
    {
      pos: [3, 0, 5], 
      state: 2
    }, 
    {
      pos: [3, 0, 6], 
      state: 1
    }, 
    {
      pos: [3, 0, 7], 
      state: 0
    }, 
    {
      pos: [4, 0, 0], 
      state: 0
    }, 
    {
      pos: [4, 0, 1], 
      state: 0
    }, 
    {
      pos: [4, 0, 2], 
      state: 0
    }, 
    {
      pos: [4, 0, 3], 
      state: 1
    }, 
    {
      pos: [4, 0, 4], 
      state: 2
    }, 
    {
      pos: [4, 0, 5], 
      state: 2
    }, 
    {
      pos: [4, 0, 6], 
      state: 1
    }, 
    {
      pos: [4, 0, 7], 
      state: 0
    }, 
    {
      pos: [5, 0, 0], 
      state: 0
    }, 
    {
      pos: [5, 0, 1], 
      state: 0
    }, 
    {
      pos: [5, 0, 2], 
      state: 1
    }, 
    {
      pos: [5, 0, 3], 
      state: 0
    }, 
    {
      pos: [5, 0, 4], 
      state: 0
    }, 
    {
      pos: [5, 0, 5], 
      state: 1
    }, 
    {
      pos: [5, 0, 6], 
      state: 0
    }, 
    {
      pos: [5, 0, 7], 
      state: 0
    }, 
    {
      pos: [6, 0, 0], 
      state: 0
    }, 
    {
      pos: [6, 0, 1], 
      state: 0
    }, 
    {
      pos: [6, 0, 2], 
      state: 0
    }, 
    {
      pos: [6, 0, 4], 
      state: 1
    }, 
    {
      pos: [6, 0, 5], 
      state: 0
    }, 
    {
      pos: [6, 0, 7], 
      state: 0
    }, 
    {
      pos: [7, 0, 0], 
      state: 0
    }, 
    {
      pos: [7, 0, 1], 
      state: 0
    }, 
    {
      pos: [7, 0, 2], 
      state: 0
    }, 
    {
      pos: [7, 0, 3], 
      state: 0
    }, 
    {
      pos: [7, 0, 4], 
      state: 0
    }, 
    {
      pos: [7, 0, 7], 
      state: 0
    }, 
    {
      pos: [8, 0, 3], 
      state: 0
    }, 
    {
      pos: [8, 0, 4], 
      state: 0
    }, 
    {
      pos: [8, 0, 5], 
      state: 0
    }, 
    {
      pos: [8, 0, 6], 
      state: 0
    }, 
    {
      pos: [8, 0, 7], 
      state: 0
    }, 
    {
      pos: [3, 1, 5], 
      state: 3
    }, 
    {
      pos: [4, 1, 4], 
      state: 3
    }, 
    {
      pos: [4, 1, 5], 
      state: 3
    }, 
    {
      pos: [4, 2, 5], 
      state: 3
    }, 
    {
      pos: [6, 0, 6], 
      state: 4
    }, 
    {
      pos: [7, 0, 5], 
      state: 4
    }, 
    {
      pos: [7, 0, 6], 
      state: 4
    }, 
    {
      pos: [0, 1, 0], 
      state: 5
    }, 
    {
      pos: [0, 1, 1], 
      state: 5
    }, 
    {
      pos: [0, 1, 2], 
      state: 6
    }, 
    {
      pos: [0, 1, 3], 
      state: 7
    }, 
    {
      pos: [0, 1, 4], 
      state: 7
    }, 
    {
      pos: [0, 1, 5], 
      state: 7
    }, 
    {
      pos: [0, 1, 6], 
      state: 7
    }, 
    {
      pos: [0, 1, 7], 
      state: 8
    }, 
    {
      pos: [1, 1, 0], 
      state: 5
    }, 
    {
      pos: [1, 1, 1], 
      state: 5
    }, 
    {
      pos: [1, 1, 2], 
      state: 9
    }, 
    {
      pos: [1, 1, 3], 
      state: 5
    }, 
    {
      pos: [1, 1, 4], 
      state: 10
    }, 
    {
      pos: [1, 1, 5], 
      state: 10
    }, 
    {
      pos: [1, 1, 6], 
      state: 10
    }, 
    {
      pos: [1, 1, 7], 
      state: 9
    }, 
    {
      pos: [2, 1, 0], 
      state: 5
    }, 
    {
      pos: [2, 1, 1], 
      state: 5
    }, 
    {
      pos: [2, 1, 2], 
      state: 9
    }, 
    {
      pos: [2, 1, 3], 
      state: 10
    }, 
    {
      pos: [2, 1, 4], 
      state: 5
    }, 
    {
      pos: [2, 1, 5], 
      state: 10
    }, 
    {
      pos: [2, 1, 6], 
      state: 10
    }, 
    {
      pos: [2, 1, 7], 
      state: 9
    }, 
    {
      pos: [3, 1, 1], 
      state: 5
    }, 
    {
      pos: [3, 1, 2], 
      state: 9
    }, 
    {
      pos: [3, 1, 3], 
      state: 10
    }, 
    {
      pos: [3, 1, 4], 
      state: 11
    }, 
    {
      pos: [3, 1, 6], 
      state: 10
    }, 
    {
      pos: [3, 1, 7], 
      state: 9
    }, 
    {
      pos: [4, 1, 0], 
      state: 6
    }, 
    {
      pos: [4, 1, 1], 
      state: 7
    }, 
    {
      pos: [4, 1, 2], 
      state: 12
    }, 
    {
      pos: [4, 1, 3], 
      state: 10
    }, 
    {
      pos: [4, 1, 6], 
      state: 10
    }, 
    {
      pos: [4, 1, 7], 
      state: 9
    }, 
    {
      pos: [5, 1, 0], 
      state: 13
    }, 
    {
      pos: [5, 1, 1], 
      state: 5
    }, 
    {
      pos: [5, 1, 2], 
      state: 10
    }, 
    {
      pos: [5, 1, 3], 
      state: 10
    }, 
    {
      pos: [5, 1, 4], 
      state: 10
    }, 
    {
      pos: [5, 1, 5], 
      state: 14
    }, 
    {
      pos: [5, 1, 6], 
      state: 5
    }, 
    {
      pos: [5, 1, 7], 
      state: 9
    }, 
    {
      pos: [6, 1, 0], 
      state: 9
    }, 
    {
      pos: [6, 1, 1], 
      state: 5
    }, 
    {
      pos: [6, 1, 2], 
      state: 5
    }, 
    {
      pos: [6, 1, 3], 
      state: 5
    }, 
    {
      pos: [6, 1, 4], 
      state: 10
    }, 
    {
      pos: [6, 1, 5], 
      state: 5
    }, 
    {
      pos: [6, 1, 6], 
      state: 5
    }, 
    {
      pos: [6, 1, 7], 
      state: 9
    }, 
    {
      pos: [7, 1, 0], 
      state: 15
    }, 
    {
      pos: [7, 1, 1], 
      state: 7
    }, 
    {
      pos: [7, 1, 2], 
      state: 7
    }, 
    {
      pos: [7, 1, 3], 
      state: 8
    }, 
    {
      pos: [7, 1, 4], 
      state: 5
    }, 
    {
      pos: [7, 1, 5], 
      state: 5
    }, 
    {
      pos: [7, 1, 6], 
      state: 5
    }, 
    {
      pos: [7, 1, 7], 
      state: 9
    }, 
    {
      pos: [8, 1, 0], 
      state: 5
    }, 
    {
      pos: [8, 1, 1], 
      state: 5
    }, 
    {
      pos: [8, 1, 2], 
      state: 5
    }, 
    {
      pos: [8, 1, 3], 
      state: 15
    }, 
    {
      pos: [8, 1, 4], 
      state: 7
    }, 
    {
      pos: [8, 1, 5], 
      state: 7
    }, 
    {
      pos: [8, 1, 6], 
      state: 7
    }, 
    {
      pos: [8, 1, 7], 
      state: 12
    }, 
    {
      pos: [0, 2, 0], 
      state: 5
    }, 
    {
      pos: [0, 2, 1], 
      state: 5
    }, 
    {
      pos: [0, 2, 2], 
      state: 5
    }, 
    {
      pos: [0, 2, 3], 
      state: 5
    }, 
    {
      pos: [0, 2, 4], 
      state: 5
    }, 
    {
      pos: [0, 2, 5], 
      state: 5
    }, 
    {
      pos: [0, 2, 6], 
      state: 5
    }, 
    {
      pos: [0, 2, 7], 
      state: 5
    }, 
    {
      pos: [1, 2, 0], 
      state: 5
    }, 
    {
      pos: [1, 2, 1], 
      state: 5
    }, 
    {
      pos: [1, 2, 2], 
      state: 5
    }, 
    {
      pos: [1, 2, 3], 
      state: 5
    }, 
    {
      pos: [1, 2, 4], 
      state: 5
    }, 
    {
      pos: [1, 2, 5], 
      state: 5
    }, 
    {
      pos: [1, 2, 6], 
      state: 5
    }, 
    {
      pos: [1, 2, 7], 
      state: 5
    }, 
    {
      pos: [2, 2, 0], 
      state: 5
    }, 
    {
      pos: [2, 2, 1], 
      state: 5
    }, 
    {
      pos: [2, 2, 2], 
      state: 5
    }, 
    {
      pos: [2, 2, 3], 
      state: 5
    }, 
    {
      pos: [2, 2, 4], 
      state: 5
    }, 
    {
      pos: [2, 2, 5], 
      state: 5
    }, 
    {
      pos: [2, 2, 6], 
      state: 5
    }, 
    {
      pos: [2, 2, 7], 
      state: 5
    }, 
    {
      pos: [3, 2, 0], 
      state: 5
    }, 
    {
      pos: [3, 2, 1], 
      state: 5
    }, 
    {
      pos: [3, 2, 2], 
      state: 5
    }, 
    {
      pos: [3, 2, 3], 
      state: 5
    }, 
    {
      pos: [3, 2, 4], 
      state: 5
    }, 
    {
      pos: [3, 2, 5], 
      state: 5
    }, 
    {
      pos: [3, 2, 6], 
      state: 5
    }, 
    {
      pos: [3, 2, 7], 
      state: 5
    }, 
    {
      pos: [4, 2, 0], 
      state: 5
    }, 
    {
      pos: [4, 2, 1], 
      state: 5
    }, 
    {
      pos: [4, 2, 2], 
      state: 5
    }, 
    {
      pos: [4, 2, 3], 
      state: 5
    }, 
    {
      pos: [4, 2, 4], 
      state: 5
    }, 
    {
      pos: [4, 2, 6], 
      state: 5
    }, 
    {
      pos: [4, 2, 7], 
      state: 5
    }, 
    {
      pos: [5, 2, 0], 
      state: 5
    }, 
    {
      pos: [5, 2, 1], 
      state: 5
    }, 
    {
      pos: [5, 2, 2], 
      state: 5
    }, 
    {
      pos: [5, 2, 3], 
      state: 5
    }, 
    {
      pos: [5, 2, 4], 
      state: 5
    }, 
    {
      pos: [5, 2, 5], 
      state: 5
    }, 
    {
      pos: [5, 2, 6], 
      state: 5
    }, 
    {
      pos: [5, 2, 7], 
      state: 5
    }, 
    {
      pos: [6, 2, 0], 
      state: 5
    }, 
    {
      pos: [6, 2, 1], 
      state: 5
    }, 
    {
      pos: [6, 2, 2], 
      state: 5
    }, 
    {
      pos: [6, 2, 3], 
      state: 5
    }, 
    {
      pos: [6, 2, 4], 
      state: 5
    }, 
    {
      pos: [6, 2, 5], 
      state: 5
    }, 
    {
      pos: [6, 2, 6], 
      state: 5
    }, 
    {
      pos: [6, 2, 7], 
      state: 5
    }, 
    {
      pos: [7, 2, 0], 
      state: 5
    }, 
    {
      pos: [7, 2, 1], 
      state: 5
    }, 
    {
      pos: [7, 2, 2], 
      state: 5
    }, 
    {
      pos: [7, 2, 3], 
      state: 5
    }, 
    {
      pos: [7, 2, 4], 
      state: 5
    }, 
    {
      pos: [7, 2, 5], 
      state: 5
    }, 
    {
      pos: [7, 2, 6], 
      state: 5
    }, 
    {
      pos: [7, 2, 7], 
      state: 5
    }, 
    {
      pos: [8, 2, 0], 
      state: 5
    }, 
    {
      pos: [8, 2, 1], 
      state: 5
    }, 
    {
      pos: [8, 2, 2], 
      state: 5
    }, 
    {
      pos: [8, 2, 3], 
      state: 5
    }, 
    {
      pos: [8, 2, 4], 
      state: 5
    }, 
    {
      pos: [8, 2, 5], 
      state: 5
    }, 
    {
      pos: [8, 2, 6], 
      state: 5
    }, 
    {
      pos: [8, 2, 7], 
      state: 16
    }, 
    {
      nbt: {
        joint: "rollable", 
        final_state: "minecraft:dirt", 
        name: "minecraft:bottom", 
        pool: "minecraft:village/common/animals", 
        id: "minecraft:jigsaw", 
        target: "minecraft:bottom"
      }, 
      pos: [2, 0, 4], 
      state: 17
    }, 
    {
      nbt: {
        joint: "rollable", 
        final_state: "minecraft:structure_void", 
        name: "minecraft:bottom", 
        pool: "minecraft:village/common/animals", 
        id: "minecraft:jigsaw", 
        target: "minecraft:bottom"
      }, 
      pos: [6, 0, 3], 
      state: 17
    }, 
    {
      nbt: {
        joint: "aligned", 
        final_state: "minecraft:structure_void", 
        name: "minecraft:building_entrance", 
        pool: "minecraft:empty", 
        id: "minecraft:jigsaw", 
        target: "minecraft:building_entrance"
      }, 
      pos: [3, 1, 0], 
      state: 18
    }
  ], 
  palette: [
    {
      Properties: {
        snowy: "false"
      }, 
      Name: "minecraft:grass_block"
    }, 
    {
      Properties: {
        snowy: "true"
      }, 
      Name: "minecraft:grass_block"
    }, 
    {
      Name: "minecraft:dirt"
    }, 
    {
      Name: "minecraft:snow_block"
    }, 
    {
      Properties: {
        level: "0"
      }, 
      Name: "minecraft:water"
    }, 
    {
      Name: "minecraft:air"
    }, 
    {
      Properties: {
        east: "true", 
        waterlogged: "false", 
        south: "true", 
        north: "false", 
        west: "false"
      }, 
      Name: "minecraft:spruce_fence"
    }, 
    {
      Properties: {
        east: "false", 
        waterlogged: "false", 
        south: "true", 
        north: "true", 
        west: "false"
      }, 
      Name: "minecraft:spruce_fence"
    }, 
    {
      Properties: {
        east: "true", 
        waterlogged: "false", 
        south: "false", 
        north: "true", 
        west: "false"
      }, 
      Name: "minecraft:spruce_fence"
    }, 
    {
      Properties: {
        east: "true", 
        waterlogged: "false", 
        south: "false", 
        north: "false", 
        west: "true"
      }, 
      Name: "minecraft:spruce_fence"
    }, 
    {
      Properties: {
        layers: "1"
      }, 
      Name: "minecraft:snow"
    }, 
    {
      Properties: {
        layers: "3"
      }, 
      Name: "minecraft:snow"
    }, 
    {
      Properties: {
        east: "false", 
        waterlogged: "false", 
        south: "false", 
        north: "true", 
        west: "true"
      }, 
      Name: "minecraft:spruce_fence"
    }, 
    {
      Properties: {
        in_wall: "false", 
        powered: "false", 
        facing: "south", 
        open: "false"
      }, 
      Name: "minecraft:spruce_fence_gate"
    }, 
    {
      Properties: {
        layers: "4"
      }, 
      Name: "minecraft:snow"
    }, 
    {
      Properties: {
        east: "false", 
        waterlogged: "false", 
        south: "true", 
        north: "false", 
        west: "true"
      }, 
      Name: "minecraft:spruce_fence"
    }, 
    {
      Properties: {
        waterlogged: "false", 
        hanging: "false"
      }, 
      Name: "minecraft:lantern"
    }, 
    {
      Properties: {
        orientation: "up_north"
      }, 
      Name: "minecraft:jigsaw"
    }, 
    {
      Properties: {
        orientation: "north_up"
      }, 
      Name: "minecraft:jigsaw"
    }
  ]
}
