{
  size: [9, 5, 5], 
  entities: [], 
  blocks: [
    {
      pos: [0, 0, 0], 
      state: 0
    }, 
    {
      pos: [1, 0, 0], 
      state: 1
    }, 
    {
      pos: [2, 0, 0], 
      state: 1
    }, 
    {
      pos: [3, 0, 0], 
      state: 1
    }, 
    {
      pos: [4, 0, 0], 
      state: 2
    }, 
    {
      pos: [5, 0, 0], 
      state: 2
    }, 
    {
      pos: [6, 0, 0], 
      state: 2
    }, 
    {
      pos: [7, 0, 0], 
      state: 2
    }, 
    {
      pos: [8, 0, 0], 
      state: 2
    }, 
    {
      pos: [0, 0, 1], 
      state: 1
    }, 
    {
      pos: [1, 0, 1], 
      state: 1
    }, 
    {
      pos: [2, 0, 1], 
      state: 1
    }, 
    {
      pos: [3, 0, 1], 
      state: 1
    }, 
    {
      pos: [4, 0, 1], 
      state: 1
    }, 
    {
      pos: [5, 0, 1], 
      state: 0
    }, 
    {
      pos: [6, 0, 1], 
      state: 0
    }, 
    {
      pos: [7, 0, 1], 
      state: 2
    }, 
    {
      pos: [8, 0, 1], 
      state: 2
    }, 
    {
      pos: [0, 0, 2], 
      state: 2
    }, 
    {
      pos: [1, 0, 2], 
      state: 0
    }, 
    {
      pos: [2, 0, 2], 
      state: 0
    }, 
    {
      pos: [3, 0, 2], 
      state: 2
    }, 
    {
      pos: [4, 0, 2], 
      state: 2
    }, 
    {
      pos: [6, 0, 2], 
      state: 2
    }, 
    {
      pos: [7, 0, 2], 
      state: 1
    }, 
    {
      pos: [8, 0, 2], 
      state: 2
    }, 
    {
      pos: [0, 0, 3], 
      state: 1
    }, 
    {
      pos: [1, 0, 3], 
      state: 0
    }, 
    {
      pos: [2, 0, 3], 
      state: 2
    }, 
    {
      pos: [3, 0, 3], 
      state: 2
    }, 
    {
      pos: [4, 0, 3], 
      state: 1
    }, 
    {
      pos: [5, 0, 3], 
      state: 2
    }, 
    {
      pos: [6, 0, 3], 
      state: 2
    }, 
    {
      pos: [7, 0, 3], 
      state: 2
    }, 
    {
      pos: [8, 0, 3], 
      state: 2
    }, 
    {
      pos: [0, 0, 4], 
      state: 0
    }, 
    {
      pos: [1, 0, 4], 
      state: 1
    }, 
    {
      pos: [2, 0, 4], 
      state: 1
    }, 
    {
      pos: [3, 0, 4], 
      state: 1
    }, 
    {
      pos: [4, 0, 4], 
      state: 2
    }, 
    {
      pos: [5, 0, 4], 
      state: 2
    }, 
    {
      pos: [6, 0, 4], 
      state: 2
    }, 
    {
      pos: [7, 0, 4], 
      state: 2
    }, 
    {
      pos: [8, 0, 4], 
      state: 2
    }, 
    {
      nbt: {
        final_state: "minecraft:dirt", 
        name: "minecraft:bottom", 
        pool: "minecraft:village/common/butcher_animals", 
        id: "minecraft:jigsaw", 
        target: "minecraft:bottom"
      }, 
      pos: [5, 0, 2], 
      state: 3
    }, 
    {
      pos: [1, 1, 0], 
      state: 4
    }, 
    {
      pos: [2, 1, 0], 
      state: 4
    }, 
    {
      pos: [3, 1, 0], 
      state: 4
    }, 
    {
      pos: [0, 1, 1], 
      state: 4
    }, 
    {
      pos: [1, 1, 1], 
      state: 5
    }, 
    {
      pos: [2, 1, 1], 
      state: 5
    }, 
    {
      pos: [4, 1, 1], 
      state: 4
    }, 
    {
      pos: [4, 1, 3], 
      state: 4
    }, 
    {
      pos: [1, 1, 4], 
      state: 4
    }, 
    {
      pos: [2, 1, 4], 
      state: 4
    }, 
    {
      pos: [3, 1, 4], 
      state: 4
    }, 
    {
      nbt: {
        CookTime: 0s, 
        BurnTime: 0s, 
        Items: [], 
        id: "minecraft:smoker", 
        CookTimeTotal: 0s, 
        RecipesUsed: {}
      }, 
      pos: [7, 1, 2], 
      state: 6
    }, 
    {
      nbt: {
        final_state: "minecraft:snow_block", 
        name: "minecraft:building_entrance", 
        pool: "minecraft:empty", 
        id: "minecraft:jigsaw", 
        target: "minecraft:building_entrance"
      }, 
      pos: [0, 1, 3], 
      state: 7
    }, 
    {
      pos: [0, 1, 0], 
      state: 8
    }, 
    {
      pos: [4, 1, 0], 
      state: 9
    }, 
    {
      pos: [5, 1, 0], 
      state: 10
    }, 
    {
      pos: [6, 1, 0], 
      state: 10
    }, 
    {
      pos: [7, 1, 0], 
      state: 10
    }, 
    {
      pos: [8, 1, 0], 
      state: 11
    }, 
    {
      pos: [3, 1, 1], 
      state: 12
    }, 
    {
      pos: [5, 1, 1], 
      state: 8
    }, 
    {
      pos: [6, 1, 1], 
      state: 8
    }, 
    {
      pos: [7, 1, 1], 
      state: 13
    }, 
    {
      pos: [8, 1, 1], 
      state: 14
    }, 
    {
      pos: [0, 1, 2], 
      state: 15
    }, 
    {
      pos: [1, 1, 2], 
      state: 8
    }, 
    {
      pos: [2, 1, 2], 
      state: 8
    }, 
    {
      pos: [3, 1, 2], 
      state: 13
    }, 
    {
      pos: [4, 1, 2], 
      state: 16
    }, 
    {
      pos: [5, 1, 2], 
      state: 13
    }, 
    {
      pos: [6, 1, 2], 
      state: 13
    }, 
    {
      pos: [8, 1, 2], 
      state: 14
    }, 
    {
      pos: [1, 1, 3], 
      state: 8
    }, 
    {
      pos: [2, 1, 3], 
      state: 13
    }, 
    {
      pos: [3, 1, 3], 
      state: 17
    }, 
    {
      pos: [5, 1, 3], 
      state: 13
    }, 
    {
      pos: [6, 1, 3], 
      state: 13
    }, 
    {
      pos: [7, 1, 3], 
      state: 13
    }, 
    {
      pos: [8, 1, 3], 
      state: 14
    }, 
    {
      pos: [0, 1, 4], 
      state: 8
    }, 
    {
      pos: [4, 1, 4], 
      state: 18
    }, 
    {
      pos: [5, 1, 4], 
      state: 10
    }, 
    {
      pos: [6, 1, 4], 
      state: 10
    }, 
    {
      pos: [7, 1, 4], 
      state: 10
    }, 
    {
      pos: [8, 1, 4], 
      state: 19
    }, 
    {
      pos: [1, 2, 0], 
      state: 4
    }, 
    {
      pos: [2, 2, 0], 
      state: 4
    }, 
    {
      pos: [3, 2, 0], 
      state: 4
    }, 
    {
      pos: [0, 2, 1], 
      state: 4
    }, 
    {
      pos: [4, 2, 1], 
      state: 4
    }, 
    {
      pos: [0, 2, 3], 
      state: 4
    }, 
    {
      pos: [4, 2, 3], 
      state: 4
    }, 
    {
      pos: [1, 2, 4], 
      state: 4
    }, 
    {
      pos: [2, 2, 4], 
      state: 4
    }, 
    {
      pos: [3, 2, 4], 
      state: 4
    }, 
    {
      pos: [0, 2, 0], 
      state: 13
    }, 
    {
      pos: [4, 2, 0], 
      state: 13
    }, 
    {
      pos: [5, 2, 0], 
      state: 13
    }, 
    {
      pos: [6, 2, 0], 
      state: 13
    }, 
    {
      pos: [7, 2, 0], 
      state: 13
    }, 
    {
      pos: [8, 2, 0], 
      state: 13
    }, 
    {
      pos: [1, 2, 1], 
      state: 13
    }, 
    {
      pos: [2, 2, 1], 
      state: 13
    }, 
    {
      pos: [3, 2, 1], 
      state: 13
    }, 
    {
      pos: [5, 2, 1], 
      state: 13
    }, 
    {
      pos: [6, 2, 1], 
      state: 13
    }, 
    {
      pos: [7, 2, 1], 
      state: 13
    }, 
    {
      pos: [8, 2, 1], 
      state: 13
    }, 
    {
      pos: [0, 2, 2], 
      state: 20
    }, 
    {
      pos: [1, 2, 2], 
      state: 13
    }, 
    {
      pos: [2, 2, 2], 
      state: 13
    }, 
    {
      pos: [3, 2, 2], 
      state: 13
    }, 
    {
      pos: [4, 2, 2], 
      state: 21
    }, 
    {
      pos: [5, 2, 2], 
      state: 13
    }, 
    {
      pos: [6, 2, 2], 
      state: 13
    }, 
    {
      pos: [7, 2, 2], 
      state: 13
    }, 
    {
      pos: [8, 2, 2], 
      state: 13
    }, 
    {
      pos: [1, 2, 3], 
      state: 13
    }, 
    {
      pos: [2, 2, 3], 
      state: 13
    }, 
    {
      pos: [3, 2, 3], 
      state: 22
    }, 
    {
      pos: [5, 2, 3], 
      state: 13
    }, 
    {
      pos: [6, 2, 3], 
      state: 13
    }, 
    {
      pos: [7, 2, 3], 
      state: 13
    }, 
    {
      pos: [8, 2, 3], 
      state: 13
    }, 
    {
      pos: [0, 2, 4], 
      state: 13
    }, 
    {
      pos: [4, 2, 4], 
      state: 13
    }, 
    {
      pos: [5, 2, 4], 
      state: 13
    }, 
    {
      pos: [6, 2, 4], 
      state: 23
    }, 
    {
      pos: [7, 2, 4], 
      state: 13
    }, 
    {
      pos: [8, 2, 4], 
      state: 13
    }, 
    {
      pos: [0, 3, 1], 
      state: 4
    }, 
    {
      pos: [1, 3, 1], 
      state: 4
    }, 
    {
      pos: [2, 3, 1], 
      state: 4
    }, 
    {
      pos: [3, 3, 1], 
      state: 4
    }, 
    {
      pos: [4, 3, 1], 
      state: 4
    }, 
    {
      pos: [0, 3, 2], 
      state: 4
    }, 
    {
      pos: [4, 3, 2], 
      state: 4
    }, 
    {
      pos: [0, 3, 3], 
      state: 4
    }, 
    {
      pos: [1, 3, 3], 
      state: 4
    }, 
    {
      pos: [2, 3, 3], 
      state: 4
    }, 
    {
      pos: [3, 3, 3], 
      state: 4
    }, 
    {
      pos: [4, 3, 3], 
      state: 4
    }, 
    {
      pos: [0, 3, 0], 
      state: 13
    }, 
    {
      pos: [1, 3, 0], 
      state: 13
    }, 
    {
      pos: [2, 3, 0], 
      state: 13
    }, 
    {
      pos: [3, 3, 0], 
      state: 13
    }, 
    {
      pos: [4, 3, 0], 
      state: 13
    }, 
    {
      pos: [5, 3, 0], 
      state: 13
    }, 
    {
      pos: [6, 3, 0], 
      state: 13
    }, 
    {
      pos: [7, 3, 0], 
      state: 13
    }, 
    {
      pos: [8, 3, 0], 
      state: 13
    }, 
    {
      pos: [5, 3, 1], 
      state: 13
    }, 
    {
      pos: [6, 3, 1], 
      state: 13
    }, 
    {
      pos: [7, 3, 1], 
      state: 13
    }, 
    {
      pos: [8, 3, 1], 
      state: 13
    }, 
    {
      pos: [1, 3, 2], 
      state: 13
    }, 
    {
      pos: [2, 3, 2], 
      state: 13
    }, 
    {
      pos: [3, 3, 2], 
      state: 13
    }, 
    {
      pos: [5, 3, 2], 
      state: 13
    }, 
    {
      pos: [6, 3, 2], 
      state: 13
    }, 
    {
      pos: [7, 3, 2], 
      state: 13
    }, 
    {
      pos: [8, 3, 2], 
      state: 13
    }, 
    {
      pos: [5, 3, 3], 
      state: 13
    }, 
    {
      pos: [6, 3, 3], 
      state: 24
    }, 
    {
      pos: [7, 3, 3], 
      state: 13
    }, 
    {
      pos: [8, 3, 3], 
      state: 13
    }, 
    {
      pos: [0, 3, 4], 
      state: 13
    }, 
    {
      pos: [1, 3, 4], 
      state: 13
    }, 
    {
      pos: [2, 3, 4], 
      state: 13
    }, 
    {
      pos: [3, 3, 4], 
      state: 13
    }, 
    {
      pos: [4, 3, 4], 
      state: 13
    }, 
    {
      pos: [5, 3, 4], 
      state: 13
    }, 
    {
      pos: [6, 3, 4], 
      state: 23
    }, 
    {
      pos: [7, 3, 4], 
      state: 13
    }, 
    {
      pos: [8, 3, 4], 
      state: 13
    }, 
    {
      pos: [1, 4, 2], 
      state: 4
    }, 
    {
      pos: [2, 4, 2], 
      state: 4
    }, 
    {
      pos: [3, 4, 2], 
      state: 4
    }, 
    {
      pos: [0, 4, 0], 
      state: 13
    }, 
    {
      pos: [1, 4, 0], 
      state: 13
    }, 
    {
      pos: [2, 4, 0], 
      state: 13
    }, 
    {
      pos: [3, 4, 0], 
      state: 13
    }, 
    {
      pos: [4, 4, 0], 
      state: 13
    }, 
    {
      pos: [5, 4, 0], 
      state: 13
    }, 
    {
      pos: [6, 4, 0], 
      state: 13
    }, 
    {
      pos: [7, 4, 0], 
      state: 13
    }, 
    {
      pos: [8, 4, 0], 
      state: 13
    }, 
    {
      pos: [0, 4, 1], 
      state: 13
    }, 
    {
      pos: [1, 4, 1], 
      state: 13
    }, 
    {
      pos: [2, 4, 1], 
      state: 13
    }, 
    {
      pos: [3, 4, 1], 
      state: 13
    }, 
    {
      pos: [4, 4, 1], 
      state: 13
    }, 
    {
      pos: [5, 4, 1], 
      state: 13
    }, 
    {
      pos: [6, 4, 1], 
      state: 13
    }, 
    {
      pos: [7, 4, 1], 
      state: 13
    }, 
    {
      pos: [8, 4, 1], 
      state: 13
    }, 
    {
      pos: [0, 4, 2], 
      state: 13
    }, 
    {
      pos: [4, 4, 2], 
      state: 13
    }, 
    {
      pos: [5, 4, 2], 
      state: 13
    }, 
    {
      pos: [6, 4, 2], 
      state: 13
    }, 
    {
      pos: [7, 4, 2], 
      state: 13
    }, 
    {
      pos: [8, 4, 2], 
      state: 13
    }, 
    {
      pos: [0, 4, 3], 
      state: 13
    }, 
    {
      pos: [1, 4, 3], 
      state: 13
    }, 
    {
      pos: [2, 4, 3], 
      state: 13
    }, 
    {
      pos: [3, 4, 3], 
      state: 13
    }, 
    {
      pos: [4, 4, 3], 
      state: 13
    }, 
    {
      pos: [5, 4, 3], 
      state: 13
    }, 
    {
      pos: [6, 4, 3], 
      state: 25
    }, 
    {
      pos: [7, 4, 3], 
      state: 13
    }, 
    {
      pos: [8, 4, 3], 
      state: 13
    }, 
    {
      pos: [0, 4, 4], 
      state: 13
    }, 
    {
      pos: [1, 4, 4], 
      state: 13
    }, 
    {
      pos: [2, 4, 4], 
      state: 13
    }, 
    {
      pos: [3, 4, 4], 
      state: 13
    }, 
    {
      pos: [4, 4, 4], 
      state: 13
    }, 
    {
      pos: [5, 4, 4], 
      state: 13
    }, 
    {
      pos: [6, 4, 4], 
      state: 26
    }, 
    {
      pos: [7, 4, 4], 
      state: 13
    }, 
    {
      pos: [8, 4, 4], 
      state: 13
    }
  ], 
  palette: [
    {
      Properties: {
        snowy: "true"
      }, 
      Name: "minecraft:grass_block"
    }, 
    {
      Name: "minecraft:dirt"
    }, 
    {
      Properties: {
        snowy: "false"
      }, 
      Name: "minecraft:grass_block"
    }, 
    {
      Properties: {
        orientation: "up_north"
      }, 
      Name: "minecraft:jigsaw"
    }, 
    {
      Name: "minecraft:snow_block"
    }, 
    {
      Name: "minecraft:spruce_planks"
    }, 
    {
      Properties: {
        lit: "false", 
        facing: "west"
      }, 
      Name: "minecraft:smoker"
    }, 
    {
      Properties: {
        orientation: "west_up"
      }, 
      Name: "minecraft:jigsaw"
    }, 
    {
      Properties: {
        layers: "1"
      }, 
      Name: "minecraft:snow"
    }, 
    {
      Properties: {
        east: "true", 
        waterlogged: "false", 
        south: "true", 
        north: "false", 
        west: "true"
      }, 
      Name: "minecraft:spruce_fence"
    }, 
    {
      Properties: {
        east: "true", 
        waterlogged: "false", 
        south: "false", 
        north: "false", 
        west: "true"
      }, 
      Name: "minecraft:spruce_fence"
    }, 
    {
      Properties: {
        east: "false", 
        waterlogged: "false", 
        south: "true", 
        north: "false", 
        west: "true"
      }, 
      Name: "minecraft:spruce_fence"
    }, 
    {
      Properties: {
        half: "bottom", 
        waterlogged: "false", 
        shape: "straight", 
        facing: "north"
      }, 
      Name: "minecraft:spruce_stairs"
    }, 
    {
      Name: "minecraft:air"
    }, 
    {
      Properties: {
        east: "false", 
        waterlogged: "false", 
        south: "true", 
        north: "true", 
        west: "false"
      }, 
      Name: "minecraft:spruce_fence"
    }, 
    {
      Properties: {
        hinge: "right", 
        half: "lower", 
        powered: "false", 
        facing: "west", 
        open: "false"
      }, 
      Name: "minecraft:spruce_door"
    }, 
    {
      Properties: {
        hinge: "left", 
        half: "lower", 
        powered: "false", 
        facing: "east", 
        open: "false"
      }, 
      Name: "minecraft:spruce_door"
    }, 
    {
      Properties: {
        east: "true", 
        waterlogged: "false", 
        south: "true", 
        north: "false", 
        west: "false"
      }, 
      Name: "minecraft:spruce_fence"
    }, 
    {
      Properties: {
        east: "true", 
        waterlogged: "false", 
        south: "false", 
        north: "true", 
        west: "true"
      }, 
      Name: "minecraft:spruce_fence"
    }, 
    {
      Properties: {
        east: "false", 
        waterlogged: "false", 
        south: "false", 
        north: "true", 
        west: "true"
      }, 
      Name: "minecraft:spruce_fence"
    }, 
    {
      Properties: {
        hinge: "right", 
        half: "upper", 
        powered: "false", 
        facing: "west", 
        open: "false"
      }, 
      Name: "minecraft:spruce_door"
    }, 
    {
      Properties: {
        hinge: "left", 
        half: "upper", 
        powered: "false", 
        facing: "east", 
        open: "false"
      }, 
      Name: "minecraft:spruce_door"
    }, 
    {
      Name: "minecraft:torch"
    }, 
    {
      Properties: {
        east: "false", 
        waterlogged: "false", 
        south: "false", 
        north: "false", 
        west: "false"
      }, 
      Name: "minecraft:spruce_fence"
    }, 
    {
      Properties: {
        hanging: "true"
      }, 
      Name: "minecraft:lantern"
    }, 
    {
      Properties: {
        east: "false", 
        waterlogged: "false", 
        south: "true", 
        north: "false", 
        west: "false"
      }, 
      Name: "minecraft:spruce_fence"
    }, 
    {
      Properties: {
        east: "false", 
        waterlogged: "false", 
        south: "false", 
        north: "true", 
        west: "false"
      }, 
      Name: "minecraft:spruce_fence"
    }
  ]
}
