{
  size: [8, 6, 9], 
  entities: [], 
  blocks: [
    {
      pos: [1, 0, 2], 
      state: 0
    }, 
    {
      pos: [1, 0, 3], 
      state: 0
    }, 
    {
      pos: [1, 0, 4], 
      state: 0
    }, 
    {
      pos: [1, 0, 5], 
      state: 0
    }, 
    {
      pos: [1, 0, 6], 
      state: 0
    }, 
    {
      pos: [1, 0, 7], 
      state: 0
    }, 
    {
      pos: [1, 0, 8], 
      state: 0
    }, 
    {
      pos: [2, 0, 2], 
      state: 0
    }, 
    {
      pos: [2, 0, 3], 
      state: 1
    }, 
    {
      pos: [2, 0, 4], 
      state: 1
    }, 
    {
      pos: [2, 0, 6], 
      state: 1
    }, 
    {
      pos: [2, 0, 7], 
      state: 1
    }, 
    {
      pos: [2, 0, 8], 
      state: 0
    }, 
    {
      pos: [3, 0, 1], 
      state: 2
    }, 
    {
      pos: [3, 0, 2], 
      state: 0
    }, 
    {
      pos: [3, 0, 3], 
      state: 1
    }, 
    {
      pos: [3, 0, 4], 
      state: 1
    }, 
    {
      pos: [3, 0, 5], 
      state: 1
    }, 
    {
      pos: [3, 0, 6], 
      state: 1
    }, 
    {
      pos: [3, 0, 7], 
      state: 1
    }, 
    {
      pos: [3, 0, 8], 
      state: 0
    }, 
    {
      pos: [4, 0, 0], 
      state: 2
    }, 
    {
      pos: [4, 0, 1], 
      state: 2
    }, 
    {
      pos: [4, 0, 2], 
      state: 0
    }, 
    {
      pos: [4, 0, 3], 
      state: 1
    }, 
    {
      pos: [4, 0, 4], 
      state: 1
    }, 
    {
      pos: [4, 0, 5], 
      state: 3
    }, 
    {
      pos: [4, 0, 6], 
      state: 3
    }, 
    {
      pos: [4, 0, 7], 
      state: 1
    }, 
    {
      pos: [4, 0, 8], 
      state: 0
    }, 
    {
      pos: [5, 0, 1], 
      state: 2
    }, 
    {
      pos: [5, 0, 2], 
      state: 0
    }, 
    {
      pos: [5, 0, 3], 
      state: 1
    }, 
    {
      pos: [5, 0, 4], 
      state: 1
    }, 
    {
      pos: [5, 0, 5], 
      state: 4
    }, 
    {
      pos: [5, 0, 6], 
      state: 3
    }, 
    {
      pos: [5, 0, 7], 
      state: 1
    }, 
    {
      pos: [5, 0, 8], 
      state: 0
    }, 
    {
      pos: [6, 0, 2], 
      state: 0
    }, 
    {
      pos: [6, 0, 3], 
      state: 1
    }, 
    {
      pos: [6, 0, 4], 
      state: 1
    }, 
    {
      pos: [6, 0, 5], 
      state: 1
    }, 
    {
      pos: [6, 0, 6], 
      state: 1
    }, 
    {
      pos: [6, 0, 7], 
      state: 1
    }, 
    {
      pos: [6, 0, 8], 
      state: 0
    }, 
    {
      pos: [7, 0, 2], 
      state: 0
    }, 
    {
      pos: [7, 0, 3], 
      state: 0
    }, 
    {
      pos: [7, 0, 4], 
      state: 0
    }, 
    {
      pos: [7, 0, 5], 
      state: 0
    }, 
    {
      pos: [7, 0, 6], 
      state: 0
    }, 
    {
      pos: [7, 0, 7], 
      state: 0
    }, 
    {
      pos: [7, 0, 8], 
      state: 0
    }, 
    {
      pos: [4, 1, 1], 
      state: 2
    }, 
    {
      pos: [0, 0, 0], 
      state: 5
    }, 
    {
      pos: [0, 0, 1], 
      state: 5
    }, 
    {
      pos: [0, 0, 2], 
      state: 5
    }, 
    {
      pos: [0, 0, 3], 
      state: 6
    }, 
    {
      pos: [0, 0, 4], 
      state: 7
    }, 
    {
      pos: [0, 0, 6], 
      state: 8
    }, 
    {
      pos: [0, 0, 7], 
      state: 6
    }, 
    {
      pos: [0, 0, 8], 
      state: 9
    }, 
    {
      pos: [1, 0, 0], 
      state: 5
    }, 
    {
      pos: [1, 0, 1], 
      state: 5
    }, 
    {
      pos: [2, 0, 0], 
      state: 5
    }, 
    {
      pos: [2, 0, 1], 
      state: 6
    }, 
    {
      pos: [3, 0, 0], 
      state: 10
    }, 
    {
      pos: [5, 0, 0], 
      state: 11
    }, 
    {
      pos: [6, 0, 0], 
      state: 5
    }, 
    {
      pos: [6, 0, 1], 
      state: 6
    }, 
    {
      pos: [7, 0, 0], 
      state: 5
    }, 
    {
      pos: [7, 0, 1], 
      state: 5
    }, 
    {
      pos: [0, 1, 0], 
      state: 12
    }, 
    {
      pos: [0, 1, 1], 
      state: 12
    }, 
    {
      pos: [0, 1, 2], 
      state: 12
    }, 
    {
      pos: [0, 1, 3], 
      state: 12
    }, 
    {
      pos: [0, 1, 4], 
      state: 12
    }, 
    {
      pos: [0, 1, 5], 
      state: 12
    }, 
    {
      pos: [0, 1, 6], 
      state: 12
    }, 
    {
      pos: [0, 1, 7], 
      state: 12
    }, 
    {
      pos: [0, 1, 8], 
      state: 12
    }, 
    {
      pos: [1, 1, 0], 
      state: 12
    }, 
    {
      pos: [1, 1, 1], 
      state: 12
    }, 
    {
      pos: [1, 1, 2], 
      state: 13
    }, 
    {
      pos: [1, 1, 3], 
      state: 14
    }, 
    {
      pos: [1, 1, 4], 
      state: 14
    }, 
    {
      pos: [1, 1, 5], 
      state: 15
    }, 
    {
      pos: [1, 1, 6], 
      state: 14
    }, 
    {
      pos: [1, 1, 7], 
      state: 14
    }, 
    {
      pos: [1, 1, 8], 
      state: 16
    }, 
    {
      pos: [2, 1, 0], 
      state: 12
    }, 
    {
      pos: [2, 1, 1], 
      state: 12
    }, 
    {
      pos: [2, 1, 2], 
      state: 17
    }, 
    {
      pos: [2, 1, 3], 
      state: 5
    }, 
    {
      pos: [2, 1, 4], 
      state: 5
    }, 
    {
      pos: [2, 1, 5], 
      state: 12
    }, 
    {
      pos: [2, 1, 6], 
      state: 5
    }, 
    {
      pos: [2, 1, 7], 
      state: 5
    }, 
    {
      pos: [2, 1, 8], 
      state: 17
    }, 
    {
      pos: [3, 1, 0], 
      state: 12
    }, 
    {
      pos: [3, 1, 1], 
      state: 12
    }, 
    {
      pos: [3, 1, 2], 
      state: 17
    }, 
    {
      pos: [3, 1, 3], 
      state: 5
    }, 
    {
      pos: [3, 1, 4], 
      state: 5
    }, 
    {
      pos: [3, 1, 5], 
      state: 5
    }, 
    {
      pos: [3, 1, 6], 
      state: 5
    }, 
    {
      pos: [3, 1, 7], 
      state: 5
    }, 
    {
      pos: [3, 1, 8], 
      state: 17
    }, 
    {
      pos: [4, 1, 0], 
      state: 12
    }, 
    {
      pos: [4, 1, 2], 
      state: 18
    }, 
    {
      pos: [4, 1, 3], 
      state: 5
    }, 
    {
      pos: [4, 1, 4], 
      state: 5
    }, 
    {
      pos: [4, 1, 5], 
      state: 19
    }, 
    {
      pos: [4, 1, 6], 
      state: 20
    }, 
    {
      pos: [4, 1, 7], 
      state: 5
    }, 
    {
      pos: [4, 1, 8], 
      state: 17
    }, 
    {
      pos: [5, 1, 0], 
      state: 12
    }, 
    {
      pos: [5, 1, 1], 
      state: 21
    }, 
    {
      pos: [5, 1, 2], 
      state: 17
    }, 
    {
      pos: [5, 1, 3], 
      state: 5
    }, 
    {
      pos: [5, 1, 4], 
      state: 5
    }, 
    {
      pos: [5, 1, 5], 
      state: 22
    }, 
    {
      pos: [5, 1, 6], 
      state: 23
    }, 
    {
      pos: [5, 1, 7], 
      state: 5
    }, 
    {
      pos: [5, 1, 8], 
      state: 17
    }, 
    {
      pos: [6, 1, 0], 
      state: 12
    }, 
    {
      pos: [6, 1, 1], 
      state: 12
    }, 
    {
      pos: [6, 1, 2], 
      state: 17
    }, 
    {
      pos: [6, 1, 3], 
      state: 5
    }, 
    {
      pos: [6, 1, 4], 
      state: 5
    }, 
    {
      pos: [6, 1, 5], 
      state: 5
    }, 
    {
      pos: [6, 1, 6], 
      state: 5
    }, 
    {
      pos: [6, 1, 7], 
      state: 5
    }, 
    {
      pos: [6, 1, 8], 
      state: 17
    }, 
    {
      pos: [7, 1, 0], 
      state: 12
    }, 
    {
      pos: [7, 1, 1], 
      state: 12
    }, 
    {
      pos: [7, 1, 2], 
      state: 24
    }, 
    {
      pos: [7, 1, 3], 
      state: 14
    }, 
    {
      pos: [7, 1, 4], 
      state: 14
    }, 
    {
      pos: [7, 1, 5], 
      state: 14
    }, 
    {
      pos: [7, 1, 6], 
      state: 14
    }, 
    {
      pos: [7, 1, 7], 
      state: 14
    }, 
    {
      pos: [7, 1, 8], 
      state: 25
    }, 
    {
      pos: [0, 2, 0], 
      state: 12
    }, 
    {
      pos: [0, 2, 1], 
      state: 12
    }, 
    {
      pos: [0, 2, 2], 
      state: 12
    }, 
    {
      pos: [0, 2, 3], 
      state: 12
    }, 
    {
      pos: [0, 2, 4], 
      state: 12
    }, 
    {
      pos: [0, 2, 5], 
      state: 12
    }, 
    {
      pos: [0, 2, 6], 
      state: 12
    }, 
    {
      pos: [0, 2, 7], 
      state: 12
    }, 
    {
      pos: [0, 2, 8], 
      state: 12
    }, 
    {
      pos: [1, 2, 0], 
      state: 12
    }, 
    {
      pos: [1, 2, 1], 
      state: 12
    }, 
    {
      pos: [1, 2, 2], 
      state: 12
    }, 
    {
      pos: [1, 2, 3], 
      state: 12
    }, 
    {
      pos: [1, 2, 4], 
      state: 26
    }, 
    {
      pos: [1, 2, 5], 
      state: 12
    }, 
    {
      pos: [1, 2, 6], 
      state: 26
    }, 
    {
      pos: [1, 2, 7], 
      state: 12
    }, 
    {
      pos: [1, 2, 8], 
      state: 12
    }, 
    {
      pos: [2, 2, 0], 
      state: 12
    }, 
    {
      pos: [2, 2, 1], 
      state: 12
    }, 
    {
      pos: [2, 2, 2], 
      state: 12
    }, 
    {
      pos: [2, 2, 3], 
      state: 12
    }, 
    {
      pos: [2, 2, 4], 
      state: 12
    }, 
    {
      pos: [2, 2, 5], 
      state: 12
    }, 
    {
      pos: [2, 2, 6], 
      state: 12
    }, 
    {
      pos: [2, 2, 7], 
      state: 12
    }, 
    {
      pos: [2, 2, 8], 
      state: 12
    }, 
    {
      pos: [3, 2, 0], 
      state: 12
    }, 
    {
      pos: [3, 2, 1], 
      state: 12
    }, 
    {
      pos: [3, 2, 2], 
      state: 12
    }, 
    {
      pos: [3, 2, 3], 
      state: 12
    }, 
    {
      pos: [3, 2, 4], 
      state: 12
    }, 
    {
      pos: [3, 2, 5], 
      state: 12
    }, 
    {
      pos: [3, 2, 6], 
      state: 12
    }, 
    {
      pos: [3, 2, 7], 
      state: 12
    }, 
    {
      pos: [3, 2, 8], 
      state: 12
    }, 
    {
      pos: [4, 2, 0], 
      state: 12
    }, 
    {
      pos: [4, 2, 1], 
      state: 12
    }, 
    {
      pos: [4, 2, 2], 
      state: 12
    }, 
    {
      pos: [4, 2, 3], 
      state: 12
    }, 
    {
      pos: [4, 2, 4], 
      state: 12
    }, 
    {
      pos: [4, 2, 5], 
      state: 12
    }, 
    {
      pos: [4, 2, 6], 
      state: 12
    }, 
    {
      pos: [4, 2, 7], 
      state: 12
    }, 
    {
      pos: [4, 2, 8], 
      state: 12
    }, 
    {
      pos: [5, 2, 0], 
      state: 12
    }, 
    {
      pos: [5, 2, 1], 
      state: 12
    }, 
    {
      pos: [5, 2, 2], 
      state: 12
    }, 
    {
      pos: [5, 2, 3], 
      state: 12
    }, 
    {
      pos: [5, 2, 4], 
      state: 12
    }, 
    {
      pos: [5, 2, 5], 
      state: 12
    }, 
    {
      pos: [5, 2, 6], 
      state: 12
    }, 
    {
      pos: [5, 2, 7], 
      state: 12
    }, 
    {
      pos: [5, 2, 8], 
      state: 12
    }, 
    {
      pos: [6, 2, 0], 
      state: 12
    }, 
    {
      pos: [6, 2, 1], 
      state: 12
    }, 
    {
      pos: [6, 2, 2], 
      state: 12
    }, 
    {
      pos: [6, 2, 3], 
      state: 12
    }, 
    {
      pos: [6, 2, 4], 
      state: 12
    }, 
    {
      pos: [6, 2, 5], 
      state: 12
    }, 
    {
      pos: [6, 2, 6], 
      state: 12
    }, 
    {
      pos: [6, 2, 7], 
      state: 12
    }, 
    {
      pos: [6, 2, 8], 
      state: 12
    }, 
    {
      pos: [7, 2, 0], 
      state: 12
    }, 
    {
      pos: [7, 2, 1], 
      state: 12
    }, 
    {
      pos: [7, 2, 2], 
      state: 12
    }, 
    {
      pos: [7, 2, 3], 
      state: 12
    }, 
    {
      pos: [7, 2, 4], 
      state: 12
    }, 
    {
      pos: [7, 2, 5], 
      state: 12
    }, 
    {
      pos: [7, 2, 6], 
      state: 12
    }, 
    {
      pos: [7, 2, 7], 
      state: 12
    }, 
    {
      pos: [7, 2, 8], 
      state: 12
    }, 
    {
      pos: [0, 3, 0], 
      state: 12
    }, 
    {
      pos: [0, 3, 1], 
      state: 12
    }, 
    {
      pos: [0, 3, 2], 
      state: 12
    }, 
    {
      pos: [0, 3, 3], 
      state: 12
    }, 
    {
      pos: [0, 3, 4], 
      state: 12
    }, 
    {
      pos: [0, 3, 5], 
      state: 12
    }, 
    {
      pos: [0, 3, 6], 
      state: 12
    }, 
    {
      pos: [0, 3, 7], 
      state: 12
    }, 
    {
      pos: [0, 3, 8], 
      state: 12
    }, 
    {
      pos: [1, 3, 0], 
      state: 12
    }, 
    {
      pos: [1, 3, 1], 
      state: 12
    }, 
    {
      pos: [1, 3, 2], 
      state: 12
    }, 
    {
      pos: [1, 3, 3], 
      state: 12
    }, 
    {
      pos: [1, 3, 4], 
      state: 27
    }, 
    {
      pos: [1, 3, 5], 
      state: 12
    }, 
    {
      pos: [1, 3, 6], 
      state: 27
    }, 
    {
      pos: [1, 3, 7], 
      state: 12
    }, 
    {
      pos: [1, 3, 8], 
      state: 12
    }, 
    {
      pos: [2, 3, 0], 
      state: 12
    }, 
    {
      pos: [2, 3, 1], 
      state: 12
    }, 
    {
      pos: [2, 3, 2], 
      state: 12
    }, 
    {
      pos: [2, 3, 3], 
      state: 12
    }, 
    {
      pos: [2, 3, 4], 
      state: 12
    }, 
    {
      pos: [2, 3, 5], 
      state: 12
    }, 
    {
      pos: [2, 3, 6], 
      state: 12
    }, 
    {
      pos: [2, 3, 7], 
      state: 12
    }, 
    {
      pos: [2, 3, 8], 
      state: 12
    }, 
    {
      pos: [3, 3, 0], 
      state: 12
    }, 
    {
      pos: [3, 3, 1], 
      state: 12
    }, 
    {
      pos: [3, 3, 2], 
      state: 12
    }, 
    {
      pos: [3, 3, 3], 
      state: 12
    }, 
    {
      pos: [3, 3, 4], 
      state: 12
    }, 
    {
      pos: [3, 3, 5], 
      state: 12
    }, 
    {
      pos: [3, 3, 6], 
      state: 12
    }, 
    {
      pos: [3, 3, 7], 
      state: 12
    }, 
    {
      pos: [3, 3, 8], 
      state: 12
    }, 
    {
      pos: [4, 3, 0], 
      state: 12
    }, 
    {
      pos: [4, 3, 1], 
      state: 12
    }, 
    {
      pos: [4, 3, 2], 
      state: 12
    }, 
    {
      pos: [4, 3, 3], 
      state: 12
    }, 
    {
      pos: [4, 3, 4], 
      state: 12
    }, 
    {
      pos: [4, 3, 5], 
      state: 12
    }, 
    {
      pos: [4, 3, 6], 
      state: 12
    }, 
    {
      pos: [4, 3, 7], 
      state: 12
    }, 
    {
      pos: [4, 3, 8], 
      state: 12
    }, 
    {
      pos: [5, 3, 0], 
      state: 12
    }, 
    {
      pos: [5, 3, 1], 
      state: 12
    }, 
    {
      pos: [5, 3, 2], 
      state: 12
    }, 
    {
      pos: [5, 3, 3], 
      state: 12
    }, 
    {
      pos: [5, 3, 4], 
      state: 12
    }, 
    {
      pos: [5, 3, 5], 
      state: 12
    }, 
    {
      pos: [5, 3, 6], 
      state: 12
    }, 
    {
      pos: [5, 3, 7], 
      state: 12
    }, 
    {
      pos: [5, 3, 8], 
      state: 12
    }, 
    {
      pos: [6, 3, 0], 
      state: 12
    }, 
    {
      pos: [6, 3, 1], 
      state: 12
    }, 
    {
      pos: [6, 3, 2], 
      state: 12
    }, 
    {
      pos: [6, 3, 3], 
      state: 12
    }, 
    {
      pos: [6, 3, 4], 
      state: 12
    }, 
    {
      pos: [6, 3, 5], 
      state: 12
    }, 
    {
      pos: [6, 3, 6], 
      state: 12
    }, 
    {
      pos: [6, 3, 7], 
      state: 12
    }, 
    {
      pos: [6, 3, 8], 
      state: 12
    }, 
    {
      pos: [7, 3, 0], 
      state: 12
    }, 
    {
      pos: [7, 3, 1], 
      state: 12
    }, 
    {
      pos: [7, 3, 2], 
      state: 12
    }, 
    {
      pos: [7, 3, 3], 
      state: 12
    }, 
    {
      pos: [7, 3, 4], 
      state: 12
    }, 
    {
      pos: [7, 3, 5], 
      state: 12
    }, 
    {
      pos: [7, 3, 6], 
      state: 12
    }, 
    {
      pos: [7, 3, 7], 
      state: 12
    }, 
    {
      pos: [7, 3, 8], 
      state: 12
    }, 
    {
      nbt: {
        final_state: "minecraft:spruce_stairs[facing=east]", 
        name: "minecraft:building_entrance", 
        pool: "minecraft:empty", 
        id: "minecraft:jigsaw", 
        target: "minecraft:building_entrance"
      }, 
      pos: [0, 0, 5], 
      state: 28
    }, 
    {
      nbt: {
        final_state: "minecraft:dirt", 
        name: "minecraft:bottom", 
        pool: "minecraft:village/common/animals", 
        id: "minecraft:jigsaw", 
        target: "minecraft:bottom"
      }, 
      pos: [2, 0, 5], 
      state: 29
    }
  ], 
  palette: [
    {
      Properties: {
        axis: "y"
      }, 
      Name: "minecraft:stripped_spruce_log"
    }, 
    {
      Properties: {
        snowy: "true"
      }, 
      Name: "minecraft:grass_block"
    }, 
    {
      Name: "minecraft:snow_block"
    }, 
    {
      Properties: {
        snowy: "false"
      }, 
      Name: "minecraft:grass_block"
    }, 
    {
      Name: "minecraft:dirt"
    }, 
    {
      Properties: {
        layers: "1"
      }, 
      Name: "minecraft:snow"
    }, 
    {
      Properties: {
        layers: "5"
      }, 
      Name: "minecraft:snow"
    }, 
    {
      Properties: {
        half: "bottom", 
        waterlogged: "false", 
        shape: "outer_left", 
        facing: "south"
      }, 
      Name: "minecraft:spruce_stairs"
    }, 
    {
      Properties: {
        half: "bottom", 
        waterlogged: "false", 
        shape: "outer_right", 
        facing: "north"
      }, 
      Name: "minecraft:spruce_stairs"
    }, 
    {
      Properties: {
        layers: "2"
      }, 
      Name: "minecraft:snow"
    }, 
    {
      Properties: {
        layers: "6"
      }, 
      Name: "minecraft:snow"
    }, 
    {
      Properties: {
        layers: "4"
      }, 
      Name: "minecraft:snow"
    }, 
    {
      Name: "minecraft:air"
    }, 
    {
      Properties: {
        east: "true", 
        waterlogged: "false", 
        south: "true", 
        north: "false", 
        west: "false"
      }, 
      Name: "minecraft:spruce_fence"
    }, 
    {
      Properties: {
        east: "false", 
        waterlogged: "false", 
        south: "true", 
        north: "true", 
        west: "false"
      }, 
      Name: "minecraft:spruce_fence"
    }, 
    {
      Properties: {
        in_wall: "false", 
        powered: "false", 
        facing: "east", 
        open: "false"
      }, 
      Name: "minecraft:spruce_fence_gate"
    }, 
    {
      Properties: {
        east: "true", 
        waterlogged: "false", 
        south: "false", 
        north: "true", 
        west: "false"
      }, 
      Name: "minecraft:spruce_fence"
    }, 
    {
      Properties: {
        east: "true", 
        waterlogged: "false", 
        south: "false", 
        north: "false", 
        west: "true"
      }, 
      Name: "minecraft:spruce_fence"
    }, 
    {
      Properties: {
        east: "true", 
        waterlogged: "false", 
        south: "false", 
        north: "true", 
        west: "true"
      }, 
      Name: "minecraft:spruce_fence"
    }, 
    {
      Properties: {
        half: "bottom", 
        waterlogged: "true", 
        shape: "inner_right", 
        facing: "west"
      }, 
      Name: "minecraft:spruce_stairs"
    }, 
    {
      Properties: {
        half: "bottom", 
        waterlogged: "true", 
        shape: "inner_right", 
        facing: "south"
      }, 
      Name: "minecraft:spruce_stairs"
    }, 
    {
      Properties: {
        layers: "3"
      }, 
      Name: "minecraft:snow"
    }, 
    {
      Properties: {
        half: "bottom", 
        waterlogged: "true", 
        shape: "inner_right", 
        facing: "north"
      }, 
      Name: "minecraft:spruce_stairs"
    }, 
    {
      Properties: {
        half: "bottom", 
        waterlogged: "true", 
        shape: "inner_right", 
        facing: "east"
      }, 
      Name: "minecraft:spruce_stairs"
    }, 
    {
      Properties: {
        east: "false", 
        waterlogged: "false", 
        south: "true", 
        north: "false", 
        west: "true"
      }, 
      Name: "minecraft:spruce_fence"
    }, 
    {
      Properties: {
        east: "false", 
        waterlogged: "false", 
        south: "false", 
        north: "true", 
        west: "true"
      }, 
      Name: "minecraft:spruce_fence"
    }, 
    {
      Properties: {
        east: "false", 
        waterlogged: "false", 
        south: "false", 
        north: "false", 
        west: "false"
      }, 
      Name: "minecraft:spruce_fence"
    }, 
    {
      Name: "minecraft:torch"
    }, 
    {
      Properties: {
        orientation: "west_up"
      }, 
      Name: "minecraft:jigsaw"
    }, 
    {
      Properties: {
        orientation: "up_north"
      }, 
      Name: "minecraft:jigsaw"
    }
  ]
}
