{
  size: [7, 6, 7], 
  entities: [], 
  blocks: [
    {
      pos: [0, 0, 0], 
      state: 0
    }, 
    {
      pos: [5, 0, 0], 
      state: 0
    }, 
    {
      pos: [0, 0, 1], 
      state: 0
    }, 
    {
      pos: [1, 0, 1], 
      state: 1
    }, 
    {
      pos: [2, 0, 1], 
      state: 1
    }, 
    {
      pos: [3, 0, 1], 
      state: 1
    }, 
    {
      pos: [4, 0, 1], 
      state: 1
    }, 
    {
      pos: [5, 0, 1], 
      state: 0
    }, 
    {
      pos: [0, 0, 2], 
      state: 0
    }, 
    {
      pos: [1, 0, 2], 
      state: 0
    }, 
    {
      pos: [2, 0, 2], 
      state: 0
    }, 
    {
      pos: [4, 0, 2], 
      state: 0
    }, 
    {
      pos: [5, 0, 2], 
      state: 0
    }, 
    {
      pos: [0, 0, 3], 
      state: 0
    }, 
    {
      pos: [1, 0, 3], 
      state: 0
    }, 
    {
      pos: [2, 0, 3], 
      state: 0
    }, 
    {
      pos: [3, 0, 3], 
      state: 0
    }, 
    {
      pos: [4, 0, 3], 
      state: 0
    }, 
    {
      pos: [5, 0, 3], 
      state: 0
    }, 
    {
      pos: [0, 0, 4], 
      state: 0
    }, 
    {
      pos: [1, 0, 4], 
      state: 1
    }, 
    {
      pos: [2, 0, 4], 
      state: 1
    }, 
    {
      pos: [3, 0, 4], 
      state: 1
    }, 
    {
      pos: [4, 0, 4], 
      state: 1
    }, 
    {
      pos: [5, 0, 4], 
      state: 0
    }, 
    {
      pos: [6, 0, 4], 
      state: 2
    }, 
    {
      pos: [0, 0, 5], 
      state: 0
    }, 
    {
      pos: [4, 0, 5], 
      state: 2
    }, 
    {
      pos: [5, 0, 5], 
      state: 0
    }, 
    {
      pos: [6, 0, 5], 
      state: 2
    }, 
    {
      pos: [5, 0, 6], 
      state: 2
    }, 
    {
      nbt: {
        final_state: "minecraft:spruce_planks", 
        name: "minecraft:bottom", 
        pool: "minecraft:village/snowy/villagers", 
        id: "minecraft:jigsaw", 
        target: "minecraft:bottom"
      }, 
      pos: [3, 0, 2], 
      state: 3
    }, 
    {
      nbt: {
        final_state: "minecraft:structure_void", 
        name: "minecraft:building_entrance", 
        pool: "minecraft:empty", 
        id: "minecraft:jigsaw", 
        target: "minecraft:building_entrance"
      }, 
      pos: [3, 0, 6], 
      state: 4
    }, 
    {
      pos: [1, 0, 0], 
      state: 5
    }, 
    {
      pos: [2, 0, 0], 
      state: 5
    }, 
    {
      pos: [3, 0, 0], 
      state: 5
    }, 
    {
      pos: [4, 0, 0], 
      state: 5
    }, 
    {
      pos: [6, 0, 0], 
      state: 5
    }, 
    {
      pos: [6, 0, 1], 
      state: 5
    }, 
    {
      pos: [6, 0, 2], 
      state: 5
    }, 
    {
      pos: [6, 0, 3], 
      state: 5
    }, 
    {
      pos: [1, 0, 5], 
      state: 5
    }, 
    {
      pos: [2, 0, 5], 
      state: 6
    }, 
    {
      pos: [3, 0, 5], 
      state: 6
    }, 
    {
      pos: [0, 0, 6], 
      state: 5
    }, 
    {
      pos: [1, 0, 6], 
      state: 5
    }, 
    {
      pos: [2, 0, 6], 
      state: 5
    }, 
    {
      pos: [4, 0, 6], 
      state: 5
    }, 
    {
      pos: [6, 0, 6], 
      state: 5
    }, 
    {
      pos: [0, 1, 0], 
      state: 0
    }, 
    {
      pos: [5, 1, 0], 
      state: 0
    }, 
    {
      pos: [0, 1, 1], 
      state: 0
    }, 
    {
      pos: [1, 1, 1], 
      state: 1
    }, 
    {
      pos: [2, 1, 1], 
      state: 1
    }, 
    {
      pos: [3, 1, 1], 
      state: 1
    }, 
    {
      pos: [4, 1, 1], 
      state: 1
    }, 
    {
      pos: [5, 1, 1], 
      state: 0
    }, 
    {
      pos: [0, 1, 2], 
      state: 0
    }, 
    {
      pos: [1, 1, 2], 
      state: 0
    }, 
    {
      pos: [5, 1, 2], 
      state: 0
    }, 
    {
      pos: [0, 1, 3], 
      state: 0
    }, 
    {
      pos: [1, 1, 3], 
      state: 0
    }, 
    {
      pos: [5, 1, 3], 
      state: 0
    }, 
    {
      pos: [0, 1, 4], 
      state: 0
    }, 
    {
      pos: [1, 1, 4], 
      state: 1
    }, 
    {
      pos: [4, 1, 4], 
      state: 1
    }, 
    {
      pos: [5, 1, 4], 
      state: 0
    }, 
    {
      pos: [6, 1, 4], 
      state: 2
    }, 
    {
      pos: [0, 1, 5], 
      state: 0
    }, 
    {
      pos: [5, 1, 5], 
      state: 0
    }, 
    {
      nbt: {
        id: "minecraft:bed"
      }, 
      pos: [2, 1, 2], 
      state: 7
    }, 
    {
      nbt: {
        CookTime: 0s, 
        BurnTime: 0s, 
        Items: [], 
        id: "minecraft:furnace", 
        CookTimeTotal: 0s, 
        RecipesUsed: {}
      }, 
      pos: [4, 1, 2], 
      state: 8
    }, 
    {
      nbt: {
        id: "minecraft:bed"
      }, 
      pos: [2, 1, 3], 
      state: 9
    }, 
    {
      nbt: {
        CookTime: 0s, 
        BurnTime: 0s, 
        Items: [], 
        id: "minecraft:furnace", 
        CookTimeTotal: 0s, 
        RecipesUsed: {}
      }, 
      pos: [4, 1, 3], 
      state: 8
    }, 
    {
      pos: [1, 1, 0], 
      state: 5
    }, 
    {
      pos: [2, 1, 0], 
      state: 5
    }, 
    {
      pos: [3, 1, 0], 
      state: 5
    }, 
    {
      pos: [4, 1, 0], 
      state: 5
    }, 
    {
      pos: [6, 1, 0], 
      state: 5
    }, 
    {
      pos: [6, 1, 1], 
      state: 5
    }, 
    {
      pos: [3, 1, 2], 
      state: 5
    }, 
    {
      pos: [6, 1, 2], 
      state: 5
    }, 
    {
      pos: [3, 1, 3], 
      state: 5
    }, 
    {
      pos: [6, 1, 3], 
      state: 5
    }, 
    {
      pos: [2, 1, 4], 
      state: 10
    }, 
    {
      pos: [3, 1, 4], 
      state: 11
    }, 
    {
      pos: [1, 1, 5], 
      state: 5
    }, 
    {
      pos: [2, 1, 5], 
      state: 5
    }, 
    {
      pos: [3, 1, 5], 
      state: 5
    }, 
    {
      pos: [4, 1, 5], 
      state: 12
    }, 
    {
      pos: [6, 1, 5], 
      state: 13
    }, 
    {
      pos: [0, 1, 6], 
      state: 5
    }, 
    {
      pos: [1, 1, 6], 
      state: 5
    }, 
    {
      pos: [2, 1, 6], 
      state: 5
    }, 
    {
      pos: [3, 1, 6], 
      state: 5
    }, 
    {
      pos: [4, 1, 6], 
      state: 5
    }, 
    {
      pos: [5, 1, 6], 
      state: 12
    }, 
    {
      pos: [6, 1, 6], 
      state: 5
    }, 
    {
      pos: [1, 2, 0], 
      state: 0
    }, 
    {
      pos: [4, 2, 0], 
      state: 0
    }, 
    {
      pos: [1, 2, 1], 
      state: 0
    }, 
    {
      pos: [2, 2, 1], 
      state: 1
    }, 
    {
      pos: [3, 2, 1], 
      state: 1
    }, 
    {
      pos: [4, 2, 1], 
      state: 0
    }, 
    {
      pos: [1, 2, 2], 
      state: 0
    }, 
    {
      pos: [4, 2, 2], 
      state: 0
    }, 
    {
      pos: [1, 2, 3], 
      state: 0
    }, 
    {
      pos: [4, 2, 3], 
      state: 0
    }, 
    {
      pos: [1, 2, 4], 
      state: 1
    }, 
    {
      pos: [4, 2, 4], 
      state: 1
    }, 
    {
      pos: [0, 2, 0], 
      state: 14
    }, 
    {
      pos: [2, 2, 0], 
      state: 5
    }, 
    {
      pos: [3, 2, 0], 
      state: 5
    }, 
    {
      pos: [5, 2, 0], 
      state: 15
    }, 
    {
      pos: [6, 2, 0], 
      state: 5
    }, 
    {
      pos: [0, 2, 1], 
      state: 14
    }, 
    {
      pos: [5, 2, 1], 
      state: 15
    }, 
    {
      pos: [6, 2, 1], 
      state: 5
    }, 
    {
      pos: [0, 2, 2], 
      state: 13
    }, 
    {
      pos: [2, 2, 2], 
      state: 5
    }, 
    {
      pos: [3, 2, 2], 
      state: 5
    }, 
    {
      pos: [5, 2, 2], 
      state: 16
    }, 
    {
      pos: [6, 2, 2], 
      state: 5
    }, 
    {
      pos: [0, 2, 3], 
      state: 13
    }, 
    {
      pos: [2, 2, 3], 
      state: 5
    }, 
    {
      pos: [3, 2, 3], 
      state: 5
    }, 
    {
      pos: [5, 2, 3], 
      state: 12
    }, 
    {
      pos: [6, 2, 3], 
      state: 5
    }, 
    {
      pos: [0, 2, 4], 
      state: 14
    }, 
    {
      pos: [2, 2, 4], 
      state: 17
    }, 
    {
      pos: [3, 2, 4], 
      state: 18
    }, 
    {
      pos: [5, 2, 4], 
      state: 15
    }, 
    {
      pos: [6, 2, 4], 
      state: 13
    }, 
    {
      pos: [0, 2, 5], 
      state: 14
    }, 
    {
      pos: [1, 2, 5], 
      state: 19
    }, 
    {
      pos: [2, 2, 5], 
      state: 5
    }, 
    {
      pos: [3, 2, 5], 
      state: 5
    }, 
    {
      pos: [4, 2, 5], 
      state: 20
    }, 
    {
      pos: [5, 2, 5], 
      state: 15
    }, 
    {
      pos: [6, 2, 5], 
      state: 5
    }, 
    {
      pos: [0, 2, 6], 
      state: 5
    }, 
    {
      pos: [1, 2, 6], 
      state: 21
    }, 
    {
      pos: [2, 2, 6], 
      state: 5
    }, 
    {
      pos: [3, 2, 6], 
      state: 5
    }, 
    {
      pos: [4, 2, 6], 
      state: 21
    }, 
    {
      pos: [5, 2, 6], 
      state: 5
    }, 
    {
      pos: [6, 2, 6], 
      state: 5
    }, 
    {
      pos: [1, 3, 0], 
      state: 0
    }, 
    {
      pos: [4, 3, 0], 
      state: 0
    }, 
    {
      pos: [1, 3, 1], 
      state: 0
    }, 
    {
      pos: [2, 3, 1], 
      state: 1
    }, 
    {
      pos: [3, 3, 1], 
      state: 1
    }, 
    {
      pos: [4, 3, 1], 
      state: 0
    }, 
    {
      pos: [1, 3, 2], 
      state: 0
    }, 
    {
      pos: [4, 3, 2], 
      state: 0
    }, 
    {
      pos: [1, 3, 3], 
      state: 0
    }, 
    {
      pos: [4, 3, 3], 
      state: 0
    }, 
    {
      pos: [1, 3, 4], 
      state: 0
    }, 
    {
      pos: [2, 3, 4], 
      state: 1
    }, 
    {
      pos: [3, 3, 4], 
      state: 1
    }, 
    {
      pos: [4, 3, 4], 
      state: 0
    }, 
    {
      pos: [1, 3, 5], 
      state: 0
    }, 
    {
      pos: [4, 3, 5], 
      state: 0
    }, 
    {
      pos: [0, 3, 0], 
      state: 5
    }, 
    {
      pos: [2, 3, 0], 
      state: 5
    }, 
    {
      pos: [3, 3, 0], 
      state: 5
    }, 
    {
      pos: [5, 3, 0], 
      state: 5
    }, 
    {
      pos: [6, 3, 0], 
      state: 5
    }, 
    {
      pos: [0, 3, 1], 
      state: 5
    }, 
    {
      pos: [5, 3, 1], 
      state: 5
    }, 
    {
      pos: [6, 3, 1], 
      state: 5
    }, 
    {
      pos: [0, 3, 2], 
      state: 5
    }, 
    {
      pos: [2, 3, 2], 
      state: 5
    }, 
    {
      pos: [3, 3, 2], 
      state: 5
    }, 
    {
      pos: [5, 3, 2], 
      state: 5
    }, 
    {
      pos: [6, 3, 2], 
      state: 5
    }, 
    {
      pos: [0, 3, 3], 
      state: 5
    }, 
    {
      pos: [2, 3, 3], 
      state: 22
    }, 
    {
      pos: [3, 3, 3], 
      state: 22
    }, 
    {
      pos: [5, 3, 3], 
      state: 5
    }, 
    {
      pos: [6, 3, 3], 
      state: 5
    }, 
    {
      pos: [0, 3, 4], 
      state: 5
    }, 
    {
      pos: [5, 3, 4], 
      state: 5
    }, 
    {
      pos: [6, 3, 4], 
      state: 5
    }, 
    {
      pos: [0, 3, 5], 
      state: 5
    }, 
    {
      pos: [2, 3, 5], 
      state: 5
    }, 
    {
      pos: [3, 3, 5], 
      state: 5
    }, 
    {
      pos: [5, 3, 5], 
      state: 5
    }, 
    {
      pos: [6, 3, 5], 
      state: 5
    }, 
    {
      pos: [0, 3, 6], 
      state: 5
    }, 
    {
      pos: [1, 3, 6], 
      state: 23
    }, 
    {
      pos: [2, 3, 6], 
      state: 5
    }, 
    {
      pos: [3, 3, 6], 
      state: 5
    }, 
    {
      pos: [4, 3, 6], 
      state: 23
    }, 
    {
      pos: [5, 3, 6], 
      state: 5
    }, 
    {
      pos: [6, 3, 6], 
      state: 5
    }, 
    {
      pos: [2, 4, 0], 
      state: 0
    }, 
    {
      pos: [3, 4, 0], 
      state: 0
    }, 
    {
      pos: [2, 4, 1], 
      state: 0
    }, 
    {
      pos: [3, 4, 1], 
      state: 0
    }, 
    {
      pos: [2, 4, 2], 
      state: 0
    }, 
    {
      pos: [3, 4, 2], 
      state: 0
    }, 
    {
      pos: [2, 4, 3], 
      state: 0
    }, 
    {
      pos: [3, 4, 3], 
      state: 0
    }, 
    {
      pos: [2, 4, 4], 
      state: 1
    }, 
    {
      pos: [3, 4, 4], 
      state: 1
    }, 
    {
      pos: [0, 4, 0], 
      state: 5
    }, 
    {
      pos: [1, 4, 0], 
      state: 14
    }, 
    {
      pos: [4, 4, 0], 
      state: 15
    }, 
    {
      pos: [5, 4, 0], 
      state: 5
    }, 
    {
      pos: [6, 4, 0], 
      state: 5
    }, 
    {
      pos: [0, 4, 1], 
      state: 5
    }, 
    {
      pos: [1, 4, 1], 
      state: 14
    }, 
    {
      pos: [4, 4, 1], 
      state: 15
    }, 
    {
      pos: [5, 4, 1], 
      state: 5
    }, 
    {
      pos: [6, 4, 1], 
      state: 5
    }, 
    {
      pos: [0, 4, 2], 
      state: 5
    }, 
    {
      pos: [1, 4, 2], 
      state: 13
    }, 
    {
      pos: [4, 4, 2], 
      state: 12
    }, 
    {
      pos: [5, 4, 2], 
      state: 5
    }, 
    {
      pos: [6, 4, 2], 
      state: 5
    }, 
    {
      pos: [0, 4, 3], 
      state: 5
    }, 
    {
      pos: [1, 4, 3], 
      state: 13
    }, 
    {
      pos: [4, 4, 3], 
      state: 13
    }, 
    {
      pos: [5, 4, 3], 
      state: 5
    }, 
    {
      pos: [6, 4, 3], 
      state: 5
    }, 
    {
      pos: [0, 4, 4], 
      state: 5
    }, 
    {
      pos: [1, 4, 4], 
      state: 14
    }, 
    {
      pos: [4, 4, 4], 
      state: 15
    }, 
    {
      pos: [5, 4, 4], 
      state: 5
    }, 
    {
      pos: [6, 4, 4], 
      state: 5
    }, 
    {
      pos: [0, 4, 5], 
      state: 5
    }, 
    {
      pos: [1, 4, 5], 
      state: 14
    }, 
    {
      pos: [2, 4, 5], 
      state: 19
    }, 
    {
      pos: [3, 4, 5], 
      state: 20
    }, 
    {
      pos: [4, 4, 5], 
      state: 15
    }, 
    {
      pos: [5, 4, 5], 
      state: 5
    }, 
    {
      pos: [6, 4, 5], 
      state: 5
    }, 
    {
      pos: [0, 4, 6], 
      state: 5
    }, 
    {
      pos: [1, 4, 6], 
      state: 5
    }, 
    {
      pos: [2, 4, 6], 
      state: 5
    }, 
    {
      pos: [3, 4, 6], 
      state: 5
    }, 
    {
      pos: [4, 4, 6], 
      state: 5
    }, 
    {
      pos: [5, 4, 6], 
      state: 5
    }, 
    {
      pos: [6, 4, 6], 
      state: 5
    }, 
    {
      pos: [0, 5, 0], 
      state: 5
    }, 
    {
      pos: [1, 5, 0], 
      state: 5
    }, 
    {
      pos: [2, 5, 0], 
      state: 24
    }, 
    {
      pos: [3, 5, 0], 
      state: 24
    }, 
    {
      pos: [4, 5, 0], 
      state: 5
    }, 
    {
      pos: [5, 5, 0], 
      state: 5
    }, 
    {
      pos: [6, 5, 0], 
      state: 5
    }, 
    {
      pos: [0, 5, 1], 
      state: 5
    }, 
    {
      pos: [1, 5, 1], 
      state: 5
    }, 
    {
      pos: [2, 5, 1], 
      state: 24
    }, 
    {
      pos: [3, 5, 1], 
      state: 24
    }, 
    {
      pos: [4, 5, 1], 
      state: 5
    }, 
    {
      pos: [5, 5, 1], 
      state: 5
    }, 
    {
      pos: [6, 5, 1], 
      state: 5
    }, 
    {
      pos: [0, 5, 2], 
      state: 5
    }, 
    {
      pos: [1, 5, 2], 
      state: 5
    }, 
    {
      pos: [2, 5, 2], 
      state: 24
    }, 
    {
      pos: [3, 5, 2], 
      state: 24
    }, 
    {
      pos: [4, 5, 2], 
      state: 5
    }, 
    {
      pos: [5, 5, 2], 
      state: 5
    }, 
    {
      pos: [6, 5, 2], 
      state: 5
    }, 
    {
      pos: [0, 5, 3], 
      state: 5
    }, 
    {
      pos: [1, 5, 3], 
      state: 5
    }, 
    {
      pos: [2, 5, 3], 
      state: 24
    }, 
    {
      pos: [3, 5, 3], 
      state: 24
    }, 
    {
      pos: [4, 5, 3], 
      state: 5
    }, 
    {
      pos: [5, 5, 3], 
      state: 5
    }, 
    {
      pos: [6, 5, 3], 
      state: 5
    }, 
    {
      pos: [0, 5, 4], 
      state: 5
    }, 
    {
      pos: [1, 5, 4], 
      state: 5
    }, 
    {
      pos: [2, 5, 4], 
      state: 24
    }, 
    {
      pos: [3, 5, 4], 
      state: 24
    }, 
    {
      pos: [4, 5, 4], 
      state: 5
    }, 
    {
      pos: [5, 5, 4], 
      state: 5
    }, 
    {
      pos: [6, 5, 4], 
      state: 5
    }, 
    {
      pos: [0, 5, 5], 
      state: 5
    }, 
    {
      pos: [1, 5, 5], 
      state: 5
    }, 
    {
      pos: [2, 5, 5], 
      state: 24
    }, 
    {
      pos: [3, 5, 5], 
      state: 24
    }, 
    {
      pos: [4, 5, 5], 
      state: 5
    }, 
    {
      pos: [5, 5, 5], 
      state: 5
    }, 
    {
      pos: [6, 5, 5], 
      state: 5
    }, 
    {
      pos: [0, 5, 6], 
      state: 5
    }, 
    {
      pos: [1, 5, 6], 
      state: 5
    }, 
    {
      pos: [2, 5, 6], 
      state: 5
    }, 
    {
      pos: [3, 5, 6], 
      state: 5
    }, 
    {
      pos: [4, 5, 6], 
      state: 5
    }, 
    {
      pos: [5, 5, 6], 
      state: 5
    }, 
    {
      pos: [6, 5, 6], 
      state: 5
    }
  ], 
  palette: [
    {
      Name: "minecraft:spruce_planks"
    }, 
    {
      Properties: {
        axis: "y"
      }, 
      Name: "minecraft:stripped_spruce_wood"
    }, 
    {
      Name: "minecraft:snow_block"
    }, 
    {
      Properties: {
        orientation: "up_north"
      }, 
      Name: "minecraft:jigsaw"
    }, 
    {
      Properties: {
        orientation: "south_up"
      }, 
      Name: "minecraft:jigsaw"
    }, 
    {
      Name: "minecraft:air"
    }, 
    {
      Properties: {
        half: "bottom", 
        waterlogged: "false", 
        shape: "straight", 
        facing: "north"
      }, 
      Name: "minecraft:spruce_stairs"
    }, 
    {
      Properties: {
        part: "head", 
        facing: "north", 
        occupied: "false"
      }, 
      Name: "minecraft:blue_bed"
    }, 
    {
      Properties: {
        lit: "false", 
        facing: "west"
      }, 
      Name: "minecraft:furnace"
    }, 
    {
      Properties: {
        part: "foot", 
        facing: "north", 
        occupied: "false"
      }, 
      Name: "minecraft:blue_bed"
    }, 
    {
      Properties: {
        hinge: "left", 
        half: "lower", 
        powered: "false", 
        facing: "north", 
        open: "false"
      }, 
      Name: "minecraft:spruce_door"
    }, 
    {
      Properties: {
        hinge: "right", 
        half: "lower", 
        powered: "false", 
        facing: "north", 
        open: "false"
      }, 
      Name: "minecraft:spruce_door"
    }, 
    {
      Properties: {
        layers: "4"
      }, 
      Name: "minecraft:snow"
    }, 
    {
      Properties: {
        layers: "1"
      }, 
      Name: "minecraft:snow"
    }, 
    {
      Properties: {
        half: "bottom", 
        waterlogged: "false", 
        shape: "straight", 
        facing: "east"
      }, 
      Name: "minecraft:spruce_stairs"
    }, 
    {
      Properties: {
        half: "bottom", 
        waterlogged: "false", 
        shape: "straight", 
        facing: "west"
      }, 
      Name: "minecraft:spruce_stairs"
    }, 
    {
      Properties: {
        layers: "2"
      }, 
      Name: "minecraft:snow"
    }, 
    {
      Properties: {
        hinge: "left", 
        half: "upper", 
        powered: "false", 
        facing: "north", 
        open: "false"
      }, 
      Name: "minecraft:spruce_door"
    }, 
    {
      Properties: {
        hinge: "right", 
        half: "upper", 
        powered: "false", 
        facing: "north", 
        open: "false"
      }, 
      Name: "minecraft:spruce_door"
    }, 
    {
      Properties: {
        half: "top", 
        waterlogged: "false", 
        shape: "straight", 
        facing: "west"
      }, 
      Name: "minecraft:spruce_stairs"
    }, 
    {
      Properties: {
        half: "top", 
        waterlogged: "false", 
        shape: "straight", 
        facing: "east"
      }, 
      Name: "minecraft:spruce_stairs"
    }, 
    {
      Properties: {
        hanging: "true"
      }, 
      Name: "minecraft:lantern"
    }, 
    {
      Properties: {
        facing: "north"
      }, 
      Name: "minecraft:wall_torch"
    }, 
    {
      Properties: {
        east: "false", 
        waterlogged: "false", 
        south: "false", 
        north: "true", 
        west: "false"
      }, 
      Name: "minecraft:spruce_fence"
    }, 
    {
      Properties: {
        waterlogged: "false", 
        type: "bottom"
      }, 
      Name: "minecraft:spruce_slab"
    }
  ]
}
