{
  size: [7, 8, 7], 
  entities: [], 
  blocks: [
    {
      pos: [1, 0, 1], 
      state: 0
    }, 
    {
      pos: [2, 0, 1], 
      state: 0
    }, 
    {
      pos: [3, 0, 1], 
      state: 0
    }, 
    {
      pos: [4, 0, 1], 
      state: 0
    }, 
    {
      pos: [5, 0, 1], 
      state: 0
    }, 
    {
      pos: [1, 0, 2], 
      state: 0
    }, 
    {
      pos: [2, 0, 2], 
      state: 1
    }, 
    {
      pos: [3, 0, 2], 
      state: 1
    }, 
    {
      pos: [4, 0, 2], 
      state: 1
    }, 
    {
      pos: [5, 0, 2], 
      state: 0
    }, 
    {
      pos: [1, 0, 3], 
      state: 0
    }, 
    {
      pos: [2, 0, 3], 
      state: 1
    }, 
    {
      pos: [4, 0, 3], 
      state: 2
    }, 
    {
      pos: [5, 0, 3], 
      state: 0
    }, 
    {
      pos: [1, 0, 4], 
      state: 0
    }, 
    {
      pos: [2, 0, 4], 
      state: 1
    }, 
    {
      pos: [3, 0, 4], 
      state: 1
    }, 
    {
      pos: [4, 0, 4], 
      state: 1
    }, 
    {
      pos: [5, 0, 4], 
      state: 0
    }, 
    {
      pos: [1, 0, 5], 
      state: 0
    }, 
    {
      pos: [2, 0, 5], 
      state: 0
    }, 
    {
      pos: [3, 0, 5], 
      state: 0
    }, 
    {
      pos: [4, 0, 5], 
      state: 0
    }, 
    {
      pos: [5, 0, 5], 
      state: 0
    }, 
    {
      nbt: {
        final_state: "minecraft:spruce_stairs[facing=south]", 
        name: "minecraft:building_entrance", 
        pool: "minecraft:empty", 
        id: "minecraft:jigsaw", 
        target: "minecraft:building_entrance"
      }, 
      pos: [3, 0, 0], 
      state: 3
    }, 
    {
      nbt: {
        final_state: "minecraft:spruce_planks", 
        name: "minecraft:bottom", 
        pool: "minecraft:village/snowy/villagers", 
        id: "minecraft:jigsaw", 
        target: "minecraft:bottom"
      }, 
      pos: [3, 0, 3], 
      state: 4
    }, 
    {
      pos: [0, 0, 0], 
      state: 5
    }, 
    {
      pos: [1, 0, 0], 
      state: 5
    }, 
    {
      pos: [2, 0, 0], 
      state: 6
    }, 
    {
      pos: [4, 0, 0], 
      state: 7
    }, 
    {
      pos: [5, 0, 0], 
      state: 5
    }, 
    {
      pos: [6, 0, 0], 
      state: 5
    }, 
    {
      pos: [0, 0, 1], 
      state: 5
    }, 
    {
      pos: [6, 0, 1], 
      state: 5
    }, 
    {
      pos: [0, 0, 2], 
      state: 5
    }, 
    {
      pos: [6, 0, 2], 
      state: 5
    }, 
    {
      pos: [0, 0, 3], 
      state: 5
    }, 
    {
      pos: [6, 0, 3], 
      state: 5
    }, 
    {
      pos: [0, 0, 4], 
      state: 5
    }, 
    {
      pos: [6, 0, 4], 
      state: 5
    }, 
    {
      pos: [0, 0, 5], 
      state: 5
    }, 
    {
      pos: [6, 0, 5], 
      state: 5
    }, 
    {
      pos: [0, 0, 6], 
      state: 5
    }, 
    {
      pos: [1, 0, 6], 
      state: 5
    }, 
    {
      pos: [2, 0, 6], 
      state: 5
    }, 
    {
      pos: [3, 0, 6], 
      state: 5
    }, 
    {
      pos: [4, 0, 6], 
      state: 5
    }, 
    {
      pos: [5, 0, 6], 
      state: 5
    }, 
    {
      pos: [6, 0, 6], 
      state: 5
    }, 
    {
      pos: [0, 1, 1], 
      state: 1
    }, 
    {
      pos: [1, 1, 1], 
      state: 0
    }, 
    {
      pos: [2, 1, 1], 
      state: 0
    }, 
    {
      pos: [4, 1, 1], 
      state: 0
    }, 
    {
      pos: [5, 1, 1], 
      state: 0
    }, 
    {
      pos: [6, 1, 1], 
      state: 1
    }, 
    {
      pos: [1, 1, 2], 
      state: 0
    }, 
    {
      pos: [5, 1, 2], 
      state: 0
    }, 
    {
      pos: [0, 1, 3], 
      state: 1
    }, 
    {
      pos: [1, 1, 3], 
      state: 0
    }, 
    {
      pos: [5, 1, 3], 
      state: 0
    }, 
    {
      pos: [6, 1, 3], 
      state: 1
    }, 
    {
      pos: [1, 1, 4], 
      state: 0
    }, 
    {
      pos: [5, 1, 4], 
      state: 0
    }, 
    {
      pos: [0, 1, 5], 
      state: 1
    }, 
    {
      pos: [1, 1, 5], 
      state: 0
    }, 
    {
      pos: [2, 1, 5], 
      state: 0
    }, 
    {
      pos: [3, 1, 5], 
      state: 0
    }, 
    {
      pos: [4, 1, 5], 
      state: 0
    }, 
    {
      pos: [5, 1, 5], 
      state: 0
    }, 
    {
      pos: [6, 1, 5], 
      state: 1
    }, 
    {
      nbt: {
        id: "minecraft:bed"
      }, 
      pos: [2, 1, 3], 
      state: 8
    }, 
    {
      nbt: {
        id: "minecraft:bed"
      }, 
      pos: [2, 1, 4], 
      state: 9
    }, 
    {
      nbt: {
        CookTime: 0s, 
        BurnTime: 0s, 
        Items: [], 
        id: "minecraft:furnace", 
        CookTimeTotal: 0s, 
        RecipesUsed: {}
      }, 
      pos: [4, 1, 4], 
      state: 10
    }, 
    {
      pos: [0, 1, 0], 
      state: 11
    }, 
    {
      pos: [1, 1, 0], 
      state: 12
    }, 
    {
      pos: [2, 1, 0], 
      state: 12
    }, 
    {
      pos: [3, 1, 0], 
      state: 12
    }, 
    {
      pos: [4, 1, 0], 
      state: 12
    }, 
    {
      pos: [5, 1, 0], 
      state: 12
    }, 
    {
      pos: [6, 1, 0], 
      state: 11
    }, 
    {
      pos: [3, 1, 1], 
      state: 13
    }, 
    {
      pos: [0, 1, 2], 
      state: 11
    }, 
    {
      pos: [2, 1, 2], 
      state: 12
    }, 
    {
      pos: [3, 1, 2], 
      state: 12
    }, 
    {
      pos: [4, 1, 2], 
      state: 12
    }, 
    {
      pos: [6, 1, 2], 
      state: 11
    }, 
    {
      pos: [3, 1, 3], 
      state: 12
    }, 
    {
      pos: [4, 1, 3], 
      state: 12
    }, 
    {
      pos: [0, 1, 4], 
      state: 11
    }, 
    {
      pos: [3, 1, 4], 
      state: 12
    }, 
    {
      pos: [6, 1, 4], 
      state: 11
    }, 
    {
      pos: [0, 1, 6], 
      state: 11
    }, 
    {
      pos: [1, 1, 6], 
      state: 12
    }, 
    {
      pos: [2, 1, 6], 
      state: 12
    }, 
    {
      pos: [3, 1, 6], 
      state: 12
    }, 
    {
      pos: [4, 1, 6], 
      state: 12
    }, 
    {
      pos: [5, 1, 6], 
      state: 12
    }, 
    {
      pos: [6, 1, 6], 
      state: 11
    }, 
    {
      pos: [0, 2, 0], 
      state: 1
    }, 
    {
      pos: [6, 2, 0], 
      state: 1
    }, 
    {
      pos: [0, 2, 1], 
      state: 1
    }, 
    {
      pos: [1, 2, 1], 
      state: 0
    }, 
    {
      pos: [2, 2, 1], 
      state: 0
    }, 
    {
      pos: [4, 2, 1], 
      state: 0
    }, 
    {
      pos: [5, 2, 1], 
      state: 0
    }, 
    {
      pos: [6, 2, 1], 
      state: 1
    }, 
    {
      pos: [0, 2, 2], 
      state: 1
    }, 
    {
      pos: [1, 2, 2], 
      state: 14
    }, 
    {
      pos: [5, 2, 2], 
      state: 14
    }, 
    {
      pos: [6, 2, 2], 
      state: 1
    }, 
    {
      pos: [0, 2, 3], 
      state: 1
    }, 
    {
      pos: [1, 2, 3], 
      state: 14
    }, 
    {
      pos: [5, 2, 3], 
      state: 14
    }, 
    {
      pos: [6, 2, 3], 
      state: 1
    }, 
    {
      pos: [0, 2, 4], 
      state: 1
    }, 
    {
      pos: [1, 2, 4], 
      state: 14
    }, 
    {
      pos: [5, 2, 4], 
      state: 14
    }, 
    {
      pos: [6, 2, 4], 
      state: 1
    }, 
    {
      pos: [0, 2, 5], 
      state: 1
    }, 
    {
      pos: [1, 2, 5], 
      state: 0
    }, 
    {
      pos: [2, 2, 5], 
      state: 0
    }, 
    {
      pos: [3, 2, 5], 
      state: 0
    }, 
    {
      pos: [4, 2, 5], 
      state: 0
    }, 
    {
      pos: [5, 2, 5], 
      state: 0
    }, 
    {
      pos: [6, 2, 5], 
      state: 1
    }, 
    {
      pos: [0, 2, 6], 
      state: 1
    }, 
    {
      pos: [6, 2, 6], 
      state: 1
    }, 
    {
      pos: [1, 2, 0], 
      state: 12
    }, 
    {
      pos: [2, 2, 0], 
      state: 12
    }, 
    {
      pos: [3, 2, 0], 
      state: 12
    }, 
    {
      pos: [4, 2, 0], 
      state: 12
    }, 
    {
      pos: [5, 2, 0], 
      state: 12
    }, 
    {
      pos: [3, 2, 1], 
      state: 15
    }, 
    {
      pos: [2, 2, 2], 
      state: 12
    }, 
    {
      pos: [3, 2, 2], 
      state: 12
    }, 
    {
      pos: [4, 2, 2], 
      state: 12
    }, 
    {
      pos: [2, 2, 3], 
      state: 12
    }, 
    {
      pos: [3, 2, 3], 
      state: 12
    }, 
    {
      pos: [4, 2, 3], 
      state: 12
    }, 
    {
      pos: [2, 2, 4], 
      state: 12
    }, 
    {
      pos: [3, 2, 4], 
      state: 12
    }, 
    {
      pos: [4, 2, 4], 
      state: 16
    }, 
    {
      pos: [1, 2, 6], 
      state: 11
    }, 
    {
      pos: [2, 2, 6], 
      state: 12
    }, 
    {
      pos: [3, 2, 6], 
      state: 12
    }, 
    {
      pos: [4, 2, 6], 
      state: 12
    }, 
    {
      pos: [5, 2, 6], 
      state: 11
    }, 
    {
      pos: [1, 3, 0], 
      state: 1
    }, 
    {
      pos: [5, 3, 0], 
      state: 1
    }, 
    {
      pos: [1, 3, 1], 
      state: 1
    }, 
    {
      pos: [2, 3, 1], 
      state: 0
    }, 
    {
      pos: [3, 3, 1], 
      state: 0
    }, 
    {
      pos: [4, 3, 1], 
      state: 0
    }, 
    {
      pos: [5, 3, 1], 
      state: 1
    }, 
    {
      pos: [1, 3, 2], 
      state: 1
    }, 
    {
      pos: [5, 3, 2], 
      state: 1
    }, 
    {
      pos: [1, 3, 4], 
      state: 1
    }, 
    {
      pos: [5, 3, 4], 
      state: 1
    }, 
    {
      pos: [1, 3, 5], 
      state: 1
    }, 
    {
      pos: [2, 3, 5], 
      state: 0
    }, 
    {
      pos: [4, 3, 5], 
      state: 0
    }, 
    {
      pos: [5, 3, 5], 
      state: 1
    }, 
    {
      pos: [1, 3, 6], 
      state: 1
    }, 
    {
      pos: [5, 3, 6], 
      state: 1
    }, 
    {
      pos: [0, 3, 0], 
      state: 17
    }, 
    {
      pos: [2, 3, 0], 
      state: 12
    }, 
    {
      pos: [3, 3, 0], 
      state: 18
    }, 
    {
      pos: [4, 3, 0], 
      state: 12
    }, 
    {
      pos: [6, 3, 0], 
      state: 17
    }, 
    {
      pos: [0, 3, 1], 
      state: 5
    }, 
    {
      pos: [6, 3, 1], 
      state: 5
    }, 
    {
      pos: [0, 3, 2], 
      state: 17
    }, 
    {
      pos: [2, 3, 2], 
      state: 12
    }, 
    {
      pos: [3, 3, 2], 
      state: 12
    }, 
    {
      pos: [4, 3, 2], 
      state: 12
    }, 
    {
      pos: [6, 3, 2], 
      state: 17
    }, 
    {
      pos: [0, 3, 3], 
      state: 5
    }, 
    {
      pos: [1, 3, 3], 
      state: 19
    }, 
    {
      pos: [2, 3, 3], 
      state: 12
    }, 
    {
      pos: [3, 3, 3], 
      state: 12
    }, 
    {
      pos: [4, 3, 3], 
      state: 12
    }, 
    {
      pos: [5, 3, 3], 
      state: 19
    }, 
    {
      pos: [6, 3, 3], 
      state: 5
    }, 
    {
      pos: [0, 3, 4], 
      state: 17
    }, 
    {
      pos: [2, 3, 4], 
      state: 12
    }, 
    {
      pos: [3, 3, 4], 
      state: 12
    }, 
    {
      pos: [4, 3, 4], 
      state: 16
    }, 
    {
      pos: [6, 3, 4], 
      state: 17
    }, 
    {
      pos: [0, 3, 5], 
      state: 5
    }, 
    {
      pos: [3, 3, 5], 
      state: 20
    }, 
    {
      pos: [6, 3, 5], 
      state: 5
    }, 
    {
      pos: [0, 3, 6], 
      state: 17
    }, 
    {
      pos: [2, 3, 6], 
      state: 12
    }, 
    {
      pos: [3, 3, 6], 
      state: 12
    }, 
    {
      pos: [4, 3, 6], 
      state: 12
    }, 
    {
      pos: [6, 3, 6], 
      state: 17
    }, 
    {
      pos: [1, 4, 0], 
      state: 1
    }, 
    {
      pos: [5, 4, 0], 
      state: 1
    }, 
    {
      pos: [1, 4, 1], 
      state: 1
    }, 
    {
      pos: [2, 4, 1], 
      state: 0
    }, 
    {
      pos: [3, 4, 1], 
      state: 0
    }, 
    {
      pos: [4, 4, 1], 
      state: 0
    }, 
    {
      pos: [5, 4, 1], 
      state: 1
    }, 
    {
      pos: [1, 4, 2], 
      state: 1
    }, 
    {
      pos: [5, 4, 2], 
      state: 1
    }, 
    {
      pos: [1, 4, 3], 
      state: 1
    }, 
    {
      pos: [5, 4, 3], 
      state: 1
    }, 
    {
      pos: [1, 4, 4], 
      state: 1
    }, 
    {
      pos: [5, 4, 4], 
      state: 1
    }, 
    {
      pos: [1, 4, 5], 
      state: 1
    }, 
    {
      pos: [2, 4, 5], 
      state: 0
    }, 
    {
      pos: [3, 4, 5], 
      state: 0
    }, 
    {
      pos: [4, 4, 5], 
      state: 0
    }, 
    {
      pos: [5, 4, 5], 
      state: 1
    }, 
    {
      pos: [1, 4, 6], 
      state: 1
    }, 
    {
      pos: [5, 4, 6], 
      state: 1
    }, 
    {
      pos: [0, 4, 0], 
      state: 12
    }, 
    {
      pos: [2, 4, 0], 
      state: 11
    }, 
    {
      pos: [3, 4, 0], 
      state: 12
    }, 
    {
      pos: [4, 4, 0], 
      state: 11
    }, 
    {
      pos: [6, 4, 0], 
      state: 12
    }, 
    {
      pos: [0, 4, 1], 
      state: 12
    }, 
    {
      pos: [6, 4, 1], 
      state: 12
    }, 
    {
      pos: [0, 4, 2], 
      state: 12
    }, 
    {
      pos: [2, 4, 2], 
      state: 12
    }, 
    {
      pos: [3, 4, 2], 
      state: 12
    }, 
    {
      pos: [4, 4, 2], 
      state: 12
    }, 
    {
      pos: [6, 4, 2], 
      state: 12
    }, 
    {
      pos: [0, 4, 3], 
      state: 12
    }, 
    {
      pos: [2, 4, 3], 
      state: 12
    }, 
    {
      pos: [3, 4, 3], 
      state: 12
    }, 
    {
      pos: [4, 4, 3], 
      state: 12
    }, 
    {
      pos: [6, 4, 3], 
      state: 12
    }, 
    {
      pos: [0, 4, 4], 
      state: 12
    }, 
    {
      pos: [2, 4, 4], 
      state: 12
    }, 
    {
      pos: [3, 4, 4], 
      state: 12
    }, 
    {
      pos: [4, 4, 4], 
      state: 16
    }, 
    {
      pos: [6, 4, 4], 
      state: 12
    }, 
    {
      pos: [0, 4, 5], 
      state: 12
    }, 
    {
      pos: [6, 4, 5], 
      state: 12
    }, 
    {
      pos: [0, 4, 6], 
      state: 12
    }, 
    {
      pos: [2, 4, 6], 
      state: 11
    }, 
    {
      pos: [3, 4, 6], 
      state: 12
    }, 
    {
      pos: [4, 4, 6], 
      state: 11
    }, 
    {
      pos: [6, 4, 6], 
      state: 12
    }, 
    {
      pos: [2, 5, 0], 
      state: 1
    }, 
    {
      pos: [4, 5, 0], 
      state: 1
    }, 
    {
      pos: [2, 5, 1], 
      state: 1
    }, 
    {
      pos: [3, 5, 1], 
      state: 0
    }, 
    {
      pos: [4, 5, 1], 
      state: 1
    }, 
    {
      pos: [2, 5, 2], 
      state: 1
    }, 
    {
      pos: [4, 5, 2], 
      state: 1
    }, 
    {
      pos: [2, 5, 3], 
      state: 1
    }, 
    {
      pos: [4, 5, 3], 
      state: 1
    }, 
    {
      pos: [2, 5, 4], 
      state: 1
    }, 
    {
      pos: [4, 5, 4], 
      state: 2
    }, 
    {
      pos: [2, 5, 5], 
      state: 1
    }, 
    {
      pos: [3, 5, 5], 
      state: 0
    }, 
    {
      pos: [4, 5, 5], 
      state: 1
    }, 
    {
      pos: [2, 5, 6], 
      state: 1
    }, 
    {
      pos: [4, 5, 6], 
      state: 1
    }, 
    {
      pos: [0, 5, 0], 
      state: 12
    }, 
    {
      pos: [1, 5, 0], 
      state: 5
    }, 
    {
      pos: [3, 5, 0], 
      state: 11
    }, 
    {
      pos: [5, 5, 0], 
      state: 5
    }, 
    {
      pos: [6, 5, 0], 
      state: 12
    }, 
    {
      pos: [0, 5, 1], 
      state: 12
    }, 
    {
      pos: [1, 5, 1], 
      state: 5
    }, 
    {
      pos: [5, 5, 1], 
      state: 5
    }, 
    {
      pos: [6, 5, 1], 
      state: 12
    }, 
    {
      pos: [0, 5, 2], 
      state: 12
    }, 
    {
      pos: [1, 5, 2], 
      state: 5
    }, 
    {
      pos: [3, 5, 2], 
      state: 21
    }, 
    {
      pos: [5, 5, 2], 
      state: 5
    }, 
    {
      pos: [6, 5, 2], 
      state: 12
    }, 
    {
      pos: [0, 5, 3], 
      state: 12
    }, 
    {
      pos: [1, 5, 3], 
      state: 17
    }, 
    {
      pos: [3, 5, 3], 
      state: 12
    }, 
    {
      pos: [5, 5, 3], 
      state: 17
    }, 
    {
      pos: [6, 5, 3], 
      state: 12
    }, 
    {
      pos: [0, 5, 4], 
      state: 12
    }, 
    {
      pos: [1, 5, 4], 
      state: 5
    }, 
    {
      pos: [3, 5, 4], 
      state: 18
    }, 
    {
      pos: [5, 5, 4], 
      state: 12
    }, 
    {
      pos: [6, 5, 4], 
      state: 12
    }, 
    {
      pos: [0, 5, 5], 
      state: 12
    }, 
    {
      pos: [1, 5, 5], 
      state: 5
    }, 
    {
      pos: [5, 5, 5], 
      state: 5
    }, 
    {
      pos: [6, 5, 5], 
      state: 12
    }, 
    {
      pos: [0, 5, 6], 
      state: 12
    }, 
    {
      pos: [1, 5, 6], 
      state: 5
    }, 
    {
      pos: [3, 5, 6], 
      state: 11
    }, 
    {
      pos: [5, 5, 6], 
      state: 5
    }, 
    {
      pos: [6, 5, 6], 
      state: 12
    }, 
    {
      pos: [3, 6, 0], 
      state: 1
    }, 
    {
      pos: [3, 6, 1], 
      state: 1
    }, 
    {
      pos: [3, 6, 2], 
      state: 1
    }, 
    {
      pos: [3, 6, 3], 
      state: 1
    }, 
    {
      pos: [3, 6, 4], 
      state: 1
    }, 
    {
      pos: [3, 6, 5], 
      state: 1
    }, 
    {
      pos: [3, 6, 6], 
      state: 1
    }, 
    {
      pos: [0, 6, 0], 
      state: 12
    }, 
    {
      pos: [1, 6, 0], 
      state: 12
    }, 
    {
      pos: [2, 6, 0], 
      state: 5
    }, 
    {
      pos: [4, 6, 0], 
      state: 5
    }, 
    {
      pos: [5, 6, 0], 
      state: 12
    }, 
    {
      pos: [6, 6, 0], 
      state: 12
    }, 
    {
      pos: [0, 6, 1], 
      state: 12
    }, 
    {
      pos: [1, 6, 1], 
      state: 12
    }, 
    {
      pos: [2, 6, 1], 
      state: 5
    }, 
    {
      pos: [4, 6, 1], 
      state: 5
    }, 
    {
      pos: [5, 6, 1], 
      state: 12
    }, 
    {
      pos: [6, 6, 1], 
      state: 12
    }, 
    {
      pos: [0, 6, 2], 
      state: 12
    }, 
    {
      pos: [1, 6, 2], 
      state: 12
    }, 
    {
      pos: [2, 6, 2], 
      state: 5
    }, 
    {
      pos: [4, 6, 2], 
      state: 5
    }, 
    {
      pos: [5, 6, 2], 
      state: 12
    }, 
    {
      pos: [6, 6, 2], 
      state: 12
    }, 
    {
      pos: [0, 6, 3], 
      state: 12
    }, 
    {
      pos: [1, 6, 3], 
      state: 12
    }, 
    {
      pos: [2, 6, 3], 
      state: 5
    }, 
    {
      pos: [4, 6, 3], 
      state: 5
    }, 
    {
      pos: [5, 6, 3], 
      state: 12
    }, 
    {
      pos: [6, 6, 3], 
      state: 12
    }, 
    {
      pos: [0, 6, 4], 
      state: 12
    }, 
    {
      pos: [1, 6, 4], 
      state: 12
    }, 
    {
      pos: [2, 6, 4], 
      state: 5
    }, 
    {
      pos: [4, 6, 4], 
      state: 22
    }, 
    {
      pos: [5, 6, 4], 
      state: 12
    }, 
    {
      pos: [6, 6, 4], 
      state: 12
    }, 
    {
      pos: [0, 6, 5], 
      state: 12
    }, 
    {
      pos: [1, 6, 5], 
      state: 12
    }, 
    {
      pos: [2, 6, 5], 
      state: 5
    }, 
    {
      pos: [4, 6, 5], 
      state: 5
    }, 
    {
      pos: [5, 6, 5], 
      state: 12
    }, 
    {
      pos: [6, 6, 5], 
      state: 12
    }, 
    {
      pos: [0, 6, 6], 
      state: 12
    }, 
    {
      pos: [1, 6, 6], 
      state: 12
    }, 
    {
      pos: [2, 6, 6], 
      state: 5
    }, 
    {
      pos: [4, 6, 6], 
      state: 5
    }, 
    {
      pos: [5, 6, 6], 
      state: 12
    }, 
    {
      pos: [6, 6, 6], 
      state: 12
    }, 
    {
      pos: [0, 7, 0], 
      state: 12
    }, 
    {
      pos: [1, 7, 0], 
      state: 12
    }, 
    {
      pos: [2, 7, 0], 
      state: 12
    }, 
    {
      pos: [3, 7, 0], 
      state: 5
    }, 
    {
      pos: [4, 7, 0], 
      state: 12
    }, 
    {
      pos: [5, 7, 0], 
      state: 12
    }, 
    {
      pos: [6, 7, 0], 
      state: 12
    }, 
    {
      pos: [0, 7, 1], 
      state: 12
    }, 
    {
      pos: [1, 7, 1], 
      state: 12
    }, 
    {
      pos: [2, 7, 1], 
      state: 12
    }, 
    {
      pos: [3, 7, 1], 
      state: 5
    }, 
    {
      pos: [4, 7, 1], 
      state: 12
    }, 
    {
      pos: [5, 7, 1], 
      state: 12
    }, 
    {
      pos: [6, 7, 1], 
      state: 12
    }, 
    {
      pos: [0, 7, 2], 
      state: 12
    }, 
    {
      pos: [1, 7, 2], 
      state: 12
    }, 
    {
      pos: [2, 7, 2], 
      state: 12
    }, 
    {
      pos: [3, 7, 2], 
      state: 5
    }, 
    {
      pos: [4, 7, 2], 
      state: 12
    }, 
    {
      pos: [5, 7, 2], 
      state: 12
    }, 
    {
      pos: [6, 7, 2], 
      state: 12
    }, 
    {
      pos: [0, 7, 3], 
      state: 12
    }, 
    {
      pos: [1, 7, 3], 
      state: 12
    }, 
    {
      pos: [2, 7, 3], 
      state: 12
    }, 
    {
      pos: [3, 7, 3], 
      state: 5
    }, 
    {
      pos: [4, 7, 3], 
      state: 12
    }, 
    {
      pos: [5, 7, 3], 
      state: 12
    }, 
    {
      pos: [6, 7, 3], 
      state: 12
    }, 
    {
      pos: [0, 7, 4], 
      state: 12
    }, 
    {
      pos: [1, 7, 4], 
      state: 12
    }, 
    {
      pos: [2, 7, 4], 
      state: 12
    }, 
    {
      pos: [3, 7, 4], 
      state: 5
    }, 
    {
      pos: [4, 7, 4], 
      state: 23
    }, 
    {
      pos: [5, 7, 4], 
      state: 12
    }, 
    {
      pos: [6, 7, 4], 
      state: 12
    }, 
    {
      pos: [0, 7, 5], 
      state: 12
    }, 
    {
      pos: [1, 7, 5], 
      state: 12
    }, 
    {
      pos: [2, 7, 5], 
      state: 12
    }, 
    {
      pos: [3, 7, 5], 
      state: 5
    }, 
    {
      pos: [4, 7, 5], 
      state: 12
    }, 
    {
      pos: [5, 7, 5], 
      state: 12
    }, 
    {
      pos: [6, 7, 5], 
      state: 12
    }, 
    {
      pos: [0, 7, 6], 
      state: 12
    }, 
    {
      pos: [1, 7, 6], 
      state: 12
    }, 
    {
      pos: [2, 7, 6], 
      state: 12
    }, 
    {
      pos: [3, 7, 6], 
      state: 5
    }, 
    {
      pos: [4, 7, 6], 
      state: 12
    }, 
    {
      pos: [5, 7, 6], 
      state: 12
    }, 
    {
      pos: [6, 7, 6], 
      state: 12
    }
  ], 
  palette: [
    {
      Properties: {
        axis: "y"
      }, 
      Name: "minecraft:stripped_spruce_wood"
    }, 
    {
      Name: "minecraft:spruce_planks"
    }, 
    {
      Name: "minecraft:cobblestone"
    }, 
    {
      Properties: {
        orientation: "north_up"
      }, 
      Name: "minecraft:jigsaw"
    }, 
    {
      Properties: {
        orientation: "up_north"
      }, 
      Name: "minecraft:jigsaw"
    }, 
    {
      Properties: {
        layers: "1"
      }, 
      Name: "minecraft:snow"
    }, 
    {
      Properties: {
        half: "bottom", 
        waterlogged: "false", 
        shape: "straight", 
        facing: "east"
      }, 
      Name: "minecraft:spruce_stairs"
    }, 
    {
      Properties: {
        half: "bottom", 
        waterlogged: "false", 
        shape: "straight", 
        facing: "west"
      }, 
      Name: "minecraft:spruce_stairs"
    }, 
    {
      Properties: {
        part: "foot", 
        facing: "south", 
        occupied: "false"
      }, 
      Name: "minecraft:blue_bed"
    }, 
    {
      Properties: {
        part: "head", 
        facing: "south", 
        occupied: "false"
      }, 
      Name: "minecraft:blue_bed"
    }, 
    {
      Properties: {
        lit: "false", 
        facing: "north"
      }, 
      Name: "minecraft:furnace"
    }, 
    {
      Properties: {
        waterlogged: "false", 
        type: "top"
      }, 
      Name: "minecraft:spruce_slab"
    }, 
    {
      Name: "minecraft:air"
    }, 
    {
      Properties: {
        hinge: "left", 
        half: "lower", 
        powered: "false", 
        facing: "south", 
        open: "false"
      }, 
      Name: "minecraft:spruce_door"
    }, 
    {
      Properties: {
        axis: "x"
      }, 
      Name: "minecraft:stripped_spruce_wood"
    }, 
    {
      Properties: {
        hinge: "left", 
        half: "upper", 
        powered: "false", 
        facing: "south", 
        open: "false"
      }, 
      Name: "minecraft:spruce_door"
    }, 
    {
      Properties: {
        east: "tall", 
        waterlogged: "false", 
        south: "tall", 
        north: "none", 
        west: "none", 
        up: "true"
      }, 
      Name: "minecraft:cobblestone_wall"
    }, 
    {
      Properties: {
        waterlogged: "false", 
        type: "bottom"
      }, 
      Name: "minecraft:spruce_slab"
    }, 
    {
      Properties: {
        facing: "north"
      }, 
      Name: "minecraft:wall_torch"
    }, 
    {
      Properties: {
        east: "false", 
        waterlogged: "false", 
        south: "true", 
        north: "true", 
        west: "false"
      }, 
      Name: "minecraft:glass_pane"
    }, 
    {
      Properties: {
        east: "true", 
        waterlogged: "false", 
        south: "false", 
        north: "false", 
        west: "true"
      }, 
      Name: "minecraft:glass_pane"
    }, 
    {
      Properties: {
        facing: "south"
      }, 
      Name: "minecraft:wall_torch"
    }, 
    {
      Properties: {
        east: "none", 
        waterlogged: "false", 
        south: "none", 
        north: "none", 
        west: "low", 
        up: "true"
      }, 
      Name: "minecraft:cobblestone_wall"
    }, 
    {
      Properties: {
        east: "none", 
        waterlogged: "false", 
        south: "none", 
        north: "none", 
        west: "none", 
        up: "true"
      }, 
      Name: "minecraft:cobblestone_wall"
    }
  ]
}
