{
  size: [9, 5, 10], 
  entities: [], 
  blocks: [
    {
      pos: [0, 0, 0], 
      state: 0
    }, 
    {
      pos: [1, 0, 0], 
      state: 0
    }, 
    {
      pos: [2, 0, 0], 
      state: 0
    }, 
    {
      pos: [3, 0, 0], 
      state: 0
    }, 
    {
      pos: [3, 1, 0], 
      state: 1
    }, 
    {
      pos: [8, 1, 0], 
      state: 1
    }, 
    {
      pos: [3, 2, 0], 
      state: 1
    }, 
    {
      pos: [8, 2, 0], 
      state: 1
    }, 
    {
      pos: [4, 3, 0], 
      state: 1
    }, 
    {
      pos: [7, 3, 0], 
      state: 1
    }, 
    {
      pos: [5, 4, 0], 
      state: 1
    }, 
    {
      pos: [6, 4, 0], 
      state: 1
    }, 
    {
      pos: [0, 0, 1], 
      state: 0
    }, 
    {
      pos: [1, 0, 1], 
      state: 2
    }, 
    {
      pos: [2, 0, 1], 
      state: 2
    }, 
    {
      pos: [3, 0, 1], 
      state: 2
    }, 
    {
      pos: [4, 0, 1], 
      state: 0
    }, 
    {
      pos: [5, 0, 1], 
      state: 0
    }, 
    {
      pos: [6, 0, 1], 
      state: 0
    }, 
    {
      pos: [7, 0, 1], 
      state: 0
    }, 
    {
      pos: [4, 1, 1], 
      state: 0
    }, 
    {
      pos: [5, 1, 1], 
      state: 0
    }, 
    {
      pos: [6, 1, 1], 
      state: 0
    }, 
    {
      pos: [7, 1, 1], 
      state: 0
    }, 
    {
      pos: [8, 1, 1], 
      state: 1
    }, 
    {
      pos: [4, 2, 1], 
      state: 0
    }, 
    {
      pos: [5, 2, 1], 
      state: 0
    }, 
    {
      pos: [6, 2, 1], 
      state: 0
    }, 
    {
      pos: [7, 2, 1], 
      state: 0
    }, 
    {
      pos: [8, 2, 1], 
      state: 1
    }, 
    {
      pos: [4, 3, 1], 
      state: 1
    }, 
    {
      pos: [5, 3, 1], 
      state: 0
    }, 
    {
      pos: [6, 3, 1], 
      state: 0
    }, 
    {
      pos: [7, 3, 1], 
      state: 1
    }, 
    {
      pos: [5, 4, 1], 
      state: 1
    }, 
    {
      pos: [6, 4, 1], 
      state: 1
    }, 
    {
      pos: [0, 0, 2], 
      state: 0
    }, 
    {
      pos: [2, 0, 2], 
      state: 2
    }, 
    {
      pos: [3, 0, 2], 
      state: 2
    }, 
    {
      pos: [4, 0, 2], 
      state: 0
    }, 
    {
      pos: [5, 0, 2], 
      state: 1
    }, 
    {
      pos: [6, 0, 2], 
      state: 1
    }, 
    {
      pos: [7, 0, 2], 
      state: 0
    }, 
    {
      pos: [4, 1, 2], 
      state: 0
    }, 
    {
      pos: [5, 1, 2], 
      state: 3
    }, 
    {
      pos: [6, 1, 2], 
      state: 3
    }, 
    {
      pos: [7, 1, 2], 
      state: 0
    }, 
    {
      pos: [8, 1, 2], 
      state: 1
    }, 
    {
      pos: [4, 2, 2], 
      state: 0
    }, 
    {
      pos: [7, 2, 2], 
      state: 0
    }, 
    {
      pos: [8, 2, 2], 
      state: 1
    }, 
    {
      pos: [4, 3, 2], 
      state: 1
    }, 
    {
      pos: [7, 3, 2], 
      state: 1
    }, 
    {
      pos: [5, 4, 2], 
      state: 1
    }, 
    {
      pos: [6, 4, 2], 
      state: 1
    }, 
    {
      pos: [0, 0, 3], 
      state: 0
    }, 
    {
      pos: [1, 0, 3], 
      state: 2
    }, 
    {
      pos: [2, 0, 3], 
      state: 2
    }, 
    {
      pos: [3, 0, 3], 
      state: 2
    }, 
    {
      pos: [4, 0, 3], 
      state: 0
    }, 
    {
      pos: [5, 0, 3], 
      state: 1
    }, 
    {
      pos: [6, 0, 3], 
      state: 1
    }, 
    {
      pos: [7, 0, 3], 
      state: 0
    }, 
    {
      pos: [7, 1, 3], 
      state: 0
    }, 
    {
      pos: [8, 1, 3], 
      state: 1
    }, 
    {
      pos: [7, 2, 3], 
      state: 0
    }, 
    {
      pos: [8, 2, 3], 
      state: 1
    }, 
    {
      pos: [4, 3, 3], 
      state: 1
    }, 
    {
      pos: [7, 3, 3], 
      state: 1
    }, 
    {
      pos: [5, 4, 3], 
      state: 1
    }, 
    {
      pos: [6, 4, 3], 
      state: 1
    }, 
    {
      pos: [0, 0, 4], 
      state: 0
    }, 
    {
      pos: [1, 0, 4], 
      state: 2
    }, 
    {
      pos: [2, 0, 4], 
      state: 2
    }, 
    {
      pos: [3, 0, 4], 
      state: 2
    }, 
    {
      pos: [4, 0, 4], 
      state: 0
    }, 
    {
      pos: [5, 0, 4], 
      state: 1
    }, 
    {
      pos: [6, 0, 4], 
      state: 1
    }, 
    {
      pos: [7, 0, 4], 
      state: 0
    }, 
    {
      pos: [4, 1, 4], 
      state: 0
    }, 
    {
      pos: [7, 1, 4], 
      state: 0
    }, 
    {
      pos: [8, 1, 4], 
      state: 1
    }, 
    {
      pos: [4, 2, 4], 
      state: 0
    }, 
    {
      pos: [7, 2, 4], 
      state: 0
    }, 
    {
      pos: [8, 2, 4], 
      state: 1
    }, 
    {
      pos: [4, 3, 4], 
      state: 1
    }, 
    {
      pos: [7, 3, 4], 
      state: 1
    }, 
    {
      pos: [5, 4, 4], 
      state: 1
    }, 
    {
      pos: [6, 4, 4], 
      state: 1
    }, 
    {
      pos: [0, 0, 5], 
      state: 0
    }, 
    {
      pos: [1, 0, 5], 
      state: 2
    }, 
    {
      pos: [2, 0, 5], 
      state: 2
    }, 
    {
      pos: [3, 0, 5], 
      state: 2
    }, 
    {
      pos: [4, 0, 5], 
      state: 0
    }, 
    {
      pos: [5, 0, 5], 
      state: 1
    }, 
    {
      pos: [6, 0, 5], 
      state: 1
    }, 
    {
      pos: [7, 0, 5], 
      state: 0
    }, 
    {
      pos: [0, 1, 5], 
      state: 1
    }, 
    {
      pos: [4, 1, 5], 
      state: 0
    }, 
    {
      pos: [7, 1, 5], 
      state: 0
    }, 
    {
      pos: [8, 1, 5], 
      state: 1
    }, 
    {
      pos: [0, 2, 5], 
      state: 1
    }, 
    {
      pos: [4, 2, 5], 
      state: 0
    }, 
    {
      pos: [7, 2, 5], 
      state: 0
    }, 
    {
      pos: [8, 2, 5], 
      state: 1
    }, 
    {
      pos: [4, 3, 5], 
      state: 1
    }, 
    {
      pos: [7, 3, 5], 
      state: 1
    }, 
    {
      pos: [5, 4, 5], 
      state: 1
    }, 
    {
      pos: [6, 4, 5], 
      state: 1
    }, 
    {
      pos: [1, 0, 6], 
      state: 0
    }, 
    {
      pos: [2, 0, 6], 
      state: 0
    }, 
    {
      pos: [3, 0, 6], 
      state: 0
    }, 
    {
      pos: [4, 0, 6], 
      state: 1
    }, 
    {
      pos: [5, 0, 6], 
      state: 1
    }, 
    {
      pos: [6, 0, 6], 
      state: 1
    }, 
    {
      pos: [7, 0, 6], 
      state: 0
    }, 
    {
      pos: [1, 1, 6], 
      state: 0
    }, 
    {
      pos: [2, 1, 6], 
      state: 0
    }, 
    {
      pos: [3, 1, 6], 
      state: 0
    }, 
    {
      pos: [7, 1, 6], 
      state: 0
    }, 
    {
      pos: [1, 2, 6], 
      state: 0
    }, 
    {
      pos: [2, 2, 6], 
      state: 0
    }, 
    {
      pos: [3, 2, 6], 
      state: 0
    }, 
    {
      pos: [7, 2, 6], 
      state: 0
    }, 
    {
      pos: [0, 3, 6], 
      state: 1
    }, 
    {
      pos: [1, 3, 6], 
      state: 1
    }, 
    {
      pos: [2, 3, 6], 
      state: 1
    }, 
    {
      pos: [3, 3, 6], 
      state: 1
    }, 
    {
      pos: [4, 3, 6], 
      state: 1
    }, 
    {
      pos: [5, 3, 6], 
      state: 1
    }, 
    {
      pos: [6, 3, 6], 
      state: 1
    }, 
    {
      pos: [7, 3, 6], 
      state: 1
    }, 
    {
      pos: [8, 3, 6], 
      state: 1
    }, 
    {
      pos: [5, 4, 6], 
      state: 1
    }, 
    {
      pos: [6, 4, 6], 
      state: 1
    }, 
    {
      pos: [1, 0, 7], 
      state: 0
    }, 
    {
      pos: [2, 0, 7], 
      state: 1
    }, 
    {
      pos: [3, 0, 7], 
      state: 1
    }, 
    {
      pos: [4, 0, 7], 
      state: 1
    }, 
    {
      pos: [5, 0, 7], 
      state: 1
    }, 
    {
      pos: [6, 0, 7], 
      state: 1
    }, 
    {
      pos: [7, 0, 7], 
      state: 0
    }, 
    {
      pos: [7, 1, 7], 
      state: 0
    }, 
    {
      pos: [7, 2, 7], 
      state: 0
    }, 
    {
      pos: [1, 3, 7], 
      state: 4
    }, 
    {
      pos: [7, 3, 7], 
      state: 0
    }, 
    {
      pos: [0, 4, 7], 
      state: 1
    }, 
    {
      pos: [1, 4, 7], 
      state: 1
    }, 
    {
      pos: [2, 4, 7], 
      state: 1
    }, 
    {
      pos: [3, 4, 7], 
      state: 1
    }, 
    {
      pos: [4, 4, 7], 
      state: 1
    }, 
    {
      pos: [5, 4, 7], 
      state: 1
    }, 
    {
      pos: [6, 4, 7], 
      state: 1
    }, 
    {
      pos: [7, 4, 7], 
      state: 1
    }, 
    {
      pos: [8, 4, 7], 
      state: 1
    }, 
    {
      pos: [1, 0, 8], 
      state: 0
    }, 
    {
      pos: [2, 0, 8], 
      state: 0
    }, 
    {
      pos: [3, 0, 8], 
      state: 0
    }, 
    {
      pos: [4, 0, 8], 
      state: 0
    }, 
    {
      pos: [5, 0, 8], 
      state: 0
    }, 
    {
      pos: [6, 0, 8], 
      state: 0
    }, 
    {
      pos: [7, 0, 8], 
      state: 0
    }, 
    {
      pos: [1, 1, 8], 
      state: 0
    }, 
    {
      pos: [2, 1, 8], 
      state: 0
    }, 
    {
      pos: [3, 1, 8], 
      state: 0
    }, 
    {
      pos: [4, 1, 8], 
      state: 0
    }, 
    {
      pos: [5, 1, 8], 
      state: 0
    }, 
    {
      pos: [6, 1, 8], 
      state: 0
    }, 
    {
      pos: [7, 1, 8], 
      state: 0
    }, 
    {
      pos: [1, 2, 8], 
      state: 0
    }, 
    {
      pos: [2, 2, 8], 
      state: 0
    }, 
    {
      pos: [3, 2, 8], 
      state: 0
    }, 
    {
      pos: [4, 2, 8], 
      state: 0
    }, 
    {
      pos: [5, 2, 8], 
      state: 0
    }, 
    {
      pos: [6, 2, 8], 
      state: 0
    }, 
    {
      pos: [7, 2, 8], 
      state: 0
    }, 
    {
      pos: [0, 3, 8], 
      state: 1
    }, 
    {
      pos: [1, 3, 8], 
      state: 1
    }, 
    {
      pos: [2, 3, 8], 
      state: 1
    }, 
    {
      pos: [3, 3, 8], 
      state: 1
    }, 
    {
      pos: [4, 3, 8], 
      state: 1
    }, 
    {
      pos: [5, 3, 8], 
      state: 1
    }, 
    {
      pos: [6, 3, 8], 
      state: 1
    }, 
    {
      pos: [7, 3, 8], 
      state: 1
    }, 
    {
      pos: [8, 3, 8], 
      state: 1
    }, 
    {
      pos: [0, 1, 9], 
      state: 1
    }, 
    {
      pos: [1, 1, 9], 
      state: 1
    }, 
    {
      pos: [2, 1, 9], 
      state: 1
    }, 
    {
      pos: [3, 1, 9], 
      state: 1
    }, 
    {
      pos: [4, 1, 9], 
      state: 1
    }, 
    {
      pos: [5, 1, 9], 
      state: 1
    }, 
    {
      pos: [6, 1, 9], 
      state: 1
    }, 
    {
      pos: [7, 1, 9], 
      state: 1
    }, 
    {
      pos: [8, 1, 9], 
      state: 1
    }, 
    {
      pos: [0, 2, 9], 
      state: 1
    }, 
    {
      pos: [1, 2, 9], 
      state: 1
    }, 
    {
      pos: [2, 2, 9], 
      state: 1
    }, 
    {
      pos: [3, 2, 9], 
      state: 1
    }, 
    {
      pos: [4, 2, 9], 
      state: 1
    }, 
    {
      pos: [5, 2, 9], 
      state: 1
    }, 
    {
      pos: [6, 2, 9], 
      state: 1
    }, 
    {
      pos: [7, 2, 9], 
      state: 1
    }, 
    {
      pos: [8, 2, 9], 
      state: 1
    }, 
    {
      nbt: {
        target_pool: "minecraft:village/common/sheep", 
        final_state: "minecraft:grass_block", 
        id: "minecraft:jigsaw", 
        attachement_type: "minecraft:bottom"
      }, 
      pos: [1, 0, 2], 
      state: 5
    }, 
    {
      nbt: {
        target_pool: "minecraft:empty", 
        final_state: "minecraft:structure_void", 
        id: "minecraft:jigsaw", 
        attachement_type: "minecraft:buidling_entrance"
      }, 
      pos: [0, 0, 6], 
      state: 6
    }, 
    {
      nbt: {
        LootTable: "minecraft:chests/village/village_shepherd", 
        Items: [], 
        id: "minecraft:chest", 
        Lock: "", 
        LootTableSeed: 0L
      }, 
      pos: [6, 1, 7], 
      state: 7
    }, 
    {
      nbt: {
        target_pool: "minecraft:empty", 
        final_state: "minecraft:structure_void", 
        id: "minecraft:jigsaw", 
        attachement_type: "minecraft:empty"
      }, 
      pos: [0, 3, 7], 
      state: 8
    }, 
    {
      pos: [4, 0, 0], 
      state: 9
    }, 
    {
      pos: [5, 0, 0], 
      state: 9
    }, 
    {
      pos: [6, 0, 0], 
      state: 9
    }, 
    {
      pos: [7, 0, 0], 
      state: 9
    }, 
    {
      pos: [8, 0, 0], 
      state: 9
    }, 
    {
      pos: [0, 1, 0], 
      state: 10
    }, 
    {
      pos: [1, 1, 0], 
      state: 11
    }, 
    {
      pos: [2, 1, 0], 
      state: 11
    }, 
    {
      pos: [4, 1, 0], 
      state: 12
    }, 
    {
      pos: [5, 1, 0], 
      state: 12
    }, 
    {
      pos: [6, 1, 0], 
      state: 12
    }, 
    {
      pos: [7, 1, 0], 
      state: 12
    }, 
    {
      pos: [0, 2, 0], 
      state: 13
    }, 
    {
      pos: [1, 2, 0], 
      state: 12
    }, 
    {
      pos: [2, 2, 0], 
      state: 12
    }, 
    {
      pos: [4, 2, 0], 
      state: 12
    }, 
    {
      pos: [5, 2, 0], 
      state: 12
    }, 
    {
      pos: [6, 2, 0], 
      state: 12
    }, 
    {
      pos: [7, 2, 0], 
      state: 12
    }, 
    {
      pos: [0, 3, 0], 
      state: 12
    }, 
    {
      pos: [1, 3, 0], 
      state: 12
    }, 
    {
      pos: [2, 3, 0], 
      state: 12
    }, 
    {
      pos: [3, 3, 0], 
      state: 14
    }, 
    {
      pos: [5, 3, 0], 
      state: 12
    }, 
    {
      pos: [6, 3, 0], 
      state: 12
    }, 
    {
      pos: [8, 3, 0], 
      state: 14
    }, 
    {
      pos: [0, 4, 0], 
      state: 12
    }, 
    {
      pos: [1, 4, 0], 
      state: 12
    }, 
    {
      pos: [2, 4, 0], 
      state: 12
    }, 
    {
      pos: [3, 4, 0], 
      state: 12
    }, 
    {
      pos: [4, 4, 0], 
      state: 14
    }, 
    {
      pos: [7, 4, 0], 
      state: 14
    }, 
    {
      pos: [8, 4, 0], 
      state: 12
    }, 
    {
      pos: [8, 0, 1], 
      state: 9
    }, 
    {
      pos: [0, 1, 1], 
      state: 15
    }, 
    {
      pos: [1, 1, 1], 
      state: 12
    }, 
    {
      pos: [2, 1, 1], 
      state: 12
    }, 
    {
      pos: [3, 1, 1], 
      state: 12
    }, 
    {
      pos: [0, 2, 1], 
      state: 12
    }, 
    {
      pos: [1, 2, 1], 
      state: 12
    }, 
    {
      pos: [2, 2, 1], 
      state: 12
    }, 
    {
      pos: [3, 2, 1], 
      state: 12
    }, 
    {
      pos: [0, 3, 1], 
      state: 12
    }, 
    {
      pos: [1, 3, 1], 
      state: 12
    }, 
    {
      pos: [2, 3, 1], 
      state: 12
    }, 
    {
      pos: [3, 3, 1], 
      state: 14
    }, 
    {
      pos: [8, 3, 1], 
      state: 12
    }, 
    {
      pos: [0, 4, 1], 
      state: 12
    }, 
    {
      pos: [1, 4, 1], 
      state: 12
    }, 
    {
      pos: [2, 4, 1], 
      state: 12
    }, 
    {
      pos: [3, 4, 1], 
      state: 12
    }, 
    {
      pos: [4, 4, 1], 
      state: 12
    }, 
    {
      pos: [7, 4, 1], 
      state: 12
    }, 
    {
      pos: [8, 4, 1], 
      state: 12
    }, 
    {
      pos: [8, 0, 2], 
      state: 9
    }, 
    {
      pos: [0, 1, 2], 
      state: 15
    }, 
    {
      pos: [1, 1, 2], 
      state: 12
    }, 
    {
      pos: [2, 1, 2], 
      state: 12
    }, 
    {
      pos: [3, 1, 2], 
      state: 12
    }, 
    {
      pos: [0, 2, 2], 
      state: 12
    }, 
    {
      pos: [1, 2, 2], 
      state: 12
    }, 
    {
      pos: [2, 2, 2], 
      state: 12
    }, 
    {
      pos: [3, 2, 2], 
      state: 12
    }, 
    {
      pos: [5, 2, 2], 
      state: 12
    }, 
    {
      pos: [6, 2, 2], 
      state: 12
    }, 
    {
      pos: [0, 3, 2], 
      state: 12
    }, 
    {
      pos: [1, 3, 2], 
      state: 12
    }, 
    {
      pos: [2, 3, 2], 
      state: 12
    }, 
    {
      pos: [3, 3, 2], 
      state: 14
    }, 
    {
      pos: [5, 3, 2], 
      state: 12
    }, 
    {
      pos: [6, 3, 2], 
      state: 12
    }, 
    {
      pos: [8, 3, 2], 
      state: 12
    }, 
    {
      pos: [0, 4, 2], 
      state: 12
    }, 
    {
      pos: [1, 4, 2], 
      state: 12
    }, 
    {
      pos: [2, 4, 2], 
      state: 12
    }, 
    {
      pos: [3, 4, 2], 
      state: 12
    }, 
    {
      pos: [4, 4, 2], 
      state: 12
    }, 
    {
      pos: [7, 4, 2], 
      state: 12
    }, 
    {
      pos: [8, 4, 2], 
      state: 12
    }, 
    {
      pos: [8, 0, 3], 
      state: 9
    }, 
    {
      pos: [0, 1, 3], 
      state: 15
    }, 
    {
      pos: [1, 1, 3], 
      state: 12
    }, 
    {
      pos: [2, 1, 3], 
      state: 12
    }, 
    {
      pos: [3, 1, 3], 
      state: 12
    }, 
    {
      pos: [4, 1, 3], 
      state: 16
    }, 
    {
      pos: [5, 1, 3], 
      state: 12
    }, 
    {
      pos: [6, 1, 3], 
      state: 12
    }, 
    {
      pos: [0, 2, 3], 
      state: 12
    }, 
    {
      pos: [1, 2, 3], 
      state: 12
    }, 
    {
      pos: [2, 2, 3], 
      state: 12
    }, 
    {
      pos: [3, 2, 3], 
      state: 12
    }, 
    {
      pos: [4, 2, 3], 
      state: 17
    }, 
    {
      pos: [5, 2, 3], 
      state: 12
    }, 
    {
      pos: [6, 2, 3], 
      state: 18
    }, 
    {
      pos: [0, 3, 3], 
      state: 12
    }, 
    {
      pos: [1, 3, 3], 
      state: 12
    }, 
    {
      pos: [2, 3, 3], 
      state: 12
    }, 
    {
      pos: [3, 3, 3], 
      state: 14
    }, 
    {
      pos: [5, 3, 3], 
      state: 12
    }, 
    {
      pos: [6, 3, 3], 
      state: 12
    }, 
    {
      pos: [8, 3, 3], 
      state: 12
    }, 
    {
      pos: [0, 4, 3], 
      state: 12
    }, 
    {
      pos: [1, 4, 3], 
      state: 12
    }, 
    {
      pos: [2, 4, 3], 
      state: 12
    }, 
    {
      pos: [3, 4, 3], 
      state: 12
    }, 
    {
      pos: [4, 4, 3], 
      state: 12
    }, 
    {
      pos: [7, 4, 3], 
      state: 12
    }, 
    {
      pos: [8, 4, 3], 
      state: 12
    }, 
    {
      pos: [8, 0, 4], 
      state: 9
    }, 
    {
      pos: [0, 1, 4], 
      state: 15
    }, 
    {
      pos: [1, 1, 4], 
      state: 12
    }, 
    {
      pos: [2, 1, 4], 
      state: 12
    }, 
    {
      pos: [3, 1, 4], 
      state: 12
    }, 
    {
      pos: [5, 1, 4], 
      state: 12
    }, 
    {
      pos: [6, 1, 4], 
      state: 12
    }, 
    {
      pos: [0, 2, 4], 
      state: 12
    }, 
    {
      pos: [1, 2, 4], 
      state: 12
    }, 
    {
      pos: [2, 2, 4], 
      state: 12
    }, 
    {
      pos: [3, 2, 4], 
      state: 12
    }, 
    {
      pos: [5, 2, 4], 
      state: 12
    }, 
    {
      pos: [6, 2, 4], 
      state: 12
    }, 
    {
      pos: [0, 3, 4], 
      state: 12
    }, 
    {
      pos: [1, 3, 4], 
      state: 12
    }, 
    {
      pos: [2, 3, 4], 
      state: 12
    }, 
    {
      pos: [3, 3, 4], 
      state: 14
    }, 
    {
      pos: [5, 3, 4], 
      state: 12
    }, 
    {
      pos: [6, 3, 4], 
      state: 12
    }, 
    {
      pos: [8, 3, 4], 
      state: 12
    }, 
    {
      pos: [0, 4, 4], 
      state: 12
    }, 
    {
      pos: [1, 4, 4], 
      state: 12
    }, 
    {
      pos: [2, 4, 4], 
      state: 12
    }, 
    {
      pos: [3, 4, 4], 
      state: 12
    }, 
    {
      pos: [4, 4, 4], 
      state: 12
    }, 
    {
      pos: [7, 4, 4], 
      state: 12
    }, 
    {
      pos: [8, 4, 4], 
      state: 12
    }, 
    {
      pos: [8, 0, 5], 
      state: 9
    }, 
    {
      pos: [1, 1, 5], 
      state: 12
    }, 
    {
      pos: [2, 1, 5], 
      state: 12
    }, 
    {
      pos: [3, 1, 5], 
      state: 12
    }, 
    {
      pos: [5, 1, 5], 
      state: 12
    }, 
    {
      pos: [6, 1, 5], 
      state: 12
    }, 
    {
      pos: [1, 2, 5], 
      state: 12
    }, 
    {
      pos: [2, 2, 5], 
      state: 12
    }, 
    {
      pos: [3, 2, 5], 
      state: 12
    }, 
    {
      pos: [5, 2, 5], 
      state: 12
    }, 
    {
      pos: [6, 2, 5], 
      state: 12
    }, 
    {
      pos: [0, 3, 5], 
      state: 14
    }, 
    {
      pos: [1, 3, 5], 
      state: 14
    }, 
    {
      pos: [2, 3, 5], 
      state: 14
    }, 
    {
      pos: [3, 3, 5], 
      state: 14
    }, 
    {
      pos: [5, 3, 5], 
      state: 12
    }, 
    {
      pos: [6, 3, 5], 
      state: 12
    }, 
    {
      pos: [8, 3, 5], 
      state: 14
    }, 
    {
      pos: [0, 4, 5], 
      state: 12
    }, 
    {
      pos: [1, 4, 5], 
      state: 12
    }, 
    {
      pos: [2, 4, 5], 
      state: 12
    }, 
    {
      pos: [3, 4, 5], 
      state: 12
    }, 
    {
      pos: [4, 4, 5], 
      state: 12
    }, 
    {
      pos: [7, 4, 5], 
      state: 12
    }, 
    {
      pos: [8, 4, 5], 
      state: 12
    }, 
    {
      pos: [8, 0, 6], 
      state: 9
    }, 
    {
      pos: [0, 1, 6], 
      state: 12
    }, 
    {
      pos: [4, 1, 6], 
      state: 12
    }, 
    {
      pos: [5, 1, 6], 
      state: 12
    }, 
    {
      pos: [6, 1, 6], 
      state: 12
    }, 
    {
      pos: [8, 1, 6], 
      state: 12
    }, 
    {
      pos: [0, 2, 6], 
      state: 12
    }, 
    {
      pos: [4, 2, 6], 
      state: 12
    }, 
    {
      pos: [5, 2, 6], 
      state: 12
    }, 
    {
      pos: [6, 2, 6], 
      state: 12
    }, 
    {
      pos: [8, 2, 6], 
      state: 12
    }, 
    {
      pos: [0, 4, 6], 
      state: 14
    }, 
    {
      pos: [1, 4, 6], 
      state: 12
    }, 
    {
      pos: [2, 4, 6], 
      state: 12
    }, 
    {
      pos: [3, 4, 6], 
      state: 12
    }, 
    {
      pos: [4, 4, 6], 
      state: 12
    }, 
    {
      pos: [7, 4, 6], 
      state: 12
    }, 
    {
      pos: [8, 4, 6], 
      state: 14
    }, 
    {
      pos: [0, 0, 7], 
      state: 19
    }, 
    {
      pos: [8, 0, 7], 
      state: 9
    }, 
    {
      pos: [0, 1, 7], 
      state: 12
    }, 
    {
      pos: [1, 1, 7], 
      state: 20
    }, 
    {
      pos: [2, 1, 7], 
      state: 12
    }, 
    {
      pos: [3, 1, 7], 
      state: 12
    }, 
    {
      pos: [4, 1, 7], 
      state: 12
    }, 
    {
      pos: [5, 1, 7], 
      state: 12
    }, 
    {
      pos: [8, 1, 7], 
      state: 12
    }, 
    {
      pos: [0, 2, 7], 
      state: 12
    }, 
    {
      pos: [1, 2, 7], 
      state: 21
    }, 
    {
      pos: [2, 2, 7], 
      state: 12
    }, 
    {
      pos: [3, 2, 7], 
      state: 12
    }, 
    {
      pos: [4, 2, 7], 
      state: 12
    }, 
    {
      pos: [5, 2, 7], 
      state: 22
    }, 
    {
      pos: [6, 2, 7], 
      state: 12
    }, 
    {
      pos: [8, 2, 7], 
      state: 12
    }, 
    {
      pos: [2, 3, 7], 
      state: 12
    }, 
    {
      pos: [3, 3, 7], 
      state: 12
    }, 
    {
      pos: [4, 3, 7], 
      state: 12
    }, 
    {
      pos: [5, 3, 7], 
      state: 12
    }, 
    {
      pos: [6, 3, 7], 
      state: 12
    }, 
    {
      pos: [8, 3, 7], 
      state: 12
    }, 
    {
      pos: [0, 0, 8], 
      state: 9
    }, 
    {
      pos: [8, 0, 8], 
      state: 23
    }, 
    {
      pos: [0, 1, 8], 
      state: 12
    }, 
    {
      pos: [8, 1, 8], 
      state: 12
    }, 
    {
      pos: [0, 2, 8], 
      state: 12
    }, 
    {
      pos: [8, 2, 8], 
      state: 12
    }, 
    {
      pos: [0, 4, 8], 
      state: 14
    }, 
    {
      pos: [1, 4, 8], 
      state: 12
    }, 
    {
      pos: [2, 4, 8], 
      state: 12
    }, 
    {
      pos: [3, 4, 8], 
      state: 12
    }, 
    {
      pos: [4, 4, 8], 
      state: 12
    }, 
    {
      pos: [5, 4, 8], 
      state: 12
    }, 
    {
      pos: [6, 4, 8], 
      state: 12
    }, 
    {
      pos: [7, 4, 8], 
      state: 12
    }, 
    {
      pos: [8, 4, 8], 
      state: 14
    }, 
    {
      pos: [0, 0, 9], 
      state: 9
    }, 
    {
      pos: [1, 0, 9], 
      state: 9
    }, 
    {
      pos: [2, 0, 9], 
      state: 9
    }, 
    {
      pos: [3, 0, 9], 
      state: 9
    }, 
    {
      pos: [4, 0, 9], 
      state: 9
    }, 
    {
      pos: [5, 0, 9], 
      state: 9
    }, 
    {
      pos: [6, 0, 9], 
      state: 9
    }, 
    {
      pos: [7, 0, 9], 
      state: 9
    }, 
    {
      pos: [8, 0, 9], 
      state: 9
    }, 
    {
      pos: [0, 3, 9], 
      state: 14
    }, 
    {
      pos: [1, 3, 9], 
      state: 12
    }, 
    {
      pos: [2, 3, 9], 
      state: 12
    }, 
    {
      pos: [3, 3, 9], 
      state: 12
    }, 
    {
      pos: [4, 3, 9], 
      state: 12
    }, 
    {
      pos: [5, 3, 9], 
      state: 12
    }, 
    {
      pos: [6, 3, 9], 
      state: 12
    }, 
    {
      pos: [7, 3, 9], 
      state: 12
    }, 
    {
      pos: [8, 3, 9], 
      state: 14
    }, 
    {
      pos: [0, 4, 9], 
      state: 12
    }, 
    {
      pos: [1, 4, 9], 
      state: 12
    }, 
    {
      pos: [2, 4, 9], 
      state: 12
    }, 
    {
      pos: [3, 4, 9], 
      state: 12
    }, 
    {
      pos: [4, 4, 9], 
      state: 12
    }, 
    {
      pos: [5, 4, 9], 
      state: 12
    }, 
    {
      pos: [6, 4, 9], 
      state: 12
    }, 
    {
      pos: [7, 4, 9], 
      state: 12
    }, 
    {
      pos: [8, 4, 9], 
      state: 12
    }
  ], 
  palette: [
    {
      Properties: {
        axis: "y"
      }, 
      Name: "minecraft:stripped_spruce_log"
    }, 
    {
      Name: "minecraft:spruce_planks"
    }, 
    {
      Properties: {
        snowy: "false"
      }, 
      Name: "minecraft:grass_block"
    }, 
    {
      Properties: {
        facing: "south"
      }, 
      Name: "minecraft:loom"
    }, 
    {
      Properties: {
        axis: "z"
      }, 
      Name: "minecraft:stripped_spruce_log"
    }, 
    {
      Properties: {
        facing: "up"
      }, 
      Name: "minecraft:jigsaw"
    }, 
    {
      Properties: {
        facing: "west"
      }, 
      Name: "minecraft:jigsaw"
    }, 
    {
      Properties: {
        waterlogged: "false", 
        facing: "west", 
        type: "single"
      }, 
      Name: "minecraft:chest"
    }, 
    {
      Properties: {
        hanging: "true"
      }, 
      Name: "minecraft:lantern"
    }, 
    {
      Properties: {
        layers: "1"
      }, 
      Name: "minecraft:snow"
    }, 
    {
      Properties: {
        east: "true", 
        waterlogged: "false", 
        south: "true", 
        north: "false", 
        west: "false"
      }, 
      Name: "minecraft:spruce_fence"
    }, 
    {
      Properties: {
        east: "true", 
        waterlogged: "false", 
        south: "false", 
        north: "false", 
        west: "true"
      }, 
      Name: "minecraft:spruce_fence"
    }, 
    {
      Name: "minecraft:air"
    }, 
    {
      Properties: {
        hanging: "false"
      }, 
      Name: "minecraft:lantern"
    }, 
    {
      Properties: {
        waterlogged: "false", 
        type: "bottom"
      }, 
      Name: "minecraft:spruce_slab"
    }, 
    {
      Properties: {
        east: "false", 
        waterlogged: "false", 
        south: "true", 
        north: "true", 
        west: "false"
      }, 
      Name: "minecraft:spruce_fence"
    }, 
    {
      Properties: {
        hinge: "right", 
        half: "lower", 
        powered: "false", 
        facing: "east", 
        open: "false"
      }, 
      Name: "minecraft:spruce_door"
    }, 
    {
      Properties: {
        hinge: "right", 
        half: "upper", 
        powered: "false", 
        facing: "east", 
        open: "false"
      }, 
      Name: "minecraft:spruce_door"
    }, 
    {
      Properties: {
        facing: "west"
      }, 
      Name: "minecraft:wall_torch"
    }, 
    {
      Properties: {
        half: "bottom", 
        waterlogged: "false", 
        shape: "straight", 
        facing: "east"
      }, 
      Name: "minecraft:spruce_stairs"
    }, 
    {
      Properties: {
        hinge: "left", 
        half: "lower", 
        powered: "false", 
        facing: "east", 
        open: "false"
      }, 
      Name: "minecraft:spruce_door"
    }, 
    {
      Properties: {
        hinge: "left", 
        half: "upper", 
        powered: "false", 
        facing: "east", 
        open: "false"
      }, 
      Name: "minecraft:spruce_door"
    }, 
    {
      Properties: {
        facing: "north"
      }, 
      Name: "minecraft:wall_torch"
    }, 
    {
      Name: "minecraft:grass"
    }
  ]
}
