{
  size: [9, 8, 7], 
  entities: [], 
  blocks: [
    {
      pos: [0, 0, 0], 
      state: 0
    }, 
    {
      pos: [1, 0, 0], 
      state: 1
    }, 
    {
      pos: [2, 0, 0], 
      state: 0
    }, 
    {
      pos: [3, 0, 0], 
      state: 0
    }, 
    {
      pos: [4, 0, 0], 
      state: 0
    }, 
    {
      pos: [5, 0, 0], 
      state: 0
    }, 
    {
      pos: [6, 0, 0], 
      state: 0
    }, 
    {
      pos: [7, 0, 0], 
      state: 0
    }, 
    {
      pos: [8, 0, 0], 
      state: 0
    }, 
    {
      pos: [3, 3, 0], 
      state: 2
    }, 
    {
      pos: [4, 3, 0], 
      state: 2
    }, 
    {
      pos: [5, 3, 0], 
      state: 2
    }, 
    {
      pos: [6, 3, 0], 
      state: 2
    }, 
    {
      pos: [7, 3, 0], 
      state: 2
    }, 
    {
      pos: [8, 3, 0], 
      state: 2
    }, 
    {
      pos: [0, 0, 1], 
      state: 3
    }, 
    {
      pos: [1, 0, 1], 
      state: 3
    }, 
    {
      pos: [2, 0, 1], 
      state: 3
    }, 
    {
      pos: [3, 0, 1], 
      state: 3
    }, 
    {
      pos: [4, 0, 1], 
      state: 3
    }, 
    {
      pos: [5, 0, 1], 
      state: 3
    }, 
    {
      pos: [6, 0, 1], 
      state: 3
    }, 
    {
      pos: [7, 0, 1], 
      state: 3
    }, 
    {
      pos: [8, 0, 1], 
      state: 0
    }, 
    {
      pos: [0, 1, 1], 
      state: 1
    }, 
    {
      pos: [1, 1, 1], 
      state: 1
    }, 
    {
      pos: [2, 1, 1], 
      state: 1
    }, 
    {
      pos: [3, 1, 1], 
      state: 1
    }, 
    {
      pos: [4, 1, 1], 
      state: 4
    }, 
    {
      pos: [5, 1, 1], 
      state: 4
    }, 
    {
      pos: [6, 1, 1], 
      state: 4
    }, 
    {
      pos: [7, 1, 1], 
      state: 4
    }, 
    {
      pos: [4, 2, 1], 
      state: 4
    }, 
    {
      pos: [5, 2, 1], 
      state: 4
    }, 
    {
      pos: [6, 2, 1], 
      state: 4
    }, 
    {
      pos: [7, 2, 1], 
      state: 4
    }, 
    {
      pos: [4, 3, 1], 
      state: 4
    }, 
    {
      pos: [5, 3, 1], 
      state: 4
    }, 
    {
      pos: [6, 3, 1], 
      state: 4
    }, 
    {
      pos: [7, 3, 1], 
      state: 4
    }, 
    {
      pos: [3, 4, 1], 
      state: 2
    }, 
    {
      pos: [4, 4, 1], 
      state: 2
    }, 
    {
      pos: [5, 4, 1], 
      state: 2
    }, 
    {
      pos: [6, 4, 1], 
      state: 2
    }, 
    {
      pos: [7, 4, 1], 
      state: 2
    }, 
    {
      pos: [8, 4, 1], 
      state: 2
    }, 
    {
      pos: [0, 0, 2], 
      state: 3
    }, 
    {
      pos: [1, 0, 2], 
      state: 1
    }, 
    {
      pos: [2, 0, 2], 
      state: 1
    }, 
    {
      pos: [3, 0, 2], 
      state: 3
    }, 
    {
      pos: [4, 0, 2], 
      state: 3
    }, 
    {
      pos: [5, 0, 2], 
      state: 3
    }, 
    {
      pos: [6, 0, 2], 
      state: 3
    }, 
    {
      pos: [7, 0, 2], 
      state: 3
    }, 
    {
      pos: [8, 0, 2], 
      state: 0
    }, 
    {
      pos: [0, 1, 2], 
      state: 1
    }, 
    {
      pos: [3, 1, 2], 
      state: 1
    }, 
    {
      pos: [4, 1, 2], 
      state: 4
    }, 
    {
      pos: [5, 1, 2], 
      state: 2
    }, 
    {
      pos: [6, 1, 2], 
      state: 2
    }, 
    {
      pos: [7, 1, 2], 
      state: 4
    }, 
    {
      pos: [4, 2, 2], 
      state: 4
    }, 
    {
      pos: [7, 2, 2], 
      state: 4
    }, 
    {
      pos: [4, 3, 2], 
      state: 4
    }, 
    {
      pos: [7, 3, 2], 
      state: 5
    }, 
    {
      pos: [4, 4, 2], 
      state: 4
    }, 
    {
      pos: [7, 4, 2], 
      state: 4
    }, 
    {
      pos: [3, 5, 2], 
      state: 2
    }, 
    {
      pos: [4, 5, 2], 
      state: 2
    }, 
    {
      pos: [5, 5, 2], 
      state: 2
    }, 
    {
      pos: [6, 5, 2], 
      state: 2
    }, 
    {
      pos: [7, 5, 2], 
      state: 2
    }, 
    {
      pos: [8, 5, 2], 
      state: 2
    }, 
    {
      pos: [0, 0, 3], 
      state: 3
    }, 
    {
      pos: [1, 0, 3], 
      state: 1
    }, 
    {
      pos: [2, 0, 3], 
      state: 1
    }, 
    {
      pos: [3, 0, 3], 
      state: 1
    }, 
    {
      pos: [4, 0, 3], 
      state: 3
    }, 
    {
      pos: [5, 0, 3], 
      state: 3
    }, 
    {
      pos: [6, 0, 3], 
      state: 3
    }, 
    {
      pos: [7, 0, 3], 
      state: 3
    }, 
    {
      pos: [8, 0, 3], 
      state: 0
    }, 
    {
      pos: [0, 1, 3], 
      state: 1
    }, 
    {
      pos: [4, 1, 3], 
      state: 4
    }, 
    {
      pos: [5, 1, 3], 
      state: 2
    }, 
    {
      pos: [6, 1, 3], 
      state: 2
    }, 
    {
      pos: [7, 1, 3], 
      state: 4
    }, 
    {
      pos: [7, 2, 3], 
      state: 5
    }, 
    {
      pos: [4, 4, 3], 
      state: 5
    }, 
    {
      pos: [7, 4, 3], 
      state: 5
    }, 
    {
      pos: [4, 5, 3], 
      state: 4
    }, 
    {
      pos: [7, 5, 3], 
      state: 4
    }, 
    {
      pos: [3, 6, 3], 
      state: 2
    }, 
    {
      pos: [4, 6, 3], 
      state: 2
    }, 
    {
      pos: [5, 6, 3], 
      state: 2
    }, 
    {
      pos: [6, 6, 3], 
      state: 2
    }, 
    {
      pos: [7, 6, 3], 
      state: 2
    }, 
    {
      pos: [8, 6, 3], 
      state: 2
    }, 
    {
      pos: [0, 0, 4], 
      state: 3
    }, 
    {
      pos: [1, 0, 4], 
      state: 1
    }, 
    {
      pos: [2, 0, 4], 
      state: 1
    }, 
    {
      pos: [3, 0, 4], 
      state: 1
    }, 
    {
      pos: [4, 0, 4], 
      state: 3
    }, 
    {
      pos: [5, 0, 4], 
      state: 3
    }, 
    {
      pos: [6, 0, 4], 
      state: 3
    }, 
    {
      pos: [7, 0, 4], 
      state: 3
    }, 
    {
      pos: [8, 0, 4], 
      state: 0
    }, 
    {
      pos: [0, 1, 4], 
      state: 1
    }, 
    {
      pos: [4, 1, 4], 
      state: 4
    }, 
    {
      pos: [5, 1, 4], 
      state: 2
    }, 
    {
      pos: [6, 1, 4], 
      state: 2
    }, 
    {
      pos: [7, 1, 4], 
      state: 4
    }, 
    {
      pos: [4, 2, 4], 
      state: 4
    }, 
    {
      pos: [7, 2, 4], 
      state: 4
    }, 
    {
      pos: [4, 3, 4], 
      state: 4
    }, 
    {
      pos: [7, 3, 4], 
      state: 5
    }, 
    {
      pos: [4, 4, 4], 
      state: 4
    }, 
    {
      pos: [7, 4, 4], 
      state: 4
    }, 
    {
      pos: [3, 5, 4], 
      state: 2
    }, 
    {
      pos: [4, 5, 4], 
      state: 2
    }, 
    {
      pos: [5, 5, 4], 
      state: 2
    }, 
    {
      pos: [6, 5, 4], 
      state: 2
    }, 
    {
      pos: [7, 5, 4], 
      state: 2
    }, 
    {
      pos: [8, 5, 4], 
      state: 2
    }, 
    {
      pos: [0, 0, 5], 
      state: 0
    }, 
    {
      pos: [1, 0, 5], 
      state: 1
    }, 
    {
      pos: [2, 0, 5], 
      state: 0
    }, 
    {
      pos: [3, 0, 5], 
      state: 0
    }, 
    {
      pos: [4, 0, 5], 
      state: 3
    }, 
    {
      pos: [5, 0, 5], 
      state: 3
    }, 
    {
      pos: [6, 0, 5], 
      state: 3
    }, 
    {
      pos: [7, 0, 5], 
      state: 3
    }, 
    {
      pos: [8, 0, 5], 
      state: 0
    }, 
    {
      pos: [4, 1, 5], 
      state: 4
    }, 
    {
      pos: [5, 1, 5], 
      state: 4
    }, 
    {
      pos: [6, 1, 5], 
      state: 4
    }, 
    {
      pos: [7, 1, 5], 
      state: 4
    }, 
    {
      pos: [4, 2, 5], 
      state: 4
    }, 
    {
      pos: [5, 2, 5], 
      state: 4
    }, 
    {
      pos: [6, 2, 5], 
      state: 4
    }, 
    {
      pos: [7, 2, 5], 
      state: 4
    }, 
    {
      pos: [4, 3, 5], 
      state: 4
    }, 
    {
      pos: [5, 3, 5], 
      state: 4
    }, 
    {
      pos: [6, 3, 5], 
      state: 4
    }, 
    {
      pos: [7, 3, 5], 
      state: 4
    }, 
    {
      pos: [3, 4, 5], 
      state: 2
    }, 
    {
      pos: [4, 4, 5], 
      state: 2
    }, 
    {
      pos: [5, 4, 5], 
      state: 2
    }, 
    {
      pos: [6, 4, 5], 
      state: 2
    }, 
    {
      pos: [7, 4, 5], 
      state: 2
    }, 
    {
      pos: [8, 4, 5], 
      state: 2
    }, 
    {
      pos: [0, 0, 6], 
      state: 0
    }, 
    {
      pos: [2, 0, 6], 
      state: 0
    }, 
    {
      pos: [3, 0, 6], 
      state: 0
    }, 
    {
      pos: [4, 0, 6], 
      state: 0
    }, 
    {
      pos: [5, 0, 6], 
      state: 0
    }, 
    {
      pos: [6, 0, 6], 
      state: 0
    }, 
    {
      pos: [7, 0, 6], 
      state: 0
    }, 
    {
      pos: [8, 0, 6], 
      state: 0
    }, 
    {
      pos: [3, 3, 6], 
      state: 2
    }, 
    {
      pos: [4, 3, 6], 
      state: 2
    }, 
    {
      pos: [5, 3, 6], 
      state: 2
    }, 
    {
      pos: [6, 3, 6], 
      state: 2
    }, 
    {
      pos: [7, 3, 6], 
      state: 2
    }, 
    {
      pos: [8, 3, 6], 
      state: 2
    }, 
    {
      nbt: {
        Items: [], 
        id: "minecraft:barrel", 
        Lock: ""
      }, 
      pos: [5, 2, 2], 
      state: 6
    }, 
    {
      nbt: {
        Items: [], 
        id: "minecraft:barrel", 
        Lock: ""
      }, 
      pos: [6, 2, 2], 
      state: 7
    }, 
    {
      nbt: {
        Items: [], 
        id: "minecraft:barrel", 
        Lock: ""
      }, 
      pos: [6, 3, 2], 
      state: 8
    }, 
    {
      nbt: {
        target_pool: "minecraft:empty", 
        final_state: "minecraft:structure_void", 
        id: "minecraft:jigsaw", 
        attachement_type: "minecraft:building_entrance"
      }, 
      pos: [1, 1, 6], 
      state: 9
    }, 
    {
      pos: [0, 1, 0], 
      state: 10
    }, 
    {
      pos: [1, 1, 0], 
      state: 11
    }, 
    {
      pos: [2, 1, 0], 
      state: 10
    }, 
    {
      pos: [3, 1, 0], 
      state: 10
    }, 
    {
      pos: [4, 1, 0], 
      state: 10
    }, 
    {
      pos: [5, 1, 0], 
      state: 10
    }, 
    {
      pos: [6, 1, 0], 
      state: 10
    }, 
    {
      pos: [7, 1, 0], 
      state: 10
    }, 
    {
      pos: [8, 1, 0], 
      state: 10
    }, 
    {
      pos: [0, 2, 0], 
      state: 11
    }, 
    {
      pos: [1, 2, 0], 
      state: 11
    }, 
    {
      pos: [2, 2, 0], 
      state: 11
    }, 
    {
      pos: [3, 2, 0], 
      state: 12
    }, 
    {
      pos: [4, 2, 0], 
      state: 11
    }, 
    {
      pos: [5, 2, 0], 
      state: 12
    }, 
    {
      pos: [6, 2, 0], 
      state: 12
    }, 
    {
      pos: [7, 2, 0], 
      state: 11
    }, 
    {
      pos: [8, 2, 0], 
      state: 12
    }, 
    {
      pos: [0, 3, 0], 
      state: 11
    }, 
    {
      pos: [1, 3, 0], 
      state: 11
    }, 
    {
      pos: [2, 3, 0], 
      state: 11
    }, 
    {
      pos: [0, 4, 0], 
      state: 11
    }, 
    {
      pos: [1, 4, 0], 
      state: 11
    }, 
    {
      pos: [2, 4, 0], 
      state: 11
    }, 
    {
      pos: [3, 4, 0], 
      state: 13
    }, 
    {
      pos: [4, 4, 0], 
      state: 11
    }, 
    {
      pos: [5, 4, 0], 
      state: 13
    }, 
    {
      pos: [6, 4, 0], 
      state: 13
    }, 
    {
      pos: [7, 4, 0], 
      state: 11
    }, 
    {
      pos: [8, 4, 0], 
      state: 13
    }, 
    {
      pos: [0, 5, 0], 
      state: 11
    }, 
    {
      pos: [1, 5, 0], 
      state: 11
    }, 
    {
      pos: [2, 5, 0], 
      state: 11
    }, 
    {
      pos: [3, 5, 0], 
      state: 11
    }, 
    {
      pos: [4, 5, 0], 
      state: 11
    }, 
    {
      pos: [5, 5, 0], 
      state: 11
    }, 
    {
      pos: [6, 5, 0], 
      state: 11
    }, 
    {
      pos: [7, 5, 0], 
      state: 11
    }, 
    {
      pos: [8, 5, 0], 
      state: 11
    }, 
    {
      pos: [0, 6, 0], 
      state: 11
    }, 
    {
      pos: [1, 6, 0], 
      state: 11
    }, 
    {
      pos: [2, 6, 0], 
      state: 11
    }, 
    {
      pos: [3, 6, 0], 
      state: 11
    }, 
    {
      pos: [4, 6, 0], 
      state: 11
    }, 
    {
      pos: [5, 6, 0], 
      state: 11
    }, 
    {
      pos: [6, 6, 0], 
      state: 11
    }, 
    {
      pos: [7, 6, 0], 
      state: 11
    }, 
    {
      pos: [8, 6, 0], 
      state: 11
    }, 
    {
      pos: [0, 7, 0], 
      state: 11
    }, 
    {
      pos: [1, 7, 0], 
      state: 11
    }, 
    {
      pos: [2, 7, 0], 
      state: 11
    }, 
    {
      pos: [3, 7, 0], 
      state: 11
    }, 
    {
      pos: [4, 7, 0], 
      state: 11
    }, 
    {
      pos: [5, 7, 0], 
      state: 11
    }, 
    {
      pos: [6, 7, 0], 
      state: 11
    }, 
    {
      pos: [7, 7, 0], 
      state: 11
    }, 
    {
      pos: [8, 7, 0], 
      state: 11
    }, 
    {
      pos: [8, 1, 1], 
      state: 10
    }, 
    {
      pos: [0, 2, 1], 
      state: 14
    }, 
    {
      pos: [1, 2, 1], 
      state: 11
    }, 
    {
      pos: [2, 2, 1], 
      state: 11
    }, 
    {
      pos: [3, 2, 1], 
      state: 11
    }, 
    {
      pos: [8, 2, 1], 
      state: 11
    }, 
    {
      pos: [0, 3, 1], 
      state: 14
    }, 
    {
      pos: [1, 3, 1], 
      state: 15
    }, 
    {
      pos: [2, 3, 1], 
      state: 11
    }, 
    {
      pos: [3, 3, 1], 
      state: 11
    }, 
    {
      pos: [8, 3, 1], 
      state: 11
    }, 
    {
      pos: [0, 4, 1], 
      state: 16
    }, 
    {
      pos: [1, 4, 1], 
      state: 17
    }, 
    {
      pos: [2, 4, 1], 
      state: 17
    }, 
    {
      pos: [0, 5, 1], 
      state: 11
    }, 
    {
      pos: [1, 5, 1], 
      state: 11
    }, 
    {
      pos: [2, 5, 1], 
      state: 11
    }, 
    {
      pos: [3, 5, 1], 
      state: 13
    }, 
    {
      pos: [4, 5, 1], 
      state: 11
    }, 
    {
      pos: [5, 5, 1], 
      state: 13
    }, 
    {
      pos: [6, 5, 1], 
      state: 13
    }, 
    {
      pos: [7, 5, 1], 
      state: 11
    }, 
    {
      pos: [8, 5, 1], 
      state: 13
    }, 
    {
      pos: [0, 6, 1], 
      state: 11
    }, 
    {
      pos: [1, 6, 1], 
      state: 11
    }, 
    {
      pos: [2, 6, 1], 
      state: 11
    }, 
    {
      pos: [3, 6, 1], 
      state: 11
    }, 
    {
      pos: [4, 6, 1], 
      state: 11
    }, 
    {
      pos: [5, 6, 1], 
      state: 11
    }, 
    {
      pos: [6, 6, 1], 
      state: 11
    }, 
    {
      pos: [7, 6, 1], 
      state: 11
    }, 
    {
      pos: [8, 6, 1], 
      state: 11
    }, 
    {
      pos: [0, 7, 1], 
      state: 11
    }, 
    {
      pos: [1, 7, 1], 
      state: 11
    }, 
    {
      pos: [2, 7, 1], 
      state: 11
    }, 
    {
      pos: [3, 7, 1], 
      state: 11
    }, 
    {
      pos: [4, 7, 1], 
      state: 11
    }, 
    {
      pos: [5, 7, 1], 
      state: 11
    }, 
    {
      pos: [6, 7, 1], 
      state: 11
    }, 
    {
      pos: [7, 7, 1], 
      state: 11
    }, 
    {
      pos: [8, 7, 1], 
      state: 11
    }, 
    {
      pos: [1, 1, 2], 
      state: 18
    }, 
    {
      pos: [2, 1, 2], 
      state: 18
    }, 
    {
      pos: [8, 1, 2], 
      state: 10
    }, 
    {
      pos: [0, 2, 2], 
      state: 11
    }, 
    {
      pos: [1, 2, 2], 
      state: 11
    }, 
    {
      pos: [2, 2, 2], 
      state: 11
    }, 
    {
      pos: [3, 2, 2], 
      state: 11
    }, 
    {
      pos: [8, 2, 2], 
      state: 11
    }, 
    {
      pos: [0, 3, 2], 
      state: 15
    }, 
    {
      pos: [1, 3, 2], 
      state: 11
    }, 
    {
      pos: [2, 3, 2], 
      state: 11
    }, 
    {
      pos: [3, 3, 2], 
      state: 11
    }, 
    {
      pos: [5, 3, 2], 
      state: 11
    }, 
    {
      pos: [8, 3, 2], 
      state: 11
    }, 
    {
      pos: [0, 4, 2], 
      state: 19
    }, 
    {
      pos: [1, 4, 2], 
      state: 11
    }, 
    {
      pos: [2, 4, 2], 
      state: 11
    }, 
    {
      pos: [3, 4, 2], 
      state: 11
    }, 
    {
      pos: [5, 4, 2], 
      state: 11
    }, 
    {
      pos: [6, 4, 2], 
      state: 11
    }, 
    {
      pos: [8, 4, 2], 
      state: 11
    }, 
    {
      pos: [0, 5, 2], 
      state: 11
    }, 
    {
      pos: [1, 5, 2], 
      state: 11
    }, 
    {
      pos: [2, 5, 2], 
      state: 11
    }, 
    {
      pos: [0, 6, 2], 
      state: 11
    }, 
    {
      pos: [1, 6, 2], 
      state: 11
    }, 
    {
      pos: [2, 6, 2], 
      state: 11
    }, 
    {
      pos: [3, 6, 2], 
      state: 13
    }, 
    {
      pos: [4, 6, 2], 
      state: 11
    }, 
    {
      pos: [5, 6, 2], 
      state: 13
    }, 
    {
      pos: [6, 6, 2], 
      state: 13
    }, 
    {
      pos: [7, 6, 2], 
      state: 11
    }, 
    {
      pos: [8, 6, 2], 
      state: 13
    }, 
    {
      pos: [0, 7, 2], 
      state: 11
    }, 
    {
      pos: [1, 7, 2], 
      state: 11
    }, 
    {
      pos: [2, 7, 2], 
      state: 11
    }, 
    {
      pos: [3, 7, 2], 
      state: 11
    }, 
    {
      pos: [4, 7, 2], 
      state: 11
    }, 
    {
      pos: [5, 7, 2], 
      state: 11
    }, 
    {
      pos: [6, 7, 2], 
      state: 11
    }, 
    {
      pos: [7, 7, 2], 
      state: 11
    }, 
    {
      pos: [8, 7, 2], 
      state: 11
    }, 
    {
      pos: [1, 1, 3], 
      state: 18
    }, 
    {
      pos: [2, 1, 3], 
      state: 18
    }, 
    {
      pos: [3, 1, 3], 
      state: 20
    }, 
    {
      pos: [8, 1, 3], 
      state: 10
    }, 
    {
      pos: [0, 2, 3], 
      state: 11
    }, 
    {
      pos: [1, 2, 3], 
      state: 11
    }, 
    {
      pos: [2, 2, 3], 
      state: 11
    }, 
    {
      pos: [3, 2, 3], 
      state: 11
    }, 
    {
      pos: [4, 2, 3], 
      state: 21
    }, 
    {
      pos: [5, 2, 3], 
      state: 11
    }, 
    {
      pos: [6, 2, 3], 
      state: 11
    }, 
    {
      pos: [8, 2, 3], 
      state: 11
    }, 
    {
      pos: [0, 3, 3], 
      state: 11
    }, 
    {
      pos: [1, 3, 3], 
      state: 11
    }, 
    {
      pos: [2, 3, 3], 
      state: 11
    }, 
    {
      pos: [3, 3, 3], 
      state: 11
    }, 
    {
      pos: [4, 3, 3], 
      state: 22
    }, 
    {
      pos: [5, 3, 3], 
      state: 11
    }, 
    {
      pos: [6, 3, 3], 
      state: 11
    }, 
    {
      pos: [7, 3, 3], 
      state: 23
    }, 
    {
      pos: [8, 3, 3], 
      state: 11
    }, 
    {
      pos: [0, 4, 3], 
      state: 19
    }, 
    {
      pos: [1, 4, 3], 
      state: 11
    }, 
    {
      pos: [2, 4, 3], 
      state: 11
    }, 
    {
      pos: [3, 4, 3], 
      state: 11
    }, 
    {
      pos: [5, 4, 3], 
      state: 11
    }, 
    {
      pos: [6, 4, 3], 
      state: 11
    }, 
    {
      pos: [8, 4, 3], 
      state: 11
    }, 
    {
      pos: [0, 5, 3], 
      state: 11
    }, 
    {
      pos: [1, 5, 3], 
      state: 11
    }, 
    {
      pos: [2, 5, 3], 
      state: 11
    }, 
    {
      pos: [3, 5, 3], 
      state: 11
    }, 
    {
      pos: [5, 5, 3], 
      state: 11
    }, 
    {
      pos: [6, 5, 3], 
      state: 15
    }, 
    {
      pos: [8, 5, 3], 
      state: 11
    }, 
    {
      pos: [0, 6, 3], 
      state: 11
    }, 
    {
      pos: [1, 6, 3], 
      state: 11
    }, 
    {
      pos: [2, 6, 3], 
      state: 11
    }, 
    {
      pos: [0, 7, 3], 
      state: 11
    }, 
    {
      pos: [1, 7, 3], 
      state: 11
    }, 
    {
      pos: [2, 7, 3], 
      state: 11
    }, 
    {
      pos: [3, 7, 3], 
      state: 13
    }, 
    {
      pos: [4, 7, 3], 
      state: 11
    }, 
    {
      pos: [5, 7, 3], 
      state: 13
    }, 
    {
      pos: [6, 7, 3], 
      state: 13
    }, 
    {
      pos: [7, 7, 3], 
      state: 11
    }, 
    {
      pos: [8, 7, 3], 
      state: 13
    }, 
    {
      pos: [1, 1, 4], 
      state: 20
    }, 
    {
      pos: [2, 1, 4], 
      state: 20
    }, 
    {
      pos: [3, 1, 4], 
      state: 20
    }, 
    {
      pos: [8, 1, 4], 
      state: 10
    }, 
    {
      pos: [0, 2, 4], 
      state: 14
    }, 
    {
      pos: [1, 2, 4], 
      state: 11
    }, 
    {
      pos: [2, 2, 4], 
      state: 11
    }, 
    {
      pos: [3, 2, 4], 
      state: 11
    }, 
    {
      pos: [5, 2, 4], 
      state: 11
    }, 
    {
      pos: [6, 2, 4], 
      state: 11
    }, 
    {
      pos: [8, 2, 4], 
      state: 11
    }, 
    {
      pos: [0, 3, 4], 
      state: 14
    }, 
    {
      pos: [1, 3, 4], 
      state: 11
    }, 
    {
      pos: [2, 3, 4], 
      state: 11
    }, 
    {
      pos: [3, 3, 4], 
      state: 11
    }, 
    {
      pos: [5, 3, 4], 
      state: 11
    }, 
    {
      pos: [6, 3, 4], 
      state: 11
    }, 
    {
      pos: [8, 3, 4], 
      state: 11
    }, 
    {
      pos: [0, 4, 4], 
      state: 24
    }, 
    {
      pos: [1, 4, 4], 
      state: 11
    }, 
    {
      pos: [2, 4, 4], 
      state: 11
    }, 
    {
      pos: [3, 4, 4], 
      state: 11
    }, 
    {
      pos: [5, 4, 4], 
      state: 11
    }, 
    {
      pos: [6, 4, 4], 
      state: 11
    }, 
    {
      pos: [8, 4, 4], 
      state: 11
    }, 
    {
      pos: [0, 5, 4], 
      state: 11
    }, 
    {
      pos: [1, 5, 4], 
      state: 11
    }, 
    {
      pos: [2, 5, 4], 
      state: 11
    }, 
    {
      pos: [0, 6, 4], 
      state: 11
    }, 
    {
      pos: [1, 6, 4], 
      state: 11
    }, 
    {
      pos: [2, 6, 4], 
      state: 11
    }, 
    {
      pos: [3, 6, 4], 
      state: 13
    }, 
    {
      pos: [4, 6, 4], 
      state: 11
    }, 
    {
      pos: [5, 6, 4], 
      state: 13
    }, 
    {
      pos: [6, 6, 4], 
      state: 13
    }, 
    {
      pos: [7, 6, 4], 
      state: 11
    }, 
    {
      pos: [8, 6, 4], 
      state: 13
    }, 
    {
      pos: [0, 7, 4], 
      state: 11
    }, 
    {
      pos: [1, 7, 4], 
      state: 11
    }, 
    {
      pos: [2, 7, 4], 
      state: 11
    }, 
    {
      pos: [3, 7, 4], 
      state: 11
    }, 
    {
      pos: [4, 7, 4], 
      state: 11
    }, 
    {
      pos: [5, 7, 4], 
      state: 11
    }, 
    {
      pos: [6, 7, 4], 
      state: 11
    }, 
    {
      pos: [7, 7, 4], 
      state: 11
    }, 
    {
      pos: [8, 7, 4], 
      state: 11
    }, 
    {
      pos: [0, 1, 5], 
      state: 10
    }, 
    {
      pos: [1, 1, 5], 
      state: 25
    }, 
    {
      pos: [2, 1, 5], 
      state: 10
    }, 
    {
      pos: [3, 1, 5], 
      state: 10
    }, 
    {
      pos: [8, 1, 5], 
      state: 10
    }, 
    {
      pos: [0, 2, 5], 
      state: 11
    }, 
    {
      pos: [1, 2, 5], 
      state: 11
    }, 
    {
      pos: [2, 2, 5], 
      state: 11
    }, 
    {
      pos: [3, 2, 5], 
      state: 11
    }, 
    {
      pos: [8, 2, 5], 
      state: 11
    }, 
    {
      pos: [0, 3, 5], 
      state: 11
    }, 
    {
      pos: [1, 3, 5], 
      state: 11
    }, 
    {
      pos: [2, 3, 5], 
      state: 11
    }, 
    {
      pos: [3, 3, 5], 
      state: 11
    }, 
    {
      pos: [8, 3, 5], 
      state: 11
    }, 
    {
      pos: [0, 4, 5], 
      state: 11
    }, 
    {
      pos: [1, 4, 5], 
      state: 11
    }, 
    {
      pos: [2, 4, 5], 
      state: 11
    }, 
    {
      pos: [0, 5, 5], 
      state: 11
    }, 
    {
      pos: [1, 5, 5], 
      state: 11
    }, 
    {
      pos: [2, 5, 5], 
      state: 11
    }, 
    {
      pos: [3, 5, 5], 
      state: 13
    }, 
    {
      pos: [4, 5, 5], 
      state: 11
    }, 
    {
      pos: [5, 5, 5], 
      state: 13
    }, 
    {
      pos: [6, 5, 5], 
      state: 13
    }, 
    {
      pos: [7, 5, 5], 
      state: 11
    }, 
    {
      pos: [8, 5, 5], 
      state: 13
    }, 
    {
      pos: [0, 6, 5], 
      state: 11
    }, 
    {
      pos: [1, 6, 5], 
      state: 11
    }, 
    {
      pos: [2, 6, 5], 
      state: 11
    }, 
    {
      pos: [3, 6, 5], 
      state: 11
    }, 
    {
      pos: [4, 6, 5], 
      state: 11
    }, 
    {
      pos: [5, 6, 5], 
      state: 11
    }, 
    {
      pos: [6, 6, 5], 
      state: 11
    }, 
    {
      pos: [7, 6, 5], 
      state: 11
    }, 
    {
      pos: [8, 6, 5], 
      state: 11
    }, 
    {
      pos: [0, 7, 5], 
      state: 11
    }, 
    {
      pos: [1, 7, 5], 
      state: 11
    }, 
    {
      pos: [2, 7, 5], 
      state: 11
    }, 
    {
      pos: [3, 7, 5], 
      state: 11
    }, 
    {
      pos: [4, 7, 5], 
      state: 11
    }, 
    {
      pos: [5, 7, 5], 
      state: 11
    }, 
    {
      pos: [6, 7, 5], 
      state: 11
    }, 
    {
      pos: [7, 7, 5], 
      state: 11
    }, 
    {
      pos: [8, 7, 5], 
      state: 11
    }, 
    {
      pos: [1, 0, 6], 
      state: 20
    }, 
    {
      pos: [0, 1, 6], 
      state: 10
    }, 
    {
      pos: [2, 1, 6], 
      state: 10
    }, 
    {
      pos: [3, 1, 6], 
      state: 10
    }, 
    {
      pos: [4, 1, 6], 
      state: 10
    }, 
    {
      pos: [5, 1, 6], 
      state: 10
    }, 
    {
      pos: [6, 1, 6], 
      state: 10
    }, 
    {
      pos: [7, 1, 6], 
      state: 10
    }, 
    {
      pos: [8, 1, 6], 
      state: 10
    }, 
    {
      pos: [0, 2, 6], 
      state: 11
    }, 
    {
      pos: [1, 2, 6], 
      state: 11
    }, 
    {
      pos: [2, 2, 6], 
      state: 11
    }, 
    {
      pos: [3, 2, 6], 
      state: 12
    }, 
    {
      pos: [4, 2, 6], 
      state: 11
    }, 
    {
      pos: [5, 2, 6], 
      state: 12
    }, 
    {
      pos: [6, 2, 6], 
      state: 12
    }, 
    {
      pos: [7, 2, 6], 
      state: 11
    }, 
    {
      pos: [8, 2, 6], 
      state: 12
    }, 
    {
      pos: [0, 3, 6], 
      state: 11
    }, 
    {
      pos: [1, 3, 6], 
      state: 11
    }, 
    {
      pos: [2, 3, 6], 
      state: 11
    }, 
    {
      pos: [0, 4, 6], 
      state: 11
    }, 
    {
      pos: [1, 4, 6], 
      state: 11
    }, 
    {
      pos: [2, 4, 6], 
      state: 11
    }, 
    {
      pos: [3, 4, 6], 
      state: 13
    }, 
    {
      pos: [4, 4, 6], 
      state: 11
    }, 
    {
      pos: [5, 4, 6], 
      state: 13
    }, 
    {
      pos: [6, 4, 6], 
      state: 13
    }, 
    {
      pos: [7, 4, 6], 
      state: 11
    }, 
    {
      pos: [8, 4, 6], 
      state: 13
    }, 
    {
      pos: [0, 5, 6], 
      state: 11
    }, 
    {
      pos: [1, 5, 6], 
      state: 11
    }, 
    {
      pos: [2, 5, 6], 
      state: 11
    }, 
    {
      pos: [3, 5, 6], 
      state: 11
    }, 
    {
      pos: [4, 5, 6], 
      state: 11
    }, 
    {
      pos: [5, 5, 6], 
      state: 11
    }, 
    {
      pos: [6, 5, 6], 
      state: 11
    }, 
    {
      pos: [7, 5, 6], 
      state: 11
    }, 
    {
      pos: [8, 5, 6], 
      state: 11
    }, 
    {
      pos: [0, 6, 6], 
      state: 11
    }, 
    {
      pos: [1, 6, 6], 
      state: 11
    }, 
    {
      pos: [2, 6, 6], 
      state: 11
    }, 
    {
      pos: [3, 6, 6], 
      state: 11
    }, 
    {
      pos: [4, 6, 6], 
      state: 11
    }, 
    {
      pos: [5, 6, 6], 
      state: 11
    }, 
    {
      pos: [6, 6, 6], 
      state: 11
    }, 
    {
      pos: [7, 6, 6], 
      state: 11
    }, 
    {
      pos: [8, 6, 6], 
      state: 11
    }, 
    {
      pos: [0, 7, 6], 
      state: 11
    }, 
    {
      pos: [1, 7, 6], 
      state: 11
    }, 
    {
      pos: [2, 7, 6], 
      state: 11
    }, 
    {
      pos: [3, 7, 6], 
      state: 11
    }, 
    {
      pos: [4, 7, 6], 
      state: 11
    }, 
    {
      pos: [5, 7, 6], 
      state: 11
    }, 
    {
      pos: [6, 7, 6], 
      state: 11
    }, 
    {
      pos: [7, 7, 6], 
      state: 11
    }, 
    {
      pos: [8, 7, 6], 
      state: 11
    }
  ], 
  palette: [
    {
      Properties: {
        snowy: "true"
      }, 
      Name: "minecraft:grass_block"
    }, 
    {
      Properties: {
        snowy: "false"
      }, 
      Name: "minecraft:grass_block"
    }, 
    {
      Name: "minecraft:spruce_planks"
    }, 
    {
      Name: "minecraft:dirt"
    }, 
    {
      Properties: {
        axis: "y"
      }, 
      Name: "minecraft:stripped_spruce_log"
    }, 
    {
      Properties: {
        axis: "x"
      }, 
      Name: "minecraft:stripped_spruce_log"
    }, 
    {
      Properties: {
        facing: "down"
      }, 
      Name: "minecraft:barrel"
    }, 
    {
      Properties: {
        facing: "up"
      }, 
      Name: "minecraft:barrel"
    }, 
    {
      Properties: {
        facing: "south"
      }, 
      Name: "minecraft:barrel"
    }, 
    {
      Properties: {
        facing: "south"
      }, 
      Name: "minecraft:jigsaw"
    }, 
    {
      Properties: {
        layers: "1"
      }, 
      Name: "minecraft:snow"
    }, 
    {
      Name: "minecraft:air"
    }, 
    {
      Properties: {
        waterlogged: "false", 
        type: "top"
      }, 
      Name: "minecraft:spruce_slab"
    }, 
    {
      Properties: {
        waterlogged: "false", 
        type: "bottom"
      }, 
      Name: "minecraft:spruce_slab"
    }, 
    {
      Properties: {
        east: "false", 
        waterlogged: "false", 
        south: "false", 
        north: "false", 
        west: "false"
      }, 
      Name: "minecraft:spruce_fence"
    }, 
    {
      Properties: {
        hanging: "true"
      }, 
      Name: "minecraft:lantern"
    }, 
    {
      Properties: {
        east: "true", 
        waterlogged: "false", 
        south: "true", 
        north: "false", 
        west: "false"
      }, 
      Name: "minecraft:spruce_fence"
    }, 
    {
      Properties: {
        east: "true", 
        waterlogged: "false", 
        south: "false", 
        north: "false", 
        west: "true"
      }, 
      Name: "minecraft:spruce_fence"
    }, 
    {
      Properties: {
        level: "0"
      }, 
      Name: "minecraft:water"
    }, 
    {
      Properties: {
        east: "false", 
        waterlogged: "false", 
        south: "true", 
        north: "true", 
        west: "false"
      }, 
      Name: "minecraft:spruce_fence"
    }, 
    {
      Name: "minecraft:grass_path"
    }, 
    {
      Properties: {
        hinge: "right", 
        half: "lower", 
        powered: "false", 
        facing: "east", 
        open: "false"
      }, 
      Name: "minecraft:spruce_door"
    }, 
    {
      Properties: {
        hinge: "right", 
        half: "upper", 
        powered: "false", 
        facing: "east", 
        open: "false"
      }, 
      Name: "minecraft:spruce_door"
    }, 
    {
      Properties: {
        east: "false", 
        waterlogged: "false", 
        south: "true", 
        north: "true", 
        west: "false"
      }, 
      Name: "minecraft:glass_pane"
    }, 
    {
      Properties: {
        east: "false", 
        waterlogged: "false", 
        south: "false", 
        north: "true", 
        west: "false"
      }, 
      Name: "minecraft:spruce_fence"
    }, 
    {
      Properties: {
        half: "bottom", 
        waterlogged: "false", 
        shape: "straight", 
        facing: "north"
      }, 
      Name: "minecraft:spruce_stairs"
    }
  ]
}
