{
  size: [13, 10, 7], 
  entities: [], 
  blocks: [
    {
      pos: [6, 0, 0], 
      state: 0
    }, 
    {
      pos: [1, 0, 1], 
      state: 0
    }, 
    {
      pos: [2, 0, 1], 
      state: 1
    }, 
    {
      pos: [3, 0, 1], 
      state: 1
    }, 
    {
      pos: [4, 0, 1], 
      state: 2
    }, 
    {
      pos: [5, 0, 1], 
      state: 2
    }, 
    {
      pos: [6, 0, 1], 
      state: 1
    }, 
    {
      pos: [7, 0, 1], 
      state: 2
    }, 
    {
      pos: [8, 0, 1], 
      state: 1
    }, 
    {
      pos: [9, 0, 1], 
      state: 1
    }, 
    {
      pos: [10, 0, 1], 
      state: 1
    }, 
    {
      pos: [11, 0, 1], 
      state: 0
    }, 
    {
      pos: [1, 0, 2], 
      state: 0
    }, 
    {
      pos: [2, 0, 2], 
      state: 1
    }, 
    {
      pos: [3, 0, 2], 
      state: 3
    }, 
    {
      pos: [4, 0, 2], 
      state: 3
    }, 
    {
      pos: [5, 0, 2], 
      state: 3
    }, 
    {
      pos: [6, 0, 2], 
      state: 3
    }, 
    {
      pos: [7, 0, 2], 
      state: 3
    }, 
    {
      pos: [8, 0, 2], 
      state: 3
    }, 
    {
      pos: [9, 0, 2], 
      state: 3
    }, 
    {
      pos: [10, 0, 2], 
      state: 1
    }, 
    {
      pos: [11, 0, 2], 
      state: 0
    }, 
    {
      pos: [2, 0, 3], 
      state: 1
    }, 
    {
      pos: [3, 0, 3], 
      state: 3
    }, 
    {
      pos: [4, 0, 3], 
      state: 3
    }, 
    {
      pos: [5, 0, 3], 
      state: 3
    }, 
    {
      pos: [6, 0, 3], 
      state: 3
    }, 
    {
      pos: [7, 0, 3], 
      state: 3
    }, 
    {
      pos: [8, 0, 3], 
      state: 3
    }, 
    {
      pos: [9, 0, 3], 
      state: 3
    }, 
    {
      pos: [10, 0, 3], 
      state: 1
    }, 
    {
      pos: [11, 0, 3], 
      state: 0
    }, 
    {
      pos: [1, 0, 4], 
      state: 4
    }, 
    {
      pos: [2, 0, 4], 
      state: 5
    }, 
    {
      pos: [3, 0, 4], 
      state: 3
    }, 
    {
      pos: [4, 0, 4], 
      state: 3
    }, 
    {
      pos: [5, 0, 4], 
      state: 3
    }, 
    {
      pos: [6, 0, 4], 
      state: 3
    }, 
    {
      pos: [7, 0, 4], 
      state: 3
    }, 
    {
      pos: [8, 0, 4], 
      state: 3
    }, 
    {
      pos: [9, 0, 4], 
      state: 3
    }, 
    {
      pos: [10, 0, 4], 
      state: 1
    }, 
    {
      pos: [1, 0, 5], 
      state: 0
    }, 
    {
      pos: [2, 0, 5], 
      state: 1
    }, 
    {
      pos: [3, 0, 5], 
      state: 1
    }, 
    {
      pos: [4, 0, 5], 
      state: 1
    }, 
    {
      pos: [5, 0, 5], 
      state: 1
    }, 
    {
      pos: [6, 0, 5], 
      state: 1
    }, 
    {
      pos: [7, 0, 5], 
      state: 1
    }, 
    {
      pos: [8, 0, 5], 
      state: 1
    }, 
    {
      pos: [9, 0, 5], 
      state: 1
    }, 
    {
      pos: [10, 0, 5], 
      state: 1
    }, 
    {
      pos: [4, 0, 6], 
      state: 0
    }, 
    {
      pos: [5, 0, 6], 
      state: 0
    }, 
    {
      pos: [10, 0, 6], 
      state: 4
    }, 
    {
      pos: [11, 0, 6], 
      state: 4
    }, 
    {
      nbt: {
        target_pool: "minecraft:empty", 
        final_state: "minecraft:structure_void", 
        id: "minecraft:jigsaw", 
        attachement_type: "minecraft:building_entrance"
      }, 
      pos: [0, 0, 3], 
      state: 6
    }, 
    {
      pos: [0, 0, 0], 
      state: 7
    }, 
    {
      pos: [1, 0, 0], 
      state: 8
    }, 
    {
      pos: [2, 0, 0], 
      state: 8
    }, 
    {
      pos: [3, 0, 0], 
      state: 7
    }, 
    {
      pos: [4, 0, 0], 
      state: 7
    }, 
    {
      pos: [5, 0, 0], 
      state: 8
    }, 
    {
      pos: [7, 0, 0], 
      state: 9
    }, 
    {
      pos: [8, 0, 0], 
      state: 8
    }, 
    {
      pos: [9, 0, 0], 
      state: 7
    }, 
    {
      pos: [10, 0, 0], 
      state: 7
    }, 
    {
      pos: [11, 0, 0], 
      state: 10
    }, 
    {
      pos: [12, 0, 0], 
      state: 7
    }, 
    {
      pos: [0, 0, 1], 
      state: 8
    }, 
    {
      pos: [12, 0, 1], 
      state: 9
    }, 
    {
      pos: [0, 0, 2], 
      state: 11
    }, 
    {
      pos: [12, 0, 2], 
      state: 7
    }, 
    {
      pos: [1, 0, 3], 
      state: 12
    }, 
    {
      pos: [12, 0, 3], 
      state: 9
    }, 
    {
      pos: [0, 0, 4], 
      state: 13
    }, 
    {
      pos: [11, 0, 4], 
      state: 7
    }, 
    {
      pos: [12, 0, 4], 
      state: 7
    }, 
    {
      pos: [0, 0, 5], 
      state: 7
    }, 
    {
      pos: [11, 0, 5], 
      state: 9
    }, 
    {
      pos: [12, 0, 5], 
      state: 7
    }, 
    {
      pos: [0, 0, 6], 
      state: 7
    }, 
    {
      pos: [1, 0, 6], 
      state: 7
    }, 
    {
      pos: [2, 0, 6], 
      state: 7
    }, 
    {
      pos: [3, 0, 6], 
      state: 9
    }, 
    {
      pos: [6, 0, 6], 
      state: 13
    }, 
    {
      pos: [7, 0, 6], 
      state: 7
    }, 
    {
      pos: [8, 0, 6], 
      state: 7
    }, 
    {
      pos: [9, 0, 6], 
      state: 8
    }, 
    {
      pos: [12, 0, 6], 
      state: 7
    }, 
    {
      pos: [2, 1, 1], 
      state: 1
    }, 
    {
      pos: [3, 1, 1], 
      state: 1
    }, 
    {
      pos: [5, 1, 1], 
      state: 1
    }, 
    {
      pos: [7, 1, 1], 
      state: 1
    }, 
    {
      pos: [9, 1, 1], 
      state: 1
    }, 
    {
      pos: [10, 1, 1], 
      state: 1
    }, 
    {
      pos: [1, 1, 2], 
      state: 0
    }, 
    {
      pos: [2, 1, 2], 
      state: 1
    }, 
    {
      pos: [5, 1, 2], 
      state: 14
    }, 
    {
      pos: [9, 1, 2], 
      state: 3
    }, 
    {
      pos: [10, 1, 2], 
      state: 1
    }, 
    {
      pos: [11, 1, 2], 
      state: 0
    }, 
    {
      pos: [2, 1, 4], 
      state: 1
    }, 
    {
      pos: [9, 1, 4], 
      state: 3
    }, 
    {
      pos: [10, 1, 4], 
      state: 1
    }, 
    {
      pos: [2, 1, 5], 
      state: 1
    }, 
    {
      pos: [3, 1, 5], 
      state: 1
    }, 
    {
      pos: [5, 1, 5], 
      state: 1
    }, 
    {
      pos: [7, 1, 5], 
      state: 1
    }, 
    {
      pos: [9, 1, 5], 
      state: 1
    }, 
    {
      pos: [10, 1, 5], 
      state: 1
    }, 
    {
      pos: [4, 1, 6], 
      state: 0
    }, 
    {
      nbt: {
        id: "minecraft:lectern"
      }, 
      pos: [7, 1, 3], 
      state: 15
    }, 
    {
      pos: [0, 1, 0], 
      state: 16
    }, 
    {
      pos: [1, 1, 0], 
      state: 16
    }, 
    {
      pos: [2, 1, 0], 
      state: 16
    }, 
    {
      pos: [3, 1, 0], 
      state: 16
    }, 
    {
      pos: [4, 1, 0], 
      state: 16
    }, 
    {
      pos: [5, 1, 0], 
      state: 16
    }, 
    {
      pos: [6, 1, 0], 
      state: 13
    }, 
    {
      pos: [7, 1, 0], 
      state: 16
    }, 
    {
      pos: [8, 1, 0], 
      state: 16
    }, 
    {
      pos: [9, 1, 0], 
      state: 16
    }, 
    {
      pos: [10, 1, 0], 
      state: 16
    }, 
    {
      pos: [11, 1, 0], 
      state: 16
    }, 
    {
      pos: [12, 1, 0], 
      state: 16
    }, 
    {
      pos: [0, 1, 1], 
      state: 16
    }, 
    {
      pos: [1, 1, 1], 
      state: 16
    }, 
    {
      pos: [4, 1, 1], 
      state: 17
    }, 
    {
      pos: [6, 1, 1], 
      state: 17
    }, 
    {
      pos: [8, 1, 1], 
      state: 17
    }, 
    {
      pos: [11, 1, 1], 
      state: 8
    }, 
    {
      pos: [12, 1, 1], 
      state: 16
    }, 
    {
      pos: [0, 1, 2], 
      state: 16
    }, 
    {
      pos: [3, 1, 2], 
      state: 18
    }, 
    {
      pos: [4, 1, 2], 
      state: 16
    }, 
    {
      pos: [6, 1, 2], 
      state: 16
    }, 
    {
      pos: [7, 1, 2], 
      state: 16
    }, 
    {
      pos: [8, 1, 2], 
      state: 16
    }, 
    {
      pos: [12, 1, 2], 
      state: 16
    }, 
    {
      pos: [0, 1, 3], 
      state: 16
    }, 
    {
      pos: [1, 1, 3], 
      state: 16
    }, 
    {
      pos: [2, 1, 3], 
      state: 19
    }, 
    {
      pos: [3, 1, 3], 
      state: 16
    }, 
    {
      pos: [4, 1, 3], 
      state: 16
    }, 
    {
      pos: [5, 1, 3], 
      state: 16
    }, 
    {
      pos: [6, 1, 3], 
      state: 16
    }, 
    {
      pos: [8, 1, 3], 
      state: 16
    }, 
    {
      pos: [9, 1, 3], 
      state: 16
    }, 
    {
      pos: [10, 1, 3], 
      state: 20
    }, 
    {
      pos: [11, 1, 3], 
      state: 13
    }, 
    {
      pos: [12, 1, 3], 
      state: 16
    }, 
    {
      pos: [0, 1, 4], 
      state: 16
    }, 
    {
      pos: [1, 1, 4], 
      state: 13
    }, 
    {
      pos: [3, 1, 4], 
      state: 21
    }, 
    {
      pos: [4, 1, 4], 
      state: 16
    }, 
    {
      pos: [5, 1, 4], 
      state: 16
    }, 
    {
      pos: [6, 1, 4], 
      state: 16
    }, 
    {
      pos: [7, 1, 4], 
      state: 16
    }, 
    {
      pos: [8, 1, 4], 
      state: 16
    }, 
    {
      pos: [11, 1, 4], 
      state: 16
    }, 
    {
      pos: [12, 1, 4], 
      state: 16
    }, 
    {
      pos: [0, 1, 5], 
      state: 16
    }, 
    {
      pos: [1, 1, 5], 
      state: 16
    }, 
    {
      pos: [4, 1, 5], 
      state: 22
    }, 
    {
      pos: [6, 1, 5], 
      state: 17
    }, 
    {
      pos: [8, 1, 5], 
      state: 17
    }, 
    {
      pos: [11, 1, 5], 
      state: 16
    }, 
    {
      pos: [12, 1, 5], 
      state: 16
    }, 
    {
      pos: [0, 1, 6], 
      state: 16
    }, 
    {
      pos: [1, 1, 6], 
      state: 16
    }, 
    {
      pos: [2, 1, 6], 
      state: 16
    }, 
    {
      pos: [3, 1, 6], 
      state: 16
    }, 
    {
      pos: [5, 1, 6], 
      state: 16
    }, 
    {
      pos: [6, 1, 6], 
      state: 16
    }, 
    {
      pos: [7, 1, 6], 
      state: 16
    }, 
    {
      pos: [8, 1, 6], 
      state: 16
    }, 
    {
      pos: [9, 1, 6], 
      state: 16
    }, 
    {
      pos: [10, 1, 6], 
      state: 10
    }, 
    {
      pos: [11, 1, 6], 
      state: 16
    }, 
    {
      pos: [12, 1, 6], 
      state: 16
    }, 
    {
      pos: [2, 2, 1], 
      state: 1
    }, 
    {
      pos: [3, 2, 1], 
      state: 1
    }, 
    {
      pos: [5, 2, 1], 
      state: 1
    }, 
    {
      pos: [7, 2, 1], 
      state: 1
    }, 
    {
      pos: [9, 2, 1], 
      state: 1
    }, 
    {
      pos: [10, 2, 1], 
      state: 1
    }, 
    {
      pos: [2, 2, 2], 
      state: 1
    }, 
    {
      pos: [5, 2, 2], 
      state: 14
    }, 
    {
      pos: [10, 2, 2], 
      state: 5
    }, 
    {
      pos: [2, 2, 4], 
      state: 1
    }, 
    {
      pos: [10, 2, 4], 
      state: 1
    }, 
    {
      pos: [2, 2, 5], 
      state: 1
    }, 
    {
      pos: [3, 2, 5], 
      state: 1
    }, 
    {
      pos: [5, 2, 5], 
      state: 1
    }, 
    {
      pos: [7, 2, 5], 
      state: 1
    }, 
    {
      pos: [9, 2, 5], 
      state: 1
    }, 
    {
      pos: [10, 2, 5], 
      state: 1
    }, 
    {
      pos: [0, 2, 0], 
      state: 16
    }, 
    {
      pos: [1, 2, 0], 
      state: 16
    }, 
    {
      pos: [2, 2, 0], 
      state: 16
    }, 
    {
      pos: [3, 2, 0], 
      state: 16
    }, 
    {
      pos: [4, 2, 0], 
      state: 16
    }, 
    {
      pos: [5, 2, 0], 
      state: 16
    }, 
    {
      pos: [6, 2, 0], 
      state: 16
    }, 
    {
      pos: [7, 2, 0], 
      state: 16
    }, 
    {
      pos: [8, 2, 0], 
      state: 16
    }, 
    {
      pos: [9, 2, 0], 
      state: 16
    }, 
    {
      pos: [10, 2, 0], 
      state: 16
    }, 
    {
      pos: [11, 2, 0], 
      state: 16
    }, 
    {
      pos: [12, 2, 0], 
      state: 16
    }, 
    {
      pos: [0, 2, 1], 
      state: 16
    }, 
    {
      pos: [1, 2, 1], 
      state: 16
    }, 
    {
      pos: [4, 2, 1], 
      state: 17
    }, 
    {
      pos: [6, 2, 1], 
      state: 17
    }, 
    {
      pos: [8, 2, 1], 
      state: 17
    }, 
    {
      pos: [11, 2, 1], 
      state: 16
    }, 
    {
      pos: [12, 2, 1], 
      state: 16
    }, 
    {
      pos: [0, 2, 2], 
      state: 16
    }, 
    {
      pos: [1, 2, 2], 
      state: 16
    }, 
    {
      pos: [3, 2, 2], 
      state: 23
    }, 
    {
      pos: [4, 2, 2], 
      state: 16
    }, 
    {
      pos: [6, 2, 2], 
      state: 16
    }, 
    {
      pos: [7, 2, 2], 
      state: 16
    }, 
    {
      pos: [8, 2, 2], 
      state: 16
    }, 
    {
      pos: [9, 2, 2], 
      state: 16
    }, 
    {
      pos: [11, 2, 2], 
      state: 7
    }, 
    {
      pos: [12, 2, 2], 
      state: 16
    }, 
    {
      pos: [0, 2, 3], 
      state: 16
    }, 
    {
      pos: [1, 2, 3], 
      state: 16
    }, 
    {
      pos: [2, 2, 3], 
      state: 24
    }, 
    {
      pos: [3, 2, 3], 
      state: 16
    }, 
    {
      pos: [4, 2, 3], 
      state: 16
    }, 
    {
      pos: [5, 2, 3], 
      state: 16
    }, 
    {
      pos: [6, 2, 3], 
      state: 16
    }, 
    {
      pos: [7, 2, 3], 
      state: 16
    }, 
    {
      pos: [8, 2, 3], 
      state: 16
    }, 
    {
      pos: [9, 2, 3], 
      state: 16
    }, 
    {
      pos: [10, 2, 3], 
      state: 20
    }, 
    {
      pos: [11, 2, 3], 
      state: 16
    }, 
    {
      pos: [12, 2, 3], 
      state: 16
    }, 
    {
      pos: [0, 2, 4], 
      state: 16
    }, 
    {
      pos: [1, 2, 4], 
      state: 16
    }, 
    {
      pos: [3, 2, 4], 
      state: 23
    }, 
    {
      pos: [4, 2, 4], 
      state: 16
    }, 
    {
      pos: [5, 2, 4], 
      state: 16
    }, 
    {
      pos: [6, 2, 4], 
      state: 16
    }, 
    {
      pos: [7, 2, 4], 
      state: 16
    }, 
    {
      pos: [8, 2, 4], 
      state: 16
    }, 
    {
      pos: [9, 2, 4], 
      state: 25
    }, 
    {
      pos: [11, 2, 4], 
      state: 16
    }, 
    {
      pos: [12, 2, 4], 
      state: 16
    }, 
    {
      pos: [0, 2, 5], 
      state: 16
    }, 
    {
      pos: [1, 2, 5], 
      state: 16
    }, 
    {
      pos: [4, 2, 5], 
      state: 17
    }, 
    {
      pos: [6, 2, 5], 
      state: 17
    }, 
    {
      pos: [8, 2, 5], 
      state: 17
    }, 
    {
      pos: [11, 2, 5], 
      state: 16
    }, 
    {
      pos: [12, 2, 5], 
      state: 16
    }, 
    {
      pos: [0, 2, 6], 
      state: 16
    }, 
    {
      pos: [1, 2, 6], 
      state: 16
    }, 
    {
      pos: [2, 2, 6], 
      state: 16
    }, 
    {
      pos: [3, 2, 6], 
      state: 16
    }, 
    {
      pos: [4, 2, 6], 
      state: 16
    }, 
    {
      pos: [5, 2, 6], 
      state: 16
    }, 
    {
      pos: [6, 2, 6], 
      state: 16
    }, 
    {
      pos: [7, 2, 6], 
      state: 16
    }, 
    {
      pos: [8, 2, 6], 
      state: 16
    }, 
    {
      pos: [9, 2, 6], 
      state: 16
    }, 
    {
      pos: [10, 2, 6], 
      state: 16
    }, 
    {
      pos: [11, 2, 6], 
      state: 16
    }, 
    {
      pos: [12, 2, 6], 
      state: 16
    }, 
    {
      pos: [1, 3, 0], 
      state: 3
    }, 
    {
      pos: [2, 3, 0], 
      state: 3
    }, 
    {
      pos: [3, 3, 0], 
      state: 3
    }, 
    {
      pos: [4, 3, 0], 
      state: 3
    }, 
    {
      pos: [5, 3, 0], 
      state: 3
    }, 
    {
      pos: [6, 3, 0], 
      state: 3
    }, 
    {
      pos: [7, 3, 0], 
      state: 3
    }, 
    {
      pos: [8, 3, 0], 
      state: 3
    }, 
    {
      pos: [9, 3, 0], 
      state: 3
    }, 
    {
      pos: [10, 3, 0], 
      state: 3
    }, 
    {
      pos: [11, 3, 0], 
      state: 3
    }, 
    {
      pos: [2, 3, 1], 
      state: 5
    }, 
    {
      pos: [3, 3, 1], 
      state: 1
    }, 
    {
      pos: [4, 3, 1], 
      state: 1
    }, 
    {
      pos: [5, 3, 1], 
      state: 1
    }, 
    {
      pos: [6, 3, 1], 
      state: 1
    }, 
    {
      pos: [7, 3, 1], 
      state: 1
    }, 
    {
      pos: [8, 3, 1], 
      state: 1
    }, 
    {
      pos: [9, 3, 1], 
      state: 1
    }, 
    {
      pos: [10, 3, 1], 
      state: 1
    }, 
    {
      pos: [2, 3, 2], 
      state: 1
    }, 
    {
      pos: [5, 3, 2], 
      state: 14
    }, 
    {
      pos: [10, 3, 2], 
      state: 1
    }, 
    {
      pos: [2, 3, 3], 
      state: 5
    }, 
    {
      pos: [10, 3, 3], 
      state: 5
    }, 
    {
      pos: [2, 3, 4], 
      state: 1
    }, 
    {
      pos: [10, 3, 4], 
      state: 1
    }, 
    {
      pos: [2, 3, 5], 
      state: 5
    }, 
    {
      pos: [3, 3, 5], 
      state: 1
    }, 
    {
      pos: [4, 3, 5], 
      state: 1
    }, 
    {
      pos: [5, 3, 5], 
      state: 1
    }, 
    {
      pos: [6, 3, 5], 
      state: 1
    }, 
    {
      pos: [7, 3, 5], 
      state: 1
    }, 
    {
      pos: [8, 3, 5], 
      state: 1
    }, 
    {
      pos: [9, 3, 5], 
      state: 1
    }, 
    {
      pos: [10, 3, 5], 
      state: 1
    }, 
    {
      pos: [1, 3, 6], 
      state: 3
    }, 
    {
      pos: [2, 3, 6], 
      state: 3
    }, 
    {
      pos: [3, 3, 6], 
      state: 3
    }, 
    {
      pos: [4, 3, 6], 
      state: 3
    }, 
    {
      pos: [5, 3, 6], 
      state: 3
    }, 
    {
      pos: [6, 3, 6], 
      state: 3
    }, 
    {
      pos: [7, 3, 6], 
      state: 3
    }, 
    {
      pos: [8, 3, 6], 
      state: 3
    }, 
    {
      pos: [9, 3, 6], 
      state: 3
    }, 
    {
      pos: [10, 3, 6], 
      state: 3
    }, 
    {
      pos: [11, 3, 6], 
      state: 3
    }, 
    {
      pos: [0, 3, 0], 
      state: 16
    }, 
    {
      pos: [12, 3, 0], 
      state: 16
    }, 
    {
      pos: [0, 3, 1], 
      state: 16
    }, 
    {
      pos: [1, 3, 1], 
      state: 16
    }, 
    {
      pos: [11, 3, 1], 
      state: 16
    }, 
    {
      pos: [12, 3, 1], 
      state: 16
    }, 
    {
      pos: [0, 3, 2], 
      state: 16
    }, 
    {
      pos: [1, 3, 2], 
      state: 16
    }, 
    {
      pos: [3, 3, 2], 
      state: 16
    }, 
    {
      pos: [4, 3, 2], 
      state: 16
    }, 
    {
      pos: [6, 3, 2], 
      state: 16
    }, 
    {
      pos: [7, 3, 2], 
      state: 16
    }, 
    {
      pos: [8, 3, 2], 
      state: 16
    }, 
    {
      pos: [9, 3, 2], 
      state: 16
    }, 
    {
      pos: [11, 3, 2], 
      state: 16
    }, 
    {
      pos: [12, 3, 2], 
      state: 16
    }, 
    {
      pos: [0, 3, 3], 
      state: 16
    }, 
    {
      pos: [1, 3, 3], 
      state: 16
    }, 
    {
      pos: [3, 3, 3], 
      state: 16
    }, 
    {
      pos: [4, 3, 3], 
      state: 16
    }, 
    {
      pos: [5, 3, 3], 
      state: 16
    }, 
    {
      pos: [6, 3, 3], 
      state: 16
    }, 
    {
      pos: [7, 3, 3], 
      state: 16
    }, 
    {
      pos: [8, 3, 3], 
      state: 16
    }, 
    {
      pos: [9, 3, 3], 
      state: 16
    }, 
    {
      pos: [11, 3, 3], 
      state: 16
    }, 
    {
      pos: [12, 3, 3], 
      state: 16
    }, 
    {
      pos: [0, 3, 4], 
      state: 16
    }, 
    {
      pos: [1, 3, 4], 
      state: 16
    }, 
    {
      pos: [3, 3, 4], 
      state: 16
    }, 
    {
      pos: [4, 3, 4], 
      state: 16
    }, 
    {
      pos: [5, 3, 4], 
      state: 16
    }, 
    {
      pos: [6, 3, 4], 
      state: 16
    }, 
    {
      pos: [7, 3, 4], 
      state: 16
    }, 
    {
      pos: [8, 3, 4], 
      state: 16
    }, 
    {
      pos: [9, 3, 4], 
      state: 16
    }, 
    {
      pos: [11, 3, 4], 
      state: 16
    }, 
    {
      pos: [12, 3, 4], 
      state: 16
    }, 
    {
      pos: [0, 3, 5], 
      state: 16
    }, 
    {
      pos: [1, 3, 5], 
      state: 16
    }, 
    {
      pos: [11, 3, 5], 
      state: 16
    }, 
    {
      pos: [12, 3, 5], 
      state: 16
    }, 
    {
      pos: [0, 3, 6], 
      state: 16
    }, 
    {
      pos: [12, 3, 6], 
      state: 16
    }, 
    {
      pos: [1, 4, 0], 
      state: 3
    }, 
    {
      pos: [2, 4, 0], 
      state: 3
    }, 
    {
      pos: [3, 4, 0], 
      state: 3
    }, 
    {
      pos: [4, 4, 0], 
      state: 3
    }, 
    {
      pos: [5, 4, 0], 
      state: 3
    }, 
    {
      pos: [6, 4, 0], 
      state: 3
    }, 
    {
      pos: [7, 4, 0], 
      state: 3
    }, 
    {
      pos: [8, 4, 0], 
      state: 3
    }, 
    {
      pos: [9, 4, 0], 
      state: 3
    }, 
    {
      pos: [10, 4, 0], 
      state: 3
    }, 
    {
      pos: [11, 4, 0], 
      state: 3
    }, 
    {
      pos: [2, 4, 1], 
      state: 1
    }, 
    {
      pos: [3, 4, 1], 
      state: 1
    }, 
    {
      pos: [4, 4, 1], 
      state: 1
    }, 
    {
      pos: [5, 4, 1], 
      state: 1
    }, 
    {
      pos: [6, 4, 1], 
      state: 1
    }, 
    {
      pos: [7, 4, 1], 
      state: 1
    }, 
    {
      pos: [8, 4, 1], 
      state: 1
    }, 
    {
      pos: [9, 4, 1], 
      state: 1
    }, 
    {
      pos: [10, 4, 1], 
      state: 1
    }, 
    {
      pos: [2, 4, 2], 
      state: 1
    }, 
    {
      pos: [5, 4, 2], 
      state: 14
    }, 
    {
      pos: [10, 4, 2], 
      state: 1
    }, 
    {
      pos: [2, 4, 4], 
      state: 1
    }, 
    {
      pos: [10, 4, 4], 
      state: 1
    }, 
    {
      pos: [2, 4, 5], 
      state: 1
    }, 
    {
      pos: [3, 4, 5], 
      state: 1
    }, 
    {
      pos: [4, 4, 5], 
      state: 1
    }, 
    {
      pos: [5, 4, 5], 
      state: 1
    }, 
    {
      pos: [6, 4, 5], 
      state: 1
    }, 
    {
      pos: [7, 4, 5], 
      state: 2
    }, 
    {
      pos: [8, 4, 5], 
      state: 1
    }, 
    {
      pos: [9, 4, 5], 
      state: 1
    }, 
    {
      pos: [10, 4, 5], 
      state: 1
    }, 
    {
      pos: [1, 4, 6], 
      state: 3
    }, 
    {
      pos: [2, 4, 6], 
      state: 3
    }, 
    {
      pos: [3, 4, 6], 
      state: 3
    }, 
    {
      pos: [4, 4, 6], 
      state: 3
    }, 
    {
      pos: [5, 4, 6], 
      state: 3
    }, 
    {
      pos: [6, 4, 6], 
      state: 3
    }, 
    {
      pos: [7, 4, 6], 
      state: 3
    }, 
    {
      pos: [8, 4, 6], 
      state: 3
    }, 
    {
      pos: [9, 4, 6], 
      state: 3
    }, 
    {
      pos: [10, 4, 6], 
      state: 3
    }, 
    {
      pos: [11, 4, 6], 
      state: 3
    }, 
    {
      pos: [0, 4, 0], 
      state: 16
    }, 
    {
      pos: [12, 4, 0], 
      state: 16
    }, 
    {
      pos: [0, 4, 1], 
      state: 16
    }, 
    {
      pos: [1, 4, 1], 
      state: 16
    }, 
    {
      pos: [11, 4, 1], 
      state: 16
    }, 
    {
      pos: [12, 4, 1], 
      state: 16
    }, 
    {
      pos: [0, 4, 2], 
      state: 16
    }, 
    {
      pos: [1, 4, 2], 
      state: 16
    }, 
    {
      pos: [3, 4, 2], 
      state: 16
    }, 
    {
      pos: [4, 4, 2], 
      state: 16
    }, 
    {
      pos: [6, 4, 2], 
      state: 16
    }, 
    {
      pos: [7, 4, 2], 
      state: 16
    }, 
    {
      pos: [8, 4, 2], 
      state: 16
    }, 
    {
      pos: [9, 4, 2], 
      state: 16
    }, 
    {
      pos: [11, 4, 2], 
      state: 16
    }, 
    {
      pos: [12, 4, 2], 
      state: 16
    }, 
    {
      pos: [0, 4, 3], 
      state: 16
    }, 
    {
      pos: [1, 4, 3], 
      state: 16
    }, 
    {
      pos: [2, 4, 3], 
      state: 20
    }, 
    {
      pos: [3, 4, 3], 
      state: 16
    }, 
    {
      pos: [4, 4, 3], 
      state: 16
    }, 
    {
      pos: [5, 4, 3], 
      state: 16
    }, 
    {
      pos: [6, 4, 3], 
      state: 16
    }, 
    {
      pos: [7, 4, 3], 
      state: 16
    }, 
    {
      pos: [8, 4, 3], 
      state: 16
    }, 
    {
      pos: [9, 4, 3], 
      state: 16
    }, 
    {
      pos: [10, 4, 3], 
      state: 20
    }, 
    {
      pos: [11, 4, 3], 
      state: 16
    }, 
    {
      pos: [12, 4, 3], 
      state: 16
    }, 
    {
      pos: [0, 4, 4], 
      state: 16
    }, 
    {
      pos: [1, 4, 4], 
      state: 16
    }, 
    {
      pos: [3, 4, 4], 
      state: 16
    }, 
    {
      pos: [4, 4, 4], 
      state: 16
    }, 
    {
      pos: [5, 4, 4], 
      state: 16
    }, 
    {
      pos: [6, 4, 4], 
      state: 16
    }, 
    {
      pos: [7, 4, 4], 
      state: 16
    }, 
    {
      pos: [8, 4, 4], 
      state: 16
    }, 
    {
      pos: [9, 4, 4], 
      state: 16
    }, 
    {
      pos: [11, 4, 4], 
      state: 16
    }, 
    {
      pos: [12, 4, 4], 
      state: 16
    }, 
    {
      pos: [0, 4, 5], 
      state: 16
    }, 
    {
      pos: [1, 4, 5], 
      state: 16
    }, 
    {
      pos: [11, 4, 5], 
      state: 16
    }, 
    {
      pos: [12, 4, 5], 
      state: 16
    }, 
    {
      pos: [0, 4, 6], 
      state: 16
    }, 
    {
      pos: [12, 4, 6], 
      state: 16
    }, 
    {
      pos: [2, 5, 0], 
      state: 0
    }, 
    {
      pos: [1, 5, 1], 
      state: 3
    }, 
    {
      pos: [2, 5, 1], 
      state: 3
    }, 
    {
      pos: [3, 5, 1], 
      state: 3
    }, 
    {
      pos: [4, 5, 1], 
      state: 3
    }, 
    {
      pos: [5, 5, 1], 
      state: 3
    }, 
    {
      pos: [6, 5, 1], 
      state: 3
    }, 
    {
      pos: [7, 5, 1], 
      state: 3
    }, 
    {
      pos: [8, 5, 1], 
      state: 3
    }, 
    {
      pos: [9, 5, 1], 
      state: 3
    }, 
    {
      pos: [10, 5, 1], 
      state: 3
    }, 
    {
      pos: [11, 5, 1], 
      state: 3
    }, 
    {
      pos: [2, 5, 2], 
      state: 1
    }, 
    {
      pos: [5, 5, 2], 
      state: 14
    }, 
    {
      pos: [10, 5, 2], 
      state: 1
    }, 
    {
      pos: [2, 5, 4], 
      state: 1
    }, 
    {
      pos: [10, 5, 4], 
      state: 1
    }, 
    {
      pos: [1, 5, 5], 
      state: 3
    }, 
    {
      pos: [2, 5, 5], 
      state: 3
    }, 
    {
      pos: [3, 5, 5], 
      state: 3
    }, 
    {
      pos: [4, 5, 5], 
      state: 3
    }, 
    {
      pos: [5, 5, 5], 
      state: 3
    }, 
    {
      pos: [6, 5, 5], 
      state: 3
    }, 
    {
      pos: [7, 5, 5], 
      state: 3
    }, 
    {
      pos: [8, 5, 5], 
      state: 3
    }, 
    {
      pos: [9, 5, 5], 
      state: 3
    }, 
    {
      pos: [10, 5, 5], 
      state: 3
    }, 
    {
      pos: [11, 5, 5], 
      state: 3
    }, 
    {
      pos: [0, 5, 0], 
      state: 16
    }, 
    {
      pos: [1, 5, 0], 
      state: 8
    }, 
    {
      pos: [3, 5, 0], 
      state: 8
    }, 
    {
      pos: [4, 5, 0], 
      state: 7
    }, 
    {
      pos: [5, 5, 0], 
      state: 7
    }, 
    {
      pos: [6, 5, 0], 
      state: 7
    }, 
    {
      pos: [7, 5, 0], 
      state: 7
    }, 
    {
      pos: [8, 5, 0], 
      state: 7
    }, 
    {
      pos: [9, 5, 0], 
      state: 7
    }, 
    {
      pos: [10, 5, 0], 
      state: 7
    }, 
    {
      pos: [11, 5, 0], 
      state: 7
    }, 
    {
      pos: [12, 5, 0], 
      state: 16
    }, 
    {
      pos: [0, 5, 1], 
      state: 16
    }, 
    {
      pos: [12, 5, 1], 
      state: 16
    }, 
    {
      pos: [0, 5, 2], 
      state: 16
    }, 
    {
      pos: [1, 5, 2], 
      state: 16
    }, 
    {
      pos: [3, 5, 2], 
      state: 26
    }, 
    {
      pos: [4, 5, 2], 
      state: 26
    }, 
    {
      pos: [6, 5, 2], 
      state: 26
    }, 
    {
      pos: [7, 5, 2], 
      state: 26
    }, 
    {
      pos: [8, 5, 2], 
      state: 26
    }, 
    {
      pos: [9, 5, 2], 
      state: 26
    }, 
    {
      pos: [11, 5, 2], 
      state: 16
    }, 
    {
      pos: [12, 5, 2], 
      state: 16
    }, 
    {
      pos: [0, 5, 3], 
      state: 16
    }, 
    {
      pos: [1, 5, 3], 
      state: 16
    }, 
    {
      pos: [2, 5, 3], 
      state: 20
    }, 
    {
      pos: [3, 5, 3], 
      state: 16
    }, 
    {
      pos: [4, 5, 3], 
      state: 16
    }, 
    {
      pos: [5, 5, 3], 
      state: 16
    }, 
    {
      pos: [6, 5, 3], 
      state: 27
    }, 
    {
      pos: [7, 5, 3], 
      state: 16
    }, 
    {
      pos: [8, 5, 3], 
      state: 16
    }, 
    {
      pos: [9, 5, 3], 
      state: 16
    }, 
    {
      pos: [10, 5, 3], 
      state: 20
    }, 
    {
      pos: [11, 5, 3], 
      state: 16
    }, 
    {
      pos: [12, 5, 3], 
      state: 16
    }, 
    {
      pos: [0, 5, 4], 
      state: 16
    }, 
    {
      pos: [1, 5, 4], 
      state: 16
    }, 
    {
      pos: [3, 5, 4], 
      state: 16
    }, 
    {
      pos: [4, 5, 4], 
      state: 16
    }, 
    {
      pos: [5, 5, 4], 
      state: 16
    }, 
    {
      pos: [6, 5, 4], 
      state: 16
    }, 
    {
      pos: [7, 5, 4], 
      state: 16
    }, 
    {
      pos: [8, 5, 4], 
      state: 16
    }, 
    {
      pos: [9, 5, 4], 
      state: 16
    }, 
    {
      pos: [11, 5, 4], 
      state: 16
    }, 
    {
      pos: [12, 5, 4], 
      state: 16
    }, 
    {
      pos: [0, 5, 5], 
      state: 16
    }, 
    {
      pos: [12, 5, 5], 
      state: 16
    }, 
    {
      pos: [0, 5, 6], 
      state: 16
    }, 
    {
      pos: [1, 5, 6], 
      state: 16
    }, 
    {
      pos: [2, 5, 6], 
      state: 7
    }, 
    {
      pos: [3, 5, 6], 
      state: 10
    }, 
    {
      pos: [4, 5, 6], 
      state: 13
    }, 
    {
      pos: [5, 5, 6], 
      state: 7
    }, 
    {
      pos: [6, 5, 6], 
      state: 7
    }, 
    {
      pos: [7, 5, 6], 
      state: 7
    }, 
    {
      pos: [8, 5, 6], 
      state: 7
    }, 
    {
      pos: [9, 5, 6], 
      state: 7
    }, 
    {
      pos: [10, 5, 6], 
      state: 7
    }, 
    {
      pos: [11, 5, 6], 
      state: 7
    }, 
    {
      pos: [12, 5, 6], 
      state: 16
    }, 
    {
      pos: [1, 6, 1], 
      state: 3
    }, 
    {
      pos: [2, 6, 1], 
      state: 3
    }, 
    {
      pos: [3, 6, 1], 
      state: 3
    }, 
    {
      pos: [4, 6, 1], 
      state: 3
    }, 
    {
      pos: [5, 6, 1], 
      state: 3
    }, 
    {
      pos: [6, 6, 1], 
      state: 3
    }, 
    {
      pos: [7, 6, 1], 
      state: 3
    }, 
    {
      pos: [8, 6, 1], 
      state: 3
    }, 
    {
      pos: [9, 6, 1], 
      state: 3
    }, 
    {
      pos: [10, 6, 1], 
      state: 3
    }, 
    {
      pos: [11, 6, 1], 
      state: 3
    }, 
    {
      pos: [2, 6, 2], 
      state: 1
    }, 
    {
      pos: [3, 6, 2], 
      state: 14
    }, 
    {
      pos: [4, 6, 2], 
      state: 14
    }, 
    {
      pos: [5, 6, 2], 
      state: 14
    }, 
    {
      pos: [6, 6, 2], 
      state: 3
    }, 
    {
      pos: [7, 6, 2], 
      state: 14
    }, 
    {
      pos: [8, 6, 2], 
      state: 14
    }, 
    {
      pos: [9, 6, 2], 
      state: 14
    }, 
    {
      pos: [10, 6, 2], 
      state: 1
    }, 
    {
      pos: [2, 6, 3], 
      state: 5
    }, 
    {
      pos: [10, 6, 3], 
      state: 5
    }, 
    {
      pos: [2, 6, 4], 
      state: 1
    }, 
    {
      pos: [10, 6, 4], 
      state: 1
    }, 
    {
      pos: [1, 6, 5], 
      state: 3
    }, 
    {
      pos: [2, 6, 5], 
      state: 3
    }, 
    {
      pos: [3, 6, 5], 
      state: 3
    }, 
    {
      pos: [4, 6, 5], 
      state: 3
    }, 
    {
      pos: [5, 6, 5], 
      state: 3
    }, 
    {
      pos: [6, 6, 5], 
      state: 3
    }, 
    {
      pos: [7, 6, 5], 
      state: 3
    }, 
    {
      pos: [8, 6, 5], 
      state: 3
    }, 
    {
      pos: [9, 6, 5], 
      state: 3
    }, 
    {
      pos: [10, 6, 5], 
      state: 3
    }, 
    {
      pos: [11, 6, 5], 
      state: 3
    }, 
    {
      pos: [0, 6, 0], 
      state: 16
    }, 
    {
      pos: [1, 6, 0], 
      state: 16
    }, 
    {
      pos: [2, 6, 0], 
      state: 7
    }, 
    {
      pos: [3, 6, 0], 
      state: 16
    }, 
    {
      pos: [4, 6, 0], 
      state: 16
    }, 
    {
      pos: [5, 6, 0], 
      state: 16
    }, 
    {
      pos: [6, 6, 0], 
      state: 16
    }, 
    {
      pos: [7, 6, 0], 
      state: 16
    }, 
    {
      pos: [8, 6, 0], 
      state: 16
    }, 
    {
      pos: [9, 6, 0], 
      state: 16
    }, 
    {
      pos: [10, 6, 0], 
      state: 16
    }, 
    {
      pos: [11, 6, 0], 
      state: 16
    }, 
    {
      pos: [12, 6, 0], 
      state: 16
    }, 
    {
      pos: [0, 6, 1], 
      state: 16
    }, 
    {
      pos: [12, 6, 1], 
      state: 16
    }, 
    {
      pos: [0, 6, 2], 
      state: 16
    }, 
    {
      pos: [1, 6, 2], 
      state: 16
    }, 
    {
      pos: [11, 6, 2], 
      state: 16
    }, 
    {
      pos: [12, 6, 2], 
      state: 16
    }, 
    {
      pos: [0, 6, 3], 
      state: 16
    }, 
    {
      pos: [1, 6, 3], 
      state: 16
    }, 
    {
      pos: [3, 6, 3], 
      state: 16
    }, 
    {
      pos: [4, 6, 3], 
      state: 16
    }, 
    {
      pos: [5, 6, 3], 
      state: 16
    }, 
    {
      pos: [6, 6, 3], 
      state: 28
    }, 
    {
      pos: [7, 6, 3], 
      state: 16
    }, 
    {
      pos: [8, 6, 3], 
      state: 16
    }, 
    {
      pos: [9, 6, 3], 
      state: 16
    }, 
    {
      pos: [11, 6, 3], 
      state: 16
    }, 
    {
      pos: [12, 6, 3], 
      state: 16
    }, 
    {
      pos: [0, 6, 4], 
      state: 16
    }, 
    {
      pos: [1, 6, 4], 
      state: 16
    }, 
    {
      pos: [3, 6, 4], 
      state: 16
    }, 
    {
      pos: [4, 6, 4], 
      state: 16
    }, 
    {
      pos: [5, 6, 4], 
      state: 16
    }, 
    {
      pos: [6, 6, 4], 
      state: 16
    }, 
    {
      pos: [7, 6, 4], 
      state: 16
    }, 
    {
      pos: [8, 6, 4], 
      state: 16
    }, 
    {
      pos: [9, 6, 4], 
      state: 16
    }, 
    {
      pos: [11, 6, 4], 
      state: 16
    }, 
    {
      pos: [12, 6, 4], 
      state: 16
    }, 
    {
      pos: [0, 6, 5], 
      state: 16
    }, 
    {
      pos: [12, 6, 5], 
      state: 16
    }, 
    {
      pos: [0, 6, 6], 
      state: 16
    }, 
    {
      pos: [1, 6, 6], 
      state: 16
    }, 
    {
      pos: [2, 6, 6], 
      state: 16
    }, 
    {
      pos: [3, 6, 6], 
      state: 16
    }, 
    {
      pos: [4, 6, 6], 
      state: 16
    }, 
    {
      pos: [5, 6, 6], 
      state: 16
    }, 
    {
      pos: [6, 6, 6], 
      state: 16
    }, 
    {
      pos: [7, 6, 6], 
      state: 16
    }, 
    {
      pos: [8, 6, 6], 
      state: 16
    }, 
    {
      pos: [9, 6, 6], 
      state: 16
    }, 
    {
      pos: [10, 6, 6], 
      state: 16
    }, 
    {
      pos: [11, 6, 6], 
      state: 16
    }, 
    {
      pos: [12, 6, 6], 
      state: 16
    }, 
    {
      pos: [1, 7, 2], 
      state: 3
    }, 
    {
      pos: [2, 7, 2], 
      state: 3
    }, 
    {
      pos: [3, 7, 2], 
      state: 3
    }, 
    {
      pos: [4, 7, 2], 
      state: 3
    }, 
    {
      pos: [5, 7, 2], 
      state: 3
    }, 
    {
      pos: [6, 7, 2], 
      state: 3
    }, 
    {
      pos: [7, 7, 2], 
      state: 3
    }, 
    {
      pos: [8, 7, 2], 
      state: 3
    }, 
    {
      pos: [9, 7, 2], 
      state: 3
    }, 
    {
      pos: [10, 7, 2], 
      state: 3
    }, 
    {
      pos: [11, 7, 2], 
      state: 3
    }, 
    {
      pos: [2, 7, 3], 
      state: 5
    }, 
    {
      pos: [10, 7, 3], 
      state: 1
    }, 
    {
      pos: [1, 7, 4], 
      state: 3
    }, 
    {
      pos: [2, 7, 4], 
      state: 3
    }, 
    {
      pos: [3, 7, 4], 
      state: 3
    }, 
    {
      pos: [4, 7, 4], 
      state: 3
    }, 
    {
      pos: [5, 7, 4], 
      state: 3
    }, 
    {
      pos: [6, 7, 4], 
      state: 3
    }, 
    {
      pos: [7, 7, 4], 
      state: 3
    }, 
    {
      pos: [8, 7, 4], 
      state: 3
    }, 
    {
      pos: [9, 7, 4], 
      state: 3
    }, 
    {
      pos: [10, 7, 4], 
      state: 3
    }, 
    {
      pos: [11, 7, 4], 
      state: 3
    }, 
    {
      pos: [0, 7, 0], 
      state: 16
    }, 
    {
      pos: [1, 7, 0], 
      state: 16
    }, 
    {
      pos: [2, 7, 0], 
      state: 16
    }, 
    {
      pos: [3, 7, 0], 
      state: 16
    }, 
    {
      pos: [4, 7, 0], 
      state: 16
    }, 
    {
      pos: [5, 7, 0], 
      state: 16
    }, 
    {
      pos: [6, 7, 0], 
      state: 16
    }, 
    {
      pos: [7, 7, 0], 
      state: 16
    }, 
    {
      pos: [8, 7, 0], 
      state: 16
    }, 
    {
      pos: [9, 7, 0], 
      state: 16
    }, 
    {
      pos: [10, 7, 0], 
      state: 16
    }, 
    {
      pos: [11, 7, 0], 
      state: 16
    }, 
    {
      pos: [12, 7, 0], 
      state: 16
    }, 
    {
      pos: [0, 7, 1], 
      state: 16
    }, 
    {
      pos: [1, 7, 1], 
      state: 7
    }, 
    {
      pos: [2, 7, 1], 
      state: 7
    }, 
    {
      pos: [3, 7, 1], 
      state: 7
    }, 
    {
      pos: [4, 7, 1], 
      state: 7
    }, 
    {
      pos: [5, 7, 1], 
      state: 7
    }, 
    {
      pos: [6, 7, 1], 
      state: 7
    }, 
    {
      pos: [7, 7, 1], 
      state: 7
    }, 
    {
      pos: [8, 7, 1], 
      state: 7
    }, 
    {
      pos: [9, 7, 1], 
      state: 7
    }, 
    {
      pos: [10, 7, 1], 
      state: 7
    }, 
    {
      pos: [11, 7, 1], 
      state: 7
    }, 
    {
      pos: [12, 7, 1], 
      state: 16
    }, 
    {
      pos: [0, 7, 2], 
      state: 16
    }, 
    {
      pos: [12, 7, 2], 
      state: 16
    }, 
    {
      pos: [0, 7, 3], 
      state: 16
    }, 
    {
      pos: [1, 7, 3], 
      state: 16
    }, 
    {
      pos: [3, 7, 3], 
      state: 16
    }, 
    {
      pos: [4, 7, 3], 
      state: 16
    }, 
    {
      pos: [5, 7, 3], 
      state: 16
    }, 
    {
      pos: [6, 7, 3], 
      state: 29
    }, 
    {
      pos: [7, 7, 3], 
      state: 16
    }, 
    {
      pos: [8, 7, 3], 
      state: 16
    }, 
    {
      pos: [9, 7, 3], 
      state: 16
    }, 
    {
      pos: [11, 7, 3], 
      state: 16
    }, 
    {
      pos: [12, 7, 3], 
      state: 16
    }, 
    {
      pos: [0, 7, 4], 
      state: 16
    }, 
    {
      pos: [12, 7, 4], 
      state: 16
    }, 
    {
      pos: [0, 7, 5], 
      state: 16
    }, 
    {
      pos: [1, 7, 5], 
      state: 10
    }, 
    {
      pos: [2, 7, 5], 
      state: 9
    }, 
    {
      pos: [3, 7, 5], 
      state: 13
    }, 
    {
      pos: [4, 7, 5], 
      state: 10
    }, 
    {
      pos: [5, 7, 5], 
      state: 7
    }, 
    {
      pos: [6, 7, 5], 
      state: 7
    }, 
    {
      pos: [7, 7, 5], 
      state: 7
    }, 
    {
      pos: [8, 7, 5], 
      state: 7
    }, 
    {
      pos: [9, 7, 5], 
      state: 7
    }, 
    {
      pos: [10, 7, 5], 
      state: 7
    }, 
    {
      pos: [11, 7, 5], 
      state: 7
    }, 
    {
      pos: [12, 7, 5], 
      state: 16
    }, 
    {
      pos: [0, 7, 6], 
      state: 16
    }, 
    {
      pos: [1, 7, 6], 
      state: 16
    }, 
    {
      pos: [2, 7, 6], 
      state: 16
    }, 
    {
      pos: [3, 7, 6], 
      state: 16
    }, 
    {
      pos: [4, 7, 6], 
      state: 16
    }, 
    {
      pos: [5, 7, 6], 
      state: 16
    }, 
    {
      pos: [6, 7, 6], 
      state: 16
    }, 
    {
      pos: [7, 7, 6], 
      state: 16
    }, 
    {
      pos: [8, 7, 6], 
      state: 16
    }, 
    {
      pos: [9, 7, 6], 
      state: 16
    }, 
    {
      pos: [10, 7, 6], 
      state: 16
    }, 
    {
      pos: [11, 7, 6], 
      state: 16
    }, 
    {
      pos: [12, 7, 6], 
      state: 16
    }, 
    {
      pos: [1, 8, 3], 
      state: 3
    }, 
    {
      pos: [2, 8, 3], 
      state: 3
    }, 
    {
      pos: [3, 8, 3], 
      state: 3
    }, 
    {
      pos: [4, 8, 3], 
      state: 3
    }, 
    {
      pos: [5, 8, 3], 
      state: 3
    }, 
    {
      pos: [6, 8, 3], 
      state: 3
    }, 
    {
      pos: [7, 8, 3], 
      state: 3
    }, 
    {
      pos: [8, 8, 3], 
      state: 3
    }, 
    {
      pos: [9, 8, 3], 
      state: 3
    }, 
    {
      pos: [10, 8, 3], 
      state: 3
    }, 
    {
      pos: [11, 8, 3], 
      state: 3
    }, 
    {
      pos: [0, 8, 0], 
      state: 16
    }, 
    {
      pos: [1, 8, 0], 
      state: 16
    }, 
    {
      pos: [2, 8, 0], 
      state: 16
    }, 
    {
      pos: [3, 8, 0], 
      state: 16
    }, 
    {
      pos: [4, 8, 0], 
      state: 16
    }, 
    {
      pos: [5, 8, 0], 
      state: 16
    }, 
    {
      pos: [6, 8, 0], 
      state: 16
    }, 
    {
      pos: [7, 8, 0], 
      state: 16
    }, 
    {
      pos: [8, 8, 0], 
      state: 16
    }, 
    {
      pos: [9, 8, 0], 
      state: 16
    }, 
    {
      pos: [10, 8, 0], 
      state: 16
    }, 
    {
      pos: [11, 8, 0], 
      state: 16
    }, 
    {
      pos: [12, 8, 0], 
      state: 16
    }, 
    {
      pos: [0, 8, 1], 
      state: 16
    }, 
    {
      pos: [1, 8, 1], 
      state: 16
    }, 
    {
      pos: [2, 8, 1], 
      state: 16
    }, 
    {
      pos: [3, 8, 1], 
      state: 16
    }, 
    {
      pos: [4, 8, 1], 
      state: 16
    }, 
    {
      pos: [5, 8, 1], 
      state: 16
    }, 
    {
      pos: [6, 8, 1], 
      state: 16
    }, 
    {
      pos: [7, 8, 1], 
      state: 16
    }, 
    {
      pos: [8, 8, 1], 
      state: 16
    }, 
    {
      pos: [9, 8, 1], 
      state: 16
    }, 
    {
      pos: [10, 8, 1], 
      state: 16
    }, 
    {
      pos: [11, 8, 1], 
      state: 16
    }, 
    {
      pos: [12, 8, 1], 
      state: 16
    }, 
    {
      pos: [0, 8, 2], 
      state: 16
    }, 
    {
      pos: [1, 8, 2], 
      state: 7
    }, 
    {
      pos: [2, 8, 2], 
      state: 7
    }, 
    {
      pos: [3, 8, 2], 
      state: 10
    }, 
    {
      pos: [4, 8, 2], 
      state: 7
    }, 
    {
      pos: [5, 8, 2], 
      state: 7
    }, 
    {
      pos: [6, 8, 2], 
      state: 13
    }, 
    {
      pos: [7, 8, 2], 
      state: 10
    }, 
    {
      pos: [8, 8, 2], 
      state: 7
    }, 
    {
      pos: [9, 8, 2], 
      state: 13
    }, 
    {
      pos: [10, 8, 2], 
      state: 7
    }, 
    {
      pos: [11, 8, 2], 
      state: 7
    }, 
    {
      pos: [12, 8, 2], 
      state: 16
    }, 
    {
      pos: [0, 8, 3], 
      state: 16
    }, 
    {
      pos: [12, 8, 3], 
      state: 16
    }, 
    {
      pos: [0, 8, 4], 
      state: 16
    }, 
    {
      pos: [1, 8, 4], 
      state: 7
    }, 
    {
      pos: [2, 8, 4], 
      state: 7
    }, 
    {
      pos: [3, 8, 4], 
      state: 7
    }, 
    {
      pos: [4, 8, 4], 
      state: 7
    }, 
    {
      pos: [5, 8, 4], 
      state: 7
    }, 
    {
      pos: [6, 8, 4], 
      state: 7
    }, 
    {
      pos: [7, 8, 4], 
      state: 7
    }, 
    {
      pos: [8, 8, 4], 
      state: 7
    }, 
    {
      pos: [9, 8, 4], 
      state: 7
    }, 
    {
      pos: [10, 8, 4], 
      state: 7
    }, 
    {
      pos: [11, 8, 4], 
      state: 7
    }, 
    {
      pos: [12, 8, 4], 
      state: 16
    }, 
    {
      pos: [0, 8, 5], 
      state: 16
    }, 
    {
      pos: [1, 8, 5], 
      state: 16
    }, 
    {
      pos: [2, 8, 5], 
      state: 16
    }, 
    {
      pos: [3, 8, 5], 
      state: 16
    }, 
    {
      pos: [4, 8, 5], 
      state: 16
    }, 
    {
      pos: [5, 8, 5], 
      state: 16
    }, 
    {
      pos: [6, 8, 5], 
      state: 16
    }, 
    {
      pos: [7, 8, 5], 
      state: 16
    }, 
    {
      pos: [8, 8, 5], 
      state: 16
    }, 
    {
      pos: [9, 8, 5], 
      state: 16
    }, 
    {
      pos: [10, 8, 5], 
      state: 16
    }, 
    {
      pos: [11, 8, 5], 
      state: 16
    }, 
    {
      pos: [12, 8, 5], 
      state: 16
    }, 
    {
      pos: [0, 8, 6], 
      state: 16
    }, 
    {
      pos: [1, 8, 6], 
      state: 16
    }, 
    {
      pos: [2, 8, 6], 
      state: 16
    }, 
    {
      pos: [3, 8, 6], 
      state: 16
    }, 
    {
      pos: [4, 8, 6], 
      state: 16
    }, 
    {
      pos: [5, 8, 6], 
      state: 16
    }, 
    {
      pos: [6, 8, 6], 
      state: 16
    }, 
    {
      pos: [7, 8, 6], 
      state: 16
    }, 
    {
      pos: [8, 8, 6], 
      state: 16
    }, 
    {
      pos: [9, 8, 6], 
      state: 16
    }, 
    {
      pos: [10, 8, 6], 
      state: 16
    }, 
    {
      pos: [11, 8, 6], 
      state: 16
    }, 
    {
      pos: [12, 8, 6], 
      state: 16
    }, 
    {
      pos: [0, 9, 0], 
      state: 16
    }, 
    {
      pos: [1, 9, 0], 
      state: 16
    }, 
    {
      pos: [2, 9, 0], 
      state: 16
    }, 
    {
      pos: [3, 9, 0], 
      state: 16
    }, 
    {
      pos: [4, 9, 0], 
      state: 16
    }, 
    {
      pos: [5, 9, 0], 
      state: 16
    }, 
    {
      pos: [6, 9, 0], 
      state: 16
    }, 
    {
      pos: [7, 9, 0], 
      state: 16
    }, 
    {
      pos: [8, 9, 0], 
      state: 16
    }, 
    {
      pos: [9, 9, 0], 
      state: 16
    }, 
    {
      pos: [10, 9, 0], 
      state: 16
    }, 
    {
      pos: [11, 9, 0], 
      state: 16
    }, 
    {
      pos: [12, 9, 0], 
      state: 16
    }, 
    {
      pos: [0, 9, 1], 
      state: 16
    }, 
    {
      pos: [1, 9, 1], 
      state: 16
    }, 
    {
      pos: [2, 9, 1], 
      state: 16
    }, 
    {
      pos: [3, 9, 1], 
      state: 16
    }, 
    {
      pos: [4, 9, 1], 
      state: 16
    }, 
    {
      pos: [5, 9, 1], 
      state: 16
    }, 
    {
      pos: [6, 9, 1], 
      state: 16
    }, 
    {
      pos: [7, 9, 1], 
      state: 16
    }, 
    {
      pos: [8, 9, 1], 
      state: 16
    }, 
    {
      pos: [9, 9, 1], 
      state: 16
    }, 
    {
      pos: [10, 9, 1], 
      state: 16
    }, 
    {
      pos: [11, 9, 1], 
      state: 16
    }, 
    {
      pos: [12, 9, 1], 
      state: 16
    }, 
    {
      pos: [0, 9, 2], 
      state: 16
    }, 
    {
      pos: [1, 9, 2], 
      state: 16
    }, 
    {
      pos: [2, 9, 2], 
      state: 16
    }, 
    {
      pos: [3, 9, 2], 
      state: 16
    }, 
    {
      pos: [4, 9, 2], 
      state: 16
    }, 
    {
      pos: [5, 9, 2], 
      state: 16
    }, 
    {
      pos: [6, 9, 2], 
      state: 16
    }, 
    {
      pos: [7, 9, 2], 
      state: 16
    }, 
    {
      pos: [8, 9, 2], 
      state: 16
    }, 
    {
      pos: [9, 9, 2], 
      state: 16
    }, 
    {
      pos: [10, 9, 2], 
      state: 16
    }, 
    {
      pos: [11, 9, 2], 
      state: 16
    }, 
    {
      pos: [12, 9, 2], 
      state: 16
    }, 
    {
      pos: [0, 9, 3], 
      state: 16
    }, 
    {
      pos: [1, 9, 3], 
      state: 7
    }, 
    {
      pos: [2, 9, 3], 
      state: 7
    }, 
    {
      pos: [3, 9, 3], 
      state: 10
    }, 
    {
      pos: [4, 9, 3], 
      state: 13
    }, 
    {
      pos: [5, 9, 3], 
      state: 8
    }, 
    {
      pos: [6, 9, 3], 
      state: 7
    }, 
    {
      pos: [7, 9, 3], 
      state: 7
    }, 
    {
      pos: [8, 9, 3], 
      state: 13
    }, 
    {
      pos: [9, 9, 3], 
      state: 7
    }, 
    {
      pos: [10, 9, 3], 
      state: 7
    }, 
    {
      pos: [11, 9, 3], 
      state: 7
    }, 
    {
      pos: [12, 9, 3], 
      state: 16
    }, 
    {
      pos: [0, 9, 4], 
      state: 16
    }, 
    {
      pos: [1, 9, 4], 
      state: 16
    }, 
    {
      pos: [2, 9, 4], 
      state: 16
    }, 
    {
      pos: [3, 9, 4], 
      state: 16
    }, 
    {
      pos: [4, 9, 4], 
      state: 16
    }, 
    {
      pos: [5, 9, 4], 
      state: 16
    }, 
    {
      pos: [6, 9, 4], 
      state: 16
    }, 
    {
      pos: [7, 9, 4], 
      state: 16
    }, 
    {
      pos: [8, 9, 4], 
      state: 16
    }, 
    {
      pos: [9, 9, 4], 
      state: 16
    }, 
    {
      pos: [10, 9, 4], 
      state: 16
    }, 
    {
      pos: [11, 9, 4], 
      state: 16
    }, 
    {
      pos: [12, 9, 4], 
      state: 16
    }, 
    {
      pos: [0, 9, 5], 
      state: 16
    }, 
    {
      pos: [1, 9, 5], 
      state: 16
    }, 
    {
      pos: [2, 9, 5], 
      state: 16
    }, 
    {
      pos: [3, 9, 5], 
      state: 16
    }, 
    {
      pos: [4, 9, 5], 
      state: 16
    }, 
    {
      pos: [5, 9, 5], 
      state: 16
    }, 
    {
      pos: [6, 9, 5], 
      state: 16
    }, 
    {
      pos: [7, 9, 5], 
      state: 16
    }, 
    {
      pos: [8, 9, 5], 
      state: 16
    }, 
    {
      pos: [9, 9, 5], 
      state: 16
    }, 
    {
      pos: [10, 9, 5], 
      state: 16
    }, 
    {
      pos: [11, 9, 5], 
      state: 16
    }, 
    {
      pos: [12, 9, 5], 
      state: 16
    }, 
    {
      pos: [0, 9, 6], 
      state: 16
    }, 
    {
      pos: [1, 9, 6], 
      state: 16
    }, 
    {
      pos: [2, 9, 6], 
      state: 16
    }, 
    {
      pos: [3, 9, 6], 
      state: 16
    }, 
    {
      pos: [4, 9, 6], 
      state: 16
    }, 
    {
      pos: [5, 9, 6], 
      state: 16
    }, 
    {
      pos: [6, 9, 6], 
      state: 16
    }, 
    {
      pos: [7, 9, 6], 
      state: 16
    }, 
    {
      pos: [8, 9, 6], 
      state: 16
    }, 
    {
      pos: [9, 9, 6], 
      state: 16
    }, 
    {
      pos: [10, 9, 6], 
      state: 16
    }, 
    {
      pos: [11, 9, 6], 
      state: 16
    }, 
    {
      pos: [12, 9, 6], 
      state: 16
    }
  ], 
  palette: [
    {
      Name: "minecraft:snow_block"
    }, 
    {
      Properties: {
        axis: "y"
      }, 
      Name: "minecraft:stripped_spruce_wood"
    }, 
    {
      Properties: {
        axis: "z"
      }, 
      Name: "minecraft:stripped_spruce_wood"
    }, 
    {
      Name: "minecraft:spruce_planks"
    }, 
    {
      Properties: {
        layers: "8"
      }, 
      Name: "minecraft:snow"
    }, 
    {
      Properties: {
        axis: "x"
      }, 
      Name: "minecraft:stripped_spruce_wood"
    }, 
    {
      Properties: {
        facing: "west"
      }, 
      Name: "minecraft:jigsaw"
    }, 
    {
      Properties: {
        layers: "1"
      }, 
      Name: "minecraft:snow"
    }, 
    {
      Properties: {
        layers: "4"
      }, 
      Name: "minecraft:snow"
    }, 
    {
      Properties: {
        layers: "5"
      }, 
      Name: "minecraft:snow"
    }, 
    {
      Properties: {
        layers: "2"
      }, 
      Name: "minecraft:snow"
    }, 
    {
      Properties: {
        layers: "6"
      }, 
      Name: "minecraft:snow"
    }, 
    {
      Properties: {
        half: "bottom", 
        waterlogged: "false", 
        shape: "straight", 
        facing: "east"
      }, 
      Name: "minecraft:spruce_stairs"
    }, 
    {
      Properties: {
        layers: "3"
      }, 
      Name: "minecraft:snow"
    }, 
    {
      Name: "minecraft:bookshelf"
    }, 
    {
      Properties: {
        has_book: "false", 
        powered: "false", 
        facing: "west"
      }, 
      Name: "minecraft:lectern"
    }, 
    {
      Name: "minecraft:air"
    }, 
    {
      Properties: {
        east: "true", 
        waterlogged: "false", 
        south: "false", 
        north: "false", 
        west: "true"
      }, 
      Name: "minecraft:glass_pane"
    }, 
    {
      Properties: {
        east: "false", 
        waterlogged: "false", 
        south: "false", 
        north: "true", 
        west: "true"
      }, 
      Name: "minecraft:spruce_fence"
    }, 
    {
      Properties: {
        hinge: "left", 
        half: "lower", 
        powered: "false", 
        facing: "east", 
        open: "false"
      }, 
      Name: "minecraft:spruce_door"
    }, 
    {
      Properties: {
        east: "false", 
        waterlogged: "false", 
        south: "true", 
        north: "true", 
        west: "false"
      }, 
      Name: "minecraft:glass_pane"
    }, 
    {
      Properties: {
        east: "false", 
        waterlogged: "false", 
        south: "true", 
        north: "false", 
        west: "true"
      }, 
      Name: "minecraft:spruce_fence"
    }, 
    {
      Properties: {
        east: "true", 
        waterlogged: "false", 
        south: "true", 
        north: "false", 
        west: "true"
      }, 
      Name: "minecraft:glass_pane"
    }, 
    {
      Name: "minecraft:torch"
    }, 
    {
      Properties: {
        hinge: "left", 
        half: "upper", 
        powered: "false", 
        facing: "east", 
        open: "false"
      }, 
      Name: "minecraft:spruce_door"
    }, 
    {
      Properties: {
        hanging: "false"
      }, 
      Name: "minecraft:lantern"
    }, 
    {
      Properties: {
        east: "true", 
        waterlogged: "false", 
        south: "false", 
        north: "true", 
        west: "true"
      }, 
      Name: "minecraft:spruce_fence"
    }, 
    {
      Properties: {
        hanging: "true"
      }, 
      Name: "minecraft:lantern"
    }, 
    {
      Properties: {
        east: "false", 
        waterlogged: "false", 
        south: "false", 
        north: "true", 
        west: "false"
      }, 
      Name: "minecraft:spruce_fence"
    }, 
    {
      Properties: {
        east: "false", 
        waterlogged: "false", 
        south: "true", 
        north: "true", 
        west: "false"
      }, 
      Name: "minecraft:spruce_fence"
    }
  ]
}
