{
  size: [9, 9, 24], 
  entities: [], 
  blocks: [
    {
      pos: [4, 0, 9], 
      state: 0
    }, 
    {
      pos: [4, 0, 10], 
      state: 0
    }, 
    {
      pos: [4, 0, 11], 
      state: 0
    }, 
    {
      pos: [4, 0, 12], 
      state: 0
    }, 
    {
      pos: [4, 0, 13], 
      state: 0
    }, 
    {
      pos: [4, 0, 14], 
      state: 0
    }, 
    {
      pos: [4, 0, 15], 
      state: 0
    }, 
    {
      pos: [4, 0, 16], 
      state: 0
    }, 
    {
      pos: [4, 0, 17], 
      state: 0
    }, 
    {
      pos: [4, 0, 18], 
      state: 0
    }, 
    {
      pos: [4, 0, 19], 
      state: 0
    }, 
    {
      pos: [4, 0, 20], 
      state: 0
    }, 
    {
      pos: [3, 1, 9], 
      state: 1
    }, 
    {
      pos: [3, 1, 10], 
      state: 1
    }, 
    {
      pos: [3, 1, 11], 
      state: 1
    }, 
    {
      pos: [3, 1, 12], 
      state: 1
    }, 
    {
      pos: [3, 1, 13], 
      state: 1
    }, 
    {
      pos: [3, 1, 14], 
      state: 1
    }, 
    {
      pos: [3, 1, 15], 
      state: 1
    }, 
    {
      pos: [3, 1, 16], 
      state: 1
    }, 
    {
      pos: [3, 1, 17], 
      state: 1
    }, 
    {
      pos: [3, 1, 18], 
      state: 1
    }, 
    {
      pos: [3, 1, 20], 
      state: 1
    }, 
    {
      pos: [4, 1, 7], 
      state: 0
    }, 
    {
      pos: [4, 1, 8], 
      state: 1
    }, 
    {
      pos: [4, 1, 9], 
      state: 1
    }, 
    {
      pos: [4, 1, 10], 
      state: 1
    }, 
    {
      pos: [4, 1, 11], 
      state: 1
    }, 
    {
      pos: [4, 1, 12], 
      state: 1
    }, 
    {
      pos: [4, 1, 13], 
      state: 1
    }, 
    {
      pos: [4, 1, 14], 
      state: 1
    }, 
    {
      pos: [4, 1, 15], 
      state: 1
    }, 
    {
      pos: [4, 1, 16], 
      state: 1
    }, 
    {
      pos: [4, 1, 17], 
      state: 1
    }, 
    {
      pos: [4, 1, 19], 
      state: 1
    }, 
    {
      pos: [4, 1, 22], 
      state: 1
    }, 
    {
      pos: [5, 1, 9], 
      state: 1
    }, 
    {
      pos: [5, 1, 10], 
      state: 1
    }, 
    {
      pos: [5, 1, 11], 
      state: 1
    }, 
    {
      pos: [5, 1, 12], 
      state: 1
    }, 
    {
      pos: [5, 1, 13], 
      state: 1
    }, 
    {
      pos: [5, 1, 14], 
      state: 1
    }, 
    {
      pos: [5, 1, 15], 
      state: 1
    }, 
    {
      pos: [5, 1, 16], 
      state: 1
    }, 
    {
      pos: [5, 1, 17], 
      state: 1
    }, 
    {
      pos: [5, 1, 18], 
      state: 1
    }, 
    {
      pos: [5, 1, 19], 
      state: 1
    }, 
    {
      pos: [5, 1, 20], 
      state: 1
    }, 
    {
      pos: [2, 2, 9], 
      state: 1
    }, 
    {
      pos: [2, 2, 10], 
      state: 1
    }, 
    {
      pos: [2, 2, 11], 
      state: 1
    }, 
    {
      pos: [2, 2, 13], 
      state: 1
    }, 
    {
      pos: [2, 2, 14], 
      state: 1
    }, 
    {
      pos: [2, 2, 16], 
      state: 1
    }, 
    {
      pos: [2, 2, 17], 
      state: 1
    }, 
    {
      pos: [2, 2, 19], 
      state: 1
    }, 
    {
      pos: [3, 2, 8], 
      state: 1
    }, 
    {
      pos: [4, 2, 6], 
      state: 0
    }, 
    {
      pos: [4, 2, 7], 
      state: 1
    }, 
    {
      pos: [4, 2, 11], 
      state: 2
    }, 
    {
      pos: [4, 2, 16], 
      state: 2
    }, 
    {
      pos: [5, 2, 8], 
      state: 1
    }, 
    {
      pos: [5, 2, 16], 
      state: 1
    }, 
    {
      pos: [5, 2, 20], 
      state: 1
    }, 
    {
      pos: [6, 2, 9], 
      state: 1
    }, 
    {
      pos: [6, 2, 10], 
      state: 1
    }, 
    {
      pos: [6, 2, 11], 
      state: 1
    }, 
    {
      pos: [6, 2, 13], 
      state: 1
    }, 
    {
      pos: [6, 2, 14], 
      state: 1
    }, 
    {
      pos: [6, 2, 16], 
      state: 1
    }, 
    {
      pos: [6, 2, 17], 
      state: 1
    }, 
    {
      pos: [6, 2, 19], 
      state: 1
    }, 
    {
      pos: [6, 2, 20], 
      state: 1
    }, 
    {
      pos: [1, 3, 9], 
      state: 1
    }, 
    {
      pos: [1, 3, 10], 
      state: 1
    }, 
    {
      pos: [1, 3, 11], 
      state: 1
    }, 
    {
      pos: [1, 3, 13], 
      state: 1
    }, 
    {
      pos: [1, 3, 14], 
      state: 1
    }, 
    {
      pos: [1, 3, 16], 
      state: 1
    }, 
    {
      pos: [1, 3, 17], 
      state: 1
    }, 
    {
      pos: [2, 3, 8], 
      state: 1
    }, 
    {
      pos: [2, 3, 9], 
      state: 1
    }, 
    {
      pos: [2, 3, 10], 
      state: 1
    }, 
    {
      pos: [2, 3, 11], 
      state: 1
    }, 
    {
      pos: [2, 3, 13], 
      state: 1
    }, 
    {
      pos: [2, 3, 14], 
      state: 1
    }, 
    {
      pos: [2, 3, 16], 
      state: 1
    }, 
    {
      pos: [2, 3, 17], 
      state: 1
    }, 
    {
      pos: [3, 3, 7], 
      state: 1
    }, 
    {
      pos: [4, 3, 5], 
      state: 1
    }, 
    {
      pos: [4, 3, 6], 
      state: 1
    }, 
    {
      pos: [4, 3, 7], 
      state: 1
    }, 
    {
      pos: [4, 3, 11], 
      state: 2
    }, 
    {
      pos: [4, 3, 16], 
      state: 2
    }, 
    {
      pos: [5, 3, 7], 
      state: 1
    }, 
    {
      pos: [5, 3, 16], 
      state: 1
    }, 
    {
      pos: [6, 3, 8], 
      state: 1
    }, 
    {
      pos: [6, 3, 9], 
      state: 1
    }, 
    {
      pos: [6, 3, 10], 
      state: 1
    }, 
    {
      pos: [6, 3, 11], 
      state: 1
    }, 
    {
      pos: [6, 3, 13], 
      state: 1
    }, 
    {
      pos: [6, 3, 14], 
      state: 1
    }, 
    {
      pos: [6, 3, 16], 
      state: 1
    }, 
    {
      pos: [7, 3, 9], 
      state: 1
    }, 
    {
      pos: [7, 3, 10], 
      state: 1
    }, 
    {
      pos: [7, 3, 11], 
      state: 1
    }, 
    {
      pos: [7, 3, 13], 
      state: 1
    }, 
    {
      pos: [7, 3, 14], 
      state: 1
    }, 
    {
      pos: [7, 3, 16], 
      state: 1
    }, 
    {
      pos: [7, 3, 17], 
      state: 1
    }, 
    {
      pos: [7, 3, 19], 
      state: 1
    }, 
    {
      pos: [1, 4, 8], 
      state: 1
    }, 
    {
      pos: [1, 4, 9], 
      state: 0
    }, 
    {
      pos: [1, 4, 10], 
      state: 0
    }, 
    {
      pos: [1, 4, 11], 
      state: 0
    }, 
    {
      pos: [1, 4, 12], 
      state: 0
    }, 
    {
      pos: [1, 4, 13], 
      state: 0
    }, 
    {
      pos: [1, 4, 14], 
      state: 0
    }, 
    {
      pos: [1, 4, 15], 
      state: 0
    }, 
    {
      pos: [1, 4, 16], 
      state: 0
    }, 
    {
      pos: [2, 4, 7], 
      state: 1
    }, 
    {
      pos: [2, 4, 8], 
      state: 0
    }, 
    {
      pos: [2, 4, 9], 
      state: 0
    }, 
    {
      pos: [2, 4, 10], 
      state: 0
    }, 
    {
      pos: [2, 4, 11], 
      state: 0
    }, 
    {
      pos: [2, 4, 13], 
      state: 0
    }, 
    {
      pos: [3, 4, 5], 
      state: 1
    }, 
    {
      pos: [3, 4, 6], 
      state: 1
    }, 
    {
      pos: [3, 4, 7], 
      state: 1
    }, 
    {
      pos: [3, 4, 11], 
      state: 0
    }, 
    {
      pos: [4, 4, 4], 
      state: 0
    }, 
    {
      pos: [4, 4, 5], 
      state: 1
    }, 
    {
      pos: [4, 4, 6], 
      state: 1
    }, 
    {
      pos: [4, 4, 7], 
      state: 2
    }, 
    {
      pos: [4, 4, 11], 
      state: 2
    }, 
    {
      pos: [5, 4, 5], 
      state: 1
    }, 
    {
      pos: [5, 4, 6], 
      state: 1
    }, 
    {
      pos: [5, 4, 7], 
      state: 1
    }, 
    {
      pos: [5, 4, 11], 
      state: 0
    }, 
    {
      pos: [5, 4, 16], 
      state: 0
    }, 
    {
      pos: [6, 4, 7], 
      state: 1
    }, 
    {
      pos: [6, 4, 8], 
      state: 0
    }, 
    {
      pos: [6, 4, 9], 
      state: 0
    }, 
    {
      pos: [6, 4, 10], 
      state: 0
    }, 
    {
      pos: [6, 4, 11], 
      state: 0
    }, 
    {
      pos: [6, 4, 13], 
      state: 0
    }, 
    {
      pos: [6, 4, 14], 
      state: 0
    }, 
    {
      pos: [7, 4, 8], 
      state: 1
    }, 
    {
      pos: [7, 4, 9], 
      state: 0
    }, 
    {
      pos: [7, 4, 10], 
      state: 0
    }, 
    {
      pos: [7, 4, 11], 
      state: 0
    }, 
    {
      pos: [7, 4, 12], 
      state: 0
    }, 
    {
      pos: [7, 4, 13], 
      state: 0
    }, 
    {
      pos: [7, 4, 14], 
      state: 0
    }, 
    {
      pos: [7, 4, 15], 
      state: 0
    }, 
    {
      pos: [7, 4, 16], 
      state: 0
    }, 
    {
      pos: [0, 5, 9], 
      state: 1
    }, 
    {
      pos: [0, 5, 10], 
      state: 1
    }, 
    {
      pos: [1, 5, 7], 
      state: 1
    }, 
    {
      pos: [1, 5, 8], 
      state: 1
    }, 
    {
      pos: [2, 5, 5], 
      state: 1
    }, 
    {
      pos: [2, 5, 6], 
      state: 0
    }, 
    {
      pos: [2, 5, 7], 
      state: 0
    }, 
    {
      pos: [3, 5, 4], 
      state: 1
    }, 
    {
      pos: [3, 5, 5], 
      state: 0
    }, 
    {
      pos: [3, 5, 6], 
      state: 0
    }, 
    {
      pos: [4, 5, 3], 
      state: 0
    }, 
    {
      pos: [4, 5, 4], 
      state: 1
    }, 
    {
      pos: [4, 5, 5], 
      state: 0
    }, 
    {
      pos: [4, 5, 6], 
      state: 0
    }, 
    {
      pos: [4, 5, 7], 
      state: 2
    }, 
    {
      pos: [4, 5, 11], 
      state: 2
    }, 
    {
      pos: [5, 5, 4], 
      state: 1
    }, 
    {
      pos: [5, 5, 5], 
      state: 0
    }, 
    {
      pos: [5, 5, 6], 
      state: 0
    }, 
    {
      pos: [6, 5, 5], 
      state: 1
    }, 
    {
      pos: [6, 5, 6], 
      state: 0
    }, 
    {
      pos: [6, 5, 7], 
      state: 0
    }, 
    {
      pos: [7, 5, 7], 
      state: 1
    }, 
    {
      pos: [7, 5, 8], 
      state: 1
    }, 
    {
      pos: [8, 5, 9], 
      state: 1
    }, 
    {
      pos: [8, 5, 10], 
      state: 1
    }, 
    {
      pos: [0, 6, 8], 
      state: 1
    }, 
    {
      pos: [1, 6, 6], 
      state: 1
    }, 
    {
      pos: [1, 6, 7], 
      state: 1
    }, 
    {
      pos: [2, 6, 5], 
      state: 1
    }, 
    {
      pos: [3, 6, 4], 
      state: 1
    }, 
    {
      pos: [4, 6, 3], 
      state: 0
    }, 
    {
      pos: [5, 6, 4], 
      state: 1
    }, 
    {
      pos: [6, 6, 5], 
      state: 1
    }, 
    {
      pos: [7, 6, 6], 
      state: 1
    }, 
    {
      pos: [7, 6, 7], 
      state: 1
    }, 
    {
      pos: [8, 6, 8], 
      state: 1
    }, 
    {
      pos: [4, 7, 2], 
      state: 0
    }, 
    {
      pos: [4, 0, 8], 
      state: 3
    }, 
    {
      pos: [4, 0, 21], 
      state: 4
    }, 
    {
      pos: [2, 1, 9], 
      state: 5
    }, 
    {
      pos: [2, 1, 10], 
      state: 5
    }, 
    {
      pos: [2, 1, 11], 
      state: 5
    }, 
    {
      pos: [2, 1, 12], 
      state: 5
    }, 
    {
      pos: [2, 1, 13], 
      state: 5
    }, 
    {
      pos: [2, 1, 14], 
      state: 5
    }, 
    {
      pos: [2, 1, 15], 
      state: 5
    }, 
    {
      pos: [2, 1, 16], 
      state: 5
    }, 
    {
      pos: [2, 1, 17], 
      state: 5
    }, 
    {
      pos: [2, 1, 18], 
      state: 5
    }, 
    {
      pos: [2, 1, 19], 
      state: 5
    }, 
    {
      pos: [2, 1, 20], 
      state: 5
    }, 
    {
      pos: [3, 1, 8], 
      state: 5
    }, 
    {
      pos: [3, 1, 21], 
      state: 5
    }, 
    {
      pos: [4, 1, 6], 
      state: 3
    }, 
    {
      pos: [5, 1, 8], 
      state: 6
    }, 
    {
      pos: [5, 1, 21], 
      state: 6
    }, 
    {
      pos: [5, 1, 22], 
      state: 6
    }, 
    {
      pos: [5, 1, 23], 
      state: 6
    }, 
    {
      pos: [6, 1, 9], 
      state: 6
    }, 
    {
      pos: [6, 1, 10], 
      state: 6
    }, 
    {
      pos: [6, 1, 11], 
      state: 6
    }, 
    {
      pos: [6, 1, 12], 
      state: 6
    }, 
    {
      pos: [6, 1, 13], 
      state: 6
    }, 
    {
      pos: [6, 1, 14], 
      state: 6
    }, 
    {
      pos: [6, 1, 15], 
      state: 6
    }, 
    {
      pos: [6, 1, 16], 
      state: 6
    }, 
    {
      pos: [6, 1, 17], 
      state: 6
    }, 
    {
      pos: [6, 1, 18], 
      state: 6
    }, 
    {
      pos: [6, 1, 19], 
      state: 6
    }, 
    {
      pos: [6, 1, 20], 
      state: 6
    }, 
    {
      pos: [1, 2, 9], 
      state: 5
    }, 
    {
      pos: [1, 2, 10], 
      state: 5
    }, 
    {
      pos: [1, 2, 11], 
      state: 5
    }, 
    {
      pos: [1, 2, 12], 
      state: 5
    }, 
    {
      pos: [1, 2, 13], 
      state: 5
    }, 
    {
      pos: [1, 2, 14], 
      state: 5
    }, 
    {
      pos: [1, 2, 15], 
      state: 5
    }, 
    {
      pos: [1, 2, 16], 
      state: 5
    }, 
    {
      pos: [1, 2, 17], 
      state: 5
    }, 
    {
      pos: [1, 2, 18], 
      state: 5
    }, 
    {
      pos: [2, 2, 8], 
      state: 5
    }, 
    {
      pos: [2, 2, 12], 
      state: 7
    }, 
    {
      pos: [2, 2, 15], 
      state: 7
    }, 
    {
      pos: [2, 2, 18], 
      state: 7
    }, 
    {
      pos: [3, 2, 7], 
      state: 5
    }, 
    {
      pos: [3, 2, 16], 
      state: 8
    }, 
    {
      pos: [4, 2, 5], 
      state: 3
    }, 
    {
      pos: [5, 2, 7], 
      state: 6
    }, 
    {
      pos: [6, 2, 8], 
      state: 6
    }, 
    {
      pos: [6, 2, 12], 
      state: 9
    }, 
    {
      pos: [6, 2, 15], 
      state: 9
    }, 
    {
      pos: [6, 2, 18], 
      state: 9
    }, 
    {
      pos: [7, 2, 9], 
      state: 6
    }, 
    {
      pos: [7, 2, 10], 
      state: 6
    }, 
    {
      pos: [7, 2, 11], 
      state: 6
    }, 
    {
      pos: [7, 2, 12], 
      state: 6
    }, 
    {
      pos: [7, 2, 13], 
      state: 6
    }, 
    {
      pos: [7, 2, 14], 
      state: 6
    }, 
    {
      pos: [7, 2, 15], 
      state: 6
    }, 
    {
      pos: [7, 2, 16], 
      state: 6
    }, 
    {
      pos: [7, 2, 17], 
      state: 6
    }, 
    {
      pos: [7, 2, 18], 
      state: 6
    }, 
    {
      pos: [7, 2, 19], 
      state: 6
    }, 
    {
      pos: [7, 2, 20], 
      state: 6
    }, 
    {
      pos: [1, 3, 8], 
      state: 5
    }, 
    {
      pos: [2, 3, 7], 
      state: 5
    }, 
    {
      pos: [3, 3, 5], 
      state: 5
    }, 
    {
      pos: [3, 3, 6], 
      state: 5
    }, 
    {
      pos: [3, 3, 16], 
      state: 10
    }, 
    {
      pos: [4, 3, 4], 
      state: 3
    }, 
    {
      pos: [5, 3, 5], 
      state: 6
    }, 
    {
      pos: [5, 3, 6], 
      state: 6
    }, 
    {
      pos: [6, 3, 7], 
      state: 6
    }, 
    {
      pos: [7, 3, 8], 
      state: 6
    }, 
    {
      pos: [0, 4, 9], 
      state: 5
    }, 
    {
      pos: [0, 4, 10], 
      state: 5
    }, 
    {
      pos: [0, 4, 11], 
      state: 5
    }, 
    {
      pos: [0, 4, 12], 
      state: 5
    }, 
    {
      pos: [0, 4, 13], 
      state: 5
    }, 
    {
      pos: [0, 4, 14], 
      state: 5
    }, 
    {
      pos: [0, 4, 15], 
      state: 5
    }, 
    {
      pos: [0, 4, 16], 
      state: 5
    }, 
    {
      pos: [1, 4, 7], 
      state: 5
    }, 
    {
      pos: [2, 4, 5], 
      state: 5
    }, 
    {
      pos: [2, 4, 6], 
      state: 5
    }, 
    {
      pos: [2, 4, 12], 
      state: 11
    }, 
    {
      pos: [3, 4, 4], 
      state: 12
    }, 
    {
      pos: [3, 4, 8], 
      state: 4
    }, 
    {
      pos: [3, 4, 9], 
      state: 13
    }, 
    {
      pos: [3, 4, 10], 
      state: 14
    }, 
    {
      pos: [3, 4, 12], 
      state: 13
    }, 
    {
      pos: [3, 4, 13], 
      state: 15
    }, 
    {
      pos: [4, 4, 3], 
      state: 3
    }, 
    {
      pos: [4, 4, 8], 
      state: 4
    }, 
    {
      pos: [4, 4, 12], 
      state: 13
    }, 
    {
      pos: [5, 4, 4], 
      state: 12
    }, 
    {
      pos: [5, 4, 8], 
      state: 4
    }, 
    {
      pos: [5, 4, 9], 
      state: 13
    }, 
    {
      pos: [5, 4, 10], 
      state: 16
    }, 
    {
      pos: [5, 4, 12], 
      state: 13
    }, 
    {
      pos: [5, 4, 13], 
      state: 16
    }, 
    {
      pos: [5, 4, 14], 
      state: 16
    }, 
    {
      pos: [5, 4, 15], 
      state: 14
    }, 
    {
      pos: [6, 4, 5], 
      state: 6
    }, 
    {
      pos: [6, 4, 6], 
      state: 6
    }, 
    {
      pos: [6, 4, 12], 
      state: 17
    }, 
    {
      pos: [6, 4, 15], 
      state: 17
    }, 
    {
      pos: [7, 4, 7], 
      state: 6
    }, 
    {
      pos: [8, 4, 9], 
      state: 6
    }, 
    {
      pos: [8, 4, 10], 
      state: 6
    }, 
    {
      pos: [8, 4, 11], 
      state: 6
    }, 
    {
      pos: [8, 4, 12], 
      state: 6
    }, 
    {
      pos: [8, 4, 13], 
      state: 6
    }, 
    {
      pos: [8, 4, 14], 
      state: 6
    }, 
    {
      pos: [8, 4, 15], 
      state: 6
    }, 
    {
      pos: [8, 4, 16], 
      state: 6
    }, 
    {
      pos: [8, 4, 17], 
      state: 6
    }, 
    {
      pos: [8, 4, 18], 
      state: 6
    }, 
    {
      pos: [0, 5, 8], 
      state: 12
    }, 
    {
      pos: [0, 5, 11], 
      state: 18
    }, 
    {
      pos: [0, 5, 12], 
      state: 18
    }, 
    {
      pos: [0, 5, 13], 
      state: 18
    }, 
    {
      pos: [0, 5, 15], 
      state: 18
    }, 
    {
      pos: [1, 5, 6], 
      state: 5
    }, 
    {
      pos: [3, 5, 3], 
      state: 12
    }, 
    {
      pos: [3, 5, 7], 
      state: 19
    }, 
    {
      pos: [5, 5, 3], 
      state: 12
    }, 
    {
      pos: [5, 5, 7], 
      state: 19
    }, 
    {
      pos: [7, 5, 6], 
      state: 6
    }, 
    {
      pos: [8, 5, 8], 
      state: 12
    }, 
    {
      pos: [8, 5, 11], 
      state: 18
    }, 
    {
      pos: [8, 5, 12], 
      state: 18
    }, 
    {
      pos: [8, 5, 13], 
      state: 18
    }, 
    {
      pos: [8, 5, 15], 
      state: 18
    }, 
    {
      pos: [8, 5, 16], 
      state: 18
    }, 
    {
      pos: [8, 5, 17], 
      state: 18
    }, 
    {
      pos: [0, 6, 9], 
      state: 20
    }, 
    {
      pos: [1, 6, 8], 
      state: 20
    }, 
    {
      pos: [3, 6, 2], 
      state: 18
    }, 
    {
      pos: [3, 6, 3], 
      state: 21
    }, 
    {
      pos: [4, 6, 2], 
      state: 3
    }, 
    {
      pos: [4, 6, 4], 
      state: 19
    }, 
    {
      pos: [5, 6, 2], 
      state: 18
    }, 
    {
      pos: [5, 6, 3], 
      state: 21
    }, 
    {
      pos: [7, 6, 8], 
      state: 20
    }, 
    {
      pos: [8, 6, 9], 
      state: 20
    }, 
    {
      pos: [3, 7, 2], 
      state: 18
    }, 
    {
      pos: [3, 7, 3], 
      state: 18
    }, 
    {
      pos: [3, 7, 4], 
      state: 18
    }, 
    {
      pos: [4, 7, 1], 
      state: 3
    }, 
    {
      pos: [4, 7, 3], 
      state: 19
    }, 
    {
      pos: [5, 7, 2], 
      state: 18
    }, 
    {
      pos: [5, 7, 3], 
      state: 18
    }, 
    {
      pos: [5, 7, 4], 
      state: 18
    }, 
    {
      pos: [4, 8, 0], 
      state: 3
    }, 
    {
      pos: [4, 8, 1], 
      state: 19
    }, 
    {
      nbt: {
        Items: [], 
        id: "minecraft:chest"
      }, 
      pos: [4, 2, 8], 
      state: 22
    }, 
    {
      nbt: {
        metadata: "supply_chest", 
        mirror: "NONE", 
        ignoreEntities: 1b, 
        powered: 0b, 
        seed: 0L, 
        author: "CascadianBacon", 
        rotation: "NONE", 
        mode: "DATA", 
        posX: 0, 
        posY: 1, 
        sizeX: 0, 
        integrity: 1.0f, 
        posZ: 0, 
        showair: 0b, 
        name: "", 
        id: "minecraft:structure_block", 
        sizeY: 0, 
        showboundingbox: 1b, 
        sizeZ: 0
      }, 
      pos: [4, 3, 8], 
      state: 23
    }
  ], 
  palettes: [
    [
      {
        id: "minecraft:spruce_planks"
      }, 
      {
        id: "minecraft:oak_planks"
      }, 
      {
        id: "minecraft:oak_log", 
        properties: {
          axis: "y"
        }
      }, 
      {
        id: "minecraft:spruce_stairs", 
        properties: {
          half: "top", 
          waterlogged: "false", 
          shape: "outer_right", 
          facing: "south"
        }
      }, 
      {
        id: "minecraft:spruce_stairs", 
        properties: {
          half: "top", 
          waterlogged: "false", 
          shape: "outer_right", 
          facing: "north"
        }
      }, 
      {
        id: "minecraft:oak_stairs", 
        properties: {
          half: "top", 
          waterlogged: "false", 
          shape: "outer_right", 
          facing: "east"
        }
      }, 
      {
        id: "minecraft:oak_stairs", 
        properties: {
          half: "top", 
          waterlogged: "false", 
          shape: "outer_right", 
          facing: "west"
        }
      }, 
      {
        id: "minecraft:oak_stairs", 
        properties: {
          half: "bottom", 
          waterlogged: "false", 
          shape: "outer_right", 
          facing: "west"
        }
      }, 
      {
        id: "minecraft:oak_door", 
        properties: {
          hinge: "right", 
          half: "lower", 
          powered: "false", 
          facing: "south", 
          open: "false"
        }
      }, 
      {
        id: "minecraft:oak_stairs", 
        properties: {
          half: "bottom", 
          waterlogged: "false", 
          shape: "outer_right", 
          facing: "east"
        }
      }, 
      {
        id: "minecraft:oak_door", 
        properties: {
          hinge: "left", 
          half: "upper", 
          powered: "false", 
          facing: "east", 
          open: "false"
        }
      }, 
      {
        id: "minecraft:spruce_stairs", 
        properties: {
          half: "top", 
          waterlogged: "false", 
          shape: "outer_right", 
          facing: "west"
        }
      }, 
      {
        id: "minecraft:oak_stairs", 
        properties: {
          half: "top", 
          waterlogged: "false", 
          shape: "outer_right", 
          facing: "south"
        }
      }, 
      {
        id: "minecraft:oak_trapdoor", 
        properties: {
          half: "top", 
          waterlogged: "false", 
          powered: "false", 
          facing: "south", 
          open: "false"
        }
      }, 
      {
        id: "minecraft:oak_trapdoor", 
        properties: {
          half: "top", 
          waterlogged: "false", 
          powered: "false", 
          facing: "north", 
          open: "false"
        }
      }, 
      {
        id: "minecraft:oak_trapdoor", 
        properties: {
          half: "top", 
          waterlogged: "false", 
          powered: "false", 
          facing: "east", 
          open: "false"
        }
      }, 
      {
        id: "minecraft:oak_trapdoor", 
        properties: {
          half: "top", 
          waterlogged: "false", 
          powered: "false", 
          facing: "west", 
          open: "false"
        }
      }, 
      {
        id: "minecraft:spruce_stairs", 
        properties: {
          half: "top", 
          waterlogged: "false", 
          shape: "outer_right", 
          facing: "east"
        }
      }, 
      {
        id: "minecraft:spruce_fence", 
        properties: {
          east: "false", 
          waterlogged: "false", 
          south: "false", 
          north: "false", 
          west: "false"
        }
      }, 
      {
        id: "minecraft:spruce_stairs", 
        properties: {
          half: "bottom", 
          waterlogged: "false", 
          shape: "outer_right", 
          facing: "north"
        }
      }, 
      {
        id: "minecraft:oak_stairs", 
        properties: {
          half: "bottom", 
          waterlogged: "false", 
          shape: "outer_right", 
          facing: "north"
        }
      }, 
      {
        id: "minecraft:oak_stairs", 
        properties: {
          half: "bottom", 
          waterlogged: "false", 
          shape: "outer_right", 
          facing: "south"
        }
      }, 
      {
        id: "minecraft:chest", 
        properties: {
          waterlogged: "false", 
          facing: "south", 
          type: "single"
        }
      }, 
      {
        id: "minecraft:structure_block", 
        properties: {
          mode: "data"
        }
      }
    ], 
    [
      {
        id: "minecraft:spruce_planks"
      }, 
      {
        id: "minecraft:jungle_planks"
      }, 
      {
        id: "minecraft:jungle_log", 
        properties: {
          axis: "y"
        }
      }, 
      {
        id: "minecraft:spruce_stairs", 
        properties: {
          half: "top", 
          waterlogged: "false", 
          shape: "outer_right", 
          facing: "south"
        }
      }, 
      {
        id: "minecraft:spruce_stairs", 
        properties: {
          half: "top", 
          waterlogged: "false", 
          shape: "outer_right", 
          facing: "north"
        }
      }, 
      {
        id: "minecraft:jungle_stairs", 
        properties: {
          half: "top", 
          waterlogged: "false", 
          shape: "outer_right", 
          facing: "east"
        }
      }, 
      {
        id: "minecraft:jungle_stairs", 
        properties: {
          half: "top", 
          waterlogged: "false", 
          shape: "outer_right", 
          facing: "west"
        }
      }, 
      {
        id: "minecraft:jungle_stairs", 
        properties: {
          half: "bottom", 
          waterlogged: "false", 
          shape: "outer_right", 
          facing: "west"
        }
      }, 
      {
        id: "minecraft:jungle_door", 
        properties: {
          hinge: "right", 
          half: "lower", 
          powered: "false", 
          facing: "south", 
          open: "false"
        }
      }, 
      {
        id: "minecraft:jungle_stairs", 
        properties: {
          half: "bottom", 
          waterlogged: "false", 
          shape: "outer_right", 
          facing: "east"
        }
      }, 
      {
        id: "minecraft:jungle_door", 
        properties: {
          hinge: "left", 
          half: "upper", 
          powered: "false", 
          facing: "east", 
          open: "false"
        }
      }, 
      {
        id: "minecraft:spruce_stairs", 
        properties: {
          half: "top", 
          waterlogged: "false", 
          shape: "outer_right", 
          facing: "west"
        }
      }, 
      {
        id: "minecraft:jungle_stairs", 
        properties: {
          half: "top", 
          waterlogged: "false", 
          shape: "outer_right", 
          facing: "south"
        }
      }, 
      {
        id: "minecraft:jungle_trapdoor", 
        properties: {
          half: "top", 
          waterlogged: "false", 
          powered: "false", 
          facing: "south", 
          open: "false"
        }
      }, 
      {
        id: "minecraft:jungle_trapdoor", 
        properties: {
          half: "top", 
          waterlogged: "false", 
          powered: "false", 
          facing: "north", 
          open: "false"
        }
      }, 
      {
        id: "minecraft:jungle_trapdoor", 
        properties: {
          half: "top", 
          waterlogged: "false", 
          powered: "false", 
          facing: "east", 
          open: "false"
        }
      }, 
      {
        id: "minecraft:jungle_trapdoor", 
        properties: {
          half: "top", 
          waterlogged: "false", 
          powered: "false", 
          facing: "west", 
          open: "false"
        }
      }, 
      {
        id: "minecraft:spruce_stairs", 
        properties: {
          half: "top", 
          waterlogged: "false", 
          shape: "outer_right", 
          facing: "east"
        }
      }, 
      {
        id: "minecraft:spruce_fence", 
        properties: {
          east: "false", 
          waterlogged: "false", 
          south: "false", 
          north: "false", 
          west: "false"
        }
      }, 
      {
        id: "minecraft:spruce_stairs", 
        properties: {
          half: "bottom", 
          waterlogged: "false", 
          shape: "outer_right", 
          facing: "north"
        }
      }, 
      {
        id: "minecraft:jungle_stairs", 
        properties: {
          half: "bottom", 
          waterlogged: "false", 
          shape: "outer_right", 
          facing: "north"
        }
      }, 
      {
        id: "minecraft:jungle_stairs", 
        properties: {
          half: "bottom", 
          waterlogged: "false", 
          shape: "outer_right", 
          facing: "south"
        }
      }, 
      {
        id: "minecraft:chest", 
        properties: {
          waterlogged: "false", 
          facing: "south", 
          type: "single"
        }
      }, 
      {
        id: "minecraft:structure_block", 
        properties: {
          mode: "data"
        }
      }
    ], 
    [
      {
        id: "minecraft:jungle_planks"
      }, 
      {
        id: "minecraft:dark_oak_planks"
      }, 
      {
        id: "minecraft:dark_oak_log", 
        properties: {
          axis: "y"
        }
      }, 
      {
        id: "minecraft:jungle_stairs", 
        properties: {
          half: "top", 
          waterlogged: "false", 
          shape: "outer_right", 
          facing: "south"
        }
      }, 
      {
        id: "minecraft:jungle_stairs", 
        properties: {
          half: "top", 
          waterlogged: "false", 
          shape: "outer_right", 
          facing: "north"
        }
      }, 
      {
        id: "minecraft:dark_oak_stairs", 
        properties: {
          half: "top", 
          waterlogged: "false", 
          shape: "outer_right", 
          facing: "east"
        }
      }, 
      {
        id: "minecraft:dark_oak_stairs", 
        properties: {
          half: "top", 
          waterlogged: "false", 
          shape: "outer_right", 
          facing: "west"
        }
      }, 
      {
        id: "minecraft:dark_oak_stairs", 
        properties: {
          half: "bottom", 
          waterlogged: "false", 
          shape: "outer_right", 
          facing: "west"
        }
      }, 
      {
        id: "minecraft:dark_oak_door", 
        properties: {
          hinge: "right", 
          half: "lower", 
          powered: "false", 
          facing: "south", 
          open: "false"
        }
      }, 
      {
        id: "minecraft:dark_oak_stairs", 
        properties: {
          half: "bottom", 
          waterlogged: "false", 
          shape: "outer_right", 
          facing: "east"
        }
      }, 
      {
        id: "minecraft:dark_oak_door", 
        properties: {
          hinge: "left", 
          half: "upper", 
          powered: "false", 
          facing: "east", 
          open: "false"
        }
      }, 
      {
        id: "minecraft:jungle_stairs", 
        properties: {
          half: "top", 
          waterlogged: "false", 
          shape: "outer_right", 
          facing: "west"
        }
      }, 
      {
        id: "minecraft:dark_oak_stairs", 
        properties: {
          half: "top", 
          waterlogged: "false", 
          shape: "outer_right", 
          facing: "south"
        }
      }, 
      {
        id: "minecraft:dark_oak_trapdoor", 
        properties: {
          half: "top", 
          waterlogged: "false", 
          powered: "false", 
          facing: "south", 
          open: "false"
        }
      }, 
      {
        id: "minecraft:dark_oak_trapdoor", 
        properties: {
          half: "top", 
          waterlogged: "false", 
          powered: "false", 
          facing: "north", 
          open: "false"
        }
      }, 
      {
        id: "minecraft:dark_oak_trapdoor", 
        properties: {
          half: "top", 
          waterlogged: "false", 
          powered: "false", 
          facing: "east", 
          open: "false"
        }
      }, 
      {
        id: "minecraft:dark_oak_trapdoor", 
        properties: {
          half: "top", 
          waterlogged: "false", 
          powered: "false", 
          facing: "west", 
          open: "false"
        }
      }, 
      {
        id: "minecraft:jungle_stairs", 
        properties: {
          half: "top", 
          waterlogged: "false", 
          shape: "outer_right", 
          facing: "east"
        }
      }, 
      {
        id: "minecraft:jungle_fence", 
        properties: {
          east: "false", 
          waterlogged: "false", 
          south: "false", 
          north: "false", 
          west: "false"
        }
      }, 
      {
        id: "minecraft:jungle_stairs", 
        properties: {
          half: "bottom", 
          waterlogged: "false", 
          shape: "outer_right", 
          facing: "north"
        }
      }, 
      {
        id: "minecraft:dark_oak_stairs", 
        properties: {
          half: "bottom", 
          waterlogged: "false", 
          shape: "outer_right", 
          facing: "north"
        }
      }, 
      {
        id: "minecraft:dark_oak_stairs", 
        properties: {
          half: "bottom", 
          waterlogged: "false", 
          shape: "outer_right", 
          facing: "south"
        }
      }, 
      {
        id: "minecraft:chest", 
        properties: {
          waterlogged: "false", 
          facing: "south", 
          type: "single"
        }
      }, 
      {
        id: "minecraft:structure_block", 
        properties: {
          mode: "data"
        }
      }
    ], 
    [
      {
        id: "minecraft:spruce_planks"
      }, 
      {
        id: "minecraft:dark_oak_planks"
      }, 
      {
        id: "minecraft:dark_oak_log", 
        properties: {
          axis: "y"
        }
      }, 
      {
        id: "minecraft:spruce_stairs", 
        properties: {
          half: "top", 
          waterlogged: "false", 
          shape: "outer_right", 
          facing: "south"
        }
      }, 
      {
        id: "minecraft:spruce_stairs", 
        properties: {
          half: "top", 
          waterlogged: "false", 
          shape: "outer_right", 
          facing: "north"
        }
      }, 
      {
        id: "minecraft:dark_oak_stairs", 
        properties: {
          half: "top", 
          waterlogged: "false", 
          shape: "outer_right", 
          facing: "east"
        }
      }, 
      {
        id: "minecraft:dark_oak_stairs", 
        properties: {
          half: "top", 
          waterlogged: "false", 
          shape: "outer_right", 
          facing: "west"
        }
      }, 
      {
        id: "minecraft:dark_oak_stairs", 
        properties: {
          half: "bottom", 
          waterlogged: "false", 
          shape: "outer_right", 
          facing: "west"
        }
      }, 
      {
        id: "minecraft:dark_oak_door", 
        properties: {
          hinge: "right", 
          half: "lower", 
          powered: "false", 
          facing: "south", 
          open: "false"
        }
      }, 
      {
        id: "minecraft:dark_oak_stairs", 
        properties: {
          half: "bottom", 
          waterlogged: "false", 
          shape: "outer_right", 
          facing: "east"
        }
      }, 
      {
        id: "minecraft:dark_oak_door", 
        properties: {
          hinge: "left", 
          half: "upper", 
          powered: "false", 
          facing: "east", 
          open: "false"
        }
      }, 
      {
        id: "minecraft:spruce_stairs", 
        properties: {
          half: "top", 
          waterlogged: "false", 
          shape: "outer_right", 
          facing: "west"
        }
      }, 
      {
        id: "minecraft:dark_oak_stairs", 
        properties: {
          half: "top", 
          waterlogged: "false", 
          shape: "outer_right", 
          facing: "south"
        }
      }, 
      {
        id: "minecraft:dark_oak_trapdoor", 
        properties: {
          half: "top", 
          waterlogged: "false", 
          powered: "false", 
          facing: "south", 
          open: "false"
        }
      }, 
      {
        id: "minecraft:dark_oak_trapdoor", 
        properties: {
          half: "top", 
          waterlogged: "false", 
          powered: "false", 
          facing: "north", 
          open: "false"
        }
      }, 
      {
        id: "minecraft:dark_oak_trapdoor", 
        properties: {
          half: "top", 
          waterlogged: "false", 
          powered: "false", 
          facing: "east", 
          open: "false"
        }
      }, 
      {
        id: "minecraft:dark_oak_trapdoor", 
        properties: {
          half: "top", 
          waterlogged: "false", 
          powered: "false", 
          facing: "west", 
          open: "false"
        }
      }, 
      {
        id: "minecraft:spruce_stairs", 
        properties: {
          half: "top", 
          waterlogged: "false", 
          shape: "outer_right", 
          facing: "east"
        }
      }, 
      {
        id: "minecraft:spruce_fence", 
        properties: {
          east: "false", 
          waterlogged: "false", 
          south: "false", 
          north: "false", 
          west: "false"
        }
      }, 
      {
        id: "minecraft:spruce_stairs", 
        properties: {
          half: "bottom", 
          waterlogged: "false", 
          shape: "outer_right", 
          facing: "north"
        }
      }, 
      {
        id: "minecraft:dark_oak_stairs", 
        properties: {
          half: "bottom", 
          waterlogged: "false", 
          shape: "outer_right", 
          facing: "north"
        }
      }, 
      {
        id: "minecraft:dark_oak_stairs", 
        properties: {
          half: "bottom", 
          waterlogged: "false", 
          shape: "outer_right", 
          facing: "south"
        }
      }, 
      {
        id: "minecraft:chest", 
        properties: {
          waterlogged: "false", 
          facing: "south", 
          type: "single"
        }
      }, 
      {
        id: "minecraft:structure_block", 
        properties: {
          mode: "data"
        }
      }
    ], 
    [
      {
        id: "minecraft:oak_planks"
      }, 
      {
        id: "minecraft:spruce_planks"
      }, 
      {
        id: "minecraft:spruce_log", 
        properties: {
          axis: "y"
        }
      }, 
      {
        id: "minecraft:oak_stairs", 
        properties: {
          half: "top", 
          waterlogged: "false", 
          shape: "outer_right", 
          facing: "south"
        }
      }, 
      {
        id: "minecraft:oak_stairs", 
        properties: {
          half: "top", 
          waterlogged: "false", 
          shape: "outer_right", 
          facing: "north"
        }
      }, 
      {
        id: "minecraft:spruce_stairs", 
        properties: {
          half: "top", 
          waterlogged: "false", 
          shape: "outer_right", 
          facing: "east"
        }
      }, 
      {
        id: "minecraft:spruce_stairs", 
        properties: {
          half: "top", 
          waterlogged: "false", 
          shape: "outer_right", 
          facing: "west"
        }
      }, 
      {
        id: "minecraft:spruce_stairs", 
        properties: {
          half: "bottom", 
          waterlogged: "false", 
          shape: "outer_right", 
          facing: "west"
        }
      }, 
      {
        id: "minecraft:spruce_door", 
        properties: {
          hinge: "right", 
          half: "lower", 
          powered: "false", 
          facing: "south", 
          open: "false"
        }
      }, 
      {
        id: "minecraft:spruce_stairs", 
        properties: {
          half: "bottom", 
          waterlogged: "false", 
          shape: "outer_right", 
          facing: "east"
        }
      }, 
      {
        id: "minecraft:spruce_door", 
        properties: {
          hinge: "left", 
          half: "upper", 
          powered: "false", 
          facing: "east", 
          open: "false"
        }
      }, 
      {
        id: "minecraft:oak_stairs", 
        properties: {
          half: "top", 
          waterlogged: "false", 
          shape: "outer_right", 
          facing: "west"
        }
      }, 
      {
        id: "minecraft:spruce_stairs", 
        properties: {
          half: "top", 
          waterlogged: "false", 
          shape: "outer_right", 
          facing: "south"
        }
      }, 
      {
        id: "minecraft:spruce_trapdoor", 
        properties: {
          half: "top", 
          waterlogged: "false", 
          powered: "false", 
          facing: "south", 
          open: "false"
        }
      }, 
      {
        id: "minecraft:spruce_trapdoor", 
        properties: {
          half: "top", 
          waterlogged: "false", 
          powered: "false", 
          facing: "north", 
          open: "false"
        }
      }, 
      {
        id: "minecraft:spruce_trapdoor", 
        properties: {
          half: "top", 
          waterlogged: "false", 
          powered: "false", 
          facing: "east", 
          open: "false"
        }
      }, 
      {
        id: "minecraft:spruce_trapdoor", 
        properties: {
          half: "top", 
          waterlogged: "false", 
          powered: "false", 
          facing: "west", 
          open: "false"
        }
      }, 
      {
        id: "minecraft:oak_stairs", 
        properties: {
          half: "top", 
          waterlogged: "false", 
          shape: "outer_right", 
          facing: "east"
        }
      }, 
      {
        id: "minecraft:oak_fence", 
        properties: {
          east: "false", 
          waterlogged: "false", 
          south: "false", 
          north: "false", 
          west: "false"
        }
      }, 
      {
        id: "minecraft:oak_stairs", 
        properties: {
          half: "bottom", 
          waterlogged: "false", 
          shape: "outer_right", 
          facing: "north"
        }
      }, 
      {
        id: "minecraft:spruce_stairs", 
        properties: {
          half: "bottom", 
          waterlogged: "false", 
          shape: "outer_right", 
          facing: "north"
        }
      }, 
      {
        id: "minecraft:spruce_stairs", 
        properties: {
          half: "bottom", 
          waterlogged: "false", 
          shape: "outer_right", 
          facing: "south"
        }
      }, 
      {
        id: "minecraft:chest", 
        properties: {
          waterlogged: "false", 
          facing: "south", 
          type: "single"
        }
      }, 
      {
        id: "minecraft:structure_block", 
        properties: {
          mode: "data"
        }
      }
    ], 
    [
      {
        id: "minecraft:jungle_planks"
      }, 
      {
        id: "minecraft:spruce_planks"
      }, 
      {
        id: "minecraft:spruce_log", 
        properties: {
          axis: "y"
        }
      }, 
      {
        id: "minecraft:jungle_stairs", 
        properties: {
          half: "top", 
          waterlogged: "false", 
          shape: "outer_right", 
          facing: "south"
        }
      }, 
      {
        id: "minecraft:jungle_stairs", 
        properties: {
          half: "top", 
          waterlogged: "false", 
          shape: "outer_right", 
          facing: "north"
        }
      }, 
      {
        id: "minecraft:spruce_stairs", 
        properties: {
          half: "top", 
          waterlogged: "false", 
          shape: "outer_right", 
          facing: "east"
        }
      }, 
      {
        id: "minecraft:spruce_stairs", 
        properties: {
          half: "top", 
          waterlogged: "false", 
          shape: "outer_right", 
          facing: "west"
        }
      }, 
      {
        id: "minecraft:spruce_stairs", 
        properties: {
          half: "bottom", 
          waterlogged: "false", 
          shape: "outer_right", 
          facing: "west"
        }
      }, 
      {
        id: "minecraft:spruce_door", 
        properties: {
          hinge: "right", 
          half: "lower", 
          powered: "false", 
          facing: "south", 
          open: "false"
        }
      }, 
      {
        id: "minecraft:spruce_stairs", 
        properties: {
          half: "bottom", 
          waterlogged: "false", 
          shape: "outer_right", 
          facing: "east"
        }
      }, 
      {
        id: "minecraft:spruce_door", 
        properties: {
          hinge: "left", 
          half: "upper", 
          powered: "false", 
          facing: "east", 
          open: "false"
        }
      }, 
      {
        id: "minecraft:jungle_stairs", 
        properties: {
          half: "top", 
          waterlogged: "false", 
          shape: "outer_right", 
          facing: "west"
        }
      }, 
      {
        id: "minecraft:spruce_stairs", 
        properties: {
          half: "top", 
          waterlogged: "false", 
          shape: "outer_right", 
          facing: "south"
        }
      }, 
      {
        id: "minecraft:spruce_trapdoor", 
        properties: {
          half: "top", 
          waterlogged: "false", 
          powered: "false", 
          facing: "south", 
          open: "false"
        }
      }, 
      {
        id: "minecraft:spruce_trapdoor", 
        properties: {
          half: "top", 
          waterlogged: "false", 
          powered: "false", 
          facing: "north", 
          open: "false"
        }
      }, 
      {
        id: "minecraft:spruce_trapdoor", 
        properties: {
          half: "top", 
          waterlogged: "false", 
          powered: "false", 
          facing: "east", 
          open: "false"
        }
      }, 
      {
        id: "minecraft:spruce_trapdoor", 
        properties: {
          half: "top", 
          waterlogged: "false", 
          powered: "false", 
          facing: "west", 
          open: "false"
        }
      }, 
      {
        id: "minecraft:jungle_stairs", 
        properties: {
          half: "top", 
          waterlogged: "false", 
          shape: "outer_right", 
          facing: "east"
        }
      }, 
      {
        id: "minecraft:jungle_fence", 
        properties: {
          east: "false", 
          waterlogged: "false", 
          south: "false", 
          north: "false", 
          west: "false"
        }
      }, 
      {
        id: "minecraft:jungle_stairs", 
        properties: {
          half: "bottom", 
          waterlogged: "false", 
          shape: "outer_right", 
          facing: "north"
        }
      }, 
      {
        id: "minecraft:spruce_stairs", 
        properties: {
          half: "bottom", 
          waterlogged: "false", 
          shape: "outer_right", 
          facing: "north"
        }
      }, 
      {
        id: "minecraft:spruce_stairs", 
        properties: {
          half: "bottom", 
          waterlogged: "false", 
          shape: "outer_right", 
          facing: "south"
        }
      }, 
      {
        id: "minecraft:chest", 
        properties: {
          waterlogged: "false", 
          facing: "south", 
          type: "single"
        }
      }, 
      {
        id: "minecraft:structure_block", 
        properties: {
          mode: "data"
        }
      }
    ], 
    [
      {
        id: "minecraft:dark_oak_planks"
      }, 
      {
        id: "minecraft:spruce_planks"
      }, 
      {
        id: "minecraft:spruce_log", 
        properties: {
          axis: "y"
        }
      }, 
      {
        id: "minecraft:dark_oak_stairs", 
        properties: {
          half: "top", 
          waterlogged: "false", 
          shape: "outer_right", 
          facing: "south"
        }
      }, 
      {
        id: "minecraft:dark_oak_stairs", 
        properties: {
          half: "top", 
          waterlogged: "false", 
          shape: "outer_right", 
          facing: "north"
        }
      }, 
      {
        id: "minecraft:spruce_stairs", 
        properties: {
          half: "top", 
          waterlogged: "false", 
          shape: "outer_right", 
          facing: "east"
        }
      }, 
      {
        id: "minecraft:spruce_stairs", 
        properties: {
          half: "top", 
          waterlogged: "false", 
          shape: "outer_right", 
          facing: "west"
        }
      }, 
      {
        id: "minecraft:spruce_stairs", 
        properties: {
          half: "bottom", 
          waterlogged: "false", 
          shape: "outer_right", 
          facing: "west"
        }
      }, 
      {
        id: "minecraft:spruce_door", 
        properties: {
          hinge: "right", 
          half: "lower", 
          powered: "false", 
          facing: "south", 
          open: "false"
        }
      }, 
      {
        id: "minecraft:spruce_stairs", 
        properties: {
          half: "bottom", 
          waterlogged: "false", 
          shape: "outer_right", 
          facing: "east"
        }
      }, 
      {
        id: "minecraft:spruce_door", 
        properties: {
          hinge: "left", 
          half: "upper", 
          powered: "false", 
          facing: "east", 
          open: "false"
        }
      }, 
      {
        id: "minecraft:dark_oak_stairs", 
        properties: {
          half: "top", 
          waterlogged: "false", 
          shape: "outer_right", 
          facing: "west"
        }
      }, 
      {
        id: "minecraft:spruce_stairs", 
        properties: {
          half: "top", 
          waterlogged: "false", 
          shape: "outer_right", 
          facing: "south"
        }
      }, 
      {
        id: "minecraft:spruce_trapdoor", 
        properties: {
          half: "top", 
          waterlogged: "false", 
          powered: "false", 
          facing: "south", 
          open: "false"
        }
      }, 
      {
        id: "minecraft:spruce_trapdoor", 
        properties: {
          half: "top", 
          waterlogged: "false", 
          powered: "false", 
          facing: "north", 
          open: "false"
        }
      }, 
      {
        id: "minecraft:spruce_trapdoor", 
        properties: {
          half: "top", 
          waterlogged: "false", 
          powered: "false", 
          facing: "east", 
          open: "false"
        }
      }, 
      {
        id: "minecraft:spruce_trapdoor", 
        properties: {
          half: "top", 
          waterlogged: "false", 
          powered: "false", 
          facing: "west", 
          open: "false"
        }
      }, 
      {
        id: "minecraft:dark_oak_stairs", 
        properties: {
          half: "top", 
          waterlogged: "false", 
          shape: "outer_right", 
          facing: "east"
        }
      }, 
      {
        id: "minecraft:dark_oak_fence", 
        properties: {
          east: "false", 
          waterlogged: "false", 
          south: "false", 
          north: "false", 
          west: "false"
        }
      }, 
      {
        id: "minecraft:dark_oak_stairs", 
        properties: {
          half: "bottom", 
          waterlogged: "false", 
          shape: "outer_right", 
          facing: "north"
        }
      }, 
      {
        id: "minecraft:spruce_stairs", 
        properties: {
          half: "bottom", 
          waterlogged: "false", 
          shape: "outer_right", 
          facing: "north"
        }
      }, 
      {
        id: "minecraft:spruce_stairs", 
        properties: {
          half: "bottom", 
          waterlogged: "false", 
          shape: "outer_right", 
          facing: "south"
        }
      }, 
      {
        id: "minecraft:chest", 
        properties: {
          waterlogged: "false", 
          facing: "south", 
          type: "single"
        }
      }, 
      {
        id: "minecraft:structure_block", 
        properties: {
          mode: "data"
        }
      }
    ], 
    [
      {
        id: "minecraft:birch_planks"
      }, 
      {
        id: "minecraft:oak_planks"
      }, 
      {
        id: "minecraft:oak_log", 
        properties: {
          axis: "y"
        }
      }, 
      {
        id: "minecraft:birch_stairs", 
        properties: {
          half: "top", 
          waterlogged: "false", 
          shape: "outer_right", 
          facing: "south"
        }
      }, 
      {
        id: "minecraft:birch_stairs", 
        properties: {
          half: "top", 
          waterlogged: "false", 
          shape: "outer_right", 
          facing: "north"
        }
      }, 
      {
        id: "minecraft:oak_stairs", 
        properties: {
          half: "top", 
          waterlogged: "false", 
          shape: "outer_right", 
          facing: "east"
        }
      }, 
      {
        id: "minecraft:oak_stairs", 
        properties: {
          half: "top", 
          waterlogged: "false", 
          shape: "outer_right", 
          facing: "west"
        }
      }, 
      {
        id: "minecraft:oak_stairs", 
        properties: {
          half: "bottom", 
          waterlogged: "false", 
          shape: "outer_right", 
          facing: "west"
        }
      }, 
      {
        id: "minecraft:oak_door", 
        properties: {
          hinge: "right", 
          half: "lower", 
          powered: "false", 
          facing: "south", 
          open: "false"
        }
      }, 
      {
        id: "minecraft:oak_stairs", 
        properties: {
          half: "bottom", 
          waterlogged: "false", 
          shape: "outer_right", 
          facing: "east"
        }
      }, 
      {
        id: "minecraft:oak_door", 
        properties: {
          hinge: "left", 
          half: "upper", 
          powered: "false", 
          facing: "east", 
          open: "false"
        }
      }, 
      {
        id: "minecraft:birch_stairs", 
        properties: {
          half: "top", 
          waterlogged: "false", 
          shape: "outer_right", 
          facing: "west"
        }
      }, 
      {
        id: "minecraft:oak_stairs", 
        properties: {
          half: "top", 
          waterlogged: "false", 
          shape: "outer_right", 
          facing: "south"
        }
      }, 
      {
        id: "minecraft:oak_trapdoor", 
        properties: {
          half: "top", 
          waterlogged: "false", 
          powered: "false", 
          facing: "south", 
          open: "false"
        }
      }, 
      {
        id: "minecraft:oak_trapdoor", 
        properties: {
          half: "top", 
          waterlogged: "false", 
          powered: "false", 
          facing: "north", 
          open: "false"
        }
      }, 
      {
        id: "minecraft:oak_trapdoor", 
        properties: {
          half: "top", 
          waterlogged: "false", 
          powered: "false", 
          facing: "east", 
          open: "false"
        }
      }, 
      {
        id: "minecraft:oak_trapdoor", 
        properties: {
          half: "top", 
          waterlogged: "false", 
          powered: "false", 
          facing: "west", 
          open: "false"
        }
      }, 
      {
        id: "minecraft:birch_stairs", 
        properties: {
          half: "top", 
          waterlogged: "false", 
          shape: "outer_right", 
          facing: "east"
        }
      }, 
      {
        id: "minecraft:birch_fence", 
        properties: {
          east: "false", 
          waterlogged: "false", 
          south: "false", 
          north: "false", 
          west: "false"
        }
      }, 
      {
        id: "minecraft:birch_stairs", 
        properties: {
          half: "bottom", 
          waterlogged: "false", 
          shape: "outer_right", 
          facing: "north"
        }
      }, 
      {
        id: "minecraft:oak_stairs", 
        properties: {
          half: "bottom", 
          waterlogged: "false", 
          shape: "outer_right", 
          facing: "north"
        }
      }, 
      {
        id: "minecraft:oak_stairs", 
        properties: {
          half: "bottom", 
          waterlogged: "false", 
          shape: "outer_right", 
          facing: "south"
        }
      }, 
      {
        id: "minecraft:chest", 
        properties: {
          waterlogged: "false", 
          facing: "south", 
          type: "single"
        }
      }, 
      {
        id: "minecraft:structure_block", 
        properties: {
          mode: "data"
        }
      }
    ]
  ]
}
