{
  size: [5, 15, 24], 
  entities: [], 
  blocks: [
    {
      pos: [4, 0, 1], 
      state: 0
    }, 
    {
      pos: [4, 0, 5], 
      state: 0
    }, 
    {
      pos: [0, 0, 9], 
      state: 1
    }, 
    {
      pos: [1, 0, 9], 
      state: 1
    }, 
    {
      pos: [2, 0, 9], 
      state: 1
    }, 
    {
      pos: [3, 0, 9], 
      state: 0
    }, 
    {
      pos: [4, 0, 9], 
      state: 0
    }, 
    {
      pos: [0, 0, 10], 
      state: 0
    }, 
    {
      pos: [1, 0, 10], 
      state: 0
    }, 
    {
      pos: [2, 0, 10], 
      state: 0
    }, 
    {
      pos: [3, 0, 10], 
      state: 0
    }, 
    {
      pos: [4, 0, 10], 
      state: 0
    }, 
    {
      pos: [0, 0, 11], 
      state: 0
    }, 
    {
      pos: [2, 0, 11], 
      state: 1
    }, 
    {
      pos: [3, 0, 11], 
      state: 0
    }, 
    {
      pos: [0, 0, 12], 
      state: 0
    }, 
    {
      pos: [3, 0, 12], 
      state: 1
    }, 
    {
      pos: [4, 0, 12], 
      state: 0
    }, 
    {
      pos: [0, 0, 13], 
      state: 0
    }, 
    {
      pos: [2, 0, 13], 
      state: 1
    }, 
    {
      pos: [3, 0, 13], 
      state: 0
    }, 
    {
      pos: [4, 0, 13], 
      state: 0
    }, 
    {
      pos: [0, 0, 14], 
      state: 0
    }, 
    {
      pos: [1, 0, 14], 
      state: 0
    }, 
    {
      pos: [2, 0, 14], 
      state: 0
    }, 
    {
      pos: [3, 0, 14], 
      state: 0
    }, 
    {
      pos: [4, 0, 14], 
      state: 0
    }, 
    {
      pos: [0, 0, 16], 
      state: 0
    }, 
    {
      pos: [0, 0, 18], 
      state: 1
    }, 
    {
      pos: [1, 0, 18], 
      state: 1
    }, 
    {
      pos: [4, 0, 18], 
      state: 0
    }, 
    {
      pos: [1, 0, 19], 
      state: 1
    }, 
    {
      pos: [4, 0, 19], 
      state: 1
    }, 
    {
      pos: [2, 0, 21], 
      state: 1
    }, 
    {
      pos: [4, 0, 22], 
      state: 0
    }, 
    {
      nbt: {
        joint: "rollable", 
        final_state: "minecraft:air", 
        name: "minecraft:empty", 
        pool: "minecraft:bastion/treasure/corners/middle", 
        id: "minecraft:jigsaw", 
        target: "minecraft:corner_connector"
      }, 
      pos: [3, 0, 0], 
      state: 2
    }, 
    {
      nbt: {
        joint: "rollable", 
        final_state: "minecraft:polished_basalt", 
        name: "minecraft:center_connector", 
        pool: "minecraft:empty", 
        id: "minecraft:jigsaw", 
        target: "minecraft:empty"
      }, 
      pos: [4, 0, 11], 
      state: 3
    }, 
    {
      nbt: {
        joint: "rollable", 
        final_state: "minecraft:polished_blackstone_bricks", 
        name: "minecraft:empty", 
        pool: "minecraft:bastion/treasure/walls/outer", 
        id: "minecraft:jigsaw", 
        target: "minecraft:outer_wall_connector"
      }, 
      pos: [0, 0, 23], 
      state: 4
    }, 
    {
      nbt: {
        joint: "rollable", 
        final_state: "minecraft:air", 
        name: "minecraft:empty", 
        pool: "minecraft:bastion/treasure/corners/middle", 
        id: "minecraft:jigsaw", 
        target: "minecraft:corner_connector"
      }, 
      pos: [3, 0, 23], 
      state: 5
    }, 
    {
      pos: [0, 0, 0], 
      state: 6
    }, 
    {
      pos: [1, 0, 0], 
      state: 6
    }, 
    {
      pos: [2, 0, 0], 
      state: 6
    }, 
    {
      pos: [4, 0, 0], 
      state: 6
    }, 
    {
      pos: [0, 0, 1], 
      state: 6
    }, 
    {
      pos: [1, 0, 1], 
      state: 6
    }, 
    {
      pos: [2, 0, 1], 
      state: 6
    }, 
    {
      pos: [3, 0, 1], 
      state: 6
    }, 
    {
      pos: [0, 0, 2], 
      state: 6
    }, 
    {
      pos: [1, 0, 2], 
      state: 6
    }, 
    {
      pos: [2, 0, 2], 
      state: 6
    }, 
    {
      pos: [3, 0, 2], 
      state: 6
    }, 
    {
      pos: [4, 0, 2], 
      state: 6
    }, 
    {
      pos: [0, 0, 3], 
      state: 6
    }, 
    {
      pos: [1, 0, 3], 
      state: 6
    }, 
    {
      pos: [2, 0, 3], 
      state: 6
    }, 
    {
      pos: [3, 0, 3], 
      state: 6
    }, 
    {
      pos: [4, 0, 3], 
      state: 6
    }, 
    {
      pos: [0, 0, 4], 
      state: 6
    }, 
    {
      pos: [1, 0, 4], 
      state: 6
    }, 
    {
      pos: [2, 0, 4], 
      state: 6
    }, 
    {
      pos: [3, 0, 4], 
      state: 6
    }, 
    {
      pos: [4, 0, 4], 
      state: 6
    }, 
    {
      pos: [0, 0, 5], 
      state: 6
    }, 
    {
      pos: [1, 0, 5], 
      state: 6
    }, 
    {
      pos: [2, 0, 5], 
      state: 6
    }, 
    {
      pos: [3, 0, 5], 
      state: 6
    }, 
    {
      pos: [0, 0, 6], 
      state: 6
    }, 
    {
      pos: [1, 0, 6], 
      state: 6
    }, 
    {
      pos: [2, 0, 6], 
      state: 6
    }, 
    {
      pos: [3, 0, 6], 
      state: 6
    }, 
    {
      pos: [4, 0, 6], 
      state: 6
    }, 
    {
      pos: [0, 0, 7], 
      state: 6
    }, 
    {
      pos: [1, 0, 7], 
      state: 6
    }, 
    {
      pos: [2, 0, 7], 
      state: 6
    }, 
    {
      pos: [3, 0, 7], 
      state: 6
    }, 
    {
      pos: [4, 0, 7], 
      state: 6
    }, 
    {
      pos: [0, 0, 8], 
      state: 6
    }, 
    {
      pos: [1, 0, 8], 
      state: 6
    }, 
    {
      pos: [2, 0, 8], 
      state: 6
    }, 
    {
      pos: [3, 0, 8], 
      state: 6
    }, 
    {
      pos: [4, 0, 8], 
      state: 6
    }, 
    {
      pos: [1, 0, 11], 
      state: 6
    }, 
    {
      pos: [1, 0, 12], 
      state: 6
    }, 
    {
      pos: [2, 0, 12], 
      state: 6
    }, 
    {
      pos: [1, 0, 13], 
      state: 6
    }, 
    {
      pos: [0, 0, 15], 
      state: 6
    }, 
    {
      pos: [1, 0, 15], 
      state: 6
    }, 
    {
      pos: [2, 0, 15], 
      state: 6
    }, 
    {
      pos: [3, 0, 15], 
      state: 6
    }, 
    {
      pos: [4, 0, 15], 
      state: 6
    }, 
    {
      pos: [1, 0, 16], 
      state: 6
    }, 
    {
      pos: [2, 0, 16], 
      state: 6
    }, 
    {
      pos: [3, 0, 16], 
      state: 6
    }, 
    {
      pos: [4, 0, 16], 
      state: 6
    }, 
    {
      pos: [0, 0, 17], 
      state: 6
    }, 
    {
      pos: [1, 0, 17], 
      state: 6
    }, 
    {
      pos: [2, 0, 17], 
      state: 6
    }, 
    {
      pos: [3, 0, 17], 
      state: 6
    }, 
    {
      pos: [4, 0, 17], 
      state: 6
    }, 
    {
      pos: [2, 0, 18], 
      state: 6
    }, 
    {
      pos: [3, 0, 18], 
      state: 6
    }, 
    {
      pos: [0, 0, 19], 
      state: 6
    }, 
    {
      pos: [2, 0, 19], 
      state: 6
    }, 
    {
      pos: [3, 0, 19], 
      state: 6
    }, 
    {
      pos: [0, 0, 20], 
      state: 6
    }, 
    {
      pos: [1, 0, 20], 
      state: 6
    }, 
    {
      pos: [2, 0, 20], 
      state: 6
    }, 
    {
      pos: [3, 0, 20], 
      state: 6
    }, 
    {
      pos: [4, 0, 20], 
      state: 6
    }, 
    {
      pos: [0, 0, 21], 
      state: 6
    }, 
    {
      pos: [1, 0, 21], 
      state: 6
    }, 
    {
      pos: [3, 0, 21], 
      state: 6
    }, 
    {
      pos: [4, 0, 21], 
      state: 6
    }, 
    {
      pos: [0, 0, 22], 
      state: 6
    }, 
    {
      pos: [1, 0, 22], 
      state: 6
    }, 
    {
      pos: [2, 0, 22], 
      state: 6
    }, 
    {
      pos: [3, 0, 22], 
      state: 6
    }, 
    {
      pos: [1, 0, 23], 
      state: 6
    }, 
    {
      pos: [2, 0, 23], 
      state: 6
    }, 
    {
      pos: [4, 0, 23], 
      state: 6
    }, 
    {
      pos: [4, 1, 0], 
      state: 0
    }, 
    {
      pos: [4, 1, 1], 
      state: 0
    }, 
    {
      pos: [4, 1, 2], 
      state: 0
    }, 
    {
      pos: [4, 1, 4], 
      state: 0
    }, 
    {
      pos: [4, 1, 5], 
      state: 0
    }, 
    {
      pos: [4, 1, 6], 
      state: 0
    }, 
    {
      pos: [4, 1, 7], 
      state: 0
    }, 
    {
      pos: [4, 1, 8], 
      state: 0
    }, 
    {
      pos: [0, 1, 9], 
      state: 0
    }, 
    {
      pos: [1, 1, 9], 
      state: 0
    }, 
    {
      pos: [2, 1, 9], 
      state: 1
    }, 
    {
      pos: [3, 1, 9], 
      state: 1
    }, 
    {
      pos: [4, 1, 9], 
      state: 0
    }, 
    {
      pos: [0, 1, 10], 
      state: 0
    }, 
    {
      pos: [1, 1, 10], 
      state: 0
    }, 
    {
      pos: [2, 1, 10], 
      state: 0
    }, 
    {
      pos: [4, 1, 10], 
      state: 0
    }, 
    {
      pos: [0, 1, 11], 
      state: 0
    }, 
    {
      pos: [1, 1, 11], 
      state: 0
    }, 
    {
      pos: [2, 1, 11], 
      state: 1
    }, 
    {
      pos: [4, 1, 11], 
      state: 0
    }, 
    {
      pos: [0, 1, 12], 
      state: 0
    }, 
    {
      pos: [1, 1, 12], 
      state: 1
    }, 
    {
      pos: [2, 1, 12], 
      state: 0
    }, 
    {
      pos: [4, 1, 12], 
      state: 0
    }, 
    {
      pos: [0, 1, 13], 
      state: 0
    }, 
    {
      pos: [1, 1, 13], 
      state: 1
    }, 
    {
      pos: [2, 1, 13], 
      state: 1
    }, 
    {
      pos: [4, 1, 13], 
      state: 0
    }, 
    {
      pos: [0, 1, 14], 
      state: 7
    }, 
    {
      pos: [1, 1, 14], 
      state: 7
    }, 
    {
      pos: [2, 1, 14], 
      state: 0
    }, 
    {
      pos: [3, 1, 14], 
      state: 0
    }, 
    {
      pos: [4, 1, 14], 
      state: 0
    }, 
    {
      pos: [4, 1, 15], 
      state: 0
    }, 
    {
      pos: [4, 1, 17], 
      state: 0
    }, 
    {
      pos: [4, 1, 18], 
      state: 0
    }, 
    {
      pos: [4, 1, 22], 
      state: 1
    }, 
    {
      pos: [4, 1, 23], 
      state: 0
    }, 
    {
      pos: [0, 1, 0], 
      state: 6
    }, 
    {
      pos: [1, 1, 0], 
      state: 6
    }, 
    {
      pos: [2, 1, 0], 
      state: 6
    }, 
    {
      pos: [3, 1, 0], 
      state: 6
    }, 
    {
      pos: [0, 1, 1], 
      state: 6
    }, 
    {
      pos: [1, 1, 1], 
      state: 6
    }, 
    {
      pos: [2, 1, 1], 
      state: 6
    }, 
    {
      pos: [3, 1, 1], 
      state: 6
    }, 
    {
      pos: [0, 1, 2], 
      state: 6
    }, 
    {
      pos: [1, 1, 2], 
      state: 6
    }, 
    {
      pos: [2, 1, 2], 
      state: 6
    }, 
    {
      pos: [3, 1, 2], 
      state: 6
    }, 
    {
      pos: [0, 1, 3], 
      state: 6
    }, 
    {
      pos: [1, 1, 3], 
      state: 6
    }, 
    {
      pos: [2, 1, 3], 
      state: 6
    }, 
    {
      pos: [3, 1, 3], 
      state: 6
    }, 
    {
      pos: [4, 1, 3], 
      state: 6
    }, 
    {
      pos: [0, 1, 4], 
      state: 6
    }, 
    {
      pos: [1, 1, 4], 
      state: 6
    }, 
    {
      pos: [2, 1, 4], 
      state: 6
    }, 
    {
      pos: [3, 1, 4], 
      state: 6
    }, 
    {
      pos: [0, 1, 5], 
      state: 6
    }, 
    {
      pos: [1, 1, 5], 
      state: 6
    }, 
    {
      pos: [2, 1, 5], 
      state: 6
    }, 
    {
      pos: [3, 1, 5], 
      state: 6
    }, 
    {
      pos: [0, 1, 6], 
      state: 6
    }, 
    {
      pos: [1, 1, 6], 
      state: 6
    }, 
    {
      pos: [2, 1, 6], 
      state: 6
    }, 
    {
      pos: [3, 1, 6], 
      state: 6
    }, 
    {
      pos: [0, 1, 7], 
      state: 6
    }, 
    {
      pos: [1, 1, 7], 
      state: 6
    }, 
    {
      pos: [2, 1, 7], 
      state: 6
    }, 
    {
      pos: [3, 1, 7], 
      state: 6
    }, 
    {
      pos: [0, 1, 8], 
      state: 6
    }, 
    {
      pos: [1, 1, 8], 
      state: 6
    }, 
    {
      pos: [2, 1, 8], 
      state: 6
    }, 
    {
      pos: [3, 1, 8], 
      state: 6
    }, 
    {
      pos: [3, 1, 10], 
      state: 8
    }, 
    {
      pos: [3, 1, 11], 
      state: 8
    }, 
    {
      pos: [3, 1, 12], 
      state: 8
    }, 
    {
      pos: [3, 1, 13], 
      state: 8
    }, 
    {
      pos: [0, 1, 15], 
      state: 6
    }, 
    {
      pos: [1, 1, 15], 
      state: 6
    }, 
    {
      pos: [2, 1, 15], 
      state: 6
    }, 
    {
      pos: [3, 1, 15], 
      state: 6
    }, 
    {
      pos: [0, 1, 16], 
      state: 6
    }, 
    {
      pos: [1, 1, 16], 
      state: 6
    }, 
    {
      pos: [2, 1, 16], 
      state: 6
    }, 
    {
      pos: [3, 1, 16], 
      state: 6
    }, 
    {
      pos: [4, 1, 16], 
      state: 6
    }, 
    {
      pos: [0, 1, 17], 
      state: 6
    }, 
    {
      pos: [1, 1, 17], 
      state: 6
    }, 
    {
      pos: [2, 1, 17], 
      state: 6
    }, 
    {
      pos: [3, 1, 17], 
      state: 6
    }, 
    {
      pos: [0, 1, 18], 
      state: 6
    }, 
    {
      pos: [1, 1, 18], 
      state: 6
    }, 
    {
      pos: [2, 1, 18], 
      state: 6
    }, 
    {
      pos: [3, 1, 18], 
      state: 6
    }, 
    {
      pos: [0, 1, 19], 
      state: 6
    }, 
    {
      pos: [1, 1, 19], 
      state: 6
    }, 
    {
      pos: [2, 1, 19], 
      state: 6
    }, 
    {
      pos: [3, 1, 19], 
      state: 6
    }, 
    {
      pos: [4, 1, 19], 
      state: 6
    }, 
    {
      pos: [0, 1, 20], 
      state: 6
    }, 
    {
      pos: [1, 1, 20], 
      state: 6
    }, 
    {
      pos: [2, 1, 20], 
      state: 6
    }, 
    {
      pos: [3, 1, 20], 
      state: 6
    }, 
    {
      pos: [4, 1, 20], 
      state: 6
    }, 
    {
      pos: [0, 1, 21], 
      state: 6
    }, 
    {
      pos: [1, 1, 21], 
      state: 6
    }, 
    {
      pos: [2, 1, 21], 
      state: 6
    }, 
    {
      pos: [3, 1, 21], 
      state: 6
    }, 
    {
      pos: [4, 1, 21], 
      state: 6
    }, 
    {
      pos: [0, 1, 22], 
      state: 6
    }, 
    {
      pos: [1, 1, 22], 
      state: 6
    }, 
    {
      pos: [2, 1, 22], 
      state: 6
    }, 
    {
      pos: [3, 1, 22], 
      state: 6
    }, 
    {
      pos: [0, 1, 23], 
      state: 6
    }, 
    {
      pos: [1, 1, 23], 
      state: 6
    }, 
    {
      pos: [2, 1, 23], 
      state: 6
    }, 
    {
      pos: [3, 1, 23], 
      state: 6
    }, 
    {
      pos: [4, 2, 1], 
      state: 0
    }, 
    {
      pos: [4, 2, 5], 
      state: 0
    }, 
    {
      pos: [1, 2, 9], 
      state: 7
    }, 
    {
      pos: [2, 2, 9], 
      state: 1
    }, 
    {
      pos: [3, 2, 9], 
      state: 1
    }, 
    {
      pos: [4, 2, 9], 
      state: 0
    }, 
    {
      pos: [0, 2, 10], 
      state: 7
    }, 
    {
      pos: [1, 2, 10], 
      state: 7
    }, 
    {
      pos: [2, 2, 10], 
      state: 0
    }, 
    {
      pos: [4, 2, 10], 
      state: 0
    }, 
    {
      pos: [0, 2, 11], 
      state: 7
    }, 
    {
      pos: [1, 2, 11], 
      state: 7
    }, 
    {
      pos: [2, 2, 11], 
      state: 0
    }, 
    {
      pos: [4, 2, 11], 
      state: 9
    }, 
    {
      pos: [0, 2, 12], 
      state: 0
    }, 
    {
      pos: [1, 2, 12], 
      state: 0
    }, 
    {
      pos: [2, 2, 12], 
      state: 0
    }, 
    {
      pos: [0, 2, 13], 
      state: 7
    }, 
    {
      pos: [1, 2, 13], 
      state: 7
    }, 
    {
      pos: [2, 2, 13], 
      state: 1
    }, 
    {
      pos: [4, 2, 13], 
      state: 9
    }, 
    {
      pos: [3, 2, 14], 
      state: 0
    }, 
    {
      pos: [4, 2, 14], 
      state: 0
    }, 
    {
      pos: [4, 2, 15], 
      state: 1
    }, 
    {
      pos: [4, 2, 18], 
      state: 1
    }, 
    {
      pos: [4, 2, 22], 
      state: 0
    }, 
    {
      pos: [0, 2, 0], 
      state: 6
    }, 
    {
      pos: [1, 2, 0], 
      state: 6
    }, 
    {
      pos: [2, 2, 0], 
      state: 6
    }, 
    {
      pos: [3, 2, 0], 
      state: 6
    }, 
    {
      pos: [4, 2, 0], 
      state: 6
    }, 
    {
      pos: [0, 2, 1], 
      state: 6
    }, 
    {
      pos: [1, 2, 1], 
      state: 6
    }, 
    {
      pos: [2, 2, 1], 
      state: 6
    }, 
    {
      pos: [3, 2, 1], 
      state: 6
    }, 
    {
      pos: [0, 2, 2], 
      state: 6
    }, 
    {
      pos: [1, 2, 2], 
      state: 6
    }, 
    {
      pos: [2, 2, 2], 
      state: 6
    }, 
    {
      pos: [3, 2, 2], 
      state: 6
    }, 
    {
      pos: [4, 2, 2], 
      state: 6
    }, 
    {
      pos: [0, 2, 3], 
      state: 6
    }, 
    {
      pos: [1, 2, 3], 
      state: 6
    }, 
    {
      pos: [2, 2, 3], 
      state: 6
    }, 
    {
      pos: [3, 2, 3], 
      state: 6
    }, 
    {
      pos: [4, 2, 3], 
      state: 6
    }, 
    {
      pos: [0, 2, 4], 
      state: 6
    }, 
    {
      pos: [1, 2, 4], 
      state: 6
    }, 
    {
      pos: [2, 2, 4], 
      state: 6
    }, 
    {
      pos: [3, 2, 4], 
      state: 6
    }, 
    {
      pos: [4, 2, 4], 
      state: 6
    }, 
    {
      pos: [0, 2, 5], 
      state: 6
    }, 
    {
      pos: [1, 2, 5], 
      state: 6
    }, 
    {
      pos: [2, 2, 5], 
      state: 6
    }, 
    {
      pos: [3, 2, 5], 
      state: 6
    }, 
    {
      pos: [0, 2, 6], 
      state: 6
    }, 
    {
      pos: [1, 2, 6], 
      state: 6
    }, 
    {
      pos: [2, 2, 6], 
      state: 6
    }, 
    {
      pos: [3, 2, 6], 
      state: 6
    }, 
    {
      pos: [4, 2, 6], 
      state: 6
    }, 
    {
      pos: [0, 2, 7], 
      state: 6
    }, 
    {
      pos: [1, 2, 7], 
      state: 6
    }, 
    {
      pos: [2, 2, 7], 
      state: 6
    }, 
    {
      pos: [3, 2, 7], 
      state: 6
    }, 
    {
      pos: [4, 2, 7], 
      state: 6
    }, 
    {
      pos: [0, 2, 8], 
      state: 6
    }, 
    {
      pos: [1, 2, 8], 
      state: 6
    }, 
    {
      pos: [2, 2, 8], 
      state: 6
    }, 
    {
      pos: [3, 2, 8], 
      state: 6
    }, 
    {
      pos: [4, 2, 8], 
      state: 6
    }, 
    {
      pos: [0, 2, 9], 
      state: 6
    }, 
    {
      pos: [3, 2, 10], 
      state: 10
    }, 
    {
      pos: [3, 2, 11], 
      state: 8
    }, 
    {
      pos: [3, 2, 12], 
      state: 8
    }, 
    {
      pos: [4, 2, 12], 
      state: 6
    }, 
    {
      pos: [3, 2, 13], 
      state: 8
    }, 
    {
      pos: [0, 2, 14], 
      state: 6
    }, 
    {
      pos: [1, 2, 14], 
      state: 6
    }, 
    {
      pos: [2, 2, 14], 
      state: 6
    }, 
    {
      pos: [0, 2, 15], 
      state: 6
    }, 
    {
      pos: [1, 2, 15], 
      state: 6
    }, 
    {
      pos: [2, 2, 15], 
      state: 6
    }, 
    {
      pos: [3, 2, 15], 
      state: 6
    }, 
    {
      pos: [0, 2, 16], 
      state: 6
    }, 
    {
      pos: [1, 2, 16], 
      state: 6
    }, 
    {
      pos: [2, 2, 16], 
      state: 6
    }, 
    {
      pos: [3, 2, 16], 
      state: 6
    }, 
    {
      pos: [4, 2, 16], 
      state: 6
    }, 
    {
      pos: [0, 2, 17], 
      state: 6
    }, 
    {
      pos: [1, 2, 17], 
      state: 6
    }, 
    {
      pos: [2, 2, 17], 
      state: 6
    }, 
    {
      pos: [3, 2, 17], 
      state: 6
    }, 
    {
      pos: [4, 2, 17], 
      state: 6
    }, 
    {
      pos: [0, 2, 18], 
      state: 6
    }, 
    {
      pos: [1, 2, 18], 
      state: 6
    }, 
    {
      pos: [2, 2, 18], 
      state: 6
    }, 
    {
      pos: [3, 2, 18], 
      state: 6
    }, 
    {
      pos: [0, 2, 19], 
      state: 6
    }, 
    {
      pos: [1, 2, 19], 
      state: 6
    }, 
    {
      pos: [2, 2, 19], 
      state: 6
    }, 
    {
      pos: [3, 2, 19], 
      state: 6
    }, 
    {
      pos: [4, 2, 19], 
      state: 6
    }, 
    {
      pos: [0, 2, 20], 
      state: 6
    }, 
    {
      pos: [1, 2, 20], 
      state: 6
    }, 
    {
      pos: [2, 2, 20], 
      state: 6
    }, 
    {
      pos: [3, 2, 20], 
      state: 6
    }, 
    {
      pos: [4, 2, 20], 
      state: 6
    }, 
    {
      pos: [0, 2, 21], 
      state: 6
    }, 
    {
      pos: [1, 2, 21], 
      state: 6
    }, 
    {
      pos: [2, 2, 21], 
      state: 6
    }, 
    {
      pos: [3, 2, 21], 
      state: 6
    }, 
    {
      pos: [4, 2, 21], 
      state: 6
    }, 
    {
      pos: [0, 2, 22], 
      state: 6
    }, 
    {
      pos: [1, 2, 22], 
      state: 6
    }, 
    {
      pos: [2, 2, 22], 
      state: 6
    }, 
    {
      pos: [3, 2, 22], 
      state: 6
    }, 
    {
      pos: [0, 2, 23], 
      state: 6
    }, 
    {
      pos: [1, 2, 23], 
      state: 6
    }, 
    {
      pos: [2, 2, 23], 
      state: 6
    }, 
    {
      pos: [3, 2, 23], 
      state: 6
    }, 
    {
      pos: [4, 2, 23], 
      state: 6
    }, 
    {
      pos: [4, 3, 0], 
      state: 0
    }, 
    {
      pos: [4, 3, 1], 
      state: 0
    }, 
    {
      pos: [4, 3, 4], 
      state: 0
    }, 
    {
      pos: [4, 3, 5], 
      state: 0
    }, 
    {
      pos: [4, 3, 8], 
      state: 0
    }, 
    {
      pos: [2, 3, 9], 
      state: 7
    }, 
    {
      pos: [3, 3, 9], 
      state: 0
    }, 
    {
      pos: [4, 3, 9], 
      state: 0
    }, 
    {
      pos: [1, 3, 10], 
      state: 7
    }, 
    {
      pos: [2, 3, 10], 
      state: 7
    }, 
    {
      pos: [3, 3, 10], 
      state: 0
    }, 
    {
      pos: [4, 3, 10], 
      state: 0
    }, 
    {
      pos: [0, 3, 11], 
      state: 7
    }, 
    {
      pos: [1, 3, 11], 
      state: 0
    }, 
    {
      pos: [2, 3, 11], 
      state: 0
    }, 
    {
      pos: [4, 3, 11], 
      state: 7
    }, 
    {
      pos: [0, 3, 12], 
      state: 0
    }, 
    {
      pos: [2, 3, 12], 
      state: 7
    }, 
    {
      pos: [4, 3, 12], 
      state: 0
    }, 
    {
      pos: [3, 3, 14], 
      state: 0
    }, 
    {
      pos: [4, 3, 14], 
      state: 0
    }, 
    {
      pos: [4, 3, 16], 
      state: 0
    }, 
    {
      pos: [4, 3, 17], 
      state: 0
    }, 
    {
      pos: [4, 3, 18], 
      state: 1
    }, 
    {
      pos: [4, 3, 19], 
      state: 1
    }, 
    {
      pos: [4, 3, 20], 
      state: 0
    }, 
    {
      pos: [4, 3, 23], 
      state: 0
    }, 
    {
      pos: [0, 3, 0], 
      state: 6
    }, 
    {
      pos: [1, 3, 0], 
      state: 6
    }, 
    {
      pos: [2, 3, 0], 
      state: 6
    }, 
    {
      pos: [3, 3, 0], 
      state: 6
    }, 
    {
      pos: [0, 3, 1], 
      state: 6
    }, 
    {
      pos: [1, 3, 1], 
      state: 6
    }, 
    {
      pos: [2, 3, 1], 
      state: 6
    }, 
    {
      pos: [3, 3, 1], 
      state: 6
    }, 
    {
      pos: [0, 3, 2], 
      state: 6
    }, 
    {
      pos: [1, 3, 2], 
      state: 6
    }, 
    {
      pos: [2, 3, 2], 
      state: 6
    }, 
    {
      pos: [3, 3, 2], 
      state: 6
    }, 
    {
      pos: [4, 3, 2], 
      state: 6
    }, 
    {
      pos: [0, 3, 3], 
      state: 6
    }, 
    {
      pos: [1, 3, 3], 
      state: 6
    }, 
    {
      pos: [2, 3, 3], 
      state: 6
    }, 
    {
      pos: [3, 3, 3], 
      state: 6
    }, 
    {
      pos: [4, 3, 3], 
      state: 6
    }, 
    {
      pos: [0, 3, 4], 
      state: 6
    }, 
    {
      pos: [1, 3, 4], 
      state: 6
    }, 
    {
      pos: [2, 3, 4], 
      state: 6
    }, 
    {
      pos: [3, 3, 4], 
      state: 6
    }, 
    {
      pos: [0, 3, 5], 
      state: 6
    }, 
    {
      pos: [1, 3, 5], 
      state: 6
    }, 
    {
      pos: [2, 3, 5], 
      state: 6
    }, 
    {
      pos: [3, 3, 5], 
      state: 6
    }, 
    {
      pos: [0, 3, 6], 
      state: 6
    }, 
    {
      pos: [1, 3, 6], 
      state: 6
    }, 
    {
      pos: [2, 3, 6], 
      state: 6
    }, 
    {
      pos: [3, 3, 6], 
      state: 6
    }, 
    {
      pos: [4, 3, 6], 
      state: 6
    }, 
    {
      pos: [0, 3, 7], 
      state: 6
    }, 
    {
      pos: [1, 3, 7], 
      state: 6
    }, 
    {
      pos: [2, 3, 7], 
      state: 6
    }, 
    {
      pos: [3, 3, 7], 
      state: 6
    }, 
    {
      pos: [4, 3, 7], 
      state: 6
    }, 
    {
      pos: [0, 3, 8], 
      state: 6
    }, 
    {
      pos: [1, 3, 8], 
      state: 6
    }, 
    {
      pos: [2, 3, 8], 
      state: 6
    }, 
    {
      pos: [3, 3, 8], 
      state: 6
    }, 
    {
      pos: [0, 3, 9], 
      state: 6
    }, 
    {
      pos: [1, 3, 9], 
      state: 6
    }, 
    {
      pos: [0, 3, 10], 
      state: 6
    }, 
    {
      pos: [3, 3, 11], 
      state: 8
    }, 
    {
      pos: [1, 3, 12], 
      state: 6
    }, 
    {
      pos: [3, 3, 12], 
      state: 8
    }, 
    {
      pos: [0, 3, 13], 
      state: 6
    }, 
    {
      pos: [1, 3, 13], 
      state: 6
    }, 
    {
      pos: [2, 3, 13], 
      state: 6
    }, 
    {
      pos: [3, 3, 13], 
      state: 8
    }, 
    {
      pos: [4, 3, 13], 
      state: 6
    }, 
    {
      pos: [0, 3, 14], 
      state: 6
    }, 
    {
      pos: [1, 3, 14], 
      state: 6
    }, 
    {
      pos: [2, 3, 14], 
      state: 6
    }, 
    {
      pos: [0, 3, 15], 
      state: 6
    }, 
    {
      pos: [1, 3, 15], 
      state: 6
    }, 
    {
      pos: [2, 3, 15], 
      state: 6
    }, 
    {
      pos: [3, 3, 15], 
      state: 6
    }, 
    {
      pos: [4, 3, 15], 
      state: 6
    }, 
    {
      pos: [0, 3, 16], 
      state: 6
    }, 
    {
      pos: [1, 3, 16], 
      state: 6
    }, 
    {
      pos: [2, 3, 16], 
      state: 6
    }, 
    {
      pos: [3, 3, 16], 
      state: 6
    }, 
    {
      pos: [0, 3, 17], 
      state: 6
    }, 
    {
      pos: [1, 3, 17], 
      state: 6
    }, 
    {
      pos: [2, 3, 17], 
      state: 6
    }, 
    {
      pos: [3, 3, 17], 
      state: 6
    }, 
    {
      pos: [0, 3, 18], 
      state: 6
    }, 
    {
      pos: [1, 3, 18], 
      state: 11
    }, 
    {
      pos: [2, 3, 18], 
      state: 6
    }, 
    {
      pos: [3, 3, 18], 
      state: 6
    }, 
    {
      pos: [0, 3, 19], 
      state: 6
    }, 
    {
      pos: [1, 3, 19], 
      state: 6
    }, 
    {
      pos: [2, 3, 19], 
      state: 6
    }, 
    {
      pos: [3, 3, 19], 
      state: 6
    }, 
    {
      pos: [0, 3, 20], 
      state: 6
    }, 
    {
      pos: [1, 3, 20], 
      state: 6
    }, 
    {
      pos: [2, 3, 20], 
      state: 6
    }, 
    {
      pos: [3, 3, 20], 
      state: 6
    }, 
    {
      pos: [0, 3, 21], 
      state: 6
    }, 
    {
      pos: [1, 3, 21], 
      state: 6
    }, 
    {
      pos: [2, 3, 21], 
      state: 6
    }, 
    {
      pos: [3, 3, 21], 
      state: 6
    }, 
    {
      pos: [4, 3, 21], 
      state: 6
    }, 
    {
      pos: [0, 3, 22], 
      state: 6
    }, 
    {
      pos: [1, 3, 22], 
      state: 6
    }, 
    {
      pos: [2, 3, 22], 
      state: 6
    }, 
    {
      pos: [3, 3, 22], 
      state: 6
    }, 
    {
      pos: [4, 3, 22], 
      state: 6
    }, 
    {
      pos: [0, 3, 23], 
      state: 6
    }, 
    {
      pos: [1, 3, 23], 
      state: 6
    }, 
    {
      pos: [2, 3, 23], 
      state: 6
    }, 
    {
      pos: [3, 3, 23], 
      state: 6
    }, 
    {
      pos: [4, 4, 1], 
      state: 0
    }, 
    {
      pos: [4, 4, 5], 
      state: 0
    }, 
    {
      pos: [1, 4, 9], 
      state: 0
    }, 
    {
      pos: [2, 4, 9], 
      state: 0
    }, 
    {
      pos: [4, 4, 9], 
      state: 0
    }, 
    {
      pos: [0, 4, 10], 
      state: 0
    }, 
    {
      pos: [1, 4, 10], 
      state: 0
    }, 
    {
      pos: [2, 4, 10], 
      state: 7
    }, 
    {
      pos: [4, 4, 10], 
      state: 0
    }, 
    {
      pos: [0, 4, 11], 
      state: 0
    }, 
    {
      pos: [1, 4, 11], 
      state: 0
    }, 
    {
      pos: [2, 4, 11], 
      state: 0
    }, 
    {
      pos: [0, 4, 12], 
      state: 0
    }, 
    {
      pos: [1, 4, 12], 
      state: 0
    }, 
    {
      pos: [2, 4, 12], 
      state: 0
    }, 
    {
      pos: [1, 4, 13], 
      state: 0
    }, 
    {
      pos: [2, 4, 13], 
      state: 0
    }, 
    {
      pos: [4, 4, 13], 
      state: 7
    }, 
    {
      pos: [2, 4, 14], 
      state: 9
    }, 
    {
      pos: [3, 4, 14], 
      state: 0
    }, 
    {
      pos: [4, 4, 14], 
      state: 0
    }, 
    {
      pos: [4, 4, 18], 
      state: 1
    }, 
    {
      pos: [0, 4, 0], 
      state: 6
    }, 
    {
      pos: [1, 4, 0], 
      state: 6
    }, 
    {
      pos: [2, 4, 0], 
      state: 6
    }, 
    {
      pos: [3, 4, 0], 
      state: 6
    }, 
    {
      pos: [4, 4, 0], 
      state: 6
    }, 
    {
      pos: [0, 4, 1], 
      state: 6
    }, 
    {
      pos: [1, 4, 1], 
      state: 6
    }, 
    {
      pos: [2, 4, 1], 
      state: 6
    }, 
    {
      pos: [3, 4, 1], 
      state: 6
    }, 
    {
      pos: [0, 4, 2], 
      state: 6
    }, 
    {
      pos: [1, 4, 2], 
      state: 6
    }, 
    {
      pos: [2, 4, 2], 
      state: 6
    }, 
    {
      pos: [3, 4, 2], 
      state: 6
    }, 
    {
      pos: [4, 4, 2], 
      state: 6
    }, 
    {
      pos: [0, 4, 3], 
      state: 6
    }, 
    {
      pos: [1, 4, 3], 
      state: 6
    }, 
    {
      pos: [2, 4, 3], 
      state: 6
    }, 
    {
      pos: [3, 4, 3], 
      state: 6
    }, 
    {
      pos: [4, 4, 3], 
      state: 6
    }, 
    {
      pos: [0, 4, 4], 
      state: 6
    }, 
    {
      pos: [1, 4, 4], 
      state: 6
    }, 
    {
      pos: [2, 4, 4], 
      state: 6
    }, 
    {
      pos: [3, 4, 4], 
      state: 6
    }, 
    {
      pos: [4, 4, 4], 
      state: 6
    }, 
    {
      pos: [0, 4, 5], 
      state: 6
    }, 
    {
      pos: [1, 4, 5], 
      state: 6
    }, 
    {
      pos: [2, 4, 5], 
      state: 6
    }, 
    {
      pos: [3, 4, 5], 
      state: 6
    }, 
    {
      pos: [0, 4, 6], 
      state: 6
    }, 
    {
      pos: [1, 4, 6], 
      state: 6
    }, 
    {
      pos: [2, 4, 6], 
      state: 6
    }, 
    {
      pos: [3, 4, 6], 
      state: 6
    }, 
    {
      pos: [4, 4, 6], 
      state: 6
    }, 
    {
      pos: [0, 4, 7], 
      state: 6
    }, 
    {
      pos: [1, 4, 7], 
      state: 6
    }, 
    {
      pos: [2, 4, 7], 
      state: 6
    }, 
    {
      pos: [3, 4, 7], 
      state: 6
    }, 
    {
      pos: [4, 4, 7], 
      state: 6
    }, 
    {
      pos: [0, 4, 8], 
      state: 6
    }, 
    {
      pos: [1, 4, 8], 
      state: 6
    }, 
    {
      pos: [2, 4, 8], 
      state: 6
    }, 
    {
      pos: [3, 4, 8], 
      state: 6
    }, 
    {
      pos: [4, 4, 8], 
      state: 6
    }, 
    {
      pos: [0, 4, 9], 
      state: 6
    }, 
    {
      pos: [3, 4, 9], 
      state: 6
    }, 
    {
      pos: [3, 4, 10], 
      state: 8
    }, 
    {
      pos: [3, 4, 11], 
      state: 8
    }, 
    {
      pos: [4, 4, 11], 
      state: 6
    }, 
    {
      pos: [3, 4, 12], 
      state: 8
    }, 
    {
      pos: [4, 4, 12], 
      state: 6
    }, 
    {
      pos: [0, 4, 13], 
      state: 6
    }, 
    {
      pos: [3, 4, 13], 
      state: 8
    }, 
    {
      pos: [0, 4, 14], 
      state: 6
    }, 
    {
      pos: [1, 4, 14], 
      state: 6
    }, 
    {
      pos: [0, 4, 15], 
      state: 6
    }, 
    {
      pos: [1, 4, 15], 
      state: 6
    }, 
    {
      pos: [2, 4, 15], 
      state: 6
    }, 
    {
      pos: [3, 4, 15], 
      state: 6
    }, 
    {
      pos: [4, 4, 15], 
      state: 6
    }, 
    {
      pos: [0, 4, 16], 
      state: 6
    }, 
    {
      pos: [1, 4, 16], 
      state: 6
    }, 
    {
      pos: [2, 4, 16], 
      state: 6
    }, 
    {
      pos: [3, 4, 16], 
      state: 6
    }, 
    {
      pos: [4, 4, 16], 
      state: 6
    }, 
    {
      pos: [0, 4, 17], 
      state: 6
    }, 
    {
      pos: [1, 4, 17], 
      state: 6
    }, 
    {
      pos: [2, 4, 17], 
      state: 6
    }, 
    {
      pos: [3, 4, 17], 
      state: 6
    }, 
    {
      pos: [4, 4, 17], 
      state: 6
    }, 
    {
      pos: [0, 4, 18], 
      state: 6
    }, 
    {
      pos: [1, 4, 18], 
      state: 12
    }, 
    {
      pos: [2, 4, 18], 
      state: 6
    }, 
    {
      pos: [3, 4, 18], 
      state: 6
    }, 
    {
      pos: [0, 4, 19], 
      state: 6
    }, 
    {
      pos: [1, 4, 19], 
      state: 6
    }, 
    {
      pos: [2, 4, 19], 
      state: 6
    }, 
    {
      pos: [3, 4, 19], 
      state: 6
    }, 
    {
      pos: [4, 4, 19], 
      state: 6
    }, 
    {
      pos: [0, 4, 20], 
      state: 6
    }, 
    {
      pos: [1, 4, 20], 
      state: 6
    }, 
    {
      pos: [2, 4, 20], 
      state: 6
    }, 
    {
      pos: [3, 4, 20], 
      state: 6
    }, 
    {
      pos: [4, 4, 20], 
      state: 6
    }, 
    {
      pos: [0, 4, 21], 
      state: 6
    }, 
    {
      pos: [1, 4, 21], 
      state: 6
    }, 
    {
      pos: [2, 4, 21], 
      state: 6
    }, 
    {
      pos: [3, 4, 21], 
      state: 6
    }, 
    {
      pos: [4, 4, 21], 
      state: 6
    }, 
    {
      pos: [0, 4, 22], 
      state: 6
    }, 
    {
      pos: [1, 4, 22], 
      state: 6
    }, 
    {
      pos: [2, 4, 22], 
      state: 6
    }, 
    {
      pos: [3, 4, 22], 
      state: 6
    }, 
    {
      pos: [4, 4, 22], 
      state: 6
    }, 
    {
      pos: [0, 4, 23], 
      state: 6
    }, 
    {
      pos: [1, 4, 23], 
      state: 6
    }, 
    {
      pos: [2, 4, 23], 
      state: 6
    }, 
    {
      pos: [3, 4, 23], 
      state: 6
    }, 
    {
      pos: [4, 4, 23], 
      state: 6
    }, 
    {
      pos: [0, 5, 0], 
      state: 0
    }, 
    {
      pos: [0, 5, 1], 
      state: 0
    }, 
    {
      pos: [1, 5, 1], 
      state: 0
    }, 
    {
      pos: [2, 5, 1], 
      state: 0
    }, 
    {
      pos: [3, 5, 1], 
      state: 0
    }, 
    {
      pos: [4, 5, 1], 
      state: 0
    }, 
    {
      pos: [0, 5, 2], 
      state: 0
    }, 
    {
      pos: [1, 5, 2], 
      state: 7
    }, 
    {
      pos: [0, 5, 3], 
      state: 0
    }, 
    {
      pos: [1, 5, 3], 
      state: 7
    }, 
    {
      pos: [0, 5, 4], 
      state: 0
    }, 
    {
      pos: [1, 5, 4], 
      state: 0
    }, 
    {
      pos: [0, 5, 5], 
      state: 0
    }, 
    {
      pos: [1, 5, 5], 
      state: 0
    }, 
    {
      pos: [4, 5, 5], 
      state: 0
    }, 
    {
      pos: [0, 5, 6], 
      state: 7
    }, 
    {
      pos: [1, 5, 6], 
      state: 0
    }, 
    {
      pos: [0, 5, 7], 
      state: 7
    }, 
    {
      pos: [1, 5, 7], 
      state: 0
    }, 
    {
      pos: [0, 5, 8], 
      state: 7
    }, 
    {
      pos: [1, 5, 8], 
      state: 0
    }, 
    {
      pos: [0, 5, 9], 
      state: 0
    }, 
    {
      pos: [1, 5, 9], 
      state: 0
    }, 
    {
      pos: [2, 5, 9], 
      state: 0
    }, 
    {
      pos: [3, 5, 9], 
      state: 0
    }, 
    {
      pos: [4, 5, 9], 
      state: 0
    }, 
    {
      pos: [0, 5, 10], 
      state: 7
    }, 
    {
      pos: [1, 5, 10], 
      state: 0
    }, 
    {
      pos: [2, 5, 10], 
      state: 0
    }, 
    {
      pos: [4, 5, 10], 
      state: 0
    }, 
    {
      pos: [0, 5, 11], 
      state: 0
    }, 
    {
      pos: [1, 5, 11], 
      state: 0
    }, 
    {
      pos: [2, 5, 11], 
      state: 0
    }, 
    {
      pos: [4, 5, 11], 
      state: 0
    }, 
    {
      pos: [0, 5, 12], 
      state: 0
    }, 
    {
      pos: [1, 5, 12], 
      state: 0
    }, 
    {
      pos: [2, 5, 12], 
      state: 0
    }, 
    {
      pos: [4, 5, 12], 
      state: 9
    }, 
    {
      pos: [0, 5, 13], 
      state: 0
    }, 
    {
      pos: [1, 5, 13], 
      state: 0
    }, 
    {
      pos: [2, 5, 13], 
      state: 0
    }, 
    {
      pos: [4, 5, 13], 
      state: 9
    }, 
    {
      pos: [0, 5, 14], 
      state: 0
    }, 
    {
      pos: [1, 5, 14], 
      state: 0
    }, 
    {
      pos: [2, 5, 14], 
      state: 9
    }, 
    {
      pos: [3, 5, 14], 
      state: 1
    }, 
    {
      pos: [4, 5, 14], 
      state: 7
    }, 
    {
      pos: [0, 5, 15], 
      state: 0
    }, 
    {
      pos: [1, 5, 15], 
      state: 0
    }, 
    {
      pos: [0, 5, 16], 
      state: 0
    }, 
    {
      pos: [1, 5, 16], 
      state: 0
    }, 
    {
      pos: [0, 5, 17], 
      state: 0
    }, 
    {
      pos: [1, 5, 17], 
      state: 0
    }, 
    {
      pos: [0, 5, 18], 
      state: 0
    }, 
    {
      pos: [1, 5, 18], 
      state: 0
    }, 
    {
      pos: [2, 5, 18], 
      state: 0
    }, 
    {
      pos: [3, 5, 18], 
      state: 0
    }, 
    {
      pos: [4, 5, 18], 
      state: 1
    }, 
    {
      pos: [0, 5, 19], 
      state: 0
    }, 
    {
      pos: [1, 5, 19], 
      state: 1
    }, 
    {
      pos: [0, 5, 20], 
      state: 7
    }, 
    {
      pos: [1, 5, 20], 
      state: 0
    }, 
    {
      pos: [0, 5, 21], 
      state: 0
    }, 
    {
      pos: [1, 5, 21], 
      state: 0
    }, 
    {
      pos: [0, 5, 22], 
      state: 0
    }, 
    {
      pos: [1, 5, 22], 
      state: 0
    }, 
    {
      pos: [2, 5, 22], 
      state: 0
    }, 
    {
      pos: [3, 5, 22], 
      state: 0
    }, 
    {
      pos: [0, 5, 23], 
      state: 0
    }, 
    {
      pos: [1, 5, 23], 
      state: 0
    }, 
    {
      pos: [1, 5, 0], 
      state: 6
    }, 
    {
      pos: [2, 5, 0], 
      state: 6
    }, 
    {
      pos: [3, 5, 0], 
      state: 6
    }, 
    {
      pos: [4, 5, 0], 
      state: 6
    }, 
    {
      pos: [2, 5, 2], 
      state: 6
    }, 
    {
      pos: [3, 5, 2], 
      state: 6
    }, 
    {
      pos: [4, 5, 2], 
      state: 6
    }, 
    {
      pos: [2, 5, 3], 
      state: 6
    }, 
    {
      pos: [3, 5, 3], 
      state: 6
    }, 
    {
      pos: [4, 5, 3], 
      state: 6
    }, 
    {
      pos: [2, 5, 4], 
      state: 6
    }, 
    {
      pos: [3, 5, 4], 
      state: 6
    }, 
    {
      pos: [4, 5, 4], 
      state: 6
    }, 
    {
      pos: [2, 5, 5], 
      state: 6
    }, 
    {
      pos: [3, 5, 5], 
      state: 6
    }, 
    {
      pos: [2, 5, 6], 
      state: 6
    }, 
    {
      pos: [3, 5, 6], 
      state: 6
    }, 
    {
      pos: [4, 5, 6], 
      state: 6
    }, 
    {
      pos: [2, 5, 7], 
      state: 6
    }, 
    {
      pos: [3, 5, 7], 
      state: 6
    }, 
    {
      pos: [4, 5, 7], 
      state: 6
    }, 
    {
      pos: [2, 5, 8], 
      state: 6
    }, 
    {
      pos: [3, 5, 8], 
      state: 6
    }, 
    {
      pos: [4, 5, 8], 
      state: 6
    }, 
    {
      pos: [3, 5, 10], 
      state: 13
    }, 
    {
      pos: [3, 5, 11], 
      state: 13
    }, 
    {
      pos: [3, 5, 12], 
      state: 10
    }, 
    {
      pos: [3, 5, 13], 
      state: 13
    }, 
    {
      pos: [2, 5, 15], 
      state: 6
    }, 
    {
      pos: [3, 5, 15], 
      state: 6
    }, 
    {
      pos: [4, 5, 15], 
      state: 6
    }, 
    {
      pos: [2, 5, 16], 
      state: 6
    }, 
    {
      pos: [3, 5, 16], 
      state: 6
    }, 
    {
      pos: [4, 5, 16], 
      state: 6
    }, 
    {
      pos: [2, 5, 17], 
      state: 6
    }, 
    {
      pos: [3, 5, 17], 
      state: 6
    }, 
    {
      pos: [4, 5, 17], 
      state: 6
    }, 
    {
      pos: [2, 5, 19], 
      state: 6
    }, 
    {
      pos: [3, 5, 19], 
      state: 6
    }, 
    {
      pos: [4, 5, 19], 
      state: 6
    }, 
    {
      pos: [2, 5, 20], 
      state: 6
    }, 
    {
      pos: [3, 5, 20], 
      state: 6
    }, 
    {
      pos: [4, 5, 20], 
      state: 6
    }, 
    {
      pos: [2, 5, 21], 
      state: 6
    }, 
    {
      pos: [3, 5, 21], 
      state: 6
    }, 
    {
      pos: [4, 5, 21], 
      state: 6
    }, 
    {
      pos: [4, 5, 22], 
      state: 6
    }, 
    {
      pos: [2, 5, 23], 
      state: 6
    }, 
    {
      pos: [3, 5, 23], 
      state: 6
    }, 
    {
      pos: [4, 5, 23], 
      state: 6
    }, 
    {
      pos: [0, 6, 0], 
      state: 7
    }, 
    {
      pos: [1, 6, 0], 
      state: 7
    }, 
    {
      pos: [0, 6, 1], 
      state: 0
    }, 
    {
      pos: [1, 6, 1], 
      state: 0
    }, 
    {
      pos: [2, 6, 1], 
      state: 0
    }, 
    {
      pos: [3, 6, 1], 
      state: 7
    }, 
    {
      pos: [4, 6, 1], 
      state: 0
    }, 
    {
      pos: [0, 6, 2], 
      state: 0
    }, 
    {
      pos: [1, 6, 2], 
      state: 0
    }, 
    {
      pos: [0, 6, 3], 
      state: 7
    }, 
    {
      pos: [1, 6, 3], 
      state: 0
    }, 
    {
      pos: [0, 6, 4], 
      state: 7
    }, 
    {
      pos: [1, 6, 4], 
      state: 0
    }, 
    {
      pos: [0, 6, 5], 
      state: 7
    }, 
    {
      pos: [1, 6, 5], 
      state: 7
    }, 
    {
      pos: [4, 6, 5], 
      state: 0
    }, 
    {
      pos: [0, 6, 6], 
      state: 0
    }, 
    {
      pos: [1, 6, 6], 
      state: 7
    }, 
    {
      pos: [0, 6, 7], 
      state: 0
    }, 
    {
      pos: [1, 6, 7], 
      state: 0
    }, 
    {
      pos: [0, 6, 8], 
      state: 0
    }, 
    {
      pos: [1, 6, 8], 
      state: 0
    }, 
    {
      pos: [0, 6, 9], 
      state: 0
    }, 
    {
      pos: [1, 6, 9], 
      state: 0
    }, 
    {
      pos: [2, 6, 9], 
      state: 0
    }, 
    {
      pos: [3, 6, 9], 
      state: 0
    }, 
    {
      pos: [4, 6, 9], 
      state: 0
    }, 
    {
      pos: [0, 6, 10], 
      state: 7
    }, 
    {
      pos: [1, 6, 10], 
      state: 0
    }, 
    {
      pos: [2, 6, 10], 
      state: 0
    }, 
    {
      pos: [3, 6, 10], 
      state: 0
    }, 
    {
      pos: [4, 6, 10], 
      state: 0
    }, 
    {
      pos: [0, 6, 11], 
      state: 0
    }, 
    {
      pos: [1, 6, 11], 
      state: 0
    }, 
    {
      pos: [2, 6, 11], 
      state: 0
    }, 
    {
      pos: [3, 6, 11], 
      state: 14
    }, 
    {
      pos: [4, 6, 11], 
      state: 0
    }, 
    {
      pos: [0, 6, 12], 
      state: 7
    }, 
    {
      pos: [1, 6, 12], 
      state: 0
    }, 
    {
      pos: [2, 6, 12], 
      state: 0
    }, 
    {
      pos: [3, 6, 12], 
      state: 0
    }, 
    {
      pos: [4, 6, 12], 
      state: 7
    }, 
    {
      pos: [0, 6, 13], 
      state: 0
    }, 
    {
      pos: [1, 6, 13], 
      state: 0
    }, 
    {
      pos: [3, 6, 13], 
      state: 9
    }, 
    {
      pos: [0, 6, 14], 
      state: 0
    }, 
    {
      pos: [1, 6, 14], 
      state: 0
    }, 
    {
      pos: [0, 6, 15], 
      state: 0
    }, 
    {
      pos: [1, 6, 15], 
      state: 0
    }, 
    {
      pos: [0, 6, 16], 
      state: 0
    }, 
    {
      pos: [1, 6, 16], 
      state: 0
    }, 
    {
      pos: [0, 6, 17], 
      state: 9
    }, 
    {
      pos: [1, 6, 17], 
      state: 0
    }, 
    {
      pos: [0, 6, 18], 
      state: 0
    }, 
    {
      pos: [1, 6, 18], 
      state: 0
    }, 
    {
      pos: [2, 6, 18], 
      state: 1
    }, 
    {
      pos: [3, 6, 18], 
      state: 1
    }, 
    {
      pos: [0, 6, 19], 
      state: 7
    }, 
    {
      pos: [1, 6, 19], 
      state: 1
    }, 
    {
      pos: [2, 6, 19], 
      state: 1
    }, 
    {
      pos: [1, 6, 21], 
      state: 0
    }, 
    {
      pos: [0, 6, 22], 
      state: 0
    }, 
    {
      pos: [1, 6, 22], 
      state: 0
    }, 
    {
      pos: [2, 6, 22], 
      state: 0
    }, 
    {
      pos: [3, 6, 22], 
      state: 0
    }, 
    {
      pos: [0, 6, 23], 
      state: 7
    }, 
    {
      pos: [1, 6, 23], 
      state: 7
    }, 
    {
      pos: [2, 6, 0], 
      state: 6
    }, 
    {
      pos: [3, 6, 0], 
      state: 6
    }, 
    {
      pos: [4, 6, 0], 
      state: 6
    }, 
    {
      pos: [2, 6, 2], 
      state: 6
    }, 
    {
      pos: [3, 6, 2], 
      state: 6
    }, 
    {
      pos: [4, 6, 2], 
      state: 6
    }, 
    {
      pos: [2, 6, 3], 
      state: 6
    }, 
    {
      pos: [3, 6, 3], 
      state: 11
    }, 
    {
      pos: [4, 6, 3], 
      state: 6
    }, 
    {
      pos: [2, 6, 4], 
      state: 6
    }, 
    {
      pos: [3, 6, 4], 
      state: 6
    }, 
    {
      pos: [4, 6, 4], 
      state: 6
    }, 
    {
      pos: [2, 6, 5], 
      state: 6
    }, 
    {
      pos: [3, 6, 5], 
      state: 6
    }, 
    {
      pos: [2, 6, 6], 
      state: 6
    }, 
    {
      pos: [3, 6, 6], 
      state: 6
    }, 
    {
      pos: [4, 6, 6], 
      state: 6
    }, 
    {
      pos: [2, 6, 7], 
      state: 6
    }, 
    {
      pos: [3, 6, 7], 
      state: 6
    }, 
    {
      pos: [4, 6, 7], 
      state: 6
    }, 
    {
      pos: [2, 6, 8], 
      state: 6
    }, 
    {
      pos: [3, 6, 8], 
      state: 6
    }, 
    {
      pos: [4, 6, 8], 
      state: 6
    }, 
    {
      pos: [2, 6, 13], 
      state: 15
    }, 
    {
      pos: [4, 6, 13], 
      state: 6
    }, 
    {
      pos: [2, 6, 14], 
      state: 6
    }, 
    {
      pos: [3, 6, 14], 
      state: 6
    }, 
    {
      pos: [4, 6, 14], 
      state: 6
    }, 
    {
      pos: [2, 6, 15], 
      state: 6
    }, 
    {
      pos: [3, 6, 15], 
      state: 6
    }, 
    {
      pos: [4, 6, 15], 
      state: 6
    }, 
    {
      pos: [2, 6, 16], 
      state: 6
    }, 
    {
      pos: [3, 6, 16], 
      state: 6
    }, 
    {
      pos: [4, 6, 16], 
      state: 6
    }, 
    {
      pos: [2, 6, 17], 
      state: 6
    }, 
    {
      pos: [3, 6, 17], 
      state: 6
    }, 
    {
      pos: [4, 6, 17], 
      state: 6
    }, 
    {
      pos: [4, 6, 18], 
      state: 6
    }, 
    {
      pos: [3, 6, 19], 
      state: 6
    }, 
    {
      pos: [4, 6, 19], 
      state: 6
    }, 
    {
      pos: [0, 6, 20], 
      state: 6
    }, 
    {
      pos: [1, 6, 20], 
      state: 6
    }, 
    {
      pos: [2, 6, 20], 
      state: 6
    }, 
    {
      pos: [3, 6, 20], 
      state: 6
    }, 
    {
      pos: [4, 6, 20], 
      state: 6
    }, 
    {
      pos: [0, 6, 21], 
      state: 6
    }, 
    {
      pos: [2, 6, 21], 
      state: 6
    }, 
    {
      pos: [3, 6, 21], 
      state: 6
    }, 
    {
      pos: [4, 6, 21], 
      state: 6
    }, 
    {
      pos: [4, 6, 22], 
      state: 6
    }, 
    {
      pos: [2, 6, 23], 
      state: 6
    }, 
    {
      pos: [3, 6, 23], 
      state: 6
    }, 
    {
      pos: [4, 6, 23], 
      state: 6
    }, 
    {
      pos: [0, 7, 1], 
      state: 0
    }, 
    {
      pos: [4, 7, 1], 
      state: 0
    }, 
    {
      pos: [4, 7, 5], 
      state: 7
    }, 
    {
      pos: [0, 7, 7], 
      state: 0
    }, 
    {
      pos: [0, 7, 8], 
      state: 0
    }, 
    {
      pos: [0, 7, 9], 
      state: 7
    }, 
    {
      pos: [1, 7, 9], 
      state: 0
    }, 
    {
      pos: [2, 7, 9], 
      state: 0
    }, 
    {
      pos: [3, 7, 9], 
      state: 0
    }, 
    {
      pos: [4, 7, 9], 
      state: 0
    }, 
    {
      pos: [1, 7, 10], 
      state: 7
    }, 
    {
      pos: [2, 7, 10], 
      state: 7
    }, 
    {
      pos: [3, 7, 10], 
      state: 0
    }, 
    {
      pos: [4, 7, 10], 
      state: 0
    }, 
    {
      pos: [0, 7, 11], 
      state: 7
    }, 
    {
      pos: [1, 7, 11], 
      state: 7
    }, 
    {
      pos: [2, 7, 11], 
      state: 0
    }, 
    {
      pos: [3, 7, 11], 
      state: 0
    }, 
    {
      pos: [4, 7, 11], 
      state: 7
    }, 
    {
      pos: [1, 7, 12], 
      state: 0
    }, 
    {
      pos: [2, 7, 12], 
      state: 0
    }, 
    {
      pos: [3, 7, 12], 
      state: 0
    }, 
    {
      pos: [4, 7, 12], 
      state: 0
    }, 
    {
      pos: [0, 7, 13], 
      state: 0
    }, 
    {
      pos: [1, 7, 13], 
      state: 0
    }, 
    {
      pos: [2, 7, 13], 
      state: 0
    }, 
    {
      pos: [0, 7, 14], 
      state: 0
    }, 
    {
      pos: [1, 7, 14], 
      state: 0
    }, 
    {
      pos: [0, 7, 15], 
      state: 9
    }, 
    {
      pos: [0, 7, 18], 
      state: 7
    }, 
    {
      pos: [0, 7, 22], 
      state: 0
    }, 
    {
      pos: [0, 7, 0], 
      state: 6
    }, 
    {
      pos: [1, 7, 0], 
      state: 6
    }, 
    {
      pos: [2, 7, 0], 
      state: 6
    }, 
    {
      pos: [3, 7, 0], 
      state: 6
    }, 
    {
      pos: [4, 7, 0], 
      state: 6
    }, 
    {
      pos: [1, 7, 1], 
      state: 6
    }, 
    {
      pos: [2, 7, 1], 
      state: 6
    }, 
    {
      pos: [3, 7, 1], 
      state: 6
    }, 
    {
      pos: [0, 7, 2], 
      state: 6
    }, 
    {
      pos: [1, 7, 2], 
      state: 6
    }, 
    {
      pos: [2, 7, 2], 
      state: 6
    }, 
    {
      pos: [3, 7, 2], 
      state: 6
    }, 
    {
      pos: [4, 7, 2], 
      state: 6
    }, 
    {
      pos: [0, 7, 3], 
      state: 6
    }, 
    {
      pos: [1, 7, 3], 
      state: 6
    }, 
    {
      pos: [2, 7, 3], 
      state: 6
    }, 
    {
      pos: [3, 7, 3], 
      state: 12
    }, 
    {
      pos: [4, 7, 3], 
      state: 6
    }, 
    {
      pos: [0, 7, 4], 
      state: 6
    }, 
    {
      pos: [1, 7, 4], 
      state: 6
    }, 
    {
      pos: [2, 7, 4], 
      state: 6
    }, 
    {
      pos: [3, 7, 4], 
      state: 6
    }, 
    {
      pos: [4, 7, 4], 
      state: 6
    }, 
    {
      pos: [0, 7, 5], 
      state: 6
    }, 
    {
      pos: [1, 7, 5], 
      state: 6
    }, 
    {
      pos: [2, 7, 5], 
      state: 6
    }, 
    {
      pos: [3, 7, 5], 
      state: 6
    }, 
    {
      pos: [0, 7, 6], 
      state: 6
    }, 
    {
      pos: [1, 7, 6], 
      state: 6
    }, 
    {
      pos: [2, 7, 6], 
      state: 6
    }, 
    {
      pos: [3, 7, 6], 
      state: 6
    }, 
    {
      pos: [4, 7, 6], 
      state: 6
    }, 
    {
      pos: [1, 7, 7], 
      state: 6
    }, 
    {
      pos: [2, 7, 7], 
      state: 6
    }, 
    {
      pos: [3, 7, 7], 
      state: 6
    }, 
    {
      pos: [4, 7, 7], 
      state: 6
    }, 
    {
      pos: [1, 7, 8], 
      state: 6
    }, 
    {
      pos: [2, 7, 8], 
      state: 6
    }, 
    {
      pos: [3, 7, 8], 
      state: 6
    }, 
    {
      pos: [4, 7, 8], 
      state: 6
    }, 
    {
      pos: [0, 7, 10], 
      state: 6
    }, 
    {
      pos: [0, 7, 12], 
      state: 6
    }, 
    {
      pos: [3, 7, 13], 
      state: 15
    }, 
    {
      pos: [4, 7, 13], 
      state: 6
    }, 
    {
      pos: [2, 7, 14], 
      state: 6
    }, 
    {
      pos: [3, 7, 14], 
      state: 6
    }, 
    {
      pos: [4, 7, 14], 
      state: 6
    }, 
    {
      pos: [1, 7, 15], 
      state: 6
    }, 
    {
      pos: [2, 7, 15], 
      state: 6
    }, 
    {
      pos: [3, 7, 15], 
      state: 6
    }, 
    {
      pos: [4, 7, 15], 
      state: 6
    }, 
    {
      pos: [0, 7, 16], 
      state: 6
    }, 
    {
      pos: [1, 7, 16], 
      state: 6
    }, 
    {
      pos: [2, 7, 16], 
      state: 6
    }, 
    {
      pos: [3, 7, 16], 
      state: 6
    }, 
    {
      pos: [4, 7, 16], 
      state: 6
    }, 
    {
      pos: [0, 7, 17], 
      state: 6
    }, 
    {
      pos: [1, 7, 17], 
      state: 6
    }, 
    {
      pos: [2, 7, 17], 
      state: 6
    }, 
    {
      pos: [3, 7, 17], 
      state: 6
    }, 
    {
      pos: [4, 7, 17], 
      state: 6
    }, 
    {
      pos: [1, 7, 18], 
      state: 6
    }, 
    {
      pos: [2, 7, 18], 
      state: 6
    }, 
    {
      pos: [3, 7, 18], 
      state: 6
    }, 
    {
      pos: [4, 7, 18], 
      state: 6
    }, 
    {
      pos: [0, 7, 19], 
      state: 6
    }, 
    {
      pos: [1, 7, 19], 
      state: 6
    }, 
    {
      pos: [2, 7, 19], 
      state: 6
    }, 
    {
      pos: [3, 7, 19], 
      state: 6
    }, 
    {
      pos: [4, 7, 19], 
      state: 6
    }, 
    {
      pos: [0, 7, 20], 
      state: 6
    }, 
    {
      pos: [1, 7, 20], 
      state: 6
    }, 
    {
      pos: [2, 7, 20], 
      state: 6
    }, 
    {
      pos: [3, 7, 20], 
      state: 6
    }, 
    {
      pos: [4, 7, 20], 
      state: 6
    }, 
    {
      pos: [0, 7, 21], 
      state: 6
    }, 
    {
      pos: [1, 7, 21], 
      state: 6
    }, 
    {
      pos: [2, 7, 21], 
      state: 6
    }, 
    {
      pos: [3, 7, 21], 
      state: 6
    }, 
    {
      pos: [4, 7, 21], 
      state: 6
    }, 
    {
      pos: [1, 7, 22], 
      state: 6
    }, 
    {
      pos: [2, 7, 22], 
      state: 6
    }, 
    {
      pos: [3, 7, 22], 
      state: 6
    }, 
    {
      pos: [4, 7, 22], 
      state: 6
    }, 
    {
      pos: [0, 7, 23], 
      state: 6
    }, 
    {
      pos: [1, 7, 23], 
      state: 6
    }, 
    {
      pos: [2, 7, 23], 
      state: 6
    }, 
    {
      pos: [3, 7, 23], 
      state: 6
    }, 
    {
      pos: [4, 7, 23], 
      state: 6
    }, 
    {
      pos: [0, 8, 1], 
      state: 0
    }, 
    {
      pos: [4, 8, 1], 
      state: 0
    }, 
    {
      pos: [4, 8, 5], 
      state: 7
    }, 
    {
      pos: [0, 8, 7], 
      state: 0
    }, 
    {
      pos: [0, 8, 8], 
      state: 0
    }, 
    {
      pos: [1, 8, 9], 
      state: 0
    }, 
    {
      pos: [2, 8, 9], 
      state: 0
    }, 
    {
      pos: [3, 8, 9], 
      state: 0
    }, 
    {
      pos: [4, 8, 9], 
      state: 0
    }, 
    {
      pos: [2, 8, 10], 
      state: 0
    }, 
    {
      pos: [3, 8, 10], 
      state: 7
    }, 
    {
      pos: [2, 8, 11], 
      state: 7
    }, 
    {
      pos: [3, 8, 11], 
      state: 0
    }, 
    {
      pos: [1, 8, 12], 
      state: 0
    }, 
    {
      pos: [2, 8, 12], 
      state: 0
    }, 
    {
      pos: [3, 8, 12], 
      state: 0
    }, 
    {
      pos: [4, 8, 12], 
      state: 0
    }, 
    {
      pos: [0, 8, 13], 
      state: 0
    }, 
    {
      pos: [1, 8, 13], 
      state: 0
    }, 
    {
      pos: [2, 8, 13], 
      state: 0
    }, 
    {
      pos: [3, 8, 13], 
      state: 0
    }, 
    {
      pos: [4, 8, 13], 
      state: 0
    }, 
    {
      pos: [0, 8, 14], 
      state: 0
    }, 
    {
      pos: [1, 8, 14], 
      state: 0
    }, 
    {
      pos: [2, 8, 14], 
      state: 0
    }, 
    {
      pos: [3, 8, 14], 
      state: 0
    }, 
    {
      pos: [4, 8, 14], 
      state: 0
    }, 
    {
      pos: [0, 8, 15], 
      state: 0
    }, 
    {
      pos: [0, 8, 16], 
      state: 9
    }, 
    {
      pos: [0, 8, 18], 
      state: 9
    }, 
    {
      pos: [0, 8, 22], 
      state: 0
    }, 
    {
      pos: [0, 8, 0], 
      state: 6
    }, 
    {
      pos: [1, 8, 0], 
      state: 6
    }, 
    {
      pos: [2, 8, 0], 
      state: 6
    }, 
    {
      pos: [3, 8, 0], 
      state: 6
    }, 
    {
      pos: [4, 8, 0], 
      state: 6
    }, 
    {
      pos: [1, 8, 1], 
      state: 6
    }, 
    {
      pos: [2, 8, 1], 
      state: 6
    }, 
    {
      pos: [3, 8, 1], 
      state: 6
    }, 
    {
      pos: [0, 8, 2], 
      state: 6
    }, 
    {
      pos: [1, 8, 2], 
      state: 6
    }, 
    {
      pos: [2, 8, 2], 
      state: 6
    }, 
    {
      pos: [3, 8, 2], 
      state: 6
    }, 
    {
      pos: [4, 8, 2], 
      state: 6
    }, 
    {
      pos: [0, 8, 3], 
      state: 6
    }, 
    {
      pos: [1, 8, 3], 
      state: 6
    }, 
    {
      pos: [2, 8, 3], 
      state: 6
    }, 
    {
      pos: [3, 8, 3], 
      state: 12
    }, 
    {
      pos: [4, 8, 3], 
      state: 6
    }, 
    {
      pos: [0, 8, 4], 
      state: 6
    }, 
    {
      pos: [1, 8, 4], 
      state: 6
    }, 
    {
      pos: [2, 8, 4], 
      state: 6
    }, 
    {
      pos: [3, 8, 4], 
      state: 6
    }, 
    {
      pos: [4, 8, 4], 
      state: 6
    }, 
    {
      pos: [0, 8, 5], 
      state: 6
    }, 
    {
      pos: [1, 8, 5], 
      state: 6
    }, 
    {
      pos: [2, 8, 5], 
      state: 6
    }, 
    {
      pos: [3, 8, 5], 
      state: 6
    }, 
    {
      pos: [0, 8, 6], 
      state: 6
    }, 
    {
      pos: [1, 8, 6], 
      state: 6
    }, 
    {
      pos: [2, 8, 6], 
      state: 6
    }, 
    {
      pos: [3, 8, 6], 
      state: 6
    }, 
    {
      pos: [4, 8, 6], 
      state: 6
    }, 
    {
      pos: [1, 8, 7], 
      state: 6
    }, 
    {
      pos: [2, 8, 7], 
      state: 6
    }, 
    {
      pos: [3, 8, 7], 
      state: 6
    }, 
    {
      pos: [4, 8, 7], 
      state: 6
    }, 
    {
      pos: [1, 8, 8], 
      state: 6
    }, 
    {
      pos: [2, 8, 8], 
      state: 6
    }, 
    {
      pos: [3, 8, 8], 
      state: 6
    }, 
    {
      pos: [4, 8, 8], 
      state: 6
    }, 
    {
      pos: [0, 8, 9], 
      state: 6
    }, 
    {
      pos: [0, 8, 10], 
      state: 6
    }, 
    {
      pos: [1, 8, 10], 
      state: 6
    }, 
    {
      pos: [4, 8, 10], 
      state: 6
    }, 
    {
      pos: [0, 8, 11], 
      state: 6
    }, 
    {
      pos: [1, 8, 11], 
      state: 6
    }, 
    {
      pos: [4, 8, 11], 
      state: 6
    }, 
    {
      pos: [0, 8, 12], 
      state: 6
    }, 
    {
      pos: [1, 8, 15], 
      state: 6
    }, 
    {
      pos: [2, 8, 15], 
      state: 6
    }, 
    {
      pos: [3, 8, 15], 
      state: 6
    }, 
    {
      pos: [4, 8, 15], 
      state: 6
    }, 
    {
      pos: [1, 8, 16], 
      state: 6
    }, 
    {
      pos: [2, 8, 16], 
      state: 6
    }, 
    {
      pos: [3, 8, 16], 
      state: 6
    }, 
    {
      pos: [4, 8, 16], 
      state: 6
    }, 
    {
      pos: [0, 8, 17], 
      state: 6
    }, 
    {
      pos: [1, 8, 17], 
      state: 6
    }, 
    {
      pos: [2, 8, 17], 
      state: 6
    }, 
    {
      pos: [3, 8, 17], 
      state: 6
    }, 
    {
      pos: [4, 8, 17], 
      state: 6
    }, 
    {
      pos: [1, 8, 18], 
      state: 6
    }, 
    {
      pos: [2, 8, 18], 
      state: 6
    }, 
    {
      pos: [3, 8, 18], 
      state: 6
    }, 
    {
      pos: [4, 8, 18], 
      state: 6
    }, 
    {
      pos: [0, 8, 19], 
      state: 6
    }, 
    {
      pos: [1, 8, 19], 
      state: 6
    }, 
    {
      pos: [2, 8, 19], 
      state: 6
    }, 
    {
      pos: [3, 8, 19], 
      state: 6
    }, 
    {
      pos: [4, 8, 19], 
      state: 6
    }, 
    {
      pos: [0, 8, 20], 
      state: 6
    }, 
    {
      pos: [1, 8, 20], 
      state: 6
    }, 
    {
      pos: [2, 8, 20], 
      state: 6
    }, 
    {
      pos: [3, 8, 20], 
      state: 6
    }, 
    {
      pos: [4, 8, 20], 
      state: 6
    }, 
    {
      pos: [0, 8, 21], 
      state: 6
    }, 
    {
      pos: [1, 8, 21], 
      state: 6
    }, 
    {
      pos: [2, 8, 21], 
      state: 6
    }, 
    {
      pos: [3, 8, 21], 
      state: 6
    }, 
    {
      pos: [4, 8, 21], 
      state: 6
    }, 
    {
      pos: [1, 8, 22], 
      state: 6
    }, 
    {
      pos: [2, 8, 22], 
      state: 6
    }, 
    {
      pos: [3, 8, 22], 
      state: 6
    }, 
    {
      pos: [4, 8, 22], 
      state: 6
    }, 
    {
      pos: [0, 8, 23], 
      state: 6
    }, 
    {
      pos: [1, 8, 23], 
      state: 6
    }, 
    {
      pos: [2, 8, 23], 
      state: 6
    }, 
    {
      pos: [3, 8, 23], 
      state: 6
    }, 
    {
      pos: [4, 8, 23], 
      state: 6
    }, 
    {
      pos: [0, 9, 0], 
      state: 0
    }, 
    {
      pos: [1, 9, 0], 
      state: 0
    }, 
    {
      pos: [2, 9, 0], 
      state: 0
    }, 
    {
      pos: [3, 9, 0], 
      state: 0
    }, 
    {
      pos: [4, 9, 0], 
      state: 0
    }, 
    {
      pos: [0, 9, 1], 
      state: 0
    }, 
    {
      pos: [1, 9, 1], 
      state: 0
    }, 
    {
      pos: [2, 9, 1], 
      state: 0
    }, 
    {
      pos: [3, 9, 1], 
      state: 0
    }, 
    {
      pos: [4, 9, 1], 
      state: 0
    }, 
    {
      pos: [0, 9, 2], 
      state: 0
    }, 
    {
      pos: [1, 9, 2], 
      state: 0
    }, 
    {
      pos: [2, 9, 2], 
      state: 0
    }, 
    {
      pos: [3, 9, 2], 
      state: 0
    }, 
    {
      pos: [4, 9, 2], 
      state: 0
    }, 
    {
      pos: [0, 9, 3], 
      state: 0
    }, 
    {
      pos: [1, 9, 3], 
      state: 0
    }, 
    {
      pos: [2, 9, 3], 
      state: 0
    }, 
    {
      pos: [3, 9, 3], 
      state: 0
    }, 
    {
      pos: [4, 9, 3], 
      state: 7
    }, 
    {
      pos: [0, 9, 4], 
      state: 0
    }, 
    {
      pos: [1, 9, 4], 
      state: 0
    }, 
    {
      pos: [2, 9, 4], 
      state: 0
    }, 
    {
      pos: [3, 9, 4], 
      state: 0
    }, 
    {
      pos: [4, 9, 4], 
      state: 7
    }, 
    {
      pos: [0, 9, 5], 
      state: 0
    }, 
    {
      pos: [1, 9, 5], 
      state: 0
    }, 
    {
      pos: [2, 9, 5], 
      state: 0
    }, 
    {
      pos: [0, 9, 6], 
      state: 0
    }, 
    {
      pos: [1, 9, 6], 
      state: 0
    }, 
    {
      pos: [2, 9, 6], 
      state: 7
    }, 
    {
      pos: [3, 9, 6], 
      state: 7
    }, 
    {
      pos: [4, 9, 6], 
      state: 7
    }, 
    {
      pos: [0, 9, 7], 
      state: 0
    }, 
    {
      pos: [1, 9, 7], 
      state: 0
    }, 
    {
      pos: [2, 9, 7], 
      state: 0
    }, 
    {
      pos: [3, 9, 7], 
      state: 7
    }, 
    {
      pos: [0, 9, 8], 
      state: 7
    }, 
    {
      pos: [1, 9, 8], 
      state: 0
    }, 
    {
      pos: [2, 9, 8], 
      state: 0
    }, 
    {
      pos: [3, 9, 8], 
      state: 7
    }, 
    {
      pos: [0, 9, 9], 
      state: 0
    }, 
    {
      pos: [1, 9, 9], 
      state: 0
    }, 
    {
      pos: [2, 9, 9], 
      state: 0
    }, 
    {
      pos: [3, 9, 9], 
      state: 0
    }, 
    {
      pos: [4, 9, 9], 
      state: 0
    }, 
    {
      pos: [2, 9, 10], 
      state: 0
    }, 
    {
      pos: [3, 9, 10], 
      state: 0
    }, 
    {
      pos: [3, 9, 11], 
      state: 0
    }, 
    {
      pos: [4, 9, 11], 
      state: 7
    }, 
    {
      pos: [1, 9, 12], 
      state: 0
    }, 
    {
      pos: [2, 9, 12], 
      state: 0
    }, 
    {
      pos: [3, 9, 12], 
      state: 0
    }, 
    {
      pos: [0, 9, 13], 
      state: 7
    }, 
    {
      pos: [1, 9, 13], 
      state: 0
    }, 
    {
      pos: [2, 9, 13], 
      state: 0
    }, 
    {
      pos: [3, 9, 13], 
      state: 0
    }, 
    {
      pos: [4, 9, 13], 
      state: 0
    }, 
    {
      pos: [0, 9, 14], 
      state: 7
    }, 
    {
      pos: [1, 9, 14], 
      state: 0
    }, 
    {
      pos: [2, 9, 14], 
      state: 0
    }, 
    {
      pos: [3, 9, 14], 
      state: 0
    }, 
    {
      pos: [4, 9, 14], 
      state: 0
    }, 
    {
      pos: [0, 9, 15], 
      state: 7
    }, 
    {
      pos: [1, 9, 15], 
      state: 0
    }, 
    {
      pos: [2, 9, 15], 
      state: 0
    }, 
    {
      pos: [4, 9, 15], 
      state: 0
    }, 
    {
      pos: [0, 9, 16], 
      state: 0
    }, 
    {
      pos: [1, 9, 16], 
      state: 0
    }, 
    {
      pos: [2, 9, 16], 
      state: 0
    }, 
    {
      pos: [3, 9, 16], 
      state: 0
    }, 
    {
      pos: [4, 9, 16], 
      state: 9
    }, 
    {
      pos: [0, 9, 17], 
      state: 0
    }, 
    {
      pos: [1, 9, 17], 
      state: 7
    }, 
    {
      pos: [2, 9, 17], 
      state: 0
    }, 
    {
      pos: [3, 9, 17], 
      state: 0
    }, 
    {
      pos: [0, 9, 18], 
      state: 0
    }, 
    {
      pos: [2, 9, 18], 
      state: 7
    }, 
    {
      pos: [3, 9, 18], 
      state: 0
    }, 
    {
      pos: [4, 9, 18], 
      state: 0
    }, 
    {
      pos: [0, 9, 19], 
      state: 0
    }, 
    {
      pos: [1, 9, 19], 
      state: 0
    }, 
    {
      pos: [3, 9, 19], 
      state: 0
    }, 
    {
      pos: [4, 9, 19], 
      state: 0
    }, 
    {
      pos: [0, 9, 20], 
      state: 0
    }, 
    {
      pos: [1, 9, 20], 
      state: 0
    }, 
    {
      pos: [2, 9, 20], 
      state: 7
    }, 
    {
      pos: [3, 9, 20], 
      state: 0
    }, 
    {
      pos: [4, 9, 20], 
      state: 0
    }, 
    {
      pos: [0, 9, 21], 
      state: 9
    }, 
    {
      pos: [1, 9, 21], 
      state: 0
    }, 
    {
      pos: [2, 9, 21], 
      state: 7
    }, 
    {
      pos: [3, 9, 21], 
      state: 0
    }, 
    {
      pos: [4, 9, 21], 
      state: 7
    }, 
    {
      pos: [0, 9, 22], 
      state: 9
    }, 
    {
      pos: [1, 9, 22], 
      state: 0
    }, 
    {
      pos: [2, 9, 22], 
      state: 0
    }, 
    {
      pos: [3, 9, 22], 
      state: 0
    }, 
    {
      pos: [4, 9, 22], 
      state: 0
    }, 
    {
      pos: [0, 9, 23], 
      state: 0
    }, 
    {
      pos: [1, 9, 23], 
      state: 0
    }, 
    {
      pos: [2, 9, 23], 
      state: 9
    }, 
    {
      pos: [3, 9, 23], 
      state: 9
    }, 
    {
      pos: [4, 9, 23], 
      state: 7
    }, 
    {
      pos: [3, 9, 5], 
      state: 6
    }, 
    {
      pos: [4, 9, 5], 
      state: 6
    }, 
    {
      pos: [4, 9, 7], 
      state: 6
    }, 
    {
      pos: [4, 9, 8], 
      state: 6
    }, 
    {
      pos: [0, 9, 10], 
      state: 6
    }, 
    {
      pos: [1, 9, 10], 
      state: 6
    }, 
    {
      pos: [4, 9, 10], 
      state: 6
    }, 
    {
      pos: [0, 9, 11], 
      state: 6
    }, 
    {
      pos: [1, 9, 11], 
      state: 6
    }, 
    {
      pos: [2, 9, 11], 
      state: 6
    }, 
    {
      pos: [0, 9, 12], 
      state: 6
    }, 
    {
      pos: [4, 9, 12], 
      state: 6
    }, 
    {
      pos: [3, 9, 15], 
      state: 6
    }, 
    {
      pos: [4, 9, 17], 
      state: 6
    }, 
    {
      pos: [1, 9, 18], 
      state: 6
    }, 
    {
      pos: [2, 9, 19], 
      state: 6
    }, 
    {
      pos: [1, 10, 0], 
      state: 7
    }, 
    {
      pos: [4, 10, 0], 
      state: 0
    }, 
    {
      pos: [1, 10, 1], 
      state: 7
    }, 
    {
      pos: [4, 10, 1], 
      state: 0
    }, 
    {
      pos: [0, 10, 2], 
      state: 0
    }, 
    {
      pos: [1, 10, 2], 
      state: 0
    }, 
    {
      pos: [0, 10, 3], 
      state: 0
    }, 
    {
      pos: [1, 10, 3], 
      state: 0
    }, 
    {
      pos: [2, 10, 3], 
      state: 7
    }, 
    {
      pos: [4, 10, 3], 
      state: 7
    }, 
    {
      pos: [0, 10, 4], 
      state: 0
    }, 
    {
      pos: [1, 10, 4], 
      state: 0
    }, 
    {
      pos: [2, 10, 4], 
      state: 0
    }, 
    {
      pos: [3, 10, 4], 
      state: 7
    }, 
    {
      pos: [4, 10, 4], 
      state: 7
    }, 
    {
      pos: [0, 10, 5], 
      state: 0
    }, 
    {
      pos: [1, 10, 5], 
      state: 0
    }, 
    {
      pos: [2, 10, 5], 
      state: 0
    }, 
    {
      pos: [3, 10, 5], 
      state: 0
    }, 
    {
      pos: [4, 10, 5], 
      state: 0
    }, 
    {
      pos: [0, 10, 6], 
      state: 0
    }, 
    {
      pos: [1, 10, 6], 
      state: 7
    }, 
    {
      pos: [2, 10, 6], 
      state: 7
    }, 
    {
      pos: [4, 10, 6], 
      state: 7
    }, 
    {
      pos: [0, 10, 7], 
      state: 7
    }, 
    {
      pos: [1, 10, 7], 
      state: 0
    }, 
    {
      pos: [2, 10, 7], 
      state: 0
    }, 
    {
      pos: [3, 10, 7], 
      state: 7
    }, 
    {
      pos: [4, 10, 7], 
      state: 7
    }, 
    {
      pos: [1, 10, 8], 
      state: 0
    }, 
    {
      pos: [2, 10, 8], 
      state: 7
    }, 
    {
      pos: [3, 10, 8], 
      state: 7
    }, 
    {
      pos: [0, 10, 9], 
      state: 0
    }, 
    {
      pos: [1, 10, 9], 
      state: 0
    }, 
    {
      pos: [2, 10, 9], 
      state: 0
    }, 
    {
      pos: [3, 10, 9], 
      state: 0
    }, 
    {
      pos: [4, 10, 9], 
      state: 0
    }, 
    {
      pos: [1, 10, 10], 
      state: 0
    }, 
    {
      pos: [2, 10, 10], 
      state: 0
    }, 
    {
      pos: [3, 10, 10], 
      state: 0
    }, 
    {
      pos: [4, 10, 10], 
      state: 0
    }, 
    {
      pos: [1, 10, 11], 
      state: 0
    }, 
    {
      pos: [2, 10, 11], 
      state: 0
    }, 
    {
      pos: [3, 10, 11], 
      state: 0
    }, 
    {
      pos: [4, 10, 11], 
      state: 7
    }, 
    {
      pos: [0, 10, 12], 
      state: 0
    }, 
    {
      pos: [1, 10, 12], 
      state: 0
    }, 
    {
      pos: [2, 10, 12], 
      state: 0
    }, 
    {
      pos: [3, 10, 12], 
      state: 0
    }, 
    {
      pos: [1, 10, 13], 
      state: 0
    }, 
    {
      pos: [2, 10, 13], 
      state: 0
    }, 
    {
      pos: [3, 10, 13], 
      state: 0
    }, 
    {
      pos: [4, 10, 13], 
      state: 0
    }, 
    {
      pos: [1, 10, 14], 
      state: 0
    }, 
    {
      pos: [2, 10, 14], 
      state: 0
    }, 
    {
      pos: [0, 10, 15], 
      state: 7
    }, 
    {
      pos: [1, 10, 15], 
      state: 7
    }, 
    {
      pos: [2, 10, 15], 
      state: 0
    }, 
    {
      pos: [2, 10, 16], 
      state: 0
    }, 
    {
      pos: [4, 10, 18], 
      state: 0
    }, 
    {
      pos: [0, 10, 19], 
      state: 9
    }, 
    {
      pos: [1, 10, 19], 
      state: 0
    }, 
    {
      pos: [4, 10, 20], 
      state: 7
    }, 
    {
      pos: [1, 10, 21], 
      state: 7
    }, 
    {
      pos: [2, 10, 22], 
      state: 7
    }, 
    {
      pos: [3, 10, 22], 
      state: 0
    }, 
    {
      pos: [4, 10, 22], 
      state: 7
    }, 
    {
      pos: [1, 10, 23], 
      state: 9
    }, 
    {
      pos: [2, 10, 23], 
      state: 7
    }, 
    {
      pos: [3, 10, 23], 
      state: 7
    }, 
    {
      nbt: {
        joint: "rollable", 
        final_state: "minecraft:air", 
        name: "minecraft:empty", 
        pool: "minecraft:bastion/treasure/extensions/small_pool", 
        id: "minecraft:jigsaw", 
        target: "minecraft:extension_connector"
      }, 
      pos: [4, 10, 2], 
      state: 3
    }, 
    {
      nbt: {
        joint: "rollable", 
        final_state: "minecraft:basalt", 
        name: "minecraft:empty", 
        pool: "minecraft:bastion/mobs/piglin", 
        id: "minecraft:jigsaw", 
        target: "minecraft:mob_connector"
      }, 
      pos: [1, 10, 16], 
      state: 16
    }, 
    {
      nbt: {
        joint: "rollable", 
        final_state: "minecraft:air", 
        name: "minecraft:empty", 
        pool: "minecraft:bastion/treasure/extensions/small_pool", 
        id: "minecraft:jigsaw", 
        target: "minecraft:extension_connector"
      }, 
      pos: [4, 10, 19], 
      state: 3
    }, 
    {
      nbt: {
        joint: "rollable", 
        final_state: "minecraft:basalt", 
        name: "minecraft:empty", 
        pool: "minecraft:bastion/mobs/piglin", 
        id: "minecraft:jigsaw", 
        target: "minecraft:mob_connector"
      }, 
      pos: [1, 10, 22], 
      state: 17
    }, 
    {
      pos: [0, 10, 0], 
      state: 6
    }, 
    {
      pos: [2, 10, 0], 
      state: 6
    }, 
    {
      pos: [3, 10, 0], 
      state: 6
    }, 
    {
      pos: [0, 10, 1], 
      state: 6
    }, 
    {
      pos: [2, 10, 1], 
      state: 6
    }, 
    {
      pos: [3, 10, 1], 
      state: 6
    }, 
    {
      pos: [2, 10, 2], 
      state: 6
    }, 
    {
      pos: [3, 10, 2], 
      state: 6
    }, 
    {
      pos: [3, 10, 3], 
      state: 6
    }, 
    {
      pos: [3, 10, 6], 
      state: 6
    }, 
    {
      pos: [0, 10, 8], 
      state: 6
    }, 
    {
      pos: [4, 10, 8], 
      state: 6
    }, 
    {
      pos: [0, 10, 10], 
      state: 6
    }, 
    {
      pos: [0, 10, 11], 
      state: 6
    }, 
    {
      pos: [4, 10, 12], 
      state: 6
    }, 
    {
      pos: [0, 10, 13], 
      state: 6
    }, 
    {
      pos: [0, 10, 14], 
      state: 6
    }, 
    {
      pos: [3, 10, 14], 
      state: 6
    }, 
    {
      pos: [4, 10, 14], 
      state: 6
    }, 
    {
      pos: [3, 10, 15], 
      state: 6
    }, 
    {
      pos: [4, 10, 15], 
      state: 6
    }, 
    {
      pos: [0, 10, 16], 
      state: 6
    }, 
    {
      pos: [3, 10, 16], 
      state: 6
    }, 
    {
      pos: [4, 10, 16], 
      state: 6
    }, 
    {
      pos: [0, 10, 17], 
      state: 6
    }, 
    {
      pos: [1, 10, 17], 
      state: 6
    }, 
    {
      pos: [2, 10, 17], 
      state: 6
    }, 
    {
      pos: [3, 10, 17], 
      state: 6
    }, 
    {
      pos: [4, 10, 17], 
      state: 6
    }, 
    {
      pos: [0, 10, 18], 
      state: 6
    }, 
    {
      pos: [1, 10, 18], 
      state: 6
    }, 
    {
      pos: [2, 10, 18], 
      state: 6
    }, 
    {
      pos: [3, 10, 18], 
      state: 6
    }, 
    {
      pos: [2, 10, 19], 
      state: 6
    }, 
    {
      pos: [3, 10, 19], 
      state: 6
    }, 
    {
      pos: [0, 10, 20], 
      state: 6
    }, 
    {
      pos: [1, 10, 20], 
      state: 6
    }, 
    {
      pos: [2, 10, 20], 
      state: 6
    }, 
    {
      pos: [3, 10, 20], 
      state: 6
    }, 
    {
      pos: [0, 10, 21], 
      state: 6
    }, 
    {
      pos: [2, 10, 21], 
      state: 6
    }, 
    {
      pos: [3, 10, 21], 
      state: 6
    }, 
    {
      pos: [4, 10, 21], 
      state: 6
    }, 
    {
      pos: [0, 10, 22], 
      state: 6
    }, 
    {
      pos: [0, 10, 23], 
      state: 6
    }, 
    {
      pos: [4, 10, 23], 
      state: 6
    }, 
    {
      pos: [4, 11, 1], 
      state: 0
    }, 
    {
      pos: [4, 11, 5], 
      state: 0
    }, 
    {
      pos: [0, 11, 9], 
      state: 7
    }, 
    {
      pos: [1, 11, 9], 
      state: 0
    }, 
    {
      pos: [2, 11, 9], 
      state: 0
    }, 
    {
      pos: [3, 11, 9], 
      state: 0
    }, 
    {
      pos: [4, 11, 9], 
      state: 0
    }, 
    {
      pos: [0, 11, 10], 
      state: 0
    }, 
    {
      pos: [1, 11, 10], 
      state: 0
    }, 
    {
      pos: [2, 11, 10], 
      state: 0
    }, 
    {
      pos: [3, 11, 10], 
      state: 0
    }, 
    {
      pos: [4, 11, 10], 
      state: 0
    }, 
    {
      pos: [0, 11, 11], 
      state: 0
    }, 
    {
      pos: [1, 11, 11], 
      state: 0
    }, 
    {
      pos: [2, 11, 11], 
      state: 0
    }, 
    {
      pos: [3, 11, 11], 
      state: 0
    }, 
    {
      pos: [4, 11, 11], 
      state: 7
    }, 
    {
      pos: [1, 11, 12], 
      state: 0
    }, 
    {
      pos: [2, 11, 12], 
      state: 0
    }, 
    {
      pos: [3, 11, 12], 
      state: 0
    }, 
    {
      pos: [4, 11, 12], 
      state: 0
    }, 
    {
      pos: [1, 11, 13], 
      state: 0
    }, 
    {
      pos: [2, 11, 13], 
      state: 0
    }, 
    {
      pos: [3, 11, 13], 
      state: 0
    }, 
    {
      pos: [4, 11, 13], 
      state: 7
    }, 
    {
      pos: [1, 11, 14], 
      state: 0
    }, 
    {
      pos: [2, 11, 14], 
      state: 0
    }, 
    {
      pos: [4, 11, 18], 
      state: 0
    }, 
    {
      pos: [4, 11, 22], 
      state: 7
    }, 
    {
      pos: [0, 11, 0], 
      state: 6
    }, 
    {
      pos: [1, 11, 0], 
      state: 6
    }, 
    {
      pos: [2, 11, 0], 
      state: 6
    }, 
    {
      pos: [3, 11, 0], 
      state: 6
    }, 
    {
      pos: [4, 11, 0], 
      state: 6
    }, 
    {
      pos: [0, 11, 1], 
      state: 6
    }, 
    {
      pos: [1, 11, 1], 
      state: 6
    }, 
    {
      pos: [2, 11, 1], 
      state: 6
    }, 
    {
      pos: [3, 11, 1], 
      state: 6
    }, 
    {
      pos: [0, 11, 2], 
      state: 6
    }, 
    {
      pos: [1, 11, 2], 
      state: 6
    }, 
    {
      pos: [2, 11, 2], 
      state: 6
    }, 
    {
      pos: [3, 11, 2], 
      state: 6
    }, 
    {
      pos: [4, 11, 2], 
      state: 6
    }, 
    {
      pos: [0, 11, 3], 
      state: 6
    }, 
    {
      pos: [1, 11, 3], 
      state: 6
    }, 
    {
      pos: [2, 11, 3], 
      state: 6
    }, 
    {
      pos: [3, 11, 3], 
      state: 6
    }, 
    {
      pos: [4, 11, 3], 
      state: 6
    }, 
    {
      pos: [0, 11, 4], 
      state: 6
    }, 
    {
      pos: [1, 11, 4], 
      state: 6
    }, 
    {
      pos: [2, 11, 4], 
      state: 6
    }, 
    {
      pos: [3, 11, 4], 
      state: 6
    }, 
    {
      pos: [4, 11, 4], 
      state: 6
    }, 
    {
      pos: [0, 11, 5], 
      state: 6
    }, 
    {
      pos: [1, 11, 5], 
      state: 6
    }, 
    {
      pos: [2, 11, 5], 
      state: 6
    }, 
    {
      pos: [3, 11, 5], 
      state: 6
    }, 
    {
      pos: [0, 11, 6], 
      state: 6
    }, 
    {
      pos: [1, 11, 6], 
      state: 6
    }, 
    {
      pos: [2, 11, 6], 
      state: 6
    }, 
    {
      pos: [3, 11, 6], 
      state: 6
    }, 
    {
      pos: [4, 11, 6], 
      state: 6
    }, 
    {
      pos: [0, 11, 7], 
      state: 6
    }, 
    {
      pos: [1, 11, 7], 
      state: 6
    }, 
    {
      pos: [2, 11, 7], 
      state: 6
    }, 
    {
      pos: [3, 11, 7], 
      state: 6
    }, 
    {
      pos: [4, 11, 7], 
      state: 6
    }, 
    {
      pos: [0, 11, 8], 
      state: 6
    }, 
    {
      pos: [1, 11, 8], 
      state: 6
    }, 
    {
      pos: [2, 11, 8], 
      state: 6
    }, 
    {
      pos: [3, 11, 8], 
      state: 6
    }, 
    {
      pos: [4, 11, 8], 
      state: 6
    }, 
    {
      pos: [0, 11, 12], 
      state: 6
    }, 
    {
      pos: [0, 11, 13], 
      state: 6
    }, 
    {
      pos: [0, 11, 14], 
      state: 6
    }, 
    {
      pos: [3, 11, 14], 
      state: 6
    }, 
    {
      pos: [4, 11, 14], 
      state: 6
    }, 
    {
      pos: [0, 11, 15], 
      state: 6
    }, 
    {
      pos: [1, 11, 15], 
      state: 6
    }, 
    {
      pos: [2, 11, 15], 
      state: 6
    }, 
    {
      pos: [3, 11, 15], 
      state: 6
    }, 
    {
      pos: [4, 11, 15], 
      state: 6
    }, 
    {
      pos: [0, 11, 16], 
      state: 6
    }, 
    {
      pos: [1, 11, 16], 
      state: 6
    }, 
    {
      pos: [2, 11, 16], 
      state: 6
    }, 
    {
      pos: [3, 11, 16], 
      state: 6
    }, 
    {
      pos: [4, 11, 16], 
      state: 6
    }, 
    {
      pos: [0, 11, 17], 
      state: 6
    }, 
    {
      pos: [1, 11, 17], 
      state: 6
    }, 
    {
      pos: [2, 11, 17], 
      state: 6
    }, 
    {
      pos: [3, 11, 17], 
      state: 6
    }, 
    {
      pos: [4, 11, 17], 
      state: 6
    }, 
    {
      pos: [0, 11, 18], 
      state: 6
    }, 
    {
      pos: [1, 11, 18], 
      state: 6
    }, 
    {
      pos: [2, 11, 18], 
      state: 6
    }, 
    {
      pos: [3, 11, 18], 
      state: 6
    }, 
    {
      pos: [0, 11, 19], 
      state: 6
    }, 
    {
      pos: [1, 11, 19], 
      state: 6
    }, 
    {
      pos: [2, 11, 19], 
      state: 6
    }, 
    {
      pos: [3, 11, 19], 
      state: 6
    }, 
    {
      pos: [4, 11, 19], 
      state: 6
    }, 
    {
      pos: [0, 11, 20], 
      state: 6
    }, 
    {
      pos: [1, 11, 20], 
      state: 6
    }, 
    {
      pos: [2, 11, 20], 
      state: 6
    }, 
    {
      pos: [3, 11, 20], 
      state: 6
    }, 
    {
      pos: [4, 11, 20], 
      state: 6
    }, 
    {
      pos: [0, 11, 21], 
      state: 6
    }, 
    {
      pos: [1, 11, 21], 
      state: 6
    }, 
    {
      pos: [2, 11, 21], 
      state: 6
    }, 
    {
      pos: [3, 11, 21], 
      state: 6
    }, 
    {
      pos: [4, 11, 21], 
      state: 6
    }, 
    {
      pos: [0, 11, 22], 
      state: 6
    }, 
    {
      pos: [1, 11, 22], 
      state: 6
    }, 
    {
      pos: [2, 11, 22], 
      state: 6
    }, 
    {
      pos: [3, 11, 22], 
      state: 6
    }, 
    {
      pos: [0, 11, 23], 
      state: 6
    }, 
    {
      pos: [1, 11, 23], 
      state: 6
    }, 
    {
      pos: [2, 11, 23], 
      state: 6
    }, 
    {
      pos: [3, 11, 23], 
      state: 6
    }, 
    {
      pos: [4, 11, 23], 
      state: 6
    }, 
    {
      pos: [4, 12, 1], 
      state: 0
    }, 
    {
      pos: [4, 12, 5], 
      state: 0
    }, 
    {
      pos: [1, 12, 9], 
      state: 0
    }, 
    {
      pos: [2, 12, 9], 
      state: 0
    }, 
    {
      pos: [3, 12, 9], 
      state: 0
    }, 
    {
      pos: [4, 12, 9], 
      state: 0
    }, 
    {
      pos: [0, 12, 10], 
      state: 7
    }, 
    {
      pos: [1, 12, 10], 
      state: 0
    }, 
    {
      pos: [2, 12, 10], 
      state: 0
    }, 
    {
      pos: [3, 12, 10], 
      state: 0
    }, 
    {
      pos: [4, 12, 10], 
      state: 0
    }, 
    {
      pos: [0, 12, 11], 
      state: 0
    }, 
    {
      pos: [1, 12, 11], 
      state: 0
    }, 
    {
      pos: [2, 12, 11], 
      state: 0
    }, 
    {
      pos: [3, 12, 11], 
      state: 0
    }, 
    {
      pos: [4, 12, 11], 
      state: 7
    }, 
    {
      pos: [0, 12, 12], 
      state: 0
    }, 
    {
      pos: [1, 12, 12], 
      state: 0
    }, 
    {
      pos: [2, 12, 12], 
      state: 0
    }, 
    {
      pos: [3, 12, 12], 
      state: 0
    }, 
    {
      pos: [4, 12, 12], 
      state: 7
    }, 
    {
      pos: [0, 12, 13], 
      state: 0
    }, 
    {
      pos: [1, 12, 13], 
      state: 0
    }, 
    {
      pos: [2, 12, 13], 
      state: 0
    }, 
    {
      pos: [3, 12, 13], 
      state: 0
    }, 
    {
      pos: [4, 12, 13], 
      state: 9
    }, 
    {
      pos: [0, 12, 14], 
      state: 0
    }, 
    {
      pos: [1, 12, 14], 
      state: 0
    }, 
    {
      pos: [2, 12, 14], 
      state: 0
    }, 
    {
      pos: [3, 12, 14], 
      state: 0
    }, 
    {
      pos: [4, 12, 14], 
      state: 0
    }, 
    {
      pos: [4, 12, 22], 
      state: 0
    }, 
    {
      pos: [0, 12, 0], 
      state: 6
    }, 
    {
      pos: [1, 12, 0], 
      state: 6
    }, 
    {
      pos: [2, 12, 0], 
      state: 6
    }, 
    {
      pos: [3, 12, 0], 
      state: 6
    }, 
    {
      pos: [4, 12, 0], 
      state: 6
    }, 
    {
      pos: [0, 12, 1], 
      state: 6
    }, 
    {
      pos: [1, 12, 1], 
      state: 6
    }, 
    {
      pos: [2, 12, 1], 
      state: 6
    }, 
    {
      pos: [3, 12, 1], 
      state: 6
    }, 
    {
      pos: [0, 12, 2], 
      state: 6
    }, 
    {
      pos: [1, 12, 2], 
      state: 6
    }, 
    {
      pos: [2, 12, 2], 
      state: 6
    }, 
    {
      pos: [3, 12, 2], 
      state: 6
    }, 
    {
      pos: [4, 12, 2], 
      state: 6
    }, 
    {
      pos: [0, 12, 3], 
      state: 6
    }, 
    {
      pos: [1, 12, 3], 
      state: 6
    }, 
    {
      pos: [2, 12, 3], 
      state: 6
    }, 
    {
      pos: [3, 12, 3], 
      state: 6
    }, 
    {
      pos: [4, 12, 3], 
      state: 6
    }, 
    {
      pos: [0, 12, 4], 
      state: 6
    }, 
    {
      pos: [1, 12, 4], 
      state: 6
    }, 
    {
      pos: [2, 12, 4], 
      state: 6
    }, 
    {
      pos: [3, 12, 4], 
      state: 6
    }, 
    {
      pos: [4, 12, 4], 
      state: 6
    }, 
    {
      pos: [0, 12, 5], 
      state: 6
    }, 
    {
      pos: [1, 12, 5], 
      state: 6
    }, 
    {
      pos: [2, 12, 5], 
      state: 6
    }, 
    {
      pos: [3, 12, 5], 
      state: 6
    }, 
    {
      pos: [0, 12, 6], 
      state: 6
    }, 
    {
      pos: [1, 12, 6], 
      state: 6
    }, 
    {
      pos: [2, 12, 6], 
      state: 6
    }, 
    {
      pos: [3, 12, 6], 
      state: 6
    }, 
    {
      pos: [4, 12, 6], 
      state: 6
    }, 
    {
      pos: [0, 12, 7], 
      state: 6
    }, 
    {
      pos: [1, 12, 7], 
      state: 6
    }, 
    {
      pos: [2, 12, 7], 
      state: 6
    }, 
    {
      pos: [3, 12, 7], 
      state: 6
    }, 
    {
      pos: [4, 12, 7], 
      state: 6
    }, 
    {
      pos: [0, 12, 8], 
      state: 6
    }, 
    {
      pos: [1, 12, 8], 
      state: 6
    }, 
    {
      pos: [2, 12, 8], 
      state: 6
    }, 
    {
      pos: [3, 12, 8], 
      state: 6
    }, 
    {
      pos: [4, 12, 8], 
      state: 6
    }, 
    {
      pos: [0, 12, 9], 
      state: 6
    }, 
    {
      pos: [0, 12, 15], 
      state: 6
    }, 
    {
      pos: [1, 12, 15], 
      state: 6
    }, 
    {
      pos: [2, 12, 15], 
      state: 6
    }, 
    {
      pos: [3, 12, 15], 
      state: 6
    }, 
    {
      pos: [4, 12, 15], 
      state: 6
    }, 
    {
      pos: [0, 12, 16], 
      state: 6
    }, 
    {
      pos: [1, 12, 16], 
      state: 6
    }, 
    {
      pos: [2, 12, 16], 
      state: 6
    }, 
    {
      pos: [3, 12, 16], 
      state: 6
    }, 
    {
      pos: [4, 12, 16], 
      state: 6
    }, 
    {
      pos: [0, 12, 17], 
      state: 6
    }, 
    {
      pos: [1, 12, 17], 
      state: 6
    }, 
    {
      pos: [2, 12, 17], 
      state: 6
    }, 
    {
      pos: [3, 12, 17], 
      state: 6
    }, 
    {
      pos: [4, 12, 17], 
      state: 6
    }, 
    {
      pos: [0, 12, 18], 
      state: 6
    }, 
    {
      pos: [1, 12, 18], 
      state: 6
    }, 
    {
      pos: [2, 12, 18], 
      state: 6
    }, 
    {
      pos: [3, 12, 18], 
      state: 6
    }, 
    {
      pos: [4, 12, 18], 
      state: 6
    }, 
    {
      pos: [0, 12, 19], 
      state: 6
    }, 
    {
      pos: [1, 12, 19], 
      state: 6
    }, 
    {
      pos: [2, 12, 19], 
      state: 6
    }, 
    {
      pos: [3, 12, 19], 
      state: 6
    }, 
    {
      pos: [4, 12, 19], 
      state: 6
    }, 
    {
      pos: [0, 12, 20], 
      state: 6
    }, 
    {
      pos: [1, 12, 20], 
      state: 6
    }, 
    {
      pos: [2, 12, 20], 
      state: 6
    }, 
    {
      pos: [3, 12, 20], 
      state: 6
    }, 
    {
      pos: [4, 12, 20], 
      state: 6
    }, 
    {
      pos: [0, 12, 21], 
      state: 6
    }, 
    {
      pos: [1, 12, 21], 
      state: 6
    }, 
    {
      pos: [2, 12, 21], 
      state: 6
    }, 
    {
      pos: [3, 12, 21], 
      state: 6
    }, 
    {
      pos: [4, 12, 21], 
      state: 6
    }, 
    {
      pos: [0, 12, 22], 
      state: 6
    }, 
    {
      pos: [1, 12, 22], 
      state: 6
    }, 
    {
      pos: [2, 12, 22], 
      state: 6
    }, 
    {
      pos: [3, 12, 22], 
      state: 6
    }, 
    {
      pos: [0, 12, 23], 
      state: 6
    }, 
    {
      pos: [1, 12, 23], 
      state: 6
    }, 
    {
      pos: [2, 12, 23], 
      state: 6
    }, 
    {
      pos: [3, 12, 23], 
      state: 6
    }, 
    {
      pos: [4, 12, 23], 
      state: 6
    }, 
    {
      pos: [0, 13, 0], 
      state: 0
    }, 
    {
      pos: [1, 13, 0], 
      state: 0
    }, 
    {
      pos: [2, 13, 0], 
      state: 0
    }, 
    {
      pos: [3, 13, 0], 
      state: 0
    }, 
    {
      pos: [4, 13, 0], 
      state: 0
    }, 
    {
      pos: [0, 13, 1], 
      state: 0
    }, 
    {
      pos: [1, 13, 1], 
      state: 0
    }, 
    {
      pos: [2, 13, 1], 
      state: 0
    }, 
    {
      pos: [3, 13, 1], 
      state: 0
    }, 
    {
      pos: [4, 13, 1], 
      state: 0
    }, 
    {
      pos: [0, 13, 2], 
      state: 0
    }, 
    {
      pos: [1, 13, 2], 
      state: 0
    }, 
    {
      pos: [2, 13, 2], 
      state: 0
    }, 
    {
      pos: [3, 13, 2], 
      state: 0
    }, 
    {
      pos: [4, 13, 2], 
      state: 0
    }, 
    {
      pos: [0, 13, 3], 
      state: 0
    }, 
    {
      pos: [1, 13, 3], 
      state: 0
    }, 
    {
      pos: [2, 13, 3], 
      state: 0
    }, 
    {
      pos: [3, 13, 3], 
      state: 0
    }, 
    {
      pos: [4, 13, 3], 
      state: 0
    }, 
    {
      pos: [0, 13, 4], 
      state: 0
    }, 
    {
      pos: [1, 13, 4], 
      state: 0
    }, 
    {
      pos: [2, 13, 4], 
      state: 0
    }, 
    {
      pos: [3, 13, 4], 
      state: 0
    }, 
    {
      pos: [4, 13, 4], 
      state: 0
    }, 
    {
      pos: [0, 13, 5], 
      state: 0
    }, 
    {
      pos: [1, 13, 5], 
      state: 0
    }, 
    {
      pos: [2, 13, 5], 
      state: 0
    }, 
    {
      pos: [3, 13, 5], 
      state: 0
    }, 
    {
      pos: [4, 13, 5], 
      state: 0
    }, 
    {
      pos: [0, 13, 6], 
      state: 0
    }, 
    {
      pos: [1, 13, 6], 
      state: 0
    }, 
    {
      pos: [2, 13, 6], 
      state: 0
    }, 
    {
      pos: [3, 13, 6], 
      state: 0
    }, 
    {
      pos: [4, 13, 6], 
      state: 0
    }, 
    {
      pos: [0, 13, 7], 
      state: 7
    }, 
    {
      pos: [1, 13, 7], 
      state: 7
    }, 
    {
      pos: [2, 13, 7], 
      state: 0
    }, 
    {
      pos: [3, 13, 7], 
      state: 0
    }, 
    {
      pos: [4, 13, 7], 
      state: 0
    }, 
    {
      pos: [0, 13, 8], 
      state: 7
    }, 
    {
      pos: [1, 13, 8], 
      state: 0
    }, 
    {
      pos: [2, 13, 8], 
      state: 0
    }, 
    {
      pos: [3, 13, 8], 
      state: 0
    }, 
    {
      pos: [4, 13, 8], 
      state: 0
    }, 
    {
      pos: [1, 13, 9], 
      state: 7
    }, 
    {
      pos: [2, 13, 9], 
      state: 0
    }, 
    {
      pos: [3, 13, 9], 
      state: 0
    }, 
    {
      pos: [4, 13, 9], 
      state: 0
    }, 
    {
      pos: [1, 13, 10], 
      state: 7
    }, 
    {
      pos: [2, 13, 10], 
      state: 0
    }, 
    {
      pos: [3, 13, 10], 
      state: 0
    }, 
    {
      pos: [4, 13, 10], 
      state: 0
    }, 
    {
      pos: [0, 13, 11], 
      state: 7
    }, 
    {
      pos: [1, 13, 11], 
      state: 7
    }, 
    {
      pos: [2, 13, 11], 
      state: 0
    }, 
    {
      pos: [3, 13, 11], 
      state: 0
    }, 
    {
      pos: [0, 13, 12], 
      state: 7
    }, 
    {
      pos: [1, 13, 12], 
      state: 0
    }, 
    {
      pos: [2, 13, 12], 
      state: 0
    }, 
    {
      pos: [3, 13, 12], 
      state: 0
    }, 
    {
      pos: [0, 13, 13], 
      state: 7
    }, 
    {
      pos: [1, 13, 13], 
      state: 7
    }, 
    {
      pos: [2, 13, 13], 
      state: 0
    }, 
    {
      pos: [3, 13, 13], 
      state: 0
    }, 
    {
      pos: [4, 13, 13], 
      state: 9
    }, 
    {
      pos: [0, 13, 14], 
      state: 0
    }, 
    {
      pos: [1, 13, 14], 
      state: 7
    }, 
    {
      pos: [2, 13, 14], 
      state: 0
    }, 
    {
      pos: [3, 13, 14], 
      state: 0
    }, 
    {
      pos: [4, 13, 14], 
      state: 0
    }, 
    {
      pos: [0, 13, 15], 
      state: 0
    }, 
    {
      pos: [1, 13, 15], 
      state: 0
    }, 
    {
      pos: [2, 13, 15], 
      state: 0
    }, 
    {
      pos: [3, 13, 15], 
      state: 0
    }, 
    {
      pos: [4, 13, 15], 
      state: 0
    }, 
    {
      pos: [0, 13, 16], 
      state: 0
    }, 
    {
      pos: [1, 13, 16], 
      state: 0
    }, 
    {
      pos: [2, 13, 16], 
      state: 0
    }, 
    {
      pos: [3, 13, 16], 
      state: 0
    }, 
    {
      pos: [4, 13, 16], 
      state: 0
    }, 
    {
      pos: [0, 13, 17], 
      state: 0
    }, 
    {
      pos: [2, 13, 17], 
      state: 7
    }, 
    {
      pos: [3, 13, 17], 
      state: 0
    }, 
    {
      pos: [4, 13, 17], 
      state: 0
    }, 
    {
      pos: [0, 13, 18], 
      state: 7
    }, 
    {
      pos: [1, 13, 18], 
      state: 7
    }, 
    {
      pos: [2, 13, 18], 
      state: 0
    }, 
    {
      pos: [3, 13, 18], 
      state: 0
    }, 
    {
      pos: [1, 13, 19], 
      state: 7
    }, 
    {
      pos: [2, 13, 19], 
      state: 0
    }, 
    {
      pos: [3, 13, 19], 
      state: 0
    }, 
    {
      pos: [0, 13, 20], 
      state: 0
    }, 
    {
      pos: [2, 13, 20], 
      state: 0
    }, 
    {
      pos: [3, 13, 20], 
      state: 0
    }, 
    {
      pos: [4, 13, 20], 
      state: 0
    }, 
    {
      pos: [0, 13, 21], 
      state: 0
    }, 
    {
      pos: [3, 13, 21], 
      state: 0
    }, 
    {
      pos: [4, 13, 21], 
      state: 0
    }, 
    {
      pos: [0, 13, 22], 
      state: 0
    }, 
    {
      pos: [2, 13, 22], 
      state: 0
    }, 
    {
      pos: [3, 13, 22], 
      state: 0
    }, 
    {
      pos: [4, 13, 22], 
      state: 0
    }, 
    {
      pos: [2, 13, 23], 
      state: 0
    }, 
    {
      pos: [3, 13, 23], 
      state: 0
    }, 
    {
      pos: [4, 13, 23], 
      state: 0
    }, 
    {
      pos: [0, 13, 9], 
      state: 6
    }, 
    {
      pos: [0, 13, 10], 
      state: 6
    }, 
    {
      pos: [4, 13, 11], 
      state: 6
    }, 
    {
      pos: [4, 13, 12], 
      state: 6
    }, 
    {
      pos: [1, 13, 17], 
      state: 6
    }, 
    {
      pos: [4, 13, 18], 
      state: 6
    }, 
    {
      pos: [0, 13, 19], 
      state: 6
    }, 
    {
      pos: [4, 13, 19], 
      state: 6
    }, 
    {
      pos: [1, 13, 20], 
      state: 6
    }, 
    {
      pos: [1, 13, 21], 
      state: 6
    }, 
    {
      pos: [2, 13, 21], 
      state: 6
    }, 
    {
      pos: [1, 13, 22], 
      state: 6
    }, 
    {
      pos: [0, 13, 23], 
      state: 6
    }, 
    {
      pos: [1, 13, 23], 
      state: 6
    }, 
    {
      pos: [0, 14, 0], 
      state: 0
    }, 
    {
      pos: [1, 14, 0], 
      state: 0
    }, 
    {
      pos: [2, 14, 0], 
      state: 0
    }, 
    {
      pos: [3, 14, 0], 
      state: 0
    }, 
    {
      pos: [4, 14, 0], 
      state: 0
    }, 
    {
      pos: [0, 14, 1], 
      state: 0
    }, 
    {
      pos: [1, 14, 1], 
      state: 0
    }, 
    {
      pos: [2, 14, 1], 
      state: 0
    }, 
    {
      pos: [3, 14, 1], 
      state: 0
    }, 
    {
      pos: [4, 14, 1], 
      state: 0
    }, 
    {
      pos: [0, 14, 2], 
      state: 0
    }, 
    {
      pos: [1, 14, 2], 
      state: 0
    }, 
    {
      pos: [2, 14, 2], 
      state: 0
    }, 
    {
      pos: [3, 14, 2], 
      state: 0
    }, 
    {
      pos: [4, 14, 2], 
      state: 0
    }, 
    {
      pos: [0, 14, 3], 
      state: 0
    }, 
    {
      pos: [1, 14, 3], 
      state: 0
    }, 
    {
      pos: [2, 14, 3], 
      state: 0
    }, 
    {
      pos: [3, 14, 3], 
      state: 0
    }, 
    {
      pos: [4, 14, 3], 
      state: 0
    }, 
    {
      pos: [0, 14, 4], 
      state: 0
    }, 
    {
      pos: [1, 14, 4], 
      state: 0
    }, 
    {
      pos: [2, 14, 4], 
      state: 7
    }, 
    {
      pos: [4, 14, 4], 
      state: 0
    }, 
    {
      pos: [0, 14, 5], 
      state: 0
    }, 
    {
      pos: [1, 14, 5], 
      state: 7
    }, 
    {
      pos: [3, 14, 5], 
      state: 0
    }, 
    {
      pos: [4, 14, 5], 
      state: 0
    }, 
    {
      pos: [1, 14, 6], 
      state: 7
    }, 
    {
      pos: [4, 14, 6], 
      state: 0
    }, 
    {
      pos: [1, 14, 7], 
      state: 7
    }, 
    {
      pos: [3, 14, 7], 
      state: 0
    }, 
    {
      pos: [4, 14, 7], 
      state: 0
    }, 
    {
      pos: [1, 14, 8], 
      state: 7
    }, 
    {
      pos: [3, 14, 8], 
      state: 0
    }, 
    {
      pos: [2, 14, 9], 
      state: 0
    }, 
    {
      pos: [3, 14, 9], 
      state: 0
    }, 
    {
      pos: [4, 14, 9], 
      state: 0
    }, 
    {
      pos: [2, 14, 10], 
      state: 0
    }, 
    {
      pos: [2, 14, 11], 
      state: 0
    }, 
    {
      pos: [3, 14, 11], 
      state: 0
    }, 
    {
      pos: [1, 14, 12], 
      state: 7
    }, 
    {
      pos: [2, 14, 12], 
      state: 0
    }, 
    {
      pos: [2, 14, 13], 
      state: 7
    }, 
    {
      pos: [3, 14, 13], 
      state: 0
    }, 
    {
      pos: [4, 14, 13], 
      state: 9
    }, 
    {
      pos: [0, 14, 14], 
      state: 7
    }, 
    {
      pos: [1, 14, 14], 
      state: 7
    }, 
    {
      pos: [2, 14, 14], 
      state: 0
    }, 
    {
      pos: [3, 14, 14], 
      state: 0
    }, 
    {
      pos: [1, 14, 15], 
      state: 7
    }, 
    {
      pos: [2, 14, 15], 
      state: 0
    }, 
    {
      pos: [3, 14, 15], 
      state: 0
    }, 
    {
      pos: [1, 14, 16], 
      state: 7
    }, 
    {
      pos: [2, 14, 16], 
      state: 0
    }, 
    {
      pos: [3, 14, 16], 
      state: 0
    }, 
    {
      pos: [3, 14, 17], 
      state: 0
    }, 
    {
      pos: [2, 14, 18], 
      state: 7
    }, 
    {
      pos: [3, 14, 18], 
      state: 0
    }, 
    {
      pos: [2, 14, 19], 
      state: 7
    }, 
    {
      pos: [3, 14, 19], 
      state: 0
    }, 
    {
      pos: [2, 14, 20], 
      state: 7
    }, 
    {
      pos: [3, 14, 20], 
      state: 0
    }, 
    {
      pos: [3, 14, 21], 
      state: 0
    }, 
    {
      pos: [4, 14, 22], 
      state: 0
    }, 
    {
      pos: [3, 14, 23], 
      state: 0
    }, 
    {
      pos: [4, 14, 23], 
      state: 0
    }, 
    {
      pos: [3, 14, 4], 
      state: 6
    }, 
    {
      pos: [2, 14, 5], 
      state: 6
    }, 
    {
      pos: [0, 14, 6], 
      state: 6
    }, 
    {
      pos: [2, 14, 6], 
      state: 6
    }, 
    {
      pos: [3, 14, 6], 
      state: 6
    }, 
    {
      pos: [0, 14, 7], 
      state: 6
    }, 
    {
      pos: [2, 14, 7], 
      state: 6
    }, 
    {
      pos: [0, 14, 8], 
      state: 6
    }, 
    {
      pos: [2, 14, 8], 
      state: 6
    }, 
    {
      pos: [4, 14, 8], 
      state: 6
    }, 
    {
      pos: [0, 14, 9], 
      state: 6
    }, 
    {
      pos: [1, 14, 9], 
      state: 6
    }, 
    {
      pos: [0, 14, 10], 
      state: 6
    }, 
    {
      pos: [1, 14, 10], 
      state: 6
    }, 
    {
      pos: [3, 14, 10], 
      state: 6
    }, 
    {
      pos: [4, 14, 10], 
      state: 6
    }, 
    {
      pos: [0, 14, 11], 
      state: 6
    }, 
    {
      pos: [1, 14, 11], 
      state: 6
    }, 
    {
      pos: [4, 14, 11], 
      state: 6
    }, 
    {
      pos: [0, 14, 12], 
      state: 6
    }, 
    {
      pos: [3, 14, 12], 
      state: 6
    }, 
    {
      pos: [4, 14, 12], 
      state: 6
    }, 
    {
      pos: [0, 14, 13], 
      state: 6
    }, 
    {
      pos: [1, 14, 13], 
      state: 6
    }, 
    {
      pos: [4, 14, 14], 
      state: 6
    }, 
    {
      pos: [0, 14, 15], 
      state: 6
    }, 
    {
      pos: [4, 14, 15], 
      state: 6
    }, 
    {
      pos: [0, 14, 16], 
      state: 6
    }, 
    {
      pos: [4, 14, 16], 
      state: 6
    }, 
    {
      pos: [0, 14, 17], 
      state: 6
    }, 
    {
      pos: [1, 14, 17], 
      state: 6
    }, 
    {
      pos: [2, 14, 17], 
      state: 6
    }, 
    {
      pos: [4, 14, 17], 
      state: 6
    }, 
    {
      pos: [0, 14, 18], 
      state: 6
    }, 
    {
      pos: [1, 14, 18], 
      state: 6
    }, 
    {
      pos: [4, 14, 18], 
      state: 6
    }, 
    {
      pos: [0, 14, 19], 
      state: 6
    }, 
    {
      pos: [1, 14, 19], 
      state: 6
    }, 
    {
      pos: [4, 14, 19], 
      state: 6
    }, 
    {
      pos: [0, 14, 20], 
      state: 6
    }, 
    {
      pos: [1, 14, 20], 
      state: 6
    }, 
    {
      pos: [4, 14, 20], 
      state: 6
    }, 
    {
      pos: [0, 14, 21], 
      state: 6
    }, 
    {
      pos: [1, 14, 21], 
      state: 6
    }, 
    {
      pos: [2, 14, 21], 
      state: 6
    }, 
    {
      pos: [4, 14, 21], 
      state: 6
    }, 
    {
      pos: [0, 14, 22], 
      state: 6
    }, 
    {
      pos: [1, 14, 22], 
      state: 6
    }, 
    {
      pos: [2, 14, 22], 
      state: 6
    }, 
    {
      pos: [3, 14, 22], 
      state: 6
    }, 
    {
      pos: [0, 14, 23], 
      state: 6
    }, 
    {
      pos: [1, 14, 23], 
      state: 6
    }, 
    {
      pos: [2, 14, 23], 
      state: 6
    }
  ], 
  palette: [
    {
      Name: "minecraft:polished_blackstone_bricks"
    }, 
    {
      Name: "minecraft:blackstone"
    }, 
    {
      Properties: {
        orientation: "north_up"
      }, 
      Name: "minecraft:jigsaw"
    }, 
    {
      Properties: {
        orientation: "east_up"
      }, 
      Name: "minecraft:jigsaw"
    }, 
    {
      Properties: {
        orientation: "west_up"
      }, 
      Name: "minecraft:jigsaw"
    }, 
    {
      Properties: {
        orientation: "south_up"
      }, 
      Name: "minecraft:jigsaw"
    }, 
    {
      Name: "minecraft:air"
    }, 
    {
      Properties: {
        axis: "y"
      }, 
      Name: "minecraft:basalt"
    }, 
    {
      Properties: {
        level: "8"
      }, 
      Name: "minecraft:lava"
    }, 
    {
      Name: "minecraft:cracked_polished_blackstone_bricks"
    }, 
    {
      Properties: {
        level: "2"
      }, 
      Name: "minecraft:lava"
    }, 
    {
      Properties: {
        hanging: "true"
      }, 
      Name: "minecraft:lantern"
    }, 
    {
      Properties: {
        waterlogged: "false"
      }, 
      Name: "minecraft:chain"
    }, 
    {
      Properties: {
        level: "0"
      }, 
      Name: "minecraft:lava"
    }, 
    {
      Properties: {
        axis: "x"
      }, 
      Name: "minecraft:basalt"
    }, 
    {
      Properties: {
        half: "bottom", 
        waterlogged: "false", 
        shape: "straight", 
        facing: "west"
      }, 
      Name: "minecraft:blackstone_stairs"
    }, 
    {
      Properties: {
        orientation: "up_south"
      }, 
      Name: "minecraft:jigsaw"
    }, 
    {
      Properties: {
        orientation: "up_west"
      }, 
      Name: "minecraft:jigsaw"
    }
  ]
}
