{
  size: [12, 10, 12], 
  entities: [
    {
      nbt: {
        Motion: [0.0d, 0.0d, 0.0d], 
        color: "brown", 
        block_pos: [I; -87, -61, 229], 
        Invulnerable: 0b, 
        Air: 300s, 
        OnGround: 0b, 
        fall_distance: 0.0d, 
        PortalCooldown: 0, 
        Rotation: [0.0f, 0.0f], 
        Pos: [-86.5d, -60.0625d, 229.5d], 
        Fire: 0s, 
        id: "minecraft:cushion", 
        UUID: [I; -389131759, -1812182476, -1514367543, 1357476207]
      }, 
      blockPos: [7, 0, 9], 
      pos: [7.5d, 0.9375d, 9.5d]
    }, 
    {
      nbt: {
        Motion: [0.0d, 0.0d, 0.0d], 
        color: "green", 
        block_pos: [I; -89, -60, 227], 
        Invulnerable: 0b, 
        Air: 300s, 
        OnGround: 0b, 
        fall_distance: 0.0d, 
        PortalCooldown: 0, 
        Rotation: [90.0f, 0.0f], 
        Pos: [-88.5d, -60.0d, 227.5d], 
        Fire: 0s, 
        id: "minecraft:cushion", 
        UUID: [I; 299144012, 1757301618, -2096348184, -626120290]
      }, 
      blockPos: [5, 1, 7], 
      pos: [5.5d, 1.0d, 7.5d]
    }
  ], 
  blocks: [
    {
      pos: [2, 0, 5], 
      state: 0
    }, 
    {
      pos: [2, 0, 6], 
      state: 0
    }, 
    {
      pos: [2, 0, 7], 
      state: 0
    }, 
    {
      pos: [2, 0, 8], 
      state: 0
    }, 
    {
      pos: [2, 0, 9], 
      state: 0
    }, 
    {
      pos: [3, 0, 4], 
      state: 0
    }, 
    {
      pos: [3, 0, 5], 
      state: 0
    }, 
    {
      pos: [3, 0, 6], 
      state: 0
    }, 
    {
      pos: [3, 0, 7], 
      state: 0
    }, 
    {
      pos: [3, 0, 8], 
      state: 0
    }, 
    {
      pos: [3, 0, 9], 
      state: 0
    }, 
    {
      pos: [3, 0, 10], 
      state: 0
    }, 
    {
      pos: [4, 0, 3], 
      state: 1
    }, 
    {
      pos: [4, 0, 4], 
      state: 0
    }, 
    {
      pos: [4, 0, 5], 
      state: 0
    }, 
    {
      pos: [4, 0, 6], 
      state: 2
    }, 
    {
      pos: [4, 0, 7], 
      state: 2
    }, 
    {
      pos: [4, 0, 8], 
      state: 2
    }, 
    {
      pos: [4, 0, 9], 
      state: 2
    }, 
    {
      pos: [4, 0, 10], 
      state: 2
    }, 
    {
      pos: [5, 0, 3], 
      state: 0
    }, 
    {
      pos: [5, 0, 4], 
      state: 0
    }, 
    {
      pos: [5, 0, 5], 
      state: 2
    }, 
    {
      pos: [5, 0, 6], 
      state: 2
    }, 
    {
      pos: [5, 0, 7], 
      state: 2
    }, 
    {
      pos: [6, 0, 4], 
      state: 0
    }, 
    {
      pos: [6, 0, 5], 
      state: 2
    }, 
    {
      pos: [6, 0, 6], 
      state: 2
    }, 
    {
      pos: [6, 0, 8], 
      state: 0
    }, 
    {
      pos: [7, 0, 3], 
      state: 3
    }, 
    {
      pos: [7, 0, 4], 
      state: 3
    }, 
    {
      pos: [8, 0, 3], 
      state: 3
    }, 
    {
      pos: [8, 0, 6], 
      state: 4
    }, 
    {
      pos: [2, 1, 5], 
      state: 1
    }, 
    {
      pos: [2, 1, 6], 
      state: 5
    }, 
    {
      pos: [2, 1, 7], 
      state: 6
    }, 
    {
      pos: [2, 1, 8], 
      state: 1
    }, 
    {
      pos: [2, 1, 9], 
      state: 6
    }, 
    {
      pos: [3, 1, 4], 
      state: 5
    }, 
    {
      pos: [3, 1, 5], 
      state: 6
    }, 
    {
      pos: [3, 1, 9], 
      state: 5
    }, 
    {
      pos: [3, 1, 10], 
      state: 1
    }, 
    {
      pos: [4, 1, 4], 
      state: 6
    }, 
    {
      pos: [4, 1, 5], 
      state: 5
    }, 
    {
      pos: [5, 1, 3], 
      state: 1
    }, 
    {
      pos: [5, 1, 4], 
      state: 5
    }, 
    {
      pos: [6, 1, 4], 
      state: 5
    }, 
    {
      pos: [2, 2, 8], 
      state: 1
    }, 
    {
      pos: [3, 2, 5], 
      state: 1
    }, 
    {
      pos: [3, 2, 6], 
      state: 1
    }, 
    {
      pos: [3, 2, 7], 
      state: 1
    }, 
    {
      pos: [3, 2, 8], 
      state: 1
    }, 
    {
      pos: [3, 2, 9], 
      state: 1
    }, 
    {
      pos: [4, 2, 5], 
      state: 5
    }, 
    {
      pos: [4, 2, 6], 
      state: 5
    }, 
    {
      pos: [4, 2, 9], 
      state: 1
    }, 
    {
      pos: [5, 2, 4], 
      state: 1
    }, 
    {
      pos: [5, 2, 5], 
      state: 5
    }, 
    {
      pos: [6, 2, 4], 
      state: 1
    }, 
    {
      pos: [3, 3, 7], 
      state: 5
    }, 
    {
      pos: [4, 3, 5], 
      state: 1
    }, 
    {
      pos: [4, 3, 6], 
      state: 6
    }, 
    {
      pos: [4, 3, 7], 
      state: 6
    }, 
    {
      pos: [4, 3, 8], 
      state: 6
    }, 
    {
      pos: [5, 3, 5], 
      state: 5
    }, 
    {
      pos: [5, 3, 6], 
      state: 5
    }, 
    {
      pos: [5, 3, 7], 
      state: 6
    }, 
    {
      pos: [6, 3, 4], 
      state: 5
    }, 
    {
      pos: [6, 3, 5], 
      state: 5
    }, 
    {
      pos: [6, 3, 6], 
      state: 6
    }, 
    {
      pos: [5, 0, 8], 
      state: 7
    }, 
    {
      pos: [5, 0, 9], 
      state: 7
    }, 
    {
      pos: [5, 0, 10], 
      state: 7
    }, 
    {
      pos: [5, 0, 11], 
      state: 7
    }, 
    {
      pos: [6, 0, 7], 
      state: 7
    }, 
    {
      pos: [6, 0, 9], 
      state: 7
    }, 
    {
      pos: [6, 0, 11], 
      state: 7
    }, 
    {
      pos: [7, 0, 7], 
      state: 7
    }, 
    {
      pos: [7, 0, 8], 
      state: 7
    }, 
    {
      pos: [7, 0, 9], 
      state: 7
    }, 
    {
      pos: [7, 0, 10], 
      state: 7
    }, 
    {
      pos: [7, 0, 11], 
      state: 7
    }, 
    {
      pos: [8, 0, 7], 
      state: 7
    }, 
    {
      pos: [8, 0, 8], 
      state: 7
    }, 
    {
      pos: [8, 0, 9], 
      state: 7
    }, 
    {
      pos: [8, 0, 11], 
      state: 7
    }, 
    {
      pos: [9, 0, 6], 
      state: 7
    }, 
    {
      pos: [9, 0, 7], 
      state: 7
    }, 
    {
      pos: [9, 0, 8], 
      state: 7
    }, 
    {
      pos: [9, 0, 9], 
      state: 7
    }, 
    {
      pos: [9, 0, 10], 
      state: 7
    }, 
    {
      pos: [10, 0, 6], 
      state: 7
    }, 
    {
      pos: [10, 0, 7], 
      state: 7
    }, 
    {
      pos: [11, 0, 7], 
      state: 7
    }, 
    {
      pos: [8, 1, 6], 
      state: 8
    }, 
    {
      nbt: {
        components: {}, 
        joint: "rollable", 
        final_state: "minecraft:dirt", 
        name: "minecraft:bottom", 
        placement_priority: 0, 
        pool: "minecraft:abandoned_camp/trees/mega_pine", 
        selection_priority: 0, 
        id: "minecraft:jigsaw", 
        target: "minecraft:bottom"
      }, 
      pos: [8, 0, 4], 
      state: 9
    }, 
    {
      nbt: {
        components: {}, 
        joint: "rollable", 
        final_state: "minecraft:dirt_path", 
        name: "minecraft:end_connector", 
        placement_priority: 0, 
        pool: "minecraft:empty", 
        selection_priority: 0, 
        id: "minecraft:jigsaw", 
        target: "minecraft:connector"
      }, 
      pos: [11, 0, 6], 
      state: 10
    }, 
    {
      nbt: {
        LootTable: "minecraft:barrels/abandoned_camp_barrel", 
        components: {}, 
        id: "minecraft:barrel"
      }, 
      pos: [3, 1, 8], 
      state: 11
    }, 
    {
      nbt: {
        components: {}, 
        Items: [], 
        CookingTimes: [I; 0, 0, 0, 0], 
        CookingTotalTimes: [I; 0, 0, 0, 0], 
        id: "minecraft:campfire"
      }, 
      pos: [6, 1, 8], 
      state: 12
    }
  ], 
  palette: [
    {
      Name: "minecraft:dirt"
    }, 
    {
      Name: "minecraft:mossy_cobblestone"
    }, 
    {
      Name: "minecraft:gravel"
    }, 
    {
      Properties: {
        snowy: "false"
      }, 
      Name: "minecraft:podzol"
    }, 
    {
      Properties: {
        snowy: "false"
      }, 
      Name: "minecraft:grass_block"
    }, 
    {
      Name: "minecraft:stone"
    }, 
    {
      Name: "minecraft:cobblestone"
    }, 
    {
      Name: "minecraft:dirt_path"
    }, 
    {
      Properties: {
        east: "false", 
        waterlogged: "false", 
        south: "false", 
        north: "false", 
        west: "false"
      }, 
      Name: "minecraft:spruce_fence"
    }, 
    {
      Properties: {
        orientation: "up_south"
      }, 
      Name: "minecraft:jigsaw"
    }, 
    {
      Properties: {
        orientation: "east_up"
      }, 
      Name: "minecraft:jigsaw"
    }, 
    {
      Properties: {
        facing: "east", 
        open: "false"
      }, 
      Name: "minecraft:barrel"
    }, 
    {
      Properties: {
        waterlogged: "false", 
        signal_fire: "false", 
        lit: "false", 
        facing: "west"
      }, 
      Name: "minecraft:campfire"
    }
  ]
}
