{
  size: [10, 10, 10], 
  entities: [
    {
      nbt: {
        Motion: [0.0d, 0.0d, 0.0d], 
        color: "green", 
        block_pos: [I; -105, -61, 225], 
        Invulnerable: 0b, 
        Air: 300s, 
        OnGround: 0b, 
        fall_distance: 0.0d, 
        PortalCooldown: 0, 
        Rotation: [90.0f, 0.0f], 
        Pos: [-104.5d, -60.0625d, 225.5d], 
        Fire: 0s, 
        id: "minecraft:cushion", 
        UUID: [I; 977809131, 1059015783, -1672180861, -1818617641]
      }, 
      blockPos: [6, 0, 3], 
      pos: [6.5d, 0.9375d, 3.5d]
    }, 
    {
      nbt: {
        Motion: [0.0d, 0.0d, 0.0d], 
        color: "green", 
        block_pos: [I; -104, -61, 227], 
        Invulnerable: 0b, 
        Air: 300s, 
        OnGround: 0b, 
        fall_distance: 0.0d, 
        PortalCooldown: 0, 
        Rotation: [90.0f, 0.0f], 
        Pos: [-103.5d, -60.0625d, 227.5d], 
        Fire: 0s, 
        id: "minecraft:cushion", 
        UUID: [I; 2015922119, -1352972579, -1124772188, 1624056353]
      }, 
      blockPos: [7, 0, 5], 
      pos: [7.5d, 0.9375d, 5.5d]
    }
  ], 
  blocks: [
    {
      pos: [2, 0, 6], 
      state: 0
    }, 
    {
      pos: [2, 0, 7], 
      state: 0
    }, 
    {
      pos: [2, 0, 8], 
      state: 0
    }, 
    {
      pos: [3, 0, 6], 
      state: 0
    }, 
    {
      pos: [3, 0, 7], 
      state: 0
    }, 
    {
      pos: [3, 0, 8], 
      state: 0
    }, 
    {
      pos: [4, 0, 6], 
      state: 0
    }, 
    {
      pos: [4, 0, 7], 
      state: 0
    }, 
    {
      pos: [4, 0, 8], 
      state: 0
    }, 
    {
      pos: [5, 0, 3], 
      state: 1
    }, 
    {
      pos: [6, 0, 1], 
      state: 2
    }, 
    {
      pos: [6, 0, 2], 
      state: 2
    }, 
    {
      pos: [6, 0, 4], 
      state: 1
    }, 
    {
      pos: [7, 0, 1], 
      state: 2
    }, 
    {
      pos: [7, 0, 7], 
      state: 0
    }, 
    {
      pos: [8, 0, 6], 
      state: 0
    }, 
    {
      pos: [8, 0, 7], 
      state: 0
    }, 
    {
      pos: [8, 0, 8], 
      state: 0
    }, 
    {
      pos: [9, 0, 7], 
      state: 0
    }, 
    {
      pos: [2, 1, 2], 
      state: 0
    }, 
    {
      pos: [2, 1, 7], 
      state: 0
    }, 
    {
      pos: [3, 1, 1], 
      state: 0
    }, 
    {
      pos: [3, 1, 2], 
      state: 0
    }, 
    {
      pos: [3, 1, 3], 
      state: 0
    }, 
    {
      pos: [3, 1, 6], 
      state: 0
    }, 
    {
      pos: [3, 1, 7], 
      state: 0
    }, 
    {
      pos: [3, 1, 8], 
      state: 0
    }, 
    {
      pos: [4, 1, 2], 
      state: 0
    }, 
    {
      pos: [4, 1, 7], 
      state: 0
    }, 
    {
      pos: [7, 1, 6], 
      state: 0
    }, 
    {
      pos: [7, 1, 7], 
      state: 0
    }, 
    {
      pos: [7, 1, 8], 
      state: 0
    }, 
    {
      pos: [8, 1, 6], 
      state: 0
    }, 
    {
      pos: [8, 1, 7], 
      state: 0
    }, 
    {
      pos: [8, 1, 8], 
      state: 0
    }, 
    {
      pos: [9, 1, 6], 
      state: 0
    }, 
    {
      pos: [9, 1, 7], 
      state: 0
    }, 
    {
      pos: [9, 1, 8], 
      state: 0
    }, 
    {
      pos: [2, 2, 1], 
      state: 0
    }, 
    {
      pos: [2, 2, 2], 
      state: 0
    }, 
    {
      pos: [2, 2, 3], 
      state: 0
    }, 
    {
      pos: [3, 2, 1], 
      state: 0
    }, 
    {
      pos: [3, 2, 2], 
      state: 0
    }, 
    {
      pos: [3, 2, 3], 
      state: 0
    }, 
    {
      pos: [4, 2, 1], 
      state: 0
    }, 
    {
      pos: [4, 2, 2], 
      state: 0
    }, 
    {
      pos: [4, 2, 3], 
      state: 0
    }, 
    {
      pos: [7, 2, 7], 
      state: 0
    }, 
    {
      pos: [8, 2, 6], 
      state: 0
    }, 
    {
      pos: [8, 2, 7], 
      state: 0
    }, 
    {
      pos: [8, 2, 8], 
      state: 0
    }, 
    {
      pos: [9, 2, 7], 
      state: 0
    }, 
    {
      pos: [2, 3, 2], 
      state: 0
    }, 
    {
      pos: [3, 3, 1], 
      state: 0
    }, 
    {
      pos: [3, 3, 2], 
      state: 0
    }, 
    {
      pos: [3, 3, 3], 
      state: 0
    }, 
    {
      pos: [4, 3, 2], 
      state: 0
    }, 
    {
      pos: [4, 0, 4], 
      state: 3
    }, 
    {
      pos: [4, 0, 5], 
      state: 3
    }, 
    {
      pos: [5, 0, 4], 
      state: 3
    }, 
    {
      pos: [5, 0, 5], 
      state: 3
    }, 
    {
      pos: [5, 0, 6], 
      state: 3
    }, 
    {
      pos: [5, 0, 7], 
      state: 3
    }, 
    {
      pos: [6, 0, 3], 
      state: 3
    }, 
    {
      pos: [6, 0, 5], 
      state: 3
    }, 
    {
      pos: [6, 0, 6], 
      state: 3
    }, 
    {
      pos: [7, 0, 3], 
      state: 3
    }, 
    {
      pos: [7, 0, 4], 
      state: 3
    }, 
    {
      pos: [7, 0, 5], 
      state: 3
    }, 
    {
      pos: [8, 0, 4], 
      state: 3
    }, 
    {
      pos: [8, 0, 5], 
      state: 3
    }, 
    {
      pos: [9, 0, 5], 
      state: 3
    }, 
    {
      nbt: {
        LootTable: "minecraft:chests/abandoned_camp_secret_chest", 
        components: {}, 
        Items: [], 
        id: "minecraft:chest"
      }, 
      pos: [3, 0, 2], 
      state: 4
    }, 
    {
      nbt: {
        components: {}, 
        joint: "rollable", 
        final_state: "minecraft:dirt", 
        name: "minecraft:bottom", 
        placement_priority: 0, 
        pool: "minecraft:abandoned_camp/trees/mega_pine", 
        selection_priority: 0, 
        id: "minecraft:jigsaw", 
        target: "minecraft:bottom"
      }, 
      pos: [7, 0, 2], 
      state: 5
    }, 
    {
      nbt: {
        components: {}, 
        joint: "rollable", 
        final_state: "minecraft:dirt_path", 
        name: "minecraft:end_connector", 
        placement_priority: 0, 
        pool: "minecraft:empty", 
        selection_priority: 0, 
        id: "minecraft:jigsaw", 
        target: "minecraft:connector"
      }, 
      pos: [9, 0, 4], 
      state: 6
    }, 
    {
      nbt: {
        LootTable: "minecraft:chests/abandoned_camp_common_chest", 
        components: {}, 
        Items: [], 
        id: "minecraft:chest"
      }, 
      pos: [5, 1, 3], 
      state: 7
    }, 
    {
      nbt: {
        components: {}, 
        Items: [], 
        CookingTimes: [I; 0, 0, 0, 0], 
        CookingTotalTimes: [I; 0, 0, 0, 0], 
        id: "minecraft:campfire"
      }, 
      pos: [6, 1, 4], 
      state: 8
    }
  ], 
  palette: [
    {
      id: "minecraft:mossy_cobblestone"
    }, 
    {
      id: "minecraft:grass_block", 
      properties: {
        snowy: "false"
      }
    }, 
    {
      id: "minecraft:podzol", 
      properties: {
        snowy: "false"
      }
    }, 
    {
      id: "minecraft:dirt_path"
    }, 
    {
      id: "minecraft:oxidized_copper_chest", 
      properties: {
        waterlogged: "false", 
        facing: "east", 
        type: "single"
      }
    }, 
    {
      id: "minecraft:jigsaw", 
      properties: {
        orientation: "up_east"
      }
    }, 
    {
      id: "minecraft:jigsaw", 
      properties: {
        orientation: "east_up"
      }
    }, 
    {
      id: "minecraft:chest", 
      properties: {
        waterlogged: "false", 
        facing: "east", 
        type: "single"
      }
    }, 
    {
      id: "minecraft:campfire", 
      properties: {
        waterlogged: "false", 
        signal_fire: "false", 
        lit: "false", 
        facing: "west"
      }
    }
  ]
}
