{
  size: [17, 30, 14], 
  entities: [], 
  blocks: [
    {
      pos: [8, 0, 0], 
      state: 0
    }, 
    {
      pos: [9, 0, 0], 
      state: 0
    }, 
    {
      pos: [10, 0, 0], 
      state: 0
    }, 
    {
      pos: [11, 0, 0], 
      state: 0
    }, 
    {
      pos: [12, 0, 0], 
      state: 0
    }, 
    {
      pos: [13, 0, 0], 
      state: 0
    }, 
    {
      pos: [14, 0, 0], 
      state: 0
    }, 
    {
      pos: [15, 0, 0], 
      state: 0
    }, 
    {
      pos: [16, 0, 0], 
      state: 0
    }, 
    {
      pos: [7, 0, 1], 
      state: 0
    }, 
    {
      pos: [8, 0, 1], 
      state: 0
    }, 
    {
      pos: [9, 0, 1], 
      state: 0
    }, 
    {
      pos: [10, 0, 1], 
      state: 0
    }, 
    {
      pos: [11, 0, 1], 
      state: 0
    }, 
    {
      pos: [12, 0, 1], 
      state: 0
    }, 
    {
      pos: [13, 0, 1], 
      state: 0
    }, 
    {
      pos: [14, 0, 1], 
      state: 0
    }, 
    {
      pos: [15, 0, 1], 
      state: 0
    }, 
    {
      pos: [16, 0, 1], 
      state: 0
    }, 
    {
      pos: [9, 0, 2], 
      state: 0
    }, 
    {
      pos: [10, 0, 2], 
      state: 0
    }, 
    {
      pos: [11, 0, 2], 
      state: 0
    }, 
    {
      pos: [12, 0, 2], 
      state: 0
    }, 
    {
      pos: [13, 0, 2], 
      state: 0
    }, 
    {
      pos: [14, 0, 2], 
      state: 0
    }, 
    {
      pos: [15, 0, 2], 
      state: 0
    }, 
    {
      pos: [16, 0, 2], 
      state: 0
    }, 
    {
      pos: [9, 0, 3], 
      state: 0
    }, 
    {
      pos: [10, 0, 3], 
      state: 0
    }, 
    {
      pos: [11, 0, 3], 
      state: 0
    }, 
    {
      pos: [12, 0, 3], 
      state: 0
    }, 
    {
      pos: [13, 0, 3], 
      state: 0
    }, 
    {
      pos: [14, 0, 3], 
      state: 0
    }, 
    {
      pos: [15, 0, 3], 
      state: 0
    }, 
    {
      pos: [16, 0, 3], 
      state: 0
    }, 
    {
      pos: [7, 0, 4], 
      state: 0
    }, 
    {
      pos: [8, 0, 4], 
      state: 0
    }, 
    {
      pos: [9, 0, 4], 
      state: 0
    }, 
    {
      pos: [10, 0, 4], 
      state: 0
    }, 
    {
      pos: [11, 0, 4], 
      state: 0
    }, 
    {
      pos: [12, 0, 4], 
      state: 0
    }, 
    {
      pos: [13, 0, 4], 
      state: 0
    }, 
    {
      pos: [14, 0, 4], 
      state: 0
    }, 
    {
      pos: [15, 0, 4], 
      state: 0
    }, 
    {
      pos: [16, 0, 4], 
      state: 0
    }, 
    {
      pos: [7, 0, 5], 
      state: 0
    }, 
    {
      pos: [8, 0, 5], 
      state: 0
    }, 
    {
      pos: [9, 0, 5], 
      state: 0
    }, 
    {
      pos: [10, 0, 5], 
      state: 0
    }, 
    {
      pos: [11, 0, 5], 
      state: 0
    }, 
    {
      pos: [12, 0, 5], 
      state: 0
    }, 
    {
      pos: [14, 0, 5], 
      state: 1
    }, 
    {
      pos: [15, 0, 5], 
      state: 0
    }, 
    {
      pos: [16, 0, 5], 
      state: 0
    }, 
    {
      pos: [9, 0, 6], 
      state: 0
    }, 
    {
      pos: [12, 0, 6], 
      state: 0
    }, 
    {
      pos: [13, 0, 6], 
      state: 1
    }, 
    {
      pos: [14, 0, 6], 
      state: 1
    }, 
    {
      pos: [15, 0, 6], 
      state: 0
    }, 
    {
      pos: [16, 0, 6], 
      state: 0
    }, 
    {
      pos: [9, 0, 7], 
      state: 0
    }, 
    {
      pos: [12, 0, 7], 
      state: 0
    }, 
    {
      pos: [13, 0, 7], 
      state: 1
    }, 
    {
      pos: [14, 0, 7], 
      state: 1
    }, 
    {
      pos: [15, 0, 7], 
      state: 0
    }, 
    {
      pos: [16, 0, 7], 
      state: 0
    }, 
    {
      pos: [7, 0, 8], 
      state: 0
    }, 
    {
      pos: [8, 0, 8], 
      state: 0
    }, 
    {
      pos: [9, 0, 8], 
      state: 0
    }, 
    {
      pos: [12, 0, 8], 
      state: 0
    }, 
    {
      pos: [13, 0, 8], 
      state: 0
    }, 
    {
      pos: [14, 0, 8], 
      state: 0
    }, 
    {
      pos: [15, 0, 8], 
      state: 0
    }, 
    {
      pos: [16, 0, 8], 
      state: 0
    }, 
    {
      pos: [7, 0, 9], 
      state: 2
    }, 
    {
      pos: [8, 0, 9], 
      state: 0
    }, 
    {
      pos: [9, 0, 9], 
      state: 0
    }, 
    {
      pos: [12, 0, 9], 
      state: 0
    }, 
    {
      pos: [13, 0, 9], 
      state: 0
    }, 
    {
      pos: [14, 0, 9], 
      state: 0
    }, 
    {
      pos: [15, 0, 9], 
      state: 0
    }, 
    {
      pos: [16, 0, 9], 
      state: 0
    }, 
    {
      pos: [9, 0, 10], 
      state: 0
    }, 
    {
      pos: [12, 0, 10], 
      state: 0
    }, 
    {
      pos: [13, 0, 10], 
      state: 0
    }, 
    {
      pos: [14, 0, 10], 
      state: 0
    }, 
    {
      pos: [15, 0, 10], 
      state: 0
    }, 
    {
      pos: [16, 0, 10], 
      state: 0
    }, 
    {
      pos: [9, 0, 11], 
      state: 0
    }, 
    {
      pos: [10, 0, 11], 
      state: 0
    }, 
    {
      pos: [11, 0, 11], 
      state: 0
    }, 
    {
      pos: [12, 0, 11], 
      state: 0
    }, 
    {
      pos: [13, 0, 11], 
      state: 0
    }, 
    {
      pos: [14, 0, 11], 
      state: 0
    }, 
    {
      pos: [15, 0, 11], 
      state: 0
    }, 
    {
      pos: [16, 0, 11], 
      state: 0
    }, 
    {
      pos: [7, 0, 12], 
      state: 2
    }, 
    {
      pos: [8, 0, 12], 
      state: 0
    }, 
    {
      pos: [9, 0, 12], 
      state: 0
    }, 
    {
      pos: [10, 0, 12], 
      state: 0
    }, 
    {
      pos: [11, 0, 12], 
      state: 0
    }, 
    {
      pos: [12, 0, 12], 
      state: 0
    }, 
    {
      pos: [13, 0, 12], 
      state: 0
    }, 
    {
      pos: [14, 0, 12], 
      state: 0
    }, 
    {
      pos: [15, 0, 12], 
      state: 0
    }, 
    {
      pos: [16, 0, 12], 
      state: 0
    }, 
    {
      pos: [7, 0, 13], 
      state: 2
    }, 
    {
      pos: [8, 0, 13], 
      state: 0
    }, 
    {
      pos: [9, 0, 13], 
      state: 0
    }, 
    {
      pos: [10, 0, 13], 
      state: 0
    }, 
    {
      pos: [11, 0, 13], 
      state: 0
    }, 
    {
      pos: [12, 0, 13], 
      state: 0
    }, 
    {
      pos: [13, 0, 13], 
      state: 0
    }, 
    {
      pos: [15, 0, 13], 
      state: 0
    }, 
    {
      pos: [16, 0, 13], 
      state: 0
    }, 
    {
      nbt: {
        joint: "aligned", 
        final_state: "minecraft:polished_blackstone_bricks", 
        name: "minecraft:empty", 
        pool: "minecraft:bastion/treasure/ramparts", 
        id: "minecraft:jigsaw", 
        target: "minecraft:ramparts_bottom_connector"
      }, 
      pos: [7, 0, 0], 
      state: 3
    }, 
    {
      nbt: {
        joint: "rollable", 
        final_state: "minecraft:polished_blackstone_bricks", 
        name: "minecraft:empty", 
        pool: "minecraft:bastion/mobs/piglin", 
        id: "minecraft:jigsaw", 
        target: "minecraft:mob_connector"
      }, 
      pos: [13, 0, 5], 
      state: 4
    }, 
    {
      nbt: {
        joint: "rollable", 
        final_state: "minecraft:polished_blackstone_bricks", 
        name: "minecraft:empty", 
        pool: "minecraft:bastion/treasure/ramparts", 
        id: "minecraft:jigsaw", 
        target: "minecraft:rampart_mid_side_wall_connector"
      }, 
      pos: [14, 0, 13], 
      state: 5
    }, 
    {
      pos: [5, 0, 2], 
      state: 6
    }, 
    {
      pos: [6, 0, 2], 
      state: 6
    }, 
    {
      pos: [7, 0, 2], 
      state: 6
    }, 
    {
      pos: [8, 0, 2], 
      state: 6
    }, 
    {
      pos: [4, 0, 3], 
      state: 6
    }, 
    {
      pos: [5, 0, 3], 
      state: 6
    }, 
    {
      pos: [6, 0, 3], 
      state: 6
    }, 
    {
      pos: [7, 0, 3], 
      state: 6
    }, 
    {
      pos: [8, 0, 3], 
      state: 6
    }, 
    {
      pos: [3, 0, 4], 
      state: 6
    }, 
    {
      pos: [4, 0, 4], 
      state: 6
    }, 
    {
      pos: [5, 0, 4], 
      state: 6
    }, 
    {
      pos: [6, 0, 4], 
      state: 6
    }, 
    {
      pos: [3, 0, 5], 
      state: 6
    }, 
    {
      pos: [4, 0, 5], 
      state: 6
    }, 
    {
      pos: [5, 0, 5], 
      state: 6
    }, 
    {
      pos: [6, 0, 5], 
      state: 6
    }, 
    {
      pos: [2, 0, 6], 
      state: 6
    }, 
    {
      pos: [3, 0, 6], 
      state: 6
    }, 
    {
      pos: [4, 0, 6], 
      state: 6
    }, 
    {
      pos: [5, 0, 6], 
      state: 6
    }, 
    {
      pos: [6, 0, 6], 
      state: 6
    }, 
    {
      pos: [7, 0, 6], 
      state: 6
    }, 
    {
      pos: [8, 0, 6], 
      state: 6
    }, 
    {
      pos: [10, 0, 6], 
      state: 6
    }, 
    {
      pos: [11, 0, 6], 
      state: 6
    }, 
    {
      pos: [2, 0, 7], 
      state: 6
    }, 
    {
      pos: [3, 0, 7], 
      state: 6
    }, 
    {
      pos: [4, 0, 7], 
      state: 6
    }, 
    {
      pos: [5, 0, 7], 
      state: 6
    }, 
    {
      pos: [6, 0, 7], 
      state: 6
    }, 
    {
      pos: [7, 0, 7], 
      state: 6
    }, 
    {
      pos: [8, 0, 7], 
      state: 6
    }, 
    {
      pos: [10, 0, 7], 
      state: 6
    }, 
    {
      pos: [11, 0, 7], 
      state: 6
    }, 
    {
      pos: [2, 0, 8], 
      state: 6
    }, 
    {
      pos: [3, 0, 8], 
      state: 6
    }, 
    {
      pos: [4, 0, 8], 
      state: 6
    }, 
    {
      pos: [5, 0, 8], 
      state: 6
    }, 
    {
      pos: [6, 0, 8], 
      state: 6
    }, 
    {
      pos: [10, 0, 8], 
      state: 6
    }, 
    {
      pos: [11, 0, 8], 
      state: 6
    }, 
    {
      pos: [3, 0, 9], 
      state: 6
    }, 
    {
      pos: [4, 0, 9], 
      state: 6
    }, 
    {
      pos: [5, 0, 9], 
      state: 6
    }, 
    {
      pos: [6, 0, 9], 
      state: 6
    }, 
    {
      pos: [10, 0, 9], 
      state: 6
    }, 
    {
      pos: [11, 0, 9], 
      state: 6
    }, 
    {
      pos: [3, 0, 10], 
      state: 6
    }, 
    {
      pos: [4, 0, 10], 
      state: 6
    }, 
    {
      pos: [5, 0, 10], 
      state: 6
    }, 
    {
      pos: [6, 0, 10], 
      state: 6
    }, 
    {
      pos: [7, 0, 10], 
      state: 6
    }, 
    {
      pos: [8, 0, 10], 
      state: 6
    }, 
    {
      pos: [10, 0, 10], 
      state: 6
    }, 
    {
      pos: [11, 0, 10], 
      state: 6
    }, 
    {
      pos: [3, 0, 11], 
      state: 6
    }, 
    {
      pos: [4, 0, 11], 
      state: 6
    }, 
    {
      pos: [5, 0, 11], 
      state: 6
    }, 
    {
      pos: [6, 0, 11], 
      state: 6
    }, 
    {
      pos: [7, 0, 11], 
      state: 6
    }, 
    {
      pos: [8, 0, 11], 
      state: 6
    }, 
    {
      pos: [3, 0, 12], 
      state: 6
    }, 
    {
      pos: [4, 0, 12], 
      state: 6
    }, 
    {
      pos: [5, 0, 12], 
      state: 6
    }, 
    {
      pos: [6, 0, 12], 
      state: 6
    }, 
    {
      pos: [3, 0, 13], 
      state: 6
    }, 
    {
      pos: [4, 0, 13], 
      state: 6
    }, 
    {
      pos: [5, 0, 13], 
      state: 6
    }, 
    {
      pos: [6, 0, 13], 
      state: 6
    }, 
    {
      pos: [7, 1, 0], 
      state: 0
    }, 
    {
      pos: [8, 1, 0], 
      state: 0
    }, 
    {
      pos: [9, 1, 0], 
      state: 0
    }, 
    {
      pos: [10, 1, 0], 
      state: 0
    }, 
    {
      pos: [11, 1, 0], 
      state: 0
    }, 
    {
      pos: [12, 1, 0], 
      state: 0
    }, 
    {
      pos: [13, 1, 0], 
      state: 0
    }, 
    {
      pos: [14, 1, 0], 
      state: 0
    }, 
    {
      pos: [15, 1, 0], 
      state: 0
    }, 
    {
      pos: [16, 1, 0], 
      state: 0
    }, 
    {
      pos: [7, 1, 1], 
      state: 0
    }, 
    {
      pos: [8, 1, 1], 
      state: 0
    }, 
    {
      pos: [12, 1, 1], 
      state: 0
    }, 
    {
      pos: [13, 1, 1], 
      state: 0
    }, 
    {
      pos: [14, 1, 1], 
      state: 0
    }, 
    {
      pos: [15, 1, 1], 
      state: 0
    }, 
    {
      pos: [16, 1, 1], 
      state: 0
    }, 
    {
      pos: [9, 1, 2], 
      state: 0
    }, 
    {
      pos: [12, 1, 2], 
      state: 0
    }, 
    {
      pos: [13, 1, 2], 
      state: 0
    }, 
    {
      pos: [14, 1, 2], 
      state: 0
    }, 
    {
      pos: [15, 1, 2], 
      state: 0
    }, 
    {
      pos: [16, 1, 2], 
      state: 0
    }, 
    {
      pos: [9, 1, 3], 
      state: 0
    }, 
    {
      pos: [13, 1, 3], 
      state: 0
    }, 
    {
      pos: [14, 1, 3], 
      state: 0
    }, 
    {
      pos: [15, 1, 3], 
      state: 0
    }, 
    {
      pos: [16, 1, 3], 
      state: 0
    }, 
    {
      pos: [7, 1, 4], 
      state: 0
    }, 
    {
      pos: [8, 1, 4], 
      state: 0
    }, 
    {
      pos: [14, 1, 4], 
      state: 0
    }, 
    {
      pos: [15, 1, 4], 
      state: 0
    }, 
    {
      pos: [16, 1, 4], 
      state: 0
    }, 
    {
      pos: [7, 1, 5], 
      state: 0
    }, 
    {
      pos: [8, 1, 5], 
      state: 0
    }, 
    {
      pos: [9, 1, 5], 
      state: 0
    }, 
    {
      pos: [10, 1, 5], 
      state: 0
    }, 
    {
      pos: [15, 1, 5], 
      state: 0
    }, 
    {
      pos: [16, 1, 5], 
      state: 0
    }, 
    {
      pos: [9, 1, 6], 
      state: 0
    }, 
    {
      pos: [11, 1, 6], 
      state: 0
    }, 
    {
      pos: [15, 1, 6], 
      state: 0
    }, 
    {
      pos: [16, 1, 6], 
      state: 0
    }, 
    {
      pos: [9, 1, 7], 
      state: 0
    }, 
    {
      pos: [12, 1, 7], 
      state: 0
    }, 
    {
      pos: [15, 1, 7], 
      state: 0
    }, 
    {
      pos: [16, 1, 7], 
      state: 0
    }, 
    {
      pos: [7, 1, 8], 
      state: 0
    }, 
    {
      pos: [8, 1, 8], 
      state: 0
    }, 
    {
      pos: [9, 1, 8], 
      state: 0
    }, 
    {
      pos: [12, 1, 8], 
      state: 0
    }, 
    {
      pos: [15, 1, 8], 
      state: 0
    }, 
    {
      pos: [16, 1, 8], 
      state: 0
    }, 
    {
      pos: [7, 1, 9], 
      state: 2
    }, 
    {
      pos: [8, 1, 9], 
      state: 0
    }, 
    {
      pos: [9, 1, 9], 
      state: 0
    }, 
    {
      pos: [12, 1, 9], 
      state: 0
    }, 
    {
      pos: [15, 1, 9], 
      state: 0
    }, 
    {
      pos: [16, 1, 9], 
      state: 0
    }, 
    {
      pos: [9, 1, 10], 
      state: 0
    }, 
    {
      pos: [12, 1, 10], 
      state: 0
    }, 
    {
      pos: [15, 1, 10], 
      state: 0
    }, 
    {
      pos: [16, 1, 10], 
      state: 0
    }, 
    {
      pos: [9, 1, 11], 
      state: 0
    }, 
    {
      pos: [12, 1, 11], 
      state: 0
    }, 
    {
      pos: [13, 1, 11], 
      state: 0
    }, 
    {
      pos: [14, 1, 11], 
      state: 0
    }, 
    {
      pos: [15, 1, 11], 
      state: 0
    }, 
    {
      pos: [16, 1, 11], 
      state: 0
    }, 
    {
      pos: [7, 1, 12], 
      state: 2
    }, 
    {
      pos: [8, 1, 12], 
      state: 0
    }, 
    {
      pos: [9, 1, 12], 
      state: 0
    }, 
    {
      pos: [10, 1, 12], 
      state: 0
    }, 
    {
      pos: [11, 1, 12], 
      state: 0
    }, 
    {
      pos: [12, 1, 12], 
      state: 0
    }, 
    {
      pos: [13, 1, 12], 
      state: 0
    }, 
    {
      pos: [14, 1, 12], 
      state: 0
    }, 
    {
      pos: [15, 1, 12], 
      state: 0
    }, 
    {
      pos: [16, 1, 12], 
      state: 0
    }, 
    {
      pos: [7, 1, 13], 
      state: 2
    }, 
    {
      pos: [8, 1, 13], 
      state: 0
    }, 
    {
      pos: [9, 1, 13], 
      state: 0
    }, 
    {
      pos: [10, 1, 13], 
      state: 0
    }, 
    {
      pos: [11, 1, 13], 
      state: 0
    }, 
    {
      pos: [12, 1, 13], 
      state: 0
    }, 
    {
      pos: [13, 1, 13], 
      state: 0
    }, 
    {
      pos: [14, 1, 13], 
      state: 0
    }, 
    {
      pos: [15, 1, 13], 
      state: 0
    }, 
    {
      pos: [16, 1, 13], 
      state: 0
    }, 
    {
      pos: [9, 1, 1], 
      state: 6
    }, 
    {
      pos: [10, 1, 1], 
      state: 6
    }, 
    {
      pos: [11, 1, 1], 
      state: 6
    }, 
    {
      pos: [4, 1, 2], 
      state: 6
    }, 
    {
      pos: [5, 1, 2], 
      state: 6
    }, 
    {
      pos: [6, 1, 2], 
      state: 6
    }, 
    {
      pos: [7, 1, 2], 
      state: 6
    }, 
    {
      pos: [8, 1, 2], 
      state: 6
    }, 
    {
      pos: [10, 1, 2], 
      state: 6
    }, 
    {
      pos: [11, 1, 2], 
      state: 6
    }, 
    {
      pos: [3, 1, 3], 
      state: 6
    }, 
    {
      pos: [4, 1, 3], 
      state: 6
    }, 
    {
      pos: [5, 1, 3], 
      state: 6
    }, 
    {
      pos: [6, 1, 3], 
      state: 6
    }, 
    {
      pos: [7, 1, 3], 
      state: 6
    }, 
    {
      pos: [8, 1, 3], 
      state: 6
    }, 
    {
      pos: [10, 1, 3], 
      state: 6
    }, 
    {
      pos: [11, 1, 3], 
      state: 6
    }, 
    {
      pos: [12, 1, 3], 
      state: 6
    }, 
    {
      pos: [2, 1, 4], 
      state: 6
    }, 
    {
      pos: [3, 1, 4], 
      state: 6
    }, 
    {
      pos: [4, 1, 4], 
      state: 6
    }, 
    {
      pos: [5, 1, 4], 
      state: 6
    }, 
    {
      pos: [6, 1, 4], 
      state: 6
    }, 
    {
      pos: [9, 1, 4], 
      state: 6
    }, 
    {
      pos: [10, 1, 4], 
      state: 6
    }, 
    {
      pos: [11, 1, 4], 
      state: 6
    }, 
    {
      pos: [12, 1, 4], 
      state: 6
    }, 
    {
      pos: [13, 1, 4], 
      state: 6
    }, 
    {
      pos: [2, 1, 5], 
      state: 6
    }, 
    {
      pos: [3, 1, 5], 
      state: 6
    }, 
    {
      pos: [4, 1, 5], 
      state: 6
    }, 
    {
      pos: [5, 1, 5], 
      state: 6
    }, 
    {
      pos: [6, 1, 5], 
      state: 6
    }, 
    {
      pos: [11, 1, 5], 
      state: 6
    }, 
    {
      pos: [12, 1, 5], 
      state: 6
    }, 
    {
      pos: [13, 1, 5], 
      state: 6
    }, 
    {
      pos: [14, 1, 5], 
      state: 6
    }, 
    {
      pos: [2, 1, 6], 
      state: 6
    }, 
    {
      pos: [3, 1, 6], 
      state: 6
    }, 
    {
      pos: [4, 1, 6], 
      state: 6
    }, 
    {
      pos: [5, 1, 6], 
      state: 6
    }, 
    {
      pos: [6, 1, 6], 
      state: 6
    }, 
    {
      pos: [7, 1, 6], 
      state: 6
    }, 
    {
      pos: [8, 1, 6], 
      state: 6
    }, 
    {
      pos: [10, 1, 6], 
      state: 6
    }, 
    {
      pos: [12, 1, 6], 
      state: 6
    }, 
    {
      pos: [13, 1, 6], 
      state: 6
    }, 
    {
      pos: [14, 1, 6], 
      state: 6
    }, 
    {
      pos: [2, 1, 7], 
      state: 6
    }, 
    {
      pos: [3, 1, 7], 
      state: 6
    }, 
    {
      pos: [4, 1, 7], 
      state: 6
    }, 
    {
      pos: [5, 1, 7], 
      state: 6
    }, 
    {
      pos: [6, 1, 7], 
      state: 6
    }, 
    {
      pos: [7, 1, 7], 
      state: 6
    }, 
    {
      pos: [8, 1, 7], 
      state: 6
    }, 
    {
      pos: [10, 1, 7], 
      state: 6
    }, 
    {
      pos: [11, 1, 7], 
      state: 6
    }, 
    {
      pos: [13, 1, 7], 
      state: 6
    }, 
    {
      pos: [14, 1, 7], 
      state: 6
    }, 
    {
      pos: [3, 1, 8], 
      state: 6
    }, 
    {
      pos: [4, 1, 8], 
      state: 6
    }, 
    {
      pos: [5, 1, 8], 
      state: 6
    }, 
    {
      pos: [6, 1, 8], 
      state: 6
    }, 
    {
      pos: [10, 1, 8], 
      state: 6
    }, 
    {
      pos: [11, 1, 8], 
      state: 6
    }, 
    {
      pos: [13, 1, 8], 
      state: 6
    }, 
    {
      pos: [14, 1, 8], 
      state: 6
    }, 
    {
      pos: [3, 1, 9], 
      state: 6
    }, 
    {
      pos: [4, 1, 9], 
      state: 6
    }, 
    {
      pos: [5, 1, 9], 
      state: 6
    }, 
    {
      pos: [6, 1, 9], 
      state: 6
    }, 
    {
      pos: [10, 1, 9], 
      state: 6
    }, 
    {
      pos: [11, 1, 9], 
      state: 6
    }, 
    {
      pos: [13, 1, 9], 
      state: 6
    }, 
    {
      pos: [14, 1, 9], 
      state: 6
    }, 
    {
      pos: [3, 1, 10], 
      state: 6
    }, 
    {
      pos: [4, 1, 10], 
      state: 6
    }, 
    {
      pos: [5, 1, 10], 
      state: 6
    }, 
    {
      pos: [6, 1, 10], 
      state: 6
    }, 
    {
      pos: [7, 1, 10], 
      state: 6
    }, 
    {
      pos: [8, 1, 10], 
      state: 6
    }, 
    {
      pos: [10, 1, 10], 
      state: 6
    }, 
    {
      pos: [11, 1, 10], 
      state: 6
    }, 
    {
      pos: [13, 1, 10], 
      state: 6
    }, 
    {
      pos: [14, 1, 10], 
      state: 6
    }, 
    {
      pos: [3, 1, 11], 
      state: 6
    }, 
    {
      pos: [4, 1, 11], 
      state: 6
    }, 
    {
      pos: [5, 1, 11], 
      state: 6
    }, 
    {
      pos: [6, 1, 11], 
      state: 6
    }, 
    {
      pos: [7, 1, 11], 
      state: 6
    }, 
    {
      pos: [8, 1, 11], 
      state: 6
    }, 
    {
      pos: [10, 1, 11], 
      state: 6
    }, 
    {
      pos: [11, 1, 11], 
      state: 6
    }, 
    {
      pos: [1, 1, 12], 
      state: 6
    }, 
    {
      pos: [3, 1, 12], 
      state: 6
    }, 
    {
      pos: [4, 1, 12], 
      state: 6
    }, 
    {
      pos: [5, 1, 12], 
      state: 6
    }, 
    {
      pos: [6, 1, 12], 
      state: 6
    }, 
    {
      pos: [3, 1, 13], 
      state: 6
    }, 
    {
      pos: [4, 1, 13], 
      state: 6
    }, 
    {
      pos: [5, 1, 13], 
      state: 6
    }, 
    {
      pos: [6, 1, 13], 
      state: 6
    }, 
    {
      pos: [7, 2, 0], 
      state: 0
    }, 
    {
      pos: [8, 2, 0], 
      state: 0
    }, 
    {
      pos: [9, 2, 0], 
      state: 0
    }, 
    {
      pos: [10, 2, 0], 
      state: 0
    }, 
    {
      pos: [11, 2, 0], 
      state: 0
    }, 
    {
      pos: [12, 2, 0], 
      state: 0
    }, 
    {
      pos: [13, 2, 0], 
      state: 0
    }, 
    {
      pos: [14, 2, 0], 
      state: 0
    }, 
    {
      pos: [15, 2, 0], 
      state: 0
    }, 
    {
      pos: [16, 2, 0], 
      state: 0
    }, 
    {
      pos: [7, 2, 1], 
      state: 0
    }, 
    {
      pos: [8, 2, 1], 
      state: 0
    }, 
    {
      pos: [13, 2, 1], 
      state: 0
    }, 
    {
      pos: [14, 2, 1], 
      state: 0
    }, 
    {
      pos: [15, 2, 1], 
      state: 0
    }, 
    {
      pos: [16, 2, 1], 
      state: 0
    }, 
    {
      pos: [9, 2, 2], 
      state: 0
    }, 
    {
      pos: [13, 2, 2], 
      state: 0
    }, 
    {
      pos: [14, 2, 2], 
      state: 0
    }, 
    {
      pos: [15, 2, 2], 
      state: 0
    }, 
    {
      pos: [16, 2, 2], 
      state: 0
    }, 
    {
      pos: [9, 2, 3], 
      state: 0
    }, 
    {
      pos: [13, 2, 3], 
      state: 0
    }, 
    {
      pos: [14, 2, 3], 
      state: 0
    }, 
    {
      pos: [15, 2, 3], 
      state: 0
    }, 
    {
      pos: [16, 2, 3], 
      state: 0
    }, 
    {
      pos: [7, 2, 4], 
      state: 0
    }, 
    {
      pos: [8, 2, 4], 
      state: 0
    }, 
    {
      pos: [14, 2, 4], 
      state: 0
    }, 
    {
      pos: [15, 2, 4], 
      state: 0
    }, 
    {
      pos: [16, 2, 4], 
      state: 0
    }, 
    {
      pos: [7, 2, 5], 
      state: 0
    }, 
    {
      pos: [8, 2, 5], 
      state: 0
    }, 
    {
      pos: [9, 2, 5], 
      state: 0
    }, 
    {
      pos: [10, 2, 5], 
      state: 0
    }, 
    {
      pos: [15, 2, 5], 
      state: 0
    }, 
    {
      pos: [16, 2, 5], 
      state: 0
    }, 
    {
      pos: [9, 2, 6], 
      state: 0
    }, 
    {
      pos: [10, 2, 6], 
      state: 0
    }, 
    {
      pos: [11, 2, 6], 
      state: 0
    }, 
    {
      pos: [15, 2, 6], 
      state: 0
    }, 
    {
      pos: [16, 2, 6], 
      state: 0
    }, 
    {
      pos: [9, 2, 7], 
      state: 0
    }, 
    {
      pos: [10, 2, 7], 
      state: 0
    }, 
    {
      pos: [11, 2, 7], 
      state: 0
    }, 
    {
      pos: [12, 2, 7], 
      state: 0
    }, 
    {
      pos: [16, 2, 7], 
      state: 0
    }, 
    {
      pos: [7, 2, 8], 
      state: 0
    }, 
    {
      pos: [8, 2, 8], 
      state: 0
    }, 
    {
      pos: [9, 2, 8], 
      state: 0
    }, 
    {
      pos: [12, 2, 8], 
      state: 0
    }, 
    {
      pos: [15, 2, 8], 
      state: 0
    }, 
    {
      pos: [16, 2, 8], 
      state: 0
    }, 
    {
      pos: [7, 2, 9], 
      state: 2
    }, 
    {
      pos: [8, 2, 9], 
      state: 0
    }, 
    {
      pos: [9, 2, 9], 
      state: 0
    }, 
    {
      pos: [12, 2, 9], 
      state: 0
    }, 
    {
      pos: [15, 2, 9], 
      state: 0
    }, 
    {
      pos: [16, 2, 9], 
      state: 0
    }, 
    {
      pos: [9, 2, 10], 
      state: 0
    }, 
    {
      pos: [12, 2, 10], 
      state: 0
    }, 
    {
      pos: [15, 2, 10], 
      state: 0
    }, 
    {
      pos: [16, 2, 10], 
      state: 0
    }, 
    {
      pos: [9, 2, 11], 
      state: 0
    }, 
    {
      pos: [14, 2, 11], 
      state: 0
    }, 
    {
      pos: [15, 2, 11], 
      state: 0
    }, 
    {
      pos: [16, 2, 11], 
      state: 0
    }, 
    {
      pos: [7, 2, 12], 
      state: 2
    }, 
    {
      pos: [8, 2, 12], 
      state: 0
    }, 
    {
      pos: [9, 2, 12], 
      state: 0
    }, 
    {
      pos: [13, 2, 12], 
      state: 0
    }, 
    {
      pos: [14, 2, 12], 
      state: 0
    }, 
    {
      pos: [15, 2, 12], 
      state: 0
    }, 
    {
      pos: [16, 2, 12], 
      state: 0
    }, 
    {
      pos: [7, 2, 13], 
      state: 2
    }, 
    {
      pos: [8, 2, 13], 
      state: 0
    }, 
    {
      pos: [9, 2, 13], 
      state: 0
    }, 
    {
      pos: [10, 2, 13], 
      state: 0
    }, 
    {
      pos: [11, 2, 13], 
      state: 0
    }, 
    {
      pos: [12, 2, 13], 
      state: 0
    }, 
    {
      pos: [13, 2, 13], 
      state: 0
    }, 
    {
      pos: [14, 2, 13], 
      state: 0
    }, 
    {
      pos: [15, 2, 13], 
      state: 0
    }, 
    {
      pos: [16, 2, 13], 
      state: 0
    }, 
    {
      pos: [3, 2, 0], 
      state: 6
    }, 
    {
      pos: [5, 2, 0], 
      state: 6
    }, 
    {
      pos: [4, 2, 1], 
      state: 6
    }, 
    {
      pos: [5, 2, 1], 
      state: 6
    }, 
    {
      pos: [9, 2, 1], 
      state: 7
    }, 
    {
      pos: [10, 2, 1], 
      state: 6
    }, 
    {
      pos: [11, 2, 1], 
      state: 6
    }, 
    {
      pos: [12, 2, 1], 
      state: 6
    }, 
    {
      pos: [0, 2, 2], 
      state: 6
    }, 
    {
      pos: [1, 2, 2], 
      state: 6
    }, 
    {
      pos: [2, 2, 2], 
      state: 6
    }, 
    {
      pos: [3, 2, 2], 
      state: 6
    }, 
    {
      pos: [4, 2, 2], 
      state: 6
    }, 
    {
      pos: [5, 2, 2], 
      state: 6
    }, 
    {
      pos: [6, 2, 2], 
      state: 6
    }, 
    {
      pos: [7, 2, 2], 
      state: 6
    }, 
    {
      pos: [8, 2, 2], 
      state: 6
    }, 
    {
      pos: [10, 2, 2], 
      state: 6
    }, 
    {
      pos: [11, 2, 2], 
      state: 6
    }, 
    {
      pos: [12, 2, 2], 
      state: 6
    }, 
    {
      pos: [0, 2, 3], 
      state: 6
    }, 
    {
      pos: [1, 2, 3], 
      state: 6
    }, 
    {
      pos: [2, 2, 3], 
      state: 6
    }, 
    {
      pos: [3, 2, 3], 
      state: 6
    }, 
    {
      pos: [4, 2, 3], 
      state: 6
    }, 
    {
      pos: [5, 2, 3], 
      state: 6
    }, 
    {
      pos: [6, 2, 3], 
      state: 6
    }, 
    {
      pos: [7, 2, 3], 
      state: 6
    }, 
    {
      pos: [8, 2, 3], 
      state: 6
    }, 
    {
      pos: [10, 2, 3], 
      state: 6
    }, 
    {
      pos: [11, 2, 3], 
      state: 6
    }, 
    {
      pos: [12, 2, 3], 
      state: 6
    }, 
    {
      pos: [2, 2, 4], 
      state: 6
    }, 
    {
      pos: [3, 2, 4], 
      state: 6
    }, 
    {
      pos: [4, 2, 4], 
      state: 6
    }, 
    {
      pos: [5, 2, 4], 
      state: 6
    }, 
    {
      pos: [6, 2, 4], 
      state: 6
    }, 
    {
      pos: [9, 2, 4], 
      state: 7
    }, 
    {
      pos: [10, 2, 4], 
      state: 6
    }, 
    {
      pos: [11, 2, 4], 
      state: 6
    }, 
    {
      pos: [12, 2, 4], 
      state: 6
    }, 
    {
      pos: [13, 2, 4], 
      state: 6
    }, 
    {
      pos: [2, 2, 5], 
      state: 6
    }, 
    {
      pos: [3, 2, 5], 
      state: 6
    }, 
    {
      pos: [4, 2, 5], 
      state: 6
    }, 
    {
      pos: [5, 2, 5], 
      state: 6
    }, 
    {
      pos: [6, 2, 5], 
      state: 6
    }, 
    {
      pos: [11, 2, 5], 
      state: 6
    }, 
    {
      pos: [12, 2, 5], 
      state: 6
    }, 
    {
      pos: [13, 2, 5], 
      state: 6
    }, 
    {
      pos: [14, 2, 5], 
      state: 6
    }, 
    {
      pos: [2, 2, 6], 
      state: 6
    }, 
    {
      pos: [3, 2, 6], 
      state: 6
    }, 
    {
      pos: [4, 2, 6], 
      state: 6
    }, 
    {
      pos: [5, 2, 6], 
      state: 6
    }, 
    {
      pos: [6, 2, 6], 
      state: 6
    }, 
    {
      pos: [7, 2, 6], 
      state: 6
    }, 
    {
      pos: [8, 2, 6], 
      state: 6
    }, 
    {
      pos: [12, 2, 6], 
      state: 6
    }, 
    {
      pos: [13, 2, 6], 
      state: 6
    }, 
    {
      pos: [14, 2, 6], 
      state: 6
    }, 
    {
      pos: [3, 2, 7], 
      state: 6
    }, 
    {
      pos: [4, 2, 7], 
      state: 6
    }, 
    {
      pos: [5, 2, 7], 
      state: 6
    }, 
    {
      pos: [6, 2, 7], 
      state: 6
    }, 
    {
      pos: [7, 2, 7], 
      state: 6
    }, 
    {
      pos: [8, 2, 7], 
      state: 6
    }, 
    {
      pos: [13, 2, 7], 
      state: 6
    }, 
    {
      pos: [14, 2, 7], 
      state: 6
    }, 
    {
      pos: [15, 2, 7], 
      state: 8
    }, 
    {
      pos: [3, 2, 8], 
      state: 6
    }, 
    {
      pos: [4, 2, 8], 
      state: 6
    }, 
    {
      pos: [5, 2, 8], 
      state: 6
    }, 
    {
      pos: [6, 2, 8], 
      state: 6
    }, 
    {
      pos: [10, 2, 8], 
      state: 6
    }, 
    {
      pos: [11, 2, 8], 
      state: 6
    }, 
    {
      pos: [13, 2, 8], 
      state: 6
    }, 
    {
      pos: [14, 2, 8], 
      state: 6
    }, 
    {
      pos: [3, 2, 9], 
      state: 6
    }, 
    {
      pos: [4, 2, 9], 
      state: 6
    }, 
    {
      pos: [5, 2, 9], 
      state: 6
    }, 
    {
      pos: [6, 2, 9], 
      state: 6
    }, 
    {
      pos: [10, 2, 9], 
      state: 6
    }, 
    {
      pos: [11, 2, 9], 
      state: 6
    }, 
    {
      pos: [13, 2, 9], 
      state: 6
    }, 
    {
      pos: [14, 2, 9], 
      state: 6
    }, 
    {
      pos: [3, 2, 10], 
      state: 6
    }, 
    {
      pos: [4, 2, 10], 
      state: 6
    }, 
    {
      pos: [5, 2, 10], 
      state: 6
    }, 
    {
      pos: [6, 2, 10], 
      state: 6
    }, 
    {
      pos: [7, 2, 10], 
      state: 6
    }, 
    {
      pos: [8, 2, 10], 
      state: 6
    }, 
    {
      pos: [10, 2, 10], 
      state: 6
    }, 
    {
      pos: [11, 2, 10], 
      state: 6
    }, 
    {
      pos: [13, 2, 10], 
      state: 6
    }, 
    {
      pos: [14, 2, 10], 
      state: 6
    }, 
    {
      pos: [3, 2, 11], 
      state: 6
    }, 
    {
      pos: [4, 2, 11], 
      state: 6
    }, 
    {
      pos: [5, 2, 11], 
      state: 6
    }, 
    {
      pos: [6, 2, 11], 
      state: 6
    }, 
    {
      pos: [7, 2, 11], 
      state: 6
    }, 
    {
      pos: [8, 2, 11], 
      state: 6
    }, 
    {
      pos: [10, 2, 11], 
      state: 6
    }, 
    {
      pos: [11, 2, 11], 
      state: 6
    }, 
    {
      pos: [12, 2, 11], 
      state: 6
    }, 
    {
      pos: [13, 2, 11], 
      state: 6
    }, 
    {
      pos: [3, 2, 12], 
      state: 6
    }, 
    {
      pos: [4, 2, 12], 
      state: 6
    }, 
    {
      pos: [5, 2, 12], 
      state: 6
    }, 
    {
      pos: [6, 2, 12], 
      state: 6
    }, 
    {
      pos: [10, 2, 12], 
      state: 6
    }, 
    {
      pos: [11, 2, 12], 
      state: 6
    }, 
    {
      pos: [12, 2, 12], 
      state: 6
    }, 
    {
      pos: [4, 2, 13], 
      state: 6
    }, 
    {
      pos: [5, 2, 13], 
      state: 6
    }, 
    {
      pos: [6, 2, 13], 
      state: 6
    }, 
    {
      pos: [7, 3, 0], 
      state: 0
    }, 
    {
      pos: [8, 3, 0], 
      state: 9
    }, 
    {
      pos: [9, 3, 0], 
      state: 9
    }, 
    {
      pos: [10, 3, 0], 
      state: 9
    }, 
    {
      pos: [11, 3, 0], 
      state: 0
    }, 
    {
      pos: [12, 3, 0], 
      state: 0
    }, 
    {
      pos: [13, 3, 0], 
      state: 0
    }, 
    {
      pos: [14, 3, 0], 
      state: 0
    }, 
    {
      pos: [15, 3, 0], 
      state: 0
    }, 
    {
      pos: [16, 3, 0], 
      state: 0
    }, 
    {
      pos: [7, 3, 1], 
      state: 0
    }, 
    {
      pos: [8, 3, 1], 
      state: 0
    }, 
    {
      pos: [9, 3, 1], 
      state: 0
    }, 
    {
      pos: [14, 3, 1], 
      state: 0
    }, 
    {
      pos: [15, 3, 1], 
      state: 0
    }, 
    {
      pos: [16, 3, 1], 
      state: 0
    }, 
    {
      pos: [9, 3, 2], 
      state: 0
    }, 
    {
      pos: [14, 3, 2], 
      state: 0
    }, 
    {
      pos: [15, 3, 2], 
      state: 0
    }, 
    {
      pos: [16, 3, 2], 
      state: 0
    }, 
    {
      pos: [9, 3, 3], 
      state: 0
    }, 
    {
      pos: [13, 3, 3], 
      state: 0
    }, 
    {
      pos: [14, 3, 3], 
      state: 0
    }, 
    {
      pos: [15, 3, 3], 
      state: 0
    }, 
    {
      pos: [16, 3, 3], 
      state: 0
    }, 
    {
      pos: [7, 3, 4], 
      state: 0
    }, 
    {
      pos: [8, 3, 4], 
      state: 0
    }, 
    {
      pos: [9, 3, 4], 
      state: 0
    }, 
    {
      pos: [10, 3, 4], 
      state: 0
    }, 
    {
      pos: [14, 3, 4], 
      state: 0
    }, 
    {
      pos: [15, 3, 4], 
      state: 0
    }, 
    {
      pos: [16, 3, 4], 
      state: 0
    }, 
    {
      pos: [7, 3, 5], 
      state: 0
    }, 
    {
      pos: [8, 3, 5], 
      state: 0
    }, 
    {
      pos: [9, 3, 5], 
      state: 0
    }, 
    {
      pos: [10, 3, 5], 
      state: 0
    }, 
    {
      pos: [11, 3, 5], 
      state: 0
    }, 
    {
      pos: [15, 3, 5], 
      state: 0
    }, 
    {
      pos: [16, 3, 5], 
      state: 0
    }, 
    {
      pos: [9, 3, 6], 
      state: 0
    }, 
    {
      pos: [10, 3, 6], 
      state: 0
    }, 
    {
      pos: [11, 3, 6], 
      state: 0
    }, 
    {
      pos: [12, 3, 6], 
      state: 0
    }, 
    {
      pos: [15, 3, 6], 
      state: 0
    }, 
    {
      pos: [16, 3, 6], 
      state: 0
    }, 
    {
      pos: [9, 3, 7], 
      state: 0
    }, 
    {
      pos: [10, 3, 7], 
      state: 0
    }, 
    {
      pos: [11, 3, 7], 
      state: 0
    }, 
    {
      pos: [12, 3, 7], 
      state: 0
    }, 
    {
      pos: [15, 3, 7], 
      state: 0
    }, 
    {
      pos: [16, 3, 7], 
      state: 0
    }, 
    {
      pos: [7, 3, 8], 
      state: 0
    }, 
    {
      pos: [8, 3, 8], 
      state: 0
    }, 
    {
      pos: [9, 3, 8], 
      state: 0
    }, 
    {
      pos: [10, 3, 8], 
      state: 0
    }, 
    {
      pos: [11, 3, 8], 
      state: 0
    }, 
    {
      pos: [12, 3, 8], 
      state: 0
    }, 
    {
      pos: [15, 3, 8], 
      state: 0
    }, 
    {
      pos: [16, 3, 8], 
      state: 0
    }, 
    {
      pos: [7, 3, 9], 
      state: 2
    }, 
    {
      pos: [8, 3, 9], 
      state: 0
    }, 
    {
      pos: [9, 3, 9], 
      state: 0
    }, 
    {
      pos: [12, 3, 9], 
      state: 0
    }, 
    {
      pos: [15, 3, 9], 
      state: 0
    }, 
    {
      pos: [16, 3, 9], 
      state: 0
    }, 
    {
      pos: [9, 3, 10], 
      state: 0
    }, 
    {
      pos: [15, 3, 10], 
      state: 0
    }, 
    {
      pos: [16, 3, 10], 
      state: 0
    }, 
    {
      pos: [9, 3, 11], 
      state: 0
    }, 
    {
      pos: [14, 3, 11], 
      state: 0
    }, 
    {
      pos: [15, 3, 11], 
      state: 0
    }, 
    {
      pos: [16, 3, 11], 
      state: 0
    }, 
    {
      pos: [7, 3, 12], 
      state: 2
    }, 
    {
      pos: [8, 3, 12], 
      state: 0
    }, 
    {
      pos: [9, 3, 12], 
      state: 0
    }, 
    {
      pos: [14, 3, 12], 
      state: 0
    }, 
    {
      pos: [15, 3, 12], 
      state: 0
    }, 
    {
      pos: [16, 3, 12], 
      state: 0
    }, 
    {
      pos: [7, 3, 13], 
      state: 2
    }, 
    {
      pos: [8, 3, 13], 
      state: 0
    }, 
    {
      pos: [9, 3, 13], 
      state: 0
    }, 
    {
      pos: [10, 3, 13], 
      state: 0
    }, 
    {
      pos: [11, 3, 13], 
      state: 9
    }, 
    {
      pos: [12, 3, 13], 
      state: 0
    }, 
    {
      pos: [13, 3, 13], 
      state: 0
    }, 
    {
      pos: [14, 3, 13], 
      state: 0
    }, 
    {
      pos: [15, 3, 13], 
      state: 0
    }, 
    {
      pos: [16, 3, 13], 
      state: 0
    }, 
    {
      pos: [3, 3, 0], 
      state: 6
    }, 
    {
      pos: [4, 3, 0], 
      state: 6
    }, 
    {
      pos: [5, 3, 0], 
      state: 6
    }, 
    {
      pos: [3, 3, 1], 
      state: 6
    }, 
    {
      pos: [4, 3, 1], 
      state: 6
    }, 
    {
      pos: [5, 3, 1], 
      state: 6
    }, 
    {
      pos: [10, 3, 1], 
      state: 6
    }, 
    {
      pos: [11, 3, 1], 
      state: 6
    }, 
    {
      pos: [12, 3, 1], 
      state: 6
    }, 
    {
      pos: [13, 3, 1], 
      state: 6
    }, 
    {
      pos: [0, 3, 2], 
      state: 6
    }, 
    {
      pos: [1, 3, 2], 
      state: 6
    }, 
    {
      pos: [2, 3, 2], 
      state: 6
    }, 
    {
      pos: [3, 3, 2], 
      state: 6
    }, 
    {
      pos: [4, 3, 2], 
      state: 6
    }, 
    {
      pos: [5, 3, 2], 
      state: 6
    }, 
    {
      pos: [6, 3, 2], 
      state: 6
    }, 
    {
      pos: [7, 3, 2], 
      state: 6
    }, 
    {
      pos: [8, 3, 2], 
      state: 6
    }, 
    {
      pos: [10, 3, 2], 
      state: 6
    }, 
    {
      pos: [11, 3, 2], 
      state: 6
    }, 
    {
      pos: [12, 3, 2], 
      state: 6
    }, 
    {
      pos: [13, 3, 2], 
      state: 6
    }, 
    {
      pos: [0, 3, 3], 
      state: 6
    }, 
    {
      pos: [1, 3, 3], 
      state: 6
    }, 
    {
      pos: [2, 3, 3], 
      state: 6
    }, 
    {
      pos: [3, 3, 3], 
      state: 6
    }, 
    {
      pos: [4, 3, 3], 
      state: 6
    }, 
    {
      pos: [5, 3, 3], 
      state: 6
    }, 
    {
      pos: [6, 3, 3], 
      state: 6
    }, 
    {
      pos: [7, 3, 3], 
      state: 6
    }, 
    {
      pos: [8, 3, 3], 
      state: 6
    }, 
    {
      pos: [10, 3, 3], 
      state: 6
    }, 
    {
      pos: [11, 3, 3], 
      state: 6
    }, 
    {
      pos: [12, 3, 3], 
      state: 6
    }, 
    {
      pos: [0, 3, 4], 
      state: 6
    }, 
    {
      pos: [1, 3, 4], 
      state: 6
    }, 
    {
      pos: [2, 3, 4], 
      state: 6
    }, 
    {
      pos: [3, 3, 4], 
      state: 6
    }, 
    {
      pos: [4, 3, 4], 
      state: 6
    }, 
    {
      pos: [5, 3, 4], 
      state: 6
    }, 
    {
      pos: [6, 3, 4], 
      state: 6
    }, 
    {
      pos: [11, 3, 4], 
      state: 6
    }, 
    {
      pos: [12, 3, 4], 
      state: 6
    }, 
    {
      pos: [13, 3, 4], 
      state: 6
    }, 
    {
      pos: [1, 3, 5], 
      state: 6
    }, 
    {
      pos: [2, 3, 5], 
      state: 6
    }, 
    {
      pos: [3, 3, 5], 
      state: 6
    }, 
    {
      pos: [4, 3, 5], 
      state: 6
    }, 
    {
      pos: [5, 3, 5], 
      state: 6
    }, 
    {
      pos: [6, 3, 5], 
      state: 6
    }, 
    {
      pos: [12, 3, 5], 
      state: 6
    }, 
    {
      pos: [13, 3, 5], 
      state: 6
    }, 
    {
      pos: [14, 3, 5], 
      state: 6
    }, 
    {
      pos: [1, 3, 6], 
      state: 6
    }, 
    {
      pos: [2, 3, 6], 
      state: 6
    }, 
    {
      pos: [3, 3, 6], 
      state: 6
    }, 
    {
      pos: [4, 3, 6], 
      state: 6
    }, 
    {
      pos: [5, 3, 6], 
      state: 6
    }, 
    {
      pos: [6, 3, 6], 
      state: 6
    }, 
    {
      pos: [7, 3, 6], 
      state: 6
    }, 
    {
      pos: [8, 3, 6], 
      state: 6
    }, 
    {
      pos: [13, 3, 6], 
      state: 6
    }, 
    {
      pos: [14, 3, 6], 
      state: 6
    }, 
    {
      pos: [1, 3, 7], 
      state: 6
    }, 
    {
      pos: [2, 3, 7], 
      state: 6
    }, 
    {
      pos: [3, 3, 7], 
      state: 6
    }, 
    {
      pos: [4, 3, 7], 
      state: 6
    }, 
    {
      pos: [5, 3, 7], 
      state: 6
    }, 
    {
      pos: [6, 3, 7], 
      state: 6
    }, 
    {
      pos: [7, 3, 7], 
      state: 6
    }, 
    {
      pos: [8, 3, 7], 
      state: 6
    }, 
    {
      pos: [13, 3, 7], 
      state: 6
    }, 
    {
      pos: [14, 3, 7], 
      state: 6
    }, 
    {
      pos: [2, 3, 8], 
      state: 6
    }, 
    {
      pos: [3, 3, 8], 
      state: 6
    }, 
    {
      pos: [4, 3, 8], 
      state: 6
    }, 
    {
      pos: [5, 3, 8], 
      state: 6
    }, 
    {
      pos: [6, 3, 8], 
      state: 6
    }, 
    {
      pos: [13, 3, 8], 
      state: 6
    }, 
    {
      pos: [14, 3, 8], 
      state: 6
    }, 
    {
      pos: [2, 3, 9], 
      state: 6
    }, 
    {
      pos: [3, 3, 9], 
      state: 6
    }, 
    {
      pos: [4, 3, 9], 
      state: 6
    }, 
    {
      pos: [5, 3, 9], 
      state: 6
    }, 
    {
      pos: [6, 3, 9], 
      state: 6
    }, 
    {
      pos: [10, 3, 9], 
      state: 6
    }, 
    {
      pos: [11, 3, 9], 
      state: 6
    }, 
    {
      pos: [13, 3, 9], 
      state: 6
    }, 
    {
      pos: [14, 3, 9], 
      state: 6
    }, 
    {
      pos: [2, 3, 10], 
      state: 6
    }, 
    {
      pos: [3, 3, 10], 
      state: 6
    }, 
    {
      pos: [4, 3, 10], 
      state: 6
    }, 
    {
      pos: [5, 3, 10], 
      state: 6
    }, 
    {
      pos: [6, 3, 10], 
      state: 6
    }, 
    {
      pos: [7, 3, 10], 
      state: 6
    }, 
    {
      pos: [8, 3, 10], 
      state: 6
    }, 
    {
      pos: [10, 3, 10], 
      state: 6
    }, 
    {
      pos: [11, 3, 10], 
      state: 6
    }, 
    {
      pos: [12, 3, 10], 
      state: 6
    }, 
    {
      pos: [13, 3, 10], 
      state: 6
    }, 
    {
      pos: [14, 3, 10], 
      state: 6
    }, 
    {
      pos: [2, 3, 11], 
      state: 6
    }, 
    {
      pos: [3, 3, 11], 
      state: 6
    }, 
    {
      pos: [4, 3, 11], 
      state: 6
    }, 
    {
      pos: [5, 3, 11], 
      state: 6
    }, 
    {
      pos: [6, 3, 11], 
      state: 6
    }, 
    {
      pos: [7, 3, 11], 
      state: 6
    }, 
    {
      pos: [8, 3, 11], 
      state: 6
    }, 
    {
      pos: [10, 3, 11], 
      state: 6
    }, 
    {
      pos: [11, 3, 11], 
      state: 6
    }, 
    {
      pos: [12, 3, 11], 
      state: 6
    }, 
    {
      pos: [13, 3, 11], 
      state: 6
    }, 
    {
      pos: [2, 3, 12], 
      state: 6
    }, 
    {
      pos: [3, 3, 12], 
      state: 6
    }, 
    {
      pos: [4, 3, 12], 
      state: 6
    }, 
    {
      pos: [5, 3, 12], 
      state: 6
    }, 
    {
      pos: [6, 3, 12], 
      state: 6
    }, 
    {
      pos: [10, 3, 12], 
      state: 6
    }, 
    {
      pos: [11, 3, 12], 
      state: 6
    }, 
    {
      pos: [12, 3, 12], 
      state: 6
    }, 
    {
      pos: [13, 3, 12], 
      state: 6
    }, 
    {
      pos: [3, 3, 13], 
      state: 6
    }, 
    {
      pos: [4, 3, 13], 
      state: 6
    }, 
    {
      pos: [5, 3, 13], 
      state: 6
    }, 
    {
      pos: [6, 3, 13], 
      state: 6
    }, 
    {
      pos: [7, 4, 0], 
      state: 0
    }, 
    {
      pos: [8, 4, 0], 
      state: 0
    }, 
    {
      pos: [9, 4, 0], 
      state: 9
    }, 
    {
      pos: [10, 4, 0], 
      state: 9
    }, 
    {
      pos: [11, 4, 0], 
      state: 9
    }, 
    {
      pos: [12, 4, 0], 
      state: 0
    }, 
    {
      pos: [13, 4, 0], 
      state: 0
    }, 
    {
      pos: [14, 4, 0], 
      state: 0
    }, 
    {
      pos: [15, 4, 0], 
      state: 0
    }, 
    {
      pos: [16, 4, 0], 
      state: 0
    }, 
    {
      pos: [7, 4, 1], 
      state: 0
    }, 
    {
      pos: [8, 4, 1], 
      state: 0
    }, 
    {
      pos: [9, 4, 1], 
      state: 0
    }, 
    {
      pos: [10, 4, 1], 
      state: 0
    }, 
    {
      pos: [11, 4, 1], 
      state: 0
    }, 
    {
      pos: [16, 4, 1], 
      state: 0
    }, 
    {
      pos: [9, 4, 2], 
      state: 0
    }, 
    {
      pos: [10, 4, 2], 
      state: 0
    }, 
    {
      pos: [11, 4, 2], 
      state: 0
    }, 
    {
      pos: [16, 4, 2], 
      state: 0
    }, 
    {
      pos: [9, 4, 3], 
      state: 0
    }, 
    {
      pos: [10, 4, 3], 
      state: 0
    }, 
    {
      pos: [11, 4, 3], 
      state: 0
    }, 
    {
      pos: [12, 4, 3], 
      state: 0
    }, 
    {
      pos: [13, 4, 3], 
      state: 0
    }, 
    {
      pos: [14, 4, 3], 
      state: 0
    }, 
    {
      pos: [15, 4, 3], 
      state: 0
    }, 
    {
      pos: [16, 4, 3], 
      state: 0
    }, 
    {
      pos: [7, 4, 4], 
      state: 0
    }, 
    {
      pos: [8, 4, 4], 
      state: 0
    }, 
    {
      pos: [9, 4, 4], 
      state: 0
    }, 
    {
      pos: [10, 4, 4], 
      state: 0
    }, 
    {
      pos: [11, 4, 4], 
      state: 0
    }, 
    {
      pos: [12, 4, 4], 
      state: 0
    }, 
    {
      pos: [13, 4, 4], 
      state: 0
    }, 
    {
      pos: [14, 4, 4], 
      state: 0
    }, 
    {
      pos: [15, 4, 4], 
      state: 0
    }, 
    {
      pos: [16, 4, 4], 
      state: 0
    }, 
    {
      pos: [7, 4, 5], 
      state: 0
    }, 
    {
      pos: [8, 4, 5], 
      state: 0
    }, 
    {
      pos: [9, 4, 5], 
      state: 0
    }, 
    {
      pos: [10, 4, 5], 
      state: 0
    }, 
    {
      pos: [11, 4, 5], 
      state: 0
    }, 
    {
      pos: [12, 4, 5], 
      state: 0
    }, 
    {
      pos: [13, 4, 5], 
      state: 0
    }, 
    {
      pos: [14, 4, 5], 
      state: 0
    }, 
    {
      pos: [15, 4, 5], 
      state: 0
    }, 
    {
      pos: [16, 4, 5], 
      state: 0
    }, 
    {
      pos: [9, 4, 6], 
      state: 0
    }, 
    {
      pos: [10, 4, 6], 
      state: 0
    }, 
    {
      pos: [11, 4, 6], 
      state: 0
    }, 
    {
      pos: [12, 4, 6], 
      state: 0
    }, 
    {
      pos: [13, 4, 6], 
      state: 0
    }, 
    {
      pos: [14, 4, 6], 
      state: 0
    }, 
    {
      pos: [15, 4, 6], 
      state: 0
    }, 
    {
      pos: [16, 4, 6], 
      state: 0
    }, 
    {
      pos: [9, 4, 7], 
      state: 0
    }, 
    {
      pos: [10, 4, 7], 
      state: 0
    }, 
    {
      pos: [11, 4, 7], 
      state: 0
    }, 
    {
      pos: [12, 4, 7], 
      state: 0
    }, 
    {
      pos: [13, 4, 7], 
      state: 0
    }, 
    {
      pos: [14, 4, 7], 
      state: 0
    }, 
    {
      pos: [15, 4, 7], 
      state: 0
    }, 
    {
      pos: [16, 4, 7], 
      state: 0
    }, 
    {
      pos: [7, 4, 8], 
      state: 2
    }, 
    {
      pos: [8, 4, 8], 
      state: 0
    }, 
    {
      pos: [9, 4, 8], 
      state: 0
    }, 
    {
      pos: [10, 4, 8], 
      state: 0
    }, 
    {
      pos: [11, 4, 8], 
      state: 0
    }, 
    {
      pos: [12, 4, 8], 
      state: 0
    }, 
    {
      pos: [13, 4, 8], 
      state: 0
    }, 
    {
      pos: [14, 4, 8], 
      state: 0
    }, 
    {
      pos: [15, 4, 8], 
      state: 0
    }, 
    {
      pos: [16, 4, 8], 
      state: 0
    }, 
    {
      pos: [7, 4, 9], 
      state: 2
    }, 
    {
      pos: [8, 4, 9], 
      state: 0
    }, 
    {
      pos: [9, 4, 9], 
      state: 0
    }, 
    {
      pos: [10, 4, 9], 
      state: 0
    }, 
    {
      pos: [11, 4, 9], 
      state: 0
    }, 
    {
      pos: [12, 4, 9], 
      state: 0
    }, 
    {
      pos: [13, 4, 9], 
      state: 0
    }, 
    {
      pos: [14, 4, 9], 
      state: 0
    }, 
    {
      pos: [15, 4, 9], 
      state: 0
    }, 
    {
      pos: [16, 4, 9], 
      state: 0
    }, 
    {
      pos: [9, 4, 10], 
      state: 0
    }, 
    {
      pos: [10, 4, 10], 
      state: 0
    }, 
    {
      pos: [11, 4, 10], 
      state: 0
    }, 
    {
      pos: [14, 4, 10], 
      state: 0
    }, 
    {
      pos: [15, 4, 10], 
      state: 0
    }, 
    {
      pos: [16, 4, 10], 
      state: 0
    }, 
    {
      pos: [9, 4, 11], 
      state: 0
    }, 
    {
      pos: [10, 4, 11], 
      state: 0
    }, 
    {
      pos: [15, 4, 11], 
      state: 0
    }, 
    {
      pos: [16, 4, 11], 
      state: 0
    }, 
    {
      pos: [7, 4, 12], 
      state: 2
    }, 
    {
      pos: [8, 4, 12], 
      state: 0
    }, 
    {
      pos: [9, 4, 12], 
      state: 0
    }, 
    {
      pos: [10, 4, 12], 
      state: 0
    }, 
    {
      pos: [15, 4, 12], 
      state: 0
    }, 
    {
      pos: [16, 4, 12], 
      state: 0
    }, 
    {
      pos: [7, 4, 13], 
      state: 2
    }, 
    {
      pos: [8, 4, 13], 
      state: 0
    }, 
    {
      pos: [9, 4, 13], 
      state: 0
    }, 
    {
      pos: [10, 4, 13], 
      state: 0
    }, 
    {
      pos: [11, 4, 13], 
      state: 0
    }, 
    {
      pos: [12, 4, 13], 
      state: 9
    }, 
    {
      pos: [13, 4, 13], 
      state: 9
    }, 
    {
      pos: [14, 4, 13], 
      state: 0
    }, 
    {
      pos: [15, 4, 13], 
      state: 0
    }, 
    {
      pos: [16, 4, 13], 
      state: 0
    }, 
    {
      pos: [3, 4, 0], 
      state: 6
    }, 
    {
      pos: [4, 4, 0], 
      state: 6
    }, 
    {
      pos: [5, 4, 0], 
      state: 6
    }, 
    {
      pos: [3, 4, 1], 
      state: 6
    }, 
    {
      pos: [4, 4, 1], 
      state: 6
    }, 
    {
      pos: [5, 4, 1], 
      state: 6
    }, 
    {
      pos: [12, 4, 1], 
      state: 6
    }, 
    {
      pos: [13, 4, 1], 
      state: 6
    }, 
    {
      pos: [14, 4, 1], 
      state: 6
    }, 
    {
      pos: [15, 4, 1], 
      state: 6
    }, 
    {
      pos: [2, 4, 2], 
      state: 6
    }, 
    {
      pos: [3, 4, 2], 
      state: 6
    }, 
    {
      pos: [4, 4, 2], 
      state: 6
    }, 
    {
      pos: [5, 4, 2], 
      state: 6
    }, 
    {
      pos: [6, 4, 2], 
      state: 6
    }, 
    {
      pos: [7, 4, 2], 
      state: 6
    }, 
    {
      pos: [8, 4, 2], 
      state: 6
    }, 
    {
      pos: [12, 4, 2], 
      state: 6
    }, 
    {
      pos: [13, 4, 2], 
      state: 6
    }, 
    {
      pos: [14, 4, 2], 
      state: 6
    }, 
    {
      pos: [15, 4, 2], 
      state: 6
    }, 
    {
      pos: [1, 4, 3], 
      state: 6
    }, 
    {
      pos: [2, 4, 3], 
      state: 6
    }, 
    {
      pos: [3, 4, 3], 
      state: 6
    }, 
    {
      pos: [4, 4, 3], 
      state: 6
    }, 
    {
      pos: [5, 4, 3], 
      state: 6
    }, 
    {
      pos: [6, 4, 3], 
      state: 6
    }, 
    {
      pos: [7, 4, 3], 
      state: 6
    }, 
    {
      pos: [8, 4, 3], 
      state: 6
    }, 
    {
      pos: [1, 4, 4], 
      state: 6
    }, 
    {
      pos: [2, 4, 4], 
      state: 6
    }, 
    {
      pos: [3, 4, 4], 
      state: 6
    }, 
    {
      pos: [4, 4, 4], 
      state: 6
    }, 
    {
      pos: [5, 4, 4], 
      state: 6
    }, 
    {
      pos: [6, 4, 4], 
      state: 6
    }, 
    {
      pos: [1, 4, 5], 
      state: 6
    }, 
    {
      pos: [2, 4, 5], 
      state: 6
    }, 
    {
      pos: [3, 4, 5], 
      state: 6
    }, 
    {
      pos: [4, 4, 5], 
      state: 6
    }, 
    {
      pos: [5, 4, 5], 
      state: 6
    }, 
    {
      pos: [6, 4, 5], 
      state: 6
    }, 
    {
      pos: [2, 4, 6], 
      state: 6
    }, 
    {
      pos: [3, 4, 6], 
      state: 6
    }, 
    {
      pos: [4, 4, 6], 
      state: 6
    }, 
    {
      pos: [5, 4, 6], 
      state: 6
    }, 
    {
      pos: [6, 4, 6], 
      state: 6
    }, 
    {
      pos: [7, 4, 6], 
      state: 6
    }, 
    {
      pos: [8, 4, 6], 
      state: 6
    }, 
    {
      pos: [2, 4, 7], 
      state: 6
    }, 
    {
      pos: [3, 4, 7], 
      state: 6
    }, 
    {
      pos: [4, 4, 7], 
      state: 6
    }, 
    {
      pos: [5, 4, 7], 
      state: 6
    }, 
    {
      pos: [6, 4, 7], 
      state: 6
    }, 
    {
      pos: [7, 4, 7], 
      state: 6
    }, 
    {
      pos: [8, 4, 7], 
      state: 6
    }, 
    {
      pos: [3, 4, 8], 
      state: 6
    }, 
    {
      pos: [4, 4, 8], 
      state: 6
    }, 
    {
      pos: [5, 4, 8], 
      state: 6
    }, 
    {
      pos: [6, 4, 8], 
      state: 6
    }, 
    {
      pos: [1, 4, 9], 
      state: 6
    }, 
    {
      pos: [2, 4, 9], 
      state: 6
    }, 
    {
      pos: [3, 4, 9], 
      state: 6
    }, 
    {
      pos: [4, 4, 9], 
      state: 6
    }, 
    {
      pos: [5, 4, 9], 
      state: 6
    }, 
    {
      pos: [6, 4, 9], 
      state: 6
    }, 
    {
      pos: [1, 4, 10], 
      state: 6
    }, 
    {
      pos: [2, 4, 10], 
      state: 6
    }, 
    {
      pos: [3, 4, 10], 
      state: 6
    }, 
    {
      pos: [4, 4, 10], 
      state: 6
    }, 
    {
      pos: [5, 4, 10], 
      state: 6
    }, 
    {
      pos: [6, 4, 10], 
      state: 6
    }, 
    {
      pos: [7, 4, 10], 
      state: 6
    }, 
    {
      pos: [8, 4, 10], 
      state: 6
    }, 
    {
      pos: [12, 4, 10], 
      state: 6
    }, 
    {
      pos: [13, 4, 10], 
      state: 6
    }, 
    {
      pos: [1, 4, 11], 
      state: 6
    }, 
    {
      pos: [2, 4, 11], 
      state: 6
    }, 
    {
      pos: [3, 4, 11], 
      state: 6
    }, 
    {
      pos: [4, 4, 11], 
      state: 6
    }, 
    {
      pos: [5, 4, 11], 
      state: 6
    }, 
    {
      pos: [6, 4, 11], 
      state: 6
    }, 
    {
      pos: [7, 4, 11], 
      state: 6
    }, 
    {
      pos: [8, 4, 11], 
      state: 6
    }, 
    {
      pos: [11, 4, 11], 
      state: 6
    }, 
    {
      pos: [12, 4, 11], 
      state: 6
    }, 
    {
      pos: [13, 4, 11], 
      state: 6
    }, 
    {
      pos: [14, 4, 11], 
      state: 6
    }, 
    {
      pos: [1, 4, 12], 
      state: 6
    }, 
    {
      pos: [2, 4, 12], 
      state: 6
    }, 
    {
      pos: [3, 4, 12], 
      state: 6
    }, 
    {
      pos: [4, 4, 12], 
      state: 6
    }, 
    {
      pos: [5, 4, 12], 
      state: 6
    }, 
    {
      pos: [6, 4, 12], 
      state: 6
    }, 
    {
      pos: [11, 4, 12], 
      state: 6
    }, 
    {
      pos: [12, 4, 12], 
      state: 6
    }, 
    {
      pos: [13, 4, 12], 
      state: 6
    }, 
    {
      pos: [14, 4, 12], 
      state: 6
    }, 
    {
      pos: [2, 4, 13], 
      state: 6
    }, 
    {
      pos: [3, 4, 13], 
      state: 6
    }, 
    {
      pos: [4, 4, 13], 
      state: 6
    }, 
    {
      pos: [5, 4, 13], 
      state: 6
    }, 
    {
      pos: [6, 4, 13], 
      state: 6
    }, 
    {
      pos: [8, 5, 0], 
      state: 0
    }, 
    {
      pos: [9, 5, 0], 
      state: 0
    }, 
    {
      pos: [10, 5, 0], 
      state: 9
    }, 
    {
      pos: [11, 5, 0], 
      state: 0
    }, 
    {
      pos: [12, 5, 0], 
      state: 0
    }, 
    {
      pos: [13, 5, 0], 
      state: 0
    }, 
    {
      pos: [14, 5, 0], 
      state: 0
    }, 
    {
      pos: [15, 5, 0], 
      state: 0
    }, 
    {
      pos: [8, 5, 1], 
      state: 0
    }, 
    {
      pos: [9, 5, 1], 
      state: 0
    }, 
    {
      pos: [10, 5, 1], 
      state: 0
    }, 
    {
      pos: [11, 5, 1], 
      state: 0
    }, 
    {
      pos: [12, 5, 1], 
      state: 0
    }, 
    {
      pos: [16, 5, 1], 
      state: 0
    }, 
    {
      pos: [9, 5, 2], 
      state: 0
    }, 
    {
      pos: [10, 5, 2], 
      state: 0
    }, 
    {
      pos: [11, 5, 2], 
      state: 0
    }, 
    {
      pos: [12, 5, 2], 
      state: 0
    }, 
    {
      pos: [16, 5, 2], 
      state: 0
    }, 
    {
      pos: [9, 5, 3], 
      state: 0
    }, 
    {
      pos: [10, 5, 3], 
      state: 0
    }, 
    {
      pos: [11, 5, 3], 
      state: 0
    }, 
    {
      pos: [12, 5, 3], 
      state: 0
    }, 
    {
      pos: [13, 5, 3], 
      state: 0
    }, 
    {
      pos: [16, 5, 3], 
      state: 0
    }, 
    {
      pos: [8, 5, 4], 
      state: 0
    }, 
    {
      pos: [9, 5, 4], 
      state: 0
    }, 
    {
      pos: [10, 5, 4], 
      state: 0
    }, 
    {
      pos: [11, 5, 4], 
      state: 0
    }, 
    {
      pos: [12, 5, 4], 
      state: 0
    }, 
    {
      pos: [13, 5, 4], 
      state: 0
    }, 
    {
      pos: [14, 5, 4], 
      state: 0
    }, 
    {
      pos: [15, 5, 4], 
      state: 0
    }, 
    {
      pos: [16, 5, 4], 
      state: 0
    }, 
    {
      pos: [8, 5, 5], 
      state: 0
    }, 
    {
      pos: [9, 5, 5], 
      state: 0
    }, 
    {
      pos: [10, 5, 5], 
      state: 0
    }, 
    {
      pos: [11, 5, 5], 
      state: 0
    }, 
    {
      pos: [12, 5, 5], 
      state: 0
    }, 
    {
      pos: [13, 5, 5], 
      state: 0
    }, 
    {
      pos: [14, 5, 5], 
      state: 0
    }, 
    {
      pos: [15, 5, 5], 
      state: 0
    }, 
    {
      pos: [16, 5, 5], 
      state: 0
    }, 
    {
      pos: [9, 5, 6], 
      state: 0
    }, 
    {
      pos: [10, 5, 6], 
      state: 0
    }, 
    {
      pos: [11, 5, 6], 
      state: 0
    }, 
    {
      pos: [12, 5, 6], 
      state: 0
    }, 
    {
      pos: [13, 5, 6], 
      state: 0
    }, 
    {
      pos: [14, 5, 6], 
      state: 0
    }, 
    {
      pos: [15, 5, 6], 
      state: 0
    }, 
    {
      pos: [16, 5, 6], 
      state: 0
    }, 
    {
      pos: [10, 5, 7], 
      state: 0
    }, 
    {
      pos: [11, 5, 7], 
      state: 0
    }, 
    {
      pos: [12, 5, 7], 
      state: 0
    }, 
    {
      pos: [13, 5, 7], 
      state: 0
    }, 
    {
      pos: [14, 5, 7], 
      state: 0
    }, 
    {
      pos: [15, 5, 7], 
      state: 0
    }, 
    {
      pos: [16, 5, 7], 
      state: 0
    }, 
    {
      pos: [8, 5, 8], 
      state: 0
    }, 
    {
      pos: [9, 5, 8], 
      state: 0
    }, 
    {
      pos: [10, 5, 8], 
      state: 0
    }, 
    {
      pos: [11, 5, 8], 
      state: 0
    }, 
    {
      pos: [12, 5, 8], 
      state: 0
    }, 
    {
      pos: [13, 5, 8], 
      state: 0
    }, 
    {
      pos: [14, 5, 8], 
      state: 0
    }, 
    {
      pos: [15, 5, 8], 
      state: 0
    }, 
    {
      pos: [16, 5, 8], 
      state: 0
    }, 
    {
      pos: [8, 5, 9], 
      state: 2
    }, 
    {
      pos: [9, 5, 9], 
      state: 0
    }, 
    {
      pos: [10, 5, 9], 
      state: 0
    }, 
    {
      pos: [11, 5, 9], 
      state: 0
    }, 
    {
      pos: [12, 5, 9], 
      state: 0
    }, 
    {
      pos: [13, 5, 9], 
      state: 0
    }, 
    {
      pos: [14, 5, 9], 
      state: 0
    }, 
    {
      pos: [15, 5, 9], 
      state: 0
    }, 
    {
      pos: [16, 5, 9], 
      state: 0
    }, 
    {
      pos: [9, 5, 10], 
      state: 0
    }, 
    {
      pos: [10, 5, 10], 
      state: 0
    }, 
    {
      pos: [11, 5, 10], 
      state: 0
    }, 
    {
      pos: [12, 5, 10], 
      state: 0
    }, 
    {
      pos: [13, 5, 10], 
      state: 0
    }, 
    {
      pos: [16, 5, 10], 
      state: 0
    }, 
    {
      pos: [9, 5, 11], 
      state: 0
    }, 
    {
      pos: [10, 5, 11], 
      state: 0
    }, 
    {
      pos: [11, 5, 11], 
      state: 0
    }, 
    {
      pos: [16, 5, 11], 
      state: 0
    }, 
    {
      pos: [8, 5, 12], 
      state: 0
    }, 
    {
      pos: [9, 5, 12], 
      state: 0
    }, 
    {
      pos: [10, 5, 12], 
      state: 0
    }, 
    {
      pos: [11, 5, 12], 
      state: 0
    }, 
    {
      pos: [16, 5, 12], 
      state: 0
    }, 
    {
      pos: [8, 5, 13], 
      state: 0
    }, 
    {
      pos: [9, 5, 13], 
      state: 0
    }, 
    {
      pos: [10, 5, 13], 
      state: 9
    }, 
    {
      pos: [11, 5, 13], 
      state: 9
    }, 
    {
      pos: [12, 5, 13], 
      state: 9
    }, 
    {
      pos: [13, 5, 13], 
      state: 9
    }, 
    {
      pos: [14, 5, 13], 
      state: 0
    }, 
    {
      pos: [15, 5, 13], 
      state: 0
    }, 
    {
      pos: [16, 5, 13], 
      state: 0
    }, 
    {
      nbt: {
        joint: "rollable", 
        final_state: "minecraft:polished_blackstone_bricks", 
        name: "minecraft:empty", 
        pool: "minecraft:bastion/treasure/ramparts", 
        id: "minecraft:jigsaw", 
        target: "minecraft:lava_basin_connector_main"
      }, 
      pos: [16, 5, 0], 
      state: 10
    }, 
    {
      pos: [2, 5, 0], 
      state: 6
    }, 
    {
      pos: [3, 5, 0], 
      state: 6
    }, 
    {
      pos: [4, 5, 0], 
      state: 6
    }, 
    {
      pos: [5, 5, 0], 
      state: 6
    }, 
    {
      pos: [6, 5, 0], 
      state: 6
    }, 
    {
      pos: [7, 5, 0], 
      state: 6
    }, 
    {
      pos: [1, 5, 1], 
      state: 6
    }, 
    {
      pos: [2, 5, 1], 
      state: 6
    }, 
    {
      pos: [3, 5, 1], 
      state: 6
    }, 
    {
      pos: [4, 5, 1], 
      state: 6
    }, 
    {
      pos: [5, 5, 1], 
      state: 6
    }, 
    {
      pos: [6, 5, 1], 
      state: 6
    }, 
    {
      pos: [7, 5, 1], 
      state: 6
    }, 
    {
      pos: [13, 5, 1], 
      state: 6
    }, 
    {
      pos: [14, 5, 1], 
      state: 6
    }, 
    {
      pos: [15, 5, 1], 
      state: 6
    }, 
    {
      pos: [2, 5, 2], 
      state: 6
    }, 
    {
      pos: [3, 5, 2], 
      state: 6
    }, 
    {
      pos: [4, 5, 2], 
      state: 6
    }, 
    {
      pos: [5, 5, 2], 
      state: 6
    }, 
    {
      pos: [6, 5, 2], 
      state: 6
    }, 
    {
      pos: [7, 5, 2], 
      state: 6
    }, 
    {
      pos: [8, 5, 2], 
      state: 6
    }, 
    {
      pos: [13, 5, 2], 
      state: 6
    }, 
    {
      pos: [14, 5, 2], 
      state: 6
    }, 
    {
      pos: [15, 5, 2], 
      state: 6
    }, 
    {
      pos: [2, 5, 3], 
      state: 6
    }, 
    {
      pos: [3, 5, 3], 
      state: 6
    }, 
    {
      pos: [4, 5, 3], 
      state: 6
    }, 
    {
      pos: [5, 5, 3], 
      state: 6
    }, 
    {
      pos: [6, 5, 3], 
      state: 6
    }, 
    {
      pos: [7, 5, 3], 
      state: 6
    }, 
    {
      pos: [8, 5, 3], 
      state: 6
    }, 
    {
      pos: [14, 5, 3], 
      state: 6
    }, 
    {
      pos: [15, 5, 3], 
      state: 6
    }, 
    {
      pos: [3, 5, 4], 
      state: 6
    }, 
    {
      pos: [4, 5, 4], 
      state: 6
    }, 
    {
      pos: [5, 5, 4], 
      state: 6
    }, 
    {
      pos: [6, 5, 4], 
      state: 6
    }, 
    {
      pos: [7, 5, 4], 
      state: 6
    }, 
    {
      pos: [1, 5, 5], 
      state: 6
    }, 
    {
      pos: [2, 5, 5], 
      state: 6
    }, 
    {
      pos: [3, 5, 5], 
      state: 6
    }, 
    {
      pos: [4, 5, 5], 
      state: 6
    }, 
    {
      pos: [5, 5, 5], 
      state: 6
    }, 
    {
      pos: [6, 5, 5], 
      state: 6
    }, 
    {
      pos: [7, 5, 5], 
      state: 6
    }, 
    {
      pos: [2, 5, 6], 
      state: 6
    }, 
    {
      pos: [3, 5, 6], 
      state: 6
    }, 
    {
      pos: [4, 5, 6], 
      state: 6
    }, 
    {
      pos: [5, 5, 6], 
      state: 6
    }, 
    {
      pos: [6, 5, 6], 
      state: 6
    }, 
    {
      pos: [7, 5, 6], 
      state: 6
    }, 
    {
      pos: [8, 5, 6], 
      state: 6
    }, 
    {
      pos: [2, 5, 7], 
      state: 6
    }, 
    {
      pos: [3, 5, 7], 
      state: 6
    }, 
    {
      pos: [4, 5, 7], 
      state: 6
    }, 
    {
      pos: [5, 5, 7], 
      state: 6
    }, 
    {
      pos: [6, 5, 7], 
      state: 6
    }, 
    {
      pos: [7, 5, 7], 
      state: 6
    }, 
    {
      pos: [8, 5, 7], 
      state: 6
    }, 
    {
      pos: [9, 5, 7], 
      state: 6
    }, 
    {
      pos: [1, 5, 8], 
      state: 6
    }, 
    {
      pos: [2, 5, 8], 
      state: 6
    }, 
    {
      pos: [3, 5, 8], 
      state: 6
    }, 
    {
      pos: [4, 5, 8], 
      state: 6
    }, 
    {
      pos: [5, 5, 8], 
      state: 6
    }, 
    {
      pos: [6, 5, 8], 
      state: 6
    }, 
    {
      pos: [7, 5, 8], 
      state: 6
    }, 
    {
      pos: [1, 5, 9], 
      state: 6
    }, 
    {
      pos: [2, 5, 9], 
      state: 6
    }, 
    {
      pos: [3, 5, 9], 
      state: 6
    }, 
    {
      pos: [4, 5, 9], 
      state: 6
    }, 
    {
      pos: [5, 5, 9], 
      state: 6
    }, 
    {
      pos: [6, 5, 9], 
      state: 6
    }, 
    {
      pos: [7, 5, 9], 
      state: 6
    }, 
    {
      pos: [1, 5, 10], 
      state: 6
    }, 
    {
      pos: [2, 5, 10], 
      state: 6
    }, 
    {
      pos: [3, 5, 10], 
      state: 6
    }, 
    {
      pos: [4, 5, 10], 
      state: 6
    }, 
    {
      pos: [5, 5, 10], 
      state: 6
    }, 
    {
      pos: [6, 5, 10], 
      state: 6
    }, 
    {
      pos: [7, 5, 10], 
      state: 6
    }, 
    {
      pos: [8, 5, 10], 
      state: 6
    }, 
    {
      pos: [14, 5, 10], 
      state: 6
    }, 
    {
      pos: [15, 5, 10], 
      state: 6
    }, 
    {
      pos: [1, 5, 11], 
      state: 6
    }, 
    {
      pos: [2, 5, 11], 
      state: 6
    }, 
    {
      pos: [3, 5, 11], 
      state: 6
    }, 
    {
      pos: [4, 5, 11], 
      state: 6
    }, 
    {
      pos: [5, 5, 11], 
      state: 6
    }, 
    {
      pos: [6, 5, 11], 
      state: 6
    }, 
    {
      pos: [7, 5, 11], 
      state: 6
    }, 
    {
      pos: [8, 5, 11], 
      state: 6
    }, 
    {
      pos: [12, 5, 11], 
      state: 6
    }, 
    {
      pos: [13, 5, 11], 
      state: 6
    }, 
    {
      pos: [14, 5, 11], 
      state: 6
    }, 
    {
      pos: [15, 5, 11], 
      state: 6
    }, 
    {
      pos: [1, 5, 12], 
      state: 6
    }, 
    {
      pos: [2, 5, 12], 
      state: 6
    }, 
    {
      pos: [3, 5, 12], 
      state: 6
    }, 
    {
      pos: [4, 5, 12], 
      state: 6
    }, 
    {
      pos: [5, 5, 12], 
      state: 6
    }, 
    {
      pos: [6, 5, 12], 
      state: 6
    }, 
    {
      pos: [7, 5, 12], 
      state: 6
    }, 
    {
      pos: [12, 5, 12], 
      state: 6
    }, 
    {
      pos: [13, 5, 12], 
      state: 6
    }, 
    {
      pos: [14, 5, 12], 
      state: 6
    }, 
    {
      pos: [15, 5, 12], 
      state: 6
    }, 
    {
      pos: [2, 5, 13], 
      state: 6
    }, 
    {
      pos: [3, 5, 13], 
      state: 6
    }, 
    {
      pos: [4, 5, 13], 
      state: 6
    }, 
    {
      pos: [5, 5, 13], 
      state: 6
    }, 
    {
      pos: [6, 5, 13], 
      state: 6
    }, 
    {
      pos: [7, 5, 13], 
      state: 6
    }, 
    {
      pos: [8, 6, 0], 
      state: 0
    }, 
    {
      pos: [9, 6, 0], 
      state: 0
    }, 
    {
      pos: [10, 6, 0], 
      state: 0
    }, 
    {
      pos: [11, 6, 0], 
      state: 0
    }, 
    {
      pos: [12, 6, 0], 
      state: 0
    }, 
    {
      pos: [13, 6, 0], 
      state: 0
    }, 
    {
      pos: [14, 6, 0], 
      state: 0
    }, 
    {
      pos: [15, 6, 0], 
      state: 0
    }, 
    {
      pos: [16, 6, 0], 
      state: 0
    }, 
    {
      pos: [8, 6, 1], 
      state: 0
    }, 
    {
      pos: [9, 6, 1], 
      state: 0
    }, 
    {
      pos: [10, 6, 1], 
      state: 0
    }, 
    {
      pos: [11, 6, 1], 
      state: 0
    }, 
    {
      pos: [12, 6, 1], 
      state: 0
    }, 
    {
      pos: [13, 6, 1], 
      state: 0
    }, 
    {
      pos: [16, 6, 1], 
      state: 0
    }, 
    {
      pos: [9, 6, 2], 
      state: 0
    }, 
    {
      pos: [10, 6, 2], 
      state: 0
    }, 
    {
      pos: [11, 6, 2], 
      state: 0
    }, 
    {
      pos: [12, 6, 2], 
      state: 0
    }, 
    {
      pos: [13, 6, 2], 
      state: 0
    }, 
    {
      pos: [16, 6, 2], 
      state: 0
    }, 
    {
      pos: [9, 6, 3], 
      state: 0
    }, 
    {
      pos: [10, 6, 3], 
      state: 0
    }, 
    {
      pos: [11, 6, 3], 
      state: 0
    }, 
    {
      pos: [12, 6, 3], 
      state: 0
    }, 
    {
      pos: [13, 6, 3], 
      state: 0
    }, 
    {
      pos: [16, 6, 3], 
      state: 0
    }, 
    {
      pos: [8, 6, 4], 
      state: 0
    }, 
    {
      pos: [9, 6, 4], 
      state: 0
    }, 
    {
      pos: [10, 6, 4], 
      state: 0
    }, 
    {
      pos: [11, 6, 4], 
      state: 0
    }, 
    {
      pos: [12, 6, 4], 
      state: 0
    }, 
    {
      pos: [13, 6, 4], 
      state: 0
    }, 
    {
      pos: [16, 6, 4], 
      state: 0
    }, 
    {
      pos: [8, 6, 5], 
      state: 0
    }, 
    {
      pos: [9, 6, 5], 
      state: 0
    }, 
    {
      pos: [10, 6, 5], 
      state: 0
    }, 
    {
      pos: [11, 6, 5], 
      state: 0
    }, 
    {
      pos: [12, 6, 5], 
      state: 0
    }, 
    {
      pos: [13, 6, 5], 
      state: 0
    }, 
    {
      pos: [14, 6, 5], 
      state: 0
    }, 
    {
      pos: [15, 6, 5], 
      state: 0
    }, 
    {
      pos: [16, 6, 5], 
      state: 0
    }, 
    {
      pos: [9, 6, 6], 
      state: 0
    }, 
    {
      pos: [10, 6, 6], 
      state: 0
    }, 
    {
      pos: [11, 6, 6], 
      state: 0
    }, 
    {
      pos: [12, 6, 6], 
      state: 0
    }, 
    {
      pos: [13, 6, 6], 
      state: 0
    }, 
    {
      pos: [14, 6, 6], 
      state: 0
    }, 
    {
      pos: [15, 6, 6], 
      state: 0
    }, 
    {
      pos: [16, 6, 6], 
      state: 0
    }, 
    {
      pos: [9, 6, 7], 
      state: 0
    }, 
    {
      pos: [10, 6, 7], 
      state: 0
    }, 
    {
      pos: [11, 6, 7], 
      state: 0
    }, 
    {
      pos: [12, 6, 7], 
      state: 0
    }, 
    {
      pos: [13, 6, 7], 
      state: 0
    }, 
    {
      pos: [14, 6, 7], 
      state: 0
    }, 
    {
      pos: [15, 6, 7], 
      state: 0
    }, 
    {
      pos: [16, 6, 7], 
      state: 0
    }, 
    {
      pos: [8, 6, 8], 
      state: 0
    }, 
    {
      pos: [9, 6, 8], 
      state: 0
    }, 
    {
      pos: [10, 6, 8], 
      state: 0
    }, 
    {
      pos: [11, 6, 8], 
      state: 0
    }, 
    {
      pos: [12, 6, 8], 
      state: 0
    }, 
    {
      pos: [13, 6, 8], 
      state: 0
    }, 
    {
      pos: [14, 6, 8], 
      state: 0
    }, 
    {
      pos: [15, 6, 8], 
      state: 0
    }, 
    {
      pos: [16, 6, 8], 
      state: 0
    }, 
    {
      pos: [8, 6, 9], 
      state: 2
    }, 
    {
      pos: [9, 6, 9], 
      state: 0
    }, 
    {
      pos: [10, 6, 9], 
      state: 0
    }, 
    {
      pos: [11, 6, 9], 
      state: 0
    }, 
    {
      pos: [12, 6, 9], 
      state: 0
    }, 
    {
      pos: [13, 6, 9], 
      state: 0
    }, 
    {
      pos: [16, 6, 9], 
      state: 0
    }, 
    {
      pos: [9, 6, 10], 
      state: 0
    }, 
    {
      pos: [10, 6, 10], 
      state: 0
    }, 
    {
      pos: [11, 6, 10], 
      state: 0
    }, 
    {
      pos: [12, 6, 10], 
      state: 0
    }, 
    {
      pos: [13, 6, 10], 
      state: 0
    }, 
    {
      pos: [16, 6, 10], 
      state: 0
    }, 
    {
      pos: [9, 6, 11], 
      state: 0
    }, 
    {
      pos: [10, 6, 11], 
      state: 0
    }, 
    {
      pos: [11, 6, 11], 
      state: 0
    }, 
    {
      pos: [12, 6, 11], 
      state: 0
    }, 
    {
      pos: [13, 6, 11], 
      state: 0
    }, 
    {
      pos: [16, 6, 11], 
      state: 0
    }, 
    {
      pos: [8, 6, 12], 
      state: 0
    }, 
    {
      pos: [9, 6, 12], 
      state: 0
    }, 
    {
      pos: [10, 6, 12], 
      state: 0
    }, 
    {
      pos: [11, 6, 12], 
      state: 0
    }, 
    {
      pos: [12, 6, 12], 
      state: 0
    }, 
    {
      pos: [13, 6, 12], 
      state: 0
    }, 
    {
      pos: [16, 6, 12], 
      state: 0
    }, 
    {
      pos: [8, 6, 13], 
      state: 0
    }, 
    {
      pos: [9, 6, 13], 
      state: 0
    }, 
    {
      pos: [10, 6, 13], 
      state: 0
    }, 
    {
      pos: [11, 6, 13], 
      state: 9
    }, 
    {
      pos: [12, 6, 13], 
      state: 0
    }, 
    {
      pos: [13, 6, 13], 
      state: 0
    }, 
    {
      pos: [14, 6, 13], 
      state: 0
    }, 
    {
      pos: [15, 6, 13], 
      state: 0
    }, 
    {
      pos: [16, 6, 13], 
      state: 0
    }, 
    {
      pos: [1, 6, 0], 
      state: 6
    }, 
    {
      pos: [2, 6, 0], 
      state: 6
    }, 
    {
      pos: [3, 6, 0], 
      state: 6
    }, 
    {
      pos: [4, 6, 0], 
      state: 6
    }, 
    {
      pos: [5, 6, 0], 
      state: 6
    }, 
    {
      pos: [6, 6, 0], 
      state: 6
    }, 
    {
      pos: [7, 6, 0], 
      state: 6
    }, 
    {
      pos: [1, 6, 1], 
      state: 6
    }, 
    {
      pos: [2, 6, 1], 
      state: 6
    }, 
    {
      pos: [3, 6, 1], 
      state: 6
    }, 
    {
      pos: [4, 6, 1], 
      state: 6
    }, 
    {
      pos: [5, 6, 1], 
      state: 6
    }, 
    {
      pos: [6, 6, 1], 
      state: 6
    }, 
    {
      pos: [7, 6, 1], 
      state: 6
    }, 
    {
      pos: [14, 6, 1], 
      state: 6
    }, 
    {
      pos: [15, 6, 1], 
      state: 7
    }, 
    {
      pos: [1, 6, 2], 
      state: 6
    }, 
    {
      pos: [2, 6, 2], 
      state: 6
    }, 
    {
      pos: [3, 6, 2], 
      state: 6
    }, 
    {
      pos: [4, 6, 2], 
      state: 6
    }, 
    {
      pos: [5, 6, 2], 
      state: 6
    }, 
    {
      pos: [6, 6, 2], 
      state: 6
    }, 
    {
      pos: [7, 6, 2], 
      state: 6
    }, 
    {
      pos: [8, 6, 2], 
      state: 6
    }, 
    {
      pos: [14, 6, 2], 
      state: 6
    }, 
    {
      pos: [15, 6, 2], 
      state: 6
    }, 
    {
      pos: [2, 6, 3], 
      state: 6
    }, 
    {
      pos: [3, 6, 3], 
      state: 6
    }, 
    {
      pos: [4, 6, 3], 
      state: 6
    }, 
    {
      pos: [5, 6, 3], 
      state: 6
    }, 
    {
      pos: [6, 6, 3], 
      state: 6
    }, 
    {
      pos: [7, 6, 3], 
      state: 6
    }, 
    {
      pos: [8, 6, 3], 
      state: 6
    }, 
    {
      pos: [14, 6, 3], 
      state: 6
    }, 
    {
      pos: [15, 6, 3], 
      state: 6
    }, 
    {
      pos: [2, 6, 4], 
      state: 6
    }, 
    {
      pos: [3, 6, 4], 
      state: 6
    }, 
    {
      pos: [4, 6, 4], 
      state: 6
    }, 
    {
      pos: [5, 6, 4], 
      state: 6
    }, 
    {
      pos: [6, 6, 4], 
      state: 6
    }, 
    {
      pos: [7, 6, 4], 
      state: 6
    }, 
    {
      pos: [14, 6, 4], 
      state: 6
    }, 
    {
      pos: [15, 6, 4], 
      state: 6
    }, 
    {
      pos: [2, 6, 5], 
      state: 6
    }, 
    {
      pos: [3, 6, 5], 
      state: 6
    }, 
    {
      pos: [4, 6, 5], 
      state: 6
    }, 
    {
      pos: [5, 6, 5], 
      state: 6
    }, 
    {
      pos: [6, 6, 5], 
      state: 6
    }, 
    {
      pos: [7, 6, 5], 
      state: 6
    }, 
    {
      pos: [2, 6, 6], 
      state: 6
    }, 
    {
      pos: [3, 6, 6], 
      state: 6
    }, 
    {
      pos: [4, 6, 6], 
      state: 6
    }, 
    {
      pos: [5, 6, 6], 
      state: 6
    }, 
    {
      pos: [6, 6, 6], 
      state: 6
    }, 
    {
      pos: [7, 6, 6], 
      state: 6
    }, 
    {
      pos: [8, 6, 6], 
      state: 6
    }, 
    {
      pos: [2, 6, 7], 
      state: 6
    }, 
    {
      pos: [3, 6, 7], 
      state: 6
    }, 
    {
      pos: [4, 6, 7], 
      state: 6
    }, 
    {
      pos: [5, 6, 7], 
      state: 6
    }, 
    {
      pos: [6, 6, 7], 
      state: 6
    }, 
    {
      pos: [7, 6, 7], 
      state: 6
    }, 
    {
      pos: [8, 6, 7], 
      state: 6
    }, 
    {
      pos: [2, 6, 8], 
      state: 6
    }, 
    {
      pos: [3, 6, 8], 
      state: 6
    }, 
    {
      pos: [4, 6, 8], 
      state: 6
    }, 
    {
      pos: [5, 6, 8], 
      state: 6
    }, 
    {
      pos: [6, 6, 8], 
      state: 6
    }, 
    {
      pos: [7, 6, 8], 
      state: 6
    }, 
    {
      pos: [2, 6, 9], 
      state: 6
    }, 
    {
      pos: [3, 6, 9], 
      state: 6
    }, 
    {
      pos: [4, 6, 9], 
      state: 6
    }, 
    {
      pos: [5, 6, 9], 
      state: 6
    }, 
    {
      pos: [6, 6, 9], 
      state: 6
    }, 
    {
      pos: [7, 6, 9], 
      state: 6
    }, 
    {
      pos: [14, 6, 9], 
      state: 6
    }, 
    {
      pos: [15, 6, 9], 
      state: 6
    }, 
    {
      pos: [1, 6, 10], 
      state: 6
    }, 
    {
      pos: [2, 6, 10], 
      state: 6
    }, 
    {
      pos: [3, 6, 10], 
      state: 6
    }, 
    {
      pos: [4, 6, 10], 
      state: 6
    }, 
    {
      pos: [5, 6, 10], 
      state: 6
    }, 
    {
      pos: [6, 6, 10], 
      state: 6
    }, 
    {
      pos: [7, 6, 10], 
      state: 6
    }, 
    {
      pos: [8, 6, 10], 
      state: 6
    }, 
    {
      pos: [14, 6, 10], 
      state: 6
    }, 
    {
      pos: [15, 6, 10], 
      state: 6
    }, 
    {
      pos: [1, 6, 11], 
      state: 6
    }, 
    {
      pos: [2, 6, 11], 
      state: 6
    }, 
    {
      pos: [3, 6, 11], 
      state: 6
    }, 
    {
      pos: [4, 6, 11], 
      state: 6
    }, 
    {
      pos: [5, 6, 11], 
      state: 6
    }, 
    {
      pos: [6, 6, 11], 
      state: 6
    }, 
    {
      pos: [7, 6, 11], 
      state: 6
    }, 
    {
      pos: [8, 6, 11], 
      state: 6
    }, 
    {
      pos: [14, 6, 11], 
      state: 6
    }, 
    {
      pos: [15, 6, 11], 
      state: 6
    }, 
    {
      pos: [1, 6, 12], 
      state: 6
    }, 
    {
      pos: [2, 6, 12], 
      state: 6
    }, 
    {
      pos: [3, 6, 12], 
      state: 6
    }, 
    {
      pos: [4, 6, 12], 
      state: 6
    }, 
    {
      pos: [5, 6, 12], 
      state: 6
    }, 
    {
      pos: [6, 6, 12], 
      state: 6
    }, 
    {
      pos: [7, 6, 12], 
      state: 6
    }, 
    {
      pos: [14, 6, 12], 
      state: 6
    }, 
    {
      pos: [15, 6, 12], 
      state: 6
    }, 
    {
      pos: [2, 6, 13], 
      state: 6
    }, 
    {
      pos: [3, 6, 13], 
      state: 6
    }, 
    {
      pos: [4, 6, 13], 
      state: 6
    }, 
    {
      pos: [5, 6, 13], 
      state: 6
    }, 
    {
      pos: [6, 6, 13], 
      state: 6
    }, 
    {
      pos: [7, 6, 13], 
      state: 6
    }, 
    {
      pos: [8, 7, 0], 
      state: 0
    }, 
    {
      pos: [9, 7, 0], 
      state: 0
    }, 
    {
      pos: [10, 7, 0], 
      state: 0
    }, 
    {
      pos: [11, 7, 0], 
      state: 0
    }, 
    {
      pos: [12, 7, 0], 
      state: 0
    }, 
    {
      pos: [13, 7, 0], 
      state: 0
    }, 
    {
      pos: [14, 7, 0], 
      state: 0
    }, 
    {
      pos: [15, 7, 0], 
      state: 9
    }, 
    {
      pos: [16, 7, 0], 
      state: 0
    }, 
    {
      pos: [8, 7, 1], 
      state: 0
    }, 
    {
      pos: [9, 7, 1], 
      state: 0
    }, 
    {
      pos: [10, 7, 1], 
      state: 0
    }, 
    {
      pos: [11, 7, 1], 
      state: 0
    }, 
    {
      pos: [12, 7, 1], 
      state: 0
    }, 
    {
      pos: [13, 7, 1], 
      state: 0
    }, 
    {
      pos: [14, 7, 1], 
      state: 0
    }, 
    {
      pos: [15, 7, 1], 
      state: 0
    }, 
    {
      pos: [16, 7, 1], 
      state: 0
    }, 
    {
      pos: [9, 7, 2], 
      state: 0
    }, 
    {
      pos: [10, 7, 2], 
      state: 0
    }, 
    {
      pos: [11, 7, 2], 
      state: 0
    }, 
    {
      pos: [12, 7, 2], 
      state: 0
    }, 
    {
      pos: [13, 7, 2], 
      state: 0
    }, 
    {
      pos: [14, 7, 2], 
      state: 0
    }, 
    {
      pos: [15, 7, 2], 
      state: 0
    }, 
    {
      pos: [16, 7, 2], 
      state: 0
    }, 
    {
      pos: [9, 7, 3], 
      state: 0
    }, 
    {
      pos: [10, 7, 3], 
      state: 0
    }, 
    {
      pos: [11, 7, 3], 
      state: 0
    }, 
    {
      pos: [12, 7, 3], 
      state: 0
    }, 
    {
      pos: [13, 7, 3], 
      state: 0
    }, 
    {
      pos: [16, 7, 3], 
      state: 0
    }, 
    {
      pos: [8, 7, 4], 
      state: 0
    }, 
    {
      pos: [9, 7, 4], 
      state: 0
    }, 
    {
      pos: [10, 7, 4], 
      state: 0
    }, 
    {
      pos: [11, 7, 4], 
      state: 0
    }, 
    {
      pos: [12, 7, 4], 
      state: 0
    }, 
    {
      pos: [13, 7, 4], 
      state: 0
    }, 
    {
      pos: [16, 7, 4], 
      state: 0
    }, 
    {
      pos: [8, 7, 5], 
      state: 0
    }, 
    {
      pos: [9, 7, 5], 
      state: 0
    }, 
    {
      pos: [10, 7, 5], 
      state: 0
    }, 
    {
      pos: [11, 7, 5], 
      state: 0
    }, 
    {
      pos: [12, 7, 5], 
      state: 0
    }, 
    {
      pos: [13, 7, 5], 
      state: 0
    }, 
    {
      pos: [16, 7, 5], 
      state: 0
    }, 
    {
      pos: [9, 7, 6], 
      state: 0
    }, 
    {
      pos: [10, 7, 6], 
      state: 0
    }, 
    {
      pos: [11, 7, 6], 
      state: 0
    }, 
    {
      pos: [12, 7, 6], 
      state: 0
    }, 
    {
      pos: [13, 7, 6], 
      state: 0
    }, 
    {
      pos: [14, 7, 6], 
      state: 0
    }, 
    {
      pos: [15, 7, 6], 
      state: 0
    }, 
    {
      pos: [16, 7, 6], 
      state: 0
    }, 
    {
      pos: [9, 7, 7], 
      state: 0
    }, 
    {
      pos: [10, 7, 7], 
      state: 0
    }, 
    {
      pos: [11, 7, 7], 
      state: 0
    }, 
    {
      pos: [12, 7, 7], 
      state: 0
    }, 
    {
      pos: [13, 7, 7], 
      state: 0
    }, 
    {
      pos: [14, 7, 7], 
      state: 0
    }, 
    {
      pos: [15, 7, 7], 
      state: 0
    }, 
    {
      pos: [16, 7, 7], 
      state: 0
    }, 
    {
      pos: [8, 7, 8], 
      state: 0
    }, 
    {
      pos: [9, 7, 8], 
      state: 0
    }, 
    {
      pos: [10, 7, 8], 
      state: 0
    }, 
    {
      pos: [11, 7, 8], 
      state: 0
    }, 
    {
      pos: [12, 7, 8], 
      state: 0
    }, 
    {
      pos: [13, 7, 8], 
      state: 0
    }, 
    {
      pos: [16, 7, 8], 
      state: 0
    }, 
    {
      pos: [8, 7, 9], 
      state: 0
    }, 
    {
      pos: [9, 7, 9], 
      state: 0
    }, 
    {
      pos: [10, 7, 9], 
      state: 0
    }, 
    {
      pos: [11, 7, 9], 
      state: 0
    }, 
    {
      pos: [12, 7, 9], 
      state: 0
    }, 
    {
      pos: [13, 7, 9], 
      state: 0
    }, 
    {
      pos: [16, 7, 9], 
      state: 0
    }, 
    {
      pos: [9, 7, 10], 
      state: 0
    }, 
    {
      pos: [10, 7, 10], 
      state: 0
    }, 
    {
      pos: [11, 7, 10], 
      state: 0
    }, 
    {
      pos: [12, 7, 10], 
      state: 0
    }, 
    {
      pos: [13, 7, 10], 
      state: 0
    }, 
    {
      pos: [16, 7, 10], 
      state: 0
    }, 
    {
      pos: [9, 7, 11], 
      state: 0
    }, 
    {
      pos: [10, 7, 11], 
      state: 0
    }, 
    {
      pos: [11, 7, 11], 
      state: 0
    }, 
    {
      pos: [12, 7, 11], 
      state: 0
    }, 
    {
      pos: [13, 7, 11], 
      state: 0
    }, 
    {
      pos: [16, 7, 11], 
      state: 0
    }, 
    {
      pos: [8, 7, 12], 
      state: 0
    }, 
    {
      pos: [9, 7, 12], 
      state: 0
    }, 
    {
      pos: [10, 7, 12], 
      state: 0
    }, 
    {
      pos: [11, 7, 12], 
      state: 0
    }, 
    {
      pos: [12, 7, 12], 
      state: 0
    }, 
    {
      pos: [13, 7, 12], 
      state: 0
    }, 
    {
      pos: [14, 7, 12], 
      state: 0
    }, 
    {
      pos: [15, 7, 12], 
      state: 0
    }, 
    {
      pos: [16, 7, 12], 
      state: 0
    }, 
    {
      pos: [8, 7, 13], 
      state: 0
    }, 
    {
      pos: [9, 7, 13], 
      state: 0
    }, 
    {
      pos: [10, 7, 13], 
      state: 0
    }, 
    {
      pos: [11, 7, 13], 
      state: 0
    }, 
    {
      pos: [12, 7, 13], 
      state: 0
    }, 
    {
      pos: [13, 7, 13], 
      state: 0
    }, 
    {
      pos: [14, 7, 13], 
      state: 0
    }, 
    {
      pos: [15, 7, 13], 
      state: 0
    }, 
    {
      pos: [16, 7, 13], 
      state: 0
    }, 
    {
      pos: [1, 7, 0], 
      state: 6
    }, 
    {
      pos: [2, 7, 0], 
      state: 6
    }, 
    {
      pos: [3, 7, 0], 
      state: 6
    }, 
    {
      pos: [4, 7, 0], 
      state: 6
    }, 
    {
      pos: [5, 7, 0], 
      state: 6
    }, 
    {
      pos: [6, 7, 0], 
      state: 6
    }, 
    {
      pos: [7, 7, 0], 
      state: 6
    }, 
    {
      pos: [1, 7, 1], 
      state: 6
    }, 
    {
      pos: [2, 7, 1], 
      state: 6
    }, 
    {
      pos: [3, 7, 1], 
      state: 6
    }, 
    {
      pos: [4, 7, 1], 
      state: 6
    }, 
    {
      pos: [5, 7, 1], 
      state: 6
    }, 
    {
      pos: [6, 7, 1], 
      state: 6
    }, 
    {
      pos: [7, 7, 1], 
      state: 6
    }, 
    {
      pos: [1, 7, 2], 
      state: 6
    }, 
    {
      pos: [2, 7, 2], 
      state: 6
    }, 
    {
      pos: [3, 7, 2], 
      state: 6
    }, 
    {
      pos: [4, 7, 2], 
      state: 6
    }, 
    {
      pos: [5, 7, 2], 
      state: 6
    }, 
    {
      pos: [6, 7, 2], 
      state: 6
    }, 
    {
      pos: [7, 7, 2], 
      state: 6
    }, 
    {
      pos: [8, 7, 2], 
      state: 6
    }, 
    {
      pos: [1, 7, 3], 
      state: 6
    }, 
    {
      pos: [2, 7, 3], 
      state: 6
    }, 
    {
      pos: [3, 7, 3], 
      state: 6
    }, 
    {
      pos: [4, 7, 3], 
      state: 6
    }, 
    {
      pos: [5, 7, 3], 
      state: 6
    }, 
    {
      pos: [6, 7, 3], 
      state: 6
    }, 
    {
      pos: [7, 7, 3], 
      state: 6
    }, 
    {
      pos: [8, 7, 3], 
      state: 6
    }, 
    {
      pos: [14, 7, 3], 
      state: 6
    }, 
    {
      pos: [15, 7, 3], 
      state: 6
    }, 
    {
      pos: [1, 7, 4], 
      state: 6
    }, 
    {
      pos: [2, 7, 4], 
      state: 6
    }, 
    {
      pos: [3, 7, 4], 
      state: 6
    }, 
    {
      pos: [4, 7, 4], 
      state: 6
    }, 
    {
      pos: [5, 7, 4], 
      state: 6
    }, 
    {
      pos: [6, 7, 4], 
      state: 6
    }, 
    {
      pos: [7, 7, 4], 
      state: 6
    }, 
    {
      pos: [14, 7, 4], 
      state: 6
    }, 
    {
      pos: [15, 7, 4], 
      state: 6
    }, 
    {
      pos: [1, 7, 5], 
      state: 6
    }, 
    {
      pos: [2, 7, 5], 
      state: 6
    }, 
    {
      pos: [3, 7, 5], 
      state: 6
    }, 
    {
      pos: [4, 7, 5], 
      state: 6
    }, 
    {
      pos: [5, 7, 5], 
      state: 6
    }, 
    {
      pos: [6, 7, 5], 
      state: 6
    }, 
    {
      pos: [7, 7, 5], 
      state: 6
    }, 
    {
      pos: [14, 7, 5], 
      state: 6
    }, 
    {
      pos: [15, 7, 5], 
      state: 6
    }, 
    {
      pos: [2, 7, 6], 
      state: 6
    }, 
    {
      pos: [3, 7, 6], 
      state: 6
    }, 
    {
      pos: [4, 7, 6], 
      state: 6
    }, 
    {
      pos: [5, 7, 6], 
      state: 6
    }, 
    {
      pos: [6, 7, 6], 
      state: 6
    }, 
    {
      pos: [7, 7, 6], 
      state: 6
    }, 
    {
      pos: [8, 7, 6], 
      state: 6
    }, 
    {
      pos: [2, 7, 7], 
      state: 6
    }, 
    {
      pos: [3, 7, 7], 
      state: 6
    }, 
    {
      pos: [4, 7, 7], 
      state: 6
    }, 
    {
      pos: [5, 7, 7], 
      state: 6
    }, 
    {
      pos: [6, 7, 7], 
      state: 6
    }, 
    {
      pos: [7, 7, 7], 
      state: 6
    }, 
    {
      pos: [8, 7, 7], 
      state: 6
    }, 
    {
      pos: [2, 7, 8], 
      state: 6
    }, 
    {
      pos: [3, 7, 8], 
      state: 6
    }, 
    {
      pos: [4, 7, 8], 
      state: 6
    }, 
    {
      pos: [5, 7, 8], 
      state: 6
    }, 
    {
      pos: [6, 7, 8], 
      state: 6
    }, 
    {
      pos: [7, 7, 8], 
      state: 6
    }, 
    {
      pos: [14, 7, 8], 
      state: 6
    }, 
    {
      pos: [15, 7, 8], 
      state: 6
    }, 
    {
      pos: [2, 7, 9], 
      state: 6
    }, 
    {
      pos: [3, 7, 9], 
      state: 6
    }, 
    {
      pos: [4, 7, 9], 
      state: 6
    }, 
    {
      pos: [5, 7, 9], 
      state: 6
    }, 
    {
      pos: [6, 7, 9], 
      state: 6
    }, 
    {
      pos: [7, 7, 9], 
      state: 6
    }, 
    {
      pos: [14, 7, 9], 
      state: 6
    }, 
    {
      pos: [15, 7, 9], 
      state: 6
    }, 
    {
      pos: [2, 7, 10], 
      state: 6
    }, 
    {
      pos: [3, 7, 10], 
      state: 6
    }, 
    {
      pos: [4, 7, 10], 
      state: 6
    }, 
    {
      pos: [5, 7, 10], 
      state: 6
    }, 
    {
      pos: [6, 7, 10], 
      state: 6
    }, 
    {
      pos: [7, 7, 10], 
      state: 6
    }, 
    {
      pos: [8, 7, 10], 
      state: 6
    }, 
    {
      pos: [14, 7, 10], 
      state: 6
    }, 
    {
      pos: [15, 7, 10], 
      state: 6
    }, 
    {
      pos: [1, 7, 11], 
      state: 6
    }, 
    {
      pos: [2, 7, 11], 
      state: 6
    }, 
    {
      pos: [3, 7, 11], 
      state: 6
    }, 
    {
      pos: [4, 7, 11], 
      state: 6
    }, 
    {
      pos: [5, 7, 11], 
      state: 6
    }, 
    {
      pos: [6, 7, 11], 
      state: 6
    }, 
    {
      pos: [7, 7, 11], 
      state: 6
    }, 
    {
      pos: [8, 7, 11], 
      state: 6
    }, 
    {
      pos: [14, 7, 11], 
      state: 6
    }, 
    {
      pos: [15, 7, 11], 
      state: 7
    }, 
    {
      pos: [1, 7, 12], 
      state: 6
    }, 
    {
      pos: [2, 7, 12], 
      state: 6
    }, 
    {
      pos: [3, 7, 12], 
      state: 6
    }, 
    {
      pos: [4, 7, 12], 
      state: 6
    }, 
    {
      pos: [5, 7, 12], 
      state: 6
    }, 
    {
      pos: [6, 7, 12], 
      state: 6
    }, 
    {
      pos: [7, 7, 12], 
      state: 6
    }, 
    {
      pos: [2, 7, 13], 
      state: 6
    }, 
    {
      pos: [3, 7, 13], 
      state: 6
    }, 
    {
      pos: [4, 7, 13], 
      state: 6
    }, 
    {
      pos: [5, 7, 13], 
      state: 6
    }, 
    {
      pos: [6, 7, 13], 
      state: 6
    }, 
    {
      pos: [7, 7, 13], 
      state: 6
    }, 
    {
      pos: [8, 8, 0], 
      state: 0
    }, 
    {
      pos: [9, 8, 0], 
      state: 0
    }, 
    {
      pos: [10, 8, 0], 
      state: 0
    }, 
    {
      pos: [11, 8, 0], 
      state: 0
    }, 
    {
      pos: [12, 8, 0], 
      state: 2
    }, 
    {
      pos: [13, 8, 0], 
      state: 0
    }, 
    {
      pos: [14, 8, 0], 
      state: 9
    }, 
    {
      pos: [15, 8, 0], 
      state: 0
    }, 
    {
      pos: [16, 8, 0], 
      state: 0
    }, 
    {
      pos: [8, 8, 1], 
      state: 0
    }, 
    {
      pos: [9, 8, 1], 
      state: 0
    }, 
    {
      pos: [10, 8, 1], 
      state: 0
    }, 
    {
      pos: [11, 8, 1], 
      state: 0
    }, 
    {
      pos: [12, 8, 1], 
      state: 0
    }, 
    {
      pos: [13, 8, 1], 
      state: 0
    }, 
    {
      pos: [14, 8, 1], 
      state: 0
    }, 
    {
      pos: [15, 8, 1], 
      state: 0
    }, 
    {
      pos: [16, 8, 1], 
      state: 0
    }, 
    {
      pos: [9, 8, 2], 
      state: 0
    }, 
    {
      pos: [10, 8, 2], 
      state: 0
    }, 
    {
      pos: [11, 8, 2], 
      state: 0
    }, 
    {
      pos: [12, 8, 2], 
      state: 0
    }, 
    {
      pos: [13, 8, 2], 
      state: 0
    }, 
    {
      pos: [14, 8, 2], 
      state: 0
    }, 
    {
      pos: [15, 8, 2], 
      state: 0
    }, 
    {
      pos: [16, 8, 2], 
      state: 0
    }, 
    {
      pos: [9, 8, 3], 
      state: 0
    }, 
    {
      pos: [10, 8, 3], 
      state: 0
    }, 
    {
      pos: [11, 8, 3], 
      state: 0
    }, 
    {
      pos: [12, 8, 3], 
      state: 0
    }, 
    {
      pos: [13, 8, 3], 
      state: 0
    }, 
    {
      pos: [14, 8, 3], 
      state: 0
    }, 
    {
      pos: [15, 8, 3], 
      state: 0
    }, 
    {
      pos: [16, 8, 3], 
      state: 0
    }, 
    {
      pos: [8, 8, 4], 
      state: 0
    }, 
    {
      pos: [9, 8, 4], 
      state: 0
    }, 
    {
      pos: [10, 8, 4], 
      state: 0
    }, 
    {
      pos: [11, 8, 4], 
      state: 0
    }, 
    {
      pos: [12, 8, 4], 
      state: 0
    }, 
    {
      pos: [13, 8, 4], 
      state: 0
    }, 
    {
      pos: [16, 8, 4], 
      state: 0
    }, 
    {
      pos: [8, 8, 5], 
      state: 0
    }, 
    {
      pos: [9, 8, 5], 
      state: 0
    }, 
    {
      pos: [10, 8, 5], 
      state: 0
    }, 
    {
      pos: [11, 8, 5], 
      state: 0
    }, 
    {
      pos: [12, 8, 5], 
      state: 0
    }, 
    {
      pos: [13, 8, 5], 
      state: 0
    }, 
    {
      pos: [16, 8, 5], 
      state: 0
    }, 
    {
      pos: [9, 8, 6], 
      state: 0
    }, 
    {
      pos: [10, 8, 6], 
      state: 0
    }, 
    {
      pos: [11, 8, 6], 
      state: 0
    }, 
    {
      pos: [12, 8, 6], 
      state: 0
    }, 
    {
      pos: [13, 8, 6], 
      state: 0
    }, 
    {
      pos: [16, 8, 6], 
      state: 0
    }, 
    {
      pos: [9, 8, 7], 
      state: 0
    }, 
    {
      pos: [10, 8, 7], 
      state: 0
    }, 
    {
      pos: [11, 8, 7], 
      state: 0
    }, 
    {
      pos: [12, 8, 7], 
      state: 0
    }, 
    {
      pos: [13, 8, 7], 
      state: 0
    }, 
    {
      pos: [16, 8, 7], 
      state: 0
    }, 
    {
      pos: [8, 8, 8], 
      state: 0
    }, 
    {
      pos: [9, 8, 8], 
      state: 0
    }, 
    {
      pos: [10, 8, 8], 
      state: 0
    }, 
    {
      pos: [11, 8, 8], 
      state: 0
    }, 
    {
      pos: [12, 8, 8], 
      state: 0
    }, 
    {
      pos: [13, 8, 8], 
      state: 0
    }, 
    {
      pos: [16, 8, 8], 
      state: 0
    }, 
    {
      pos: [8, 8, 9], 
      state: 0
    }, 
    {
      pos: [9, 8, 9], 
      state: 0
    }, 
    {
      pos: [10, 8, 9], 
      state: 0
    }, 
    {
      pos: [11, 8, 9], 
      state: 0
    }, 
    {
      pos: [12, 8, 9], 
      state: 0
    }, 
    {
      pos: [13, 8, 9], 
      state: 0
    }, 
    {
      pos: [16, 8, 9], 
      state: 0
    }, 
    {
      pos: [9, 8, 10], 
      state: 0
    }, 
    {
      pos: [10, 8, 10], 
      state: 0
    }, 
    {
      pos: [11, 8, 10], 
      state: 0
    }, 
    {
      pos: [12, 8, 10], 
      state: 0
    }, 
    {
      pos: [13, 8, 10], 
      state: 0
    }, 
    {
      pos: [14, 8, 10], 
      state: 0
    }, 
    {
      pos: [15, 8, 10], 
      state: 0
    }, 
    {
      pos: [16, 8, 10], 
      state: 0
    }, 
    {
      pos: [9, 8, 11], 
      state: 0
    }, 
    {
      pos: [10, 8, 11], 
      state: 0
    }, 
    {
      pos: [11, 8, 11], 
      state: 0
    }, 
    {
      pos: [12, 8, 11], 
      state: 0
    }, 
    {
      pos: [13, 8, 11], 
      state: 0
    }, 
    {
      pos: [14, 8, 11], 
      state: 0
    }, 
    {
      pos: [15, 8, 11], 
      state: 0
    }, 
    {
      pos: [16, 8, 11], 
      state: 0
    }, 
    {
      pos: [8, 8, 12], 
      state: 0
    }, 
    {
      pos: [9, 8, 12], 
      state: 0
    }, 
    {
      pos: [10, 8, 12], 
      state: 0
    }, 
    {
      pos: [11, 8, 12], 
      state: 0
    }, 
    {
      pos: [12, 8, 12], 
      state: 0
    }, 
    {
      pos: [13, 8, 12], 
      state: 0
    }, 
    {
      pos: [14, 8, 12], 
      state: 0
    }, 
    {
      pos: [15, 8, 12], 
      state: 0
    }, 
    {
      pos: [16, 8, 12], 
      state: 0
    }, 
    {
      pos: [8, 8, 13], 
      state: 0
    }, 
    {
      pos: [9, 8, 13], 
      state: 0
    }, 
    {
      pos: [10, 8, 13], 
      state: 0
    }, 
    {
      pos: [11, 8, 13], 
      state: 0
    }, 
    {
      pos: [12, 8, 13], 
      state: 0
    }, 
    {
      pos: [13, 8, 13], 
      state: 9
    }, 
    {
      pos: [14, 8, 13], 
      state: 9
    }, 
    {
      pos: [15, 8, 13], 
      state: 0
    }, 
    {
      pos: [16, 8, 13], 
      state: 0
    }, 
    {
      pos: [1, 8, 0], 
      state: 6
    }, 
    {
      pos: [2, 8, 0], 
      state: 6
    }, 
    {
      pos: [3, 8, 0], 
      state: 6
    }, 
    {
      pos: [4, 8, 0], 
      state: 6
    }, 
    {
      pos: [5, 8, 0], 
      state: 6
    }, 
    {
      pos: [6, 8, 0], 
      state: 6
    }, 
    {
      pos: [7, 8, 0], 
      state: 6
    }, 
    {
      pos: [1, 8, 1], 
      state: 6
    }, 
    {
      pos: [2, 8, 1], 
      state: 6
    }, 
    {
      pos: [3, 8, 1], 
      state: 6
    }, 
    {
      pos: [4, 8, 1], 
      state: 6
    }, 
    {
      pos: [5, 8, 1], 
      state: 6
    }, 
    {
      pos: [6, 8, 1], 
      state: 6
    }, 
    {
      pos: [7, 8, 1], 
      state: 6
    }, 
    {
      pos: [1, 8, 2], 
      state: 6
    }, 
    {
      pos: [2, 8, 2], 
      state: 6
    }, 
    {
      pos: [3, 8, 2], 
      state: 6
    }, 
    {
      pos: [4, 8, 2], 
      state: 6
    }, 
    {
      pos: [5, 8, 2], 
      state: 6
    }, 
    {
      pos: [6, 8, 2], 
      state: 6
    }, 
    {
      pos: [7, 8, 2], 
      state: 6
    }, 
    {
      pos: [8, 8, 2], 
      state: 6
    }, 
    {
      pos: [1, 8, 3], 
      state: 6
    }, 
    {
      pos: [2, 8, 3], 
      state: 6
    }, 
    {
      pos: [3, 8, 3], 
      state: 6
    }, 
    {
      pos: [4, 8, 3], 
      state: 6
    }, 
    {
      pos: [5, 8, 3], 
      state: 6
    }, 
    {
      pos: [6, 8, 3], 
      state: 6
    }, 
    {
      pos: [7, 8, 3], 
      state: 6
    }, 
    {
      pos: [8, 8, 3], 
      state: 6
    }, 
    {
      pos: [0, 8, 4], 
      state: 6
    }, 
    {
      pos: [1, 8, 4], 
      state: 6
    }, 
    {
      pos: [2, 8, 4], 
      state: 6
    }, 
    {
      pos: [3, 8, 4], 
      state: 6
    }, 
    {
      pos: [4, 8, 4], 
      state: 6
    }, 
    {
      pos: [5, 8, 4], 
      state: 6
    }, 
    {
      pos: [6, 8, 4], 
      state: 6
    }, 
    {
      pos: [7, 8, 4], 
      state: 6
    }, 
    {
      pos: [14, 8, 4], 
      state: 6
    }, 
    {
      pos: [15, 8, 4], 
      state: 6
    }, 
    {
      pos: [0, 8, 5], 
      state: 6
    }, 
    {
      pos: [1, 8, 5], 
      state: 6
    }, 
    {
      pos: [2, 8, 5], 
      state: 6
    }, 
    {
      pos: [3, 8, 5], 
      state: 6
    }, 
    {
      pos: [4, 8, 5], 
      state: 6
    }, 
    {
      pos: [5, 8, 5], 
      state: 6
    }, 
    {
      pos: [6, 8, 5], 
      state: 6
    }, 
    {
      pos: [7, 8, 5], 
      state: 6
    }, 
    {
      pos: [14, 8, 5], 
      state: 6
    }, 
    {
      pos: [15, 8, 5], 
      state: 6
    }, 
    {
      pos: [2, 8, 6], 
      state: 6
    }, 
    {
      pos: [3, 8, 6], 
      state: 6
    }, 
    {
      pos: [4, 8, 6], 
      state: 6
    }, 
    {
      pos: [5, 8, 6], 
      state: 6
    }, 
    {
      pos: [6, 8, 6], 
      state: 6
    }, 
    {
      pos: [7, 8, 6], 
      state: 6
    }, 
    {
      pos: [8, 8, 6], 
      state: 6
    }, 
    {
      pos: [14, 8, 6], 
      state: 6
    }, 
    {
      pos: [15, 8, 6], 
      state: 6
    }, 
    {
      pos: [2, 8, 7], 
      state: 6
    }, 
    {
      pos: [3, 8, 7], 
      state: 6
    }, 
    {
      pos: [4, 8, 7], 
      state: 6
    }, 
    {
      pos: [5, 8, 7], 
      state: 6
    }, 
    {
      pos: [6, 8, 7], 
      state: 6
    }, 
    {
      pos: [7, 8, 7], 
      state: 6
    }, 
    {
      pos: [8, 8, 7], 
      state: 6
    }, 
    {
      pos: [14, 8, 7], 
      state: 6
    }, 
    {
      pos: [15, 8, 7], 
      state: 6
    }, 
    {
      pos: [1, 8, 8], 
      state: 6
    }, 
    {
      pos: [2, 8, 8], 
      state: 6
    }, 
    {
      pos: [3, 8, 8], 
      state: 6
    }, 
    {
      pos: [4, 8, 8], 
      state: 6
    }, 
    {
      pos: [5, 8, 8], 
      state: 6
    }, 
    {
      pos: [6, 8, 8], 
      state: 6
    }, 
    {
      pos: [7, 8, 8], 
      state: 6
    }, 
    {
      pos: [14, 8, 8], 
      state: 6
    }, 
    {
      pos: [15, 8, 8], 
      state: 6
    }, 
    {
      pos: [2, 8, 9], 
      state: 6
    }, 
    {
      pos: [3, 8, 9], 
      state: 6
    }, 
    {
      pos: [4, 8, 9], 
      state: 6
    }, 
    {
      pos: [5, 8, 9], 
      state: 6
    }, 
    {
      pos: [6, 8, 9], 
      state: 6
    }, 
    {
      pos: [7, 8, 9], 
      state: 6
    }, 
    {
      pos: [14, 8, 9], 
      state: 6
    }, 
    {
      pos: [15, 8, 9], 
      state: 6
    }, 
    {
      pos: [2, 8, 10], 
      state: 6
    }, 
    {
      pos: [3, 8, 10], 
      state: 6
    }, 
    {
      pos: [4, 8, 10], 
      state: 6
    }, 
    {
      pos: [5, 8, 10], 
      state: 6
    }, 
    {
      pos: [6, 8, 10], 
      state: 6
    }, 
    {
      pos: [7, 8, 10], 
      state: 6
    }, 
    {
      pos: [8, 8, 10], 
      state: 6
    }, 
    {
      pos: [1, 8, 11], 
      state: 6
    }, 
    {
      pos: [2, 8, 11], 
      state: 6
    }, 
    {
      pos: [3, 8, 11], 
      state: 6
    }, 
    {
      pos: [4, 8, 11], 
      state: 6
    }, 
    {
      pos: [5, 8, 11], 
      state: 6
    }, 
    {
      pos: [6, 8, 11], 
      state: 6
    }, 
    {
      pos: [7, 8, 11], 
      state: 6
    }, 
    {
      pos: [8, 8, 11], 
      state: 6
    }, 
    {
      pos: [1, 8, 12], 
      state: 6
    }, 
    {
      pos: [2, 8, 12], 
      state: 6
    }, 
    {
      pos: [3, 8, 12], 
      state: 6
    }, 
    {
      pos: [4, 8, 12], 
      state: 6
    }, 
    {
      pos: [5, 8, 12], 
      state: 6
    }, 
    {
      pos: [6, 8, 12], 
      state: 6
    }, 
    {
      pos: [7, 8, 12], 
      state: 6
    }, 
    {
      pos: [2, 8, 13], 
      state: 6
    }, 
    {
      pos: [3, 8, 13], 
      state: 6
