{
  size: [8, 5, 7], 
  entities: [], 
  blocks: [
    {
      pos: [0, 0, 0], 
      state: 0
    }, 
    {
      pos: [0, 0, 1], 
      state: 1
    }, 
    {
      pos: [0, 0, 2], 
      state: 0
    }, 
    {
      pos: [0, 0, 3], 
      state: 0
    }, 
    {
      pos: [0, 0, 4], 
      state: 0
    }, 
    {
      pos: [0, 0, 5], 
      state: 0
    }, 
    {
      pos: [0, 0, 6], 
      state: 0
    }, 
    {
      pos: [1, 0, 0], 
      state: 0
    }, 
    {
      pos: [1, 0, 1], 
      state: 1
    }, 
    {
      pos: [1, 0, 2], 
      state: 0
    }, 
    {
      pos: [1, 0, 6], 
      state: 0
    }, 
    {
      pos: [2, 0, 0], 
      state: 0
    }, 
    {
      pos: [2, 0, 1], 
      state: 1
    }, 
    {
      pos: [2, 0, 2], 
      state: 0
    }, 
    {
      pos: [2, 0, 4], 
      state: 0
    }, 
    {
      pos: [2, 0, 6], 
      state: 0
    }, 
    {
      pos: [3, 0, 0], 
      state: 0
    }, 
    {
      pos: [3, 0, 1], 
      state: 1
    }, 
    {
      pos: [3, 0, 2], 
      state: 0
    }, 
    {
      pos: [3, 0, 6], 
      state: 0
    }, 
    {
      pos: [4, 0, 0], 
      state: 0
    }, 
    {
      pos: [4, 0, 1], 
      state: 1
    }, 
    {
      pos: [4, 0, 2], 
      state: 0
    }, 
    {
      pos: [4, 0, 3], 
      state: 0
    }, 
    {
      pos: [4, 0, 4], 
      state: 1
    }, 
    {
      pos: [4, 0, 5], 
      state: 0
    }, 
    {
      pos: [4, 0, 6], 
      state: 0
    }, 
    {
      pos: [5, 0, 0], 
      state: 0
    }, 
    {
      pos: [5, 0, 1], 
      state: 1
    }, 
    {
      pos: [5, 0, 2], 
      state: 1
    }, 
    {
      pos: [5, 0, 4], 
      state: 1
    }, 
    {
      pos: [5, 0, 5], 
      state: 1
    }, 
    {
      pos: [5, 0, 6], 
      state: 0
    }, 
    {
      pos: [6, 0, 0], 
      state: 0
    }, 
    {
      pos: [6, 0, 1], 
      state: 1
    }, 
    {
      pos: [6, 0, 2], 
      state: 1
    }, 
    {
      pos: [6, 0, 3], 
      state: 1
    }, 
    {
      pos: [6, 0, 4], 
      state: 1
    }, 
    {
      pos: [6, 0, 5], 
      state: 1
    }, 
    {
      pos: [6, 0, 6], 
      state: 0
    }, 
    {
      pos: [7, 0, 0], 
      state: 0
    }, 
    {
      pos: [7, 0, 1], 
      state: 0
    }, 
    {
      pos: [7, 0, 2], 
      state: 0
    }, 
    {
      pos: [7, 0, 3], 
      state: 0
    }, 
    {
      pos: [7, 0, 4], 
      state: 0
    }, 
    {
      pos: [7, 0, 5], 
      state: 0
    }, 
    {
      pos: [7, 0, 6], 
      state: 0
    }, 
    {
      pos: [4, 1, 0], 
      state: 1
    }, 
    {
      pos: [4, 1, 2], 
      state: 1
    }, 
    {
      pos: [4, 1, 3], 
      state: 1
    }, 
    {
      pos: [4, 1, 5], 
      state: 1
    }, 
    {
      pos: [4, 1, 6], 
      state: 1
    }, 
    {
      pos: [5, 1, 0], 
      state: 1
    }, 
    {
      pos: [5, 1, 6], 
      state: 1
    }, 
    {
      pos: [6, 1, 0], 
      state: 1
    }, 
    {
      pos: [6, 1, 2], 
      state: 2
    }, 
    {
      pos: [6, 1, 6], 
      state: 1
    }, 
    {
      pos: [7, 1, 0], 
      state: 1
    }, 
    {
      pos: [7, 1, 1], 
      state: 1
    }, 
    {
      pos: [7, 1, 2], 
      state: 1
    }, 
    {
      pos: [7, 1, 3], 
      state: 1
    }, 
    {
      pos: [7, 1, 4], 
      state: 1
    }, 
    {
      pos: [7, 1, 5], 
      state: 1
    }, 
    {
      pos: [7, 1, 6], 
      state: 1
    }, 
    {
      pos: [4, 2, 0], 
      state: 1
    }, 
    {
      pos: [4, 2, 2], 
      state: 1
    }, 
    {
      pos: [4, 2, 3], 
      state: 1
    }, 
    {
      pos: [4, 2, 5], 
      state: 1
    }, 
    {
      pos: [4, 2, 6], 
      state: 1
    }, 
    {
      pos: [7, 2, 0], 
      state: 1
    }, 
    {
      pos: [7, 2, 1], 
      state: 1
    }, 
    {
      pos: [7, 2, 3], 
      state: 1
    }, 
    {
      pos: [7, 2, 5], 
      state: 1
    }, 
    {
      pos: [7, 2, 6], 
      state: 1
    }, 
    {
      pos: [4, 3, 0], 
      state: 1
    }, 
    {
      pos: [4, 3, 1], 
      state: 1
    }, 
    {
      pos: [4, 3, 2], 
      state: 1
    }, 
    {
      pos: [4, 3, 3], 
      state: 1
    }, 
    {
      pos: [4, 3, 4], 
      state: 1
    }, 
    {
      pos: [4, 3, 5], 
      state: 1
    }, 
    {
      pos: [4, 3, 6], 
      state: 1
    }, 
    {
      pos: [5, 3, 0], 
      state: 1
    }, 
    {
      pos: [5, 3, 6], 
      state: 1
    }, 
    {
      pos: [6, 3, 0], 
      state: 1
    }, 
    {
      pos: [6, 3, 6], 
      state: 1
    }, 
    {
      pos: [7, 3, 0], 
      state: 1
    }, 
    {
      pos: [7, 3, 1], 
      state: 1
    }, 
    {
      pos: [7, 3, 2], 
      state: 1
    }, 
    {
      pos: [7, 3, 3], 
      state: 1
    }, 
    {
      pos: [7, 3, 4], 
      state: 1
    }, 
    {
      pos: [7, 3, 5], 
      state: 1
    }, 
    {
      pos: [7, 3, 6], 
      state: 1
    }, 
    {
      pos: [1, 0, 3], 
      state: 3
    }, 
    {
      pos: [3, 0, 5], 
      state: 3
    }, 
    {
      pos: [0, 1, 0], 
      state: 4
    }, 
    {
      pos: [0, 1, 2], 
      state: 5
    }, 
    {
      pos: [0, 1, 3], 
      state: 6
    }, 
    {
      pos: [0, 1, 4], 
      state: 7
    }, 
    {
      pos: [0, 1, 5], 
      state: 6
    }, 
    {
      pos: [0, 1, 6], 
      state: 8
    }, 
    {
      pos: [1, 1, 0], 
      state: 9
    }, 
    {
      pos: [1, 1, 1], 
      state: 3
    }, 
    {
      pos: [1, 1, 2], 
      state: 9
    }, 
    {
      pos: [1, 1, 3], 
      state: 3
    }, 
    {
      pos: [1, 1, 4], 
      state: 3
    }, 
    {
      pos: [1, 1, 5], 
      state: 3
    }, 
    {
      pos: [1, 1, 6], 
      state: 9
    }, 
    {
      pos: [2, 1, 0], 
      state: 10
    }, 
    {
      pos: [2, 1, 1], 
      state: 3
    }, 
    {
      pos: [2, 1, 2], 
      state: 10
    }, 
    {
      pos: [2, 1, 3], 
      state: 3
    }, 
    {
      pos: [2, 1, 4], 
      state: 11
    }, 
    {
      pos: [2, 1, 5], 
      state: 3
    }, 
    {
      pos: [2, 1, 6], 
      state: 10
    }, 
    {
      pos: [3, 1, 0], 
      state: 9
    }, 
    {
      pos: [3, 1, 1], 
      state: 3
    }, 
    {
      pos: [3, 1, 2], 
      state: 9
    }, 
    {
      pos: [3, 1, 3], 
      state: 3
    }, 
    {
      pos: [3, 1, 4], 
      state: 3
    }, 
    {
      pos: [3, 1, 5], 
      state: 3
    }, 
    {
      pos: [3, 1, 6], 
      state: 9
    }, 
    {
      pos: [4, 1, 1], 
      state: 12
    }, 
    {
      pos: [4, 1, 4], 
      state: 13
    }, 
    {
      pos: [5, 1, 1], 
      state: 3
    }, 
    {
      pos: [5, 1, 2], 
      state: 3
    }, 
    {
      pos: [5, 1, 3], 
      state: 3
    }, 
    {
      pos: [5, 1, 4], 
      state: 3
    }, 
    {
      pos: [5, 1, 5], 
      state: 3
    }, 
    {
      pos: [6, 1, 1], 
      state: 14
    }, 
    {
      pos: [6, 1, 3], 
      state: 15
    }, 
    {
      pos: [6, 1, 4], 
      state: 16
    }, 
    {
      pos: [6, 1, 5], 
      state: 17
    }, 
    {
      pos: [0, 2, 0], 
      state: 3
    }, 
    {
      pos: [0, 2, 1], 
      state: 3
    }, 
    {
      pos: [0, 2, 2], 
      state: 3
    }, 
    {
      pos: [0, 2, 3], 
      state: 3
    }, 
    {
      pos: [0, 2, 4], 
      state: 18
    }, 
    {
      pos: [0, 2, 5], 
      state: 3
    }, 
    {
      pos: [0, 2, 6], 
      state: 3
    }, 
    {
      pos: [1, 2, 0], 
      state: 3
    }, 
    {
      pos: [1, 2, 1], 
      state: 3
    }, 
    {
      pos: [1, 2, 2], 
      state: 3
    }, 
    {
      pos: [1, 2, 3], 
      state: 3
    }, 
    {
      pos: [1, 2, 4], 
      state: 3
    }, 
    {
      pos: [1, 2, 5], 
      state: 3
    }, 
    {
      pos: [1, 2, 6], 
      state: 3
    }, 
    {
      pos: [2, 2, 0], 
      state: 19
    }, 
    {
      pos: [2, 2, 1], 
      state: 3
    }, 
    {
      pos: [2, 2, 2], 
      state: 19
    }, 
    {
      pos: [2, 2, 3], 
      state: 3
    }, 
    {
      pos: [2, 2, 4], 
      state: 11
    }, 
    {
      pos: [2, 2, 5], 
      state: 3
    }, 
    {
      pos: [2, 2, 6], 
      state: 18
    }, 
    {
      pos: [3, 2, 0], 
      state: 3
    }, 
    {
      pos: [3, 2, 1], 
      state: 3
    }, 
    {
      pos: [3, 2, 2], 
      state: 3
    }, 
    {
      pos: [3, 2, 3], 
      state: 3
    }, 
    {
      pos: [3, 2, 4], 
      state: 3
    }, 
    {
      pos: [3, 2, 5], 
      state: 3
    }, 
    {
      pos: [3, 2, 6], 
      state: 3
    }, 
    {
      pos: [4, 2, 1], 
      state: 20
    }, 
    {
      pos: [4, 2, 4], 
      state: 21
    }, 
    {
      pos: [5, 2, 0], 
      state: 22
    }, 
    {
      pos: [5, 2, 1], 
      state: 3
    }, 
    {
      pos: [5, 2, 2], 
      state: 3
    }, 
    {
      pos: [5, 2, 3], 
      state: 3
    }, 
    {
      pos: [5, 2, 4], 
      state: 3
    }, 
    {
      pos: [5, 2, 5], 
      state: 3
    }, 
    {
      pos: [5, 2, 6], 
      state: 22
    }, 
    {
      pos: [6, 2, 0], 
      state: 22
    }, 
    {
      pos: [6, 2, 1], 
      state: 3
    }, 
    {
      pos: [6, 2, 2], 
      state: 19
    }, 
    {
      pos: [6, 2, 3], 
      state: 3
    }, 
    {
      pos: [6, 2, 4], 
      state: 3
    }, 
    {
      pos: [6, 2, 5], 
      state: 3
    }, 
    {
      pos: [6, 2, 6], 
      state: 22
    }, 
    {
      pos: [7, 2, 2], 
      state: 22
    }, 
    {
      pos: [7, 2, 4], 
      state: 22
    }, 
    {
      pos: [0, 3, 0], 
      state: 3
    }, 
    {
      pos: [0, 3, 1], 
      state: 3
    }, 
    {
      pos: [0, 3, 2], 
      state: 3
    }, 
    {
      pos: [0, 3, 3], 
      state: 3
    }, 
    {
      pos: [0, 3, 4], 
      state: 3
    }, 
    {
      pos: [0, 3, 5], 
      state: 3
    }, 
    {
      pos: [0, 3, 6], 
      state: 3
    }, 
    {
      pos: [1, 3, 0], 
      state: 3
    }, 
    {
      pos: [1, 3, 1], 
      state: 3
    }, 
    {
      pos: [1, 3, 2], 
      state: 3
    }, 
    {
      pos: [1, 3, 3], 
      state: 3
    }, 
    {
      pos: [1, 3, 4], 
      state: 3
    }, 
    {
      pos: [1, 3, 5], 
      state: 3
    }, 
    {
      pos: [1, 3, 6], 
      state: 3
    }, 
    {
      pos: [2, 3, 0], 
      state: 3
    }, 
    {
      pos: [2, 3, 1], 
      state: 3
    }, 
    {
      pos: [2, 3, 2], 
      state: 3
    }, 
    {
      pos: [2, 3, 3], 
      state: 3
    }, 
    {
      pos: [2, 3, 4], 
      state: 11
    }, 
    {
      pos: [2, 3, 5], 
      state: 3
    }, 
    {
      pos: [2, 3, 6], 
      state: 3
    }, 
    {
      pos: [3, 3, 0], 
      state: 3
    }, 
    {
      pos: [3, 3, 1], 
      state: 3
    }, 
    {
      pos: [3, 3, 2], 
      state: 3
    }, 
    {
      pos: [3, 3, 3], 
      state: 3
    }, 
    {
      pos: [3, 3, 4], 
      state: 3
    }, 
    {
      pos: [3, 3, 5], 
      state: 3
    }, 
    {
      pos: [3, 3, 6], 
      state: 3
    }, 
    {
      pos: [5, 3, 1], 
      state: 23
    }, 
    {
      pos: [5, 3, 2], 
      state: 23
    }, 
    {
      pos: [5, 3, 3], 
      state: 23
    }, 
    {
      pos: [5, 3, 4], 
      state: 23
    }, 
    {
      pos: [5, 3, 5], 
      state: 23
    }, 
    {
      pos: [6, 3, 1], 
      state: 23
    }, 
    {
      pos: [6, 3, 2], 
      state: 23
    }, 
    {
      pos: [6, 3, 3], 
      state: 23
    }, 
    {
      pos: [6, 3, 4], 
      state: 23
    }, 
    {
      pos: [6, 3, 5], 
      state: 23
    }, 
    {
      pos: [0, 4, 0], 
      state: 3
    }, 
    {
      pos: [0, 4, 1], 
      state: 3
    }, 
    {
      pos: [0, 4, 2], 
      state: 3
    }, 
    {
      pos: [0, 4, 3], 
      state: 3
    }, 
    {
      pos: [0, 4, 4], 
      state: 3
    }, 
    {
      pos: [0, 4, 5], 
      state: 3
    }, 
    {
      pos: [0, 4, 6], 
      state: 3
    }, 
    {
      pos: [1, 4, 0], 
      state: 3
    }, 
    {
      pos: [1, 4, 1], 
      state: 3
    }, 
    {
      pos: [1, 4, 2], 
      state: 3
    }, 
    {
      pos: [1, 4, 3], 
      state: 3
    }, 
    {
      pos: [1, 4, 4], 
      state: 3
    }, 
    {
      pos: [1, 4, 5], 
      state: 3
    }, 
    {
      pos: [1, 4, 6], 
      state: 3
    }, 
    {
      pos: [2, 4, 0], 
      state: 3
    }, 
    {
      pos: [2, 4, 1], 
      state: 3
    }, 
    {
      pos: [2, 4, 2], 
      state: 3
    }, 
    {
      pos: [2, 4, 3], 
      state: 3
    }, 
    {
      pos: [2, 4, 4], 
      state: 3
    }, 
    {
      pos: [2, 4, 5], 
      state: 3
    }, 
    {
      pos: [2, 4, 6], 
      state: 3
    }, 
    {
      pos: [3, 4, 0], 
      state: 3
    }, 
    {
      pos: [3, 4, 1], 
      state: 3
    }, 
    {
      pos: [3, 4, 2], 
      state: 3
    }, 
    {
      pos: [3, 4, 3], 
      state: 3
    }, 
    {
      pos: [3, 4, 4], 
      state: 3
    }, 
    {
      pos: [3, 4, 5], 
      state: 3
    }, 
    {
      pos: [3, 4, 6], 
      state: 3
    }, 
    {
      pos: [4, 4, 0], 
      state: 22
    }, 
    {
      pos: [4, 4, 1], 
      state: 3
    }, 
    {
      pos: [4, 4, 2], 
      state: 22
    }, 
    {
      pos: [4, 4, 3], 
      state: 3
    }, 
    {
      pos: [4, 4, 4], 
      state: 22
    }, 
    {
      pos: [4, 4, 5], 
      state: 3
    }, 
    {
      pos: [4, 4, 6], 
      state: 22
    }, 
    {
      pos: [5, 4, 0], 
      state: 3
    }, 
    {
      pos: [5, 4, 1], 
      state: 3
    }, 
    {
      pos: [5, 4, 2], 
      state: 3
    }, 
    {
      pos: [5, 4, 3], 
      state: 3
    }, 
    {
      pos: [5, 4, 4], 
      state: 3
    }, 
    {
      pos: [5, 4, 5], 
      state: 3
    }, 
    {
      pos: [5, 4, 6], 
      state: 3
    }, 
    {
      pos: [6, 4, 0], 
      state: 3
    }, 
    {
      pos: [6, 4, 1], 
      state: 3
    }, 
    {
      pos: [6, 4, 2], 
      state: 3
    }, 
    {
      pos: [6, 4, 3], 
      state: 3
    }, 
    {
      pos: [6, 4, 4], 
      state: 3
    }, 
    {
      pos: [6, 4, 5], 
      state: 3
    }, 
    {
      pos: [6, 4, 6], 
      state: 3
    }, 
    {
      pos: [7, 4, 0], 
      state: 22
    }, 
    {
      pos: [7, 4, 1], 
      state: 3
    }, 
    {
      pos: [7, 4, 2], 
      state: 22
    }, 
    {
      pos: [7, 4, 3], 
      state: 3
    }, 
    {
      pos: [7, 4, 4], 
      state: 22
    }, 
    {
      pos: [7, 4, 5], 
      state: 3
    }, 
    {
      pos: [7, 4, 6], 
      state: 22
    }, 
    {
      nbt: {
        joint: "rollable", 
        final_state: "minecraft:smooth_sandstone", 
        name: "minecraft:bottom", 
        pool: "minecraft:village/desert/villagers", 
        id: "minecraft:jigsaw", 
        target: "minecraft:bottom"
      }, 
      pos: [5, 0, 3], 
      state: 24
    }, 
    {
      nbt: {
        joint: "aligned", 
        final_state: "minecraft:structure_void", 
        name: "minecraft:building_entrance", 
        pool: "minecraft:empty", 
        id: "minecraft:jigsaw", 
        target: "minecraft:building_entrance"
      }, 
      pos: [0, 1, 1], 
      state: 25
    }
  ], 
  palette: [
    {
      Name: "minecraft:sand"
    }, 
    {
      Name: "minecraft:smooth_sandstone"
    }, 
    {
      Name: "minecraft:cut_sandstone"
    }, 
    {
      Name: "minecraft:air"
    }, 
    {
      Properties: {
        east: "low", 
        waterlogged: "false", 
        south: "none", 
        north: "none", 
        west: "none", 
        up: "true"
      }, 
      Name: "minecraft:sandstone_wall"
    }, 
    {
      Properties: {
        east: "low", 
        waterlogged: "false", 
        south: "low", 
        north: "none", 
        west: "none", 
        up: "true"
      }, 
      Name: "minecraft:sandstone_wall"
    }, 
    {
      Properties: {
        east: "none", 
        waterlogged: "false", 
        south: "low", 
        north: "low", 
        west: "none", 
        up: "false"
      }, 
      Name: "minecraft:sandstone_wall"
    }, 
    {
      Properties: {
        east: "none", 
        waterlogged: "false", 
        south: "low", 
        north: "low", 
        west: "none", 
        up: "true"
      }, 
      Name: "minecraft:sandstone_wall"
    }, 
    {
      Properties: {
        east: "low", 
        waterlogged: "false", 
        south: "none", 
        north: "low", 
        west: "none", 
        up: "true"
      }, 
      Name: "minecraft:sandstone_wall"
    }, 
    {
      Properties: {
        east: "low", 
        waterlogged: "false", 
        south: "none", 
        north: "none", 
        west: "low", 
        up: "false"
      }, 
      Name: "minecraft:sandstone_wall"
    }, 
    {
      Properties: {
        east: "low", 
        waterlogged: "false", 
        south: "none", 
        north: "none", 
        west: "low", 
        up: "true"
      }, 
      Name: "minecraft:sandstone_wall"
    }, 
    {
      Properties: {
        age: "0"
      }, 
      Name: "minecraft:cactus"
    }, 
    {
      Properties: {
        hinge: "left", 
        half: "lower", 
        powered: "false", 
        facing: "west", 
        open: "false"
      }, 
      Name: "minecraft:jungle_door"
    }, 
    {
      Properties: {
        hinge: "right", 
        half: "lower", 
        powered: "false", 
        facing: "west", 
        open: "false"
      }, 
      Name: "minecraft:jungle_door"
    }, 
    {
      Properties: {
        half: "bottom", 
        waterlogged: "false", 
        shape: "straight", 
        facing: "north"
      }, 
      Name: "minecraft:smooth_sandstone_stairs"
    }, 
    {
      Properties: {
        half: "bottom", 
        waterlogged: "false", 
        shape: "straight", 
        facing: "south"
      }, 
      Name: "minecraft:smooth_sandstone_stairs"
    }, 
    {
      Properties: {
        part: "foot", 
        facing: "south", 
        occupied: "false"
      }, 
      Name: "minecraft:lime_bed"
    }, 
    {
      Properties: {
        part: "head", 
        facing: "south", 
        occupied: "false"
      }, 
      Name: "minecraft:lime_bed"
    }, 
    {
      Name: "minecraft:potted_dead_bush"
    }, 
    {
      Name: "minecraft:torch"
    }, 
    {
      Properties: {
        hinge: "left", 
        half: "upper", 
        powered: "false", 
        facing: "west", 
        open: "false"
      }, 
      Name: "minecraft:jungle_door"
    }, 
    {
      Properties: {
        hinge: "right", 
        half: "upper", 
        powered: "false", 
        facing: "west", 
        open: "false"
      }, 
      Name: "minecraft:jungle_door"
    }, 
    {
      Properties: {
        waterlogged: "false", 
        type: "bottom"
      }, 
      Name: "minecraft:smooth_sandstone_slab"
    }, 
    {
      Properties: {
        waterlogged: "false", 
        type: "top"
      }, 
      Name: "minecraft:smooth_sandstone_slab"
    }, 
    {
      Properties: {
        orientation: "up_north"
      }, 
      Name: "minecraft:jigsaw"
    }, 
    {
      Properties: {
        orientation: "west_up"
      }, 
      Name: "minecraft:jigsaw"
    }
  ]
}
