{
  size: [22, 3, 18], 
  entities: [], 
  blocks: [
    {
      pos: [3, 0, 1], 
      state: 0
    }, 
    {
      pos: [8, 0, 1], 
      state: 0
    }, 
    {
      pos: [9, 0, 1], 
      state: 0
    }, 
    {
      pos: [2, 0, 2], 
      state: 0
    }, 
    {
      pos: [6, 0, 2], 
      state: 0
    }, 
    {
      pos: [9, 0, 2], 
      state: 0
    }, 
    {
      pos: [11, 0, 2], 
      state: 0
    }, 
    {
      pos: [1, 0, 3], 
      state: 0
    }, 
    {
      pos: [8, 0, 3], 
      state: 0
    }, 
    {
      pos: [10, 0, 3], 
      state: 0
    }, 
    {
      pos: [9, 0, 4], 
      state: 0
    }, 
    {
      pos: [1, 0, 5], 
      state: 0
    }, 
    {
      pos: [3, 0, 5], 
      state: 0
    }, 
    {
      pos: [6, 0, 5], 
      state: 0
    }, 
    {
      pos: [8, 0, 5], 
      state: 0
    }, 
    {
      pos: [1, 0, 6], 
      state: 0
    }, 
    {
      pos: [9, 0, 6], 
      state: 0
    }, 
    {
      nbt: {
        target_pool: "minecraft:village/taiga/villagers", 
        final_state: "minecraft:grass_path", 
        id: "minecraft:jigsaw", 
        attachement_type: "minecraft:bottom"
      }, 
      pos: [7, 0, 2], 
      state: 1
    }, 
    {
      nbt: {
        target_pool: "minecraft:village/common/cats", 
        final_state: "minecraft:grass_block", 
        id: "minecraft:jigsaw", 
        attachement_type: "minecraft:bottom"
      }, 
      pos: [3, 0, 3], 
      state: 1
    }, 
    {
      nbt: {
        target_pool: "minecraft:village/common/cats", 
        final_state: "minecraft:grass_block", 
        id: "minecraft:jigsaw", 
        attachement_type: "minecraft:bottom"
      }, 
      pos: [5, 0, 3], 
      state: 1
    }, 
    {
      nbt: {
        target_pool: "minecraft:village/taiga/villagers", 
        final_state: "minecraft:grass_path", 
        id: "minecraft:jigsaw", 
        attachement_type: "minecraft:bottom"
      }, 
      pos: [2, 0, 4], 
      state: 1
    }, 
    {
      nbt: {
        target_pool: "minecraft:village/common/iron_golem", 
        final_state: "minecraft:grass_path", 
        id: "minecraft:jigsaw", 
        attachement_type: "minecraft:bottom"
      }, 
      pos: [6, 0, 4], 
      state: 1
    }, 
    {
      nbt: {
        target_pool: "minecraft:village/taiga/villagers", 
        final_state: "minecraft:grass_path", 
        id: "minecraft:jigsaw", 
        attachement_type: "minecraft:bottom"
      }, 
      pos: [9, 0, 5], 
      state: 1
    }, 
    {
      pos: [0, 0, 0], 
      state: 2
    }, 
    {
      pos: [1, 0, 0], 
      state: 2
    }, 
    {
      pos: [2, 0, 0], 
      state: 2
    }, 
    {
      pos: [3, 0, 0], 
      state: 2
    }, 
    {
      pos: [4, 0, 0], 
      state: 2
    }, 
    {
      pos: [5, 0, 0], 
      state: 3
    }, 
    {
      pos: [6, 0, 0], 
      state: 3
    }, 
    {
      pos: [7, 0, 0], 
      state: 3
    }, 
    {
      pos: [8, 0, 0], 
      state: 2
    }, 
    {
      pos: [9, 0, 0], 
      state: 2
    }, 
    {
      pos: [10, 0, 0], 
      state: 2
    }, 
    {
      pos: [11, 0, 0], 
      state: 2
    }, 
    {
      pos: [12, 0, 0], 
      state: 2
    }, 
    {
      pos: [13, 0, 0], 
      state: 2
    }, 
    {
      pos: [14, 0, 0], 
      state: 2
    }, 
    {
      pos: [15, 0, 0], 
      state: 2
    }, 
    {
      pos: [16, 0, 0], 
      state: 2
    }, 
    {
      pos: [17, 0, 0], 
      state: 2
    }, 
    {
      pos: [18, 0, 0], 
      state: 2
    }, 
    {
      pos: [19, 0, 0], 
      state: 2
    }, 
    {
      pos: [20, 0, 0], 
      state: 2
    }, 
    {
      pos: [21, 0, 0], 
      state: 2
    }, 
    {
      pos: [0, 0, 1], 
      state: 2
    }, 
    {
      pos: [1, 0, 1], 
      state: 3
    }, 
    {
      pos: [2, 0, 1], 
      state: 3
    }, 
    {
      pos: [4, 0, 1], 
      state: 3
    }, 
    {
      pos: [5, 0, 1], 
      state: 3
    }, 
    {
      pos: [6, 0, 1], 
      state: 3
    }, 
    {
      pos: [7, 0, 1], 
      state: 3
    }, 
    {
      pos: [10, 0, 1], 
      state: 3
    }, 
    {
      pos: [11, 0, 1], 
      state: 3
    }, 
    {
      pos: [12, 0, 1], 
      state: 2
    }, 
    {
      pos: [13, 0, 1], 
      state: 2
    }, 
    {
      pos: [14, 0, 1], 
      state: 2
    }, 
    {
      pos: [15, 0, 1], 
      state: 2
    }, 
    {
      pos: [16, 0, 1], 
      state: 2
    }, 
    {
      pos: [17, 0, 1], 
      state: 2
    }, 
    {
      pos: [18, 0, 1], 
      state: 2
    }, 
    {
      pos: [19, 0, 1], 
      state: 2
    }, 
    {
      pos: [20, 0, 1], 
      state: 2
    }, 
    {
      pos: [21, 0, 1], 
      state: 2
    }, 
    {
      pos: [0, 0, 2], 
      state: 3
    }, 
    {
      pos: [1, 0, 2], 
      state: 3
    }, 
    {
      pos: [3, 0, 2], 
      state: 3
    }, 
    {
      pos: [4, 0, 2], 
      state: 3
    }, 
    {
      pos: [5, 0, 2], 
      state: 3
    }, 
    {
      pos: [8, 0, 2], 
      state: 3
    }, 
    {
      pos: [10, 0, 2], 
      state: 3
    }, 
    {
      pos: [12, 0, 2], 
      state: 2
    }, 
    {
      pos: [13, 0, 2], 
      state: 2
    }, 
    {
      pos: [14, 0, 2], 
      state: 2
    }, 
    {
      pos: [15, 0, 2], 
      state: 2
    }, 
    {
      pos: [16, 0, 2], 
      state: 2
    }, 
    {
      pos: [17, 0, 2], 
      state: 2
    }, 
    {
      pos: [18, 0, 2], 
      state: 2
    }, 
    {
      pos: [19, 0, 2], 
      state: 2
    }, 
    {
      pos: [20, 0, 2], 
      state: 2
    }, 
    {
      pos: [21, 0, 2], 
      state: 2
    }, 
    {
      pos: [0, 0, 3], 
      state: 3
    }, 
    {
      pos: [2, 0, 3], 
      state: 3
    }, 
    {
      pos: [4, 0, 3], 
      state: 3
    }, 
    {
      pos: [6, 0, 3], 
      state: 3
    }, 
    {
      pos: [7, 0, 3], 
      state: 3
    }, 
    {
      pos: [9, 0, 3], 
      state: 3
    }, 
    {
      pos: [11, 0, 3], 
      state: 3
    }, 
    {
      pos: [12, 0, 3], 
      state: 2
    }, 
    {
      pos: [13, 0, 3], 
      state: 2
    }, 
    {
      pos: [14, 0, 3], 
      state: 2
    }, 
    {
      pos: [15, 0, 3], 
      state: 2
    }, 
    {
      pos: [16, 0, 3], 
      state: 2
    }, 
    {
      pos: [17, 0, 3], 
      state: 2
    }, 
    {
      pos: [18, 0, 3], 
      state: 2
    }, 
    {
      pos: [19, 0, 3], 
      state: 2
    }, 
    {
      pos: [20, 0, 3], 
      state: 2
    }, 
    {
      pos: [21, 0, 3], 
      state: 2
    }, 
    {
      pos: [0, 0, 4], 
      state: 3
    }, 
    {
      pos: [1, 0, 4], 
      state: 3
    }, 
    {
      pos: [3, 0, 4], 
      state: 3
    }, 
    {
      pos: [4, 0, 4], 
      state: 3
    }, 
    {
      pos: [5, 0, 4], 
      state: 3
    }, 
    {
      pos: [7, 0, 4], 
      state: 3
    }, 
    {
      pos: [8, 0, 4], 
      state: 3
    }, 
    {
      pos: [10, 0, 4], 
      state: 3
    }, 
    {
      pos: [11, 0, 4], 
      state: 3
    }, 
    {
      pos: [12, 0, 4], 
      state: 2
    }, 
    {
      pos: [13, 0, 4], 
      state: 2
    }, 
    {
      pos: [14, 0, 4], 
      state: 2
    }, 
    {
      pos: [15, 0, 4], 
      state: 2
    }, 
    {
      pos: [16, 0, 4], 
      state: 2
    }, 
    {
      pos: [17, 0, 4], 
      state: 2
    }, 
    {
      pos: [18, 0, 4], 
      state: 2
    }, 
    {
      pos: [19, 0, 4], 
      state: 2
    }, 
    {
      pos: [20, 0, 4], 
      state: 2
    }, 
    {
      pos: [21, 0, 4], 
      state: 2
    }, 
    {
      pos: [0, 0, 5], 
      state: 2
    }, 
    {
      pos: [2, 0, 5], 
      state: 3
    }, 
    {
      pos: [4, 0, 5], 
      state: 3
    }, 
    {
      pos: [5, 0, 5], 
      state: 3
    }, 
    {
      pos: [7, 0, 5], 
      state: 3
    }, 
    {
      pos: [10, 0, 5], 
      state: 3
    }, 
    {
      pos: [11, 0, 5], 
      state: 3
    }, 
    {
      pos: [12, 0, 5], 
      state: 2
    }, 
    {
      pos: [13, 0, 5], 
      state: 2
    }, 
    {
      pos: [14, 0, 5], 
      state: 2
    }, 
    {
      pos: [15, 0, 5], 
      state: 2
    }, 
    {
      pos: [16, 0, 5], 
      state: 2
    }, 
    {
      pos: [17, 0, 5], 
      state: 2
    }, 
    {
      pos: [18, 0, 5], 
      state: 2
    }, 
    {
      pos: [19, 0, 5], 
      state: 2
    }, 
    {
      pos: [20, 0, 5], 
      state: 2
    }, 
    {
      pos: [21, 0, 5], 
      state: 2
    }, 
    {
      pos: [0, 0, 6], 
      state: 2
    }, 
    {
      pos: [2, 0, 6], 
      state: 3
    }, 
    {
      pos: [3, 0, 6], 
      state: 3
    }, 
    {
      pos: [4, 0, 6], 
      state: 3
    }, 
    {
      pos: [5, 0, 6], 
      state: 3
    }, 
    {
      pos: [6, 0, 6], 
      state: 3
    }, 
    {
      pos: [7, 0, 6], 
      state: 3
    }, 
    {
      pos: [8, 0, 6], 
      state: 3
    }, 
    {
      pos: [10, 0, 6], 
      state: 3
    }, 
    {
      pos: [11, 0, 6], 
      state: 3
    }, 
    {
      pos: [12, 0, 6], 
      state: 2
    }, 
    {
      pos: [13, 0, 6], 
      state: 2
    }, 
    {
      pos: [14, 0, 6], 
      state: 2
    }, 
    {
      pos: [15, 0, 6], 
      state: 2
    }, 
    {
      pos: [16, 0, 6], 
      state: 2
    }, 
    {
      pos: [17, 0, 6], 
      state: 2
    }, 
    {
      pos: [18, 0, 6], 
      state: 2
    }, 
    {
      pos: [19, 0, 6], 
      state: 2
    }, 
    {
      pos: [20, 0, 6], 
      state: 2
    }, 
    {
      pos: [21, 0, 6], 
      state: 2
    }, 
    {
      pos: [0, 0, 7], 
      state: 2
    }, 
    {
      pos: [1, 0, 7], 
      state: 2
    }, 
    {
      pos: [2, 0, 7], 
      state: 2
    }, 
    {
      pos: [3, 0, 7], 
      state: 2
    }, 
    {
      pos: [4, 0, 7], 
      state: 2
    }, 
    {
      pos: [5, 0, 7], 
      state: 2
    }, 
    {
      pos: [6, 0, 7], 
      state: 2
    }, 
    {
      pos: [7, 0, 7], 
      state: 2
    }, 
    {
      pos: [8, 0, 7], 
      state: 2
    }, 
    {
      pos: [9, 0, 7], 
      state: 2
    }, 
    {
      pos: [10, 0, 7], 
      state: 2
    }, 
    {
      pos: [11, 0, 7], 
      state: 2
    }, 
    {
      pos: [12, 0, 7], 
      state: 2
    }, 
    {
      pos: [13, 0, 7], 
      state: 2
    }, 
    {
      pos: [14, 0, 7], 
      state: 2
    }, 
    {
      pos: [15, 0, 7], 
      state: 2
    }, 
    {
      pos: [16, 0, 7], 
      state: 2
    }, 
    {
      pos: [17, 0, 7], 
      state: 2
    }, 
    {
      pos: [18, 0, 7], 
      state: 2
    }, 
    {
      pos: [19, 0, 7], 
      state: 2
    }, 
    {
      pos: [20, 0, 7], 
      state: 2
    }, 
    {
      pos: [21, 0, 7], 
      state: 2
    }, 
    {
      pos: [0, 0, 8], 
      state: 2
    }, 
    {
      pos: [1, 0, 8], 
      state: 2
    }, 
    {
      pos: [2, 0, 8], 
      state: 2
    }, 
    {
      pos: [3, 0, 8], 
      state: 2
    }, 
    {
      pos: [4, 0, 8], 
      state: 2
    }, 
    {
      pos: [5, 0, 8], 
      state: 2
    }, 
    {
      pos: [6, 0, 8], 
      state: 2
    }, 
    {
      pos: [7, 0, 8], 
      state: 2
    }, 
    {
      pos: [8, 0, 8], 
      state: 2
    }, 
    {
      pos: [9, 0, 8], 
      state: 2
    }, 
    {
      pos: [10, 0, 8], 
      state: 2
    }, 
    {
      pos: [11, 0, 8], 
      state: 2
    }, 
    {
      pos: [12, 0, 8], 
      state: 2
    }, 
    {
      pos: [13, 0, 8], 
      state: 2
    }, 
    {
      pos: [14, 0, 8], 
      state: 2
    }, 
    {
      pos: [15, 0, 8], 
      state: 2
    }, 
    {
      pos: [16, 0, 8], 
      state: 2
    }, 
    {
      pos: [17, 0, 8], 
      state: 2
    }, 
    {
      pos: [18, 0, 8], 
      state: 2
    }, 
    {
      pos: [19, 0, 8], 
      state: 2
    }, 
    {
      pos: [20, 0, 8], 
      state: 2
    }, 
    {
      pos: [21, 0, 8], 
      state: 2
    }, 
    {
      pos: [0, 0, 9], 
      state: 2
    }, 
    {
      pos: [1, 0, 9], 
      state: 2
    }, 
    {
      pos: [2, 0, 9], 
      state: 2
    }, 
    {
      pos: [3, 0, 9], 
      state: 2
    }, 
    {
      pos: [4, 0, 9], 
      state: 2
    }, 
    {
      pos: [5, 0, 9], 
      state: 2
    }, 
    {
      pos: [6, 0, 9], 
      state: 2
    }, 
    {
      pos: [7, 0, 9], 
      state: 2
    }, 
    {
      pos: [8, 0, 9], 
      state: 2
    }, 
    {
      pos: [9, 0, 9], 
      state: 2
    }, 
    {
      pos: [10, 0, 9], 
      state: 2
    }, 
    {
      pos: [11, 0, 9], 
      state: 2
    }, 
    {
      pos: [12, 0, 9], 
      state: 2
    }, 
    {
      pos: [13, 0, 9], 
      state: 2
    }, 
    {
      pos: [14, 0, 9], 
      state: 2
    }, 
    {
      pos: [15, 0, 9], 
      state: 2
    }, 
    {
      pos: [16, 0, 9], 
      state: 2
    }, 
    {
      pos: [17, 0, 9], 
      state: 2
    }, 
    {
      pos: [18, 0, 9], 
      state: 2
    }, 
    {
      pos: [19, 0, 9], 
      state: 2
    }, 
    {
      pos: [20, 0, 9], 
      state: 2
    }, 
    {
      pos: [21, 0, 9], 
      state: 2
    }, 
    {
      pos: [0, 0, 10], 
      state: 2
    }, 
    {
      pos: [1, 0, 10], 
      state: 2
    }, 
    {
      pos: [2, 0, 10], 
      state: 2
    }, 
    {
      pos: [3, 0, 10], 
      state: 2
    }, 
    {
      pos: [4, 0, 10], 
      state: 2
    }, 
    {
      pos: [5, 0, 10], 
      state: 2
    }, 
    {
      pos: [6, 0, 10], 
      state: 2
    }, 
    {
      pos: [7, 0, 10], 
      state: 2
    }, 
    {
      pos: [8, 0, 10], 
      state: 2
    }, 
    {
      pos: [9, 0, 10], 
      state: 2
    }, 
    {
      pos: [10, 0, 10], 
      state: 2
    }, 
    {
      pos: [11, 0, 10], 
      state: 2
    }, 
    {
      pos: [12, 0, 10], 
      state: 2
    }, 
    {
      pos: [13, 0, 10], 
      state: 2
    }, 
    {
      pos: [14, 0, 10], 
      state: 2
    }, 
    {
      pos: [15, 0, 10], 
      state: 2
    }, 
    {
      pos: [16, 0, 10], 
      state: 2
    }, 
    {
      pos: [17, 0, 10], 
      state: 2
    }, 
    {
      pos: [18, 0, 10], 
      state: 2
    }, 
    {
      pos: [19, 0, 10], 
      state: 2
    }, 
    {
      pos: [20, 0, 10], 
      state: 2
    }, 
    {
      pos: [21, 0, 10], 
      state: 2
    }, 
    {
      pos: [0, 0, 11], 
      state: 2
    }, 
    {
      pos: [1, 0, 11], 
      state: 2
    }, 
    {
      pos: [2, 0, 11], 
      state: 2
    }, 
    {
      pos: [3, 0, 11], 
      state: 2
    }, 
    {
      pos: [4, 0, 11], 
      state: 2
    }, 
    {
      pos: [5, 0, 11], 
      state: 2
    }, 
    {
      pos: [6, 0, 11], 
      state: 2
    }, 
    {
      pos: [7, 0, 11], 
      state: 2
    }, 
    {
      pos: [8, 0, 11], 
      state: 2
    }, 
    {
      pos: [9, 0, 11], 
      state: 2
    }, 
    {
      pos: [10, 0, 11], 
      state: 2
    }, 
    {
      pos: [11, 0, 11], 
      state: 2
    }, 
    {
      pos: [12, 0, 11], 
      state: 2
    }, 
    {
      pos: [13, 0, 11], 
      state: 2
    }, 
    {
      pos: [14, 0, 11], 
      state: 2
    }, 
    {
      pos: [15, 0, 11], 
      state: 2
    }, 
    {
      pos: [16, 0, 11], 
      state: 2
    }, 
    {
      pos: [17, 0, 11], 
      state: 2
    }, 
    {
      pos: [18, 0, 11], 
      state: 2
    }, 
    {
      pos: [19, 0, 11], 
      state: 2
    }, 
    {
      pos: [20, 0, 11], 
      state: 2
    }, 
    {
      pos: [21, 0, 11], 
      state: 2
    }, 
    {
      pos: [0, 0, 12], 
      state: 2
    }, 
    {
      pos: [1, 0, 12], 
      state: 2
    }, 
    {
      pos: [2, 0, 12], 
      state: 2
    }, 
    {
      pos: [3, 0, 12], 
      state: 2
    }, 
    {
      pos: [4, 0, 12], 
      state: 2
    }, 
    {
      pos: [5, 0, 12], 
      state: 2
    }, 
    {
      pos: [6, 0, 12], 
      state: 2
    }, 
    {
      pos: [7, 0, 12], 
      state: 2
    }, 
    {
      pos: [8, 0, 12], 
      state: 2
    }, 
    {
      pos: [9, 0, 12], 
      state: 2
    }, 
    {
      pos: [10, 0, 12], 
      state: 2
    }, 
    {
      pos: [11, 0, 12], 
      state: 2
    }, 
    {
      pos: [12, 0, 12], 
      state: 2
    }, 
    {
      pos: [13, 0, 12], 
      state: 2
    }, 
    {
      pos: [14, 0, 12], 
      state: 2
    }, 
    {
      pos: [15, 0, 12], 
      state: 2
    }, 
    {
      pos: [16, 0, 12], 
      state: 2
    }, 
    {
      pos: [17, 0, 12], 
      state: 2
    }, 
    {
      pos: [18, 0, 12], 
      state: 2
    }, 
    {
      pos: [19, 0, 12], 
      state: 2
    }, 
    {
      pos: [20, 0, 12], 
      state: 2
    }, 
    {
      pos: [21, 0, 12], 
      state: 2
    }, 
    {
      pos: [0, 0, 13], 
      state: 2
    }, 
    {
      pos: [1, 0, 13], 
      state: 2
    }, 
    {
      pos: [2, 0, 13], 
      state: 2
    }, 
    {
      pos: [3, 0, 13], 
      state: 2
    }, 
    {
      pos: [4, 0, 13], 
      state: 2
    }, 
    {
      pos: [5, 0, 13], 
      state: 2
    }, 
    {
      pos: [6, 0, 13], 
      state: 2
    }, 
    {
      pos: [7, 0, 13], 
      state: 2
    }, 
    {
      pos: [8, 0, 13], 
      state: 2
    }, 
    {
      pos: [9, 0, 13], 
      state: 2
    }, 
    {
      pos: [10, 0, 13], 
      state: 2
    }, 
    {
      pos: [11, 0, 13], 
      state: 2
    }, 
    {
      pos: [12, 0, 13], 
      state: 2
    }, 
    {
      pos: [13, 0, 13], 
      state: 2
    }, 
    {
      pos: [14, 0, 13], 
      state: 2
    }, 
    {
      pos: [15, 0, 13], 
      state: 2
    }, 
    {
      pos: [16, 0, 13], 
      state: 2
    }, 
    {
      pos: [17, 0, 13], 
      state: 2
    }, 
    {
      pos: [18, 0, 13], 
      state: 2
    }, 
    {
      pos: [19, 0, 13], 
      state: 2
    }, 
    {
      pos: [20, 0, 13], 
      state: 2
    }, 
    {
      pos: [21, 0, 13], 
      state: 2
    }, 
    {
      pos: [0, 0, 14], 
      state: 2
    }, 
    {
      pos: [1, 0, 14], 
      state: 2
    }, 
    {
      pos: [2, 0, 14], 
      state: 2
    }, 
    {
      pos: [3, 0, 14], 
      state: 2
    }, 
    {
      pos: [4, 0, 14], 
      state: 2
    }, 
    {
      pos: [5, 0, 14], 
      state: 2
    }, 
    {
      pos: [6, 0, 14], 
      state: 2
    }, 
    {
      pos: [7, 0, 14], 
      state: 2
    }, 
    {
      pos: [8, 0, 14], 
      state: 2
    }, 
    {
      pos: [9, 0, 14], 
      state: 2
    }, 
    {
      pos: [10, 0, 14], 
      state: 2
    }, 
    {
      pos: [11, 0, 14], 
      state: 2
    }, 
    {
      pos: [12, 0, 14], 
      state: 2
    }, 
    {
      pos: [13, 0, 14], 
      state: 2
    }, 
    {
      pos: [14, 0, 14], 
      state: 2
    }, 
    {
      pos: [15, 0, 14], 
      state: 2
    }, 
    {
      pos: [16, 0, 14], 
      state: 2
    }, 
    {
      pos: [17, 0, 14], 
      state: 2
    }, 
    {
      pos: [18, 0, 14], 
      state: 2
    }, 
    {
      pos: [19, 0, 14], 
      state: 2
    }, 
    {
      pos: [20, 0, 14], 
      state: 2
    }, 
    {
      pos: [21, 0, 14], 
      state: 2
    }, 
    {
      pos: [0, 0, 15], 
      state: 2
    }, 
    {
      pos: [1, 0, 15], 
      state: 2
    }, 
    {
      pos: [2, 0, 15], 
      state: 2
    }, 
    {
      pos: [3, 0, 15], 
      state: 2
    }, 
    {
      pos: [4, 0, 15], 
      state: 2
    }, 
    {
      pos: [5, 0, 15], 
      state: 2
    }, 
    {
      pos: [6, 0, 15], 
      state: 2
    }, 
    {
      pos: [7, 0, 15], 
      state: 2
    }, 
    {
      pos: [8, 0, 15], 
      state: 2
    }, 
    {
      pos: [9, 0, 15], 
      state: 2
    }, 
    {
      pos: [10, 0, 15], 
      state: 2
    }, 
    {
      pos: [11, 0, 15], 
      state: 2
    }, 
    {
      pos: [12, 0, 15], 
      state: 2
    }, 
    {
      pos: [13, 0, 15], 
      state: 2
    }, 
    {
      pos: [14, 0, 15], 
      state: 2
    }, 
    {
      pos: [15, 0, 15], 
      state: 2
    }, 
    {
      pos: [16, 0, 15], 
      state: 2
    }, 
    {
      pos: [17, 0, 15], 
      state: 2
    }, 
    {
      pos: [18, 0, 15], 
      state: 2
    }, 
    {
      pos: [19, 0, 15], 
      state: 2
    }, 
    {
      pos: [20, 0, 15], 
      state: 2
    }, 
    {
      pos: [21, 0, 15], 
      state: 2
    }, 
    {
      pos: [0, 0, 16], 
      state: 2
    }, 
    {
      pos: [1, 0, 16], 
      state: 2
    }, 
    {
      pos: [2, 0, 16], 
      state: 2
    }, 
    {
      pos: [3, 0, 16], 
      state: 2
    }, 
    {
      pos: [4, 0, 16], 
      state: 2
    }, 
    {
      pos: [5, 0, 16], 
      state: 2
    }, 
    {
      pos: [6, 0, 16], 
      state: 2
    }, 
    {
      pos: [7, 0, 16], 
      state: 2
    }, 
    {
      pos: [8, 0, 16], 
      state: 2
    }, 
    {
      pos: [9, 0, 16], 
      state: 2
    }, 
    {
      pos: [10, 0, 16], 
      state: 2
    }, 
    {
      pos: [11, 0, 16], 
      state: 2
    }, 
    {
      pos: [12, 0, 16], 
      state: 2
    }, 
    {
      pos: [13, 0, 16], 
      state: 2
    }, 
    {
      pos: [14, 0, 16], 
      state: 2
    }, 
    {
      pos: [15, 0, 16], 
      state: 2
    }, 
    {
      pos: [16, 0, 16], 
      state: 2
    }, 
    {
      pos: [17, 0, 16], 
      state: 2
    }, 
    {
      pos: [18, 0, 16], 
      state: 2
    }, 
    {
      pos: [19, 0, 16], 
      state: 2
    }, 
    {
      pos: [20, 0, 16], 
      state: 2
    }, 
    {
      pos: [21, 0, 16], 
      state: 2
    }, 
    {
      pos: [0, 0, 17], 
      state: 2
    }, 
    {
      pos: [1, 0, 17], 
      state: 2
    }, 
    {
      pos: [2, 0, 17], 
      state: 2
    }, 
    {
      pos: [3, 0, 17], 
      state: 2
    }, 
    {
      pos: [4, 0, 17], 
      state: 2
    }, 
    {
      pos: [5, 0, 17], 
      state: 2
    }, 
    {
      pos: [6, 0, 17], 
      state: 2
    }, 
    {
      pos: [7, 0, 17], 
      state: 2
    }, 
    {
      pos: [8, 0, 17], 
      state: 2
    }, 
    {
      pos: [9, 0, 17], 
      state: 2
    }, 
    {
      pos: [10, 0, 17], 
      state: 2
    }, 
    {
      pos: [11, 0, 17], 
      state: 2
    }, 
    {
      pos: [12, 0, 17], 
      state: 2
    }, 
    {
      pos: [13, 0, 17], 
      state: 2
    }, 
    {
      pos: [14, 0, 17], 
      state: 2
    }, 
    {
      pos: [15, 0, 17], 
      state: 2
    }, 
    {
      pos: [16, 0, 17], 
      state: 2
    }, 
    {
      pos: [17, 0, 17], 
      state: 2
    }, 
    {
      pos: [18, 0, 17], 
      state: 2
    }, 
    {
      pos: [19, 0, 17], 
      state: 2
    }, 
    {
      pos: [20, 0, 17], 
      state: 2
    }, 
    {
      pos: [21, 0, 17], 
      state: 2
    }, 
    {
      pos: [9, 1, 3], 
      state: 4
    }, 
    {
      nbt: {
        target_pool: "minecraft:village/taiga/streets", 
        final_state: "minecraft:structure_void", 
        id: "minecraft:jigsaw", 
        attachement_type: "minecraft:street"
      }, 
      pos: [6, 1, 0], 
      state: 5
    }, 
    {
      nbt: {
        target_pool: "minecraft:village/taiga/streets", 
        final_state: "minecraft:structure_void", 
        id: "minecraft:jigsaw", 
        attachement_type: "minecraft:street"
      }, 
      pos: [0, 1, 3], 
      state: 6
    }, 
    {
      nbt: {
        target_pool: "minecraft:village/taiga/houses", 
        final_state: "minecraft:structure_void", 
        id: "minecraft:jigsaw", 
        attachement_type: "minecraft:building_entrance"
      }, 
      pos: [11, 1, 3], 
      state: 7
    }, 
    {
      nbt: {
        target_pool: "minecraft:village/taiga/houses", 
        final_state: "minecraft:structure_void", 
        id: "minecraft:jigsaw", 
        attachement_type: "minecraft:building_entrance"
      }, 
      pos: [11, 1, 4], 
      state: 7
    }, 
    {
      nbt: {
        target_pool: "minecraft:village/taiga/houses", 
        final_state: "minecraft:structure_void", 
        id: "minecraft:jigsaw", 
        attachement_type: "minecraft:building_entrance"
      }, 
      pos: [11, 1, 5], 
      state: 7
    }, 
    {
      nbt: {
        target_pool: "minecraft:village/taiga/houses", 
        final_state: "minecraft:structure_void", 
        id: "minecraft:jigsaw", 
        attachement_type: "minecraft:building_entrance"
      }, 
      pos: [2, 1, 6], 
      state: 8
    }, 
    {
      nbt: {
        target_pool: "minecraft:village/taiga/houses", 
        final_state: "minecraft:structure_void", 
        id: "minecraft:jigsaw", 
        attachement_type: "minecraft:building_entrance"
      }, 
      pos: [3, 1, 6], 
      state: 8
    }, 
    {
      nbt: {
        target_pool: "minecraft:village/taiga/houses", 
        final_state: "minecraft:structure_void", 
        id: "minecraft:jigsaw", 
        attachement_type: "minecraft:building_entrance"
      }, 
      pos: [4, 1, 6], 
      state: 8
    }, 
    {
      nbt: {
        target_pool: "minecraft:village/taiga/houses", 
        final_state: "minecraft:structure_void", 
        id: "minecraft:jigsaw", 
        attachement_type: "minecraft:building_entrance"
      }, 
      pos: [5, 1, 6], 
      state: 8
    }, 
    {
      nbt: {
        target_pool: "minecraft:village/taiga/houses", 
        final_state: "minecraft:structure_void", 
        id: "minecraft:jigsaw", 
        attachement_type: "minecraft:building_entrance"
      }, 
      pos: [6, 1, 6], 
      state: 8
    }, 
    {
      nbt: {
        target_pool: "minecraft:village/taiga/houses", 
        final_state: "minecraft:structure_void", 
        id: "minecraft:jigsaw", 
        attachement_type: "minecraft:building_entrance"
      }, 
      pos: [7, 1, 6], 
      state: 8
    }, 
    {
      nbt: {
        target_pool: "minecraft:village/taiga/houses", 
        final_state: "minecraft:structure_void", 
        id: "minecraft:jigsaw", 
        attachement_type: "minecraft:building_entrance"
      }, 
      pos: [11, 1, 6], 
      state: 7
    }, 
    {
      pos: [0, 1, 0], 
      state: 2
    }, 
    {
      pos: [1, 1, 0], 
      state: 2
    }, 
    {
      pos: [2, 1, 0], 
      state: 2
    }, 
    {
      pos: [3, 1, 0], 
      state: 2
    }, 
    {
      pos: [4, 1, 0], 
      state: 2
    }, 
    {
      pos: [5, 1, 0], 
      state: 2
    }, 
    {
      pos: [7, 1, 0], 
      state: 2
    }, 
    {
      pos: [8, 1, 0], 
      state: 2
    }, 
    {
      pos: [9, 1, 0], 
      state: 2
    }, 
    {
      pos: [10, 1, 0], 
      state: 2
    }, 
    {
      pos: [11, 1, 0], 
      state: 2
    }, 
    {
      pos: [12, 1, 0], 
      state: 2
    }, 
    {
      pos: [13, 1, 0], 
      state: 2
    }, 
    {
      pos: [14, 1, 0], 
      state: 2
    }, 
    {
      pos: [15, 1, 0], 
      state: 2
    }, 
    {
      pos: [16, 1, 0], 
      state: 2
    }, 
    {
      pos: [17, 1, 0], 
      state: 2
    }, 
    {
      pos: [18, 1, 0], 
      state: 2
    }, 
    {
      pos: [19, 1, 0], 
      state: 2
    }, 
    {
      pos: [20, 1, 0], 
      state: 2
    }, 
    {
      pos: [21, 1, 0], 
      state: 2
    }, 
    {
      pos: [0, 1, 1], 
      state: 2
    }, 
    {
      pos: [1, 1, 1], 
      state: 2
    }, 
    {
      pos: [2, 1, 1], 
      state: 2
    }, 
    {
      pos: [3, 1, 1], 
      state: 2
    }, 
    {
      pos: [4, 1, 1], 
      state: 2
    }, 
    {
      pos: [5, 1, 1], 
      state: 2
    }, 
    {
      pos: [6, 1, 1], 
      state: 2
    }, 
    {
      pos: [7, 1, 1], 
      state: 2
    }, 
    {
      pos: [8, 1, 1], 
      state: 2
    }, 
    {
      pos: [9, 1, 1], 
      state: 2
    }, 
    {
      pos: [10, 1, 1], 
      state: 2
    }, 
    {
      pos: [11, 1, 1], 
      state: 2
    }, 
    {
      pos: [12, 1, 1], 
      state: 2
    }, 
    {
      pos: [13, 1, 1], 
      state: 2
    }, 
    {
      pos: [14, 1, 1], 
      state: 2
    }, 
    {
      pos: [15, 1, 1], 
      state: 2
    }, 
    {
      pos: [16, 1, 1], 
      state: 2
    }, 
    {
      pos: [17, 1, 1], 
      state: 2
    }, 
    {
      pos: [18, 1, 1], 
      state: 2
    }, 
    {
      pos: [19, 1, 1], 
      state: 2
    }, 
    {
      pos: [20, 1, 1], 
      state: 2
    }, 
    {
      pos: [21, 1, 1], 
      state: 2
    }, 
    {
      pos: [0, 1, 2], 
      state: 2
    }, 
    {
      pos: [1, 1, 2], 
      state: 2
    }, 
    {
      pos: [2, 1, 2], 
      state: 2
    }, 
    {
      pos: [3, 1, 2], 
      state: 2
    }, 
    {
      pos: [4, 1, 2], 
      state: 2
    }, 
    {
      pos: [5, 1, 2], 
      state: 2
    }, 
    {
      pos: [6, 1, 2], 
      state: 2
    }, 
    {
      pos: [7, 1, 2], 
      state: 2
    }, 
    {
      pos: [8, 1, 2], 
      state: 2
    }, 
    {
      pos: [9, 1, 2], 
      state: 9
    }, 
    {
      pos: [10, 1, 2], 
      state: 2
    }, 
    {
      pos: [11, 1, 2], 
      state: 2
    }, 
    {
      pos: [12, 1, 2], 
      state: 2
    }, 
    {
      pos: [13, 1, 2], 
      state: 2
    }, 
    {
      pos: [14, 1, 2], 
      state: 2
    }, 
    {
      pos: [15, 1, 2], 
      state: 2
    }, 
    {
      pos: [16, 1, 2], 
      state: 2
    }, 
    {
      pos: [17, 1, 2], 
      state: 2
    }, 
    {
      pos: [18, 1, 2], 
      state: 2
    }, 
    {
      pos: [19, 1, 2], 
      state: 2
    }, 
    {
      pos: [20, 1, 2], 
      state: 2
    }, 
    {
      pos: [21, 1, 2], 
      state: 2
    }, 
    {
      pos: [1, 1, 3], 
      state: 2
    }, 
    {
      pos: [2, 1, 3], 
      state: 2
    }, 
    {
      pos: [3, 1, 3], 
      state: 2
    }, 
    {
      pos: [4, 1, 3], 
      state: 2
    }, 
    {
      pos: [5, 1, 3], 
      state: 2
    }, 
    {
      pos: [6, 1, 3], 
      state: 2
    }, 
    {
      pos: [7, 1, 3], 
      state: 2
    }, 
    {
      pos: [8, 1, 3], 
      state: 10
    }, 
    {
      pos: [10, 1, 3], 
      state: 11
    }, 
    {
      pos: [12, 1, 3], 
      state: 2
    }, 
    {
      pos: [13, 1, 3], 
      state: 2
    }, 
    {
      pos: [14, 1, 3], 
      state: 2
    }, 
    {
      pos: [15, 1, 3], 
      state: 2
    }, 
    {
      pos: [16, 1, 3], 
      state: 2
    }, 
    {
      pos: [17, 1, 3], 
      state: 2
    }, 
    {
      pos: [18, 1, 3], 
      state: 2
    }, 
    {
      pos: [19, 1, 3], 
      state: 2
    }, 
    {
      pos: [20, 1, 3], 
      state: 2
    }, 
    {
      pos: [21, 1, 3], 
      state: 2
    }, 
    {
      pos: [0, 1, 4], 
      state: 2
    }, 
    {
      pos: [1, 1, 4], 
      state: 2
    }, 
    {
      pos: [2, 1, 4], 
      state: 2
    }, 
    {
      pos: [3, 1, 4], 
      state: 2
    }, 
    {
      pos: [4, 1, 4], 
      state: 2
    }, 
    {
      pos: [5, 1, 4], 
      state: 2
    }, 
    {
      pos: [6, 1, 4], 
      state: 2
    }, 
    {
      pos: [7, 1, 4], 
      state: 2
    }, 
    {
      pos: [8, 1, 4], 
      state: 2
    }, 
    {
      pos: [9, 1, 4], 
      state: 12
    }, 
    {
      pos: [10, 1, 4], 
      state: 2
    }, 
    {
      pos: [12, 1, 4], 
      state: 2
    }, 
    {
      pos: [13, 1, 4], 
      state: 2
    }, 
    {
      pos: [14, 1, 4], 
      state: 2
    }, 
    {
      pos: [15, 1, 4], 
      state: 2
    }, 
    {
      pos: [16, 1, 4], 
      state: 2
    }, 
    {
      pos: [17, 1, 4], 
      state: 2
    }, 
    {
      pos: [18, 1, 4], 
      state: 2
    }, 
    {
      pos: [19, 1, 4], 
      state: 2
    }, 
    {
      pos: [20, 1, 4], 
      state: 2
    }, 
    {
      pos: [21, 1, 4], 
      state: 2
    }, 
    {
      pos: [0, 1, 5], 
      state: 2
    }, 
    {
      pos: [1, 1, 5], 
      state: 2
    }, 
    {
      pos: [2, 1, 5], 
      state: 2
    }, 
    {
      pos: [3, 1, 5], 
      state: 2
    }, 
    {
      pos: [4, 1, 5], 
      state: 2
    }, 
    {
      pos: [5, 1, 5], 
      state: 2
    }, 
    {
      pos: [6, 1, 5], 
      state: 2
    }, 
    {
      pos: [7, 1, 5], 
      state: 2
    }, 
    {
      pos: [8, 1, 5], 
      state: 2
    }, 
    {
      pos: [9, 1, 5], 
      state: 2
    }, 
    {
      pos: [10, 1, 5], 
      state: 2
    }, 
    {
      pos: [12, 1, 5], 
      state: 2
    }, 
    {
      pos: [13, 1, 5], 
      state: 2
    }, 
    {
      pos: [14, 1, 5], 
      state: 2
    }, 
    {
      pos: [15, 1, 5], 
      state: 2
    }, 
    {
      pos: [16, 1, 5], 
      state: 2
    }, 
    {
      pos: [17, 1, 5], 
      state: 2
    }, 
    {
      pos: [18, 1, 5], 
      state: 2
    }, 
    {
      pos: [19, 1, 5], 
      state: 2
    }, 
    {
      pos: [20, 1, 5], 
      state: 2
    }, 
    {
      pos: [21, 1, 5], 
      state: 2
    }, 
    {
      pos: [0, 1, 6], 
      state: 2
    }, 
    {
      pos: [1, 1, 6], 
      state: 2
    }, 
    {
      pos: [8, 1, 6], 
      state: 2
    }, 
    {
      pos: [9, 1, 6], 
      state: 2
    }, 
    {
      pos: [10, 1, 6], 
      state: 2
    }, 
    {
      pos: [12, 1, 6], 
      state: 2
    }, 
    {
      pos: [13, 1, 6], 
      state: 2
    }, 
    {
      pos: [14, 1, 6], 
      state: 2
    }, 
    {
      pos: [15, 1, 6], 
      state: 2
    }, 
    {
      pos: [16, 1, 6], 
      state: 2
    }, 
    {
      pos: [17, 1, 6], 
      state: 2
    }, 
    {
      pos: [18, 1, 6], 
      state: 2
    }, 
    {
      pos: [19, 1, 6], 
      state: 2
    }, 
    {
      pos: [20, 1, 6], 
      state: 2
    }, 
    {
      pos: [21, 1, 6], 
      state: 2
    }, 
    {
      pos: [0, 1, 7], 
      state: 2
    }, 
    {
      pos: [1, 1, 7], 
      state: 2
    }, 
    {
      pos: [2, 1, 7], 
      state: 2
    }, 
    {
      pos: [3, 1, 7], 
      state: 2
    }, 
    {
      pos: [4, 1, 7], 
      state: 2
    }, 
    {
      pos: [5, 1, 7], 
      state: 2
    }, 
    {
      pos: [6, 1, 7], 
      state: 2
    }, 
    {
      pos: [7, 1, 7], 
      state: 2
    }, 
    {
      pos: [8, 1, 7], 
      state: 2
    }, 
    {
      pos: [9, 1, 7], 
      state: 2
    }, 
    {
      pos: [10, 1, 7], 
      state: 2
    }, 
    {
      pos: [11, 1, 7], 
      state: 2
    }, 
    {
      pos: [12, 1, 7], 
      state: 2
    }, 
    {
      pos: [13, 1, 7], 
      state: 2
    }, 
    {
      pos: [14, 1, 7], 
      state: 2
    }, 
    {
      pos: [15, 1, 7], 
      state: 2
    }, 
    {
      pos: [16, 1, 7], 
      state: 2
    }, 
    {
      pos: [17, 1, 7], 
      state: 2
    }, 
    {
      pos: [18, 1, 7], 
      state: 2
    }, 
    {
      pos: [19, 1, 7], 
      state: 2
    }, 
    {
      pos: [20, 1, 7], 
      state: 2
    }, 
    {
      pos: [21, 1, 7], 
      state: 2
    }, 
    {
      pos: [0, 1, 8], 
      state: 2
    }, 
    {
      pos: [1, 1, 8], 
      state: 2
    }, 
    {
      pos: [2, 1, 8], 
      state: 2
    }, 
    {
      pos: [3, 1, 8], 
      state: 2
    }, 
    {
      pos: [4, 1, 8], 
      state: 2
    }, 
    {
      pos: [5, 1, 8], 
      state: 2
    }, 
    {
      pos: [6, 1, 8], 
      state: 2
    }, 
    {
      pos: [7, 1, 8], 
      state: 2
    }, 
    {
      pos: [8, 1, 8], 
      state: 2
    }, 
    {
      pos: [9, 1, 8], 
      state: 2
    }, 
    {
      pos: [10, 1, 8], 
      state: 2
    }, 
    {
      pos: [11, 1, 8], 
      state: 2
    }, 
    {
      pos: [12, 1, 8], 
      state: 2
    }, 
    {
      pos: [13, 1, 8], 
      state: 2
    }, 
    {
      pos: [14, 1, 8], 
      state: 2
    }, 
    {
      pos: [15, 1, 8], 
      state: 2
    }, 
    {
      pos: [16, 1, 8], 
      state: 2
    }, 
    {
      pos: [17, 1, 8], 
      state: 2
    }, 
    {
      pos: [18, 1, 8], 
      state: 2
    }, 
    {
      pos: [19, 1, 8], 
      state: 2
    }, 
    {
      pos: [20, 1, 8], 
      state: 2
    }, 
    {
      pos: [21, 1, 8], 
      state: 2
    }, 
    {
      pos: [0, 1, 9], 
      state: 2
    }, 
    {
      pos: [1, 1, 9], 
      state: 2
    }, 
    {
      pos: [2, 1, 9], 
      state: 2
    }, 
    {
      pos: [3, 1, 9], 
      state: 2
    }, 
    {
      pos: [4, 1, 9], 
      state: 2
    }, 
    {
      pos: [5, 1, 9], 
      state: 2
    }, 
    {
      pos: [6, 1, 9], 
      state: 2
    }, 
    {
      pos: [7, 1, 9], 
      state: 2
    }, 
    {
      pos: [8, 1, 9], 
      state: 2
    }, 
    {
      pos: [9, 1, 9], 
      state: 2
    }, 
    {
      pos: [10, 1, 9], 
      state: 2
    }, 
    {
      pos: [11, 1, 9], 
      state: 2
    }, 
    {
      pos: [12, 1, 9], 
      state: 2
    }, 
    {
      pos: [13, 1, 9], 
      state: 2
    }, 
    {
      pos: [14, 1, 9], 
      state: 2
    }, 
    {
      pos: [15, 1, 9], 
      state: 2
    }, 
    {
      pos: [16, 1, 9], 
      state: 2
    }, 
    {
      pos: [17, 1, 9], 
      state: 2
    }, 
    {
      pos: [18, 1, 9], 
      state: 2
    }, 
    {
      pos: [19, 1, 9], 
      state: 2
    }, 
    {
      pos: [20, 1, 9], 
      state: 2
    }, 
    {
      pos: [21, 1, 9], 
      state: 2
    }, 
    {
      pos: [0, 1, 10], 
      state: 2
    }, 
    {
      pos: [1, 1, 10], 
      state: 2
    }, 
    {
      pos: [2, 1, 10], 
      state: 2
    }, 
    {
      pos: [3, 1, 10], 
      state: 2
    }, 
    {
      pos: [4, 1, 10], 
      state: 2
    }, 
    {
      pos: [5, 1, 10], 
      state: 2
    }, 
    {
      pos: [6, 1, 10], 
      state: 2
    }, 
    {
      pos: [7, 1, 10], 
      state: 2
    }, 
    {
      pos: [8, 1, 10], 
      state: 2
    }, 
    {
      pos: [9, 1, 10], 
      state: 2
    }, 
    {
      pos: [10, 1, 10], 
      state: 2
    }, 
    {
      pos: [11, 1, 10], 
      state: 2
    }, 
    {
      pos: [12, 1, 10], 
      state: 2
    }, 
    {
      pos: [13, 1, 10], 
      state: 2
    }, 
    {
      pos: [14, 1, 10], 
      state: 2
    }, 
    {
      pos: [15, 1, 10], 
      state: 2
    }, 
    {
      pos: [16, 1, 10], 
      state: 2
    }, 
    {
      pos: [17, 1, 10], 
      state: 2
    }, 
    {
      pos: [18, 1, 10], 
      state: 2
    }, 
    {
      pos: [19, 1, 10], 
      state: 2
    }, 
    {
      pos: [20, 1, 10], 
      state: 2
    }, 
    {
      pos: [21, 1, 10], 
      state: 2
    }, 
    {
      pos: [0, 1, 11], 
      state: 2
    }, 
    {
      pos: [1, 1, 11], 
      state: 2
    }, 
    {
      pos: [2, 1, 11], 
      state: 2
    }, 
    {
      pos: [3, 1, 11], 
      state: 2
    }, 
    {
      pos: [4, 1, 11], 
      state: 2
    }, 
    {
      pos: [5, 1, 11], 
      state: 2
    }, 
    {
      pos: [6, 1, 11], 
      state: 2
    }, 
    {
      pos: [7, 1, 11], 
      state: 2
    }, 
    {
      pos: [8, 1, 11], 
      state: 2
    }, 
    {
      pos: [9, 1, 11], 
      state: 2
    }, 
    {
      pos: [10, 1, 11], 
      state: 2
    }, 
    {
      pos: [11, 1, 11], 
      state: 2
    }, 
    {
      pos: [12, 1, 11], 
      state: 2
    }, 
    {
      pos: [13, 1, 11], 
      state: 2
    }, 
    {
      pos: [14, 1, 11], 
      state: 2
    }, 
    {
      pos: [15, 1, 11], 
      state: 2
    }, 
    {
      pos: [16, 1, 11], 
      state: 2
    }, 
    {
      pos: [17, 1, 11], 
      state: 2
    }, 
    {
      pos: [18, 1, 11], 
      state: 2
    }, 
    {
      pos: [19, 1, 11], 
      state: 2
    }, 
    {
      pos: [20, 1, 11], 
      state: 2
    }, 
    {
      pos: [21, 1, 11], 
      state: 2
    }, 
    {
      pos: [0, 1, 12], 
      state: 2
    }, 
    {
      pos: [1, 1, 12], 
      state: 2
    }, 
    {
      pos: [2, 1, 12], 
      state: 2
    }, 
    {
      pos: [3, 1, 12], 
      state: 2
    }, 
    {
      pos: [4, 1, 12], 
      state: 2
    }, 
    {
      pos: [5, 1, 12], 
      state: 2
    }, 
    {
      pos: [6, 1, 12], 
      state: 2
    }, 
    {
      pos: [7, 1, 12], 
      state: 2
    }, 
    {
      pos: [8, 1, 12], 
      state: 2
    }, 
    {
      pos: [9, 1, 12], 
      state: 2
    }, 
    {
      pos: [10, 1, 12], 
      state: 2
    }, 
    {
      pos: [11, 1, 12], 
      state: 2
    }, 
    {
      pos: [12, 1, 12], 
      state: 2
    }, 
    {
      pos: [13, 1, 12], 
      state: 2
    }, 
    {
      pos: [14, 1, 12], 
      state: 2
    }, 
    {
      pos: [15, 1, 12], 
      state: 2
    }, 
    {
      pos: [16, 1, 12], 
      state: 2
    }, 
    {
      pos: [17, 1, 12], 
      state: 2
    }, 
    {
      pos: [18, 1, 12], 
      state: 2
    }, 
    {
      pos: [19, 1, 12], 
      state: 2
    }, 
    {
      pos: [20, 1, 12], 
      state: 2
    }, 
    {
      pos: [21, 1, 12], 
      state: 2
    }, 
    {
      pos: [0, 1, 13], 
      state: 2
    }, 
    {
      pos: [1, 1, 13], 
      state: 2
    }, 
    {
      pos: [2, 1, 13], 
      state: 2
    }, 
    {
      pos: [3, 1, 13], 
      state: 2
    }, 
    {
      pos: [4, 1, 13], 
      state: 2
    }, 
    {
      pos: [5, 1, 13], 
      state: 2
    }, 
    {
      pos: [6, 1, 13], 
      state: 2
    }, 
    {
      pos: [7, 1, 13], 
      state: 2
    }, 
    {
      pos: [8, 1, 13], 
      state: 2
    }, 
    {
      pos: [9, 1, 13], 
      state: 2
    }, 
    {
      pos: [10, 1, 13], 
      state: 2
    }, 
    {
      pos: [11, 1, 13], 
      state: 2
    }, 
    {
      pos: [12, 1, 13], 
      state: 2
    }, 
    {
      pos: [13, 1, 13], 
      state: 2
    }, 
    {
      pos: [14, 1, 13], 
      state: 2
    }, 
    {
      pos: [15, 1, 13], 
      state: 2
    }, 
    {
      pos: [16, 1, 13], 
      state: 2
    }, 
    {
      pos: [17, 1, 13], 
      state: 2
    }, 
    {
      pos: [18, 1, 13], 
      state: 2
    }, 
    {
      pos: [19, 1, 13], 
      state: 2
    }, 
    {
      pos: [20, 1, 13], 
      state: 2
    }, 
    {
      pos: [21, 1, 13], 
      state: 2
    }, 
    {
      pos: [0, 1, 14], 
      state: 2
    }, 
    {
      pos: [1, 1, 14], 
      state: 2
    }, 
    {
      pos: [2, 1, 14], 
      state: 2
    }, 
    {
      pos: [3, 1, 14], 
      state: 2
    }, 
    {
      pos: [4, 1, 14], 
      state: 2
    }, 
    {
      pos: [5, 1, 14], 
      state: 2
    }, 
    {
      pos: [6, 1, 14], 
      state: 2
    }, 
    {
      pos: [7, 1, 14], 
      state: 2
    }, 
    {
      pos: [8, 1, 14], 
      state: 2
    }, 
    {
      pos: [9, 1, 14], 
      state: 2
    }, 
    {
      pos: [10, 1, 14], 
      state: 2
    }, 
    {
      pos: [11, 1, 14], 
      state: 2
    }, 
    {
      pos: [12, 1, 14], 
      state: 2
    }, 
    {
      pos: [13, 1, 14], 
      state: 2
    }, 
    {
      pos: [14, 1, 14], 
      state: 2
    }, 
    {
      pos: [15, 1, 14], 
      state: 2
    }, 
    {
      pos: [16, 1, 14], 
      state: 2
    }, 
    {
      pos: [17, 1, 14], 
      state: 2
    }, 
    {
      pos: [18, 1, 14], 
      state: 2
    }, 
    {
      pos: [19, 1, 14], 
      state: 2
    }, 
    {
      pos: [20, 1, 14], 
      state: 2
    }, 
    {
      pos: [21, 1, 14], 
      state: 2
    }, 
    {
      pos: [0, 1, 15], 
      state: 2
    }, 
    {
      pos: [1, 1, 15], 
      state: 2
    }, 
    {
      pos: [2, 1, 15], 
      state: 2
    }, 
    {
      pos: [3, 1, 15], 
      state: 2
    }, 
    {
      pos: [4, 1, 15], 
      state: 2
    }, 
    {
      pos: [5, 1, 15], 
      state: 2
    }, 
    {
      pos: [6, 1, 15], 
      state: 2
    }, 
    {
      pos: [7, 1, 15], 
      state: 2
    }, 
    {
      pos: [8, 1, 15], 
      state: 2
    }, 
    {
      pos: [9, 1, 15], 
      state: 2
    }, 
    {
      pos: [10, 1, 15], 
      state: 2
    }, 
    {
      pos: [11, 1, 15], 
      state: 2
    }, 
    {
      pos: [12, 1, 15], 
      state: 2
    }, 
    {
      pos: [13, 1, 15], 
      state: 2
    }, 
    {
      pos: [14, 1, 15], 
      state: 2
    }, 
    {
      pos: [15, 1, 15], 
      state: 2
    }, 
    {
      pos: [16, 1, 15], 
      state: 2
    }, 
    {
      pos: [17, 1, 15], 
      state: 2
    }, 
    {
      pos: [18, 1, 15], 
      state: 2
    }, 
    {
      pos: [19, 1, 15], 
      state: 2
    }, 
    {
      pos: [20, 1, 15], 
      state: 2
    }, 
    {
      pos: [21, 1, 15], 
      state: 2
    }, 
    {
      pos: [0, 1, 16], 
      state: 2
    }, 
    {
      pos: [1, 1, 16], 
      state: 2
    }, 
    {
      pos: [2, 1, 16], 
      state: 2
    }, 
    {
      pos: [3, 1, 16], 
      state: 2
    }, 
    {
      pos: [4, 1, 16], 
      state: 2
    }, 
    {
      pos: [5, 1, 16], 
      state: 2
    }, 
    {
      pos: [6, 1, 16], 
      state: 2
    }, 
    {
      pos: [7, 1, 16], 
      state: 2
    }, 
    {
      pos: [8, 1, 16], 
      state: 2
    }, 
    {
      pos: [9, 1, 16], 
      state: 2
    }, 
    {
      pos: [10, 1, 16], 
      state: 2
    }, 
    {
      pos: [11, 1, 16], 
      state: 2
    }, 
    {
      pos: [12, 1, 16], 
      state: 2
    }, 
    {
      pos: [13, 1, 16], 
      state: 2
    }, 
    {
      pos: [14, 1, 16], 
      state: 2
    }, 
    {
      pos: [15, 1, 16], 
      state: 2
    }, 
    {
      pos: [16, 1, 16], 
      state: 2
    }, 
    {
      pos: [17, 1, 16], 
      state: 2
    }, 
    {
      pos: [18, 1, 16], 
      state: 2
    }, 
    {
      pos: [19, 1, 16], 
      state: 2
    }, 
    {
      pos: [20, 1, 16], 
      state: 2
    }, 
    {
      pos: [21, 1, 16], 
      state: 2
    }, 
    {
      pos: [0, 1, 17], 
      state: 2
    }, 
    {
      pos: [1, 1, 17], 
      state: 2
    }, 
    {
      pos: [2, 1, 17], 
      state: 2
    }, 
    {
      pos: [3, 1, 17], 
      state: 2
    }, 
    {
      pos: [4, 1, 17], 
      state: 2
    }, 
    {
      pos: [5, 1, 17], 
      state: 2
    }, 
    {
      pos: [6, 1, 17], 
      state: 2
    }, 
    {
      pos: [7, 1, 17], 
      state: 2
    }, 
    {
      pos: [8, 1, 17], 
      state: 2
    }, 
    {
      pos: [9, 1, 17], 
      state: 2
    }, 
    {
      pos: [10, 1, 17], 
      state: 2
    }, 
    {
      pos: [11, 1, 17], 
      state: 2
    }, 
    {
      pos: [12, 1, 17], 
      state: 2
    }, 
    {
      pos: [13, 1, 17], 
      state: 2
    }, 
    {
      pos: [14, 1, 17], 
      state: 2
    }, 
    {
      pos: [15, 1, 17], 
      state: 2
    }, 
    {
      pos: [16, 1, 17], 
      state: 2
    }, 
    {
      pos: [17, 1, 17], 
      state: 2
    }, 
    {
      pos: [18, 1, 17], 
      state: 2
    }, 
    {
      pos: [19, 1, 17], 
      state: 2
    }, 
    {
      pos: [20, 1, 17], 
      state: 2
    }, 
    {
      pos: [21, 1, 17], 
      state: 2
    }, 
    {
      nbt: {
        id: "minecraft:bell"
      }, 
      pos: [9, 2, 3], 
      state: 13
    }, 
    {
      pos: [0, 2, 0], 
      state: 2
    }, 
    {
      pos: [1, 2, 0], 
      state: 2
    }, 
    {
      pos: [2, 2, 0], 
      state: 2
    }, 
    {
      pos: [3, 2, 0], 
      state: 2
    }, 
    {
      pos: [4, 2, 0], 
      state: 2
    }, 
    {
      pos: [5, 2, 0], 
      state: 2
    }, 
    {
      pos: [6, 2, 0], 
      state: 2
    }, 
    {
      pos: [7, 2, 0], 
      state: 2
    }, 
    {
      pos: [8, 2, 0], 
      state: 2
    }, 
    {
      pos: [9, 2, 0], 
      state: 2
    }, 
    {
      pos: [10, 2, 0], 
      state: 2
    }, 
    {
      pos: [11, 2, 0], 
      state: 2
    }, 
    {
      pos: [12, 2, 0], 
      state: 2
    }, 
    {
      pos: [13, 2, 0], 
      state: 2
    }, 
    {
      pos: [14, 2, 0], 
      state: 2
    }, 
    {
      pos: [15, 2, 0], 
      state: 2
    }, 
    {
      pos: [16, 2, 0], 
      state: 2
    }, 
    {
      pos: [17, 2, 0], 
      state: 2
    }, 
    {
      pos: [18, 2, 0], 
      state: 2
    }, 
    {
      pos: [19, 2, 0], 
      state: 2
    }, 
    {
      pos: [20, 2, 0], 
      state: 2
    }, 
    {
      pos: [21, 2, 0], 
      state: 2
    }, 
    {
      pos: [0, 2, 1], 
      state: 2
    }, 
    {
      pos: [1, 2, 1], 
      state: 2
    }, 
    {
      pos: [2, 2, 1], 
      state: 2
    }, 
    {
      pos: [3, 2, 1], 
      state: 2
    }, 
    {
      pos: [4, 2, 1], 
      state: 2
    }, 
    {
      pos: [5, 2, 1], 
      state: 2
    }, 
    {
      pos: [6, 2, 1], 
      state: 2
    }, 
    {
      pos: [7, 2, 1], 
      state: 2
    }, 
    {
      pos: [8, 2, 1], 
      state: 2
    }, 
    {
      pos: [9, 2, 1], 
      state: 2
    }, 
    {
      pos: [10, 2, 1], 
      state: 2
    }, 
    {
      pos: [11, 2, 1], 
      state: 2
    }, 
    {
      pos: [12, 2, 1], 
      state: 2
    }, 
    {
      pos: [13, 2, 1], 
      state: 2
    }, 
    {
      pos: [14, 2, 1], 
      state: 2
    }, 
    {
      pos: [15, 2, 1], 
      state: 2
    }, 
    {
      pos: [16, 2, 1], 
      state: 2
    }, 
    {
      pos: [17, 2, 1], 
      state: 2
    }, 
    {
      pos: [18, 2, 1], 
      state: 2
    }, 
    {
      pos: [19, 2, 1], 
      state: 2
    }, 
    {
      pos: [20, 2, 1], 
      state: 2
    }, 
    {
      pos: [21, 2, 1], 
      state: 2
    }, 
    {
      pos: [0, 2, 2], 
      state: 2
    }, 
    {
      pos: [1, 2, 2], 
      state: 2
    }, 
    {
      pos: [2, 2, 2], 
      state: 2
    }, 
    {
      pos: [3, 2, 2], 
      state: 2
    }, 
    {
      pos: [4, 2, 2], 
      state: 2
    }, 
    {
      pos: [5, 2, 2], 
      state: 2
    }, 
    {
      pos: [6, 2, 2], 
      state: 2
    }, 
    {
      pos: [7, 2, 2], 
      state: 2
    }, 
    {
      pos: [8, 2, 2], 
      state: 2
    }, 
    {
      pos: [9, 2, 2], 
      state: 2
    }, 
    {
      pos: [10, 2, 2], 
      state: 2
    }, 
    {
      pos: [11, 2, 2], 
      state: 2
    }, 
    {
      pos: [12, 2, 2], 
      state: 2
    }, 
    {
      pos: [13, 2, 2], 
      state: 2
    }, 
    {
      pos: [14, 2, 2], 
      state: 2
    }, 
    {
      pos: [15, 2, 2], 
      state: 2
    }, 
    {
      pos: [16, 2, 2], 
      state: 2
    }, 
    {
      pos: [17, 2, 2], 
      state: 2
    }, 
    {
      pos: [18, 2, 2], 
      state: 2
    }, 
    {
      pos: [19, 2, 2], 
      state: 2
    }, 
    {
      pos: [20, 2, 2], 
      state: 2
    }, 
    {
      pos: [21, 2, 2], 
      state: 2
    }, 
    {
      pos: [0, 2, 3], 
      state: 2
    }, 
    {
      pos: [1, 2, 3], 
      state: 2
    }, 
    {
      pos: [2, 2, 3], 
      state: 2
    }, 
    {
      pos: [3, 2, 3], 
      state: 2
    }, 
    {
      pos: [4, 2, 3], 
      state: 2
    }, 
    {
      pos: [5, 2, 3], 
      state: 2
    }, 
    {
      pos: [6, 2, 3], 
      state: 2
    }, 
    {
      pos: [7, 2, 3], 
      state: 2
    }, 
    {
      pos: [8, 2, 3], 
      state: 2
    }, 
    {
      pos: [10, 2, 3], 
      state: 2
    }, 
    {
      pos: [11, 2, 3], 
      state: 2
    }, 
    {
      pos: [12, 2, 3], 
      state: 2
    }, 
    {
      pos: [13, 2, 3], 
      state: 2
    }, 
    {
      pos: [14, 2, 3], 
      state: 2
    }, 
    {
      pos: [15, 2, 3], 
      state: 2
    }, 
    {
      pos: [16, 2, 3], 
      state: 2
    }, 
    {
      pos: [17, 2, 3], 
      state: 2
    }, 
    {
      pos: [18, 2, 3], 
      state: 2
    }, 
    {
      pos: [19, 2, 3], 
      state: 2
    }, 
    {
      pos: [20, 2, 3], 
      state: 2
    }, 
    {
      pos: [21, 2, 3], 
      state: 2
    }, 
    {
      pos: [0, 2, 4], 
      state: 2
    }, 
    {
      pos: [1, 2, 4], 
      state: 2
    }, 
    {
      pos: [2, 2, 4], 
      state: 2
    }, 
    {
      pos: [3, 2, 4], 
      state: 2
    }, 
    {
      pos: [4, 2, 4], 
      state: 2
    }, 
    {
      pos: [5, 2, 4], 
      state: 2
    }, 
    {
      pos: [6, 2, 4], 
      state: 2
    }, 
    {
      pos: [7, 2, 4], 
      state: 2
    }, 
    {
      pos: [8, 2, 4], 
      state: 2
    }, 
    {
      pos: [9, 2, 4], 
      state: 2
    }, 
    {
      pos: [10, 2, 4], 
      state: 2
    }, 
    {
      pos: [11, 2, 4], 
      state: 2
    }, 
    {
      pos: [12, 2, 4], 
      state: 2
    }, 
    {
      pos: [13, 2, 4], 
      state: 2
    }, 
    {
      pos: [14, 2, 4], 
      state: 2
    }, 
    {
      pos: [15, 2, 4], 
      state: 2
    }, 
    {
      pos: [16, 2, 4], 
      state: 2
    }, 
    {
      pos: [17, 2, 4], 
      state: 2
    }, 
    {
      pos: [18, 2, 4], 
      state: 2
    }, 
    {
      pos: [19, 2, 4], 
      state: 2
    }, 
    {
      pos: [20, 2, 4], 
      state: 2
    }, 
    {
      pos: [21, 2, 4], 
      state: 2
    }, 
    {
      pos: [0, 2, 5], 
      state: 2
    }, 
    {
      pos: [1, 2, 5], 
      state: 2
    }, 
    {
      pos: [2, 2, 5], 
      state: 2
    }, 
    {
      pos: [3, 2, 5], 
      state: 2
    }, 
    {
      pos: [4, 2, 5], 
      state: 2
    }, 
    {
      pos: [5, 2, 5], 
      state: 2
    }, 
    {
      pos: [6, 2, 5], 
      state: 2
    }, 
    {
      pos: [7, 2, 5], 
      state: 2
    }, 
    {
      pos: [8, 2, 5], 
      state: 2
    }, 
    {
      pos: [9, 2, 5], 
      state: 2
    }, 
    {
      pos: [10, 2, 5], 
      state: 2
    }, 
    {
      pos: [11, 2, 5], 
      state: 2
    }, 
    {
      pos: [12, 2, 5], 
      state: 2
    }, 
    {
      pos: [13, 2, 5], 
      state: 2
    }, 
    {
      pos: [14, 2, 5], 
      state: 2
    }, 
    {
      pos: [15, 2, 5], 
      state: 2
    }, 
    {
      pos: [16, 2, 5], 
      state: 2
    }, 
    {
      pos: [17, 2, 5], 
      state: 2
    }, 
    {
      pos: [18, 2, 5], 
      state: 2
    }, 
    {
      pos: [19, 2, 5], 
      state: 2
    }, 
    {
      pos: [20, 2, 5], 
      state: 2
    }, 
    {
      pos: [21, 2, 5], 
      state: 2
    }, 
    {
      pos: [0, 2, 6], 
      state: 2
    }, 
    {
      pos: [1, 2, 6], 
      state: 2
    }, 
    {
      pos: [2, 2, 6], 
      state: 2
    }, 
    {
      pos: [3, 2, 6], 
      state: 2
    }, 
    {
      pos: [4, 2, 6], 
      state: 2
    }, 
    {
      pos: [5, 2, 6], 
      state: 2
    }, 
    {
      pos: [6, 2, 6], 
      state: 2
    }, 
    {
      pos: [7, 2, 6], 
      state: 2
    }, 
    {
      pos: [8, 2, 6], 
      state: 2
    }, 
    {
      pos: [9, 2, 6], 
      state: 2
    }, 
    {
      pos: [10, 2, 6], 
      state: 2
    }, 
    {
      pos: [11, 2, 6], 
      state: 2
    }, 
    {
      pos: [12, 2, 6], 
      state: 2
    }, 
    {
      pos: [13, 2, 6], 
      state: 2
    }, 
    {
      pos: [14, 2, 6], 
      state: 2
    }, 
    {
      pos: [15, 2, 6], 
      state: 2
    }, 
    {
      pos: [16, 2, 6], 
      state: 2
    }, 
    {
      pos: [17, 2, 6], 
      state: 2
    }, 
    {
      pos: [18, 2, 6], 
      state: 2
    }, 
    {
      pos: [19, 2, 6], 
      state: 2
    }, 
    {
      pos: [20, 2, 6], 
      state: 2
    }, 
    {
      pos: [21, 2, 6], 
      state: 2
    }, 
    {
      pos: [0, 2, 7], 
      state: 2
    }, 
    {
      pos: [1, 2, 7], 
      state: 2
    }, 
    {
      pos: [2, 2, 7], 
      state: 2
    }, 
    {
      pos: [3, 2, 7], 
      state: 2
    }, 
    {
      pos: [4, 2, 7], 
      state: 2
    }, 
    {
      pos: [5, 2, 7], 
      state: 2
    }, 
    {
      pos: [6, 2, 7], 
      state: 2
    }, 
    {
      pos: [7, 2, 7], 
      state: 2
    }, 
    {
      pos: [8, 2, 7], 
      state: 2
    }, 
    {
      pos: [9, 2, 7], 
      state: 2
    }, 
    {
      pos: [10, 2, 7], 
      state: 2
    }, 
    {
      pos: [11, 2, 7], 
      state: 2
    }, 
    {
      pos: [12, 2, 7], 
      state: 2
    }, 
    {
      pos: [13, 2, 7], 
      state: 2
    }, 
    {
      pos: [14, 2, 7], 
      state: 2
    }, 
    {
      pos: [15, 2, 7], 
      state: 2
    }, 
    {
      pos: [16, 2, 7], 
      state: 2
    }, 
    {
      pos: [17, 2, 7], 
      state: 2
    }, 
    {
      pos: [18, 2, 7], 
      state: 2
    }, 
    {
      pos: [19, 2, 7], 
      state: 2
    }, 
    {
      pos: [20, 2, 7], 
      state: 2
    }, 
    {
      pos: [21, 2, 7], 
      state: 2
    }, 
    {
      pos: [0, 2, 8], 
      state: 2
    }, 
    {
      pos: [1, 2, 8], 
      state: 2
    }, 
    {
      pos: [2, 2, 8], 
      state: 2
    }, 
    {
      pos: [3, 2, 8], 
      state: 2
    }, 
    {
      pos: [4, 2, 8], 
      state: 2
    }, 
    {
      pos: [5, 2, 8], 
      state: 2
    }, 
    {
      pos: [6, 2, 8], 
      state: 2
    }, 
    {
      pos: [7, 2, 8], 
      state: 2
    }, 
    {
      pos: [8, 2, 8], 
      state: 2
    }, 
    {
      pos: [9, 2, 8], 
      state: 2
    }, 
    {
      pos: [10, 2, 8], 
      state: 2
    }, 
    {
      pos: [11, 2, 8], 
      state: 2
    }, 
    {
      pos: [12, 2, 8], 
      state: 2
    }, 
    {
      pos: [13, 2, 8], 
      state: 2
    }, 
    {
      pos: [14, 2, 8], 
      state: 2
    }, 
    {
      pos: [15, 2, 8], 
      state: 2
    }, 
    {
      pos: [16, 2, 8], 
      state: 2
    }, 
    {
      pos: [17, 2, 8], 
      state: 2
    }, 
    {
      pos: [18, 2, 8], 
      state: 2
    }, 
    {
      pos: [19, 2, 8], 
      state: 2
    }, 
    {
      pos: [20, 2, 8], 
      state: 2
    }, 
    {
      pos: [21, 2, 8], 
      state: 2
    }, 
    {
      pos: [0, 2, 9], 
      state: 2
    }, 
    {
      pos: [1, 2, 9], 
      state: 2
    }, 
    {
      pos: [2, 2, 9], 
      state: 2
    }, 
    {
      pos: [3, 2, 9], 
      state: 2
    }, 
    {
      pos: [4, 2, 9], 
      state: 2
    }, 
    {
      pos: [5, 2, 9], 
      state: 2
    }, 
    {
      pos: [6, 2, 9], 
      state: 2
    }, 
    {
      pos: [7, 2, 9], 
      state: 2
    }, 
    {
      pos: [8, 2, 9], 
      state: 2
    }, 
    {
      pos: [9, 2, 9], 
      state: 2
    }, 
    {
      pos: [10, 2, 9], 
      state: 2
    }, 
    {
      pos: [11, 2, 9], 
      state: 2
    }, 
    {
      pos: [12, 2, 9], 
      state: 2
    }, 
    {
      pos: [13, 2, 9], 
      state: 2
    }, 
    {
      pos: [14, 2, 9], 
      state: 2
    }, 
    {
      pos: [15, 2, 9], 
      state: 2
    }, 
    {
      pos: [16, 2, 9], 
      state: 2
    }, 
    {
      pos: [17, 2, 9], 
      state: 2
    }, 
    {
      pos: [18, 2, 9], 
      state: 2
    }, 
    {
      pos: [19, 2, 9], 
      state: 2
    }, 
    {
      pos: [20, 2, 9], 
      state: 2
    }, 
    {
      pos: [21, 2, 9], 
      state: 2
    }, 
    {
      pos: [0, 2, 10], 
      state: 2
    }, 
    {
      pos: [1, 2, 10], 
      state: 2
    }, 
    {
      pos: [2, 2, 10], 
      state: 2
    }, 
    {
      pos: [3, 2, 10], 
      state: 2
    }, 
    {
      pos: [4, 2, 10], 
      state: 2
    }, 
    {
      pos: [5, 2, 10], 
      state: 2
    }, 
    {
      pos: [6, 2, 10], 
      state: 2
    }, 
    {
      pos: [7, 2, 10], 
      state: 2
    }, 
    {
      pos: [8, 2, 10], 
      state: 2
    }, 
    {
      pos: [9, 2, 10], 
      state: 2
    }, 
    {
      pos: [10, 2, 10], 
      state: 2
    }, 
    {
      pos: [11, 2, 10], 
      state: 2
    }, 
    {
      pos: [12, 2, 10], 
      state: 2
    }, 
    {
      pos: [13, 2, 10], 
      state: 2
    }, 
    {
      pos: [14, 2, 10], 
      state: 2
    }, 
    {
      pos: [15, 2, 10], 
      state: 2
    }, 
    {
      pos: [16, 2, 10], 
      state: 2
    }, 
    {
      pos: [17, 2, 10], 
      state: 2
    }, 
    {
      pos: [18, 2, 10], 
      state: 2
    }, 
    {
      pos: [19, 2, 10], 
      state: 2
    }, 
    {
      pos: [20, 2, 10], 
      state: 2
    }, 
    {
      pos: [21, 2, 10], 
      state: 2
    }, 
    {
      pos: [0, 2, 11], 
      state: 2
    }, 
    {
      pos: [1, 2, 11], 
      state: 2
    }, 
    {
      pos: [2, 2, 11], 
      state: 2
    }, 
    {
      pos: [3, 2, 11], 
      state: 2
    }, 
    {
      pos: [4, 2, 11], 
      state: 2
    }, 
    {
      pos: [5, 2, 11], 
      state: 2
    }, 
    {
      pos: [6, 2, 11], 
      state: 2
    }, 
    {
      pos: [7, 2, 11], 
      state: 2
    }, 
    {
      pos: [8, 2, 11], 
      state: 2
    }, 
    {
      pos: [9, 2, 11], 
      state: 2
    }, 
    {
      pos: [10, 2, 11], 
      state: 2
    }, 
    {
      pos: [11, 2, 11], 
      state: 2
    }, 
    {
      pos: [12, 2, 11], 
      state: 2
    }, 
    {
      pos: [13, 2, 11], 
      state: 2
    }, 
    {
      pos: [14, 2, 11], 
      state: 2
    }, 
    {
      pos: [15, 2, 11], 
      state: 2
    }, 
    {
      pos: [16, 2, 11], 
      state: 2
    }, 
    {
      pos: [17, 2, 11], 
      state: 2
    }, 
    {
      pos: [18, 2, 11], 
      state: 2
    }, 
    {
      pos: [19, 2, 11], 
      state: 2
    }, 
    {
      pos: [20, 2, 11], 
      state: 2
    }, 
    {
      pos: [21, 2, 11], 
      state: 2
    }, 
    {
      pos: [0, 2, 12], 
      state: 2
    }, 
    {
      pos: [1, 2, 12], 
      state: 2
    }, 
    {
      pos: [2, 2, 12], 
      state: 2
    }, 
    {
      pos: [3, 2, 12], 
      state: 2
    }, 
    {
      pos: [4, 2, 12], 
      state: 2
    }, 
    {
      pos: [5, 2, 12], 
      state: 2
    }, 
    {
      pos: [6, 2, 12], 
      state: 2
    }, 
    {
      pos: [7, 2, 12], 
      state: 2
    }, 
    {
      pos: [8, 2, 12], 
      state: 2
    }, 
    {
      pos: [9, 2, 12], 
      state: 2
    }, 
    {
      pos: [10, 2, 12], 
      state: 2
    }, 
    {
      pos: [11, 2, 12], 
      state: 2
    }, 
    {
      pos: [12, 2, 12], 
      state: 2
    }, 
    {
      pos: [13, 2, 12], 
      state: 2
    }, 
    {
      pos: [14, 2, 12], 
      state: 2
    }, 
    {
      pos: [15, 2, 12], 
      state: 2
    }, 
    {
      pos: [16, 2, 12], 
      state: 2
    }, 
    {
      pos: [17, 2, 12], 
      state: 2
    }, 
    {
      pos: [18, 2, 12], 
      state: 2
    }, 
    {
      pos: [19, 2, 12], 
      state: 2
    }, 
    {
      pos: [20, 2, 12], 
      state: 2
    }, 
    {
      pos: [21, 2, 12], 
      state: 2
    }, 
    {
      pos: [0, 2, 13], 
      state: 2
    }, 
    {
      pos: [1, 2, 13], 
      state: 2
    }, 
    {
      pos: [2, 2, 13], 
      state: 2
    }, 
    {
      pos: [3, 2, 13], 
      state: 2
    }, 
    {
      pos: [4, 2, 13], 
      state: 2
    }, 
    {
      pos: [5, 2, 13], 
      state: 2
    }, 
    {
      pos: [6, 2, 13], 
      state: 2
    }, 
    {
      pos: [7, 2, 13], 
      state: 2
    }, 
    {
      pos: [8, 2, 13], 
      state: 2
    }, 
    {
      pos: [9, 2, 13], 
      state: 2
    }, 
    {
      pos: [10, 2, 13], 
      state: 2
    }, 
    {
      pos: [11, 2, 13], 
      state: 2
    }, 
    {
      pos: [12, 2, 13], 
      state: 2
    }, 
    {
      pos: [13, 2, 13], 
      state: 2
    }, 
    {
      pos: [14, 2, 13], 
      state: 2
    }, 
    {
      pos: [15, 2, 13], 
      state: 2
    }, 
    {
      pos: [16, 2, 13], 
      state: 2
    }, 
    {
      pos: [17, 2, 13], 
      state: 2
    }, 
    {
      pos: [18, 2, 13], 
      state: 2
    }, 
    {
      pos: [19, 2, 13], 
      state: 2
    }, 
    {
      pos: [20, 2, 13], 
      state: 2
    }, 
    {
      pos: [21, 2, 13], 
      state: 2
    }, 
    {
      pos: [0, 2, 14], 
      state: 2
    }, 
    {
      pos: [1, 2, 14], 
      state: 2
    }, 
    {
      pos: [2, 2, 14], 
      state: 2
    }, 
    {
      pos: [3, 2, 14], 
      state: 2
    }, 
    {
      pos: [4, 2, 14], 
      state: 2
    }, 
    {
      pos: [5, 2, 14], 
      state: 2
    }, 
    {
      pos: [6, 2, 14], 
      state: 2
    }, 
    {
      pos: [7, 2, 14], 
      state: 2
    }, 
    {
      pos: [8, 2, 14], 
      state: 2
    }, 
    {
      pos: [9, 2, 14], 
      state: 2
    }, 
    {
      pos: [10, 2, 14], 
      state: 2
    }, 
    {
      pos: [11, 2, 14], 
      state: 2
    }, 
    {
      pos: [12, 2, 14], 
      state: 2
    }, 
    {
      pos: [13, 2, 14], 
      state: 2
    }, 
    {
      pos: [14, 2, 14], 
      state: 2
    }, 
    {
      pos: [15, 2, 14], 
      state: 2
    }, 
    {
      pos: [16, 2, 14], 
      state: 2
    }, 
    {
      pos: [17, 2, 14], 
      state: 2
    }, 
    {
      pos: [18, 2, 14], 
      state: 2
    }, 
    {
      pos: [19, 2, 14], 
      state: 2
    }, 
    {
      pos: [20, 2, 14], 
      state: 2
    }, 
    {
      pos: [21, 2, 14], 
      state: 2
    }, 
    {
      pos: [0, 2, 15], 
      state: 2
    }, 
    {
      pos: [1, 2, 15], 
      state: 2
    }, 
    {
      pos: [2, 2, 15], 
      state: 2
    }, 
    {
      pos: [3, 2, 15], 
      state: 2
    }, 
    {
      pos: [4, 2, 15], 
      state: 2
    }, 
    {
      pos: [5, 2, 15], 
      state: 2
    }, 
    {
      pos: [6, 2, 15], 
      state: 2
    }, 
    {
      pos: [7, 2, 15], 
      state: 2
    }, 
    {
      pos: [8, 2, 15], 
      state: 2
    }, 
    {
      pos: [9, 2, 15], 
      state: 2
    }, 
    {
      pos: [10, 2, 15], 
      state: 2
    }, 
    {
      pos: [11, 2, 15], 
      state: 2
    }, 
    {
      pos: [12, 2, 15], 
      state: 2
    }, 
    {
      pos: [13, 2, 15], 
      state: 2
    }, 
    {
      pos: [14, 2, 15], 
      state: 2
    }, 
    {
      pos: [15, 2, 15], 
      state: 2
    }, 
    {
      pos: [16, 2, 15], 
      state: 2
    }, 
    {
      pos: [17, 2, 15], 
      state: 2
    }, 
    {
      pos: [18, 2, 15], 
      state: 2
    }, 
    {
      pos: [19, 2, 15], 
      state: 2
    }, 
    {
      pos: [20, 2, 15], 
      state: 2
    }, 
    {
      pos: [21, 2, 15], 
      state: 2
    }, 
    {
      pos: [0, 2, 16], 
      state: 2
    }, 
    {
      pos: [1, 2, 16], 
      state: 2
    }, 
    {
      pos: [2, 2, 16], 
      state: 2
    }, 
    {
      pos: [3, 2, 16], 
      state: 2
    }, 
    {
      pos: [4, 2, 16], 
      state: 2
    }, 
    {
      pos: [5, 2, 16], 
      state: 2
    }, 
    {
      pos: [6, 2, 16], 
      state: 2
    }, 
    {
      pos: [7, 2, 16], 
      state: 2
    }, 
    {
      pos: [8, 2, 16], 
      state: 2
    }, 
    {
      pos: [9, 2, 16], 
      state: 2
    }, 
    {
      pos: [10, 2, 16], 
      state: 2
    }, 
    {
      pos: [11, 2, 16], 
      state: 2
    }, 
    {
      pos: [12, 2, 16], 
      state: 2
    }, 
    {
      pos: [13, 2, 16], 
      state: 2
    }, 
    {
      pos: [14, 2, 16], 
      state: 2
    }, 
    {
      pos: [15, 2, 16], 
      state: 2
    }, 
    {
      pos: [16, 2, 16], 
      state: 2
    }, 
    {
      pos: [17, 2, 16], 
      state: 2
    }, 
    {
      pos: [18, 2, 16], 
      state: 2
    }, 
    {
      pos: [19, 2, 16], 
      state: 2
    }, 
    {
      pos: [20, 2, 16], 
      state: 2
    }, 
    {
      pos: [21, 2, 16], 
      state: 2
    }, 
    {
      pos: [0, 2, 17], 
      state: 2
    }, 
    {
      pos: [1, 2, 17], 
      state: 2
    }, 
    {
      pos: [2, 2, 17], 
      state: 2
    }, 
    {
      pos: [3, 2, 17], 
      state: 2
    }, 
    {
      pos: [4, 2, 17], 
      state: 2
    }, 
    {
      pos: [5, 2, 17], 
      state: 2
    }, 
    {
      pos: [6, 2, 17], 
      state: 2
    }, 
    {
      pos: [7, 2, 17], 
      state: 2
    }, 
    {
      pos: [8, 2, 17], 
      state: 2
    }, 
    {
      pos: [9, 2, 17], 
      state: 2
    }, 
    {
      pos: [10, 2, 17], 
      state: 2
    }, 
    {
      pos: [11, 2, 17], 
      state: 2
    }, 
    {
      pos: [12, 2, 17], 
      state: 2
    }, 
    {
      pos: [13, 2, 17], 
      state: 2
    }, 
    {
      pos: [14, 2, 17], 
      state: 2
    }, 
    {
      pos: [15, 2, 17], 
      state: 2
    }, 
    {
      pos: [16, 2, 17], 
      state: 2
    }, 
    {
      pos: [17, 2, 17], 
      state: 2
    }, 
    {
      pos: [18, 2, 17], 
      state: 2
    }, 
    {
      pos: [19, 2, 17], 
      state: 2
    }, 
    {
      pos: [20, 2, 17], 
      state: 2
    }, 
    {
      pos: [21, 2, 17], 
      state: 2
    }
  ], 
  palette: [
    {
      Properties: {
        snowy: "false"
      }, 
      Name: "minecraft:grass_block"
    }, 
    {
      Properties: {
        facing: "up"
      }, 
      Name: "minecraft:jigsaw"
    }, 
    {
      Name: "minecraft:air"
    }, 
    {
      Name: "minecraft:grass_path"
    }, 
    {
      Name: "minecraft:spruce_planks"
    }, 
    {
      Properties: {
        facing: "north"
      }, 
      Name: "minecraft:jigsaw"
    }, 
    {
      Properties: {
        facing: "west"
      }, 
      Name: "minecraft:jigsaw"
    }, 
    {
      Properties: {
        facing: "east"
      }, 
      Name: "minecraft:jigsaw"
    }, 
    {
      Properties: {
        facing: "south"
      }, 
      Name: "minecraft:jigsaw"
    }, 
    {
      Properties: {
        half: "bottom", 
        waterlogged: "false", 
        powered: "false", 
        facing: "north", 
        open: "true"
      }, 
      Name: "minecraft:spruce_trapdoor"
    }, 
    {
      Properties: {
        half: "bottom", 
        waterlogged: "false", 
        powered: "false", 
        facing: "west", 
        open: "true"
      }, 
      Name: "minecraft:spruce_trapdoor"
    }, 
    {
      Properties: {
        half: "bottom", 
        waterlogged: "false", 
        powered: "false", 
        facing: "east", 
        open: "true"
      }, 
      Name: "minecraft:spruce_trapdoor"
    }, 
    {
      Properties: {
        half: "bottom", 
        waterlogged: "false", 
        powered: "false", 
        facing: "south", 
        open: "true"
      }, 
      Name: "minecraft:spruce_trapdoor"
    }, 
    {
      Properties: {
        attachment: "floor", 
        powered: "false", 
        facing: "north"
      }, 
      Name: "minecraft:bell"
    }
  ]
}
