{
  size: [12, 6, 12], 
  entities: [], 
  blocks: [
    {
      pos: [5, 0, 0], 
      state: 0
    }, 
    {
      pos: [6, 0, 0], 
      state: 0
    }, 
    {
      pos: [7, 0, 0], 
      state: 0
    }, 
    {
      pos: [2, 0, 1], 
      state: 0
    }, 
    {
      pos: [3, 0, 1], 
      state: 0
    }, 
    {
      pos: [4, 0, 1], 
      state: 0
    }, 
    {
      pos: [5, 0, 1], 
      state: 0
    }, 
    {
      pos: [6, 0, 1], 
      state: 0
    }, 
    {
      pos: [7, 0, 1], 
      state: 0
    }, 
    {
      pos: [8, 0, 1], 
      state: 0
    }, 
    {
      pos: [9, 0, 1], 
      state: 0
    }, 
    {
      pos: [10, 0, 1], 
      state: 0
    }, 
    {
      pos: [1, 0, 2], 
      state: 0
    }, 
    {
      pos: [2, 0, 2], 
      state: 0
    }, 
    {
      pos: [3, 0, 2], 
      state: 0
    }, 
    {
      pos: [4, 0, 2], 
      state: 0
    }, 
    {
      pos: [5, 0, 2], 
      state: 0
    }, 
    {
      pos: [6, 0, 2], 
      state: 0
    }, 
    {
      pos: [7, 0, 2], 
      state: 0
    }, 
    {
      pos: [8, 0, 2], 
      state: 0
    }, 
    {
      pos: [9, 0, 2], 
      state: 0
    }, 
    {
      pos: [10, 0, 2], 
      state: 0
    }, 
    {
      pos: [1, 0, 3], 
      state: 0
    }, 
    {
      pos: [2, 0, 3], 
      state: 0
    }, 
    {
      pos: [3, 0, 3], 
      state: 1
    }, 
    {
      pos: [4, 0, 3], 
      state: 1
    }, 
    {
      pos: [5, 0, 3], 
      state: 1
    }, 
    {
      pos: [6, 0, 3], 
      state: 1
    }, 
    {
      pos: [7, 0, 3], 
      state: 1
    }, 
    {
      pos: [8, 0, 3], 
      state: 1
    }, 
    {
      pos: [9, 0, 3], 
      state: 0
    }, 
    {
      pos: [0, 0, 4], 
      state: 0
    }, 
    {
      pos: [1, 0, 4], 
      state: 0
    }, 
    {
      pos: [2, 0, 4], 
      state: 0
    }, 
    {
      pos: [3, 0, 4], 
      state: 1
    }, 
    {
      pos: [4, 0, 4], 
      state: 1
    }, 
    {
      pos: [5, 0, 4], 
      state: 1
    }, 
    {
      pos: [6, 0, 4], 
      state: 1
    }, 
    {
      pos: [7, 0, 4], 
      state: 1
    }, 
    {
      pos: [8, 0, 4], 
      state: 1
    }, 
    {
      pos: [9, 0, 4], 
      state: 0
    }, 
    {
      pos: [10, 0, 4], 
      state: 0
    }, 
    {
      pos: [0, 0, 5], 
      state: 0
    }, 
    {
      pos: [1, 0, 5], 
      state: 0
    }, 
    {
      pos: [2, 0, 5], 
      state: 0
    }, 
    {
      pos: [3, 0, 5], 
      state: 1
    }, 
    {
      pos: [4, 0, 5], 
      state: 1
    }, 
    {
      pos: [5, 0, 5], 
      state: 1
    }, 
    {
      pos: [6, 0, 5], 
      state: 1
    }, 
    {
      pos: [7, 0, 5], 
      state: 1
    }, 
    {
      pos: [8, 0, 5], 
      state: 1
    }, 
    {
      pos: [9, 0, 5], 
      state: 0
    }, 
    {
      pos: [10, 0, 5], 
      state: 0
    }, 
    {
      pos: [11, 0, 5], 
      state: 0
    }, 
    {
      pos: [0, 0, 6], 
      state: 0
    }, 
    {
      pos: [1, 0, 6], 
      state: 0
    }, 
    {
      pos: [2, 0, 6], 
      state: 0
    }, 
    {
      pos: [3, 0, 6], 
      state: 1
    }, 
    {
      pos: [4, 0, 6], 
      state: 1
    }, 
    {
      pos: [5, 0, 6], 
      state: 1
    }, 
    {
      pos: [6, 0, 6], 
      state: 1
    }, 
    {
      pos: [7, 0, 6], 
      state: 1
    }, 
    {
      pos: [8, 0, 6], 
      state: 1
    }, 
    {
      pos: [9, 0, 6], 
      state: 0
    }, 
    {
      pos: [10, 0, 6], 
      state: 0
    }, 
    {
      pos: [11, 0, 6], 
      state: 0
    }, 
    {
      pos: [1, 0, 7], 
      state: 0
    }, 
    {
      pos: [2, 0, 7], 
      state: 0
    }, 
    {
      pos: [3, 0, 7], 
      state: 1
    }, 
    {
      pos: [4, 0, 7], 
      state: 1
    }, 
    {
      pos: [5, 0, 7], 
      state: 1
    }, 
    {
      pos: [6, 0, 7], 
      state: 1
    }, 
    {
      pos: [7, 0, 7], 
      state: 1
    }, 
    {
      pos: [8, 0, 7], 
      state: 1
    }, 
    {
      pos: [9, 0, 7], 
      state: 0
    }, 
    {
      pos: [10, 0, 7], 
      state: 0
    }, 
    {
      pos: [11, 0, 7], 
      state: 0
    }, 
    {
      pos: [1, 0, 8], 
      state: 0
    }, 
    {
      pos: [2, 0, 8], 
      state: 0
    }, 
    {
      pos: [3, 0, 8], 
      state: 1
    }, 
    {
      pos: [4, 0, 8], 
      state: 1
    }, 
    {
      pos: [5, 0, 8], 
      state: 1
    }, 
    {
      pos: [6, 0, 8], 
      state: 1
    }, 
    {
      pos: [7, 0, 8], 
      state: 1
    }, 
    {
      pos: [8, 0, 8], 
      state: 1
    }, 
    {
      pos: [9, 0, 8], 
      state: 0
    }, 
    {
      pos: [10, 0, 8], 
      state: 0
    }, 
    {
      pos: [1, 0, 9], 
      state: 0
    }, 
    {
      pos: [2, 0, 9], 
      state: 0
    }, 
    {
      pos: [3, 0, 9], 
      state: 0
    }, 
    {
      pos: [4, 0, 9], 
      state: 0
    }, 
    {
      pos: [5, 0, 9], 
      state: 0
    }, 
    {
      pos: [6, 0, 9], 
      state: 0
    }, 
    {
      pos: [7, 0, 9], 
      state: 0
    }, 
    {
      pos: [8, 0, 9], 
      state: 0
    }, 
    {
      pos: [9, 0, 9], 
      state: 0
    }, 
    {
      pos: [10, 0, 9], 
      state: 0
    }, 
    {
      pos: [1, 0, 10], 
      state: 0
    }, 
    {
      pos: [2, 0, 10], 
      state: 0
    }, 
    {
      pos: [3, 0, 10], 
      state: 0
    }, 
    {
      pos: [4, 0, 10], 
      state: 0
    }, 
    {
      pos: [5, 0, 10], 
      state: 0
    }, 
    {
      pos: [6, 0, 10], 
      state: 0
    }, 
    {
      pos: [7, 0, 10], 
      state: 0
    }, 
    {
      pos: [8, 0, 10], 
      state: 0
    }, 
    {
      pos: [9, 0, 10], 
      state: 0
    }, 
    {
      pos: [10, 0, 10], 
      state: 0
    }, 
    {
      pos: [4, 0, 11], 
      state: 0
    }, 
    {
      pos: [5, 0, 11], 
      state: 0
    }, 
    {
      pos: [6, 0, 11], 
      state: 0
    }, 
    {
      nbt: {
        target_pool: "minecraft:village/common/cats", 
        final_state: "minecraft:smooth_sandstone", 
        id: "minecraft:jigsaw", 
        attachement_type: "minecraft:bottom"
      }, 
      pos: [1, 0, 1], 
      state: 2
    }, 
    {
      nbt: {
        target_pool: "minecraft:village/common/cats", 
        final_state: "minecraft:smooth_sandstone", 
        id: "minecraft:jigsaw", 
        attachement_type: "minecraft:bottom"
      }, 
      pos: [10, 0, 3], 
      state: 2
    }, 
    {
      pos: [0, 0, 0], 
      state: 3
    }, 
    {
      pos: [1, 0, 0], 
      state: 3
    }, 
    {
      pos: [2, 0, 0], 
      state: 3
    }, 
    {
      pos: [3, 0, 0], 
      state: 3
    }, 
    {
      pos: [4, 0, 0], 
      state: 3
    }, 
    {
      pos: [8, 0, 0], 
      state: 3
    }, 
    {
      pos: [9, 0, 0], 
      state: 3
    }, 
    {
      pos: [10, 0, 0], 
      state: 3
    }, 
    {
      pos: [11, 0, 0], 
      state: 3
    }, 
    {
      pos: [0, 0, 1], 
      state: 3
    }, 
    {
      pos: [11, 0, 1], 
      state: 3
    }, 
    {
      pos: [0, 0, 2], 
      state: 3
    }, 
    {
      pos: [11, 0, 2], 
      state: 3
    }, 
    {
      pos: [0, 0, 3], 
      state: 3
    }, 
    {
      pos: [11, 0, 3], 
      state: 3
    }, 
    {
      pos: [11, 0, 4], 
      state: 3
    }, 
    {
      pos: [0, 0, 7], 
      state: 3
    }, 
    {
      pos: [0, 0, 8], 
      state: 3
    }, 
    {
      pos: [11, 0, 8], 
      state: 3
    }, 
    {
      pos: [0, 0, 9], 
      state: 3
    }, 
    {
      pos: [11, 0, 9], 
      state: 3
    }, 
    {
      pos: [0, 0, 10], 
      state: 3
    }, 
    {
      pos: [11, 0, 10], 
      state: 3
    }, 
    {
      pos: [0, 0, 11], 
      state: 3
    }, 
    {
      pos: [1, 0, 11], 
      state: 3
    }, 
    {
      pos: [2, 0, 11], 
      state: 3
    }, 
    {
      pos: [3, 0, 11], 
      state: 3
    }, 
    {
      pos: [7, 0, 11], 
      state: 3
    }, 
    {
      pos: [8, 0, 11], 
      state: 3
    }, 
    {
      pos: [9, 0, 11], 
      state: 3
    }, 
    {
      pos: [10, 0, 11], 
      state: 3
    }, 
    {
      pos: [11, 0, 11], 
      state: 3
    }, 
    {
      pos: [3, 1, 3], 
      state: 0
    }, 
    {
      pos: [4, 1, 3], 
      state: 0
    }, 
    {
      pos: [5, 1, 3], 
      state: 0
    }, 
    {
      pos: [6, 1, 3], 
      state: 0
    }, 
    {
      pos: [7, 1, 3], 
      state: 0
    }, 
    {
      pos: [8, 1, 3], 
      state: 0
    }, 
    {
      pos: [3, 1, 4], 
      state: 0
    }, 
    {
      pos: [4, 1, 4], 
      state: 4
    }, 
    {
      pos: [7, 1, 4], 
      state: 4
    }, 
    {
      pos: [8, 1, 4], 
      state: 0
    }, 
    {
      pos: [3, 1, 5], 
      state: 0
    }, 
    {
      pos: [8, 1, 5], 
      state: 0
    }, 
    {
      pos: [3, 1, 6], 
      state: 0
    }, 
    {
      pos: [8, 1, 6], 
      state: 0
    }, 
    {
      pos: [3, 1, 7], 
      state: 0
    }, 
    {
      pos: [4, 1, 7], 
      state: 4
    }, 
    {
      pos: [7, 1, 7], 
      state: 4
    }, 
    {
      pos: [8, 1, 7], 
      state: 0
    }, 
    {
      pos: [3, 1, 8], 
      state: 0
    }, 
    {
      pos: [4, 1, 8], 
      state: 0
    }, 
    {
      pos: [5, 1, 8], 
      state: 0
    }, 
    {
      pos: [6, 1, 8], 
      state: 0
    }, 
    {
      pos: [7, 1, 8], 
      state: 0
    }, 
    {
      pos: [8, 1, 8], 
      state: 0
    }, 
    {
      nbt: {
        target_pool: "minecraft:village/desert/zombie/streets", 
        final_state: "minecraft:structure_void", 
        id: "minecraft:jigsaw", 
        attachement_type: "minecraft:street"
      }, 
      pos: [6, 1, 0], 
      state: 5
    }, 
    {
      nbt: {
        id: "minecraft:bell"
      }, 
      pos: [3, 1, 1], 
      state: 6
    }, 
    {
      nbt: {
        target_pool: "minecraft:village/desert/zombie/streets", 
        final_state: "minecraft:structure_void", 
        id: "minecraft:jigsaw", 
        attachement_type: "minecraft:street"
      }, 
      pos: [0, 1, 5], 
      state: 7
    }, 
    {
      nbt: {
        target_pool: "minecraft:village/desert/zombie/streets", 
        final_state: "minecraft:structure_void", 
        id: "minecraft:jigsaw", 
        attachement_type: "minecraft:street"
      }, 
      pos: [11, 1, 6], 
      state: 8
    }, 
    {
      nbt: {
        target_pool: "minecraft:village/desert/zombie/streets", 
        final_state: "minecraft:structure_void", 
        id: "minecraft:jigsaw", 
        attachement_type: "minecraft:street"
      }, 
      pos: [5, 1, 11], 
      state: 9
    }, 
    {
      pos: [0, 1, 0], 
      state: 3
    }, 
    {
      pos: [1, 1, 0], 
      state: 3
    }, 
    {
      pos: [2, 1, 0], 
      state: 3
    }, 
    {
      pos: [3, 1, 0], 
      state: 3
    }, 
    {
      pos: [4, 1, 0], 
      state: 3
    }, 
    {
      pos: [5, 1, 0], 
      state: 3
    }, 
    {
      pos: [7, 1, 0], 
      state: 3
    }, 
    {
      pos: [8, 1, 0], 
      state: 3
    }, 
    {
      pos: [9, 1, 0], 
      state: 3
    }, 
    {
      pos: [10, 1, 0], 
      state: 3
    }, 
    {
      pos: [11, 1, 0], 
      state: 3
    }, 
    {
      pos: [0, 1, 1], 
      state: 3
    }, 
    {
      pos: [1, 1, 1], 
      state: 3
    }, 
    {
      pos: [2, 1, 1], 
      state: 3
    }, 
    {
      pos: [4, 1, 1], 
      state: 3
    }, 
    {
      pos: [5, 1, 1], 
      state: 3
    }, 
    {
      pos: [6, 1, 1], 
      state: 3
    }, 
    {
      pos: [7, 1, 1], 
      state: 3
    }, 
    {
      pos: [8, 1, 1], 
      state: 3
    }, 
    {
      pos: [9, 1, 1], 
      state: 3
    }, 
    {
      pos: [10, 1, 1], 
      state: 3
    }, 
    {
      pos: [11, 1, 1], 
      state: 3
    }, 
    {
      pos: [0, 1, 2], 
      state: 3
    }, 
    {
      pos: [1, 1, 2], 
      state: 3
    }, 
    {
      pos: [2, 1, 2], 
      state: 3
    }, 
    {
      pos: [3, 1, 2], 
      state: 3
    }, 
    {
      pos: [4, 1, 2], 
      state: 3
    }, 
    {
      pos: [5, 1, 2], 
      state: 3
    }, 
    {
      pos: [6, 1, 2], 
      state: 3
    }, 
    {
      pos: [7, 1, 2], 
      state: 3
    }, 
    {
      pos: [8, 1, 2], 
      state: 3
    }, 
    {
      pos: [9, 1, 2], 
      state: 3
    }, 
    {
      pos: [10, 1, 2], 
      state: 3
    }, 
    {
      pos: [11, 1, 2], 
      state: 3
    }, 
    {
      pos: [0, 1, 3], 
      state: 3
    }, 
    {
      pos: [1, 1, 3], 
      state: 3
    }, 
    {
      pos: [2, 1, 3], 
      state: 3
    }, 
    {
      pos: [9, 1, 3], 
      state: 3
    }, 
    {
      pos: [10, 1, 3], 
      state: 3
    }, 
    {
      pos: [11, 1, 3], 
      state: 3
    }, 
    {
      pos: [0, 1, 4], 
      state: 3
    }, 
    {
      pos: [1, 1, 4], 
      state: 3
    }, 
    {
      pos: [2, 1, 4], 
      state: 3
    }, 
    {
      pos: [5, 1, 4], 
      state: 10
    }, 
    {
      pos: [6, 1, 4], 
      state: 10
    }, 
    {
      pos: [9, 1, 4], 
      state: 3
    }, 
    {
      pos: [10, 1, 4], 
      state: 3
    }, 
    {
      pos: [11, 1, 4], 
      state: 3
    }, 
    {
      pos: [4, 1, 5], 
      state: 10
    }, 
    {
      pos: [5, 1, 5], 
      state: 10
    }, 
    {
      pos: [6, 1, 5], 
      state: 10
    }, 
    {
      pos: [7, 1, 5], 
      state: 10
    }, 
    {
      pos: [9, 1, 5], 
      state: 3
    }, 
    {
      pos: [10, 1, 5], 
      state: 3
    }, 
    {
      pos: [11, 1, 5], 
      state: 3
    }, 
    {
      pos: [1, 1, 6], 
      state: 3
    }, 
    {
      pos: [4, 1, 6], 
      state: 10
    }, 
    {
      pos: [5, 1, 6], 
      state: 10
    }, 
    {
      pos: [6, 1, 6], 
      state: 10
    }, 
    {
      pos: [7, 1, 6], 
      state: 10
    }, 
    {
      pos: [10, 1, 6], 
      state: 3
    }, 
    {
      pos: [0, 1, 7], 
      state: 3
    }, 
    {
      pos: [5, 1, 7], 
      state: 11
    }, 
    {
      pos: [6, 1, 7], 
      state: 11
    }, 
    {
      pos: [10, 1, 7], 
      state: 3
    }, 
    {
      pos: [11, 1, 7], 
      state: 3
    }, 
    {
      pos: [0, 1, 8], 
      state: 3
    }, 
    {
      pos: [2, 1, 8], 
      state: 3
    }, 
    {
      pos: [10, 1, 8], 
      state: 3
    }, 
    {
      pos: [11, 1, 8], 
      state: 3
    }, 
    {
      pos: [0, 1, 9], 
      state: 3
    }, 
    {
      pos: [3, 1, 9], 
      state: 3
    }, 
    {
      pos: [4, 1, 9], 
      state: 3
    }, 
    {
      pos: [9, 1, 9], 
      state: 3
    }, 
    {
      pos: [10, 1, 9], 
      state: 3
    }, 
    {
      pos: [11, 1, 9], 
      state: 3
    }, 
    {
      pos: [7, 1, 10], 
      state: 3
    }, 
    {
      pos: [8, 1, 10], 
      state: 3
    }, 
    {
      pos: [9, 1, 10], 
      state: 3
    }, 
    {
      pos: [10, 1, 10], 
      state: 3
    }, 
    {
      pos: [11, 1, 10], 
      state: 3
    }, 
    {
      pos: [6, 1, 11], 
      state: 3
    }, 
    {
      pos: [7, 1, 11], 
      state: 3
    }, 
    {
      pos: [8, 1, 11], 
      state: 3
    }, 
    {
      pos: [9, 1, 11], 
      state: 3
    }, 
    {
      pos: [10, 1, 11], 
      state: 3
    }, 
    {
      pos: [11, 1, 11], 
      state: 3
    }, 
    {
      pos: [4, 2, 4], 
      state: 4
    }, 
    {
      pos: [7, 2, 4], 
      state: 4
    }, 
    {
      pos: [4, 2, 7], 
      state: 4
    }, 
    {
      pos: [7, 2, 7], 
      state: 4
    }, 
    {
      pos: [0, 2, 0], 
      state: 3
    }, 
    {
      pos: [1, 2, 0], 
      state: 3
    }, 
    {
      pos: [2, 2, 0], 
      state: 3
    }, 
    {
      pos: [3, 2, 0], 
      state: 3
    }, 
    {
      pos: [4, 2, 0], 
      state: 3
    }, 
    {
      pos: [5, 2, 0], 
      state: 3
    }, 
    {
      pos: [6, 2, 0], 
      state: 3
    }, 
    {
      pos: [7, 2, 0], 
      state: 3
    }, 
    {
      pos: [8, 2, 0], 
      state: 3
    }, 
    {
      pos: [9, 2, 0], 
      state: 3
    }, 
    {
      pos: [10, 2, 0], 
      state: 3
    }, 
    {
      pos: [11, 2, 0], 
      state: 3
    }, 
    {
      pos: [0, 2, 1], 
      state: 3
    }, 
    {
      pos: [1, 2, 1], 
      state: 3
    }, 
    {
      pos: [2, 2, 1], 
      state: 3
    }, 
    {
      pos: [3, 2, 1], 
      state: 3
    }, 
    {
      pos: [4, 2, 1], 
      state: 3
    }, 
    {
      pos: [5, 2, 1], 
      state: 3
    }, 
    {
      pos: [6, 2, 1], 
      state: 3
    }, 
    {
      pos: [7, 2, 1], 
      state: 3
    }, 
    {
      pos: [8, 2, 1], 
      state: 3
    }, 
    {
      pos: [9, 2, 1], 
      state: 3
    }, 
    {
      pos: [10, 2, 1], 
      state: 3
    }, 
    {
      pos: [11, 2, 1], 
      state: 3
    }, 
    {
      pos: [0, 2, 2], 
      state: 3
    }, 
    {
      pos: [1, 2, 2], 
      state: 3
    }, 
    {
      pos: [2, 2, 2], 
      state: 3
    }, 
    {
      pos: [3, 2, 2], 
      state: 3
    }, 
    {
      pos: [4, 2, 2], 
      state: 3
    }, 
    {
      pos: [5, 2, 2], 
      state: 3
    }, 
    {
      pos: [6, 2, 2], 
      state: 3
    }, 
    {
      pos: [7, 2, 2], 
      state: 3
    }, 
    {
      pos: [8, 2, 2], 
      state: 3
    }, 
    {
      pos: [9, 2, 2], 
      state: 3
    }, 
    {
      pos: [10, 2, 2], 
      state: 3
    }, 
    {
      pos: [11, 2, 2], 
      state: 3
    }, 
    {
      pos: [0, 2, 3], 
      state: 3
    }, 
    {
      pos: [1, 2, 3], 
      state: 3
    }, 
    {
      pos: [2, 2, 3], 
      state: 3
    }, 
    {
      pos: [3, 2, 3], 
      state: 3
    }, 
    {
      pos: [4, 2, 3], 
      state: 3
    }, 
    {
      pos: [5, 2, 3], 
      state: 3
    }, 
    {
      pos: [6, 2, 3], 
      state: 3
    }, 
    {
      pos: [7, 2, 3], 
      state: 3
    }, 
    {
      pos: [8, 2, 3], 
      state: 3
    }, 
    {
      pos: [9, 2, 3], 
      state: 3
    }, 
    {
      pos: [10, 2, 3], 
      state: 3
    }, 
    {
      pos: [11, 2, 3], 
      state: 3
    }, 
    {
      pos: [0, 2, 4], 
      state: 3
    }, 
    {
      pos: [1, 2, 4], 
      state: 3
    }, 
    {
      pos: [2, 2, 4], 
      state: 3
    }, 
    {
      pos: [3, 2, 4], 
      state: 3
    }, 
    {
      pos: [5, 2, 4], 
      state: 3
    }, 
    {
      pos: [6, 2, 4], 
      state: 3
    }, 
    {
      pos: [8, 2, 4], 
      state: 3
    }, 
    {
      pos: [9, 2, 4], 
      state: 3
    }, 
    {
      pos: [10, 2, 4], 
      state: 3
    }, 
    {
      pos: [11, 2, 4], 
      state: 3
    }, 
    {
      pos: [1, 2, 5], 
      state: 3
    }, 
    {
      pos: [2, 2, 5], 
      state: 3
    }, 
    {
      pos: [10, 2, 5], 
      state: 3
    }, 
    {
      pos: [11, 2, 5], 
      state: 3
    }, 
    {
      pos: [1, 2, 6], 
      state: 3
    }, 
    {
      pos: [2, 2, 6], 
      state: 3
    }, 
    {
      pos: [9, 2, 6], 
      state: 3
    }, 
    {
      pos: [10, 2, 6], 
      state: 3
    }, 
    {
      pos: [11, 2, 6], 
      state: 3
    }, 
    {
      pos: [0, 2, 7], 
      state: 3
    }, 
    {
      pos: [1, 2, 7], 
      state: 3
    }, 
    {
      pos: [9, 2, 7], 
      state: 3
    }, 
    {
      pos: [10, 2, 7], 
      state: 3
    }, 
    {
      pos: [11, 2, 7], 
      state: 3
    }, 
    {
      pos: [1, 2, 8], 
      state: 3
    }, 
    {
      pos: [10, 2, 8], 
      state: 3
    }, 
    {
      pos: [11, 2, 8], 
      state: 3
    }, 
    {
      pos: [1, 2, 9], 
      state: 3
    }, 
    {
      pos: [3, 2, 9], 
      state: 3
    }, 
    {
      pos: [4, 2, 9], 
      state: 3
    }, 
    {
      pos: [5, 2, 9], 
      state: 3
    }, 
    {
      pos: [6, 2, 9], 
      state: 3
    }, 
    {
      pos: [7, 2, 9], 
      state: 3
    }, 
    {
      pos: [8, 2, 9], 
      state: 3
    }, 
    {
      pos: [9, 2, 9], 
      state: 3
    }, 
    {
      pos: [10, 2, 9], 
      state: 3
    }, 
    {
      pos: [11, 2, 9], 
      state: 3
    }, 
    {
      pos: [7, 2, 10], 
      state: 3
    }, 
    {
      pos: [8, 2, 10], 
      state: 3
    }, 
    {
      pos: [9, 2, 10], 
      state: 3
    }, 
    {
      pos: [10, 2, 10], 
      state: 3
    }, 
    {
      pos: [11, 2, 10], 
      state: 3
    }, 
    {
      pos: [2, 2, 11], 
      state: 3
    }, 
    {
      pos: [9, 2, 11], 
      state: 3
    }, 
    {
      pos: [10, 2, 11], 
      state: 3
    }, 
    {
      pos: [11, 2, 11], 
      state: 3
    }, 
    {
      pos: [4, 3, 4], 
      state: 4
    }, 
    {
      pos: [7, 3, 4], 
      state: 4
    }, 
    {
      pos: [4, 3, 7], 
      state: 4
    }, 
    {
      pos: [7, 3, 7], 
      state: 4
    }, 
    {
      pos: [0, 3, 0], 
      state: 3
    }, 
    {
      pos: [1, 3, 0], 
      state: 3
    }, 
    {
      pos: [2, 3, 0], 
      state: 3
    }, 
    {
      pos: [3, 3, 0], 
      state: 3
    }, 
    {
      pos: [4, 3, 0], 
      state: 3
    }, 
    {
      pos: [5, 3, 0], 
      state: 3
    }, 
    {
      pos: [6, 3, 0], 
      state: 3
    }, 
    {
      pos: [7, 3, 0], 
      state: 3
    }, 
    {
      pos: [8, 3, 0], 
      state: 3
    }, 
    {
      pos: [9, 3, 0], 
      state: 3
    }, 
    {
      pos: [10, 3, 0], 
      state: 3
    }, 
    {
      pos: [11, 3, 0], 
      state: 3
    }, 
    {
      pos: [0, 3, 1], 
      state: 3
    }, 
    {
      pos: [1, 3, 1], 
      state: 3
    }, 
    {
      pos: [2, 3, 1], 
      state: 3
    }, 
    {
      pos: [3, 3, 1], 
      state: 3
    }, 
    {
      pos: [4, 3, 1], 
      state: 3
    }, 
    {
      pos: [5, 3, 1], 
      state: 3
    }, 
    {
      pos: [6, 3, 1], 
      state: 3
    }, 
    {
      pos: [7, 3, 1], 
      state: 3
    }, 
    {
      pos: [8, 3, 1], 
      state: 3
    }, 
    {
      pos: [9, 3, 1], 
      state: 3
    }, 
    {
      pos: [10, 3, 1], 
      state: 3
    }, 
    {
      pos: [11, 3, 1], 
      state: 3
    }, 
    {
      pos: [0, 3, 2], 
      state: 3
    }, 
    {
      pos: [1, 3, 2], 
      state: 3
    }, 
    {
      pos: [2, 3, 2], 
      state: 3
    }, 
    {
      pos: [3, 3, 2], 
      state: 3
    }, 
    {
      pos: [4, 3, 2], 
      state: 3
    }, 
    {
      pos: [5, 3, 2], 
      state: 3
    }, 
    {
      pos: [6, 3, 2], 
      state: 3
    }, 
    {
      pos: [7, 3, 2], 
      state: 3
    }, 
    {
      pos: [8, 3, 2], 
      state: 3
    }, 
    {
      pos: [9, 3, 2], 
      state: 3
    }, 
    {
      pos: [10, 3, 2], 
      state: 3
    }, 
    {
      pos: [11, 3, 2], 
      state: 3
    }, 
    {
      pos: [0, 3, 3], 
      state: 3
    }, 
    {
      pos: [1, 3, 3], 
      state: 3
    }, 
    {
      pos: [2, 3, 3], 
      state: 3
    }, 
    {
      pos: [3, 3, 3], 
      state: 3
    }, 
    {
      pos: [4, 3, 3], 
      state: 3
    }, 
    {
      pos: [5, 3, 3], 
      state: 3
    }, 
    {
      pos: [6, 3, 3], 
      state: 3
    }, 
    {
      pos: [7, 3, 3], 
      state: 3
    }, 
    {
      pos: [8, 3, 3], 
      state: 3
    }, 
    {
      pos: [9, 3, 3], 
      state: 3
    }, 
    {
      pos: [10, 3, 3], 
      state: 3
    }, 
    {
      pos: [11, 3, 3], 
      state: 3
    }, 
    {
      pos: [0, 3, 4], 
      state: 3
    }, 
    {
      pos: [1, 3, 4], 
      state: 3
    }, 
    {
      pos: [2, 3, 4], 
      state: 3
    }, 
    {
      pos: [3, 3, 4], 
      state: 3
    }, 
    {
      pos: [5, 3, 4], 
      state: 3
    }, 
    {
      pos: [6, 3, 4], 
      state: 3
    }, 
    {
      pos: [8, 3, 4], 
      state: 3
    }, 
    {
      pos: [9, 3, 4], 
      state: 3
    }, 
    {
      pos: [10, 3, 4], 
      state: 3
    }, 
    {
      pos: [11, 3, 4], 
      state: 3
    }, 
    {
      pos: [10, 3, 5], 
      state: 3
    }, 
    {
      pos: [11, 3, 5], 
      state: 3
    }, 
    {
      pos: [10, 3, 6], 
      state: 3
    }, 
    {
      pos: [11, 3, 6], 
      state: 3
    }, 
    {
      pos: [10, 3, 7], 
      state: 3
    }, 
    {
      pos: [11, 3, 7], 
      state: 3
    }, 
    {
      pos: [10, 3, 8], 
      state: 3
    }, 
    {
      pos: [11, 3, 8], 
      state: 3
    }, 
    {
      pos: [10, 3, 9], 
      state: 3
    }, 
    {
      pos: [11, 3, 9], 
      state: 3
    }, 
    {
      pos: [10, 3, 10], 
      state: 3
    }, 
    {
      pos: [11, 3, 10], 
      state: 3
    }, 
    {
      pos: [10, 3, 11], 
      state: 3
    }, 
    {
      pos: [11, 3, 11], 
      state: 3
    }, 
    {
      pos: [4, 4, 4], 
      state: 4
    }, 
    {
      pos: [7, 4, 4], 
      state: 4
    }, 
    {
      pos: [5, 4, 5], 
      state: 12
    }, 
    {
      pos: [6, 4, 5], 
      state: 12
    }, 
    {
      pos: [5, 4, 6], 
      state: 12
    }, 
    {
      pos: [6, 4, 6], 
      state: 12
    }, 
    {
      pos: [4, 4, 7], 
      state: 4
    }, 
    {
      pos: [7, 4, 7], 
      state: 4
    }, 
    {
      pos: [0, 4, 0], 
      state: 3
    }, 
    {
      pos: [1, 4, 0], 
      state: 3
    }, 
    {
      pos: [2, 4, 0], 
      state: 3
    }, 
    {
      pos: [3, 4, 0], 
      state: 3
    }, 
    {
      pos: [4, 4, 0], 
      state: 3
    }, 
    {
      pos: [5, 4, 0], 
      state: 3
    }, 
    {
      pos: [6, 4, 0], 
      state: 3
    }, 
    {
      pos: [7, 4, 0], 
      state: 3
    }, 
    {
      pos: [8, 4, 0], 
      state: 3
    }, 
    {
      pos: [9, 4, 0], 
      state: 3
    }, 
    {
      pos: [10, 4, 0], 
      state: 3
    }, 
    {
      pos: [11, 4, 0], 
      state: 3
    }, 
    {
      pos: [0, 4, 1], 
      state: 3
    }, 
    {
      pos: [1, 4, 1], 
      state: 3
    }, 
    {
      pos: [2, 4, 1], 
      state: 3
    }, 
    {
      pos: [3, 4, 1], 
      state: 3
    }, 
    {
      pos: [4, 4, 1], 
      state: 3
    }, 
    {
      pos: [5, 4, 1], 
      state: 3
    }, 
    {
      pos: [6, 4, 1], 
      state: 3
    }, 
    {
      pos: [7, 4, 1], 
      state: 3
    }, 
    {
      pos: [8, 4, 1], 
      state: 3
    }, 
    {
      pos: [9, 4, 1], 
      state: 3
    }, 
    {
      pos: [10, 4, 1], 
      state: 3
    }, 
    {
      pos: [11, 4, 1], 
      state: 3
    }, 
    {
      pos: [0, 4, 2], 
      state: 3
    }, 
    {
      pos: [1, 4, 2], 
      state: 3
    }, 
    {
      pos: [2, 4, 2], 
      state: 3
    }, 
    {
      pos: [3, 4, 2], 
      state: 3
    }, 
    {
      pos: [4, 4, 2], 
      state: 3
    }, 
    {
      pos: [5, 4, 2], 
      state: 3
    }, 
    {
      pos: [6, 4, 2], 
      state: 3
    }, 
    {
      pos: [7, 4, 2], 
      state: 3
    }, 
    {
      pos: [8, 4, 2], 
      state: 3
    }, 
    {
      pos: [9, 4, 2], 
      state: 3
    }, 
    {
      pos: [10, 4, 2], 
      state: 3
    }, 
    {
      pos: [11, 4, 2], 
      state: 3
    }, 
    {
      pos: [0, 4, 3], 
      state: 3
    }, 
    {
      pos: [1, 4, 3], 
      state: 3
    }, 
    {
      pos: [2, 4, 3], 
      state: 3
    }, 
    {
      pos: [3, 4, 3], 
      state: 3
    }, 
    {
      pos: [4, 4, 3], 
      state: 3
    }, 
    {
      pos: [5, 4, 3], 
      state: 3
    }, 
    {
      pos: [6, 4, 3], 
      state: 3
    }, 
    {
      pos: [7, 4, 3], 
      state: 3
    }, 
    {
      pos: [8, 4, 3], 
      state: 3
    }, 
    {
      pos: [9, 4, 3], 
      state: 3
    }, 
    {
      pos: [10, 4, 3], 
      state: 3
    }, 
    {
      pos: [11, 4, 3], 
      state: 3
    }, 
    {
      pos: [0, 4, 4], 
      state: 3
    }, 
    {
      pos: [1, 4, 4], 
      state: 3
    }, 
    {
      pos: [2, 4, 4], 
      state: 3
    }, 
    {
      pos: [3, 4, 4], 
      state: 3
    }, 
    {
      pos: [5, 4, 4], 
      state: 13
    }, 
    {
      pos: [6, 4, 4], 
      state: 13
    }, 
    {
      pos: [8, 4, 4], 
      state: 3
    }, 
    {
      pos: [9, 4, 4], 
      state: 3
    }, 
    {
      pos: [10, 4, 4], 
      state: 3
    }, 
    {
      pos: [11, 4, 4], 
      state: 3
    }, 
    {
      pos: [4, 4, 5], 
      state: 13
    }, 
    {
      pos: [7, 4, 5], 
      state: 13
    }, 
    {
      pos: [10, 4, 5], 
      state: 3
    }, 
    {
      pos: [11, 4, 5], 
      state: 3
    }, 
    {
      pos: [4, 4, 6], 
      state: 13
    }, 
    {
      pos: [7, 4, 6], 
      state: 13
    }, 
    {
      pos: [10, 4, 6], 
      state: 3
    }, 
    {
      pos: [11, 4, 6], 
      state: 3
    }, 
    {
      pos: [5, 4, 7], 
      state: 13
    }, 
    {
      pos: [6, 4, 7], 
      state: 13
    }, 
    {
      pos: [10, 4, 7], 
      state: 3
    }, 
    {
      pos: [11, 4, 7], 
      state: 3
    }, 
    {
      pos: [10, 4, 8], 
      state: 3
    }, 
    {
      pos: [11, 4, 8], 
      state: 3
    }, 
    {
      pos: [10, 4, 9], 
      state: 3
    }, 
    {
      pos: [11, 4, 9], 
      state: 3
    }, 
    {
      pos: [10, 4, 10], 
      state: 3
    }, 
    {
      pos: [11, 4, 10], 
      state: 3
    }, 
    {
      pos: [10, 4, 11], 
      state: 3
    }, 
    {
      pos: [11, 4, 11], 
      state: 3
    }, 
    {
      pos: [0, 5, 0], 
      state: 3
    }, 
    {
      pos: [1, 5, 0], 
      state: 3
    }, 
    {
      pos: [2, 5, 0], 
      state: 3
    }, 
    {
      pos: [3, 5, 0], 
      state: 3
    }, 
    {
      pos: [4, 5, 0], 
      state: 3
    }, 
    {
      pos: [5, 5, 0], 
      state: 3
    }, 
    {
      pos: [6, 5, 0], 
      state: 3
    }, 
    {
      pos: [7, 5, 0], 
      state: 3
    }, 
    {
      pos: [8, 5, 0], 
      state: 3
    }, 
    {
      pos: [9, 5, 0], 
      state: 3
    }, 
    {
      pos: [10, 5, 0], 
      state: 3
    }, 
    {
      pos: [11, 5, 0], 
      state: 3
    }, 
    {
      pos: [0, 5, 1], 
      state: 3
    }, 
    {
      pos: [1, 5, 1], 
      state: 3
    }, 
    {
      pos: [2, 5, 1], 
      state: 3
    }, 
    {
      pos: [3, 5, 1], 
      state: 3
    }, 
    {
      pos: [4, 5, 1], 
      state: 3
    }, 
    {
      pos: [5, 5, 1], 
      state: 3
    }, 
    {
      pos: [6, 5, 1], 
      state: 3
    }, 
    {
      pos: [7, 5, 1], 
      state: 3
    }, 
    {
      pos: [8, 5, 1], 
      state: 3
    }, 
    {
      pos: [9, 5, 1], 
      state: 3
    }, 
    {
      pos: [10, 5, 1], 
      state: 3
    }, 
    {
      pos: [11, 5, 1], 
      state: 3
    }, 
    {
      pos: [0, 5, 2], 
      state: 3
    }, 
    {
      pos: [1, 5, 2], 
      state: 3
    }, 
    {
      pos: [2, 5, 2], 
      state: 3
    }, 
    {
      pos: [3, 5, 2], 
      state: 3
    }, 
    {
      pos: [4, 5, 2], 
      state: 3
    }, 
    {
      pos: [5, 5, 2], 
      state: 3
    }, 
    {
      pos: [6, 5, 2], 
      state: 3
    }, 
    {
      pos: [7, 5, 2], 
      state: 3
    }, 
    {
      pos: [8, 5, 2], 
      state: 3
    }, 
    {
      pos: [9, 5, 2], 
      state: 3
    }, 
    {
      pos: [10, 5, 2], 
      state: 3
    }, 
    {
      pos: [11, 5, 2], 
      state: 3
    }, 
    {
      pos: [0, 5, 3], 
      state: 3
    }, 
    {
      pos: [1, 5, 3], 
      state: 3
    }, 
    {
      pos: [2, 5, 3], 
      state: 3
    }, 
    {
      pos: [3, 5, 3], 
      state: 3
    }, 
    {
      pos: [4, 5, 3], 
      state: 3
    }, 
    {
      pos: [5, 5, 3], 
      state: 3
    }, 
    {
      pos: [6, 5, 3], 
      state: 3
    }, 
    {
      pos: [7, 5, 3], 
      state: 3
    }, 
    {
      pos: [8, 5, 3], 
      state: 3
    }, 
    {
      pos: [9, 5, 3], 
      state: 3
    }, 
    {
      pos: [10, 5, 3], 
      state: 3
    }, 
    {
      pos: [11, 5, 3], 
      state: 3
    }, 
    {
      pos: [0, 5, 4], 
      state: 3
    }, 
    {
      pos: [1, 5, 4], 
      state: 3
    }, 
    {
      pos: [2, 5, 4], 
      state: 3
    }, 
    {
      pos: [3, 5, 4], 
      state: 3
    }, 
    {
      pos: [4, 5, 4], 
      state: 14
    }, 
    {
      pos: [5, 5, 4], 
      state: 3
    }, 
    {
      pos: [6, 5, 4], 
      state: 3
    }, 
    {
      pos: [7, 5, 4], 
      state: 14
    }, 
    {
      pos: [8, 5, 4], 
      state: 3
    }, 
    {
      pos: [9, 5, 4], 
      state: 3
    }, 
    {
      pos: [10, 5, 4], 
      state: 3
    }, 
    {
      pos: [11, 5, 4], 
      state: 3
    }, 
    {
      pos: [10, 5, 5], 
      state: 3
    }, 
    {
      pos: [11, 5, 5], 
      state: 3
    }, 
    {
      pos: [10, 5, 6], 
      state: 3
    }, 
    {
      pos: [11, 5, 6], 
      state: 3
    }, 
    {
      pos: [4, 5, 7], 
      state: 14
    }, 
    {
      pos: [7, 5, 7], 
      state: 14
    }, 
    {
      pos: [10, 5, 7], 
      state: 3
    }, 
    {
      pos: [11, 5, 7], 
      state: 3
    }, 
    {
      pos: [10, 5, 8], 
      state: 3
    }, 
    {
      pos: [11, 5, 8], 
      state: 3
    }, 
    {
      pos: [10, 5, 9], 
      state: 3
    }, 
    {
      pos: [11, 5, 9], 
      state: 3
    }, 
    {
      pos: [10, 5, 10], 
      state: 3
    }, 
    {
      pos: [11, 5, 10], 
      state: 3
    }, 
    {
      pos: [10, 5, 11], 
      state: 3
    }, 
    {
      pos: [11, 5, 11], 
      state: 3
    }
  ], 
  palette: [
    {
      Name: "minecraft:smooth_sandstone"
    }, 
    {
      Name: "minecraft:sand"
    }, 
    {
      Properties: {
        facing: "up"
      }, 
      Name: "minecraft:jigsaw"
    }, 
    {
      Name: "minecraft:air"
    }, 
    {
      Name: "minecraft:cut_sandstone"
    }, 
    {
      Properties: {
        facing: "north"
      }, 
      Name: "minecraft:jigsaw"
    }, 
    {
      Properties: {
        attachment: "floor", 
        powered: "false", 
        facing: "south"
      }, 
      Name: "minecraft:bell"
    }, 
    {
      Properties: {
        facing: "west"
      }, 
      Name: "minecraft:jigsaw"
    }, 
    {
      Properties: {
        facing: "east"
      }, 
      Name: "minecraft:jigsaw"
    }, 
    {
      Properties: {
        facing: "south"
      }, 
      Name: "minecraft:jigsaw"
    }, 
    {
      Properties: {
        level: "0"
      }, 
      Name: "minecraft:water"
    }, 
    {
      Properties: {
        level: "1"
      }, 
      Name: "minecraft:water"
    }, 
    {
      Properties: {
        waterlogged: "false", 
        type: "double"
      }, 
      Name: "minecraft:smooth_sandstone_slab"
    }, 
    {
      Properties: {
        waterlogged: "false", 
        type: "bottom"
      }, 
      Name: "minecraft:smooth_sandstone_slab"
    }, 
    {
      Name: "minecraft:torch"
    }
  ]
}
