{
  size: [10, 10, 10], 
  entities: [], 
  blocks: [
    {
      pos: [1, 0, 1], 
      state: 0
    }, 
    {
      pos: [2, 0, 1], 
      state: 0
    }, 
    {
      pos: [3, 0, 1], 
      state: 0
    }, 
    {
      pos: [4, 0, 1], 
      state: 0
    }, 
    {
      pos: [5, 0, 1], 
      state: 0
    }, 
    {
      pos: [6, 0, 1], 
      state: 0
    }, 
    {
      pos: [7, 0, 1], 
      state: 0
    }, 
    {
      pos: [8, 0, 1], 
      state: 0
    }, 
    {
      pos: [1, 0, 2], 
      state: 0
    }, 
    {
      pos: [2, 0, 2], 
      state: 0
    }, 
    {
      pos: [3, 0, 2], 
      state: 0
    }, 
    {
      pos: [4, 0, 2], 
      state: 0
    }, 
    {
      pos: [5, 0, 2], 
      state: 0
    }, 
    {
      pos: [6, 0, 2], 
      state: 0
    }, 
    {
      pos: [7, 0, 2], 
      state: 0
    }, 
    {
      pos: [8, 0, 2], 
      state: 0
    }, 
    {
      pos: [1, 0, 3], 
      state: 0
    }, 
    {
      pos: [2, 0, 3], 
      state: 0
    }, 
    {
      pos: [3, 0, 3], 
      state: 0
    }, 
    {
      pos: [4, 0, 3], 
      state: 0
    }, 
    {
      pos: [5, 0, 3], 
      state: 0
    }, 
    {
      pos: [6, 0, 3], 
      state: 0
    }, 
    {
      pos: [7, 0, 3], 
      state: 0
    }, 
    {
      pos: [8, 0, 3], 
      state: 0
    }, 
    {
      pos: [0, 0, 4], 
      state: 0
    }, 
    {
      pos: [1, 0, 4], 
      state: 0
    }, 
    {
      pos: [2, 0, 4], 
      state: 0
    }, 
    {
      pos: [3, 0, 4], 
      state: 0
    }, 
    {
      pos: [4, 0, 4], 
      state: 0
    }, 
    {
      pos: [5, 0, 4], 
      state: 0
    }, 
    {
      pos: [6, 0, 4], 
      state: 0
    }, 
    {
      pos: [7, 0, 4], 
      state: 0
    }, 
    {
      pos: [8, 0, 4], 
      state: 0
    }, 
    {
      pos: [0, 0, 5], 
      state: 0
    }, 
    {
      pos: [1, 0, 5], 
      state: 0
    }, 
    {
      pos: [2, 0, 5], 
      state: 0
    }, 
    {
      pos: [3, 0, 5], 
      state: 0
    }, 
    {
      pos: [4, 0, 5], 
      state: 0
    }, 
    {
      pos: [5, 0, 5], 
      state: 0
    }, 
    {
      pos: [6, 0, 5], 
      state: 0
    }, 
    {
      pos: [7, 0, 5], 
      state: 0
    }, 
    {
      pos: [8, 0, 5], 
      state: 0
    }, 
    {
      pos: [1, 0, 6], 
      state: 0
    }, 
    {
      pos: [2, 0, 6], 
      state: 0
    }, 
    {
      pos: [3, 0, 6], 
      state: 0
    }, 
    {
      pos: [4, 0, 6], 
      state: 0
    }, 
    {
      pos: [5, 0, 6], 
      state: 0
    }, 
    {
      pos: [6, 0, 6], 
      state: 0
    }, 
    {
      pos: [7, 0, 6], 
      state: 0
    }, 
    {
      pos: [8, 0, 6], 
      state: 0
    }, 
    {
      pos: [1, 0, 7], 
      state: 0
    }, 
    {
      pos: [2, 0, 7], 
      state: 0
    }, 
    {
      pos: [3, 0, 7], 
      state: 0
    }, 
    {
      pos: [4, 0, 7], 
      state: 0
    }, 
    {
      pos: [5, 0, 7], 
      state: 0
    }, 
    {
      pos: [6, 0, 7], 
      state: 0
    }, 
    {
      pos: [7, 0, 7], 
      state: 0
    }, 
    {
      pos: [8, 0, 7], 
      state: 0
    }, 
    {
      pos: [1, 0, 8], 
      state: 0
    }, 
    {
      pos: [2, 0, 8], 
      state: 0
    }, 
    {
      pos: [3, 0, 8], 
      state: 0
    }, 
    {
      pos: [4, 0, 8], 
      state: 0
    }, 
    {
      pos: [5, 0, 8], 
      state: 0
    }, 
    {
      pos: [6, 0, 8], 
      state: 0
    }, 
    {
      pos: [7, 0, 8], 
      state: 0
    }, 
    {
      pos: [8, 0, 8], 
      state: 0
    }, 
    {
      pos: [4, 0, 9], 
      state: 0
    }, 
    {
      pos: [5, 0, 9], 
      state: 0
    }, 
    {
      pos: [1, 1, 1], 
      state: 0
    }, 
    {
      pos: [2, 1, 1], 
      state: 0
    }, 
    {
      pos: [3, 1, 1], 
      state: 0
    }, 
    {
      pos: [4, 1, 1], 
      state: 1
    }, 
    {
      pos: [5, 1, 1], 
      state: 2
    }, 
    {
      pos: [8, 1, 1], 
      state: 0
    }, 
    {
      pos: [1, 1, 2], 
      state: 0
    }, 
    {
      pos: [2, 1, 2], 
      state: 0
    }, 
    {
      pos: [3, 1, 2], 
      state: 0
    }, 
    {
      pos: [4, 1, 2], 
      state: 0
    }, 
    {
      pos: [5, 1, 2], 
      state: 2
    }, 
    {
      pos: [6, 1, 2], 
      state: 0
    }, 
    {
      pos: [7, 1, 2], 
      state: 1
    }, 
    {
      pos: [8, 1, 2], 
      state: 1
    }, 
    {
      pos: [1, 1, 3], 
      state: 0
    }, 
    {
      pos: [2, 1, 3], 
      state: 3
    }, 
    {
      pos: [3, 1, 3], 
      state: 3
    }, 
    {
      pos: [4, 1, 3], 
      state: 2
    }, 
    {
      pos: [5, 1, 3], 
      state: 2
    }, 
    {
      pos: [6, 1, 3], 
      state: 3
    }, 
    {
      pos: [7, 1, 3], 
      state: 1
    }, 
    {
      pos: [8, 1, 3], 
      state: 1
    }, 
    {
      pos: [0, 1, 4], 
      state: 0
    }, 
    {
      pos: [1, 1, 4], 
      state: 0
    }, 
    {
      pos: [2, 1, 4], 
      state: 3
    }, 
    {
      pos: [3, 1, 4], 
      state: 3
    }, 
    {
      pos: [4, 1, 4], 
      state: 0
    }, 
    {
      pos: [5, 1, 4], 
      state: 0
    }, 
    {
      pos: [6, 1, 4], 
      state: 0
    }, 
    {
      pos: [7, 1, 4], 
      state: 3
    }, 
    {
      pos: [8, 1, 4], 
      state: 3
    }, 
    {
      pos: [1, 1, 5], 
      state: 0
    }, 
    {
      pos: [2, 1, 5], 
      state: 3
    }, 
    {
      pos: [3, 1, 5], 
      state: 3
    }, 
    {
      pos: [4, 1, 5], 
      state: 0
    }, 
    {
      pos: [5, 1, 5], 
      state: 0
    }, 
    {
      pos: [7, 1, 5], 
      state: 1
    }, 
    {
      pos: [8, 1, 5], 
      state: 3
    }, 
    {
      pos: [1, 1, 6], 
      state: 0
    }, 
    {
      pos: [3, 1, 6], 
      state: 0
    }, 
    {
      pos: [4, 1, 6], 
      state: 3
    }, 
    {
      pos: [5, 1, 6], 
      state: 0
    }, 
    {
      pos: [6, 1, 6], 
      state: 1
    }, 
    {
      pos: [8, 1, 6], 
      state: 1
    }, 
    {
      pos: [1, 1, 7], 
      state: 0
    }, 
    {
      pos: [2, 1, 7], 
      state: 0
    }, 
    {
      pos: [3, 1, 7], 
      state: 0
    }, 
    {
      pos: [4, 1, 7], 
      state: 3
    }, 
    {
      pos: [5, 1, 7], 
      state: 1
    }, 
    {
      pos: [6, 1, 7], 
      state: 0
    }, 
    {
      pos: [7, 1, 7], 
      state: 0
    }, 
    {
      pos: [8, 1, 7], 
      state: 1
    }, 
    {
      pos: [1, 1, 8], 
      state: 0
    }, 
    {
      pos: [2, 1, 8], 
      state: 0
    }, 
    {
      pos: [3, 1, 8], 
      state: 0
    }, 
    {
      pos: [4, 1, 8], 
      state: 0
    }, 
    {
      pos: [5, 1, 8], 
      state: 0
    }, 
    {
      pos: [6, 1, 8], 
      state: 0
    }, 
    {
      pos: [7, 1, 8], 
      state: 0
    }, 
    {
      pos: [8, 1, 8], 
      state: 0
    }, 
    {
      pos: [4, 1, 9], 
      state: 0
    }, 
    {
      pos: [5, 1, 9], 
      state: 0
    }, 
    {
      nbt: {
        joint: "rollable", 
        final_state: "minecraft:air", 
        name: "minecraft:extension_connector", 
        pool: "minecraft:empty", 
        id: "minecraft:jigsaw", 
        target: "minecraft:empty"
      }, 
      pos: [0, 1, 5], 
      state: 4
    }, 
    {
      pos: [1, 2, 1], 
      state: 3
    }, 
    {
      pos: [3, 2, 1], 
      state: 3
    }, 
    {
      pos: [6, 2, 1], 
      state: 1
    }, 
    {
      pos: [8, 2, 1], 
      state: 0
    }, 
    {
      pos: [8, 2, 3], 
      state: 0
    }, 
    {
      pos: [4, 2, 4], 
      state: 0
    }, 
    {
      pos: [5, 2, 4], 
      state: 0
    }, 
    {
      pos: [4, 2, 5], 
      state: 1
    }, 
    {
      pos: [5, 2, 5], 
      state: 0
    }, 
    {
      pos: [1, 2, 6], 
      state: 0
    }, 
    {
      pos: [8, 2, 6], 
      state: 0
    }, 
    {
      pos: [6, 2, 7], 
      state: 3
    }, 
    {
      pos: [7, 2, 7], 
      state: 1
    }, 
    {
      pos: [1, 2, 8], 
      state: 0
    }, 
    {
      pos: [8, 2, 8], 
      state: 0
    }, 
    {
      pos: [6, 3, 1], 
      state: 1
    }, 
    {
      pos: [8, 3, 1], 
      state: 0
    }, 
    {
      pos: [1, 3, 3], 
      state: 3
    }, 
    {
      pos: [8, 3, 3], 
      state: 0
    }, 
    {
      pos: [4, 3, 4], 
      state: 5
    }, 
    {
      pos: [5, 3, 4], 
      state: 5
    }, 
    {
      pos: [4, 3, 5], 
      state: 5
    }, 
    {
      pos: [5, 3, 5], 
      state: 5
    }, 
    {
      pos: [1, 3, 6], 
      state: 0
    }, 
    {
      pos: [8, 3, 6], 
      state: 0
    }, 
    {
      pos: [3, 3, 8], 
      state: 0
    }, 
    {
      pos: [8, 3, 8], 
      state: 0
    }, 
    {
      pos: [1, 4, 1], 
      state: 0
    }, 
    {
      pos: [3, 4, 1], 
      state: 3
    }, 
    {
      pos: [6, 4, 1], 
      state: 0
    }, 
    {
      pos: [8, 4, 1], 
      state: 3
    }, 
    {
      pos: [1, 4, 3], 
      state: 0
    }, 
    {
      pos: [8, 4, 3], 
      state: 0
    }, 
    {
      pos: [1, 4, 6], 
      state: 0
    }, 
    {
      pos: [8, 4, 6], 
      state: 0
    }, 
    {
      pos: [3, 4, 8], 
      state: 0
    }, 
    {
      pos: [6, 4, 8], 
      state: 0
    }, 
    {
      pos: [8, 4, 8], 
      state: 0
    }, 
    {
      pos: [4, 4, 4], 
      state: 6
    }, 
    {
      pos: [5, 4, 4], 
      state: 6
    }, 
    {
      pos: [4, 4, 5], 
      state: 6
    }, 
    {
      pos: [5, 4, 5], 
      state: 6
    }, 
    {
      pos: [1, 5, 1], 
      state: 0
    }, 
    {
      pos: [2, 5, 1], 
      state: 0
    }, 
    {
      pos: [3, 5, 1], 
      state: 3
    }, 
    {
      pos: [4, 5, 1], 
      state: 0
    }, 
    {
      pos: [5, 5, 1], 
      state: 0
    }, 
    {
      pos: [6, 5, 1], 
      state: 0
    }, 
    {
      pos: [7, 5, 1], 
      state: 0
    }, 
    {
      pos: [8, 5, 1], 
      state: 3
    }, 
    {
      pos: [1, 5, 2], 
      state: 0
    }, 
    {
      pos: [2, 5, 2], 
      state: 0
    }, 
    {
      pos: [3, 5, 2], 
      state: 0
    }, 
    {
      pos: [4, 5, 2], 
      state: 0
    }, 
    {
      pos: [5, 5, 2], 
      state: 0
    }, 
    {
      pos: [6, 5, 2], 
      state: 0
    }, 
    {
      pos: [7, 5, 2], 
      state: 0
    }, 
    {
      pos: [8, 5, 2], 
      state: 0
    }, 
    {
      pos: [1, 5, 3], 
      state: 0
    }, 
    {
      pos: [2, 5, 3], 
      state: 0
    }, 
    {
      pos: [7, 5, 3], 
      state: 0
    }, 
    {
      pos: [8, 5, 3], 
      state: 3
    }, 
    {
      pos: [1, 5, 4], 
      state: 0
    }, 
    {
      pos: [2, 5, 4], 
      state: 0
    }, 
    {
      pos: [7, 5, 4], 
      state: 0
    }, 
    {
      pos: [1, 5, 5], 
      state: 0
    }, 
    {
      pos: [2, 5, 5], 
      state: 0
    }, 
    {
      pos: [7, 5, 5], 
      state: 0
    }, 
    {
      pos: [8, 5, 5], 
      state: 0
    }, 
    {
      pos: [1, 5, 6], 
      state: 0
    }, 
    {
      pos: [2, 5, 6], 
      state: 0
    }, 
    {
      pos: [7, 5, 6], 
      state: 0
    }, 
    {
      pos: [8, 5, 6], 
      state: 0
    }, 
    {
      pos: [1, 5, 7], 
      state: 0
    }, 
    {
      pos: [2, 5, 7], 
      state: 0
    }, 
    {
      pos: [3, 5, 7], 
      state: 0
    }, 
    {
      pos: [4, 5, 7], 
      state: 0
    }, 
    {
      pos: [5, 5, 7], 
      state: 0
    }, 
    {
      pos: [6, 5, 7], 
      state: 0
    }, 
    {
      pos: [7, 5, 7], 
      state: 0
    }, 
    {
      pos: [8, 5, 7], 
      state: 3
    }, 
    {
      pos: [1, 5, 8], 
      state: 0
    }, 
    {
      pos: [2, 5, 8], 
      state: 0
    }, 
    {
      pos: [3, 5, 8], 
      state: 0
    }, 
    {
      pos: [4, 5, 8], 
      state: 0
    }, 
    {
      pos: [5, 5, 8], 
      state: 0
    }, 
    {
      pos: [6, 5, 8], 
      state: 3
    }, 
    {
      pos: [7, 5, 8], 
      state: 0
    }, 
    {
      pos: [8, 5, 8], 
      state: 3
    }, 
    {
      pos: [1, 6, 1], 
      state: 0
    }, 
    {
      pos: [2, 6, 1], 
      state: 0
    }, 
    {
      pos: [3, 6, 1], 
      state: 0
    }, 
    {
      pos: [4, 6, 1], 
      state: 0
    }, 
    {
      pos: [5, 6, 1], 
      state: 3
    }, 
    {
      pos: [6, 6, 1], 
      state: 3
    }, 
    {
      pos: [7, 6, 1], 
      state: 3
    }, 
    {
      pos: [8, 6, 1], 
      state: 3
    }, 
    {
      pos: [1, 6, 2], 
      state: 0
    }, 
    {
      pos: [2, 6, 2], 
      state: 0
    }, 
    {
      pos: [3, 6, 2], 
      state: 0
    }, 
    {
      pos: [4, 6, 2], 
      state: 0
    }, 
    {
      pos: [5, 6, 2], 
      state: 0
    }, 
    {
      pos: [6, 6, 2], 
      state: 0
    }, 
    {
      pos: [7, 6, 2], 
      state: 0
    }, 
    {
      pos: [8, 6, 2], 
      state: 0
    }, 
    {
      pos: [1, 6, 3], 
      state: 0
    }, 
    {
      pos: [2, 6, 3], 
      state: 0
    }, 
    {
      pos: [7, 6, 3], 
      state: 0
    }, 
    {
      pos: [8, 6, 3], 
      state: 0
    }, 
    {
      pos: [1, 6, 4], 
      state: 0
    }, 
    {
      pos: [2, 6, 4], 
      state: 0
    }, 
    {
      pos: [7, 6, 4], 
      state: 0
    }, 
    {
      pos: [8, 6, 4], 
      state: 3
    }, 
    {
      pos: [1, 6, 5], 
      state: 0
    }, 
    {
      pos: [2, 6, 5], 
      state: 0
    }, 
    {
      pos: [7, 6, 5], 
      state: 0
    }, 
    {
      pos: [8, 6, 5], 
      state: 3
    }, 
    {
      pos: [1, 6, 6], 
      state: 0
    }, 
    {
      pos: [2, 6, 6], 
      state: 0
    }, 
    {
      pos: [7, 6, 6], 
      state: 0
    }, 
    {
      pos: [8, 6, 6], 
      state: 0
    }, 
    {
      pos: [1, 6, 7], 
      state: 0
    }, 
    {
      pos: [2, 6, 7], 
      state: 0
    }, 
    {
      pos: [3, 6, 7], 
      state: 0
    }, 
    {
      pos: [4, 6, 7], 
      state: 0
    }, 
    {
      pos: [5, 6, 7], 
      state: 0
    }, 
    {
      pos: [6, 6, 7], 
      state: 0
    }, 
    {
      pos: [7, 6, 7], 
      state: 0
    }, 
    {
      pos: [8, 6, 7], 
      state: 0
    }, 
    {
      pos: [1, 6, 8], 
      state: 0
    }, 
    {
      pos: [2, 6, 8], 
      state: 0
    }, 
    {
      pos: [3, 6, 8], 
      state: 0
    }, 
    {
      pos: [4, 6, 8], 
      state: 3
    }, 
    {
      pos: [5, 6, 8], 
      state: 3
    }, 
    {
      pos: [6, 6, 8], 
      state: 0
    }, 
    {
      pos: [7, 6, 8], 
      state: 0
    }, 
    {
      pos: [8, 6, 8], 
      state: 0
    }, 
    {
      pos: [0, 7, 0], 
      state: 0
    }, 
    {
      pos: [1, 7, 0], 
      state: 0
    }, 
    {
      pos: [2, 7, 0], 
      state: 3
    }, 
    {
      pos: [3, 7, 0], 
      state: 3
    }, 
    {
      pos: [4, 7, 0], 
      state: 3
    }, 
    {
      pos: [5, 7, 0], 
      state: 0
    }, 
    {
      pos: [6, 7, 0], 
      state: 0
    }, 
    {
      pos: [7, 7, 0], 
      state: 0
    }, 
    {
      pos: [8, 7, 0], 
      state: 0
    }, 
    {
      pos: [9, 7, 0], 
      state: 0
    }, 
    {
      pos: [0, 7, 1], 
      state: 0
    }, 
    {
      pos: [1, 7, 1], 
      state: 0
    }, 
    {
      pos: [2, 7, 1], 
      state: 0
    }, 
    {
      pos: [3, 7, 1], 
      state: 0
    }, 
    {
      pos: [4, 7, 1], 
      state: 0
    }, 
    {
      pos: [5, 7, 1], 
      state: 0
    }, 
    {
      pos: [6, 7, 1], 
      state: 0
    }, 
    {
      pos: [7, 7, 1], 
      state: 0
    }, 
    {
      pos: [8, 7, 1], 
      state: 0
    }, 
    {
      pos: [9, 7, 1], 
      state: 0
    }, 
    {
      pos: [1, 7, 2], 
      state: 0
    }, 
    {
      pos: [2, 7, 2], 
      state: 0
    }, 
    {
      pos: [3, 7, 2], 
      state: 0
    }, 
    {
      pos: [4, 7, 2], 
      state: 0
    }, 
    {
      pos: [5, 7, 2], 
      state: 0
    }, 
    {
      pos: [6, 7, 2], 
      state: 0
    }, 
    {
      pos: [7, 7, 2], 
      state: 0
    }, 
    {
      pos: [8, 7, 2], 
      state: 0
    }, 
    {
      pos: [9, 7, 2], 
      state: 0
    }, 
    {
      pos: [0, 7, 3], 
      state: 3
    }, 
    {
      pos: [1, 7, 3], 
      state: 0
    }, 
    {
      pos: [2, 7, 3], 
      state: 0
    }, 
    {
      pos: [3, 7, 3], 
      state: 0
    }, 
    {
      pos: [4, 7, 3], 
      state: 0
    }, 
    {
      pos: [5, 7, 3], 
      state: 0
    }, 
    {
      pos: [6, 7, 3], 
      state: 0
    }, 
    {
      pos: [7, 7, 3], 
      state: 0
    }, 
    {
      pos: [8, 7, 3], 
      state: 0
    }, 
    {
      pos: [9, 7, 3], 
      state: 0
    }, 
    {
      pos: [0, 7, 4], 
      state: 3
    }, 
    {
      pos: [1, 7, 4], 
      state: 0
    }, 
    {
      pos: [2, 7, 4], 
      state: 0
    }, 
    {
      pos: [3, 7, 4], 
      state: 0
    }, 
    {
      pos: [6, 7, 4], 
      state: 0
    }, 
    {
      pos: [7, 7, 4], 
      state: 0
    }, 
    {
      pos: [8, 7, 4], 
      state: 0
    }, 
    {
      pos: [9, 7, 4], 
      state: 0
    }, 
    {
      pos: [0, 7, 5], 
      state: 0
    }, 
    {
      pos: [1, 7, 5], 
      state: 0
    }, 
    {
      pos: [2, 7, 5], 
      state: 0
    }, 
    {
      pos: [3, 7, 5], 
      state: 0
    }, 
    {
      pos: [6, 7, 5], 
      state: 0
    }, 
    {
      pos: [7, 7, 5], 
      state: 0
    }, 
    {
      pos: [8, 7, 5], 
      state: 0
    }, 
    {
      pos: [9, 7, 5], 
      state: 0
    }, 
    {
      pos: [0, 7, 6], 
      state: 0
    }, 
    {
      pos: [1, 7, 6], 
      state: 0
    }, 
    {
      pos: [2, 7, 6], 
      state: 0
    }, 
    {
      pos: [3, 7, 6], 
      state: 0
    }, 
    {
      pos: [4, 7, 6], 
      state: 0
    }, 
    {
      pos: [5, 7, 6], 
      state: 0
    }, 
    {
      pos: [6, 7, 6], 
      state: 0
    }, 
    {
      pos: [7, 7, 6], 
      state: 0
    }, 
    {
      pos: [8, 7, 6], 
      state: 0
    }, 
    {
      pos: [9, 7, 6], 
      state: 0
    }, 
    {
      pos: [0, 7, 7], 
      state: 0
    }, 
    {
      pos: [1, 7, 7], 
      state: 0
    }, 
    {
      pos: [2, 7, 7], 
      state: 0
    }, 
    {
      pos: [3, 7, 7], 
      state: 0
    }, 
    {
      pos: [4, 7, 7], 
      state: 0
    }, 
    {
      pos: [5, 7, 7], 
      state: 0
    }, 
    {
      pos: [6, 7, 7], 
      state: 0
    }, 
    {
      pos: [7, 7, 7], 
      state: 0
    }, 
    {
      pos: [8, 7, 7], 
      state: 0
    }, 
    {
      pos: [9, 7, 7], 
      state: 0
    }, 
    {
      pos: [0, 7, 8], 
      state: 0
    }, 
    {
      pos: [1, 7, 8], 
      state: 0
    }, 
    {
      pos: [2, 7, 8], 
      state: 0
    }, 
    {
      pos: [3, 7, 8], 
      state: 0
    }, 
    {
      pos: [4, 7, 8], 
      state: 0
    }, 
    {
      pos: [5, 7, 8], 
      state: 0
    }, 
    {
      pos: [6, 7, 8], 
      state: 0
    }, 
    {
      pos: [7, 7, 8], 
      state: 0
    }, 
    {
      pos: [8, 7, 8], 
      state: 0
    }, 
    {
      pos: [9, 7, 8], 
      state: 0
    }, 
    {
      pos: [0, 7, 9], 
      state: 0
    }, 
    {
      pos: [1, 7, 9], 
      state: 0
    }, 
    {
      pos: [2, 7, 9], 
      state: 0
    }, 
    {
      pos: [3, 7, 9], 
      state: 0
    }, 
    {
      pos: [4, 7, 9], 
      state: 0
    }, 
    {
      pos: [5, 7, 9], 
      state: 0
    }, 
    {
      pos: [6, 7, 9], 
      state: 0
    }, 
    {
      pos: [7, 7, 9], 
      state: 0
    }, 
    {
      pos: [8, 7, 9], 
      state: 0
    }, 
    {
      pos: [9, 7, 9], 
      state: 0
    }, 
    {
      pos: [0, 8, 0], 
      state: 3
    }, 
    {
      pos: [1, 8, 0], 
      state: 0
    }, 
    {
      pos: [2, 8, 0], 
      state: 0
    }, 
    {
      pos: [3, 8, 0], 
      state: 0
    }, 
    {
      pos: [4, 8, 0], 
      state: 0
    }, 
    {
      pos: [5, 8, 0], 
      state: 0
    }, 
    {
      pos: [6, 8, 0], 
      state: 0
    }, 
    {
      pos: [7, 8, 0], 
      state: 0
    }, 
    {
      pos: [8, 8, 0], 
      state: 1
    }, 
    {
      pos: [9, 8, 0], 
      state: 1
    }, 
    {
      pos: [1, 8, 1], 
      state: 0
    }, 
    {
      pos: [2, 8, 1], 
      state: 0
    }, 
    {
      pos: [3, 8, 1], 
      state: 0
    }, 
    {
      pos: [4, 8, 1], 
      state: 3
    }, 
    {
      pos: [5, 8, 1], 
      state: 3
    }, 
    {
      pos: [6, 8, 1], 
      state: 3
    }, 
    {
      pos: [7, 8, 1], 
      state: 0
    }, 
    {
      pos: [8, 8, 1], 
      state: 1
    }, 
    {
      pos: [9, 8, 1], 
      state: 0
    }, 
    {
      pos: [0, 8, 2], 
      state: 3
    }, 
    {
      pos: [3, 8, 2], 
      state: 0
    }, 
    {
      pos: [4, 8, 2], 
      state: 0
    }, 
    {
      pos: [5, 8, 2], 
      state: 0
    }, 
    {
      pos: [6, 8, 2], 
      state: 3
    }, 
    {
      pos: [7, 8, 2], 
      state: 3
    }, 
    {
      pos: [8, 8, 2], 
      state: 1
    }, 
    {
      pos: [9, 8, 2], 
      state: 0
    }, 
    {
      pos: [0, 8, 3], 
      state: 0
    }, 
    {
      pos: [1, 8, 3], 
      state: 3
    }, 
    {
      pos: [2, 8, 3], 
      state: 3
    }, 
    {
      pos: [3, 8, 3], 
      state: 0
    }, 
    {
      pos: [4, 8, 3], 
      state: 0
    }, 
    {
      pos: [5, 8, 3], 
      state: 0
    }, 
    {
      pos: [6, 8, 3], 
      state: 0
    }, 
    {
      pos: [7, 8, 3], 
      state: 3
    }, 
    {
      pos: [8, 8, 3], 
      state: 0
    }, 
    {
      pos: [9, 8, 3], 
      state: 0
    }, 
    {
      pos: [0, 8, 4], 
      state: 0
    }, 
    {
      pos: [1, 8, 4], 
      state: 0
    }, 
    {
      pos: [2, 8, 4], 
      state: 0
    }, 
    {
      pos: [3, 8, 4], 
      state: 0
    }, 
    {
      pos: [6, 8, 4], 
      state: 0
    }, 
    {
      pos: [7, 8, 4], 
      state: 0
    }, 
    {
      pos: [8, 8, 4], 
      state: 0
    }, 
    {
      pos: [9, 8, 4], 
      state: 2
    }, 
    {
      pos: [0, 8, 5], 
      state: 0
    }, 
    {
      pos: [1, 8, 5], 
      state: 0
    }, 
    {
      pos: [2, 8, 5], 
      state: 0
    }, 
    {
      pos: [3, 8, 5], 
      state: 0
    }, 
    {
      pos: [6, 8, 5], 
      state: 0
    }, 
    {
      pos: [7, 8, 5], 
      state: 0
    }, 
    {
      pos: [8, 8, 5], 
      state: 2
    }, 
    {
      pos: [9, 8, 5], 
      state: 2
    }, 
    {
      pos: [1, 8, 6], 
      state: 3
    }, 
    {
      pos: [2, 8, 6], 
      state: 0
    }, 
    {
      pos: [3, 8, 6], 
      state: 0
    }, 
    {
      pos: [4, 8, 6], 
      state: 0
    }, 
    {
      pos: [5, 8, 6], 
      state: 0
    }, 
    {
      pos: [6, 8, 6], 
      state: 0
    }, 
    {
      pos: [7, 8, 6], 
      state: 0
    }, 
    {
      pos: [8, 8, 6], 
      state: 2
    }, 
    {
      pos: [9, 8, 6], 
      state: 2
    }, 
    {
      pos: [0, 8, 7], 
      state: 3
    }, 
    {
      pos: [1, 8, 7], 
      state: 3
    }, 
    {
      pos: [2, 8, 7], 
      state: 3
    }, 
    {
      pos: [3, 8, 7], 
      state: 0
    }, 
    {
      pos: [4, 8, 7], 
      state: 0
    }, 
    {
      pos: [5, 8, 7], 
      state: 2
    }, 
    {
      pos: [6, 8, 7], 
      state: 0
    }, 
    {
      pos: [7, 8, 7], 
      state: 2
    }, 
    {
      pos: [8, 8, 7], 
      state: 3
    }, 
    {
      pos: [9, 8, 7], 
      state: 3
    }, 
    {
      pos: [0, 8, 8], 
      state: 3
    }, 
    {
      pos: [1, 8, 8], 
      state: 0
    }, 
    {
      pos: [2, 8, 8], 
      state: 3
    }, 
    {
      pos: [3, 8, 8], 
      state: 3
    }, 
    {
      pos: [4, 8, 8], 
      state: 2
    }, 
    {
      pos: [5, 8, 8], 
      state: 2
    }, 
    {
      pos: [6, 8, 8], 
      state: 3
    }, 
    {
      pos: [8, 8, 8], 
      state: 3
    }, 
    {
      pos: [0, 8, 9], 
      state: 3
    }, 
    {
      pos: [1, 8, 9], 
      state: 3
    }, 
    {
      pos: [2, 8, 9], 
      state: 3
    }, 
    {
      pos: [3, 8, 9], 
      state: 3
    }, 
    {
      pos: [6, 8, 9], 
      state: 3
    }, 
    {
      pos: [7, 8, 9], 
      state: 0
    }, 
    {
      pos: [8, 8, 9], 
      state: 0
    }, 
    {
      pos: [9, 8, 9], 
      state: 0
    }, 
    {
      pos: [3, 9, 3], 
      state: 0
    }, 
    {
      pos: [4, 9, 3], 
      state: 3
    }, 
    {
      pos: [5, 9, 3], 
      state: 3
    }, 
    {
      pos: [6, 9, 3], 
      state: 0
    }, 
    {
      pos: [3, 9, 4], 
      state: 3
    }, 
    {
      pos: [6, 9, 4], 
      state: 0
    }, 
    {
      pos: [3, 9, 5], 
      state: 0
    }, 
    {
      pos: [6, 9, 5], 
      state: 0
    }, 
    {
      pos: [4, 9, 6], 
      state: 0
    }, 
    {
      pos: [6, 9, 6], 
      state: 0
    }, 
    {
      pos: [2, 9, 5], 
      state: 7
    }, 
    {
      pos: [3, 9, 6], 
      state: 8
    }
  ], 
  palette: [
    {
      Name: "minecraft:polished_blackstone_bricks"
    }, 
    {
      Properties: {
        axis: "y"
      }, 
      Name: "minecraft:basalt"
    }, 
    {
      Name: "minecraft:cracked_polished_blackstone_bricks"
    }, 
    {
      Name: "minecraft:blackstone"
    }, 
    {
      Properties: {
        orientation: "west_up"
      }, 
      Name: "minecraft:jigsaw"
    }, 
    {
      Name: "minecraft:netherrack"
    }, 
    {
      Properties: {
        east: "false", 
        south: "false", 
        north: "false", 
        west: "false", 
        up: "false", 
        age: "15"
      }, 
      Name: "minecraft:fire"
    }, 
    {
      Properties: {
        waterlogged: "false", 
        type: "bottom"
      }, 
      Name: "minecraft:blackstone_slab"
    }, 
    {
      Name: "minecraft:air"
    }
  ]
}
