{
  size: [10, 3, 10], 
  entities: [], 
  blocks: [
    {
      pos: [0, 0, 0], 
      state: 0
    }, 
    {
      pos: [0, 0, 1], 
      state: 0
    }, 
    {
      pos: [0, 0, 2], 
      state: 0
    }, 
    {
      pos: [0, 0, 3], 
      state: 0
    }, 
    {
      pos: [0, 0, 4], 
      state: 0
    }, 
    {
      pos: [0, 0, 5], 
      state: 0
    }, 
    {
      pos: [0, 0, 6], 
      state: 0
    }, 
    {
      pos: [0, 0, 7], 
      state: 0
    }, 
    {
      pos: [0, 0, 8], 
      state: 0
    }, 
    {
      pos: [0, 0, 9], 
      state: 0
    }, 
    {
      pos: [1, 0, 0], 
      state: 0
    }, 
    {
      pos: [1, 0, 1], 
      state: 0
    }, 
    {
      pos: [1, 0, 2], 
      state: 0
    }, 
    {
      pos: [1, 0, 3], 
      state: 0
    }, 
    {
      pos: [1, 0, 4], 
      state: 0
    }, 
    {
      pos: [1, 0, 5], 
      state: 0
    }, 
    {
      pos: [1, 0, 6], 
      state: 0
    }, 
    {
      pos: [1, 0, 7], 
      state: 0
    }, 
    {
      pos: [1, 0, 8], 
      state: 0
    }, 
    {
      pos: [1, 0, 9], 
      state: 0
    }, 
    {
      pos: [2, 0, 0], 
      state: 0
    }, 
    {
      pos: [2, 0, 1], 
      state: 0
    }, 
    {
      pos: [2, 0, 2], 
      state: 0
    }, 
    {
      pos: [2, 0, 3], 
      state: 0
    }, 
    {
      pos: [2, 0, 4], 
      state: 0
    }, 
    {
      pos: [2, 0, 5], 
      state: 0
    }, 
    {
      pos: [2, 0, 6], 
      state: 0
    }, 
    {
      pos: [2, 0, 7], 
      state: 0
    }, 
    {
      pos: [2, 0, 8], 
      state: 0
    }, 
    {
      pos: [2, 0, 9], 
      state: 0
    }, 
    {
      pos: [3, 0, 0], 
      state: 0
    }, 
    {
      pos: [3, 0, 1], 
      state: 0
    }, 
    {
      pos: [3, 0, 2], 
      state: 0
    }, 
    {
      pos: [3, 0, 3], 
      state: 0
    }, 
    {
      pos: [3, 0, 4], 
      state: 0
    }, 
    {
      pos: [3, 0, 5], 
      state: 0
    }, 
    {
      pos: [3, 0, 6], 
      state: 0
    }, 
    {
      pos: [3, 0, 7], 
      state: 0
    }, 
    {
      pos: [3, 0, 8], 
      state: 0
    }, 
    {
      pos: [3, 0, 9], 
      state: 0
    }, 
    {
      pos: [4, 0, 0], 
      state: 0
    }, 
    {
      pos: [4, 0, 1], 
      state: 0
    }, 
    {
      pos: [4, 0, 2], 
      state: 0
    }, 
    {
      pos: [4, 0, 4], 
      state: 0
    }, 
    {
      pos: [4, 0, 5], 
      state: 0
    }, 
    {
      pos: [4, 0, 6], 
      state: 0
    }, 
    {
      pos: [4, 0, 7], 
      state: 0
    }, 
    {
      pos: [4, 0, 8], 
      state: 0
    }, 
    {
      pos: [4, 0, 9], 
      state: 0
    }, 
    {
      pos: [5, 0, 0], 
      state: 0
    }, 
    {
      pos: [5, 0, 1], 
      state: 0
    }, 
    {
      pos: [5, 0, 5], 
      state: 0
    }, 
    {
      pos: [5, 0, 6], 
      state: 0
    }, 
    {
      pos: [5, 0, 7], 
      state: 0
    }, 
    {
      pos: [5, 0, 8], 
      state: 0
    }, 
    {
      pos: [5, 0, 9], 
      state: 0
    }, 
    {
      pos: [6, 0, 0], 
      state: 0
    }, 
    {
      pos: [6, 0, 1], 
      state: 0
    }, 
    {
      pos: [6, 0, 5], 
      state: 0
    }, 
    {
      pos: [6, 0, 7], 
      state: 0
    }, 
    {
      pos: [6, 0, 8], 
      state: 0
    }, 
    {
      pos: [6, 0, 9], 
      state: 0
    }, 
    {
      pos: [7, 0, 0], 
      state: 0
    }, 
    {
      pos: [7, 0, 1], 
      state: 0
    }, 
    {
      pos: [7, 0, 3], 
      state: 0
    }, 
    {
      pos: [7, 0, 8], 
      state: 0
    }, 
    {
      pos: [7, 0, 9], 
      state: 0
    }, 
    {
      pos: [8, 0, 0], 
      state: 0
    }, 
    {
      pos: [8, 0, 1], 
      state: 0
    }, 
    {
      pos: [8, 0, 2], 
      state: 0
    }, 
    {
      pos: [8, 0, 5], 
      state: 1
    }, 
    {
      pos: [8, 0, 8], 
      state: 0
    }, 
    {
      pos: [8, 0, 9], 
      state: 0
    }, 
    {
      pos: [9, 0, 0], 
      state: 0
    }, 
    {
      pos: [9, 0, 1], 
      state: 0
    }, 
    {
      pos: [9, 0, 2], 
      state: 0
    }, 
    {
      pos: [9, 0, 8], 
      state: 0
    }, 
    {
      pos: [9, 0, 9], 
      state: 0
    }, 
    {
      pos: [4, 0, 3], 
      state: 2
    }, 
    {
      pos: [5, 0, 2], 
      state: 2
    }, 
    {
      pos: [5, 0, 3], 
      state: 2
    }, 
    {
      pos: [5, 0, 4], 
      state: 2
    }, 
    {
      pos: [6, 0, 2], 
      state: 2
    }, 
    {
      pos: [6, 0, 3], 
      state: 2
    }, 
    {
      pos: [6, 0, 4], 
      state: 2
    }, 
    {
      pos: [6, 0, 6], 
      state: 2
    }, 
    {
      pos: [7, 0, 2], 
      state: 2
    }, 
    {
      pos: [7, 0, 4], 
      state: 2
    }, 
    {
      pos: [7, 0, 5], 
      state: 2
    }, 
    {
      pos: [7, 0, 6], 
      state: 2
    }, 
    {
      pos: [7, 0, 7], 
      state: 2
    }, 
    {
      pos: [8, 0, 3], 
      state: 2
    }, 
    {
      pos: [8, 0, 4], 
      state: 2
    }, 
    {
      pos: [8, 0, 6], 
      state: 2
    }, 
    {
      pos: [8, 0, 7], 
      state: 2
    }, 
    {
      pos: [9, 0, 3], 
      state: 2
    }, 
    {
      pos: [9, 0, 5], 
      state: 2
    }, 
    {
      pos: [9, 0, 6], 
      state: 2
    }, 
    {
      pos: [9, 0, 7], 
      state: 2
    }, 
    {
      pos: [0, 1, 0], 
      state: 3
    }, 
    {
      pos: [0, 1, 1], 
      state: 3
    }, 
    {
      pos: [0, 1, 2], 
      state: 3
    }, 
    {
      pos: [0, 1, 3], 
      state: 3
    }, 
    {
      pos: [0, 1, 4], 
      state: 3
    }, 
    {
      pos: [0, 1, 5], 
      state: 3
    }, 
    {
      pos: [0, 1, 6], 
      state: 3
    }, 
    {
      pos: [0, 1, 7], 
      state: 3
    }, 
    {
      pos: [0, 1, 8], 
      state: 3
    }, 
    {
      pos: [0, 1, 9], 
      state: 3
    }, 
    {
      pos: [1, 1, 0], 
      state: 3
    }, 
    {
      pos: [1, 1, 1], 
      state: 3
    }, 
    {
      pos: [1, 1, 2], 
      state: 3
    }, 
    {
      pos: [1, 1, 3], 
      state: 3
    }, 
    {
      pos: [1, 1, 4], 
      state: 3
    }, 
    {
      pos: [1, 1, 5], 
      state: 3
    }, 
    {
      pos: [1, 1, 6], 
      state: 3
    }, 
    {
      pos: [1, 1, 7], 
      state: 3
    }, 
    {
      pos: [1, 1, 8], 
      state: 3
    }, 
    {
      pos: [1, 1, 9], 
      state: 3
    }, 
    {
      pos: [2, 1, 0], 
      state: 3
    }, 
    {
      pos: [2, 1, 1], 
      state: 3
    }, 
    {
      pos: [2, 1, 2], 
      state: 3
    }, 
    {
      pos: [2, 1, 3], 
      state: 3
    }, 
    {
      pos: [2, 1, 4], 
      state: 3
    }, 
    {
      pos: [2, 1, 5], 
      state: 3
    }, 
    {
      pos: [2, 1, 6], 
      state: 3
    }, 
    {
      pos: [2, 1, 7], 
      state: 3
    }, 
    {
      pos: [2, 1, 8], 
      state: 3
    }, 
    {
      pos: [2, 1, 9], 
      state: 3
    }, 
    {
      pos: [3, 1, 0], 
      state: 3
    }, 
    {
      pos: [3, 1, 1], 
      state: 3
    }, 
    {
      pos: [3, 1, 2], 
      state: 3
    }, 
    {
      pos: [3, 1, 3], 
      state: 3
    }, 
    {
      pos: [3, 1, 4], 
      state: 3
    }, 
    {
      pos: [3, 1, 5], 
      state: 3
    }, 
    {
      pos: [3, 1, 6], 
      state: 3
    }, 
    {
      pos: [3, 1, 7], 
      state: 3
    }, 
    {
      pos: [3, 1, 8], 
      state: 3
    }, 
    {
      pos: [3, 1, 9], 
      state: 3
    }, 
    {
      pos: [4, 1, 0], 
      state: 3
    }, 
    {
      pos: [4, 1, 1], 
      state: 3
    }, 
    {
      pos: [4, 1, 2], 
      state: 3
    }, 
    {
      pos: [4, 1, 3], 
      state: 3
    }, 
    {
      pos: [4, 1, 5], 
      state: 3
    }, 
    {
      pos: [4, 1, 6], 
      state: 3
    }, 
    {
      pos: [4, 1, 7], 
      state: 3
    }, 
    {
      pos: [4, 1, 8], 
      state: 3
    }, 
    {
      pos: [4, 1, 9], 
      state: 3
    }, 
    {
      pos: [5, 1, 0], 
      state: 3
    }, 
    {
      pos: [5, 1, 1], 
      state: 3
    }, 
    {
      pos: [5, 1, 2], 
      state: 3
    }, 
    {
      pos: [5, 1, 3], 
      state: 3
    }, 
    {
      pos: [5, 1, 4], 
      state: 3
    }, 
    {
      pos: [5, 1, 5], 
      state: 3
    }, 
    {
      pos: [5, 1, 6], 
      state: 3
    }, 
    {
      pos: [5, 1, 7], 
      state: 3
    }, 
    {
      pos: [5, 1, 8], 
      state: 3
    }, 
    {
      pos: [5, 1, 9], 
      state: 3
    }, 
    {
      pos: [6, 1, 0], 
      state: 3
    }, 
    {
      pos: [6, 1, 1], 
      state: 3
    }, 
    {
      pos: [6, 1, 2], 
      state: 3
    }, 
    {
      pos: [6, 1, 3], 
      state: 3
    }, 
    {
      pos: [6, 1, 4], 
      state: 3
    }, 
    {
      pos: [6, 1, 6], 
      state: 3
    }, 
    {
      pos: [6, 1, 7], 
      state: 3
    }, 
    {
      pos: [6, 1, 8], 
      state: 3
    }, 
    {
      pos: [6, 1, 9], 
      state: 3
    }, 
    {
      pos: [7, 1, 0], 
      state: 3
    }, 
    {
      pos: [7, 1, 1], 
      state: 3
    }, 
    {
      pos: [7, 1, 2], 
      state: 3
    }, 
    {
      pos: [7, 1, 3], 
      state: 3
    }, 
    {
      pos: [7, 1, 4], 
      state: 3
    }, 
    {
      pos: [7, 1, 5], 
      state: 3
    }, 
    {
      pos: [7, 1, 6], 
      state: 3
    }, 
    {
      pos: [7, 1, 7], 
      state: 3
    }, 
    {
      pos: [7, 1, 8], 
      state: 3
    }, 
    {
      pos: [7, 1, 9], 
      state: 3
    }, 
    {
      pos: [8, 1, 0], 
      state: 3
    }, 
    {
      pos: [8, 1, 1], 
      state: 3
    }, 
    {
      pos: [8, 1, 2], 
      state: 3
    }, 
    {
      pos: [8, 1, 3], 
      state: 3
    }, 
    {
      pos: [8, 1, 4], 
      state: 3
    }, 
    {
      pos: [8, 1, 5], 
      state: 3
    }, 
    {
      pos: [8, 1, 6], 
      state: 3
    }, 
    {
      pos: [8, 1, 7], 
      state: 3
    }, 
    {
      pos: [8, 1, 8], 
      state: 3
    }, 
    {
      pos: [8, 1, 9], 
      state: 3
    }, 
    {
      pos: [9, 1, 0], 
      state: 3
    }, 
    {
      pos: [9, 1, 1], 
      state: 3
    }, 
    {
      pos: [9, 1, 2], 
      state: 3
    }, 
    {
      pos: [9, 1, 3], 
      state: 3
    }, 
    {
      pos: [9, 1, 4], 
      state: 3
    }, 
    {
      pos: [9, 1, 5], 
      state: 3
    }, 
    {
      pos: [9, 1, 6], 
      state: 3
    }, 
    {
      pos: [9, 1, 7], 
      state: 3
    }, 
    {
      pos: [9, 1, 8], 
      state: 3
    }, 
    {
      pos: [9, 1, 9], 
      state: 3
    }, 
    {
      pos: [0, 2, 0], 
      state: 3
    }, 
    {
      pos: [0, 2, 1], 
      state: 3
    }, 
    {
      pos: [0, 2, 2], 
      state: 3
    }, 
    {
      pos: [0, 2, 3], 
      state: 3
    }, 
    {
      pos: [0, 2, 4], 
      state: 3
    }, 
    {
      pos: [0, 2, 5], 
      state: 3
    }, 
    {
      pos: [0, 2, 6], 
      state: 3
    }, 
    {
      pos: [0, 2, 7], 
      state: 3
    }, 
    {
      pos: [0, 2, 8], 
      state: 3
    }, 
    {
      pos: [0, 2, 9], 
      state: 3
    }, 
    {
      pos: [1, 2, 0], 
      state: 3
    }, 
    {
      pos: [1, 2, 1], 
      state: 3
    }, 
    {
      pos: [1, 2, 2], 
      state: 3
    }, 
    {
      pos: [1, 2, 3], 
      state: 3
    }, 
    {
      pos: [1, 2, 4], 
      state: 3
    }, 
    {
      pos: [1, 2, 5], 
      state: 3
    }, 
    {
      pos: [1, 2, 6], 
      state: 3
    }, 
    {
      pos: [1, 2, 7], 
      state: 3
    }, 
    {
      pos: [1, 2, 8], 
      state: 3
    }, 
    {
      pos: [1, 2, 9], 
      state: 3
    }, 
    {
      pos: [2, 2, 0], 
      state: 3
    }, 
    {
      pos: [2, 2, 1], 
      state: 3
    }, 
    {
      pos: [2, 2, 2], 
      state: 3
    }, 
    {
      pos: [2, 2, 3], 
      state: 3
    }, 
    {
      pos: [2, 2, 4], 
      state: 3
    }, 
    {
      pos: [2, 2, 5], 
      state: 3
    }, 
    {
      pos: [2, 2, 6], 
      state: 3
    }, 
    {
      pos: [2, 2, 7], 
      state: 3
    }, 
    {
      pos: [2, 2, 8], 
      state: 3
    }, 
    {
      pos: [2, 2, 9], 
      state: 3
    }, 
    {
      pos: [3, 2, 0], 
      state: 3
    }, 
    {
      pos: [3, 2, 1], 
      state: 3
    }, 
    {
      pos: [3, 2, 2], 
      state: 3
    }, 
    {
      pos: [3, 2, 3], 
      state: 3
    }, 
    {
      pos: [3, 2, 4], 
      state: 3
    }, 
    {
      pos: [3, 2, 5], 
      state: 3
    }, 
    {
      pos: [3, 2, 6], 
      state: 3
    }, 
    {
      pos: [3, 2, 7], 
      state: 3
    }, 
    {
      pos: [3, 2, 8], 
      state: 3
    }, 
    {
      pos: [3, 2, 9], 
      state: 3
    }, 
    {
      pos: [4, 2, 0], 
      state: 3
    }, 
    {
      pos: [4, 2, 1], 
      state: 3
    }, 
    {
      pos: [4, 2, 2], 
      state: 3
    }, 
    {
      pos: [4, 2, 3], 
      state: 3
    }, 
    {
      pos: [4, 2, 4], 
      state: 3
    }, 
    {
      pos: [4, 2, 5], 
      state: 3
    }, 
    {
      pos: [4, 2, 6], 
      state: 3
    }, 
    {
      pos: [4, 2, 7], 
      state: 3
    }, 
    {
      pos: [4, 2, 8], 
      state: 3
    }, 
    {
      pos: [4, 2, 9], 
      state: 3
    }, 
    {
      pos: [5, 2, 0], 
      state: 3
    }, 
    {
      pos: [5, 2, 1], 
      state: 3
    }, 
    {
      pos: [5, 2, 2], 
      state: 3
    }, 
    {
      pos: [5, 2, 3], 
      state: 3
    }, 
    {
      pos: [5, 2, 4], 
      state: 3
    }, 
    {
      pos: [5, 2, 5], 
      state: 3
    }, 
    {
      pos: [5, 2, 6], 
      state: 3
    }, 
    {
      pos: [5, 2, 7], 
      state: 3
    }, 
    {
      pos: [5, 2, 8], 
      state: 3
    }, 
    {
      pos: [5, 2, 9], 
      state: 3
    }, 
    {
      pos: [6, 2, 0], 
      state: 3
    }, 
    {
      pos: [6, 2, 1], 
      state: 3
    }, 
    {
      pos: [6, 2, 2], 
      state: 3
    }, 
    {
      pos: [6, 2, 3], 
      state: 3
    }, 
    {
      pos: [6, 2, 4], 
      state: 3
    }, 
    {
      pos: [6, 2, 5], 
      state: 3
    }, 
    {
      pos: [6, 2, 6], 
      state: 3
    }, 
    {
      pos: [6, 2, 7], 
      state: 3
    }, 
    {
      pos: [6, 2, 8], 
      state: 3
    }, 
    {
      pos: [6, 2, 9], 
      state: 3
    }, 
    {
      pos: [7, 2, 0], 
      state: 3
    }, 
    {
      pos: [7, 2, 1], 
      state: 3
    }, 
    {
      pos: [7, 2, 2], 
      state: 3
    }, 
    {
      pos: [7, 2, 3], 
      state: 3
    }, 
    {
      pos: [7, 2, 4], 
      state: 3
    }, 
    {
      pos: [7, 2, 5], 
      state: 3
    }, 
    {
      pos: [7, 2, 6], 
      state: 3
    }, 
    {
      pos: [7, 2, 7], 
      state: 3
    }, 
    {
      pos: [7, 2, 8], 
      state: 3
    }, 
    {
      pos: [7, 2, 9], 
      state: 3
    }, 
    {
      pos: [8, 2, 0], 
      state: 3
    }, 
    {
      pos: [8, 2, 1], 
      state: 3
    }, 
    {
      pos: [8, 2, 2], 
      state: 3
    }, 
    {
      pos: [8, 2, 3], 
      state: 3
    }, 
    {
      pos: [8, 2, 4], 
      state: 3
    }, 
    {
      pos: [8, 2, 5], 
      state: 3
    }, 
    {
      pos: [8, 2, 6], 
      state: 3
    }, 
    {
      pos: [8, 2, 7], 
      state: 3
    }, 
    {
      pos: [8, 2, 8], 
      state: 3
    }, 
    {
      pos: [8, 2, 9], 
      state: 3
    }, 
    {
      pos: [9, 2, 0], 
      state: 3
    }, 
    {
      pos: [9, 2, 1], 
      state: 3
    }, 
    {
      pos: [9, 2, 2], 
      state: 3
    }, 
    {
      pos: [9, 2, 3], 
      state: 3
    }, 
    {
      pos: [9, 2, 4], 
      state: 3
    }, 
    {
      pos: [9, 2, 5], 
      state: 3
    }, 
    {
      pos: [9, 2, 6], 
      state: 3
    }, 
    {
      pos: [9, 2, 7], 
      state: 3
    }, 
    {
      pos: [9, 2, 8], 
      state: 3
    }, 
    {
      pos: [9, 2, 9], 
      state: 3
    }, 
    {
      nbt: {
        components: {}, 
        joint: "rollable", 
        final_state: "minecraft:dirt_path", 
        name: "minecraft:end_connector", 
        placement_priority: 0, 
        pool: "minecraft:empty", 
        selection_priority: 0, 
        id: "minecraft:jigsaw", 
        target: "minecraft:connector"
      }, 
      pos: [9, 0, 4], 
      state: 4
    }, 
    {
      nbt: {
        LootTable: "minecraft:chests/abandoned_camp_common_chest", 
        components: {}, 
        Items: [], 
        id: "minecraft:chest"
      }, 
      pos: [4, 1, 4], 
      state: 5
    }, 
    {
      nbt: {
        components: {}, 
        Items: [], 
        CookingTimes: [I; 0, 0, 0, 0], 
        CookingTotalTimes: [I; 0, 0, 0, 0], 
        id: "minecraft:campfire"
      }, 
      pos: [6, 1, 5], 
      state: 6
    }
  ], 
  palette: [
    {
      Properties: {
        snowy: "false"
      }, 
      Name: "minecraft:grass_block"
    }, 
    {
      Name: "minecraft:dirt"
    }, 
    {
      Name: "minecraft:dirt_path"
    }, 
    {
      Name: "minecraft:air"
    }, 
    {
      Properties: {
        orientation: "east_up"
      }, 
      Name: "minecraft:jigsaw"
    }, 
    {
      Properties: {
        waterlogged: "false", 
        facing: "east", 
        type: "single"
      }, 
      Name: "minecraft:chest"
    }, 
    {
      Properties: {
        waterlogged: "false", 
        signal_fire: "false", 
        lit: "false", 
        facing: "west"
      }, 
      Name: "minecraft:campfire"
    }
  ]
}
