{
  size: [10, 3, 10], 
  entities: [], 
  blocks: [
    {
      pos: [0, 0, 0], 
      state: 0
    }, 
    {
      pos: [0, 0, 1], 
      state: 0
    }, 
    {
      pos: [0, 0, 2], 
      state: 0
    }, 
    {
      pos: [0, 0, 3], 
      state: 0
    }, 
    {
      pos: [0, 0, 4], 
      state: 0
    }, 
    {
      pos: [0, 0, 5], 
      state: 0
    }, 
    {
      pos: [0, 0, 6], 
      state: 0
    }, 
    {
      pos: [0, 0, 7], 
      state: 0
    }, 
    {
      pos: [0, 0, 8], 
      state: 0
    }, 
    {
      pos: [0, 0, 9], 
      state: 0
    }, 
    {
      pos: [1, 0, 0], 
      state: 0
    }, 
    {
      pos: [1, 0, 1], 
      state: 0
    }, 
    {
      pos: [1, 0, 2], 
      state: 0
    }, 
    {
      pos: [1, 0, 3], 
      state: 1
    }, 
    {
      pos: [1, 0, 4], 
      state: 1
    }, 
    {
      pos: [1, 0, 5], 
      state: 1
    }, 
    {
      pos: [1, 0, 6], 
      state: 2
    }, 
    {
      pos: [1, 0, 7], 
      state: 0
    }, 
    {
      pos: [1, 0, 8], 
      state: 2
    }, 
    {
      pos: [1, 0, 9], 
      state: 0
    }, 
    {
      pos: [2, 0, 0], 
      state: 0
    }, 
    {
      pos: [2, 0, 1], 
      state: 0
    }, 
    {
      pos: [2, 0, 2], 
      state: 1
    }, 
    {
      pos: [2, 0, 3], 
      state: 0
    }, 
    {
      pos: [2, 0, 4], 
      state: 0
    }, 
    {
      pos: [2, 0, 5], 
      state: 0
    }, 
    {
      pos: [2, 0, 6], 
      state: 1
    }, 
    {
      pos: [2, 0, 7], 
      state: 0
    }, 
    {
      pos: [2, 0, 8], 
      state: 0
    }, 
    {
      pos: [2, 0, 9], 
      state: 0
    }, 
    {
      pos: [3, 0, 0], 
      state: 0
    }, 
    {
      pos: [3, 0, 1], 
      state: 0
    }, 
    {
      pos: [3, 0, 2], 
      state: 0
    }, 
    {
      pos: [3, 0, 3], 
      state: 1
    }, 
    {
      pos: [3, 0, 4], 
      state: 1
    }, 
    {
      pos: [3, 0, 5], 
      state: 1
    }, 
    {
      pos: [3, 0, 6], 
      state: 0
    }, 
    {
      pos: [3, 0, 7], 
      state: 2
    }, 
    {
      pos: [3, 0, 8], 
      state: 0
    }, 
    {
      pos: [3, 0, 9], 
      state: 0
    }, 
    {
      pos: [4, 0, 0], 
      state: 0
    }, 
    {
      pos: [4, 0, 1], 
      state: 1
    }, 
    {
      pos: [4, 0, 2], 
      state: 0
    }, 
    {
      pos: [4, 0, 3], 
      state: 1
    }, 
    {
      pos: [4, 0, 4], 
      state: 1
    }, 
    {
      pos: [4, 0, 5], 
      state: 0
    }, 
    {
      pos: [4, 0, 6], 
      state: 1
    }, 
    {
      pos: [4, 0, 7], 
      state: 0
    }, 
    {
      pos: [4, 0, 8], 
      state: 1
    }, 
    {
      pos: [4, 0, 9], 
      state: 0
    }, 
    {
      pos: [5, 0, 0], 
      state: 0
    }, 
    {
      pos: [5, 0, 1], 
      state: 0
    }, 
    {
      pos: [5, 0, 2], 
      state: 1
    }, 
    {
      pos: [5, 0, 4], 
      state: 1
    }, 
    {
      pos: [5, 0, 6], 
      state: 1
    }, 
    {
      pos: [5, 0, 7], 
      state: 0
    }, 
    {
      pos: [5, 0, 8], 
      state: 1
    }, 
    {
      pos: [5, 0, 9], 
      state: 0
    }, 
    {
      pos: [6, 0, 0], 
      state: 0
    }, 
    {
      pos: [6, 0, 1], 
      state: 0
    }, 
    {
      pos: [6, 0, 2], 
      state: 1
    }, 
    {
      pos: [6, 0, 5], 
      state: 1
    }, 
    {
      pos: [6, 0, 6], 
      state: 1
    }, 
    {
      pos: [6, 0, 7], 
      state: 0
    }, 
    {
      pos: [6, 0, 8], 
      state: 1
    }, 
    {
      pos: [6, 0, 9], 
      state: 0
    }, 
    {
      pos: [7, 0, 0], 
      state: 0
    }, 
    {
      pos: [7, 0, 1], 
      state: 0
    }, 
    {
      pos: [7, 0, 2], 
      state: 1
    }, 
    {
      pos: [7, 0, 5], 
      state: 1
    }, 
    {
      pos: [7, 0, 6], 
      state: 0
    }, 
    {
      pos: [7, 0, 7], 
      state: 1
    }, 
    {
      pos: [7, 0, 8], 
      state: 0
    }, 
    {
      pos: [7, 0, 9], 
      state: 0
    }, 
    {
      pos: [8, 0, 0], 
      state: 0
    }, 
    {
      pos: [8, 0, 1], 
      state: 0
    }, 
    {
      pos: [8, 0, 2], 
      state: 0
    }, 
    {
      pos: [8, 0, 3], 
      state: 0
    }, 
    {
      pos: [8, 0, 7], 
      state: 0
    }, 
    {
      pos: [8, 0, 8], 
      state: 0
    }, 
    {
      pos: [8, 0, 9], 
      state: 0
    }, 
    {
      pos: [9, 0, 0], 
      state: 0
    }, 
    {
      pos: [9, 0, 1], 
      state: 0
    }, 
    {
      pos: [9, 0, 2], 
      state: 0
    }, 
    {
      pos: [9, 0, 3], 
      state: 0
    }, 
    {
      pos: [9, 0, 7], 
      state: 0
    }, 
    {
      pos: [9, 0, 8], 
      state: 0
    }, 
    {
      pos: [9, 0, 9], 
      state: 0
    }, 
    {
      pos: [1, 1, 6], 
      state: 3
    }, 
    {
      pos: [1, 1, 8], 
      state: 3
    }, 
    {
      pos: [3, 1, 7], 
      state: 3
    }, 
    {
      pos: [5, 0, 3], 
      state: 4
    }, 
    {
      pos: [5, 0, 5], 
      state: 4
    }, 
    {
      pos: [6, 0, 3], 
      state: 4
    }, 
    {
      pos: [6, 0, 4], 
      state: 4
    }, 
    {
      pos: [7, 0, 3], 
      state: 4
    }, 
    {
      pos: [7, 0, 4], 
      state: 4
    }, 
    {
      pos: [8, 0, 4], 
      state: 4
    }, 
    {
      pos: [8, 0, 5], 
      state: 4
    }, 
    {
      pos: [8, 0, 6], 
      state: 4
    }, 
    {
      pos: [9, 0, 5], 
      state: 4
    }, 
    {
      pos: [9, 0, 6], 
      state: 4
    }, 
    {
      pos: [0, 1, 0], 
      state: 5
    }, 
    {
      pos: [0, 1, 1], 
      state: 5
    }, 
    {
      pos: [0, 1, 2], 
      state: 5
    }, 
    {
      pos: [0, 1, 3], 
      state: 5
    }, 
    {
      pos: [0, 1, 4], 
      state: 5
    }, 
    {
      pos: [0, 1, 5], 
      state: 6
    }, 
    {
      pos: [0, 1, 6], 
      state: 7
    }, 
    {
      pos: [0, 1, 7], 
      state: 8
    }, 
    {
      pos: [0, 1, 8], 
      state: 5
    }, 
    {
      pos: [0, 1, 9], 
      state: 5
    }, 
    {
      pos: [1, 1, 0], 
      state: 5
    }, 
    {
      pos: [1, 1, 1], 
      state: 5
    }, 
    {
      pos: [1, 1, 2], 
      state: 5
    }, 
    {
      pos: [1, 1, 3], 
      state: 5
    }, 
    {
      pos: [1, 1, 4], 
      state: 5
    }, 
    {
      pos: [1, 1, 5], 
      state: 9
    }, 
    {
      pos: [1, 1, 7], 
      state: 5
    }, 
    {
      pos: [1, 1, 9], 
      state: 10
    }, 
    {
      pos: [2, 1, 0], 
      state: 5
    }, 
    {
      pos: [2, 1, 1], 
      state: 5
    }, 
    {
      pos: [2, 1, 2], 
      state: 5
    }, 
    {
      pos: [2, 1, 3], 
      state: 5
    }, 
    {
      pos: [2, 1, 4], 
      state: 5
    }, 
    {
      pos: [2, 1, 5], 
      state: 5
    }, 
    {
      pos: [2, 1, 6], 
      state: 5
    }, 
    {
      pos: [2, 1, 7], 
      state: 11
    }, 
    {
      pos: [2, 1, 8], 
      state: 5
    }, 
    {
      pos: [2, 1, 9], 
      state: 12
    }, 
    {
      pos: [3, 1, 0], 
      state: 5
    }, 
    {
      pos: [3, 1, 1], 
      state: 5
    }, 
    {
      pos: [3, 1, 2], 
      state: 5
    }, 
    {
      pos: [3, 1, 3], 
      state: 5
    }, 
    {
      pos: [3, 1, 4], 
      state: 5
    }, 
    {
      pos: [3, 1, 5], 
      state: 13
    }, 
    {
      pos: [3, 1, 6], 
      state: 11
    }, 
    {
      pos: [3, 1, 8], 
      state: 5
    }, 
    {
      pos: [3, 1, 9], 
      state: 14
    }, 
    {
      pos: [4, 1, 0], 
      state: 5
    }, 
    {
      pos: [4, 1, 1], 
      state: 5
    }, 
    {
      pos: [4, 1, 2], 
      state: 5
    }, 
    {
      pos: [4, 1, 3], 
      state: 5
    }, 
    {
      pos: [4, 1, 4], 
      state: 5
    }, 
    {
      pos: [4, 1, 5], 
      state: 15
    }, 
    {
      pos: [4, 1, 6], 
      state: 16
    }, 
    {
      pos: [4, 1, 7], 
      state: 17
    }, 
    {
      pos: [4, 1, 8], 
      state: 5
    }, 
    {
      pos: [4, 1, 9], 
      state: 9
    }, 
    {
      pos: [5, 1, 0], 
      state: 5
    }, 
    {
      pos: [5, 1, 1], 
      state: 5
    }, 
    {
      pos: [5, 1, 2], 
      state: 5
    }, 
    {
      pos: [5, 1, 3], 
      state: 5
    }, 
    {
      pos: [5, 1, 5], 
      state: 5
    }, 
    {
      pos: [5, 1, 6], 
      state: 5
    }, 
    {
      pos: [5, 1, 7], 
      state: 5
    }, 
    {
      pos: [5, 1, 8], 
      state: 5
    }, 
    {
      pos: [5, 1, 9], 
      state: 5
    }, 
    {
      pos: [6, 1, 0], 
      state: 5
    }, 
    {
      pos: [6, 1, 1], 
      state: 5
    }, 
    {
      pos: [6, 1, 2], 
      state: 5
    }, 
    {
      pos: [6, 1, 3], 
      state: 5
    }, 
    {
      pos: [6, 1, 4], 
      state: 5
    }, 
    {
      pos: [6, 1, 5], 
      state: 5
    }, 
    {
      pos: [6, 1, 6], 
      state: 5
    }, 
    {
      pos: [6, 1, 7], 
      state: 5
    }, 
    {
      pos: [6, 1, 8], 
      state: 5
    }, 
    {
      pos: [6, 1, 9], 
      state: 5
    }, 
    {
      pos: [7, 1, 0], 
      state: 5
    }, 
    {
      pos: [7, 1, 1], 
      state: 5
    }, 
    {
      pos: [7, 1, 2], 
      state: 5
    }, 
    {
      pos: [7, 1, 3], 
      state: 5
    }, 
    {
      pos: [7, 1, 4], 
      state: 5
    }, 
    {
      pos: [7, 1, 5], 
      state: 5
    }, 
    {
      pos: [7, 1, 6], 
      state: 5
    }, 
    {
      pos: [7, 1, 7], 
      state: 5
    }, 
    {
      pos: [7, 1, 8], 
      state: 5
    }, 
    {
      pos: [7, 1, 9], 
      state: 5
    }, 
    {
      pos: [8, 1, 0], 
      state: 5
    }, 
    {
      pos: [8, 1, 1], 
      state: 5
    }, 
    {
      pos: [8, 1, 2], 
      state: 5
    }, 
    {
      pos: [8, 1, 3], 
      state: 5
    }, 
    {
      pos: [8, 1, 4], 
      state: 5
    }, 
    {
      pos: [8, 1, 5], 
      state: 5
    }, 
    {
      pos: [8, 1, 6], 
      state: 5
    }, 
    {
      pos: [8, 1, 7], 
      state: 5
    }, 
    {
      pos: [8, 1, 8], 
      state: 5
    }, 
    {
      pos: [8, 1, 9], 
      state: 5
    }, 
    {
      pos: [9, 1, 0], 
      state: 5
    }, 
    {
      pos: [9, 1, 1], 
      state: 5
    }, 
    {
      pos: [9, 1, 2], 
      state: 5
    }, 
    {
      pos: [9, 1, 3], 
      state: 5
    }, 
    {
      pos: [9, 1, 4], 
      state: 5
    }, 
    {
      pos: [9, 1, 5], 
      state: 5
    }, 
    {
      pos: [9, 1, 6], 
      state: 5
    }, 
    {
      pos: [9, 1, 7], 
      state: 5
    }, 
    {
      pos: [9, 1, 8], 
      state: 5
    }, 
    {
      pos: [9, 1, 9], 
      state: 5
    }, 
    {
      pos: [0, 2, 0], 
      state: 5
    }, 
    {
      pos: [0, 2, 1], 
      state: 5
    }, 
    {
      pos: [0, 2, 2], 
      state: 5
    }, 
    {
      pos: [0, 2, 3], 
      state: 5
    }, 
    {
      pos: [0, 2, 4], 
      state: 5
    }, 
    {
      pos: [0, 2, 5], 
      state: 5
    }, 
    {
      pos: [0, 2, 6], 
      state: 5
    }, 
    {
      pos: [0, 2, 7], 
      state: 5
    }, 
    {
      pos: [0, 2, 8], 
      state: 5
    }, 
    {
      pos: [0, 2, 9], 
      state: 5
    }, 
    {
      pos: [1, 2, 0], 
      state: 5
    }, 
    {
      pos: [1, 2, 1], 
      state: 5
    }, 
    {
      pos: [1, 2, 2], 
      state: 5
    }, 
    {
      pos: [1, 2, 3], 
      state: 5
    }, 
    {
      pos: [1, 2, 4], 
      state: 5
    }, 
    {
      pos: [1, 2, 5], 
      state: 5
    }, 
    {
      pos: [1, 2, 6], 
      state: 5
    }, 
    {
      pos: [1, 2, 7], 
      state: 5
    }, 
    {
      pos: [1, 2, 8], 
      state: 5
    }, 
    {
      pos: [1, 2, 9], 
      state: 5
    }, 
    {
      pos: [2, 2, 0], 
      state: 5
    }, 
    {
      pos: [2, 2, 1], 
      state: 5
    }, 
    {
      pos: [2, 2, 2], 
      state: 5
    }, 
    {
      pos: [2, 2, 3], 
      state: 5
    }, 
    {
      pos: [2, 2, 4], 
      state: 5
    }, 
    {
      pos: [2, 2, 5], 
      state: 5
    }, 
    {
      pos: [2, 2, 6], 
      state: 5
    }, 
    {
      pos: [2, 2, 7], 
      state: 5
    }, 
    {
      pos: [2, 2, 8], 
      state: 5
    }, 
    {
      pos: [2, 2, 9], 
      state: 5
    }, 
    {
      pos: [3, 2, 0], 
      state: 5
    }, 
    {
      pos: [3, 2, 1], 
      state: 5
    }, 
    {
      pos: [3, 2, 2], 
      state: 5
    }, 
    {
      pos: [3, 2, 3], 
      state: 5
    }, 
    {
      pos: [3, 2, 4], 
      state: 5
    }, 
    {
      pos: [3, 2, 5], 
      state: 5
    }, 
    {
      pos: [3, 2, 6], 
      state: 5
    }, 
    {
      pos: [3, 2, 7], 
      state: 5
    }, 
    {
      pos: [3, 2, 8], 
      state: 5
    }, 
    {
      pos: [3, 2, 9], 
      state: 5
    }, 
    {
      pos: [4, 2, 0], 
      state: 5
    }, 
    {
      pos: [4, 2, 1], 
      state: 5
    }, 
    {
      pos: [4, 2, 2], 
      state: 5
    }, 
    {
      pos: [4, 2, 3], 
      state: 5
    }, 
    {
      pos: [4, 2, 4], 
      state: 5
    }, 
    {
      pos: [4, 2, 5], 
      state: 5
    }, 
    {
      pos: [4, 2, 6], 
      state: 5
    }, 
    {
      pos: [4, 2, 7], 
      state: 5
    }, 
    {
      pos: [4, 2, 8], 
      state: 5
    }, 
    {
      pos: [4, 2, 9], 
      state: 5
    }, 
    {
      pos: [5, 2, 0], 
      state: 5
    }, 
    {
      pos: [5, 2, 1], 
      state: 5
    }, 
    {
      pos: [5, 2, 2], 
      state: 5
    }, 
    {
      pos: [5, 2, 3], 
      state: 5
    }, 
    {
      pos: [5, 2, 4], 
      state: 5
    }, 
    {
      pos: [5, 2, 5], 
      state: 5
    }, 
    {
      pos: [5, 2, 6], 
      state: 5
    }, 
    {
      pos: [5, 2, 7], 
      state: 5
    }, 
    {
      pos: [5, 2, 8], 
      state: 5
    }, 
    {
      pos: [5, 2, 9], 
      state: 5
    }, 
    {
      pos: [6, 2, 0], 
      state: 5
    }, 
    {
      pos: [6, 2, 1], 
      state: 5
    }, 
    {
      pos: [6, 2, 2], 
      state: 5
    }, 
    {
      pos: [6, 2, 3], 
      state: 5
    }, 
    {
      pos: [6, 2, 4], 
      state: 5
    }, 
    {
      pos: [6, 2, 5], 
      state: 5
    }, 
    {
      pos: [6, 2, 6], 
      state: 5
    }, 
    {
      pos: [6, 2, 7], 
      state: 5
    }, 
    {
      pos: [6, 2, 8], 
      state: 5
    }, 
    {
      pos: [6, 2, 9], 
      state: 5
    }, 
    {
      pos: [7, 2, 0], 
      state: 5
    }, 
    {
      pos: [7, 2, 1], 
      state: 5
    }, 
    {
      pos: [7, 2, 2], 
      state: 5
    }, 
    {
      pos: [7, 2, 3], 
      state: 5
    }, 
    {
      pos: [7, 2, 4], 
      state: 5
    }, 
    {
      pos: [7, 2, 5], 
      state: 5
    }, 
    {
      pos: [7, 2, 6], 
      state: 5
    }, 
    {
      pos: [7, 2, 7], 
      state: 5
    }, 
    {
      pos: [7, 2, 8], 
      state: 5
    }, 
    {
      pos: [7, 2, 9], 
      state: 5
    }, 
    {
      pos: [8, 2, 0], 
      state: 5
    }, 
    {
      pos: [8, 2, 1], 
      state: 5
    }, 
    {
      pos: [8, 2, 2], 
      state: 5
    }, 
    {
      pos: [8, 2, 3], 
      state: 5
    }, 
    {
      pos: [8, 2, 4], 
      state: 5
    }, 
    {
      pos: [8, 2, 5], 
      state: 5
    }, 
    {
      pos: [8, 2, 6], 
      state: 5
    }, 
    {
      pos: [8, 2, 7], 
      state: 5
    }, 
    {
      pos: [8, 2, 8], 
      state: 5
    }, 
    {
      pos: [8, 2, 9], 
      state: 5
    }, 
    {
      pos: [9, 2, 0], 
      state: 5
    }, 
    {
      pos: [9, 2, 1], 
      state: 5
    }, 
    {
      pos: [9, 2, 2], 
      state: 5
    }, 
    {
      pos: [9, 2, 3], 
      state: 5
    }, 
    {
      pos: [9, 2, 4], 
      state: 5
    }, 
    {
      pos: [9, 2, 5], 
      state: 5
    }, 
    {
      pos: [9, 2, 6], 
      state: 5
    }, 
    {
      pos: [9, 2, 7], 
      state: 5
    }, 
    {
      pos: [9, 2, 8], 
      state: 5
    }, 
    {
      pos: [9, 2, 9], 
      state: 5
    }, 
    {
      nbt: {
        components: {}, 
        joint: "rollable", 
        final_state: "minecraft:dirt_path", 
        name: "minecraft:end_connector", 
        placement_priority: 0, 
        pool: "minecraft:empty", 
        selection_priority: 0, 
        id: "minecraft:jigsaw", 
        target: "minecraft:connector"
      }, 
      pos: [9, 0, 4], 
      state: 18
    }, 
    {
      nbt: {
        components: {}, 
        Items: [], 
        CookingTimes: [I; 0, 0, 0, 0], 
        CookingTotalTimes: [I; 0, 0, 0, 0], 
        id: "minecraft:campfire"
      }, 
      pos: [5, 1, 4], 
      state: 19
    }
  ], 
  palette: [
    {
      Properties: {
        snowy: "false"
      }, 
      Name: "minecraft:grass_block"
    }, 
    {
      Name: "minecraft:gravel"
    }, 
    {
      Name: "minecraft:dirt"
    }, 
    {
      Name: "minecraft:pumpkin"
    }, 
    {
      Name: "minecraft:dirt_path"
    }, 
    {
      Name: "minecraft:air"
    }, 
    {
      Properties: {
        east: "low", 
        waterlogged: "false", 
        south: "low", 
        north: "none", 
        west: "none", 
        up: "true"
      }, 
      Name: "minecraft:mossy_cobblestone_wall"
    }, 
    {
      Properties: {
        east: "none", 
        waterlogged: "false", 
        south: "low", 
        north: "low", 
        west: "none", 
        up: "false"
      }, 
      Name: "minecraft:mossy_cobblestone_wall"
    }, 
    {
      Properties: {
        east: "none", 
        waterlogged: "false", 
        south: "none", 
        north: "low", 
        west: "none", 
        up: "true"
      }, 
      Name: "minecraft:cobblestone_wall"
    }, 
    {
      Properties: {
        east: "none", 
        waterlogged: "false", 
        south: "none", 
        north: "none", 
        west: "low", 
        up: "true"
      }, 
      Name: "minecraft:cobblestone_wall"
    }, 
    {
      Properties: {
        east: "low", 
        waterlogged: "false", 
        south: "none", 
        north: "none", 
        west: "none", 
        up: "true"
      }, 
      Name: "minecraft:mossy_cobblestone_wall"
    }, 
    {
      Name: "minecraft:cobweb"
    }, 
    {
      Properties: {
        east: "low", 
        waterlogged: "false", 
        south: "none", 
        north: "none", 
        west: "low", 
        up: "false"
      }, 
      Name: "minecraft:mossy_cobblestone_wall"
    }, 
    {
      Properties: {
        east: "low", 
        waterlogged: "false", 
        south: "none", 
        north: "none", 
        west: "none", 
        up: "true"
      }, 
      Name: "minecraft:cobblestone_wall"
    }, 
    {
      Properties: {
        east: "low", 
        waterlogged: "false", 
        south: "none", 
        north: "none", 
        west: "low", 
        up: "false"
      }, 
      Name: "minecraft:cobblestone_wall"
    }, 
    {
      Properties: {
        east: "none", 
        waterlogged: "false", 
        south: "low", 
        north: "none", 
        west: "low", 
        up: "true"
      }, 
      Name: "minecraft:cobblestone_wall"
    }, 
    {
      Properties: {
        east: "none", 
        waterlogged: "false", 
        south: "low", 
        north: "low", 
        west: "none", 
        up: "false"
      }, 
      Name: "minecraft:cobblestone_wall"
    }, 
    {
      Properties: {
        east: "none", 
        waterlogged: "false", 
        south: "none", 
        north: "low", 
        west: "none", 
        up: "true"
      }, 
      Name: "minecraft:mossy_cobblestone_wall"
    }, 
    {
      Properties: {
        orientation: "east_up"
      }, 
      Name: "minecraft:jigsaw"
    }, 
    {
      Properties: {
        waterlogged: "false", 
        signal_fire: "false", 
        lit: "false", 
        facing: "west"
      }, 
      Name: "minecraft:campfire"
    }
  ]
}
