{
  size: [12, 6, 11], 
  entities: [], 
  blocks: [
    {
      pos: [0, 0, 2], 
      state: 0
    }, 
    {
      pos: [0, 0, 8], 
      state: 0
    }, 
    {
      pos: [3, 0, 1], 
      state: 1
    }, 
    {
      pos: [3, 0, 2], 
      state: 1
    }, 
    {
      pos: [3, 0, 7], 
      state: 1
    }, 
    {
      pos: [3, 0, 8], 
      state: 1
    }, 
    {
      pos: [3, 0, 9], 
      state: 1
    }, 
    {
      pos: [4, 0, 0], 
      state: 1
    }, 
    {
      pos: [4, 0, 1], 
      state: 0
    }, 
    {
      pos: [4, 0, 2], 
      state: 0
    }, 
    {
      pos: [4, 0, 3], 
      state: 1
    }, 
    {
      pos: [4, 0, 4], 
      state: 1
    }, 
    {
      pos: [4, 0, 5], 
      state: 1
    }, 
    {
      pos: [4, 0, 6], 
      state: 1
    }, 
    {
      pos: [4, 0, 7], 
      state: 0
    }, 
    {
      pos: [4, 0, 8], 
      state: 0
    }, 
    {
      pos: [4, 0, 9], 
      state: 0
    }, 
    {
      pos: [4, 0, 10], 
      state: 1
    }, 
    {
      pos: [5, 0, 0], 
      state: 0
    }, 
    {
      pos: [5, 0, 1], 
      state: 0
    }, 
    {
      pos: [5, 0, 2], 
      state: 0
    }, 
    {
      pos: [5, 0, 3], 
      state: 1
    }, 
    {
      pos: [5, 0, 4], 
      state: 1
    }, 
    {
      pos: [5, 0, 5], 
      state: 1
    }, 
    {
      pos: [5, 0, 6], 
      state: 1
    }, 
    {
      pos: [5, 0, 7], 
      state: 0
    }, 
    {
      pos: [5, 0, 8], 
      state: 0
    }, 
    {
      pos: [5, 0, 9], 
      state: 0
    }, 
    {
      pos: [5, 0, 10], 
      state: 0
    }, 
    {
      pos: [6, 0, 0], 
      state: 1
    }, 
    {
      pos: [6, 0, 1], 
      state: 0
    }, 
    {
      pos: [6, 0, 2], 
      state: 0
    }, 
    {
      pos: [6, 0, 3], 
      state: 0
    }, 
    {
      pos: [6, 0, 4], 
      state: 0
    }, 
    {
      pos: [6, 0, 5], 
      state: 0
    }, 
    {
      pos: [6, 0, 6], 
      state: 0
    }, 
    {
      pos: [6, 0, 7], 
      state: 0
    }, 
    {
      pos: [6, 0, 8], 
      state: 0
    }, 
    {
      pos: [6, 0, 9], 
      state: 0
    }, 
    {
      pos: [6, 0, 10], 
      state: 1
    }, 
    {
      pos: [7, 0, 0], 
      state: 1
    }, 
    {
      pos: [7, 0, 1], 
      state: 0
    }, 
    {
      pos: [7, 0, 2], 
      state: 0
    }, 
    {
      pos: [7, 0, 3], 
      state: 0
    }, 
    {
      pos: [7, 0, 4], 
      state: 0
    }, 
    {
      pos: [7, 0, 5], 
      state: 0
    }, 
    {
      pos: [7, 0, 6], 
      state: 0
    }, 
    {
      pos: [7, 0, 7], 
      state: 0
    }, 
    {
      pos: [7, 0, 8], 
      state: 0
    }, 
    {
      pos: [7, 0, 9], 
      state: 0
    }, 
    {
      pos: [7, 0, 10], 
      state: 1
    }, 
    {
      pos: [8, 0, 0], 
      state: 1
    }, 
    {
      pos: [8, 0, 1], 
      state: 0
    }, 
    {
      pos: [8, 0, 2], 
      state: 0
    }, 
    {
      pos: [8, 0, 3], 
      state: 0
    }, 
    {
      pos: [8, 0, 4], 
      state: 0
    }, 
    {
      pos: [8, 0, 5], 
      state: 0
    }, 
    {
      pos: [8, 0, 6], 
      state: 0
    }, 
    {
      pos: [8, 0, 7], 
      state: 0
    }, 
    {
      pos: [8, 0, 8], 
      state: 0
    }, 
    {
      pos: [8, 0, 9], 
      state: 0
    }, 
    {
      pos: [8, 0, 10], 
      state: 1
    }, 
    {
      pos: [9, 0, 0], 
      state: 1
    }, 
    {
      pos: [9, 0, 1], 
      state: 0
    }, 
    {
      pos: [9, 0, 2], 
      state: 0
    }, 
    {
      pos: [9, 0, 3], 
      state: 0
    }, 
    {
      pos: [9, 0, 4], 
      state: 0
    }, 
    {
      pos: [9, 0, 5], 
      state: 0
    }, 
    {
      pos: [9, 0, 6], 
      state: 0
    }, 
    {
      pos: [9, 0, 7], 
      state: 0
    }, 
    {
      pos: [9, 0, 8], 
      state: 0
    }, 
    {
      pos: [9, 0, 9], 
      state: 0
    }, 
    {
      pos: [9, 0, 10], 
      state: 1
    }, 
    {
      pos: [10, 0, 1], 
      state: 0
    }, 
    {
      pos: [10, 0, 2], 
      state: 1
    }, 
    {
      pos: [10, 0, 3], 
      state: 1
    }, 
    {
      pos: [10, 0, 4], 
      state: 1
    }, 
    {
      pos: [10, 0, 5], 
      state: 1
    }, 
    {
      pos: [10, 0, 6], 
      state: 1
    }, 
    {
      pos: [10, 0, 7], 
      state: 1
    }, 
    {
      pos: [10, 0, 8], 
      state: 0
    }, 
    {
      pos: [10, 0, 9], 
      state: 0
    }, 
    {
      pos: [10, 0, 10], 
      state: 1
    }, 
    {
      pos: [11, 0, 1], 
      state: 0
    }, 
    {
      pos: [11, 0, 2], 
      state: 1
    }, 
    {
      pos: [11, 0, 3], 
      state: 1
    }, 
    {
      pos: [11, 0, 4], 
      state: 1
    }, 
    {
      pos: [11, 0, 5], 
      state: 1
    }, 
    {
      pos: [11, 0, 7], 
      state: 1
    }, 
    {
      pos: [11, 0, 8], 
      state: 0
    }, 
    {
      pos: [11, 0, 9], 
      state: 0
    }, 
    {
      pos: [11, 0, 10], 
      state: 1
    }, 
    {
      pos: [0, 1, 2], 
      state: 2
    }, 
    {
      pos: [0, 1, 8], 
      state: 2
    }, 
    {
      pos: [3, 1, 1], 
      state: 0
    }, 
    {
      pos: [3, 1, 2], 
      state: 0
    }, 
    {
      pos: [3, 1, 8], 
      state: 1
    }, 
    {
      pos: [3, 1, 9], 
      state: 3
    }, 
    {
      pos: [4, 1, 0], 
      state: 0
    }, 
    {
      pos: [4, 1, 1], 
      state: 0
    }, 
    {
      pos: [4, 1, 2], 
      state: 0
    }, 
    {
      pos: [4, 1, 3], 
      state: 1
    }, 
    {
      pos: [4, 1, 4], 
      state: 1
    }, 
    {
      pos: [4, 1, 5], 
      state: 1
    }, 
    {
      pos: [4, 1, 6], 
      state: 1
    }, 
    {
      pos: [4, 1, 7], 
      state: 2
    }, 
    {
      pos: [4, 1, 8], 
      state: 0
    }, 
    {
      pos: [4, 1, 9], 
      state: 0
    }, 
    {
      pos: [4, 1, 10], 
      state: 0
    }, 
    {
      pos: [5, 1, 0], 
      state: 0
    }, 
    {
      pos: [5, 1, 1], 
      state: 0
    }, 
    {
      pos: [5, 1, 2], 
      state: 1
    }, 
    {
      pos: [5, 1, 3], 
      state: 1
    }, 
    {
      pos: [5, 1, 4], 
      state: 1
    }, 
    {
      pos: [5, 1, 5], 
      state: 1
    }, 
    {
      pos: [5, 1, 6], 
      state: 1
    }, 
    {
      pos: [5, 1, 7], 
      state: 1
    }, 
    {
      pos: [5, 1, 8], 
      state: 1
    }, 
    {
      pos: [5, 1, 9], 
      state: 0
    }, 
    {
      pos: [5, 1, 10], 
      state: 0
    }, 
    {
      pos: [6, 1, 0], 
      state: 0
    }, 
    {
      pos: [6, 1, 1], 
      state: 0
    }, 
    {
      pos: [6, 1, 2], 
      state: 1
    }, 
    {
      pos: [6, 1, 3], 
      state: 3
    }, 
    {
      pos: [6, 1, 4], 
      state: 3
    }, 
    {
      pos: [6, 1, 5], 
      state: 3
    }, 
    {
      pos: [6, 1, 6], 
      state: 3
    }, 
    {
      pos: [6, 1, 7], 
      state: 3
    }, 
    {
      pos: [6, 1, 8], 
      state: 1
    }, 
    {
      pos: [6, 1, 9], 
      state: 0
    }, 
    {
      pos: [6, 1, 10], 
      state: 0
    }, 
    {
      pos: [7, 1, 0], 
      state: 0
    }, 
    {
      pos: [7, 1, 1], 
      state: 0
    }, 
    {
      pos: [7, 1, 2], 
      state: 1
    }, 
    {
      pos: [7, 1, 3], 
      state: 3
    }, 
    {
      pos: [7, 1, 4], 
      state: 3
    }, 
    {
      pos: [7, 1, 5], 
      state: 3
    }, 
    {
      pos: [7, 1, 6], 
      state: 3
    }, 
    {
      pos: [7, 1, 7], 
      state: 3
    }, 
    {
      pos: [7, 1, 8], 
      state: 1
    }, 
    {
      pos: [7, 1, 9], 
      state: 0
    }, 
    {
      pos: [8, 1, 0], 
      state: 0
    }, 
    {
      pos: [8, 1, 1], 
      state: 0
    }, 
    {
      pos: [8, 1, 2], 
      state: 1
    }, 
    {
      pos: [8, 1, 3], 
      state: 3
    }, 
    {
      pos: [8, 1, 4], 
      state: 3
    }, 
    {
      pos: [8, 1, 6], 
      state: 3
    }, 
    {
      pos: [8, 1, 7], 
      state: 3
    }, 
    {
      pos: [8, 1, 8], 
      state: 1
    }, 
    {
      pos: [8, 1, 9], 
      state: 0
    }, 
    {
      pos: [8, 1, 10], 
      state: 0
    }, 
    {
      pos: [9, 1, 0], 
      state: 0
    }, 
    {
      pos: [9, 1, 1], 
      state: 0
    }, 
    {
      pos: [9, 1, 2], 
      state: 1
    }, 
    {
      pos: [9, 1, 3], 
      state: 3
    }, 
    {
      pos: [9, 1, 4], 
      state: 3
    }, 
    {
      pos: [9, 1, 5], 
      state: 3
    }, 
    {
      pos: [9, 1, 6], 
      state: 3
    }, 
    {
      pos: [9, 1, 7], 
      state: 3
    }, 
    {
      pos: [9, 1, 8], 
      state: 1
    }, 
    {
      pos: [9, 1, 9], 
      state: 0
    }, 
    {
      pos: [9, 1, 10], 
      state: 0
    }, 
    {
      pos: [10, 1, 1], 
      state: 0
    }, 
    {
      pos: [10, 1, 2], 
      state: 1
    }, 
    {
      pos: [10, 1, 3], 
      state: 1
    }, 
    {
      pos: [10, 1, 4], 
      state: 1
    }, 
    {
      pos: [10, 1, 5], 
      state: 1
    }, 
    {
      pos: [10, 1, 6], 
      state: 1
    }, 
    {
      pos: [10, 1, 7], 
      state: 1
    }, 
    {
      pos: [10, 1, 8], 
      state: 1
    }, 
    {
      pos: [10, 1, 9], 
      state: 0
    }, 
    {
      pos: [10, 1, 10], 
      state: 0
    }, 
    {
      pos: [11, 1, 1], 
      state: 0
    }, 
    {
      pos: [11, 1, 2], 
      state: 1
    }, 
    {
      pos: [11, 1, 3], 
      state: 1
    }, 
    {
      pos: [11, 1, 4], 
      state: 1
    }, 
    {
      pos: [11, 1, 5], 
      state: 1
    }, 
    {
      pos: [11, 1, 6], 
      state: 1
    }, 
    {
      pos: [11, 1, 7], 
      state: 1
    }, 
    {
      pos: [11, 1, 8], 
      state: 1
    }, 
    {
      pos: [11, 1, 9], 
      state: 0
    }, 
    {
      pos: [11, 1, 10], 
      state: 0
    }, 
    {
      pos: [0, 2, 2], 
      state: 1
    }, 
    {
      pos: [0, 2, 8], 
      state: 1
    }, 
    {
      pos: [3, 2, 2], 
      state: 0
    }, 
    {
      pos: [3, 2, 8], 
      state: 0
    }, 
    {
      pos: [3, 2, 9], 
      state: 0
    }, 
    {
      pos: [4, 2, 1], 
      state: 0
    }, 
    {
      pos: [4, 2, 2], 
      state: 0
    }, 
    {
      pos: [4, 2, 8], 
      state: 0
    }, 
    {
      pos: [4, 2, 9], 
      state: 0
    }, 
    {
      pos: [5, 2, 0], 
      state: 0
    }, 
    {
      pos: [5, 2, 1], 
      state: 0
    }, 
    {
      pos: [5, 2, 9], 
      state: 0
    }, 
    {
      pos: [5, 2, 10], 
      state: 0
    }, 
    {
      pos: [6, 2, 0], 
      state: 0
    }, 
    {
      pos: [6, 2, 1], 
      state: 0
    }, 
    {
      pos: [6, 2, 9], 
      state: 0
    }, 
    {
      pos: [6, 2, 10], 
      state: 0
    }, 
    {
      pos: [7, 2, 0], 
      state: 0
    }, 
    {
      pos: [7, 2, 1], 
      state: 0
    }, 
    {
      pos: [7, 2, 2], 
      state: 1
    }, 
    {
      pos: [7, 2, 8], 
      state: 1
    }, 
    {
      pos: [7, 2, 9], 
      state: 0
    }, 
    {
      pos: [7, 2, 10], 
      state: 0
    }, 
    {
      pos: [8, 2, 0], 
      state: 0
    }, 
    {
      pos: [8, 2, 1], 
      state: 0
    }, 
    {
      pos: [8, 2, 9], 
      state: 0
    }, 
    {
      pos: [8, 2, 10], 
      state: 0
    }, 
    {
      pos: [9, 2, 0], 
      state: 0
    }, 
    {
      pos: [9, 2, 1], 
      state: 0
    }, 
    {
      pos: [9, 2, 9], 
      state: 0
    }, 
    {
      pos: [9, 2, 10], 
      state: 0
    }, 
    {
      pos: [10, 2, 1], 
      state: 0
    }, 
    {
      pos: [10, 2, 9], 
      state: 0
    }, 
    {
      pos: [11, 2, 1], 
      state: 0
    }, 
    {
      pos: [11, 2, 2], 
      state: 0
    }, 
    {
      pos: [11, 2, 3], 
      state: 3
    }, 
    {
      pos: [11, 2, 4], 
      state: 3
    }, 
    {
      pos: [11, 2, 5], 
      state: 3
    }, 
    {
      pos: [11, 2, 6], 
      state: 3
    }, 
    {
      pos: [11, 2, 7], 
      state: 3
    }, 
    {
      pos: [11, 2, 8], 
      state: 3
    }, 
    {
      pos: [11, 2, 9], 
      state: 0
    }, 
    {
      pos: [3, 3, 8], 
      state: 0
    }, 
    {
      pos: [4, 3, 1], 
      state: 0
    }, 
    {
      pos: [4, 3, 2], 
      state: 0
    }, 
    {
      pos: [4, 3, 8], 
      state: 0
    }, 
    {
      pos: [5, 3, 1], 
      state: 0
    }, 
    {
      pos: [5, 3, 9], 
      state: 0
    }, 
    {
      pos: [5, 3, 10], 
      state: 0
    }, 
    {
      pos: [6, 3, 1], 
      state: 0
    }, 
    {
      pos: [6, 3, 9], 
      state: 0
    }, 
    {
      pos: [6, 3, 10], 
      state: 0
    }, 
    {
      pos: [7, 3, 1], 
      state: 0
    }, 
    {
      pos: [7, 3, 2], 
      state: 1
    }, 
    {
      pos: [7, 3, 8], 
      state: 1
    }, 
    {
      pos: [7, 3, 9], 
      state: 0
    }, 
    {
      pos: [7, 3, 10], 
      state: 0
    }, 
    {
      pos: [8, 3, 1], 
      state: 0
    }, 
    {
      pos: [8, 3, 9], 
      state: 0
    }, 
    {
      pos: [8, 3, 10], 
      state: 0
    }, 
    {
      pos: [9, 3, 1], 
      state: 0
    }, 
    {
      pos: [9, 3, 9], 
      state: 0
    }, 
    {
      pos: [9, 3, 10], 
      state: 0
    }, 
    {
      pos: [10, 3, 9], 
      state: 0
    }, 
    {
      pos: [11, 3, 3], 
      state: 0
    }, 
    {
      pos: [11, 3, 4], 
      state: 3
    }, 
    {
      pos: [11, 3, 5], 
      state: 3
    }, 
    {
      pos: [11, 3, 6], 
      state: 3
    }, 
    {
      pos: [11, 3, 7], 
      state: 0
    }, 
    {
      pos: [11, 3, 8], 
      state: 3
    }, 
    {
      pos: [11, 3, 9], 
      state: 0
    }, 
    {
      pos: [7, 4, 2], 
      state: 2
    }, 
    {
      pos: [7, 4, 8], 
      state: 2
    }, 
    {
      pos: [8, 4, 9], 
      state: 3
    }, 
    {
      pos: [8, 4, 10], 
      state: 3
    }, 
    {
      pos: [9, 4, 9], 
      state: 1
    }, 
    {
      pos: [9, 4, 10], 
      state: 1
    }, 
    {
      pos: [10, 4, 9], 
      state: 0
    }, 
    {
      pos: [11, 4, 4], 
      state: 0
    }, 
    {
      pos: [11, 4, 5], 
      state: 0
    }, 
    {
      pos: [11, 4, 6], 
      state: 0
    }, 
    {
      pos: [11, 4, 7], 
      state: 3
    }, 
    {
      pos: [11, 4, 8], 
      state: 0
    }, 
    {
      pos: [11, 4, 9], 
      state: 0
    }, 
    {
      pos: [8, 5, 9], 
      state: 0
    }, 
    {
      pos: [11, 5, 5], 
      state: 0
    }, 
    {
      pos: [11, 5, 6], 
      state: 0
    }, 
    {
      pos: [11, 5, 7], 
      state: 0
    }, 
    {
      pos: [11, 5, 8], 
      state: 0
    }, 
    {
      nbt: {
        joint: "rollable", 
        final_state: "minecraft:structure_void", 
        name: "minecraft:connect_structure", 
        pool: "minecraft:empty", 
        id: "minecraft:jigsaw", 
        target: "minecraft:empty"
      }, 
      pos: [11, 0, 6], 
      state: 4
    }, 
    {
      nbt: {
        joint: "rollable", 
        final_state: "minecraft:deepslate", 
        name: "minecraft:bottom", 
        pool: "minecraft:ancient_city/sculk", 
        id: "minecraft:jigsaw", 
        target: "minecraft:bottom"
      }, 
      pos: [8, 1, 5], 
      state: 5
    }, 
    {
      nbt: {
        LootTable: "minecraft:chests/ancient_city", 
        id: "minecraft:chest"
      }, 
      pos: [10, 2, 5], 
      state: 6
    }
  ], 
  palette: [
    {
      Name: "minecraft:cobbled_deepslate"
    }, 
    {
      Name: "minecraft:deepslate_bricks"
    }, 
    {
      Name: "minecraft:chiseled_deepslate"
    }, 
    {
      Name: "minecraft:deepslate_tiles"
    }, 
    {
      Properties: {
        orientation: "east_up"
      }, 
      Name: "minecraft:jigsaw"
    }, 
    {
      Properties: {
        orientation: "up_west"
      }, 
      Name: "minecraft:jigsaw"
    }, 
    {
      Properties: {
        waterlogged: "false", 
        facing: "west", 
        type: "single"
      }, 
      Name: "minecraft:chest"
    }
  ]
}
