{
  size: [6, 15, 6], 
  entities: [], 
  blocks: [
    {
      pos: [0, 0, 0], 
      state: 0
    }, 
    {
      pos: [0, 0, 1], 
      state: 0
    }, 
    {
      pos: [0, 0, 2], 
      state: 0
    }, 
    {
      pos: [0, 0, 3], 
      state: 0
    }, 
    {
      pos: [0, 0, 4], 
      state: 0
    }, 
    {
      pos: [0, 0, 5], 
      state: 0
    }, 
    {
      pos: [1, 0, 0], 
      state: 0
    }, 
    {
      pos: [1, 0, 1], 
      state: 0
    }, 
    {
      pos: [1, 0, 2], 
      state: 0
    }, 
    {
      pos: [1, 0, 3], 
      state: 0
    }, 
    {
      pos: [1, 0, 4], 
      state: 0
    }, 
    {
      pos: [1, 0, 5], 
      state: 0
    }, 
    {
      pos: [2, 0, 0], 
      state: 0
    }, 
    {
      pos: [2, 0, 1], 
      state: 0
    }, 
    {
      pos: [2, 0, 2], 
      state: 0
    }, 
    {
      pos: [2, 0, 3], 
      state: 0
    }, 
    {
      pos: [2, 0, 4], 
      state: 0
    }, 
    {
      pos: [2, 0, 5], 
      state: 0
    }, 
    {
      pos: [3, 0, 0], 
      state: 0
    }, 
    {
      pos: [3, 0, 1], 
      state: 0
    }, 
    {
      pos: [3, 0, 2], 
      state: 0
    }, 
    {
      pos: [3, 0, 3], 
      state: 0
    }, 
    {
      pos: [3, 0, 4], 
      state: 0
    }, 
    {
      pos: [3, 0, 5], 
      state: 0
    }, 
    {
      pos: [4, 0, 0], 
      state: 0
    }, 
    {
      pos: [4, 0, 1], 
      state: 0
    }, 
    {
      pos: [4, 0, 2], 
      state: 0
    }, 
    {
      pos: [4, 0, 3], 
      state: 0
    }, 
    {
      pos: [4, 0, 4], 
      state: 0
    }, 
    {
      pos: [4, 0, 5], 
      state: 0
    }, 
    {
      pos: [5, 0, 0], 
      state: 0
    }, 
    {
      pos: [5, 0, 1], 
      state: 0
    }, 
    {
      pos: [5, 0, 3], 
      state: 0
    }, 
    {
      pos: [5, 0, 4], 
      state: 0
    }, 
    {
      pos: [5, 0, 5], 
      state: 0
    }, 
    {
      pos: [1, 1, 1], 
      state: 0
    }, 
    {
      pos: [1, 1, 2], 
      state: 0
    }, 
    {
      pos: [1, 1, 3], 
      state: 0
    }, 
    {
      pos: [1, 1, 4], 
      state: 0
    }, 
    {
      pos: [2, 1, 1], 
      state: 0
    }, 
    {
      pos: [2, 1, 2], 
      state: 0
    }, 
    {
      pos: [2, 1, 3], 
      state: 0
    }, 
    {
      pos: [2, 1, 4], 
      state: 0
    }, 
    {
      pos: [3, 1, 1], 
      state: 0
    }, 
    {
      pos: [3, 1, 2], 
      state: 0
    }, 
    {
      pos: [3, 1, 3], 
      state: 0
    }, 
    {
      pos: [3, 1, 4], 
      state: 0
    }, 
    {
      pos: [4, 1, 1], 
      state: 0
    }, 
    {
      pos: [4, 1, 2], 
      state: 0
    }, 
    {
      pos: [4, 1, 3], 
      state: 0
    }, 
    {
      pos: [4, 1, 4], 
      state: 0
    }, 
    {
      pos: [1, 2, 1], 
      state: 0
    }, 
    {
      pos: [1, 2, 2], 
      state: 0
    }, 
    {
      pos: [1, 2, 3], 
      state: 0
    }, 
    {
      pos: [1, 2, 4], 
      state: 0
    }, 
    {
      pos: [2, 2, 1], 
      state: 0
    }, 
    {
      pos: [2, 2, 2], 
      state: 0
    }, 
    {
      pos: [2, 2, 3], 
      state: 0
    }, 
    {
      pos: [2, 2, 4], 
      state: 0
    }, 
    {
      pos: [3, 2, 1], 
      state: 0
    }, 
    {
      pos: [3, 2, 2], 
      state: 0
    }, 
    {
      pos: [3, 2, 3], 
      state: 0
    }, 
    {
      pos: [3, 2, 4], 
      state: 0
    }, 
    {
      pos: [4, 2, 1], 
      state: 0
    }, 
    {
      pos: [4, 2, 2], 
      state: 0
    }, 
    {
      pos: [4, 2, 3], 
      state: 0
    }, 
    {
      pos: [4, 2, 4], 
      state: 0
    }, 
    {
      pos: [2, 3, 2], 
      state: 1
    }, 
    {
      pos: [2, 3, 3], 
      state: 1
    }, 
    {
      pos: [3, 3, 2], 
      state: 1
    }, 
    {
      pos: [3, 3, 3], 
      state: 1
    }, 
    {
      pos: [1, 4, 1], 
      state: 1
    }, 
    {
      pos: [1, 4, 2], 
      state: 1
    }, 
    {
      pos: [1, 4, 3], 
      state: 1
    }, 
    {
      pos: [1, 4, 4], 
      state: 1
    }, 
    {
      pos: [2, 4, 1], 
      state: 1
    }, 
    {
      pos: [2, 4, 2], 
      state: 1
    }, 
    {
      pos: [2, 4, 3], 
      state: 1
    }, 
    {
      pos: [2, 4, 4], 
      state: 1
    }, 
    {
      pos: [3, 4, 1], 
      state: 1
    }, 
    {
      pos: [3, 4, 2], 
      state: 1
    }, 
    {
      pos: [3, 4, 3], 
      state: 1
    }, 
    {
      pos: [3, 4, 4], 
      state: 1
    }, 
    {
      pos: [4, 4, 1], 
      state: 1
    }, 
    {
      pos: [4, 4, 2], 
      state: 1
    }, 
    {
      pos: [4, 4, 3], 
      state: 1
    }, 
    {
      pos: [4, 4, 4], 
      state: 1
    }, 
    {
      pos: [1, 5, 1], 
      state: 2
    }, 
    {
      pos: [1, 5, 2], 
      state: 3
    }, 
    {
      pos: [1, 5, 3], 
      state: 3
    }, 
    {
      pos: [1, 5, 4], 
      state: 2
    }, 
    {
      pos: [2, 5, 1], 
      state: 3
    }, 
    {
      pos: [2, 5, 2], 
      state: 1
    }, 
    {
      pos: [2, 5, 3], 
      state: 1
    }, 
    {
      pos: [2, 5, 4], 
      state: 3
    }, 
    {
      pos: [3, 5, 1], 
      state: 3
    }, 
    {
      pos: [3, 5, 2], 
      state: 1
    }, 
    {
      pos: [3, 5, 3], 
      state: 1
    }, 
    {
      pos: [3, 5, 4], 
      state: 3
    }, 
    {
      pos: [4, 5, 1], 
      state: 2
    }, 
    {
      pos: [4, 5, 2], 
      state: 3
    }, 
    {
      pos: [4, 5, 3], 
      state: 3
    }, 
    {
      pos: [4, 5, 4], 
      state: 2
    }, 
    {
      pos: [1, 6, 1], 
      state: 1
    }, 
    {
      pos: [1, 6, 2], 
      state: 1
    }, 
    {
      pos: [1, 6, 3], 
      state: 1
    }, 
    {
      pos: [1, 6, 4], 
      state: 1
    }, 
    {
      pos: [2, 6, 1], 
      state: 1
    }, 
    {
      pos: [2, 6, 2], 
      state: 1
    }, 
    {
      pos: [2, 6, 3], 
      state: 1
    }, 
    {
      pos: [2, 6, 4], 
      state: 1
    }, 
    {
      pos: [3, 6, 1], 
      state: 1
    }, 
    {
      pos: [3, 6, 2], 
      state: 1
    }, 
    {
      pos: [3, 6, 3], 
      state: 1
    }, 
    {
      pos: [3, 6, 4], 
      state: 1
    }, 
    {
      pos: [4, 6, 1], 
      state: 1
    }, 
    {
      pos: [4, 6, 2], 
      state: 1
    }, 
    {
      pos: [4, 6, 3], 
      state: 1
    }, 
    {
      pos: [4, 6, 4], 
      state: 1
    }, 
    {
      pos: [1, 7, 1], 
      state: 3
    }, 
    {
      pos: [1, 7, 2], 
      state: 2
    }, 
    {
      pos: [1, 7, 3], 
      state: 2
    }, 
    {
      pos: [1, 7, 4], 
      state: 3
    }, 
    {
      pos: [2, 7, 1], 
      state: 2
    }, 
    {
      pos: [2, 7, 2], 
      state: 1
    }, 
    {
      pos: [2, 7, 3], 
      state: 1
    }, 
    {
      pos: [2, 7, 4], 
      state: 2
    }, 
    {
      pos: [3, 7, 1], 
      state: 2
    }, 
    {
      pos: [3, 7, 2], 
      state: 1
    }, 
    {
      pos: [3, 7, 3], 
      state: 1
    }, 
    {
      pos: [3, 7, 4], 
      state: 2
    }, 
    {
      pos: [4, 7, 1], 
      state: 3
    }, 
    {
      pos: [4, 7, 2], 
      state: 2
    }, 
    {
      pos: [4, 7, 3], 
      state: 2
    }, 
    {
      pos: [4, 7, 4], 
      state: 3
    }, 
    {
      pos: [1, 8, 1], 
      state: 1
    }, 
    {
      pos: [1, 8, 2], 
      state: 1
    }, 
    {
      pos: [1, 8, 3], 
      state: 1
    }, 
    {
      pos: [1, 8, 4], 
      state: 1
    }, 
    {
      pos: [2, 8, 1], 
      state: 1
    }, 
    {
      pos: [2, 8, 2], 
      state: 1
    }, 
    {
      pos: [2, 8, 3], 
      state: 1
    }, 
    {
      pos: [2, 8, 4], 
      state: 1
    }, 
    {
      pos: [3, 8, 1], 
      state: 1
    }, 
    {
      pos: [3, 8, 2], 
      state: 1
    }, 
    {
      pos: [3, 8, 3], 
      state: 1
    }, 
    {
      pos: [3, 8, 4], 
      state: 1
    }, 
    {
      pos: [4, 8, 1], 
      state: 1
    }, 
    {
      pos: [4, 8, 2], 
      state: 1
    }, 
    {
      pos: [4, 8, 3], 
      state: 1
    }, 
    {
      pos: [4, 8, 4], 
      state: 1
    }, 
    {
      pos: [1, 9, 1], 
      state: 2
    }, 
    {
      pos: [1, 9, 2], 
      state: 3
    }, 
    {
      pos: [1, 9, 3], 
      state: 3
    }, 
    {
      pos: [1, 9, 4], 
      state: 2
    }, 
    {
      pos: [2, 9, 1], 
      state: 3
    }, 
    {
      pos: [2, 9, 2], 
      state: 1
    }, 
    {
      pos: [2, 9, 3], 
      state: 1
    }, 
    {
      pos: [2, 9, 4], 
      state: 3
    }, 
    {
      pos: [3, 9, 1], 
      state: 3
    }, 
    {
      pos: [3, 9, 2], 
      state: 1
    }, 
    {
      pos: [3, 9, 3], 
      state: 1
    }, 
    {
      pos: [3, 9, 4], 
      state: 3
    }, 
    {
      pos: [4, 9, 1], 
      state: 2
    }, 
    {
      pos: [4, 9, 2], 
      state: 3
    }, 
    {
      pos: [4, 9, 3], 
      state: 3
    }, 
    {
      pos: [4, 9, 4], 
      state: 2
    }, 
    {
      pos: [1, 10, 1], 
      state: 1
    }, 
    {
      pos: [1, 10, 2], 
      state: 1
    }, 
    {
      pos: [1, 10, 3], 
      state: 1
    }, 
    {
      pos: [1, 10, 4], 
      state: 1
    }, 
    {
      pos: [2, 10, 1], 
      state: 1
    }, 
    {
      pos: [2, 10, 2], 
      state: 1
    }, 
    {
      pos: [2, 10, 3], 
      state: 1
    }, 
    {
      pos: [2, 10, 4], 
      state: 1
    }, 
    {
      pos: [3, 10, 1], 
      state: 1
    }, 
    {
      pos: [3, 10, 2], 
      state: 1
    }, 
    {
      pos: [3, 10, 3], 
      state: 1
    }, 
    {
      pos: [3, 10, 4], 
      state: 1
    }, 
    {
      pos: [4, 10, 1], 
      state: 1
    }, 
    {
      pos: [4, 10, 2], 
      state: 1
    }, 
    {
      pos: [4, 10, 3], 
      state: 1
    }, 
    {
      pos: [4, 10, 4], 
      state: 1
    }, 
    {
      pos: [2, 11, 2], 
      state: 1
    }, 
    {
      pos: [2, 11, 3], 
      state: 1
    }, 
    {
      pos: [3, 11, 2], 
      state: 1
    }, 
    {
      pos: [3, 11, 3], 
      state: 1
    }, 
    {
      pos: [1, 12, 1], 
      state: 0
    }, 
    {
      pos: [1, 12, 2], 
      state: 0
    }, 
    {
      pos: [1, 12, 3], 
      state: 0
    }, 
    {
      pos: [1, 12, 4], 
      state: 0
    }, 
    {
      pos: [2, 12, 1], 
      state: 0
    }, 
    {
      pos: [2, 12, 2], 
      state: 0
    }, 
    {
      pos: [2, 12, 3], 
      state: 0
    }, 
    {
      pos: [2, 12, 4], 
      state: 0
    }, 
    {
      pos: [3, 12, 1], 
      state: 0
    }, 
    {
      pos: [3, 12, 2], 
      state: 0
    }, 
    {
      pos: [3, 12, 3], 
      state: 0
    }, 
    {
      pos: [3, 12, 4], 
      state: 0
    }, 
    {
      pos: [4, 12, 1], 
      state: 0
    }, 
    {
      pos: [4, 12, 2], 
      state: 0
    }, 
    {
      pos: [4, 12, 3], 
      state: 0
    }, 
    {
      pos: [4, 12, 4], 
      state: 0
    }, 
    {
      pos: [1, 13, 1], 
      state: 0
    }, 
    {
      pos: [1, 13, 2], 
      state: 0
    }, 
    {
      pos: [1, 13, 3], 
      state: 0
    }, 
    {
      pos: [1, 13, 4], 
      state: 0
    }, 
    {
      pos: [2, 13, 1], 
      state: 0
    }, 
    {
      pos: [2, 13, 2], 
      state: 0
    }, 
    {
      pos: [2, 13, 3], 
      state: 0
    }, 
    {
      pos: [2, 13, 4], 
      state: 0
    }, 
    {
      pos: [3, 13, 1], 
      state: 0
    }, 
    {
      pos: [3, 13, 2], 
      state: 0
    }, 
    {
      pos: [3, 13, 3], 
      state: 0
    }, 
    {
      pos: [3, 13, 4], 
      state: 0
    }, 
    {
      pos: [4, 13, 1], 
      state: 0
    }, 
    {
      pos: [4, 13, 2], 
      state: 0
    }, 
    {
      pos: [4, 13, 3], 
      state: 0
    }, 
    {
      pos: [4, 13, 4], 
      state: 0
    }, 
    {
      pos: [0, 14, 0], 
      state: 0
    }, 
    {
      pos: [0, 14, 1], 
      state: 0
    }, 
    {
      pos: [0, 14, 2], 
      state: 0
    }, 
    {
      pos: [0, 14, 3], 
      state: 0
    }, 
    {
      pos: [0, 14, 4], 
      state: 0
    }, 
    {
      pos: [0, 14, 5], 
      state: 0
    }, 
    {
      pos: [1, 14, 0], 
      state: 0
    }, 
    {
      pos: [1, 14, 1], 
      state: 0
    }, 
    {
      pos: [1, 14, 2], 
      state: 0
    }, 
    {
      pos: [1, 14, 3], 
      state: 0
    }, 
    {
      pos: [1, 14, 4], 
      state: 0
    }, 
    {
      pos: [1, 14, 5], 
      state: 0
    }, 
    {
      pos: [2, 14, 0], 
      state: 0
    }, 
    {
      pos: [2, 14, 1], 
      state: 0
    }, 
    {
      pos: [2, 14, 2], 
      state: 0
    }, 
    {
      pos: [2, 14, 3], 
      state: 0
    }, 
    {
      pos: [2, 14, 4], 
      state: 0
    }, 
    {
      pos: [2, 14, 5], 
      state: 0
    }, 
    {
      pos: [3, 14, 0], 
      state: 0
    }, 
    {
      pos: [3, 14, 1], 
      state: 0
    }, 
    {
      pos: [3, 14, 2], 
      state: 0
    }, 
    {
      pos: [3, 14, 3], 
      state: 0
    }, 
    {
      pos: [3, 14, 4], 
      state: 0
    }, 
    {
      pos: [3, 14, 5], 
      state: 0
    }, 
    {
      pos: [4, 14, 0], 
      state: 0
    }, 
    {
      pos: [4, 14, 1], 
      state: 0
    }, 
    {
      pos: [4, 14, 2], 
      state: 0
    }, 
    {
      pos: [4, 14, 3], 
      state: 0
    }, 
    {
      pos: [4, 14, 4], 
      state: 0
    }, 
    {
      pos: [4, 14, 5], 
      state: 0
    }, 
    {
      pos: [5, 14, 0], 
      state: 0
    }, 
    {
      pos: [5, 14, 1], 
      state: 0
    }, 
    {
      pos: [5, 14, 2], 
      state: 0
    }, 
    {
      pos: [5, 14, 3], 
      state: 0
    }, 
    {
      pos: [5, 14, 4], 
      state: 0
    }, 
    {
      pos: [5, 14, 5], 
      state: 0
    }, 
    {
      pos: [0, 1, 0], 
      state: 4
    }, 
    {
      pos: [0, 1, 1], 
      state: 5
    }, 
    {
      pos: [0, 1, 2], 
      state: 5
    }, 
    {
      pos: [0, 1, 3], 
      state: 5
    }, 
    {
      pos: [0, 1, 4], 
      state: 5
    }, 
    {
      pos: [0, 1, 5], 
      state: 6
    }, 
    {
      pos: [1, 1, 0], 
      state: 7
    }, 
    {
      pos: [1, 1, 5], 
      state: 8
    }, 
    {
      pos: [2, 1, 0], 
      state: 7
    }, 
    {
      pos: [2, 1, 5], 
      state: 8
    }, 
    {
      pos: [3, 1, 0], 
      state: 7
    }, 
    {
      pos: [3, 1, 5], 
      state: 8
    }, 
    {
      pos: [4, 1, 0], 
      state: 7
    }, 
    {
      pos: [4, 1, 5], 
      state: 8
    }, 
    {
      pos: [5, 1, 0], 
      state: 9
    }, 
    {
      pos: [5, 1, 1], 
      state: 10
    }, 
    {
      pos: [5, 1, 2], 
      state: 10
    }, 
    {
      pos: [5, 1, 3], 
      state: 10
    }, 
    {
      pos: [5, 1, 4], 
      state: 10
    }, 
    {
      pos: [5, 1, 5], 
      state: 11
    }, 
    {
      pos: [1, 3, 1], 
      state: 4
    }, 
    {
      pos: [1, 3, 2], 
      state: 5
    }, 
    {
      pos: [1, 3, 3], 
      state: 5
    }, 
    {
      pos: [1, 3, 4], 
      state: 6
    }, 
    {
      pos: [2, 3, 1], 
      state: 7
    }, 
    {
      pos: [2, 3, 4], 
      state: 8
    }, 
    {
      pos: [3, 3, 1], 
      state: 7
    }, 
    {
      pos: [3, 3, 4], 
      state: 8
    }, 
    {
      pos: [4, 3, 1], 
      state: 12
    }, 
    {
      pos: [4, 3, 2], 
      state: 10
    }, 
    {
      pos: [4, 3, 3], 
      state: 10
    }, 
    {
      pos: [4, 3, 4], 
      state: 11
    }, 
    {
      pos: [1, 11, 1], 
      state: 13
    }, 
    {
      pos: [1, 11, 2], 
      state: 14
    }, 
    {
      pos: [1, 11, 3], 
      state: 14
    }, 
    {
      pos: [1, 11, 4], 
      state: 15
    }, 
    {
      pos: [2, 11, 1], 
      state: 16
    }, 
    {
      pos: [2, 11, 4], 
      state: 17
    }, 
    {
      pos: [3, 11, 1], 
      state: 16
    }, 
    {
      pos: [3, 11, 4], 
      state: 17
    }, 
    {
      pos: [4, 11, 1], 
      state: 18
    }, 
    {
      pos: [4, 11, 2], 
      state: 19
    }, 
    {
      pos: [4, 11, 3], 
      state: 19
    }, 
    {
      pos: [4, 11, 4], 
      state: 20
    }, 
    {
      pos: [0, 13, 0], 
      state: 13
    }, 
    {
      pos: [0, 13, 1], 
      state: 14
    }, 
    {
      pos: [0, 13, 2], 
      state: 14
    }, 
    {
      pos: [0, 13, 3], 
      state: 14
    }, 
    {
      pos: [0, 13, 4], 
      state: 14
    }, 
    {
      pos: [0, 13, 5], 
      state: 15
    }, 
    {
      pos: [1, 13, 0], 
      state: 16
    }, 
    {
      pos: [1, 13, 5], 
      state: 17
    }, 
    {
      pos: [2, 13, 0], 
      state: 16
    }, 
    {
      pos: [2, 13, 5], 
      state: 17
    }, 
    {
      pos: [3, 13, 0], 
      state: 16
    }, 
    {
      pos: [3, 13, 5], 
      state: 17
    }, 
    {
      pos: [4, 13, 0], 
      state: 16
    }, 
    {
      pos: [4, 13, 5], 
      state: 17
    }, 
    {
      pos: [5, 13, 0], 
      state: 21
    }, 
    {
      pos: [5, 13, 1], 
      state: 19
    }, 
    {
      pos: [5, 13, 2], 
      state: 19
    }, 
    {
      pos: [5, 13, 3], 
      state: 19
    }, 
    {
      pos: [5, 13, 4], 
      state: 19
    }, 
    {
      pos: [5, 13, 5], 
      state: 20
    }, 
    {
      nbt: {
        joint: "rollable", 
        final_state: "minecraft:structure_void", 
        name: "minecraft:connect_structure", 
        pool: "minecraft:empty", 
        id: "minecraft:jigsaw", 
        target: "minecraft:empty"
      }, 
      pos: [5, 0, 2], 
      state: 22
    }
  ], 
  palette: [
    {
      Properties: {
        axis: "y"
      }, 
      Name: "minecraft:deepslate"
    }, 
    {
      Name: "minecraft:polished_deepslate"
    }, 
    {
      Name: "minecraft:chiseled_deepslate"
    }, 
    {
      Name: "minecraft:deepslate_tiles"
    }, 
    {
      Properties: {
        half: "bottom", 
        waterlogged: "false", 
        shape: "outer_right", 
        facing: "east"
      }, 
      Name: "minecraft:deepslate_tile_stairs"
    }, 
    {
      Properties: {
        half: "bottom", 
        waterlogged: "false", 
        shape: "straight", 
        facing: "east"
      }, 
      Name: "minecraft:deepslate_tile_stairs"
    }, 
    {
      Properties: {
        half: "bottom", 
        waterlogged: "false", 
        shape: "outer_left", 
        facing: "east"
      }, 
      Name: "minecraft:deepslate_tile_stairs"
    }, 
    {
      Properties: {
        half: "bottom", 
        waterlogged: "false", 
        shape: "straight", 
        facing: "south"
      }, 
      Name: "minecraft:deepslate_tile_stairs"
    }, 
    {
      Properties: {
        half: "bottom", 
        waterlogged: "false", 
        shape: "straight", 
        facing: "north"
      }, 
      Name: "minecraft:deepslate_tile_stairs"
    }, 
    {
      Properties: {
        half: "bottom", 
        waterlogged: "false", 
        shape: "outer_left", 
        facing: "west"
      }, 
      Name: "minecraft:deepslate_tile_stairs"
    }, 
    {
      Properties: {
        half: "bottom", 
        waterlogged: "false", 
        shape: "straight", 
        facing: "west"
      }, 
      Name: "minecraft:deepslate_tile_stairs"
    }, 
    {
      Properties: {
        half: "bottom", 
        waterlogged: "false", 
        shape: "outer_right", 
        facing: "west"
      }, 
      Name: "minecraft:deepslate_tile_stairs"
    }, 
    {
      Properties: {
        half: "bottom", 
        waterlogged: "false", 
        shape: "outer_right", 
        facing: "south"
      }, 
      Name: "minecraft:deepslate_tile_stairs"
    }, 
    {
      Properties: {
        half: "top", 
        waterlogged: "false", 
        shape: "outer_left", 
        facing: "south"
      }, 
      Name: "minecraft:deepslate_tile_stairs"
    }, 
    {
      Properties: {
        half: "top", 
        waterlogged: "false", 
        shape: "straight", 
        facing: "east"
      }, 
      Name: "minecraft:deepslate_tile_stairs"
    }, 
    {
      Properties: {
        half: "top", 
        waterlogged: "false", 
        shape: "outer_left", 
        facing: "east"
      }, 
      Name: "minecraft:deepslate_tile_stairs"
    }, 
    {
      Properties: {
        half: "top", 
        waterlogged: "false", 
        shape: "straight", 
        facing: "south"
      }, 
      Name: "minecraft:deepslate_tile_stairs"
    }, 
    {
      Properties: {
        half: "top", 
        waterlogged: "false", 
        shape: "straight", 
        facing: "north"
      }, 
      Name: "minecraft:deepslate_tile_stairs"
    }, 
    {
      Properties: {
        half: "top", 
        waterlogged: "false", 
        shape: "outer_right", 
        facing: "south"
      }, 
      Name: "minecraft:deepslate_tile_stairs"
    }, 
    {
      Properties: {
        half: "top", 
        waterlogged: "false", 
        shape: "straight", 
        facing: "west"
      }, 
      Name: "minecraft:deepslate_tile_stairs"
    }, 
    {
      Properties: {
        half: "top", 
        waterlogged: "false", 
        shape: "outer_right", 
        facing: "west"
      }, 
      Name: "minecraft:deepslate_tile_stairs"
    }, 
    {
      Properties: {
        half: "top", 
        waterlogged: "false", 
        shape: "outer_left", 
        facing: "west"
      }, 
      Name: "minecraft:deepslate_tile_stairs"
    }, 
    {
      Properties: {
        orientation: "east_up"
      }, 
      Name: "minecraft:jigsaw"
    }
  ]
}
