{
  size: [17, 23, 17], 
  entities: [], 
  blocks: [
    {
      pos: [4, 0, 6], 
      state: 0
    }, 
    {
      pos: [4, 0, 7], 
      state: 1
    }, 
    {
      pos: [4, 0, 8], 
      state: 1
    }, 
    {
      pos: [4, 0, 10], 
      state: 0
    }, 
    {
      pos: [5, 0, 5], 
      state: 1
    }, 
    {
      pos: [5, 0, 6], 
      state: 1
    }, 
    {
      pos: [5, 0, 7], 
      state: 1
    }, 
    {
      pos: [5, 0, 11], 
      state: 1
    }, 
    {
      pos: [6, 0, 4], 
      state: 0
    }, 
    {
      pos: [6, 0, 5], 
      state: 1
    }, 
    {
      pos: [6, 0, 6], 
      state: 1
    }, 
    {
      pos: [6, 0, 12], 
      state: 0
    }, 
    {
      pos: [7, 0, 4], 
      state: 1
    }, 
    {
      pos: [7, 0, 5], 
      state: 1
    }, 
    {
      pos: [7, 0, 6], 
      state: 0
    }, 
    {
      pos: [7, 0, 7], 
      state: 0
    }, 
    {
      pos: [7, 0, 12], 
      state: 1
    }, 
    {
      pos: [8, 0, 4], 
      state: 1
    }, 
    {
      pos: [8, 0, 5], 
      state: 1
    }, 
    {
      pos: [8, 0, 6], 
      state: 0
    }, 
    {
      pos: [8, 0, 11], 
      state: 1
    }, 
    {
      pos: [8, 0, 12], 
      state: 1
    }, 
    {
      pos: [9, 0, 4], 
      state: 1
    }, 
    {
      pos: [9, 0, 5], 
      state: 1
    }, 
    {
      pos: [9, 0, 6], 
      state: 0
    }, 
    {
      pos: [9, 0, 12], 
      state: 1
    }, 
    {
      pos: [10, 0, 4], 
      state: 1
    }, 
    {
      pos: [10, 0, 5], 
      state: 1
    }, 
    {
      pos: [10, 0, 6], 
      state: 1
    }, 
    {
      pos: [10, 0, 7], 
      state: 0
    }, 
    {
      pos: [10, 0, 10], 
      state: 1
    }, 
    {
      pos: [10, 0, 12], 
      state: 0
    }, 
    {
      pos: [11, 0, 5], 
      state: 1
    }, 
    {
      pos: [11, 0, 6], 
      state: 1
    }, 
    {
      pos: [11, 0, 7], 
      state: 1
    }, 
    {
      pos: [11, 0, 8], 
      state: 1
    }, 
    {
      pos: [11, 0, 9], 
      state: 1
    }, 
    {
      pos: [11, 0, 10], 
      state: 1
    }, 
    {
      pos: [11, 0, 11], 
      state: 1
    }, 
    {
      pos: [12, 0, 6], 
      state: 0
    }, 
    {
      pos: [12, 0, 7], 
      state: 1
    }, 
    {
      pos: [12, 0, 8], 
      state: 1
    }, 
    {
      pos: [12, 0, 9], 
      state: 1
    }, 
    {
      pos: [12, 0, 10], 
      state: 0
    }, 
    {
      pos: [5, 1, 5], 
      state: 1
    }, 
    {
      pos: [10, 1, 6], 
      state: 0
    }, 
    {
      pos: [11, 1, 5], 
      state: 1
    }, 
    {
      pos: [5, 2, 5], 
      state: 1
    }, 
    {
      pos: [10, 2, 6], 
      state: 0
    }, 
    {
      pos: [11, 2, 5], 
      state: 1
    }, 
    {
      pos: [11, 3, 5], 
      state: 1
    }, 
    {
      pos: [5, 4, 5], 
      state: 1
    }, 
    {
      pos: [10, 4, 6], 
      state: 0
    }, 
    {
      pos: [11, 4, 5], 
      state: 1
    }, 
    {
      pos: [5, 5, 5], 
      state: 1
    }, 
    {
      pos: [10, 5, 6], 
      state: 0
    }, 
    {
      pos: [11, 5, 5], 
      state: 1
    }, 
    {
      pos: [5, 6, 5], 
      state: 1
    }, 
    {
      pos: [10, 6, 6], 
      state: 0
    }, 
    {
      pos: [10, 6, 10], 
      state: 0
    }, 
    {
      pos: [11, 6, 5], 
      state: 1
    }, 
    {
      pos: [11, 6, 11], 
      state: 1
    }, 
    {
      pos: [4, 7, 5], 
      state: 1
    }, 
    {
      pos: [5, 7, 4], 
      state: 1
    }, 
    {
      pos: [5, 7, 5], 
      state: 1
    }, 
    {
      pos: [6, 7, 3], 
      state: 1
    }, 
    {
      pos: [6, 7, 4], 
      state: 1
    }, 
    {
      pos: [6, 7, 6], 
      state: 1
    }, 
    {
      pos: [7, 7, 3], 
      state: 1
    }, 
    {
      pos: [7, 7, 4], 
      state: 1
    }, 
    {
      pos: [7, 7, 5], 
      state: 1
    }, 
    {
      pos: [8, 7, 3], 
      state: 1
    }, 
    {
      pos: [8, 7, 4], 
      state: 1
    }, 
    {
      pos: [8, 7, 5], 
      state: 1
    }, 
    {
      pos: [9, 7, 3], 
      state: 1
    }, 
    {
      pos: [9, 7, 4], 
      state: 1
    }, 
    {
      pos: [9, 7, 5], 
      state: 1
    }, 
    {
      pos: [9, 7, 6], 
      state: 1
    }, 
    {
      pos: [9, 7, 7], 
      state: 1
    }, 
    {
      pos: [9, 7, 8], 
      state: 1
    }, 
    {
      pos: [10, 7, 3], 
      state: 1
    }, 
    {
      pos: [10, 7, 4], 
      state: 1
    }, 
    {
      pos: [10, 7, 6], 
      state: 1
    }, 
    {
      pos: [10, 7, 7], 
      state: 1
    }, 
    {
      pos: [10, 7, 8], 
      state: 1
    }, 
    {
      pos: [10, 7, 10], 
      state: 1
    }, 
    {
      pos: [11, 7, 4], 
      state: 1
    }, 
    {
      pos: [11, 7, 5], 
      state: 1
    }, 
    {
      pos: [11, 7, 7], 
      state: 1
    }, 
    {
      pos: [11, 7, 8], 
      state: 1
    }, 
    {
      pos: [11, 7, 9], 
      state: 1
    }, 
    {
      pos: [11, 7, 11], 
      state: 1
    }, 
    {
      pos: [11, 7, 12], 
      state: 1
    }, 
    {
      pos: [12, 7, 5], 
      state: 1
    }, 
    {
      pos: [12, 7, 6], 
      state: 1
    }, 
    {
      pos: [12, 7, 7], 
      state: 1
    }, 
    {
      pos: [12, 7, 8], 
      state: 1
    }, 
    {
      pos: [12, 7, 9], 
      state: 1
    }, 
    {
      pos: [12, 7, 10], 
      state: 1
    }, 
    {
      pos: [12, 7, 11], 
      state: 1
    }, 
    {
      pos: [13, 7, 6], 
      state: 1
    }, 
    {
      pos: [13, 7, 7], 
      state: 1
    }, 
    {
      pos: [13, 7, 8], 
      state: 1
    }, 
    {
      pos: [13, 7, 9], 
      state: 1
    }, 
    {
      pos: [13, 7, 10], 
      state: 1
    }, 
    {
      pos: [6, 13, 3], 
      state: 0
    }, 
    {
      pos: [9, 13, 6], 
      state: 0
    }, 
    {
      pos: [9, 13, 10], 
      state: 0
    }, 
    {
      pos: [10, 13, 3], 
      state: 0
    }, 
    {
      pos: [10, 13, 4], 
      state: 0
    }, 
    {
      pos: [10, 13, 5], 
      state: 0
    }, 
    {
      pos: [10, 13, 6], 
      state: 0
    }, 
    {
      pos: [10, 13, 7], 
      state: 0
    }, 
    {
      pos: [10, 13, 8], 
      state: 0
    }, 
    {
      pos: [10, 13, 10], 
      state: 0
    }, 
    {
      pos: [10, 13, 11], 
      state: 0
    }, 
    {
      pos: [10, 13, 12], 
      state: 0
    }, 
    {
      pos: [10, 13, 13], 
      state: 0
    }, 
    {
      pos: [11, 13, 5], 
      state: 0
    }, 
    {
      pos: [11, 13, 6], 
      state: 0
    }, 
    {
      pos: [12, 13, 6], 
      state: 0
    }, 
    {
      pos: [13, 13, 6], 
      state: 0
    }, 
    {
      pos: [2, 14, 6], 
      state: 0
    }, 
    {
      pos: [6, 14, 2], 
      state: 0
    }, 
    {
      pos: [10, 14, 2], 
      state: 0
    }, 
    {
      pos: [10, 14, 3], 
      state: 0
    }, 
    {
      pos: [10, 14, 14], 
      state: 0
    }, 
    {
      pos: [14, 14, 6], 
      state: 0
    }, 
    {
      pos: [14, 14, 10], 
      state: 0
    }, 
    {
      pos: [1, 15, 6], 
      state: 0
    }, 
    {
      pos: [2, 15, 6], 
      state: 0
    }, 
    {
      pos: [6, 15, 1], 
      state: 0
    }, 
    {
      pos: [6, 15, 2], 
      state: 0
    }, 
    {
      pos: [10, 15, 1], 
      state: 0
    }, 
    {
      pos: [10, 15, 2], 
      state: 0
    }, 
    {
      pos: [10, 15, 14], 
      state: 0
    }, 
    {
      pos: [14, 15, 6], 
      state: 0
    }, 
    {
      pos: [14, 15, 10], 
      state: 0
    }, 
    {
      pos: [15, 15, 6], 
      state: 0
    }, 
    {
      pos: [15, 15, 10], 
      state: 0
    }, 
    {
      pos: [1, 16, 6], 
      state: 0
    }, 
    {
      pos: [2, 16, 6], 
      state: 0
    }, 
    {
      pos: [6, 16, 1], 
      state: 0
    }, 
    {
      pos: [6, 16, 2], 
      state: 0
    }, 
    {
      pos: [10, 16, 1], 
      state: 0
    }, 
    {
      pos: [10, 16, 2], 
      state: 0
    }, 
    {
      pos: [10, 16, 14], 
      state: 0
    }, 
    {
      pos: [10, 16, 15], 
      state: 0
    }, 
    {
      pos: [14, 16, 6], 
      state: 0
    }, 
    {
      pos: [15, 16, 6], 
      state: 0
    }, 
    {
      pos: [15, 16, 10], 
      state: 0
    }, 
    {
      pos: [2, 17, 6], 
      state: 0
    }, 
    {
      pos: [3, 17, 6], 
      state: 0
    }, 
    {
      pos: [6, 17, 2], 
      state: 0
    }, 
    {
      pos: [6, 17, 3], 
      state: 0
    }, 
    {
      pos: [10, 17, 2], 
      state: 0
    }, 
    {
      pos: [10, 17, 3], 
      state: 0
    }, 
    {
      pos: [10, 17, 13], 
      state: 0
    }, 
    {
      pos: [10, 17, 14], 
      state: 0
    }, 
    {
      pos: [13, 17, 6], 
      state: 0
    }, 
    {
      pos: [14, 17, 6], 
      state: 0
    }, 
    {
      pos: [14, 17, 10], 
      state: 0
    }, 
    {
      pos: [3, 18, 6], 
      state: 0
    }, 
    {
      pos: [4, 18, 6], 
      state: 0
    }, 
    {
      pos: [5, 18, 6], 
      state: 0
    }, 
    {
      pos: [6, 18, 3], 
      state: 0
    }, 
    {
      pos: [6, 18, 4], 
      state: 0
    }, 
    {
      pos: [6, 18, 5], 
      state: 0
    }, 
    {
      pos: [6, 18, 6], 
      state: 0
    }, 
    {
      pos: [6, 18, 7], 
      state: 0
    }, 
    {
      pos: [6, 18, 8], 
      state: 0
    }, 
    {
      pos: [6, 18, 9], 
      state: 0
    }, 
    {
      pos: [6, 18, 10], 
      state: 0
    }, 
    {
      pos: [6, 18, 11], 
      state: 0
    }, 
    {
      pos: [6, 18, 12], 
      state: 0
    }, 
    {
      pos: [6, 18, 13], 
      state: 0
    }, 
    {
      pos: [7, 18, 6], 
      state: 0
    }, 
    {
      pos: [7, 18, 10], 
      state: 0
    }, 
    {
      pos: [8, 18, 6], 
      state: 0
    }, 
    {
      pos: [8, 18, 10], 
      state: 0
    }, 
    {
      pos: [9, 18, 6], 
      state: 0
    }, 
    {
      pos: [9, 18, 10], 
      state: 0
    }, 
    {
      pos: [10, 18, 3], 
      state: 0
    }, 
    {
      pos: [10, 18, 4], 
      state: 0
    }, 
    {
      pos: [10, 18, 5], 
      state: 0
    }, 
    {
      pos: [10, 18, 6], 
      state: 0
    }, 
    {
      pos: [10, 18, 7], 
      state: 0
    }, 
    {
      pos: [10, 18, 8], 
      state: 0
    }, 
    {
      pos: [10, 18, 9], 
      state: 0
    }, 
    {
      pos: [10, 18, 10], 
      state: 0
    }, 
    {
      pos: [10, 18, 11], 
      state: 0
    }, 
    {
      pos: [10, 18, 12], 
      state: 0
    }, 
    {
      pos: [10, 18, 13], 
      state: 0
    }, 
    {
      pos: [11, 18, 6], 
      state: 0
    }, 
    {
      pos: [11, 18, 10], 
      state: 0
    }, 
    {
      pos: [12, 18, 6], 
      state: 0
    }, 
    {
      pos: [12, 18, 10], 
      state: 0
    }, 
    {
      pos: [13, 18, 6], 
      state: 0
    }, 
    {
      pos: [13, 18, 10], 
      state: 0
    }, 
    {
      pos: [3, 0, 5], 
      state: 2
    }, 
    {
      pos: [3, 0, 6], 
      state: 3
    }, 
    {
      pos: [3, 0, 7], 
      state: 3
    }, 
    {
      pos: [3, 0, 8], 
      state: 3
    }, 
    {
      pos: [3, 0, 9], 
      state: 3
    }, 
    {
      pos: [3, 0, 10], 
      state: 3
    }, 
    {
      pos: [3, 0, 11], 
      state: 4
    }, 
    {
      pos: [4, 0, 4], 
      state: 2
    }, 
    {
      pos: [4, 0, 5], 
      state: 5
    }, 
    {
      pos: [4, 0, 11], 
      state: 6
    }, 
    {
      pos: [4, 0, 12], 
      state: 4
    }, 
    {
      pos: [5, 0, 3], 
      state: 2
    }, 
    {
      pos: [5, 0, 4], 
      state: 5
    }, 
    {
      pos: [5, 0, 12], 
      state: 6
    }, 
    {
      pos: [5, 0, 13], 
      state: 4
    }, 
    {
      pos: [6, 0, 3], 
      state: 7
    }, 
    {
      pos: [6, 0, 13], 
      state: 8
    }, 
    {
      pos: [7, 0, 3], 
      state: 7
    }, 
    {
      pos: [7, 0, 13], 
      state: 8
    }, 
    {
      pos: [8, 0, 3], 
      state: 7
    }, 
    {
      pos: [8, 0, 13], 
      state: 8
    }, 
    {
      pos: [9, 0, 3], 
      state: 7
    }, 
    {
      pos: [10, 0, 3], 
      state: 7
    }, 
    {
      pos: [10, 0, 13], 
      state: 8
    }, 
    {
      pos: [11, 0, 3], 
      state: 9
    }, 
    {
      pos: [11, 0, 4], 
      state: 10
    }, 
    {
      pos: [11, 0, 12], 
      state: 8
    }, 
    {
      pos: [12, 0, 4], 
      state: 9
    }, 
    {
      pos: [12, 0, 5], 
      state: 10
    }, 
    {
      pos: [12, 0, 11], 
      state: 11
    }, 
    {
      pos: [12, 0, 12], 
      state: 12
    }, 
    {
      pos: [13, 0, 5], 
      state: 9
    }, 
    {
      pos: [13, 0, 6], 
      state: 13
    }, 
    {
      pos: [11, 7, 6], 
      state: 14
    }, 
    {
      pos: [6, 8, 3], 
      state: 15
    }, 
    {
      pos: [10, 8, 3], 
      state: 15
    }, 
    {
      pos: [13, 8, 6], 
      state: 15
    }, 
    {
      pos: [13, 8, 10], 
      state: 15
    }, 
    {
      pos: [6, 9, 3], 
      state: 15
    }, 
    {
      pos: [10, 9, 3], 
      state: 15
    }, 
    {
      pos: [13, 9, 6], 
      state: 15
    }, 
    {
      pos: [13, 9, 10], 
      state: 15
    }, 
    {
      pos: [6, 10, 3], 
      state: 15
    }, 
    {
      pos: [10, 10, 3], 
      state: 15
    }, 
    {
      pos: [13, 10, 6], 
      state: 15
    }, 
    {
      pos: [13, 10, 10], 
      state: 15
    }, 
    {
      pos: [6, 11, 3], 
      state: 15
    }, 
    {
      pos: [10, 11, 3], 
      state: 15
    }, 
    {
      pos: [13, 11, 6], 
      state: 15
    }, 
    {
      pos: [13, 11, 10], 
      state: 15
    }, 
    {
      pos: [6, 12, 3], 
      state: 15
    }, 
    {
      pos: [10, 12, 3], 
      state: 15
    }, 
    {
      pos: [10, 12, 13], 
      state: 15
    }, 
    {
      pos: [13, 12, 6], 
      state: 15
    }, 
    {
      pos: [13, 12, 10], 
      state: 15
    }, 
    {
      pos: [8, 13, 4], 
      state: 16
    }, 
    {
      pos: [9, 13, 4], 
      state: 16
    }, 
    {
      pos: [9, 13, 5], 
      state: 16
    }, 
    {
      pos: [9, 13, 7], 
      state: 16
    }, 
    {
      pos: [9, 13, 9], 
      state: 16
    }, 
    {
      pos: [9, 13, 11], 
      state: 16
    }, 
    {
      pos: [9, 13, 12], 
      state: 16
    }, 
    {
      pos: [11, 13, 4], 
      state: 16
    }, 
    {
      pos: [11, 13, 7], 
      state: 16
    }, 
    {
      pos: [11, 13, 12], 
      state: 16
    }, 
    {
      pos: [12, 13, 5], 
      state: 16
    }, 
    {
      pos: [12, 13, 7], 
      state: 16
    }, 
    {
      pos: [3, 14, 5], 
      state: 16
    }, 
    {
      pos: [11, 14, 3], 
      state: 16
    }, 
    {
      pos: [12, 14, 4], 
      state: 16
    }, 
    {
      pos: [13, 14, 5], 
      state: 16
    }, 
    {
      pos: [2, 15, 5], 
      state: 16
    }, 
    {
      pos: [3, 15, 4], 
      state: 16
    }, 
    {
      pos: [5, 15, 2], 
      state: 16
    }, 
    {
      pos: [8, 15, 14], 
      state: 16
    }, 
    {
      pos: [9, 15, 14], 
      state: 16
    }, 
    {
      pos: [11, 15, 2], 
      state: 16
    }, 
    {
      pos: [11, 15, 14], 
      state: 16
    }, 
    {
      pos: [12, 15, 3], 
      state: 16
    }, 
    {
      pos: [12, 15, 13], 
      state: 16
    }, 
    {
      pos: [13, 15, 4], 
      state: 16
    }, 
    {
      pos: [14, 15, 5], 
      state: 16
    }, 
    {
      pos: [14, 15, 7], 
      state: 16
    }, 
    {
      pos: [14, 15, 8], 
      state: 16
    }, 
    {
      pos: [14, 15, 9], 
      state: 16
    }, 
    {
      pos: [6, 17, 6], 
      state: 17
    }, 
    {
      pos: [10, 17, 6], 
      state: 17
    }, 
    {
      nbt: {
        final_state: "minecraft:air", 
        name: "minecraft:connect_structure", 
        pool: "minecraft:empty", 
        joint: "rollable", 
        id: "minecraft:jigsaw", 
        target: "minecraft:empty"
      }, 
      pos: [8, 0, 16], 
      state: 18
    }, 
    {
      nbt: {
        LootTable: "minecraft:chests/ancient_city", 
        id: "minecraft:chest"
      }, 
      pos: [10, 14, 7], 
      state: 19
    }
  ], 
  palette: [
    {
      Name: "minecraft:deepslate_tiles"
    }, 
    {
      Name: "minecraft:deepslate_bricks"
    }, 
    {
      Properties: {
        half: "bottom", 
        waterlogged: "false", 
        shape: "outer_right", 
        facing: "east"
      }, 
      Name: "minecraft:deepslate_tile_stairs"
    }, 
    {
      Properties: {
        half: "bottom", 
        waterlogged: "false", 
        shape: "straight", 
        facing: "east"
      }, 
      Name: "minecraft:deepslate_tile_stairs"
    }, 
    {
      Properties: {
        half: "bottom", 
        waterlogged: "false", 
        shape: "outer_right", 
        facing: "north"
      }, 
      Name: "minecraft:deepslate_tile_stairs"
    }, 
    {
      Properties: {
        half: "bottom", 
        waterlogged: "false", 
        shape: "inner_left", 
        facing: "south"
      }, 
      Name: "minecraft:deepslate_tile_stairs"
    }, 
    {
      Properties: {
        half: "bottom", 
        waterlogged: "false", 
        shape: "inner_left", 
        facing: "east"
      }, 
      Name: "minecraft:deepslate_tile_stairs"
    }, 
    {
      Properties: {
        half: "bottom", 
        waterlogged: "false", 
        shape: "straight", 
        facing: "south"
      }, 
      Name: "minecraft:deepslate_tile_stairs"
    }, 
    {
      Properties: {
        half: "bottom", 
        waterlogged: "false", 
        shape: "straight", 
        facing: "north"
      }, 
      Name: "minecraft:deepslate_tile_stairs"
    }, 
    {
      Properties: {
        half: "bottom", 
        waterlogged: "false", 
        shape: "outer_right", 
        facing: "south"
      }, 
      Name: "minecraft:deepslate_tile_stairs"
    }, 
    {
      Properties: {
        half: "bottom", 
        waterlogged: "false", 
        shape: "inner_left", 
        facing: "west"
      }, 
      Name: "minecraft:deepslate_tile_stairs"
    }, 
    {
      Properties: {
        half: "bottom", 
        waterlogged: "false", 
        shape: "inner_left", 
        facing: "north"
      }, 
      Name: "minecraft:deepslate_tile_stairs"
    }, 
    {
      Properties: {
        half: "bottom", 
        waterlogged: "false", 
        shape: "outer_right", 
        facing: "west"
      }, 
      Name: "minecraft:deepslate_tile_stairs"
    }, 
    {
      Properties: {
        half: "bottom", 
        waterlogged: "false", 
        shape: "straight", 
        facing: "west"
      }, 
      Name: "minecraft:deepslate_tile_stairs"
    }, 
    {
      Properties: {
        waterlogged: "false", 
        facing: "south"
      }, 
      Name: "minecraft:ladder"
    }, 
    {
      Properties: {
        east: "none", 
        waterlogged: "false", 
        south: "none", 
        north: "none", 
        west: "none", 
        up: "true"
      }, 
      Name: "minecraft:polished_deepslate_wall"
    }, 
    {
      Properties: {
        waterlogged: "false", 
        type: "top"
      }, 
      Name: "minecraft:deepslate_tile_slab"
    }, 
    {
      Properties: {
        east: "none", 
        waterlogged: "false", 
        south: "none", 
        north: "none", 
        west: "none", 
        up: "true"
      }, 
      Name: "minecraft:deepslate_tile_wall"
    }, 
    {
      Properties: {
        orientation: "south_up"
      }, 
      Name: "minecraft:jigsaw"
    }, 
    {
      Properties: {
        waterlogged: "false", 
        facing: "south", 
        type: "single"
      }, 
      Name: "minecraft:chest"
    }
  ]
}
